Workbook

Sheet README
A1: 南電（8046.TW）收支與估值模型 v0.1（AI 半導體 Project：載板與 PCB 次產業） 2026-10-25
A2: 版本：v0.1（初版）。樣板：unimicron/。AI 加速器載板的每顆金額、Ibiden 份額與非 NVIDIA 權重讀 ibiden/dist，欣興份額讀 unimicron/dist（本專案權威）；三家份額合計在 Units 頁檢查。
A3: 模型命題：南電的 ABF 載板營收＝MIN（需求, 產能）；需求以網通交換器載板為主（隨 markets/network 的交換晶片與交換器市場），加上 AI 加速器顆數 × 每顆載板金額（與 Ibiden、欣興同口徑）× 南電份額（個位數）與非 AI ABF；產能 2026–28 年靠去瓶頸與昆山廠爬坡，新廠約 2029 年。BT 載板（約三成營收）以漲價為主。資本支出低（2026 年約 40 億）、折舊約 70 億。
A4: 核心問題：2026 年下半年的漲價與交換器載板需求，能不能讓毛利率從 FY2026 約 27% 再升、EPS 在 FY2027–28 倍增；約 1,265 元的股價隱含什麼路徑。
A6: 會計年度＝日曆年，FY(t)＝CY(t)，不平移。預測期 FY2027–FY2029 由驅動因子推導；FY2030 起為收斂法，非驅動因子推導（延伸到 FY2032；PL 頁灰底）。金額：十億新台幣；EPS：新台幣（基本、歸屬母公司）。3Q26 財報約 10 月底公布，本版只納入 3Q26 營收實績。
A8: 驅動因子 → 推導量（全部唯讀上游，不修改）
A9: 加速器載板：markets/network 的 NVIDIA 與非 NVIDIA 顆數 × tsmc 同字母情境係數 × 每顆 NVIDIA 載板金額（Ibiden 模型 US$215 × 面積層數 +18%／年 × Ibiden 溢價指數）× 南電份額（NVIDIA 2%→4%、非 NVIDIA 金額 5%→7%，Assumed）× 漲價年度化 1.15。
A10: 其他 AI 載板（交換器為主）＝FY2026 AI 載板（ABF × 65%）− 加速器載板（校準殘差），之後 × 交換晶片與交換器市場成長 ^ 0.5 × 情境係數 × 溢價 × 漲價年度化；非 AI ABF +3%。ABF 產能指數 1.20／1.35／1.60（Assumed）× 組合 +5%／年。BT 年增依情境（A 30%／10%／5%、B 25%／5%／3%、C 15%／0%／0%），PCB 持平。
A11: 毛利＝FY2026 錨點＋ABF 現金毛利增量（50%）＋其他產品現金毛利增量（40%）＋漲價溢價營收 − 折舊增量；折舊＝前一年 ×（1 − 1／8 年）＋前一年資本支出 ÷ 8 年；資本支出 140／180／120 億（三情境相同）。營業費用彈性 0.6；業外每年 6 億；稅率 21%；股數持平 6.46 億股。
A12: 校準：FY2026 ＝ 1Q26、2Q26 財報實績（EPS 2.03、3.50）＋3Q26 營收實績 163.8 億＋3Q26 毛利率 30%、4Q26 營收季增 10%、毛利率 32.5%（Assumed）。不用券商數字（只在 Recon 對帳）。
A13: 估值：Val 第 0 節目標價＝0.5 × DCF 目標價（股東現金流＝每股（淨利＋折舊－資本支出），FY2027–32 明確期＋永續，r 10%、g 4%，三情境權重 0.3／0.5／0.2，負值取 0）＋0.5 × Comparable 目標價（欣興、景碩、Ibiden、三星電機、AT&S 前瞻 P/E 中位數 × 12 個月後前瞻 EPS；無 A 股）；另列 Comparable 單獨目標價、市場共識目標價與差距拆解。十年 P/E 規則值 × FY2027 EPS 保留為參考（不是目標價）。本版未做先驗，無 Andy 合理 P/E 對照。
A14: 情境與行業一致：A／B／C 讀 tsmc 同字母顆數係數（＝markets/memory SCEN_UNITS，建置時核對）；交換器市場讀 markets/network（單一路徑 × 同字母係數）；公司特有變數只有 BT 年增隨情境，A 最有利、C 最不利。
... A17: 已知限制：(1) 加速器、交換器與 CPU 載板的拆分公司未揭露，其他 AI 載板為校準殘差；(2) 份額、產能指數、漲價年度化皆為 Assumed，與 Ibiden、欣興合計只做上限檢查；(3) 毛利用現金流通率近似，未建分廠稼動率；(4) AMD 伺服器 CPU 認證（美銀：成功則 2027 年逾兩成營收）未建入；(5) 新廠資本支出未定，DCF 現金流可能偏高；(6) 十年 P/E 2016–2018 年虧損不計，其餘與盈餘反向；(7) FactSet 共識為 2026-06；(8) 3Q26 財報（約 10 月底）後更新錨點。

Sheet In
A1: In — 輸入（藍字；基準欄 E，低 D、高 F）。金額：十億新台幣（NT$B）；顆數：百萬顆；比例：%。每個輸入附兩個來源（找不到者寫「未找到」）；公司原文算一個
A2: 標記：Verified／Interested-party／Analogy／Assumed／Derived；Analogy、Assumed 給低／高區間，不當點估計（放情境或 Sens）。SemiAnalysis 未使用。公司數字經資料商（stockanalysis）與媒體轉載；公司說法為 Interested-party；券商、媒體、資料商為 Interested-party
A3: 鍵 | B3: 項目 | C3: 單位 | D3: 低 | E3: 基準 | F3: 高 | G3: 標記 | H3: 來源1 | I3: 來源2／說明
A4: A. AI 加速器顆數、AI IT 資本支出與交換器市場（讀 markets/network、tsmc 成品；唯讀，不自行重估）
A5: u_bw_26 | B5: NVIDIA Blackwell（B200／B300） 顆數 2026 | C5: 百萬顆 | E5: 5.4 | G5: Derived | H5: markets/network/dist/20261023_AI網通市場模型_v0.2.2.xlsx｜In!E5 | I5: 唯讀上游；與 Ibiden、欣興、台積電模型同一份顆數
A6: u_bw_27 | B6: NVIDIA Blackwell（B200／B300） 顆數 2027 | C6: 百萬顆 | E6: 2.4 | G6: Derived | H6: markets/network/dist/20261023_AI網通市場模型_v0.2.2.xlsx｜In!E6 | I6: 唯讀上游；與 Ibiden、欣興、台積電模型同一份顆數
A7: u_bw_28 | B7: NVIDIA Blackwell（B200／B300） 顆數 2028 | C7: 百萬顆 | E7: 0.5 | G7: Derived | H7: markets/network/dist/20261023_AI網通市場模型_v0.2.2.xlsx｜In!E7 | I7: 唯讀上游；與 Ibiden、欣興、台積電模型同一份顆數
A8: g29_bw | B8: NVIDIA Blackwell（B200／B300） 2029 顆數成長 | C8: % | E8: -0.5 | G8: Derived | H8: markets/network/dist/20261023_AI網通市場模型_v0.2.2.xlsx｜In!E8 | I8: 同上
A9: u_rb_26 | B9: NVIDIA Rubin 顆數 2026 | C9: 百萬顆 | E9: 1.7 | G9: Derived | H9: markets/network/dist/20261023_AI網通市場模型_v0.2.2.xlsx｜In!E9 | I9: 唯讀上游；與 Ibiden、欣興、台積電模型同一份顆數
A10: u_rb_27 | B10: NVIDIA Rubin 顆數 2027 | C10: 百萬顆 | E10: 7 | G10: Derived | H10: markets/network/dist/20261023_AI網通市場模型_v0.2.2.xlsx｜In!E10 | I10: 唯讀上游；與 Ibiden、欣興、台積電模型同一份顆數
A11: u_rb_28 | B11: NVIDIA Rubin 顆數 2028 | C11: 百萬顆 | E11: 7 | G11: Derived | H11: markets/network/dist/20261023_AI網通市場模型_v0.2.2.xlsx｜In!E11 | I11: 唯讀上游；與 Ibiden、欣興、台積電模型同一份顆數
A12: g29_rb | B12: NVIDIA Rubin 2029 顆數成長 | C12: % | E12: 0.15 | G12: Derived | H12: markets/network/dist/20261023_AI網通市場模型_v0.2.2.xlsx｜In!E12 | I12: 同上
A13: u_ru_26 | B13: NVIDIA Rubin Ultra 顆數 2026 | C13: 百萬顆 | E13: 0 | G13: Derived | H13: markets/network/dist/20261023_AI網通市場模型_v0.2.2.xlsx｜In!E13 | I13: 唯讀上游；與 Ibiden、欣興、台積電模型同一份顆數
A14: u_ru_27 | B14: NVIDIA Rubin Ultra 顆數 2027 | C14: 百萬顆 | E14: 0.3 | G14: Derived | H14: markets/network/dist/20261023_AI網通市場模型_v0.2.2.xlsx｜In!E14 | I14: 唯讀上游；與 Ibiden、欣興、台積電模型同一份顆數
A15: u_ru_28 | B15: NVIDIA Rubin Ultra 顆數 2028 | C15: 百萬顆 | E15: 2 | G15: Derived | H15: markets/network/dist/20261023_AI網通市場模型_v0.2.2.xlsx｜In!E15 | I15: 唯讀上游；與 Ibiden、欣興、台積電模型同一份顆數
A16: g29_ru | B16: NVIDIA Rubin Ultra 2029 顆數成長 | C16: % | E16: 0.15 | G16: Derived | H16: markets/network/dist/20261023_AI網通市場模型_v0.2.2.xlsx｜In!E16 | I16: 同上
... A50: um29_C | B50: 情境 C：2029 顆數 ÷ 基準 | C50: x | E50: 0.6 | G50: Assumed | H50: tsmc/dist/20261025_台積電模型_v0.3.xlsx｜In!E42 | I50: 同上
A51: B. 每顆加速器載板金額與份額（口徑與 Ibiden、欣興一致；兩者數字唯讀取自各自 dist）
A52: v26 | B52: FY2026 每顆 NVIDIA 加速器載板金額（全市場；Ibiden 模型校準） | C52: US$ | E52: 215.3086 | G52: Derived | H52: ibiden/dist/20261025_Ibiden模型_v0.2.xlsx｜Units!C8 | I52: Ibiden 模型：Ibiden 每顆營收 ÷ 份額 70%（BofA，Interested-party）
A53: g_asp | B53: 每顆載板金額年增（面積、層數；Ibiden 模型） | C53: % | D53: 0.1 | E53: 0.18 | F53: 0.22 | G53: Analogy | H53: ibiden/dist/20261025_Ibiden模型_v0.2.xlsx｜In!E50 | I53: Ibiden 路線圖 2026 年 90×90 mm → 2028 年 110×110 mm（經 Ibiden 模型）
A54: ibpp_27 | B54: ABF 價格溢價指數 2027（FY2026＝1；Ibiden 模型） | C54: x | D54: 0.95 | E54: 1 | F54: 1.05 | G54: Assumed | H54: ibiden/dist/20261025_Ibiden模型_v0.2.xlsx｜In!E55 | I54: 全市場短缺溢價；新產能到位後回落（Ibiden 模型；欣興模型同值）
A55: ibrel_27 | B55: Ibiden NVIDIA 份額 2027 ÷ 2026（Ibiden 模型） | C55: x | E55: 0.95 | G55: Assumed | H55: ibiden/dist/20261025_Ibiden模型_v0.2.xlsx｜In!E51 | I55: Units 頁份額合計檢查用
A56: ibpp_28 | B56: ABF 價格溢價指數 2028（FY2026＝1；Ibiden 模型） | C56: x | D56: 0.85 | E56: 0.95 | F56: 1.05 | G56: Assumed | H56: ibiden/dist/20261025_Ibiden模型_v0.2.xlsx｜In!E56 | I56: 同上
A57: ibrel_28 | B57: Ibiden NVIDIA 份額 2028 ÷ 2026（Ibiden 模型） | C57: x | E57: 0.88 | G57: Assumed | H57: ibiden/dist/20261025_Ibiden模型_v0.2.xlsx｜In!E52 | I57: Units 頁份額合計檢查用
A58: ibpp_29 | B58: ABF 價格溢價指數 2029（FY2026＝1；Ibiden 模型） | C58: x | D58: 0.75 | E58: 0.9 | F58: 1 | G58: Assumed | H58: ibiden/dist/20261025_Ibiden模型_v0.2.xlsx｜In!E57 | I58: 同上
A59: ibrel_29 | B59: Ibiden NVIDIA 份額 2029 ÷ 2026（Ibiden 模型） | C59: x | E59: 0.85 | G59: Assumed | H59: ibiden/dist/20261025_Ibiden模型_v0.2.xlsx｜In!E53 | I59: Units 頁份額合計檢查用
A60: ib_sh26 | B60: Ibiden 占 NVIDIA 加速器載板 FY2026（Ibiden 模型假設） | C60: % | D60: 0.7 | E60: 0.7 | F60: 0.8 | G60: Interested-party | H60: ibiden/dist/20261025_Ibiden模型_v0.2.xlsx｜Units!C8（列標籤：假設 FY2026 份額 70%） | I60: BofA：Ibiden 70–80%
A61: ib_w_ot | B61: Ibiden 非 NVIDIA 權重（份額 × 每顆金額，相對 NVIDIA；Ibiden 模型） | C61: x | D61: 0.2 | E61: 0.4 | F61: 0.6 | G61: Assumed | H61: ibiden/dist/20261025_Ibiden模型_v0.2.xlsx｜In!E48 | I61: Units 頁：÷ v_ot 即 Ibiden 非 NVIDIA 份額
A62: v_ot | B62: 非 NVIDIA 加速器每顆載板金額 ÷ NVIDIA（欣興模型同值） | C62: x | D62: 0.6 | E62: 0.8 | F62: 1 | G62: Assumed | H62: TPU、Trainium、MI 系列封裝面積接近 GPU；量化：未找到 | I62: 與欣興模型 v_ot 相同
A63: un_nv_26 | B63: 欣興占 NVIDIA 加速器載板 2026（欣興模型） | C63: % | E63: 0.25 | G63: Assumed | H63: unimicron/dist/20261025_欣興模型_v0.1.xlsx｜In!E59 | I63: Units 頁份額合計檢查用
A64: un_ot_26 | B64: 欣興占非 NVIDIA 加速器載板（金額）2026（欣興模型） | C64: % | E64: 0.3 | G64: Assumed | H64: unimicron/dist/20261025_欣興模型_v0.1.xlsx｜In!E63 | I64: 同上
A65: un_nv_27 | B65: 欣興占 NVIDIA 加速器載板 2027（欣興模型） | C65: % | E65: 0.27 | G65: Assumed | H65: unimicron/dist/20261025_欣興模型_v0.1.xlsx｜In!E60 | I65: Units 頁份額合計檢查用
A66: un_ot_27 | B66: 欣興占非 NVIDIA 加速器載板（金額）2027（欣興模型） | C66: % | E66: 0.31 | G66: Assumed | H66: unimicron/dist/20261025_欣興模型_v0.1.xlsx｜In!E64 | I66: 同上
A67: un_nv_28 | B67: 欣興占 NVIDIA 加速器載板 2028（欣興模型） | C67: % | E67: 0.29 | G67: Assumed | H67: unimicron/dist/20261025_欣興模型_v0.1.xlsx｜In!E61 | I67: Units 頁份額合計檢查用
A68: un_ot_28 | B68: 欣興占非 NVIDIA 加速器載板（金額）2028（欣興模型） | C68: % | E68: 0.32 | G68: Assumed | H68: unimicron/dist/20261025_欣興模型_v0.1.xlsx｜In!E65 | I68: 同上
A69: un_nv_29 | B69: 欣興占 NVIDIA 加速器載板 2029（欣興模型） | C69: % | E69: 0.3 | G69: Assumed | H69: unimicron/dist/20261025_欣興模型_v0.1.xlsx｜In!E62 | I69: Units 頁份額合計檢查用
A70: un_ot_29 | B70: 欣興占非 NVIDIA 加速器載板（金額）2029（欣興模型） | C70: % | E70: 0.33 | G70: Assumed | H70: unimicron/dist/20261025_欣興模型_v0.1.xlsx｜In!E66 | I70: 同上
A71: sh_nv_26 | B71: 南電占 NVIDIA 加速器載板 2026 | C71: % | D71: 0.01 | E71: 0.02 | F71: 0.03 | G71: Assumed | H71: 凱基 PCB 產業報告 2026-07-20（Interested-party）：客戶含博通、輝達、超微、蘋果（份額未揭露） | I71: 南電 AI 載板以網通交換器為主，GPU 載板份額小（brodoginvestment 南電深度分析（引述券商報告；Interested-party））；量化：未找到
A72: sh_nv_27 | B72: 南電占 NVIDIA 加速器載板 2027 | C72: % | D72: 0.01 | E72: 0.03 | F72: 0.05 | G72: Assumed | H72: Ibiden、欣興合計 95%→約 90%，其餘由南電、三星電機分食（Units 頁） | I72: —
A73: sh_nv_28 | B73: 南電占 NVIDIA 加速器載板 2028 | C73: % | D73: 0.01 | E73: 0.04 | F73: 0.06 | G73: Assumed | H73: Ibiden、欣興合計 95%→約 90%，其餘由南電、三星電機分食（Units 頁） | I73: —
...

Sheet Q
A1: Q — FY2025 實績、1Q26／2Q26 實績、3Q26 營收實績與 FY2026 錨點（十億新台幣；EPS 新台幣、基本；股數十億股）。藍字＝輸入；黑字＝公式
A2: FY2026 錨點＝1Q、2Q26 財報實績＋3Q26 營收實績（月營收）與 3Q26 毛利率、費用假設＋4Q26 假設。3Q26 財報約 10 月底公布，屆時以實績取代 E 欄（毛利率、費用、業外、淨利）
A3: 項目 | B3: FY2025A | C3: 1Q26（實績） | D3: 2Q26（實績） | E3: 3Q26（營收實績） | F3: 4Q26（模型） | G3: FY2026 錨點 | H3: 標記 | I3: 來源1（公司） | J3: 來源2／說明
A4: 營收 | B4: 40.173 | C4: 11.177 | D4: 13.575 | E4: =q3_rev -> 16.379 | F4: =E4*(1+q4_g) -> 18.0169 | G4: =SUM(C4:F4) -> 59.1479 | H4: Verified／Assumed（4Q） | I4: stockanalysis 年度與季損益表（公司財報轉載） | J4: FY2025 401.73 億（vocus 4Q25 法說、FactSet 同）；1Q26 111.77 億（富果同）；2Q26 135.75 億（大和、三立同）
A5: 毛利 | B5: 3.647 | C5: 1.771 | D5: 3.36 | E5: =E4*q3_gm -> 4.9137 | F5: =F4*q4_gm -> 5.8554925 | G5: =SUM(C5:F5) -> 15.900192 | H5: Verified／Assumed | I5: stockanalysis 年度與季損益表（公司財報轉載） | J5: 1Q26 毛利率 15.8%（三立同；富果摘要 16.8% 與此不符，不採用）
A6: 毛利率 | B6: =B5/B4 -> 0.090782366 | C6: =C5/C4 -> 0.15845039 | D6: =D5/D4 -> 0.24751381 | E6: =E5/E4 -> 0.3 | F6: =F5/F4 -> 0.325 | G6: =G5/G4 -> 0.26882091 | H6: Derived | I6: — | J6: FY2025 9.08%（凱基、美銀 9.1%）
A7: 營業費用 | B7: =B5-B8 -> 1.665 | C7: =C5-C8 -> 0.419 | D7: =D5-D8 -> 0.461 | E7: =q3_opx -> 0.5 | F7: =q4_opx -> 0.52 | G7: =SUM(C7:F7) -> 1.9 | H7: Derived／Assumed | I7: 毛利 − 營業利益 | J7: —
A8: 營業利益 | B8: 1.982 | C8: 1.352 | D8: 2.899 | E8: =E5-E7 -> 4.4137 | F8: =F5-F7 -> 5.3354925 | G8: =SUM(C8:F8) -> 14.000193 | H8: Verified／Derived | I8: stockanalysis 年度與季損益表（公司財報轉載） | J8: FY2025 19.82 億（vocus 同）；1Q26 13.52 億（富果同）
A9: 營業外淨額 | B9: 0.364 | C9: 0.246 | D9: 0.077 | E9: =q_nonop -> 0.15 | F9: =q_nonop -> 0.15 | G9: =SUM(C9:F9) -> 0.623 | H9: Derived／Assumed | I9: stockanalysis 年度與季損益表（公司財報轉載） | J9: 稅前利益 − 營業利益；稅前利益由 stockanalysis 稅前利益率 × 營收推得（近似）
A10: 稅前利益 | B10: =B8+B9 -> 2.346 | C10: =C8+C9 -> 1.598 | D10: =D8+D9 -> 2.976 | E10: =E8+E9 -> 4.5637 | F10: =F8+F9 -> 5.4854925 | G10: =SUM(C10:F10) -> 14.623193 | H10: Derived | I10: —
A11: 歸屬母公司淨利 | B11: 1.947 | C11: 1.309 | D11: 2.262 | E11: =E10*(1-tax) -> 3.605323 | F11: =F10*(1-tax) -> 4.3335391 | G11: =SUM(C11:F11) -> 11.509862 | H11: Verified／Derived | I11: stockanalysis 年度與季損益表（公司財報轉載） | J11: FY2025 19.47 億（FactSet 表同）；2Q26 22.61 億（大和同）
A12: 所得稅 | B12: =B10-B11 -> 0.399 | C12: =C10-C11 -> 0.289 | D12: =D10-D11 -> 0.714 | E12: =E10-E11 -> 0.958377 | F12: =F10-F11 -> 1.1519534 | G12: =SUM(C12:F12) -> 3.1133304 | H12: Derived | I12: — | J12: —
A13: 加權股數（十億股） | B13: =B11/B14 -> 0.64684385 | C13: =C11/C14 -> 0.64482759 | D13: =D11/D14 -> 0.64628571 | E13: =q_sh -> 0.64617 | F13: =q_sh -> 0.64617 | G13: =AVERAGE(C13:F13) -> 0.64586333 | H13: Derived | I13: 淨利 ÷ EPS | J13: —
A14: EPS（基本） | B14: 3.01 | C14: 2.03 | D14: 3.5 | E14: =E11/E13 -> 5.5795271 | F14: =F11/F13 -> 6.7065 | G14: =G11/G13 -> 17.820894 | H14: Verified／Derived | I14: stockanalysis 年度與季損益表（公司財報轉載） | J14: FY2025 3.01（wantgoo 同）；1Q26 2.03（winvest 同）；2Q26 3.50（大和、HiStock 同）
A15: 折舊攤提（年度） | B15: 6.894 | G15: =da26 -> 7.1 | H15: Verified／Interested-party | I15: stockanalysis 現金流量表 | J15: FY2026：TTM 至 2026-06 71.0 億
A16: 資本支出（年度） | B16: 2.422 | G16: =capex26 -> 4 | H16: Verified／Interested-party | I16: FY2025：stockanalysis 現金流量表；FY2026：公司計畫約 40 億 | J16: 富果摘要稱 2025 年實際 43.14 億（口徑可能含預付設備款；不採用）
A18: FY2026 產品別（錨點營收 × In 頁 C 節占比）
A19: ABF 載板 | G19: =G4*mx_abf -> 34.305782 | H19: Derived
A20: BT 載板 | G20: =G4*mx_bt -> 18.927328 | H20: Derived
A21: PCB（一般電路板） | G21: =G4*(1-mx_abf-mx_bt) -> 5.91479 | H21: Derived
A23: 檢查（參考；校準未使用券商數字）
A24: 1H26 營收 自算 − 前 9 月累計 41.131 + 3Q26（應為 0） | B24: =C4+D4-(41.131-q3_rev) -> 0
A25: FY2026 營收年增 | B25: =G4/B4-1 -> 0.47232967
A26: FY2025→FY2026 現金毛利增量 ÷ 營收增量（含漲價；In 頁 ft_abf、ft_oth 的對照） | B26: =((G5+G15)-(B5+B15))/(G4-B4) -> 0.6566144
A27: FY2026 EPS ÷ 凱基 17.27 − 1 | B27: =G14/17.27-1 -> 0.03189892
A28: 3Q26 EPS ÷ 大和估 5.62 − 1 | B28: =E14/5.62-1 -> -0.0072015908
A29: 4Q26 營收年化 ÷ FY2026 營收（漲價年度化 carry 的對照） | B29: =F4*4/G4 -> 1.2184304

Sheet Units
A1: Units — 南電在 AI 加速器載板的份額與每顆金額（口徑與 Ibiden、欣興模型一致；情境 A）。份額合計＝Ibiden（ibiden/dist）＋欣興（unimicron/dist）＋南電，其餘為三星電機、景碩、AT&S 等
A3: 項目 | B3: 單位 | C3: CY2026 | D3: CY2027 | E3: CY2028 | F3: CY2029 | G3: 說明
A4: NVIDIA 加速器顆數 | B4: 百萬顆 | C4: =PL!D63 -> 7.6 | D4: =PL!E63 -> 9.7 | E4: =PL!F63 -> 9.5 | F4: =PL!G63 -> 10.6 | G4: markets/network
A5: 非 NVIDIA 加速器顆數 | B5: 百萬顆 | C5: =PL!D64 -> 7.6 | D5: =PL!E64 -> 14 | E5: =PL!F64 -> 17 | F5: =PL!G64 -> 19.55
A6: 每顆 NVIDIA 加速器載板金額（全市場） | B6: US$ | C6: =PL!D68 -> 215.3086 | D6: =PL!E68 -> 254.06414 | E6: =PL!F68 -> 284.8059 | F6: =PL!G68 -> 318.38302 | G6: Ibiden 模型 Units 頁同值（FY2026 校準 × 面積層數 × 溢價）
A7: 南電份額：NVIDIA | B7: % | C7: =PL!D69 -> 0.02 | D7: =PL!E69 -> 0.03 | E7: =PL!F69 -> 0.04 | F7: =PL!G69 -> 0.04 | G7: Assumed
A8: Ibiden 份額：NVIDIA（70% × Ibiden 份額相對值） | B8: % | C8: =ib_sh26*1 -> 0.7 | D8: =ib_sh26*ibrel_27 -> 0.665 | E8: =ib_sh26*ibrel_28 -> 0.616 | F8: =ib_sh26*ibrel_29 -> 0.595 | G8: Ibiden 模型
A9: 欣興份額：NVIDIA | B9: % | C9: =un_nv_26 -> 0.25 | D9: =un_nv_27 -> 0.27 | E9: =un_nv_28 -> 0.29 | F9: =un_nv_29 -> 0.3 | G9: 欣興模型
A10: 合計：Ibiden＋欣興＋南電（NVIDIA） | B10: % | C10: =C7+C8+C9 -> 0.97 | D10: =D7+D8+D9 -> 0.965 | E10: =E7+E8+E9 -> 0.946 | F10: =F7+F8+F9 -> 0.935 | G10: 應 ≤ 100%；其餘為三星電機等
A11: 南電份額：非 NVIDIA（金額） | B11: % | C11: =PL!D70 -> 0.05 | D11: =PL!E70 -> 0.06 | E11: =PL!F70 -> 0.07 | F11: =PL!G70 -> 0.07 | G11: Assumed
A12: Ibiden 份額：非 NVIDIA（Ibiden 權重 × 份額相對值 ÷ v_ot） | B12: % | C12: =ib_w_ot*1/v_ot -> 0.5 | D12: =ib_w_ot*ibrel_27/v_ot -> 0.475 | E12: =ib_w_ot*ibrel_28/v_ot -> 0.44 | F12: =ib_w_ot*ibrel_29/v_ot -> 0.425 | G12: 與欣興模型同算法
A13: 欣興份額：非 NVIDIA（金額） | B13: % | C13: =un_ot_26 -> 0.3 | D13: =un_ot_27 -> 0.31 | E13: =un_ot_28 -> 0.32 | F13: =un_ot_29 -> 0.33 | G13: 欣興模型
A14: 合計：Ibiden＋欣興＋南電（非 NVIDIA） | B14: % | C14: =C11+C12+C13 -> 0.85 | D14: =D11+D12+D13 -> 0.845 | E14: =E11+E12+E13 -> 0.83 | F14: =F11+F12+F13 -> 0.825 | G14: 應 ≤ 100%；其餘為三星電機、景碩、AT&S
A15: 每顆 NVIDIA 加速器的南電營收 | B15: US$ | C15: =PL!D68*PL!D69*PL!D67 -> 4.3061719 | D15: =PL!E68*PL!E69*PL!E67 -> 8.7652129 | E15: =PL!F68*PL!F69*PL!F67 -> 13.101072 | F15: =PL!G68*PL!G69*PL!G67 -> 14.645619 | G15: Ibiden、欣興對照值見各自 dist Units 頁
A16: 南電加速器載板營收 | B16: US$M | C16: =PL!D71 -> 98.18072 | D16: =PL!E71 -> 281.36334 | E16: =PL!F71 -> 436.26568 | F16: =PL!G71 -> 556.09415
A17: 南電 AI 載板營收（含交換器等其他 AI） | B17: NT$B | C17: =PL!D81 -> 22.298758 | D17: =PL!E81 -> 37.942577 | E17: =PL!F81 -> 43.600329 | F17: =PL!G81 -> 49.818301
A18: 南電 AI 載板營收 ÷ AI IT 資本支出 | B18: % | C18: =PL!D81/fx/itc_26 -> 0.00087752834 | D18: =PL!E81/fx/itc_27 -> 0.00074581653 | E18: =PL!F81/fx/itc_28 -> 0.00067609383 | F18: =PL!G81/fx/itc_29 -> 0.00067814431 | G18: × 每 GW IT capex 即每 GW 營收
A19: 每 GW 南電 AI 載板營收（VR200 每 GW IT capex 37.59B） | B19: US$M | C19: =PL!D81/fx/itc_26*37.59*1000 -> 32.98629 | D19: =PL!E81/fx/itc_27*37.59*1000 -> 28.035243 | E19: =PL!F81/fx/itc_28*37.59*1000 -> 25.414367 | F19: =PL!G81/fx/itc_29*37.59*1000 -> 25.491445 | G19: Tokenomics IF_CapexIT（VR200 基準，經橋接表；與 Ibiden、欣興模型相同係數）
A21: 讀法：南電在 GPU、ASIC 加速器載板的份額小（個位數），AI 載板以網通交換器（800G／1.6T 交換晶片）為主；加速器載板只占南電 AI 載板一小部分，其餘為校準殘差（公司未揭露）。三家合計留給三星電機、景碩、AT&S。

Sheet PL
A1: PL — 南電損益（十億新台幣；EPS 新台幣、基本；歸屬母公司）。FY2025A 實績、FY2026 錨點（1H26 實績＋3Q26 營收實績＋假設；三情境相同），FY2027–FY2029 由驅動因子推導，FY2030 起為收斂法。三情境各一個完整推導區塊（本頁下方），頂端為摘要
A2: 灰底＝FY2030–FY2032 收斂法（上游顆數只到 2029）：營收年增線性收斂到 fade_g、淨利率線性收斂到 fade_m（In 頁 I 節），非驅動因子推導
A3: 情境／項目 | B3: 單位 | C3: FY2025A | D3: FY2026（錨點） | E3: FY2027 | F3: FY2028 | G3: FY2029 | H3: FY2030（收斂） | I3: FY2031（收斂） | J3: FY2032（收斂） | K3: 說明
A4: 情境 A
A5: 營收 | B5: NT$B | C5: =C86 -> 40.173 | D5: =D86 -> 59.1479 | E5: =E86 -> 80.229395 | F5: =F86 -> 88.763775 | G5: =G86 -> 97.272873 | H5: =H86 -> 105.43486 | I5: =I86 -> 113.02133 | J5: =J86 -> 119.80261
A6: 營收年增 | B6: % | D6: =D87 -> 0.47232967 | E6: =E87 -> 0.35642 | F6: =F87 -> 0.10637474 | G6: =G87 -> 0.095862283 | H6: =H87 -> 0.083908189 | I6: =I87 -> 0.071954094 | J6: =J87 -> 0.06
A7: ABF 載板 | B7: NT$B | D7: =D79 -> 34.305782 | E7: =E79 -> 49.709078 | F7: =F79 -> 55.782906 | G7: =G79 -> 62.9387
A8: AI 載板 | B8: NT$B | D8: =D81 -> 22.298758 | E8: =E81 -> 37.942577 | F8: =F81 -> 43.600329 | G8: =G81 -> 49.818301
A9: ABF 需求滿足率 | B9: % | D9: =D80 -> 1 | E9: =E80 -> 0.95142541 | F9: =F80 -> 0.95637753 | G9: =G80 -> 1
A10: 毛利率 | B10: % | C10: =C96 -> 0.090782366 | D10: =D96 -> 0.26882091 | E10: =E96 -> 0.35816219 | F10: =F96 -> 0.35168173 | G10: =G96 -> 0.33961477
A11: 折舊攤提 | B11: NT$B | C11: =C92 -> 6.894 | D11: =D92 -> 7.1 | E11: =E92 -> 6.7125 | F11: =F92 -> 7.6234375 | G11: =G92 -> 8.9205078 | H11: =H92 -> 9.6690115 | I11: =I92 -> 10.364736 | J11: =J92 -> 10.986621
A12: 營業利益率 | B12: % | C12: =C99 -> 0.049336619 | D12: =D99 -> 0.23669805 | E12: =E99 -> 0.32941564 | F12: =F99 -> 0.32404073 | G12: =G99 -> 0.31294095
A13: 歸屬母公司淨利 | B13: NT$B | C13: =C103 -> 1.947 | D13: =D103 -> 11.509862 | E13: =E103 -> 21.352765 | F13: =F103 -> 23.196832 | G13: =G103 -> 24.522125 | H13: =H103 -> 26.579733 | I13: =I103 -> 28.492253 | J13: =J103 -> 30.201788
A14: 淨利率 | B14: % | C14: =C107 -> 0.048465387 | D14: =D107 -> 0.1945946 | E14: =E107 -> 0.26614641 | F14: =F107 -> 0.2613322 | G14: =G107 -> 0.25209624 | H14: =H107 -> 0.25209624 | I14: =I107 -> 0.25209624 | J14: =J107 -> 0.25209624
A15: EPS | B15: NT$ | C15: =C105 -> 3.01 | D15: =D105 -> 17.820894 | E15: =E105 -> 33.04512 | F15: =F105 -> 35.898962 | G15: =G105 -> 37.94996 | H15: =H105 -> 41.134272 | I15: =I105 -> 44.094051 | J15: =J105 -> 46.739694
A16: EPS 年增 | B16: % | D16: =D106 -> 4.9205629 | E16: =E106 -> 0.8542908 | F16: =F106 -> 0.086361964 | G16: =G106 -> 0.057132507 | H16: =H106 -> 0.083908189 | I16: =I106 -> 0.071954094 | J16: =J106 -> 0.06
A18: 情境 B
A19: 營收 | B19: NT$B | C19: =C139 -> 40.173 | D19: =D139 -> 59.1479 | E19: =E139 -> 79.283028 | F19: =F139 -> 79.966387 | G19: =G139 -> 86.968127 | H19: =H139 -> 93.204236 | I19: =I139 -> 98.409957 | J19: =J139 -> 102.34636
A20: 營收年增 | B20: % | D20: =D140 -> 0.47232967 | E20: =E140 -> 0.34042 | F20: =F140 -> 0.0086192381 | G20: =G140 -> 0.087558528 | H20: =H140 -> 0.071705686 | I20: =I140 -> 0.055852843 | J20: =J140 -> 0.04
A21: ABF 載板 | B21: NT$B | D21: =D132 -> 34.305782 | E21: =E132 -> 49.709078 | F21: =F132 -> 49.209479 | G21: =G132 -> 55.465955
A22: AI 載板 | B22: NT$B | D22: =D134 -> 22.298758 | E22: =E134 -> 37.942577 | F22: =F134 -> 36.471228 | G22: =G134 -> 42.345556
A23: ABF 需求滿足率 | B23: % | D23: =D133 -> 1 | E23: =E133 -> 0.95142541 | F23: =F133 -> 1 | G23: =G133 -> 1
A24: 毛利率 | B24: % | C24: =C149 -> 0.090782366 | D24: =D149 -> 0.26882091 | E24: =E149 -> 0.35766279 | F24: =F149 -> 0.33437169 | G24: =G149 -> 0.32241445
A25: 折舊攤提 | B25: NT$B | C25: =C145 -> 6.894 | D25: =D145 -> 7.1 | E25: =E145 -> 6.7125 | F25: =F145 -> 7.6234375 | G25: =G145 -> 8.9205078 | H25: =H145 -> 9.5601589 | I25: =I145 -> 10.094121 | J25: =J145 -> 10.497886
A26: 營業利益率 | B26: % | C26: =C152 -> 0.049336619 | D26: =D152 -> 0.23669805 | E26: =E152 -> 0.32880316 | F26: =F152 -> 0.30561071 | G26: =G152 -> 0.29457968
A27: 歸屬母公司淨利 | B27: NT$B | C27: =C156 -> 1.947 | D27: =D156 -> 11.509862 | E27: =E156 -> 21.068123 | F27: =F156 -> 19.780482 | G27: =G156 -> 20.713044 | H27: =H156 -> 21.458344 | I27: =I156 -> 21.875582 | J27: =J156 -> 21.938084
A28: 淨利率 | B28: % | C28: =C160 -> 0.048465387 | D28: =D160 -> 0.1945946 | E28: =E160 -> 0.26573308 | F28: =F160 -> 0.24735995 | G28: =G160 -> 0.23816822 | H28: =H160 -> 0.23022928 | I28: =I160 -> 0.22229033 | J28: =J160 -> 0.21435139
A29: EPS | B29: NT$ | C29: =C158 -> 3.01 | D29: =D158 -> 17.820894 | E29: =E158 -> 32.604614 | F29: =F158 -> 30.611885 | G29: =G158 -> 32.055099 | H29: =H158 -> 33.208511 | I29: =I158 -> 33.854222 | J29: =J158 -> 33.950948
A30: EPS 年增 | B30: % | D30: =D159 -> 4.9205629 | E30: =E159 -> 0.82957225 | F30: =F159 -> -0.061117998 | G30: =G159 -> 0.047145556 | H30: =H159 -> 0.035982163 | I30: =I159 -> 0.019444124 | J30: =J159 -> 0.0028571429
A32: 情境 C
A33: 營收 | B33: NT$B | C33: =C192 -> 40.173 | D33: =D192 -> 59.1479 | E33: =E192 -> 77.390295 | F33: =F192 -> 67.77289 | G33: =G192 -> 70.692597 | H33: =H192 -> 73.194208 | I33: =I192 -> 75.221218 | J33: =J192 -> 76.725642
A34: 營收年增 | B34: % | D34: =D193 -> 0.47232967 | E34: =E193 -> 0.30842 | F34: =F193 -> -0.12427147 | G34: =G193 -> 0.043080756 | H34: =H193 -> 0.035387171 | I34: =I193 -> 0.027693585 | J34: =J193 -> 0.02
A35: ABF 載板 | B35: NT$B | D35: =D185 -> 34.305782 | E35: =E185 -> 49.709078 | F35: =F185 -> 40.091672 | G35: =G185 -> 43.01138
A36: AI 載板 | B36: NT$B | D36: =D187 -> 22.298758 | E36: =E187 -> 37.942577 | F36: =F187 -> 27.353421 | G36: =G187 -> 29.890981
A37: ABF 需求滿足率 | B37: % | D37: =D186 -> 1 | E37: =E186 -> 0.95142541 | F37: =F186 -> 1 | G37: =G186 -> 1
A38: 毛利率 | B38: % | C38: =C202 -> 0.090782366 | D38: =D202 -> 0.26882091 | E38: =E202 -> 0.35662735 | F38: =F202 -> 0.30341516 | G38: =G202 -> 0.28395514
A39: 折舊攤提 | B39: NT$B | C39: =C198 -> 6.894 | D39: =D198 -> 7.1 | E39: =E198 -> 6.7125 | F39: =F198 -> 7.6234375 | G39: =G198 -> 8.9205078 | H39: =H198 -> 9.2361793 | I39: =I198 -> 9.4919623 | J39: =J198 -> 9.6818015
A40: 營業利益率 | B40: % | C40: =C205 -> 0.049336619 | D40: =D205 -> 0.23669805 | E40: =E205 -> 0.32753328 | F40: =F205 -> 0.27266964 | G40: =G205 -> 0.25371755
A41: 歸屬母公司淨利 | B41: NT$B | C41: =C209 -> 1.947 | D41: =D209 -> 11.509862 | E41: =E209 -> 20.498839 | F41: =F209 -> 15.072891 | G41: =G209 -> 14.643402 | H41: =H209 -> 14.150818 | I41: =I209 -> 13.503941 | J41: =J209 -> 12.714479
A42: 淨利率 | B42: % | C42: =C213 -> 0.048465387 | D42: =D213 -> 0.1945946 | E42: =E213 -> 0.26487609 | F42: =F213 -> 0.22240296 | G42: =G213 -> 0.20714195 | H42: =H213 -> 0.19333249 | I42: =I213 -> 0.17952302 | J42: =J213 -> 0.16571356
...

Sheet Val
A1: Val — P/E 估值（新台幣）。結論用「現價 ÷ FY2027、FY2028 EPS（模型）」；目標價＝DCF 與 Comparable 加權（第 0 節）；十年 P/E 規則值（第 3 節，年底落後 P/E）只作參考
A2: 循環位置：南電不是設備股，不套設備市場見頂年；以本模型營收最高的會計年度為見頂年（比照 Ibiden、欣興；FY(t)＝CY(t)）。營收到 FY2029 仍在增加時，見頂年未知，判為中段
A4: 0. 目標價
A5: 0.1 DCF（股東權益現金流，FY2027–FY2032 明確期＋FY2032 後永續）
A6: 項目 | B6: A（順利） | C6: B（平平） | D6: C（不如預期） | E6: 說明
A7: 情境 EPS（FY2027–FY2032） | E7: PL 頁各情境；FY2030 起為收斂法
A8: FY2027 | B8: =PL!E15 -> 33.04512 | C8: =PL!E29 -> 32.604614 | D8: =PL!E43 -> 31.7236
A9: FY2028 | B9: =PL!F15 -> 35.898962 | C9: =PL!F29 -> 30.611885 | D9: =PL!F43 -> 23.32651
A10: FY2029 | B10: =PL!G15 -> 37.94996 | C10: =PL!G29 -> 32.055099 | D10: =PL!G43 -> 22.661842
A11: FY2030 | B11: =PL!H15 -> 41.134272 | C11: =PL!H29 -> 33.208511 | D11: =PL!H43 -> 21.899528
A12: FY2031 | B12: =PL!I15 -> 44.094051 | C12: =PL!I29 -> 33.854222 | D12: =PL!I43 -> 20.898433
A13: FY2032 | B13: =PL!J15 -> 46.739694 | C13: =PL!J29 -> 33.950948 | D13: =PL!J43 -> 19.676679
A14: 股東現金流＝EPS ×（1 − tp_g ÷ tp_roe） | E14: 方法：南電模型有資本支出與折舊，改用每股（淨利＋折舊－資本支出）（PL 頁「每股股東現金流」；FY2030 起資本支出率收斂到穩態更新）
A15: 參考：再投資率（tp_g ÷ tp_roe，上限 0.8） | B15: =MIN(tp_g/tp_roe,0.8) -> 0.74349442 | E15: ROE 為近三年平均（In 頁 tp_roe）；本模型不採用，只作對照（第 25 列）
A16: FY2027 | B16: =PL!E110 -> 21.767129 | C16: =PL!E163 -> 21.326622 | D16: =PL!E216 -> 20.445609
A17: FY2028 | B17: =PL!F110 -> 19.840398 | C17: =PL!F163 -> 14.553321 | D17: =PL!F216 -> 7.2679461
A18: FY2029 | B18: =PL!G110 -> 33.184198 | C18: =PL!G163 -> 27.289338 | D18: =PL!G216 -> 17.89608
A19: FY2030 | B19: =PL!H110 -> 36.843276 | C19: =PL!H163 -> 28.965823 | D19: =PL!H216 -> 17.800619
A20: FY2031 | B20: =PL!I110 -> 40.431888 | C20: =PL!I163 -> 30.287675 | D20: =PL!I216 -> 17.544646
A21: FY2032 | B21: =PL!J110 -> 43.851644 | C21: =PL!J163 -> 31.191371 | D21: =PL!J216 -> 17.131626
A22: DCF 情境每股價值（折現率 tp_r） | B22: =MAX(0,SUMPRODUCT(B16:B21,1/(1+tp_r)^{1;2;3;4;5;6})+B21*(1+tp_g)/(tp_r-tp_g)/(1+tp_r)^6) -> 565.19359 | C22: =MAX(0,SUMPRODUCT(C16:C21,1/(1+tp_r)^{1;2;3;4;5;6})+C21*(1+tp_g)/(tp_r-tp_g)/(1+tp_r)^6) -> 413.29836 | D22: =MAX(0,SUMPRODUCT(D16:D21,1/(1+tp_r)^{1;2;3;4;5;6})+D21*(1+tp_g)/(tp_r-tp_g)/(1+tp_r)^6) -> 238.38084 | E22: Σ 明確期現金流 ÷ (1＋r)^t ＋ 永續價值 ÷ (1＋r)^6；永續價值＝FY2032 現金流 ×(1＋g)÷(r−g)；基準日 2026 年底；< 0 時取 0（股東有限責任）
A23: DCF 情境價值推到 12 個月後（×(1＋tp_r)） | B23: =B22*(1+tp_r) -> 621.71295 | C23: =C22*(1+tp_r) -> 454.62819 | D23: =D22*(1+tp_r) -> 262.21893
A24: DCF 目標價（情境加權） | B24: =tp_wA*B23+tp_wB*C23+tp_wC*D23 -> 466.27177 | E24: Σ 權重 × 情境價值 ×(1＋r)；權重見 In 頁
A25: 參考：EPS ×（1 − g／ROE）法的 DCF 目標價（情境加權） | B25: =(tp_wA*MAX(0,SUMPRODUCT(B8:B13,1/(1+tp_r)^{1;2;3;4;5;6})+B13*(1+tp_g)/(tp_r-tp_g)/(1+tp_r)^6)+tp_wB*MAX(0,SUMPRODUCT(C8:C13,1/(1+tp_r)^{1;2;3;4;5;6})+C13*(1+tp_g)/(tp_r-tp_g)/(1+tp_r)^6)+tp_wC*MAX(0,SUMPRODUCT(D8:D13,1/(1+tp_r)^{1;2;3;4;5;6})+D13*(1+tp_g)/(tp_r-tp_g)/(1+tp_r)^6))*(1-B15)*(1+tp_r) -> 136.73149 | E25: 近三年 ROE 約 5%（2024 年接近 0）→ 再投資率約 74%；不進目標價
A26: 0.2 Comparable（市場主流同業前瞻 P/E）
A27: 同業與前瞻 P/E | B27: 代號 | C27: 前瞻 12 月 P/E | D27: 日期 | E27: 來源 | F27: 標記
A28: 欣興（Unimicron） | B28: 3037.TW | C28: 42.28 | D28: 2026-10-22 | E28: stockanalysis.com forward PE（分析師共識；價格日期如左；與欣興、Ibiden 模型同一組數字） | F28: Interested-party
A29: 景碩（Kinsus） | B29: 3189.TW | C29: 44.7 | D29: 2026-10-22 | E29: stockanalysis.com forward PE（分析師共識；價格日期如左；與欣興、Ibiden 模型同一組數字） | F29: Interested-party
A30: Ibiden（揖斐電） | B30: 4062.T | C30: 53.97 | D30: 2026-10-16 | E30: stockanalysis.com forward PE（分析師共識；價格日期如左；與欣興、Ibiden 模型同一組數字） | F30: Interested-party
A31: 三星電機（Samsung Electro-Mechanics） | B31: 009150.KS | C31: 43.4 | D31: 2026-08-28 | E31: stockanalysis.com forward PE（分析師共識；價格日期如左；與欣興、Ibiden 模型同一組數字） | F31: Interested-party
A32: AT&S | B32: ATS.VI | C32: 14.91 | D32: 2026-10-23 | E32: stockanalysis.com forward PE（分析師共識；價格日期如左；與欣興、Ibiden 模型同一組數字） | F32: Interested-party
A33: 同業前瞻 P/E 中位數 | B33: =MEDIAN(C28:C32) -> 43.4 | E33: ABF 載板同業：欣興、景碩、Ibiden、三星電機、AT&S（無中國 A 股）；三星電機價格日期較舊
A34: 12 個月後的前瞻 EPS（情境加權） | B34: =tp_wA*(2/12*B8+10/12*B9)+tp_wB*(2/12*C8+10/12*C9)+tp_wC*(2/12*D8+10/12*D9) -> 31.044205 | E34: 約 2027-10 時的未來 12 月 EPS ≈ 2／12 × FY2027＋10／12 × FY2028（會計年度＝日曆年）
A35: Comparable 目標價 | B35: =B33*B34 -> 1347.3185 | E35: 同業中位數 × 前瞻 EPS
A37: 0.3 結論
A38: 項目 | B38: 數值 | E38: 說明
A39: 目標價（DCF 與 Comparable 加權） | B39: =tp_w_dcf*B24+(1-tp_w_dcf)*B35 -> 906.79513 | E39: tp_w_dcf × DCF＋（1 − tp_w_dcf）× Comparable；tp_w_dcf 見 In 頁（0.5）
A40: Comparable 目標價（市場主流同業法） | B40: =B35 -> 1347.3185
A41: 市場共識目標價 | B41: =cons_tp -> 1651.31 | E41: stockanalysis：14 位分析師平均 1,651.31（頁面價格日期 2026-09-07）；10 月美銀 2,000、大和 2,460
A42: 上檔空間：加權目標價 | B42: =B39/px-1 -> -0.28316591 | E42: 現價＝In 頁 px（2026-10-22 收盤）
...

Sheet Recon
A1: Recon — 本模型 vs 券商、共識與市場口徑。只作事後對照，不為對上數字而調參數。FactSet 共識為 2026-06（2Q26 財報前），10 月券商數字只取得美銀一家完整年度預估
A3: 項目 | B3: 對照值 | C3: 模型 A | D3: 差距 A | E3: 模型 B | F3: 差距 B | G3: 模型 C | H3: 差距 C | I3: 對照來源 | J3: 說明
A4: A. EPS 與營收 vs 共識、券商
A5: FY2026 EPS vs 美銀 18.44（2026-10-02） | B5: 18.44 | C5: =PL!D105 -> 17.820894 | D5: =C5/B5-1 -> -0.03357406 | E5: =PL!D158 -> 17.820894 | F5: =E5/B5-1 -> -0.03357406 | G5: =PL!D211 -> 17.820894 | H5: =G5/B5-1 -> -0.03357406 | I5: TechNews（美銀） | J5: FactSet 2026-06 平均 13.19 為 2Q26 財報之前
A6: FY2026 EPS vs 凱基 17.27（2026-07-20） | B6: 17.27 | C6: =PL!D105 -> 17.820894 | D6: =C6/B6-1 -> 0.03189892 | E6: =PL!D158 -> 17.820894 | F6: =E6/B6-1 -> 0.03189892 | G6: =PL!D211 -> 17.820894 | H6: =G6/B6-1 -> 0.03189892 | I6: 凱基
A7: FY2027 EPS vs 券商平均（美銀 43.80、凱基 38.88） | B7: =bk_eps27 -> 41.34 | C7: =PL!E105 -> 33.04512 | D7: =C7/B7-1 -> -0.20065021 | E7: =PL!E158 -> 32.604614 | F7: =E7/B7-1 -> -0.21130591 | G7: =PL!E211 -> 31.7236 | H7: =G7/B7-1 -> -0.23261731 | I7: TechNews（美銀）、凱基 | J7: 差距超過 30% 的原因見 README
A8: FY2027 EPS vs FactSet 平均 32.12（2026-06） | B8: =cons_eps27 -> 32.12 | C8: =PL!E105 -> 33.04512 | D8: =C8/B8-1 -> 0.028802005 | E8: =PL!E158 -> 32.604614 | F8: =E8/B8-1 -> 0.015087601 | G8: =PL!E211 -> 31.7236 | H8: =G8/B8-1 -> -0.012341207 | I8: 鉅亨（FactSet 14 位）
A9: FY2028 EPS vs FactSet 平均 59.21（2026-06） | B9: =cons_eps28 -> 59.21 | C9: =PL!F105 -> 35.898962 | D9: =C9/B9-1 -> -0.39370103 | E9: =PL!F158 -> 30.611885 | F9: =E9/B9-1 -> -0.48299468 | G9: =PL!F211 -> 23.32651 | H9: =G9/B9-1 -> -0.60603766 | I9: 鉅亨（FactSet）
A10: FY2028 EPS vs 券商平均（美銀 70.09、凱基 61.35） | B10: =bk_eps28 -> 65.72 | C10: =PL!F105 -> 35.898962 | D10: =C10/B10-1 -> -0.45375895 | E10: =PL!F158 -> 30.611885 | F10: =E10/B10-1 -> -0.53420747 | G10: =PL!F211 -> 23.32651 | H10: =G10/B10-1 -> -0.64506223 | I10: TechNews（美銀）、凱基
A11: FY2027 營收 vs FactSet 平均（2026-06） | B11: =cons_rev27 -> 90.26 | C11: =PL!E86 -> 80.229395 | D11: =C11/B11-1 -> -0.11113013 | E11: =PL!E139 -> 79.283028 | F11: =E11/B11-1 -> -0.12161502 | G11: =PL!E192 -> 77.390295 | H11: =G11/B11-1 -> -0.14258481 | I11: 鉅亨（FactSet） | J11: 美銀 90.33
A12: FY2028 營收 vs FactSet 平均（2026-06） | B12: =cons_rev28 -> 133.54 | C12: =PL!F86 -> 88.763775 | D12: =C12/B12-1 -> -0.33530197 | E12: =PL!F139 -> 79.966387 | F12: =E12/B12-1 -> -0.40118026 | G12: =PL!F192 -> 67.77289 | H12: =G12/B12-1 -> -0.49248997 | I12: 鉅亨（FactSet） | J12: 美銀 120.65
A13: 模型前瞻 12 月 EPS（0.2 × FY2026＋0.8 × FY2027）vs 頁面價格 ÷ 前瞻 P/E | B13: =cons_feps -> 31.129558 | C13: =0.2*PL!D105+0.8*PL!E105 -> 30.000275 | D13: =C13/B13-1 -> -0.036276875 | E13: =0.2*PL!D158+0.8*PL!E158 -> 29.64787 | F13: =E13/B13-1 -> -0.047597476 | G13: =0.2*PL!D211+0.8*PL!E211 -> 28.943059 | H13: =G13/B13-1 -> -0.070238679 | I13: stockanalysis（推導） | J13: 口徑不同，只作量級比較
A14: B. 錨點與毛利率
A15: 3Q26 毛利率（假設）vs 法人估 28.1%（百分點） | B15: 0.281 | C15: =Q!E6 -> 0.3 | D15: =C15-B15 -> 0.019 | E15: =Q!E6 -> 0.3 | F15: =E15-B15 -> 0.019 | G15: =Q!E6 -> 0.3 | H15: =G15-B15 -> 0.019 | I15: 三立 2026-07-27（法人） | J15: 3Q26 財報約 10 月底
A16: 3Q26 EPS（模型）vs 大和估 5.62 | B16: 5.62 | C16: =Q!E14 -> 5.5795271 | D16: =C16/B16-1 -> -0.0072015908 | E16: =Q!E14 -> 5.5795271 | F16: =E16/B16-1 -> -0.0072015908 | G16: =Q!E14 -> 5.5795271 | H16: =G16/B16-1 -> -0.0072015908 | I16: TechNews（大和）
A17: 4Q26 毛利率（假設）vs 美銀估 32.5%（百分點） | B17: 0.325 | C17: =Q!F6 -> 0.325 | D17: =C17-B17 -> 0 | E17: =Q!F6 -> 0.325 | F17: =E17-B17 -> 0 | G17: =Q!F6 -> 0.325 | H17: =G17-B17 -> 0 | I17: TechNews（美銀）：32–33%
A18: FY2027 毛利率 vs 美銀 39.9%（百分點） | B18: 0.399 | C18: =PL!E96 -> 0.35816219 | D18: =C18-B18 -> -0.040837808 | E18: =PL!E149 -> 0.35766279 | F18: =E18-B18 -> -0.041337207 | G18: =PL!E202 -> 0.35662735 | H18: =G18-B18 -> -0.042372647 | I18: TechNews（美銀） | J18: 凱基 37.4%
A19: FY2028 毛利率 vs 美銀 46.6%（百分點） | B19: 0.466 | C19: =PL!F96 -> 0.35168173 | D19: =C19-B19 -> -0.11431827 | E19: =PL!F149 -> 0.33437169 | F19: =E19-B19 -> -0.13162831 | G19: =PL!F202 -> 0.30341516 | H19: =G19-B19 -> -0.16258484 | I19: TechNews（美銀） | J19: 凱基 42.1%
A20: C. 產能、份額與 AI 口徑
A21: FY2027 ABF 需求滿足率（< 100%＝產能受限） | C21: =PL!E80 -> 0.95142541 | E21: =PL!E133 -> 0.95142541 | G21: =PL!E186 -> 0.95142541 | I21: PL 頁 | J21: 凱基：ABF 供需缺口 2027 年 22%、2028 年 29%
A22: FY2028 ABF 需求滿足率 | C22: =PL!F80 -> 0.95637753 | E22: =PL!F133 -> 1 | G22: =PL!F186 -> 1 | I22: PL 頁
A23: FY2026 AI 載板占營收 | C23: =PL!D89 -> 0.377 | E23: =PL!D142 -> 0.377 | G23: =PL!D195 -> 0.377 | I23: PL 頁 | J23: 公司應用別：網通 49%、AI 與 HPC 16%（1Q26）
A24: FY2027 份額合計：Ibiden＋欣興＋南電（NVIDIA） | C24: =Units!D10 -> 0.965 | E24: =Units!D10 -> 0.965 | G24: =Units!D10 -> 0.965 | I24: Units 頁 | J24: 應 ≤ 100%
A25: FY2027 份額合計：Ibiden＋欣興＋南電（非 NVIDIA） | C25: =Units!D14 -> 0.845 | E25: =Units!D14 -> 0.845 | G25: =Units!D14 -> 0.845 | I25: Units 頁 | J25: 應 ≤ 100%
A26: FY2027 每顆 NVIDIA 加速器的南電營收（US$） | C26: =Units!D15 -> 8.7652129 | E26: =Units!D15 -> 8.7652129 | G26: =Units!D15 -> 8.7652129 | I26: Units 頁 | J26: Ibiden 同期約 169（ibiden/dist Units 頁）
A27: FY2027 每 GW 南電 AI 載板營收（US$M） | C27: =Units!D19 -> 28.035243 | E27: =Units!D19 -> 28.035243 | G27: =Units!D19 -> 28.035243 | I27: Units 頁 | J27: Ibiden 同期約 62（只含加速器載板）
A28: D. 資本支出
A29: FY2027＋FY2028 資本支出 vs 凱基 2025–28 合計約 416 億扣除 2025–26（約 64 億） | B29: 35.2 | C29: =PL!E91+PL!F91 -> 32 | D29: =C29/B29-1 -> -0.090909091 | E29: =PL!E144+PL!F144 -> 32 | F29: =E29/B29-1 -> -0.090909091 | G29: =PL!E197+PL!F197 -> 32 | H29: =G29/B29-1 -> -0.090909091 | I29: 凱基（US$12.8 億 × 32.5）

Sheet Sens
A1: Sens — 一次動一個輸入（情境 A；FY2026 恆等於錨點，其他 AI 載板在每個案例內重新校準）：對 FY2027、FY2028 營收、毛利率與 EPS 的影響。每個案例是一個完整推導區塊（本頁下方）
A3: 案例 | B3: 設定 | C3: FY2027 營收 | D3: FY2027 毛利率 | E3: FY2027 EPS | F3: FY2027 EPS 相對基準 | G3: FY2028 營收 | H3: FY2028 毛利率 | I3: FY2028 EPS | J3: FY2028 EPS 相對基準
A4: 基準（情境 A） | B4: PL 區塊 A | C4: =PL!E86 -> 80.229395 | D4: =PL!E96 -> 0.35816219 | E4: =PL!E105 -> 33.04512 | F4: =E4/E$4-1 -> 0 | G4: =PL!F86 -> 88.763775 | H4: =PL!F96 -> 0.35168173 | I4: =PL!F105 -> 35.898962 | J4: =I4/I$4-1 -> 0
A5: AI 部署 ×0.8 | B5: FY2027 起顆數與其他 AI ×0.8 | C5: =E76 -> 74.791325 | D5: =E86 -> 0.3425834 | E5: =E95 -> 29.367504 | F5: =E5/E$4-1 -> -0.11129077 | G5: =F76 -> 82.190348 | H5: =F86 -> 0.33614751 | I5: =F95 -> 31.660027 | J5: =I5/I$4-1 -> -0.1180796
A6: AI 部署 ×1.2 | B6: ×1.2 | C6: =E129 -> 80.229395 | D6: =E139 -> 0.35942896 | E6: =E148 -> 33.169375 | F6: =E6/E$4-1 -> 0.0037601413 | G6: =F129 -> 88.763775 | H6: =F139 -> 0.35246721 | I6: =F148 -> 35.984203 | J6: =I6/I$4-1 -> 0.0023744767
A7: ABF 產能 低 | B7: 產能指數 1.10／1.20／1.35 | C7: =E182 -> 76.086971 | D7: =E192 -> 0.3477299 | E7: =E201 -> 30.358383 | F7: =E7/E$4-1 -> -0.081305125 | G7: =F182 -> 82.565674 | H7: =F192 -> 0.33806374 | I7: =F201 -> 31.997871 | J7: =I7/I$4-1 -> -0.10866864
A8: ABF 產能 高 | B8: 1.30／1.50／1.85 | C8: =E235 -> 82.767269 | D8: =E245 -> 0.36403772 | E8: =E254 -> 34.691162 | F8: =E8/E$4-1 -> 0.049811951 | G8: =F235 -> 91.308155 | H8: =F245 -> 0.35673679 | I8: =F254 -> 37.499137 | J8: =I8/I$4-1 -> 0.044574421
A9: ABF 溢價 低（Ibiden 低值） | B9: 0.95／0.85／0.75 | C9: =E288 -> 77.743941 | D9: =E298 -> 0.34118502 | E9: =E307 -> 30.401683 | F9: =E9/E$4-1 -> -0.079994779 | G9: =F288 -> 82.89189 | H9: =F298 -> 0.31362716 | I9: =F307 -> 29.646556 | J9: =I9/I$4-1 -> -0.17416677
A10: ABF 溢價 高（Ibiden 高值） | B10: 1.05／1.05／1.00 | C10: =E341 -> 82.714848 | D10: =E351 -> 0.37436388 | E10: =E360 -> 35.713312 | F10: =E10/E$4-1 -> 0.080743878 | G10: =F341 -> 94.63566 | H10: =F351 -> 0.38606213 | I10: =F360 -> 42.27399 | J10: =I10/I$4-1 -> 0.17758251
A11: 漲價年度化 8% | B11: 基準 15% | C11: =E394 -> 77.203625 | D11: =E404 -> 0.33738746 | E11: =E413 -> 29.830589 | F11: =E11/E$4-1 -> -0.097277026 | G11: =F394 -> 85.368294 | H11: =F404 -> 0.3301536 | I11: =F413 -> 32.269008 | J11: =I11/I$4-1 -> -0.10111585
A12: 漲價年度化 22% | C12: =E447 -> 83.255164 | D12: =E457 -> 0.37778755 | E12: =E466 -> 36.296364 | F12: =E12/E$4-1 -> 0.098388003 | G12: =F447 -> 92.159256 | H12: =F457 -> 0.3719818 | I12: =F466 -> 39.569311 | J12: =I12/I$4-1 -> 0.10224109
A13: ABF 現金毛利率 40% | B13: 基準 50% | C13: =E500 -> 80.229395 | D13: =E510 -> 0.34513173 | E13: =E519 -> 31.766994 | F13: =E13/E$4-1 -> -0.038678216 | G13: =F500 -> 88.763775 | H13: =F510 -> 0.33164477 | I13: =F519 -> 33.724519 | J13: =I13/I$4-1 -> -0.060571179
A14: ABF 現金毛利率 60% | C14: =E553 -> 80.229395 | D14: =E563 -> 0.37119266 | E14: =E572 -> 34.323247 | F14: =E14/E$4-1 -> 0.038678216 | G14: =F553 -> 88.763775 | H14: =F563 -> 0.37171869 | I14: =F572 -> 38.073404 | J14: =I14/I$4-1 -> 0.060571179
A15: 其他產品現金毛利率 25% | B15: 基準 40% | C15: =E606 -> 80.229395 | D15: =E616 -> 0.34754601 | E15: =E625 -> 32.003805 | F15: =E15/E$4-1 -> -0.031511914 | G15: =F606 -> 88.763775 | H15: =F616 -> 0.33792823 | I15: =F625 -> 34.40641 | J15: =I15/I$4-1 -> -0.041576453
A16: 其他產品現金毛利率 55% | C16: =E659 -> 80.229395 | D16: =E669 -> 0.36877837 | E16: =E678 -> 34.086435 | F16: =E16/E$4-1 -> 0.031511914 | G16: =F659 -> 88.763775 | H16: =F669 -> 0.36543523 | I16: =F678 -> 37.391513 | J16: =I16/I$4-1 -> 0.041576453
A17: BT 年增 走 C 路徑 | B17: 15%／0%／0% | C17: =E712 -> 77.390295 | D17: =E722 -> 0.35662735 | E17: =E731 -> 31.7236 | F17: =E17/E$4-1 -> -0.03999138 | G17: =F712 -> 83.464123 | H17: =F722 -> 0.3486137 | I17: =F731 -> 33.424482 | J17: =I17/I$4-1 -> -0.068929003
A18: 折舊年限 6 年 | B18: 基準 8 年 | C18: =E765 -> 80.229395 | D18: =E775 -> 0.35977216 | E18: =E784 -> 33.203038 | F18: =E18/E$4-1 -> 0.0047788502 | G18: =F765 -> 88.763775 | H18: =F775 -> 0.34947354 | I18: =F784 -> 35.659326 | J18: =I18/I$4-1 -> -0.0066752859
A19: 折舊年限 10 年 | C19: =E818 -> 80.229395 | D19: =E828 -> 0.35719621 | E19: =E837 -> 32.95037 | F19: =E19/E$4-1 -> -0.0028673101 | G19: =F818 -> 88.763775 | H19: =F828 -> 0.35294843 | I19: =F837 -> 36.036427 | J19: =I19/I$4-1 -> 0.0038292136
A20: 資本支出 低 | B20: 每年 60 億 | C20: =E871 -> 80.229395 | D20: =E881 -> 0.35816219 | E20: =E890 -> 33.04512 | F20: =E20/E$4-1 -> 0 | G20: =F871 -> 88.763775 | H20: =F881 -> 0.36294759 | I20: =F890 -> 37.12155 | J20: =I20/I$4-1 -> 0.034056374
A21: 資本支出 高 | B21: 200／240／200 億 | C21: =E924 -> 80.229395 | D21: =E934 -> 0.35816219 | E21: =E943 -> 33.04512 | F21: =E21/E$4-1 -> 0 | G21: =F924 -> 88.763775 | H21: =F934 -> 0.34323234 | I21: =F943 -> 34.982021 | J21: =I21/I$4-1 -> -0.025542281
A22: 南電 NVIDIA 份額 低 | B22: 1% | C22: =E977 -> 80.229395 | D22: =E987 -> 0.35797808 | E22: =E996 -> 33.027061 | F22: =E22/E$4-1 -> -0.0005465116 | G22: =F977 -> 88.763775 | H22: =F987 -> 0.35145834 | I22: =F996 -> 35.874719 | J22: =I22/I$4-1 -> -0.0006752954
A23: 南電 NVIDIA 份額 高 | B23: 3%→6% | C23: =E1030 -> 80.229395 | D23: =E1040 -> 0.35833948 | E23: =E1049 -> 33.06251 | F23: =E23/E$4-1 -> 0.00052625162 | G23: =F1030 -> 88.763775 | H23: =F1040 -> 0.3517939 | I23: =F1049 -> 35.911135 | J23: =I23/I$4-1 -> 0.00033910179
A24: 南電 ASIC 份額 低 | B24: 3% | C24: =E1083 -> 80.229395 | D24: =E1093 -> 0.35781662 | E24: =E1102 -> 33.011224 | F24: =E24/E$4-1 -> -0.0010257682 | G24: =F1083 -> 86.916229 | H24: =F1093 -> 0.34735845 | I24: =F1102 -> 34.684143 | J24: =I24/I$4-1 -> -0.033839946
A25: 南電 ASIC 份額 高 | B25: 8%→10% | C25: =E1136 -> 80.229395 | D25: =E1146 -> 0.358366 | E25: =E1155 -> 33.065111 | F25: =E25/E$4-1 -> 0.00060495349 | G25: =F1136 -> 88.763775 | H25: =F1146 -> 0.35189706 | I25: =F1155 -> 35.92233 | J25: =I25/I$4-1 -> 0.00065095175
A26: 交換器載板彈性 0.3 | B26: 基準 0.5 | C26: =E1189 -> 78.906804 | D26: =E1199 -> 0.35419514 | E26: =E1208 -> 32.11444 | F26: =E26/E$4-1 -> -0.028163942 | G26: =F1189 -> 86.572342 | H26: =F1199 -> 0.34658396 | I26: =F1208 -> 34.465763 | J26: =I26/I$4-1 -> -0.039923128
A27: 交換器載板彈性 0.8 | C27: =E1242 -> 80.229395 | D27: =E1252 -> 0.35927157 | E27: =E1261 -> 33.153936 | F27: =E27/E$4-1 -> 0.003292948 | G27: =F1242 -> 88.763775 | H27: =F1252 -> 0.35243784 | I27: =F1261 -> 35.981016 | J27: =I27/I$4-1 -> 0.0022856925
A28: 營業費用彈性 1.0 | B28: 基準 0.6 | C28: =E1295 -> 80.229395 | D28: =E1305 -> 0.35816219 | E28: =E1314 -> 32.713947 | F28: =E28/E$4-1 -> -0.010021867 | G28: =F1295 -> 88.763775 | H28: =F1305 -> 0.35168173 | I28: =F1314 -> 35.412583 | J28: =I28/I$4-1 -> -0.013548563
A29: 稅率 24% | B29: 基準 21% | C29: =E1348 -> 80.229395 | D29: =E1358 -> 0.35816219 | E29: =E1367 -> 31.790242 | F29: =E29/E$4-1 -> -0.037974684 | G29: =F1348 -> 88.763775 | H29: =F1358 -> 0.35168173 | I29: =F1367 -> 34.53571 | J29: =I29/I$4-1 -> -0.037974684
A30: 業外 0 | B30: 每年 0（基準 6 億） | C30: =E1401 -> 80.229395 | D30: =E1411 -> 0.35816219 | E30: =E1420 -> 32.311567 | F30: =E30/E$4-1 -> -0.02219853 | G30: =F1401 -> 88.763775 | H30: =F1411 -> 0.35168173 | I30: =F1420 -> 35.165409 | J30: =I30/I$4-1 -> -0.020433825
A31: 情境 B | B31: tsmc 顆數係數 B；BT 年增較低 | C31: =PL!E139 -> 79.283028 | D31: =PL!E149 -> 0.35766279 | E31: =PL!E158 -> 32.604614 | F31: =E31/E$4-1 -> -0.01333046 | G31: =PL!F139 -> 79.966387 | H31: =PL!F149 -> 0.33437169 | I31: =PL!F158 -> 30.611885 | J31: =I31/I$4-1 -> -0.1472766
A32: 情境 C | B32: tsmc 顆數係數 C；BT 年增最低 | C32: =PL!E192 -> 77.390295 | D32: =PL!E202 -> 0.35662735 | E32: =PL!E211 -> 31.7236 | F32: =E32/E$4-1 -> -0.03999138 | G32: =PL!F192 -> 67.77289 | H32: =PL!F202 -> 0.30341516 | I32: =PL!F211 -> 23.32651 | J32: =I32/I$4-1 -> -0.35021769
A34: 讀法：漲價年度化與 ABF 溢價直接決定毛利（溢價全數落在毛利）；ABF 產能受限時，份額與部署的上修只部分轉成營收；南電加速器份額小，NVIDIA／ASIC 份額的影響有限；FY2027 情境差只來自 BT 年增。
A36: 目標價參數（只改 DCF 參數；PL 收斂法的 fade_g 與資本支出率路徑不隨 tp_g 變動）
A37: 案例 | B37: 設定 | C37: DCF 目標價 | D37: Comparable 目標價 | E37: 加權目標價 | F37: 相對基準
A38: 基準 | B38: r 10%、g 4%、DCF 權重 0.5 | C38: =(tp_wA*MAX(0,SUMPRODUCT(Val!B16:B21,1/(1+tp_r)^{1;2;3;4;5;6})+Val!B21*(1+tp_g)/(tp_r-tp_g)/(1+tp_r)^6)+tp_wB*MAX(0,SUMPRODUCT(Val!C16:C21,1/(1+tp_r)^{1;2;3;4;5;6})+Val!C21*(1+tp_g)/(tp_r-tp_g)/(1+tp_r)^6)+tp_wC*MAX(0,SUMPRODUCT(Val!D16:D21,1/(1+tp_r)^{1;2;3;4;5;6})+Val!D21*(1+tp_g)/(tp_r-tp_g)/(1+tp_r)^6))*(1+tp_r) -> 466.27177 | D38: =Val!B35 -> 1347.3185 | E38: =tp_w_dcf*C38+(1-tp_w_dcf)*D38 -> 906.79513 | F38: =E38/E$38-1 -> 0
A39: 折現率 +1pt | B39: r 11% | C39: =(tp_wA*MAX(0,SUMPRODUCT(Val!B16:B21,1/(1+(tp_r+0.01))^{1;2;3;4;5;6})+Val!B21*(1+tp_g)/((tp_r+0.01)-tp_g)/(1+(tp_r+0.01))^6)+tp_wB*MAX(0,SUMPRODUCT(Val!C16:C21,1/(1+(tp_r+0.01))^{1;2;3;4;5;6})+Val!C21*(1+tp_g)/((tp_r+0.01)-tp_g)/(1+(tp_r+0.01))^6)+tp_wC*MAX(0,SUMPRODUCT(Val!D16:D21,1/(1+(tp_r+0.01))^{1;2;3;4;5;6})+Val!D21*(1+tp_g)/((tp_r+0.01)-tp_g)/(1+(tp_r+0.01))^6))*(1+(tp_r+0.01)) -> 400.92572 | D39: =Val!B35 -> 1347.3185 | E39: =tp_w_dcf*C39+(1-tp_w_dcf)*D39 -> 874.1221 | F39: =E39/E$38-1 -> -0.036031319
A40: 折現率 −1pt | B40: r 9% | C40: =(tp_wA*MAX(0,SUMPRODUCT(Val!B16:B21,1/(1+(tp_r-0.01))^{1;2;3;4;5;6})+Val!B21*(1+tp_g)/((tp_r-0.01)-tp_g)/(1+(tp_r-0.01))^6)+tp_wB*MAX(0,SUMPRODUCT(Val!C16:C21,1/(1+(tp_r-0.01))^{1;2;3;4;5;6})+Val!C21*(1+tp_g)/((tp_r-0.01)-tp_g)/(1+(tp_r-0.01))^6)+tp_wC*MAX(0,SUMPRODUCT(Val!D16:D21,1/(1+(tp_r-0.01))^{1;2;3;4;5;6})+Val!D21*(1+tp_g)/((tp_r-0.01)-tp_g)/(1+(tp_r-0.01))^6))*(1+(tp_r-0.01)) -> 557.81032 | D40: =Val!B35 -> 1347.3185 | E40: =tp_w_dcf*C40+(1-tp_w_dcf)*D40 -> 952.5644 | F40: =E40/E$38-1 -> 0.050473669
A41: 長期成長 +1pt | B41: g 5% | C41: =(tp_wA*MAX(0,SUMPRODUCT(Val!B16:B21,1/(1+tp_r)^{1;2;3;4;5;6})+Val!B21*(1+(tp_g+0.01))/(tp_r-(tp_g+0.01))/(1+tp_r)^6)+tp_wB*MAX(0,SUMPRODUCT(Val!C16:C21,1/(1+tp_r)^{1;2;3;4;5;6})+Val!C21*(1+(tp_g+0.01))/(tp_r-(tp_g+0.01))/(1+tp_r)^6)+tp_wC*MAX(0,SUMPRODUCT(Val!D16:D21,1/(1+tp_r)^{1;2;3;4;5;6})+Val!D21*(1+(tp_g+0.01))/(tp_r-(tp_g+0.01))/(1+tp_r)^6))*(1+tp_r) -> 539.53066 | D41: =Val!B35 -> 1347.3185 | E41: =tp_w_dcf*C41+(1-tp_w_dcf)*D41 -> 943.42457 | F41: =E41/E$38-1 -> 0.040394402
A42: 長期成長 −1pt | B42: g 3% | C42: =(tp_wA*MAX(0,SUMPRODUCT(Val!B16:B21,1/(1+tp_r)^{1;2;3;4;5;6})+Val!B21*(1+(tp_g-0.01))/(tp_r-(tp_g-0.01))/(1+tp_r)^6)+tp_wB*MAX(0,SUMPRODUCT(Val!C16:C21,1/(1+tp_r)^{1;2;3;4;5;6})+Val!C21*(1+(tp_g-0.01))/(tp_r-(tp_g-0.01))/(1+tp_r)^6)+tp_wC*MAX(0,SUMPRODUCT(Val!D16:D21,1/(1+tp_r)^{1;2;3;4;5;6})+Val!D21*(1+(tp_g-0.01))/(tp_r-(tp_g-0.01))/(1+tp_r)^6))*(1+tp_r) -> 413.94399 | D42: =Val!B35 -> 1347.3185 | E42: =tp_w_dcf*C42+(1-tp_w_dcf)*D42 -> 880.63124 | F42: =E42/E$38-1 -> -0.028853144
A43: DCF 權重 0.3 | C43: =(tp_wA*MAX(0,SUMPRODUCT(Val!B16:B21,1/(1+tp_r)^{1;2;3;4;5;6})+Val!B21*(1+tp_g)/(tp_r-tp_g)/(1+tp_r)^6)+tp_wB*MAX(0,SUMPRODUCT(Val!C16:C21,1/(1+tp_r)^{1;2;3;4;5;6})+Val!C21*(1+tp_g)/(tp_r-tp_g)/(1+tp_r)^6)+tp_wC*MAX(0,SUMPRODUCT(Val!D16:D21,1/(1+tp_r)^{1;2;3;4;5;6})+Val!D21*(1+tp_g)/(tp_r-tp_g)/(1+tp_r)^6))*(1+tp_r) -> 466.27177 | D43: =Val!B35 -> 1347.3185 | E43: =0.3*C43+(1-0.3)*D43 -> 1083.0045 | F43: =E43/E$38-1 -> 0.19432101
...

Sheet Sources
A1: 來源（公司財報經資料商與媒體轉載；法說內容經媒體摘要；券商與資料商皆為 Interested-party）
A2: 資料商：stockanalysis（現價、股數、前瞻與近 12 月 P/E、目標價、FY2021–25 與季損益、現金流、ROE、年度 P/E） | B2: https://stockanalysis.com/quote/tpe/8046/
A3: 資料商：stockanalysis 歷史價格（2026-10-22 收盤 1,265） | B3: https://stockanalysis.com/quote/tpe/8046/history/
A4: 資料商：財報狗（10-22 收盤、近 12 月 P/E、近 4 季 ROE） | B4: https://statementdog.com/analysis/8046
A5: 資料商：HiStock（現價核對、2Q26 EPS） | B5: https://histock.tw/stock/8046
A6: 公司（摘要）：富果 1Q26 法說摘要（應用別、資本支出、擴產） | B6: https://blog.fugle.tw/post/earnings-call-8046-2026-06-12
A7: 公司（摘要）：vocus 4Q25 法說摘要（FY2025、產品別 2025） | B7: https://vocus.cc/article/6a12e069fd897800013a5f84
A8: 媒體：TechNews 2026-10-03（9 月營收、前 9 月累計） | B8: https://finance.technews.tw/2026/10/03/n-p-c-8046-202609-financial-report/
A9: 媒體：winvest（7 月營收、1Q26 EPS） | B9: https://winvest.tw/News/Detail/90850
A10: 券商（媒體）：三立 2026-07-27（2Q26 營收、法人 3Q26 預估、產能） | B10: https://www.mirrormedia.mg/external/setn_1879204
A11: 券商（媒體）：TechNews 2026-10-02 美銀（目標價 2,000、EPS 2026–28、毛利率、BT 漲價、AMD／博通） | B11: https://finance.technews.tw/2026/10/02/bank-of-america-gives-nanyang-power-a-buy-rating-with-a-target-price-of-nt2000/
A12: 券商（媒體）：TechNews 2026-10-05 大和（目標價 2,460、8 月自結獲利、3Q／4Q26 預估） | B12: https://finance.technews.tw/2026/10/05/daiwa-securities-strongly-supports-nan-ya-powers-target-price-of-nt2460/
A13: 券商：凱基 PCB 產業報告 2026-07-20（EPS、營收、毛利率、產品組合、產能、資本支出、ABF 缺口、同業 P/E） | B13: https://www.kgi.com.hk/zh-cn/-/media/files/kgishk/research-reports/tw-reports/pcb-sector_20260720e.pdf
... A21: SemiAnalysis | B21: 未使用
