Workbook

Sheet README
A1: Disco（6146.T）收支與估值模型 v0.1（AI 半導體 Project 步驟 5：設備與材料） 2026-10-23
A2: 模型命題：Disco 的營收由需要研削與切割的晶圓次數驅動，AI 只占約兩成；問題是 HBM 堆疊與先進封裝帶來的增量，能否抵過非 AI 後段的循環，撐住目前約 41 倍的近 12 月本益比？
A3: 註：41 倍＝現價 ¥51,230 ÷ FY2025 EPS ¥1,249.84（上一個會計年度）；嚴格的近 12 月 EPS（含 FY2026 上半）為 1,474.98，對應 34.7 倍（Val 頁）。
A5: 驅動因子 → 推導量（因果方向：左邊決定右邊）
A6: 工作表｜輸入 → 推導量 → 去向
A7: Drv（PL 區塊 A）｜HBM 出貨位元（markets/memory，三情境）÷ 晶粒容量 → DRAM 晶粒數 ×（1＋每堆疊額外工序 ÷ 層數）→ HBM 研削／切割工序 → ×（1＋混合鍵合占比 × 淨影響）→ 產能需求 → 下一年增量＋汰換 → 新機需求 × kH（以 FY2025 AI 出貨校準）→ HBM 裝置營收
A8: Drv（PL 區塊 A）｜CoWoS 片數（台積電模型；B、C × SCEN_UNITS）→ 下一年增量＋汰換 → 新機需求 × kL（同一錨點校準）→ 先進封裝裝置營收
A9: PL｜非 AI 裝置 FY2025（裝置營收 − AI 出貨）×（1＋非 AI 年增，Analogy：公司 AI 前歷史）→ 非 AI 裝置營收；情境 B、C 只在 FY2028 不同
A10: PL｜消耗品＝AI 部分 × AI 工序量指數（稼動）＋非 AI 部分 ×（1＋年增）——消耗品隨稼動、不隨新機；その他＝固定比例 ×（裝置＋消耗品）
A11: Hist → PL｜毛利率＝a ＋ b × ln 營收、銷管費＝固定＋變動 × 營收（FY2015–FY2025 迴歸）→ 營業利益與營業利益率是結果，不寫死
A12: Val｜10 年 P/E 分位 × FY2027 EPS；FY2027 的循環位置由各情境的營業利益路徑以公式判定。Recon｜上半實績、公司下一季指引、共識。Sens｜一次動一個輸入
A14: 會計年度：4 月到隔年 3 月（FY2025＝2025-04～2026-03，公司「2026年3月期」）。日曆年轉會計年度：FY(t)＝3/4 × CY(t)＋1/4 × CY(t+1)。金額為日圓，未建匯率。
... A17: 已知限制：見 disco/README.md「待辦與限制」。

Sheet In
A1: In — 輸入（藍字；基準欄 E，低 D、高 F）。金額：十億日圓（¥B）；HBM 位元：EB；CoWoS：千片。每個輸入附標記與來源；找不到者寫「未找到」，公司未揭露者寫「公司不揭露」
A2: 標記：Verified（公司文件、交易所資料）／Interested-party（寫明是誰、立場）／Analogy（寫明對照與差異）／Assumed（一律給低／高區間）／Derived（寫明換算）。SemiAnalysis 未使用。公司原文（disco.co.jp）以網頁擷取工具讀取文字（建置環境的 curl 被擋）；表格欄位錯置處以算術核對，原文版面待人工複核
A3: 鍵 | B3: 項目 | C3: 單位 | D3: 低 | E3: 基準 | F3: 高 | G3: 標記 | H3: 來源1 | I3: 來源2／說明
A4: A. FY2025 實績（2025-04～2026-03）與產品別構成（校準錨）
A5: a25_rev | B5: 營收 FY2025 | C5: ¥B | E5: 436.889 | G5: Verified | H5: 公司 2026年3月期 決算短信（2026-04-22，fr20260422.pdf）：436,889 百萬日圓 | I5: 松井證券 決算情報（finance.matsui.co.jp/stock/6146/settlement）：436,889；另見 kabuyoho 轉載之 TSE 決算短信 PDF（2026-04-22）
A6: a25_gp | B6: 毛利 FY2025 | C6: ¥B | E6: 306.477 | G6: Verified | H6: 公司 2026年3月期 決算短信（2026-04-22，fr20260422.pdf）：毛利 306,477（營收 − 銷貨成本 130,412） | I6: 公司 FY2025 4Q 決算說明資料（2026-04-22，film/20260422.pdf）：毛利 306.5、毛利率 70.1%
A7: a25_sga | B7: 銷管費 FY2025 | C7: ¥B | E7: 121.487 | G7: Verified | H7: 公司 2026年3月期 決算短信（2026-04-22，fr20260422.pdf）：121,487 | I7: 公司 FY2025 4Q 決算說明資料（2026-04-22，film/20260422.pdf）：121.5
A8: a25_oi | B8: 營業利益 FY2025 | C8: ¥B | E8: 184.989 | G8: Verified | H8: 公司 2026年3月期 決算短信（2026-04-22，fr20260422.pdf）：184,989 | I8: 松井證券 決算情報（finance.matsui.co.jp/stock/6146/settlement）：184,989
A9: a25_ni | B9: 淨利（歸屬母公司）FY2025 | C9: ¥B | E9: 135.521 | G9: Verified | H9: 公司 2026年3月期 決算短信（2026-04-22，fr20260422.pdf）：135,521 | I9: 松井證券 決算情報（finance.matsui.co.jp/stock/6146/settlement）：135,521
A10: a25_eps | B10: 基本 EPS FY2025 | C10: ¥ | E10: 1249.84 | G10: Verified | H10: 公司 2026年3月期 決算短信（2026-04-22，fr20260422.pdf）：基本 1,249.84（稀釋 1,245.90） | I10: 松井證券 決算情報（finance.matsui.co.jp/stock/6146/settlement）：1,249.84
A11: mix_eq | B11: 精密加工裝置占營收 FY2025 | C11: % | D11: 0.615 | E11: 0.62 | F11: 0.625 | G11: Verified | H11: 公司 FY2025 4Q 決算說明資料（2026-04-22，film/20260422.pdf）：製品別構成 精密加工裝置 62%（ダイサ 31%、グラインダ 28%、附屬裝置 3%）、精密加工ツール 21%、その他 16%（合計 99%，四捨五入） | I11: 公司只揭露構成比（百分比取整數），不揭露金額；低／高＝±0.5 個百分點（取整誤差）。FY2024：63%／21%／16%（film/20250417）
A12: mix_tl | B12: 精密加工ツール（消耗品：刀片、砂輪）占營收 FY2025 | C12: % | D12: 0.205 | E12: 0.21 | F12: 0.215 | G12: Verified | H12: 同上：21%（FY2024 21%、FY2023 22%） | I12: 同上；消耗品隨客戶稼動率變動（公司 FY26 Q1 說明：稼動率高，創新高）
A13: eq25 | B13: 精密加工裝置營收 FY2025（營收 × 構成比） | C13: ¥B | E13: =a25_rev*mix_eq -> 270.87118 | G13: Derived | H13: 436.9 × 62%
A14: tl25 | B14: 精密加工ツール營收 FY2025 | C14: ¥B | E14: =a25_rev*mix_tl -> 91.74669 | G14: Derived | H14: 436.9 × 21%
A15: ot25 | B15: その他（零件、服務、二手機等）FY2025 | C15: ¥B | E15: =a25_rev-eq25-tl25 -> 74.27113 | G15: Derived | H15: 營收 − 裝置 − 消耗品（＝17%，含取整差） | I15: 公司構成比為 16%
A16: r_ot | B16: その他 ÷（裝置＋消耗品） | C16: x | E16: =ot25/(eq25+tl25) -> 0.20481928 | G16: Derived | H16: FY2025 比例，各年沿用 | I16: FY2024 16/84＝0.19，相同
A17: B. AI 錨點（校準用；不使用共識營收或公司目標）
A18: ai25 | B18: 生成 AI 相關出貨額 FY2025（2026年3月期） | C18: ¥B | D18: 67.5 | E18: 75 | F18: 82.5 | G18: Interested-party | H18: 樂天證券 今中能夫（2026-04-27，決算レポート；券商分析師，有正面撰寫傾向）：2026年3月期 約 750 億、2025年3月期 約 550 億（出貨額） | I18: 第二來源：未找到金額（公司不揭露 AI 金額）。低／高 ±10%＝「約」的不確定（Assumed）。出貨額視同營收：FY2025 出貨 442.6（四季合計，公司簡報）÷ 營收 436.9＝1.013（Derived）。是否含消耗品：原文不明，本模型視為裝置
A19: w_hbm | B19: AI 出貨中 HBM 比重 FY2025（其餘為邏輯／先進封裝） | C19: % | D19: 0.45 | E19: 0.48 | F19: 0.52 | G19: Interested-party | H19: 今中能夫（同上）：2025年3月期 概算 邏輯 3：HBM 7；2026年3月期 HBM 持平、邏輯大增，邏輯略高於 HBM → HBM 約 48%（Derived：38.5÷75≈51%，再依「邏輯略高」取 48%） | I19: 第二來源：公司 FY26 2Q 法說（BigGo 摘要，2026-10-22）：全年約 HBM 一半、邏輯一半。Interested-party（公司）
A20: ai24 | B20: 生成 AI 相關出貨額 FY2024（只作參考，未用於校準） | C20: ¥B | E20: 55 | G20: Interested-party | H20: 今中能夫（同上）：約 550 億 | I20: 回測需 CY2024 的 HBM 位元與 CoWoS 片數，市場層沒有，未做（見 README 待辦）
A21: C. HBM 研削／切割需求（markets/memory，情境 A／B／C 各一列；唯讀）
A22: hsA_25 | B22: HBM 出貨位元 2025（EB；A） | C22: EB | E22: 2.2251147 | G22: Derived | H22: skhynix/dist/20261023_SK海力士模型_v0.4.xlsx｜Mkt!C24:G24 | I22: markets/memory v0.4（market.py @ 5fa3751）：出貨＝MIN(需求 × 情境顆數係數, 供給)；2028–29 隨情境，2025–27 三情境相同
A23: hsA_26 | B23: HBM 出貨位元 2026（EB；A） | C23: EB | E23: 3.782695 | G23: Derived | H23: skhynix/dist/20261023_SK海力士模型_v0.4.xlsx｜Mkt!C24:G24 | I23: 同上
A24: hsA_27 | B24: HBM 出貨位元 2027（EB；A） | C24: EB | E24: 5.8631772 | G24: Derived | H24: skhynix/dist/20261023_SK海力士模型_v0.4.xlsx｜Mkt!C24:G24 | I24: 同上
A25: hsA_28 | B25: HBM 出貨位元 2028（EB；A） | C25: EB | E25: 8.501607 | G25: Derived | H25: skhynix/dist/20261023_SK海力士模型_v0.4.xlsx｜Mkt!C24:G24 | I25: 同上
A26: hsA_29 | B26: HBM 出貨位元 2029（EB；A） | C26: EB | E26: 11.477169 | G26: Derived | H26: skhynix/dist/20261023_SK海力士模型_v0.4.xlsx｜Mkt!C24:G24 | I26: 同上
A27: hsB_25 | B27: HBM 出貨位元 2025（EB；B） | C27: EB | E27: 2.2251147 | G27: Derived | H27: skhynix/dist/20261023_SK海力士模型_v0.4.xlsx｜Mkt!C25:G25 | I27: markets/memory v0.4（market.py @ 5fa3751）：出貨＝MIN(需求 × 情境顆數係數, 供給)；2028–29 隨情境，2025–27 三情境相同
A28: hsB_26 | B28: HBM 出貨位元 2026（EB；B） | C28: EB | E28: 3.782695 | G28: Derived | H28: skhynix/dist/20261023_SK海力士模型_v0.4.xlsx｜Mkt!C25:G25 | I28: 同上
A29: hsB_27 | B29: HBM 出貨位元 2027（EB；B） | C29: EB | E29: 5.8631772 | G29: Derived | H29: skhynix/dist/20261023_SK海力士模型_v0.4.xlsx｜Mkt!C25:G25 | I29: 同上
A30: hsB_28 | B30: HBM 出貨位元 2028（EB；B） | C30: EB | E30: 8.22296 | G30: Derived | H30: skhynix/dist/20261023_SK海力士模型_v0.4.xlsx｜Mkt!C25:G25 | I30: 同上
A31: hsB_29 | B31: HBM 出貨位元 2029（EB；B） | C31: EB | E31: 11.357964 | G31: Derived | H31: skhynix/dist/20261023_SK海力士模型_v0.4.xlsx｜Mkt!C25:G25 | I31: 同上
A32: hsC_25 | B32: HBM 出貨位元 2025（EB；C） | C32: EB | E32: 2.2251147 | G32: Derived | H32: skhynix/dist/20261023_SK海力士模型_v0.4.xlsx｜Mkt!C26:G26 | I32: markets/memory v0.4（market.py @ 5fa3751）：出貨＝MIN(需求 × 情境顆數係數, 供給)；2028–29 隨情境，2025–27 三情境相同
A33: hsC_26 | B33: HBM 出貨位元 2026（EB；C） | C33: EB | E33: 3.782695 | G33: Derived | H33: skhynix/dist/20261023_SK海力士模型_v0.4.xlsx｜Mkt!C26:G26 | I33: 同上
... A36: hsC_29 | B36: HBM 出貨位元 2029（EB；C） | C36: EB | E36: 8.017386 | G36: Derived | H36: skhynix/dist/20261023_SK海力士模型_v0.4.xlsx｜Mkt!C26:G26 | I36: 同上
A37: den_25 | B37: DRAM 核心晶粒容量（組合平均）2025 | C37: Gb／顆 | D37: 22 | E37: 24 | F37: 24 | G37: Assumed | H37: JEDEC HBM4（JESD270-4）：24Gb 或 32Gb 晶粒（TrendForce 2025-04-28）；HBM3E 以 24Gb 為主 | I37: 組合比例未找到；容量愈大，同樣位元需要的晶粒（研削＋切割次數）愈少
A38: den_26 | B38: DRAM 核心晶粒容量（組合平均）2026 | C38: Gb／顆 | D38: 24 | E38: 24 | F38: 26 | G38: Assumed | H38: JEDEC HBM4（JESD270-4）：24Gb 或 32Gb 晶粒（TrendForce 2025-04-28）；HBM3E 以 24Gb 為主 | I38: 同上
A39: den_27 | B39: DRAM 核心晶粒容量（組合平均）2027 | C39: Gb／顆 | D39: 24 | E39: 26 | F39: 28 | G39: Assumed | H39: JEDEC HBM4（JESD270-4）：24Gb 或 32Gb 晶粒（TrendForce 2025-04-28）；HBM3E 以 24Gb 為主 | I39: 同上
A40: den_28 | B40: DRAM 核心晶粒容量（組合平均）2028 | C40: Gb／顆 | D40: 24 | E40: 28 | F40: 32 | G40: Assumed | H40: JEDEC HBM4（JESD270-4）：24Gb 或 32Gb 晶粒（TrendForce 2025-04-28）；HBM3E 以 24Gb 為主 | I40: 同上
A41: den_29 | B41: DRAM 核心晶粒容量（組合平均）2029 | C41: Gb／顆 | D41: 26 | E41: 30 | F41: 32 | G41: Assumed | H41: JEDEC HBM4（JESD270-4）：24Gb 或 32Gb 晶粒（TrendForce 2025-04-28）；HBM3E 以 24Gb 為主 | I41: 同上
A42: den_30 | B42: DRAM 核心晶粒容量（組合平均）2030 | C42: Gb／顆 | D42: 28 | E42: 32 | F42: 32 | G42: Assumed | H42: JEDEC HBM4（JESD270-4）：24Gb 或 32Gb 晶粒（TrendForce 2025-04-28）；HBM3E 以 24Gb 為主 | I42: 同上
...

Sheet Q
A1: Q — 季度實績（十億日圓；EPS 為日圓）。會計年度 4–3 月。來源1：公司決算說明資料（film/20260422、20261022）與決算短信；來源2：松井證券季度表（百萬日圓）
A3: 項目 | B3: FY25 Q1 | C3: FY25 Q2 | D3: FY25 Q3 | E3: FY25 Q4 | F3: FY2025 | G3: FY26 Q1 | H3: FY26 Q2 | I3: FY26 Q3（公司指引） | J3: 標記 | K3: 來源1 | L3: 來源2／說明
A4: 營收 | B4: =a25_rev-C4-D4-E4 -> 89.914 | C4: 104.623 | D4: 109.291 | E4: 133.061 | F4: =SUM(B4:E4) -> 436.889 | G4: 114.308 | H4: 142.75 | I4: =g3_rev -> 132.442 | J4: Verified／Interested-party（指引） | K4: 公司說明資料：89.9／104.6／109.3／133.1；FY26 114.3／142.8；3Q 指引 132.4 | L4: 松井：104,623／109,291／133,061；FY26 114,308／142,750（Q1 FY25 由全年減其他三季）
A5: 營業利益 | B5: =a25_oi-C5-D5-E5 -> 34.48 | C5: 44.391 | D5: 47.341 | E5: 58.777 | F5: =SUM(B5:E5) -> 184.989 | G5: 49.033 | H5: 67.606 | I5: =g3_oi -> 58.061 | J5: Verified／Interested-party（指引） | K5: 公司說明資料：34.5／44.4／47.3／58.8；FY26 49.0／67.6；3Q 58.1 | L5: 松井：44,391／47,341／58,777；49,033／67,606
A6: 淨利 | B6: =a25_ni-C6-D6-E6 -> 23.767 | C6: 32.146 | D6: 36.726 | E6: 42.882 | F6: =SUM(B6:E6) -> 135.521 | G6: 34.221 | H6: 46.145 | I6: =g9_ni-q26h1_ni -> 41.534 | J6: Verified／Interested-party（指引） | K6: 公司說明資料：23.8／32.1／36.7／42.9；FY26 34.2／46.1；3Q 41.5 | L6: 松井：32,146／36,726／42,882；34,221／46,145
A7: EPS（基本） | B7: =a25_eps-C7-D7-E7 -> 219.14 | C7: 296.49 | D7: 338.73 | E7: 395.48 | F7: =SUM(B7:E7) -> 1249.84 | G7: 315.51 | H7: 425.38 | I7: =1123.43-q26h1_eps -> 382.59 | J7: Verified／Interested-party（指引） | K7: 公司決算短信：FY26 Q1 315.51、上半 740.84；9 個月指引 1,123.43 | L7: 松井：296.49／338.73／395.48；315.51／425.38
A8: 出貨額 | B8: 111.1 | C8: 96.3 | D8: 113.6 | E8: 121.6 | F8: =SUM(B8:E8) -> 442.6 | G8: 135.9 | H8: 148.6 | I8: 149.6 | J8: Verified／Interested-party（指引） | K8: 公司說明資料 | L8: Investing.com（2026-10-22）：Q2 148.6、Q3 指引 149.6
A9: 營業利益率 | B9: =B5/B4 -> 0.38347755 | C9: =C5/C4 -> 0.42429485 | D9: =D5/D4 -> 0.43316467 | E9: =E5/E4 -> 0.44172973 | F9: =F5/F4 -> 0.42342334 | G9: =G5/G4 -> 0.4289551 | H9: =H5/H4 -> 0.4735972 | I9: =I5/I4 -> 0.43838812
A10: 毛利率（公司說明資料；FY25 Q1、Q3 未列單季毛利額） | C10: 0.695 | E10: 0.709 | F10: =a25_gp/a25_rev -> 0.70149855 | G10: 0.713 | H10: 0.717 | L10: FY25 Q3 71.4%（4Q 資料的前季對照）；3Q 指引：比 Q2 低約 2 個百分點（法說摘要）
A11: 檢查：FY2026 上半（G+H）− 決算短信上半（營收、營業利益、淨利；應約為 0） | B11: =G4+H4-q26h1_rev -> 0 | C11: =G5+H5-q26h1_oi -> 0 | D11: =G6+H6-q26h1_ni -> 0
A13: 製品別構成比（公司說明資料；出貨或營收基準，百分比取整）
A14: 製品 | B14: FY2023 | C14: FY2024 | D14: FY2025 | E14: FY26 Q2 | J14: 標記 | K14: 來源
A15: 精密加工裝置 | B15: 0.64 | C15: 0.63 | D15: 0.62 | E15: 0.63 | J15: Verified | K15: film/20240425、20250417、20260422、20261022
A16: ダイサ | B16: 0.32 | C16: 0.33 | D16: 0.31 | E16: 0.33 | J16: Verified | K16: film/20240425、20250417、20260422、20261022
A17: グラインダ | B17: 0.28 | C17: 0.27 | D17: 0.28 | E17: 0.26 | J17: Verified | K17: film/20240425、20250417、20260422、20261022
A18: 精密加工ツール（消耗品） | B18: 0.22 | C18: 0.21 | D18: 0.21 | E18: 0.23 | J18: Verified | K18: film/20240425、20250417、20260422、20261022
A19: その他 | B19: 0.14 | C19: 0.16 | D19: 0.16 | E19: 0.14 | J19: Verified | K19: film/20240425、20250417、20260422、20261022
A21: 公司揭露的季度結構（法說摘要，BigGo 2026-07-23／10-22；Interested-party）：記憶體占營收 FY26 Q1 35%、Q2 略低於 40%、Q3 預估約 30%；OSAT 占 FY26 Q1 35%；功率半導體不到一成；FY26 Q2 切割機用途 IC 73%、研削機用途 IC 77%

Sheet Hist
A1: Hist — 年度實績（十億日圓；EPS 為日圓）。來源1：公司各年決算短信（英文版 fr*.pdf，以網頁擷取讀取）；來源2：松井證券（FY2021 起）。用途：利潤率迴歸（In 頁 H 節）、非 AI 成長的 Analogy、10 年 P/E 的 EPS
A2: 股票分割：2023-04-01 一股分三股（公司 FY2022 決算短信註記；tousaiblog 第二來源）。FY2021（2022年3月期）起的 EPS 已在公司文件中依分割調整；FY2020 以前除以 3
A5: 會計年度 | B5: 營收 | C5: 毛利 | D5: 銷管費 | E5: 營業利益 | F5: 淨利 | G5: EPS（公司公布，日圓） | H5: 毛利率 | I5: ln 營收 | J5: 分割係數 | K5: EPS（分割調整後） | L5: 來源1（公司） | M5: 來源2
A6: FY2015（2016-03） | B6: 127.85 | C6: 72.298 | D6: 41.959 | E6: 30.338 | F6: 23.096 | G6: 646.09 | H6: =C6/B6 -> 0.56549081 | I6: =LN(B6) -> 4.8508577 | J6: 3 | K6: =G6/J6 -> 215.36333 | L6: fr20170510.pdf | M6: 未找到（松井只到 FY2021）
A7: FY2016（2017-03） | B7: 134.204 | C7: 74.495 | D7: 43.153 | E7: 31.341 | F7: 24.203 | G7: 675.82 | H7: =C7/B7 -> 0.55508778 | I7: =LN(B7) -> 4.899361 | J7: 3 | K7: =G7/J7 -> 225.27333 | L7: fr20170510.pdf（說明文字寫 134,240／24,230，取財務表數字） | M7: 未找到
A8: FY2017（2018-03） | B8: 167.364 | C8: 99.125 | D8: 48.13 | E8: 50.995 | F8: 37.171 | G8: 1035.67 | H8: =C8/B8 -> 0.59227193 | I8: =LN(B8) -> 5.1201711 | J8: 3 | K8: =G8/J8 -> 345.22333 | L8: fr20190508.pdf | M8: 未找到
A9: FY2018（2019-03） | B9: 147.5 | C9: 86.91 | D9: 48.264 | E9: 38.645 | F9: 28.824 | G9: 802.35 | H9: =C9/B9 -> 0.58922034 | I9: =LN(B9) -> 4.9938282 | J9: 3 | K9: =G9/J9 -> 267.45 | L9: fr20190508.pdf | M9: 未找到
A10: FY2019（2020-03） | B10: 141.083 | C10: 84.792 | D10: 48.341 | E10: 36.451 | F10: 27.653 | G10: 769.56 | H10: =C10/B10 -> 0.60100792 | I10: =LN(B10) -> 4.9493484 | J10: 3 | K10: =G10/J10 -> 256.52 | L10: fr20210422.pdf | M10: 未找到
A11: FY2020（2021-03） | B11: 182.857 | C11: 106.883 | D11: 53.776 | E11: 53.106 | F11: 39.091 | G11: 1085.47 | H11: =C11/B11 -> 0.58451686 | I11: =LN(B11) -> 5.2087044 | J11: 3 | K11: =G11/J11 -> 361.82333 | L11: fr20210422.pdf（說明文字營業利益 53,160，取表內 53,106） | M11: 未找到
A12: FY2021（2022-03） | B12: 253.781 | C12: 154.011 | D12: 62.498 | E12: 91.513 | F12: 66.206 | G12: 611.67 | H12: =C12/B12 -> 0.60686576 | I12: =LN(B12) -> 5.5364717 | J12: 1 | K12: =G12/J12 -> 611.67 | L12: fr20230420.pdf（分割調整後 EPS） | M12: 松井證券 決算情報（finance.matsui.co.jp/stock/6146/settlement）
A13: FY2022（2023-03） | B13: 284.135 | C13: 184.506 | D13: 74.093 | E13: 110.413 | F13: 82.891 | G13: 765.47 | H13: =C13/B13 -> 0.64936034 | I13: =LN(B13) -> 5.6494495 | J13: 1 | K13: =G13/J13 -> 765.47 | L13: fr20230420.pdf | M13: 松井證券 決算情報（finance.matsui.co.jp/stock/6146/settlement）
A14: FY2023（2024-03） | B14: 307.554 | C14: 208.642 | D14: 87.151 | E14: 121.49 | F14: 84.205 | G14: 777.29 | H14: =C14/B14 -> 0.67839144 | I14: =LN(B14) -> 5.7286507 | J14: 1 | K14: =G14/J14 -> 777.29 | L14: fr20250417.pdf | M14: 松井證券 決算情報（finance.matsui.co.jp/stock/6146/settlement）
A15: FY2024（2025-03） | B15: 393.313 | C15: 277.57 | D15: 110.736 | E15: 166.834 | F15: 123.891 | G15: 1143.26 | H15: =C15/B15 -> 0.70572292 | I15: =LN(B15) -> 5.9746057 | J15: 1 | K15: =G15/J15 -> 1143.26 | L15: fr20250417.pdf | M15: 松井證券 決算情報（finance.matsui.co.jp/stock/6146/settlement）
A16: FY2025（2026-03） | B16: 436.889 | C16: 306.477 | D16: 121.487 | E16: 184.989 | F16: 135.521 | G16: 1249.84 | H16: =C16/B16 -> 0.70149855 | I16: =LN(B16) -> 6.0796792 | J16: 1 | K16: =G16/J16 -> 1249.84 | L16: fr20260422.pdf | M16: 松井證券 決算情報（finance.matsui.co.jp/stock/6146/settlement）
A18: 檢查：FY2025 毛利 − 銷管費 − 營業利益（應為 0） | B18: =C16-D16-E16 -> 0.001
A19: 檢查：FY2025 列 − In 頁 a25_*（應為 0） | B19: =ABS(B16-a25_rev)+ABS(C16-a25_gp)+ABS(E16-a25_oi)+ABS(F16-a25_ni)+ABS(G16-a25_eps) -> 0
A21: 非 AI 成長的 Analogy
A22: 營收年複合 FY2015→FY2022（AI 前，含中國與功率熱潮） | B22: =(B13/B6)^(1/7)-1 -> 0.12084688
A23: 營收年複合 FY2016→FY2019（一個循環） | B23: =(B10/B7)^(1/3)-1 -> 0.016802039
A24: 最大單年下滑 FY2018（2019-03） | B24: =B9/B8-1 -> -0.11868741
A26: 迴歸結果（In 頁同值）
A27: 毛利率 ＝ a ＋ b × ln 營收：a | B27: =gm_a -> 0.010428454
A28: b | B28: =gm_b -> 0.11382596
A29: R² | B29: =RSQ(H6:H16,I6:I16) -> 0.89559667
A30: 銷管費 ＝ 固定 ＋ 變動 × 營收：固定 ¥B | B30: =sg_f -> 8.1233423
A31: 變動 | B31: =sg_v -> 0.25236703
A32: R² | B32: =RSQ(D6:D16,B6:B16) -> 0.97582671
A33: FY2025 毛利率：迴歸值 − 實績 | B33: =gm_a+gm_b*I16-H16 -> 0.00095521405
A34: FY2025 銷管費：迴歸值 − 實績（¥B） | B34: =sg_f+sg_v*B16-D16 -> -3.1072765

Sheet PL
A1: PL — Disco 損益（¥B；FY2025 為實績，FY2026–FY2029 為模型）。頂端為摘要，下方為三情境各一個完整推導區塊
A3: 情境／項目 | B3: 單位 | C3: FY2025A | D3: FY2026 | E3: FY2027 | F3: FY2028 | G3: FY2029 | H3: 說明
A4: 情境 A
A5: 營收 | B5: ¥B | C5: =C78 -> 436.889 | D5: =D78 -> 507.30654 | E5: =E78 -> 539.54937 | F5: =F78 -> 570.78984 | G5: =G78 -> 584.80298
A6: HBM 裝置 | B6: ¥B | C6: =C68 -> 36 | D6: =D68 -> 41.662759 | E6: =E68 -> 47.854941 | F6: =F68 -> 44.842416 | G6: =G68 -> 27.254861
A7: 先進封裝裝置 | B7: ¥B | C7: =C69 -> 39 | D7: =D69 -> 60.148359 | E7: =E69 -> 42.599118 | F7: =F69 -> 38.320722 | G7: =G69 -> 36.866396
A8: 非 AI 裝置 | B8: ¥B | C8: =C71 -> 195.87118 | D8: =D71 -> 207.62345 | E8: =E71 -> 220.08086 | F8: =F71 -> 233.28571 | G8: =G71 -> 247.28285
A9: 消耗品 | B9: ¥B | C9: =C76 -> 91.74669 | D9: =D76 -> 111.62986 | E9: =E76 -> 137.29106 | F9: =F76 -> 157.30672 | G9: =G76 -> 173.98236
A10: その他 | B10: ¥B | C10: =C77 -> 74.27113 | D10: =D77 -> 86.242112 | E10: =E77 -> 91.723394 | F10: =F77 -> 97.034272 | G10: =G77 -> 99.416506
A11: AI 占營收（含 AI 消耗品） | B11: % | C11: =C79 -> 0.27688438 | D11: =D79 -> 0.34146874 | E11: =E79 -> 0.34522663 | F11: =F79 -> 0.34547141 | G11: =G79 -> 0.32440691
A12: AI 裝置占營收 | B12: % | C12: =C80 -> 0.2068293 | D12: =D80 -> 0.24179463 | E12: =E80 -> 0.20198484 | F12: =F80 -> 0.17554018 | G12: =G80 -> 0.13210351
A13: 毛利率 | B13: % | C13: =C81 -> 0.70149855 | D13: =D81 -> 0.71946349 | E13: =E81 -> 0.72647732 | F13: =F81 -> 0.73288421 | G13: =G81 -> 0.73564494
A14: 營業利益 | B14: ¥B | C14: =C84 -> 184.99 | D14: =D84 -> 228.83775 | E14: =E84 -> 247.68256 | F14: =F84 -> 266.15098 | G14: =G84 -> 274.49902
A15: 營業利益率 | B15: % | C15: =C85 -> 0.42342563 | D15: =D85 -> 0.45108377 | E15: =E85 -> 0.45905449 | F15: =F85 -> 0.46628542 | G15: =G85 -> 0.46938717
A16: 淨利 | B16: ¥B | C16: =C86 -> 135.521 | D16: =D86 -> 167.64413 | E16: =E86 -> 181.44965 | F16: =F86 -> 194.97941 | G16: =G86 -> 201.0951
A17: EPS | B17: ¥ | C17: =C87 -> 1249.84 | D17: =D87 -> 1545.3795 | E17: =E87 -> 1672.6417 | F17: =F87 -> 1797.362 | G17: =G87 -> 1853.7377
A19: 情境 B
A20: 營收 | B20: ¥B | C20: =C119 -> 436.889 | D20: =D119 -> 496.46159 | E20: =E119 -> 505.09082 | F20: =F119 -> 544.97525 | G20: =G119 -> 550.96252
A21: HBM 裝置 | B21: ¥B | C21: =C109 -> 36 | D21: =D109 -> 40.474498 | E21: =E109 -> 44.88606 | F21: =F109 -> 46.568287 | G21: =G109 -> 26.971782
A22: 先進封裝裝置 | B22: ¥B | C22: =C110 -> 39 | D22: =D110 -> 52.335307 | E22: =E110 -> 19.452651 | F22: =F110 -> 37.850021 | G22: =G110 -> 31.336436
A23: 非 AI 裝置 | B23: ¥B | C23: =C112 -> 195.87118 | D23: =D112 -> 207.62345 | E23: =E112 -> 220.08086 | F23: =F112 -> 220.08086 | G23: =G112 -> 233.28571
A24: 消耗品 | B24: ¥B | C24: =C117 -> 91.74669 | D24: =D117 -> 111.62986 | E24: =E117 -> 134.80581 | F24: =F117 -> 147.83029 | G24: =G117 -> 165.70497
A25: その他 | B25: ¥B | C25: =C118 -> 74.27113 | D25: =D118 -> 84.39847 | E25: =E118 -> 85.86544 | F25: =F118 -> 92.645793 | G25: =G118 -> 93.663629
A26: AI 占營收（含 AI 消耗品） | B26: % | C26: =C120 -> 0.27688438 | D26: =D120 -> 0.32708346 | E26: =E120 -> 0.30055636 | F26: =F120 -> 0.34366046 | G26: =G120 -> 0.31351987
A27: AI 裝置占營收 | B27: % | C27: =C121 -> 0.2068293 | D27: =D121 -> 0.22523201 | E27: =E121 -> 0.15347046 | F27: =F121 -> 0.18663013 | G27: =G121 -> 0.12750571
A28: 毛利率 | B28: % | C28: =C122 -> 0.70149855 | D28: =D122 -> 0.71700379 | E28: =E122 -> 0.71896526 | F28: =F122 -> 0.72761627 | G28: =G122 -> 0.72885998
A29: 營業利益 | B29: ¥B | C29: =C125 -> 184.99 | D29: =D125 -> 222.55096 | E29: =E125 -> 227.55114 | F29: =F125 -> 250.87573 | G29: =G125 -> 254.40641
A30: 營業利益率 | B30: % | C30: =C126 -> 0.42342563 | D30: =D126 -> 0.44827428 | E30: =E126 -> 0.45051529 | F30: =F126 -> 0.46034334 | G30: =G126 -> 0.46174903
A31: 淨利 | B31: ¥B | C31: =C127 -> 135.521 | D31: =D127 -> 163.0385 | E31: =E127 -> 166.70157 | F31: =F127 -> 183.78893 | G31: =G127 -> 186.37547
A32: EPS | B32: ¥ | C32: =C128 -> 1249.84 | D32: =D128 -> 1502.9238 | E32: =E128 -> 1536.6908 | F32: =F128 -> 1694.2057 | G32: =G128 -> 1718.049
A34: 情境 C
A35: 營收 | B35: ¥B | C35: =C160 -> 436.889 | D35: =D160 -> 487.17684 | E35: =E160 -> 460.65889 | F35: =F160 -> 446.80874 | G35: =G160 -> 461.80271
A36: HBM 裝置 | B36: ¥B | C36: =C150 -> 36 | D36: =D150 -> 32.768162 | E36: =E150 -> 16.386735 | F36: =F150 -> 28.694761 | G36: =G150 -> 19.038905
A37: 先進封裝裝置 | B37: ¥B | C37: =C151 -> 39 | D37: =D151 -> 52.335307 | E37: =E151 -> 15.249439 | F37: =F151 -> 22.992433 | G37: =G151 -> 22.119837
A38: 非 AI 裝置 | B38: ¥B | C38: =C153 -> 195.87118 | D38: =D153 -> 207.62345 | E38: =E153 -> 220.08086 | F38: =F153 -> 193.67115 | G38: =G153 -> 205.29142
A39: 消耗品 | B39: ¥B | C39: =C158 -> 91.74669 | D39: =D158 -> 111.62986 | E39: =E158 -> 130.62984 | F39: =F158 -> 125.49291 | G39: =G158 -> 136.84608
A40: その他 | B40: ¥B | C40: =C159 -> 74.27113 | D40: =D159 -> 82.820064 | E40: =E159 -> 78.312011 | F40: =F159 -> 75.957486 | G40: =G159 -> 78.50646
A41: AI 占營收（含 AI 消耗品） | B41: % | C41: =C161 -> 0.27688438 | D41: =D161 -> 0.31425884 | E41: =E161 -> 0.23309292 | F41: =F161 -> 0.28053412 | G41: =G161 -> 0.2640359
A42: AI 裝置占營收 | B42: % | C42: =C162 -> 0.2068293 | D42: =D162 -> 0.21046628 | E42: =E162 -> 0.082742075 | F42: =F162 -> 0.13937446 | G42: =G162 -> 0.10738102
A43: 毛利率 | B43: % | C43: =C163 -> 0.70149855 | D43: =D163 -> 0.71485488 | E43: =E163 -> 0.70848411 | F43: =F163 -> 0.69500932 | G43: =G163 -> 0.69876639
...

Sheet Val
A1: Val — P/E 估值。跨公司規則：合理倍數＝10 年（2016–2025 年底）P/E 的分位，依循環位置：見頂年 25 分位、中段中位數、谷底 75 分位
A2: P/E 定義（自算）：日曆年底收盤價 ÷ 「當期會計年度」公司公布的基本 EPS（例：2025-12 對 FY2025＝2026年3月期）。價格與 EPS 皆以 2023-04-01 一股分三股調整
A4: 1. 10 年 P/E（年底）
A5: 年底 | B5: 收盤價（未調整） | C5: 分割係數 | D5: 收盤價（調整後） | E5: 來源2：Yahoo Finance 調整後收盤 | F5: 兩者差距 | G5: 當期 FY EPS（調整後） | H5: P/E 當期 | I5: 標記 | J5: 說明
A6: 2016-12（2016-12-30） | B6: 14160 | C6: 3 | D6: =B6/C6 -> 4720 | E6: 4720 | F6: =D6/E6-1 -> 0 | G6: =Hist!K7 -> 225.27333 | H6: =D6/G6 -> 20.952325 | I6: Verified | J6: 來源1：Yahoo!ファイナンス 時系列（終值與調整後終值）；EPS：Hist 頁（公司決算短信）
A7: 2017-12（2017-12-29） | B7: 25070 | C7: 3 | D7: =B7/C7 -> 8356.6667 | E7: 8356.67 | F7: =D7/E7-1 -> -3.9888297e-07 | G7: =Hist!K8 -> 345.22333 | H7: =D7/G7 -> 24.206552 | I7: Verified
A8: 2018-12（2018-12-28） | B8: 12850 | C8: 3 | D8: =B8/C8 -> 4283.3333 | E8: 4283.33 | F8: =D8/E8-1 -> 7.7821072e-07 | G8: =Hist!K9 -> 267.45 | H8: =D8/G8 -> 16.015455 | I8: Verified
A9: 2019-12（2019-12-30） | B9: 25900 | C9: 3 | D9: =B9/C9 -> 8633.3333 | E9: 8633.33 | F9: =D9/E9-1 -> 3.8610054e-07 | G9: =Hist!K10 -> 256.52 | H9: =D9/G9 -> 33.655595 | I9: Verified
A10: 2020-12（2020-12-30） | B10: 34750 | C10: 3 | D10: =B10/C10 -> 11583.333 | E10: 11583.33 | F10: =D10/E10-1 -> 2.8776987e-07 | G10: =Hist!K11 -> 361.82333 | H10: =D10/G10 -> 32.013782 | I10: Verified
A11: 2021-12（2021-12-30） | B11: 35150 | C11: 3 | D11: =B11/C11 -> 11716.667 | E11: 11716.67 | F11: =D11/E11-1 -> -2.8449494e-07 | G11: =Hist!K12 -> 611.67 | H11: =D11/G11 -> 19.155209 | I11: Verified
A12: 2022-12（2022-12-30） | B12: 37750 | C12: 3 | D12: =B12/C12 -> 12583.333 | E12: 12583.33 | F12: =D12/E12-1 -> 2.6490073e-07 | G12: =Hist!K13 -> 765.47 | H12: =D12/G12 -> 16.438702 | I12: Verified
A13: 2023-12（2023-12-29） | B13: 34980 | C13: 1 | D13: =B13/C13 -> 34980 | E13: 34980 | F13: =D13/E13-1 -> 0 | G13: =Hist!K14 -> 777.29 | H13: =D13/G13 -> 45.002509 | I13: Verified | J13: 2023 年 P/E 偏高：FY2023 EPS 僅成長 1.5%，股價先反映 AI
A14: 2024-12（2024-12-30） | B14: 42730 | C14: 1 | D14: =B14/C14 -> 42730 | E14: 42730 | F14: =D14/E14-1 -> 0 | G14: =Hist!K15 -> 1143.26 | H14: =D14/G14 -> 37.375575 | I14: Verified
A15: 2025-12（2025-12-30） | B15: 48170 | C15: 1 | D15: =B15/C15 -> 48170 | E15: 48170 | F15: =D15/E15-1 -> 0 | G15: =Hist!K16 -> 1249.84 | H15: =D15/G15 -> 38.540933 | I15: Verified
A17: 兩個價格來源可能共用同一資料商（不完全獨立）；10 年都有價格，無缺年。
A19: 2. 分位（10 年）
A20: 統計 | B20: P/E 當期 | C20: 用途
A21: 25 分位 | B21: =PERCENTILE(H6:H15,0.25) -> 19.604488 | C21: 見頂年
A22: 中位數 | B22: =PERCENTILE(H6:H15,0.5) -> 28.110167 | C22: 中段
A23: 75 分位 | B23: =PERCENTILE(H6:H15,0.75) -> 36.44558 | C23: 谷底
A24: 年數 | B24: =COUNT(H6:H15) -> 10
A25: 敏感度：去掉 2023 年（極端值）時 25／50／75 分位 | B25: =PERCENTILE((H6:H12~H14:H15),0.25) -> 19.155209 | C25: =PERCENTILE((H6:H12~H14:H15),0.5) -> 24.206552 | D25: =PERCENTILE((H6:H12~H14:H15),0.75) -> 33.655595
A27: 3. FY2027 的循環位置（依各情境的營業利益路徑判定，公式）
A28: 情境 | B28: FY2026 營業利益 | C28: FY2027 營業利益 | D28: FY2028 營業利益 | E28: FY2025–29 最高 | F28: 判定 | G28: 倍數 | H28: 規則
A29: A | B29: =PL!D14 -> 228.83775 | C29: =PL!E14 -> 247.68256 | D29: =PL!F14 -> 266.15098 | E29: =MAX(PL!C14:G14) -> 274.49902 | F29: =IF(C29>=E29,"見頂",IF(AND(C29<B29,C29<D29),"谷底","中段")) -> 中段 | G29: =IF(F29="見頂",pe_peak,IF(F29="谷底",pe_trough,pe_mid)) -> 28.110167 | H29: 見頂＝FY2027 為 FY2025–29 最高；谷底＝低於前後兩年；其餘為中段
A30: B | B30: =PL!D29 -> 222.55096 | C30: =PL!E29 -> 227.55114 | D30: =PL!F29 -> 250.87573 | E30: =MAX(PL!C29:G29) -> 254.40641 | F30: =IF(C30>=E30,"見頂",IF(AND(C30<B30,C30<D30),"谷底","中段")) -> 中段 | G30: =IF(F30="見頂",pe_peak,IF(F30="谷底",pe_trough,pe_mid)) -> 28.110167 | H30: 見頂＝FY2027 為 FY2025–29 最高；谷底＝低於前後兩年；其餘為中段
A31: C | B31: =PL!D44 -> 217.19003 | C31: =PL!E44 -> 201.99104 | D31: =PL!F44 -> 189.6531 | E31: =MAX(PL!C44:G44) -> 217.19003 | F31: =IF(C31>=E31,"見頂",IF(AND(C31<B31,C31<D31),"谷底","中段")) -> 中段 | G31: =IF(F31="見頂",pe_peak,IF(F31="谷底",pe_trough,pe_mid)) -> 28.110167 | H31: 見頂＝FY2027 為 FY2025–29 最高；谷底＝低於前後兩年；其餘為中段
A33: 4. 隱含股價（FY2027 EPS × 依判定的倍數；其餘倍數僅供參考）
A34: 情境 | B34: EPS 年度 | C34: EPS | D34: 倍數類型 | E34: 倍數 | F34: 隱含股價 | G34: 相對現價 | H34: 備註
A35: A | B35: FY2027 | C35: =PL!E17 -> 1672.6417 | D35: ="規則值："&F29 -> 規則值：中段 | E35: =G29 -> 28.110167 | F35: =C35*E35 -> 47018.238 | G35: =F35/px-1 -> -0.082212796
A36: A | B36: FY2027 | C36: =PL!E17 -> 1672.6417 | D36: 參考：25 分位 | E36: =pe_peak -> 19.604488 | F36: =C36*E36 -> 32791.284 | G36: =F36/px-1 -> -0.35992027
A37: A | B37: FY2027 | C37: =PL!E17 -> 1672.6417 | D37: 參考：中位數 | E37: =pe_mid -> 28.110167 | F37: =C37*E37 -> 47018.238 | G37: =F37/px-1 -> -0.082212796
A38: A | B38: FY2027 | C38: =PL!E17 -> 1672.6417 | D38: 參考：75 分位 | E38: =pe_trough -> 36.44558 | F38: =C38*E38 -> 60960.398 | G38: =F38/px-1 -> 0.18993555
A39: A | B39: FY2028 | C39: =PL!F17 -> 1797.362 | D39: 參考：FY2028 × 中位數 | E39: =pe_mid -> 28.110167 | F39: =C39*E39 -> 50524.147 | G39: =F39/px-1 -> -0.013778124
A40: B | B40: FY2027 | C40: =PL!E32 -> 1536.6908 | D40: ="規則值："&F30 -> 規則值：中段 | E40: =G30 -> 28.110167 | F40: =C40*E40 -> 43196.636 | G40: =F40/px-1 -> -0.15680976
A41: B | B41: FY2027 | C41: =PL!E32 -> 1536.6908 | D41: 參考：25 分位 | E41: =pe_peak -> 19.604488 | F41: =C41*E41 -> 30126.037 | G41: =F41/px-1 -> -0.41194541
A42: B | B42: FY2027 | C42: =PL!E32 -> 1536.6908 | D42: 參考：中位數 | E42: =pe_mid -> 28.110167 | F42: =C42*E42 -> 43196.636 | G42: =F42/px-1 -> -0.15680976
A43: B | B43: FY2027 | C43: =PL!E32 -> 1536.6908 | D43: 參考：75 分位 | E43: =pe_trough -> 36.44558 | F43: =C43*E43 -> 56005.589 | G43: =F43/px-1 -> 0.093218595
A44: B | B44: FY2028 | C44: =PL!F32 -> 1694.2057 | D44: 參考：FY2028 × 中位數 | E44: =pe_mid -> 28.110167 | F44: =C44*E44 -> 47624.405 | G44: =F44/px-1 -> -0.070380529
A45: C | B45: FY2027 | C45: =PL!E47 -> 1364.0792 | D45: ="規則值："&F31 -> 規則值：中段 | E45: =G31 -> 28.110167 | F45: =C45*E45 -> 38344.496 | G45: =F45/px-1 -> -0.25152263
...

Sheet Recon
A1: Recon — 本模型 vs 上半實績年化、公司下一季指引、共識（共識只作參考，未用於校準）。差距＝模型 ÷ 對照 − 1
A3: 項目 | B3: 對照值 | C3: 模型 A | D3: 差距 A | E3: 模型 B | F3: 差距 B | G3: 模型 C | H3: 差距 C | I3: 對照來源 | J3: 說明
A4: A. FY2026 vs 實績與公司指引（公司只給下一季）
A5: 營收 vs 上半實績 × 2 | B5: =q26h1_rev*2 -> 514.116 | C5: =PL!D5 -> 507.30654 | D5: =C5/B5-1 -> -0.013244984 | E5: =PL!D20 -> 496.46159 | F5: =E5/B5-1 -> -0.034339357 | G5: =PL!D35 -> 487.17684 | H5: =G5/B5-1 -> -0.052398983 | I5: 決算短信 2026-10-22 | J5: 上半 257.1 × 2
A6: 營收 vs 上半實績＋第三季指引＋第四季＝第三季指引（路徑） | B6: =g9_rev+g3_rev -> 521.942 | C6: =PL!D5 -> 507.30654 | D6: =C6/B6-1 -> -0.028040392 | E6: =PL!D20 -> 496.46159 | F6: =E6/B6-1 -> -0.048818475 | G6: =PL!D35 -> 487.17684 | H6: =G6/B6-1 -> -0.066607315 | I6: 決算短信＋說明資料 | J6: 389.5 ＋ 132.4；第四季無指引，假設與第三季持平（Derived）
A7: 營業利益 vs 上半實績 × 2 | B7: =q26h1_oi*2 -> 233.278 | C7: =PL!D14 -> 228.83775 | D7: =C7/B7-1 -> -0.019034172 | E7: =PL!D29 -> 222.55096 | F7: =E7/B7-1 -> -0.045983938 | G7: =PL!D44 -> 217.19003 | H7: =G7/B7-1 -> -0.068964814 | I7: 決算短信
A8: 營業利益 vs 路徑（174.7 ＋ 58.1） | B8: =g9_oi+g3_oi -> 232.761 | C8: =PL!D14 -> 228.83775 | D8: =C8/B8-1 -> -0.016855288 | E8: =PL!D29 -> 222.55096 | F8: =E8/B8-1 -> -0.043864913 | G8: =PL!D44 -> 217.19003 | H8: =G8/B8-1 -> -0.066896834 | I8: 同上
A9: 營業利益率 vs 上半實績（差距以百分點計） | B9: =q26h1_oi/q26h1_rev -> 0.45374585 | C9: =PL!D15 -> 0.45108377 | D9: =C9-B9 -> -0.0026620792 | E9: =PL!D30 -> 0.44827428 | F9: =E9-B9 -> -0.0054715706 | G9: =PL!D45 -> 0.44581352 | H9: =G9-B9 -> -0.0079323228 | I9: 同上（45.4%）
A10: 毛利率 vs 上半實績（百分點） | B10: =q26h1_gp/q26h1_rev -> 0.71546888 | C10: =PL!D13 -> 0.71946349 | D10: =C10-B10 -> 0.0039946095 | E10: =PL!D28 -> 0.71700379 | F10: =E10-B10 -> 0.0015349073 | G10: =PL!D43 -> 0.71485488 | H10: =G10-B10 -> -0.00061400454 | I10: 同上（71.5%）；第三季指引約低 2 點
A11: 下半營收（模型 FY2026 − 上半實績）÷ 2 vs 第三季指引 | B11: =g3_rev -> 132.442 | C11: =(PL!D5-q26h1_rev)/2 -> 125.12427 | D11: =C11/B11-1 -> -0.05525233 | E11: =(PL!D20-q26h1_rev)/2 -> 119.70179 | F11: =E11/B11-1 -> -0.096194609 | G11: =(PL!D35-q26h1_rev)/2 -> 115.05942 | H11: =G11/B11-1 -> -0.13124672 | I11: 說明資料 3Q 132.4
A12: EPS vs 上半實績 × 2 | B12: =q26h1_eps*2 -> 1481.68 | C12: =PL!D17 -> 1545.3795 | D12: =C12/B12-1 -> 0.042991413 | E12: =PL!D32 -> 1502.9238 | F12: =E12/B12-1 -> 0.014337638 | G12: =PL!D47 -> 1466.7205 | H12: =G12/B12-1 -> -0.010096298 | I12: 決算短信（740.84）
A13: B. FY2026 vs 共識與券商（參考）
A14: 營收 vs 共識（stockanalysis 2026-10-07，20 位） | B14: =cons_rev26 -> 564.96 | C14: =PL!D5 -> 507.30654 | D14: =C14/B14-1 -> -0.10204874 | E14: =PL!D20 -> 496.46159 | F14: =E14/B14-1 -> -0.12124471 | G14: =PL!D35 -> 487.17684 | H14: =G14/B14-1 -> -0.13767905 | I14: stockanalysis（564.96；區間 541.0–598.7） | J14: 共識早於 10-22 指引
A15: 營收 vs 樂天證券（2026-04-27） | B15: 550 | C15: =PL!D5 -> 507.30654 | D15: =C15/B15-1 -> -0.07762447 | E15: =PL!D20 -> 496.46159 | F15: =E15/B15-1 -> -0.097342569 | G15: =PL!D35 -> 487.17684 | H15: =G15/B15-1 -> -0.11422392 | I15: 今中能夫
A16: 營業利益 vs 樂天證券 | B16: =cons_oi26 -> 240 | C16: =PL!D14 -> 228.83775 | D16: =C16/B16-1 -> -0.04650939 | E16: =PL!D29 -> 222.55096 | F16: =E16/B16-1 -> -0.072704338 | G16: =PL!D44 -> 217.19003 | H16: =G16/B16-1 -> -0.095041558 | I16: 今中能夫（240）
A17: FY2027 營收 vs 樂天證券（640） | B17: =cons_rev27 -> 640 | C17: =PL!E5 -> 539.54937 | D17: =C17/B17-1 -> -0.1569541 | E17: =PL!E20 -> 505.09082 | F17: =E17/B17-1 -> -0.21079559 | G17: =PL!E35 -> 460.65889 | H17: =G17/B17-1 -> -0.28022049 | I17: 今中能夫
A18: C. 結構檢查
A19: 非 AI 裝置 FY2026 年增 vs SEMI 組裝封裝設備 CY2026 年增（百分點） | B19: =semi_pk/semi_pk_lo-1 -> 0.096 | C19: =PL!D8/PL!C8-1 -> 0.06 | D19: =C19-B19 -> -0.036 | E19: =PL!D23/PL!C23-1 -> 0.06 | F19: =E19-B19 -> -0.036 | G19: =PL!D38/PL!C38-1 -> 0.06 | H19: =G19-B19 -> -0.036 | I19: markets/equipment（SEMI 2026-07） | J19: 口徑不同（SEMI 為全球封裝設備美元金額），只看方向
A20: FY2025 AI 占營收（校準結果） | C20: =PL!C11 -> 0.27688438 | J20: AI 裝置 75 ＋ AI 消耗品，再按比例加その他；命題的「約兩成」
A21: FY2025 AI 裝置占營收（不含消耗品） | C21: =PL!C12 -> 0.2068293
A22: FY2027 AI 裝置占營收（A／B／C） | C22: =PL!E12 -> 0.20198484 | E22: =PL!E27 -> 0.15347046 | G22: =PL!E42 -> 0.082742075
A23: FY2027 AI 占營收（含 AI 消耗品；A／B／C） | C23: =PL!E11 -> 0.34522663 | E23: =PL!E26 -> 0.30055636 | G23: =PL!E41 -> 0.23309292
A24: 參考：公司稱 FY26 Q2 記憶體占營收略低於 40%、Q3 約 30%（含一般 DRAM／NAND，口徑不同，不可直接比較）

Sheet Sens
A1: Sens — 一次動一個輸入（情境 A）：對 FY2027、FY2028 營收與 EPS 的影響。每個案例是一個完整推導區塊（本頁下方，與 PL 同一引擎；校準會跟著重算）
A3: 案例 | B3: 設定 | C3: FY2027 營收 ¥B | D3: FY2027 EPS ¥ | E3: 相對基準 | F3: FY2028 營收 ¥B | G3: FY2028 EPS ¥ | H3: 相對基準 | I3: FY2027 AI 占營收
A4: 基準（情境 A） | B4: PL 區塊 A | C4: =PL!E78 -> 539.54937 | D4: =PL!E87 -> 1672.6417 | E4: =D4/D$4-1 -> 0 | F4: =PL!F78 -> 570.78984 | G4: =PL!F87 -> 1797.362 | H4: =G4/G$4-1 -> 0 | I4: =PL!E79 -> 0.34522663
A5: 汰換／升級比例 5% | B5: dlt 低 | C5: =E88 -> 531.31096 | D5: =E97 -> 1639.9803 | E5: =D5/D$4-1 -> -0.019526873 | F5: =F88 -> 557.70072 | G5: =F97 -> 1744.9425 | H5: =G5/G$4-1 -> -0.029164694 | I5: =E89 -> 0.33507383
A6: 汰換／升級比例 15% | B6: dlt 高 | C6: =E128 -> 546.77544 | D6: =E137 -> 1701.3693 | E6: =D6/D$4-1 -> 0.017174993 | F6: =F128 -> 582.24505 | G6: =F137 -> 1843.4276 | H6: =G6/G$4-1 -> 0.025629526 | I6: =E129 -> 0.35387997
A7: AI 錨點 −10%（67.5） | B7: ai25 低 | C7: =E168 -> 538.80431 | D7: =E177 -> 1669.6839 | E7: =D7/D$4-1 -> -0.0017683663 | F7: =F168 -> 571.53237 | G7: =F177 -> 1800.3427 | H7: =G7/G$4-1 -> 0.001658371 | I7: =E169 -> 0.3254776
A8: AI 錨點 +10%（82.5） | B8: ai25 高 | C8: =E208 -> 540.29444 | D8: =E217 -> 1675.6004 | E8: =D8/D$4-1 -> 0.0017688391 | F8: =F208 -> 570.0473 | G8: =F217 -> 1794.3821 | H8: =G8/G$4-1 -> -0.0016579579 | I8: =E209 -> 0.36492119
A9: HBM 比重 45% | B9: w_hbm 低 | C9: =E248 -> 539.54263 | D9: =E257 -> 1672.6149 | E9: =D9/D$4-1 -> -1.6009804e-05 | F9: =F248 -> 570.68584 | G9: =F257 -> 1796.9446 | H9: =G9/G$4-1 -> -0.00023222259 | I9: =E249 -> 0.34521844
A10: HBM 比重 52% | B10: w_hbm 高 | C10: =E288 -> 539.55837 | D10: =E297 -> 1672.6774 | E10: =D10/D$4-1 -> 2.1346466e-05 | F10: =F288 -> 570.92849 | G10: =F297 -> 1797.9186 | H10: =G10/G$4-1 -> 0.00030964272 | I10: =E289 -> 0.34523754
A11: 混合鍵合開關 0 | B11: 不納入混合鍵合 | C11: =E328 -> 538.23276 | D11: =E337 -> 1667.4154 | E11: =D11/D$4-1 -> -0.0031245729 | F11: =F328 -> 567.96459 | G11: =F337 -> 1786.0277 | H11: =G11/G$4-1 -> -0.0063060854 | I11: =E329 -> 0.34362494
A12: 混合鍵合淨影響 −20% | B12: 電漿切割取代部分切割 | C12: =E368 -> 535.59953 | D12: =E377 -> 1656.9703 | E12: =D12/D$4-1 -> -0.0093692748 | F12: =F368 -> 562.3421 | G12: =F377 -> 1763.5036 | H12: =G12/G$4-1 -> -0.018837823 | I12: =E369 -> 0.34039792
A13: 混合鍵合淨影響 +30% | B13: 精度升級較大 | C13: =E408 -> 542.1826 | D13: =E417 -> 1683.1017 | E13: =D13/D$4-1 -> 0.0062535717 | F13: =F408 -> 576.44034 | G13: =F417 -> 1820.0628 | H13: =G13/G$4-1 -> 0.012630084 | I13: =E409 -> 0.34840668
A14: 混合鍵合普及 高 | B14: hbp 高欄 | C14: =E448 -> 540.81303 | D14: =E457 -> 1677.6601 | E14: =D14/D$4-1 -> 0.0030002777 | F14: =F448 -> 572.41184 | G14: =F457 -> 1803.874 | H14: =G14/G$4-1 -> 0.0036230897 | I14: =E449 -> 0.34675656
A15: 晶粒容量 低（同位元需更多晶粒） | B15: den 低欄 | C15: =E488 -> 558.6588 | D15: =E497 -> 1748.7715 | E15: =D15/D$4-1 -> 0.045514702 | F15: =F488 -> 582.08981 | G15: =F497 -> 1842.8021 | H15: =G15/G$4-1 -> 0.025281555 | I15: =E489 -> 0.36762374
A16: 晶粒容量 高 | B16: den 高欄 | C16: =E528 -> 537.07 | D16: =E537 -> 1662.8019 | E16: =D16/D$4-1 -> -0.0058827887 | F16: =F528 -> 585.02204 | G16: =F537 -> 1854.6211 | H16: =G16/G$4-1 -> 0.031857277 | I16: =E529 -> 0.34220388
A17: 堆疊層數 低 | B17: stk 低欄 | C17: =E568 -> 542.69853 | D17: =E577 -> 1685.1523 | E17: =D17/D$4-1 -> 0.0074795136 | F17: =F568 -> 572.67294 | G17: =F577 -> 1804.9226 | H17: =G17/G$4-1 -> 0.0042065024 | I17: =E569 -> 0.34902613
A18: 堆疊層數 高 | B18: stk 高欄 | C18: =E608 -> 537.90156 | D18: =E617 -> 1666.1011 | E18: =D18/D$4-1 -> -0.003910346 | F18: =F608 -> 571.463 | G18: =F617 -> 1800.0642 | H18: =G18/G$4-1 -> 0.0015034246 | I18: =E609 -> 0.34322079
A19: 每堆疊額外工序 2 | B19: s_stk 低 | C19: =E648 -> 540.46293 | D19: =E657 -> 1676.2695 | E19: =D19/D$4-1 -> 0.0021689105 | F19: =F648 -> 572.08824 | G19: =F657 -> 1802.5746 | H19: =G19/G$4-1 -> 0.002900114 | I19: =E649 -> 0.34633341
A20: 每堆疊額外工序 4 | B20: s_stk 高 | C20: =E688 -> 538.74371 | D20: =E697 -> 1669.4434 | E20: =D20/D$4-1 -> -0.0019121639 | F20: =F688 -> 569.65021 | G20: =F697 -> 1792.7888 | H20: =G20/G$4-1 -> -0.0025444066 | I20: =E689 -> 0.34424745
A21: CY2030–31 需求年增 0% | B21: g_tail 低 | C21: =E728 -> 539.54937 | D21: =E737 -> 1672.6417 | E21: =D21/D$4-1 -> 0 | F21: =F728 -> 563.69431 | G21: =F737 -> 1768.9167 | H21: =G21/G$4-1 -> -0.015826123 | I21: =E729 -> 0.34522663
A22: CY2030–31 需求年增 20% | B22: g_tail 高 | C22: =E768 -> 539.54937 | D22: =E777 -> 1672.6417 | E22: =D22/D$4-1 -> 0 | F22: =F768 -> 581.35285 | G22: =F777 -> 1839.8335 | H22: =G22/G$4-1 -> 0.023629875 | I22: =E769 -> 0.34522663
A23: CoWoS 2025 600 千片 | B23: cw_25 低 | C23: =E808 -> 539.37297 | D23: =E817 -> 1671.9414 | E23: =D23/D$4-1 -> -0.00041871963 | F23: =F808 -> 571.6851 | G23: =F817 -> 1800.9559 | H23: =G23/G$4-1 -> 0.0019995295 | I23: =E809 -> 0.34501249
A24: 非 AI 裝置年增 0% | B24: g_non 低 | C24: =E848 -> 510.38109 | D24: =E857 -> 1557.4483 | E24: =D24/D$4-1 -> -0.068869148 | F24: =F848 -> 525.71209 | G24: =F857 -> 1617.8393 | H24: =G24/G$4-1 -> -0.099881222 | I24: =E849 -> 0.36495634
A25: 非 AI 裝置年增 12% | B25: g_non 高 | C25: =E888 -> 570.41678 | D25: =E897 -> 1795.8648 | E25: =D25/D$4-1 -> 0.073669735 | F25: =F888 -> 621.27079 | G25: =F897 -> 2001.6448 | H25: =G25/G$4-1 -> 0.11365702 | I25: =E889 -> 0.32654511
A26: 非 AI 消耗品年增 0% | B26: g_tl 低 | C26: =E928 -> 531.35636 | D26: =E937 -> 1640.16 | E26: =D26/D$4-1 -> -0.019419436 | F26: =F928 -> 558.19057 | G26: =F937 -> 1746.9001 | H26: =G26/G$4-1 -> -0.028075568 | I26: =E929 -> 0.3505497
A27: 非 AI 消耗品年增 10% | B27: g_tl 高 | C27: =E968 -> 548.14205 | D27: =E977 -> 1706.8107 | E27: =D27/D$4-1 -> 0.020428139 | F27: =F968 -> 584.64803 | G27: =F977 -> 1853.1129 | H27: =G27/G$4-1 -> 0.03101817 | I27: =E969 -> 0.33981486
A28: AI 消耗品比例 10% | B28: w_tlai 低 | C28: =E1008 -> 511.7327 | D28: =E1017 -> 1562.7584 | E28: =D28/D$4-1 -> -0.065694452 | F28: =F1008 -> 531.46013 | G28: =F1017 -> 1640.5708 | H28: =G28/G$4-1 -> -0.08723409 | I28: =E1009 -> 0.26750984
A29: AI 消耗品比例 40% | B29: w_tlai 高 | C29: =E1048 -> 558.91042 | D29: =E1057 -> 1749.7773 | E29: =D29/D$4-1 -> 0.046116027 | F29: =F1048 -> 598.16422 | G29: =F1057 -> 1907.7312 | H29: =G29/G$4-1 -> 0.061406229 | I29: =E1049 -> 0.39475334
A30: 市占 FY2029 −10pt（線性） | B30: sh_loss 高 | C30: =E1088 -> 512.8252 | D30: =E1097 -> 1567.0526 | E30: =D30/D$4-1 -> -0.063127181 | F30: =F1088 -> 529.94016 | G30: =F1097 -> 1634.5551 | H30: =G30/G$4-1 -> -0.09058101 | I30: =E1089 -> 0.34803764
A31: 毛利率迴歸只用 FY2019–25 | B31: gm_a2、gm_b2 | C31: =E1128 -> 539.54937 | D31: =E1137 -> 1670.0763 | E31: =D31/D$4-1 -> -0.0015337344 | F31: =F1128 -> 570.78984 | G31: =F1137 -> 1794.399 | H31: =G31/G$4-1 -> -0.0016485395 | I31: =E1129 -> 0.34522663
A32: 淨利÷營業利益 0.689（FY26 上半） | B32: nioi 低 | C32: =E1168 -> 539.54937 | D32: =E1177 -> 1573.1524 | E32: =D32/D$4-1 -> -0.059480352 | F32: =F1168 -> 570.78984 | G32: =F1177 -> 1690.4543 | H32: =G32/G$4-1 -> -0.059480352 | I32: =E1169 -> 0.34522663
A33: 淨利÷營業利益 0.743（FY2024） | B33: nioi 高 | C33: =E1208 -> 539.54937 | D33: =E1217 -> 1695.4986 | E33: =D33/D$4-1 -> 0.01366512 | F33: =F1208 -> 570.78984 | G33: =F1217 -> 1821.9232 | H33: =G33/G$4-1 -> 0.01366512 | I33: =E1209 -> 0.34522663
A34: 情境 B | B34: 顆數 2028 ×0.8、2029 ×0.85；非 AI FY2028 0% | C34: =PL!E119 -> 505.09082 | D34: =PL!E128 -> 1536.6908 | E34: =D34/D$4-1 -> -0.081279152 | F34: =PL!F119 -> 544.97525 | G34: =PL!F128 -> 1694.2057 | H34: =G34/G$4-1 -> -0.057393175 | I34: =PL!E120 -> 0.30055636
A35: 情境 C | B35: 顆數 ×0.6；非 AI FY2028 −12%；毛利率 −1pt | C35: =PL!E160 -> 460.65889 | D35: =PL!E169 -> 1364.0792 | E35: =D35/D$4-1 -> -0.18447614 | F35: =PL!F160 -> 446.80874 | G35: =PL!F169 -> 1280.7591 | H35: =G35/G$4-1 -> -0.28742287 | I35: =PL!E161 -> 0.23309292
A37: 讀法：校準在 FY2025 進行，所以改變 AI 錨點、HBM 比重、汰換比例等參數時，FY2025 仍等於實績，只改變之後的路徑形狀。汰換比例與校準係數只有乘積可識別（見 README）。
A60: 案例區塊：汰換／升級比例 5%（情境 A）
A61: 項目 | B61: 單位 | C61: CY2025／FY2025 | D61: CY2026／FY2026 | E61: CY2027／FY2027 | F61: CY2028／FY2028 | G61: CY2029／FY2029 | H61: CY2030 | I61: CY2031 | J61: 說明
A62: A. 日曆年（C＝CY2025 … I＝CY2031）
A63: HBM 出貨位元 | B63: EB | C63: =hsA_25 -> 2.2251147 | D63: =hsA_26 -> 3.782695 | E63: =hsA_27 -> 5.8631772 | F63: =hsA_28 -> 8.501607 | G63: =hsA_29 -> 11.477169 | H63: =G63*(1+g_tail) -> 12.624886 | I63: =H63*(1+g_tail) -> 13.887375 | J63: markets/memory；CY2030–31 以 g_tail 外推
A64: DRAM 晶粒容量 | B64: Gb | C64: =den_25 -> 24 | D64: =den_26 -> 24 | E64: =den_27 -> 26 | F64: =den_28 -> 28 | G64: =den_29 -> 30 | H64: =den_30 -> 32 | I64: =den_30 -> 32
...

Sheet Sources
A1: 來源（公司原文以網頁擷取工具讀取；表格欄位錯置處以算術核對；版面與頁碼待人工複核）
A2: 公司：2026年3月期 決算短信（英文，2026-04-22） | B2: https://www.disco.co.jp/eg/ir/library/doc/fr/fr20260422.pdf
A3: 公司：2027年3月期 第2四半期 決算短信（英文，2026-10-22） | B3: https://www.disco.co.jp/eg/ir/library/doc/fr/fr20261022.pdf
A4: 公司：2027年3月期 第1四半期 決算短信（2026-07-23） | B4: https://www.disco.co.jp/eg/ir/library/doc/fr/fr20260723.pdf
A5: 公司：FY2026 2Q 決算說明資料（2026-10-22） | B5: https://www.disco.co.jp/eg/ir/library/doc/film/20261022.pdf
A6: 公司：FY2025 4Q 決算說明資料（2026-04-22） | B6: https://www.disco.co.jp/eg/ir/library/doc/film/20260422.pdf
A7: 公司：FY2024 4Q 說明資料（2025-04-17）／FY2023（2024-04-25）／FY2022（2023-04-20） | B7: https://www.disco.co.jp/eg/ir/library/doc/film/20250417.pdf
A8: 公司：FY2026 1Q 說明筆記（2026-07-23） | B8: https://www.disco.co.jp/eg/ir/library/doc/film/20260723_note.pdf
A9: 公司：歷年決算短信（fr20250417、fr20230420、fr20210422、fr20190508、fr20170510） | B9: https://www.disco.co.jp/eg/ir/library/fr.html
A10: 公司：技術說明會 2025（2025-12）／2024（2024-12） | B10: https://www.disco.co.jp/jp/ir/movie/doc/J_Tech_Briefing_2025.pdf
A11: TSE 決算短信轉載（kabuyoho，2026-04-20 檔名；內容日期 2026-04-22） | B11: https://kabuyoho-sls-disclose.ifis.co.jp/295/140120260420506569.pdf
A12: 松井證券：決算情報（年度、季度） | B12: https://finance.matsui.co.jp/stock/6146/settlement/index
A13: 樂天證券 今中能夫：決算レポート（2026-04-27） | B13: https://media.rakuten-sec.net/articles/-/52260
... A30: tousaiblog：股票分割（2023-04-01 一股分三股） | B30: https://www.tousaiblog.org/disco-bunkatsu
A31: 市場層：markets/memory（market.py @ 5fa3751，v0.4）、tsmc／skhynix／markets/equipment 成品（本 repo）
A32: 無法開啟（建置環境被擋或逾時）：nikkei.com 株價推移、kabutan 年足、irbank、companiesmarketcap、traders.co.jp、stooq、macrotrends、gyokaidigest
A33: SemiAnalysis | B33: 未使用
