Workbook

Sheet README
A1: Disco（6146.T）收支與估值模型 v0.1.3（AI 半導體 Project 步驟 5：設備與材料） 2026-10-23
A2: v0.1.2（2026-10-23）：引用的上游成品檔名更新（SK 海力士 v0.4.1、美光 v0.3.1、三星 v0.2.1、台積電 v0.2.1 升版）；所有數值不變。
A3: 模型命題：Disco 的營收由需要研削與切割的晶圓次數驅動，AI 只占約兩成；問題是 HBM 堆疊與先進封裝帶來的增量，能否抵過非 AI 後段的循環，撐住目前約 41 倍的近 12 月本益比？
A4: 註：41 倍＝現價 ¥51,230 ÷ FY2025 EPS ¥1,249.84（上一個會計年度）；嚴格的近 12 月 EPS（含 FY2026 上半）為 1,474.98，對應 34.7 倍（Val 頁）。
A6: 驅動因子 → 推導量（因果方向：左邊決定右邊）
A7: 工作表｜輸入 → 推導量 → 去向
A8: Drv（PL 區塊 A）｜HBM 出貨位元（markets/memory，三情境）÷ 晶粒容量 → DRAM 晶粒數 ×（1＋每堆疊額外工序 ÷ 層數）→ HBM 研削／切割工序 → ×（1＋混合鍵合占比 × 淨影響）→ 產能需求 → 下一年增量＋汰換 → 新機需求 × kH（以 FY2025 AI 出貨校準）→ HBM 裝置營收
A9: Drv（PL 區塊 A）｜CoWoS 片數（台積電模型；B、C × SCEN_UNITS）→ 下一年增量＋汰換 → 新機需求 × kL（同一錨點校準）→ 先進封裝裝置營收
A10: PL｜非 AI 裝置 FY2025（裝置營收 − AI 出貨）×（1＋非 AI 年增，Analogy：公司 AI 前歷史）→ 非 AI 裝置營收；情境 B、C 只在 FY2028 不同
A11: PL｜消耗品＝AI 部分 × AI 工序量指數（稼動）＋非 AI 部分 ×（1＋年增）——消耗品隨稼動、不隨新機；その他＝固定比例 ×（裝置＋消耗品）
A12: Hist → PL｜毛利率＝a ＋ b × ln 營收、銷管費＝固定＋變動 × 營收（FY2015–FY2025 迴歸）→ 營業利益與營業利益率是結果，不寫死
A13: PL（D 節）｜FY2026 錨點：上半實績＋第三季指引（由公司累計指引推得 132.4／58.1／41.5）＋第四季（＝第三季 ×（1＋g_q4），g_q4 基準 10%，Assumed 0–22%）；各組成同比例縮放成錨點，FY2027 起 AI 兩項回到驅動推導、非 AI 兩項以錨定水準為基期
... A22: v0.1.3 變更（2026-10-23）：錨點差額（sc）延續到 FY2027 以後的非 AI 兩項時，三情境一律用情境 A 的 sc（具名範圍 sc_A）。B、C 的 sc 較大（1.078、1.099 vs A 1.055）是因為其 AI 驅動推導較低，不是非 AI 較強；原寫法把這部分算成非 AI、墊高 B、C 的基期。FY2026 不變（三情境仍各自縮放到同一錨點）；情境 A 不變；Sens 各案例皆為情境 A，用自己區塊的 sc（改 g_q4、m_q4 時隨之變動）。前後對照見 disco/README.md

Sheet In
A1: In — 輸入（藍字；基準欄 E，低 D、高 F）。金額：十億日圓（¥B）；HBM 位元：EB；CoWoS：千片。每個輸入附標記與來源；找不到者寫「未找到」，公司未揭露者寫「公司不揭露」
A2: 標記：Verified（公司文件、交易所資料）／Interested-party（寫明是誰、立場）／Analogy（寫明對照與差異）／Assumed（一律給低／高區間）／Derived（寫明換算）。SemiAnalysis 未使用。公司原文（disco.co.jp）以網頁擷取工具讀取文字（建置環境的 curl 被擋）；表格欄位錯置處以算術核對，原文版面待人工複核
A3: 鍵 | B3: 項目 | C3: 單位 | D3: 低 | E3: 基準 | F3: 高 | G3: 標記 | H3: 來源1 | I3: 來源2／說明
A4: A. FY2025 實績（2025-04～2026-03）與產品別構成（校準錨）
A5: a25_rev | B5: 營收 FY2025 | C5: ¥B | E5: 436.889 | G5: Verified | H5: 公司 2026年3月期 決算短信（2026-04-22，fr20260422.pdf）：436,889 百萬日圓 | I5: 松井證券 決算情報（finance.matsui.co.jp/stock/6146/settlement）：436,889；另見 kabuyoho 轉載之 TSE 決算短信 PDF（2026-04-22）
A6: a25_gp | B6: 毛利 FY2025 | C6: ¥B | E6: 306.477 | G6: Verified | H6: 公司 2026年3月期 決算短信（2026-04-22，fr20260422.pdf）：毛利 306,477（營收 − 銷貨成本 130,412） | I6: 公司 FY2025 4Q 決算說明資料（2026-04-22，film/20260422.pdf）：毛利 306.5、毛利率 70.1%
A7: a25_sga | B7: 銷管費 FY2025 | C7: ¥B | E7: 121.487 | G7: Verified | H7: 公司 2026年3月期 決算短信（2026-04-22，fr20260422.pdf）：121,487 | I7: 公司 FY2025 4Q 決算說明資料（2026-04-22，film/20260422.pdf）：121.5
A8: a25_oi | B8: 營業利益 FY2025 | C8: ¥B | E8: 184.989 | G8: Verified | H8: 公司 2026年3月期 決算短信（2026-04-22，fr20260422.pdf）：184,989 | I8: 松井證券 決算情報（finance.matsui.co.jp/stock/6146/settlement）：184,989
A9: a25_ni | B9: 淨利（歸屬母公司）FY2025 | C9: ¥B | E9: 135.521 | G9: Verified | H9: 公司 2026年3月期 決算短信（2026-04-22，fr20260422.pdf）：135,521 | I9: 松井證券 決算情報（finance.matsui.co.jp/stock/6146/settlement）：135,521
A10: a25_eps | B10: 基本 EPS FY2025 | C10: ¥ | E10: 1249.84 | G10: Verified | H10: 公司 2026年3月期 決算短信（2026-04-22，fr20260422.pdf）：基本 1,249.84（稀釋 1,245.90） | I10: 松井證券 決算情報（finance.matsui.co.jp/stock/6146/settlement）：1,249.84
A11: mix_eq | B11: 精密加工裝置占營收 FY2025 | C11: % | D11: 0.615 | E11: 0.62 | F11: 0.625 | G11: Verified | H11: 公司 FY2025 4Q 決算說明資料（2026-04-22，film/20260422.pdf）：製品別構成 精密加工裝置 62%（ダイサ 31%、グラインダ 28%、附屬裝置 3%）、精密加工ツール 21%、その他 16%（合計 99%，四捨五入） | I11: 公司只揭露構成比（百分比取整數），不揭露金額；低／高＝±0.5 個百分點（取整誤差）。FY2024：63%／21%／16%（film/20250417）
A12: mix_tl | B12: 精密加工ツール（消耗品：刀片、砂輪）占營收 FY2025 | C12: % | D12: 0.205 | E12: 0.21 | F12: 0.215 | G12: Verified | H12: 同上：21%（FY2024 21%、FY2023 22%） | I12: 同上；消耗品隨客戶稼動率變動（公司 FY26 Q1 說明：稼動率高，創新高）
A13: eq_25 | B13: 精密加工裝置營收 FY2025（營收 × 構成比） | C13: ¥B | E13: =a25_rev*mix_eq -> 270.87118 | G13: Derived | H13: 436.9 × 62%
A14: tl_25 | B14: 精密加工ツール營收 FY2025 | C14: ¥B | E14: =a25_rev*mix_tl -> 91.74669 | G14: Derived | H14: 436.9 × 21%
A15: ot_25 | B15: その他（零件、服務、二手機等）FY2025 | C15: ¥B | E15: =a25_rev-eq_25-tl_25 -> 74.27113 | G15: Derived | H15: 營收 − 裝置 − 消耗品（＝17%，含取整差） | I15: 公司構成比為 16%
A16: r_ot | B16: その他 ÷（裝置＋消耗品） | C16: x | E16: =ot_25/(eq_25+tl_25) -> 0.20481928 | G16: Derived | H16: FY2025 比例，各年沿用 | I16: FY2024 16/84＝0.19，相同
A17: B. AI 錨點（校準用；不使用共識營收或公司目標）
A18: ai_25 | B18: 生成 AI 相關出貨額 FY2025（2026年3月期） | C18: ¥B | D18: 67.5 | E18: 75 | F18: 82.5 | G18: Interested-party | H18: 樂天證券 今中能夫（2026-04-27，決算レポート；券商分析師，有正面撰寫傾向）：2026年3月期 約 750 億、2025年3月期 約 550 億（出貨額） | I18: 第二來源：未找到金額（公司不揭露 AI 金額）。低／高 ±10%＝「約」的不確定（Assumed）。出貨額視同營收：FY2025 出貨 442.6（四季合計，公司簡報）÷ 營收 436.9＝1.013（Derived）。是否含消耗品：原文不明，本模型視為裝置
A19: w_hbm | B19: AI 出貨中 HBM 比重 FY2025（其餘為邏輯／先進封裝） | C19: % | D19: 0.45 | E19: 0.48 | F19: 0.52 | G19: Interested-party | H19: 今中能夫（同上）：2025年3月期 概算 邏輯 3：HBM 7；2026年3月期 HBM 持平、邏輯大增，邏輯略高於 HBM → HBM 約 48%（Derived：38.5÷75≈51%，再依「邏輯略高」取 48%） | I19: 第二來源：公司 FY26 2Q 法說（BigGo 摘要，2026-10-22）：全年約 HBM 一半、邏輯一半。Interested-party（公司）
A20: ai_24 | B20: 生成 AI 相關出貨額 FY2024（只作參考，未用於校準） | C20: ¥B | E20: 55 | G20: Interested-party | H20: 今中能夫（同上）：約 550 億 | I20: 回測需 CY2024 的 HBM 位元與 CoWoS 片數，市場層沒有，未做（見 README 待辦）
A21: C. HBM 研削／切割需求（markets/memory，情境 A／B／C 各一列；唯讀）
A22: hsA_25 | B22: HBM 出貨位元 2025（EB；A） | C22: EB | E22: 2.2251147 | G22: Derived | H22: skhynix/dist/20261023_SK海力士模型_v0.4.1.xlsx｜Mkt!C24:G24 | I22: markets/memory v0.4（market.py @ 5fa3751）：出貨＝MIN(需求 × 情境顆數係數, 供給)；2028–29 隨情境，2025–27 三情境相同
A23: hsA_26 | B23: HBM 出貨位元 2026（EB；A） | C23: EB | E23: 3.782695 | G23: Derived | H23: skhynix/dist/20261023_SK海力士模型_v0.4.1.xlsx｜Mkt!C24:G24 | I23: 同上
A24: hsA_27 | B24: HBM 出貨位元 2027（EB；A） | C24: EB | E24: 5.8631772 | G24: Derived | H24: skhynix/dist/20261023_SK海力士模型_v0.4.1.xlsx｜Mkt!C24:G24 | I24: 同上
A25: hsA_28 | B25: HBM 出貨位元 2028（EB；A） | C25: EB | E25: 8.501607 | G25: Derived | H25: skhynix/dist/20261023_SK海力士模型_v0.4.1.xlsx｜Mkt!C24:G24 | I25: 同上
A26: hsA_29 | B26: HBM 出貨位元 2029（EB；A） | C26: EB | E26: 11.477169 | G26: Derived | H26: skhynix/dist/20261023_SK海力士模型_v0.4.1.xlsx｜Mkt!C24:G24 | I26: 同上
A27: hsB_25 | B27: HBM 出貨位元 2025（EB；B） | C27: EB | E27: 2.2251147 | G27: Derived | H27: skhynix/dist/20261023_SK海力士模型_v0.4.1.xlsx｜Mkt!C25:G25 | I27: markets/memory v0.4（market.py @ 5fa3751）：出貨＝MIN(需求 × 情境顆數係數, 供給)；2028–29 隨情境，2025–27 三情境相同
A28: hsB_26 | B28: HBM 出貨位元 2026（EB；B） | C28: EB | E28: 3.782695 | G28: Derived | H28: skhynix/dist/20261023_SK海力士模型_v0.4.1.xlsx｜Mkt!C25:G25 | I28: 同上
A29: hsB_27 | B29: HBM 出貨位元 2027（EB；B） | C29: EB | E29: 5.8631772 | G29: Derived | H29: skhynix/dist/20261023_SK海力士模型_v0.4.1.xlsx｜Mkt!C25:G25 | I29: 同上
A30: hsB_28 | B30: HBM 出貨位元 2028（EB；B） | C30: EB | E30: 8.22296 | G30: Derived | H30: skhynix/dist/20261023_SK海力士模型_v0.4.1.xlsx｜Mkt!C25:G25 | I30: 同上
A31: hsB_29 | B31: HBM 出貨位元 2029（EB；B） | C31: EB | E31: 11.357964 | G31: Derived | H31: skhynix/dist/20261023_SK海力士模型_v0.4.1.xlsx｜Mkt!C25:G25 | I31: 同上
A32: hsC_25 | B32: HBM 出貨位元 2025（EB；C） | C32: EB | E32: 2.2251147 | G32: Derived | H32: skhynix/dist/20261023_SK海力士模型_v0.4.1.xlsx｜Mkt!C26:G26 | I32: markets/memory v0.4（market.py @ 5fa3751）：出貨＝MIN(需求 × 情境顆數係數, 供給)；2028–29 隨情境，2025–27 三情境相同
A33: hsC_26 | B33: HBM 出貨位元 2026（EB；C） | C33: EB | E33: 3.782695 | G33: Derived | H33: skhynix/dist/20261023_SK海力士模型_v0.4.1.xlsx｜Mkt!C26:G26 | I33: 同上
... A36: hsC_29 | B36: HBM 出貨位元 2029（EB；C） | C36: EB | E36: 8.017386 | G36: Derived | H36: skhynix/dist/20261023_SK海力士模型_v0.4.1.xlsx｜Mkt!C26:G26 | I36: 同上
A37: den_25 | B37: DRAM 核心晶粒容量（組合平均）2025 | C37: Gb／顆 | D37: 22 | E37: 24 | F37: 24 | G37: Assumed | H37: JEDEC HBM4（JESD270-4）：24Gb 或 32Gb 晶粒（TrendForce 2025-04-28）；HBM3E 以 24Gb 為主 | I37: 組合比例未找到；容量愈大，同樣位元需要的晶粒（研削＋切割次數）愈少
A38: den_26 | B38: DRAM 核心晶粒容量（組合平均）2026 | C38: Gb／顆 | D38: 24 | E38: 24 | F38: 26 | G38: Assumed | H38: JEDEC HBM4（JESD270-4）：24Gb 或 32Gb 晶粒（TrendForce 2025-04-28）；HBM3E 以 24Gb 為主 | I38: 同上
A39: den_27 | B39: DRAM 核心晶粒容量（組合平均）2027 | C39: Gb／顆 | D39: 24 | E39: 26 | F39: 28 | G39: Assumed | H39: JEDEC HBM4（JESD270-4）：24Gb 或 32Gb 晶粒（TrendForce 2025-04-28）；HBM3E 以 24Gb 為主 | I39: 同上
A40: den_28 | B40: DRAM 核心晶粒容量（組合平均）2028 | C40: Gb／顆 | D40: 24 | E40: 28 | F40: 32 | G40: Assumed | H40: JEDEC HBM4（JESD270-4）：24Gb 或 32Gb 晶粒（TrendForce 2025-04-28）；HBM3E 以 24Gb 為主 | I40: 同上
A41: den_29 | B41: DRAM 核心晶粒容量（組合平均）2029 | C41: Gb／顆 | D41: 26 | E41: 30 | F41: 32 | G41: Assumed | H41: JEDEC HBM4（JESD270-4）：24Gb 或 32Gb 晶粒（TrendForce 2025-04-28）；HBM3E 以 24Gb 為主 | I41: 同上
A42: den_30 | B42: DRAM 核心晶粒容量（組合平均）2030 | C42: Gb／顆 | D42: 28 | E42: 32 | F42: 32 | G42: Assumed | H42: JEDEC HBM4（JESD270-4）：24Gb 或 32Gb 晶粒（TrendForce 2025-04-28）；HBM3E 以 24Gb 為主 | I42: 同上
...

Sheet Q
A1: Q — 季度實績（十億日圓；EPS 為日圓）。會計年度 4–3 月。來源1：公司決算說明資料（film/20260422、20261022）與決算短信；來源2：松井證券季度表（百萬日圓）
A3: 項目 | B3: FY25 Q1 | C3: FY25 Q2 | D3: FY25 Q3 | E3: FY25 Q4 | F3: FY2025 | G3: FY26 Q1 | H3: FY26 Q2 | I3: FY26 Q3（公司指引） | J3: 標記 | K3: 來源1 | L3: 來源2／說明
A4: 營收 | B4: =a25_rev-C4-D4-E4 -> 89.914 | C4: 104.623 | D4: 109.291 | E4: 133.061 | F4: =SUM(B4:E4) -> 436.889 | G4: 114.308 | H4: 142.75 | I4: =g3_rev -> 132.442 | J4: Verified／Interested-party（指引） | K4: 公司說明資料：89.9／104.6／109.3／133.1；FY26 114.3／142.8；3Q 指引 132.4 | L4: 松井：104,623／109,291／133,061；FY26 114,308／142,750（Q1 FY25 由全年減其他三季）
A5: 營業利益 | B5: =a25_oi-C5-D5-E5 -> 34.48 | C5: 44.391 | D5: 47.341 | E5: 58.777 | F5: =SUM(B5:E5) -> 184.989 | G5: 49.033 | H5: 67.606 | I5: =g3_oi -> 58.061 | J5: Verified／Interested-party（指引） | K5: 公司說明資料：34.5／44.4／47.3／58.8；FY26 49.0／67.6；3Q 58.1 | L5: 松井：44,391／47,341／58,777；49,033／67,606
A6: 淨利 | B6: =a25_ni-C6-D6-E6 -> 23.767 | C6: 32.146 | D6: 36.726 | E6: 42.882 | F6: =SUM(B6:E6) -> 135.521 | G6: 34.221 | H6: 46.145 | I6: =g9_ni-q26h1_ni -> 41.534 | J6: Verified／Interested-party（指引） | K6: 公司說明資料：23.8／32.1／36.7／42.9；FY26 34.2／46.1；3Q 41.5 | L6: 松井：32,146／36,726／42,882；34,221／46,145
A7: EPS（基本） | B7: =a25_eps-C7-D7-E7 -> 219.14 | C7: 296.49 | D7: 338.73 | E7: 395.48 | F7: =SUM(B7:E7) -> 1249.84 | G7: 315.51 | H7: 425.38 | I7: =1123.43-q26h1_eps -> 382.59 | J7: Verified／Interested-party（指引） | K7: 公司決算短信：FY26 Q1 315.51、上半 740.84；9 個月指引 1,123.43 | L7: 松井：296.49／338.73／395.48；315.51／425.38
A8: 出貨額 | B8: 111.1 | C8: 96.3 | D8: 113.6 | E8: 121.6 | F8: =SUM(B8:E8) -> 442.6 | G8: 135.9 | H8: 148.6 | I8: 149.6 | J8: Verified／Interested-party（指引） | K8: 公司說明資料 | L8: Investing.com（2026-10-22）：Q2 148.6、Q3 指引 149.6
A9: 營業利益率 | B9: =B5/B4 -> 0.38347755 | C9: =C5/C4 -> 0.42429485 | D9: =D5/D4 -> 0.43316467 | E9: =E5/E4 -> 0.44172973 | F9: =F5/F4 -> 0.42342334 | G9: =G5/G4 -> 0.4289551 | H9: =H5/H4 -> 0.4735972 | I9: =I5/I4 -> 0.43838812
A10: 毛利率（公司說明資料；FY25 Q1、Q3 未列單季毛利額） | C10: 0.695 | E10: 0.709 | F10: =a25_gp/a25_rev -> 0.70149855 | G10: 0.713 | H10: 0.717 | L10: FY25 Q3 71.4%（4Q 資料的前季對照）；3Q 指引：比 Q2 低約 2 個百分點（法說摘要）
A11: 檢查：FY2026 上半（G+H）− 決算短信上半（營收、營業利益、淨利；應約為 0） | B11: =G4+H4-q26h1_rev -> 0 | C11: =G5+H5-q26h1_oi -> 0 | D11: =G6+H6-q26h1_ni -> 0
A13: 製品別構成比（公司說明資料；出貨或營收基準，百分比取整）
A14: 製品 | B14: FY2023 | C14: FY2024 | D14: FY2025 | E14: FY26 Q2 | J14: 標記 | K14: 來源
A15: 精密加工裝置 | B15: 0.64 | C15: 0.63 | D15: 0.62 | E15: 0.63 | J15: Verified | K15: film/20240425、20250417、20260422、20261022
A16: ダイサ | B16: 0.32 | C16: 0.33 | D16: 0.31 | E16: 0.33 | J16: Verified | K16: film/20240425、20250417、20260422、20261022
A17: グラインダ | B17: 0.28 | C17: 0.27 | D17: 0.28 | E17: 0.26 | J17: Verified | K17: film/20240425、20250417、20260422、20261022
A18: 精密加工ツール（消耗品） | B18: 0.22 | C18: 0.21 | D18: 0.21 | E18: 0.23 | J18: Verified | K18: film/20240425、20250417、20260422、20261022
A19: その他 | B19: 0.14 | C19: 0.16 | D19: 0.16 | E19: 0.14 | J19: Verified | K19: film/20240425、20250417、20260422、20261022
A21: 公司揭露的季度結構（法說摘要，BigGo 2026-07-23／10-22；Interested-party）：記憶體占營收 FY26 Q1 35%、Q2 略低於 40%、Q3 預估約 30%；OSAT 占 FY26 Q1 35%；功率半導體不到一成；FY26 Q2 切割機用途 IC 73%、研削機用途 IC 77%

Sheet Hist
A1: Hist — 年度實績（十億日圓；EPS 為日圓）。來源1：公司各年決算短信（英文版 fr*.pdf，以網頁擷取讀取）；來源2：松井證券（FY2021 起）。用途：利潤率迴歸（In 頁 H 節）、非 AI 成長的 Analogy、10 年 P/E 的 EPS
A2: 股票分割：2023-04-01 一股分三股（公司 FY2022 決算短信註記；tousaiblog 第二來源）。FY2021（2022年3月期）起的 EPS 已在公司文件中依分割調整；FY2020 以前除以 3
A5: 會計年度 | B5: 營收 | C5: 毛利 | D5: 銷管費 | E5: 營業利益 | F5: 淨利 | G5: EPS（公司公布，日圓） | H5: 毛利率 | I5: ln 營收 | J5: 分割係數 | K5: EPS（分割調整後） | L5: 來源1（公司） | M5: 來源2
A6: FY2015（2016-03） | B6: 127.85 | C6: 72.298 | D6: 41.959 | E6: 30.338 | F6: 23.096 | G6: 646.09 | H6: =C6/B6 -> 0.56549081 | I6: =LN(B6) -> 4.8508577 | J6: 3 | K6: =G6/J6 -> 215.36333 | L6: fr20170510.pdf | M6: 未找到（松井只到 FY2021）
A7: FY2016（2017-03） | B7: 134.204 | C7: 74.495 | D7: 43.153 | E7: 31.341 | F7: 24.203 | G7: 675.82 | H7: =C7/B7 -> 0.55508778 | I7: =LN(B7) -> 4.899361 | J7: 3 | K7: =G7/J7 -> 225.27333 | L7: fr20170510.pdf（說明文字寫 134,240／24,230，取財務表數字） | M7: 未找到
A8: FY2017（2018-03） | B8: 167.364 | C8: 99.125 | D8: 48.13 | E8: 50.995 | F8: 37.171 | G8: 1035.67 | H8: =C8/B8 -> 0.59227193 | I8: =LN(B8) -> 5.1201711 | J8: 3 | K8: =G8/J8 -> 345.22333 | L8: fr20190508.pdf | M8: 未找到
A9: FY2018（2019-03） | B9: 147.5 | C9: 86.91 | D9: 48.264 | E9: 38.645 | F9: 28.824 | G9: 802.35 | H9: =C9/B9 -> 0.58922034 | I9: =LN(B9) -> 4.9938282 | J9: 3 | K9: =G9/J9 -> 267.45 | L9: fr20190508.pdf | M9: 未找到
A10: FY2019（2020-03） | B10: 141.083 | C10: 84.792 | D10: 48.341 | E10: 36.451 | F10: 27.653 | G10: 769.56 | H10: =C10/B10 -> 0.60100792 | I10: =LN(B10) -> 4.9493484 | J10: 3 | K10: =G10/J10 -> 256.52 | L10: fr20210422.pdf | M10: 未找到
A11: FY2020（2021-03） | B11: 182.857 | C11: 106.883 | D11: 53.776 | E11: 53.106 | F11: 39.091 | G11: 1085.47 | H11: =C11/B11 -> 0.58451686 | I11: =LN(B11) -> 5.2087044 | J11: 3 | K11: =G11/J11 -> 361.82333 | L11: fr20210422.pdf（說明文字營業利益 53,160，取表內 53,106） | M11: 未找到
A12: FY2021（2022-03） | B12: 253.781 | C12: 154.011 | D12: 62.498 | E12: 91.513 | F12: 66.206 | G12: 611.67 | H12: =C12/B12 -> 0.60686576 | I12: =LN(B12) -> 5.5364717 | J12: 1 | K12: =G12/J12 -> 611.67 | L12: fr20230420.pdf（分割調整後 EPS） | M12: 松井證券 決算情報（finance.matsui.co.jp/stock/6146/settlement）
A13: FY2022（2023-03） | B13: 284.135 | C13: 184.506 | D13: 74.093 | E13: 110.413 | F13: 82.891 | G13: 765.47 | H13: =C13/B13 -> 0.64936034 | I13: =LN(B13) -> 5.6494495 | J13: 1 | K13: =G13/J13 -> 765.47 | L13: fr20230420.pdf | M13: 松井證券 決算情報（finance.matsui.co.jp/stock/6146/settlement）
A14: FY2023（2024-03） | B14: 307.554 | C14: 208.642 | D14: 87.151 | E14: 121.49 | F14: 84.205 | G14: 777.29 | H14: =C14/B14 -> 0.67839144 | I14: =LN(B14) -> 5.7286507 | J14: 1 | K14: =G14/J14 -> 777.29 | L14: fr20250417.pdf | M14: 松井證券 決算情報（finance.matsui.co.jp/stock/6146/settlement）
A15: FY2024（2025-03） | B15: 393.313 | C15: 277.57 | D15: 110.736 | E15: 166.834 | F15: 123.891 | G15: 1143.26 | H15: =C15/B15 -> 0.70572292 | I15: =LN(B15) -> 5.9746057 | J15: 1 | K15: =G15/J15 -> 1143.26 | L15: fr20250417.pdf | M15: 松井證券 決算情報（finance.matsui.co.jp/stock/6146/settlement）
A16: FY2025（2026-03） | B16: 436.889 | C16: 306.477 | D16: 121.487 | E16: 184.989 | F16: 135.521 | G16: 1249.84 | H16: =C16/B16 -> 0.70149855 | I16: =LN(B16) -> 6.0796792 | J16: 1 | K16: =G16/J16 -> 1249.84 | L16: fr20260422.pdf | M16: 松井證券 決算情報（finance.matsui.co.jp/stock/6146/settlement）
A18: 檢查：FY2025 毛利 − 銷管費 − 營業利益（應為 0） | B18: =C16-D16-E16 -> 0.001
A19: 檢查：FY2025 列 − In 頁 a25_*（應為 0） | B19: =ABS(B16-a25_rev)+ABS(C16-a25_gp)+ABS(E16-a25_oi)+ABS(F16-a25_ni)+ABS(G16-a25_eps) -> 0
A21: 非 AI 成長的 Analogy
A22: 營收年複合 FY2015→FY2022（AI 前，含中國與功率熱潮） | B22: =(B13/B6)^(1/7)-1 -> 0.12084688
A23: 營收年複合 FY2016→FY2019（一個循環） | B23: =(B10/B7)^(1/3)-1 -> 0.016802039
A24: 最大單年下滑 FY2018（2019-03） | B24: =B9/B8-1 -> -0.11868741
A26: 迴歸結果（In 頁同值）
A27: 毛利率 ＝ a ＋ b × ln 營收：a | B27: =gm_a -> 0.010428454
A28: b | B28: =gm_b -> 0.11382596
A29: R² | B29: =RSQ(H6:H16,I6:I16) -> 0.89559667
A30: 銷管費 ＝ 固定 ＋ 變動 × 營收：固定 ¥B | B30: =sg_f -> 8.1233423
A31: 變動 | B31: =sg_v -> 0.25236703
A32: R² | B32: =RSQ(D6:D16,B6:B16) -> 0.97582671
A33: FY2025 毛利率：迴歸值 − 實績 | B33: =gm_a+gm_b*I16-H16 -> 0.00095521405
A34: FY2025 銷管費：迴歸值 − 實績（¥B） | B34: =sg_f+sg_v*B16-D16 -> -3.1072765

Sheet PL
A1: PL — Disco 損益（¥B；FY2025 實績；FY2026 錨定公司資料（上半實績＋第三季指引＋第四季假設）；FY2027–FY2029 驅動推導）。頂端為摘要，下方為三情境各一個完整推導區塊
A3: 情境／項目 | B3: 單位 | C3: FY2025A | D3: FY2026 | E3: FY2027 | F3: FY2028 | G3: FY2029 | H3: 說明
A4: 情境 A
A5: 營收 | B5: ¥B | C5: =C114 -> 436.889 | D5: =D114 -> 535.1862 | E5: =E114 -> 558.96445 | F5: =F114 -> 591.32139 | G5: =G114 -> 606.51558
A6: HBM 裝置 | B6: ¥B | C6: =C105 -> 36 | D6: =D105 -> 43.952387 | E6: =E105 -> 47.854941 | F6: =F105 -> 44.842416 | G6: =G105 -> 27.254861
A7: 先進封裝裝置 | B7: ¥B | C7: =C106 -> 39 | D7: =D106 -> 63.453886 | E7: =E106 -> 42.599118 | F7: =F106 -> 38.320722 | G7: =G106 -> 36.866396
A8: 非 AI 裝置 | B8: ¥B | C8: =C108 -> 195.87118 | D8: =D108 -> 219.03365 | E8: =E108 -> 232.17567 | F8: =F108 -> 246.10621 | G8: =G108 -> 260.87259
A9: 消耗品 | B9: ¥B | C9: =C112 -> 91.74669 | D9: =D112 -> 117.76462 | E9: =E112 -> 141.31077 | F9: =F112 -> 161.5274 | G9: =G112 -> 178.41408
A10: その他 | B10: ¥B | C10: =C113 -> 74.27113 | D10: =D113 -> 90.981654 | E10: =E113 -> 95.023957 | F10: =F113 -> 100.52464 | G10: =G113 -> 103.10765
A11: AI 占營收（含 AI 消耗品） | B11: % | C11: =C115 -> 0.27688438 | D11: =D115 -> 0.34146874 | E11: =E115 -> 0.33323552 | F11: =F115 -> 0.33347613 | G11: =G115 -> 0.3127935
A12: AI 裝置占營收 | B12: % | C12: =C116 -> 0.2068293 | D12: =D116 -> 0.24179463 | E12: =E116 -> 0.19496909 | F12: =F116 -> 0.16944517 | G12: =G116 -> 0.12737435
A13: 毛利率 | B13: % | C13: =C117 -> 0.70149855 | D13: =D117 -> 0.70639057 | E13: =E117 -> 0.73050125 | F13: =F117 -> 0.73690666 | G13: =G117 -> 0.73979451
A14: 營業利益 | B14: ¥B | C14: =C120 -> 184.99 | D14: =D120 -> 238.5671 | E14: =E120 -> 259.13669 | F14: =F120 -> 278.39531 | G14: =G120 -> 287.50901
A15: 營業利益率 | B15: % | C15: =C121 -> 0.42342563 | D15: =D121 -> 0.44576467 | E15: =E121 -> 0.46360137 | F15: =F121 -> 0.47080202 | G15: =G121 -> 0.47403402
A16: 淨利 | B16: ¥B | C16: =C122 -> 135.521 | D16: =D122 -> 167.95938 | E16: =E122 -> 186.883 | F16: =F122 -> 200.77185 | G16: =G122 -> 207.34443
A17: EPS | B17: ¥ | C17: =C123 -> 1249.84 | D17: =D123 -> 1548.2856 | E17: =E123 -> 1722.7276 | F17: =F123 -> 1850.7579 | G17: =G123 -> 1911.3454
A18: 對照：營收（只用 v0.1 驅動） | B18: ¥B | C18: =C95 -> 436.889 | D18: =D95 -> 507.30654 | E18: =E95 -> 539.54937 | F18: =F95 -> 570.78984 | G18: =G95 -> 584.80298
A19: 對照：營業利益（只用 v0.1 驅動） | B19: ¥B | C19: =C127 -> 184.989 | D19: =D127 -> 228.83775 | E19: =E127 -> 247.68256 | F19: =F127 -> 266.15098 | G19: =G127 -> 274.49902
A20: 對照：EPS（v0.1 驅動、淨利÷營業利益 0.733） | B20: ¥ | C20: =C128 -> 1249.84 | D20: =D128 -> 1545.3795 | E20: =E128 -> 1672.6417 | F20: =F128 -> 1797.362 | G20: =G128 -> 1853.7377
A22: 情境 B
A23: 營收 | B23: ¥B | C23: =C175 -> 436.889 | D23: =D175 -> 535.1862 | E23: =E175 -> 524.5059 | F23: =F175 -> 564.63248 | G23: =G175 -> 571.74834
A24: HBM 裝置 | B24: ¥B | C24: =C166 -> 36 | D24: =D166 -> 43.631559 | E24: =E166 -> 44.88606 | F24: =F166 -> 46.568287 | G24: =G166 -> 26.971782
A25: 先進封裝裝置 | B25: ¥B | C25: =C167 -> 39 | D25: =D167 -> 56.417525 | E25: =E167 -> 19.452651 | F25: =F167 -> 37.850021 | G25: =G167 -> 31.336436
A26: 非 AI 裝置 | B26: ¥B | C26: =C169 -> 195.87118 | D26: =D169 -> 223.81833 | E26: =E169 -> 232.17567 | F26: =F169 -> 232.17567 | G26: =G169 -> 246.10621
A27: 消耗品 | B27: ¥B | C27: =C173 -> 91.74669 | D27: =D173 -> 120.33713 | E27: =E173 -> 138.82551 | F27: =F173 -> 152.05098 | G27: =G173 -> 170.13669
A28: その他 | B28: ¥B | C28: =C174 -> 74.27113 | D28: =D174 -> 90.981654 | E28: =E174 -> 89.166003 | F28: =F174 -> 95.987522 | G28: =G174 -> 97.197217
A29: AI 占營收（含 AI 消耗品） | B29: % | C29: =C176 -> 0.27688438 | D29: =D176 -> 0.32708346 | E29: =E176 -> 0.28943098 | F29: =F176 -> 0.33169619 | G29: =G176 -> 0.30212191
A30: AI 裝置占營收 | B30: % | C30: =C177 -> 0.2068293 | D30: =D177 -> 0.22523201 | E30: =E177 -> 0.1477896 | F30: =F177 -> 0.18013275 | G30: =G177 -> 0.12287026
A31: 毛利率 | B31: % | C31: =C178 -> 0.70149855 | D31: =D178 -> 0.70639057 | E31: =E178 -> 0.72325859 | F31: =F178 -> 0.73164965 | G31: =G178 -> 0.7330752
A32: 營業利益 | B32: ¥B | C32: =C181 -> 184.99 | D32: =D181 -> 238.5671 | E32: =E181 -> 238.86206 | F32: =F181 -> 262.49519 | G32: =G181 -> 266.72075
A33: 營業利益率 | B33: % | C33: =C182 -> 0.42342563 | D33: =D182 -> 0.44576467 | E33: =E182 -> 0.45540395 | F33: =F182 -> 0.46489567 | G33: =G182 -> 0.46650026
A34: 淨利 | B34: ¥B | C34: =C183 -> 135.521 | D34: =D183 -> 167.95938 | E34: =E183 -> 172.26144 | F34: =F183 -> 189.30508 | G34: =G183 -> 192.35244
A35: EPS | B35: ¥ | C35: =C184 -> 1249.84 | D35: =D184 -> 1548.2856 | E35: =E184 -> 1587.9429 | F35: =F184 -> 1745.0547 | G35: =G184 -> 1773.146
A36: 對照：營收（只用 v0.1 驅動） | B36: ¥B | C36: =C156 -> 436.889 | D36: =D156 -> 496.46159 | E36: =E156 -> 505.09082 | F36: =F156 -> 544.97525 | G36: =G156 -> 550.96252
A37: 對照：營業利益（只用 v0.1 驅動） | B37: ¥B | C37: =C188 -> 184.989 | D37: =D188 -> 222.55096 | E37: =E188 -> 227.55114 | F37: =F188 -> 250.87573 | G37: =G188 -> 254.40641
A38: 對照：EPS（v0.1 驅動、淨利÷營業利益 0.733） | B38: ¥ | C38: =C189 -> 1249.84 | D38: =D189 -> 1502.9238 | E38: =E189 -> 1536.6908 | F38: =F189 -> 1694.2057 | G38: =G189 -> 1718.049
A40: 情境 C
A41: 營收 | B41: ¥B | C41: =C236 -> 436.889 | D41: =D236 -> 535.1862 | E41: =E236 -> 480.07397 | F41: =F236 -> 464.47517 | G41: =G236 -> 480.48069
A42: HBM 裝置 | B42: ¥B | C42: =C227 -> 36 | D42: =D227 -> 35.997335 | E42: =E227 -> 16.386735 | F42: =F227 -> 28.694761 | G42: =G227 -> 19.038905
A43: 先進封裝裝置 | B43: ¥B | C43: =C228 -> 39 | D43: =D228 -> 57.492745 | E43: =E228 -> 15.249439 | F43: =F228 -> 22.992433 | G43: =G228 -> 22.119837
...

Sheet Val
A1: Val — P/E 估值。跨公司規則：合理倍數＝10 年（2016–2025 年底）P/E 的分位，依循環位置：見頂年 25 分位、中段中位數、谷底 75 分位
A2: P/E 定義（自算）：日曆年底收盤價 ÷ 「當期會計年度」公司公布的基本 EPS（例：2025-12 對 FY2025＝2026年3月期）。價格與 EPS 皆以 2023-04-01 一股分三股調整
A4: 1. 10 年 P/E（年底）
A5: 年底 | B5: 收盤價（未調整） | C5: 分割係數 | D5: 收盤價（調整後） | E5: 來源2：Yahoo Finance 調整後收盤 | F5: 兩者差距 | G5: 當期 FY EPS（調整後） | H5: P/E 當期 | I5: 標記 | J5: 說明
A6: 2016-12（2016-12-30） | B6: 14160 | C6: 3 | D6: =B6/C6 -> 4720 | E6: 4720 | F6: =D6/E6-1 -> 0 | G6: =Hist!K7 -> 225.27333 | H6: =D6/G6 -> 20.952325 | I6: Verified | J6: 來源1：Yahoo!ファイナンス 時系列（終值與調整後終值）；EPS：Hist 頁（公司決算短信）
A7: 2017-12（2017-12-29） | B7: 25070 | C7: 3 | D7: =B7/C7 -> 8356.6667 | E7: 8356.67 | F7: =D7/E7-1 -> -3.9888297e-07 | G7: =Hist!K8 -> 345.22333 | H7: =D7/G7 -> 24.206552 | I7: Verified
A8: 2018-12（2018-12-28） | B8: 12850 | C8: 3 | D8: =B8/C8 -> 4283.3333 | E8: 4283.33 | F8: =D8/E8-1 -> 7.7821072e-07 | G8: =Hist!K9 -> 267.45 | H8: =D8/G8 -> 16.015455 | I8: Verified
A9: 2019-12（2019-12-30） | B9: 25900 | C9: 3 | D9: =B9/C9 -> 8633.3333 | E9: 8633.33 | F9: =D9/E9-1 -> 3.8610054e-07 | G9: =Hist!K10 -> 256.52 | H9: =D9/G9 -> 33.655595 | I9: Verified
A10: 2020-12（2020-12-30） | B10: 34750 | C10: 3 | D10: =B10/C10 -> 11583.333 | E10: 11583.33 | F10: =D10/E10-1 -> 2.8776987e-07 | G10: =Hist!K11 -> 361.82333 | H10: =D10/G10 -> 32.013782 | I10: Verified
A11: 2021-12（2021-12-30） | B11: 35150 | C11: 3 | D11: =B11/C11 -> 11716.667 | E11: 11716.67 | F11: =D11/E11-1 -> -2.8449494e-07 | G11: =Hist!K12 -> 611.67 | H11: =D11/G11 -> 19.155209 | I11: Verified
A12: 2022-12（2022-12-30） | B12: 37750 | C12: 3 | D12: =B12/C12 -> 12583.333 | E12: 12583.33 | F12: =D12/E12-1 -> 2.6490073e-07 | G12: =Hist!K13 -> 765.47 | H12: =D12/G12 -> 16.438702 | I12: Verified
A13: 2023-12（2023-12-29） | B13: 34980 | C13: 1 | D13: =B13/C13 -> 34980 | E13: 34980 | F13: =D13/E13-1 -> 0 | G13: =Hist!K14 -> 777.29 | H13: =D13/G13 -> 45.002509 | I13: Verified | J13: 2023 年 P/E 偏高：FY2023 EPS 僅成長 1.5%，股價先反映 AI
A14: 2024-12（2024-12-30） | B14: 42730 | C14: 1 | D14: =B14/C14 -> 42730 | E14: 42730 | F14: =D14/E14-1 -> 0 | G14: =Hist!K15 -> 1143.26 | H14: =D14/G14 -> 37.375575 | I14: Verified
A15: 2025-12（2025-12-30） | B15: 48170 | C15: 1 | D15: =B15/C15 -> 48170 | E15: 48170 | F15: =D15/E15-1 -> 0 | G15: =Hist!K16 -> 1249.84 | H15: =D15/G15 -> 38.540933 | I15: Verified
A17: 兩個價格來源可能共用同一資料商（不完全獨立）；10 年都有價格，無缺年。
A19: 2. 分位（10 年）
A20: 統計 | B20: P/E 當期 | C20: 用途
A21: 25 分位 | B21: =PERCENTILE(H6:H15,0.25) -> 19.604488 | C21: 見頂年
A22: 中位數 | B22: =PERCENTILE(H6:H15,0.5) -> 28.110167 | C22: 中段
A23: 75 分位 | B23: =PERCENTILE(H6:H15,0.75) -> 36.44558 | C23: 谷底
A24: 年數 | B24: =COUNT(H6:H15) -> 10
A25: 敏感度：去掉 2023 年（極端值）時 25／50／75 分位 | B25: =PERCENTILE((H6:H12~H14:H15),0.25) -> 19.155209 | C25: =PERCENTILE((H6:H12~H14:H15),0.5) -> 24.206552 | D25: =PERCENTILE((H6:H12~H14:H15),0.75) -> 33.655595
A27: 3. FY2027 的循環位置（設備股共用規則；見頂年度讀設備市場模型，不在本模型另訂）
A28: 循環位置（設備股共用規則）：各情境的見頂年度取自設備市場模型（markets/equipment 的 Mkt 頁「見頂年度」：A 2029、B 2028、C 2027）；會計年度 FY(t) 對照日曆年 t（FY(t) 有 3/4 落在 t 年）：t 早於見頂年＝中段（中位數）、等於＝見頂（25 分位）、晚於＝谷底（75 分位）
A29: 情境 | B29: 設備市場見頂年度 | C29: FY2027 對照日曆年 | D29: 判定 | E29: 倍數 | F29: v0.1 判定（營業利益路徑，對照） | G29: v0.1 倍數
A30: A | B30: =pk_A -> 2029 | C30: 2027 | D30: =IF(C30<pk_A,"中段",IF(C30=pk_A,"見頂","谷底")) -> 中段 | E30: =IF(D30="見頂",pe_peak,IF(D30="谷底",pe_trough,pe_mid)) -> 28.110167 | F30: 中段 | G30: =pe_mid -> 28.110167
A31: B | B31: =pk_B -> 2028 | C31: 2027 | D31: =IF(C31<pk_B,"中段",IF(C31=pk_B,"見頂","谷底")) -> 中段 | E31: =IF(D31="見頂",pe_peak,IF(D31="谷底",pe_trough,pe_mid)) -> 28.110167 | F31: 中段 | G31: =pe_mid -> 28.110167
A32: C | B32: =pk_C -> 2027 | C32: 2027 | D32: =IF(C32<pk_C,"中段",IF(C32=pk_C,"見頂","谷底")) -> 見頂 | E32: =IF(D32="見頂",pe_peak,IF(D32="谷底",pe_trough,pe_mid)) -> 19.604488 | F32: 中段 | G32: =pe_mid -> 28.110167
A33: 4. 隱含股價（FY2027 EPS × 依判定的倍數；其餘倍數僅供參考）
A34: 情境 | B34: EPS 年度 | C34: EPS | D34: 倍數類型 | E34: 倍數 | F34: 隱含股價 | G34: 相對現價 | H34: 備註
A35: A | B35: FY2027 | C35: =PL!E17 -> 1722.7276 | D35: ="規則值："&D30 -> 規則值：中段 | E35: =E30 -> 28.110167 | F35: =C35*E35 -> 48426.16 | G35: =F35/px-1 -> -0.054730436
A36: A | B36: FY2027 | C36: =PL!E17 -> 1722.7276 | D36: 參考：25 分位 | E36: =pe_peak -> 19.604488 | F36: =C36*E36 -> 33773.192 | G36: =F36/px-1 -> -0.34075363
A37: A | B37: FY2027 | C37: =PL!E17 -> 1722.7276 | D37: 參考：中位數 | E37: =pe_mid -> 28.110167 | F37: =C37*E37 -> 48426.16 | G37: =F37/px-1 -> -0.054730436
A38: A | B38: FY2027 | C38: =PL!E17 -> 1722.7276 | D38: 參考：75 分位 | E38: =pe_trough -> 36.44558 | F38: =C38*E38 -> 62785.806 | G38: =F38/px-1 -> 0.22556716
A39: A | B39: FY2028 | C39: =PL!F17 -> 1850.7579 | D39: 參考：FY2028 × 中位數 | E39: =pe_mid -> 28.110167 | F39: =C39*E39 -> 52025.114 | G39: =F39/px-1 -> 0.015520467
A40: B | B40: FY2027 | C40: =PL!E35 -> 1587.9429 | D40: ="規則值："&D31 -> 規則值：中段 | E40: =E31 -> 28.110167 | F40: =C40*E40 -> 44637.339 | G40: =F40/px-1 -> -0.1286875
A41: B | B41: FY2027 | C41: =PL!E35 -> 1587.9429 | D41: 參考：25 分位 | E41: =pe_peak -> 19.604488 | F41: =C41*E41 -> 31130.806 | G41: =F41/px-1 -> -0.39233249
A42: B | B42: FY2027 | C42: =PL!E35 -> 1587.9429 | D42: 參考：中位數 | E42: =pe_mid -> 28.110167 | F42: =C42*E42 -> 44637.339 | G42: =F42/px-1 -> -0.1286875
A43: B | B43: FY2027 | C43: =PL!E35 -> 1587.9429 | D43: 參考：75 分位 | E43: =pe_trough -> 36.44558 | F43: =C43*E43 -> 57873.499 | G43: =F43/px-1 -> 0.12967985
A44: B | B44: FY2028 | C44: =PL!F35 -> 1745.0547 | D44: 參考：FY2028 × 中位數 | E44: =pe_mid -> 28.110167 | F44: =C44*E44 -> 49053.781 | G44: =F44/px-1 -> -0.042479393
...

Sheet Recon
A1: Recon — FY2026 錨定公司資料（上半實績＋第三季指引＋第四季假設），A 節為恆等式；A2 節列只用 v0.1 驅動的結果；B 節共識只作參考，未用於校準或錨點。差距＝模型 ÷ 對照 − 1
A3: 項目 | B3: 對照值 | C3: 模型 A | D3: 差距 A | E3: 模型 B | F3: 差距 B | G3: 模型 C | H3: 差距 C | I3: 對照來源 | J3: 說明
A4: A. FY2026 錨點（公司資料）：模型＝錨點，差距為 0 是恆等式，不是獨立檢驗
A5: FY2026 營收 vs 上半實績＋第三季指引＋第四季（Q3 × 1.10） | B5: =q26h1_rev+g3_rev+g3_rev*(1+g_q4) -> 535.1862 | C5: =PL!D5 -> 535.1862 | D5: =C5/B5-1 -> 0 | E5: =PL!D23 -> 535.1862 | F5: =E5/B5-1 -> 0 | G5: =PL!D41 -> 535.1862 | H5: =G5/B5-1 -> 0 | I5: 決算短信＋說明資料＋g_q4（Assumed） | J5: 257.1 ＋ 132.4 ＋ 145.7
A6: FY2026 營業利益 vs 上半＋第三季＋第四季（Q4 營收 × 第三季營益率） | B6: =q26h1_oi+g3_oi+g3_rev*(1+g_q4)*m_q4 -> 238.5671 | C6: =PL!D14 -> 238.5671 | D6: =C6/B6-1 -> 0 | E6: =PL!D32 -> 238.5671 | F6: =E6/B6-1 -> 0 | G6: =PL!D50 -> 238.5671 | H6: =G6/B6-1 -> 0 | I6: 同上
A7: 第三季＋第四季平均營收 vs 第三季指引（132.4） | B7: =g3_rev -> 132.442 | C7: =(PL!D5-q26h1_rev)/2 -> 139.0641 | D7: =C7/B7-1 -> 0.05 | E7: =(PL!D23-q26h1_rev)/2 -> 139.0641 | F7: =E7/B7-1 -> 0.05 | G7: =(PL!D41-q26h1_rev)/2 -> 139.0641 | H7: =G7/B7-1 -> 0.05 | I7: 說明資料 3Q 132.4 | J7: v0.1：−5.5%／−9.6%／−13.1%（A／B／C）；v0.1.1 由 g_q4 決定（+5%）
A8: FY2026 營業利益率 vs 上半實績（百分點） | B8: =q26h1_oi/q26h1_rev -> 0.45374585 | C8: =PL!D15 -> 0.44576467 | D8: =C8-B8 -> -0.0079811769 | E8: =PL!D33 -> 0.44576467 | F8: =E8-B8 -> -0.0079811769 | G8: =PL!D51 -> 0.44576467 | H8: =G8-B8 -> -0.0079811769 | I8: 上半 45.4% | J8: 下半營益率約 44%（第三季指引 43.9%）
A9: FY2026 毛利率 vs 上半實績（百分點） | B9: =q26h1_gp/q26h1_rev -> 0.71546888 | C9: =PL!D13 -> 0.70639057 | D9: =C9-B9 -> -0.0090783149 | E9: =PL!D31 -> 0.70639057 | F9: =E9-B9 -> -0.0090783149 | G9: =PL!D49 -> 0.70639057 | H9: =G9-B9 -> -0.0090783149 | I9: 上半 71.5% | J9: 第三、四季取 69.8%（公司：低不到 2 點）
A10: FY2026 EPS vs 上半實績 × 2 | B10: =q26h1_eps*2 -> 1481.68 | C10: =PL!D17 -> 1548.2856 | D10: =C10/B10-1 -> 0.044952728 | E10: =PL!D35 -> 1548.2856 | F10: =E10/B10-1 -> 0.044952728 | G10: =PL!D53 -> 1548.2856 | H10: =G10/B10-1 -> 0.044952728 | I10: 決算短信（740.84）
A11: A2. 只用 v0.1 驅動時的 FY2026（對照；說明錨點改變了多少）
A12: 驅動推導營收 vs 錨點營收 | B12: =PL!D98 -> 535.1862 | C12: =PL!D95 -> 507.30654 | D12: =C12/B12-1 -> -0.05209338 | E12: =PL!D156 -> 496.46159 | F12: =E12/B12-1 -> -0.072357271 | G12: =PL!D217 -> 487.17684 | H12: =G12/B12-1 -> -0.089705892 | I12: PL 區塊 D、E 節 | J12: 負＝驅動推導低於公司資料
A13: 驅動推導營業利益 vs 錨點營業利益 | B13: =PL!D100 -> 238.5671 | C13: =PL!D127 -> 228.83775 | D13: =C13/B13-1 -> -0.040782462 | E13: =PL!D188 -> 222.55096 | F13: =E13/B13-1 -> -0.067134744 | G13: =PL!D249 -> 217.19003 | H13: =G13/B13-1 -> -0.089606127 | I13: 同上
A14: 驅動推導 EPS（淨利÷營業利益 0.733）vs 錨點 EPS | B14: =PL!D123 -> 1548.2856 | C14: =PL!D128 -> 1545.3795 | D14: =C14/B14-1 -> -0.0018769416 | E14: =PL!D189 -> 1502.9238 | F14: =E14/B14-1 -> -0.029298063 | G14: =PL!D250 -> 1466.7205 | H14: =G14/B14-1 -> -0.052680877 | I14: 同上
A15: 驅動推導下半平均營收 vs 第三季指引 | B15: =g3_rev -> 132.442 | C15: =(PL!D95-q26h1_rev)/2 -> 125.12427 | D15: =C15/B15-1 -> -0.05525233 | E15: =(PL!D156-q26h1_rev)/2 -> 119.70179 | F15: =E15/B15-1 -> -0.096194609 | G15: =(PL!D217-q26h1_rev)/2 -> 115.05942 | H15: =G15/B15-1 -> -0.13124672 | I15: 說明資料 3Q 132.4 | J15: ＝v0.1 的對帳結果
A16: B. FY2026 vs 共識與券商（參考）
A17: 營收 vs 共識（stockanalysis 2026-10-07，20 位） | B17: =cons_rev26 -> 564.96 | C17: =PL!D5 -> 535.1862 | D17: =C17/B17-1 -> -0.052700722 | E17: =PL!D23 -> 535.1862 | F17: =E17/B17-1 -> -0.052700722 | G17: =PL!D41 -> 535.1862 | H17: =G17/B17-1 -> -0.052700722 | I17: stockanalysis（564.96；區間 541.0–598.7） | J17: 共識早於 10-22 指引
A18: 營收 vs 樂天證券（2026-04-27） | B18: 550 | C18: =PL!D5 -> 535.1862 | D18: =C18/B18-1 -> -0.026934182 | E18: =PL!D23 -> 535.1862 | F18: =E18/B18-1 -> -0.026934182 | G18: =PL!D41 -> 535.1862 | H18: =G18/B18-1 -> -0.026934182 | I18: 今中能夫
A19: 營業利益 vs 樂天證券 | B19: =cons_oi26 -> 240 | C19: =PL!D14 -> 238.5671 | D19: =C19/B19-1 -> -0.0059704167 | E19: =PL!D32 -> 238.5671 | F19: =E19/B19-1 -> -0.0059704167 | G19: =PL!D50 -> 238.5671 | H19: =G19/B19-1 -> -0.0059704167 | I19: 今中能夫（240）
A20: FY2027 營收 vs 樂天證券（640） | B20: =cons_rev27 -> 640 | C20: =PL!E5 -> 558.96445 | D20: =C20/B20-1 -> -0.12661804 | E20: =PL!E23 -> 524.5059 | F20: =E20/B20-1 -> -0.18045953 | G20: =PL!E41 -> 480.07397 | H20: =G20/B20-1 -> -0.24988443 | I20: 今中能夫
A21: C. 結構檢查
A22: 非 AI 裝置 FY2026 年增 vs SEMI 組裝封裝設備 CY2026 年增（百分點） | B22: =semi_pk/semi_pk_lo-1 -> 0.096 | C22: =PL!D8/PL!C8-1 -> 0.11825361 | D22: =C22-B22 -> 0.022253611 | E22: =PL!D26/PL!C26-1 -> 0.1426813 | F22: =E22-B22 -> 0.0466813 | G22: =PL!D44/PL!C44-1 -> 0.16445882 | H22: =G22-B22 -> 0.068458817 | I22: markets/equipment（SEMI 2026-07） | J22: 口徑不同（SEMI 為全球封裝設備美元金額），只看方向
A23: FY2025 AI 占營收（校準結果） | C23: =PL!C11 -> 0.27688438 | J23: AI 裝置 75 ＋ AI 消耗品，再按比例加その他；命題的「約兩成」
A24: FY2025 AI 裝置占營收（不含消耗品） | C24: =PL!C12 -> 0.2068293
A25: FY2027 AI 裝置占營收（A／B／C） | C25: =PL!E12 -> 0.19496909 | E25: =PL!E30 -> 0.1477896 | G25: =PL!E48 -> 0.079395832
A26: FY2027 AI 占營收（含 AI 消耗品；A／B／C） | C26: =PL!E11 -> 0.33323552 | E26: =PL!E29 -> 0.28943098 | G26: =PL!E47 -> 0.22366621
A27: 參考：公司稱 FY26 Q2 記憶體占營收略低於 40%、Q3 約 30%（含一般 DRAM／NAND，口徑不同，不可直接比較）

Sheet Sens
A1: Sens — 一次動一個輸入（情境 A）：對 FY2027、FY2028 營收與 EPS 的影響。每個案例是一個完整推導區塊（本頁下方，與 PL 同一引擎；校準會跟著重算）
A3: 案例 | B3: 設定 | C3: FY2027 營收 ¥B | D3: FY2027 EPS ¥ | E3: 相對基準 | F3: FY2028 營收 ¥B | G3: FY2028 EPS ¥ | H3: 相對基準 | I3: FY2027 AI 占營收 | J3: FY2026 EPS ¥ | K3: 相對基準
A4: 基準（情境 A） | B4: PL 區塊 A | C4: =PL!E114 -> 558.96445 | D4: =PL!E123 -> 1722.7276 | E4: =D4/D$4-1 -> 0 | F4: =PL!F114 -> 591.32139 | G4: =PL!F123 -> 1850.7579 | H4: =G4/G$4-1 -> 0 | I4: =PL!E115 -> 0.33323552 | J4: =PL!D123 -> 1548.2856 | K4: =J4/J$4-1 -> 0
A5: 汰換／升級比例 5% | B5: dlt 低 | C5: =E124 -> 552.21192 | D5: =E133 -> 1696.1851 | E5: =D5/D$4-1 -> -0.015407209 | F5: =F124 -> 579.80359 | G5: =F133 -> 1805.0266 | H5: =G5/G$4-1 -> -0.024709474 | I5: =E125 -> 0.32239145 | J5: =D133 -> 1548.2856 | K5: =J5/J$4-1 -> 0
A6: 汰換／升級比例 15% | B6: dlt 高 | C6: =E194 -> 564.91153 | D6: =E203 -> 1746.1551 | E6: =D6/D$4-1 -> 0.01359907 | F6: =F194 -> 601.42406 | G6: =F203 -> 1891.0103 | H6: =G6/G$4-1 -> 0.021749145 | I6: =E195 -> 0.3425189 | J6: =D203 -> 1548.2856 | K6: =J6/J$4-1 -> 0
A7: AI 錨點 −10%（67.5） | B7: ai_25 低 | C7: =E264 -> 560.81976 | D7: =E273 -> 1730.0311 | E7: =D7/D$4-1 -> 0.0042395365 | F7: =F264 -> 594.81538 | G7: =F273 -> 1864.6644 | H7: =G7/G$4-1 -> 0.007513966 | I7: =E265 -> 0.3127007 | J7: =D273 -> 1548.2856 | K7: =J7/J$4-1 -> 0
A8: AI 錨點 +10%（82.5） | B8: ai_25 高 | C8: =E334 -> 557.24359 | D8: =E343 -> 1715.9574 | E8: =D8/D$4-1 -> -0.0039299087 | F8: =F334 -> 587.96986 | G8: =F343 -> 1837.433 | H8: =G8/G$4-1 -> -0.0071996775 | I8: =E335 -> 0.35382173 | J8: =D343 -> 1548.2856 | K8: =J8/J$4-1 -> 0
A9: HBM 比重 45% | B9: w_hbm 低 | C9: =E404 -> 558.07193 | D9: =E413 -> 1719.2157 | E9: =D9/D$4-1 -> -0.0020385321 | F9: =F404 -> 590.28068 | G9: =F413 -> 1846.6187 | H9: =G9/G$4-1 -> -0.0022364652 | I9: =E405 -> 0.33375638 | J9: =D413 -> 1548.2856 | K9: =J9/J$4-1 -> 0
A10: HBM 比重 52% | B10: w_hbm 高 | C10: =E474 -> 560.16108 | D10: =E483 -> 1727.4376 | E10: =D10/D$4-1 -> 0.0027340676 | F10: =F474 -> 592.71597 | G10: =F483 -> 1856.3066 | H10: =G10/G$4-1 -> 0.0029980947 | I10: =E475 -> 0.33253972 | J10: =D483 -> 1548.2856 | K10: =J10/J$4-1 -> 0
A11: 混合鍵合開關 0 | B11: 不納入混合鍵合 | C11: =E544 -> 557.80756 | D11: =E553 -> 1718.1757 | E11: =D11/D$4-1 -> -0.0026422334 | F11: =F544 -> 588.66504 | G11: =F553 -> 1840.1957 | H11: =G11/G$4-1 -> -0.0057069432 | I11: =E545 -> 0.33156632 | J11: =D553 -> 1548.2856 | K11: =J11/J$4-1 -> 0
A12: 混合鍵合淨影響 −20% | B12: 電漿切割取代部分切割 | C12: =E614 -> 555.49418 | D12: =E623 -> 1709.0791 | E12: =D12/D$4-1 -> -0.0079225984 | F12: =F614 -> 583.3808 | G12: =F623 -> 1819.2115 | H12: =G12/G$4-1 -> -0.017045124 | I12: =E615 -> 0.3282068 | J12: =D623 -> 1548.2856 | K12: =J12/J$4-1 -> 0
A13: 混合鍵合淨影響 +30% | B13: 精度升級較大 | C13: =E684 -> 561.27866 | D13: =E693 -> 1731.8383 | E13: =D13/D$4-1 -> 0.0052885576 | F13: =F684 -> 596.63452 | G13: =F693 -> 1871.911 | H13: =G13/G$4-1 -> 0.011429435 | I13: =E685 -> 0.33655304 | J13: =D693 -> 1548.2856 | K13: =J13/J$4-1 -> 0
A14: 混合鍵合普及 高 | B14: hbp 高欄 | C14: =E754 -> 559.76985 | D14: =E763 -> 1725.8975 | E14: =D14/D$4-1 -> 0.0018400696 | F14: =F754 -> 592.45879 | G14: =F763 -> 1855.2832 | H14: =G14/G$4-1 -> 0.0024450934 | I14: =E755 -> 0.33501352 | J14: =D763 -> 1548.2856 | K14: =J14/J$4-1 -> 0
A15: 晶粒容量 低（同位元需更多晶粒） | B15: den 低欄 | C15: =E824 -> 568.44568 | D15: =E833 -> 1760.0997 | E15: =D15/D$4-1 -> 0.021693596 | F15: =F824 -> 592.43948 | G15: =F833 -> 1855.2063 | H15: =G15/G$4-1 -> 0.0024035852 | I15: =E825 -> 0.3612944 | J15: =D833 -> 1548.2856 | K15: =J15/J$4-1 -> 0
A16: 晶粒容量 高 | B16: den 高欄 | C16: =E894 -> 556.04566 | D16: =E903 -> 1711.2469 | E16: =D16/D$4-1 -> -0.0066642156 | F16: =F894 -> 605.0889 | G16: =F903 -> 1905.6441 | H16: =G16/G$4-1 -> 0.029656067 | I16: =E895 -> 0.3305258 | J16: =D903 -> 1548.2856 | K16: =J16/J$4-1 -> 0
A17: 堆疊層數 低 | B17: stk 低欄 | C17: =E964 -> 562.95458 | D17: =E973 -> 1738.4407 | E17: =D17/D$4-1 -> 0.0091210935 | F17: =F964 -> 594.09383 | G17: =F973 -> 1861.7913 | H17: =G17/G$4-1 -> 0.0059615535 | I17: =E965 -> 0.33646758 | J17: =D973 -> 1548.2856 | K17: =J17/J$4-1 -> 0
A18: 堆疊層數 高 | B18: stk 高欄 | C18: =E1034 -> 559.40573 | D18: =E1043 -> 1724.4643 | E18: =D18/D$4-1 -> 0.0010081166 | F18: =F1034 -> 594.20379 | G18: =F1043 -> 1862.2291 | H18: =G18/G$4-1 -> 0.0061981181 | I18: =E1035 -> 0.330027 | J18: =D1043 -> 1548.2856 | K18: =J18/J$4-1 -> 0
A19: 每堆疊額外工序 2 | B19: s_stk 低 | C19: =E1104 -> 559.78072 | D19: =E1113 -> 1725.9403 | E19: =D19/D$4-1 -> 0.0018649052 | F19: =F1104 -> 592.51691 | G19: =F1113 -> 1855.5145 | H19: =G19/G$4-1 -> 0.0025700782 | I19: =E1105 -> 0.33438159 | J19: =D1113 -> 1548.2856 | K19: =J19/J$4-1 -> 0
A20: 每堆疊額外工序 4 | B20: s_stk 高 | C20: =E1174 -> 558.24174 | D20: =E1183 -> 1719.8838 | E20: =D20/D$4-1 -> -0.0016507336 | F20: =F1174 -> 590.26949 | G20: =F1183 -> 1846.5742 | H20: =G20/G$4-1 -> -0.0022605147 | I20: =E1175 -> 0.33222372 | J20: =D1183 -> 1548.2856 | K20: =J20/J$4-1 -> 0
A21: CY2030–31 需求年增 0% | B21: g_tail 低 | C21: =E1244 -> 558.96445 | D21: =E1253 -> 1722.7276 | E21: =D21/D$4-1 -> 0 | F21: =F1244 -> 584.22586 | G21: =F1253 -> 1822.5649 | H21: =G21/G$4-1 -> -0.015233215 | I21: =E1245 -> 0.33323552 | J21: =D1253 -> 1548.2856 | K21: =J21/J$4-1 -> 0
A22: CY2030–31 需求年增 20% | B22: g_tail 高 | C22: =E1314 -> 558.96445 | D22: =E1323 -> 1722.7276 | E22: =D22/D$4-1 -> 0 | F22: =F1314 -> 601.88441 | G22: =F1323 -> 1892.8475 | H22: =G22/G$4-1 -> 0.022741841 | I22: =E1315 -> 0.33323552 | J22: =D1323 -> 1548.2856 | K22: =J22/J$4-1 -> 0
A23: CoWoS 2025 600 千片 | B23: cw_25 低 | C23: =E1384 -> 560.92222 | D23: =E1393 -> 1730.4346 | E23: =D23/D$4-1 -> 0.0044737364 | F23: =F1384 -> 594.47355 | G23: =F1393 -> 1863.3032 | H23: =G23/G$4-1 -> 0.0067784917 | I23: =E1385 -> 0.33175796 | J23: =D1393 -> 1548.2856 | K23: =J23/J$4-1 -> 0
A24: 非 AI 裝置年增 0% | B24: g_non 低 | C24: =E1454 -> 538.01066 | D24: =E1463 -> 1640.5686 | E24: =D24/D$4-1 -> -0.047691188 | F24: =F1454 -> 553.71728 | G24: =F1463 -> 1702.0969 | H24: =G24/G$4-1 -> -0.08032436 | I24: =E1455 -> 0.34621398 | J24: =D1463 -> 1548.2856 | K24: =J24/J$4-1 -> 0
A25: 非 AI 裝置年增 12% | B25: g_non 高 | C25: =E1524 -> 580.52416 | D25: =E1533 -> 1807.8826 | E25: =D25/D$4-1 -> 0.049430349 | F25: =F1524 -> 632.42875 | G25: =F1533 -> 2015.336 | H25: =G25/G$4-1 -> 0.088924722 | I25: =E1525 -> 0.32085971 | J25: =D1533 -> 1548.2856 | K25: =J25/J$4-1 -> 0
A26: 非 AI 消耗品年增 0% | B26: g_tl 低 | C26: =E1594 -> 553.212 | D26: =E1603 -> 1700.1123 | E26: =D26/D$4-1 -> -0.013127608 | F26: =F1594 -> 581.05381 | G26: =F1603 -> 1809.9823 | H26: =G26/G$4-1 -> -0.022031838 | I26: =E1595 -> 0.3367006 | J26: =D1603 -> 1548.2856 | K26: =J26/J$4-1 -> 0
A27: 非 AI 消耗品年增 10% | B27: g_tl 高 | C27: =E1664 -> 565.04531 | D27: =E1673 -> 1746.6826 | E27: =D27/D$4-1 -> 0.013905312 | F27: =F1664 -> 602.74619 | G27: =F1673 -> 1896.2876 | H27: =G27/G$4-1 -> 0.024600591 | I27: =E1665 -> 0.32964934 | J27: =D1673 -> 1548.2856 | K27: =J27/J$4-1 -> 0
A28: AI 消耗品比例 10% | B28: w_tlai 低 | C28: =E1734 -> 541.72736 | D28: =E1743 -> 1655.0973 | E28: =D28/D$4-1 -> -0.039257679 | F28: =F1734 -> 563.1667 | G28: =F1743 -> 1739.2767 | H28: =G28/G$4-1 -> -0.06023544 | I28: =E1735 -> 0.25269821 | J28: =D1743 -> 1548.2856 | K28: =J28/J$4-1 -> 0
A29: AI 消耗品比例 40% | B29: w_tlai 高 | C29: =E1804 -> 571.82825 | D29: =E1813 -> 1773.4619 | E29: =D29/D$4-1 -> 0.029449991 | F29: =F1804 -> 611.82919 | G29: =F1813 -> 1932.602 | H29: =G29/G$4-1 -> 0.044221943 | I29: =E1805 -> 0.3858357 | J29: =D1813 -> 1548.2856 | K29: =J29/J$4-1 -> 0
A30: 市占 FY2029 −10pt（線性） | B30: sh_loss 高 | C30: =E1874 -> 540.70633 | D30: =E1883 -> 1651.1041 | E30: =D30/D$4-1 -> -0.041575616 | F30: =F1874 -> 558.58358 | G30: =F1883 -> 1721.2288 | H30: =G30/G$4-1 -> -0.069987062 | I30: =E1875 -> 0.33009133 | J30: =D1883 -> 1548.2856 | K30: =J30/J$4-1 -> 0
A31: 毛利率迴歸只用 FY2019–25 | B31: gm_a2、gm_b2 | C31: =E1944 -> 558.96445 | D31: =E1953 -> 1719.9605 | E31: =D31/D$4-1 -> -0.0016062387 | F31: =F1944 -> 591.32139 | G31: =F1953 -> 1847.5766 | H31: =G31/G$4-1 -> -0.0017189005 | I31: =E1945 -> 0.33323552 | J31: =D1953 -> 1548.2856 | K31: =J31/J$4-1 -> 0
A32: 淨利÷營業利益 低（0.687） | B32: 稅前÷營業利益 0.97、稅率 29.2% | C32: =E2014 -> 558.96445 | D32: =E2023 -> 1639.3814 | E32: =D32/D$4-1 -> -0.048380325 | F32: =F2014 -> 591.32139 | G32: =F2023 -> 1761.2176 | H32: =G32/G$4-1 -> -0.048380325 | I32: =E2015 -> 0.33323552 | J32: =D2023 -> 1527.744 | K32: =J32/J$4-1 -> -0.013267302
A33: 淨利÷營業利益 高（0.738） | B33: 稅前÷營業利益 1.00、稅率 26.2% | C33: =E2084 -> 558.96445 | D33: =E2093 -> 1762.2967 | E33: =D33/D$4-1 -> 0.022968892 | F33: =F2084 -> 591.32139 | G33: =F2093 -> 1893.2677 | H33: =G33/G$4-1 -> 0.022968892 | I33: =E2085 -> 0.33323552 | J33: =D2093 -> 1558.0378 | K33: =J33/J$4-1 -> 0.0062987429
A34: 第四季 ÷ 第三季 0% | B34: g_q4 低（持平） | C34: =E2154 -> 549.74134 | D34: =E2163 -> 1686.4896 | E34: =D34/D$4-1 -> -0.021035252 | F34: =F2154 -> 581.5679 | G34: =F2163 -> 1812.0206 | H34: =G34/G$4-1 -> -0.020930479 | I34: =E2155 -> 0.33882628 | J34: =D2163 -> 1509.6869 | K34: =J34/J$4-1 -> -0.024929935
A35: 第四季 ÷ 第三季 +22% | B35: g_q4 高（FY2025 實績） | C35: =E2224 -> 570.03219 | D35: =E2233 -> 1766.365 | E35: =D35/D$4-1 -> 0.025330448 | F35: =F2224 -> 603.02558 | G35: =F2233 -> 1897.4031 | H35: =G35/G$4-1 -> 0.02520331 | I35: =E2225 -> 0.32676543 | J35: =D2233 -> 1594.6039 | K35: =J35/J$4-1 -> 0.029915922
A36: 第四季營益率 −2pt | B36: m_q4 低 | C36: =E2294 -> 558.96445 | D36: =E2303 -> 1722.7276 | E36: =D36/D$4-1 -> 0 | F36: =F2294 -> 591.32139 | G36: =F2303 -> 1850.7579 | H36: =G36/G$4-1 -> 0 | I36: =E2295 -> 0.33323552 | J36: =D2303 -> 1528.9153 | K36: =J36/J$4-1 -> -0.012510799
A37: 第四季營益率 +2pt | B37: m_q4 高 | C37: =E2364 -> 558.96445 | D37: =E2373 -> 1722.7276 | E37: =D37/D$4-1 -> 0 | F37: =F2364 -> 591.32139 | G37: =F2373 -> 1850.7579 | H37: =G37/G$4-1 -> 0 | I37: =E2365 -> 0.33323552 | J37: =D2373 -> 1567.6558 | K37: =J37/J$4-1 -> 0.012510799
A38: 錨點差額不延續到 FY2027 | B38: anc_carry＝0（FY2027 起完全回到 v0.1 驅動） | C38: =E2434 -> 539.54937 | D38: =E2443 -> 1646.5811 | E38: =D38/D$4-1 -> -0.044201082 | F38: =F2434 -> 570.78984 | G38: =F2443 -> 1769.3582 | H38: =G38/G$4-1 -> -0.043981796 | I38: =E2435 -> 0.34522663 | J38: =D2443 -> 1548.2856 | K38: =J38/J$4-1 -> 0
A39: 情境 B | B39: 顆數 2028 ×0.8、2029 ×0.85；非 AI FY2028 0% | C39: =PL!E175 -> 524.5059 | D39: =PL!E184 -> 1587.9429 | E39: =D39/D$4-1 -> -0.07823913 | F39: =PL!F175 -> 564.63248 | G39: =PL!F184 -> 1745.0547 | H39: =G39/G$4-1 -> -0.057113433 | I39: =PL!E176 -> 0.28943098 | J39: =PL!D184 -> 1548.2856 | K39: =J39/J$4-1 -> 0
A40: 情境 C | B40: 顆數 ×0.6；非 AI FY2028 −12%；毛利率 −1pt | C40: =PL!E236 -> 480.07397 | D40: =PL!E245 -> 1416.6944 | E40: =D40/D$4-1 -> -0.17764457 | F40: =PL!F236 -> 464.47517 | G40: =PL!F245 -> 1326.4198 | H40: =G40/G$4-1 -> -0.28330993 | I40: =PL!E237 -> 0.22366621 | J40: =PL!D245 -> 1548.2856 | K40: =J40/J$4-1 -> 0
A41: 對照：只用 v0.1 驅動（情境 A） | B41: 無錨點、淨利÷營業利益 0.733 | C41: =PL!E95 -> 539.54937 | D41: =PL!E128 -> 1672.6417 | E41: =D41/D$4-1 -> -0.02907357 | F41: =PL!F95 -> 570.78984 | G41: =PL!F128 -> 1797.362 | H41: =G41/G$4-1 -> -0.028850813
...

Sheet Sources
A1: 來源（公司原文以網頁擷取工具讀取；表格欄位錯置處以算術核對；版面與頁碼待人工複核）
A2: 公司：2026年3月期 決算短信（英文，2026-04-22） | B2: https://www.disco.co.jp/eg/ir/library/doc/fr/fr20260422.pdf
A3: 公司：2027年3月期 第2四半期 決算短信（英文，2026-10-22） | B3: https://www.disco.co.jp/eg/ir/library/doc/fr/fr20261022.pdf
A4: 公司：2027年3月期 第1四半期 決算短信（2026-07-23） | B4: https://www.disco.co.jp/eg/ir/library/doc/fr/fr20260723.pdf
A5: 公司：FY2026 2Q 決算說明資料（2026-10-22） | B5: https://www.disco.co.jp/eg/ir/library/doc/film/20261022.pdf
A6: 公司：FY2025 4Q 決算說明資料（2026-04-22） | B6: https://www.disco.co.jp/eg/ir/library/doc/film/20260422.pdf
A7: 公司：FY2024 4Q 說明資料（2025-04-17）／FY2023（2024-04-25）／FY2022（2023-04-20） | B7: https://www.disco.co.jp/eg/ir/library/doc/film/20250417.pdf
A8: 公司：FY2026 1Q 說明筆記（2026-07-23） | B8: https://www.disco.co.jp/eg/ir/library/doc/film/20260723_note.pdf
A9: 公司：歷年決算短信（fr20250417、fr20230420、fr20210422、fr20190508、fr20170510） | B9: https://www.disco.co.jp/eg/ir/library/fr.html
A10: 公司：技術說明會 2025（2025-12）／2024（2024-12） | B10: https://www.disco.co.jp/jp/ir/movie/doc/J_Tech_Briefing_2025.pdf
A11: TSE 決算短信轉載（kabuyoho，2026-04-20 檔名；內容日期 2026-04-22） | B11: https://kabuyoho-sls-disclose.ifis.co.jp/295/140120260420506569.pdf
A12: 松井證券：決算情報（年度、季度） | B12: https://finance.matsui.co.jp/stock/6146/settlement/index
A13: 樂天證券 今中能夫：決算レポート（2026-04-27） | B13: https://media.rakuten-sec.net/articles/-/52260
... A30: tousaiblog：股票分割（2023-04-01 一股分三股） | B30: https://www.tousaiblog.org/disco-bunkatsu
A31: 市場層：markets/memory（market.py @ 5fa3751，v0.4）、tsmc／skhynix／markets/equipment 成品（本 repo）
A32: 無法開啟（建置環境被擋或逾時）：nikkei.com 株價推移、kabutan 年足、irbank、companiesmarketcap、traders.co.jp、stooq、macrotrends、gyokaidigest
A33: SemiAnalysis | B33: 未使用
