Workbook

Sheet README
A1: 聯發科（2454.TW）收支與估值模型 v0.1.2（AI 半導體 Project：運算層，手機 SoC＋AI ASIC） 2026-10-25
A2: 版本：v0.1（初版）。ASIC 每顆規格（核心售價、HBM 代購）讀 Broadcom 模型（本專案權威），份額與 Broadcom、Marvell 合計不超過 100%；手機、智慧邊緣平台、電源 IC 用簡化成長率。本版未做先驗。
A3: 模型命題：聯發科的 AI ASIC 營收＝Google TPU 顆數（市場層）× 聯發科份額 × 每顆營收（Broadcom 模型規格）；FY2026 只有約 20 億美元，賣方卻估 FY2028 達 500 億美元。在 Broadcom 占 TPU 75%、Marvell 5% 的份額口徑下，聯發科最多拿到兩成 TPU，推得出多少 ASIC 營收與 EPS？
A4: 核心問題：以市場層 TPU 顆數與份額上限往前推，聯發科 FY2027–28 的 ASIC 營收與 EPS 離公司目標、賣方估計有多遠；差距要靠顆數、份額還是單價補上，現價約 39 倍前瞻 P/E 隱含哪一條路徑。
A6: 會計年度＝日曆年，FY(t)＝CY(t)，不平移。FY2025A 實績、FY2026 錨點、FY2027–FY2029 驅動因子推導、FY2030–FY2032 收斂法。金額：十億新台幣；EPS：新台幣（基本）。口徑：歸屬母公司淨利（TIFRS）。3Q26 財報約 10 月底公布，本版只納入 3Q26 營收實績。
A8: 驅動因子 → 推導量（全部唯讀上游，不修改）
A9: AI ASIC：tsmc 成品的 Google TPU 顆數 × 情境係數（CY2028–29）× 聯發科份額（Assumed；CY2026 5%、CY2027 15%、CY2028 起 18%，高值以 1 − Broadcom − Marvell 份額為上限）×（核心售價 8K × 第二顆 ASIC 單價係數＋代購比例 0.6 × HBM 金額）× k_x（FY2026 以公司「超過 20 億美元」校準）× 匯率 32。
A10: 非 ASIC：手機、智慧邊緣平台（不含 ASIC）、電源 IC 由 FY2026 錨點依情境成長率推（A 順利／B 平平／C 不如預期）。
A11: 毛利：ASIC 核心毛利率 45%（Assumed）、代購 HBM 10%（Broadcom 模型）；非 ASIC 毛利率為 FY2026 殘差（Derived）後沿用。營業費用彈性 0.3（ASIC 營業費用低）、年增下限 6%；營業外 18、稅率 14%、股數持平。
A12: 校準：FY2026 ＝ 1H26 實績＋3Q26 營收實績（月營收）＋3Q26 指引（毛利率 46%、費用 48.5）＋4Q26 假設（手機 −5%、智慧邊緣 −5%、ASIC 約 17 億美元量產）。不用券商數字（只在 Recon 對帳）。
A13: 估值：Val 第 0 節目標價＝0.5 × DCF 目標價（股東現金流＝EPS ×（1 − g／ROE），FY2027–32 明確期＋永續，r 10%、g 4%，三情境權重 0.3／0.5／0.2）＋0.5 × Comparable 目標價（高通、博通、邁威爾、世芯、創意前瞻 P/E 中位數 × 12 個月後前瞻 EPS；不含 A 股）；另列 Comparable 單獨目標價、市場共識目標價與差距拆解。十年 P/E 規則值 × FY2027 EPS 保留為參考（不是目標價）。本版未做先驗，無 Andy 合理 P/E 對照。
A14: 預估期間：FY2027–FY2029 由驅動因子推導；FY2030 起為收斂法，非驅動因子推導（營收年增由 FY2029 線性收斂到 fade_g、淨利率收斂到 fade_m，FY2032 達到；PL 頁灰底）。十年平均淨利率未找到，B、C 依工作單以 FY2029 × 0.8 代替。
... A18: v0.1.1（2026-10-25）：補上檔空間級距、投資建議、重點觀察（數值不變）。Val 頁末新增「上檔空間級距」「投資建議」兩列（Andy 2026-10-25 14:00、14:17 固定規則），README 頁末新增投資建議與重點觀察三點；既有儲存格位置與數值不變。
A19: ="投資建議："&Val!B135&"（依上檔空間固定規則）" -> 投資建議：放空（依上檔空間固定規則）
A20: 重點觀察 1：目標價 NT$2,057（DCF 1,846、Comparable 2,268 各半），比現價 4,010（2026-10-22）低 48.7%，級距 −25%～−50%；Comparable 單獨為 −43.4%。主因是倍數不是 EPS：本模型 12 個月後前瞻 EPS 119.49 比共識前瞻 EPS 103.48 高 15.5%，但同業（高通、博通、邁威爾、世芯、創意）前瞻 P/E 中位數 19.0 倍，現價隱含 38.8 倍、共識目標價 6,067 隱含 58.6 倍（比同業高 208.9%）；市場給聯發科的 AI ASIC 成長溢價，Comparable 未計入。
A21: 重點觀察 2：情境分歧大：FY2028 EPS A／B／C 為 149.3／119.5／85.3，DCF 價格帶 1,012～2,466；C 情境（顆數 ×0.6、手機 −8%）FY2028 EPS 低於 FY2027 的 100.1。即使 A 情境 DCF 2,466 也比現價低 38.5%。
A22: 重點觀察 3：TPU 份額是最敏感變數：聯發科占 TPU −5pt 時 FY2027 EPS −13.2%、取上限 20% 時 +13.2%；營業費用彈性 0.6 時 −12.7%（Sens 頁）。下一個檢驗點是 3Q26 財報與法說（約 2026-10 底）的 ASIC 營收與客戶進度。
A23: v0.1.2（2026-10-28）：分部原則重建（數值不變）。Q 頁最後追加核對列「檢查：分部合計 − 合併營收」；官方分部與子列宣告見 segments.json。

Sheet In
A1: In — 輸入（藍字；基準欄 E，低 D、高 F）。金額：十億新台幣（NT$B）；ASIC 每顆價格：千美元（US$K）；顆數：百萬顆；匯率：新台幣／美元。每個輸入附兩個來源（找不到者寫「未找到」）；公司原文算一個
A2: 標記：Verified／Interested-party／Analogy／Assumed／Derived；Analogy、Assumed 給低／高區間，不當點估計（放情境或 Sens）。SemiAnalysis 未使用。公司原文＝聯發科法說營運報告、新聞稿、法說逐字稿與講稿（mediatek.com）；公司指引與目標為 Interested-party；券商、資料商、媒體為 Interested-party
A3: 鍵 | B3: 項目 | C3: 單位 | D3: 低 | E3: 基準 | F3: 高 | G3: 標記 | H3: 來源1 | I3: 來源2／說明
A4: A. AI 加速器顆數（tsmc 成品；與 HBM、台積電、Broadcom、Marvell 模型同一份；情境係數讀台積電模型，不另訂）
A5: u_tpu_26 | B5: Google TPU 顆數 CY2026 | C5: 百萬顆 | E5: 3.85 | G5: Interested-party | H5: tsmc/dist/20261028_台積電個股模型_v0.4.xlsx｜In!E25 | I5: avgo 成品同值（建置時檢查）
A6: u_tpu_27 | B6: Google TPU 顆數 CY2027 | C6: 百萬顆 | E6: 5.5 | G6: Interested-party | H6: tsmc/dist/20261028_台積電個股模型_v0.4.xlsx｜In!E26 | I6: 同上
A7: u_tpu_28 | B7: Google TPU 顆數 CY2028 | C7: 百萬顆 | E7: 7 | G7: Interested-party | H7: tsmc/dist/20261028_台積電個股模型_v0.4.xlsx｜In!E27 | I7: 同上
A8: g29_tpu | B8: Google TPU CY2029 顆數成長 | C8: % | E8: 0.15 | G8: Assumed | H8: tsmc/dist/20261028_台積電個股模型_v0.4.xlsx｜In!E28 | I8: markets/memory 無 2029；沿用台積電模型
A9: u_oth_26 | B9: 其他 ASIC（MTIA、Maia、Ascend 等） 顆數 CY2026 | C9: 百萬顆 | E9: 1 | G9: Derived／Assumed | H9: tsmc/dist/20261028_台積電個股模型_v0.4.xlsx｜In!E33 | I9: avgo 成品同值（建置時檢查）
A10: u_oth_27 | B10: 其他 ASIC（MTIA、Maia、Ascend 等） 顆數 CY2027 | C10: 百萬顆 | E10: 4.5 | G10: Derived／Assumed | H10: tsmc/dist/20261028_台積電個股模型_v0.4.xlsx｜In!E34 | I10: 同上
A11: u_oth_28 | B11: 其他 ASIC（MTIA、Maia、Ascend 等） 顆數 CY2028 | C11: 百萬顆 | E11: 5 | G11: Derived／Assumed | H11: tsmc/dist/20261028_台積電個股模型_v0.4.xlsx｜In!E35 | I11: 同上
A12: g29_oth | B12: 其他 ASIC（MTIA、Maia、Ascend 等） CY2029 顆數成長 | C12: % | E12: 0.15 | G12: Assumed | H12: tsmc/dist/20261028_台積電個股模型_v0.4.xlsx｜In!E36 | I12: markets/memory 無 2029；沿用台積電模型
A13: um28_A | B13: 情境 A：CY2028 顆數 ÷ 基準 | C13: x | E13: 1 | G13: Assumed | H13: tsmc/dist/20261028_台積電個股模型_v0.4.xlsx｜In!E37 | I13: A＝基準；B＝AI 資本支出消化；C＝明顯下修（與台積電、Broadcom、Marvell 模型相同）
A14: um29_A | B14: 情境 A：CY2029 顆數 ÷ 基準 | C14: x | E14: 1 | G14: Assumed | H14: tsmc/dist/20261028_台積電個股模型_v0.4.xlsx｜In!E38 | I14: 同上
A15: um28_B | B15: 情境 B：CY2028 顆數 ÷ 基準 | C15: x | E15: 0.8 | G15: Assumed | H15: tsmc/dist/20261028_台積電個股模型_v0.4.xlsx｜In!E39 | I15: 同上
A16: um29_B | B16: 情境 B：CY2029 顆數 ÷ 基準 | C16: x | E16: 0.85 | G16: Assumed | H16: tsmc/dist/20261028_台積電個股模型_v0.4.xlsx｜In!E40 | I16: 同上
... A18: um29_C | B18: 情境 C：CY2029 顆數 ÷ 基準 | C18: x | E18: 0.6 | G18: Assumed | H18: tsmc/dist/20261028_台積電個股模型_v0.4.xlsx｜In!E42 | I18: 同上
A19: B. ASIC 每顆規格（權威在 Broadcom 模型 In 頁，唯讀；本模型只加聯發科份額）與份額
A20: core_tpu | B20: TPU 每顆核心售價（不含 HBM） | C20: US$K | D20: 6 | E20: 8 | F20: 11 | G20: Assumed | H20: avgo/dist/20261028_Broadcom個股模型_v0.3.xlsx｜In!E56 | I20: Broadcom 模型的 ASIC 每顆規格（本專案權威）；本模型不另訂；聯發科負責的世代與 Broadcom 是否同價：未找到
A21: core_oth | B21: 其他 ASIC 每顆核心售價（不含 HBM） | C21: US$K | D21: 4 | E21: 6 | F21: 9 | G21: Assumed | H21: avgo/dist/20261028_Broadcom個股模型_v0.3.xlsx｜In!E57 | I21: Broadcom 模型的 ASIC 每顆規格（本專案權威）；本模型不另訂；聯發科負責的世代與 Broadcom 是否同價：未找到
A22: f_hbm | B22: HBM 由 ASIC 設計夥伴代購並計入營收的比例 | C22: x | D22: 0.3 | E22: 0.6 | F22: 1 | G22: Assumed | H22: avgo/dist/20261028_Broadcom個股模型_v0.3.xlsx｜In!E58 | I22: 沿用 Broadcom 模型；聯發科客戶是否自購 HBM：未找到（1Q26 法說未回答）
A23: m_hbm | B23: 代購 HBM 的毛利率 | C23: x | D23: 0 | E23: 0.1 | F23: 0.2 | G23: Assumed | H23: avgo/dist/20261028_Broadcom個股模型_v0.3.xlsx｜In!E59 | I23: 沿用 Broadcom 模型
A24: gb_tpu_26 | B24: Google TPU 每顆 HBM CY2026 | C24: GB | E24: 192 | G24: Derived／Assumed | H24: avgo/dist/20261028_Broadcom個股模型_v0.3.xlsx｜In!E43 | I24: markets/memory UNITS；CY2029 沿用 CY2028
A25: gb_tpu_27 | B25: Google TPU 每顆 HBM CY2027 | C25: GB | E25: 250 | G25: Derived／Assumed | H25: avgo/dist/20261028_Broadcom個股模型_v0.3.xlsx｜In!E44 | I25: 同上
A26: gb_tpu_28 | B26: Google TPU 每顆 HBM CY2028 | C26: GB | E26: 288 | G26: Derived／Assumed | H26: avgo/dist/20261028_Broadcom個股模型_v0.3.xlsx｜In!E45 | I26: 同上
A27: gb_oth_26 | B27: 其他 ASIC（MTIA、Maia、Ascend 等） 每顆 HBM CY2026 | C27: GB | E27: 150 | G27: Derived／Assumed | H27: avgo/dist/20261028_Broadcom個股模型_v0.3.xlsx｜In!E46 | I27: markets/memory UNITS；CY2029 沿用 CY2028
A28: gb_oth_27 | B28: 其他 ASIC（MTIA、Maia、Ascend 等） 每顆 HBM CY2027 | C28: GB | E28: 200 | G28: Derived／Assumed | H28: avgo/dist/20261028_Broadcom個股模型_v0.3.xlsx｜In!E47 | I28: 同上
A29: gb_oth_28 | B29: 其他 ASIC（MTIA、Maia、Ascend 等） 每顆 HBM CY2028 | C29: GB | E29: 250 | G29: Derived／Assumed | H29: avgo/dist/20261028_Broadcom個股模型_v0.3.xlsx｜In!E48 | I29: 同上
A30: av_tpu_26 | B30: Broadcom 占 Google TPU 顆數 CY2026（份額加總檢查用） | C30: % | E30: 0.9 | G30: Assumed | H30: avgo/dist/20261028_Broadcom個股模型_v0.3.xlsx｜In!E50 | I30: Broadcom 模型；Broadcom＋Marvell＋聯發科（高）≤ 100%（建置時檢查）
A31: mv_tpu_26 | B31: Marvell 占 Google TPU 顆數 CY2026（份額加總檢查用） | C31: % | E31: 0 | G31: Assumed | H31: mrvl/dist/20261028_邁威爾個股模型_v0.2.3.xlsx｜In!E51 | I31: Marvell 模型
A32: av_tpu_27 | B32: Broadcom 占 Google TPU 顆數 CY2027（份額加總檢查用） | C32: % | E32: 0.8 | G32: Assumed | H32: avgo/dist/20261028_Broadcom個股模型_v0.3.xlsx｜In!E51 | I32: Broadcom 模型；Broadcom＋Marvell＋聯發科（高）≤ 100%（建置時檢查）
A33: mv_tpu_27 | B33: Marvell 占 Google TPU 顆數 CY2027（份額加總檢查用） | C33: % | E33: 0 | G33: Assumed | H33: mrvl/dist/20261028_邁威爾個股模型_v0.2.3.xlsx｜In!E52 | I33: Marvell 模型
A34: av_tpu_28 | B34: Broadcom 占 Google TPU 顆數 CY2028（份額加總檢查用） | C34: % | E34: 0.75 | G34: Assumed | H34: avgo/dist/20261028_Broadcom個股模型_v0.3.xlsx｜In!E52 | I34: Broadcom 模型；Broadcom＋Marvell＋聯發科（高）≤ 100%（建置時檢查）
A35: mv_tpu_28 | B35: Marvell 占 Google TPU 顆數 CY2028（份額加總檢查用） | C35: % | E35: 0.05 | G35: Assumed | H35: mrvl/dist/20261028_邁威爾個股模型_v0.2.3.xlsx｜In!E53 | I35: Marvell 模型
... A41: mv_oth_28 | B41: Marvell 占 其他 ASIC（MTIA、Maia、Ascend 等） 顆數 CY2028（份額加總檢查用） | C41: % | E41: 0.15 | G41: Assumed | H41: mrvl/dist/20261028_邁威爾個股模型_v0.2.3.xlsx｜In!E50 | I41: Marvell 模型
A42: mtk_tpu_26 | B42: 聯發科占 Google TPU 顆數 CY2026 | C42: % | D42: 0.03 | E42: 0.05 | F42: 0.1 | G42: Assumed | H42: 公司：與一家美國大型雲端客戶合作的第一顆 AI 加速器 ASIC 於 4Q26 量產；第二顆 2028 年量產（2Q26 講稿）；客戶名稱公司未揭露 | I42: 凱基 2026-07-23：v8x Zebrafish（4Q26 起）、v9 Humufish（4Q27 起）為 Google TPU（Interested-party）；高值受 avgo、mrvl 份額限制（1 − Broadcom − Marvell 基準）
A43: mtk_tpu_27 | B43: 聯發科占 Google TPU 顆數 CY2027 | C43: % | D43: 0.08 | E43: 0.15 | F43: 0.2 | G43: Assumed | H43: 同上 | I43: —
A44: mtk_tpu_28 | B44: 聯發科占 Google TPU 顆數 CY2028（CY2029 沿用） | C44: % | D44: 0.1 | E44: 0.18 | F44: 0.2 | G44: Assumed | H44: 同上 | I44: —
A45: mtk_oth_26 | B45: 聯發科占 其他 ASIC（MTIA、Maia、Ascend 等） 顆數 CY2026 | C45: % | D45: 0 | E45: 0 | F45: 0.02 | G45: Assumed | H45: 公司：與其他多家客戶接觸中、資料中心有望取得更多設計案（2Q26 講稿） | I45: 第二客戶與量產時點：未找到；基準 0，只放 Sens
A46: mtk_oth_27 | B46: 聯發科占 其他 ASIC（MTIA、Maia、Ascend 等） 顆數 CY2027 | C46: % | D46: 0 | E46: 0 | F46: 0.03 | G46: Assumed | H46: 同上 | I46: —
...

Sheet Q
A1: Q — 實績與 FY2026 錨點（十億新台幣；EPS 為新台幣、基本；股數為十億股）。藍字＝輸入（公司營運報告）；黑字＝公式。產品線金額＝公司公布占比 × 營收（Derived）
A2: FY2026 錨點＝1Q、2Q26 實績＋3Q26 營收實績（月營收）與指引（毛利率、費用）＋4Q26 假設；AI ASIC（資料中心）全年取公司「超過 20 億美元」，1–3Q 部分全數放在 3Q 欄（簡化）。3Q26 財報約 10 月底公布，屆時以實績取代 E 欄
A3: 項目 | B3: FY2025A | C3: 1Q26（實績） | D3: 2Q26（實績） | E3: 3Q26（營收實績＋指引） | F3: 4Q26（模型） | G3: FY2026 錨點 | H3: 標記 | I3: 來源1（公司） | J3: 來源2／說明
A4: 營收 | B4: 595.966 | C4: 149.151 | D4: 152.183 | E4: =q3_rev -> 168.057 | F4: =SUM(F5:F7) -> 205.13094 | G4: =SUM(C4:F4) -> 674.52194 | H4: Verified／Assumed（4Q） | I4: FY2025：4Q25 營運報告；1Q26、2Q26：2Q26 營運報告（公司） | J4: 3Q26：月營收實績（科技新報、財報狗）
A5: 手機 | B5: =B4*0.53 -> 315.86198 | C5: =C4*0.49 -> 73.08399 | D5: =D4*0.41 -> 62.39503 | E5: =D5*(1+q3_mob)*q3_rev/(D5*(1+q3_mob)+D6*(1+q3_sep)+D7*(1+q3_pic)) -> 65.218842 | F5: =E5*(1+q4_mob) -> 61.9579 | G5: =SUM(C5:F5) -> 262.65576 | H5: Derived（占比 × 營收）／Assumed | I5: FY2025：4Q25 營運報告；1Q26、2Q26：2Q26 營運報告（公司） | J5: 占比：1Q26 49%、2Q26 41%（公司）；FY2025 約 53%（公司：手機超過 100 億美元 ÷ 191 億美元；占比未揭露，Derived）
A6: 智慧邊緣平台（含 AI ASIC） | B6: =B4*0.415 -> 247.32589 | C6: =C4*0.46 -> 68.60946 | D6: =D4*0.53 -> 80.65699 | E6: =D6*(1+q3_sep)*q3_rev/(D5*(1+q3_mob)+D6*(1+q3_sep)+D7*(1+q3_pic)) -> 92.998756 | F6: =(E6-E8)*(1+q4_sepx)+F8 -> 133.62882 | G6: =SUM(C6:F6) -> 375.89402 | H6: Derived／Assumed | I6: FY2025：4Q25 營運報告；1Q26、2Q26：2Q26 營運報告（公司） | J6: 占比：1Q26 46%、2Q26 53%（公司）；FY2025 約 41.5%（Derived；公司僅揭露美元年增 21%）
A7: 電源 IC | B7: =B4*0.055 -> 32.77813 | C7: =C4*0.05 -> 7.45755 | D7: =D4*0.06 -> 9.13098 | E7: =D7*(1+q3_pic)*q3_rev/(D5*(1+q3_mob)+D6*(1+q3_sep)+D7*(1+q3_pic)) -> 9.8394028 | F7: =E7*(1+q4_pic) -> 9.5442207 | G7: =SUM(C7:F7) -> 35.972154 | H7: Derived／Assumed | I7: FY2025：4Q25 營運報告；1Q26、2Q26：2Q26 營運報告（公司） | J7: 占比：1Q26 5%、2Q26 6%、4Q25 5%（公司）
A8: 其中 AI ASIC（資料中心） | B8: 0 | C8: 0 | D8: 0 | E8: =asic13*fx26 -> 9.6 | F8: =(dc26-asic13)*fx26 -> 54.4 | G8: =SUM(C8:F8) -> 64 | H8: Interested-party／Assumed | I8: 2Q26 講稿：FY2026 資料中心超過 20 億美元、4Q26 量產 | J8: FY2025 視為 0（量產自 4Q26）；1–3Q 部分放在 3Q 欄
A9: 智慧邊緣平台（不含 AI ASIC） | B9: =B6-B8 -> 247.32589 | C9: =C6-C8 -> 68.60946 | D9: =D6-D8 -> 80.65699 | E9: =E6-E8 -> 83.398756 | F9: =F6-F8 -> 79.228818 | G9: =SUM(C9:F9) -> 311.89402 | H9: Derived | I9: — | J9: —
A10: 毛利 | B10: 283.08 | C10: 69.055 | D10: 70.308 | E10: =E4*q3_gm -> 77.30622 | F10: =q4_gmx*(F5+F9+F7)+F8*(m_core*(1-hf26)+m_hbm*hf26) -> 90.508648 | G10: =SUM(C10:F10) -> 307.17787 | H10: Verified／Interested-party（3Q）／Assumed（4Q） | I10: FY2025：4Q25 營運報告；1Q26、2Q26：2Q26 營運報告（公司） | J10: 4Q：非 ASIC × 毛利率＋ASIC（核心 m_core、代購 HBM m_hbm）
A11: 毛利率 | B11: =B10/B4 -> 0.47499354 | C11: =C10/C4 -> 0.46298717 | D11: =D10/D4 -> 0.46199641 | E11: =E10/E4 -> 0.46 | F11: =F10/F4 -> 0.44122378 | G11: =G10/G4 -> 0.45540086 | H11: Derived | I11: — | J11: 公司：FY2025 47.5%、1Q26 46.3%、2Q26 46.2%
A12: 營業費用（推銷＋管理＋研發） | B12: 179.61 | C12: 46.165 | D12: 47.44 | E12: =q3_opx -> 48.5 | F12: =q4_opx -> 50 | G12: =SUM(C12:F12) -> 192.105 | H12: Verified／Interested-party／Assumed | I12: FY2025：4Q25 營運報告；1Q26、2Q26：2Q26 營運報告（公司） | J12: —
A13: 營業利益 | B13: =B10-B12 -> 103.47 | C13: =C10-C12 -> 22.89 | D13: =D10-D12 -> 22.868 | E13: =E10-E12 -> 28.80622 | F13: =F10-F12 -> 40.508648 | G13: =SUM(C13:F13) -> 115.07287 | H13: Derived | I13: FY2025：4Q25 營運報告；1Q26、2Q26：2Q26 營運報告（公司） | J13: 公司：FY2025 103.470、1Q26 22.891、2Q26 22.868（核對見下方）
A14: 營業外淨額 | B14: 21.418 | C14: 4.129 | D14: 5.094 | E14: =q_nonop -> 4.8 | F14: =q_nonop -> 4.8 | G14: =SUM(C14:F14) -> 18.823 | H14: Verified／Assumed | I14: FY2025：4Q25 營運報告；1Q26、2Q26：2Q26 營運報告（公司） | J14: —
A15: 稅前利益 | B15: =B13+B14 -> 124.888 | C15: =C13+C14 -> 27.019 | D15: =D13+D14 -> 27.962 | E15: =E13+E14 -> 33.60622 | F15: =F13+F14 -> 45.308648 | G15: =SUM(C15:F15) -> 133.89587 | H15: Derived | I15: — | J15: —
A16: 所得稅 | B16: 18.77 | C16: 2.643 | D16: 3.357 | E16: =E15*q_tax -> 4.3688086 | F16: =F15*q_tax -> 5.8901243 | G16: =SUM(C16:F16) -> 16.258933 | H16: Verified／Assumed | I16: FY2025：4Q25 營運報告；1Q26、2Q26：2Q26 營運報告（公司） | J16: —
A17: 非控制權益 | B17: 0.798 | C17: 0.222 | D17: 0.27 | E17: =q_nci -> 0.25 | F17: =q_nci -> 0.25 | G17: =SUM(C17:F17) -> 0.992 | H17: Verified／Derived | I17: FY2025：4Q25 營運報告；1Q26、2Q26：2Q26 營運報告（公司） | J17: —
A18: 歸屬母公司淨利 | B18: =B15-B16-B17 -> 105.32 | C18: =C15-C16-C17 -> 24.154 | D18: =D15-D16-D17 -> 24.335 | E18: =E15-E16-E17 -> 28.987411 | F18: =F15-F16-F17 -> 39.168524 | G18: =SUM(C18:F18) -> 116.64494 | H18: Derived | I18: FY2025：4Q25 營運報告；1Q26、2Q26：2Q26 營運報告（公司） | J18: 公司：FY2025 105.319、1Q26 24.154、2Q26 24.335
A19: 公司揭露歸屬母公司淨利 | B19: 105.319 | C19: 24.154 | D19: 24.335 | H19: Verified | I19: FY2025：4Q25 營運報告；1Q26、2Q26：2Q26 營運報告（公司） | J19: —
A20: 加權股數（十億股） | B20: =105.319/66.16 -> 1.5918833 | C20: =24.154/15.17 -> 1.5922215 | D20: =24.335/15.28 -> 1.5926047 | E20: =q_sh -> 1.5926047 | F20: =q_sh -> 1.5926047 | G20: =AVERAGE(C20:F20) -> 1.5925089 | H20: Derived | I20: 淨利 ÷ EPS（公司） | J20: —
A21: EPS（基本） | B21: =B18/B20 -> 66.160628 | C21: =C18/C20 -> 15.17 | D21: =D18/D20 -> 15.28 | E21: =E18/E20 -> 18.201259 | F21: =F18/F20 -> 24.594002 | G21: =G18/G20 -> 73.246018 | H21: Derived | I21: 淨利 ÷ 股數 | J21: —
A22: 公司揭露 EPS | B22: 66.16 | C22: 15.17 | D22: 15.28 | H22: Verified | I22: FY2025：4Q25 營運報告；1Q26、2Q26：2Q26 營運報告（公司） | J22: —
A24: FY2026 錨點的檢查（參考；校準未使用券商數字）
A25: FY2026 營收年增 | B25: =G4/B4-1 -> 0.13181278
A26: FY2026 美元營收年增（各季營收 ÷ 匯率；對照公司高個位數） | B26: =(C4/fx_q1+D4/fx_q2+(E4+F4)/fx26)/co_usd25-1 -> 0.1130116
A27: FY2026 手機年增 | B27: =G5/B5-1 -> -0.16844768
A28: FY2026 智慧邊緣平台（不含 ASIC）年增 | B28: =G9/B9-1 -> 0.261065
A29: 3Q26 營收 ÷ 指引上緣 159.8 − 1 | B29: =E4/159.8-1 -> 0.051670839
A30: 4Q26 營收季增 | B30: =F4/E4-1 -> 0.22060336
A31: 檢查：FY2025 營業利益 自算 − 公司 103.470（應約為 0） | B31: =B13-103.47 -> 0
A32: 檢查：1H26 歸屬淨利 自算 − 公司 48.489（應約為 0） | B32: =C18+D18-48.489 -> 0
A33: 檢查：FY2025 歸屬淨利 自算 − 公司（應約為 0） | B33: =B18-B19 -> 0.001
A35: 檢查：分部合計 − 合併營收 | B35: =ROUND(B5+B6+B7-B4,3) -> 0 | C35: =ROUND(C5+C6+C7-C4,3) -> 0 | D35: =ROUND(D5+D6+D7-D4,3) -> 0 | E35: =ROUND(E5+E6+E7-E4,3) -> 0 | F35: =ROUND(F5+F6+F7-F4,3) -> 0 | G35: =ROUND(G5+G6+G7-G4,3) -> 0
A36: 分部原則第 3 條（2026-10-28 追加）：產品線別營收；分部宣告見 segments.json

Sheet Units
A1: Units — 聯發科 AI ASIC 規格（情境 A）。ASIC 核心售價、HBM 代購比例取自 Broadcom 模型（本專案權威，唯讀）；顆數：百萬顆（日曆年；與 HBM、台積電、Broadcom、Marvell 模型同一份）；每顆價：US$K
A3: 項目 | B3: 單位 | C3: CY2026 | D3: CY2027 | E3: CY2028 | F3: CY2029 | G3: 說明
A4: 1. Google TPU（情境 A；聯發科營收口徑＝核心售價＋代購 HBM，乘 k_x）
A5: Google TPU 市場顆數 | B5: 百萬顆 | C5: =PL!D63 -> 3.85 | D5: =PL!E63 -> 5.5 | E5: =PL!F63 -> 7 | F5: =PL!G63 -> 8.05 | G5: tsmc 成品 In 頁
A6: 聯發科份額：Google TPU | B6: % | C6: =PL!D65 -> 0.05 | D6: =PL!E65 -> 0.15 | E6: =PL!F65 -> 0.18 | F6: =PL!G65 -> 0.18 | G6: In 頁 B 節（Assumed）
A7: 聯發科顆數：Google TPU | B7: 百萬顆 | C7: =PL!D67 -> 0.1925 | D7: =PL!E67 -> 0.825 | E7: =PL!F67 -> 1.26 | F7: =PL!G67 -> 1.449 | G7: 市場層顆數 × 份額
A8: 每顆 HBM 金額：Google TPU | B8: US$K | C8: =PL!D74 -> 2.8032 | D8: =PL!E74 -> 6.57 | E8: =PL!F74 -> 8.325504 | F8: =PL!G74 -> 7.9092288 | G8: 容量 × HBM 單價（情境 A）
A9: 每顆聯發科營收（校準後）：Google TPU | B9: US$K | C9: =PL!D76*PL!$D$79 -> 10.38961 | D9: =PL!E76*PL!$D$79 -> 12.814889 | E9: =PL!F76*PL!$D$79 -> 13.945181 | F9: =PL!G76*PL!$D$79 -> 13.67716 | G9: （核心＋代購比例 × HBM）× k_x
A10: 聯發科 AI ASIC 營收（美元） | B10: US$B | C10: =PL!D80 -> 2 | D10: =PL!E80 -> 10.572283 | E10: =PL!F80 -> 17.570928 | F10: =PL!G80 -> 19.818204 | G10: 含其他 ASIC（基準份額 0）
A12: 2. 份額加總檢查（Broadcom＋Marvell＋聯發科 ≤ 100%；Broadcom、Marvell 份額讀各自成品 In 頁）
A13: Broadcom＋Marvell＋聯發科：Google TPU | B13: % | C13: =av_tpu_26+mv_tpu_26+PL!D65 -> 0.95 | D13: =av_tpu_27+mv_tpu_27+PL!E65 -> 0.95 | E13: =av_tpu_28+mv_tpu_28+PL!F65 -> 0.98 | F13: =av_tpu_28+mv_tpu_28+PL!G65 -> 0.98 | G13: 其餘為世芯、創意、華為等
A14: Broadcom＋Marvell＋聯發科：其他 ASIC（MTIA、Maia、Ascend 等） | B14: % | C14: =av_oth_26+mv_oth_26+PL!D66 -> 0.4 | D14: =av_oth_27+mv_oth_27+PL!E66 -> 0.61 | E14: =av_oth_28+mv_oth_28+PL!F66 -> 0.7 | F14: =av_oth_28+mv_oth_28+PL!G66 -> 0.7 | G14: 其餘為世芯、創意、華為等
A15: 聯發科 TPU 份額上限（1 − Broadcom − Marvell 基準） | B15: % | C15: =1-av_tpu_26-mv_tpu_26 -> 0.1 | D15: =1-av_tpu_27-mv_tpu_27 -> 0.2 | E15: =1-av_tpu_28-mv_tpu_28 -> 0.2 | F15: =1-av_tpu_28-mv_tpu_28 -> 0.2 | G15: In 頁份額高值受此上限限制
A17: 3. 校準值（只用 FY2026 已發生的實績、當季指引與公司全年資料中心說法；不用共識、不用 FY2027 起的目標）
A18: ASIC 校準係數 k_x | C18: =PL!D79 -> 1.073094 | G18: 公司 FY2026 資料中心營收 ÷ 未校準由下而上
A19: 非 ASIC 毛利率（FY2026 殘差） | C19: =PL!D98 -> 0.4623407 | G19: 讓 FY2026 毛利等於錨點
A20: FY2026 資料中心營收（公司） | C20: =dc26 -> 2 | G20: US$B
A22: 讀法：聯發科 ASIC 營收受市場層 TPU 顆數與 Broadcom、Marvell 份額共同限制；CY2028 份額上限 20%（1 − 75% − 5%）。賣方 FY2028 約 500 億美元的 ASIC 營收需要的顆數或單價遠高於此口徑（Recon 第 B 節）。

Sheet PL
A1: PL — 聯發科損益（十億新台幣；EPS 新台幣、基本；歸屬母公司）。FY2025A 實績、FY2026 錨點（三情境相同），FY2027–FY2029 由驅動因子推導，FY2030–FY2032 為收斂法。FY(t)＝CY(t)。三情境各一個完整推導區塊（本頁下方），頂端為摘要
A2: 灰底＝FY2030–FY2032 收斂法（上游顆數只到 CY2029）：營收年增線性收斂到 fade_g、淨利率線性收斂到 fade_m（In 頁 I 節），非驅動因子推導
A3: 情境／項目 | B3: 單位 | C3: FY2025A | D3: FY2026（錨點） | E3: FY2027 | F3: FY2028 | G3: FY2029 | H3: FY2030（收斂） | I3: FY2031（收斂） | J3: FY2032（收斂） | K3: 說明
A4: 情境 A
A5: 營收 | B5: NT$B | C5: =C92 -> 595.966 | D5: =D92 -> 674.52194 | E5: =E92 -> 989.79708 | F5: =F92 -> 1251.4725 | G5: =G92 -> 1363.4445 | H5: =H92 -> 1472.0403 | I5: =I92 -> 1574.8241 | J5: =J92 -> 1669.3136
A6: 營收年增 | B6: % | D6: =D93 -> 0.13181278 | E6: =E93 -> 0.46740532 | F6: =F93 -> 0.26437274 | G6: =G93 -> 0.08947221 | H6: =H93 -> 0.07964814 | I6: =I93 -> 0.06982407 | J6: =J93 -> 0.06
A7: AI ASIC | B7: NT$B | C7: =C82 -> 0 | D7: =D82 -> 64 | E7: =E82 -> 338.31306 | F7: =F82 -> 562.26971 | G7: =G82 -> 634.18254
A8: 手機 | B8: NT$B | C8: =C88 -> 315.86198 | D8: =D88 -> 262.65576 | E8: =E88 -> 275.78855 | F8: =F88 -> 286.82009 | G8: =G88 -> 298.29289
A9: 智慧邊緣平台（不含 ASIC） | B9: NT$B | C9: =C89 -> 247.32589 | D9: =D89 -> 311.89402 | E9: =E89 -> 336.84555 | F9: =F89 -> 360.42473 | G9: =G89 -> 385.65446
A10: 電源 IC | B10: NT$B | C10: =C90 -> 32.77813 | D10: =D90 -> 35.972154 | E10: =E90 -> 38.849926 | F10: =F90 -> 41.95792 | G10: =G90 -> 45.314553
A11: 毛利率 | B11: % | C11: =C100 -> 0.47499354 | D11: =D100 -> 0.45540086 | E11: =E100 -> 0.41863328 | F11: =F100 -> 0.39635029 | G11: =G100 -> 0.39598675
A12: 營業利益率 | B12: % | C12: =C103 -> 0.17361729 | D12: =D103 -> 0.17059915 | E12: =E103 -> 0.1973331 | F12: =F103 -> 0.20744089 | G12: =G103 -> 0.2121877
A13: 歸屬母公司淨利 | B13: NT$B | C13: =C108 -> 105.32 | D13: =D108 -> 116.64494 | E13: =E108 -> 182.45496 | F13: =F108 -> 237.74164 | G13: =G108 -> 263.28328 | H13: =H108 -> 284.2533 | I13: =I108 -> 304.10103 | J13: =J108 -> 322.34709
A14: 淨利率 | B14: % | C14: =C112 -> 0.17672149 | D14: =D112 -> 0.17292979 | E14: =E112 -> 0.18433573 | F14: =F112 -> 0.18996954 | G14: =G112 -> 0.19310158 | H14: =H112 -> 0.19310158 | I14: =I112 -> 0.19310158 | J14: =J112 -> 0.19310158
A15: EPS | B15: NT$ | C15: =C110 -> 66.160628 | D15: =D110 -> 73.246018 | E15: =E110 -> 114.57077 | F15: =F110 -> 149.28748 | G15: =G110 -> 165.3261 | H15: =H110 -> 178.49401 | I15: =I110 -> 190.95719 | J15: =J110 -> 202.41462
A16: EPS 年增 | B16: % | D16: =D111 -> 0.10709374 | E16: =E111 -> 0.56419106 | F16: =F111 -> 0.30301548 | G16: =G111 -> 0.10743442 | H16: =H111 -> 0.07964814 | I16: =I111 -> 0.06982407 | J16: =J111 -> 0.06
A18: 情境 B
A19: 營收 | B19: NT$B | C19: =C147 -> 595.966 | D19: =D147 -> 674.52194 | E19: =E147 -> 962.74965 | F19: =F147 -> 1038.9612 | G19: =G147 -> 1146.9657 | H19: =H147 -> 1241.7467 | I19: =I147 -> 1317.8882 | J19: =J147 -> 1370.6038
A20: 營收年增 | B20: % | D20: =D148 -> 0.13181278 | E20: =E148 -> 0.42730665 | F20: =F148 -> 0.079160253 | G20: =G148 -> 0.10395438 | H20: =H148 -> 0.082636251 | I20: =I148 -> 0.061318125 | J20: =J148 -> 0.04
A21: AI ASIC | B21: NT$B | C21: =C137 -> 0 | D21: =D137 -> 64 | E21: =E137 -> 338.31306 | F21: =F137 -> 394.80022 | G21: =G137 -> 482.39652
A22: 手機 | B22: NT$B | C22: =C143 -> 315.86198 | D22: =D143 -> 262.65576 | E22: =E143 -> 262.65576 | F22: =F143 -> 267.90888 | G22: =G143 -> 273.26705
A23: 智慧邊緣平台（不含 ASIC） | B23: NT$B | C23: =C144 -> 247.32589 | D23: =D144 -> 311.89402 | E23: =E144 -> 324.36978 | F23: =F144 -> 337.34458 | G23: =G144 -> 350.83836
A24: 電源 IC | B24: NT$B | C24: =C145 -> 32.77813 | D24: =D145 -> 35.972154 | E24: =E145 -> 37.41104 | F24: =F145 -> 38.907481 | G24: =G145 -> 40.463781
A25: 毛利率 | B25: % | C25: =C155 -> 0.47499354 | D25: =D155 -> 0.45540086 | E25: =E155 -> 0.41740536 | F25: =F155 -> 0.41793695 | G25: =G155 -> 0.4131939
A26: 營業利益率 | B26: % | C26: =C158 -> 0.17361729 | D26: =D158 -> 0.17059915 | E26: =E158 -> 0.19228835 | F26: =F158 -> 0.19681685 | G26: =G158 -> 0.20087777
A27: 歸屬母公司淨利 | B27: NT$B | C27: =C163 -> 105.32 | D27: =D163 -> 116.64494 | E27: =E163 -> 173.68797 | F27: =F163 -> 190.33715 | G27: =G163 -> 212.62393 | H27: =H163 -> 222.52123 | I27: =I163 -> 228.02216 | J27: =J163 -> 228.67365
A28: 淨利率 | B28: % | C28: =C167 -> 0.17672149 | D28: =D167 -> 0.17292979 | E28: =E167 -> 0.18040824 | F28: =F167 -> 0.18319949 | G28: =G167 -> 0.1853795 | H28: =H167 -> 0.17920018 | I28: =I167 -> 0.17302087 | J28: =J167 -> 0.16684155
A29: EPS | B29: NT$ | C29: =C165 -> 66.160628 | D29: =D165 -> 73.246018 | E29: =E165 -> 109.06562 | F29: =F165 -> 119.5203 | G29: =G165 -> 133.51506 | H29: =H165 -> 139.72997 | I29: =I165 -> 143.18423 | J29: =J165 -> 143.59333
A30: EPS 年增 | B30: % | D30: =D166 -> 0.10709374 | E30: =E166 -> 0.48903136 | F30: =F166 -> 0.09585685 | G30: =G166 -> 0.11709107 | H30: =H166 -> 0.046548376 | I30: =I166 -> 0.024720949 | J30: =J166 -> 0.0028571429
A32: 情境 C
A33: 營收 | B33: NT$B | C33: =C202 -> 595.966 | D33: =D202 -> 674.52194 | E33: =E202 -> 918.46572 | F33: =F202 -> 854.34533 | G33: =G202 -> 896.19884 | H33: =H202 -> 931.44275 | I33: =I202 -> 959.07214 | J33: =J202 -> 978.25358
A34: 營收年增 | B34: % | D34: =D203 -> 0.13181278 | E34: =E203 -> 0.36165433 | F34: =F203 -> -0.069812505 | G34: =G203 -> 0.048988991 | H34: =H203 -> 0.039325994 | I34: =I203 -> 0.029662997 | J34: =J203 -> 0.02
A35: AI ASIC | B35: NT$B | C35: =C192 -> 0 | D35: =D192 -> 64 | E35: =E192 -> 338.31306 | F35: =F192 -> 278.4166 | G35: =G192 -> 324.24631
A36: 手機 | B36: NT$B | C36: =C198 -> 315.86198 | D36: =D198 -> 262.65576 | E36: =E198 -> 241.6433 | F36: =F198 -> 234.394 | G36: =G198 -> 227.36218
A37: 智慧邊緣平台（不含 ASIC） | B37: NT$B | C37: =C199 -> 247.32589 | D37: =D199 -> 311.89402 | E37: =E199 -> 302.5372 | F37: =F199 -> 305.56257 | G37: =G199 -> 308.6182
A38: 電源 IC | B38: NT$B | C38: =C200 -> 32.77813 | D38: =D200 -> 35.972154 | E38: =E200 -> 35.972154 | F38: =F200 -> 35.972154 | G38: =G200 -> 35.972154
A39: 毛利率 | B39: % | C39: =C210 -> 0.47499354 | D39: =D210 -> 0.45540086 | E39: =E210 -> 0.4152388 | F39: =F210 -> 0.42934134 | G39: =G210 -> 0.4245193
A40: 營業利益率 | B40: % | C40: =C213 -> 0.17361729 | D40: =D213 -> 0.17059915 | E40: =E213 -> 0.18338727 | F40: =F213 -> 0.16513372 | G40: =G213 -> 0.15753835
A41: 歸屬母公司淨利 | B41: NT$B | C41: =C218 -> 105.32 | D41: =D218 -> 116.64494 | E41: =E218 -> 159.33403 | F41: =F218 -> 135.80985 | G41: =G218 -> 135.89969 | H41: =H218 -> 131.82781 | I41: =I218 -> 126.04263 | J41: =J218 -> 118.67399
A42: 淨利率 | B42: % | C42: =C222 -> 0.17672149 | D42: =D222 -> 0.17292979 | E42: =E222 -> 0.17347848 | F42: =F222 -> 0.15896365 | G42: =G222 -> 0.15164011 | H42: =H222 -> 0.14153077 | I42: =I222 -> 0.13142143 | J42: =J222 -> 0.12131209
...

Sheet Val
A1: Val — P/E 估值（新台幣）。結論用「現價 ÷ FY2027、FY2028 EPS（模型）」；目標價＝DCF 與 Comparable 加權（第 0 節）；十年 P/E 規則值（第 3 節，年底落後 P/E）只作參考
A2: 循環位置：聯發科不是設備股，不套設備市場見頂年；以本模型營收最高的會計年度為見頂年（比照 Amkor、廣達；FY(t)＝CY(t)）。營收到 FY2029 仍在增加時，見頂年未知，判為中段
A4: 0. 目標價
A5: 0.1 DCF（股東權益現金流，FY2027–FY2032 明確期＋FY2032 後永續）
A6: 項目 | B6: A（順利） | C6: B（平平） | D6: C（不如預期） | E6: 說明
A7: 情境 EPS（FY2027–FY2032） | E7: PL 頁各情境；FY2030 起為收斂法
A8: FY2027 | B8: =PL!E15 -> 114.57077 | C8: =PL!E29 -> 109.06562 | D8: =PL!E43 -> 100.05221
A9: FY2028 | B9: =PL!F15 -> 149.28748 | C9: =PL!F29 -> 119.5203 | D9: =PL!F43 -> 85.280435
A10: FY2029 | B10: =PL!G15 -> 165.3261 | C10: =PL!G29 -> 133.51506 | D10: =PL!G43 -> 85.336849
A11: FY2030 | B11: =PL!H15 -> 178.49401 | C11: =PL!H29 -> 139.72997 | D11: =PL!H43 -> 82.779952
A12: FY2031 | B12: =PL!I15 -> 190.95719 | C12: =PL!I29 -> 143.18423 | D12: =PL!I43 -> 79.147207
A13: FY2032 | B13: =PL!J15 -> 202.41462 | C13: =PL!J29 -> 143.59333 | D13: =PL!J43 -> 74.520139
A14: 股東現金流＝EPS ×（1 − tp_g ÷ tp_roe）
A15: 再投資率（tp_g ÷ tp_roe，上限 0.8） | B15: =MIN(tp_g/tp_roe,0.8) -> 0.16563147 | E15: ROE 為近三年平均（In 頁 tp_roe）
A16: FY2027 | B16: =B8*(1-$B$15) -> 95.594241 | C16: =C8*(1-$B$15) -> 91.000919 | D16: =D8*(1-$B$15) -> 83.480414
A17: FY2028 | B17: =B9*(1-$B$15) -> 124.56078 | C17: =C9*(1-$B$15) -> 99.72398 | D17: =D9*(1-$B$15) -> 71.155312
A18: FY2029 | B18: =B10*(1-$B$15) -> 137.94289 | C18: =C10*(1-$B$15) -> 111.40077 | D18: =D10*(1-$B$15) -> 71.202381
A19: FY2030 | B19: =B11*(1-$B$15) -> 148.92979 | C19: =C11*(1-$B$15) -> 116.58629 | D19: =D11*(1-$B$15) -> 69.068987
A20: FY2031 | B20: =B12*(1-$B$15) -> 159.32867 | C20: =C12*(1-$B$15) -> 119.46842 | D20: =D12*(1-$B$15) -> 66.037938
A21: FY2032 | B21: =B13*(1-$B$15) -> 168.88839 | C21: =C13*(1-$B$15) -> 119.80975 | D21: =D13*(1-$B$15) -> 62.177259
A22: DCF 情境每股價值（折現率 tp_r） | B22: =SUMPRODUCT(B16:B21,1/(1+tp_r)^{1;2;3;4;5;6})+B21*(1+tp_g)/(tp_r-tp_g)/(1+tp_r)^6 -> 2241.9102 | C22: =SUMPRODUCT(C16:C21,1/(1+tp_r)^{1;2;3;4;5;6})+C21*(1+tp_g)/(tp_r-tp_g)/(1+tp_r)^6 -> 1642.526 | D22: =SUMPRODUCT(D16:D21,1/(1+tp_r)^{1;2;3;4;5;6})+D21*(1+tp_g)/(tp_r-tp_g)/(1+tp_r)^6 -> 919.82524 | E22: Σ 明確期現金流 ÷ (1＋r)^t ＋ 永續價值 ÷ (1＋r)^6；永續價值＝FY2032 現金流 ×(1＋g)÷(r−g)；基準日 2026 年底
A23: DCF 情境價值推到 12 個月後（×(1＋tp_r)） | B23: =B22*(1+tp_r) -> 2466.1012 | C23: =C22*(1+tp_r) -> 1806.7786 | D23: =D22*(1+tp_r) -> 1011.8078
A24: DCF 目標價（情境加權） | B24: =tp_wA*B23+tp_wB*C23+tp_wC*D23 -> 1845.5812 | E24: Σ 權重 × 情境價值 ×(1＋r)；權重見 In 頁
A26: 0.2 Comparable（市場主流同業前瞻 P/E）
A27: 同業與前瞻 P/E | B27: 代號 | C27: 前瞻 12 月 P/E | D27: 日期 | E27: 來源 | F27: 標記
A28: 高通（Qualcomm） | B28: QCOM | C28: 18.98 | D28: 2026-10-23 | E28: stockanalysis.com forward PE（分析師共識；價格日期如左） | F28: Interested-party
A29: 博通（Broadcom） | B29: AVGO | C29: 18.52 | D29: 2026-10-23 | E29: stockanalysis.com forward PE（分析師共識；價格日期如左） | F29: Interested-party
A30: 邁威爾（Marvell） | B30: MRVL | C30: 40.44 | D30: 2026-10-23 | E30: stockanalysis.com forward PE（分析師共識；價格日期如左） | F30: Interested-party
A31: 世芯-KY（Alchip） | B31: 3661.TW | C31: 17.15 | D31: 2026-10-22 | E31: stockanalysis.com forward PE（分析師共識；價格日期如左） | F31: Interested-party
A32: 創意（GUC） | B32: 3443.TW | C32: 102.85 | D32: 2026-10-08 | E32: stockanalysis.com forward PE（分析師共識；價格日期如左） | F32: Interested-party
A33: 同業前瞻 P/E 中位數 | B33: =MEDIAN(C28:C32) -> 18.98 | E33: 手機 SoC（高通）＋ASIC 設計（博通、邁威爾、世芯、創意）；不含 A 股（非 A 股公司，Andy 2026-10-25 11:53）
A34: 12 個月後的前瞻 EPS（情境加權） | B34: =tp_wA*(2/12*B8+10/12*B9)+tp_wB*(2/12*C8+10/12*C9)+tp_wC*(2/12*D8+10/12*D9) -> 119.48782 | E34: 約 2027-10 時的未來 12 月 EPS ≈ 2／12 × FY2027＋10／12 × FY2028（會計年度＝日曆年）
A35: Comparable 目標價 | B35: =B33*B34 -> 2267.8788 | E35: 同業中位數 × 前瞻 EPS
A37: 0.3 結論
A38: 項目 | B38: 數值 | E38: 說明
A39: 目標價（DCF 與 Comparable 加權） | B39: =tp_w_dcf*B24+(1-tp_w_dcf)*B35 -> 2056.73 | E39: tp_w_dcf × DCF＋（1 − tp_w_dcf）× Comparable；tp_w_dcf 見 In 頁
A40: Comparable 目標價（市場主流同業法） | B40: =B35 -> 2267.8788
A41: 市場共識目標價 | B41: =cons_tp -> 6067 | E41: stockanalysis：28 位分析師平均 6,067（中位數 5,861），2026-10-23 擷取
A42: 上檔空間：加權目標價 | B42: =B39/px-1 -> -0.48709975 | E42: 現價＝In 頁 px（2026-10-22 收盤）
A43: 上檔空間：Comparable 目標價 | B43: =B40/px-1 -> -0.4344442
...

Sheet Recon
A1: Recon — 本模型 vs 公司指引與目標、共識、券商。只作事後對照，不為對上數字而調參數。公司 FY2027 SAM 份額目標與券商 FY2027–28 估計為 Interested-party，不用於校準
A3: 項目 | B3: 對照值 | C3: 模型 A | D3: 差距 A | E3: 模型 B | F3: 差距 B | G3: 模型 C | H3: 差距 C | I3: 對照來源 | J3: 說明
A4: A. FY2026 錨點 vs 公司展望與共識
A5: FY2026 營收 vs 共識 | B5: =cons_rev26 -> 662.3 | C5: =PL!D92 -> 674.52194 | D5: =C5/B5-1 -> 0.018453779 | E5: =PL!D147 -> 674.52194 | F5: =E5/B5-1 -> 0.018453779 | G5: =PL!D202 -> 674.52194 | H5: =G5/B5-1 -> 0.018453779 | I5: stockanalysis（25 位） | J5: 凱基 678.0；3Q26 營收已超過指引上緣 5%
A6: FY2026 EPS vs 共識 | B6: =cons_eps26 -> 68.27 | C6: =PL!D110 -> 73.246018 | D6: =C6/B6-1 -> 0.072887323 | E6: =PL!D165 -> 73.246018 | F6: =E6/B6-1 -> 0.072887323 | G6: =PL!D220 -> 73.246018 | H6: =G6/B6-1 -> 0.072887323 | I6: stockanalysis（25 位） | J6: 共識區間 58.48–73.35
A7: FY2026 美元營收年增 vs 公司高個位數（百分點） | B7: =co_g26 -> 0.09 | C7: =Q!B26 -> 0.1130116 | D7: =C7-B7 -> 0.0230116 | E7: =Q!B26 -> 0.1130116 | F7: =E7-B7 -> 0.0230116 | G7: =Q!B26 -> 0.1130116 | H7: =G7-B7 -> 0.0230116 | I7: 2Q26 講稿 | J7: 3Q26 營收超出指引、4Q26 ASIC 量產
A8: B. AI ASIC vs 公司目標與賣方（市場層顆數 × 份額口徑）
A9: FY2027 ASIC（美元）vs 公司 SAM × 份額目標中點（80 × 17.5%） | B9: =co_sam27*co_sh27 -> 14 | C9: =PL!E80 -> 10.572283 | D9: =C9/B9-1 -> -0.24483692 | E9: =PL!E135 -> 10.572283 | F9: =E9/B9-1 -> -0.24483692 | G9: =PL!E190 -> 10.572283 | H9: =G9/B9-1 -> -0.24483692 | I9: 2Q26 講稿 | J9: 目標區間 12–16（US$B）；份額目標的分母為 SAM，不是 TPU 顆數
A10: FY2027 ASIC（美元）vs 高盛 120–160 億美元中點 | B10: =ss_asic27 -> 14 | C10: =PL!E80 -> 10.572283 | D10: =C10/B10-1 -> -0.24483692 | E10: =PL!E135 -> 10.572283 | F10: =E10/B10-1 -> -0.24483692 | G10: =PL!E190 -> 10.572283 | H10: =G10/B10-1 -> -0.24483692 | I10: 經濟日報 2026-08-03
A11: FY2027 ASIC ÷ 營收 vs 公司「20% 可能」（百分點） | B11: =co_dc27sh -> 0.2 | C11: =PL!E94 -> 0.34180042 | D11: =C11-B11 -> 0.14180042 | E11: =PL!E149 -> 0.35140295 | F11: =E11-B11 -> 0.15140295 | G11: =PL!E204 -> 0.36834588 | H11: =G11-B11 -> 0.16834588 | I11: 4Q25 法說
A12: FY2028 ASIC（美元）vs 凱基 500 億美元 | B12: =ss_asic28 -> 50 | C12: =PL!F80 -> 17.570928 | D12: =C12/B12-1 -> -0.64858143 | E12: =PL!F135 -> 12.337507 | F12: =E12/B12-1 -> -0.75324986 | G12: =PL!F190 -> 8.7005186 | H12: =G12/B12-1 -> -0.82598963 | I12: 凱基 2026-07-23 | J12: 差距為本模型最大的口徑問題（見下兩列）
A13: FY2028：達到凱基 ASIC 所需聯發科顆數（＝500 億 ÷ 模型每顆營收） | C13: =ss_asic28/PL!F86 -> 3.5854679 | E13: =ss_asic28/PL!F141 -> 4.0851041 | G13: =ss_asic28/PL!F196 -> 4.3445686 | I13: 推導 | J13: 百萬顆；凱基假設 v9 Humufish 400 萬顆
A14: FY2028：所需顆數 ÷ 市場層 TPU 顆數 | C14: =ss_asic28/PL!F86/PL!F63 -> 0.5122097 | E14: =ss_asic28/PL!F141/PL!F118 -> 0.72948288 | G14: =ss_asic28/PL!F196/PL!F173 -> 1.0344211 | I14: 推導 | J14: >（1 − Broadcom 75% − Marvell 5%）＝ 20% 即與 avgo 份額口徑衝突
A15: FY2028：凱基顆數下所需每顆營收（＝500 億 ÷ 400 萬顆）÷ 模型每顆營收 | C15: =ss_asic28/ss_hu28/PL!F86 -> 0.89636698 | E15: =ss_asic28/ss_hu28/PL!F141 -> 1.021276 | G15: =ss_asic28/ss_hu28/PL!F196 -> 1.0861421 | I15: 推導 | J15: 倍數；凱基稱 v9 單價至少 +200%
A16: C. EPS vs 券商（校準未使用）
A17: FY2027 EPS vs 凱基 | B17: =kgi_eps27 -> 112.6 | C17: =PL!E110 -> 114.57077 | D17: =C17/B17-1 -> 0.017502359 | E17: =PL!E165 -> 109.06562 | F17: =E17/B17-1 -> -0.031388834 | G17: =PL!E220 -> 100.05221 | H17: =G17/B17-1 -> -0.11143687 | I17: 凱基 2026-07-23
A18: FY2027 EPS vs Citi | B18: =citi_eps27 -> 133.87 | C18: =PL!E110 -> 114.57077 | D18: =C18/B18-1 -> -0.144164 | E18: =PL!E165 -> 109.06562 | F18: =E18/B18-1 -> -0.18528709 | G18: =PL!E220 -> 100.05221 | H18: =G18/B18-1 -> -0.25261666 | I18: 經濟日報 2026-08-03
A19: FY2028 EPS vs 凱基 | B19: =kgi_eps28 -> 246.6 | C19: =PL!F110 -> 149.28748 | D19: =C19/B19-1 -> -0.39461686 | E19: =PL!F165 -> 119.5203 | F19: =E19/B19-1 -> -0.51532724 | G19: =PL!F220 -> 85.280435 | H19: =G19/B19-1 -> -0.65417504 | I19: 凱基 2026-07-23 | J19: 差距 >30%：見 README
A20: FY2028 EPS vs Citi | B20: =citi_eps28 -> 260.38 | C20: =PL!F110 -> 149.28748 | D20: =C20/B20-1 -> -0.42665534 | E20: =PL!F165 -> 119.5203 | F20: =E20/B20-1 -> -0.5409774 | G20: =PL!F220 -> 85.280435 | H20: =G20/B20-1 -> -0.67247701 | I20: 經濟日報 2026-08-03
A21: FY2027 營收 vs 凱基 | B21: =kgi_rev27 -> 1110.805 | C21: =PL!E92 -> 989.79708 | D21: =C21/B21-1 -> -0.10893714 | E21: =PL!E147 -> 962.74965 | F21: =E21/B21-1 -> -0.13328654 | G21: =PL!E202 -> 918.46572 | H21: =G21/B21-1 -> -0.17315306 | I21: 凱基 2026-07-23
A22: 共識前瞻 12 月 EPS vs 模型（情境加權 2／12 × FY2027＋10／12 × FY2028） | B22: =cons_feps -> 103.48387 | C22: =Val!B34 -> 119.48782 | D22: =C22/B22-1 -> 0.15465159 | E22: =Val!B34 -> 119.48782 | F22: =E22/B22-1 -> 0.15465159 | G22: =Val!B34 -> 119.48782 | H22: =G22/B22-1 -> 0.15465159 | I22: stockanalysis 前瞻 P/E 推得 | J22: 三欄同值（情境加權）
A23: D. 校準與份額
A24: k_x（ASIC 校準係數） | C24: =PL!D79 -> 1.073094 | E24: =PL!D134 -> 1.073094 | G24: =PL!D189 -> 1.073094 | I24: 公司 FY2026 資料中心 ÷ 未校準 | J24: 接近 1＝市場層 TPU 顆數 × 5% × Broadcom 模型單價與公司說法一致
A25: 非 ASIC 毛利率（FY2026 殘差） | C25: =PL!D98 -> 0.4623407 | E25: =PL!D153 -> 0.4623407 | G25: =PL!D208 -> 0.4623407 | I25: FY2026 毛利殘差 | J25: FY2025 47.5%（全部非 ASIC）
A26: CY2028 Broadcom＋Marvell＋聯發科 TPU 份額 | B26: 1 | C26: =Units!E13 -> 0.98 | D26: =C26-B26 -> -0.02 | E26: =Units!E13 -> 0.98 | F26: =E26-B26 -> -0.02 | G26: =Units!E13 -> 0.98 | H26: =G26-B26 -> -0.02 | I26: avgo、mrvl 成品 | J26: 應 ≤ 100%
A27: FY2027 營業利益率 vs 高盛 22%（百分點） | B27: 0.22 | C27: =PL!E103 -> 0.1973331 | D27: =C27-B27 -> -0.0226669 | E27: =PL!E158 -> 0.19228835 | F27: =E27-B27 -> -0.027711648 | G27: =PL!E213 -> 0.18338727 | H27: =G27-B27 -> -0.036612729 | I27: 經濟日報 2026-05-03
A28: FY2028 營業利益率 vs 高盛 33%（百分點） | B28: 0.33 | C28: =PL!F103 -> 0.20744089 | D28: =C28-B28 -> -0.12255911 | E28: =PL!F158 -> 0.19681685 | F28: =E28-B28 -> -0.13318315 | G28: =PL!F213 -> 0.16513372 | H28: =G28-B28 -> -0.16486628 | I28: 經濟日報 2026-05-03
A29: E. 預留
A30: R4 產業部署路徑（markets/deploy_path/，尚未建立）：上線後以聯發科 ASIC 營收 ÷ 部署 GW 對照 Tokenomics 非 NVIDIA 加速器比例 | J30: 預留列：本版無數值

Sheet Sens
A1: Sens — 一次動一個輸入（情境 A；FY2026 恆等於錨點，k_x 與非 ASIC 毛利率在每個案例內重算）：對 FY2027、FY2028 營收、毛利率與 EPS 的影響。每個案例是一個完整推導區塊（本頁下方）
A3: 案例 | B3: 設定 | C3: FY2027 營收 | D3: FY2027 毛利率 | E3: FY2027 EPS | F3: FY2027 EPS 相對基準 | G3: FY2028 營收 | H3: FY2028 毛利率 | I3: FY2028 EPS | J3: FY2028 EPS 相對基準
A4: 基準（情境 A） | B4: PL 區塊 A | C4: =PL!E92 -> 989.79708 | D4: =PL!E100 -> 0.41863328 | E4: =PL!E110 -> 114.57077 | F4: =E4/E$4-1 -> 0 | G4: =PL!F92 -> 1251.4725 | H4: =PL!F100 -> 0.39635029 | I4: =PL!F110 -> 149.28748 | J4: =I4/I$4-1 -> 0
A5: TPU 份額 −5pt | B5: CY2027 起聯發科占 TPU −5 個百分點 | C5: =E72 -> 877.02606 | D5: =E80 -> 0.42945572 | E5: =E90 -> 99.405189 | F5: =E5/E$4-1 -> -0.13236864 | G5: =F72 -> 1095.2864 | H5: =F80 -> 0.40788476 | I5: =F90 -> 128.82195 | J5: =I5/I$4-1 -> -0.13708809
A6: TPU 份額取高值（上限） | B6: CY2027 20%、CY2028 起 20% | C6: =E127 -> 1102.5681 | D6: =E135 -> 0.41002468 | E6: =E145 -> 129.73634 | F6: =E6/E$4-1 -> 0.13236864 | G6: =F127 -> 1313.9469 | H6: =F135 -> 0.39250431 | I6: =F145 -> 156.69943 | J6: =I6/I$4-1 -> 0.049648835
A7: ASIC 顆數 ×0.8 | B7: CY2027 起聯發科顆數 ×0.8 | C7: =E182 -> 922.13447 | D7: =E190 -> 0.4248091 | E7: =E200 -> 105.47142 | F7: =E7/E$4-1 -> -0.079421183 | G7: =F182 -> 1139.0185 | H7: =F190 -> 0.40433625 | I7: =F200 -> 134.50755 | J7: =I7/I$4-1 -> -0.099003123
A8: ASIC 顆數 ×1.2 | B8: ×1.2（超出份額上限，僅示意） | C8: =E237 -> 1057.4597 | D8: =E245 -> 0.41324779 | E8: =E255 -> 123.67011 | F8: =E8/E$4-1 -> 0.079421183 | G8: =F237 -> 1363.9264 | H8: =F245 -> 0.3896812 | I8: =F255 -> 164.14875 | J8: =I8/I$4-1 -> 0.099547971
A9: 第二顆 ASIC 單價 ×2 | B9: CY2028 起核心售價 ×2（賣方：新世代單價數倍） | C9: =E292 -> 989.79708 | D9: =E300 -> 0.41863328 | E9: =E310 -> 114.57077 | F9: =E9/E$4-1 -> 0 | G9: =F292 -> 1597.6097 | H9: =F300 -> 0.40797401 | I9: =F310 -> 220.99335 | J9: =I9/I$4-1 -> 0.48032073
A10: 核心售價 ×0.8 | B10: CY2028 起 ×0.8 | C10: =E347 -> 989.79708 | D10: =E355 -> 0.41863328 | E10: =E365 -> 114.57077 | F10: =E10/E$4-1 -> 0 | G10: =F347 -> 1182.245 | H10: =F355 -> 0.39320879 | I10: =F365 -> 134.74871 | J10: =I10/I$4-1 -> -0.097387772
A11: 其他 ASIC 份額 +5pt | B11: CY2027 起第二客戶（基準 0） | C11: =E402 -> 1060.5203 | D11: =E410 -> 0.41268375 | E11: =E420 -> 123.88889 | F11: =E11/E$4-1 -> 0.081330717 | G11: =F402 -> 1340.2062 | H11: =F410 -> 0.39018088 | I11: =F420 -> 160.31659 | J11: =I11/I$4-1 -> 0.073878316
A12: HBM 代購比例 低 | B12: 代購比例取低值（k_x 重算） | C12: =E457 -> 960.82858 | D12: =E465 -> 0.43413753 | E12: =E475 -> 117.40312 | F12: =E12/E$4-1 -> 0.02472146 | G12: =F457 -> 1186.6104 | H12: =F465 -> 0.42058582 | I12: =F475 -> 153.40825 | J12: =I12/I$4-1 -> 0.027602922
A13: HBM 代購比例 高 | B13: 代購比例取高值 | C13: =E512 -> 1021.4062 | D13: =E520 -> 0.40271911 | E13: =E530 -> 111.48023 | F13: =E13/E$4-1 -> -0.026974901 | G13: =F512 -> 1322.2468 | H13: =F520 -> 0.37261832 | I13: =F530 -> 144.83252 | J13: =I13/I$4-1 -> -0.029841499
A14: ASIC 核心毛利率 35% | B14: 基準 45% | C14: =E567 -> 989.79708 | D14: =E575 -> 0.40143709 | E14: =E585 -> 105.37909 | F14: =E14/E$4-1 -> -0.08022709 | G14: =F567 -> 1251.4725 | H14: =F575 -> 0.37346206 | I14: =F585 -> 133.81891 | J14: =I14/I$4-1 -> -0.103616
A15: ASIC 核心毛利率 55% | C15: =E622 -> 989.79708 | D15: =E630 -> 0.43582946 | E15: =E640 -> 123.76244 | F15: =E15/E$4-1 -> 0.08022709 | G15: =F622 -> 1251.4725 | H15: =F630 -> 0.41923853 | I15: =F640 -> 164.75605 | J15: =I15/I$4-1 -> 0.103616
A16: 手機 情境 C 路徑 | B16: FY2027 −8%、之後 −3% | C16: =E677 -> 955.65183 | D16: =E685 -> 0.41707162 | E16: =E695 -> 107.62095 | F16: =E16/E$4-1 -> -0.060659581 | G16: =F677 -> 1199.0464 | H16: =F685 -> 0.39346499 | I16: =F695 -> 138.23736 | J16: =I16/I$4-1 -> -0.074019068
A17: 智慧邊緣 情境 C 路徑 | B17: FY2027 −3%、之後 +1% | C17: =E732 -> 955.48874 | D17: =E740 -> 0.41706389 | E17: =E750 -> 107.58776 | F17: =E17/E$4-1 -> -0.06094932 | G17: =F732 -> 1196.6103 | H17: =F740 -> 0.39332477 | I17: =F750 -> 137.719 | J17: =I17/I$4-1 -> -0.077491323
A18: 非 ASIC 毛利率 −2pt | B18: FY2027 起 | C18: =E787 -> 989.79708 | D18: =E795 -> 0.40546929 | E18: =E805 -> 107.53437 | F18: =E18/E$4-1 -> -0.061415293 | G18: =F787 -> 1251.4725 | H18: =F795 -> 0.38533603 | I18: =F805 -> 141.8437 | J18: =I18/I$4-1 -> -0.049862056
A19: 營業費用彈性 0.6 | B19: 基準 0.3 | C19: =E842 -> 989.79708 | D19: =E850 -> 0.41863328 | E19: =E860 -> 100.02388 | F19: =E19/E$4-1 -> -0.1269686 | G19: =F842 -> 1251.4725 | H19: =F850 -> 0.39635029 | I19: =F860 -> 123.05139 | J19: =I19/I$4-1 -> -0.17574207
A20: 營業費用率 +2pt | B20: 營業費用額外 +2% × 營收 | C20: =E897 -> 989.79708 | D20: =E905 -> 0.41863328 | E20: =E915 -> 103.8804 | F20: =E20/E$4-1 -> -0.093308011 | G20: =F897 -> 1251.4725 | H20: =F905 -> 0.39635029 | I20: =F915 -> 124.23263 | J20: =I20/I$4-1 -> -0.16782958
A21: 匯率 30 | B21: 基準 32（ASIC 美元營收換算） | C21: =E952 -> 968.65252 | D21: =E960 -> 0.42047054 | E21: =E970 -> 111.72722 | F21: =E21/E$4-1 -> -0.02481912 | G21: =F952 -> 1216.3306 | H21: =F960 -> 0.39868728 | I21: =F970 -> 144.65922 | J21: =I21/I$4-1 -> -0.031002371
A22: 稅率 17% | B22: 基準 14% | C22: =E1007 -> 989.79708 | D22: =E1015 -> 0.41863328 | E22: =E1025 -> 110.55221 | F22: =E22/E$4-1 -> -0.035074912 | G22: =F1007 -> 1251.4725 | H22: =F1015 -> 0.39635029 | I22: =F1025 -> 144.05787 | J22: =I22/I$4-1 -> -0.03503045
A23: 營業外 10 | B23: 基準 18 | C23: =E1062 -> 989.79708 | D23: =E1070 -> 0.41863328 | E23: =E1080 -> 110.25054 | F23: =E23/E$4-1 -> -0.037707935 | G23: =F1062 -> 1251.4725 | H23: =F1070 -> 0.39635029 | I23: =F1080 -> 144.96725 | J23: =I23/I$4-1 -> -0.028938977
A24: 情境 B | B24: CY2028 顆數 ×0.8、CY2029 ×0.85；非 ASIC 成長較低 | C24: =PL!E147 -> 962.74965 | D24: =PL!E155 -> 0.41740536 | E24: =PL!E165 -> 109.06562 | F24: =E24/E$4-1 -> -0.048050201 | G24: =PL!F147 -> 1038.9612 | H24: =PL!F155 -> 0.41793695 | I24: =PL!F165 -> 119.5203 | J24: =I24/I$4-1 -> -0.199395
A25: 情境 C | B25: CY2028–29 顆數 ×0.6；手機 −8% | C25: =PL!E202 -> 918.46572 | D25: =PL!E210 -> 0.4152388 | E25: =PL!E220 -> 100.05221 | F25: =E25/E$4-1 -> -0.12672131 | G25: =PL!F202 -> 854.34533 | H25: =PL!F210 -> 0.42934134 | I25: =PL!F220 -> 85.280435 | J25: =I25/I$4-1 -> -0.42875026
A27: 讀法：FY2027 三情境只差非 ASIC 成長率；顆數情境 B、C 的差異從 FY2028 起。TPU 份額高值受 Broadcom、Marvell 份額上限限制；第二顆 ASIC 單價 ×2 是賣方路徑的主要差異來源。
A29: 目標價參數（只改 DCF 參數；PL 收斂法的 fade_g 不隨 tp_g 變動）
A30: 案例 | B30: 設定 | C30: DCF 目標價 | D30: Comparable 目標價 | E30: 加權目標價 | F30: 相對基準
A31: 基準 | B31: r 10%、g 4%、DCF 權重 0.5 | C31: =(tp_wA*(Val!B8*(1-MIN(tp_g/tp_roe,0.8))/(1+tp_r)^1+Val!B9*(1-MIN(tp_g/tp_roe,0.8))/(1+tp_r)^2+Val!B10*(1-MIN(tp_g/tp_roe,0.8))/(1+tp_r)^3+Val!B11*(1-MIN(tp_g/tp_roe,0.8))/(1+tp_r)^4+Val!B12*(1-MIN(tp_g/tp_roe,0.8))/(1+tp_r)^5+Val!B13*(1-MIN(tp_g/tp_roe,0.8))/(1+tp_r)^6+Val!B13*(1-MIN(tp_g/tp_roe,0.8))*(1+tp_g)/(tp_r-tp_g)/(1+tp_r)^6)+tp_wB*(Val!C8*(1-MIN(tp_g/tp_roe,0.8))/(1+tp_r)^1+Val!C9*(1-MIN(tp_g/tp_roe,0.8))/(1+tp_r)^2+Val!C10*(1-MIN(tp_g/tp_roe,0.8))/(1+tp_r)^3+Val!C11*(1-MIN(tp_g/tp_roe,0.8))/(1+tp_r)^4+Val!C12*(1-MIN(tp_g/tp_roe,0.8))/(1+tp_r)^5+Val!C13*(1-MIN(tp_g/tp_roe,0.8))/(1+tp_r)^6+Val!C13*(1-MIN(tp_g/tp_roe,0.8))*(1+tp_g)/(tp_r-tp_g)/(1+tp_r)^6)+tp_wC*(Val!D8*(1-MIN(tp_g/tp_roe,0.8))/(1+tp_r)^1+Val!D9*(1-MIN(tp_g/tp_roe,0.8))/(1+tp_r)^2+Val!D10*(1-MIN(tp_g/tp_roe,0.8))/(1+tp_r)^3+Val!D11*(1-MIN(tp_g/tp_roe,0.8))/(1+tp_r)^4+Val!D12*(1-MIN(tp_g/tp_roe,0.8))/(1+tp_r)^5+Val!D13*(1-MIN(tp_g/tp_roe,0.8))/(1+tp_r)^6+Val!D13*(1-MIN(tp_g/tp_roe,0.8))*(1+tp_g)/(tp_r-tp_g)/(1+tp_r)^6))*(1+tp_r) -> 1845.5812 | D31: =Val!B35 -> 2267.8788 | E31: =tp_w_dcf*C31+(1-tp_w_dcf)*D31 -> 2056.73 | F31: =E31/E$31-1 -> 0
A32: 折現率 +1pt | B32: r 11% | C32: =(tp_wA*(Val!B8*(1-MIN(tp_g/tp_roe,0.8))/(1+(tp_r+0.01))^1+Val!B9*(1-MIN(tp_g/tp_roe,0.8))/(1+(tp_r+0.01))^2+Val!B10*(1-MIN(tp_g/tp_roe,0.8))/(1+(tp_r+0.01))^3+Val!B11*(1-MIN(tp_g/tp_roe,0.8))/(1+(tp_r+0.01))^4+Val!B12*(1-MIN(tp_g/tp_roe,0.8))/(1+(tp_r+0.01))^5+Val!B13*(1-MIN(tp_g/tp_roe,0.8))/(1+(tp_r+0.01))^6+Val!B13*(1-MIN(tp_g/tp_roe,0.8))*(1+tp_g)/((tp_r+0.01)-tp_g)/(1+(tp_r+0.01))^6)+tp_wB*(Val!C8*(1-MIN(tp_g/tp_roe,0.8))/(1+(tp_r+0.01))^1+Val!C9*(1-MIN(tp_g/tp_roe,0.8))/(1+(tp_r+0.01))^2+Val!C10*(1-MIN(tp_g/tp_roe,0.8))/(1+(tp_r+0.01))^3+Val!C11*(1-MIN(tp_g/tp_roe,0.8))/(1+(tp_r+0.01))^4+Val!C12*(1-MIN(tp_g/tp_roe,0.8))/(1+(tp_r+0.01))^5+Val!C13*(1-MIN(tp_g/tp_roe,0.8))/(1+(tp_r+0.01))^6+Val!C13*(1-MIN(tp_g/tp_roe,0.8))*(1+tp_g)/((tp_r+0.01)-tp_g)/(1+(tp_r+0.01))^6)+tp_wC*(Val!D8*(1-MIN(tp_g/tp_roe,0.8))/(1+(tp_r+0.01))^1+Val!D9*(1-MIN(tp_g/tp_roe,0.8))/(1+(tp_r+0.01))^2+Val!D10*(1-MIN(tp_g/tp_roe,0.8))/(1+(tp_r+0.01))^3+Val!D11*(1-MIN(tp_g/tp_roe,0.8))/(1+(tp_r+0.01))^4+Val!D12*(1-MIN(tp_g/tp_roe,0.8))/(1+(tp_r+0.01))^5+Val!D13*(1-MIN(tp_g/tp_roe,0.8))/(1+(tp_r+0.01))^6+Val!D13*(1-MIN(tp_g/tp_roe,0.8))*(1+tp_g)/((tp_r+0.01)-tp_g)/(1+(tp_r+0.01))^6))*(1+(tp_r+0.01)) -> 1595.1113 | D32: =Val!B35 -> 2267.8788 | E32: =tp_w_dcf*C32+(1-tp_w_dcf)*D32 -> 1931.495 | F32: =E32/E$31-1 -> -0.060890319
A33: 折現率 −1pt | B33: r 9% | C33: =(tp_wA*(Val!B8*(1-MIN(tp_g/tp_roe,0.8))/(1+(tp_r-0.01))^1+Val!B9*(1-MIN(tp_g/tp_roe,0.8))/(1+(tp_r-0.01))^2+Val!B10*(1-MIN(tp_g/tp_roe,0.8))/(1+(tp_r-0.01))^3+Val!B11*(1-MIN(tp_g/tp_roe,0.8))/(1+(tp_r-0.01))^4+Val!B12*(1-MIN(tp_g/tp_roe,0.8))/(1+(tp_r-0.01))^5+Val!B13*(1-MIN(tp_g/tp_roe,0.8))/(1+(tp_r-0.01))^6+Val!B13*(1-MIN(tp_g/tp_roe,0.8))*(1+tp_g)/((tp_r-0.01)-tp_g)/(1+(tp_r-0.01))^6)+tp_wB*(Val!C8*(1-MIN(tp_g/tp_roe,0.8))/(1+(tp_r-0.01))^1+Val!C9*(1-MIN(tp_g/tp_roe,0.8))/(1+(tp_r-0.01))^2+Val!C10*(1-MIN(tp_g/tp_roe,0.8))/(1+(tp_r-0.01))^3+Val!C11*(1-MIN(tp_g/tp_roe,0.8))/(1+(tp_r-0.01))^4+Val!C12*(1-MIN(tp_g/tp_roe,0.8))/(1+(tp_r-0.01))^5+Val!C13*(1-MIN(tp_g/tp_roe,0.8))/(1+(tp_r-0.01))^6+Val!C13*(1-MIN(tp_g/tp_roe,0.8))*(1+tp_g)/((tp_r-0.01)-tp_g)/(1+(tp_r-0.01))^6)+tp_wC*(Val!D8*(1-MIN(tp_g/tp_roe,0.8))/(1+(tp_r-0.01))^1+Val!D9*(1-MIN(tp_g/tp_roe,0.8))/(1+(tp_r-0.01))^2+Val!D10*(1-MIN(tp_g/tp_roe,0.8))/(1+(tp_r-0.01))^3+Val!D11*(1-MIN(tp_g/tp_roe,0.8))/(1+(tp_r-0.01))^4+Val!D12*(1-MIN(tp_g/tp_roe,0.8))/(1+(tp_r-0.01))^5+Val!D13*(1-MIN(tp_g/tp_roe,0.8))/(1+(tp_r-0.01))^6+Val!D13*(1-MIN(tp_g/tp_roe,0.8))*(1+tp_g)/((tp_r-0.01)-tp_g)/(1+(tp_r-0.01))^6))*(1+(tp_r-0.01)) -> 2196.1962 | D33: =Val!B35 -> 2267.8788 | E33: =tp_w_dcf*C33+(1-tp_w_dcf)*D33 -> 2232.0375 | F33: =E33/E$31-1 -> 0.085236027
A34: 長期成長 +1pt | B34: g 5% | C34: =(tp_wA*(Val!B8*(1-MIN((tp_g+0.01)/tp_roe,0.8))/(1+tp_r)^1+Val!B9*(1-MIN((tp_g+0.01)/tp_roe,0.8))/(1+tp_r)^2+Val!B10*(1-MIN((tp_g+0.01)/tp_roe,0.8))/(1+tp_r)^3+Val!B11*(1-MIN((tp_g+0.01)/tp_roe,0.8))/(1+tp_r)^4+Val!B12*(1-MIN((tp_g+0.01)/tp_roe,0.8))/(1+tp_r)^5+Val!B13*(1-MIN((tp_g+0.01)/tp_roe,0.8))/(1+tp_r)^6+Val!B13*(1-MIN((tp_g+0.01)/tp_roe,0.8))*(1+(tp_g+0.01))/(tp_r-(tp_g+0.01))/(1+tp_r)^6)+tp_wB*(Val!C8*(1-MIN((tp_g+0.01)/tp_roe,0.8))/(1+tp_r)^1+Val!C9*(1-MIN((tp_g+0.01)/tp_roe,0.8))/(1+tp_r)^2+Val!C10*(1-MIN((tp_g+0.01)/tp_roe,0.8))/(1+tp_r)^3+Val!C11*(1-MIN((tp_g+0.01)/tp_roe,0.8))/(1+tp_r)^4+Val!C12*(1-MIN((tp_g+0.01)/tp_roe,0.8))/(1+tp_r)^5+Val!C13*(1-MIN((tp_g+0.01)/tp_roe,0.8))/(1+tp_r)^6+Val!C13*(1-MIN((tp_g+0.01)/tp_roe,0.8))*(1+(tp_g+0.01))/(tp_r-(tp_g+0.01))/(1+tp_r)^6)+tp_wC*(Val!D8*(1-MIN((tp_g+0.01)/tp_roe,0.8))/(1+tp_r)^1+Val!D9*(1-MIN((tp_g+0.01)/tp_roe,0.8))/(1+tp_r)^2+Val!D10*(1-MIN((tp_g+0.01)/tp_roe,0.8))/(1+tp_r)^3+Val!D11*(1-MIN((tp_g+0.01)/tp_roe,0.8))/(1+tp_r)^4+Val!D12*(1-MIN((tp_g+0.01)/tp_roe,0.8))/(1+tp_r)^5+Val!D13*(1-MIN((tp_g+0.01)/tp_roe,0.8))/(1+tp_r)^6+Val!D13*(1-MIN((tp_g+0.01)/tp_roe,0.8))*(1+(tp_g+0.01))/(tp_r-(tp_g+0.01))/(1+tp_r)^6))*(1+tp_r) -> 2020.1419 | D34: =Val!B35 -> 2267.8788 | E34: =tp_w_dcf*C34+(1-tp_w_dcf)*D34 -> 2144.0103 | F34: =E34/E$31-1 -> 0.042436457
A35: 長期成長 −1pt | B35: g 3% | C35: =(tp_wA*(Val!B8*(1-MIN((tp_g-0.01)/tp_roe,0.8))/(1+tp_r)^1+Val!B9*(1-MIN((tp_g-0.01)/tp_roe,0.8))/(1+tp_r)^2+Val!B10*(1-MIN((tp_g-0.01)/tp_roe,0.8))/(1+tp_r)^3+Val!B11*(1-MIN((tp_g-0.01)/tp_roe,0.8))/(1+tp_r)^4+Val!B12*(1-MIN((tp_g-0.01)/tp_roe,0.8))/(1+tp_r)^5+Val!B13*(1-MIN((tp_g-0.01)/tp_roe,0.8))/(1+tp_r)^6+Val!B13*(1-MIN((tp_g-0.01)/tp_roe,0.8))*(1+(tp_g-0.01))/(tp_r-(tp_g-0.01))/(1+tp_r)^6)+tp_wB*(Val!C8*(1-MIN((tp_g-0.01)/tp_roe,0.8))/(1+tp_r)^1+Val!C9*(1-MIN((tp_g-0.01)/tp_roe,0.8))/(1+tp_r)^2+Val!C10*(1-MIN((tp_g-0.01)/tp_roe,0.8))/(1+tp_r)^3+Val!C11*(1-MIN((tp_g-0.01)/tp_roe,0.8))/(1+tp_r)^4+Val!C12*(1-MIN((tp_g-0.01)/tp_roe,0.8))/(1+tp_r)^5+Val!C13*(1-MIN((tp_g-0.01)/tp_roe,0.8))/(1+tp_r)^6+Val!C13*(1-MIN((tp_g-0.01)/tp_roe,0.8))*(1+(tp_g-0.01))/(tp_r-(tp_g-0.01))/(1+tp_r)^6)+tp_wC*(Val!D8*(1-MIN((tp_g-0.01)/tp_roe,0.8))/(1+tp_r)^1+Val!D9*(1-MIN((tp_g-0.01)/tp_roe,0.8))/(1+tp_r)^2+Val!D10*(1-MIN((tp_g-0.01)/tp_roe,0.8))/(1+tp_r)^3+Val!D11*(1-MIN((tp_g-0.01)/tp_roe,0.8))/(1+tp_r)^4+Val!D12*(1-MIN((tp_g-0.01)/tp_roe,0.8))/(1+tp_r)^5+Val!D13*(1-MIN((tp_g-0.01)/tp_roe,0.8))/(1+tp_r)^6+Val!D13*(1-MIN((tp_g-0.01)/tp_roe,0.8))*(1+(tp_g-0.01))/(tp_r-(tp_g-0.01))/(1+tp_r)^6))*(1+tp_r) -> 1727.2095 | D35: =Val!B35 -> 2267.8788 | E35: =tp_w_dcf*C35+(1-tp_w_dcf)*D35 -> 1997.5441 | F35: =E35/E$31-1 -> -0.028776688
A36: DCF 權重 0.3 | C36: =(tp_wA*(Val!B8*(1-MIN(tp_g/tp_roe,0.8))/(1+tp_r)^1+Val!B9*(1-MIN(tp_g/tp_roe,0.8))/(1+tp_r)^2+Val!B10*(1-MIN(tp_g/tp_roe,0.8))/(1+tp_r)^3+Val!B11*(1-MIN(tp_g/tp_roe,0.8))/(1+tp_r)^4+Val!B12*(1-MIN(tp_g/tp_roe,0.8))/(1+tp_r)^5+Val!B13*(1-MIN(tp_g/tp_roe,0.8))/(1+tp_r)^6+Val!B13*(1-MIN(tp_g/tp_roe,0.8))*(1+tp_g)/(tp_r-tp_g)/(1+tp_r)^6)+tp_wB*(Val!C8*(1-MIN(tp_g/tp_roe,0.8))/(1+tp_r)^1+Val!C9*(1-MIN(tp_g/tp_roe,0.8))/(1+tp_r)^2+Val!C10*(1-MIN(tp_g/tp_roe,0.8))/(1+tp_r)^3+Val!C11*(1-MIN(tp_g/tp_roe,0.8))/(1+tp_r)^4+Val!C12*(1-MIN(tp_g/tp_roe,0.8))/(1+tp_r)^5+Val!C13*(1-MIN(tp_g/tp_roe,0.8))/(1+tp_r)^6+Val!C13*(1-MIN(tp_g/tp_roe,0.8))*(1+tp_g)/(tp_r-tp_g)/(1+tp_r)^6)+tp_wC*(Val!D8*(1-MIN(tp_g/tp_roe,0.8))/(1+tp_r)^1+Val!D9*(1-MIN(tp_g/tp_roe,0.8))/(1+tp_r)^2+Val!D10*(1-MIN(tp_g/tp_roe,0.8))/(1+tp_r)^3+Val!D11*(1-MIN(tp_g/tp_roe,0.8))/(1+tp_r)^4+Val!D12*(1-MIN(tp_g/tp_roe,0.8))/(1+tp_r)^5+Val!D13*(1-MIN(tp_g/tp_roe,0.8))/(1+tp_r)^6+Val!D13*(1-MIN(tp_g/tp_roe,0.8))*(1+tp_g)/(tp_r-tp_g)/(1+tp_r)^6))*(1+tp_r) -> 1845.5812 | D36: =Val!B35 -> 2267.8788 | E36: =0.3*C36+(1-0.3)*D36 -> 2141.1895 | F36: =E36/E$31-1 -> 0.041064946
A37: DCF 權重 0.7 | C37: =(tp_wA*(Val!B8*(1-MIN(tp_g/tp_roe,0.8))/(1+tp_r)^1+Val!B9*(1-MIN(tp_g/tp_roe,0.8))/(1+tp_r)^2+Val!B10*(1-MIN(tp_g/tp_roe,0.8))/(1+tp_r)^3+Val!B11*(1-MIN(tp_g/tp_roe,0.8))/(1+tp_r)^4+Val!B12*(1-MIN(tp_g/tp_roe,0.8))/(1+tp_r)^5+Val!B13*(1-MIN(tp_g/tp_roe,0.8))/(1+tp_r)^6+Val!B13*(1-MIN(tp_g/tp_roe,0.8))*(1+tp_g)/(tp_r-tp_g)/(1+tp_r)^6)+tp_wB*(Val!C8*(1-MIN(tp_g/tp_roe,0.8))/(1+tp_r)^1+Val!C9*(1-MIN(tp_g/tp_roe,0.8))/(1+tp_r)^2+Val!C10*(1-MIN(tp_g/tp_roe,0.8))/(1+tp_r)^3+Val!C11*(1-MIN(tp_g/tp_roe,0.8))/(1+tp_r)^4+Val!C12*(1-MIN(tp_g/tp_roe,0.8))/(1+tp_r)^5+Val!C13*(1-MIN(tp_g/tp_roe,0.8))/(1+tp_r)^6+Val!C13*(1-MIN(tp_g/tp_roe,0.8))*(1+tp_g)/(tp_r-tp_g)/(1+tp_r)^6)+tp_wC*(Val!D8*(1-MIN(tp_g/tp_roe,0.8))/(1+tp_r)^1+Val!D9*(1-MIN(tp_g/tp_roe,0.8))/(1+tp_r)^2+Val!D10*(1-MIN(tp_g/tp_roe,0.8))/(1+tp_r)^3+Val!D11*(1-MIN(tp_g/tp_roe,0.8))/(1+tp_r)^4+Val!D12*(1-MIN(tp_g/tp_roe,0.8))/(1+tp_r)^5+Val!D13*(1-MIN(tp_g/tp_roe,0.8))/(1+tp_r)^6+Val!D13*(1-MIN(tp_g/tp_roe,0.8))*(1+tp_g)/(tp_r-tp_g)/(1+tp_r)^6))*(1+tp_r) -> 1845.5812 | D37: =Val!B35 -> 2267.8788 | E37: =0.7*C37+(1-0.7)*D37 -> 1972.2705 | F37: =E37/E$31-1 -> -0.041064946
A40: 案例區塊：TPU 份額 −5pt（情境 A）
A41: 項目 | B41: 單位 | C41: FY2025A | D41: FY2026（錨點） | E41: FY2027 | F41: FY2028 | G41: FY2029 | H41: FY2030（收斂） | I41: FY2031（收斂） | J41: FY2032（收斂） | K41: 說明
A42: A. AI ASIC（由下而上；D 欄＝FY2026 校準年；FY(t)＝CY(t)）
A43: Google TPU 市場顆數（含情境係數） | B43: 百萬顆 | D43: =u_tpu_26 -> 3.85 | E43: =u_tpu_27 -> 5.5 | F43: =u_tpu_28*um28_A -> 7 | G43: =u_tpu_28*(1+g29_tpu)*um29_A -> 8.05
A44: 其他 ASIC（MTIA、Maia、Ascend 等） 市場顆數（含情境係數） | B44: 百萬顆 | D44: =u_oth_26 -> 1 | E44: =u_oth_27 -> 4.5 | F44: =u_oth_28*um28_A -> 5 | G44: =u_oth_28*(1+g29_oth)*um29_A -> 5.75
A45: 聯發科份額：Google TPU | B45: % | D45: =mtk_tpu_26 -> 0.05 | E45: =MIN(1,MAX(0,mtk_tpu_27+(-0.05))) -> 0.1 | F45: =MIN(1,MAX(0,mtk_tpu_28+(-0.05))) -> 0.13 | G45: =MIN(1,MAX(0,mtk_tpu_28+(-0.05))) -> 0.13
...

Sheet Sources
A1: 來源（公司原文＝聯發科法說資料；券商、資料商、媒體皆為 Interested-party）
A2: 公司：2Q26 營運報告（1Q26、2Q26 損益表、資產負債） | B2: https://www.mediatek.com/hubfs/MediaTek%20Assets/Pdfs/Quarterly%20Earnings%20Release/2026/Quarterly%20Earnings%20Release-2026Q2/%5B%E6%B3%95%E8%AA%AA%E6%9C%83%E8%B3%87%E6%96%99%5DQ2%E7%87%9F%E9%81%8B%E5%A0%B1%E5%91%8A.pdf
A3: 公司：2Q26 法說講稿（3Q26 指引、資料中心超過 20 億美元、SAM 800 億美元、份額 15–20%、第二顆 ASIC 2028） | B3: https://www.mediatek.com/hubfs/MediaTek%20Assets/Pdfs/Quarterly%20Earnings%20Release/2026/Quarterly%20Earnings%20Release-2026Q2/Prepared%20remarks.pdf
A4: 公司：1Q26 法說逐字稿（ASIC 數十億美元、SAM 700–800 億美元、份額 10–15%） | B4: https://www.mediatek.com/hubfs/MediaTek%20Assets/Pdfs/Quarterly%20Earnings%20Release/2026/Quarterly%20Earnings%20Release-2026Q1/%E8%AA%AA%E6%98%8E%E6%9C%83%E9%80%90%E5%AD%97%E7%A8%BF.pdf
A5: 公司：4Q25 營運報告（FY2025、4Q25、3Q25 損益表） | B5: https://www.mediatek.com/hubfs/MediaTek%20Assets/Pdfs/Quarterly%20Earnings%20Release/2025/Quarterly%20Earnings%20Release-2025Q4/%5B%E6%B3%95%E8%AA%AA%E6%9C%83%E8%B3%87%E6%96%99%5DQ4%E7%87%9F%E9%81%8B%E5%A0%B1%E5%91%8A.pdf
A6: 公司：4Q25 法說逐字稿（FY2025 美元營收 191 億、資料中心 2026 超過 10 億美元、2027 占營收 20%） | B6: https://www.mediatek.com/hubfs/MediaTek%20Assets/Pdfs/Quarterly%20Earnings%20Release/2025/Quarterly%20Earnings%20Release-2025Q4/%E8%AA%AA%E6%98%8E%E6%9C%83%E9%80%90%E5%AD%97%E7%A8%BF.pdf
A7: 媒體：科技新報（9 月營收、前 9 月累計） | B7: https://finance.technews.tw/2026/10/08/mtk-2454-202609-financial-report/
A8: 媒體：財報狗（3Q26 營收 1,680.58 億、4Q 展望） | B8: https://statementdog.com/news/17861
A9: 媒體：風傳媒（2Q26 法說摘要） | B9: https://www.storm.mg/article/11153222
A10: 券商：凱基 2026-07-23（FY2026–28 預估、v8x／v9／v10 TPU、FY2028 ASIC 500 億美元、目標價 6,150） | B10: https://www.kgi.com.hk/zh-cn/-/media/files/kgishk/research-reports/tw-reports/mediatek-2454-tt_20260723_en.pdf
A11: 媒體：經濟日報 2026-08-03（高盛、Citi 目標價與 EPS、ASIC 2026–28） | B11: https://udn.com/news/story/7252/9668107
A12: 媒體：經濟日報 2026-05-03（高盛 EPS、ASIC 單價數倍、25x P/E） | B12: https://money.udn.com/money/amp/story/5607/9479348
A13: 資料商：stockanalysis（現價 10-22、近 12 月與前瞻 P/E、ROE、FY2021–25 財務） | B13: https://stockanalysis.com/quote/tpe/2454/
... A23: SemiAnalysis | B23: 未使用
