Workbook

Sheet README
A1: 味之素（Ajinomoto，2802.T）收支與估值模型 v0.1（AI 半導體 Project：載板與 PCB 次產業——ABF 增層膜材料；樣板＝ibiden/、dell/） 2026-10-26
A2: 版本：v0.1（初版）。味之素以調味料、冷凍食品、胺基酸與生技醫藥為主；AI 曝險在ファンクショナルマテリアルズ（FM）的 ABF（Ajinomoto Build-up Film）——高階 ABF 載板的增層絕緣材料，市占逾九成（媒體與股東行動派說法，Interested-party）。
A3: 模型命題：味之素的 FM 營收＝FY2026 錨點 ×〔AI 用：AI 加速器有效顆數（tsmc 成品，同字母情境係數）× 每顆載板面積層數（Ibiden 模型）× 份額；非 AI：成長率〕× 需求滿足率（可出貨量上限）× ABF 價格指數；FM 事業利益率隨價格與單位成本變動；其他事業以成長率與利益率推，不隨 AI 情境。
A4: 核心問題：FM 只占營收約 7%、卻占事業利益約三分之一；AI 載板需求能讓 ABF 成長多少、對集團 EPS 貢獻多少？現價約 31 倍 FY2027 EPS、遠高於食品同業約 18 倍，隱含多少 ABF 價值？
A5: 重點觀察 1：目標價 ¥2,537（DCF 2,110、Comparable 2,965 各半），比現價 5,064（2026-10-23）低 49.9%，級距 −25%～−50%；Comparable 單獨為 −41.5%。主因是倍數不是 EPS：本模型 12 個月後前瞻 EPS 166.9 反而比共識前瞻 EPS 154.2 高 8.2%，但食品同業前瞻 P/E 中位數 17.8 倍、共識目標價 6,321 隱含 41.0 倍（倍數因素 +131%）；DCF 也只支撐約 12 倍 FY2028 EPS，因 ROE 近三年平均 13.0% 只略高於折現率 10%。
A6: 重點觀察 2：現價隱含的 ABF 價值：FM 以外的未來 12 月 EPS 92.2 × 食品同業 17.8 倍＝1,638，現價其餘 3,426（68%）都是 ABF（FM）的價值，等於 FM 未來 12 月 EPS 56.8 的 60.3 倍，高於電子材料同業中位數 20.9 倍與 Ibiden 46.8 倍；以電子材料同業倍數計 FM 的 SOTP 為 3,176（−37.3%）。
A7: 重點觀察 3：ABF 成長：FM 營收由 FY2026 公司預測 120.6 十億日圓升到 FY2027 175.6（+46%；AI 用 48.2 → 94.6），FM 事業利益 101.8 占全公司 41%、每股貢獻 67.4（EPS 162.8 的 41%）；前提是約 30% 漲價年度化（價格指數 1.12）與可出貨量 +30%（需求 1.34 倍、滿足率 97%）。ABF 價格取低值時 FY2028 EPS −13.6%、產能取公司 +50%／五年的速度時 −7.3%；追蹤上半年決算（約 2026-11 上旬）的 FM 營收與事業利益（1Q 33.1／19.1 已達全年預測的 27%／29%）。
A8: 會計年度：FY(t)＝t 年 4 月～t＋1 年 3 月（公司稱「t＋1 年 3 月期」），對照 CY(t) 顆數（與 Ibiden 模型相同）。金額：十億日圓。口徑：IFRS 事業利益（公司主要指標）；EPS＝歸屬母公司淨利 ÷ 期中平均股數（2025-04-01 一拆二後）。
A10: 驅動因子 → 推導量（全部唯讀上游，不修改）
A11: AI 用 ABF：tsmc 成品的 NVIDIA 與非 NVIDIA 加速器顆數（非 NVIDIA × 欣興模型的面積係數 0.8）× 同字母情境係數 × Ibiden 模型的每顆載板面積層數年增 18% × 份額相對值 → 需求量；與非 AI 需求（年增 3%）加權後，受可出貨量上限（Assumed）限制。
A12: 價格：2026-05 宣布的約 30% 漲價在 FY2026 只反映部分，FY2027 價格指數 1.12、FY2028 1.15、FY2029 1.12（Assumed），FY2028 起再乘情境乘數 1.0／0.95／0.88；FM 事業利益率＝1 −（1 − 校準值）× 單位成本指數 ÷ 價格指數。
A13: 校準：FY2026 ＝ 公司 2026-08-06 上修後預測（營收 1,732、事業利益 202.0、淨利 123.5、EPS 129.84；FM 120.6／65.5）。AI 占比 40%（Assumed）。不用券商數字（只在 Recon 對帳）。
... A18: 已知限制：(1) 公司不單獨揭露 ABF 與 AI 占比，FM 以子部門揭露值、AI 占比 40% 為 Assumed；(2) 可出貨量上限與價格指數是 Assumed，FY2027 起產能受限，EPS 對兩者最敏感；(3) FY2026 錨點用公司預測，1Q FM 已達全年 27–29%，預測偏保守；(4) 本業以成長率推，中東情勢（公司估最多 −25 十億）未納入；(5) 共識 FY2027 EPS 單一來源推導、FY2028 未找到；(6) 十年 P/E 2020、2024 年受減損影響；(7) 上半年決算（約 2026-11 上旬）後更新錨點。

Sheet In
A1: In — 輸入（藍字；基準欄 E，低 D、高 F）。金額：十億日圓（¥B）；顆數：百萬顆；比例：%。口徑：IFRS 事業利益。每個輸入盡量附兩個來源（找不到者寫「未找到」）；公司原文算一個
A2: 標記：Verified／Interested-party／Analogy／Assumed／Derived；Analogy、Assumed 給低／高區間，不當點估計（放情境或 Sens）。SemiAnalysis 未使用。公司原文＝味之素決算短信、決算概要與 IR 簡報；公司預測為 Interested-party；股東行動派（Palliser）、券商、媒體、資料商皆為 Interested-party。加速器顆數讀 tsmc 成品、載板面積與層數年增讀 ibiden 成品、非 NVIDIA 每顆載板面積讀 unimicron 成品（唯讀）
A3: 鍵 | B3: 項目 | C3: 單位 | D3: 低 | E3: 基準 | F3: 高 | G3: 標記 | H3: 來源1 | I3: 來源2／說明
A4: A. AI 加速器顆數（讀 tsmc 成品；CY2026–CY2028 為輸入、CY2029＝CY2028 ×（1＋各類成長）；情境 A 基準，B／C 依同字母顆數係數縮放）
A5: unv_26 | B5: NVIDIA 加速器顆數 CY2026（Blackwell＋Rubin＋Rubin Ultra＋Hopper） | C5: 百萬顆 | E5: 7.6 | G5: Derived | H5: tsmc/dist/20261025_台積電模型_v0.3.1.xlsx｜In!E5:E36 | I5: 唯讀上游；與台積電、Ibiden、欣興模型同一份顆數
A6: unv_27 | B6: NVIDIA 加速器顆數 CY2027（Blackwell＋Rubin＋Rubin Ultra＋Hopper） | C6: 百萬顆 | E6: 9.7 | G6: Derived | H6: 同上 | I6: 同上
A7: unv_28 | B7: NVIDIA 加速器顆數 CY2028（Blackwell＋Rubin＋Rubin Ultra＋Hopper） | C7: 百萬顆 | E7: 9.5 | G7: Derived | H7: 同上 | I7: 同上
A8: unv_29 | B8: NVIDIA 加速器顆數 CY2029（Blackwell＋Rubin＋Rubin Ultra＋Hopper） | C8: 百萬顆 | E8: 10.6 | G8: Derived | H8: 同上 | I8: 同上
A9: uot_26 | B9: 非 NVIDIA 加速器顆數 CY2026（AMD、TPU、Trainium、其他 ASIC） | C9: 百萬顆 | E9: 7.6 | G9: Derived | H9: tsmc/dist/20261025_台積電模型_v0.3.1.xlsx｜In!E5:E36 | I9: ABF 由全部載板廠採用（市占逾九成），所以非 NVIDIA 加速器全數計入，不乘 Ibiden 份額權重
A10: uot_27 | B10: 非 NVIDIA 加速器顆數 CY2027（AMD、TPU、Trainium、其他 ASIC） | C10: 百萬顆 | E10: 14 | G10: Derived | H10: 同上 | I10: 同上
A11: uot_28 | B11: 非 NVIDIA 加速器顆數 CY2028（AMD、TPU、Trainium、其他 ASIC） | C11: 百萬顆 | E11: 17 | G11: Derived | H11: 同上 | I11: 同上
A12: uot_29 | B12: 非 NVIDIA 加速器顆數 CY2029（AMD、TPU、Trainium、其他 ASIC） | C12: 百萬顆 | E12: 19.55 | G12: Derived | H12: 同上 | I12: 同上
A13: um28_A | B13: 情境 A：CY2028 顆數 ÷ 基準 | C13: x | E13: 1 | G13: Assumed | H13: tsmc/dist/20261025_台積電模型_v0.3.1.xlsx｜In!E37 | I13: A＝順利（基準）；B＝平平；C＝不如預期；與台積電、Ibiden、欣興模型同字母
A14: um29_A | B14: 情境 A：CY2029 顆數 ÷ 基準 | C14: x | E14: 1 | G14: Assumed | H14: tsmc/dist/20261025_台積電模型_v0.3.1.xlsx｜In!E38 | I14: 同上
A15: um28_B | B15: 情境 B：CY2028 顆數 ÷ 基準 | C15: x | E15: 0.8 | G15: Assumed | H15: tsmc/dist/20261025_台積電模型_v0.3.1.xlsx｜In!E39 | I15: A＝順利（基準）；B＝平平；C＝不如預期；與台積電、Ibiden、欣興模型同字母
A16: um29_B | B16: 情境 B：CY2029 顆數 ÷ 基準 | C16: x | E16: 0.85 | G16: Assumed | H16: tsmc/dist/20261025_台積電模型_v0.3.1.xlsx｜In!E40 | I16: 同上
... A18: um29_C | B18: 情境 C：CY2029 顆數 ÷ 基準 | C18: x | E18: 0.6 | G18: Assumed | H18: tsmc/dist/20261025_台積電模型_v0.3.1.xlsx｜In!E42 | I18: 同上
A19: v_ot | B19: 非 NVIDIA 加速器每顆載板面積（金額）÷ NVIDIA（欣興模型） | C19: x | D19: 0.6 | E19: 0.8 | F19: 1 | G19: Assumed | H19: unimicron/dist/20261025_欣興模型_v0.1.1.xlsx｜In!E58 | I19: TPU、Trainium、MI 系列封裝面積接近 GPU、層數不同；量化：未找到（欣興模型同值）
A20: g_asp | B20: 每顆載板面積 × 層數年增（Ibiden 模型的每顆載板金額年增） | C20: % | D20: 0.1 | E20: 0.18 | F20: 0.22 | G20: Analogy | H20: ibiden/dist/20261025_Ibiden模型_v0.2.1.xlsx｜In!E50 | I20: ABF 用量與載板面積 × 增層數成正比：Palliser（Interested-party）Rubin Ultra 155×75 mm、18 層，為 PC CPU 的 13.3 倍面積；EdgeX：每顆 AI 加速器 8–16 層
A21: B. ABF（ファンクショナルマテリアルズ，FM）需求、產能與價格
A22: ai_sh | B22: FY2026 AI 用 ÷ FM 營收 | C22: % | D22: 0.3 | E22: 0.4 | F22: 0.5 | G22: Assumed | H22: Palliser Capital 價值提升計畫 2026-03（股東行動派）：ABF 營收中 AI 占比 FY2024 20%、FY2025E 29%、FY2026E 45%、FY2027E 55%（Interested-party） | I22: 公司未揭露 AI 占比：未找到；DBS 2026-08-12：FM 事業利益 1Q FY26 年增 77%（AI 伺服器帶動）
A23: g_nai | B23: 非 AI ABF 用量年增（PC、一般伺服器、網通） | C23: % | D23: -0.02 | E23: 0.03 | F23: 0.06 | G23: Assumed | H23: PC 與一般伺服器緩步成長（與欣興模型 g_nai 同值） | I23: 量化：未找到
A24: rel_27 | B24: 味之素 ABF 份額 2027 ÷ 2026（相對值） | C24: x | D24: 0.95 | E24: 1 | F24: 1 | G24: Assumed | H24: EdgeX 2026-08-08：味之素逾 95%、積水化學約 5%（媒體，Interested-party） | I24: Palliser Capital 價值提升計畫 2026-03（股東行動派）：高階 AI 用約 100%（Interested-party）
A25: rel_28 | B25: 味之素 ABF 份額 2028 ÷ 2026（相對值） | C25: x | D25: 0.88 | E25: 0.97 | F25: 1 | G25: Assumed | H25: 同上；TrendForce 2026-05-08（引日經、朝日電視）：市占逾 95% | I25: 中國廠與積水化學認證進度：未找到
A26: rel_29 | B26: 味之素 ABF 份額 2029 ÷ 2026（相對值） | C26: x | D26: 0.8 | E26: 0.95 | F26: 1 | G26: Assumed | H26: 同上；TrendForce 2026-05-08（引日經、朝日電視）：市占逾 95% | I26: 中國廠與積水化學認證進度：未找到
A27: cap_27 | B27: ABF 可出貨量上限 2027（FY2026 出貨量＝1） | C27: x | D27: 1.15 | E27: 1.3 | F27: 1.45 | G27: Assumed | H27: TrendForce 2025-04-01（引日經）：2030 年前投資 250 億日圓、ABF 產能 +50%（公司說法，Interested-party）；岐阜新廠 2032 年投產（TrendForce 2026-05-08（引日經、朝日電視）） | I27: 基準約 +22%／年：FY2025 電子材料營收 +31%（漲價前）、1Q FY26 FM 營收 +54%（含部分漲價與匯率），實際出貨成長快於公司 +50%／五年的說法；低值＝公司說法的速度、高值＝不設限
A28: cap_28 | B28: ABF 可出貨量上限 2028（FY2026 出貨量＝1） | C28: x | D28: 1.3 | E28: 1.55 | F28: 1.85 | G28: Assumed | H28: 同上 | I28: —
A29: cap_29 | B29: ABF 可出貨量上限 2029（FY2026 出貨量＝1） | C29: x | D29: 1.45 | E29: 1.8 | F29: 2.25 | G29: Assumed | H29: 同上 | I29: —
A30: pp_27 | B30: ABF 價格指數 2027（FY2026 平均＝1） | C30: x | D30: 1 | E30: 1.12 | F30: 1.2 | G30: Assumed | H30: EdgeX 2026-08-08：2026-05 宣布約 30% 漲價，逐客戶適用（FY2026 只反映部分） | I30: Palliser Capital 價值提升計畫 2026-03（股東行動派）：要求漲價 30% 以上（Interested-party）
A31: pp_28 | B31: ABF 價格指數 2028（FY2026 平均＝1） | C31: x | D31: 0.95 | E31: 1.15 | F31: 1.3 | G31: Assumed | H31: 同上；供需缺口 2027 約 21%、2028 約 42%（EdgeX 2026-08-08引用的供應鏈分析） | I31: Ibiden 模型載板溢價指數 0.95（ibiden/dist/20261025_Ibiden模型_v0.2.1.xlsx｜In!E56）
A32: pp_29 | B32: ABF 價格指數 2029（FY2026 平均＝1） | C32: x | D32: 0.9 | E32: 1.12 | F32: 1.3 | G32: Assumed | H32: 新產能到位、競爭者認證後溢價回落 | I32: Ibiden 模型載板溢價指數 0.9（ibiden/dist/20261025_Ibiden模型_v0.2.1.xlsx｜In!E57）
A33: sp_A | B33: 情境 A：FY2028 起 ABF 價格乘數 | C33: x | E33: 1 | G33: Assumed | H33: 公司特有變數依情境調整，方向 A 最有利：需求放緩時漲價難以延續 | I33: —
A34: sp_B | B34: 情境 B：FY2028 起 ABF 價格乘數 | C34: x | E34: 0.95 | G34: Assumed | H34: 公司特有變數依情境調整，方向 A 最有利：需求放緩時漲價難以延續 | I34: —
A35: sp_C | B35: 情境 C：FY2028 起 ABF 價格乘數 | C35: x | E35: 0.88 | G35: Assumed | H35: 公司特有變數依情境調整，方向 A 最有利：需求放緩時漲價難以延續 | I35: —
A36: c_g | B36: ABF 每單位成本年增（新產能折舊、原料） | C36: % | D36: 0 | E36: 0.03 | F36: 0.06 | G36: Assumed | H36: FM 事業利益率 FY2024 約 52%（40 ÷ 77，Palliser）→ FY2025 53%、1Q FY26 58% | I36: 價格指數上升的部分全部落在利潤（同 Ibiden 模型寫法）
A37: C. 其他事業（不隨 AI 情境）
A38: g_sf | B38: 調味料・食品營收年增 | C38: % | D38: 0.02 | E38: 0.04 | F38: 0.06 | G38: Assumed | H38: 公司：2026 年 3 月期決算短信（2026-05-07）：FY2025 +4.6%；FY2026 預測 +6.6%（含匯率） | I38: —
A39: m_sf | B39: 調味料・食品事業利益率（FY2027 起） | C39: % | D39: 0.135 | E39: =f_sfbp/f_sf -> 0.14610455 | F39: 0.155 | G39: Derived | H39: FY2026 預測 145.9 ÷ 998.6（公司：Q1 決算概要（分部門、子部門；2026-08-06）） | I39: FY2025 15.3%（143.0 ÷ 936.9）
A40: g_ff | B40: 冷凍食品營收年增 | C40: % | D40: 0 | E40: 0.03 | F40: 0.05 | G40: Assumed | H40: FY2025 +0.3%；FY2026 預測 +7.0%（含匯率） | I40: —
A41: m_ff | B41: 冷凍食品事業利益率（FY2027 起） | C41: % | D41: 0.03 | E41: 0.045 | F41: 0.06 | G41: Assumed | H41: FY2024 4.5%、FY2025 2.9%、FY2026 預測 3.9%（公司） | I41: Palliser Capital 價值提升計畫 2026-03（股東行動派）：要求冷凍食品重整，ROIC 由約 3% 提高到 8%
...

Sheet Q
A1: Q — FY2025 實績、1Q FY26 實績與 FY2026 錨點（¥B；EPS 日圓）。FY2026 錨點＝公司 2026-08-06 上修後的全年預測（Q1 公布時）；上半年決算（約 2026-11 上旬）後更新
A2: 公司不單獨揭露 ABF 營收；ファンクショナルマテリアルズ（FM，電子材料等）為ヘルスケア等的子部門，季度決算概要揭露其營收與事業利益。FY2025 FM 營收以 ASV Report 的 30% 占比推估（Derived），電子材料營收 100.7（媒體引公司）與子公司味之素ファインテクノ營收 98.4 為對照。FM 內 AI 用比例公司未揭露，以 In 頁 ai_sh（Assumed）切分
A3: 項目 | B3: FY2025A | C3: 1Q FY26（實績） | D3: FY2026 錨點 | E3: 年增（錨點 ÷ FY2025） | F3: 1Q ÷ 錨點（進度） | G3: 標記 | H3: 說明
A4: 營收 | B4: =a_rev -> 1583.719 | C4: =q1_rev -> 412.105 | D4: =f_rev -> 1732 | E4: =D4/B4-1 -> 0.093628352 | F4: =C4/D4 -> 0.23793591 | G4: Verified／Interested-party
A5: 調味料・食品 | B5: =a_sf -> 936.926 | C5: 238.7 | D5: =f_sf -> 998.6 | E5: =D5/B5-1 -> 0.065825903 | F5: =C5/D5 -> 0.23903465 | G5: Verified／Interested-party | H5: 1Q 子部門值取自決算概要（億日圓 ÷ 100）
A6: 冷凍食品 | B6: =a_ff -> 290.308 | C6: 72.5 | D6: =f_ff -> 310.6 | E6: =D6/B6-1 -> 0.069898177 | F6: =C6/D6 -> 0.23341919 | G6: Verified／Interested-party
A7: ヘルスケア等 | B7: =a_ho -> 341.504 | C7: 97 | D7: =f_ho -> 406.8 | E7: =D7/B7-1 -> 0.19120127 | F7: =C7/D7 -> 0.23844641 | G7: Verified／Interested-party
A8: 其中 ファンクショナルマテリアルズ（電子材料等） | B8: =a_fm -> 102.4512 | C8: =q1_fm -> 33.1 | D8: =f_fm -> 120.6 | E8: =D8/B8-1 -> 0.1771458 | F8: =C8/D8 -> 0.27446103 | G8: Derived | H8: FY2025＝0.30 × ヘルスケア等（ASV Report 占比）；1Q 與錨點為公司決算概要揭露值
A9: 其中 FM 以外（生技醫藥＆原料、其他） | B9: =a_ho-a_fm -> 239.0528 | C9: 63.9 | D9: =f_ho-f_fm -> 286.2 | E9: =D9/B9-1 -> 0.19722505 | F9: =C9/D9 -> 0.22327044 | G9: Derived
A10: その他 | B10: =a_oth -> 14.979 | C10: 3.7 | D10: =f_oth -> 15.8 | E10: =D10/B10-1 -> 0.054810067 | F10: =C10/D10 -> 0.23417722 | G10: Verified／Interested-party
A11: 事業利益 | B11: =a_bp -> 181.163 | C11: =q1_bp -> 60.116 | D11: =f_bp -> 202 | E11: =D11/B11-1 -> 0.11501797 | F11: =C11/D11 -> 0.29760396 | G11: Verified／Interested-party
A12: 調味料・食品 | B12: =a_sfbp -> 143.036 | C12: 41 | D12: =f_sfbp -> 145.9 | E12: =D12/B12-1 -> 0.020022931 | F12: =C12/D12 -> 0.28101439 | G12: Verified／Interested-party
A13: 冷凍食品 | B13: =a_ffbp -> 8.457 | C13: 2.1 | D13: =f_ffbp -> 12.1 | E13: =D13/B13-1 -> 0.43076741 | F13: =C13/D13 -> 0.17355372 | G13: Verified／Interested-party
A14: ヘルスケア等 | B14: =a_hobp -> 66.202 | C14: 25.1 | D14: =f_hobp -> 85 | E14: =D14/B14-1 -> 0.28394913 | F14: =C14/D14 -> 0.29529412 | G14: Verified／Interested-party
A15: 其中 ファンクショナルマテリアルズ | B15: =a_fmbp -> 54.6 | C15: =q1_fmbp -> 19.1 | D15: =f_fmbp -> 65.5 | E15: =D15/B15-1 -> 0.1996337 | F15: =C15/D15 -> 0.29160305 | G15: Interested-party／Verified
A16: 其中 FM 以外 | B16: =a_hobp-a_fmbp -> 11.602 | C16: 6 | D16: =f_hobp-f_fmbp -> 19.5 | E16: =D16/B16-1 -> 0.6807447 | F16: =C16/D16 -> 0.30769231 | G16: Derived
A17: その他 | B17: =a_othbp -> 6.064 | C17: 1.6 | D17: =f_othbp -> 5.1 | E17: =D17/B17-1 -> -0.15897098 | F17: =C17/D17 -> 0.31372549 | G17: Verified／Interested-party
A18: 全社共通費 | B18: =a_cc -> -42.597 | C18: -9.9 | D18: =f_cc -> -46.2 | E18: =D18/B18-1 -> 0.084583421 | F18: =C18/D18 -> 0.21428571 | G18: Verified／Interested-party | H18: 費用（負值）
A19: 營業利益 | B19: =a_oi -> 199.412 | C19: 55.895 | D19: =f_oi -> 184.2 | E19: =D19/B19-1 -> -0.076284276 | F19: =C19/D19 -> 0.30344734 | G19: Verified／Interested-party
A20: 淨利（歸屬母公司） | B20: =a_ni -> 134.675 | C20: =q1_ni -> 36.452 | D20: =f_ni -> 123.5 | E20: =D20/B20-1 -> -0.082977539 | F20: =C20/D20 -> 0.29515789 | G20: Verified／Interested-party | H20: FY2025 含本社大樓土地出售利益（營業利益 199.4 > 事業利益 181.2），FY2026 預測淨利因此年減
A21: EPS（基本，日圓） | B21: =a_eps -> 138.36 | C21: =q1_eps -> 38.11 | D21: =f_eps -> 129.84 | E21: =D21/B21-1 -> -0.061578491 | F21: =C21/D21 -> 0.2935151 | G21: Verified／Interested-party
A23: 比率
A24: FM 事業利益率 | B24: =B15/B8 -> 0.53293666 | C24: =C15/C8 -> 0.57703927 | D24: =D15/D8 -> 0.54311774 | G24: Derived | H24: 1Q 達 58%；公司全年預測隱含下半年 FM 事業利益率約 53%（保守）
A25: FM 營收 ÷ 全公司營收 | B25: =B8/B4 -> 0.064690264 | C25: =C8/C4 -> 0.080319336 | D25: =D8/D4 -> 0.069630485 | G25: Derived
A26: FM 事業利益 ÷ 全公司事業利益 | B26: =B15/B11 -> 0.30138604 | C26: =C15/C11 -> 0.31771908 | D26: =D15/D11 -> 0.32425743 | G26: Derived | H26: DBS：FY25 30%、FY26 修正預測 32%（Interested-party）
A27: 事業利益率 | B27: =B11/B4 -> 0.11439087 | C27: =C11/C4 -> 0.14587544 | D27: =D11/D4 -> 0.11662818 | G27: Derived
A28: 淨利 ÷ 事業利益 | B28: =B20/B11 -> 0.74339131 | C28: =C20/C11 -> 0.60636104 | D28: =D20/D11 -> 0.61138614 | G28: Derived
A29: 股數（十億股＝淨利 ÷ EPS） | B29: =B20/B21 -> 0.97336658 | C29: =C20/C21 -> 0.95649436 | D29: =D20/D21 -> 0.95117067 | G29: Derived
A31: 讀法：FM 只占營收約 7%，卻占事業利益約三分之一；1Q 的 FM 營收、事業利益分別達全年預測的 27%、29%，公司全年預測隱含下半年放緩，屬保守。

Sheet Units
A1: Units — AI 加速器顆數 → ABF 需求量 → 出貨（產能上限）→ FM 營收（情境 A）；每顆加速器的 ABF 金額與 Ibiden 載板金額對照。FY(t) 對照 CY(t)
A3: 項目 | B3: 單位 | C3: FY2026（CY2026） | D3: FY2027 | E3: FY2028 | F3: FY2029 | G3: 說明
A4: NVIDIA 加速器顆數 | B4: 百萬顆 | C4: =PL!D73 -> 7.6 | D4: =PL!E73 -> 9.7 | E4: =PL!F73 -> 9.5 | F4: =PL!G73 -> 10.6 | G4: tsmc 成品
A5: 非 NVIDIA 加速器顆數 | B5: 百萬顆 | C5: =PL!D74 -> 7.6 | D5: =PL!E74 -> 14 | E5: =PL!F74 -> 17 | F5: =PL!G74 -> 19.55 | G5: tsmc 成品
A6: 有效顆數（非 NVIDIA × 面積係數 v_ot） | B6: 百萬顆 | C6: =PL!D75 -> 13.68 | D6: =PL!E75 -> 20.9 | E6: =PL!F75 -> 23.1 | F6: =PL!G75 -> 26.24 | G6: v_ot 讀欣興模型
A7: 每顆載板面積 × 層數指數 | B7: x | C7: =PL!D76 -> 1 | D7: =PL!E76 -> 1.18 | E7: =PL!F76 -> 1.3924 | F7: =PL!G76 -> 1.643032 | G7: g_asp 讀 Ibiden 模型
A8: AI 用 ABF 需求量指數 | B8: x | C8: =PL!D78 -> 1 | D8: =PL!E78 -> 1.8027778 | E8: =PL!F78 -> 2.2806657 | F8: =PL!G78 -> 2.9939694 | G8: FY2026＝1
A9: ABF 需求量指數（含非 AI） | B9: x | C9: =PL!D80 -> 1 | D9: =PL!E80 -> 1.3391111 | E9: =PL!F80 -> 1.5488063 | F9: =PL!G80 -> 1.853224
A10: 可出貨量上限 | B10: x | C10: =PL!D81 -> 1 | D10: =PL!E81 -> 1.3 | E10: =PL!F81 -> 1.55 | F10: =PL!G81 -> 1.8 | G10: Assumed
A11: 需求滿足率 | B11: % | C11: =PL!D83 -> 1 | D11: =PL!E83 -> 0.97079323 | E11: =PL!F83 -> 1 | F11: =PL!G83 -> 0.97128034 | G11: 小於 100%＝產能受限
A12: ABF 價格指數 | B12: x | C12: =PL!D84 -> 1 | D12: =PL!E84 -> 1.12 | E12: =PL!F84 -> 1.15 | F12: =PL!G84 -> 1.12 | G12: Assumed
A13: FM 營收：AI 用 | B13: ¥B | C13: =PL!D85 -> 48.24 | D13: =PL!E85 -> 94.557124 | E13: =PL!F85 -> 126.52221 | F13: =PL!G85 -> 157.11487
A14: FM 營收 | B14: ¥B | C14: =PL!D87 -> 120.6 | D14: =PL!E87 -> 175.5936 | E14: =PL!F87 -> 214.80394 | F14: =PL!G87 -> 243.1296
A15: 每顆有效加速器的味之素 AI 用 ABF 營收 | B15: US$ | C15: =PL!D117 -> 23.508772 | D15: =PL!E117 -> 30.161762 | E15: =PL!F117 -> 36.514346 | F15: =PL!G117 -> 39.917395 | G15: ¥150／US$
A16: 對照：每顆 NVIDIA 載板金額（Ibiden 模型） | B16: US$ | C16: 215.3086 | D16: 254.06414 | E16: 284.8059 | F16: 318.38302 | G16: ibiden/dist/20261025_Ibiden模型_v0.2.1.xlsx｜Units!C8:F8
A17: ABF 金額 ÷ 載板金額 | B17: % | C17: =C15/C16 -> 0.10918641 | D17: =D15/D16 -> 0.11871712 | E17: =E15/E16 -> 0.12820783 | F17: =F15/F16 -> 0.12537539 | G17: Palliser：ABF 約占載板物料成本 10%（Interested-party）
A18: 對照：Ibiden AI 伺服器載板營收（Ibiden 模型） | B18: ¥B | C18: 243.75 | D18: 392.91629 | E18: 434.67123 | F18: 530.3958 | G18: ibiden/dist/20261025_Ibiden模型_v0.2.1.xlsx｜Units!C9:F9
A19: 味之素 AI 用 ABF 營收年增 − Ibiden AI 載板營收年增 | B19: pt | D19: =(D13/C13-1)-(D18/C18-1) -> 0.34817511 | E19: =(E13/D13-1)-(E18/D18-1) -> 0.23178125 | F19: =(F13/E13-1)-(F18/E18-1) -> 0.021573776 | G19: 正值＝ABF 成長快於 Ibiden 載板（漲價、ASIC 全數計入）
A21: 讀法：每顆 AI 加速器只用到約二、三十美元的 ABF（約為 NVIDIA 載板金額的一成），所以 ABF 不是成本瓶頸、而是產能與認證瓶頸：需求量（顆數 × 面積層數）每年成長三到八成，味之素的可出貨量（Assumed）跟不上時，出貨受限、成長改由價格貢獻。

Sheet PL
A1: PL — 味之素損益（¥B；EPS 日圓；IFRS 事業利益口徑）。FY2025A 實績、FY2026 錨點（公司上修後預測；三情境相同），FY2027 起為模型。FY(t)＝t/4–(t+1)/3，對照 CY(t) 顆數。三情境各一個完整推導區塊（本頁下方），頂端為摘要。FY2026–FY2027 三情境相同（顆數係數與情境價格乘數從 CY2028＝FY2028 開始）
A2: 灰底＝FY2030–FY2032 收斂法（上游顆數只到 CY2029＝FY2029）：營收年增線性收斂到 fade_g、淨利率線性收斂到 fade_m（In 頁 I 節），非驅動因子推導
A3: 情境／項目 | B3: 單位 | C3: FY2025A | D3: FY2026（錨點） | E3: FY2027 | F3: FY2028 | G3: FY2029 | H3: FY2030（收斂） | I3: FY2031（收斂） | J3: FY2032（收斂） | K3: 說明
A4: 情境 A
A5: 營收 | B5: ¥B | C5: =C103 -> 1583.719 | D5: =D103 -> 1732 | E5: =E103 -> 1850.5656 | F5: =F103 -> 1955.9407 | G5: =G103 -> 2053.1321 | H5: =H103 -> 2162.2086 | I5: =I103 -> 2284.5105 | J5: =J103 -> 2421.5812
A6: 營收年增 | B6: % | D6: =D104 -> 0.093628352 | E6: =E104 -> 0.068455889 | F6: =F104 -> 0.056942128 | G6: =G104 -> 0.049690324 | H6: =H104 -> 0.053126882 | I6: =I104 -> 0.056563441 | J6: =J104 -> 0.06
A7: ファンクショナルマテリアルズ（ABF 等） | B7: ¥B | C7: =C87 -> 102.4512 | D7: =D87 -> 120.6 | E7: =E87 -> 175.5936 | F7: =F87 -> 214.80394 | G7: =G87 -> 243.1296
A8: 其中 AI 用 | B8: ¥B | D8: =D85 -> 48.24 | E8: =E85 -> 94.557124 | F8: =F85 -> 126.52221 | G8: =G85 -> 157.11487
A9: FM 事業利益率 | B9: % | C9: =C88 -> 0.53293666 | D9: =D88 -> 0.54311774 | E9: =E88 -> 0.5798315 | F9: =F88 -> 0.57851619 | G9: =G88 -> 0.55424324
A10: FM 事業利益 | B10: ¥B | C10: =C89 -> 54.6 | D10: =D89 -> 65.5 | E10: =E89 -> 101.8147 | F10: =F89 -> 124.26756 | G10: =G89 -> 134.75294
A11: 事業利益 | B11: ¥B | C11: =C106 -> 181.163 | D11: =D106 -> 202 | E11: =E106 -> 246.03601 | F11: =F106 -> 274.58637 | G11: =G106 -> 291.43334
A12: 事業利益率 | B12: % | C12: =C107 -> 0.11439087 | D12: =D107 -> 0.11662818 | E12: =E107 -> 0.13295179 | F12: =F107 -> 0.14038583 | G12: =G107 -> 0.14194573
A13: FM 事業利益 ÷ 事業利益 | B13: % | C13: =C108 -> 0.30138604 | D13: =D108 -> 0.32425743 | E13: =E108 -> 0.41382032 | F13: =F108 -> 0.45256274 | G13: =G108 -> 0.46237996
A14: 淨利 | B14: ¥B | C14: =C110 -> 134.675 | D14: =D110 -> 123.5 | E14: =E110 -> 152.54233 | F14: =F110 -> 170.24355 | G14: =G110 -> 180.68867 | H14: =H110 -> 190.2881 | I14: =I110 -> 201.05145 | J14: =J110 -> 213.11453
A15: 淨利率 | B15: % | C15: =C114 -> 0.085037181 | D15: =D114 -> 0.07130485 | E15: =E114 -> 0.08243011 | F15: =F114 -> 0.087039215 | G15: =G114 -> 0.088006355 | H15: =H114 -> 0.088006355 | I15: =I114 -> 0.088006355 | J15: =J114 -> 0.088006355
A16: EPS | B16: ¥ | C16: =C112 -> 138.36 | D16: =D112 -> 129.84 | E16: =E112 -> 162.81548 | F16: =F112 -> 184.47595 | G16: =G112 -> 198.77592 | H16: =H112 -> 212.52413 | I16: =I112 -> 227.9647 | J16: =J112 -> 245.32242
A17: EPS 年增 | B17: % | D17: =D113 -> -0.061578491 | E17: =E113 -> 0.25397009 | F17: =F113 -> 0.13303693 | G17: =G113 -> 0.07751675 | H17: =H113 -> 0.069164348 | I17: =I113 -> 0.07265324 | J17: =J113 -> 0.076142132
A18: FM 每股貢獻 | B18: ¥ | D18: =D115 -> 42.101584 | E18: =E115 -> 67.376352 | F18: =F115 -> 83.48694 | G18: =G115 -> 91.910004
A20: 情境 B
A21: 營收 | B21: ¥B | C21: =C153 -> 1583.719 | D21: =D153 -> 1732 | E21: =E153 -> 1850.5656 | F21: =F153 -> 1921.1613 | G21: =G153 -> 2024.7543 | H21: =H153 -> 2124.537 | I21: =I153 -> 2219.3778 | J21: =J153 -> 2308.1529
A22: 營收年增 | B22: % | D22: =D154 -> 0.093628352 | E22: =E154 -> 0.068455889 | F22: =F154 -> 0.038148189 | G22: =G154 -> 0.053922071 | H22: =H154 -> 0.049281381 | I22: =I154 -> 0.04464069 | J22: =J154 -> 0.04
A23: ファンクショナルマテリアルズ（ABF 等） | B23: ¥B | C23: =C137 -> 102.4512 | D23: =D137 -> 120.6 | E23: =E137 -> 175.5936 | F23: =F137 -> 180.02453 | G23: =G137 -> 214.75185
A24: 其中 AI 用 | B24: ¥B | D24: =D135 -> 48.24 | E24: =E135 -> 94.557124 | F24: =F135 -> 96.15688 | G24: =G135 -> 130.62166
A25: FM 事業利益率 | B25: % | C25: =C138 -> 0.53293666 | D25: =D138 -> 0.54311774 | E25: =E138 -> 0.5798315 | F25: =F138 -> 0.55633283 | G25: =G138 -> 0.53078235
A26: FM 事業利益 | B26: ¥B | C26: =C139 -> 54.6 | D26: =D139 -> 65.5 | E26: =E139 -> 101.8147 | F26: =F139 -> 100.15355 | G26: =G139 -> 113.98649
A27: 事業利益 | B27: ¥B | C27: =C156 -> 181.163 | D27: =D156 -> 202 | E27: =E156 -> 246.03601 | F27: =F156 -> 250.47236 | G27: =G156 -> 270.6669
A28: 事業利益率 | B28: % | C28: =C157 -> 0.11439087 | D28: =D157 -> 0.11662818 | E28: =E157 -> 0.13295179 | F28: =F157 -> 0.1303755 | G28: =G157 -> 0.13367888
A29: FM 事業利益 ÷ 事業利益 | B29: % | C29: =C158 -> 0.30138604 | D29: =D158 -> 0.32425743 | E29: =E158 -> 0.41382032 | F29: =F158 -> 0.3998587 | G29: =G158 -> 0.42113201
A30: 淨利 | B30: ¥B | C30: =C160 -> 134.675 | D30: =D160 -> 123.5 | E30: =E160 -> 152.54233 | F30: =F160 -> 155.29287 | G30: =G160 -> 167.81348 | H30: =H160 -> 170.2141 | I30: =I160 -> 171.68111 | J30: =J160 -> 172.17163
A31: 淨利率 | B31: % | C31: =C164 -> 0.085037181 | D31: =D164 -> 0.07130485 | E31: =E164 -> 0.08243011 | F31: =F164 -> 0.080832808 | G31: =G164 -> 0.082880908 | H31: =H164 -> 0.080118211 | I31: =I164 -> 0.077355514 | J31: =J164 -> 0.074592817
A32: EPS | B32: ¥ | C32: =C162 -> 138.36 | D32: =D162 -> 129.84 | E32: =E162 -> 162.81548 | F32: =F162 -> 168.27538 | G32: =G162 -> 184.6119 | H32: =H162 -> 190.1044 | I32: =I162 -> 194.66278 | J32: =J162 -> 198.19183
A33: EPS 年增 | B33: % | D33: =D163 -> -0.061578491 | E33: =E163 -> 0.25397009 | F33: =F163 -> 0.033534331 | G33: =G163 -> 0.097082026 | H33: =H163 -> 0.029751609 | I33: =I163 -> 0.023978272 | J33: =J163 -> 0.018129079
A34: FM 每股貢獻 | B34: ¥ | D34: =D165 -> 42.101584 | E34: =E165 -> 67.376352 | F34: =F165 -> 67.286377 | G34: =G165 -> 77.74598
A36: 情境 C
A37: 營收 | B37: ¥B | C37: =C203 -> 1583.719 | D37: =D203 -> 1732 | E37: =E203 -> 1850.5656 | F37: =F203 -> 1885.6285 | G37: =G203 -> 1973.3432 | H37: =H203 -> 2047.6955 | I37: =I203 -> 2106.7493 | J37: =J203 -> 2148.8843
A38: 營收年增 | B38: % | D38: =D204 -> 0.093628352 | E38: =E204 -> 0.068455889 | F38: =F204 -> 0.0189471 | G38: =G204 -> 0.046517502 | H38: =H204 -> 0.037678335 | I38: =I204 -> 0.028839167 | J38: =J204 -> 0.02
A39: ファンクショナルマテリアルズ（ABF 等） | B39: ¥B | C39: =C187 -> 102.4512 | D39: =D187 -> 120.6 | E39: =E187 -> 175.5936 | F39: =F187 -> 144.49165 | G39: =G187 -> 163.34071
A40: 其中 AI 用 | B40: ¥B | D40: =D185 -> 48.24 | E40: =E185 -> 94.557124 | F40: =F185 -> 66.803727 | G40: =G185 -> 85.409584
A41: FM 事業利益率 | B41: % | C41: =C188 -> 0.53293666 | D41: =D188 -> 0.54311774 | E41: =E188 -> 0.5798315 | F41: =F188 -> 0.52104112 | G41: =G188 -> 0.49345822
A42: FM 事業利益 | B42: ¥B | C42: =C189 -> 54.6 | D42: =D189 -> 65.5 | E42: =E189 -> 101.8147 | F42: =F189 -> 75.286092 | G42: =G189 -> 80.601814
...

Sheet Val
A1: Val — P/E 估值（日圓）。目標價＝DCF 與 Comparable 加權（第 0 節）；結論另列「現價 ÷ FY2027、FY2028 EPS（模型）」；十年 P/E 規則值（第 6 節，年底落後 P/E）只作參考；第 7 節為分部加總（SOTP）與現價隱含 ABF 價值（參考）
A2: 循環位置：味之素不是設備股，不套設備市場見頂年；以本模型營收最高的會計年度為見頂年（比照 Ibiden、Dell）。營收到 FY2029 仍在增加時，見頂年未知，判為中段
A4: 0. 目標價
A5: 0.1 DCF（股東權益現金流，FY2027–FY2032 明確期＋FY2032 後永續）
A6: 項目 | B6: A（順利） | C6: B（平平） | D6: C（不如預期） | E6: 說明 | F6: 折現年數 t
A7: 情境 EPS（FY2027–FY2032） | E7: PL 頁各情境；FY2030 起為收斂法；F 欄＝折現年數（基準日 2026 年底，t＝1 對 FY2027；FY2027 實際於 2028-03 結束，未做季度調整）
A8: FY2027 | B8: =PL!E16 -> 162.81548 | C8: =PL!E32 -> 162.81548 | D8: =PL!E48 -> 162.81548 | F8: 1
A9: FY2028 | B9: =PL!F16 -> 184.47595 | C9: =PL!F32 -> 168.27538 | D9: =PL!F48 -> 151.56862 | F9: 2
A10: FY2029 | B10: =PL!G16 -> 198.77592 | C10: =PL!G32 -> 184.6119 | D10: =PL!G48 -> 161.84144 | F10: 3
A11: FY2030 | B11: =PL!H16 -> 212.52413 | C11: =PL!H32 -> 190.1044 | D11: =PL!H48 -> 159.13036 | F11: 4
A12: FY2031 | B12: =PL!I16 -> 227.9647 | C12: =PL!I32 -> 194.66278 | D12: =PL!I48 -> 154.3404 | F12: 5
A13: FY2032 | B13: =PL!J16 -> 245.32242 | C13: =PL!J32 -> 198.19183 | D13: =PL!J48 -> 147.53037 | F13: 6
A14: 股東現金流＝EPS ×（1 − tp_g ÷ tp_roe） | E14: 味之素資本支出約為折舊的 1.2 倍（FY2025：104.6 vs 88.9），非資本密集，用工作單通式；下列六列＝EPS ×（1 − 再投資率）
A15: 再投資率（tp_g ÷ tp_roe，上限 0.8） | B15: =MIN(tp_g/tp_roe,0.8) -> 0.30792918 | E15: ROE 為近三年平均（In 頁 tp_roe）
A16: FY2027 | B16: =B8*(1-$B$15) -> 112.67984 | C16: =C8*(1-$B$15) -> 112.67984 | D16: =D8*(1-$B$15) -> 112.67984
A17: FY2028 | B17: =B9*(1-$B$15) -> 127.67042 | C17: =C9*(1-$B$15) -> 116.45848 | D17: =D9*(1-$B$15) -> 104.89622
A18: FY2029 | B18: =B10*(1-$B$15) -> 137.56702 | C18: =C10*(1-$B$15) -> 127.76451 | D18: =D10*(1-$B$15) -> 112.00574
A19: FY2030 | B19: =B11*(1-$B$15) -> 147.08175 | C19: =C11*(1-$B$15) -> 131.56571 | D19: =D11*(1-$B$15) -> 110.12948
A20: FY2031 | B20: =B12*(1-$B$15) -> 157.76772 | C20: =C12*(1-$B$15) -> 134.72043 | D20: =D12*(1-$B$15) -> 106.81448
A21: FY2032 | B21: =B13*(1-$B$15) -> 169.78049 | C21: =C13*(1-$B$15) -> 137.16278 | D21: =D13*(1-$B$15) -> 102.10147
A22: DCF 情境每股價值（折現率 tp_r） | B22: =MAX(0,SUMPRODUCT(B16:B21,1/(1+tp_r)^$F$8:$F$13)+B21*(1+tp_g)/(tp_r-tp_g)/(1+tp_r)^$F$13) -> 2266.7307 | C22: =MAX(0,SUMPRODUCT(C16:C21,1/(1+tp_r)^$F$8:$F$13)+C21*(1+tp_g)/(tp_r-tp_g)/(1+tp_r)^$F$13) -> 1887.6412 | D22: =MAX(0,SUMPRODUCT(D16:D21,1/(1+tp_r)^$F$8:$F$13)+D21*(1+tp_g)/(tp_r-tp_g)/(1+tp_r)^$F$13) -> 1471.4385 | E22: Σ 明確期現金流 ÷ (1＋r)^t ＋ 永續價值 ÷ (1＋r)^6；永續價值＝FY2032 現金流 ×(1＋g)÷(r−g)；基準日 2026 年底；小於 0 時取 0
A23: DCF 情境價值推到 12 個月後（×(1＋tp_r)） | B23: =B22*(1+tp_r) -> 2493.4037 | C23: =C22*(1+tp_r) -> 2076.4053 | D23: =D22*(1+tp_r) -> 1618.5823
A24: DCF 目標價（情境加權） | B24: =tp_wA*B23+tp_wB*C23+tp_wC*D23 -> 2109.9402 | E24: Σ 權重 × 情境價值 ×(1＋r)；權重見 In 頁
A26: 0.2 Comparable（市場主流同業前瞻 P/E：食品同業）
A27: 同業與前瞻 P/E | B27: 代號 | C27: 前瞻 12 月 P/E | D27: 日期 | E27: 來源 | F27: 標記
A28: 龜甲萬（Kikkoman） | B28: 2801.T | C28: 22.86 | D28: 2026-09-25 | E28: stockanalysis.com forward PE（分析師共識；價格日期如左） | F28: Interested-party
A29: 日清食品 HD（Nissin Foods） | B29: 2897.T | C29: 16.97 | D29: 2026-08-07 | E29: stockanalysis.com forward PE（分析師共識；價格日期如左） | F29: Interested-party
A30: 明治 HD（Meiji） | B30: 2269.T | C30: 17.79 | D30: 2026-09-18 | E30: stockanalysis.com forward PE（分析師共識；價格日期如左） | F30: Interested-party
A31: Kewpie（丘比） | B31: 2809.T | C31: 23.4 | D31: 2026-08-14 | E31: stockanalysis.com forward PE（分析師共識；價格日期如左） | F31: Interested-party
A32: McCormick（味好美） | B32: MKC | C32: 15.56 | D32: 2026-10-23 | E32: stockanalysis.com forward PE（分析師共識；價格日期如左） | F32: Interested-party
A33: Nestlé（雀巢） | B33: NESN.SW | C33: 17.74 | D33: 2026-10-23 | E33: stockanalysis.com forward PE（分析師共識；價格日期如左） | F33: Interested-party
A34: 同業前瞻 P/E 中位數 | B34: =MEDIAN(C28:C33) -> 17.765 | E34: 食品與調味料同業：日本四家（東證食料品）＋全球調味料兩家（不含 A 股）。理由：東證與 GICS 皆歸食品，賣方由食品分析師覆蓋，事業利益約三分之二來自食品本業；電子材料同業與 SOTP 見第 7 節（參考，不進目標價）
A35: 12 個月後的前瞻 EPS（情境加權） | B35: =tp_wA*(5/12*B8+7/12*B9)+tp_wB*(5/12*C8+7/12*C9)+tp_wC*(5/12*D8+7/12*D9) -> 166.8864 | E35: 約 2027-10 時的未來 12 月（2027-11～2028-10）EPS ≈ 5／12 × FY2027＋7／12 × FY2028（會計年度 3 月底結束，依月份調整）
A36: Comparable 目標價 | B36: =B34*B35 -> 2964.7369 | E36: 同業中位數 × 前瞻 EPS
A38: 0.3 結論
A39: 項目 | B39: 數值 | C39: 對照 | D39: 對照 | E39: 說明
A40: 目標價（DCF 與 Comparable 加權） | B40: =tp_w_dcf*B24+(1-tp_w_dcf)*B36 -> 2537.3386 | E40: tp_w_dcf × DCF＋（1 − tp_w_dcf）× Comparable；tp_w_dcf 見 In 頁（0.5）
A41: Comparable 目標價（市場主流同業法） | B41: =B36 -> 2964.7369
A42: 市場共識目標價 | B42: =cons_tp -> 6321.43 | E42: Simply Wall St：14 位分析師平均 6,321（最高 7,300、最低 5,800），2026-10-26；stockanalysis 14 位 6,104（2026-08-07）
A43: 上檔空間：加權目標價 | B43: =B40/px-1 -> -0.49894578 | E43: 現價＝In 頁 px（2026-10-23 收盤 5,064）
...

Sheet Recon
A1: Recon — 本模型 vs 公司預測、共識與上游載板模型。只作事後對照，不為對上數字而調參數
A3: 項目 | B3: 對照值 | C3: 模型 A | D3: 差距 A | E3: 模型 B | F3: 差距 B | G3: 模型 C | H3: 差距 C | I3: 對照來源 | J3: 說明
A4: A. 共識（校準未使用）
A5: FY2026 營收 vs 共識 | B5: =c_rev26 -> 1730 | C5: =PL!D103 -> 1732 | D5: =C5/B5-1 -> 0.0011560694 | E5: =PL!D153 -> 1732 | F5: =E5/B5-1 -> 0.0011560694 | G5: =PL!D203 -> 1732 | H5: =G5/B5-1 -> 0.0011560694 | I5: stockanalysis（14 位） | J5: 錨點＝公司預測 1,732
A6: FY2026 EPS vs 共識 | B6: =c_eps26 -> 145.44183 | C6: =PL!D112 -> 129.84 | D6: =C6/B6-1 -> -0.10727194 | E6: =PL!D162 -> 129.84 | F6: =E6/B6-1 -> -0.10727194 | G6: =PL!D212 -> 129.84 | H6: =G6/B6-1 -> -0.10727194 | I6: stockanalysis 共識淨利 ÷ 股數 | J6: 錨點＝公司預測 129.84；共識高於公司預測（公司 FM 預測保守）
A7: FY2027 營收 vs 共識 | B7: =c_rev27 -> 1840 | C7: =PL!E103 -> 1850.5656 | D7: =C7/B7-1 -> 0.0057421739 | E7: =PL!E153 -> 1850.5656 | F7: =E7/B7-1 -> 0.0057421739 | G7: =PL!E203 -> 1850.5656 | H7: =G7/B7-1 -> 0.0057421739 | I7: stockanalysis（Revenue Next Year）
A8: FY2027 EPS vs 共識 | B8: =c_eps27 -> 179.80973 | C8: =PL!E112 -> 162.81548 | D8: =C8/B8-1 -> -0.094512428 | E8: =PL!E162 -> 162.81548 | F8: =E8/B8-1 -> -0.094512428 | G8: =PL!E212 -> 162.81548 | H8: =G8/B8-1 -> -0.094512428 | I8: Stockopedia 年增率推導 | J8: 單一來源；基期口徑未明示
A9: FY2028 EPS vs 共識 | C9: =PL!F112 -> 184.47595 | E9: =PL!F162 -> 168.27538 | G9: =PL!F212 -> 151.56862 | I9: 未找到 | J9: 共識 FY2028 EPS：未找到
A10: B. 公司預測與 ABF 說法
A11: FY2026 FM 營收 vs 1Q 年化（× 4） | B11: =q1_fm*4 -> 132.4 | C11: =PL!D87 -> 120.6 | D11: =C11/B11-1 -> -0.089123867 | E11: =PL!D137 -> 120.6 | F11: =E11/B11-1 -> -0.089123867 | G11: =PL!D187 -> 120.6 | H11: =G11/B11-1 -> -0.089123867 | I11: 公司 1Q 決算概要 | J11: 公司全年預測低於 1Q 年化：下半年放緩或保守
A12: FY2026 FM 事業利益 vs 1Q 年化 | B12: =q1_fmbp*4 -> 76.4 | C12: =PL!D89 -> 65.5 | D12: =C12/B12-1 -> -0.14267016 | E12: =PL!D139 -> 65.5 | F12: =E12/B12-1 -> -0.14267016 | G12: =PL!D189 -> 65.5 | H12: =G12/B12-1 -> -0.14267016 | I12: 同上
A13: FY2027 FM 事業利益率 vs Palliser 預估 66% | B13: 0.66 | C13: =PL!E88 -> 0.5798315 | D13: =C13/B13-1 -> -0.12146743 | E13: =PL!E138 -> 0.5798315 | F13: =E13/B13-1 -> -0.12146743 | G13: =PL!E188 -> 0.5798315 | H13: =G13/B13-1 -> -0.12146743 | I13: Palliser 2026-03（Interested-party） | J13: Palliser：FY2025E 55%、FY2026E 63%、FY2027E 66%；共識（Palliser 引用）62%
A14: FY2027 FM 營收 ÷ FY2025（兩年成長） | C14: =PL!E87/PL!C87-1 -> 0.71392429 | E14: =PL!E137/PL!C137-1 -> 0.71392429 | G14: =PL!E187/PL!C187-1 -> 0.71392429 | I14: Palliser：未來兩年 ABF 營收年複合 30% 以上（約 +69%）
A15: FY2029 FM 營收 vs FY2024 實績 77（Palliser） | B15: 77 | C15: =PL!G87 -> 243.1296 | D15: =C15/B15-1 -> 2.1575273 | E15: =PL!G137 -> 214.75185 | F15: =E15/B15-1 -> 1.7889851 | G15: =PL!G187 -> 163.34071 | H15: =G15/B15-1 -> 1.1213079 | I15: Palliser FY2024 77；TrendForce 2025-04-01（引日經：2030 年前年增 10% 以上） | J15: 公司說法：年增 10% 以上 × 5 年 ≈ 124 以上
A16: C. 上游載板模型（Ibiden；唯讀）
A17: FY2027 每顆 AI 加速器 ABF 金額 ÷ NVIDIA 載板金額 | B17: 0.1 | C17: =Units!D17 -> 0.11871712 | D17: =C17/B17-1 -> 0.18717115 | E17: =Units!D17 -> 0.11871712 | F17: =E17/B17-1 -> 0.18717115 | G17: =Units!D17 -> 0.11871712 | H17: =G17/B17-1 -> 0.18717115 | I17: Palliser：ABF 約占載板物料成本 10% | J17: Units 頁（情境 A）
A18: FY2027 AI 用 ABF 營收年增 − Ibiden AI 載板營收年增 | C18: =Units!D19 -> 0.34817511 | E18: =Units!D19 -> 0.34817511 | G18: =Units!D19 -> 0.34817511 | I18: ibiden/dist Units | J18: 負值＝味之素出貨受產能上限
A19: D. 校準
A20: FY2026 FM 事業利益率（錨點） | C20: =PL!D88 -> 0.54311774 | E20: =PL!D138 -> 0.54311774 | G20: =PL!D188 -> 0.54311774 | I20: 公司預測 65.5 ÷ 120.6
A21: FY2026 AI 用 ABF 營收（Assumed 切分） | C21: =PL!D85 -> 48.24 | E21: =PL!D135 -> 48.24 | G21: =PL!D185 -> 48.24 | I21: ai_sh 40% | J21: 公司未揭露
A22: FY2026 每顆有效加速器 AI 用 ABF 營收（US$） | C22: =PL!D117 -> 23.508772 | E22: =PL!D167 -> 23.508772 | G22: =PL!D217 -> 23.508772 | I22: —

Sheet Sens
A1: Sens — 一次動一個輸入（情境 A；FY2026 恆等於錨點）：對 FY2027、FY2028 營收、事業利益率與 EPS 的影響。每個案例是一個完整推導區塊（本頁下方）
A3: 案例 | B3: 設定 | C3: FY2027 營收 | D3: FY2027 事業利益率 | E3: FY2027 EPS | F3: FY2027 EPS 相對基準 | G3: FY2028 營收 | H3: FY2028 事業利益率 | I3: FY2028 EPS | J3: FY2028 EPS 相對基準
A4: 基準（情境 A） | B4: PL 區塊 A | C4: =PL!E103 -> 1850.5656 | D4: =PL!E107 -> 0.13295179 | E4: =PL!E112 -> 162.81548 | F4: =E4/E$4-1 -> 0 | G4: =PL!F103 -> 1955.9407 | H4: =PL!F107 -> 0.14038583 | I4: =PL!F112 -> 184.47595 | J4: =I4/I$4-1 -> 0
A5: AI 占比 30% | B5: FY2026 FM 營收中 AI 用 30% | C5: =E83 -> 1845.4104 | D5: =E87 -> 0.13170341 | E5: =E92 -> 160.83738 | F5: =E5/E$4-1 -> -0.01214934 | G5: =F83 -> 1939.0238 | H5: =F87 -> 0.13656338 | I5: =F92 -> 177.90092 | J5: =I5/I$4-1 -> -0.035641675
A6: AI 占比 50% | B6: 50% | C6: =E133 -> 1850.5656 | D6: =E137 -> 0.13295179 | E6: =E142 -> 162.81548 | F6: =E6/E$4-1 -> 0 | G6: =F133 -> 1956.1063 | H6: =F137 -> 0.14042291 | I6: =F142 -> 184.54029 | J6: =I6/I$4-1 -> 0.00034880597
A7: 面積層數 +10%／年 | B7: Ibiden 模型低值 | C7: =E183 -> 1849.2449 | D7: =E187 -> 0.13263264 | E7: =E192 -> 162.30871 | F7: =E7/E$4-1 -> -0.0031124947 | G7: =F183 -> 1939.3667 | H7: =F187 -> 0.13664153 | I7: =F192 -> 178.0342 | J7: =I7/I$4-1 -> -0.034919188
A8: 面積層數 +22%／年 | B8: Ibiden 模型高值 | C8: =E233 -> 1850.5656 | D8: =E237 -> 0.13295179 | E8: =E242 -> 162.81548 | F8: =E8/E$4-1 -> 0 | G8: =F233 -> 1956.1063 | H8: =F237 -> 0.14042291 | I8: =F242 -> 184.54029 | J8: =I8/I$4-1 -> 0.00034880597
A9: 非 NVIDIA 面積係數 0.6 | B9: 欣興模型低值 | C9: =E283 -> 1850.5656 | D9: =E287 -> 0.13295179 | E9: =E292 -> 162.81548 | F9: =E9/E$4-1 -> 0 | G9: =F283 -> 1950.8059 | H9: =F287 -> 0.1392326 | I9: =F292 -> 182.48021 | J9: =I9/I$4-1 -> -0.010818389
A10: 非 NVIDIA 面積係數 1.0 | B10: 欣興模型高值 | C10: =E333 -> 1850.5656 | D10: =E337 -> 0.13295179 | E10: =E342 -> 162.81548 | F10: =E10/E$4-1 -> 0 | G10: =F333 -> 1956.1063 | H10: =F337 -> 0.14042291 | I10: =F342 -> 184.54029 | J10: =I10/I$4-1 -> 0.00034880597
A11: 產能上限 低 | B11: 1.15／1.30／1.45（公司 +50%／五年的速度） | C11: =E383 -> 1830.3048 | D11: =E387 -> 0.128005 | E11: =E392 -> 155.04128 | F11: =E11/E$4-1 -> -0.047748498 | G11: =F383 -> 1921.4338 | H11: =F387 -> 0.13251747 | I11: =F392 -> 171.06428 | J11: =I11/I$4-1 -> -0.072701443
A12: 產能上限 高 | B12: 1.45／1.85／2.25（不設限） | C12: =E433 -> 1855.8484 | D12: =E437 -> 0.13422387 | E12: =E442 -> 164.84253 | F12: =E12/E$4-1 -> 0.012449979 | G12: =F433 -> 1955.9407 | H12: =F437 -> 0.14038583 | I12: =F442 -> 184.47595 | J12: =I12/I$4-1 -> 0
A13: ABF 價格 低 | B13: 1.00／0.95／0.90 | C13: =E483 -> 1831.752 | D13: =E487 -> 0.12404649 | E13: =E492 -> 150.36549 | F13: =E13/E$4-1 -> -0.076466855 | G13: =F483 -> 1918.5835 | H13: =F487 -> 0.12364807 | I13: =F492 -> 159.37817 | J13: =I13/I$4-1 -> -0.13604902
A14: ABF 價格 高 | B14: 1.20／1.30／1.30 | C14: =E533 -> 1863.108 | D14: =E537 -> 0.13878874 | E14: =E542 -> 171.11547 | F14: =E14/E$4-1 -> 0.050977904 | G14: =F533 -> 1983.9586 | H14: =F537 -> 0.15252549 | I14: =F542 -> 203.29928 | J14: =I14/I$4-1 -> 0.10203677
A15: 份額流失 | B15: 份額相對值 0.95／0.88／0.80 | C15: =E583 -> 1850.5656 | D15: =E587 -> 0.13295179 | E15: =E592 -> 162.81548 | F15: =E15/E$4-1 -> 0 | G15: =F583 -> 1944.2016 | H15: =F587 -> 0.13774038 | I15: =F592 -> 179.91333 | J15: =I15/I$4-1 -> -0.024732846
A16: 單位成本 +6%／年 | B16: c_g 高值 | C16: =E633 -> 1850.5656 | D16: =E637 -> 0.13179058 | E16: =E642 -> 161.39343 | F16: =E16/E$4-1 -> -0.0087340873 | G16: =F633 -> 1955.9407 | H16: =F637 -> 0.13765018 | I16: =F642 -> 180.88113 | J16: =I16/I$4-1 -> -0.019486654
A17: 非 AI ABF −2%／年 | B17: g_nai 低值 | C17: =E683 -> 1850.5656 | D17: =E687 -> 0.13295179 | E17: =E692 -> 162.81548 | F17: =E17/E$4-1 -> 0 | G17: =F683 -> 1947.5777 | H17: =F687 -> 0.13850448 | I17: =F692 -> 181.22553 | J17: =I17/I$4-1 -> -0.01761972
A18: 調味料・食品利益率 13.5% | B18: m_sf 低值 | C18: =E733 -> 1850.5656 | D18: =E737 -> 0.12671988 | E18: =E742 -> 155.18375 | F18: =E18/E$4-1 -> -0.046873464 | G18: =F733 -> 1955.9407 | H18: =F737 -> 0.13425381 | I18: =F742 -> 176.41809 | J18: =I18/I$4-1 -> -0.043679745
A19: 調味料・食品利益率 15.5% | B19: m_sf 高值 | C19: =E783 -> 1850.5656 | D19: =E787 -> 0.13794395 | E19: =E792 -> 168.92898 | F19: =E19/E$4-1 -> 0.03754865 | G19: =F783 -> 1955.9407 | H19: =F787 -> 0.14529797 | I19: =F792 -> 190.93081 | J19: =I19/I$4-1 -> 0.034990276
A20: 調味料・食品成長 2% | B20: g_sf 低值 | C20: =E833 -> 1830.5936 | D20: =E837 -> 0.13280829 | E20: =E842 -> 160.88448 | F20: =E20/E$4-1 -> -0.011860053 | G20: =F833 -> 1914.7984 | H20: =F837 -> 0.14026296 | I20: =F842 -> 180.43751 | J20: =I20/I$4-1 -> -0.0218914
A21: 冷凍食品利益率 6% | B21: m_ff 高值（重整成功） | C21: =E883 -> 1850.5656 | D21: =E887 -> 0.13554493 | E21: =E892 -> 165.99108 | F21: =E21/E$4-1 -> 0.01950434 | G21: =F883 -> 1955.9407 | H21: =F887 -> 0.14291287 | I21: =F892 -> 187.79663 | J21: =I21/I$4-1 -> 0.01800065
A22: 淨利 ÷ 事業利益 0.58 | B22: ni_bp 低值 | C22: =E933 -> 1850.5656 | D22: =E937 -> 0.13295179 | E22: =E942 -> 152.31125 | F22: =E22/E$4-1 -> -0.064516129 | G22: =F933 -> 1955.9407 | H22: =F937 -> 0.14038583 | I22: =F942 -> 172.57427 | J22: =I22/I$4-1 -> -0.064516129
A23: 淨利 ÷ 事業利益 0.66 | B23: ni_bp 高值（合併稅務利益） | C23: =E983 -> 1850.5656 | D23: =E987 -> 0.13295179 | E23: =E992 -> 173.3197 | F23: =E23/E$4-1 -> 0.064516129 | G23: =F983 -> 1955.9407 | H23: =F987 -> 0.14038583 | I23: =F992 -> 196.37762 | J23: =I23/I$4-1 -> 0.064516129
A24: 買回 多（−3%） | B24: 股數年變動 −3% | C24: =E1033 -> 1850.5656 | D24: =E1037 -> 0.13295179 | E24: =E1042 -> 165.33324 | F24: =E24/E$4-1 -> 0.015463918 | G24: =F1033 -> 1955.9407 | H24: =F1037 -> 0.14038583 | I24: =F1042 -> 190.2255 | J24: =I24/I$4-1 -> 0.031166968
A25: 情境 B | B25: CY2028 顆數 ×0.8、CY2029 ×0.85；ABF 價格 ×0.95 | C25: =PL!E153 -> 1850.5656 | D25: =PL!E157 -> 0.13295179 | E25: =PL!E162 -> 162.81548 | F25: =E25/E$4-1 -> 0 | G25: =PL!F153 -> 1921.1613 | H25: =PL!F157 -> 0.1303755 | I25: =PL!F162 -> 168.27538 | J25: =I25/I$4-1 -> -0.08781938
A26: 情境 C | B26: CY2028–29 顆數 ×0.6；ABF 價格 ×0.88 | C26: =PL!E203 -> 1850.5656 | D26: =PL!E207 -> 0.13295179 | E26: =PL!E212 -> 162.81548 | F26: =E26/E$4-1 -> 0 | G26: =PL!F203 -> 1885.6285 | H26: =PL!F207 -> 0.11964441 | I26: =PL!F212 -> 151.56862 | J26: =I26/I$4-1 -> -0.17838273
A28: 讀法：FY2027 起需求量高於可出貨量上限，AI 占比、面積層數與顆數假設的變動大多被產能上限吸收；EPS 對 ABF 價格與產能上限最敏感，其次是調味料・食品利益率（本業事業利益約三分之二）。情境 B、C 的差異從 FY2028 起。
A30: 目標價參數（只改 DCF 參數；PL 收斂法的 fade_g 不隨 tp_g 變動）
A31: 案例 | B31: 設定 | C31: DCF 目標價 | D31: Comparable 目標價 | E31: 加權目標價 | F31: 相對基準
A32: 基準 | B32: r 10%、g 4%、DCF 權重 0.5 | C32: =(tp_wA*MAX(0,Val!B8*(1-MIN(tp_g/tp_roe,0.8))/(1+tp_r)^Val!$F$8+Val!B9*(1-MIN(tp_g/tp_roe,0.8))/(1+tp_r)^Val!$F$9+Val!B10*(1-MIN(tp_g/tp_roe,0.8))/(1+tp_r)^Val!$F$10+Val!B11*(1-MIN(tp_g/tp_roe,0.8))/(1+tp_r)^Val!$F$11+Val!B12*(1-MIN(tp_g/tp_roe,0.8))/(1+tp_r)^Val!$F$12+Val!B13*(1-MIN(tp_g/tp_roe,0.8))/(1+tp_r)^Val!$F$13+Val!B13*(1-MIN(tp_g/tp_roe,0.8))*(1+tp_g)/(tp_r-tp_g)/(1+tp_r)^Val!$F$13)+tp_wB*MAX(0,Val!C8*(1-MIN(tp_g/tp_roe,0.8))/(1+tp_r)^Val!$F$8+Val!C9*(1-MIN(tp_g/tp_roe,0.8))/(1+tp_r)^Val!$F$9+Val!C10*(1-MIN(tp_g/tp_roe,0.8))/(1+tp_r)^Val!$F$10+Val!C11*(1-MIN(tp_g/tp_roe,0.8))/(1+tp_r)^Val!$F$11+Val!C12*(1-MIN(tp_g/tp_roe,0.8))/(1+tp_r)^Val!$F$12+Val!C13*(1-MIN(tp_g/tp_roe,0.8))/(1+tp_r)^Val!$F$13+Val!C13*(1-MIN(tp_g/tp_roe,0.8))*(1+tp_g)/(tp_r-tp_g)/(1+tp_r)^Val!$F$13)+tp_wC*MAX(0,Val!D8*(1-MIN(tp_g/tp_roe,0.8))/(1+tp_r)^Val!$F$8+Val!D9*(1-MIN(tp_g/tp_roe,0.8))/(1+tp_r)^Val!$F$9+Val!D10*(1-MIN(tp_g/tp_roe,0.8))/(1+tp_r)^Val!$F$10+Val!D11*(1-MIN(tp_g/tp_roe,0.8))/(1+tp_r)^Val!$F$11+Val!D12*(1-MIN(tp_g/tp_roe,0.8))/(1+tp_r)^Val!$F$12+Val!D13*(1-MIN(tp_g/tp_roe,0.8))/(1+tp_r)^Val!$F$13+Val!D13*(1-MIN(tp_g/tp_roe,0.8))*(1+tp_g)/(tp_r-tp_g)/(1+tp_r)^Val!$F$13))*(1+tp_r) -> 2109.9402 | D32: =Val!B36 -> 2964.7369 | E32: =tp_w_dcf*C32+(1-tp_w_dcf)*D32 -> 2537.3386 | F32: =E32/E$32-1 -> 0
A33: 折現率 +1pt | B33: r 11% | C33: =(tp_wA*MAX(0,Val!B8*(1-MIN(tp_g/tp_roe,0.8))/(1+(tp_r+0.01))^Val!$F$8+Val!B9*(1-MIN(tp_g/tp_roe,0.8))/(1+(tp_r+0.01))^Val!$F$9+Val!B10*(1-MIN(tp_g/tp_roe,0.8))/(1+(tp_r+0.01))^Val!$F$10+Val!B11*(1-MIN(tp_g/tp_roe,0.8))/(1+(tp_r+0.01))^Val!$F$11+Val!B12*(1-MIN(tp_g/tp_roe,0.8))/(1+(tp_r+0.01))^Val!$F$12+Val!B13*(1-MIN(tp_g/tp_roe,0.8))/(1+(tp_r+0.01))^Val!$F$13+Val!B13*(1-MIN(tp_g/tp_roe,0.8))*(1+tp_g)/((tp_r+0.01)-tp_g)/(1+(tp_r+0.01))^Val!$F$13)+tp_wB*MAX(0,Val!C8*(1-MIN(tp_g/tp_roe,0.8))/(1+(tp_r+0.01))^Val!$F$8+Val!C9*(1-MIN(tp_g/tp_roe,0.8))/(1+(tp_r+0.01))^Val!$F$9+Val!C10*(1-MIN(tp_g/tp_roe,0.8))/(1+(tp_r+0.01))^Val!$F$10+Val!C11*(1-MIN(tp_g/tp_roe,0.8))/(1+(tp_r+0.01))^Val!$F$11+Val!C12*(1-MIN(tp_g/tp_roe,0.8))/(1+(tp_r+0.01))^Val!$F$12+Val!C13*(1-MIN(tp_g/tp_roe,0.8))/(1+(tp_r+0.01))^Val!$F$13+Val!C13*(1-MIN(tp_g/tp_roe,0.8))*(1+tp_g)/((tp_r+0.01)-tp_g)/(1+(tp_r+0.01))^Val!$F$13)+tp_wC*MAX(0,Val!D8*(1-MIN(tp_g/tp_roe,0.8))/(1+(tp_r+0.01))^Val!$F$8+Val!D9*(1-MIN(tp_g/tp_roe,0.8))/(1+(tp_r+0.01))^Val!$F$9+Val!D10*(1-MIN(tp_g/tp_roe,0.8))/(1+(tp_r+0.01))^Val!$F$10+Val!D11*(1-MIN(tp_g/tp_roe,0.8))/(1+(tp_r+0.01))^Val!$F$11+Val!D12*(1-MIN(tp_g/tp_roe,0.8))/(1+(tp_r+0.01))^Val!$F$12+Val!D13*(1-MIN(tp_g/tp_roe,0.8))/(1+(tp_r+0.01))^Val!$F$13+Val!D13*(1-MIN(tp_g/tp_roe,0.8))*(1+tp_g)/((tp_r+0.01)-tp_g)/(1+(tp_r+0.01))^Val!$F$13))*(1+(tp_r+0.01)) -> 1825.0188 | D33: =Val!B36 -> 2964.7369 | E33: =tp_w_dcf*C33+(1-tp_w_dcf)*D33 -> 2394.8778 | F33: =E33/E$32-1 -> -0.056145721
A34: 折現率 −1pt | B34: r 9% | C34: =(tp_wA*MAX(0,Val!B8*(1-MIN(tp_g/tp_roe,0.8))/(1+(tp_r-0.01))^Val!$F$8+Val!B9*(1-MIN(tp_g/tp_roe,0.8))/(1+(tp_r-0.01))^Val!$F$9+Val!B10*(1-MIN(tp_g/tp_roe,0.8))/(1+(tp_r-0.01))^Val!$F$10+Val!B11*(1-MIN(tp_g/tp_roe,0.8))/(1+(tp_r-0.01))^Val!$F$11+Val!B12*(1-MIN(tp_g/tp_roe,0.8))/(1+(tp_r-0.01))^Val!$F$12+Val!B13*(1-MIN(tp_g/tp_roe,0.8))/(1+(tp_r-0.01))^Val!$F$13+Val!B13*(1-MIN(tp_g/tp_roe,0.8))*(1+tp_g)/((tp_r-0.01)-tp_g)/(1+(tp_r-0.01))^Val!$F$13)+tp_wB*MAX(0,Val!C8*(1-MIN(tp_g/tp_roe,0.8))/(1+(tp_r-0.01))^Val!$F$8+Val!C9*(1-MIN(tp_g/tp_roe,0.8))/(1+(tp_r-0.01))^Val!$F$9+Val!C10*(1-MIN(tp_g/tp_roe,0.8))/(1+(tp_r-0.01))^Val!$F$10+Val!C11*(1-MIN(tp_g/tp_roe,0.8))/(1+(tp_r-0.01))^Val!$F$11+Val!C12*(1-MIN(tp_g/tp_roe,0.8))/(1+(tp_r-0.01))^Val!$F$12+Val!C13*(1-MIN(tp_g/tp_roe,0.8))/(1+(tp_r-0.01))^Val!$F$13+Val!C13*(1-MIN(tp_g/tp_roe,0.8))*(1+tp_g)/((tp_r-0.01)-tp_g)/(1+(tp_r-0.01))^Val!$F$13)+tp_wC*MAX(0,Val!D8*(1-MIN(tp_g/tp_roe,0.8))/(1+(tp_r-0.01))^Val!$F$8+Val!D9*(1-MIN(tp_g/tp_roe,0.8))/(1+(tp_r-0.01))^Val!$F$9+Val!D10*(1-MIN(tp_g/tp_roe,0.8))/(1+(tp_r-0.01))^Val!$F$10+Val!D11*(1-MIN(tp_g/tp_roe,0.8))/(1+(tp_r-0.01))^Val!$F$11+Val!D12*(1-MIN(tp_g/tp_roe,0.8))/(1+(tp_r-0.01))^Val!$F$12+Val!D13*(1-MIN(tp_g/tp_roe,0.8))/(1+(tp_r-0.01))^Val!$F$13+Val!D13*(1-MIN(tp_g/tp_roe,0.8))*(1+tp_g)/((tp_r-0.01)-tp_g)/(1+(tp_r-0.01))^Val!$F$13))*(1+(tp_r-0.01)) -> 2508.7879 | D34: =Val!B36 -> 2964.7369 | E34: =tp_w_dcf*C34+(1-tp_w_dcf)*D34 -> 2736.7624 | F34: =E34/E$32-1 -> 0.078595667
A35: 長期成長 +1pt | B35: g 5% | C35: =(tp_wA*MAX(0,Val!B8*(1-MIN((tp_g+0.01)/tp_roe,0.8))/(1+tp_r)^Val!$F$8+Val!B9*(1-MIN((tp_g+0.01)/tp_roe,0.8))/(1+tp_r)^Val!$F$9+Val!B10*(1-MIN((tp_g+0.01)/tp_roe,0.8))/(1+tp_r)^Val!$F$10+Val!B11*(1-MIN((tp_g+0.01)/tp_roe,0.8))/(1+tp_r)^Val!$F$11+Val!B12*(1-MIN((tp_g+0.01)/tp_roe,0.8))/(1+tp_r)^Val!$F$12+Val!B13*(1-MIN((tp_g+0.01)/tp_roe,0.8))/(1+tp_r)^Val!$F$13+Val!B13*(1-MIN((tp_g+0.01)/tp_roe,0.8))*(1+(tp_g+0.01))/(tp_r-(tp_g+0.01))/(1+tp_r)^Val!$F$13)+tp_wB*MAX(0,Val!C8*(1-MIN((tp_g+0.01)/tp_roe,0.8))/(1+tp_r)^Val!$F$8+Val!C9*(1-MIN((tp_g+0.01)/tp_roe,0.8))/(1+tp_r)^Val!$F$9+Val!C10*(1-MIN((tp_g+0.01)/tp_roe,0.8))/(1+tp_r)^Val!$F$10+Val!C11*(1-MIN((tp_g+0.01)/tp_roe,0.8))/(1+tp_r)^Val!$F$11+Val!C12*(1-MIN((tp_g+0.01)/tp_roe,0.8))/(1+tp_r)^Val!$F$12+Val!C13*(1-MIN((tp_g+0.01)/tp_roe,0.8))/(1+tp_r)^Val!$F$13+Val!C13*(1-MIN((tp_g+0.01)/tp_roe,0.8))*(1+(tp_g+0.01))/(tp_r-(tp_g+0.01))/(1+tp_r)^Val!$F$13)+tp_wC*MAX(0,Val!D8*(1-MIN((tp_g+0.01)/tp_roe,0.8))/(1+tp_r)^Val!$F$8+Val!D9*(1-MIN((tp_g+0.01)/tp_roe,0.8))/(1+tp_r)^Val!$F$9+Val!D10*(1-MIN((tp_g+0.01)/tp_roe,0.8))/(1+tp_r)^Val!$F$10+Val!D11*(1-MIN((tp_g+0.01)/tp_roe,0.8))/(1+tp_r)^Val!$F$11+Val!D12*(1-MIN((tp_g+0.01)/tp_roe,0.8))/(1+tp_r)^Val!$F$12+Val!D13*(1-MIN((tp_g+0.01)/tp_roe,0.8))/(1+tp_r)^Val!$F$13+Val!D13*(1-MIN((tp_g+0.01)/tp_roe,0.8))*(1+(tp_g+0.01))/(tp_r-(tp_g+0.01))/(1+tp_r)^Val!$F$13))*(1+tp_r) -> 2158.3965 | D35: =Val!B36 -> 2964.7369 | E35: =tp_w_dcf*C35+(1-tp_w_dcf)*D35 -> 2561.5667 | F35: =E35/E$32-1 -> 0.0095486439
A36: 長期成長 −1pt | B36: g 3% | C36: =(tp_wA*MAX(0,Val!B8*(1-MIN((tp_g-0.01)/tp_roe,0.8))/(1+tp_r)^Val!$F$8+Val!B9*(1-MIN((tp_g-0.01)/tp_roe,0.8))/(1+tp_r)^Val!$F$9+Val!B10*(1-MIN((tp_g-0.01)/tp_roe,0.8))/(1+tp_r)^Val!$F$10+Val!B11*(1-MIN((tp_g-0.01)/tp_roe,0.8))/(1+tp_r)^Val!$F$11+Val!B12*(1-MIN((tp_g-0.01)/tp_roe,0.8))/(1+tp_r)^Val!$F$12+Val!B13*(1-MIN((tp_g-0.01)/tp_roe,0.8))/(1+tp_r)^Val!$F$13+Val!B13*(1-MIN((tp_g-0.01)/tp_roe,0.8))*(1+(tp_g-0.01))/(tp_r-(tp_g-0.01))/(1+tp_r)^Val!$F$13)+tp_wB*MAX(0,Val!C8*(1-MIN((tp_g-0.01)/tp_roe,0.8))/(1+tp_r)^Val!$F$8+Val!C9*(1-MIN((tp_g-0.01)/tp_roe,0.8))/(1+tp_r)^Val!$F$9+Val!C10*(1-MIN((tp_g-0.01)/tp_roe,0.8))/(1+tp_r)^Val!$F$10+Val!C11*(1-MIN((tp_g-0.01)/tp_roe,0.8))/(1+tp_r)^Val!$F$11+Val!C12*(1-MIN((tp_g-0.01)/tp_roe,0.8))/(1+tp_r)^Val!$F$12+Val!C13*(1-MIN((tp_g-0.01)/tp_roe,0.8))/(1+tp_r)^Val!$F$13+Val!C13*(1-MIN((tp_g-0.01)/tp_roe,0.8))*(1+(tp_g-0.01))/(tp_r-(tp_g-0.01))/(1+tp_r)^Val!$F$13)+tp_wC*MAX(0,Val!D8*(1-MIN((tp_g-0.01)/tp_roe,0.8))/(1+tp_r)^Val!$F$8+Val!D9*(1-MIN((tp_g-0.01)/tp_roe,0.8))/(1+tp_r)^Val!$F$9+Val!D10*(1-MIN((tp_g-0.01)/tp_roe,0.8))/(1+tp_r)^Val!$F$10+Val!D11*(1-MIN((tp_g-0.01)/tp_roe,0.8))/(1+tp_r)^Val!$F$11+Val!D12*(1-MIN((tp_g-0.01)/tp_roe,0.8))/(1+tp_r)^Val!$F$12+Val!D13*(1-MIN((tp_g-0.01)/tp_roe,0.8))/(1+tp_r)^Val!$F$13+Val!D13*(1-MIN((tp_g-0.01)/tp_roe,0.8))*(1+(tp_g-0.01))/(tp_r-(tp_g-0.01))/(1+tp_r)^Val!$F$13))*(1+tp_r) -> 2091.7587 | D36: =Val!B36 -> 2964.7369 | E36: =tp_w_dcf*C36+(1-tp_w_dcf)*D36 -> 2528.2478 | F36: =E36/E$32-1 -> -0.0035827987
A37: DCF 權重 0.3 | C37: =(tp_wA*MAX(0,Val!B8*(1-MIN(tp_g/tp_roe,0.8))/(1+tp_r)^Val!$F$8+Val!B9*(1-MIN(tp_g/tp_roe,0.8))/(1+tp_r)^Val!$F$9+Val!B10*(1-MIN(tp_g/tp_roe,0.8))/(1+tp_r)^Val!$F$10+Val!B11*(1-MIN(tp_g/tp_roe,0.8))/(1+tp_r)^Val!$F$11+Val!B12*(1-MIN(tp_g/tp_roe,0.8))/(1+tp_r)^Val!$F$12+Val!B13*(1-MIN(tp_g/tp_roe,0.8))/(1+tp_r)^Val!$F$13+Val!B13*(1-MIN(tp_g/tp_roe,0.8))*(1+tp_g)/(tp_r-tp_g)/(1+tp_r)^Val!$F$13)+tp_wB*MAX(0,Val!C8*(1-MIN(tp_g/tp_roe,0.8))/(1+tp_r)^Val!$F$8+Val!C9*(1-MIN(tp_g/tp_roe,0.8))/(1+tp_r)^Val!$F$9+Val!C10*(1-MIN(tp_g/tp_roe,0.8))/(1+tp_r)^Val!$F$10+Val!C11*(1-MIN(tp_g/tp_roe,0.8))/(1+tp_r)^Val!$F$11+Val!C12*(1-MIN(tp_g/tp_roe,0.8))/(1+tp_r)^Val!$F$12+Val!C13*(1-MIN(tp_g/tp_roe,0.8))/(1+tp_r)^Val!$F$13+Val!C13*(1-MIN(tp_g/tp_roe,0.8))*(1+tp_g)/(tp_r-tp_g)/(1+tp_r)^Val!$F$13)+tp_wC*MAX(0,Val!D8*(1-MIN(tp_g/tp_roe,0.8))/(1+tp_r)^Val!$F$8+Val!D9*(1-MIN(tp_g/tp_roe,0.8))/(1+tp_r)^Val!$F$9+Val!D10*(1-MIN(tp_g/tp_roe,0.8))/(1+tp_r)^Val!$F$10+Val!D11*(1-MIN(tp_g/tp_roe,0.8))/(1+tp_r)^Val!$F$11+Val!D12*(1-MIN(tp_g/tp_roe,0.8))/(1+tp_r)^Val!$F$12+Val!D13*(1-MIN(tp_g/tp_roe,0.8))/(1+tp_r)^Val!$F$13+Val!D13*(1-MIN(tp_g/tp_roe,0.8))*(1+tp_g)/(tp_r-tp_g)/(1+tp_r)^Val!$F$13))*(1+tp_r) -> 2109.9402 | D37: =Val!B36 -> 2964.7369 | E37: =0.3*C37+(1-0.3)*D37 -> 2708.2979 | F37: =E37/E$32-1 -> 0.067377422
A38: DCF 權重 0.7 | C38: =(tp_wA*MAX(0,Val!B8*(1-MIN(tp_g/tp_roe,0.8))/(1+tp_r)^Val!$F$8+Val!B9*(1-MIN(tp_g/tp_roe,0.8))/(1+tp_r)^Val!$F$9+Val!B10*(1-MIN(tp_g/tp_roe,0.8))/(1+tp_r)^Val!$F$10+Val!B11*(1-MIN(tp_g/tp_roe,0.8))/(1+tp_r)^Val!$F$11+Val!B12*(1-MIN(tp_g/tp_roe,0.8))/(1+tp_r)^Val!$F$12+Val!B13*(1-MIN(tp_g/tp_roe,0.8))/(1+tp_r)^Val!$F$13+Val!B13*(1-MIN(tp_g/tp_roe,0.8))*(1+tp_g)/(tp_r-tp_g)/(1+tp_r)^Val!$F$13)+tp_wB*MAX(0,Val!C8*(1-MIN(tp_g/tp_roe,0.8))/(1+tp_r)^Val!$F$8+Val!C9*(1-MIN(tp_g/tp_roe,0.8))/(1+tp_r)^Val!$F$9+Val!C10*(1-MIN(tp_g/tp_roe,0.8))/(1+tp_r)^Val!$F$10+Val!C11*(1-MIN(tp_g/tp_roe,0.8))/(1+tp_r)^Val!$F$11+Val!C12*(1-MIN(tp_g/tp_roe,0.8))/(1+tp_r)^Val!$F$12+Val!C13*(1-MIN(tp_g/tp_roe,0.8))/(1+tp_r)^Val!$F$13+Val!C13*(1-MIN(tp_g/tp_roe,0.8))*(1+tp_g)/(tp_r-tp_g)/(1+tp_r)^Val!$F$13)+tp_wC*MAX(0,Val!D8*(1-MIN(tp_g/tp_roe,0.8))/(1+tp_r)^Val!$F$8+Val!D9*(1-MIN(tp_g/tp_roe,0.8))/(1+tp_r)^Val!$F$9+Val!D10*(1-MIN(tp_g/tp_roe,0.8))/(1+tp_r)^Val!$F$10+Val!D11*(1-MIN(tp_g/tp_roe,0.8))/(1+tp_r)^Val!$F$11+Val!D12*(1-MIN(tp_g/tp_roe,0.8))/(1+tp_r)^Val!$F$12+Val!D13*(1-MIN(tp_g/tp_roe,0.8))/(1+tp_r)^Val!$F$13+Val!D13*(1-MIN(tp_g/tp_roe,0.8))*(1+tp_g)/(tp_r-tp_g)/(1+tp_r)^Val!$F$13))*(1+tp_r) -> 2109.9402 | D38: =Val!B36 -> 2964.7369 | E38: =0.7*C38+(1-0.7)*D38 -> 2366.3792 | F38: =E38/E$32-1 -> -0.067377422
A50: 案例區塊：AI 占比 30%（情境 A）
A51: 項目 | B51: 單位 | C51: FY2025A | D51: FY2026（錨點） | E51: FY2027 | F51: FY2028 | G51: FY2029 | H51: FY2030（收斂） | I51: FY2031（收斂） | J51: FY2032（收斂） | K51: 說明
A52: A. ABF 需求（D 欄＝FY2026 校準年；FY(t) 對照 CY(t) 顆數）
A53: NVIDIA 加速器顆數 × 情境係數 | B53: 百萬顆 | D53: =unv_26 -> 7.6 | E53: =unv_27 -> 9.7 | F53: =unv_28*um28_A -> 9.5 | G53: =unv_29*um29_A -> 10.6 | K53: tsmc 成品：Blackwell、Rubin、Rubin Ultra、Hopper
A54: 非 NVIDIA 加速器顆數 × 情境係數 | B54: 百萬顆 | D54: =uot_26 -> 7.6 | E54: =uot_27 -> 14 | F54: =uot_28*um28_A -> 17 | G54: =uot_29*um29_A -> 19.55 | K54: AMD、TPU、Trainium、其他 ASIC
...

Sheet Sources
A1: 來源（公司原文為決算短信、決算概要、IR 簡報；公司預測為 Interested-party；股東行動派、券商、媒體與資料商皆為 Interested-party）
A2: 公司：2026 年 3 月期決算短信（FY2025 實績、分部門、FY2026 期初預測、折舊、資本支出、股數；2026-05-07） | B2: https://www.ajinomoto.com/cms_wp_ajnmt_global/wp-content/uploads/pdf/2026_05_07_03E.pdf
A3: 公司：2027 年 3 月期 Q1 決算短信（1Q 實績、上修後全年預測、EPS 129.84、股數；2026-08-06） | B3: https://news.ajinomoto.co.jp/2026/08/2026_08_06_03.pdf
A4: 公司：2027 年 3 月期 Q1 決算概要（分部門與子部門：ファンクショナルマテリアルズ 1Q 33.1／19.1、全年 120.6／65.5；匯率前提 ¥150） | B4: https://www.ajinomoto.co.jp/company/jp/ir/event/presentation/main/011111114/teaserItems1/00/linkList/01/link/FY25Q4_Results_J.pdf
A5: 公司：2026-08-06 IR 簡報（味之素ファインテクノ FY2025 營收 98.383、營業利益 53.012；2027-04 吸收合併；中東影響 −25 十億） | B5: https://www.ajinomoto.co.jp/company/jp/ir/event/presentation/main/011111114/teaserItems1/00/linkList/03/link/FY25Q3_Presentation_J.pdf
A6: 公司：ASV Report 2026 分部門回顧（Functional Materials 占ヘルスケア等營收 30%） | B6: https://www.ajinomoto.com/sustainability/pdf/2026/ASV_Report_2026_A4_en_014-015.pdf
A7: 媒體：TrendForce 2026-05-08（FM 事業利益 546 億、電子材料營收 1,007 億、市占逾 95%、岐阜新廠 2032） | B7: https://www.trendforce.com/news/2026/05/08/news-ajinomoto-ramps-chip-packaging-push-with-%C2%A51-2b-land-buy-for-new-plant-in-2032-abf-margins-top-50-on-ai-boom/
A8: 媒體：TrendForce 2025-04-01（2030 年前投資 250 億、ABF 產能 +50%、FM 年增 10% 以上） | B8: https://www.trendforce.com/news/2025/04/01/news-japanese-firm-ajinomoto-to-invest-jpy-25-billion-by-2030-to-expand-abf-production/
A9: 媒體：EdgeX 2026-08-08（ABF 漲價約 30%、積水化學約 5%、供需缺口、股價 5,196） | B9: https://pro.edgex.exchange/en-US/news/article/ajinomoto-ai-chip-film-price-hike
A10: 媒體：BigGo Finance 2026-02-06（FY2025 預測上修，電子材料帶動） | B10: https://finance.biggo.com/news/rYUmMZwBy4YEFZDUYyRK
A11: 股東行動派：Palliser Capital 價值提升計畫 2026-03（ABF 歷年營收與利益、AI 占比、漲價建議、同業 P/E；Interested-party） | B11: https://mms.businesswire.com/media/20260331071448/ja/2761329/1/JPN_Palliser_-_Ajinomoto_Value_Enhancement_Plan_March_2026_-_vSent.pdf
A12: 券商：DBS 2026-08-12（BUY、目標價 6,200、40 倍 × FY26F 正常化 EPS 155） | B12: https://www.dbs.com.sg/treasures/aics/templatedata/article/generic/data/en/GR/Japan/2802_JP.xml
A13: 媒體：TechNews 2026-06-23（高盛目標價 6,500） | B13: https://cdnfinance.technews.tw/2026/06/23/abf-drives-strong-performance-brokers-raise-target-prices-ajinomoto-consecutive-record-highs/
... A30: SemiAnalysis | B30: 未使用
