Workbook

Sheet README
A1: Anthropic 收支模型 v0.1.5（v0.1.5；2026-10-24）
A2: 命題（與 OpenAI v0.6 同一句）：Anthropic 每 VR 等值 GW 的年營收能否覆蓋每 GW 年全成本；若不能，缺口要多少外部資金、由誰以什麼條件提供。FY2025–FY2030，曆年制，2025 為實際校準年。
A4: 本版範圍 | B4: v0.1.5：SRC_ANT、TK_Link（含 NonNV 讀表）、OAI_Link、Inputs、Demand（需求與 token 量）、Revenue（訂閱方案別、API 層級別、通路分成、淨額、容量上限）、Compute（加速器族、逐合約供給 GW、η、推論與研發 GW、容量上限、VR 等值）、Cost（逐合約實付、自建資本支出、供應商持有成本、非算力成本、股權報酬、命題表；A4 補逐家對帳與敏感度）、Bridge（逐層對照，唯讀）、EtaDiag（η 診斷，唯讀）、Funding（命題 2）、Reverse（管理層目標反解，只作對照）、Checks。
A5: v0.1.3 A 段更新 | B5: 採納外部驗收報告（v0.1.2）：①TK 快照改 v19.0（103 個值與 v18.0 相同）；②U2 新法（Inputs u2_method）：Nscale、Lambda 供給 GW 取揭露 MW（460／350），付款路徑不變（『最高 86』按 MW 比例分攤的年付款，Cost 第二十二節；隱含每 GW 年付款對照列）；③資金三層（Funding 第十節：①營運自由現金流自給、②加已到位股權＝基準、③再加條件式）；④持續擴張情境（Cost 第二十三節、Funding 第十一節；只作情境，基準不追加）；⑤HTML 結論改條件式。新列皆附加在頁尾，既有列編號不變。
A6: v0.1.3 B 段更新 | B6: ①Bridge 頁（Cost 之後；唯讀）：需求 → token → GW → 成本逐層對照（公式來源、單位、2025–2030、2030 敏感度包絡、標記），最後一節與 Tokenomics 同口徑量對照；②EtaDiag 頁（唯讀）：η（2025）拆成計價口徑 × 利用率 × 工作負載組合 × 未解釋殘差（只作診斷，η 的值不變），並列 TK L1_Gap*（OpenAI 口徑，Analogy）；③TK_Link 尾端新增 23 個對照名稱（IF_UtilActual、L1_TokGW_PaidCap_VR200、B4_MixPaid、L1_Gap* 各含低／高）；④公開 S-1 或經審計資料出現時的替換程序見 CLAUDE.md 第 8 節。兩頁不被任何計算頁引用（Checks e1_iso）。
A7: v0.1.2 更新 | B7: Tokenomics 快照 v5.26 → v18.0（master 868e2cc）：TK_Link 以同一份名稱清單重讀；公式不變。η（2025 校準）吸收 IF_TokGW_* 的整體上升；TK 值變動的名稱逐一在報告「語意核對」列出；Cost 第二十節、Checks 尾端加 L1_RevGW_PQ_VR200 對照列（只對照，不回饋計算）。
A8: v0.1.1 更新 | B8: 依 WSJ 轉述的草擬 S-1（2026-10-20）與 Q3 投資人簡報（2026-10-14）：新增 SRC_ANT_380–409；U1 2026 營收基準＝上半年實際＋Q3 實際＋Q4（Q3 持平）；U2 Nscale＋Lambda 兩約合計錨定『最高 86』；U3 逐家與三口徑承諾對照；U4 2026 算力支出對照（不校準）；U5 D22 加 Q3 11%；U6 談判中 $150B 情境（Cost 第十九節、Funding S8）；U7 上半年非現金費用列示。Inputs 回歸開關 u1_switch、u2_switch＝0 可還原 v0.1。
A9: Compute | B9: 加速器族 × 世代（NVIDIA Hopper／GB200／GB300／VR200；TPU v6e／v7；Trainium2／3；AMD MI455X）每 GW 年產能＝TK IF_TokGW_* ×（NonNV 產出比）；供給 GW 只由算力合約加總（D10 r1；機房租約只列對照）；η＝2025 token 換算推論 GW ÷ 2025 推論支出換算 GW（D8）；研發 GW＝供給 ×（1 − 閒置）− 推論（D12）；容量上限 2025、2026 固定 1；VR 等值＝各族 Sol 產能比。
A10: Cost | B10: 算力成本（現金）＝逐合約實付＋自建資本支出（D10、D11）；供應商持有成本＝GW × TK IF_HoldEcon × 持有比、雲端毛利；非算力成本 2025＝說明書營業費用 − 算力 − 平台抽成（D13、D5 r1），之後人數 × 每人成本；股權報酬單列；命題表：每 VR 等值 GW 營收淨額、算力、非算力、全成本（含／不含股權報酬）、差額、覆蓋率。
A11: Funding | B11: 自由現金流＝營收淨額（截頂後）− 算力成本（現金）− 非算力成本（不含股權報酬）；來源順序（D16 r1）：2025 年底現金 → 2026 已交割股權（Series G 30、Amazon G 5、Series H 65）→ 外部資金（補足至最低現金＝次年非算力 6 個月，D17）；條件式（Amazon 15、Google 30、NVIDIA 10、AMD 5）與 IPO 約 100 只列情境；或有負債只列示；情境 S1–S7（IPO、條件式、逐家錨定招股書、機房租金、D22、合併）；回流對照（D18）。
A12: Reverse | B12: 管理層營收目標（2026 18、2027 55、2028 70、2029 148；2030 無目標取正向）→ 只靠 API／只靠訂閱／兩線等比例的所需倍數 → 反向資金（同一支出）；只被 Checks 引用（D19）。
A13: Excel 為唯一計算引擎 | B13: 藍字＝輸入（Excel 擁有，重建時保留已改過的值）；黑字＝公式；綠字＝跨頁連結。builder 只產生結構（data/*.yaml → SRC_ANT／Inputs；Tokenomics → TK_Link；OpenAI → OAI_Link）。
A14: SRC_ANT | B14: 409 列：公司財務原始數據（A1 蒐集 376 列＋A2 新增 3 列供 Derived 列公式化＋v0.1.1 新增 30 列〔草擬 S-1 經 WSJ 轉述、Q3 投資人簡報〕）。標記 Derived 的 14 列：13 列改為公式、1 列（Reuters 自行計算後公布的通路費）保留報導值。
A15: TK_Link | B15: Tokenomics v21.2（20261023_Tokenomics_v21.2.xlsx），master 提交 45ce1ca；106 個具名範圍（OpenAI v0.6 同一組 63 名＋A2 新增任務 token 5 名＋v0.1.2 新增 v18.0 對照名稱 14 個，只對照）＋ 讀表（非具名）21 格：NonNV 18 格（規格 D6）與 PUE 3 格（A3；Tokenomics Inputs 頁）。
... A23: 分層 | B23: 公司財務原始數據→SRC_ANT；AI 技術與算力→TK_Link（取自 Tokenomics）；假設→Inputs；OpenAI 對照→OAI_Link（不進計算）。

Sheet SRC_ANT
A1: SRC_ANT — 第 0 層 Source：Anthropic 公司財務原始數據（營收、價格、用戶、合約、成本、融資、管理層目標）
A2: 只存已取得的原始訊息（非計算、非假設）。藍字＝原始值，由本活頁簿擁有。標記 Derived 的列：值欄改為公式（由其他 SRC_ANT 列推得），處理狀態欄說明；AI 技術與算力原始數據不在此登錄（取自 TK_Link）。
A3: 來源等級（1 一手／2 二手已讀或轉載／未評）、立場、立場說明、一手／二手：依 builder/source_rules.py 的機械規則由 CC 初評（AB 欄）；利害方與誘因欄為 A1 逐列登錄。
A4: SRC_ID | B4: key | C4: 分組 | D4: 項目 | E4: 值 | F4: 低 | G4: 高 | H4: 單位 | I4: 期間 | J4: 日期（序列值） | K4: 口徑 | L4: 來源 | M4: 網址 | N4: 文件日期 | O4: 擷取日 | P4: 標記 | Q4: 利害方與誘因 | R4: 來源等級 | S4: 立場 | T4: 立場說明 | U4: 一手／二手 | V4: 處理狀態 | W4: 備註 | X4: 缺值（公式） | Y4: 缺出處（公式） | Z4: 區間順序異常（公式） | AA4: Derived 未處理（公式） | AB4: 四欄標註
A5: SRC_ANT_001 | B5: rev_2025_recognized | C5: A | D5: 2025 年認列營收 | E5: 4.6 | H5: $B/年 | I5: 2025 | K5: 總額 | L5: Reuters〈Anthropic's IPO prospectus shows sweeping AI vision, surging costs〉（經 Fortune 轉述） | M5: https://fortune.com/2026/09/29/anthropic-leaked-ipo-prospectus-losses-growth-ai-end-humanity/ | N5: 2026-09-29 | O5: 2026-10-08 | P5: Interested-party | Q5: Anthropic（外流機密招股書草稿；IPO 募資誘因） | R5: 2 | S5: 利害關係方 | T5: Anthropic（外流機密招股書草稿；IPO 募資誘因） | U5: 二手 | V5: 觀測 | W5: 原文：'bringing in $4.6 billion in revenue'；'Revenue rose 1,088% in 2025'。雲端市集銷售以總額認列（見 rev_recognition_gross） | X5: =IF(AND(COUNT($E5:$G5)=0,LEFT($H5,2)<>"定性",LEFT($H5,2)<>"文字",LEFT($H5,2)<>"日期"),1,0) -> 0 | Y5: =IF(OR($L5="",$M5=""),1,0) -> 0 | Z5: =IF(AND(ISNUMBER($E5),ISNUMBER($F5)),IF($F5>$E5,1,0),0)+IF(AND(ISNUMBER($E5),ISNUMBER($G5)),IF($E5>$G5,1,0),0)+IF(AND(ISNUMBER($F5),ISNUMBER($G5)),IF($F5>$G5,1,0),0) -> 0 | AA5: =IF(AND($P5="Derived",$V5="觀測"),1,0) -> 0 | AB5: CC 初評
A6: SRC_ANT_002 | B6: rev_2025_recognized_b | C6: A | D6: 2025 年認列營收 | E6: 4.59 | H6: $B/年 | I6: 2025 | K6: 總額 | L6: KuCoin 快訊〈Anthropic fiscal year 2025 revenue surges 1,088% to $4.59 billion〉 | M6: https://www.kucoin.com/news/flash/anthropic-2025-fiscal-year-revenue-surges-1088-to-4-59-billion | N6: 2026-09-29 | O6: 2026-10-08 | P6: Interested-party | Q6: Anthropic（外流招股書；IPO 募資誘因） | R6: 2 | S6: 利害關係方 | T6: Anthropic（外流招股書；IPO 募資誘因） | U6: 二手 | V6: 觀測 | W6: 標題：'revenue surges 1,088% to $4.59 billion'。與 4.6（Reuters 'nearly $4.6 billion'）一致，為更精確值；僅見標題 | X6: =IF(AND(COUNT($E6:$G6)=0,LEFT($H6,2)<>"定性",LEFT($H6,2)<>"文字",LEFT($H6,2)<>"日期"),1,0) -> 0 | Y6: =IF(OR($L6="",$M6=""),1,0) -> 0 | Z6: =IF(AND(ISNUMBER($E6),ISNUMBER($F6)),IF($F6>$E6,1,0),0)+IF(AND(ISNUMBER($E6),ISNUMBER($G6)),IF($E6>$G6,1,0),0)+IF(AND(ISNUMBER($F6),ISNUMBER($G6)),IF($F6>$G6,1,0),0) -> 0 | AA6: =IF(AND($P6="Derived",$V6="觀測"),1,0) -> 0 | AB6: CC 初評
A7: SRC_ANT_003 | B7: rev_2024_recognized_derived | C7: A | D7: 2024 年認列營收（由 2025 年成長率反推） | E7: =SRC_ANT_002/(1+SRC_ANT_377) -> 0.38636364 | H7: $B/年 | I7: 2024 | K7: 總額 | L7: 由 rev_2025_recognized（$4.59B、+1,088%）推算 | M7: https://www.kucoin.com/news/flash/anthropic-2025-fiscal-year-revenue-surges-1088-to-4-59-billion | N7: 2026-09-29 | O7: 2026-10-08 | P7: Derived | R7: 未評 | S7: 推導 | T7: 由其他 SRC_ANT 列推得（本活頁簿以公式表示） | U7: 推導 | V7: Derived→公式 | W7: 4.59/(1+10.88)=0.386。報導未直接給 2024 營收數字；Reuters 稱 2025 年 '12-fold'，4.6/12≈0.38 一致 | X7: =IF(AND(COUNT($E7:$G7)=0,LEFT($H7,2)<>"定性",LEFT($H7,2)<>"文字",LEFT($H7,2)<>"日期"),1,0) -> 0 | Y7: =IF(OR($L7="",$M7=""),1,0) -> 0 | Z7: =IF(AND(ISNUMBER($E7),ISNUMBER($F7)),IF($F7>$E7,1,0),0)+IF(AND(ISNUMBER($E7),ISNUMBER($G7)),IF($E7>$G7,1,0),0)+IF(AND(ISNUMBER($F7),ISNUMBER($G7)),IF($F7>$G7,1,0),0) -> 0 | AA7: =IF(AND($P7="Derived",$V7="觀測"),1,0) -> 0 | AB7: CC 初評
A8: SRC_ANT_004 | B8: rev_2026_q1 | C8: A | D8: 2026 Q1 認列營收 | E8: 4.73 | H8: $B/季 | I8: 2026-Q1 | K8: 總額 | L8: Bloomberg（經 Axios 轉述）〈Anthropic's revenue run rate reportedly surpasses $65 billion pre-IPO〉 | M8: https://www.axios.com/2026/08/17/anthropic-revenue-run-rate-ipo-openai | N8: 2026-08-17 | O8: 2026-10-08 | P8: Interested-party | Q8: Anthropic（Bloomberg 取得之內部文件；IPO 前募資誘因） | R8: 2 | S8: 利害關係方 | T8: Anthropic（Bloomberg 取得之內部文件；IPO 前募資誘因） | U8: 二手 | V8: 觀測 | W8: 原文：'more than double Q1 revenue of $4.73 billion'。招股書外流（Fortune 9/29）亦引同值 | X8: =IF(AND(COUNT($E8:$G8)=0,LEFT($H8,2)<>"定性",LEFT($H8,2)<>"文字",LEFT($H8,2)<>"日期"),1,0) -> 0 | Y8: =IF(OR($L8="",$M8=""),1,0) -> 0 | Z8: =IF(AND(ISNUMBER($E8),ISNUMBER($F8)),IF($F8>$E8,1,0),0)+IF(AND(ISNUMBER($E8),ISNUMBER($G8)),IF($E8>$G8,1,0),0)+IF(AND(ISNUMBER($F8),ISNUMBER($G8)),IF($F8>$G8,1,0),0) -> 0 | AA8: =IF(AND($P8="Derived",$V8="觀測"),1,0) -> 0 | AB8: CC 初評
A9: SRC_ANT_005 | B9: rev_2026_q2 | C9: A | D9: 2026 Q2 認列營收（初步） | E9: 11.5 | H9: $B/季 | I9: 2026-Q2 | K9: 總額 | L9: Bloomberg（經 Axios 轉述） | M9: https://www.axios.com/2026/08/17/anthropic-revenue-run-rate-ipo-openai | N9: 2026-08-17 | O9: 2026-10-08 | P9: Interested-party | Q9: Anthropic（Bloomberg 取得之文件；IPO 前誘因） | R9: 2 | S9: 利害關係方 | T9: Anthropic（Bloomberg 取得之文件；IPO 前誘因） | U9: 二手 | V9: 觀測 | W9: 原文：'more than $11.5 billion in preliminary revenue in the second quarter'；'more than 14 times' 去年同季；初步數字可能修正 | X9: =IF(AND(COUNT($E9:$G9)=0,LEFT($H9,2)<>"定性",LEFT($H9,2)<>"文字",LEFT($H9,2)<>"日期"),1,0) -> 0 | Y9: =IF(OR($L9="",$M9=""),1,0) -> 0 | Z9: =IF(AND(ISNUMBER($E9),ISNUMBER($F9)),IF($F9>$E9,1,0),0)+IF(AND(ISNUMBER($E9),ISNUMBER($G9)),IF($E9>$G9,1,0),0)+IF(AND(ISNUMBER($F9),ISNUMBER($G9)),IF($F9>$G9,1,0),0) -> 0 | AA9: =IF(AND($P9="Derived",$V9="觀測"),1,0) -> 0 | AB9: CC 初評
A10: SRC_ANT_006 | B10: rev_2025_q2 | C10: A | D10: 2025 Q2 認列營收 | E10: 0.787 | H10: $B/季 | I10: 2025-Q2 | K10: 總額 | L10: The Next Web〈Anthropic's quarterly revenue passed $11.5bn, up more than 14-fold〉（引 Bloomberg 2026-08-14） | M10: https://thenextweb.com/news/anthropic-q2-2026-revenue-11-5-billion-operating-income | N10: 2026-08-15 | O10: 2026-10-08 | P10: Interested-party | Q10: Anthropic（Bloomberg 取得之文件） | R10: 2 | S10: 利害關係方 | T10: Anthropic（Bloomberg 取得之文件） | U10: 二手 | V10: 觀測 | W10: 原文：去年同季 '$787mn'；Q2 2026 'exceeded $11.5bn'；'positive adjusted operating income' | X10: =IF(AND(COUNT($E10:$G10)=0,LEFT($H10,2)<>"定性",LEFT($H10,2)<>"文字",LEFT($H10,2)<>"日期"),1,0) -> 0 | Y10: =IF(OR($L10="",$M10=""),1,0) -> 0 | Z10: =IF(AND(ISNUMBER($E10),ISNUMBER($F10)),IF($F10>$E10,1,0),0)+IF(AND(ISNUMBER($E10),ISNUMBER($G10)),IF($E10>$G10,1,0),0)+IF(AND(ISNUMBER($F10),ISNUMBER($G10)),IF($F10>$G10,1,0),0) -> 0 | AA10: =IF(AND($P10="Derived",$V10="觀測"),1,0) -> 0 | AB10: CC 初評
A11: SRC_ANT_007 | B11: rev_2026_h1_derived | C11: A | D11: 2026 上半年認列營收（Q1+Q2 加總） | E11: =SRC_ANT_004+SRC_ANT_005 -> 16.23 | H11: $B/半年 | I11: 2026-H1 | K11: 總額 | L11: 由 rev_2026_q1 + rev_2026_q2 推算 | M11: https://www.pymnts.com/news/artificial-intelligence/2026/anthropic-prospectus-shows-what-2-trillion-dollar-ai-company-costs-run/ | N11: 2026-09-29 | O11: 2026-10-08 | P11: Derived | R11: 未評 | S11: 推導 | T11: 由其他 SRC_ANT 列推得（本活頁簿以公式表示） | U11: 推導 | V11: Derived→公式 | W11: 4.73+11.5≈16.2；PYMNTS 列 '$4.73 billion in Q1 2026 and $11.5 billion in Q2 2026'，未直接給 H1 合計 | X11: =IF(AND(COUNT($E11:$G11)=0,LEFT($H11,2)<>"定性",LEFT($H11,2)<>"文字",LEFT($H11,2)<>"日期"),1,0) -> 0 | Y11: =IF(OR($L11="",$M11=""),1,0) -> 0 | Z11: =IF(AND(ISNUMBER($E11),ISNUMBER($F11)),IF($F11>$E11,1,0),0)+IF(AND(ISNUMBER($E11),ISNUMBER($G11)),IF($E11>$G11,1,0),0)+IF(AND(ISNUMBER($F11),ISNUMBER($G11)),IF($F11>$G11,1,0),0) -> 0 | AA11: =IF(AND($P11="Derived",$V11="觀測"),1,0) -> 0 | AB11: CC 初評
A12: SRC_ANT_008 | B12: rev_runrate_2024_12 | C12: A | D12: 年化營收（run-rate） | E12: 1 | H12: $B/年 | I12: 2024-12 | K12: 未明 | L12: Anthropic 新聞稿〈Anthropic raises Series F at US$183B post-money valuation〉 | M12: https://www.anthropic.com/news/anthropic-raises-series-f-at-usd183b-post-money-valuation | N12: 2025-09-02 | O12: 2026-10-08 | P12: Interested-party | Q12: Anthropic（募資誘因） | R12: 1 | S12: 利害關係方 | T12: Anthropic（募資誘因） | U12: 一手 | V12: 觀測 | W12: 原文：2025 年初 'run-rate revenue had grown to approximately $1 billion' | X12: =IF(AND(COUNT($E12:$G12)=0,LEFT($H12,2)<>"定性",LEFT($H12,2)<>"文字",LEFT($H12,2)<>"日期"),1,0) -> 0 | Y12: =IF(OR($L12="",$M12=""),1,0) -> 0 | Z12: =IF(AND(ISNUMBER($E12),ISNUMBER($F12)),IF($F12>$E12,1,0),0)+IF(AND(ISNUMBER($E12),ISNUMBER($G12)),IF($E12>$G12,1,0),0)+IF(AND(ISNUMBER($F12),ISNUMBER($G12)),IF($F12>$G12,1,0),0) -> 0 | AA12: =IF(AND($P12="Derived",$V12="觀測"),1,0) -> 0 | AB12: CC 初評
A13: SRC_ANT_009 | B13: rev_runrate_2024_12_b | C13: A | D13: 年化營收（run-rate） | E13: 1 | H13: $B/年 | I13: 2024-12 | K13: 未明 | L13: Reuters 獨家（2025-05-30，經 WizCase 轉述） | M13: https://www.wizcase.com/?p=2882381 | N13: 2025-06-03 | O13: 2026-10-08 | P13: Interested-party | Q13: Anthropic（知情人士；募資誘因） | R13: 2 | S13: 利害關係方 | T13: Anthropic（知情人士；募資誘因） | U13: 二手 | V13: 觀測 | W13: 原文：'around $1 billion in December 2024' | X13: =IF(AND(COUNT($E13:$G13)=0,LEFT($H13,2)<>"定性",LEFT($H13,2)<>"文字",LEFT($H13,2)<>"日期"),1,0) -> 0 | Y13: =IF(OR($L13="",$M13=""),1,0) -> 0 | Z13: =IF(AND(ISNUMBER($E13),ISNUMBER($F13)),IF($F13>$E13,1,0),0)+IF(AND(ISNUMBER($E13),ISNUMBER($G13)),IF($E13>$G13,1,0),0)+IF(AND(ISNUMBER($F13),ISNUMBER($G13)),IF($F13>$G13,1,0),0) -> 0 | AA13: =IF(AND($P13="Derived",$V13="觀測"),1,0) -> 0 | AB13: CC 初評
A14: SRC_ANT_010 | B14: rev_runrate_2025_03_early | C14: A | D14: 年化營收（run-rate） | E14: 1.4 | H14: $B/年 | I14: 2025-03（月初） | K14: 未明 | L14: The Information（經 Seeking Alpha 轉述） | M14: https://seekingalpha.com/news/4419473-anthropic-reaches-1_4b-in-annualized-revenue-report | N14: 2025-03-11 | O14: 2026-10-08 | P14: Interested-party | Q14: Anthropic（知情人士；募資誘因） | R14: 2 | S14: 利害關係方 | T14: Anthropic（知情人士；募資誘因） | U14: 二手 | V14: 觀測 | W14: 原文：'an annualized revenue of $1.4B as of earlier this month'；'around $1B at the end of 2024' | X14: =IF(AND(COUNT($E14:$G14)=0,LEFT($H14,2)<>"定性",LEFT($H14,2)<>"文字",LEFT($H14,2)<>"日期"),1,0) -> 0 | Y14: =IF(OR($L14="",$M14=""),1,0) -> 0 | Z14: =IF(AND(ISNUMBER($E14),ISNUMBER($F14)),IF($F14>$E14,1,0),0)+IF(AND(ISNUMBER($E14),ISNUMBER($G14)),IF($E14>$G14,1,0),0)+IF(AND(ISNUMBER($F14),ISNUMBER($G14)),IF($F14>$G14,1,0),0) -> 0 | AA14: =IF(AND($P14="Derived",$V14="觀測"),1,0) -> 0 | AB14: CC 初評
A15: SRC_ANT_011 | B15: rev_runrate_2025_03 | C15: A | D15: 年化營收（run-rate） | E15: 2 | H15: $B/年 | I15: 2025-03（月底） | K15: 未明 | L15: Reuters 獨家（2025-05-30，經 WizCase 轉述） | M15: https://www.wizcase.com/?p=2882381 | N15: 2025-06-03 | O15: 2026-10-08 | P15: Interested-party | Q15: Anthropic（知情人士；募資誘因） | R15: 2 | S15: 利害關係方 | T15: Anthropic（知情人士；募資誘因） | U15: 二手 | V15: 觀測 | W15: 原文：'hit $2 billion by the end of March'。與 The Information 3 月初 $1.4B 相差大，月內跳升或口徑不同 | X15: =IF(AND(COUNT($E15:$G15)=0,LEFT($H15,2)<>"定性",LEFT($H15,2)<>"文字",LEFT($H15,2)<>"日期"),1,0) -> 0 | Y15: =IF(OR($L15="",$M15=""),1,0) -> 0 | Z15: =IF(AND(ISNUMBER($E15),ISNUMBER($F15)),IF($F15>$E15,1,0),0)+IF(AND(ISNUMBER($E15),ISNUMBER($G15)),IF($E15>$G15,1,0),0)+IF(AND(ISNUMBER($F15),ISNUMBER($G15)),IF($F15>$G15,1,0),0) -> 0 | AA15: =IF(AND($P15="Derived",$V15="觀測"),1,0) -> 0 | AB15: CC 初評
A16: SRC_ANT_012 | B16: rev_runrate_2025_05 | C16: A | D16: 年化營收（run-rate） | E16: 3 | H16: $B/年 | I16: 2025-05 | K16: 未明 | L16: Reuters 獨家〈Anthropic hits $3 billion in annualized revenue on business demand for AI〉（經 WizCase 轉述） | M16: https://www.wizcase.com/?p=2882381 | N16: 2025-06-03 | O16: 2026-10-08 | P16: Interested-party | Q16: Anthropic（知情人士；募資誘因） | R16: 2 | S16: 利害關係方 | T16: Anthropic（知情人士；募資誘因） | U16: 二手 | V16: 觀測 | W16: 原文：'its $3 billion milestone in May' | X16: =IF(AND(COUNT($E16:$G16)=0,LEFT($H16,2)<>"定性",LEFT($H16,2)<>"文字",LEFT($H16,2)<>"日期"),1,0) -> 0 | Y16: =IF(OR($L16="",$M16=""),1,0) -> 0 | Z16: =IF(AND(ISNUMBER($E16),ISNUMBER($F16)),IF($F16>$E16,1,0),0)+IF(AND(ISNUMBER($E16),ISNUMBER($G16)),IF($E16>$G16,1,0),0)+IF(AND(ISNUMBER($F16),ISNUMBER($G16)),IF($F16>$G16,1,0),0) -> 0 | AA16: =IF(AND($P16="Derived",$V16="觀測"),1,0) -> 0 | AB16: CC 初評
A17: SRC_ANT_013 | B17: rev_runrate_2025_07 | C17: A | D17: 年化營收（run-rate） | E17: 4 | H17: $B/年 | I17: 2025-07（月初） | K17: 未明 | L17: The Information（經 Seeking Alpha 轉述） | M17: https://seekingalpha.com/news/4464440-anthropic-reaches-4b-in-annualized-revenue-report | N17: 2025-07-01 | O17: 2026-10-08 | P17: Interested-party | Q17: Anthropic（知情人士；募資誘因） | R17: 2 | S17: 利害關係方 | T17: Anthropic（知情人士；募資誘因） | U17: 二手 | V17: 觀測 | W17: 原文：'an annualized revenue rate of $4B'，'four times higher than the beginning of the year' | X17: =IF(AND(COUNT($E17:$G17)=0,LEFT($H17,2)<>"定性",LEFT($H17,2)<>"文字",LEFT($H17,2)<>"日期"),1,0) -> 0 | Y17: =IF(OR($L17="",$M17=""),1,0) -> 0 | Z17: =IF(AND(ISNUMBER($E17),ISNUMBER($F17)),IF($F17>$E17,1,0),0)+IF(AND(ISNUMBER($E17),ISNUMBER($G17)),IF($E17>$G17,1,0),0)+IF(AND(ISNUMBER($F17),ISNUMBER($G17)),IF($F17>$G17,1,0),0) -> 0 | AA17: =IF(AND($P17="Derived",$V17="觀測"),1,0) -> 0 | AB17: CC 初評
A18: SRC_ANT_014 | B18: rev_runrate_2025_07_b | C18: A | D18: 年化營收（run-rate） | E18: 4 | H18: $B/年 | I18: 2025-07 | K18: 未明 | L18: Bloomberg〈Anthropic's Revenue Run Rate Tops $9 Billion as VCs Pile In〉 | M18: https://www.bloomberg.com/news/articles/2026-01-21/anthropic-s-revenue-run-rate-tops-9-billion-as-vcs-pile-in | N18: 2026-01-21 | O18: 2026-10-08 | P18: Interested-party | Q18: Anthropic（知情人士；募資誘因） | R18: 2 | S18: 利害關係方 | T18: Anthropic（知情人士；募資誘因） | U18: 二手 | V18: 觀測 | W18: 原文：'was $4 billion in July of last year' | X18: =IF(AND(COUNT($E18:$G18)=0,LEFT($H18,2)<>"定性",LEFT($H18,2)<>"文字",LEFT($H18,2)<>"日期"),1,0) -> 0 | Y18: =IF(OR($L18="",$M18=""),1,0) -> 0 | Z18: =IF(AND(ISNUMBER($E18),ISNUMBER($F18)),IF($F18>$E18,1,0),0)+IF(AND(ISNUMBER($E18),ISNUMBER($G18)),IF($E18>$G18,1,0),0)+IF(AND(ISNUMBER($F18),ISNUMBER($G18)),IF($F18>$G18,1,0),0) -> 0 | AA18: =IF(AND($P18="Derived",$V18="觀測"),1,0) -> 0 | AB18: CC 初評
A19: SRC_ANT_015 | B19: rev_runrate_2025_08 | C19: A | D19: 年化營收（run-rate） | E19: 5 | H19: $B/年 | I19: 2025-08 | K19: 未明 | L19: Anthropic 新聞稿〈Anthropic raises Series F at US$183B post-money valuation〉 | M19: https://www.anthropic.com/news/anthropic-raises-series-f-at-usd183b-post-money-valuation | N19: 2025-09-02 | O19: 2026-10-08 | P19: Interested-party | Q19: Anthropic（募資誘因） | R19: 1 | S19: 利害關係方 | T19: Anthropic（募資誘因） | U19: 一手 | V19: 觀測 | W19: 原文：'By August 2025…our run-rate revenue reached over $5 billion'（下限值） | X19: =IF(AND(COUNT($E19:$G19)=0,LEFT($H19,2)<>"定性",LEFT($H19,2)<>"文字",LEFT($H19,2)<>"日期"),1,0) -> 0 | Y19: =IF(OR($L19="",$M19=""),1,0) -> 0 | Z19: =IF(AND(ISNUMBER($E19),ISNUMBER($F19)),IF($F19>$E19,1,0),0)+IF(AND(ISNUMBER($E19),ISNUMBER($G19)),IF($E19>$G19,1,0),0)+IF(AND(ISNUMBER($F19),ISNUMBER($G19)),IF($F19>$G19,1,0),0) -> 0 | AA19: =IF(AND($P19="Derived",$V19="觀測"),1,0) -> 0 | AB19: CC 初評
A20: SRC_ANT_016 | B20: rev_runrate_2025_10 | C20: A | D20: 年化營收（run-rate） | E20: 7 | G20: 7 | H20: $B/年 | I20: 2025-10 | K20: 未明 | L20: Reuters 獨家〈Anthropic aims to nearly triple annualized revenue in 2026, sources say〉 | M20: https://finance.yahoo.com/news/exclusive-anthropic-aims-nearly-triple-170234463.html | N20: 2025-10-15 | O20: 2026-10-08 | P20: Interested-party | Q20: Anthropic（公司向 Reuters 表示；募資誘因） | R20: 2 | S20: 利害關係方 | T20: Anthropic（公司向 Reuters 表示；募資誘因） | U20: 二手 | V20: 觀測 | W20: 原文：'annual revenue run rate is approaching $7 billion this month'（接近，未達） | X20: =IF(AND(COUNT($E20:$G20)=0,LEFT($H20,2)<>"定性",LEFT($H20,2)<>"文字",LEFT($H20,2)<>"日期"),1,0) -> 0 | Y20: =IF(OR($L20="",$M20=""),1,0) -> 0 | Z20: =IF(AND(ISNUMBER($E20),ISNUMBER($F20)),IF($F20>$E20,1,0),0)+IF(AND(ISNUMBER($E20),ISNUMBER($G20)),IF($E20>$G20,1,0),0)+IF(AND(ISNUMBER($F20),ISNUMBER($G20)),IF($F20>$G20,1,0),0) -> 0 | AA20: =IF(AND($P20="Derived",$V20="觀測"),1,0) -> 0 | AB20: CC 初評
A21: SRC_ANT_017 | B21: rev_runrate_2025_12 | C21: A | D21: 年化營收（run-rate） | E21: 9 | H21: $B/年 | I21: 2025-12 | K21: 未明 | L21: Anthropic 新聞稿〈Google and Broadcom partnership〉 | M21: https://www.anthropic.com/news/google-broadcom-partnership-compute | N21: 2026-04-06 | O21: 2026-10-08 | P21: Interested-party | Q21: Anthropic（募資、市場地位誘因） | R21: 1 | S21: 利害關係方 | T21: Anthropic（募資、市場地位誘因） | U21: 一手 | V21: 觀測 | W21: 原文：'up from approximately $9 billion at the end of 2025' | X21: =IF(AND(COUNT($E21:$G21)=0,LEFT($H21,2)<>"定性",LEFT($H21,2)<>"文字",LEFT($H21,2)<>"日期"),1,0) -> 0 | Y21: =IF(OR($L21="",$M21=""),1,0) -> 0 | Z21: =IF(AND(ISNUMBER($E21),ISNUMBER($F21)),IF($F21>$E21,1,0),0)+IF(AND(ISNUMBER($E21),ISNUMBER($G21)),IF($E21>$G21,1,0),0)+IF(AND(ISNUMBER($F21),ISNUMBER($G21)),IF($F21>$G21,1,0),0) -> 0 | AA21: =IF(AND($P21="Derived",$V21="觀測"),1,0) -> 0 | AB21: CC 初評
A22: SRC_ANT_018 | B22: rev_runrate_2025_12_b | C22: A | D22: 年化營收（run-rate） | E22: 9 | H22: $B/年 | I22: 2025-12 | K22: 未明 | L22: Bloomberg〈Anthropic's Revenue Run Rate Tops $9 Billion as VCs Pile In〉 | M22: https://www.bloomberg.com/news/articles/2026-01-21/anthropic-s-revenue-run-rate-tops-9-billion-as-vcs-pile-in | N22: 2026-01-21 | O22: 2026-10-08 | P22: Interested-party | Q22: Anthropic（知情人士；募資誘因） | R22: 2 | S22: 利害關係方 | T22: Anthropic（知情人士；募資誘因） | U22: 二手 | V22: 觀測 | W22: 原文：'hit over $9 billion at the end of 2025'（下限） | X22: =IF(AND(COUNT($E22:$G22)=0,LEFT($H22,2)<>"定性",LEFT($H22,2)<>"文字",LEFT($H22,2)<>"日期"),1,0) -> 0 | Y22: =IF(OR($L22="",$M22=""),1,0) -> 0 | Z22: =IF(AND(ISNUMBER($E22),ISNUMBER($F22)),IF($F22>$E22,1,0),0)+IF(AND(ISNUMBER($E22),ISNUMBER($G22)),IF($E22>$G22,1,0),0)+IF(AND(ISNUMBER($F22),ISNUMBER($G22)),IF($F22>$G22,1,0),0) -> 0 | AA22: =IF(AND($P22="Derived",$V22="觀測"),1,0) -> 0 | AB22: CC 初評
A23: SRC_ANT_019 | B23: rev_runrate_2026_02 | C23: A | D23: 年化營收（run-rate） | E23: 14 | H23: $B/年 | I23: 2026-02 | K23: 未明 | L23: Anthropic 新聞稿〈Anthropic raises $30 billion Series G at $380 billion post-money valuation〉 | M23: https://www.anthropic.com/news/anthropic-raises-30-billion-series-g-funding-380-billion-post-money-valuation | N23: 2026-02-12 | O23: 2026-10-08 | P23: Interested-party | Q23: Anthropic（募資誘因） | R23: 1 | S23: 利害關係方 | T23: Anthropic（募資誘因） | U23: 一手 | V23: 觀測 | W23: 原文：'Today, our run-rate revenue is $14 billion'，'growing over 10x annually' | X23: =IF(AND(COUNT($E23:$G23)=0,LEFT($H23,2)<>"定性",LEFT($H23,2)<>"文字",LEFT($H23,2)<>"日期"),1,0) -> 0 | Y23: =IF(OR($L23="",$M23=""),1,0) -> 0 | Z23: =IF(AND(ISNUMBER($E23),ISNUMBER($F23)),IF($F23>$E23,1,0),0)+IF(AND(ISNUMBER($E23),ISNUMBER($G23)),IF($E23>$G23,1,0),0)+IF(AND(ISNUMBER($F23),ISNUMBER($G23)),IF($F23>$G23,1,0),0) -> 0 | AA23: =IF(AND($P23="Derived",$V23="觀測"),1,0) -> 0 | AB23: CC 初評
A24: SRC_ANT_020 | B24: rev_runrate_2026_03 | C24: A | D24: 年化營收（run-rate） | E24: 19 | H24: $B/年 | I24: 2026-03（月初） | K24: 未明 | L24: Bloomberg〈Anthropic Nears $20 Billion Revenue Run Rate Amid Pentagon Feud〉 | M24: https://news.bgov.com/artificial-intelligence/anthropic-nears-20-billion-revenue-run-rate-amid-pentagon-feud | N24: 2026-03-03 | O24: 2026-10-08 | P24: Interested-party | Q24: Anthropic（知情人士；募資誘因） | R24: 2 | S24: 利害關係方 | T24: Anthropic（知情人士；募資誘因） | U24: 二手 | V24: 觀測 | W24: 原文：'surpassed $19 billion in run-rate revenue'；'roughly $14 billion a few weeks ago' | X24: =IF(AND(COUNT($E24:$G24)=0,LEFT($H24,2)<>"定性",LEFT($H24,2)<>"文字",LEFT($H24,2)<>"日期"),1,0) -> 0 | Y24: =IF(OR($L24="",$M24=""),1,0) -> 0 | Z24: =IF(AND(ISNUMBER($E24),ISNUMBER($F24)),IF($F24>$E24,1,0),0)+IF(AND(ISNUMBER($E24),ISNUMBER($G24)),IF($E24>$G24,1,0),0)+IF(AND(ISNUMBER($F24),ISNUMBER($G24)),IF($F24>$G24,1,0),0) -> 0 | AA24: =IF(AND($P24="Derived",$V24="觀測"),1,0) -> 0 | AB24: CC 初評
A25: SRC_ANT_021 | B25: rev_runrate_2026_04 | C25: A | D25: 年化營收（run-rate） | E25: 30 | H25: $B/年 | I25: 2026-04 | K25: 未明 | L25: Anthropic 新聞稿〈Google and Broadcom partnership〉 | M25: https://www.anthropic.com/news/google-broadcom-partnership-compute | N25: 2026-04-06 | O25: 2026-10-08 | P25: Interested-party | Q25: Anthropic（募資、市場地位誘因） | R25: 1 | S25: 利害關係方 | T25: Anthropic（募資、市場地位誘因） | U25: 一手 | V25: 觀測 | W25: 原文：'Our run-rate revenue has now surpassed $30 billion'（下限） | X25: =IF(AND(COUNT($E25:$G25)=0,LEFT($H25,2)<>"定性",LEFT($H25,2)<>"文字",LEFT($H25,2)<>"日期"),1,0) -> 0 | Y25: =IF(OR($L25="",$M25=""),1,0) -> 0 | Z25: =IF(AND(ISNUMBER($E25),ISNUMBER($F25)),IF($F25>$E25,1,0),0)+IF(AND(ISNUMBER($E25),ISNUMBER($G25)),IF($E25>$G25,1,0),0)+IF(AND(ISNUMBER($F25),ISNUMBER($G25)),IF($F25>$G25,1,0),0) -> 0 | AA25: =IF(AND($P25="Derived",$V25="觀測"),1,0) -> 0 | AB25: CC 初評
A26: SRC_ANT_022 | B26: rev_runrate_2026_05 | C26: A | D26: 年化營收（run-rate） | E26: 47 | H26: $B/年 | I26: 2026-05 | K26: 未明 | L26: Anthropic 新聞稿〈Series H〉 | M26: https://www.anthropic.com/news/series-h | N26: 2026-05-28 | O26: 2026-10-08 | P26: Interested-party | Q26: Anthropic（募資誘因） | R26: 1 | S26: 利害關係方 | T26: Anthropic（募資誘因） | U26: 一手 | V26: 觀測 | W26: 原文：'our run-rate revenue crossed $47 billion earlier this month' | X26: =IF(AND(COUNT($E26:$G26)=0,LEFT($H26,2)<>"定性",LEFT($H26,2)<>"文字",LEFT($H26,2)<>"日期"),1,0) -> 0 | Y26: =IF(OR($L26="",$M26=""),1,0) -> 0 | Z26: =IF(AND(ISNUMBER($E26),ISNUMBER($F26)),IF($F26>$E26,1,0),0)+IF(AND(ISNUMBER($E26),ISNUMBER($G26)),IF($E26>$G26,1,0),0)+IF(AND(ISNUMBER($F26),ISNUMBER($G26)),IF($F26>$G26,1,0),0) -> 0 | AA26: =IF(AND($P26="Derived",$V26="觀測"),1,0) -> 0 | AB26: CC 初評
A27: SRC_ANT_023 | B27: rev_runrate_2026_07 | C27: A | D27: 年化營收（run-rate） | E27: 65 | H27: $B/年 | I27: 2026-07（月底） | K27: 未明 | L27: Bloomberg（經 TechCrunch 轉述）〈Anthropic's annualized revenue surges to $65B〉 | M27: https://techcrunch.com/2026/08/17/anthropics-annualized-revenue-surges-to-65b/ | N27: 2026-08-17 | O27: 2026-10-08 | P27: Interested-party | Q27: Anthropic（告知投資人；IPO 誘因） | R27: 2 | S27: 利害關係方 | T27: Anthropic（告知投資人；IPO 誘因） | U27: 二手 | V27: 觀測 | W27: 原文：'surpassed $65 billion' at the end of July；'$47 billion in May'。截至 2026-10-08 未見更新的 run-rate | X27: =IF(AND(COUNT($E27:$G27)=0,LEFT($H27,2)<>"定性",LEFT($H27,2)<>"文字",LEFT($H27,2)<>"日期"),1,0) -> 0 | Y27: =IF(OR($L27="",$M27=""),1,0) -> 0 | Z27: =IF(AND(ISNUMBER($E27),ISNUMBER($F27)),IF($F27>$E27,1,0),0)+IF(AND(ISNUMBER($E27),ISNUMBER($G27)),IF($E27>$G27,1,0),0)+IF(AND(ISNUMBER($F27),ISNUMBER($G27)),IF($F27>$G27,1,0),0) -> 0 | AA27: =IF(AND($P27="Derived",$V27="觀測"),1,0) -> 0 | AB27: CC 初評
A28: SRC_ANT_024 | B28: rev_runrate_2026_07_b | C28: A | D28: 年化營收（run-rate） | E28: 65 | H28: $B/年 | I28: 2026-07 | K28: 未明 | L28: AI Magazine〈How Anthropic's Revenue Run Rate Topped US$65bn〉（引 Reuters 知情人士） | M28: https://aimagazine.com/news/how-anthropics-revenue-run-rate-topped-us-65bn | N28: 2026-08-18 | O28: 2026-10-08 | P28: Interested-party | Q28: Anthropic（知情人士；IPO 誘因） | R28: 2 | S28: 利害關係方 | T28: Anthropic（知情人士；IPO 誘因） | U28: 二手 | V28: 觀測 | W28: 原文：'US$65bn annual revenue run rate, reached by the end of July'；投資人預期年底 $100–120bn（FT） | X28: =IF(AND(COUNT($E28:$G28)=0,LEFT($H28,2)<>"定性",LEFT($H28,2)<>"文字",LEFT($H28,2)<>"日期"),1,0) -> 0 | Y28: =IF(OR($L28="",$M28=""),1,0) -> 0 | Z28: =IF(AND(ISNUMBER($E28),ISNUMBER($F28)),IF($F28>$E28,1,0),0)+IF(AND(ISNUMBER($E28),ISNUMBER($G28)),IF($E28>$G28,1,0),0)+IF(AND(ISNUMBER($F28),ISNUMBER($G28)),IF($F28>$G28,1,0),0) -> 0 | AA28: =IF(AND($P28="Derived",$V28="觀測"),1,0) -> 0 | AB28: CC 初評
A29: SRC_ANT_025 | B29: rev_mix_2025_subscription | C29: A | D29: 2025 訂閱營收 | E29: 0.789 | H29: $B/年 | I29: 2025 | K29: 總額 | L29: Reuters〈Anthropic IPO prospectus lays bare deep dependence on Big Tech partners〉（經 Khaleej Times 轉載） | M29: https://www.khaleejtimes.com/business/anthropic-ipo-prospectus-lays-bare-deep-dependence-on-big-tech-partners?amp=1 | N29: 2026-09-30 | O29: 2026-10-08 | P29: Interested-party | Q29: Anthropic（外流招股書；IPO 誘因） | R29: 2 | S29: 利害關係方 | T29: Anthropic（外流招股書；IPO 誘因） | U29: 二手 | V29: 觀測 | W29: 原文：'Subscription revenue came to $789 million'；約占 2025 營收 17%（推算） | X29: =IF(AND(COUNT($E29:$G29)=0,LEFT($H29,2)<>"定性",LEFT($H29,2)<>"文字",LEFT($H29,2)<>"日期"),1,0) -> 0 | Y29: =IF(OR($L29="",$M29=""),1,0) -> 0 | Z29: =IF(AND(ISNUMBER($E29),ISNUMBER($F29)),IF($F29>$E29,1,0),0)+IF(AND(ISNUMBER($E29),ISNUMBER($G29)),IF($E29>$G29,1,0),0)+IF(AND(ISNUMBER($F29),ISNUMBER($G29)),IF($F29>$G29,1,0),0) -> 0 | AA29: =IF(AND($P29="Derived",$V29="觀測"),1,0) -> 0 | AB29: CC 初評
A30: SRC_ANT_026 | B30: rev_mix_2025_consumption | C30: A | D30: 2025 用量計價（API／token）營收 | E30: 3.8 | H30: $B/年 | I30: 2025 | K30: 總額 | L30: Reuters（經 Khaleej Times 轉載） | M30: https://www.khaleejtimes.com/business/anthropic-ipo-prospectus-lays-bare-deep-dependence-on-big-tech-partners?amp=1 | N30: 2026-09-30 | O30: 2026-10-08 | P30: Interested-party | Q30: Anthropic（外流招股書；IPO 誘因） | R30: 2 | S30: 利害關係方 | T30: Anthropic（外流招股書；IPO 誘因） | U30: 二手 | V30: 觀測 | W30: 原文：consumption-based revenue 'about $3.8 billion'，預期仍為 'the substantial majority'；約 83%（推算） | X30: =IF(AND(COUNT($E30:$G30)=0,LEFT($H30,2)<>"定性",LEFT($H30,2)<>"文字",LEFT($H30,2)<>"日期"),1,0) -> 0 | Y30: =IF(OR($L30="",$M30=""),1,0) -> 0 | Z30: =IF(AND(ISNUMBER($E30),ISNUMBER($F30)),IF($F30>$E30,1,0),0)+IF(AND(ISNUMBER($E30),ISNUMBER($G30)),IF($E30>$G30,1,0),0)+IF(AND(ISNUMBER($F30),ISNUMBER($G30)),IF($F30>$G30,1,0),0) -> 0 | AA30: =IF(AND($P30="Derived",$V30="觀測"),1,0) -> 0 | AB30: CC 初評
A31: SRC_ANT_027 | B31: rev_mix_2025_cloud_partner_share | C31: A | D31: 經 Amazon／Google 雲端通路之營收占比 | E31: 0.47 | H31: 比例 | I31: 2025 | K31: 總額 | L31: Reuters（經 Khaleej Times 轉載） | M31: https://www.khaleejtimes.com/business/anthropic-ipo-prospectus-lays-bare-deep-dependence-on-big-tech-partners?amp=1 | N31: 2026-09-30 | O31: 2026-10-08 | P31: Interested-party | Q31: Anthropic（外流招股書；IPO 誘因） | R31: 2 | S31: 利害關係方 | T31: Anthropic（外流招股書；IPO 誘因） | U31: 二手 | V31: 觀測 | W31: 原文：'routed 47% of its sales…through cloud partners Amazon and Alphabet's Google'；未含 Microsoft | X31: =IF(AND(COUNT($E31:$G31)=0,LEFT($H31,2)<>"定性",LEFT($H31,2)<>"文字",LEFT($H31,2)<>"日期"),1,0) -> 0 | Y31: =IF(OR($L31="",$M31=""),1,0) -> 0 | Z31: =IF(AND(ISNUMBER($E31),ISNUMBER($F31)),IF($F31>$E31,1,0),0)+IF(AND(ISNUMBER($E31),ISNUMBER($G31)),IF($E31>$G31,1,0),0)+IF(AND(ISNUMBER($F31),ISNUMBER($G31)),IF($F31>$G31,1,0),0) -> 0 | AA31: =IF(AND($P31="Derived",$V31="觀測"),1,0) -> 0 | AB31: CC 初評
A32: SRC_ANT_028 | B32: rev_mix_2024_cloud_partner_share | C32: A | D32: 經 Amazon／Google 雲端通路之營收占比 | E32: 0.32 | H32: 比例 | I32: 2024 | K32: 總額 | L32: Reuters（經 Khaleej Times 轉載） | M32: https://www.khaleejtimes.com/business/anthropic-ipo-prospectus-lays-bare-deep-dependence-on-big-tech-partners?amp=1 | N32: 2026-09-30 | O32: 2026-10-08 | P32: Interested-party | Q32: Anthropic（外流招股書；IPO 誘因） | R32: 2 | S32: 利害關係方 | T32: Anthropic（外流招股書；IPO 誘因） | U32: 二手 | V32: 觀測 | W32: 原文：share 'rose from 11% in 2023 to 32% in 2024' | X32: =IF(AND(COUNT($E32:$G32)=0,LEFT($H32,2)<>"定性",LEFT($H32,2)<>"文字",LEFT($H32,2)<>"日期"),1,0) -> 0 | Y32: =IF(OR($L32="",$M32=""),1,0) -> 0 | Z32: =IF(AND(ISNUMBER($E32),ISNUMBER($F32)),IF($F32>$E32,1,0),0)+IF(AND(ISNUMBER($E32),ISNUMBER($G32)),IF($E32>$G32,1,0),0)+IF(AND(ISNUMBER($F32),ISNUMBER($G32)),IF($F32>$G32,1,0),0) -> 0 | AA32: =IF(AND($P32="Derived",$V32="觀測"),1,0) -> 0 | AB32: CC 初評
A33: SRC_ANT_029 | B33: rev_mix_2023_cloud_partner_share | C33: A | D33: 經 Amazon／Google 雲端通路之營收占比 | E33: 0.11 | H33: 比例 | I33: 2023 | K33: 總額 | L33: Reuters（經 Khaleej Times 轉載） | M33: https://www.khaleejtimes.com/business/anthropic-ipo-prospectus-lays-bare-deep-dependence-on-big-tech-partners?amp=1 | N33: 2026-09-30 | O33: 2026-10-08 | P33: Interested-party | Q33: Anthropic（外流招股書；IPO 誘因） | R33: 2 | S33: 利害關係方 | T33: Anthropic（外流招股書；IPO 誘因） | U33: 二手 | V33: 觀測 | W33: 原文：'from 11% in 2023' | X33: =IF(AND(COUNT($E33:$G33)=0,LEFT($H33,2)<>"定性",LEFT($H33,2)<>"文字",LEFT($H33,2)<>"日期"),1,0) -> 0 | Y33: =IF(OR($L33="",$M33=""),1,0) -> 0 | Z33: =IF(AND(ISNUMBER($E33),ISNUMBER($F33)),IF($F33>$E33,1,0),0)+IF(AND(ISNUMBER($E33),ISNUMBER($G33)),IF($E33>$G33,1,0),0)+IF(AND(ISNUMBER($F33),ISNUMBER($G33)),IF($F33>$G33,1,0),0) -> 0 | AA33: =IF(AND($P33="Derived",$V33="觀測"),1,0) -> 0 | AB33: CC 初評
A34: SRC_ANT_030 | B34: rev_recognition_gross | C34: A | D34: 雲端市集銷售之營收認列口徑 | H34: 定性 | I34: 2025 | K34: 總額 | L34: Reuters（經 Khaleej Times 轉載） | M34: https://www.khaleejtimes.com/business/anthropic-ipo-prospectus-lays-bare-deep-dependence-on-big-tech-partners?amp=1 | N34: 2026-09-30 | O34: 2026-10-08 | P34: Interested-party | Q34: Anthropic（外流招股書；IPO 誘因） | R34: 2 | S34: 利害關係方 | T34: Anthropic（外流招股書；IPO 誘因） | U34: 二手 | V34: 觀測 | W34: 總額認列：'books the full value of marketplace contracts as revenue and records the platforms' cut as a marketing cost'；自稱 'principal' | X34: =IF(AND(COUNT($E34:$G34)=0,LEFT($H34,2)<>"定性",LEFT($H34,2)<>"文字",LEFT($H34,2)<>"日期"),1,0) -> 0 | Y34: =IF(OR($L34="",$M34=""),1,0) -> 0 | Z34: =IF(AND(ISNUMBER($E34),ISNUMBER($F34)),IF($F34>$E34,1,0),0)+IF(AND(ISNUMBER($E34),ISNUMBER($G34)),IF($E34>$G34,1,0),0)+IF(AND(ISNUMBER($F34),ISNUMBER($G34)),IF($F34>$G34,1,0),0) -> 0 | AA34: =IF(AND($P34="Derived",$V34="觀測"),1,0) -> 0 | AB34: CC 初評
A35: SRC_ANT_031 | B35: rev_partner_fee_2025 | C35: A | D35: 2025 付給雲端平台之通路費 | E35: 0.351 | H35: $B/年 | I35: 2025 | K35: 總額 | L35: Reuters 分析（經 Khaleej Times 轉載） | M35: https://www.khaleejtimes.com/business/anthropic-ipo-prospectus-lays-bare-deep-dependence-on-big-tech-partners?amp=1 | N35: 2026-09-30 | O35: 2026-10-08 | P35: Derived | R35: 未評 | S35: 推導 | T35: 由其他 SRC_ANT 列推得（本活頁簿以公式表示） | U35: 推導 | V35: Derived→保留報導值（報導者計算後公布） | W35: 原文：'roughly $351 million back to the platforms in distribution fees'；Reuters 依招股書計算 | X35: =IF(AND(COUNT($E35:$G35)=0,LEFT($H35,2)<>"定性",LEFT($H35,2)<>"文字",LEFT($H35,2)<>"日期"),1,0) -> 0 | Y35: =IF(OR($L35="",$M35=""),1,0) -> 0 | Z35: =IF(AND(ISNUMBER($E35),ISNUMBER($F35)),IF($F35>$E35,1,0),0)+IF(AND(ISNUMBER($E35),ISNUMBER($G35)),IF($E35>$G35,1,0),0)+IF(AND(ISNUMBER($F35),ISNUMBER($G35)),IF($F35>$G35,1,0),0) -> 0 | AA35: =IF(AND($P35="Derived",$V35="觀測"),1,0) -> 0 | AB35: CC 初評
A36: SRC_ANT_032 | B36: rev_partner_fee_rate_2025 | C36: A | D36: 雲端通路抽成率（每 $1 通路營收） | E36: =SRC_ANT_031/(SRC_ANT_002*SRC_ANT_027) -> 0.16270338 | H36: 比例 | I36: 2025 | K36: 總額 | L36: Reuters 分析（經 Khaleej Times 轉載） | M36: https://www.khaleejtimes.com/business/anthropic-ipo-prospectus-lays-bare-deep-dependence-on-big-tech-partners?amp=1 | N36: 2026-09-30 | O36: 2026-10-08 | P36: Derived | R36: 未評 | S36: 推導 | T36: 由其他 SRC_ANT 列推得（本活頁簿以公式表示） | U36: 推導 | V36: Derived→公式 | W36: 原文：'some 16 cents for every dollar of those sales'。0.351/(4.59×0.47)≈0.16 一致 | X36: =IF(AND(COUNT($E36:$G36)=0,LEFT($H36,2)<>"定性",LEFT($H36,2)<>"文字",LEFT($H36,2)<>"日期"),1,0) -> 0 | Y36: =IF(OR($L36="",$M36=""),1,0) -> 0 | Z36: =IF(AND(ISNUMBER($E36),ISNUMBER($F36)),IF($F36>$E36,1,0),0)+IF(AND(ISNUMBER($E36),ISNUMBER($G36)),IF($E36>$G36,1,0),0)+IF(AND(ISNUMBER($F36),ISNUMBER($G36)),IF($F36>$G36,1,0),0) -> 0 | AA36: =IF(AND($P36="Derived",$V36="觀測"),1,0) -> 0 | AB36: CC 初評
A37: SRC_ANT_033 | B37: rev_partner_fee_2025_b | C37: A | D37: 2025 付給超大雲端之金額（券商估計） | E37: 1.9 | H37: $B/年 | I37: 2025 | K37: 總額 | L37: Forbes〈OpenAI And Anthropic Count Revenue Differently〉（引 Bank of America 2026-03 估計） | M37: https://www.forbes.com/sites/josipamajic/2026/03/25/openai-and-anthropic-count-revenue-differently-and-investors-are-looking-into-it/ | N37: 2026-03-25 | O37: 2026-10-08 | P37: Analogy | R37: 2 | S37: 第三方估計 | T37: 第三方估計；非公司揭露，作類比或區間 | U37: 二手 | V37: 觀測 | W37: 原文：'up to $6.4 billion in 2026…up from $1.9 billion in 2025'。與招股書 $351M 矛盾（BofA 口徑可能含算力租金），以招股書為準 | X37: =IF(AND(COUNT($E37:$G37)=0,LEFT($H37,2)<>"定性",LEFT($H37,2)<>"文字",LEFT($H37,2)<>"日期"),1,0) -> 0 | Y37: =IF(OR($L37="",$M37=""),1,0) -> 0 | Z37: =IF(AND(ISNUMBER($E37),ISNUMBER($F37)),IF($F37>$E37,1,0),0)+IF(AND(ISNUMBER($E37),ISNUMBER($G37)),IF($E37>$G37,1,0),0)+IF(AND(ISNUMBER($F37),ISNUMBER($G37)),IF($F37>$G37,1,0),0) -> 0 | AA37: =IF(AND($P37="Derived",$V37="觀測"),1,0) -> 0 | AB37: CC 初評
A38: SRC_ANT_034 | B38: rev_partner_fee_2026_est | C38: A | D38: 2026 付給超大雲端之金額（券商估計） | E38: 6.4 | G38: 6.4 | H38: $B/年 | I38: 2026 | K38: 總額 | L38: Forbes（引 Bank of America） | M38: https://www.forbes.com/sites/josipamajic/2026/03/25/openai-and-anthropic-count-revenue-differently-and-investors-are-looking-into-it/ | N38: 2026-03-25 | O38: 2026-10-08 | P38: Analogy | R38: 2 | S38: 第三方估計 | T38: 第三方估計；非公司揭露，作類比或區間 | U38: 二手 | V38: 觀測 | W38: 原文：'could pay hyperscale cloud providers up to $6.4 billion in 2026' | X38: =IF(AND(COUNT($E38:$G38)=0,LEFT($H38,2)<>"定性",LEFT($H38,2)<>"文字",LEFT($H38,2)<>"日期"),1,0) -> 0 | Y38: =IF(OR($L38="",$M38=""),1,0) -> 0 | Z38: =IF(AND(ISNUMBER($E38),ISNUMBER($F38)),IF($F38>$E38,1,0),0)+IF(AND(ISNUMBER($E38),ISNUMBER($G38)),IF($E38>$G38,1,0),0)+IF(AND(ISNUMBER($F38),ISNUMBER($G38)),IF($F38>$G38,1,0),0) -> 0 | AA38: =IF(AND($P38="Derived",$V38="觀測"),1,0) -> 0 | AB38: CC 初評
A39: SRC_ANT_035 | B39: rev_runrate_gross_dispute_2026_04 | C39: A | D39: OpenAI 估計之 Anthropic「淨額」run-rate | E39: 22 | H39: $B/年 | I39: 2026-04 | K39: 淨額 | L39: Implicator〈OpenAI CRO tells staff Anthropic inflates run rate by $8 billion〉（OpenAI CRO 內部備忘錄，The Verge／CNBC 取得） | M39: https://www.implicator.ai/openai-cro-tells-staff-anthropic-inflates-run-rate-by-8-billion/ | N39: 2026-04-13 | O39: 2026-10-08 | P39: Interested-party | Q39: OpenAI（競爭對手；貶低對手誘因） | R39: 2 | S39: 利害關係方 | T39: OpenAI（競爭對手；貶低對手誘因） | U39: 二手 | V39: 觀測 | W39: 原文：'Their stated run rate is inflated'；OpenAI 估 'true' run rate 約 $22B（對比公布的 $30B，差 $8B） | X39: =IF(AND(COUNT($E39:$G39)=0,LEFT($H39,2)<>"定性",LEFT($H39,2)<>"文字",LEFT($H39,2)<>"日期"),1,0) -> 0 | Y39: =IF(OR($L39="",$M39=""),1,0) -> 0 | Z39: =IF(AND(ISNUMBER($E39),ISNUMBER($F39)),IF($F39>$E39,1,0),0)+IF(AND(ISNUMBER($E39),ISNUMBER($G39)),IF($E39>$G39,1,0),0)+IF(AND(ISNUMBER($F39),ISNUMBER($G39)),IF($F39>$G39,1,0),0) -> 0 | AA39: =IF(AND($P39="Derived",$V39="觀測"),1,0) -> 0 | AB39: CC 初評
A40: SRC_ANT_036 | B40: rev_enterprise_share_2025_10 | C40: A | D40: 企業與商業客戶占營收比例 | E40: 0.8 | H40: 比例 | I40: 2025-10 | K40: 未明 | L40: Reuters 獨家〈Anthropic aims to nearly triple annualized revenue in 2026〉 | M40: https://finance.yahoo.com/news/exclusive-anthropic-aims-nearly-triple-170234463.html | N40: 2025-10-15 | O40: 2026-10-08 | P40: Interested-party | Q40: Anthropic（募資誘因） | R40: 2 | S40: 利害關係方 | T40: Anthropic（募資誘因） | U40: 二手 | V40: 觀測 | W40: 原文：business and enterprise customers 'account for about 80% of its revenue' | X40: =IF(AND(COUNT($E40:$G40)=0,LEFT($H40,2)<>"定性",LEFT($H40,2)<>"文字",LEFT($H40,2)<>"日期"),1,0) -> 0 | Y40: =IF(OR($L40="",$M40=""),1,0) -> 0 | Z40: =IF(AND(ISNUMBER($E40),ISNUMBER($F40)),IF($F40>$E40,1,0),0)+IF(AND(ISNUMBER($E40),ISNUMBER($G40)),IF($E40>$G40,1,0),0)+IF(AND(ISNUMBER($F40),ISNUMBER($G40)),IF($F40>$G40,1,0),0) -> 0 | AA40: =IF(AND($P40="Derived",$V40="觀測"),1,0) -> 0 | AB40: CC 初評
...

Sheet TK_Link
A1: TK_Link — Tokenomics 快照（第 0 層連結；不用 Excel 外部連結）
A2: 每列一個 Tokenomics 名稱。值（藍字）由 builder 從 Tokenomics master 的 model/CURRENT 讀出寫入；本模型公式只引用 TK_ 具名範圍。前 63 名與 OpenAI v0.6 相同，其後 5 名為 A2 新增（任務別每次嘗試 token）；再其後 14 名為 v0.1.2 新增（Tokenomics v18.0 的 L1_RevGW_PQ_VR200 等對照名稱，只對照、不回饋計算）；再其後 23 名為 v0.1.3 B 新增（IF_UtilActual、L1_TokGW_PaidCap_VR200、B4_MixPaid、L1_Gap*，只供 EtaDiag 對照）；其後為 NonNV 表（Tokenomics 未設具名範圍，以列標籤＋欄標題讀表；狀態「讀表（非具名）」，列入 Tokenomics 缺口：建議 Tokenomics 把 NonNV 比例列進 Interface）。
A3: Tokenomics 檔案 | B3: 20261023_Tokenomics_v21.2.xlsx | C3: 檔案 SHA-256：d221dd93543b15be9e4d27352c443dec0c80dd387625bcd12145236846946f5c
A4: Tokenomics 版本 | B4: v21.2
A5: Tokenomics 提交 SHA（master） | B5: 45ce1cad52fe64e0bf379daf94420668631f60be
A6: 讀取日期 | B6: 2026-10-24
I7: 世代 | J7: Hopper H100 | K7: Hopper H100 | L7: Hopper H100 | M7: GB200 NVL72 | N7: GB200 NVL72 | O7: GB200 NVL72 | P7: GB300 NVL72 | Q7: GB300 NVL72 | R7: GB300 NVL72 | S7: VR200 NVL72 | T7: VR200 NVL72 | U7: VR200 NVL72 | V7: Rubin Ultra（MGX NVL 單架，72 GPU） | W7: Rubin Ultra（MGX NVL 單架，72 GPU） | X7: Rubin Ultra（MGX NVL 單架，72 GPU）
I8: 成本情境 | J8: 低成本 | K8: 基準 | L8: 高成本 | M8: 低成本 | N8: 基準 | O8: 高成本 | P8: 低成本 | Q8: 基準 | R8: 高成本 | S8: 低成本 | T8: 基準 | U8: 高成本 | V8: 低成本 | W8: 基準 | X8: 高成本
A9: Tokenomics 名稱 | B9: 本模型名稱 | C9: 說明 | D9: 單位 | E9: 欄數 | F9: 狀態 | G9: Tokenomics 版本 | H9: 提交 SHA | I9: 讀取日期 | J9: 值1 | K9: 值2 | L9: 值3 | M9: 值4 | N9: 值5 | O9: 值6 | P9: 值7 | Q9: 值8 | R9: 值9 | S9: 值10 | T9: 值11 | U9: 值12 | V9: 值13 | W9: 值14 | X9: 值15
A10: IF_TokGW_Astra | B10: TK_IF_TokGW_Astra | C10: 每 GW 總產出（100%） | D10: M tok/年 | E10: 15 | F10: OK | G10: v21.2 | H10: 45ce1ca | I10: 2026-10-24 | J10: 6.8090257e+09 | K10: 6.8090257e+09 | L10: 6.8090257e+09 | M10: 3.3674782e+10 | N10: 3.3674782e+10 | O10: 3.3674782e+10 | P10: 3.9257828e+10 | Q10: 3.9257828e+10 | R10: 3.9257828e+10 | S10: 6.9625194e+10 | T10: 6.9625194e+10 | U10: 6.9625194e+10 | V10: 9.8521567e+10 | W10: 9.8521567e+10 | X10: 9.8521567e+10
A11: IF_TokGW_Luna | B11: TK_IF_TokGW_Luna | C11: 每 GW 總產出（100%） | D11: M tok/年 | E11: 15 | F11: OK | G11: v21.2 | H11: 45ce1ca | I11: 2026-10-24 | J11: 1.3212779e+11 | K11: 1.3212779e+11 | L11: 1.3212779e+11 | M11: 6.5720776e+11 | N11: 6.5720776e+11 | O11: 6.5720776e+11 | P11: 8.5215069e+11 | Q11: 8.5215069e+11 | R11: 8.5215069e+11 | S11: 1.2292711e+12 | T11: 1.2292711e+12 | U11: 1.2292711e+12 | V11: 1.6549899e+12 | W11: 1.6549899e+12 | X11: 1.6549899e+12
A12: IF_TokGW_Sol | B12: TK_IF_TokGW_Sol | C12: 每 GW 總產出（100%） | D12: M tok/年 | E12: 15 | F12: OK | G12: v21.2 | H12: 45ce1ca | I12: 2026-10-24 | J12: 3.3634916e+10 | K12: 3.3634916e+10 | L12: 3.3634916e+10 | M12: 1.6371585e+11 | N12: 1.6371585e+11 | O12: 1.6371585e+11 | P12: 2.1233432e+11 | Q12: 2.1233432e+11 | R12: 2.1233432e+11 | S12: 3.189849e+11 | T12: 3.189849e+11 | U12: 3.189849e+11 | V12: 4.3438046e+11 | W12: 4.3438046e+11 | X12: 4.3438046e+11
A13: IF_Util | B13: TK_IF_Util | C13: 基準利用率（第 0 層；下游可覆寫） | D13: % | E13: 1 | F13: OK | G13: v21.2 | H13: 45ce1ca | I13: 2026-10-24 | J13: 0.6
A14: IF_HoldEcon | B14: TK_IF_HoldEcon | C14: 每 GW 年持有成本 — 經濟口徑 | D14: $B/年 | E14: 15 | F14: OK | G14: v21.2 | H14: 45ce1ca | I14: 2026-10-24 | J14: 6.7910747 | K14: 9.7030873 | L14: 16.66377 | M14: 6.6118163 | N14: 8.8281656 | O14: 14.318575 | P14: 8.4288991 | Q14: 10.886411 | R14: 18.534646 | S14: 9.5120769 | T14: 12.225471 | U14: 19.750627 | V14: 10.102545 | W14: 15.354483 | X14: 28.030245
A15: IF_FullCost_Astra | B15: TK_IF_FullCost_Astra | C15: 全成本 $/M（服務＋快取儲存＋自下而上攤提；基準利用率） | D15: $/M | E15: 15 | F15: OK | G15: v21.2 | H15: 45ce1ca | I15: 2026-10-24 | J15: 4.4021516 | K15: 6.2896983 | L15: 10.801565 | M15: 0.52754214 | N15: 0.7043049 | O15: 1.1421871 | P15: 0.59542572 | Q15: 0.76896169 | R15: 1.3090379 | S15: 0.32750132 | T15: 0.42085994 | U15: 0.67977486 | V15: 0.22348051 | W15: 0.33954367 | X15: 0.61966677
A16: IF_FullCost_Luna | B16: TK_IF_FullCost_Luna | C16: 全成本 $/M（服務＋快取儲存＋自下而上攤提；基準利用率） | D16: $/M | E16: 15 | F16: OK | G16: v21.2 | H16: 45ce1ca | I16: 2026-10-24 | J16: 0.13007314 | K16: 0.18584385 | L16: 0.31915448 | M16: 0.019399496 | N16: 0.025898777 | O16: 0.041998998 | P16: 0.019801297 | Q16: 0.025571363 | R16: 0.043528882 | S16: 0.014424161 | T16: 0.018535675 | U16: 0.029938289 | V16: 0.010962375 | W16: 0.016655675 | X16: 0.030396683
A17: IF_FullCost_Sol | B17: TK_IF_FullCost_Sol | C17: 全成本 $/M（服務＋快取儲存＋自下而上攤提；基準利用率） | D17: $/M | E17: 15 | F17: OK | G17: v21.2 | H17: 45ce1ca | I17: 2026-10-24 | J17: 0.44900392 | K17: 0.6415302 | L17: 1.1017323 | M17: 0.075009295 | N17: 0.10014804 | O17: 0.16242251 | P17: 0.075436869 | Q17: 0.097426601 | R17: 0.16586274 | S17: 0.053723627 | T17: 0.069044327 | U17: 0.11153379 | V17: 0.04087016 | W17: 0.062109051 | X17: 0.11336996
A18: IF_PriceCached_Astra | B18: TK_IF_PriceCached_Astra | C18: 快取輸入 $/M — OpenAI 有效 | D18: $/M | E18: 1 | F18: OK | G18: v21.2 | H18: 45ce1ca | I18: 2026-10-24 | J18: 0.8
A19: IF_PriceCached_Luna | B19: TK_IF_PriceCached_Luna | C19: 快取輸入 $/M — OpenAI 有效 | D19: $/M | E19: 1 | F19: OK | G19: v21.2 | H19: 45ce1ca | I19: 2026-10-24 | J19: 0.008
A20: IF_PriceCached_Sol | B20: TK_IF_PriceCached_Sol | C20: 快取輸入 $/M — OpenAI 有效 | D20: $/M | E20: 1 | F20: OK | G20: v21.2 | H20: 45ce1ca | I20: 2026-10-24 | J20: 0.16
A21: IF_PriceFresh_Astra | B21: TK_IF_PriceFresh_Astra | C21: 新鮮輸入 $/M — OpenAI 有效 | D21: $/M | E21: 1 | F21: OK | G21: v21.2 | H21: 45ce1ca | I21: 2026-10-24 | J21: 8
A22: IF_PriceFresh_Luna | B22: TK_IF_PriceFresh_Luna | C22: 新鮮輸入 $/M — OpenAI 有效 | D22: $/M | E22: 1 | F22: OK | G22: v21.2 | H22: 45ce1ca | I22: 2026-10-24 | J22: 0.08
A23: IF_PriceFresh_Sol | B23: TK_IF_PriceFresh_Sol | C23: 新鮮輸入 $/M — OpenAI 有效 | D23: $/M | E23: 1 | F23: OK | G23: v21.2 | H23: 45ce1ca | I23: 2026-10-24 | J23: 1.6
A24: IF_PriceOut_Astra | B24: TK_IF_PriceOut_Astra | C24: 可見輸出 $/M — OpenAI 有效 | D24: $/M | E24: 1 | F24: OK | G24: v21.2 | H24: 45ce1ca | I24: 2026-10-24 | J24: 40
A25: IF_PriceOut_Luna | B25: TK_IF_PriceOut_Luna | C25: 可見輸出 $/M — OpenAI 有效 | D25: $/M | E25: 1 | F25: OK | G25: v21.2 | H25: 45ce1ca | I25: 2026-10-24 | J25: 0.4
A26: IF_PriceOut_Sol | B26: TK_IF_PriceOut_Sol | C26: 可見輸出 $/M — OpenAI 有效 | D26: $/M | E26: 1 | F26: OK | G26: v21.2 | H26: 45ce1ca | I26: 2026-10-24 | J26: 8
A27: IF_PriceRef_Astra | B27: TK_IF_PriceRef_Astra | C27: 參考請求混合 $/M — OpenAI 有效 | D27: $/M | E27: 1 | F27: OK | G27: v21.2 | H27: 45ce1ca | I27: 2026-10-24 | J27: 8.0355556
A28: IF_PriceRef_Luna | B28: TK_IF_PriceRef_Luna | C28: 參考請求混合 $/M — OpenAI 有效 | D28: $/M | E28: 1 | F28: OK | G28: v21.2 | H28: 45ce1ca | I28: 2026-10-24 | J28: 0.080355556
A29: IF_PriceRef_Sol | B29: TK_IF_PriceRef_Sol | C29: 參考請求混合 $/M — OpenAI 有效 | D29: $/M | E29: 1 | F29: OK | G29: v21.2 | H29: 45ce1ca | I29: 2026-10-24 | J29: 1.6071111
... A35: IF_FrontRef_Sol | B35: TK_IF_FrontRef_Sol | C35: 參考請求混合 $/M — 前緣有效 | D35: $/M | E35: 1 | F35: OK | G35: v21.2 | H35: 45ce1ca | I35: 2026-10-24 | J35: 1.6071111
A36: IF_ProgGWyr_Astra | B36: TK_IF_ProgGWyr_Astra | C36: 研發計畫占 1 GW 一年 | D36: % | E36: 15 | F36: OK | G36: v21.2 | H36: 45ce1ca | I36: 2026-10-24 | J36: 0.15684814 | K36: 0.15684814 | L36: 0.15684814 | M36: 0.057835529 | N36: 0.057835529 | O36: 0.057835529 | P36: 0.065586407 | Q36: 0.065586407 | R36: 0.065586407 | S36: 0.040017843 | T36: 0.040017843 | U36: 0.040017843 | V36: 0.027250415 | W36: 0.027250415 | X36: 0.027250415
A37: IF_ProgGWyr_Luna | B37: TK_IF_ProgGWyr_Luna | C37: 研發計畫占 1 GW 一年 | D37: % | E37: 15 | F37: OK | G37: v21.2 | H37: 45ce1ca | I37: 2026-10-24 | J37: 0.0090369716 | K37: 0.0090369716 | L37: 0.0090369716 | M37: 0.0026868793 | N37: 0.0026868793 | O37: 0.0026868793 | P37: 0.0032381975 | Q37: 0.0032381975 | R37: 0.0032381975 | S37: 0.002143923 | T37: 0.002143923 | U37: 0.002143923 | V37: 0.0013904609 | W37: 0.0013904609 | X37: 0.0013904609
A38: IF_ProgGWyr_Sol | B38: TK_IF_ProgGWyr_Sol | C38: 研發計畫占 1 GW 一年 | D38: % | E38: 15 | F38: OK | G38: v21.2 | H38: 45ce1ca | I38: 2026-10-24 | J38: 0.025757353 | K38: 0.025757353 | L38: 0.025757353 | M38: 0.0088777551 | N38: 0.0088777551 | O38: 0.0088777551 | P38: 0.010227304 | Q38: 0.010227304 | R38: 0.010227304 | S38: 0.006421121 | T38: 0.006421121 | U38: 0.006421121 | V38: 0.0043094856 | W38: 0.0043094856 | X38: 0.0043094856
A39: IF_RDMult | B39: TK_IF_RDMult | C39: 研發倍數（第 0 層基準；下游可覆寫） | D39: x | E39: 1 | F39: OK | G39: v21.2 | H39: 45ce1ca | I39: 2026-10-24 | J39: 8
A40: IF_TrainGenDefault | B40: TK_IF_TrainGenDefault | C40: 下游預設訓練世代（索引；J13） | D40: 索引 | E40: 1 | F40: OK | G40: v21.2 | H40: 45ce1ca | I40: 2026-10-24 | J40: 4
A41: SRC_DEM_004 | B41: TK_SRC_DEM_004 | C41: OpenAI 2025 推論支出（年度；json 一致集（與 005／006／007 同源）） | D41: $B | E41: 1 | F41: OK | G41: v21.2 | H41: 45ce1ca | I41: 2026-10-24 | J41: 8.4
A42: SRC_DEM_005 | B42: TK_SRC_DEM_005 | C42: OpenAI 2025 非付費用戶推論支出（年度） | D42: $B | E42: 1 | F42: OK | G42: v21.2 | H42: 45ce1ca | I42: 2026-10-24 | J42: 3.9
A43: SRC_DEM_006 | B43: TK_SRC_DEM_006 | C43: OpenAI 2025 訓練支出（年度；約值） | D43: $B | E43: 1 | F43: OK | G43: v21.2 | H43: 45ce1ca | I43: 2026-10-24 | J43: 12
A44: SRC_DEM_007 | B44: TK_SRC_DEM_007 | C44: OpenAI 2025 營收（年度） | D44: $B | E44: 1 | F44: OK | G44: v21.2 | H44: 45ce1ca | I44: 2026-10-24 | J44: 13.07
A45: SRC_DEM_008 | B45: TK_SRC_DEM_008 | C45: OpenAI 算力規模 2024 年底（GW 口徑未明（D1）） | D45: GW | E45: 1 | F45: OK | G45: v21.2 | H45: 45ce1ca | I45: 2026-10-24 | J45: 0.6
...

Sheet OAI_Link
A1: OAI_Link — OpenAI v0.6 命題輸出快照（規格 D20；只作並排對照）
A2: 值由 builder 從 OpenAI v0.6 活頁簿的快取值讀出寫入（藍字）。本頁只被 Checks（與 A5 的 HTML）引用，任何計算頁不得引用（Checks 列 builder 掃描結果；tests 每次重驗）。
A3: OpenAI 的 2025 為其實際校準年。注意：OpenAI v0.6 用 Tokenomics v5.26 快照，本模型自 v0.1.2 起用 v18.0（見 TK_Link）；兩家的 η、供給 GW 與每 GW 產能口徑因此不同，並排對照時差異有一部分來自 Tokenomics 版本，而非公司本身。
A4: OpenAI 檔案 | B4: 20261008_OpenAI_v0.6.xlsx
A5: 檔案 SHA-256 | B5: 34fc34a7ea2c18e8f608356ca462d8bd208496ca61780589b559fd2efc6597fe
A6: git 提交（建置時） | B6: f41bf685279cc96e84ca268df076001d02787663
A7: 讀取日期 | B7: 2026-10-24
A9: OpenAI 名稱 | B9: 本模型名稱 | C9: 說明 | D9: 2025 | E9: 2026 | F9: 2027 | G9: 2028 | H9: 2029 | I9: 2030 | J9: 單位 | K9: OpenAI 位置
A10: REV_Gross | B10: OAI_REV_Gross | C10: 營收總額 | D10: 13.07 | E10: 34.203781 | F10: 54.795653 | G10: 78.424089 | H10: 102.12737 | I10: 126.38309 | J10: $B | K10: Revenue!$D$38:$I$38
A11: REV_Net | B11: OAI_REV_Net | C11: 營收淨額（扣 Microsoft 分成） | D11: 10.456 | E11: 27.363025 | F11: 43.836523 | G11: 62.739271 | H11: 97.612079 | I11: 126.38309 | J11: $B | K11: Revenue!$D$41:$I$41
A12: REV_NetCapped | B12: OAI_REV_NetCapped | C12: 營收淨額（容量截頂後） | D12: 10.456 | E12: 27.363025 | F12: 43.836523 | G12: 62.739271 | H12: 97.612079 | I12: 126.38309 | J12: $B | K12: Revenue!$D$77:$I$77
A13: REV_Sub | B13: OAI_REV_Sub | C13: 訂閱營收 | D13: 8.9214194 | E13: 16.936529 | F13: 25.382952 | G13: 33.851419 | H13: 40.685232 | I13: 46.56514 | J13: $B | K13: Revenue!$D$27:$I$27
A14: REV_API | B14: OAI_REV_API | C14: API 營收 | D14: 4.1485806 | E14: 16.524302 | F14: 27.554274 | G14: 41.662063 | H14: 57.285336 | I14: 74.241796 | J14: $B | K14: Revenue!$D$34:$I$34
A15: DEM_Tok_Total | B15: OAI_DEM_Tok_Total | C15: token 合計（付費＋免費） | D15: 3538.0601 | E15: 10018.624 | F15: 22447.299 | G15: 47137.552 | H15: 92412.32 | I15: 173673.87 | J15: T | K15: Demand!$D$51:$I$51
A16: CMP_SupplyGW | B16: OAI_CMP_SupplyGW | C16: 供給 GW | D16: 1.2296032 | E16: 2.8342063 | F16: 9.3367692 | G16: 11.538312 | H16: 14.038324 | I16: 16.09014 | J16: GW | K16: Compute!$D$87:$I$87
A17: CMP_Supply_VReq | B17: OAI_CMP_Supply_VReq | C17: 供給 VR 等值 GW | D17: 0.28264462 | E17: 1.1565252 | F17: 5.7520321 | G17: 8.9411774 | H17: 12.146409 | I17: 14.944726 | J17: GW | K17: Compute!$D$99:$I$99
A18: COST_Compute | B18: OAI_COST_Compute | C18: 算力成本（現金） | D18: 14.755238 | E18: 53.240635 | F18: 141.72603 | G18: 175.21143 | H18: 208.69683 | I18: 228.22222 | J18: $B | K18: Cost!$D$27:$I$27
A19: COST_FullCash | B19: OAI_COST_FullCash | C19: 全成本（現金，含股權報酬） | D19: 29.235238 | E19: 76.078955 | F19: 171.94384 | G19: 212.1254 | H19: 251.9209 | I19: 276.64452 | J19: $B | K19: Cost!$D$87:$I$87
A20: COST_PropRev_VR | B20: OAI_COST_PropRev_VR | C20: 每 VR 等值 GW 營收淨額 | D20: 36.993451 | E20: 23.659688 | F20: 7.6210498 | G20: 7.0168914 | H20: 8.0362912 | I20: 8.456702 | J20: $B/GW/年 | K20: Cost!$D$90:$I$90
A21: COST_PropFull_VR | B21: OAI_COST_PropFull_VR | C21: 每 VR 等值 GW 全成本 | D21: 103.43462 | E21: 65.782359 | F21: 29.892713 | G21: 23.724549 | H21: 20.740361 | I21: 18.511181 | J21: $B/GW/年 | K21: Cost!$D$94:$I$94
... A23: COST_Coverage | B23: OAI_COST_Coverage | C23: 覆蓋率（營收 ÷ 全成本） | D23: 0.35765058 | E23: 0.35966615 | F23: 0.25494674 | G23: 0.29576501 | H23: 0.38747114 | I23: 0.45684293 | J23: 倍 | K23: Cost!$D$98:$I$98
A24: FND_ExtNeed | B24: OAI_FND_ExtNeed | C24: 外部資金需求（當年） | E24: 0 | F24: 38.433249 | G24: 134.87813 | H24: 137.62462 | I24: 131.90881 | J24: $B | K24: Funding!$D$29:$I$29
A25: FND_ExtNeedCum | B25: OAI_FND_ExtNeedCum | C25: 累計外部資金需求（命題 2） | E25: 0 | F25: 38.433249 | G25: 173.31138 | H25: 310.936 | I25: 442.84481 | J25: $B | K25: Funding!$D$31:$I$31
A26: FND_CashEnd | B26: OAI_FND_CashEnd | C26: 年底現金 | D26: 40 | E26: 87.58407 | F26: 10 | G26: 10 | H26: 10 | I26: 10 | J26: $B | K26: Funding!$D$30:$I$30

Sheet Inputs
A1: Inputs — 假設輸入（藍字）：值、低、高、標記、依據、區間理由
A2: 長表格式：一列一個（參數 × 索引）。Analogy／Assumed 一律附區間（M 欄檢查）；Decision 為定義常數或開關（低＝高＝值）。來源 data/anthropic_inputs.yaml；ID 由 builder/id_registry.json 固定。
A3: 引用 OpenAI v0.6 同類參數作 Analogy 者，依據欄寫明「OpenAI v0.6 INP_nnn」與差異。
A4: INP_ID | B4: 參數 | C4: 索引 | D4: 單位 | E4: 值 | F4: 低 | G4: 高 | H4: 標記 | I4: 依據 | J4: 區間理由 | K4: 用途／備註 | L4: 區間順序異常（公式） | M4: Analogy／Assumed 缺區間（公式） | N4: key
A5: INP_001 | B5: 模型年度 | C5: 第 1 年 | D5: 年 | E5: 2025 | F5: 2025 | G5: 2025 | H5: Decision | I5: 曆年制；2025 為實際校準年（規格 D1、D14） | J5: 定義值 | K5: Demand／Revenue 第 6 列年度 | L5: =IF(AND(ISNUMBER($E5),ISNUMBER($F5),ISNUMBER($G5)),IF(AND($F5<=$E5,$E5<=$G5),0,1),0) -> 0 | M5: =IF(AND(OR($H5="Analogy",$H5="Assumed"),OR(NOT(ISNUMBER($F5)),NOT(ISNUMBER($G5)))),1,0) -> 0 | N5: year_2025
A6: INP_002 | B6: 模型年度 | C6: 第 2 年 | D6: 年 | E6: 2026 | F6: 2026 | G6: 2026 | H6: Decision | I6: 2026 為半校準年（規格 D15 r1） | J6: 定義值 | L6: =IF(AND(ISNUMBER($E6),ISNUMBER($F6),ISNUMBER($G6)),IF(AND($F6<=$E6,$E6<=$G6),0,1),0) -> 0 | M6: =IF(AND(OR($H6="Analogy",$H6="Assumed"),OR(NOT(ISNUMBER($F6)),NOT(ISNUMBER($G6)))),1,0) -> 0 | N6: year_2026
A7: INP_003 | B7: 模型年度 | C7: 第 3 年 | D7: 年 | E7: 2027 | F7: 2027 | G7: 2027 | H7: Decision | I7: 曆年制 | J7: 定義值 | L7: =IF(AND(ISNUMBER($E7),ISNUMBER($F7),ISNUMBER($G7)),IF(AND($F7<=$E7,$E7<=$G7),0,1),0) -> 0 | M7: =IF(AND(OR($H7="Analogy",$H7="Assumed"),OR(NOT(ISNUMBER($F7)),NOT(ISNUMBER($G7)))),1,0) -> 0 | N7: year_2027
A8: INP_004 | B8: 模型年度 | C8: 第 4 年 | D8: 年 | E8: 2028 | F8: 2028 | G8: 2028 | H8: Decision | I8: 曆年制 | J8: 定義值 | L8: =IF(AND(ISNUMBER($E8),ISNUMBER($F8),ISNUMBER($G8)),IF(AND($F8<=$E8,$E8<=$G8),0,1),0) -> 0 | M8: =IF(AND(OR($H8="Analogy",$H8="Assumed"),OR(NOT(ISNUMBER($F8)),NOT(ISNUMBER($G8)))),1,0) -> 0 | N8: year_2028
A9: INP_005 | B9: 模型年度 | C9: 第 5 年 | D9: 年 | E9: 2029 | F9: 2029 | G9: 2029 | H9: Decision | I9: 曆年制 | J9: 定義值 | L9: =IF(AND(ISNUMBER($E9),ISNUMBER($F9),ISNUMBER($G9)),IF(AND($F9<=$E9,$E9<=$G9),0,1),0) -> 0 | M9: =IF(AND(OR($H9="Analogy",$H9="Assumed"),OR(NOT(ISNUMBER($F9)),NOT(ISNUMBER($G9)))),1,0) -> 0 | N9: year_2029
A10: INP_006 | B10: 模型年度 | C10: 第 6 年 | D10: 年 | E10: 2030 | F10: 2030 | G10: 2030 | H10: Decision | I10: 曆年制 | J10: 定義值 | L10: =IF(AND(ISNUMBER($E10),ISNUMBER($F10),ISNUMBER($G10)),IF(AND($F10<=$E10,$E10<=$G10),0,1),0) -> 0 | M10: =IF(AND(OR($H10="Analogy",$H10="Assumed"),OR(NOT(ISNUMBER($F10)),NOT(ISNUMBER($G10)))),1,0) -> 0 | N10: year_2030
A11: INP_007 | B11: 每年天數（定義常數） | C11: — | D11: 天 | E11: 365 | F11: 365 | G11: 365 | H11: Decision | I11: 定義常數 | J11: 不適用 | K11: 每日任務 × 天數 → 年 token | L11: =IF(AND(ISNUMBER($E11),ISNUMBER($F11),ISNUMBER($G11)),IF(AND($F11<=$E11,$E11<=$G11),0,1),0) -> 0 | M11: =IF(AND(OR($H11="Analogy",$H11="Assumed"),OR(NOT(ISNUMBER($F11)),NOT(ISNUMBER($G11)))),1,0) -> 0 | N11: days_per_year
A12: INP_008 | B12: 每年月數（定義常數） | C12: — | D12: 月 | E12: 12 | F12: 12 | G12: 12 | H12: Decision | I12: 定義常數 | J12: 不適用 | K12: 月費 × 12 → 年營收 | L12: =IF(AND(ISNUMBER($E12),ISNUMBER($F12),ISNUMBER($G12)),IF(AND($F12<=$E12,$E12<=$G12),0,1),0) -> 0 | M12: =IF(AND(OR($H12="Analogy",$H12="Assumed"),OR(NOT(ISNUMBER($F12)),NOT(ISNUMBER($G12)))),1,0) -> 0 | N12: months_per_year
A13: INP_009 | B13: 下半年月數（定義常數） | C13: — | D13: 月 | E13: 6 | F13: 6 | G13: 6 | H13: Decision | I13: 定義常數；規格 D15 r1「下半年＝最新年化營收 ÷ 2」＝年化 × 6 ÷ 12 | J13: 不適用 | K13: 2026 半校準 | L13: =IF(AND(ISNUMBER($E13),ISNUMBER($F13),ISNUMBER($G13)),IF(AND($F13<=$E13,$E13<=$G13),0,1),0) -> 0 | M13: =IF(AND(OR($H13="Analogy",$H13="Assumed"),OR(NOT(ISNUMBER($F13)),NOT(ISNUMBER($G13)))),1,0) -> 0 | N13: h2_months
A14: INP_010 | B14: 年度起始月（定義常數） | C14: — | D14: 月 | E14: 1 | F14: 1 | G14: 1 | H14: Decision | I14: 曆年制 | J14: 不適用 | K14: DATE(年度 | L14: =IF(AND(ISNUMBER($E14),ISNUMBER($F14),ISNUMBER($G14)),IF(AND($F14<=$E14,$E14<=$G14),0,1),0) -> 0 | M14: =IF(AND(OR($H14="Analogy",$H14="Assumed"),OR(NOT(ISNUMBER($F14)),NOT(ISNUMBER($G14)))),1,0) -> 0 | N14: fy_start_month
A15: INP_011 | B15: 年度起始日（定義常數） | C15: — | D15: 日 | E15: 1 | F15: 1 | G15: 1 | H15: Decision | I15: 曆年制 | J15: 不適用 | K15: 同上 | L15: =IF(AND(ISNUMBER($E15),ISNUMBER($F15),ISNUMBER($G15)),IF(AND($F15<=$E15,$E15<=$G15),0,1),0) -> 0 | M15: =IF(AND(OR($H15="Analogy",$H15="Assumed"),OR(NOT(ISNUMBER($F15)),NOT(ISNUMBER($G15)))),1,0) -> 0 | N15: fy_start_day
A16: INP_012 | B16: 單位換算：$M → $B 的除數（定義常數） | C16: — | D16: $M／$B | E16: 1000 | F16: 1000 | G16: 1000 | H16: Decision | I16: 定義常數 | J16: 不適用 | K16: 人數（M）× 月費 × 12＝$M；T token × $/M token＝$M | L16: =IF(AND(ISNUMBER($E16),ISNUMBER($F16),ISNUMBER($G16)),IF(AND($F16<=$E16,$E16<=$G16),0,1),0) -> 0 | M16: =IF(AND(OR($H16="Analogy",$H16="Assumed"),OR(NOT(ISNUMBER($F16)),NOT(ISNUMBER($G16)))),1,0) -> 0 | N16: m_to_b
A17: INP_013 | B17: 單位換算：B token → T token 的除數（定義常數） | C17: — | D17: B／T | E17: 1000 | F17: 1000 | G17: 1000 | H17: Decision | I17: 定義常數 | J17: 不適用 | K17: 人數（M）× 任務 × 每任務 K token＝B token | L17: =IF(AND(ISNUMBER($E17),ISNUMBER($F17),ISNUMBER($G17)),IF(AND($F17<=$E17,$E17<=$G17),0,1),0) -> 0 | M17: =IF(AND(OR($H17="Analogy",$H17="Assumed"),OR(NOT(ISNUMBER($F17)),NOT(ISNUMBER($G17)))),1,0) -> 0 | N17: b_to_t
A18: INP_014 | B18: SpaceX 月費合約期間（月） | C18: — | D18: 月 | E18: 36 | F18: 36 | G18: 36 | H18: Decision | I18: SRC_ANT_227 期間「2026-05 至 2029-05」＝36 個月（定義值） | J18: 由揭露期間換算，不另設區間 | K18: SRC_ANT_230（Derived）＝月費 × 本列 | L18: =IF(AND(ISNUMBER($E18),ISNUMBER($F18),ISNUMBER($G18)),IF(AND($F18<=$E18,$E18<=$G18),0,1),0) -> 0 | M18: =IF(AND(OR($H18="Analogy",$H18="Assumed"),OR(NOT(ISNUMBER($F18)),NOT(ISNUMBER($G18)))),1,0) -> 0 | N18: spacex_term_months
A19: INP_015 | B19: 價格彈性起算年 | C19: — | D19: 年 | E19: 2027 | F19: 2027 | G19: 2027 | H19: Decision | I19: 2025 校準年、2026 半校準年（D14、D15 r1）不套彈性；同 OpenAI v0.6 INP_004 | J19: 定義值 | K19: Demand API 第三節 | L19: =IF(AND(ISNUMBER($E19),ISNUMBER($F19),ISNUMBER($G19)),IF(AND($F19<=$E19,$E19<=$G19),0,1),0) -> 0 | M19: =IF(AND(OR($H19="Analogy",$H19="Assumed"),OR(NOT(ISNUMBER($F19)),NOT(ISNUMBER($G19)))),1,0) -> 0 | N19: elasticity_start_year
A20: INP_017 | B20: 廣告營收（D3） | C20: — | D20: $B/年 | E20: 0 | F20: 0 | G20: 0 | H20: Decision | I20: 規格 D3：Anthropic 公開承諾 Claude 不放廣告，不設驅動 | J20: 公司公開立場；若反轉再加驅動 | K20: Revenue 第八節 | L20: =IF(AND(ISNUMBER($E20),ISNUMBER($F20),ISNUMBER($G20)),IF(AND($F20<=$E20,$E20<=$G20),0,1),0) -> 0 | M20: =IF(AND(OR($H20="Analogy",$H20="Assumed"),OR(NOT(ISNUMBER($F20)),NOT(ISNUMBER($G20)))),1,0) -> 0 | N20: ads_revenue
A21: INP_018 | B21: 2026 年營收對里程碑推估差距的 WARN 門檻 | C21: — | D21: 比例 | E21: 0.25 | F21: 0.25 | G21: 0.25 | H21: Decision | I21: 工作單 A2 第 6 步：2026 run-rate 對照差距 >25% 立 WARN（規格 D15） | J21: 工作單定值 | K21: Checks | L21: =IF(AND(ISNUMBER($E21),ISNUMBER($F21),ISNUMBER($G21)),IF(AND($F21<=$E21,$E21<=$G21),0,1),0) -> 0 | M21: =IF(AND(OR($H21="Analogy",$H21="Assumed"),OR(NOT(ISNUMBER($F21)),NOT(ISNUMBER($G21)))),1,0) -> 0 | N21: runrate_warn_threshold
A22: INP_180 | B22: U1 D15 r2 半校準開關（1＝2026 營收基準＝上半年實際＋Q3 實際＋Q4；0＝v0.1 的 r1＝Q1＋Q2＋2026-07 年化 × 6／12） | C22: — | D22: 開關 | E22: 1 | F22: 0 | G22: 1 | H22: Decision | I22: 工作單 20261021 U1；規格 D15 r2（S-1 草稿與 Q3 投資人簡報已給上半年與 Q3 實際） | J22: 開關 | K22: 設 0 可逐位元重現 v0.1 的 2026 基準（回歸測試） | L22: =IF(AND(ISNUMBER($E22),ISNUMBER($F22),ISNUMBER($G22)),IF(AND($F22<=$E22,$E22<=$G22),0,1),0) -> 0 | M22: =IF(AND(OR($H22="Analogy",$H22="Assumed"),OR(NOT(ISNUMBER($F22)),NOT(ISNUMBER($G22)))),1,0) -> 0 | N22: u1_switch
... A26: INP_019 | B26: Pro 年付占比 | C26: — | D26: 比例 | E26: 0.3 | F26: 0.1 | G26: 0.5 | H26: Assumed | I26: 工作單 A2 判斷類預設（年付占比 0.3）；Pro 年付月均 $17（SRC_ANT_142）vs 月付 $20（SRC_ANT_141） | J26: 工作單預設區間 0.1–0.5 | K26: Pro 實收月費＝月付 ×（1−占比）＋年付月均 × 占比 | L26: =IF(AND(ISNUMBER($E26),ISNUMBER($F26),ISNUMBER($G26)),IF(AND($F26<=$E26,$E26<=$G26),0,1),0) -> 0 | M26: =IF(AND(OR($H26="Analogy",$H26="Assumed"),OR(NOT(ISNUMBER($F26)),NOT(ISNUMBER($G26)))),1,0) -> 0 | N26: pro_annual_share
A27: INP_020 | B27: Team 年付占比（標準與 Premium 席位） | C27: — | D27: 比例 | E27: 0.3 | F27: 0.1 | G27: 0.5 | H27: Assumed | I27: 同 Pro 年付占比（工作單預設）；Team 年付 $20／$100 vs 月付 $25／$125（SRC_ANT_146–149） | J27: 同上 | L27: =IF(AND(ISNUMBER($E27),ISNUMBER($F27),ISNUMBER($G27)),IF(AND($F27<=$E27,$E27<=$G27),0,1),0) -> 0 | M27: =IF(AND(OR($H27="Analogy",$H27="Assumed"),OR(NOT(ISNUMBER($F27)),NOT(ISNUMBER($G27)))),1,0) -> 0 | N27: team_annual_share
A28: INP_021 | B28: 個人付費方案組合：Pro 占付費人數 | C28: 2025 | D28: 比例 | E28: 0.85 | F28: 0.75 | G28: 0.95 | H28: Assumed | I28: 方案別人數未揭露（A1 找不到）；Max 方案 2025-04 才上市（SRC_ANT_145），2025 年均以 Pro 為主 | J28: Max 上市後占比未知，給 ±0.1 | K28: Max 20x＝1 − Pro − Max 5x | L28: =IF(AND(ISNUMBER($E28),ISNUMBER($F28),ISNUMBER($G28)),IF(AND($F28<=$E28,$E28<=$G28),0,1),0) -> 0 | M28: =IF(AND(OR($H28="Analogy",$H28="Assumed"),OR(NOT(ISNUMBER($F28)),NOT(ISNUMBER($G28)))),1,0) -> 0 | N28: cons_mix_pro_2025
A29: INP_022 | B29: 個人付費方案組合：Max 5x 占付費人數 | C29: 2025 | D29: 比例 | E29: 0.1 | F29: 0.03 | G29: 0.15 | H29: Assumed | I29: 同上；Max 5x（$100）多於 Max 20x（$200） | J29: 上市首年占比低 | L29: =IF(AND(ISNUMBER($E29),ISNUMBER($F29),ISNUMBER($G29)),IF(AND($F29<=$E29,$E29<=$G29),0,1),0) -> 0 | M29: =IF(AND(OR($H29="Analogy",$H29="Assumed"),OR(NOT(ISNUMBER($F29)),NOT(ISNUMBER($G29)))),1,0) -> 0 | N29: cons_mix_max5_2025
A30: INP_023 | B30: 個人付費方案組合：Pro 占付費人數 | C30: 2026 起 | D30: 比例 | E30: 0.7 | F30: 0.55 | G30: 0.85 | H30: Assumed | I30: Claude Code 帶動 Max 需求（Claude Code 年化營收 2025-08 $0.5B → 2026-02 $2.5B，SRC_ANT_055、058；企業占一半 SRC_ANT_059） | J30: Max 占比可能更高或回落 | K30: 2027 起沿用 | L30: =IF(AND(ISNUMBER($E30),ISNUMBER($F30),ISNUMBER($G30)),IF(AND($F30<=$E30,$E30<=$G30),0,1),0) -> 0 | M30: =IF(AND(OR($H30="Analogy",$H30="Assumed"),OR(NOT(ISNUMBER($F30)),NOT(ISNUMBER($G30)))),1,0) -> 0 | N30: cons_mix_pro_2026
