Workbook

Sheet README
A1: OpenAI 收支模型 v0.6-P2（2026-10-07）
A2: 命題（Andy 2026-09-30）：OpenAI 每 VR 等值 GW 的營收能否覆蓋每 GW 全成本；若不能，缺口由誰、以什麼條件融資。FY2025–FY2030，曆年制。
A4: 本版範圍 | B4: P1：repo 骨架、SRC_OAI（公司財務原始數據）、TK_Link（Tokenomics 快照）、Inputs（v0.5 Assumed 項目遷入）。P2：Demand（需求與 token 量）、Revenue（營收、Microsoft 分成、淨額）。算力、成本、融資於 P3–P5。
A5: Excel 為唯一計算引擎 | B5: 藍字＝輸入（Excel 擁有）；黑字＝公式；綠字＝跨頁連結。builder 只產生結構，重建時保留 Excel 內已改過的藍字。
A6: SRC_OAI | B6: 122 列；v0.5『已取得的原始訊息』逐筆遷入（Interested-party／Verified）。
A7: TK_Link | B7: Tokenomics v5.24（20261007_Tokenomics_v5.24.xlsx），master 提交 bdb0de7，讀取日 2026-10-07；62 個名稱有值、0 個待 Tokenomics 提供。
A8: Inputs | B8: 243 列；v0.5 Assumed／Analogy／Decision 項目（長表）。
A9: Map_v05 | B9: v0.5 JSON 849 個葉節點的去處。
A10: Demand | B10: P2 需求：訂閱各方案人數、每日任務數 × 每任務 token、API 任務數與計費 token；token 量（層級 × 付費／免費，具名範圍 DEM_Tok_*，供 P3）。
A11: Revenue | B11: P2 營收：API 單價路徑（2026 依價格事件時點天數加權）、訂閱、API、廣告、其他、總額、Microsoft 分成、淨額（具名範圍 REV_*）。
A12: Checks | B12: P1、P2 檢查；CHK_Errors 必須為 0。
A13: 一手／二手圖例 | B13: 『二手（含一手公告轉載）』＝媒體轉載公司公開公告；『二手（含一手轉載）』＝F2，媒體轉載外流財報或內部文件；兩者不合併。（同文見 SRC_OAI 頁首說明）
A14: 標記 | B14: Verified／Interested-party／Analogy／Assumed／Derived（Analogy、Assumed 一律附區間）。
A15: 分層 | B15: 公司財務原始數據→SRC_OAI；AI 技術與算力→TK_Link（取自 Tokenomics 名稱）；假設→Inputs。

Sheet SRC_OAI
A1: SRC_OAI — 第 0 層 Source：OpenAI 公司財務原始數據（營收、合約、現金、融資輪、算力規模）
A2: 只存已取得的原始訊息（非計算、非假設；V5）。藍字＝原始值，由本活頁簿擁有；格式比照 Tokenomics SRC_Demand。AI 技術與算力原始數據不在此登錄（取自 TK_Link）。
A3: 來源等級（1 一手已讀原文／2 二手已讀或轉載／3 待查核）、立場、立場說明、一手／二手：依 builder/source_rules.py 的機械規則由 CC 初評（欄 Y 標『CC 初評』；V10）；規則無法判定者填『未評』。本包不做新查核。 圖例：『二手（含一手公告轉載）』＝媒體轉載公司公開公告；『二手（含一手轉載）』＝媒體轉載外流財報或內部文件（F2）；兩者不合併。
A4: SRC_ID | B4: 指標 | C4: 數值 | D4: 低 | E4: 高 | F4: 單位 | G4: 口徑 | H4: 適用對象 | I4: 日期 | J4: 出處（v0.5 原文） | K4: 來源等級 | L4: 立場 | M4: 立場說明 | N4: 一手／二手 | O4: 狀態 | P4: 取代者 | Q4: v0.5 標記 | R4: 查核狀態（v0.5 chk） | S4: v0.5 路徑 | T4: 模型使用位置 | U4: 備註 | V4: 缺值（公式） | W4: 缺出處（公式） | X4: 區間順序異常（公式） | Y4: 四欄標註
A5: SRC_OAI_001 | B5: 營收：FY2024 | C5: 3.7 | F5: $B | G5: FY2024 認列營收 | H5: OpenAI | I5: — | J5: OpenAI 揭露經媒體報導；workbook OpenAI_Sim B5 | K5: 2 | L5: 利害關係方 | M5: 公司公告：誘因為宣傳成長與用戶規模 | N5: 二手（含一手公告轉載） | O5: Active | P5: — | Q5: Interested-party | R5: — | S5: tokenRevenue.actuals.revenue2024 | T5: P2 校準；P5 對帳 | V5: =IF(AND($O5="Active",$C5="",$D5="",$E5="",$F5<>"文字"),1,0) -> 0 | W5: =IF(AND($O5="Active",OR($J5="",$J5="—")),1,0) -> 0 | X5: =IF(AND(ISNUMBER($C5),ISNUMBER($D5),ISNUMBER($E5)),IF(AND($D5<=$C5,$C5<=$E5),0,1),0) -> 0 | Y5: CC 初評
A6: SRC_OAI_002 | B6: 營收：FY2025 | C6: 13.07 | F6: $B | G6: FY2025 認列營收（外流經查核財報） | H6: OpenAI | I6: 2026-06 | J6: Fortune/FT 2026-06 報導之 FY2025 認列營收（經查核數字外流） | K6: 2 | L6: 利害關係方 | M6: 管理層、內部文件或外流數據：誘因為募資與議價，傾向呈現成長與算力需求 | N6: 二手（含一手轉載） | O6: Active | P6: — | Q6: Interested-party | R6: — | S6: tokenRevenue.actuals.revenue2025 | T6: P2 校準；P5 對帳 | V6: =IF(AND($O6="Active",$C6="",$D6="",$E6="",$F6<>"文字"),1,0) -> 0 | W6: =IF(AND($O6="Active",OR($J6="",$J6="—")),1,0) -> 0 | X6: =IF(AND(ISNUMBER($C6),ISNUMBER($D6),ISNUMBER($E6)),IF(AND($D6<=$C6,$C6<=$E6),0,1),0) -> 0 | Y6: CC 初評
A7: SRC_OAI_003 | B7: 營業成本（cost of revenue）：FY2025 | C7: 7.5 | F7: $B | G7: 含推論；FY2025 | H7: OpenAI | I7: 2026-06 | J7: Fortune/FT 2026-06 報導之 FY2025 認列營收（經查核數字外流）（追溯自「同上」鏈：本列←『營收：FY2025』；原文：同上；cost of revenue 含推論） | K7: 2 | L7: 利害關係方 | M7: 管理層、內部文件或外流數據：誘因為募資與議價，傾向呈現成長與算力需求 | N7: 二手（含一手轉載） | O7: Active | P7: — | Q7: Interested-party | R7: — | S7: tokenRevenue.actuals.cogs2025 | T7: P4 對帳 | V7: =IF(AND($O7="Active",$C7="",$D7="",$E7="",$F7<>"文字"),1,0) -> 0 | W7: =IF(AND($O7="Active",OR($J7="",$J7="—")),1,0) -> 0 | X7: =IF(AND(ISNUMBER($C7),ISNUMBER($D7),ISNUMBER($E7)),IF(AND($D7<=$C7,$C7<=$E7),0,1),0) -> 0 | Y7: CC 初評
A8: SRC_OAI_004 | B8: 營收：2026 Q1 | C8: 5.7 | F8: $B | G8: 2026 Q1（股東文件） | H8: OpenAI | I8: 2026-06-16 | J8: The Information 2026-06-16（股東文件） | K8: 2 | L8: 利害關係方 | M8: 管理層、內部文件或外流數據：誘因為募資與議價，傾向呈現成長與算力需求 | N8: 二手 | O8: Active | P8: — | Q8: Interested-party | R8: — | S8: tokenRevenue.actuals.revenueQ1_2026 | T8: P2 對照（fy2026Independent 的組成） | V8: =IF(AND($O8="Active",$C8="",$D8="",$E8="",$F8<>"文字"),1,0) -> 0 | W8: =IF(AND($O8="Active",OR($J8="",$J8="—")),1,0) -> 0 | X8: =IF(AND(ISNUMBER($C8),ISNUMBER($D8),ISNUMBER($E8)),IF(AND($D8<=$C8,$C8<=$E8),0,1),0) -> 0 | Y8: CC 初評
A9: SRC_OAI_005 | B9: 營收：2026 Q2 | C9: 6.7 | F9: $B | G9: 2026 Q2（告知投資人） | H9: OpenAI | I9: 2026-08-18 | J9: WSJ 2026-08-18（告知投資人） | K9: 2 | L9: 利害關係方 | M9: 管理層、內部文件或外流數據：誘因為募資與議價，傾向呈現成長與算力需求 | N9: 二手 | O9: Active | P9: — | Q9: Interested-party | R9: — | S9: tokenRevenue.actuals.revenueQ2_2026 | T9: P2 對照 | V9: =IF(AND($O9="Active",$C9="",$D9="",$E9="",$F9<>"文字"),1,0) -> 0 | W9: =IF(AND($O9="Active",OR($J9="",$J9="—")),1,0) -> 0 | X9: =IF(AND(ISNUMBER($C9),ISNUMBER($D9),ISNUMBER($E9)),IF(AND($D9<=$C9,$C9<=$E9),0,1),0) -> 0 | Y9: CC 初評
A10: SRC_OAI_006 | B10: 年化營收（ARR）：2026-08 | C10: 40 | F10: $B | G10: ARR；2026 年 8 月 | H10: OpenAI | I10: 2026-08-13 | J10: Bloomberg 2026-08-13；CNBC 2026-08-14 證實 | K10: 2 | L10: 利害關係方 | M10: 未評 | N10: 二手 | O10: Active | P10: — | Q10: Interested-party | R10: — | S10: tokenRevenue.actuals.arrAug2026 | T10: P2 對照 | V10: =IF(AND($O10="Active",$C10="",$D10="",$E10="",$F10<>"文字"),1,0) -> 0 | W10: =IF(AND($O10="Active",OR($J10="",$J10="—")),1,0) -> 0 | X10: =IF(AND(ISNUMBER($C10),ISNUMBER($D10),ISNUMBER($E10)),IF(AND($D10<=$C10,$C10<=$E10),0,1),0) -> 0 | Y10: CC 初評
A11: SRC_OAI_007 | B11: 消費端營收占比：2026 年初 | C11: 0.6 | F11: 比例 | G11: 年初消費／企業 60／40；8 月企業已超過消費端 | H11: OpenAI | I11: 2026-08-14 | J11: CFO Friar 2026-08-14 投資人會議：年初 60/40，8 月企業已超過消費端（CNBC） | K11: 2 | L11: 利害關係方 | M11: 管理層、內部文件或外流數據：誘因為募資與議價，傾向呈現成長與算力需求 | N11: 二手 | O11: Active | P11: — | Q11: Interested-party | R11: — | S11: tokenRevenue.actuals.consumerShareStart2026 | T11: P2 對照 | V11: =IF(AND($O11="Active",$C11="",$D11="",$E11="",$F11<>"文字"),1,0) -> 0 | W11: =IF(AND($O11="Active",OR($J11="",$J11="—")),1,0) -> 0 | X11: =IF(AND(ISNUMBER($C11),ISNUMBER($D11),ISNUMBER($E11)),IF(AND($D11<=$C11,$C11<=$E11),0,1),0) -> 0 | Y11: CC 初評
A12: SRC_OAI_008 | B12: API 每分鐘處理 token：2025-10 | C12: 6 | F12: B tok/min | G12: API 每分鐘 token；DevDay 揭露 | H12: OpenAI | I12: 2025-10 | J12: Altman DevDay 2025-10；2026 年更新揭露檢索未得 | K12: 2 | L12: 利害關係方 | M12: 未評 | N12: 一手 | O12: Active | P12: — | Q12: Interested-party | R12: — | S12: tokenRevenue.actuals.apiTokensPerMinOct2025 | T12: P2 校準檢查 | U12: 2026 年更新揭露檢索未得（v0.5 註記） | V12: =IF(AND($O12="Active",$C12="",$D12="",$E12="",$F12<>"文字"),1,0) -> 0 | W12: =IF(AND($O12="Active",OR($J12="",$J12="—")),1,0) -> 0 | X12: =IF(AND(ISNUMBER($C12),ISNUMBER($D12),ISNUMBER($E12)),IF(AND($D12<=$C12,$C12<=$E12),0,1),0) -> 0 | Y12: CC 初評
A13: SRC_OAI_009 | B13: Microsoft 營收分成率 | C13: 0.2 | F13: 比例 | G13: OpenAI 付 Microsoft 之營收分成 | H13: Microsoft | I13: 2026-04-27 | J13: CNBC 2026-04-27 引述知情人士；VentureBeat 同 | K13: 2 | L13: 利害關係方 | M13: 交易對手公告或轉述：誘因為宣傳合約規模與客戶關係 | N13: 二手 | O13: Active | P13: — | Q13: Interested-party | R13: — | S13: tokenRevenue.msShare.rate | T13: P2 淨額 | V13: =IF(AND($O13="Active",$C13="",$D13="",$E13="",$F13<>"文字"),1,0) -> 0 | W13: =IF(AND($O13="Active",OR($J13="",$J13="—")),1,0) -> 0 | X13: =IF(AND(ISNUMBER($C13),ISNUMBER($D13),ISNUMBER($E13)),IF(AND($D13<=$C13,$C13<=$E13),0,1),0) -> 0 | Y13: CC 初評
A14: SRC_OAI_010 | B14: Microsoft 分成總額上限 | C14: 38 | F14: $B | G14: 分成累計上限 | H14: Microsoft | I14: 2026-05 | J14: The Information 2026-05（經 AI Magazine、GuruFocus 轉述） | K14: 2 | L14: 利害關係方 | M14: 交易對手公告或轉述：誘因為宣傳合約規模與客戶關係 | N14: 二手 | O14: Active | P14: — | Q14: Interested-party | R14: — | S14: tokenRevenue.msShare.capTotal | T14: P2 淨額 | V14: =IF(AND($O14="Active",$C14="",$D14="",$E14="",$F14<>"文字"),1,0) -> 0 | W14: =IF(AND($O14="Active",OR($J14="",$J14="—")),1,0) -> 0 | X14: =IF(AND(ISNUMBER($C14),ISNUMBER($D14),ISNUMBER($E14)),IF(AND($D14<=$C14,$C14<=$E14),0,1),0) -> 0 | Y14: CC 初評
A15: SRC_OAI_011 | B15: Microsoft 分成付款持續至 | C15: 2030 | F15: 年 | G15: 付款持續至該年；受總額上限 | H15: Microsoft | I15: 2026-04-27 | J15: OpenAI／Microsoft 2026-04-27 公告：付款持續至 2030，受總額上限 | K15: 2 | L15: 利害關係方 | M15: 合約雙方公告；OpenAI 有募資與算力規模訊號誘因，供應商有營收與股價訊號誘因；金額為承諾總額，非實付 | N15: 一手 | O15: Active | P15: — | Q15: Verified | R15: — | S15: tokenRevenue.msShare.capThroughYear | T15: P2 淨額 | V15: =IF(AND($O15="Active",$C15="",$D15="",$E15="",$F15<>"文字"),1,0) -> 0 | W15: =IF(AND($O15="Active",OR($J15="",$J15="—")),1,0) -> 0 | X15: =IF(AND(ISNUMBER($C15),ISNUMBER($D15),ISNUMBER($E15)),IF(AND($D15<=$C15,$C15<=$E15),0,1),0) -> 0 | Y15: CC 初評
A16: SRC_OAI_012 | B16: Microsoft 對 OpenAI 的分潤（2026-04 後） | C16: 0 | F16: $B | G16: 2026-04-27 起 Microsoft 不再支付 OpenAI 分潤 | H16: Microsoft | I16: 2026-04-27 | J16: 2026-04-27 公告：Microsoft 不再支付 OpenAI 分潤 | K16: 2 | L16: 利害關係方 | M16: 合約雙方公告；OpenAI 有募資與算力規模訊號誘因，供應商有營收與股價訊號誘因；金額為承諾總額，非實付 | N16: 一手 | O16: Active | P16: — | Q16: Verified | R16: — | S16: tokenRevenue.msShare.azureInflowAfterApr2026 | T16: P2 淨額 | V16: =IF(AND($O16="Active",$C16="",$D16="",$E16="",$F16<>"文字"),1,0) -> 0 | W16: =IF(AND($O16="Active",OR($J16="",$J16="—")),1,0) -> 0 | X16: =IF(AND(ISNUMBER($C16),ISNUMBER($D16),ISNUMBER($E16)),IF(AND($D16<=$C16,$C16<=$E16),0,1),0) -> 0 | Y16: CC 初評
A17: SRC_OAI_013 | B17: API 牌價：top 層 輸入 | C17: 10 | F17: $/M tokens | G17: 短上下文 Standard；層級＝gpt-6-astra | H17: OpenAI | I17: 2026-09-25 | J17: developers.openai.com/api/docs/pricing（短上下文 Standard） | K17: 2 | L17: 利害關係方 | M17: 公開且具約束力的報價，誤報誘因低 | N17: 一手 | O17: Active | P17: — | Q17: Verified | R17: — | S17: tokenRevenue.api.listPriceSnapshot | T17: P2 單價路徑起點 | V17: =IF(AND($O17="Active",$C17="",$D17="",$E17="",$F17<>"文字"),1,0) -> 0 | W17: =IF(AND($O17="Active",OR($J17="",$J17="—")),1,0) -> 0 | X17: =IF(AND(ISNUMBER($C17),ISNUMBER($D17),ISNUMBER($E17)),IF(AND($D17<=$C17,$C17<=$E17),0,1),0) -> 0 | Y17: CC 初評
A18: SRC_OAI_014 | B18: API 牌價：top 層 快取輸入 | C18: 1 | F18: $/M tokens | G18: 短上下文 Standard；層級＝gpt-6-astra | H18: OpenAI | I18: 2026-09-25 | J18: developers.openai.com/api/docs/pricing（短上下文 Standard） | K18: 2 | L18: 利害關係方 | M18: 公開且具約束力的報價，誤報誘因低 | N18: 一手 | O18: Active | P18: — | Q18: Verified | R18: — | S18: tokenRevenue.api.listPriceSnapshot | T18: P2 單價路徑起點 | V18: =IF(AND($O18="Active",$C18="",$D18="",$E18="",$F18<>"文字"),1,0) -> 0 | W18: =IF(AND($O18="Active",OR($J18="",$J18="—")),1,0) -> 0 | X18: =IF(AND(ISNUMBER($C18),ISNUMBER($D18),ISNUMBER($E18)),IF(AND($D18<=$C18,$C18<=$E18),0,1),0) -> 0 | Y18: CC 初評
A19: SRC_OAI_015 | B19: API 牌價：top 層 輸出 | C19: 50 | F19: $/M tokens | G19: 短上下文 Standard；層級＝gpt-6-astra | H19: OpenAI | I19: 2026-09-25 | J19: developers.openai.com/api/docs/pricing（短上下文 Standard） | K19: 2 | L19: 利害關係方 | M19: 公開且具約束力的報價，誤報誘因低 | N19: 一手 | O19: Active | P19: — | Q19: Verified | R19: — | S19: tokenRevenue.api.listPriceSnapshot | T19: P2 單價路徑起點 | V19: =IF(AND($O19="Active",$C19="",$D19="",$E19="",$F19<>"文字"),1,0) -> 0 | W19: =IF(AND($O19="Active",OR($J19="",$J19="—")),1,0) -> 0 | X19: =IF(AND(ISNUMBER($C19),ISNUMBER($D19),ISNUMBER($E19)),IF(AND($D19<=$C19,$C19<=$E19),0,1),0) -> 0 | Y19: CC 初評
A20: SRC_OAI_016 | B20: API 牌價：mid 層 輸入 | C20: 2 | F20: $/M tokens | G20: 短上下文 Standard；層級＝gpt-6-sol | H20: OpenAI | I20: 2026-09-25 | J20: developers.openai.com/api/docs/pricing（短上下文 Standard） | K20: 2 | L20: 利害關係方 | M20: 公開且具約束力的報價，誤報誘因低 | N20: 一手 | O20: Active | P20: — | Q20: Verified | R20: — | S20: tokenRevenue.api.listPriceSnapshot | T20: P2 單價路徑起點 | V20: =IF(AND($O20="Active",$C20="",$D20="",$E20="",$F20<>"文字"),1,0) -> 0 | W20: =IF(AND($O20="Active",OR($J20="",$J20="—")),1,0) -> 0 | X20: =IF(AND(ISNUMBER($C20),ISNUMBER($D20),ISNUMBER($E20)),IF(AND($D20<=$C20,$C20<=$E20),0,1),0) -> 0 | Y20: CC 初評
A21: SRC_OAI_017 | B21: API 牌價：mid 層 快取輸入 | C21: 0.2 | F21: $/M tokens | G21: 短上下文 Standard；層級＝gpt-6-sol | H21: OpenAI | I21: 2026-09-25 | J21: developers.openai.com/api/docs/pricing（短上下文 Standard） | K21: 2 | L21: 利害關係方 | M21: 公開且具約束力的報價，誤報誘因低 | N21: 一手 | O21: Active | P21: — | Q21: Verified | R21: — | S21: tokenRevenue.api.listPriceSnapshot | T21: P2 單價路徑起點 | V21: =IF(AND($O21="Active",$C21="",$D21="",$E21="",$F21<>"文字"),1,0) -> 0 | W21: =IF(AND($O21="Active",OR($J21="",$J21="—")),1,0) -> 0 | X21: =IF(AND(ISNUMBER($C21),ISNUMBER($D21),ISNUMBER($E21)),IF(AND($D21<=$C21,$C21<=$E21),0,1),0) -> 0 | Y21: CC 初評
A22: SRC_OAI_018 | B22: API 牌價：mid 層 輸出 | C22: 10 | F22: $/M tokens | G22: 短上下文 Standard；層級＝gpt-6-sol | H22: OpenAI | I22: 2026-09-25 | J22: developers.openai.com/api/docs/pricing（短上下文 Standard） | K22: 2 | L22: 利害關係方 | M22: 公開且具約束力的報價，誤報誘因低 | N22: 一手 | O22: Active | P22: — | Q22: Verified | R22: — | S22: tokenRevenue.api.listPriceSnapshot | T22: P2 單價路徑起點 | V22: =IF(AND($O22="Active",$C22="",$D22="",$E22="",$F22<>"文字"),1,0) -> 0 | W22: =IF(AND($O22="Active",OR($J22="",$J22="—")),1,0) -> 0 | X22: =IF(AND(ISNUMBER($C22),ISNUMBER($D22),ISNUMBER($E22)),IF(AND($D22<=$C22,$C22<=$E22),0,1),0) -> 0 | Y22: CC 初評
A23: SRC_OAI_019 | B23: API 牌價：low 層 輸入 | C23: 0.1 | F23: $/M tokens | G23: 短上下文 Standard；層級＝gpt-6-luna | H23: OpenAI | I23: 2026-09-25 | J23: developers.openai.com/api/docs/pricing（短上下文 Standard） | K23: 2 | L23: 利害關係方 | M23: 公開且具約束力的報價，誤報誘因低 | N23: 一手 | O23: Active | P23: — | Q23: Verified | R23: — | S23: tokenRevenue.api.listPriceSnapshot | T23: P2 單價路徑起點 | V23: =IF(AND($O23="Active",$C23="",$D23="",$E23="",$F23<>"文字"),1,0) -> 0 | W23: =IF(AND($O23="Active",OR($J23="",$J23="—")),1,0) -> 0 | X23: =IF(AND(ISNUMBER($C23),ISNUMBER($D23),ISNUMBER($E23)),IF(AND($D23<=$C23,$C23<=$E23),0,1),0) -> 0 | Y23: CC 初評
A24: SRC_OAI_020 | B24: API 牌價：low 層 快取輸入 | C24: 0.01 | F24: $/M tokens | G24: 短上下文 Standard；層級＝gpt-6-luna | H24: OpenAI | I24: 2026-09-25 | J24: developers.openai.com/api/docs/pricing（短上下文 Standard） | K24: 2 | L24: 利害關係方 | M24: 公開且具約束力的報價，誤報誘因低 | N24: 一手 | O24: Active | P24: — | Q24: Verified | R24: — | S24: tokenRevenue.api.listPriceSnapshot | T24: P2 單價路徑起點 | V24: =IF(AND($O24="Active",$C24="",$D24="",$E24="",$F24<>"文字"),1,0) -> 0 | W24: =IF(AND($O24="Active",OR($J24="",$J24="—")),1,0) -> 0 | X24: =IF(AND(ISNUMBER($C24),ISNUMBER($D24),ISNUMBER($E24)),IF(AND($D24<=$C24,$C24<=$E24),0,1),0) -> 0 | Y24: CC 初評
A25: SRC_OAI_021 | B25: API 牌價：low 層 輸出 | C25: 0.5 | F25: $/M tokens | G25: 短上下文 Standard；層級＝gpt-6-luna | H25: OpenAI | I25: 2026-09-25 | J25: developers.openai.com/api/docs/pricing（短上下文 Standard） | K25: 2 | L25: 利害關係方 | M25: 公開且具約束力的報價，誤報誘因低 | N25: 一手 | O25: Active | P25: — | Q25: Verified | R25: — | S25: tokenRevenue.api.listPriceSnapshot | T25: P2 單價路徑起點 | V25: =IF(AND($O25="Active",$C25="",$D25="",$E25="",$F25<>"文字"),1,0) -> 0 | W25: =IF(AND($O25="Active",OR($J25="",$J25="—")),1,0) -> 0 | X25: =IF(AND(ISNUMBER($C25),ISNUMBER($D25),ISNUMBER($E25)),IF(AND($D25<=$C25,$C25<=$E25),0,1),0) -> 0 | Y25: CC 初評
A26: SRC_OAI_022 | B26: API 層級對應：top | C26: gpt-6-astra | F26: 文字 | G26: 2026-09 各層級的旗艦型號 | H26: OpenAI | I26: 2026-09-25 | J26: OpenAI 價格頁 developers.openai.com/api/docs/pricing（2026-09-25） | K26: 2 | L26: 利害關係方 | M26: 公開且具約束力的報價，誤報誘因低 | N26: 一手 | O26: Active | P26: — | Q26: Verified | R26: — | S26: tokenRevenue.api.tierMapSep2026.top | T26: P2 層級對照 | U26: E8b：文字列，只作標籤（Verified） | V26: =IF(AND($O26="Active",$C26="",$D26="",$E26="",$F26<>"文字"),1,0) -> 0 | W26: =IF(AND($O26="Active",OR($J26="",$J26="—")),1,0) -> 0 | X26: =IF(AND(ISNUMBER($C26),ISNUMBER($D26),ISNUMBER($E26)),IF(AND($D26<=$C26,$C26<=$E26),0,1),0) -> 0 | Y26: CC 初評
A27: SRC_OAI_023 | B27: API 層級對應：mid | C27: gpt-6-sol | F27: 文字 | G27: 2026-09 各層級的旗艦型號 | H27: OpenAI | I27: 2026-09-25 | J27: OpenAI 價格頁 developers.openai.com/api/docs/pricing（2026-09-25） | K27: 2 | L27: 利害關係方 | M27: 公開且具約束力的報價，誤報誘因低 | N27: 一手 | O27: Active | P27: — | Q27: Verified | R27: — | S27: tokenRevenue.api.tierMapSep2026.mid | T27: P2 層級對照 | U27: E8b：文字列，只作標籤（Verified） | V27: =IF(AND($O27="Active",$C27="",$D27="",$E27="",$F27<>"文字"),1,0) -> 0 | W27: =IF(AND($O27="Active",OR($J27="",$J27="—")),1,0) -> 0 | X27: =IF(AND(ISNUMBER($C27),ISNUMBER($D27),ISNUMBER($E27)),IF(AND($D27<=$C27,$C27<=$E27),0,1),0) -> 0 | Y27: CC 初評
A28: SRC_OAI_024 | B28: API 層級對應：low | C28: gpt-6-luna | F28: 文字 | G28: 2026-09 各層級的旗艦型號 | H28: OpenAI | I28: 2026-09-25 | J28: OpenAI 價格頁 developers.openai.com/api/docs/pricing（2026-09-25） | K28: 2 | L28: 利害關係方 | M28: 公開且具約束力的報價，誤報誘因低 | N28: 一手 | O28: Active | P28: — | Q28: Verified | R28: — | S28: tokenRevenue.api.tierMapSep2026.low | T28: P2 層級對照 | U28: E8b：文字列，只作標籤（Verified） | V28: =IF(AND($O28="Active",$C28="",$D28="",$E28="",$F28<>"文字"),1,0) -> 0 | W28: =IF(AND($O28="Active",OR($J28="",$J28="—")),1,0) -> 0 | X28: =IF(AND(ISNUMBER($C28),ISNUMBER($D28),ISNUMBER($E28)),IF(AND($D28<=$C28,$C28<=$E28),0,1),0) -> 0 | Y28: CC 初評
A29: SRC_OAI_025 | B29: API 價格事件 1 | C29: 07-09 GPT-5.6 Sol 5/30、Terra 2.5/15、Luna 1/6 | F29: 文字 | G29: 價格事件（輸入／輸出 $/M） | H29: OpenAI | I29: 2026-07-09 | J29: openai.com 2026-07-30 GPT-5.6 降價公告；GPT-6 Sol/Luna 2026-09-22 發布（Techzine、MarkTechPost）；GPT-6 Astra 2026-09-03 | K29: 2 | L29: 利害關係方 | M29: 公開且具約束力的報價，誤報誘因低 | N29: 一手 | O29: Active | P29: — | Q29: Verified | R29: — | S29: tokenRevenue.api.priceEvents2026 | T29: P2 FY 平均牌價（2026）的月加權依據 | V29: =IF(AND($O29="Active",$C29="",$D29="",$E29="",$F29<>"文字"),1,0) -> 0 | W29: =IF(AND($O29="Active",OR($J29="",$J29="—")),1,0) -> 0 | X29: =IF(AND(ISNUMBER($C29),ISNUMBER($D29),ISNUMBER($E29)),IF(AND($D29<=$C29,$C29<=$E29),0,1),0) -> 0 | Y29: CC 初評
A30: SRC_OAI_026 | B30: API 價格事件 2 | C30: 07-30 Terra 2/12（-20%）、Luna 0.2/1.2（-80%） | F30: 文字 | G30: 價格事件（輸入／輸出 $/M） | H30: OpenAI | I30: 2026-07-30 | J30: openai.com 2026-07-30 GPT-5.6 降價公告；GPT-6 Sol/Luna 2026-09-22 發布（Techzine、MarkTechPost）；GPT-6 Astra 2026-09-03 | K30: 2 | L30: 利害關係方 | M30: 公開且具約束力的報價，誤報誘因低 | N30: 一手 | O30: Active | P30: — | Q30: Verified | R30: — | S30: tokenRevenue.api.priceEvents2026 | T30: P2 FY 平均牌價（2026）的月加權依據 | V30: =IF(AND($O30="Active",$C30="",$D30="",$E30="",$F30<>"文字"),1,0) -> 0 | W30: =IF(AND($O30="Active",OR($J30="",$J30="—")),1,0) -> 0 | X30: =IF(AND(ISNUMBER($C30),ISNUMBER($D30),ISNUMBER($E30)),IF(AND($D30<=$C30,$C30<=$E30),0,1),0) -> 0 | Y30: CC 初評
A31: SRC_OAI_027 | B31: API 價格事件 3 | C31: 08-22 Sol 促銷 4/20 | F31: 文字 | G31: 價格事件（輸入／輸出 $/M） | H31: OpenAI | I31: 2026-08-22 | J31: openai.com 2026-07-30 GPT-5.6 降價公告；GPT-6 Sol/Luna 2026-09-22 發布（Techzine、MarkTechPost）；GPT-6 Astra 2026-09-03 | K31: 2 | L31: 利害關係方 | M31: 公開且具約束力的報價，誤報誘因低 | N31: 一手 | O31: Active | P31: — | Q31: Verified | R31: — | S31: tokenRevenue.api.priceEvents2026 | T31: P2 FY 平均牌價（2026）的月加權依據 | V31: =IF(AND($O31="Active",$C31="",$D31="",$E31="",$F31<>"文字"),1,0) -> 0 | W31: =IF(AND($O31="Active",OR($J31="",$J31="—")),1,0) -> 0 | X31: =IF(AND(ISNUMBER($C31),ISNUMBER($D31),ISNUMBER($E31)),IF(AND($D31<=$C31,$C31<=$E31),0,1),0) -> 0 | Y31: CC 初評
A32: SRC_OAI_028 | B32: API 價格事件 4 | C32: 09-03 GPT-6 Astra 10/50（新旗艦，層級價格上升） | F32: 文字 | G32: 價格事件（輸入／輸出 $/M） | H32: OpenAI | I32: 2026-09-03 | J32: openai.com 2026-07-30 GPT-5.6 降價公告；GPT-6 Sol/Luna 2026-09-22 發布（Techzine、MarkTechPost）；GPT-6 Astra 2026-09-03 | K32: 2 | L32: 利害關係方 | M32: 公開且具約束力的報價，誤報誘因低 | N32: 一手 | O32: Active | P32: — | Q32: Verified | R32: — | S32: tokenRevenue.api.priceEvents2026 | T32: P2 FY 平均牌價（2026）的月加權依據 | V32: =IF(AND($O32="Active",$C32="",$D32="",$E32="",$F32<>"文字"),1,0) -> 0 | W32: =IF(AND($O32="Active",OR($J32="",$J32="—")),1,0) -> 0 | X32: =IF(AND(ISNUMBER($C32),ISNUMBER($D32),ISNUMBER($E32)),IF(AND($D32<=$C32,$C32<=$E32),0,1),0) -> 0 | Y32: CC 初評
A33: SRC_OAI_029 | B33: API 價格事件 5 | C33: 09-22 GPT-6 Sol 2/10、Luna 0.1/0.5 | F33: 文字 | G33: 價格事件（輸入／輸出 $/M） | H33: OpenAI | I33: 2026-09-22 | J33: openai.com 2026-07-30 GPT-5.6 降價公告；GPT-6 Sol/Luna 2026-09-22 發布（Techzine、MarkTechPost）；GPT-6 Astra 2026-09-03 | K33: 2 | L33: 利害關係方 | M33: 公開且具約束力的報價，誤報誘因低 | N33: 一手 | O33: Active | P33: — | Q33: Verified | R33: — | S33: tokenRevenue.api.priceEvents2026 | T33: P2 FY 平均牌價（2026）的月加權依據 | V33: =IF(AND($O33="Active",$C33="",$D33="",$E33="",$F33<>"文字"),1,0) -> 0 | W33: =IF(AND($O33="Active",OR($J33="",$J33="—")),1,0) -> 0 | X33: =IF(AND(ISNUMBER($C33),ISNUMBER($D33),ISNUMBER($E33)),IF(AND($D33<=$C33,$C33<=$E33),0,1),0) -> 0 | Y33: CC 初評
A34: SRC_OAI_030 | B34: 快取輸入價占輸入價比 | C34: 0.1 | F34: 比例 | G34: 定價頁：cached input＝輸入價 10% | H34: OpenAI | I34: 2026-09 | J34: 定價頁：cached input = 輸入價 10% | K34: 2 | L34: 利害關係方 | M34: 公開且具約束力的報價，誤報誘因低 | N34: 一手 | O34: Active | P34: — | Q34: Verified | R34: — | S34: tokenRevenue.api.cachedInputRatio | T34: P2 | V34: =IF(AND($O34="Active",$C34="",$D34="",$E34="",$F34<>"文字"),1,0) -> 0 | W34: =IF(AND($O34="Active",OR($J34="",$J34="—")),1,0) -> 0 | X34: =IF(AND(ISNUMBER($C34),ISNUMBER($D34),ISNUMBER($E34)),IF(AND($D34<=$C34,$C34<=$E34),0,1),0) -> 0 | Y34: CC 初評
A35: SRC_OAI_031 | B35: 訂閱牌價：Go | C35: 8 | F35: $/月 | G35: ChatGPT 定價頁；美國牌價 | H35: OpenAI | I35: 2026-09 | J35: ChatGPT 定價頁（多家 2026-09 核對）；Enterprise 為議價 | K35: 2 | L35: 利害關係方 | M35: 公開且具約束力的報價，誤報誘因低 | N35: 一手 | O35: Active | P35: — | Q35: Verified | R35: — | S35: tokenRevenue.subscription.listPriceSep2026 | T35: P2 ARPU 上限參照 | V35: =IF(AND($O35="Active",$C35="",$D35="",$E35="",$F35<>"文字"),1,0) -> 0 | W35: =IF(AND($O35="Active",OR($J35="",$J35="—")),1,0) -> 0 | X35: =IF(AND(ISNUMBER($C35),ISNUMBER($D35),ISNUMBER($E35)),IF(AND($D35<=$C35,$C35<=$E35),0,1),0) -> 0 | Y35: CC 初評
A36: SRC_OAI_032 | B36: 訂閱牌價：Plus | C36: 20 | F36: $/月 | G36: ChatGPT 定價頁；美國牌價 | H36: OpenAI | I36: 2026-09 | J36: ChatGPT 定價頁（多家 2026-09 核對）；Enterprise 為議價 | K36: 2 | L36: 利害關係方 | M36: 公開且具約束力的報價，誤報誘因低 | N36: 一手 | O36: Active | P36: — | Q36: Verified | R36: — | S36: tokenRevenue.subscription.listPriceSep2026 | T36: P2 | V36: =IF(AND($O36="Active",$C36="",$D36="",$E36="",$F36<>"文字"),1,0) -> 0 | W36: =IF(AND($O36="Active",OR($J36="",$J36="—")),1,0) -> 0 | X36: =IF(AND(ISNUMBER($C36),ISNUMBER($D36),ISNUMBER($E36)),IF(AND($D36<=$C36,$C36<=$E36),0,1),0) -> 0 | Y36: CC 初評
A37: SRC_OAI_033 | B37: 訂閱牌價：Pro（低檔） | C37: 100 | F37: $/月 | G37: 2026 起 Pro 兩檔之一 | H37: OpenAI | I37: 2026-09 | J37: ChatGPT 定價頁（多家 2026-09 核對）；Enterprise 為議價 | K37: 2 | L37: 利害關係方 | M37: 公開且具約束力的報價，誤報誘因低 | N37: 一手 | O37: Active | P37: — | Q37: Verified | R37: — | S37: tokenRevenue.subscription.listPriceSep2026 | T37: P2 | V37: =IF(AND($O37="Active",$C37="",$D37="",$E37="",$F37<>"文字"),1,0) -> 0 | W37: =IF(AND($O37="Active",OR($J37="",$J37="—")),1,0) -> 0 | X37: =IF(AND(ISNUMBER($C37),ISNUMBER($D37),ISNUMBER($E37)),IF(AND($D37<=$C37,$C37<=$E37),0,1),0) -> 0 | Y37: CC 初評
A38: SRC_OAI_034 | B38: 訂閱牌價：Pro（高檔） | C38: 200 | F38: $/月 | G38: 2026 起 Pro 兩檔之一 | H38: OpenAI | I38: 2026-09 | J38: ChatGPT 定價頁（多家 2026-09 核對）；Enterprise 為議價 | K38: 2 | L38: 利害關係方 | M38: 公開且具約束力的報價，誤報誘因低 | N38: 一手 | O38: Active | P38: — | Q38: Verified | R38: — | S38: tokenRevenue.subscription.listPriceSep2026 | T38: P2 | V38: =IF(AND($O38="Active",$C38="",$D38="",$E38="",$F38<>"文字"),1,0) -> 0 | W38: =IF(AND($O38="Active",OR($J38="",$J38="—")),1,0) -> 0 | X38: =IF(AND(ISNUMBER($C38),ISNUMBER($D38),ISNUMBER($E38)),IF(AND($D38<=$C38,$C38<=$E38),0,1),0) -> 0 | Y38: CC 初評
A39: SRC_OAI_035 | B39: 訂閱牌價：Business 每席 | D39: 20 | E39: 25 | F39: $/席/月 | G39: Business 席位區間；Enterprise 為議價 | H39: OpenAI | I39: 2026-09 | J39: ChatGPT 定價頁（多家 2026-09 核對）；Enterprise 為議價 | K39: 2 | L39: 利害關係方 | M39: 公開且具約束力的報價，誤報誘因低 | N39: 一手 | O39: Active | P39: — | Q39: Verified | R39: — | S39: tokenRevenue.subscription.listPriceSep2026 | T39: P2 | V39: =IF(AND($O39="Active",$C39="",$D39="",$E39="",$F39<>"文字"),1,0) -> 0 | W39: =IF(AND($O39="Active",OR($J39="",$J39="—")),1,0) -> 0 | X39: =IF(AND(ISNUMBER($C39),ISNUMBER($D39),ISNUMBER($E39)),IF(AND($D39<=$C39,$C39<=$E39),0,1),0) -> 0 | Y39: CC 初評
A40: SRC_OAI_036 | B40: 公司 2026 計畫：Go 用戶數 | C40: 112 | F40: M | G40: 年初內部預測 | H40: OpenAI | I40: 2026-04-28 | J40: The Information 2026-04-28（年初內部預測） | K40: 3 | L40: 利害關係方 | M40: 管理層、內部文件或外流數據：誘因為募資與議價，傾向呈現成長與算力需求 | N40: 二手 | O40: Active | P40: — | Q40: Interested-party | R40: 待查核-報導 | S40: tokenRevenue.subscription.migration.planGo2026 | T40: P2 T4 遷移幅度 | V40: =IF(AND($O40="Active",$C40="",$D40="",$E40="",$F40<>"文字"),1,0) -> 0 | W40: =IF(AND($O40="Active",OR($J40="",$J40="—")),1,0) -> 0 | X40: =IF(AND(ISNUMBER($C40),ISNUMBER($D40),ISNUMBER($E40)),IF(AND($D40<=$C40,$C40<=$E40),0,1),0) -> 0 | Y40: CC 初評
...

Sheet TK_Link
A1: TK_Link — Tokenomics 快照（第 0 層連結；不用 Excel 外部連結）
A2: 每列一個 Tokenomics 名稱（SRC_／IF_／L1_）。值（藍字）由 builder 從 Tokenomics master 的 model/CURRENT 讀出寫入；本模型公式只引用 TK_ 具名範圍。更新快照＝本模型的修補版。
A3: Tokenomics 檔案 | B3: 20261007_Tokenomics_v5.24.xlsx
A4: Tokenomics 版本 | B4: v5.24
A5: Tokenomics 提交 SHA（master） | B5: bdb0de7c0d94620591d665efa43856193f23fbba
A6: 讀取日期 | B6: 2026-10-07
I7: 世代 | J7: Hopper H100 | K7: Hopper H100 | L7: Hopper H100 | M7: GB200 NVL72 | N7: GB200 NVL72 | O7: GB200 NVL72 | P7: GB300 NVL72 | Q7: GB300 NVL72 | R7: GB300 NVL72 | S7: VR200 NVL72 | T7: VR200 NVL72 | U7: VR200 NVL72 | V7: Rubin Ultra（MGX NVL 單架，72 GPU） | W7: Rubin Ultra（MGX NVL 單架，72 GPU） | X7: Rubin Ultra（MGX NVL 單架，72 GPU）
I8: 成本情境 | J8: 低成本 | K8: 基準 | L8: 高成本 | M8: 低成本 | N8: 基準 | O8: 高成本 | P8: 低成本 | Q8: 基準 | R8: 高成本 | S8: 低成本 | T8: 基準 | U8: 高成本 | V8: 低成本 | W8: 基準 | X8: 高成本
A9: Tokenomics 名稱 | B9: 本模型名稱 | C9: 說明 | D9: 單位 | E9: 欄數 | F9: 狀態 | G9: Tokenomics 版本 | H9: 提交 SHA | I9: 讀取日期 | J9: 值1 | K9: 值2 | L9: 值3 | M9: 值4 | N9: 值5 | O9: 值6 | P9: 值7 | Q9: 值8 | R9: 值9 | S9: 值10 | T9: 值11 | U9: 值12 | V9: 值13 | W9: 值14 | X9: 值15
A10: IF_TokGW_Astra | B10: TK_IF_TokGW_Astra | C10: 每 GW 總產出（100%） | D10: M tok/年 | E10: 15 | F10: OK | G10: v5.24 | H10: bdb0de7 | I10: 2026-10-07 | J10: 3.8765183e+09 | K10: 3.8765183e+09 | L10: 3.8765183e+09 | M10: 2.0041839e+10 | N10: 2.0041839e+10 | O10: 2.0041839e+10 | P10: 2.4234238e+10 | Q10: 2.4234238e+10 | R10: 2.4234238e+10 | S10: 5.1167891e+10 | T10: 5.1167891e+10 | U10: 5.1167891e+10 | V10: 7.4400956e+10 | W10: 7.4400956e+10 | X10: 7.4400956e+10
A11: IF_TokGW_Luna | B11: TK_IF_TokGW_Luna | C11: 每 GW 總產出（100%） | D11: M tok/年 | E11: 15 | F11: OK | G11: v5.24 | H11: bdb0de7 | I11: 2026-10-07 | J11: 7.4067251e+10 | K11: 7.4067251e+10 | L11: 7.4067251e+10 | M11: 3.6230689e+11 | N11: 3.6230689e+11 | O11: 3.6230689e+11 | P11: 5.2747392e+11 | Q11: 5.2747392e+11 | R11: 5.2747392e+11 | S11: 7.727784e+11 | T11: 7.727784e+11 | U11: 7.727784e+11 | V11: 1.0443737e+12 | W11: 1.0443737e+12 | X11: 1.0443737e+12
A12: IF_TokGW_Sol | B12: TK_IF_TokGW_Sol | C12: 每 GW 總產出（100%） | D12: M tok/年 | E12: 15 | F12: OK | G12: v5.24 | H12: bdb0de7 | I12: 2026-10-07 | J12: 2.149043e+10 | K12: 2.149043e+10 | L12: 2.149043e+10 | M12: 1.041254e+11 | N12: 1.041254e+11 | O12: 1.041254e+11 | P12: 1.5159367e+11 | Q12: 1.5159367e+11 | R12: 1.5159367e+11 | S12: 2.3728734e+11 | T12: 2.3728734e+11 | U12: 2.3728734e+11 | V12: 3.2618567e+11 | W12: 3.2618567e+11 | X12: 3.2618567e+11
A13: IF_Util | B13: TK_IF_Util | C13: 基準利用率（第 0 層；下游可覆寫） | D13: % | E13: 1 | F13: OK | G13: v5.24 | H13: bdb0de7 | I13: 2026-10-07 | J13: 0.6
A14: IF_HoldEcon | B14: TK_IF_HoldEcon | C14: 每 GW 年持有成本 — 經濟口徑 | D14: $B/年 | E14: 15 | F14: OK | G14: v5.24 | H14: bdb0de7 | I14: 2026-10-07 | J14: 7.0000433 | K14: 10.095795 | L14: 17.405972 | M14: 6.813167 | N14: 9.1709819 | O14: 14.920029 | P14: 8.7074708 | Q14: 12.724746 | R14: 23.871869 | S14: 9.8366806 | T14: 12.762016 | U14: 20.678089 | V14: 10.452242 | W14: 16.069457 | X14: 29.454615
A15: IF_FullCost_Astra | B15: TK_IF_FullCost_Astra | C15: 全成本 $/M（服務＋快取儲存＋自下而上攤提；基準利用率） | D15: $/M | E15: 15 | F15: OK | G15: v5.24 | H15: bdb0de7 | I15: 2026-10-07 | J15: 6.9823234 | K15: 10.07014 | L15: 17.361579 | M15: 0.92982466 | N15: 1.2515294 | O15: 2.0359402 | P15: 0.93305227 | Q15: 1.3634219 | R15: 2.5576103 | S15: 0.42538461 | T15: 0.55182355 | U15: 0.89397238 | V15: 0.27809403 | W15: 0.42742659 | X15: 0.78326839
A16: IF_FullCost_Luna | B16: TK_IF_FullCost_Luna | C16: 全成本 $/M（服務＋快取儲存＋自下而上攤提；基準利用率） | D16: $/M | E16: 15 | F16: OK | G16: v5.24 | H16: bdb0de7 | I16: 2026-10-07 | J16: 0.13332981 | K16: 0.19228981 | L16: 0.33151542 | M16: 0.02765365 | N16: 0.037219928 | O16: 0.060545328 | P16: 0.024207999 | Q16: 0.035371595 | R16: 0.066348304 | S16: 0.018368232 | T16: 0.023827547 | U16: 0.038600674 | V16: 0.014351218 | W16: 0.022057988 | X16: 0.04042231
A17: IF_FullCost_Sol | B17: TK_IF_FullCost_Sol | C17: 全成本 $/M（服務＋快取儲存＋自下而上攤提；基準利用率） | D17: $/M | E17: 15 | F17: OK | G17: v5.24 | H17: bdb0de7 | I17: 2026-10-07 | J17: 0.53191053 | K17: 0.76713986 | L17: 1.3226004 | M17: 0.10319199 | N17: 0.13889806 | O17: 0.22595995 | P17: 0.090371238 | Q17: 0.13205779 | R17: 0.2477295 | S17: 0.061571891 | T17: 0.079878216 | U17: 0.12941586 | V17: 0.046474526 | W17: 0.07144248 | X17: 0.13093816
A18: IF_PriceCached_Astra | B18: TK_IF_PriceCached_Astra | C18: 快取輸入 $/M — OpenAI 有效 | D18: $/M | E18: 1 | F18: OK | G18: v5.24 | H18: bdb0de7 | I18: 2026-10-07 | J18: 0.8
A19: IF_PriceCached_Luna | B19: TK_IF_PriceCached_Luna | C19: 快取輸入 $/M — OpenAI 有效 | D19: $/M | E19: 1 | F19: OK | G19: v5.24 | H19: bdb0de7 | I19: 2026-10-07 | J19: 0.008
A20: IF_PriceCached_Sol | B20: TK_IF_PriceCached_Sol | C20: 快取輸入 $/M — OpenAI 有效 | D20: $/M | E20: 1 | F20: OK | G20: v5.24 | H20: bdb0de7 | I20: 2026-10-07 | J20: 0.16
A21: IF_PriceFresh_Astra | B21: TK_IF_PriceFresh_Astra | C21: 新鮮輸入 $/M — OpenAI 有效 | D21: $/M | E21: 1 | F21: OK | G21: v5.24 | H21: bdb0de7 | I21: 2026-10-07 | J21: 8
A22: IF_PriceFresh_Luna | B22: TK_IF_PriceFresh_Luna | C22: 新鮮輸入 $/M — OpenAI 有效 | D22: $/M | E22: 1 | F22: OK | G22: v5.24 | H22: bdb0de7 | I22: 2026-10-07 | J22: 0.08
A23: IF_PriceFresh_Sol | B23: TK_IF_PriceFresh_Sol | C23: 新鮮輸入 $/M — OpenAI 有效 | D23: $/M | E23: 1 | F23: OK | G23: v5.24 | H23: bdb0de7 | I23: 2026-10-07 | J23: 1.6
A24: IF_PriceOut_Astra | B24: TK_IF_PriceOut_Astra | C24: 可見輸出 $/M — OpenAI 有效 | D24: $/M | E24: 1 | F24: OK | G24: v5.24 | H24: bdb0de7 | I24: 2026-10-07 | J24: 40
A25: IF_PriceOut_Luna | B25: TK_IF_PriceOut_Luna | C25: 可見輸出 $/M — OpenAI 有效 | D25: $/M | E25: 1 | F25: OK | G25: v5.24 | H25: bdb0de7 | I25: 2026-10-07 | J25: 0.4
A26: IF_PriceOut_Sol | B26: TK_IF_PriceOut_Sol | C26: 可見輸出 $/M — OpenAI 有效 | D26: $/M | E26: 1 | F26: OK | G26: v5.24 | H26: bdb0de7 | I26: 2026-10-07 | J26: 8
A27: IF_PriceRef_Astra | B27: TK_IF_PriceRef_Astra | C27: 參考請求混合 $/M — OpenAI 有效 | D27: $/M | E27: 1 | F27: OK | G27: v5.24 | H27: bdb0de7 | I27: 2026-10-07 | J27: 8.0355556
A28: IF_PriceRef_Luna | B28: TK_IF_PriceRef_Luna | C28: 參考請求混合 $/M — OpenAI 有效 | D28: $/M | E28: 1 | F28: OK | G28: v5.24 | H28: bdb0de7 | I28: 2026-10-07 | J28: 0.080355556
A29: IF_PriceRef_Sol | B29: TK_IF_PriceRef_Sol | C29: 參考請求混合 $/M — OpenAI 有效 | D29: $/M | E29: 1 | F29: OK | G29: v5.24 | H29: bdb0de7 | I29: 2026-10-07 | J29: 1.6071111
... A35: IF_FrontRef_Sol | B35: TK_IF_FrontRef_Sol | C35: 參考請求混合 $/M — 前緣有效 | D35: $/M | E35: 1 | F35: OK | G35: v5.24 | H35: bdb0de7 | I35: 2026-10-07 | J35: 1.6071111
A36: IF_ProgGWyr_Astra | B36: TK_IF_ProgGWyr_Astra | C36: 研發計畫占 1 GW 一年 | D36: % | E36: 15 | F36: OK | G36: v5.24 | H36: bdb0de7 | I36: 2026-10-07 | J36: 0.14267939 | K36: 0.14267939 | L36: 0.14267939 | M36: 0.07039759 | N36: 0.07039759 | O36: 0.07039759 | P36: 0.065586407 | Q36: 0.065586407 | R36: 0.065586407 | S36: 0.040017843 | T36: 0.040017843 | U36: 0.040017843 | V36: 0.027250415 | W36: 0.027250415 | X36: 0.027250415
A37: IF_ProgGWyr_Luna | B37: TK_IF_ProgGWyr_Luna | C37: 研發計畫占 1 GW 一年 | D37: % | E37: 15 | F37: OK | G37: v5.24 | H37: bdb0de7 | I37: 2026-10-07 | J37: 0.0081323583 | K37: 0.0081323583 | L37: 0.0081323583 | M37: 0.0037853004 | N37: 0.0037853004 | O37: 0.0037853004 | P37: 0.0033289655 | Q37: 0.0033289655 | R37: 0.0033289655 | S37: 0.0022043397 | T37: 0.0022043397 | U37: 0.0022043397 | V37: 0.0014304485 | W37: 0.0014304485 | X37: 0.0014304485
A38: IF_ProgGWyr_Sol | B38: TK_IF_ProgGWyr_Sol | C38: 研發計畫占 1 GW 一年 | D38: % | E38: 15 | F38: OK | G38: v5.24 | H38: bdb0de7 | I38: 2026-10-07 | J38: 0.023146292 | K38: 0.023146292 | L38: 0.023146292 | M38: 0.011197547 | N38: 0.011197547 | O38: 0.011197547 | P38: 0.010227304 | Q38: 0.010227304 | R38: 0.010227304 | S38: 0.006421121 | T38: 0.006421121 | U38: 0.006421121 | V38: 0.0043094856 | W38: 0.0043094856 | X38: 0.0043094856
A39: IF_RDMult | B39: TK_IF_RDMult | C39: 研發倍數（第 0 層基準；下游可覆寫） | D39: x | E39: 1 | F39: OK | G39: v5.24 | H39: bdb0de7 | I39: 2026-10-07 | J39: 8
A40: IF_TrainGenDefault | B40: TK_IF_TrainGenDefault | C40: 下游預設訓練世代（索引；J13） | D40: 索引 | E40: 1 | F40: OK | G40: v5.24 | H40: bdb0de7 | I40: 2026-10-07 | J40: 4
A41: SRC_DEM_004 | B41: TK_SRC_DEM_004 | C41: OpenAI 2025 推論支出（年度） | D41: $B | E41: 1 | F41: OK | G41: v5.24 | H41: bdb0de7 | I41: 2026-10-07 | J41: 8.4
A42: SRC_DEM_005 | B42: TK_SRC_DEM_005 | C42: OpenAI 2025 非付費用戶推論支出（年度） | D42: $B | E42: 1 | F42: OK | G42: v5.24 | H42: bdb0de7 | I42: 2026-10-07 | J42: 3.9
A43: SRC_DEM_006 | B43: TK_SRC_DEM_006 | C43: OpenAI 2025 訓練支出（年度；約值） | D43: $B | E43: 1 | F43: OK | G43: v5.24 | H43: bdb0de7 | I43: 2026-10-07 | J43: 12
A44: SRC_DEM_007 | B44: TK_SRC_DEM_007 | C44: OpenAI 2025 營收（年度） | D44: $B | E44: 1 | F44: OK | G44: v5.24 | H44: bdb0de7 | I44: 2026-10-07 | J44: 13.07
A45: SRC_DEM_008 | B45: TK_SRC_DEM_008 | C45: OpenAI 算力規模 2024 年底（GW 口徑未明（D1）） | D45: GW | E45: 1 | F45: OK | G45: v5.24 | H45: bdb0de7 | I45: 2026-10-07 | J45: 0.6
...

Sheet Inputs
A1: Inputs — 假設輸入（藍字）；v0.6-P1：只建表頭與 v0.5 Assumed／Analogy／Decision 項目的遷入
A2: 長表格式：一列一個（參數 × 索引）。標記沿用 v0.5；區間倍數（低／高情境倍數）另列。Analogy／Assumed 無區間者保留空白並於備註說明（不自行補值）。
A3: 屬 Tokenomics 領域的 v0.5 項目（rack、classes、serving、hwCostPerM、tokenomicsRef、genFactor.hopper／nextGen）不在此頁，見 Map_v05：『不遷入；改取 TK_Link』。
A4: INP_ID | B4: 參數 | C4: 索引 | D4: 單位 | E4: 值 | F4: 低 | G4: 高 | H4: 標記 | I4: v0.5 原決策 | J4: 狀態 | K4: v0.5 路徑 | L4: 備註 | M4: 區間順序異常（公式）
A5: INP_001 | B5: 基準年 | C5: — | D5: 年 | E5: 2025 | H5: Decision | I5: — | J5: v0.6 沿用 | K5: tokenRevenue.meta.baseYear | M5: =IF(AND(ISNUMBER($E5),ISNUMBER($F5),ISNUMBER($G5)),IF(AND($F5<=$E5,$E5<=$G5),0,1),0) -> 0
A6: INP_002 | B6: 校準年（第 1 個） | C6: — | D6: 年 | E6: 2025 | H6: Decision | I6: — | J6: v0.6 沿用 | K6: tokenRevenue.meta.calibrationYears.0 | L6: v0.5：2025、2026 為校準年；2026 為預測校準（見 demandGrowthExPrice 註記） | M6: =IF(AND(ISNUMBER($E6),ISNUMBER($F6),ISNUMBER($G6)),IF(AND($F6<=$E6,$E6<=$G6),0,1),0) -> 0
A7: INP_003 | B7: 校準年（第 2 個） | C7: — | D7: 年 | E7: 2026 | H7: Decision | I7: — | J7: v0.6 沿用 | K7: tokenRevenue.meta.calibrationYears.1 | M7: =IF(AND(ISNUMBER($E7),ISNUMBER($F7),ISNUMBER($G7)),IF(AND($F7<=$E7,$E7<=$G7),0,1),0) -> 0
A8: INP_004 | B8: 彈性起算年 | C8: — | D8: 年 | E8: 2027 | H8: Decision | I8: — | J8: v0.6 沿用 | K8: tokenRevenue.meta.elasticityFromYear | M8: =IF(AND(ISNUMBER($E8),ISNUMBER($F8),ISNUMBER($G8)),IF(AND($F8<=$E8,$E8<=$G8),0,1),0) -> 0
A9: INP_005 | B9: 模型年度 | C9: 第 1 年 | D9: 年 | E9: 2025 | H9: Decision | I9: D10→FY2030 | J9: v0.6 沿用 | K9: tokenRevenue.meta.years.0 | L9: 曆年制；2025 為實際校準年（工作單第 0 節） | M9: =IF(AND(ISNUMBER($E9),ISNUMBER($F9),ISNUMBER($G9)),IF(AND($F9<=$E9,$E9<=$G9),0,1),0) -> 0
A10: INP_006 | B10: 模型年度 | C10: 第 2 年 | D10: 年 | E10: 2026 | H10: Decision | I10: D10→FY2030 | J10: v0.6 沿用 | K10: tokenRevenue.meta.years.1 | L10: 曆年制；2025 為實際校準年（工作單第 0 節） | M10: =IF(AND(ISNUMBER($E10),ISNUMBER($F10),ISNUMBER($G10)),IF(AND($F10<=$E10,$E10<=$G10),0,1),0) -> 0
A11: INP_007 | B11: 模型年度 | C11: 第 3 年 | D11: 年 | E11: 2027 | H11: Decision | I11: D10→FY2030 | J11: v0.6 沿用 | K11: tokenRevenue.meta.years.2 | L11: 曆年制；2025 為實際校準年（工作單第 0 節） | M11: =IF(AND(ISNUMBER($E11),ISNUMBER($F11),ISNUMBER($G11)),IF(AND($F11<=$E11,$E11<=$G11),0,1),0) -> 0
A12: INP_008 | B12: 模型年度 | C12: 第 4 年 | D12: 年 | E12: 2028 | H12: Decision | I12: D10→FY2030 | J12: v0.6 沿用 | K12: tokenRevenue.meta.years.3 | L12: 曆年制；2025 為實際校準年（工作單第 0 節） | M12: =IF(AND(ISNUMBER($E12),ISNUMBER($F12),ISNUMBER($G12)),IF(AND($F12<=$E12,$E12<=$G12),0,1),0) -> 0
A13: INP_009 | B13: 模型年度 | C13: 第 5 年 | D13: 年 | E13: 2029 | H13: Decision | I13: D10→FY2030 | J13: v0.6 沿用 | K13: tokenRevenue.meta.years.4 | L13: 曆年制；2025 為實際校準年（工作單第 0 節） | M13: =IF(AND(ISNUMBER($E13),ISNUMBER($F13),ISNUMBER($G13)),IF(AND($F13<=$E13,$E13<=$G13),0,1),0) -> 0
A14: INP_010 | B14: 模型年度 | C14: 第 6 年 | D14: 年 | E14: 2030 | H14: Decision | I14: D10→FY2030 | J14: v0.6 沿用 | K14: tokenRevenue.meta.years.5 | L14: 曆年制；2025 為實際校準年（工作單第 0 節） | M14: =IF(AND(ISNUMBER($E14),ISNUMBER($F14),ISNUMBER($G14)),IF(AND($F14<=$E14,$E14<=$G14),0,1),0) -> 0
A15: INP_011 | B15: 分成上限起算年 | C15: — | D15: 年 | E15: 2026 | H15: Assumed | I15: N2a | J15: v0.6 沿用 | K15: tokenRevenue.msShare.capCountFromYear | L15: 起算點未揭露；Andy 2026-09-29 決定 N2a（v0.5 無區間，待 Project 補） | M15: =IF(AND(ISNUMBER($E15),ISNUMBER($F15),ISNUMBER($G15)),IF(AND($F15<=$E15,$E15<=$G15),0,1),0) -> 0
A16: INP_012 | B16: T4 遷移幅度（占公司計畫）— 低 | C16: — | D16: 比例 | E16: 0 | H16: Decision | I16: T4 | J16: v0.6 沿用 | K16: tokenRevenue.subscription.migration.planFraction | L16: 情境值：Plus→Go 遷移與 Go 額外新增的幅度比例 | M16: =IF(AND(ISNUMBER($E16),ISNUMBER($F16),ISNUMBER($G16)),IF(AND($F16<=$E16,$E16<=$G16),0,1),0) -> 0
A17: INP_013 | B17: T4 遷移幅度（占公司計畫）— 基準 | C17: — | D17: 比例 | E17: 0.3 | H17: Decision | I17: T4 | J17: v0.6 沿用 | K17: tokenRevenue.subscription.migration.planFraction | L17: Andy 2026-09-29 採預設 | M17: =IF(AND(ISNUMBER($E17),ISNUMBER($F17),ISNUMBER($G17)),IF(AND($F17<=$E17,$E17<=$G17),0,1),0) -> 0
A18: INP_014 | B18: T4 遷移幅度（占公司計畫）— 高 | C18: — | D18: 比例 | E18: 0.8 | H18: Decision | I18: T4 | J18: v0.6 沿用 | K18: tokenRevenue.subscription.migration.planFraction | M18: =IF(AND(ISNUMBER($E18),ISNUMBER($F18),ISNUMBER($G18)),IF(AND($F18<=$E18,$E18<=$G18),0,1),0) -> 0
A19: INP_015 | B19: FY 平均牌價（輸入）：top 層 | C19: 2025 | D19: $/M tokens | E19: 2.5 | F19: 1.5 | G19: 4 | H19: Analogy | I19: — | J19: v0.6 沿用 | K19: tokenRevenue.api.listPriceFYAvg.in.top | L19: 2025 為 Analogy（v0.5 標 Analogy/Derived 混合；2025 屬 Analogy） | M19: =IF(AND(ISNUMBER($E19),ISNUMBER($F19),ISNUMBER($G19)),IF(AND($F19<=$E19,$E19<=$G19),0,1),0) -> 0
A20: INP_016 | B20: FY 平均牌價（輸入）：mid 層 | C20: 2025 | D20: $/M tokens | E20: 1.5 | F20: 1 | G20: 2.5 | H20: Analogy | I20: — | J20: v0.6 沿用 | K20: tokenRevenue.api.listPriceFYAvg.in.mid | L20: 2025 為 Analogy（v0.5 標 Analogy/Derived 混合；2025 屬 Analogy） | M20: =IF(AND(ISNUMBER($E20),ISNUMBER($F20),ISNUMBER($G20)),IF(AND($F20<=$E20,$E20<=$G20),0,1),0) -> 0
A21: INP_017 | B21: FY 平均牌價（輸入）：low 層 | C21: 2025 | D21: $/M tokens | E21: 0.2 | F21: 0.1 | G21: 0.4 | H21: Analogy | I21: — | J21: v0.6 沿用 | K21: tokenRevenue.api.listPriceFYAvg.in.low | L21: 2025 為 Analogy（v0.5 標 Analogy/Derived 混合；2025 屬 Analogy） | M21: =IF(AND(ISNUMBER($E21),ISNUMBER($F21),ISNUMBER($G21)),IF(AND($F21<=$E21,$E21<=$G21),0,1),0) -> 0
A22: INP_018 | B22: FY 平均牌價（輸出）：top 層 | C22: 2025 | D22: $/M tokens | E22: 14 | F22: 8 | G22: 20 | H22: Analogy | I22: — | J22: v0.6 沿用 | K22: tokenRevenue.api.listPriceFYAvg.out.top | L22: 2025 為 Analogy（v0.5 標 Analogy/Derived 混合；2025 屬 Analogy） | M22: =IF(AND(ISNUMBER($E22),ISNUMBER($F22),ISNUMBER($G22)),IF(AND($F22<=$E22,$E22<=$G22),0,1),0) -> 0
A23: INP_019 | B23: FY 平均牌價（輸出）：mid 層 | C23: 2025 | D23: $/M tokens | E23: 8 | F23: 5 | G23: 10 | H23: Analogy | I23: — | J23: v0.6 沿用 | K23: tokenRevenue.api.listPriceFYAvg.out.mid | L23: 2025 為 Analogy（v0.5 標 Analogy/Derived 混合；2025 屬 Analogy） | M23: =IF(AND(ISNUMBER($E23),ISNUMBER($F23),ISNUMBER($G23)),IF(AND($F23<=$E23,$E23<=$G23),0,1),0) -> 0
A24: INP_020 | B24: FY 平均牌價（輸出）：low 層 | C24: 2025 | D24: $/M tokens | E24: 1 | F24: 0.5 | G24: 2 | H24: Analogy | I24: — | J24: v0.6 沿用 | K24: tokenRevenue.api.listPriceFYAvg.out.low | L24: 2025 為 Analogy（v0.5 標 Analogy/Derived 混合；2025 屬 Analogy） | M24: =IF(AND(ISNUMBER($E24),ISNUMBER($F24),ISNUMBER($G24)),IF(AND($F24<=$E24,$E24<=$G24),0,1),0) -> 0
A25: INP_021 | B25: 牌價年變動率：top 層 | C25: — | D25: 比例/年 | E25: -0.3 | F25: -0.45 | G25: -0.15 | H25: Assumed | I25: D11 | J25: v0.6 沿用 | K25: tokenRevenue.api.listPriceAnnualChange.top | L25: 2027 起每年；情境軸之一 | M25: =IF(AND(ISNUMBER($E25),ISNUMBER($F25),ISNUMBER($G25)),IF(AND($F25<=$E25,$E25<=$G25),0,1),0) -> 0
A26: INP_022 | B26: 牌價年變動率：mid 層 | C26: — | D26: 比例/年 | E26: -0.4 | F26: -0.6 | G26: -0.2 | H26: Assumed | I26: D11 | J26: v0.6 沿用 | K26: tokenRevenue.api.listPriceAnnualChange.mid | L26: 2027 起每年；情境軸之一 | M26: =IF(AND(ISNUMBER($E26),ISNUMBER($F26),ISNUMBER($G26)),IF(AND($F26<=$E26,$E26<=$G26),0,1),0) -> 0
A27: INP_023 | B27: 牌價年變動率：low 層 | C27: — | D27: 比例/年 | E27: -0.4 | F27: -0.6 | G27: -0.2 | H27: Assumed | I27: D11 | J27: v0.6 沿用 | K27: tokenRevenue.api.listPriceAnnualChange.low | L27: 2027 起每年；情境軸之一 | M27: =IF(AND(ISNUMBER($E27),ISNUMBER($F27),ISNUMBER($G27)),IF(AND($F27<=$E27,$E27<=$G27),0,1),0) -> 0
A28: INP_024 | B28: API token 層級占比：top 層 | C28: 陣列[0] | D28: 比例 | E28: 0.4 | F28: 0.25 | G28: 0.5 | H28: Assumed | I28: — | J28: v0.6 沿用 | K28: tokenRevenue.api.tokenMix.top | L28: v0.5 陣列兩位（年份對應待 P2 確認：占比 top 0.40→0.15 判斷為 2025→2026） | M28: =IF(AND(ISNUMBER($E28),ISNUMBER($F28),ISNUMBER($G28)),IF(AND($F28<=$E28,$E28<=$G28),0,1),0) -> 0
A29: INP_025 | B29: API token 層級占比：top 層 | C29: 陣列[1] | D29: 比例 | E29: 0.15 | F29: 0.08 | G29: 0.25 | H29: Assumed | I29: — | J29: v0.6 沿用 | K29: tokenRevenue.api.tokenMix.top | L29: v0.5 陣列兩位（年份對應待 P2 確認：占比 top 0.40→0.15 判斷為 2025→2026） | M29: =IF(AND(ISNUMBER($E29),ISNUMBER($F29),ISNUMBER($G29)),IF(AND($F29<=$E29,$E29<=$G29),0,1),0) -> 0
A30: INP_026 | B30: API token 層級占比：mid 層 | C30: 陣列[0] | D30: 比例 | E30: 0.4 | F30: 0.3 | G30: 0.5 | H30: Assumed | I30: — | J30: v0.6 沿用 | K30: tokenRevenue.api.tokenMix.mid | L30: v0.5 陣列兩位（年份對應待 P2 確認：占比 top 0.40→0.15 判斷為 2025→2026） | M30: =IF(AND(ISNUMBER($E30),ISNUMBER($F30),ISNUMBER($G30)),IF(AND($F30<=$E30,$E30<=$G30),0,1),0) -> 0
A31: INP_027 | B31: API token 層級占比：mid 層 | C31: 陣列[1] | D31: 比例 | E31: 0.45 | F31: 0.35 | G31: 0.55 | H31: Assumed | I31: — | J31: v0.6 沿用 | K31: tokenRevenue.api.tokenMix.mid | L31: v0.5 陣列兩位（年份對應待 P2 確認：占比 top 0.40→0.15 判斷為 2025→2026） | M31: =IF(AND(ISNUMBER($E31),ISNUMBER($F31),ISNUMBER($G31)),IF(AND($F31<=$E31,$E31<=$G31),0,1),0) -> 0
A32: INP_028 | B32: 輸出 token 占比（API） | C32: — | D32: 比例 | E32: 0.2 | F32: 0.1 | G32: 0.35 | H32: Analogy | I32: — | J32: v0.6 沿用 | K32: tokenRevenue.api.outputShare | M32: =IF(AND(ISNUMBER($E32),ISNUMBER($F32),ISNUMBER($G32)),IF(AND($F32<=$E32,$E32<=$G32),0,1),0) -> 0
A33: INP_029 | B33: 快取命中率（API） | C33: — | D33: 比例 | E33: 0.55 | F33: 0.3 | G33: 0.75 | H33: Assumed | I33: — | J33: v0.6 沿用 | K33: tokenRevenue.api.cacheHitRate | M33: =IF(AND(ISNUMBER($E33),ISNUMBER($F33),ISNUMBER($G33)),IF(AND($F33<=$E33,$E33<=$G33),0,1),0) -> 0
A34: INP_030 | B34: 加權折扣率（Batch/Flex／企業） | C34: — | D34: 比例 | E34: 0.2 | F34: 0.1 | G34: 0.3 | H34: Assumed | I34: — | J34: v0.6 沿用 | K34: tokenRevenue.api.discountRate | M34: =IF(AND(ISNUMBER($E34),ISNUMBER($F34),ISNUMBER($G34)),IF(AND($F34<=$E34,$E34<=$G34),0,1),0) -> 0
A35: INP_031 | B35: 基準每任務 token（層級正規化） | C35: — | D35: K tok/task | E35: 10 | F35: 5 | G35: 30 | H35: Assumed | I35: — | J35: v0.6 沿用 | K35: tokenRevenue.api.tokensPerTaskBase | L35: 只影響 N 與 k 的水準拆分，不影響營收 | M35: =IF(AND(ISNUMBER($E35),ISNUMBER($F35),ISNUMBER($G35)),IF(AND($F35<=$E35,$E35<=$G35),0,1),0) -> 0
A36: INP_032 | B36: 任務數成長率（不含價格） | C36: 2025 | D36: 比例/年 | E36: 0 | H36: Assumed | I36: — | J36: v0.6 沿用 | K36: tokenRevenue.api.demandGrowthExPrice.tasks | L36: 2025 欄為 0（基準年） | M36: =IF(AND(ISNUMBER($E36),ISNUMBER($F36),ISNUMBER($G36)),IF(AND($F36<=$E36,$E36<=$G36),0,1),0) -> 0
A37: INP_033 | B37: 任務數成長率（不含價格） | C37: 2026 | D37: 比例/年 | E37: 1.34 | H37: Assumed | I37: — | J37: v0.6 沿用 | K37: tokenRevenue.api.demandGrowthExPrice.tasks | M37: =IF(AND(ISNUMBER($E37),ISNUMBER($F37),ISNUMBER($G37)),IF(AND($F37<=$E37,$E37<=$G37),0,1),0) -> 0
A38: INP_034 | B38: 任務數成長率（不含價格） | C38: 2027 | D38: 比例/年 | E38: 0.45 | H38: Assumed | I38: — | J38: v0.6 沿用 | K38: tokenRevenue.api.demandGrowthExPrice.tasks | M38: =IF(AND(ISNUMBER($E38),ISNUMBER($F38),ISNUMBER($G38)),IF(AND($F38<=$E38,$E38<=$G38),0,1),0) -> 0
A39: INP_035 | B39: 任務數成長率（不含價格） | C39: 2028 | D39: 比例/年 | E39: 0.35 | H39: Assumed | I39: — | J39: v0.6 沿用 | K39: tokenRevenue.api.demandGrowthExPrice.tasks | M39: =IF(AND(ISNUMBER($E39),ISNUMBER($F39),ISNUMBER($G39)),IF(AND($F39<=$E39,$E39<=$G39),0,1),0) -> 0
A40: INP_036 | B40: 任務數成長率（不含價格） | C40: 2029 | D40: 比例/年 | E40: 0.25 | H40: Assumed | I40: — | J40: v0.6 沿用 | K40: tokenRevenue.api.demandGrowthExPrice.tasks | M40: =IF(AND(ISNUMBER($E40),ISNUMBER($F40),ISNUMBER($G40)),IF(AND($F40<=$E40,$E40<=$G40),0,1),0) -> 0
...

Sheet Derived_V9
A1: Derived_V9 — 跨年混合項目與 Derived 項目的公式（V9、V12、V15、E8）；v0.5 原值並列
A2: E6：公式不內含常數（算式中的 1－比例 為恆等式），換算係數與比例都在 Inputs（標記＋區間）。『v0.5 原值』欄為 builder 由 v0.5 JSON 寫入的對照常數，不參與計算。
A3: 月營收單位 $M/月＝人數（M）× ARPU（$/月）；年營收＝月營收×月數，月數換算只在報告文字，不進公式。
A4: 編號 | B4: 項目 | C4: 值（公式） | D4: v0.5 原值（對照） | E4: 差距＝值−v0.5（公式） | F4: 單位 | G4: 說明
A5: V01 | B5: free FY2026 平均用戶（M）＝WAU×換算係數 | C5: =SRC_OAI_092*INP_234 -> 950 | D5: 950 | E5: =IF(ISNUMBER(C5),C5-D5,"—") -> 0 | F5: M | G5: SRC_OAI WAU × Inputs 換算係數
A6: V02 | B6: Plus FY2025 平均用戶（M）＝2025-07 Plus＋Pro×換算係數 | C6: =SRC_OAI_094*INP_235 -> 30 | D6: 30 | E6: =IF(ISNUMBER(C6),C6-D6,"—") -> 0 | F6: M | G6: SRC_OAI 35M × Inputs 換算係數
A7: V03 | B7: Pro FY2026 用戶（M）＝比例×付費總數（含席位） | C7: =INP_236/(1-INP_236)*(INP_065+INP_073+INP_089) -> 0.56451613 | D7: 1 | E7: =IF(ISNUMBER(C7),C7-D7,"—") -> -0.43548387 | F7: M | G7: 付費總數＝go＋plus＋seats＋pro；pro＝比例×總數 ⇒ pro＝比例/(1−比例)×(go＋plus＋seats)，無循環
A8: V04 | B8: Pro FY2025 用戶（M）＝2026÷SRC 倍數 | C8: =C7/SRC_OAI_101 -> 0.28225806 | D8: 0.5 | E8: =IF(ISNUMBER(C8),C8-D8,"—") -> -0.21774194 | F8: M | G8: SRC_OAI 倍增約束
A9: V05 | B9: Pro 占付費總數 2026（含席位） | C9: =C7/((INP_065+INP_073+INP_089)+C7) -> 0.008 | D9: 0.014084507 | E9: =IF(ISNUMBER(C9),C9-D9,"—") -> -0.006084507 | F9: 比例 | G9: v0.5 原值欄為 v0.5 pro 1.0 ÷ (go＋plus＋seats＋pro)
A10: V06 | B10: 約束檢查：Pro 占比超出 SRC 上限的部分（0＝符合） | C10: =C9-MIN(C9,SRC_OAI!$E$100) -> 0 | G10: SRC_OAI『<1%』上限（僅 2026）
A11: V07 | B11: v0.5 原值對約束的差距（百分點）＝v0.5 占比−SRC 上限 | C11: =(D9-SRC_OAI!$E$100) -> 0.004084507 | F11: 比例 | G11: 正值＝v0.5 原值超出內部預測所稱『<1%』
A12: V08 | B12: Pro 月訂閱營收 2025（$M/月）＝用戶×ARPU | C12: =C8*INP_099 -> 56.451613 | D12: 100 | E12: =IF(ISNUMBER(C12),C12-D12,"—") -> -43.548387 | F12: $M/月 | G12: ARPU 為 Inputs（2025 欄）
A13: V09 | B13: Pro 月訂閱營收 2026（$M/月）＝用戶×ARPU | C13: =C7*INP_100 -> 84.677419 | D13: 150 | E13: =IF(ISNUMBER(C13),C13-D13,"—") -> -65.322581 | F13: $M/月 | G13: ARPU 為 Inputs（2026 起欄）
A14: V10 | B14: Pro FY2027 用戶（M）＝比例_t/(1−比例_t)×(go＋plus＋seats) | C14: =INP_240/(1-INP_240)*(INP_066+INP_074+INP_090) -> 0.80645161 | D14: 1.5 | E14: =IF(ISNUMBER(C14),C14-D14,"—") -> -0.69354839 | F14: M | G14: V15：逐年比例（Inputs，0.5–2.0%）
A15: V11 | B15: Pro FY2028 用戶（M）＝比例_t/(1−比例_t)×(go＋plus＋seats) | C15: =INP_241/(1-INP_241)*(INP_067+INP_075+INP_091) -> 1.0483871 | D15: 2 | E15: =IF(ISNUMBER(C15),C15-D15,"—") -> -0.9516129 | F15: M | G15: V15：逐年比例（Inputs，0.5–2.0%）
A16: V12 | B16: Pro FY2029 用戶（M）＝比例_t/(1−比例_t)×(go＋plus＋seats) | C16: =INP_242/(1-INP_242)*(INP_068+INP_076+INP_092) -> 1.2419355 | D16: 2.5 | E16: =IF(ISNUMBER(C16),C16-D16,"—") -> -1.2580645 | F16: M | G16: V15：逐年比例（Inputs，0.5–2.0%）
A17: V13 | B17: Pro FY2030 用戶（M）＝比例_t/(1−比例_t)×(go＋plus＋seats) | C17: =INP_243/(1-INP_243)*(INP_069+INP_077+INP_093) -> 1.4112903 | D17: 3 | E17: =IF(ISNUMBER(C17),C17-D17,"—") -> -1.5887097 | F17: M | G17: V15：逐年比例（Inputs，0.5–2.0%）
A18: V14 | B18: Pro 占付費總數 2027（含席位） | C18: =C14/((INP_066+INP_074+INP_090)+C14) -> 0.008 | D18: 0.014778325 | E18: =IF(ISNUMBER(C18),C18-D18,"—") -> -0.0067783251 | F18: 比例 | G18: v0.5 原值欄＝v0.5 pro ÷ (go＋plus＋seats＋pro)（約 1.48%→1.7%）
A19: V15 | B19: Pro 占付費總數 2028（含席位） | C19: =C15/((INP_067+INP_075+INP_091)+C15) -> 0.008 | D19: 0.015151515 | E19: =IF(ISNUMBER(C19),C19-D19,"—") -> -0.0071515152 | F19: 比例 | G19: v0.5 原值欄＝v0.5 pro ÷ (go＋plus＋seats＋pro)（約 1.48%→1.7%）
A20: V16 | B20: Pro 占付費總數 2029（含席位） | C20: =C16/((INP_068+INP_076+INP_092)+C16) -> 0.008 | D20: 0.015974441 | E20: =IF(ISNUMBER(C20),C20-D20,"—") -> -0.0079744409 | F20: 比例 | G20: v0.5 原值欄＝v0.5 pro ÷ (go＋plus＋seats＋pro)（約 1.48%→1.7%）
A21: V17 | B21: Pro 占付費總數 2030（含席位） | C21: =C17/((INP_069+INP_077+INP_093)+C17) -> 0.008 | D21: 0.016853933 | E21: =IF(ISNUMBER(C21),C21-D21,"—") -> -0.0088539326 | F21: 比例 | G21: v0.5 原值欄＝v0.5 pro ÷ (go＋plus＋seats＋pro)（約 1.48%→1.7%）
A22: V18 | B22: Pro 月訂閱營收 2027（$M/月）＝用戶×ARPU | C22: =C14*INP_100 -> 120.96774 | D22: 225 | E22: =IF(ISNUMBER(C22),C22-D22,"—") -> -104.03226 | F22: $M/月 | G22: ARPU 為 Inputs（2026 起欄）
A23: V19 | B23: Pro 月訂閱營收 2028（$M/月）＝用戶×ARPU | C23: =C15*INP_100 -> 157.25806 | D23: 300 | E23: =IF(ISNUMBER(C23),C23-D23,"—") -> -142.74194 | F23: $M/月 | G23: ARPU 為 Inputs（2026 起欄）
A24: V20 | B24: Pro 月訂閱營收 2029（$M/月）＝用戶×ARPU | C24: =C16*INP_100 -> 186.29032 | D24: 375 | E24: =IF(ISNUMBER(C24),C24-D24,"—") -> -188.70968 | F24: $M/月 | G24: ARPU 為 Inputs（2026 起欄）
A25: V21 | B25: Pro 月訂閱營收 2030（$M/月）＝用戶×ARPU | C25: =C17*INP_100 -> 211.69355 | D25: 450 | E25: =IF(ISNUMBER(C25),C25-D25,"—") -> -238.30645 | F25: $M/月 | G25: ARPU 為 Inputs（2026 起欄）
A26: V22 | B26: API FY2025 token（T）＝每分鐘 token×每年分鐘數÷單位換算 | C26: =INP_237*INP_238/INP_239 -> 2628 | D26: 2628 | E26: =IF(ISNUMBER(C26),C26-D26,"—") -> 0 | F26: T | G26: E8a：驅動值＝Inputs 5B/min
A27: V23 | B27: API FY2025 token 低（T） | C27: =Inputs!$F$229*INP_238/INP_239 -> 1997.28 | D27: 2000 | E27: =IF(ISNUMBER(C27),C27-D27,"—") -> -2.72 | F27: T | G27: E8a：驅動值低端 3.8
A28: V24 | B28: API FY2025 token 高（T） | C28: =Inputs!$G$229*INP_238/INP_239 -> 3206.16 | D28: 3200 | E28: =IF(ISNUMBER(C28),C28-D28,"—") -> 6.16 | F28: T | G28: E8a：驅動值高端 6.1
A29: V25 | B29: Oracle 合約年額（$B/年）＝總額÷年數 | C29: =IF(SRC_OAI_060>=SRC_OAI_059,SRC_OAI_058/(SRC_OAI_060-SRC_OAI_059+1),"期間無效") -> 60 | D29: 60 | E29: =IF(ISNUMBER(C29),C29-D29,"—") -> 0 | F29: $B | G29: E8f：v0.5 以數值 60 寫入，改公式
A30: V26 | B30: AWS Trainium WSJ 口徑合計 GW＝推論＋訓練 | C30: =SRC_OAI_103+SRC_OAI_104 -> 5 | D30: 5 | E30: =IF(ISNUMBER(C30),C30-D30,"—") -> 0 | F30: GW | G30: E8g：『5』改公式（v0.5 區間上緣 5）
A31: V27 | B31: 2026-03 輪無條件部分＝四個組成加總 | C31: =SRC_OAI_109+SRC_OAI_110+SRC_OAI_111+SRC_OAI_112 -> 87 | D31: 87 | E31: =IF(ISNUMBER(C31),C31-D31,"—") -> 0 | F31: $B | G31: E8j：87 拆為 SRC 組成

Sheet Demand
A1: Demand — 需求：訂閱各方案人數、每日任務數 × 每任務 token、API 任務數與計費 token；token 量（層級 × 付費／免費）
A2: 機制沿用 v0.5「訂閱與廣告」「API」頁（D、N、S 決定）。2025 為校準年：API 計費 token 由 FY2025 實際營收倒推（v0.5 唯一倒推）。2027 起需求成長（不含價格）× 價格反應 (p/p前)^ε。免費用戶只產生 token 需求，不產生訂閱營收。
A3: token 單位 T＝10^12；人數 M＝百萬；任務數（API）十億。v0.5 原值欄（K–P）為 v0.5 Excel 快取值，只作對照。容量上限（V1a）於 P3 加入，本頁不截頂。
A5: 編號 | B5: 項目 | C5: 單位 | D5: 2025 | E5: 2026 | F5: 2027 | G5: 2028 | H5: 2029 | I5: 2030 | K5: v0.5 2025 | L5: v0.5 2026 | M5: v0.5 2027 | N5: v0.5 2028 | O5: v0.5 2029 | P5: v0.5 2030 | Q5: 說明
B6: 年度 | D6: =INP_005 -> 2025 | E6: =INP_006 -> 2026 | F6: =INP_007 -> 2027 | G6: =INP_008 -> 2028 | H6: =INP_009 -> 2029 | I6: =INP_010 -> 2030
A7: 一、訂閱人數（M，FY 平均；T4：2026 起 Plus→Go 遷移與 Go 額外新增）
A8: D01 | B8: 遷移率 μ（Plus→Go） | C8: 比例 | E8: =INP_013*(1-SRC_OAI_037/INP_073) -> 0.24130435 | F8: =INP_013*(1-SRC_OAI_037/INP_073) -> 0.24130435 | G8: =INP_013*(1-SRC_OAI_037/INP_073) -> 0.24130435 | H8: =INP_013*(1-SRC_OAI_037/INP_073) -> 0.24130435 | I8: =INP_013*(1-SRC_OAI_037/INP_073) -> 0.24130435 | L8: 0.24130435 | M8: 0.24130435 | N8: 0.24130435 | O8: 0.24130435 | P8: 0.24130435 | Q8: 計畫幅度（Inputs 基準 0.3）×（1 − 公司計畫 Plus ÷ 無遷移 Plus 2026）；2026 起各年同值（v0.5）
A9: D02 | B9: Go 額外新增倍數 λ | C9: 倍 | E9: =INP_013*(SRC_OAI_036-INP_073*(1-SRC_OAI_037/INP_073)-INP_065)/INP_065 -> 1.95 | F9: =INP_013*(SRC_OAI_036-INP_073*(1-SRC_OAI_037/INP_073)-INP_065)/INP_065 -> 1.95 | G9: =INP_013*(SRC_OAI_036-INP_073*(1-SRC_OAI_037/INP_073)-INP_065)/INP_065 -> 1.95 | H9: =INP_013*(SRC_OAI_036-INP_073*(1-SRC_OAI_037/INP_073)-INP_065)/INP_065 -> 1.95 | I9: =INP_013*(SRC_OAI_036-INP_073*(1-SRC_OAI_037/INP_073)-INP_065)/INP_065 -> 1.95 | L9: 1.95 | M9: 1.95 | N9: 1.95 | O9: 1.95 | P9: 1.95 | Q9: ＝計畫幅度 ×（公司計畫 Go −（無遷移 Plus 2026 − 公司計畫 Plus）− 無遷移 Go 2026）÷ 無遷移 Go 2026；計畫幅度＝1 時，2026 Go 恰等於公司計畫 112M（v0.5；與 v0.5 寫法代數相同）
A10: D03 | B10: Free 人數 | C10: M | D10: =INP_056 -> 600 | E10: =V9_Free2026 -> 950 | F10: =INP_058 -> 1250 | G10: =INP_059 -> 1500 | H10: =INP_060 -> 1700 | I10: =INP_061 -> 1850 | K10: 600 | L10: 950 | M10: 1250 | N10: 1500 | O10: 1700 | P10: 1850 | Q10: 2025、2027+ Inputs；2026＝SRC WAU × 換算係數（Derived_V9 V01）
A11: D04 | B11: Go 人數 | C11: M | D11: =INP_064 -> 2 | E11: =INP_065*(1+E9)+INP_073*E8 -> 40.6 | F11: =INP_066*(1+F9)+INP_074*F8 -> 77.447826 | G11: =INP_067*(1+G9)+INP_075*G8 -> 117.00435 | H11: =INP_068*(1+H9)+INP_076*H8 -> 147.46957 | I11: =INP_069*(1+I9)+INP_077*I8 -> 177.69348 | K11: 2 | L11: 40.6 | M11: 77.447826 | N11: 117.00435 | O11: 147.46957 | P11: 177.69348 | Q11: 2026 起＝無遷移 Go ×（1＋λ）＋無遷移 Plus × μ
A12: D05 | B12: Plus 人數 | C12: M | D12: =V9_Plus2025 -> 30 | E12: =INP_073*(1-E8) -> 34.9 | F12: =INP_074*(1-F8) -> 39.452174 | G12: =INP_075*(1-G8) -> 43.245652 | H12: =INP_076*(1-H8) -> 46.280435 | I12: =INP_077*(1-I8) -> 48.556522 | K12: 30 | L12: 34.9 | M12: 39.452174 | N12: 43.245652 | O12: 46.280435 | P12: 48.556522 | Q12: 2025＝Derived_V9 V02（SRC 35M × 換算係數）；2026 起＝無遷移 Plus ×（1 − μ）
A13: D06 | B13: Pro 人數 | C13: M | D13: =V9_Pro2025 -> 0.28225806 | E13: =V9_Pro2026 -> 0.56451613 | F13: =V9_Pro2027 -> 0.80645161 | G13: =V9_Pro2028 -> 1.0483871 | H13: =V9_Pro2029 -> 1.2419355 | I13: =V9_Pro2030 -> 1.4112903 | K13: 0.5 | L13: 1 | M13: 1.5 | N13: 2 | O13: 2.5 | P13: 3 | Q13: V12／V15：占比 × 付費總數（Derived_V9 V03、V04、V10–V13；付費總數口徑＝無遷移基準，沿用 P1 已審公式）
A14: D07 | B14: 企業席位人數 | C14: M | D14: =INP_088 -> 3 | E14: =INP_089 -> 14 | F14: =INP_090 -> 26 | G14: =INP_091 -> 38 | H14: =INP_092 -> 48 | I14: =INP_093 -> 56 | K14: 3 | L14: 14 | M14: 26 | N14: 38 | O14: 48 | P14: 56 | Q14: Inputs
A15: D08 | B15: 付費人數合計（Go＋Plus＋Pro＋席位） | C15: M | D15: =D11+D12+D13+D14 -> 35.282258 | E15: =E11+E12+E13+E14 -> 90.064516 | F15: =F11+F12+F13+F14 -> 143.70645 | G15: =G11+G12+G13+G14 -> 199.29839 | H15: =H11+H12+H13+H14 -> 242.99194 | I15: =I11+I12+I13+I14 -> 283.66129
A16: D09 | B16: 消費端付費人數（Go＋Plus＋Pro） | C16: M | D16: =D11+D12+D13 -> 32.282258 | E16: =E11+E12+E13 -> 76.064516 | F16: =F11+F12+F13 -> 117.70645 | G16: =G11+G12+G13 -> 161.29839 | H16: =H11+H12+H13 -> 194.99194 | I16: =I11+I12+I13 -> 227.66129 | K16: 32.5 | L16: 76.5 | M16: 118.4 | N16: 162.25 | O16: 196.25 | P16: 229.25
A17: 二、訂閱使用量：每日任務數 × 每任務 token（2025、2026 為 Inputs；2027 起年增）
A18: D10 | B18: Free 每日任務數 | C18: 任務/日 | D18: =INP_102 -> 1.7 | E18: =INP_103 -> 1.7 | F18: =E18*(1+INP_122) -> 1.87 | G18: =F18*(1+INP_122) -> 2.057 | H18: =G18*(1+INP_122) -> 2.2627 | I18: =H18*(1+INP_122) -> 2.48897 | K18: 1.7 | L18: 1.7 | M18: 1.87 | N18: 2.057 | O18: 2.2627 | P18: 2.48897 | Q18: 2027 起 ×（1＋每日任務數年增率）
A19: D11 | B19: Go 每日任務數 | C19: 任務/日 | D19: =INP_104 -> 5.3 | E19: =INP_105 -> 5.7 | F19: =E19*(1+INP_122) -> 6.27 | G19: =F19*(1+INP_122) -> 6.897 | H19: =G19*(1+INP_122) -> 7.5867 | I19: =H19*(1+INP_122) -> 8.34537 | K19: 5.3 | L19: 5.7 | M19: 6.27 | N19: 6.897 | O19: 7.5867 | P19: 8.34537 | Q19: 2027 起 ×（1＋每日任務數年增率）
A20: D12 | B20: Plus 每日任務數 | C20: 任務/日 | D20: =INP_106 -> 13.4 | E20: =INP_107 -> 17.9 | F20: =E20*(1+INP_122) -> 19.69 | G20: =F20*(1+INP_122) -> 21.659 | H20: =G20*(1+INP_122) -> 23.8249 | I20: =H20*(1+INP_122) -> 26.20739 | K20: 13.4 | L20: 17.9 | M20: 19.69 | N20: 21.659 | O20: 23.8249 | P20: 26.20739 | Q20: 2027 起 ×（1＋每日任務數年增率）
A21: D13 | B21: Pro 每日任務數 | C21: 任務/日 | D21: =INP_108 -> 41 | E21: =INP_109 -> 51.4 | F21: =E21*(1+INP_122) -> 56.54 | G21: =F21*(1+INP_122) -> 62.194 | H21: =G21*(1+INP_122) -> 68.4134 | I21: =H21*(1+INP_122) -> 75.25474 | K21: 41 | L21: 51.4 | M21: 56.54 | N21: 62.194 | O21: 68.4134 | P21: 75.25474 | Q21: 2027 起 ×（1＋每日任務數年增率）
A22: D14 | B22: 企業席位 每日任務數 | C22: 任務/日 | D22: =INP_110 -> 10.7 | E22: =INP_111 -> 14.3 | F22: =E22*(1+INP_122) -> 15.73 | G22: =F22*(1+INP_122) -> 17.303 | H22: =G22*(1+INP_122) -> 19.0333 | I22: =H22*(1+INP_122) -> 20.93663 | K22: 10.7 | L22: 14.3 | M22: 15.73 | N22: 17.303 | O22: 19.0333 | P22: 20.93663 | Q22: 2027 起 ×（1＋每日任務數年增率）
A23: D15 | B23: Free 每任務 token | C23: K tok/任務 | D23: =INP_112 -> 2 | E23: =INP_113 -> 2.94 | F23: =E23*(1+INP_123) -> 3.381 | G23: =F23*(1+INP_123) -> 3.88815 | H23: =G23*(1+INP_123) -> 4.4713725 | I23: =H23*(1+INP_123) -> 5.1420784 | K23: 2 | L23: 2.94 | M23: 3.381 | N23: 3.88815 | O23: 4.4713725 | P23: 5.1420784 | Q23: 2027 起 ×（1＋每任務 token 年增率；D11 情境軸）
A24: D16 | B24: Go 每任務 token | C24: K tok/任務 | D24: =INP_114 -> 3 | E24: =INP_115 -> 4.39 | F24: =E24*(1+INP_123) -> 5.0485 | G24: =F24*(1+INP_123) -> 5.805775 | H24: =G24*(1+INP_123) -> 6.6766413 | I24: =H24*(1+INP_123) -> 7.6781374 | K24: 3 | L24: 4.39 | M24: 5.0485 | N24: 5.805775 | O24: 6.6766413 | P24: 7.6781374 | Q24: 2027 起 ×（1＋每任務 token 年增率；D11 情境軸）
A25: D17 | B25: Plus 每任務 token | C25: K tok/任務 | D25: =INP_116 -> 4 | E25: =INP_117 -> 6.15 | F25: =E25*(1+INP_123) -> 7.0725 | G25: =F25*(1+INP_123) -> 8.133375 | H25: =G25*(1+INP_123) -> 9.3533812 | I25: =H25*(1+INP_123) -> 10.756388 | K25: 4 | L25: 6.15 | M25: 7.0725 | N25: 8.133375 | O25: 9.3533812 | P25: 10.756388 | Q25: 2027 起 ×（1＋每任務 token 年增率；D11 情境軸）
A26: D18 | B26: Pro 每任務 token | C26: K tok/任務 | D26: =INP_118 -> 10 | E26: =INP_119 -> 15.6 | F26: =E26*(1+INP_123) -> 17.94 | G26: =F26*(1+INP_123) -> 20.631 | H26: =G26*(1+INP_123) -> 23.72565 | I26: =H26*(1+INP_123) -> 27.284498 | K26: 10 | L26: 15.6 | M26: 17.94 | N26: 20.631 | O26: 23.72565 | P26: 27.284498 | Q26: 2027 起 ×（1＋每任務 token 年增率；D11 情境軸）
A27: D19 | B27: 企業席位 每任務 token | C27: K tok/任務 | D27: =INP_120 -> 4 | E27: =INP_121 -> 5.94 | F27: =E27*(1+INP_123) -> 6.831 | G27: =F27*(1+INP_123) -> 7.85565 | H27: =G27*(1+INP_123) -> 9.0339975 | I27: =H27*(1+INP_123) -> 10.389097 | K27: 4 | L27: 5.94 | M27: 6.831 | N27: 7.85565 | O27: 9.0339975 | P27: 10.389097 | Q27: 2027 起 ×（1＋每任務 token 年增率；D11 情境軸）
A28: D20 | B28: Free token | C28: T | D28: =D10*D18*D23*INP_251/INP_239 -> 744.6 | E28: =E10*E18*E23*INP_251/INP_239 -> 1733.0565 | F28: =F10*F18*F23*INP_251/INP_239 -> 2884.6269 | G28: =G10*G18*G23*INP_251/INP_239 -> 4378.8637 | H28: =H10*H18*H23*INP_251/INP_239 -> 6277.8309 | I28: =I10*I18*I23*INP_251/INP_239 -> 8642.1728 | K28: 744.6 | L28: 1733.0565 | M28: 2884.6269 | N28: 4378.8637 | O28: 6277.8309 | P28: 8642.1728 | Q28: 人數（M）× 每日任務 × 每任務 token（K）× 每年天數 ÷ 1000（B→T）
A29: D21 | B29: Go token | C29: T | D29: =D11*D19*D24*INP_251/INP_239 -> 11.607 | E29: =E11*E19*E24*INP_251/INP_239 -> 370.81584 | F29: =F11*F19*F24*INP_251/INP_239 -> 894.81241 | G29: =G11*G19*G24*INP_251/INP_239 -> 1710.0755 | H29: =H11*H19*H24*INP_251/INP_239 -> 2726.5045 | I29: =I11*I19*I24*INP_251/INP_239 -> 4155.9071 | K29: 11.607 | L29: 370.81584 | M29: 894.81241 | N29: 1710.0755 | O29: 2726.5045 | P29: 4155.9071 | Q29: 人數（M）× 每日任務 × 每任務 token（K）× 每年天數 ÷ 1000（B→T）
A30: D22 | B30: Plus token | C30: T | D30: =D12*D20*D25*INP_251/INP_239 -> 586.92 | E30: =E12*E20*E25*INP_251/INP_239 -> 1402.3178 | F30: =F12*F20*F25*INP_251/INP_239 -> 2005.3144 | G30: =G12*G20*G25*INP_251/INP_239 -> 2780.6384 | H30: =H12*H20*H25*INP_251/INP_239 -> 3764.3502 | I30: =I12*I20*I25*INP_251/INP_239 -> 4996.0949 | K30: 586.92 | L30: 1402.3178 | M30: 2005.3144 | N30: 2780.6384 | O30: 3764.3502 | P30: 4996.0949 | Q30: 人數（M）× 每日任務 × 每任務 token（K）× 每年天數 ÷ 1000（B→T）
A31: D23 | B31: Pro token | C31: T | D31: =D13*D21*D26*INP_251/INP_239 -> 42.239919 | E31: =E13*E21*E26*INP_251/INP_239 -> 165.21784 | F31: =F13*F21*F26*INP_251/INP_239 -> 298.57224 | G31: =G13*G21*G26*INP_251/INP_239 -> 491.00204 | H31: =H13*H21*H26*INP_251/INP_239 -> 735.78545 | I31: =I13*I21*I26*INP_251/INP_239 -> 1057.6916 | K31: 74.825 | L31: 292.6716 | M31: 555.34436 | N31: 936.68082 | O31: 1481.1266 | P31: 2248.3501 | Q31: 人數（M）× 每日任務 × 每任務 token（K）× 每年天數 ÷ 1000（B→T）
A32: D24 | B32: 企業席位 token | C32: T | D32: =D14*D22*D27*INP_251/INP_239 -> 46.866 | E32: =E14*E22*E27*INP_251/INP_239 -> 434.05362 | F32: =F14*F22*F27*INP_251/INP_239 -> 1019.716 | G32: =G14*G22*G27*INP_251/INP_239 -> 1885.2979 | H32: =H14*H22*H27*INP_251/INP_239 -> 3012.5077 | I32: =I14*I22*I27*INP_251/INP_239 -> 4445.9592 | K32: 46.866 | L32: 434.05362 | M32: 1019.716 | N32: 1885.2979 | O32: 3012.5077 | P32: 4445.9592 | Q32: 人數（M）× 每日任務 × 每任務 token（K）× 每年天數 ÷ 1000（B→T）
