Workbook

Sheet README
A1: 緯創資通（3231）收支與估值模型 v0.1.1（AI 半導體 Project：伺服器組裝次產業，樣板＝quanta/） 2026-10-25
A2: 版本：v0.1.1（2026-10-25：補上檔空間級距、投資建議、重點觀察（數值不變））。v0.1（初版）。伺服器組裝次產業第三家（廣達、鴻海之後）；AI 伺服器組裝市場、ODM 每櫃價格、客供比例讀廣達模型（規則第 13 條）。另加 GPU 基板驅動（讀 tsmc 成品顆數），並把子公司緯穎拆開以區分合併與歸母口徑。
A3: 模型命題：緯創的合併營收＝本體 AI 系統（部署 GW × 每 GW 架數 × 每櫃價格 × 份額 ×（1 − 客供））＋GPU 基板與運算板（GPU 顆數 × 每顆基板金額 × 份額）＋一般伺服器與非伺服器＋子公司緯穎（ASIC 機架為主）。緯穎占合併營收約三分之一、營益率約為本體的三倍，但緯創只持有 37.68%，合併淨利約四成歸少數股東；EPS 看歸屬母公司淨利＝本體淨利＋37.68% × 緯穎淨利。
A4: 核心問題：本體約 2% 的營益率能不能隨 AI 系統與基板放量撐住，以及緯穎的成長有多少真正流到緯創股東；約 9–10 倍前瞻 P/E 隱含什麼路徑。
A6: 會計年度＝日曆年，FY(t)＝CY(t)，不平移。金額：十億新台幣；整櫃價格與市場以美元計、以匯率換算。口徑：營收、毛利、營業利益為合併（含緯穎）；淨利與 EPS 為歸屬母公司。3Q26 財報與法說約 2026-11-10，本版只納入 3Q26 月營收。
A8: 驅動因子 → 推導量（全部唯讀上游，不修改）
A9: 本體 AI 系統：markets/network 的 AI IT 資本支出 × 情境顆數係數 ÷ 每 GW IT 資本支出（Tokenomics，經橋接表）＝部署 GW；× 每 GW 架數 × ODM 每櫃價格（廣達模型）＝組裝市場；× 本體有效份額（FY2026 以本體營收殘差校準）× 份額相對值（Assumed）×（1 − 客供比例，廣達模型）。
A10: GPU 基板與運算板：tsmc 成品的 NVIDIA＋AMD GPU 顆數 × 緯創基板份額（Assumed）× 每顆基板金額（FY2026 以券商「AI 伺服器零組件超過千億」校準，之後 × 金額指數，Assumed）。緯穎：AI＝組裝市場 × 緯穎 AI 份額（FY2026 以緯穎 AI 占比略高於五成校準）；非 AI 以成長率推。
A11: 損益：本體毛利＝各部門營收 × 毛利率（非伺服器毛利率 FY2026 校準，AI 系統、基板、一般伺服器加減差距，Assumed），營業費用彈性 phi，本體淨利＝本體營業利益 × 淨利係數；緯穎營業利益＝營收 × 營益率、淨利＝營業利益 × 係數。合併淨利＝本體＋緯穎；非控制權益＝（1 − 持股）× 緯穎淨利；歸屬母公司淨利＝合併淨利 − 非控制權益。
A12: 校準：FY2026 ＝ 1H26 實績（公司與緯穎）＋3Q26 營收實績（兩家月營收）＋假設（4Q 季增、利潤率）。不用券商數字（只在 Recon 對帳）。
A13: 估值：Val 第 0 節目標價＝0.5 × DCF 目標價（股東現金流＝EPS ×（1 − g／ROE），FY2027–32 明確期＋永續，r 10%、g 4%，三情境權重 0.3／0.5／0.2）＋0.5 × Comparable 目標價（廣達、鴻海、英業達、緯穎、美超微前瞻 P/E 中位數 × 12 個月後前瞻 EPS；不含 A 股）；另列 Comparable 單獨目標價、市場共識目標價與差距拆解。十年 P/E 規則值 × FY2027 EPS 保留為參考（不是目標價）。情境對應：A＝順利、B＝平平、C＝不如預期（即顆數情境）。本版未做先驗，無 Andy 合理 P/E 對照。
A14: 預估期間：FY2027–FY2029 由驅動因子推導；FY2030 起為收斂法，非驅動因子推導（營收年增由 FY2029 線性收斂到 fade_g、淨利率收斂到 fade_m，FY2032 達到；PL 頁灰底）。十年平均淨利率未找到，C 用 FY2029 × 0.8、B 用 FY2029 × 0.9（Assumed）。
... A17: 已知限制：(1) 本體 AI 系統、GPU 基板、一般伺服器的金額公司都沒有揭露，AI 系統是殘差，基板取單一券商說法；(2) 緯穎持股只有單一近期來源（凱基 37.68%），FY2025 用 40%（Assumed）拆分，非控制權益金額未找到；(3) 集團內交易（緯創與緯穎互供）假設為 0；(4) 客供比例、份額相對值、基板份額與每顆金額是 Assumed；(5) 業外與稅前利益未找到，以淨利 ÷ 營業利益係數涵蓋；(6) 十年 P/E 只有 2017–2025（Goodinfo）與 2021–25（stockanalysis），2016 缺；(7) 3Q26 財報（約 11-10）後更新錨點；R4 產業部署路徑未建。
A18: ="投資建議："&Val!B136&"（依上檔空間固定規則）" -> 投資建議：強力買進（依上檔空間固定規則）
A19: ="重點觀察 1：目標價 NT$"&TEXT(Val!$B$39,"0.00")&"（DCF "&TEXT(Val!$B$24,"0.00")&"、Comparable（相對倍數調整後）"&TEXT(tp_comp_adj,"0.00")&"；DCF 權重 "&TEXT(tp_w_dcf,"0%")&"），比現價 "&TEXT(px,"0.00")&"（2026-10-22）"&IF(Val!$B$42>=0,"高 "&TEXT(Val!$B$42,"0.0%"),"低 "&TEXT(-Val!$B$42,"0.0%"))&"，級距 "&Val!$B$135&"、投資建議 "&Val!$B$136&"。相對倍數調整係數 "&TEXT(rm_factor,"0.00")&"（本公司 10 年前瞻倍數中位數 ÷ 同業的中位數，夾在 0.5–2.0；Val 第 0.5 節），調整前加權上檔空間 "&TEXT((tp_w_dcf*Val!$B$24+(1-tp_w_dcf)*Val!$B$35)/px-1,"+0.0%;−0.0%")&"；Comparable 單獨（市場主流同業法、未調整）為 "&TEXT(Val!$B$43,"+0.0%;−0.0%")&"。"&"以下為 2026-10-29 相對倍數調整前撰寫的說明，其中數字為調整前：主因是 EPS 不是倍數：本模型 12 個月後前瞻 EPS 27.56 比共識前瞻 EPS 18.68 高 47.5%（兩者期間差約一年；FY2027 EPS 27.58 也比法人樂觀說法中點 24.85 高 11.0%），同業（廣達、鴻海、英業達、緯穎、美超微）前瞻 P/E 中位數 11.4 倍與現價隱含 10.2 倍相近"&"；DCF（ROE 20.2%）比 Comparable 高 26.7%，再把目標價往上拉。" -> 重點觀察 1：目標價 NT$332.77（DCF 390.01、Comparable（相對倍數調整後）275.53；DCF 權重 50%），比現價 190.00（2026-10-22）高 75.1%，級距 大於 50%、投資建議 強力買進。相對倍數調整係數 0.89（本公司 10 年前瞻倍數中位數 ÷ 同業的中位數，夾在 0.5–2.0；Val 第 0.5 節），調整前加權上檔空間 +83.9%；Comparable 單獨（市場主流同業法、未調整）為 +62.5%。以下為 2026-10-29 相對倍數調整前撰寫的說明，其中數字為調整前：主因是 EPS 不是倍數：本模型 12 個月後前瞻 EPS 27.56 比共識前瞻 EPS 18.68 高 47.5%（兩者期間差約一年；FY2027 EPS 27.58 也比法人樂觀說法中點 24.85 高 11.0%），同業（廣達、鴻海、英業達、緯穎、美超微）前瞻 P/E 中位數 11.4 倍與現價隱含 10.2 倍相近；DCF（ROE 20.2%）比 Comparable 高 26.7%，再把目標價往上拉。
A20: 重點觀察 2：獲利的兩個槓桿是本體淨利係數與緯穎（持股 37.68%）：本體淨利係數 0.45（基準 0.56）時 FY2027 EPS −11.1%，緯穎營益率 5.5%（基準 6.5%）時 −6.7%，僅次於 AI 部署 ±17.2%。3Q26 財報與法說（約 2026-11-10，緯穎約同期）可檢驗本體獲利率。
A21: 重點觀察 3：情境分歧從 FY2028 起：FY2028 EPS A／B／C＝33.13／26.96／20.64（B、C 比 A 低 18.6%、37.7%）；現價只有 FY2027 EPS 的 6.9 倍，情境 C 的 FY2028 也只有 9.2 倍，低於十年 P/E 中位數 14.5 倍。
A23: 2026-10-29：加權目標價中的 Comparable 改用相對倍數調整後的值（Val 第 0.5 節：同業前瞻倍數中位數 × 本公司 10 年相對同業的倍數比，Bloomberg 前瞻倍數；Andy 2026-10-27「照建議做」、10-29 資料取回）。「Comparable 目標價（市場主流同業法）」維持不調整。重點觀察 1 的第一句已改為公式；重點觀察 2、3 與其他說明中的目標價與上檔空間數字為調整前撰寫，以 Val 頁為準。
A25: v0.2.1（2026-10-30）：依個股模型原則第 8 節調整 In 頁呈現（數值不變）。In 頁 D／F 欄名改「敏感度低」「敏感度高」（只用於 Sens 頁、不進目標價）；In 頁最後新增「情境驅動對照」一節，把上方各情境專屬輸入三情境並排（只引用上方各列，純展示）；HTML 驅動因子一節分「情境驅動」與「單一參數」兩張表。

Sheet In
A1: In — 輸入（藍字；基準欄 E，低 D、高 F）。金額：十億新台幣（NT$B），整櫃價格與市場為美元；顆數：百萬顆；比例：%。每個輸入附兩個來源（找不到者寫「未找到」）；公司原文算一個。【v0.2.1】基準欄 E 進主模型；D／F＝敏感度低／高，只用於 Sens 頁（一次動一個參數）、不進目標價；情境 A／B／C 的驅動見本頁最後一節「情境驅動對照」。
A2: 標記：Verified／Interested-party／Analogy／Assumed／Derived；Analogy、Assumed 給低／高區間，不當點估計（放情境或 Sens）。SemiAnalysis 未使用。公司原文＝緯創、緯穎法說（經鉅亨、優分析、富果摘要）與月營收公告；公司展望為 Interested-party；券商與資料商為 Interested-party。組裝市場與 ODM 每櫃價格讀廣達模型（唯讀），口徑一致
A3: 鍵 | B3: 項目 | C3: 單位 | D3: 敏感度低 | E3: 基準 | F3: 敏感度高 | G3: 標記 | H3: 來源1 | I3: 來源2／說明
A4: A. AI 部署規模與加速器顆數（讀 markets/network、markets/chip_bridge、tsmc 成品；情境 A 基準，B／C 依顆數係數縮放）
A5: itc_26 | B5: AI IT 資本支出 2026 | C5: US$B | E5: 781.87292 | G5: Derived | H5: markets/network/dist/20261026_AI網通市場模型_v0.2.3.xlsx｜Mkt!C27:F27 | I5: 加速器顆數 × 每顆 IT capex（含 ASIC）；除以每 GW IT 資本支出得到部署 GW（與廣達、鴻海模型同口徑）
A6: itc_27 | B6: AI IT 資本支出 2027 | C6: US$B | E6: 1565.35 | G6: Derived | H6: markets/network/dist/20261026_AI網通市場模型_v0.2.3.xlsx｜Mkt!C27:F27 | I6: 同上
A7: itc_28 | B7: AI IT 資本支出 2028 | C7: US$B | E7: 1984.2639 | G7: Derived | H7: markets/network/dist/20261026_AI網通市場模型_v0.2.3.xlsx｜Mkt!C27:F27 | I7: 同上
A8: itc_29 | B8: AI IT 資本支出 2029 | C8: US$B | E8: 2260.3903 | G8: Derived | H8: markets/network/dist/20261026_AI網通市場模型_v0.2.3.xlsx｜Mkt!C27:F27 | I8: 同上
A9: itpg_gb | B9: 每 GW IT 資本支出（GB300） | C9: US$B | E9: 32.237224 | G9: Derived | H9: markets/chip_bridge/dist/20261027_晶片內容橋接表_v0.2.2.xlsx｜In!E10（GB300）、H10（VR200） | I9: Tokenomics v20.1 IF_CapexIT（經橋接表；唯讀）
A10: itpg_vr | B10: 每 GW IT 資本支出（VR200；2027 起） | C10: US$B | E10: 37.586352 | G10: Derived | H10: markets/chip_bridge/dist/20261027_晶片內容橋接表_v0.2.2.xlsx｜In!E10（GB300）、H10（VR200） | I10: 同上；Rubin Ultra 與 ASIC 機架未另訂（Assumed：同 VR200）
A11: vr26 | B11: 2026 年部署中 Rubin 世代占比（混合用；廣達模型） | C11: % | D11: 0.15 | E11: 0.22 | F11: 0.3 | G11: Derived | H11: quanta/dist/20261030_廣達個股模型_v0.3.1.xlsx｜In!D11:F11 | I11: 廣達模型輸入（TrendForce 2026 組合 Rubin 22%）；緯創：Vera Rubin 已開始出貨（2026-09，優分析）
A12: racks_gb | B12: 每 GW 機架數（GB300） | C12: 架 | E12: 6764 | G12: Derived | H12: markets/chip_bridge/dist/20261027_晶片內容橋接表_v0.2.2.xlsx｜In!E6（GB300）、H6（VR200） | I12: Tokenomics IF_RacksPerGW（經橋接表）
A13: racks_vr | B13: 每 GW 機架數（VR200） | C13: 架 | E13: 4052 | G13: Derived | H13: markets/chip_bridge/dist/20261027_晶片內容橋接表_v0.2.2.xlsx｜In!E6（GB300）、H6（VR200） | I13: 同上
A14: um28_A | B14: 情境 A：2028 顆數 ÷ 基準 | C14: x | E14: 1 | G14: Assumed | H14: tsmc/dist/20261030_台積電個股模型_v0.4.1.xlsx｜In!E37 | I14: A＝基準；B＝AI 資本支出消化；C＝明顯下修（與台積電、廣達、鴻海模型相同）
A15: um29_A | B15: 情境 A：2029 顆數 ÷ 基準 | C15: x | E15: 1 | G15: Assumed | H15: tsmc/dist/20261030_台積電個股模型_v0.4.1.xlsx｜In!E38 | I15: 同上
A16: um28_B | B16: 情境 B：2028 顆數 ÷ 基準 | C16: x | E16: 0.8 | G16: Assumed | H16: tsmc/dist/20261030_台積電個股模型_v0.4.1.xlsx｜In!E39 | I16: A＝基準；B＝AI 資本支出消化；C＝明顯下修（與台積電、廣達、鴻海模型相同）
A17: um29_B | B17: 情境 B：2029 顆數 ÷ 基準 | C17: x | E17: 0.85 | G17: Assumed | H17: tsmc/dist/20261030_台積電個股模型_v0.4.1.xlsx｜In!E40 | I17: 同上
A18: um28_C | B18: 情境 C：2028 顆數 ÷ 基準 | C18: x | E18: 0.6 | G18: Assumed | H18: tsmc/dist/20261030_台積電個股模型_v0.4.1.xlsx｜In!E41 | I18: A＝基準；B＝AI 資本支出消化；C＝明顯下修（與台積電、廣達、鴻海模型相同）
A19: um29_C | B19: 情境 C：2029 顆數 ÷ 基準 | C19: x | E19: 0.6 | G19: Assumed | H19: tsmc/dist/20261030_台積電個股模型_v0.4.1.xlsx｜In!E42 | I19: 同上
A20: gu_26 | B20: GPU 顆數 2026（NVIDIA＋AMD，情境 A 基準） | C20: 百萬顆 | E20: 8.35 | G20: Derived | H20: tsmc/dist/20261030_台積電個股模型_v0.4.1.xlsx｜In!E5:E24（NVIDIA Blackwell、Rubin、Rubin Ultra、Hopper 與 AMD Instinct 加總；2029＝2028 ×（1＋各類 2029 成長）） | I20: GPU 基板（HGX）與運算板（Bianca／Strata）只對應 GPU；Google TPU、Trainium 等 ASIC 不計
A21: gu_27 | B21: GPU 顆數 2027（NVIDIA＋AMD，情境 A 基準） | C21: 百萬顆 | E21: 11.2 | G21: Derived | H21: 同上 | I21: 同上
A22: gu_28 | B22: GPU 顆數 2028（NVIDIA＋AMD，情境 A 基準） | C22: 百萬顆 | E22: 11.5 | G22: Derived | H22: 同上 | I22: 同上
A23: gu_29 | B23: GPU 顆數 2029（NVIDIA＋AMD，情境 A 基準） | C23: 百萬顆 | E23: 12.9 | G23: Derived | H23: 同上 | I23: 同上
A24: fx | B24: 匯率（新台幣 ÷ 美元；廣達模型） | C24: NT$/US$ | D24: 30.5 | E24: 32 | F24: 33 | G24: Derived | H24: quanta/dist/20261030_廣達個股模型_v0.3.1.xlsx｜In!D22:F22 | I24: 與廣達、鴻海、台達電模型相同
A25: B. 組裝價格與客供（讀廣達模型，唯讀）、緯創本體與緯穎的份額
A26: odm_gb | B26: ODM 每櫃價格 GB300（廣達模型） | C26: US$M/架 | D26: 3.6 | E26: 4 | F26: 4.3 | G26: Derived | H26: quanta/dist/20261030_廣達個股模型_v0.3.1.xlsx｜In!D24:F24 | I26: 廣達模型標記 Interested-party（工商時報、FTNN 引述法人）；本模型不另訂
A27: odm_vr | B27: ODM 每櫃價格 VR200（廣達模型） | C27: US$M/架 | D27: 6.5 | E27: 6.75 | F27: 7 | G27: Derived | H27: quanta/dist/20261030_廣達個股模型_v0.3.1.xlsx｜In!D25:F25 | I27: 同上
A28: vpg_28 | B28: 每 GW ODM 整櫃價值 2028 ÷ 2027（Rubin Ultra；廣達模型） | C28: x | D28: 0.85 | E28: 1 | F28: 1.2 | G28: Assumed | H28: quanta/dist/20261030_廣達個股模型_v0.3.1.xlsx｜In!D26:F26 | I28: 廣達模型的 Assumed：Rubin Ultra 每櫃價格與每 GW 架數未找到
A29: vpg_29 | B29: 每 GW ODM 整櫃價值 2029 ÷ 2027（廣達模型） | C29: x | D29: 0.85 | E29: 1 | F29: 1.2 | G29: Assumed | H29: quanta/dist/20261030_廣達個股模型_v0.3.1.xlsx｜In!D27:F27 | I29: 同上
A30: cs_27 | B30: 客供比例 2027（緯創本體 AI 系統；廣達模型） | C30: % | D30: 0 | E30: 0.1 | F30: 0.25 | G30: Assumed | H30: quanta/dist/20261030_廣達個股模型_v0.3.1.xlsx｜In!D31:F31 | I30: 緯創：與新客戶議定較好的價格條件，GB／Blackwell 新計價下營益率維持合理（2Q26 法說，鉅亨）；客供比例的量化：未找到
A31: cs_28 | B31: 客供比例 2028（緯創本體 AI 系統；廣達模型） | C31: % | D31: 0 | E31: 0.2 | F31: 0.4 | G31: Assumed | H31: quanta/dist/20261030_廣達個股模型_v0.3.1.xlsx｜In!D32:F32 | I31: 同上
A32: cs_29 | B32: 客供比例 2029（緯創本體 AI 系統；廣達模型） | C32: % | D32: 0 | E32: 0.25 | F32: 0.5 | G32: Assumed | H32: quanta/dist/20261030_廣達個股模型_v0.3.1.xlsx｜In!D33:F33 | I32: 同上
A33: keep | B33: 客供部分保留的毛利比例（相對買賣模式；廣達模型） | C33: x | D33: 0.7 | E33: 0.9 | F33: 1 | G33: Assumed | H33: quanta/dist/20261030_廣達個股模型_v0.3.1.xlsx｜In!D34:F34 | I33: 同廣達模型
A34: rel_27 | B34: 緯創本體 AI 系統有效份額 2027 ÷ 2026（相對值） | C34: x | D34: 0.85 | E34: 1 | F34: 1.15 | G34: Assumed | H34: 緯創 2Q26 法說（鉅亨）：2H26 起新企業與 CSP 客戶，含 L10 與 L11 整櫃（公司） | I34: 經濟日報 2026-09-10：美系券商 8 月調查 鴻海約 2,600 櫃、廣達 2,500–2,550、緯創 2,300–2,400（Interested-party，單一來源）
A35: rel_28 | B35: 緯創本體份額 2028 ÷ 2026 | C35: x | D35: 0.75 | E35: 0.95 | F35: 1.15 | G35: Assumed | H35: 同上；鴻海、廣達同時擴產（廣達模型 0.95、鴻海模型 1.0） | I35: —
A36: rel_29 | B36: 緯創本體份額 2029 ÷ 2026 | C36: x | D36: 0.7 | E36: 0.9 | F36: 1.15 | G36: Assumed | H36: 同上 | I36: —
A37: wrel_27 | B37: 緯穎 AI 有效份額 2027 ÷ 2026（相對值） | C37: x | D37: 0.85 | E37: 1 | F37: 1.2 | G37: Assumed | H37: 緯穎 4Q25 法說（富果）：AI 伺服器約九成為 ASIC 專案；2H26 新 ASIC 與 GPU 平台開始出貨（公司） | I37: 凱基緯穎報告 2026-07-28：凱基 2027F 緯穎營收 +74%（Interested-party）
... A39: wrel_29 | B39: 緯穎 AI 份額 2029 ÷ 2026 | C39: x | D39: 0.7 | E39: 0.95 | F39: 1.2 | G39: Assumed | H39: 同上 | I39: —
A40: C. GPU 基板與運算板（緯創本體：GPU 顆數 × 每顆基板金額 × 份額；FY2026 以券商「AI 伺服器零組件超過千億」校準）
A41: brd_26 | B41: FY2026 GPU 基板與運算板營收（AI 伺服器零組件） | C41: NT$B | D41: 100 | E41: 110 | F41: 140 | G41: Interested-party | H41: 凱基緯創報告 2026-05-08：2026 AI 伺服器零組件營收超過 NT$1,000 億，由運算板（Bianca／Strata）帶動（凱基 2026-05-08） | I41: 公司：零組件（L10）出貨量逐季增加（2Q26 法說，鉅亨）；金額公司未揭露：未找到
...

Sheet Q
A1: Q — 實績與 FY2026 錨點（十億新台幣；EPS 為新台幣；股數為十億股）。藍字＝輸入；黑字＝公式。合併＝緯創本體＋緯穎；本體＝合併 − 緯穎（含其他子公司，集團內交易未扣除）
A2: FY2026 錨點＝1H26 實績＋3Q26 營收實績（緯創、緯穎月營收）＋3Q、4Q 假設（緯穎毛利率與營益率、本體毛利率與費用率、淨利係數；4Q 營收＝3Q ×（1＋季增））。1Q26 營收＝2Q26 ÷（1＋季增 5.81%）；1Q 毛利率、營益率由 2Q 與季增百分點推得。歸屬母公司淨利＝本體淨利＋持股 × 緯穎淨利；非控制權益＝（1 − 持股）× 緯穎淨利（其他子公司的少數股權併入本體係數）
A3: 項目 | B3: FY2025A | C3: 1H26（實績） | D3: 3Q26（營收實績） | E3: 4Q26（模型） | F3: FY2026 錨點 | G3: 標記 | H3: 來源1（公司） | I3: 來源2／說明
A4: 合併營收 | B4: 2186.523 | C4: =895.443/(1+0.0581)+895.443 -> 1741.7175 | D4: =q3_rev -> 1149.09 | E4: =D4*(1+q4g) -> 1206.5445 | F4: =SUM(C4:E4) -> 4097.352 | G4: Verified／Interested-party（4Q 季增） | H4: FY2025：stockanalysis 財報頁、優分析 2026-03-12；1H26：鉅亨、優分析 2026-08-04（2Q26 法說） | I4: FY2025 2,186.523（stockanalysis；公司 2.19 兆）；2Q26 8,954.43 億、季增 5.81%（公司）
A5: 合併毛利 | B5: 133.983 | C5: =895.443/(1+0.0581)*(0.0556-0.0045)+895.443*0.0556 -> 93.031255 | D5: =D10*q_wgm+D13*q_sgm -> 66.110792 | E5: =E10*q_wgm+E13*q_sgm -> 69.416332 | F5: =SUM(C5:E5) -> 228.55838 | G5: Verified／Derived（毛利率 × 營收） | H5: FY2025：stockanalysis 財報頁、優分析 2026-03-12；1H26：鉅亨、優分析 2026-08-04（2Q26 法說） | I5: FY2025 毛利率 6.13%；2Q26 5.56%、季增 0.45 個百分點（公司）
A6: 合併毛利率 | B6: =B5/B4 -> 0.061276739 | C6: =C5/C4 -> 0.053413517 | D6: =D5/D4 -> 0.057533171 | E6: =E5/E4 -> 0.057533171 | F6: =F5/F4 -> 0.055781974 | G6: Derived | H6: — | I6: —
A7: 合併營業利益 | B7: 78.553 | C7: =895.443/(1+0.0581)*(0.0374-0.0029)+895.443*0.0374 -> 62.686037 | D7: =D12+D15 -> 44.915172 | E7: =E12+E15 -> 47.160931 | F7: =SUM(C7:E7) -> 154.76214 | G7: Verified／Derived | H7: FY2025：stockanalysis 財報頁、優分析 2026-03-12；1H26：鉅亨、優分析 2026-08-04（2Q26 法說） | I7: FY2025 營益率 3.59%；2Q26 3.74%、季增 0.29 個百分點（公司）
A8: 合併營業利益率 | B8: =B7/B4 -> 0.035925988 | C8: =C7/C4 -> 0.035990933 | D8: =D7/D4 -> 0.039087601 | E8: =E7/E4 -> 0.039087601 | F8: =F7/F4 -> 0.037771258 | G8: Derived | H8: — | I8: —
A9: 合併營業費用 | B9: =B5-B7 -> 55.43 | C9: =C5-C7 -> 30.345219 | D9: =D5-D7 -> 21.19562 | E9: =E5-E7 -> 22.255401 | F9: =SUM(C9:E9) -> 73.79624 | G9: Derived | H9: 毛利 − 營業利益 | I9: —
A10: 緯穎營收 | B10: 950.663 | C10: 554.66 | D10: =q3_wrev -> 434.618 | E10: =D10*(1+q4gw) -> 456.3489 | F10: =SUM(C10:E10) -> 1445.6269 | G10: Verified／Assumed（4Q） | H10: 緯穎：富果 FY2025 法說、優分析 2Q26 財報、TechNews 9 月營收 | I10: FY2025 9,506.63 億；1H26 5,546.6 億（緯穎）
A11: 緯穎毛利 | B11: 78.454 | C11: =554.66*0.0841 -> 46.646906 | D11: =D10*q_wgm -> 38.246384 | E11: =E10*q_wgm -> 40.158703 | F11: =SUM(C11:E11) -> 125.05199 | G11: Verified／Derived | H11: 緯穎：富果 FY2025 法說、優分析 2Q26 財報、TechNews 9 月營收 | I11: FY2025 784.54 億；1H26 毛利率 8.41%
A12: 緯穎營業利益 | B12: 63.918 | C12: =554.66*0.0679 -> 37.661414 | D12: =D10*q_wopm -> 29.554024 | E12: =E10*q_wopm -> 31.031725 | F12: =SUM(C12:E12) -> 98.247163 | G12: Verified／Derived | H12: 緯穎：富果 FY2025 法說、優分析 2Q26 財報、TechNews 9 月營收 | I12: FY2025 639.18 億；1H26 營益率 6.79%
A13: 緯創本體營收（合併 − 緯穎） | B13: =B4-B10 -> 1235.86 | C13: =C4-C10 -> 1187.0575 | D13: =D4-D10 -> 714.472 | E13: =E4-E10 -> 750.1956 | F13: =SUM(C13:E13) -> 2651.7251 | G13: Derived | H13: — | I13: 集團內交易：未找到（假設為 0）
A14: 緯創本體毛利 | B14: =B5-B11 -> 55.529 | C14: =C5-C11 -> 46.384349 | D14: =D5-D11 -> 27.864408 | E14: =E5-E11 -> 29.257628 | F14: =SUM(C14:E14) -> 103.50639 | G14: Derived | H14: — | I14: —
A15: 緯創本體營業利益 | B15: =B7-B12 -> 14.635 | C15: =C7-C12 -> 25.024623 | D15: =D14-D13*q_sopx -> 15.361148 | E15: =E14-E13*q_sopx -> 16.129205 | F15: =SUM(C15:E15) -> 56.514976 | G15: Derived | H15: — | I15: 凱基：1Q26 本體營益率約 2%、緯穎 6.3%
A16: 緯創本體營業費用 | B16: =B14-B15 -> 40.894 | C16: =C14-C15 -> 21.359727 | D16: =D14-D15 -> 12.50326 | E16: =E14-E15 -> 13.128423 | F16: =SUM(C16:E16) -> 46.99141 | G16: Derived | H16: — | I16: —
A17: 緯穎淨利 | B17: 51.118 | C17: 29.084 | D17: =D12*q_wnio -> 22.756598 | E17: =E12*q_wnio -> 23.894428 | F17: =SUM(C17:E17) -> 75.735027 | G17: Verified／Derived | H17: 緯穎：富果 FY2025 法說、優分析 2Q26 財報、TechNews 9 月營收 | I17: FY2025 511.18 億；1H26 290.84 億（緯穎）
A18: 緯創持有緯穎比例 | B18: =stake25 -> 0.4 | C18: =stake -> 0.3768 | D18: =stake -> 0.3768 | E18: =stake -> 0.3768 | F18: =stake -> 0.3768 | G18: Interested-party／Assumed（FY2025） | H18: 凱基 2026-07-28：37.68% | I18: 2024 年 42.66%（CMoney）
A19: 非控制權益（≈（1 − 持股）× 緯穎淨利） | B19: =(1-B18)*B17 -> 30.6708 | C19: =(1-C18)*C17 -> 18.125149 | D19: =(1-D18)*D17 -> 14.181912 | E19: =(1-E18)*E17 -> 14.891008 | F19: =SUM(C19:E19) -> 47.198069 | G19: Derived | H19: 其他子公司的少數股權併入本體係數 | I19: 公司揭露的非控制權益金額：未找到
A20: 歸屬母公司淨利 | B20: 27.408 | C20: =9.631+14.827 -> 24.458 | D20: =D21+D18*D17 -> 17.176929 | E20: =E21+E18*E17 -> 18.035776 | F20: =SUM(C20:E20) -> 59.670705 | G20: Verified／Derived（3Q、4Q） | H20: FY2025：stockanalysis 財報頁、優分析 2026-03-12；1H26：鉅亨、優分析 2026-08-04（2Q26 法說） | I20: FY2025 274.08 億；1Q26 96.31 億、2Q26 148.27 億（公司稅後純益）
A21: 緯創本體淨利（歸屬母公司淨利 − 持股 × 緯穎淨利） | B21: =B20-B18*B17 -> 6.9608 | C21: =C20-C18*C17 -> 13.499149 | D21: =D15*q_snio -> 8.6022429 | E21: =E15*q_snio -> 9.032355 | F21: =SUM(C21:E21) -> 31.133747 | G21: Derived | H21: — | I21: —
A22: 合併淨利（含非控制權益） | B22: =B20+B19 -> 58.0788 | C22: =C20+C19 -> 42.583149 | D22: =D20+D19 -> 31.358841 | E22: =E20+E19 -> 32.926783 | F22: =SUM(C22:E22) -> 106.86877 | G22: Derived | H22: — | I22: —
A23: 股數（十億股；加權） | B23: =27.408/9.04 -> 3.0318584 | C23: =24.458/7.78 -> 3.1437018 | D23: =q_sh3 -> 3.2370652 | E23: =q_sh4 -> 3.43 | F23: =(2*C23+D23+E23)/4 -> 3.2386172 | G23: Derived | H23: FY2025：stockanalysis 財報頁、優分析 2026-03-12；1H26：鉅亨、優分析 2026-08-04（2Q26 法說） | I23: 淨利 ÷ EPS；3Q 起含 GDR 2.5 億股
A24: EPS | B24: =B20/B23 -> 9.04 | C24: =C20/C23 -> 7.78 | D24: =D20/D23 -> 5.3063278 | E24: =E20/E23 -> 5.2582436 | F24: =F20/F23 -> 18.424748 | G24: Derived | H24: 淨利 ÷ 股數 | I24: —
A25: 公司揭露 EPS | B25: 9.04 | C25: 7.78 | G25: Verified | H25: FY2025：stockanalysis 財報頁、優分析 2026-03-12；1H26：鉅亨、優分析 2026-08-04（2Q26 法說） | I25: 1Q26 3.06、2Q26 4.72
A26: FY2026 營收拆分（緯創本體與緯穎；FY2025 拆分未找到）
A27: 緯創本體：GPU 基板與運算板 | F27: =brd_26 -> 110 | G27: Interested-party | H27: 凱基：AI 伺服器零組件超過千億 | I27: —
A28: 緯創本體：一般伺服器與交換器 | F28: =gen_26 -> 150 | G28: Assumed | H28: — | I28: —
A29: 緯創本體：非伺服器（筆電、桌機、顯示器等） | F29: =F4*nsv_26 -> 614.60279 | G29: Interested-party | H29: 凱基：伺服器 85% | I29: —
A30: 緯創本體：AI 系統（L10／L11；殘差） | F30: =F13-F27-F28-F29 -> 1777.1223 | G30: Derived | H30: 本體營收 − 基板 − 一般伺服器 − 非伺服器 | I30: 公司未揭露：未找到
A31: 緯穎：AI 伺服器 | F31: =F10*wai_26 -> 693.90091 | G31: Interested-party | H31: 緯穎：略高於 50% | I31: —
A32: 緯穎：非 AI（一般伺服器） | F32: =F10-F31 -> 751.72599 | G32: Derived | H32: — | I32: —
A34: FY2026 錨點的檢查（參考；校準未使用券商數字）
A35: FY2026 合併營收年增 | B35: =F4/B4-1 -> 0.87391212
A36: FY2026 緯穎營收年增 | B36: =F10/B10-1 -> 0.52065127
A37: FY2026 本體營收年增 | B37: =F13/B13-1 -> 1.1456517
A38: FY2026 本體營業費用年增 | B38: =F16/B16-1 -> 0.14910279
A39: 本體營業費用彈性（費用年增 ÷ 營收年增；In 頁 phi 的依據） | B39: =B38/B37 -> 0.13014671
A40: FY2026 營收 ÷ 共識 − 1 | B40: =F4/cons_rev26-1 -> -0.00064586483
A41: FY2026 EPS ÷ 共識 − 1 | B41: =F24/cons_eps26-1 -> 0.078101093
...

Sheet Units
A1: Units — AI 伺服器組裝市場（與廣達模型同口徑）、緯創本體與緯穎份額、GPU 基板（情境 A）。部署 GW＝AI IT 資本支出（markets/network）÷ 每 GW IT 資本支出（Tokenomics，經橋接表）；ODM 每櫃價格讀廣達模型
A3: 項目 | B3: 單位 | C3: CY2026 | D3: CY2027 | E3: CY2028 | F3: CY2029 | G3: 說明
A4: 部署 GW（情境 A） | B4: GW | C4: =PL!D65 -> 23.399538 | D4: =PL!E65 -> 41.646766 | E4: =PL!F65 -> 52.792138 | F4: =PL!G65 -> 60.138592 | G4: AI IT 資本支出 ÷ 每 GW IT 資本支出
A5: AI 伺服器組裝市場（ODM 價） | B5: US$B | C5: =PL!D67 -> 634.61653 | D5: =PL!E67 -> 1139.0807 | E5: =PL!F67 -> 1443.9178 | F5: =PL!G67 -> 1644.8506 | G5: 含 ASIC 機架（假設每 GW 價值相同；廣達模型口徑）
A6: 緯創本體 AI 系統有效份額（金額口徑） | B6: % | C6: =PL!D72 -> 0.08750965 | D6: =PL!E72 -> 0.08750965 | E6: =PL!F72 -> 0.083134168 | F6: =PL!G72 -> 0.078758685 | G6: FY2026 以本體營收殘差校準
A7: 緯穎 AI 有效份額 | B7: % | C7: =PL!D86 -> 0.034169301 | D7: =PL!E86 -> 0.034169301 | E7: =PL!F86 -> 0.034169301 | F7: =PL!G86 -> 0.032460836 | G7: 緯穎 AI 約九成為 ASIC（AWS Trainium 等）
A8: 緯創合併 AI 系統份額（本體＋緯穎） | B8: % | C8: =C6+C7 -> 0.12167895 | D8: =D6+D7 -> 0.12167895 | E8: =E6+E7 -> 0.11730347 | F8: =F6+F7 -> 0.11121952
A9: 廣達有效份額（廣達模型 Units，唯讀） | B9: % | C9: 0.13389612 | D9: 0.13389612 | E9: 0.12720132 | F9: 0.12050651 | G9: 來源：quanta/dist/20261030_廣達個股模型_v0.3.1.xlsx｜Units!C7:F7
A10: 鴻海有效份額（鴻海模型 Units，唯讀） | B10: % | C10: 0.17461006 | D10: 0.17461006 | E10: 0.17461006 | F10: 0.16587955 | G10: 來源：foxconn/dist/20261030_鴻海個股模型_v0.3.1.xlsx｜Units!C7:F7
A11: 鴻海＋廣達＋緯創（含緯穎）合計有效份額 | B11: % | C11: =C8+C9+C10 -> 0.43018513 | D11: =D8+D9+D10 -> 0.43018513 | E11: =E8+E9+E10 -> 0.41911484 | F11: =F8+F9+F10 -> 0.39760559 | G11: 其餘為英業達、Dell、Supermicro、ASIC 自有組裝等
A12: 緯創本體 AI 系統營收 | B12: US$B | C12: =PL!D75/fx -> 55.535071 | D12: =PL!E75/fx -> 89.712498 | E12: =PL!F75/fx -> 96.031122 | F12: =PL!G75/fx -> 97.159704 | G12: 扣除客供
A13: 隱含本體出貨櫃數（NVL72 等值） | B13: 千櫃 | C13: =PL!D98 -> 12.059733 | D13: =PL!E98 -> 14.767489 | E13: =PL!F98 -> 17.783541 | F13: =PL!G98 -> 19.19204 | G13: 毛額價值 ÷ ODM 每櫃價格
A14: GPU 顆數（NVIDIA＋AMD） | B14: 百萬顆 | C14: =PL!D77 -> 8.35 | D14: =PL!E77 -> 11.2 | E14: =PL!F77 -> 11.5 | F14: =PL!G77 -> 12.9 | G14: tsmc 成品 In 頁
A15: 每顆 GPU 基板金額 | B15: US$／顆 | C15: =PL!D79 -> 823.35329 | D15: =PL!E79 -> 946.85629 | E15: =PL!F79 -> 988.02395 | F15: =PL!G79 -> 988.02395 | G15: FY2026 校準；份額 50% 為 Assumed
A16: GPU 基板與運算板營收 | B16: US$B | C16: =PL!D80/fx -> 3.4375 | D16: =PL!E80/fx -> 5.3023952 | E16: =PL!F80/fx -> 5.3970808 | F16: =PL!G80/fx -> 5.735479 | G16: 顆數 × 份額 × 每顆金額
A17: 緯穎 AI 伺服器營收 | B17: US$B | C17: =PL!D87/fx -> 21.684403 | D17: =PL!E87/fx -> 38.921591 | E17: =PL!F87/fx -> 49.337661 | F17: =PL!G87/fx -> 53.393227
A19: 讀法：有效份額為金額口徑（分母為全部 AI IT 資本支出換算的組裝市場，含 ASIC、HGX 與其他組裝廠），低於櫃數份額。GPU 基板只對應 NVIDIA 與 AMD 的 GPU 顆數；基板份額與每顆金額是 Assumed，FY2026 金額取券商說法。緯穎以 ASIC 機架為主，所以份額跟著 ASIC 部署走。

Sheet PL
A1: PL — 緯創損益（十億新台幣；EPS 新台幣）。營收、毛利、營業利益為合併（含緯穎）；EPS 用歸屬母公司淨利。FY2025A 實績、FY2026 錨點（三情境相同），FY2027 起為模型。FY(t)＝CY(t)。三情境各一個完整推導區塊（本頁下方），頂端為摘要
A2: 灰底＝FY2030–FY2032 收斂法（上游只到 2029）：營收年增線性收斂到 fade_g、淨利率（歸屬母公司淨利 ÷ 合併營收）線性收斂到 fade_m（In 頁 J 節），非驅動因子推導
A3: 情境／項目 | B3: 單位 | C3: FY2025A | D3: FY2026（錨點） | E3: FY2027 | F3: FY2028 | G3: FY2029 | H3: FY2030（收斂） | I3: FY2031（收斂） | J3: FY2032（收斂） | K3: 說明
A4: 情境 A
A5: 合併營收 | B5: NT$B | C5: =C90 -> 2186.523 | D5: =D90 -> 4097.352 | E5: =E90 -> 5889.0308 | F5: =F90 -> 6495.1849 | G5: =G90 -> 6731.572 | H5: =H90 -> 7029.5302 | I5: =I90 -> 7395.9895 | J5: =J90 -> 7839.7488
A6: 營收年增 | B6: % | D6: =D95 -> 0.87391212 | E6: =E95 -> 0.43727726 | F6: =F95 -> 0.10292934 | G6: =G95 -> 0.036394206 | H6: =H95 -> 0.044262804 | I6: =I95 -> 0.052131402 | J6: =J95 -> 0.06
A7: 本體 AI 系統 | B7: NT$B | D7: =D75 -> 1777.1223 | E7: =E75 -> 2870.7999 | F7: =F75 -> 3072.9959 | G7: =G75 -> 3109.1105
A8: GPU 基板與運算板 | B8: NT$B | D8: =D80 -> 110 | E8: =E80 -> 169.67665 | F8: =F80 -> 172.70659 | G8: =G80 -> 183.53533
A9: 緯穎 | B9: NT$B | C9: =C89 -> 950.663 | D9: =D89 -> 1445.6269 | E9: =E89 -> 2072.3895 | F9: =F89 -> 2455.3177 | G9: =G89 -> 2628.9214
A10: 合併毛利率 | B10: % | C10: =C116 -> 0.061276739 | D10: =D116 -> 0.055781974 | E10: =E116 -> 0.055211978 | F10: =F116 -> 0.058222361 | G10: =G116 -> 0.059930432
A11: 合併營業利益率 | B11: % | C11: =C118 -> 0.035925988 | D11: =D118 -> 0.037771258 | E11: =E118 -> 0.039142734 | F11: =F118 -> 0.04232997 | G11: =G118 -> 0.044042849
A12: 合併淨利（含非控制權益） | B12: NT$B | C12: =C119 -> 58.0788 | D12: =D119 -> 106.86877 | E12: =E119 -> 158.72232 | F12: =F119 -> 189.07799 | G12: =G119 -> 203.62104
A13: 歸屬母公司淨利 | B13: NT$B | C13: =C121 -> 27.408 | D13: =D121 -> 59.670705 | E13: =E121 -> 93.242604 | F13: =F121 -> 111.49918 | G13: =G121 -> 120.557 | H13: =H121 -> 125.8932 | I13: =I121 -> 132.45618 | J13: =J121 -> 140.40356
A14: 淨利率 | B14: % | C14: =C126 -> 0.01253497 | D14: =D126 -> 0.014563236 | E14: =E126 -> 0.015833268 | F14: =F126 -> 0.017166437 | G14: =G126 -> 0.017909191 | H14: =H126 -> 0.017909191 | I14: =I126 -> 0.017909191 | J14: =J126 -> 0.017909191
A15: EPS | B15: NT$ | C15: =C124 -> 9.04 | D15: =D124 -> 18.424748 | E15: =E124 -> 27.184433 | F15: =F124 -> 32.507051 | G15: =G124 -> 35.147815 | H15: =H124 -> 36.703556 | I15: =I124 -> 38.616963 | J15: =J124 -> 40.933981
A16: EPS 年增 | B16: % | D16: =D125 -> 1.0381358 | E16: =E125 -> 0.47543038 | F16: =F125 -> 0.19579656 | G16: =G125 -> 0.081236649 | H16: =H125 -> 0.044262804 | I16: =I125 -> 0.052131402 | J16: =J125 -> 0.06
A18: 情境 B
A19: 合併營收 | B19: NT$B | C19: =C159 -> 2186.523 | D19: =D159 -> 4097.352 | E19: =E159 -> 5889.0308 | F19: =F159 -> 5530.2833 | G19: =G159 -> 5981.3876 | H19: =H159 -> 6386.4066 | I19: =I159 -> 6730.3568 | J19: =J159 -> 6999.5711
A20: 營收年增 | B20: % | D20: =D164 -> 0.87391212 | E20: =E164 -> 0.43727726 | F20: =F164 -> -0.060917912 | G20: =G164 -> 0.081569828 | H20: =H164 -> 0.067713219 | I20: =I164 -> 0.053856609 | J20: =J164 -> 0.04
A21: 本體 AI 系統 | B21: NT$B | D21: =D144 -> 1777.1223 | E21: =E144 -> 2870.7999 | F21: =F144 -> 2458.3967 | G21: =G144 -> 2642.744
A22: GPU 基板與運算板 | B22: NT$B | D22: =D149 -> 110 | E22: =E149 -> 169.67665 | F22: =F149 -> 138.16527 | G22: =G149 -> 156.00503
A23: 緯穎 | B23: NT$B | C23: =C158 -> 950.663 | D23: =D158 -> 1445.6269 | E23: =E158 -> 2072.3895 | F23: =F158 -> 2139.5566 | G23: =G158 -> 2372.6339
A24: 合併毛利率 | B24: % | C24: =C185 -> 0.061276739 | D24: =D185 -> 0.055781974 | E24: =E185 -> 0.055211978 | F24: =F185 -> 0.058759839 | G24: =G185 -> 0.060258617
A25: 合併營業利益率 | B25: % | C25: =C187 -> 0.035925988 | D25: =D187 -> 0.037771258 | E25: =E187 -> 0.039142734 | F25: =F187 -> 0.041405284 | G25: =G187 -> 0.043262042
A26: 合併淨利（含非控制權益） | B26: NT$B | C26: =C188 -> 58.0788 | D26: =D188 -> 106.86877 | E26: =E188 -> 158.72232 | F26: =F188 -> 158.82611 | G26: =G188 -> 178.83821
A27: 歸屬母公司淨利 | B27: NT$B | C27: =C190 -> 27.408 | D27: =D190 -> 59.670705 | E27: =E190 -> 93.242604 | F27: =F190 -> 91.224167 | G27: =G190 -> 103.8719 | H27: =H190 -> 107.20855 | I27: =I190 -> 109.0865 | J27: =J190 -> 109.39817
A28: 淨利率 | B28: % | C28: =C195 -> 0.01253497 | D28: =D195 -> 0.014563236 | E28: =E195 -> 0.015833268 | F28: =F195 -> 0.016495388 | G28: =G195 -> 0.017365853 | H28: =H195 -> 0.016786991 | I28: =I195 -> 0.01620813 | J28: =J195 -> 0.015629268
A29: EPS | B29: NT$ | C29: =C193 -> 9.04 | D29: =D193 -> 18.424748 | E29: =E193 -> 27.184433 | F29: =F193 -> 26.595967 | G29: =G193 -> 30.283352 | H29: =H193 -> 31.256138 | I29: =I193 -> 31.803643 | J29: =J193 -> 31.894511
A30: EPS 年增 | B30: % | D30: =D194 -> 1.0381358 | E30: =E194 -> 0.47543038 | F30: =F194 -> -0.021647154 | G30: =G194 -> 0.13864454 | H30: =H194 -> 0.032122778 | I30: =I194 -> 0.017516726 | J30: =J194 -> 0.0028571429
A32: 情境 C
A33: 合併營收 | B33: NT$B | C33: =C228 -> 2186.523 | D33: =D228 -> 4097.352 | E33: =E228 -> 5889.0308 | F33: =F228 -> 4565.3818 | G33: =G228 -> 4731.0803 | H33: =H228 -> 4877.0958 | I33: =I228 -> 5001.1278 | J33: =J228 -> 5101.1503
A34: 營收年增 | B34: % | D34: =D233 -> 0.87391212 | E34: =E233 -> 0.43727726 | F34: =F233 -> -0.22476517 | G34: =G233 -> 0.036294557 | H34: =H233 -> 0.030863038 | I34: =I233 -> 0.025431519 | J34: =J233 -> 0.02
A35: 本體 AI 系統 | B35: NT$B | D35: =D213 -> 1777.1223 | E35: =E213 -> 2870.7999 | F35: =F213 -> 1843.7975 | G35: =G213 -> 1865.4663
A36: GPU 基板與運算板 | B36: NT$B | D36: =D218 -> 110 | E36: =E218 -> 169.67665 | F36: =F218 -> 103.62395 | G36: =G218 -> 110.1212
A37: 緯穎 | B37: NT$B | C37: =C227 -> 950.663 | D37: =D227 -> 1445.6269 | E37: =E227 -> 2072.3895 | F37: =F227 -> 1823.7956 | G37: =G227 -> 1945.4881
A38: 合併毛利率 | B38: % | C38: =C254 -> 0.061276739 | D38: =D254 -> 0.055781974 | E38: =E254 -> 0.055211978 | F38: =F254 -> 0.059524512 | G38: =G254 -> 0.061036876
A39: 合併營業利益率 | B39: % | C39: =C256 -> 0.035925988 | D39: =D256 -> 0.037771258 | E39: =E256 -> 0.039142734 | F39: =F256 -> 0.039885324 | G39: =G256 -> 0.041516948
A40: 合併淨利（含非控制權益） | B40: NT$B | C40: =C257 -> 58.0788 | D40: =D257 -> 106.86877 | E40: =E257 -> 158.72232 | F40: =F257 -> 128.05165 | G40: =G257 -> 137.81569
A41: 歸屬母公司淨利 | B41: NT$B | C41: =C259 -> 27.408 | D41: =D259 -> 59.670705 | E41: =E259 -> 93.242604 | F41: =F259 -> 70.426563 | G41: =G259 -> 76.34558 | H41: =H259 -> 73.455047 | I41: =I259 -> 69.942898 | J41: =J259 -> 65.853928
A42: 淨利率 | B42: % | C42: =C264 -> 0.01253497 | D42: =D264 -> 0.014563236 | E42: =E264 -> 0.015833268 | F42: =F264 -> 0.015426215 | G42: =G264 -> 0.016137029 | H42: =H264 -> 0.015061227 | I42: =I264 -> 0.013985425 | J42: =J264 -> 0.012909623
...

Sheet Val
A1: Val — P/E 估值（新台幣；EPS 為歸屬母公司）。結論用「現價 ÷ FY2027、FY2028 EPS（模型）」；目標價＝DCF 與 Comparable 加權（第 0 節）；十年 P/E 規則值（第 3 節，年底落後 P/E）只作參考
A2: 循環位置：緯創不是設備股，不套設備市場見頂年；以本模型營收最高的會計年度為見頂年（比照廣達、鴻海、NVIDIA；FY(t)＝CY(t)）。營收到 FY2029 仍在增加時，見頂年未知，判為中段
A4: 0. 目標價
A5: 0.1 DCF（股東權益現金流，FY2027–FY2032 明確期＋FY2032 後永續）
A6: 項目 | B6: A（順利） | C6: B（平平） | D6: C（不如預期） | E6: 說明
A7: 情境 EPS（FY2027–FY2032） | E7: PL 頁各情境（歸屬母公司 EPS）；FY2030 起為收斂法
A8: FY2027 | B8: =PL!E15 -> 27.184433 | C8: =PL!E29 -> 27.184433 | D8: =PL!E43 -> 27.184433
A9: FY2028 | B9: =PL!F15 -> 32.507051 | C9: =PL!F29 -> 26.595967 | D9: =PL!F43 -> 20.532526
A10: FY2029 | B10: =PL!G15 -> 35.147815 | C10: =PL!G29 -> 30.283352 | D10: =PL!G43 -> 22.258187
A11: FY2030 | B11: =PL!H15 -> 36.703556 | C11: =PL!H29 -> 31.256138 | D11: =PL!H43 -> 21.415466
A12: FY2031 | B12: =PL!I15 -> 38.616963 | C12: =PL!I29 -> 31.803643 | D12: =PL!I43 -> 20.391515
A13: FY2032 | B13: =PL!J15 -> 40.933981 | C13: =PL!J29 -> 31.894511 | D13: =PL!J43 -> 19.199396
A14: 股東現金流＝EPS ×（1 − tp_g ÷ tp_roe）
A15: 再投資率（tp_g ÷ tp_roe，上限 0.8） | B15: =MIN(tp_g/tp_roe,0.8) -> 0.19851117 | E15: ROE 為近三年平均（In 頁 tp_roe）
A16: FY2027 | B16: =B8*(1-$B$15) -> 21.788019 | C16: =C8*(1-$B$15) -> 21.788019 | D16: =D8*(1-$B$15) -> 21.788019
A17: FY2028 | B17: =B9*(1-$B$15) -> 26.054038 | C17: =C9*(1-$B$15) -> 21.316371 | D17: =D9*(1-$B$15) -> 16.45659
A18: FY2029 | B18: =B10*(1-$B$15) -> 28.170581 | C18: =C10*(1-$B$15) -> 24.271769 | D18: =D10*(1-$B$15) -> 17.839688
A19: FY2030 | B19: =B11*(1-$B$15) -> 29.41749 | C19: =C11*(1-$B$15) -> 25.051445 | D19: =D11*(1-$B$15) -> 17.164257
A20: FY2031 | B20: =B12*(1-$B$15) -> 30.951065 | C20: =C12*(1-$B$15) -> 25.490265 | D20: =D12*(1-$B$15) -> 16.343572
A21: FY2032 | B21: =B13*(1-$B$15) -> 32.808129 | C21: =C13*(1-$B$15) -> 25.563094 | D21: =D13*(1-$B$15) -> 15.388102
A22: DCF 情境每股價值（折現率 tp_r） | B22: =SUMPRODUCT(B16:B21,1/(1+tp_r)^{1;2;3;4;5;6})+B21*(1+tp_g)/(tp_r-tp_g)/(1+tp_r)^6 -> 441.33636 | C22: =SUMPRODUCT(C16:C21,1/(1+tp_r)^{1;2;3;4;5;6})+C21*(1+tp_g)/(tp_r-tp_g)/(1+tp_r)^6 -> 353.14229 | D22: =SUMPRODUCT(D16:D21,1/(1+tp_r)^{1;2;3;4;5;6})+D21*(1+tp_g)/(tp_r-tp_g)/(1+tp_r)^6 -> 227.92916 | E22: Σ 明確期現金流 ÷ (1＋r)^t ＋ 永續價值 ÷ (1＋r)^6；永續價值＝FY2032 現金流 ×(1＋g)÷(r−g)；基準日 2026 年底
A23: DCF 情境價值推到 12 個月後（×(1＋tp_r)） | B23: =B22*(1+tp_r) -> 485.46999 | C23: =C22*(1+tp_r) -> 388.45652 | D23: =D22*(1+tp_r) -> 250.72208
A24: DCF 目標價（情境加權） | B24: =tp_wA*B23+tp_wB*C23+tp_wC*D23 -> 390.01367 | E24: Σ 權重 × 情境價值 ×(1＋r)；權重見 In 頁
A26: 0.2 Comparable（市場主流同業前瞻 P/E）
A27: 同業與前瞻 P/E | B27: 代號 | C27: 前瞻 12 月 P/E | D27: 日期 | E27: 來源 | F27: 標記
A28: 廣達（Quanta） | B28: 2382.TW | C28: 11.31 | D28: 2026-10-14 | E28: stockanalysis.com forward PE（分析師共識；價格日期如左） | F28: Interested-party
A29: 鴻海（Hon Hai） | B29: 2317.TW | C29: 11.37 | D29: 2026-10-19 | E29: stockanalysis.com forward PE（分析師共識；價格日期如左） | F29: Interested-party
A30: 英業達（Inventec） | B30: 2356.TW | C30: 18 | D30: 2026-08-14 | E30: stockanalysis.com forward PE（分析師共識；價格日期如左） | F30: Interested-party
A31: 緯穎（Wiwynn；緯創子公司） | B31: 6669.TW | C31: 13.87 | D31: 2026-10-02 | E31: stockanalysis.com forward PE（分析師共識；價格日期如左） | F31: Interested-party
A32: 美超微（Supermicro） | B32: SMCI | C32: 7.06 | D32: 2026-10-23 | E32: stockanalysis.com forward PE（分析師共識；價格日期如左） | F32: Interested-party
A33: 同業前瞻 P/E 中位數 | B33: =MEDIAN(C28:C32) -> 11.37 | E33: 伺服器 ODM 同業：廣達、鴻海、英業達、緯穎、美超微（券商常用比較組；不含 A 股）
A34: 12 個月後的前瞻 EPS（情境加權） | B34: =tp_wA*(2/12*B8+10/12*B9)+tp_wB*(2/12*C8+10/12*C9)+tp_wC*(2/12*D8+10/12*D9) -> 27.161242 | E34: 約 2027-10 時的未來 12 月 EPS ≈ 2／12 × FY2027＋10／12 × FY2028（會計年度＝日曆年）
A35: Comparable 目標價 | B35: =B33*B34 -> 308.82332 | E35: 同業中位數 × 前瞻 EPS
A37: 0.3 結論
A38: 項目 | B38: 數值 | E38: 說明
A39: 目標價（DCF 與 Comparable 加權） | B39: =tp_w_dcf*B24+(1-tp_w_dcf)*tp_comp_adj -> 332.77339 | E39: tp_w_dcf × DCF＋（1 − tp_w_dcf）× Comparable；tp_w_dcf 見 In 頁（0.5）
A40: Comparable 目標價（市場主流同業法） | B40: =B35 -> 308.82332
A41: 市場共識目標價 | B41: =cons_tp -> 268.71 | E41: stockanalysis：17 位分析師平均 268.71（中位數 275、區間 165–400），2026-09-16 擷取
A42: 上檔空間：加權目標價 | B42: =B39/px-1 -> 0.75143888 | E42: 現價＝In 頁 px（2026-10-22 收盤）
A43: 上檔空間：Comparable 目標價 | B43: =B40/px-1 -> 0.6253859
...

Sheet Recon
A1: Recon — 本模型 vs 共識、券商估計與櫃數調查。只作事後對照，不為對上數字而調參數。券商多未具名或單一來源；共識 FY2027（付費）未找到
A3: 項目 | B3: 對照值 | C3: 模型 A | D3: 差距 A | E3: 模型 B | F3: 差距 B | G3: 模型 C | H3: 差距 C | I3: 對照來源 | J3: 說明
A4: A. 共識與券商估計（校準未使用）
A5: FY2026 營收 vs 共識 | B5: =cons_rev26 -> 4100 | C5: =PL!D90 -> 4097.352 | D5: =C5/B5-1 -> -0.00064586483 | E5: =PL!D159 -> 4097.352 | F5: =E5/B5-1 -> -0.00064586483 | G5: =PL!D228 -> 4097.352 | H5: =G5/B5-1 -> -0.00064586483 | I5: stockanalysis（7 家，09-16）
A6: FY2026 EPS vs 共識 | B6: =cons_eps26 -> 17.09 | C6: =PL!D124 -> 18.424748 | D6: =C6/B6-1 -> 0.078101093 | E6: =PL!D193 -> 18.424748 | F6: =E6/B6-1 -> 0.078101093 | G6: =PL!D262 -> 18.424748 | H6: =G6/B6-1 -> 0.078101093 | I6: stockanalysis（7 家，09-16） | J6: 3Q 營收創高後，共識可能上修
A7: FY2026 EPS vs 凱基（05-08，2Q 前） | B7: =k_eps26 -> 13.96 | C7: =PL!D124 -> 18.424748 | D7: =C7/B7-1 -> 0.31982433 | E7: =PL!D193 -> 18.424748 | F7: =E7/B7-1 -> 0.31982433 | G7: =PL!D262 -> 18.424748 | H7: =G7/B7-1 -> 0.31982433 | I7: 凱基 2026-05-08
A8: FY2027 EPS vs 法人下限說法（20 元以上） | B8: =b_eps27 -> 20 | C8: =PL!E124 -> 27.184433 | D8: =C8/B8-1 -> 0.35922163 | E8: =PL!E193 -> 27.184433 | F8: =E8/B8-1 -> 0.35922163 | G8: =PL!E262 -> 27.184433 | H8: =G8/B8-1 -> 0.35922163 | I8: 旺得富 2026-08-10（未具名）
A9: FY2027 EPS vs 法人樂觀說法中點（23.3–26.4） | B9: =b_eps27h -> 24.85 | C9: =PL!E124 -> 27.184433 | D9: =C9/B9-1 -> 0.093940948 | E9: =PL!E193 -> 27.184433 | F9: =E9/B9-1 -> 0.093940948 | G9: =PL!E262 -> 27.184433 | H9: =G9/B9-1 -> 0.093940948 | I9: 旺得富 2026-08-10（未具名）
A10: FY2027 EPS vs 凱基（05-08） | B10: =k_eps27 -> 18.29 | C10: =PL!E124 -> 27.184433 | D10: =C10/B10-1 -> 0.4863003 | E10: =PL!E193 -> 27.184433 | F10: =E10/B10-1 -> 0.4863003 | G10: =PL!E262 -> 27.184433 | H10: =G10/B10-1 -> 0.4863003 | I10: 凱基 2026-05-08 | J10: 2Q 財報前，偏舊
A11: FY2027 營收年增（模型） | C11: =PL!E95 -> 0.43727726 | E11: =PL!E164 -> 0.43727726 | G11: =PL!E233 -> 0.43727726 | I11: —
A12: B. 緯穎（子公司）vs 凱基緯穎報告
A13: FY2026 緯穎營收 vs 凱基（07-28） | B13: =kw_rev26 -> 1361.998 | C13: =PL!D89 -> 1445.6269 | D13: =C13/B13-1 -> 0.061401632 | E13: =PL!D158 -> 1445.6269 | F13: =E13/B13-1 -> 0.061401632 | G13: =PL!D227 -> 1445.6269 | H13: =G13/B13-1 -> 0.061401632 | I13: 凱基 2026-07-28 | J13: 3Q26 緯穎月營收大增，高於凱基
A14: FY2027 緯穎營收 vs 凱基 | B14: =kw_rev27 -> 2368.079 | C14: =PL!E89 -> 2072.3895 | D14: =C14/B14-1 -> -0.12486471 | E14: =PL!E158 -> 2072.3895 | F14: =E14/B14-1 -> -0.12486471 | G14: =PL!E227 -> 2072.3895 | H14: =G14/B14-1 -> -0.12486471 | I14: 凱基 2026-07-28
A15: FY2027 緯穎淨利 vs 凱基 | B15: =kw_ni27 -> 105.263 | C15: =PL!E112 -> 105.07015 | D15: =C15/B15-1 -> -0.001832094 | E15: =PL!E181 -> 105.07015 | F15: =E15/B15-1 -> -0.001832094 | G15: =PL!E250 -> 105.07015 | H15: =G15/B15-1 -> -0.001832094 | I15: 凱基 2026-07-28
A16: FY2027 緯穎對歸屬母公司淨利的貢獻比重（模型） | C16: =PL!E122 -> 0.42459595 | E16: =PL!E191 -> 0.42459595 | G16: =PL!E260 -> 0.42459595 | I16: — | J16: 持股 37.68% × 緯穎淨利 ÷ 歸屬母公司淨利
A17: C. 櫃數與份額（機制檢查）
A18: FY2026 隱含本體出貨櫃數 vs 凱基 GB＋VR 約 1.5 萬櫃（千櫃） | B18: =k_racks -> 15 | C18: =PL!D98 -> 12.059733 | D18: =C18/B18-1 -> -0.1960178 | E18: =PL!D167 -> 12.059733 | F18: =E18/B18-1 -> -0.1960178 | G18: =PL!D236 -> 12.059733 | H18: =G18/B18-1 -> -0.1960178 | I18: 凱基 2026-05-08 | J18: 本體 AI 系統營收為殘差；凱基口徑（L10 是否含 GPU）不明
A19: FY2026 本體有效份額 vs 三家 ODM 中緯創的 NVL72 櫃數份額（百分點） | B19: =rk_sh -> 0.31438127 | C19: =PL!D70 -> 0.08750965 | D19: =C19-B19 -> -0.22687162 | E19: =PL!D139 -> 0.08750965 | F19: =E19-B19 -> -0.22687162 | G19: =PL!D208 -> 0.08750965 | H19: =G19-B19 -> -0.22687162 | I19: 經濟日報 2026-09-10（美系券商） | J19: 口徑不同：本模型分母為全部 AI 組裝市場
A20: 8 月調查年化櫃數（2,300–2,400 × 12；千櫃）vs 隱含本體櫃數 | B20: =2.35*12 -> 28.2 | C20: =PL!D98 -> 12.059733 | D20: =C20/B20-1 -> -0.57234989 | E20: =PL!D167 -> 12.059733 | F20: =E20/B20-1 -> -0.57234989 | G20: =PL!D236 -> 12.059733 | H20: =G20/B20-1 -> -0.57234989 | I20: 經濟日報 2026-09-10 | J20: 調查可能含緯穎或運算托盤口徑
A21: FY2026 GPU 基板營收 vs 凱基「超過千億」（NT$B） | B21: 100 | C21: =PL!D80 -> 110 | D21: =C21/B21-1 -> 0.1 | E21: =PL!D149 -> 110 | F21: =E21/B21-1 -> 0.1 | G21: =PL!D218 -> 110 | H21: =G21/B21-1 -> 0.1 | I21: 凱基 2026-05-08 | J21: 校準值（brd_26 取 110）
A22: FY2026 本體一般伺服器與交換器 vs 凱基交換器 160–180 億（NT$B） | B22: 17 | C22: =PL!D82 -> 150 | D22: =C22/B22-1 -> 7.8235294 | E22: =PL!D151 -> 150 | F22: =E22/B22-1 -> 7.8235294 | G22: =PL!D220 -> 150 | H22: =G22/B22-1 -> 7.8235294 | I22: 凱基 2026-05-08 | J22: 本模型含一般伺服器（Assumed）
A23: D. 合併與歸母
A24: FY2026 非控制權益 ÷ 合併淨利 | C24: =PL!D120/PL!D119 -> 0.44164509 | E24: =PL!D189/PL!D188 -> 0.44164509 | G24: =PL!D258/PL!D257 -> 0.44164509 | I24: — | J24: 合併淨利約四成歸緯穎的少數股東
A25: FY2027 緯穎 ÷ 合併營收 | C25: =PL!E97 -> 0.35190672 | E25: =PL!E166 -> 0.35190672 | G25: =PL!E235 -> 0.35190672 | I25: —
A26: 4Q26 EPS（模型） | C26: =Q!E24 -> 5.2582436 | E26: =Q!E24 -> 5.2582436 | G26: =Q!E24 -> 5.2582436 | I26: —
A27: E. 預留
A28: R4 產業部署路徑（markets/deploy_path/，尚未建立）：上線後以部署路徑取代「AI IT 資本支出 ÷ 每 GW IT 資本支出」 | J28: 預留列：本版無數值

Sheet Sens
A1: Sens — 一次動一個輸入（情境 A；FY2026 恆等於錨點，份額與本體毛利率在每個案例內依錨點重算）：對 FY2027、FY2028 合併營收、合併毛利率與 EPS 的影響。每個案例是一個完整推導區塊（本頁下方）
A3: 案例 | B3: 設定 | C3: FY2027 營收 | D3: FY2027 毛利率 | E3: FY2027 EPS | F3: FY2027 EPS 相對基準 | G3: FY2028 營收 | H3: FY2028 毛利率 | I3: FY2028 EPS | J3: FY2028 EPS 相對基準
A4: 基準（情境 A） | B4: PL 區塊 A | C4: =PL!E90 -> 5889.0308 | D4: =PL!E116 -> 0.055211978 | E4: =PL!E124 -> 27.184433 | F4: =E4/E$4-1 -> 0 | G4: =PL!F90 -> 6495.1849 | H4: =PL!F116 -> 0.058222361 | I4: =PL!F124 -> 32.507051 | J4: =I4/I$4-1 -> 0
A5: AI 部署 ×0.8 | B5: FY2027 起 AI IT 資本支出與 GPU 顆數 ×0.8 | C5: =E70 -> 5031.8373 | D5: =E96 -> 0.055941404 | E5: =E104 -> 22.654062 | F5: =E5/E$4-1 -> -0.16665312 | G5: =F70 -> 5530.2833 | H5: =F96 -> 0.058759839 | I5: =F104 -> 26.984858 | J5: =I5/I$4-1 -> -0.16987678
A6: AI 部署 ×1.2 | B6: ×1.2 | C6: =E139 -> 6746.2243 | D6: =E165 -> 0.054667917 | E6: =E173 -> 31.714803 | F6: =E6/E$4-1 -> 0.16665312 | G6: =F139 -> 7460.0864 | H6: =F165 -> 0.05782392 | I6: =F173 -> 38.03 | J6: =I6/I$4-1 -> 0.16990004
A7: 本體份額流失 | B7: 相對值 2027 0.85、2028 0.75、2029 0.70 | C7: =E208 -> 5458.4108 | D7: =E234 -> 0.056821778 | E7: =E242 -> 25.111108 | F7: =E7/E$4-1 -> -0.076268825 | G7: =F208 -> 5848.2384 | H7: =F234 -> 0.060375123 | I7: =F242 -> 28.933908 | J7: =I7/I$4-1 -> -0.10991901
A8: 本體份額上升 | B8: 相對值 1.15 | C8: =E277 -> 6319.6508 | D8: =E303 -> 0.05382156 | E8: =E311 -> 29.257757 | F8: =E8/E$4-1 -> 0.076268825 | G8: =F277 -> 7142.1314 | H8: =F303 -> 0.056459601 | I8: =F311 -> 36.098636 | J8: =I8/I$4-1 -> 0.11048633
A9: 緯穎份額流失 | B9: 相對值 2027 0.85、2028 0.75、2029 0.70 | C9: =E346 -> 5702.2072 | D9: =E372 -> 0.054236021 | E9: =E380 -> 26.143898 | F9: =E9/E$4-1 -> -0.038276859 | G9: =F346 -> 6100.4836 | H9: =F372 -> 0.056489848 | I9: =F380 -> 30.308719 | J9: =I9/I$4-1 -> -0.067626313
A10: 緯穎份額上升 | B10: 相對值 1.2 | C10: =E415 -> 6138.129 | D10: =E441 -> 0.056420838 | E10: =E449 -> 28.571812 | F10: =E10/E$4-1 -> 0.051035812 | G10: =F415 -> 6810.9459 | H10: =F441 -> 0.059463795 | I10: =F449 -> 34.265716 | J10: =I10/I$4-1 -> 0.05410105
A11: 客供 高 | B11: 客供比例 25%／40%／50% | C11: =E484 -> 5410.5641 | D11: =E510 -> 0.05981466 | E11: =E518 -> 27.352547 | F11: =E11/E$4-1 -> 0.0061842111 | G11: =F484 -> 5726.9359 | H11: =F510 -> 0.065608221 | I11: =F518 -> 32.677818 | J11: =I11/I$4-1 -> 0.0052532306
A12: 客供保留毛利 0.7 | B12: 客供部分只保留 70% 毛利 | C12: =E553 -> 5889.0308 | D12: =E579 -> 0.054869197 | E12: =E587 -> 26.854858 | F12: =E12/E$4-1 -> -0.012123647 | G12: =F553 -> 6495.1849 | H12: =F579 -> 0.05747383 | I12: =F587 -> 31.71328 | J12: =I12/I$4-1 -> -0.024418419
A13: 每 GW 價值 低 | B13: 2028–29 每 GW ODM 價值 ×0.85 | C13: =E622 -> 5889.0308 | D13: =E648 -> 0.055211978 | E13: =E656 -> 27.184433 | F13: =E13/E$4-1 -> 0 | G13: =F622 -> 5797.4147 | H13: =F648 -> 0.058675801 | I13: =F656 -> 28.423301 | J13: =I13/I$4-1 -> -0.12562658
A14: 每 GW 價值 高 | B14: ×1.2 | C14: =E691 -> 5889.0308 | D14: =E717 -> 0.055211978 | E14: =E725 -> 27.184433 | F14: =E14/E$4-1 -> 0 | G14: =F691 -> 7425.5451 | H14: =F717 -> 0.057750337 | I14: =F725 -> 37.735714 | J14: =I14/I$4-1 -> 0.16084704
A15: 基板份額 低 | B15: 2027 0.8、2028 0.7、2029 0.65 | C15: =E760 -> 5855.0955 | D15: =E786 -> 0.055105158 | E15: =E794 -> 26.805875 | F15: =E15/E$4-1 -> -0.013925542 | G15: =F760 -> 6449.7358 | H15: =F786 -> 0.058113702 | I15: =F794 -> 31.997117 | J15: =I15/I$4-1 -> -0.01568688
A16: 基板每顆金額 高 | B16: 2027 1.4、2028–29 1.5 | C16: =E829 -> 5925.917 | D16: =E855 -> 0.055326699 | E16: =E863 -> 27.595909 | F16: =E16/E$4-1 -> 0.015136459 | G16: =F829 -> 6538.3615 | H16: =F855 -> 0.058324189 | I16: =F863 -> 32.990792 | J16: =I16/I$4-1 -> 0.01488112
A17: 本體 AI 毛利率差距 −2pt | B17: 基準 −1pt | C17: =E898 -> 5889.0308 | D17: =E924 -> 0.054519733 | E17: =E932 -> 26.518857 | F17: =E17/E$4-1 -> -0.024483686 | G17: =F898 -> 6495.1849 | H17: =F924 -> 0.057308419 | I17: =F932 -> 31.537871 | J17: =I17/I$4-1 -> -0.029814443
A18: 緯穎營益率 5.5% | B18: 基準 6.5% | C18: =E967 -> 5889.0308 | D18: =E993 -> 0.055211978 | E18: =E1001 -> 25.408679 | F18: =E18/E$4-1 -> -0.065322454 | G18: =F967 -> 6495.1849 | H18: =F993 -> 0.058222361 | I18: =F1001 -> 30.40318 | J18: =I18/I$4-1 -> -0.064720445
A19: 緯穎營益率 7.5% | C19: =E1036 -> 5889.0308 | D19: =E1062 -> 0.055211978 | E19: =E1070 -> 28.960186 | F19: =E19/E$4-1 -> 0.065322454 | G19: =F1036 -> 6495.1849 | H19: =F1062 -> 0.058222361 | I19: =F1070 -> 34.610922 | J19: =I19/I$4-1 -> 0.064720445
A20: 本體淨利係數 0.45 | B20: 基準 0.56 | C20: =E1105 -> 5889.0308 | D20: =E1131 -> 0.055211978 | E20: =E1139 -> 24.11189 | F20: =E20/E$4-1 -> -0.1130258 | G20: =F1105 -> 6495.1849 | H20: =F1131 -> 0.058222361 | I20: =F1139 -> 28.80793 | J20: =I20/I$4-1 -> -0.11379443
A21: 本體淨利係數 0.65 | C21: =E1174 -> 5889.0308 | D21: =E1200 -> 0.055211978 | E21: =E1208 -> 29.698331 | F21: =E21/E$4-1 -> 0.092475651 | G21: =F1174 -> 6495.1849 | H21: =F1200 -> 0.058222361 | I21: =F1208 -> 35.533605 | J21: =I21/I$4-1 -> 0.093104535
A22: 緯穎持股 35% | B22: 基準 37.68% | C22: =E1243 -> 5889.0308 | D22: =E1269 -> 0.055211978 | E22: =E1277 -> 26.363476 | F22: =E22/E$4-1 -> -0.0301995 | G22: =F1243 -> 6495.1849 | H22: =F1269 -> 0.058222361 | I22: =F1277 -> 31.534401 | J22: =I22/I$4-1 -> -0.029921182
A23: 本體營業費用率 +0.2pt | B23: 營業費用額外 +0.2% × 本體營收 | C23: =E1312 -> 5889.0308 | D23: =E1338 -> 0.055211978 | E23: =E1346 -> 25.938182 | F23: =E23/E$4-1 -> -0.045844261 | G23: =F1312 -> 6495.1849 | H23: =F1338 -> 0.058222361 | I23: =F1346 -> 29.919793 | J23: =I23/I$4-1 -> -0.079590657
A24: 情境 B | B24: CY2028 顆數 ×0.8、CY2029 ×0.85 | C24: =PL!E159 -> 5889.0308 | D24: =PL!E185 -> 0.055211978 | E24: =PL!E193 -> 27.184433 | F24: =E24/E$4-1 -> 0 | G24: =PL!F159 -> 5530.2833 | H24: =PL!F185 -> 0.058759839 | I24: =PL!F193 -> 26.595967 | J24: =I24/I$4-1 -> -0.18184006
A25: 情境 C | B25: CY2028–29 顆數 ×0.6 | C25: =PL!E228 -> 5889.0308 | D25: =PL!E254 -> 0.055211978 | E25: =PL!E262 -> 27.184433 | F25: =E25/E$4-1 -> 0 | G25: =PL!F228 -> 4565.3818 | H25: =PL!F254 -> 0.059524512 | I25: =PL!F262 -> 20.532526 | J25: =I25/I$4-1 -> -0.36836701
A27: 讀法：FY2027 三情境相同；顆數情境 B、C 的差異從 FY2028 起。緯穎持股比例只影響歸屬母公司淨利（合併營收與毛利率不變）；客供案例同時改變營收與毛利率，EPS 只受保留毛利比例影響。
A29: 目標價參數（只改 DCF 參數與權重；PL 收斂法的 fade_g 不隨 tp_g 變動）
A30: 案例 | B30: 設定 | C30: DCF 目標價 | D30: Comparable 目標價（相對倍數調整後） | E30: 加權目標價 | F30: 相對基準
A31: 基準 | B31: r 10%、g 4%、DCF 權重 0.5 | C31: =(tp_wA*(Val!B8*(1-MIN(tp_g/tp_roe,0.8))/(1+tp_r)^1+Val!B9*(1-MIN(tp_g/tp_roe,0.8))/(1+tp_r)^2+Val!B10*(1-MIN(tp_g/tp_roe,0.8))/(1+tp_r)^3+Val!B11*(1-MIN(tp_g/tp_roe,0.8))/(1+tp_r)^4+Val!B12*(1-MIN(tp_g/tp_roe,0.8))/(1+tp_r)^5+Val!B13*(1-MIN(tp_g/tp_roe,0.8))/(1+tp_r)^6+Val!B13*(1-MIN(tp_g/tp_roe,0.8))*(1+tp_g)/(tp_r-tp_g)/(1+tp_r)^6)+tp_wB*(Val!C8*(1-MIN(tp_g/tp_roe,0.8))/(1+tp_r)^1+Val!C9*(1-MIN(tp_g/tp_roe,0.8))/(1+tp_r)^2+Val!C10*(1-MIN(tp_g/tp_roe,0.8))/(1+tp_r)^3+Val!C11*(1-MIN(tp_g/tp_roe,0.8))/(1+tp_r)^4+Val!C12*(1-MIN(tp_g/tp_roe,0.8))/(1+tp_r)^5+Val!C13*(1-MIN(tp_g/tp_roe,0.8))/(1+tp_r)^6+Val!C13*(1-MIN(tp_g/tp_roe,0.8))*(1+tp_g)/(tp_r-tp_g)/(1+tp_r)^6)+tp_wC*(Val!D8*(1-MIN(tp_g/tp_roe,0.8))/(1+tp_r)^1+Val!D9*(1-MIN(tp_g/tp_roe,0.8))/(1+tp_r)^2+Val!D10*(1-MIN(tp_g/tp_roe,0.8))/(1+tp_r)^3+Val!D11*(1-MIN(tp_g/tp_roe,0.8))/(1+tp_r)^4+Val!D12*(1-MIN(tp_g/tp_roe,0.8))/(1+tp_r)^5+Val!D13*(1-MIN(tp_g/tp_roe,0.8))/(1+tp_r)^6+Val!D13*(1-MIN(tp_g/tp_roe,0.8))*(1+tp_g)/(tp_r-tp_g)/(1+tp_r)^6))*(1+tp_r) -> 390.01367 | D31: =tp_comp_adj -> 275.5331 | E31: =tp_w_dcf*C31+(1-tp_w_dcf)*D31 -> 332.77339 | F31: =E31/E$31-1 -> 0
A32: 折現率 +1pt | B32: r 11% | C32: =(tp_wA*(Val!B8*(1-MIN(tp_g/tp_roe,0.8))/(1+(tp_r+0.01))^1+Val!B9*(1-MIN(tp_g/tp_roe,0.8))/(1+(tp_r+0.01))^2+Val!B10*(1-MIN(tp_g/tp_roe,0.8))/(1+(tp_r+0.01))^3+Val!B11*(1-MIN(tp_g/tp_roe,0.8))/(1+(tp_r+0.01))^4+Val!B12*(1-MIN(tp_g/tp_roe,0.8))/(1+(tp_r+0.01))^5+Val!B13*(1-MIN(tp_g/tp_roe,0.8))/(1+(tp_r+0.01))^6+Val!B13*(1-MIN(tp_g/tp_roe,0.8))*(1+tp_g)/((tp_r+0.01)-tp_g)/(1+(tp_r+0.01))^6)+tp_wB*(Val!C8*(1-MIN(tp_g/tp_roe,0.8))/(1+(tp_r+0.01))^1+Val!C9*(1-MIN(tp_g/tp_roe,0.8))/(1+(tp_r+0.01))^2+Val!C10*(1-MIN(tp_g/tp_roe,0.8))/(1+(tp_r+0.01))^3+Val!C11*(1-MIN(tp_g/tp_roe,0.8))/(1+(tp_r+0.01))^4+Val!C12*(1-MIN(tp_g/tp_roe,0.8))/(1+(tp_r+0.01))^5+Val!C13*(1-MIN(tp_g/tp_roe,0.8))/(1+(tp_r+0.01))^6+Val!C13*(1-MIN(tp_g/tp_roe,0.8))*(1+tp_g)/((tp_r+0.01)-tp_g)/(1+(tp_r+0.01))^6)+tp_wC*(Val!D8*(1-MIN(tp_g/tp_roe,0.8))/(1+(tp_r+0.01))^1+Val!D9*(1-MIN(tp_g/tp_roe,0.8))/(1+(tp_r+0.01))^2+Val!D10*(1-MIN(tp_g/tp_roe,0.8))/(1+(tp_r+0.01))^3+Val!D11*(1-MIN(tp_g/tp_roe,0.8))/(1+(tp_r+0.01))^4+Val!D12*(1-MIN(tp_g/tp_roe,0.8))/(1+(tp_r+0.01))^5+Val!D13*(1-MIN(tp_g/tp_roe,0.8))/(1+(tp_r+0.01))^6+Val!D13*(1-MIN(tp_g/tp_roe,0.8))*(1+tp_g)/((tp_r+0.01)-tp_g)/(1+(tp_r+0.01))^6))*(1+(tp_r+0.01)) -> 337.65205 | D32: =tp_comp_adj -> 275.5331 | E32: =tp_w_dcf*C32+(1-tp_w_dcf)*D32 -> 306.59258 | F32: =E32/E$31-1 -> -0.078674591
A33: 折現率 −1pt | B33: r 9% | C33: =(tp_wA*(Val!B8*(1-MIN(tp_g/tp_roe,0.8))/(1+(tp_r-0.01))^1+Val!B9*(1-MIN(tp_g/tp_roe,0.8))/(1+(tp_r-0.01))^2+Val!B10*(1-MIN(tp_g/tp_roe,0.8))/(1+(tp_r-0.01))^3+Val!B11*(1-MIN(tp_g/tp_roe,0.8))/(1+(tp_r-0.01))^4+Val!B12*(1-MIN(tp_g/tp_roe,0.8))/(1+(tp_r-0.01))^5+Val!B13*(1-MIN(tp_g/tp_roe,0.8))/(1+(tp_r-0.01))^6+Val!B13*(1-MIN(tp_g/tp_roe,0.8))*(1+tp_g)/((tp_r-0.01)-tp_g)/(1+(tp_r-0.01))^6)+tp_wB*(Val!C8*(1-MIN(tp_g/tp_roe,0.8))/(1+(tp_r-0.01))^1+Val!C9*(1-MIN(tp_g/tp_roe,0.8))/(1+(tp_r-0.01))^2+Val!C10*(1-MIN(tp_g/tp_roe,0.8))/(1+(tp_r-0.01))^3+Val!C11*(1-MIN(tp_g/tp_roe,0.8))/(1+(tp_r-0.01))^4+Val!C12*(1-MIN(tp_g/tp_roe,0.8))/(1+(tp_r-0.01))^5+Val!C13*(1-MIN(tp_g/tp_roe,0.8))/(1+(tp_r-0.01))^6+Val!C13*(1-MIN(tp_g/tp_roe,0.8))*(1+tp_g)/((tp_r-0.01)-tp_g)/(1+(tp_r-0.01))^6)+tp_wC*(Val!D8*(1-MIN(tp_g/tp_roe,0.8))/(1+(tp_r-0.01))^1+Val!D9*(1-MIN(tp_g/tp_roe,0.8))/(1+(tp_r-0.01))^2+Val!D10*(1-MIN(tp_g/tp_roe,0.8))/(1+(tp_r-0.01))^3+Val!D11*(1-MIN(tp_g/tp_roe,0.8))/(1+(tp_r-0.01))^4+Val!D12*(1-MIN(tp_g/tp_roe,0.8))/(1+(tp_r-0.01))^5+Val!D13*(1-MIN(tp_g/tp_roe,0.8))/(1+(tp_r-0.01))^6+Val!D13*(1-MIN(tp_g/tp_roe,0.8))*(1+tp_g)/((tp_r-0.01)-tp_g)/(1+(tp_r-0.01))^6))*(1+(tp_r-0.01)) -> 463.30088 | D33: =tp_comp_adj -> 275.5331 | E33: =tp_w_dcf*C33+(1-tp_w_dcf)*D33 -> 369.41699 | F33: =E33/E$31-1 -> 0.11011578
A34: 長期成長 +1pt | B34: g 5% | C34: =(tp_wA*(Val!B8*(1-MIN((tp_g+0.01)/tp_roe,0.8))/(1+tp_r)^1+Val!B9*(1-MIN((tp_g+0.01)/tp_roe,0.8))/(1+tp_r)^2+Val!B10*(1-MIN((tp_g+0.01)/tp_roe,0.8))/(1+tp_r)^3+Val!B11*(1-MIN((tp_g+0.01)/tp_roe,0.8))/(1+tp_r)^4+Val!B12*(1-MIN((tp_g+0.01)/tp_roe,0.8))/(1+tp_r)^5+Val!B13*(1-MIN((tp_g+0.01)/tp_roe,0.8))/(1+tp_r)^6+Val!B13*(1-MIN((tp_g+0.01)/tp_roe,0.8))*(1+(tp_g+0.01))/(tp_r-(tp_g+0.01))/(1+tp_r)^6)+tp_wB*(Val!C8*(1-MIN((tp_g+0.01)/tp_roe,0.8))/(1+tp_r)^1+Val!C9*(1-MIN((tp_g+0.01)/tp_roe,0.8))/(1+tp_r)^2+Val!C10*(1-MIN((tp_g+0.01)/tp_roe,0.8))/(1+tp_r)^3+Val!C11*(1-MIN((tp_g+0.01)/tp_roe,0.8))/(1+tp_r)^4+Val!C12*(1-MIN((tp_g+0.01)/tp_roe,0.8))/(1+tp_r)^5+Val!C13*(1-MIN((tp_g+0.01)/tp_roe,0.8))/(1+tp_r)^6+Val!C13*(1-MIN((tp_g+0.01)/tp_roe,0.8))*(1+(tp_g+0.01))/(tp_r-(tp_g+0.01))/(1+tp_r)^6)+tp_wC*(Val!D8*(1-MIN((tp_g+0.01)/tp_roe,0.8))/(1+tp_r)^1+Val!D9*(1-MIN((tp_g+0.01)/tp_roe,0.8))/(1+tp_r)^2+Val!D10*(1-MIN((tp_g+0.01)/tp_roe,0.8))/(1+tp_r)^3+Val!D11*(1-MIN((tp_g+0.01)/tp_roe,0.8))/(1+tp_r)^4+Val!D12*(1-MIN((tp_g+0.01)/tp_roe,0.8))/(1+tp_r)^5+Val!D13*(1-MIN((tp_g+0.01)/tp_roe,0.8))/(1+tp_r)^6+Val!D13*(1-MIN((tp_g+0.01)/tp_roe,0.8))*(1+(tp_g+0.01))/(tp_r-(tp_g+0.01))/(1+tp_r)^6))*(1+tp_r) -> 420.75613 | D34: =tp_comp_adj -> 275.5331 | E34: =tp_w_dcf*C34+(1-tp_w_dcf)*D34 -> 348.14462 | F34: =E34/E$31-1 -> 0.046191284
A35: 長期成長 −1pt | B35: g 3% | C35: =(tp_wA*(Val!B8*(1-MIN((tp_g-0.01)/tp_roe,0.8))/(1+tp_r)^1+Val!B9*(1-MIN((tp_g-0.01)/tp_roe,0.8))/(1+tp_r)^2+Val!B10*(1-MIN((tp_g-0.01)/tp_roe,0.8))/(1+tp_r)^3+Val!B11*(1-MIN((tp_g-0.01)/tp_roe,0.8))/(1+tp_r)^4+Val!B12*(1-MIN((tp_g-0.01)/tp_roe,0.8))/(1+tp_r)^5+Val!B13*(1-MIN((tp_g-0.01)/tp_roe,0.8))/(1+tp_r)^6+Val!B13*(1-MIN((tp_g-0.01)/tp_roe,0.8))*(1+(tp_g-0.01))/(tp_r-(tp_g-0.01))/(1+tp_r)^6)+tp_wB*(Val!C8*(1-MIN((tp_g-0.01)/tp_roe,0.8))/(1+tp_r)^1+Val!C9*(1-MIN((tp_g-0.01)/tp_roe,0.8))/(1+tp_r)^2+Val!C10*(1-MIN((tp_g-0.01)/tp_roe,0.8))/(1+tp_r)^3+Val!C11*(1-MIN((tp_g-0.01)/tp_roe,0.8))/(1+tp_r)^4+Val!C12*(1-MIN((tp_g-0.01)/tp_roe,0.8))/(1+tp_r)^5+Val!C13*(1-MIN((tp_g-0.01)/tp_roe,0.8))/(1+tp_r)^6+Val!C13*(1-MIN((tp_g-0.01)/tp_roe,0.8))*(1+(tp_g-0.01))/(tp_r-(tp_g-0.01))/(1+tp_r)^6)+tp_wC*(Val!D8*(1-MIN((tp_g-0.01)/tp_roe,0.8))/(1+tp_r)^1+Val!D9*(1-MIN((tp_g-0.01)/tp_roe,0.8))/(1+tp_r)^2+Val!D10*(1-MIN((tp_g-0.01)/tp_roe,0.8))/(1+tp_r)^3+Val!D11*(1-MIN((tp_g-0.01)/tp_roe,0.8))/(1+tp_r)^4+Val!D12*(1-MIN((tp_g-0.01)/tp_roe,0.8))/(1+tp_r)^5+Val!D13*(1-MIN((tp_g-0.01)/tp_roe,0.8))/(1+tp_r)^6+Val!D13*(1-MIN((tp_g-0.01)/tp_roe,0.8))*(1+(tp_g-0.01))/(tp_r-(tp_g-0.01))/(1+tp_r)^6))*(1+tp_r) -> 369.77858 | D35: =tp_comp_adj -> 275.5331 | E35: =tp_w_dcf*C35+(1-tp_w_dcf)*D35 -> 322.65584 | F35: =E35/E$31-1 -> -0.030403719
A36: DCF 權重 0.3 | C36: =(tp_wA*(Val!B8*(1-MIN(tp_g/tp_roe,0.8))/(1+tp_r)^1+Val!B9*(1-MIN(tp_g/tp_roe,0.8))/(1+tp_r)^2+Val!B10*(1-MIN(tp_g/tp_roe,0.8))/(1+tp_r)^3+Val!B11*(1-MIN(tp_g/tp_roe,0.8))/(1+tp_r)^4+Val!B12*(1-MIN(tp_g/tp_roe,0.8))/(1+tp_r)^5+Val!B13*(1-MIN(tp_g/tp_roe,0.8))/(1+tp_r)^6+Val!B13*(1-MIN(tp_g/tp_roe,0.8))*(1+tp_g)/(tp_r-tp_g)/(1+tp_r)^6)+tp_wB*(Val!C8*(1-MIN(tp_g/tp_roe,0.8))/(1+tp_r)^1+Val!C9*(1-MIN(tp_g/tp_roe,0.8))/(1+tp_r)^2+Val!C10*(1-MIN(tp_g/tp_roe,0.8))/(1+tp_r)^3+Val!C11*(1-MIN(tp_g/tp_roe,0.8))/(1+tp_r)^4+Val!C12*(1-MIN(tp_g/tp_roe,0.8))/(1+tp_r)^5+Val!C13*(1-MIN(tp_g/tp_roe,0.8))/(1+tp_r)^6+Val!C13*(1-MIN(tp_g/tp_roe,0.8))*(1+tp_g)/(tp_r-tp_g)/(1+tp_r)^6)+tp_wC*(Val!D8*(1-MIN(tp_g/tp_roe,0.8))/(1+tp_r)^1+Val!D9*(1-MIN(tp_g/tp_roe,0.8))/(1+tp_r)^2+Val!D10*(1-MIN(tp_g/tp_roe,0.8))/(1+tp_r)^3+Val!D11*(1-MIN(tp_g/tp_roe,0.8))/(1+tp_r)^4+Val!D12*(1-MIN(tp_g/tp_roe,0.8))/(1+tp_r)^5+Val!D13*(1-MIN(tp_g/tp_roe,0.8))/(1+tp_r)^6+Val!D13*(1-MIN(tp_g/tp_roe,0.8))*(1+tp_g)/(tp_r-tp_g)/(1+tp_r)^6))*(1+tp_r) -> 390.01367 | D36: =tp_comp_adj -> 275.5331 | E36: =0.3*C36+(1-0.3)*D36 -> 309.87727 | F36: =E36/E$31-1 -> -0.068803923
A37: DCF 權重 0.7 | C37: =(tp_wA*(Val!B8*(1-MIN(tp_g/tp_roe,0.8))/(1+tp_r)^1+Val!B9*(1-MIN(tp_g/tp_roe,0.8))/(1+tp_r)^2+Val!B10*(1-MIN(tp_g/tp_roe,0.8))/(1+tp_r)^3+Val!B11*(1-MIN(tp_g/tp_roe,0.8))/(1+tp_r)^4+Val!B12*(1-MIN(tp_g/tp_roe,0.8))/(1+tp_r)^5+Val!B13*(1-MIN(tp_g/tp_roe,0.8))/(1+tp_r)^6+Val!B13*(1-MIN(tp_g/tp_roe,0.8))*(1+tp_g)/(tp_r-tp_g)/(1+tp_r)^6)+tp_wB*(Val!C8*(1-MIN(tp_g/tp_roe,0.8))/(1+tp_r)^1+Val!C9*(1-MIN(tp_g/tp_roe,0.8))/(1+tp_r)^2+Val!C10*(1-MIN(tp_g/tp_roe,0.8))/(1+tp_r)^3+Val!C11*(1-MIN(tp_g/tp_roe,0.8))/(1+tp_r)^4+Val!C12*(1-MIN(tp_g/tp_roe,0.8))/(1+tp_r)^5+Val!C13*(1-MIN(tp_g/tp_roe,0.8))/(1+tp_r)^6+Val!C13*(1-MIN(tp_g/tp_roe,0.8))*(1+tp_g)/(tp_r-tp_g)/(1+tp_r)^6)+tp_wC*(Val!D8*(1-MIN(tp_g/tp_roe,0.8))/(1+tp_r)^1+Val!D9*(1-MIN(tp_g/tp_roe,0.8))/(1+tp_r)^2+Val!D10*(1-MIN(tp_g/tp_roe,0.8))/(1+tp_r)^3+Val!D11*(1-MIN(tp_g/tp_roe,0.8))/(1+tp_r)^4+Val!D12*(1-MIN(tp_g/tp_roe,0.8))/(1+tp_r)^5+Val!D13*(1-MIN(tp_g/tp_roe,0.8))/(1+tp_r)^6+Val!D13*(1-MIN(tp_g/tp_roe,0.8))*(1+tp_g)/(tp_r-tp_g)/(1+tp_r)^6))*(1+tp_r) -> 390.01367 | D37: =tp_comp_adj -> 275.5331 | E37: =0.7*C37+(1-0.7)*D37 -> 355.6695 | F37: =E37/E$31-1 -> 0.068803923
A40: 案例區塊：AI 部署 ×0.8（情境 A）
A41: 項目 | B41: 單位 | C41: FY2025A | D41: FY2026（錨點） | E41: FY2027 | F41: FY2028 | G41: FY2029 | H41: FY2030（收斂） | I41: FY2031（收斂） | J41: FY2032（收斂） | K41: 說明
A42: A. AI 部署與整櫃組裝市場（D 欄＝FY2026 校準年；E–G＝FY2027–FY2029；與廣達模型同口徑）
A43: AI IT 資本支出 × 情境顆數係數 | B43: US$B | D43: =itc_26*1 -> 781.87292 | E43: =itc_27*1*0.8 -> 1252.28 | F43: =itc_28*um28_A*0.8 -> 1587.4111 | G43: =itc_29*um29_A*0.8 -> 1808.3122
A44: 每 GW IT 資本支出 | B44: US$B | D44: =itpg_gb*(1-vr26)+itpg_vr*vr26 -> 33.414032 | E44: =itpg_vr -> 37.586352 | F44: =itpg_vr -> 37.586352 | G44: =itpg_vr -> 37.586352
A45: 部署 GW（IT 電力） | B45: GW | D45: =D43/D44 -> 23.399538 | E45: =E43/E44 -> 33.317413 | F45: =F43/F44 -> 42.233711 | G45: =G43/G44 -> 48.110873
...

Sheet Sources
A1: 來源（公司原文只經法說摘要與新聞轉述，原始簡報待人工複核；券商與資料商皆為 Interested-party）
A2: 公司（摘要）：鉅亨 2Q26 法說（2Q26 營收、毛利率、營益率、淨利、EPS；AI 伺服器展望、L10／L11、交換器、GDR） | B2: https://news.cnyes.com/news/id/6559382
A3: 公司（摘要）：優分析 2Q26 法說（1H26 營收、毛利率、營益率、淨利 244.58 億、EPS 7.78；資本支出） | B3: https://uanalyze.com.tw/articles/5392152784
A4: 公司（摘要）：優分析 2025 財報（FY2025 營收 2.19 兆、毛利率 6.13%、營益率 3.59%、淨利 274.08 億、EPS 9.04） | B4: https://uanalyze.com.tw/articles/6054848921
A5: 公司：月營收公告（TechNews 7 月） | B5: https://finance.technews.tw/2026/08/07/wistron-3231-202607-financial-report/
A6: 公司：月營收公告（TechNews 8 月） | B6: https://finance.technews.tw/2026/09/09/wistron-3231-202608-financial-report/
A7: 公司：月營收公告（TechNews 9 月） | B7: https://finance.technews.tw/2026/10/08/wistron-3231-202609-financial-report/
A8: 公司（摘要）：優分析 2026-10-08（3Q26 約 1.15 兆、4Q 展望） | B8: https://uanalyze.com.tw/articles/5406456758
A9: 緯穎（摘要）：富果 4Q25 法說（FY2025 營收、毛利、營業利益、淨利、AI 占比、2026 展望） | B9: https://blog.fugle.tw/post/earnings-call-6669-2026-02-26-2
A10: 緯穎（摘要）：優分析 2Q26 財報（1H26、2Q26 營收、毛利率、營益率、淨利） | B10: https://uanalyze.com.tw/articles/3734153022
A11: 緯穎：月營收公告（TechNews 9 月；前 9 月 9,892.78 億） | B11: https://finance.technews.tw/2026/10/08/wiwynn-6669-202609-financial-report/
A12: 券商：凱基緯創報告 2026-05-08（2026–27 EPS、伺服器占比、零組件、櫃數、交換器） | B12: https://www.kgi.com.hk/zh-cn/-/media/files/kgishk/research-reports/tw-reports/wistron_3231-tt_08052026e.pdf
A13: 券商：凱基緯穎報告 2026-07-28（緯穎 2025A–2027F、緯創持股 37.68%） | B13: https://www.kgi.com.hk/zh-hk/-/media/files/kgishk/research-reports/tw-reports/wiwynn-6669-tt20260728en.pdf
... A28: SemiAnalysis | B28: 未使用
