Workbook
Name w_irr: 參數!$B$2
Name w_pos: 參數!$B$3
Name w_vc: 參數!$B$4
Name s_irr1: 參數!$B$5
Name s_irr2: 參數!$B$6
Name s_irr3: 參數!$B$7
Name s_pos1: 參數!$B$8
Name s_pos2: 參數!$B$9
Name s_pos3: 參數!$B$10
Name s_pos4: 參數!$B$11

Sheet README
A1: AI 投資地圖 資料活頁簿 v0.5.1（20261026）
A2: 用途：AI 投資地圖網站（markets/invest_map/dist/index.html）的唯一數字來源。網站只呈現本活頁簿重算後的值。
A3: 三個視角：(1) 供應鏈地圖＝「價值鏈」頁＋Tokenomics 每 GW 金額；(2) 產業地位＝「地位」頁；(3) 可投資性＝「估值」頁。
A4: 黃底＝判斷輸入（Andy 可直接改；重建時讀回，不被程式覆寫）。藍字＝自各模型或 Tokenomics 抄錄的值，旁欄註明來源儲存格。其餘為公式。
A5: Tokenomics：20261024_Tokenomics_v21.4.xlsx（commit 3ac70ac；擷取 2026-10-25）
A6: 公司模型：company-models 各公司 dist/*.xlsx（extract_models.py 抽數）。
A7: AI半導體 候選母體 v0.2.2（2026-10-24）：次產業排序、公司重要性、市場地位文字。權威在 AI半導體 Project。
A8: 收支關卡（Andy 2026-10-25 10:48）：先看收支、再看評價。模型期間（2026 起約五年）現金收支合計為負＝入不敷出、有資金缺口，不論估值空間多大，最終分級一律為「收支不足」。口徑：雲端／neocloud／MAG 模板一律用「營運缺口＋股東回饋（股利、回購）」；記憶體、模型商用自由現金流；只有損益的半導體模型以「各情境淨利皆為正」判定（現金流本專案未建立）。
A9: 可投資性口徑（v0.5，Andy 2026-10-25 18:14：數字引用個股模型，模型沒有的才自算）：半導體 52 家的中心價＝模型「目標價（DCF 與 Comparable 加權）」、中心空間＝模型「上檔空間：加權目標價」、現價＝模型現價（上檔空間的分母）、投資建議與上檔空間級距＝模型 Val 列；模型尚未補列者依 AI半導體 固定規則（>+50% 強力買進、+25～+50% 買進、−25～+25% 中立、−50～−25% 放空、<−50% 強力放空）以模型上檔空間自算。悲觀情境空間（v0.5.1 前稱「下檔空間」）＝C 情境 DCF 價值 ÷ 模型現價 − 1（模型無此欄，自算）；不是一般所說目標價相對現價的下跌幅度。雲端與 neocloud（v0.5.1）：上檔空間＝模型加權目標價 ÷ 最近外部收盤價 − 1，依同一五級規則自算（不用模型自身評等，不再出現「賣出」）；MiniMax 用反向檢驗折現價值，依同一固定規則自算。
A10: 本活頁簿是研究整理，不是投資建議；各模型的方法與假設見各自 README 與 Val／摘要頁。

Sheet 參數
A1: 名稱 | B1: 值 | C1: 說明
A2: w_irr | B2: 0.4 | C2: 地位分數權重：不可替代性
A3: w_pos | B3: 0.35 | C3: 地位分數權重：市場位置
A4: w_vc | B4: 0.25 | C4: 地位分數權重：價值鏈分量
A5: s_irr1 | B5: 100 | C5: 不可替代性／重要性 1 → 分數
A6: s_irr2 | B6: 60 | C6: 2 → 分數
A7: s_irr3 | B7: 30 | C7: 3 → 分數
A8: s_pos1 | B8: 100 | C8: 市場位置 1 龍頭 → 分數
A9: s_pos2 | B9: 75 | C9: 2 前二或寡占 → 分數
A10: s_pos3 | B10: 50 | C10: 3 主要參與者 → 分數
A11: s_pos4 | B11: 25 | C11: 4 追隨者 → 分數

Sheet 每GW
A1: 項目 | B1: 世代 | C1: 低 | D1: 基準 | E1: 高 | F1: 單位 | G1: Tokenomics 名稱 | H1: 來源儲存格（基準）
A2: 每 GW 資本支出：IT 設備 | B2: GB300 | C2: 28.554902 | D2: 32.237224 | E2: 39.282606 | F2: $B | G2: IF_CapexIT | H2: Interface!J9
A3: 每 GW 資本支出：IT 設備 | B3: VR200 | C3: 31.997023 | D3: 37.586352 | E3: 42.637575 | F3: $B | G3: IF_CapexIT | H3: Interface!M9
A4: 每 GW 資本支出：設施（電力、機房、冷卻） | B4: GB300 | C4: 10.212 | D4: 12.67 | E4: 16.186 | F4: $B | G4: IF_CapexFacility | H4: Interface!J10
A5: 每 GW 資本支出：設施（電力、機房、冷卻） | B5: VR200 | C5: 10.212 | D5: 12.67 | E5: 16.186 | F5: $B | G5: IF_CapexFacility | H5: Interface!M10
A6: 每 GW 資本支出：合計 | B6: GB300 | C6: 38.766902 | D6: 44.907224 | E6: 55.468606 | F6: $B | G6: IF_CapexTotal | H6: Interface!J11
A7: 每 GW 資本支出：合計 | B7: VR200 | C7: 42.209023 | D7: 50.256352 | E7: 58.823575 | F7: $B | G7: IF_CapexTotal | H7: Interface!M11
A8: 每 GW 年經濟持有成本 | B8: GB300 | C8: 8.4288991 | D8: 10.886411 | E8: 18.534646 | F8: $B/GW/年 | G8: IF_HoldEcon | H8: Interface!J13
A9: 每 GW 年經濟持有成本 | B9: VR200 | C9: 9.2190715 | D9: 12.225471 | E9: 19.750627 | F9: $B/GW/年 | G9: IF_HoldEcon | H9: Interface!M13
A10: VR200 每 GW 營收 P×Q：第一年（m＝2026 Q2） | B10: VR200 | C10: 36.229598 | D10: 49.513784 | E10: 78.497462 | F10: $B/GW/年 | G10: L1_RevGW_PQ_VR200 | H10: L1!D129
A11: VR200 每 GW 營收 P×Q：壽命期平均（含 L） | B11: VR200 | C11: 16.158351 | D11: 34.602437 | E11: 85.88756 | F11: $B/GW/年 | G11: L1_RevGW_PQ_VR200_Life | H11: L1!D131
A12: 實際 L（機隊、折現） | B12: 機隊 | C12: 0.47944189 | D12: 0.75859737 | E12: 1.1382722 | F12: x | G12: L1_LTotalFleetVDisc | H12: L1!D116
A13: 回本所需 L（全部算力持有成本口徑） | B13: 機隊 | C13: 0.71561734 | D13: 0.80707823 | E13: 0.89452167 | F13: x | G13: L1_LReqFleet_Full | H13: L1!D140
A14: 回本比值（實際 L ÷ 所需 L） | B14: 機隊 | D14: =D12/D13 | F14: 倍 | G14: [Derived] | H14: Tokenomics 交接：0.940，「未定」

Sheet 價值鏈
A1: 層級 | B1: 次產業 | C1: 占 AI IT 資本支出 | D1: 比例中值 | E1: 每 GW 金額（GB300，$B） | F1: 不可替代性（1–3） | G1: 價值鏈分量分 | H1: 依據
A2: L5 模型商 | B2: AI 模型商 | C2: 營收端（P×Q） | F2: 2 | G2: 75 | H2: 收入池最上游：每 GW 第一年 P×Q 營收高於持有成本，但回本比值約 0.94，未定 [Derived]；分量分為判斷
A3: L4 算力平台 | B3: AI 雲端平台 | C3: 持有算力資產 | F3: 2 | G3: 100 | H3: 持有並出租算力；年持有成本由此層支付，是上游資本支出的付款方 [判斷]
A4: L4 算力平台 | B4: Neocloud（GPU 租賃） | C4: 持有算力資產 | F4: 3 | G4: 50 | H4: 同為算力持有者，但客戶集中、融資依賴高、可替代 [判斷]
A5: L3 IT 設備 | B5: 運算 | C5: 57.3%（VR200 2027 約 37%） | D5: 0.573 | E5: =D5*每GW!$D$2 | F5: 1 | G5: 100 | H5: 晶片內容橋接表 v0.2.1 Bridge GB300 欄 B10＋B11＋B13＋B14（NVIDIA 晶片毛利 48.5%＋台積電 3.5%＋其他製造 2.3%＋CPU 3.0%）÷ B7；HBM 移到記憶體 [Derived]
A6: L3 IT 設備 | B6: 記憶體 | C6: 13.4%（VR200 2027 約 23%） | D6: 0.134 | E6: =D6*每GW!$D$2 | F6: 1 | G6: 100 | H6: 晶片內容橋接表 v0.2.1 Bridge GB300 欄 B12＋B15＋B16（HBM 6.7%＋LPDDR 4.6%＋機架內 SSD 2.1%）÷ B7；2027 HBM 合約價約翻倍，VR200 2027 約 23%，級距沿用 100 [Derived]
A7: L3 IT 設備 | B7: 網通 | C7: 17.5%（VR200 約 19%） | D7: 0.175 | E7: =D7*每GW!$D$2 | F7: 2 | G7: 75 | H7: 晶片內容橋接表 v0.2.1 Bridge GB300 欄 B17＋B20（網卡與 DPU 4.0%＋NVLink 4.5%＋機架外交換器、光模組、線纜 9.0%）÷ B7 [Derived]
A8: L3 IT 設備 | B8: 載板與 PCB | C8: 含在運算「其他製造」2.3% 內（ABF 約 0.3%），不另加 | D8: 0.003 | E8: =D8*每GW!$D$2 | F8: 2 | G8: 25 | H8: AI半導體 次產業排序 v0.2.2（Ibiden 比對）；屬 晶片內容橋接表 v0.2.1 Bridge GB300 欄 B13 的一部分，金額不與運算相加 [Assumed] 區間
A9: L3 IT 設備 | B9: 電源與散熱 | C9: 6.3%（電源、散熱、機構、整合；電源＋散熱約 3–5%） | D9: 0.063 | E9: =D9*每GW!$D$2 | F9: 2 | G9: 25 | H9: 晶片內容橋接表 v0.2.1 Bridge GB300 欄 B18 ÷ B7；電源＋散熱 3–5% 為 AI半導體 判斷，級距依 3–5% 給 25 [Derived]／[Assumed]
A10: L3 IT 設備 | B10: 伺服器組裝 | C10: 4.6%（板卡、供電與組裝加價；ODM 附加價值約 1–3%） | D10: 0.046 | E10: =D10*每GW!$D$2 | F10: 3 | G10: 25 | H10: 晶片內容橋接表 v0.2.1 Bridge GB300 欄 B19 ÷ B7（殘差：匣級電路板、供電、NVIDIA／ODM 匣級加價）；ODM 附加價值 1–3% 為 AI半導體 判斷 [Derived]
A11: L2 半導體製造與設備 | B11: 代工與封測 | C11: 約 3.5%（含在 L3 運算內，不另加；僅 NVIDIA 平台） | D11: 0.035 | F11: 1 | G11: 75 | H11: 例外：晶片內容橋接表 v0.2.1 Bridge GB300 欄 B11 ÷ B7 只見 3.5%，但先進製程與 CoWoS 的價值藏在運算的晶片成本內，給 75 [判斷]
A12: L2 半導體製造與設備 | B12: 設備與材料 | C12: 約 7.5%（軸 B，不可與軸 A 相加） | D12: 0.075 | F12: 1 | G12: 50 | H12: AI半導體 次產業排序 v0.2.2（設備模型情境 A：2027 AI 相關設備 117.8B ÷ 1,565B）

Sheet 地位
A1: 代號 | B1: 公司 | C1: 層級 | D1: 次產業 | E1: 公司重要性（1–3） | F1: 市場位置（1–4） | G1: 地位依據 | H1: 標記 | I1: 次產業不可替代性 | J1: 價值鏈分量分 | K1: 不可替代性分 | L1: 市場位置分 | M1: 地位分數 | N1: 排名
A2: NVDA | B2: NVIDIA | C2: =價值鏈!A5 | D2: 運算 | E2: 1 | F2: 1 | G2: AI 加速器金額份額 CY2027 約 75–82%（本專案推導） | H2: [D] | I2: =價值鏈!F5 | J2: =價值鏈!G5 | K2: =(CHOOSE(I2,s_irr1,s_irr2,s_irr3)+CHOOSE(E2,s_irr1,s_irr2,s_irr3))/2 | L2: =CHOOSE(F2,s_pos1,s_pos2,s_pos3,s_pos4) | M2: =w_irr*K2+w_pos*L2+w_vc*J2 | N2: =RANK(M2,$M$2:$M$64,0)
A3: AVGO | B3: Broadcom | C3: =價值鏈!A5 | D3: 運算 | E3: 1 | F3: 2 | G3: 客製 ASIC 約 80–85%（JPMorgan）；運算整體第二 | H3: [IP] | I3: =價值鏈!F5 | J3: =價值鏈!G5 | K3: =(CHOOSE(I3,s_irr1,s_irr2,s_irr3)+CHOOSE(E3,s_irr1,s_irr2,s_irr3))/2 | L3: =CHOOSE(F3,s_pos1,s_pos2,s_pos3,s_pos4) | M3: =w_irr*K3+w_pos*L3+w_vc*J3 | N3: =RANK(M3,$M$2:$M$64,0)
A4: 000660 | B4: SK 海力士 | C4: =價值鏈!A6 | D4: 記憶體 | E4: 1 | F4: 1 | G4: 2026 HBM 市占 52–55%（本專案） | H4: [D] | I4: =價值鏈!F6 | J4: =價值鏈!G6 | K4: =(CHOOSE(I4,s_irr1,s_irr2,s_irr3)+CHOOSE(E4,s_irr1,s_irr2,s_irr3))/2 | L4: =CHOOSE(F4,s_pos1,s_pos2,s_pos3,s_pos4) | M4: =w_irr*K4+w_pos*L4+w_vc*J4 | N4: =RANK(M4,$M$2:$M$64,0)
A5: 005930 | B5: 三星電子 | C5: =價值鏈!A6 | D5: 記憶體 | E5: 1 | F5: 2 | G5: 2026 HBM 市占 28–32%（本專案） | H5: [D] | I5: =價值鏈!F6 | J5: =價值鏈!G6 | K5: =(CHOOSE(I5,s_irr1,s_irr2,s_irr3)+CHOOSE(E5,s_irr1,s_irr2,s_irr3))/2 | L5: =CHOOSE(F5,s_pos1,s_pos2,s_pos3,s_pos4) | M5: =w_irr*K5+w_pos*L5+w_vc*J5 | N5: =RANK(M5,$M$2:$M$64,0)
A6: MU | B6: 美光 | C6: =價值鏈!A6 | D6: 記憶體 | E6: 1 | F6: 3 | G6: 2026 HBM 市占 18–20%（本專案） | H6: [D] | I6: =價值鏈!F6 | J6: =價值鏈!G6 | K6: =(CHOOSE(I6,s_irr1,s_irr2,s_irr3)+CHOOSE(E6,s_irr1,s_irr2,s_irr3))/2 | L6: =CHOOSE(F6,s_pos1,s_pos2,s_pos3,s_pos4) | M6: =w_irr*K6+w_pos*L6+w_vc*J6 | N6: =RANK(M6,$M$2:$M$64,0)
A7: ANET | B7: Arista | C7: =價值鏈!A7 | D7: 網通 | E7: 1 | F7: 2 | G7: AI 後端乙太網路交換器份額約 18.7%（本專案 Arista 比對）；NVIDIA、白牌競爭 | H7: [D] | I7: =價值鏈!F7 | J7: =價值鏈!G7 | K7: =(CHOOSE(I7,s_irr1,s_irr2,s_irr3)+CHOOSE(E7,s_irr1,s_irr2,s_irr3))/2 | L7: =CHOOSE(F7,s_pos1,s_pos2,s_pos3,s_pos4) | M7: =w_irr*K7+w_pos*L7+w_vc*J7 | N7: =RANK(M7,$M$2:$M$64,0)
A8: 300308 | B8: 中際旭創 | C8: =價值鏈!A7 | D8: 網通 | E8: 1 | F8: 1 | G8: 高速光模組出貨領先（媒體與券商） | H8: [IP] | I8: =價值鏈!F7 | J8: =價值鏈!G7 | K8: =(CHOOSE(I8,s_irr1,s_irr2,s_irr3)+CHOOSE(E8,s_irr1,s_irr2,s_irr3))/2 | L8: =CHOOSE(F8,s_pos1,s_pos2,s_pos3,s_pos4) | M8: =w_irr*K8+w_pos*L8+w_vc*J8 | N8: =RANK(M8,$M$2:$M$64,0)
A9: 2330 | B9: 台積電 | C9: =價值鏈!A11 | D9: 代工與封測 | E9: 1 | F9: 1 | G9: 先進製程晶圓與 CoWoS 接近獨占 | H9: [判斷] | I9: =價值鏈!F11 | J9: =價值鏈!G11 | K9: =(CHOOSE(I9,s_irr1,s_irr2,s_irr3)+CHOOSE(E9,s_irr1,s_irr2,s_irr3))/2 | L9: =CHOOSE(F9,s_pos1,s_pos2,s_pos3,s_pos4) | M9: =w_irr*K9+w_pos*L9+w_vc*J9 | N9: =RANK(M9,$M$2:$M$64,0)
A10: 4062 | B10: Ibiden | C10: =價值鏈!A8 | D10: 載板與 PCB | E10: 1 | F10: 1 | G10: 高階 AI 載板主要供應者 | H10: [判斷] | I10: =價值鏈!F8 | J10: =價值鏈!G8 | K10: =(CHOOSE(I10,s_irr1,s_irr2,s_irr3)+CHOOSE(E10,s_irr1,s_irr2,s_irr3))/2 | L10: =CHOOSE(F10,s_pos1,s_pos2,s_pos3,s_pos4) | M10: =w_irr*K10+w_pos*L10+w_vc*J10 | N10: =RANK(M10,$M$2:$M$64,0)
A11: 2308 | B11: 台達電 | C11: =價值鏈!A9 | D11: 電源與散熱 | E11: 1 | F11: 1 | G11: 伺服器電源龍頭 | H11: [判斷] | I11: =價值鏈!F9 | J11: =價值鏈!G9 | K11: =(CHOOSE(I11,s_irr1,s_irr2,s_irr3)+CHOOSE(E11,s_irr1,s_irr2,s_irr3))/2 | L11: =CHOOSE(F11,s_pos1,s_pos2,s_pos3,s_pos4) | M11: =w_irr*K11+w_pos*L11+w_vc*J11 | N11: =RANK(M11,$M$2:$M$64,0)
A12: 2382 | B12: 廣達 | C12: =價值鏈!A10 | D12: 伺服器組裝 | E12: 1 | F12: 2 | G12: 雲端與 NVIDIA 整櫃主要 ODM；鴻海為最大組裝廠 | H12: [判斷] | I12: =價值鏈!F10 | J12: =價值鏈!G10 | K12: =(CHOOSE(I12,s_irr1,s_irr2,s_irr3)+CHOOSE(E12,s_irr1,s_irr2,s_irr3))/2 | L12: =CHOOSE(F12,s_pos1,s_pos2,s_pos3,s_pos4) | M12: =w_irr*K12+w_pos*L12+w_vc*J12 | N12: =RANK(M12,$M$2:$M$64,0)
A13: 6857 | B13: Advantest | C13: =價值鏈!A12 | D13: 設備與材料 | E13: 1 | F13: 1 | G13: SoC 測試市占 66%（公司自估 CY2025） | H13: [IP] | I13: =價值鏈!F12 | J13: =價值鏈!G12 | K13: =(CHOOSE(I13,s_irr1,s_irr2,s_irr3)+CHOOSE(E13,s_irr1,s_irr2,s_irr3))/2 | L13: =CHOOSE(F13,s_pos1,s_pos2,s_pos3,s_pos4) | M13: =w_irr*K13+w_pos*L13+w_vc*J13 | N13: =RANK(M13,$M$2:$M$64,0)
A14: 6146 | B14: Disco | C14: =價值鏈!A12 | D14: 設備與材料 | E14: 2 | F14: 1 | G14: 研削與切割市占 60–80%（兩來源） | H14: [IP] | I14: =價值鏈!F12 | J14: =價值鏈!G12 | K14: =(CHOOSE(I14,s_irr1,s_irr2,s_irr3)+CHOOSE(E14,s_irr1,s_irr2,s_irr3))/2 | L14: =CHOOSE(F14,s_pos1,s_pos2,s_pos3,s_pos4) | M14: =w_irr*K14+w_pos*L14+w_vc*J14 | N14: =RANK(M14,$M$2:$M$64,0)
A15: AMZN | B15: Amazon | C15: =價值鏈!A3 | D15: AI 雲端平台 | E15: 1 | F15: 1 | G15: AWS 為最大公有雲；自研 Trainium | H15: [判斷] | I15: =價值鏈!F3 | J15: =價值鏈!G3 | K15: =(CHOOSE(I15,s_irr1,s_irr2,s_irr3)+CHOOSE(E15,s_irr1,s_irr2,s_irr3))/2 | L15: =CHOOSE(F15,s_pos1,s_pos2,s_pos3,s_pos4) | M15: =w_irr*K15+w_pos*L15+w_vc*J15 | N15: =RANK(M15,$M$2:$M$64,0)
A16: MSFT | B16: Microsoft | C16: =價值鏈!A3 | D16: AI 雲端平台 | E16: 1 | F16: 2 | G16: Azure 第二大公有雲；OpenAI 主要算力夥伴 | H16: [判斷] | I16: =價值鏈!F3 | J16: =價值鏈!G3 | K16: =(CHOOSE(I16,s_irr1,s_irr2,s_irr3)+CHOOSE(E16,s_irr1,s_irr2,s_irr3))/2 | L16: =CHOOSE(F16,s_pos1,s_pos2,s_pos3,s_pos4) | M16: =w_irr*K16+w_pos*L16+w_vc*J16 | N16: =RANK(M16,$M$2:$M$64,0)
A17: GOOGL | B17: Alphabet | C17: =價值鏈!A3 | D17: AI 雲端平台 | E17: 1 | F17: 2 | G17: TPU＋Gemini 垂直整合；雲端第三 | H17: [判斷] | I17: =價值鏈!F3 | J17: =價值鏈!G3 | K17: =(CHOOSE(I17,s_irr1,s_irr2,s_irr3)+CHOOSE(E17,s_irr1,s_irr2,s_irr3))/2 | L17: =CHOOSE(F17,s_pos1,s_pos2,s_pos3,s_pos4) | M17: =w_irr*K17+w_pos*L17+w_vc*J17 | N17: =RANK(M17,$M$2:$M$64,0)
A18: ORCL | B18: Oracle | C18: =價值鏈!A3 | D18: AI 雲端平台 | E18: 2 | F18: 3 | G18: OCI 規模較小；Stargate 主要承建方，客戶集中 | H18: [判斷] | I18: =價值鏈!F3 | J18: =價值鏈!G3 | K18: =(CHOOSE(I18,s_irr1,s_irr2,s_irr3)+CHOOSE(E18,s_irr1,s_irr2,s_irr3))/2 | L18: =CHOOSE(F18,s_pos1,s_pos2,s_pos3,s_pos4) | M18: =w_irr*K18+w_pos*L18+w_vc*J18 | N18: =RANK(M18,$M$2:$M$64,0)
A19: CRWV | B19: CoreWeave | C19: =價值鏈!A4 | D19: Neocloud（GPU 租賃） | E19: 2 | F19: 1 | G19: 最大 neocloud；客戶集中於 Microsoft、OpenAI | H19: [判斷] | I19: =價值鏈!F4 | J19: =價值鏈!G4 | K19: =(CHOOSE(I19,s_irr1,s_irr2,s_irr3)+CHOOSE(E19,s_irr1,s_irr2,s_irr3))/2 | L19: =CHOOSE(F19,s_pos1,s_pos2,s_pos3,s_pos4) | M19: =w_irr*K19+w_pos*L19+w_vc*J19 | N19: =RANK(M19,$M$2:$M$64,0)
A20: NBIS | B20: Nebius | C20: =價值鏈!A4 | D20: Neocloud（GPU 租賃） | E20: 2 | F20: 2 | G20: 歐洲為主的 neocloud；Microsoft 長約 | H20: [判斷] | I20: =價值鏈!F4 | J20: =價值鏈!G4 | K20: =(CHOOSE(I20,s_irr1,s_irr2,s_irr3)+CHOOSE(E20,s_irr1,s_irr2,s_irr3))/2 | L20: =CHOOSE(F20,s_pos1,s_pos2,s_pos3,s_pos4) | M20: =w_irr*K20+w_pos*L20+w_vc*J20 | N20: =RANK(M20,$M$2:$M$64,0)
A21: WYFI | B21: WhiteFiber | C21: =價值鏈!A4 | D21: Neocloud（GPU 租賃） | E21: 3 | F21: 4 | G21: 小型 neocloud＋託管 | H21: [判斷] | I21: =價值鏈!F4 | J21: =價值鏈!G4 | K21: =(CHOOSE(I21,s_irr1,s_irr2,s_irr3)+CHOOSE(E21,s_irr1,s_irr2,s_irr3))/2 | L21: =CHOOSE(F21,s_pos1,s_pos2,s_pos3,s_pos4) | M21: =w_irr*K21+w_pos*L21+w_vc*J21 | N21: =RANK(M21,$M$2:$M$64,0)
A22: OpenAI | B22: OpenAI | C22: =價值鏈!A2 | D22: AI 模型商 | E22: 1 | F22: 1 | G22: ChatGPT 與 API 用量最大的模型商；算力承諾最大（本專案 OpenAI 模型） | H22: [判斷] | I22: =價值鏈!F2 | J22: =價值鏈!G2 | K22: =(CHOOSE(I22,s_irr1,s_irr2,s_irr3)+CHOOSE(E22,s_irr1,s_irr2,s_irr3))/2 | L22: =CHOOSE(F22,s_pos1,s_pos2,s_pos3,s_pos4) | M22: =w_irr*K22+w_pos*L22+w_vc*J22 | N22: =RANK(M22,$M$2:$M$64,0)
A23: Anthropic | B23: Anthropic | C23: =價值鏈!A2 | D23: AI 模型商 | E23: 1 | F23: 2 | G23: 企業與程式開發用途為主的前沿模型商（本專案 Anthropic 模型） | H23: [判斷] | I23: =價值鏈!F2 | J23: =價值鏈!G2 | K23: =(CHOOSE(I23,s_irr1,s_irr2,s_irr3)+CHOOSE(E23,s_irr1,s_irr2,s_irr3))/2 | L23: =CHOOSE(F23,s_pos1,s_pos2,s_pos3,s_pos4) | M23: =w_irr*K23+w_pos*L23+w_vc*J23 | N23: =RANK(M23,$M$2:$M$64,0)
A24: 00100 | B24: MiniMax | C24: =價值鏈!A2 | D24: AI 模型商 | E24: 3 | F24: 3 | G24: 中國第二梯隊模型商；多模態、海外營收占比高 | H24: [判斷] | I24: =價值鏈!F2 | J24: =價值鏈!G2 | K24: =(CHOOSE(I24,s_irr1,s_irr2,s_irr3)+CHOOSE(E24,s_irr1,s_irr2,s_irr3))/2 | L24: =CHOOSE(F24,s_pos1,s_pos2,s_pos3,s_pos4) | M24: =w_irr*K24+w_pos*L24+w_vc*J24 | N24: =RANK(M24,$M$2:$M$64,0)
A25: 02513 | B25: 智譜 | C25: =價值鏈!A2 | D25: AI 模型商 | E25: 3 | F25: 3 | G25: 中國第二梯隊模型商；政企本地化部署 | H25: [判斷] | I25: =價值鏈!F2 | J25: =價值鏈!G2 | K25: =(CHOOSE(I25,s_irr1,s_irr2,s_irr3)+CHOOSE(E25,s_irr1,s_irr2,s_irr3))/2 | L25: =CHOOSE(F25,s_pos1,s_pos2,s_pos3,s_pos4) | M25: =w_irr*K25+w_pos*L25+w_vc*J25 | N25: =RANK(M25,$M$2:$M$64,0)
A26: AMD | B26: AMD | C26: =價值鏈!A5 | D26: 運算 | E26: 2 | F26: 3 | G26: AI 加速器金額份額 CY2027 約 3–6%（本專案推導）；2027 資料中心「超過一倍」（公司）（AI半導體 候選母體 v0.2.2；市場位置由次產業內優先序 3 換算） | H26: [判斷] | I26: =價值鏈!F5 | J26: =價值鏈!G5 | K26: =(CHOOSE(I26,s_irr1,s_irr2,s_irr3)+CHOOSE(E26,s_irr1,s_irr2,s_irr3))/2 | L26: =CHOOSE(F26,s_pos1,s_pos2,s_pos3,s_pos4) | M26: =w_irr*K26+w_pos*L26+w_vc*J26 | N26: =RANK(M26,$M$2:$M$64,0)
A27: 2454 | B27: 聯發科 | C27: =價值鏈!A5 | D27: 運算 | E27: 2 | F27: 3 | G27: Google TPU 合作（媒體報導）（AI半導體 候選母體 v0.2.2；市場位置由次產業內優先序 4 換算） | H27: [判斷] | I27: =價值鏈!F5 | J27: =價值鏈!G5 | K27: =(CHOOSE(I27,s_irr1,s_irr2,s_irr3)+CHOOSE(E27,s_irr1,s_irr2,s_irr3))/2 | L27: =CHOOSE(F27,s_pos1,s_pos2,s_pos3,s_pos4) | M27: =w_irr*K27+w_pos*L27+w_vc*J27 | N27: =RANK(M27,$M$2:$M$64,0)
A28: MRVL | B28: Marvell | C28: =價值鏈!A5 | D28: 運算 | E28: 2 | F28: 3 | G28: 光 DSP 主要供應商之一（AI半導體 候選母體 v0.2.2；市場位置由次產業內優先序 5 換算） | H28: [判斷] | I28: =價值鏈!F5 | J28: =價值鏈!G5 | K28: =(CHOOSE(I28,s_irr1,s_irr2,s_irr3)+CHOOSE(E28,s_irr1,s_irr2,s_irr3))/2 | L28: =CHOOSE(F28,s_pos1,s_pos2,s_pos3,s_pos4) | M28: =w_irr*K28+w_pos*L28+w_vc*J28 | N28: =RANK(M28,$M$2:$M$64,0)
A29: 3661 | B29: 世芯-KY | C29: =價值鏈!A5 | D29: 運算 | E29: 2 | F29: 4 | G29: 雲端客製晶片設計服務（AI半導體 候選母體 v0.2.2；市場位置由次產業內優先序 6 換算） | H29: [判斷] | I29: =價值鏈!F5 | J29: =價值鏈!G5 | K29: =(CHOOSE(I29,s_irr1,s_irr2,s_irr3)+CHOOSE(E29,s_irr1,s_irr2,s_irr3))/2 | L29: =CHOOSE(F29,s_pos1,s_pos2,s_pos3,s_pos4) | M29: =w_irr*K29+w_pos*L29+w_vc*J29 | N29: =RANK(M29,$M$2:$M$64,0)
A30: 3443 | B30: 創意 | C30: =價值鏈!A5 | D30: 運算 | E30: 3 | F30: 4 | G30: 台積電轉投資的設計服務廠（AI半導體 候選母體 v0.2.2；市場位置由次產業內優先序 7 換算） | H30: [判斷] | I30: =價值鏈!F5 | J30: =價值鏈!G5 | K30: =(CHOOSE(I30,s_irr1,s_irr2,s_irr3)+CHOOSE(E30,s_irr1,s_irr2,s_irr3))/2 | L30: =CHOOSE(F30,s_pos1,s_pos2,s_pos3,s_pos4) | M30: =w_irr*K30+w_pos*L30+w_vc*J30 | N30: =RANK(M30,$M$2:$M$64,0)
A31: 285A | B31: Kioxia | C31: =價值鏈!A6 | D31: 記憶體 | E31: 3 | F31: 3 | G31: NAND 主要廠之一；10-23 曾因「不能由既有層推得」排除，15:59 已取消該關卡（AI半導體 候選母體 v0.2.2；市場位置由次產業內優先序 4 換算） | H31: [判斷] | I31: =價值鏈!F6 | J31: =價值鏈!G6 | K31: =(CHOOSE(I31,s_irr1,s_irr2,s_irr3)+CHOOSE(E31,s_irr1,s_irr2,s_irr3))/2 | L31: =CHOOSE(F31,s_pos1,s_pos2,s_pos3,s_pos4) | M31: =w_irr*K31+w_pos*L31+w_vc*J31 | N31: =RANK(M31,$M$2:$M$64,0)
A32: SNDK | B32: SanDisk | C32: =價值鏈!A6 | D32: 記憶體 | E32: 3 | F32: 3 | G32: 與 Kioxia 合資產能（AI半導體 候選母體 v0.2.2；市場位置由次產業內優先序 5 換算） | H32: [判斷] | I32: =價值鏈!F6 | J32: =價值鏈!G6 | K32: =(CHOOSE(I32,s_irr1,s_irr2,s_irr3)+CHOOSE(E32,s_irr1,s_irr2,s_irr3))/2 | L32: =CHOOSE(F32,s_pos1,s_pos2,s_pos3,s_pos4) | M32: =w_irr*K32+w_pos*L32+w_vc*J32 | N32: =RANK(M32,$M$2:$M$64,0)
A33: COHR | B33: Coherent | C33: =價值鏈!A7 | D33: 網通 | E33: 2 | F33: 3 | G33: 光模組與元件垂直整合廠（AI半導體 候選母體 v0.2.2；市場位置由次產業內優先序 3 換算） | H33: [判斷] | I33: =價值鏈!F7 | J33: =價值鏈!G7 | K33: =(CHOOSE(I33,s_irr1,s_irr2,s_irr3)+CHOOSE(E33,s_irr1,s_irr2,s_irr3))/2 | L33: =CHOOSE(F33,s_pos1,s_pos2,s_pos3,s_pos4) | M33: =w_irr*K33+w_pos*L33+w_vc*J33 | N33: =RANK(M33,$M$2:$M$64,0)
A34: LITE | B34: Lumentum | C34: =價值鏈!A7 | D34: 網通 | E34: 2 | F34: 3 | G34: 高速 EML 雷射主要供應商之一（AI半導體 候選母體 v0.2.2；市場位置由次產業內優先序 4 換算） | H34: [判斷] | I34: =價值鏈!F7 | J34: =價值鏈!G7 | K34: =(CHOOSE(I34,s_irr1,s_irr2,s_irr3)+CHOOSE(E34,s_irr1,s_irr2,s_irr3))/2 | L34: =CHOOSE(F34,s_pos1,s_pos2,s_pos3,s_pos4) | M34: =w_irr*K34+w_pos*L34+w_vc*J34 | N34: =RANK(M34,$M$2:$M$64,0)
A35: 300502 | B35: 新易盛 | C35: =價值鏈!A7 | D35: 網通 | E35: 2 | F35: 3 | G35: 高速光模組第二梯隊領先者（AI半導體 候選母體 v0.2.2；市場位置由次產業內優先序 5 換算） | H35: [判斷] | I35: =價值鏈!F7 | J35: =價值鏈!G7 | K35: =(CHOOSE(I35,s_irr1,s_irr2,s_irr3)+CHOOSE(E35,s_irr1,s_irr2,s_irr3))/2 | L35: =CHOOSE(F35,s_pos1,s_pos2,s_pos3,s_pos4) | M35: =w_irr*K35+w_pos*L35+w_vc*J35 | N35: =RANK(M35,$M$2:$M$64,0)
A36: 2345 | B36: 智邦 | C36: =價值鏈!A7 | D36: 網通 | E36: 2 | F36: 4 | G36: 雲端白牌交換器主要 ODM（AI半導體 候選母體 v0.2.2；市場位置由次產業內優先序 6 換算） | H36: [判斷] | I36: =價值鏈!F7 | J36: =價值鏈!G7 | K36: =(CHOOSE(I36,s_irr1,s_irr2,s_irr3)+CHOOSE(E36,s_irr1,s_irr2,s_irr3))/2 | L36: =CHOOSE(F36,s_pos1,s_pos2,s_pos3,s_pos4) | M36: =w_irr*K36+w_pos*L36+w_vc*J36 | N36: =RANK(M36,$M$2:$M$64,0)
A37: FN | B37: Fabrinet | C37: =價值鏈!A7 | D37: 網通 | E37: 2 | F37: 4 | G37: NVIDIA 光模組主要代工之一（AI半導體 候選母體 v0.2.2；市場位置由次產業內優先序 7 換算） | H37: [判斷] | I37: =價值鏈!F7 | J37: =價值鏈!G7 | K37: =(CHOOSE(I37,s_irr1,s_irr2,s_irr3)+CHOOSE(E37,s_irr1,s_irr2,s_irr3))/2 | L37: =CHOOSE(F37,s_pos1,s_pos2,s_pos3,s_pos4) | M37: =w_irr*K37+w_pos*L37+w_vc*J37 | N37: =RANK(M37,$M$2:$M$64,0)
A38: CRDO | B38: Credo | C38: =價值鏈!A7 | D38: 網通 | E38: 2 | F38: 4 | G38: AEC 主要供應商（AI半導體 候選母體 v0.2.2；市場位置由次產業內優先序 8 換算） | H38: [判斷] | I38: =價值鏈!F7 | J38: =價值鏈!G7 | K38: =(CHOOSE(I38,s_irr1,s_irr2,s_irr3)+CHOOSE(E38,s_irr1,s_irr2,s_irr3))/2 | L38: =CHOOSE(F38,s_pos1,s_pos2,s_pos3,s_pos4) | M38: =w_irr*K38+w_pos*L38+w_vc*J38 | N38: =RANK(M38,$M$2:$M$64,0)
A39: ALAB | B39: Astera Labs | C39: =價值鏈!A7 | D39: 網通 | E39: 3 | F39: 4 | G39: retimer 主要供應商（AI半導體 候選母體 v0.2.2；市場位置由次產業內優先序 9 換算） | H39: [判斷] | I39: =價值鏈!F7 | J39: =價值鏈!G7 | K39: =(CHOOSE(I39,s_irr1,s_irr2,s_irr3)+CHOOSE(E39,s_irr1,s_irr2,s_irr3))/2 | L39: =CHOOSE(F39,s_pos1,s_pos2,s_pos3,s_pos4) | M39: =w_irr*K39+w_pos*L39+w_vc*J39 | N39: =RANK(M39,$M$2:$M$64,0)
A40: 2449 | B40: 京元電 | C40: =價值鏈!A11 | D40: 代工與封測 | E40: 2 | F40: 3 | G40: AI GPU 測試主要代工之一（媒體）（AI半導體 候選母體 v0.2.2；市場位置由次產業內優先序 3 換算） | H40: [判斷] | I40: =價值鏈!F11 | J40: =價值鏈!G11 | K40: =(CHOOSE(I40,s_irr1,s_irr2,s_irr3)+CHOOSE(E40,s_irr1,s_irr2,s_irr3))/2 | L40: =CHOOSE(F40,s_pos1,s_pos2,s_pos3,s_pos4) | M40: =w_irr*K40+w_pos*L40+w_vc*J40 | N40: =RANK(M40,$M$2:$M$64,0)
...

Sheet 價格
A1: 代號 | B1: 幣別 | C1: 模型內現價 | D1: 模型價日期 | E1: 模型價來源 | F1: 外部收盤（非半導體模型） | G1: 收盤來源 | H1: 採用價
A2: NVDA | B2: USD | C2: 210.96 | D2: 2026-10-23 | E2: nvidia/dist/20261025_NVIDIA模型_v0.2.xlsx Val!B57 | H2: =C2
A3: AVGO | B3: USD | C3: 321.68 | D3: 2026-10-23 | E3: avgo/dist/20261025_Broadcom模型_v0.2.xlsx Val!B57 | H3: =C3
A4: 000660 | B4: KRW | C4: 1277000 | D4: 2026-10-23 | E4: skhynix/dist/20261025_SK海力士模型_v0.5.xlsx In!E6 | H4: =C4
A5: 005930 | B5: KRW | C5: 215500 | D5: 2026-10-23 | E5: samsung/dist/20261025_三星電子模型_v0.3.xlsx In!E6 | H5: =C5
A6: MU | B6: USD | C6: 877.55 | D6: 2026-10-23 | E6: micron/dist/20261025_美光模型_v0.4.xlsx In!E5 | H6: =C6
A7: 2330 | B7: TWD | C7: 2385 | D7: 2026-10-22 | E7: tsmc/dist/20261025_台積電模型_v0.3.xlsx In!E135 | H7: =C7
A8: ANET | B8: USD | C8: 172.37 | D8: 2026-10-23 | E8: arista/dist/20261025_Arista模型_v0.2.xlsx Val!B57 | H8: =C8
A9: 300308 | B9: CNY | C9: 612.63 | D9: 2026-10-23 | E9: innolight/dist/20261025_中際旭創模型_v0.2.xlsx Val!B53 | H9: =C9
A10: 2308 | B10: TWD | C10: 1605 | D10: 2026-10-23 | E10: delta/dist/20261025_台達電模型_v0.2.xlsx Val!B6 | H10: =C10
A11: 2382 | B11: TWD | C11: 322 | D11: 2026-10-22 | E11: quanta/dist/20261025_廣達模型_v0.2.xlsx Val!B6 | H11: =C11
A12: 4062 | B12: JPY | C12: 8512 | D12: 2026-10-23 | E12: ibiden/dist/20261025_Ibiden模型_v0.2.xlsx Val!B6 | H12: =C12
A13: 6857 | B13: JPY | C13: 32340 | D13: 2026-10-23 | E13: advantest/dist/20261025_Advantest模型_v0.3.xlsx Val!B92 | H13: =C13
A14: 6146 | B14: JPY | C14: 49290 | D14: 2026-10-23 | E14: disco/dist/20261025_Disco模型_v0.2.1.xlsx Val!B53 | H14: =C14
A15: MSFT | B15: USD | C15: 529.76 | D15: 2026-10-07 | E15: microsoft/dist/20261025_Microsoft收支模型_v0_2_2.xlsx 輸入與假設!C345 | F15: 524.51 | G15: 2026-10-23｜stockscan；bullfincher | H15: =IF(ISNUMBER(F15),F15,C15)
A16: AMZN | B16: USD | C16: 259.92 | D16: 2026-10-07 | E16: amazon/dist/20261025_Amazon收支模型_v0_2_2.xlsx 輸入與假設!C328 | F16: 248 | G16: 2026-10-23｜stockanalysis；stockscan | H16: =IF(ISNUMBER(F16),F16,C16)
A17: GOOGL | B17: USD | C17: 350.5 | D17: 2026-10-07 | E17: alphabet/dist/20261025_Alphabet收支模型_v0_2_2.xlsx 輸入與假設!C374 | F17: 320.21 | G17: 2026-10-23｜stockscan；bullfincher | H17: =IF(ISNUMBER(F17),F17,C17)
A18: ORCL | B18: USD | C18: 129.13 | D18: 2026-10-21 | E18: oracle/dist/20261022_Oracle收支模型_v0_3_1.xlsx 輸入與假設!C175 | F18: 126.16 | G18: 2026-10-23｜stockanalysis；stockscan | H18: =IF(ISNUMBER(F18),F18,C18)
A19: CRWV | B19: USD | C19: 90.13 | D19: 2026-09-24 | E19: coreweave/dist/20261021_CoreWeave收支模型_v4_12.xlsx 輸入與假設!C221 | F19: 54.23 | G19: 2026-10-23｜stockscan；digrin | H19: =IF(ISNUMBER(F19),F19,C19)
A20: NBIS | B20: USD | C20: 249.87 | D20: 2026-10-06 | E20: nebius/dist/20261022_Nebius收支模型_v0_5.xlsx 輸入與假設!C125 | F20: 158.74 | G20: 2026-10-23｜stockscan（digrin 158.64） | H20: =IF(ISNUMBER(F20),F20,C20)
A21: WYFI | B21: USD | C21: 16.83 | D21: 2026-10-07 | E21: whitefiber/dist/20261022_WhiteFiber收支模型_v0_2.xlsx 輸入與假設!C228 | F21: 9.98 | G21: 2026-10-23｜stockscan；digrin | H21: =IF(ISNUMBER(F21),F21,C21)
A22: 00100 | B22: HKD | C22: 171.9 | D22: 2026-10-21 | E22: minimax/dist/20261022_MiniMax收支模型_v0_2.xlsx Valuation!D7 | F22: 187.6 | G22: 2026-10-23｜etnet；老虎 | H22: =IF(ISNUMBER(F22),F22,C22)
A23: 02513 | B23: HKD | F23: 499 | G23: 2026-10-23｜老虎 | H23: =IF(ISNUMBER(F23),F23,C23)
A24: OpenAI | B24: USD | H24: 未上市
A25: Anthropic | B25: USD | H25: 未上市
A26: AMD | B26: USD | C26: 516.79 | D26: 2026-10-23 | E26: amd/dist/20261025_AMD模型_v0.2.1.xlsx Val!B67 | H26: =C26
A27: 2454 | B27: TWD | C27: 4010 | D27: 2026-10-22 | E27: mediatek/dist/20261025_聯發科模型_v0.1.xlsx Val!B53 | H27: =C27
A28: MRVL | B28: USD | C28: 228.51 | D28: 2026-10-23 | E28: mrvl/dist/20261025_邁威爾模型_v0.2.xlsx Val!B68 | H28: =C28
A29: 3661 | B29: TWD | C29: 3495 | D29: 2026-10-22 | E29: alchip/dist/20261025_世芯-KY模型_v0.1.xlsx Val!B53 | H29: =C29
A30: 3443 | B30: TWD | C30: 7585 | D30: 2026-10-22 | E30: guc/dist/20261025_創意模型_v0.1.xlsx Val!B53 | H30: =C30
A31: 285A | B31: JPY | C31: 12755 | D31: 2026-10-23 | E31: kioxia/dist/20261025_Kioxia模型_v0.1.xlsx Val!B82 | H31: =C31
A32: SNDK | B32: USD | C32: 1238.03 | D32: 2026-10-23 | E32: sndk/dist/20261025_SanDisk模型_v0.1.xlsx Val!B82 | H32: =C32
A33: COHR | B33: USD | C33: 209.17 | D33: 2026-10-23 | E33: cohr/dist/20261025_Coherent模型_v0.2.xlsx Val!B64 | H33: =C33
A34: LITE | B34: USD | C34: 756.17 | D34: 2026-10-23 | E34: lite/dist/20261025_Lumentum模型_v0.2.xlsx Val!B63 | H34: =C34
A35: 300502 | B35: CNY | C35: 261 | D35: 2026-10-23 | E35: eoptolink/dist/20261025_新易盛模型_v0.2.xlsx Val!B63 | H35: =C35
A36: 2345 | B36: TWD | C36: 1775 | D36: 2026-10-22 | E36: accton/dist/20261025_智邦模型_v0.2.xlsx Val!B66 | H36: =C36
A37: FN | B37: USD | C37: 314.94 | D37: 2026-10-23 | E37: fabrinet/dist/20261025_Fabrinet模型_v0.1.xlsx Val!B64 | H37: =C37
... A64: 3653 | B64: TWD | C64: 6070 | D64: 2026-10-22 | E64: jentech/dist/20261025_健策模型_v0.1.xlsx Val!B56 | H64: =C64

Sheet 估值
A1: 代號 | B1: 公司 | C1: 層級 | D1: 次產業 | E1: 方法 | F1: 中心候選 1 | G1: 中心候選 1 來源 | H1: 中心候選 2 | I1: 中心候選 2 來源 | J1: 悲觀情境候選 1 | K1: 悲觀情境候選 1 來源 | L1: 悲觀情境候選 2 | M1: 悲觀情境候選 2 來源 | N1: 採用價 | O1: 中心價 | P1: 悲觀情境價 | Q1: 中心空間 | R1: 悲觀情境空間 | S1: 分級 | T1: 對照口徑空間 | U1: 對照口徑 | V1: 現價 ÷ 模型 FY2028 EPS（A／B／C） | W1: 註記 | X1: 輔助 1 | Y1: 輔助 2 | Z1: 模型價日以來漲跌 | AA1: 價格變動旗標 | AB1: 收支口徑 | AC1: 收支列（模型） | AD1: 收支序列 | AE1: 期間合計 | AF1: 最小值 | AG1: 收支來源 | AH1: 收支關卡 | AI1: 最終分級 | AJ1: 上檔空間級距 | AK1: 投資建議與上檔空間依據
A2: NVDA | B2: NVIDIA | C2: =價值鏈!A5 | D2: 運算 | E2: 加權目標價（DCF 50%＋Comparable 50%） | F2: 251.8803 | G2: nvidia/dist/20261025_NVIDIA模型_v0.2.xlsx Val!B40 | J2: 128.62269 | K2: nvidia/dist/20261025_NVIDIA模型_v0.2.xlsx Val!B47 | N2: =價格!H2 | O2: =MIN(F2,H2) | P2: =MIN(J2,L2) | Q2: 0.19397183 | R2: =P2/N2-1 | S2: =IF(Q2>0.5,"強力買進",IF(Q2>0.25,"買進",IF(Q2>=-0.25,"中立",IF(Q2>=-0.5,"放空","強力放空")))) | T2: =467.571184194614/N2-1 | U2: 舊法：規則值情境加權價（參考，Val!B170） | V2: 14.3 ／ 14.3 ／ 14.3 | W2: DCF 目標價 235.0（Val!B23）；Comparable 目標價 268.7（Val!B41）；市場共識目標價 328.9（Val!B42，外部、僅供對照）；價格帶 C～A 情境 DCF 128.6～313.1 | Z2: =IF(ISNUMBER(價格!C2),價格!H2/價格!C2-1,"") | AA2: =IF(Z2="","",IF(ABS(Z2)>0.2,"模型尚未反映期間變化","")) | AB2: 淨利 | AC2: PL 頁各情境模型年度淨利（不含實績） | AD2: 12 個情境年度淨利（不含實績），全部為正 | AE2: 4314.7715 | AF2: 219.76039 | AG2: [Derived] nvidia/dist/20261025_NVIDIA模型_v0.2.xlsx PL!D12…PL!G292 | AH2: =IF(AB2="淨利",IF(AF2>0,"通過（淨利）","不通過"),IF(AE2<0,"不通過","通過（現金流）")) | AI2: =IF(S2="未上市","未上市",IF(AH2="不通過","收支不足",S2)) | AJ2: =IF(Q2>0.5,"大於 50%",IF(Q2>0.25,"25%–50%",IF(Q2>=0,"0%–25%",IF(Q2>=-0.25,"0%～−25%",IF(Q2>=-0.5,"−25%～−50%","小於 −50%"))))) | AK2: 上檔空間 nvidia/dist/20261025_NVIDIA模型_v0.2.xlsx Val!B43；投資建議：模型尚未補列，依 AI半導體 固定規則自算；級距：模型尚未補列，依 AI半導體 固定規則自算
A3: AVGO | B3: Broadcom | C3: =價值鏈!A5 | D3: 運算 | E3: 加權目標價（DCF 50%＋Comparable 50%） | F3: 340.64325 | G3: avgo/dist/20261025_Broadcom模型_v0.2.xlsx Val!B40 | J3: 221.91455 | K3: avgo/dist/20261025_Broadcom模型_v0.2.xlsx Val!B47 | N3: =價格!H3 | O3: =MIN(F3,H3) | P3: =MIN(J3,L3) | Q3: 0.058950661 | R3: =P3/N3-1 | S3: =IF(Q3>0.5,"強力買進",IF(Q3>0.25,"買進",IF(Q3>=-0.25,"中立",IF(Q3>=-0.5,"放空","強力放空")))) | T3: =647.367676593253/N3-1 | U3: 舊法：規則值情境加權價（參考，Val!B104） | V3: 15.3 ／ 18.0 ／ 21.7 | W3: DCF 目標價 324.6（Val!B23）；Comparable 目標價 356.7（Val!B41）；市場共識目標價 529.1（Val!B42，外部、僅供對照）；價格帶 C～A 情境 DCF 221.9～394.3 | Z3: =IF(ISNUMBER(價格!C3),價格!H3/價格!C3-1,"") | AA3: =IF(Z3="","",IF(ABS(Z3)>0.2,"模型尚未反映期間變化","")) | AB3: 淨利 | AC3: PL 頁各情境模型年度淨利（不含實績） | AD3: 8 個情境年度淨利（不含實績），全部為正 | AE3: 711.22804 | AF3: 57.42012 | AG3: [Derived] avgo/dist/20261025_Broadcom模型_v0.2.xlsx PL!D13…PL!G39 | AH3: =IF(AB3="淨利",IF(AF3>0,"通過（淨利）","不通過"),IF(AE3<0,"不通過","通過（現金流）")) | AI3: =IF(S3="未上市","未上市",IF(AH3="不通過","收支不足",S3)) | AJ3: =IF(Q3>0.5,"大於 50%",IF(Q3>0.25,"25%–50%",IF(Q3>=0,"0%–25%",IF(Q3>=-0.25,"0%～−25%",IF(Q3>=-0.5,"−25%～−50%","小於 −50%"))))) | AK3: 上檔空間 avgo/dist/20261025_Broadcom模型_v0.2.xlsx Val!B43；投資建議：模型尚未補列，依 AI半導體 固定規則自算；級距：模型尚未補列，依 AI半導體 固定規則自算
A4: 000660 | B4: SK 海力士 | C4: =價值鏈!A6 | D4: 記憶體 | E4: 加權目標價（DCF 50%＋Comparable 50%） | F4: 3087845.4 | G4: skhynix/dist/20261025_SK海力士模型_v0.5.xlsx Val!B161 | J4: 1308904.1 | K4: skhynix/dist/20261025_SK海力士模型_v0.5.xlsx Val!D145 | N4: =價格!H4 | O4: =MIN(F4,H4) | P4: =MIN(J4,L4) | Q4: 1.4180465 | R4: =P4/N4-1 | S4: =IF(Q4>0.5,"強力買進",IF(Q4>0.25,"買進",IF(Q4>=-0.25,"中立",IF(Q4>=-0.5,"放空","強力放空")))) | T4: =1392208.55280262/N4-1 | U4: 舊法：規則值情境加權價（參考，Val!B176） | W4: DCF 目標價 3,709,129.8（Val!B146）；Comparable 目標價 2,466,561.0（Val!B162）；市場共識目標價 3,096,288.0（Val!B163，外部、僅供對照）；價格帶 C～A 情境 DCF 1,308,904.1～6,513,978.2 | Z4: =IF(ISNUMBER(價格!C4),價格!H4/價格!C4-1,"") | AA4: =IF(Z4="","",IF(ABS(Z4)>0.2,"模型尚未反映期間變化","")) | AB4: 現金流 | AC4: 自由現金流（淨利＋折舊 − 資本支出） | AD4: 2026（基準） 232.9、2027 A 301.3、2028 A 334.4、2029 A 372.3、2027 B 293.3、2028 B 151.6、2029 B 188.0、2027 C 293.3、2028 C 77.1、2029 C 63.7 | AE4: 2307.9577 | AF4: 63.73385 | AG4: [Derived] skhynix/dist/20261025_SK海力士模型_v0.5.xlsx Y!C22…Y!L22 | AH4: =IF(AB4="淨利",IF(AF4>0,"通過（淨利）","不通過"),IF(AE4<0,"不通過","通過（現金流）")) | AI4: =IF(S4="未上市","未上市",IF(AH4="不通過","收支不足",S4)) | AJ4: =IF(Q4>0.5,"大於 50%",IF(Q4>0.25,"25%–50%",IF(Q4>=0,"0%–25%",IF(Q4>=-0.25,"0%～−25%",IF(Q4>=-0.5,"−25%～−50%","小於 −50%"))))) | AK4: 上檔空間 skhynix/dist/20261025_SK海力士模型_v0.5.xlsx Val!B164；投資建議：模型尚未補列，依 AI半導體 固定規則自算；級距：模型尚未補列，依 AI半導體 固定規則自算
A5: 005930 | B5: 三星電子 | C5: =價值鏈!A6 | D5: 記憶體 | E5: 加權目標價（DCF 50%＋Comparable 50%） | F5: 477143.17 | G5: samsung/dist/20261025_三星電子模型_v0.3.xlsx Val!B161 | J5: 218882.5 | K5: samsung/dist/20261025_三星電子模型_v0.3.xlsx Val!D145 | N5: =價格!H5 | O5: =MIN(F5,H5) | P5: =MIN(J5,L5) | Q5: 1.2141215 | R5: =P5/N5-1 | S5: =IF(Q5>0.5,"強力買進",IF(Q5>0.25,"買進",IF(Q5>=-0.25,"中立",IF(Q5>=-0.5,"放空","強力放空")))) | T5: =255831.994790815/N5-1 | U5: 舊法：規則值情境加權價（參考，Val!B176） | W5: DCF 目標價 486,542.2（Val!B146）；Comparable 目標價 467,744.1（Val!B162）；市場共識目標價 478,906.0（Val!B163，外部、僅供對照）；價格帶 C～A 情境 DCF 218,882.5～818,535.4 | Z5: =IF(ISNUMBER(價格!C5),價格!H5/價格!C5-1,"") | AA5: =IF(Z5="","",IF(ABS(Z5)>0.2,"模型尚未反映期間變化","")) | AB5: 現金流 | AC5: 自由現金流（淨利＋折舊 − 資本支出） | AD5: 2026（基準） 291.2、2027 A 506.0、2028 A 561.3、2029 A 611.6、2027 B 492.5、2028 B 274.2、2029 B 324.1、2027 C 492.5、2028 C 165.3、2029 C 138.4 | AE5: 3857.2674 | AF5: 138.43 | AG5: [Derived] samsung/dist/20261025_三星電子模型_v0.3.xlsx Y!C22…Y!L22 | AH5: =IF(AB5="淨利",IF(AF5>0,"通過（淨利）","不通過"),IF(AE5<0,"不通過","通過（現金流）")) | AI5: =IF(S5="未上市","未上市",IF(AH5="不通過","收支不足",S5)) | AJ5: =IF(Q5>0.5,"大於 50%",IF(Q5>0.25,"25%–50%",IF(Q5>=0,"0%–25%",IF(Q5>=-0.25,"0%～−25%",IF(Q5>=-0.5,"−25%～−50%","小於 −50%"))))) | AK5: 上檔空間 samsung/dist/20261025_三星電子模型_v0.3.xlsx Val!B164；投資建議：模型尚未補列，依 AI半導體 固定規則自算；級距：模型尚未補列，依 AI半導體 固定規則自算
A6: MU | B6: 美光 | C6: =價值鏈!A6 | D6: 記憶體 | E6: 加權目標價（DCF 50%＋Comparable 50%） | F6: 684.08947 | G6: micron/dist/20261025_美光模型_v0.4.xlsx Val!B208 | J6: 321.89649 | K6: micron/dist/20261025_美光模型_v0.4.xlsx Val!D192 | N6: =價格!H6 | O6: =MIN(F6,H6) | P6: =MIN(J6,L6) | Q6: -0.22045528 | R6: =P6/N6-1 | S6: =IF(Q6>0.5,"強力買進",IF(Q6>0.25,"買進",IF(Q6>=-0.25,"中立",IF(Q6>=-0.5,"放空","強力放空")))) | T6: =348.754265504643/N6-1 | U6: 舊法：規則值情境加權價（參考，Val!B223） | W6: DCF 目標價 932.6（Val!B193）；Comparable 目標價 435.6（Val!B209）；市場共識目標價 1,560.6（Val!B210，外部、僅供對照）；價格帶 C～A 情境 DCF 321.9～1,714.0 | Z6: =IF(ISNUMBER(價格!C6),價格!H6/價格!C6-1,"") | AA6: =IF(Z6="","",IF(ABS(Z6)>0.2,"模型尚未反映期間變化","")) | AB6: 現金流 | AC6: 自由現金流（淨利＋折舊 − 資本支出） | AD6: FY2026（基準） 67.1、FY2027 A 152.2、FY2028 A 172.3、FY2029 A 191.8、FY2027 B 154.2、FY2028 B 87.7、FY2029 B 77.3、FY2027 C 154.2、FY2028 C 59.6、FY2029 C 8.8 | AE6: 1125.2991 | AF6: 8.8007654 | AG6: [Derived] micron/dist/20261025_美光模型_v0.4.xlsx Y!C22…Y!L22 | AH6: =IF(AB6="淨利",IF(AF6>0,"通過（淨利）","不通過"),IF(AE6<0,"不通過","通過（現金流）")) | AI6: =IF(S6="未上市","未上市",IF(AH6="不通過","收支不足",S6)) | AJ6: =IF(Q6>0.5,"大於 50%",IF(Q6>0.25,"25%–50%",IF(Q6>=0,"0%–25%",IF(Q6>=-0.25,"0%～−25%",IF(Q6>=-0.5,"−25%～−50%","小於 −50%"))))) | AK6: 上檔空間 micron/dist/20261025_美光模型_v0.4.xlsx Val!B211；投資建議：模型尚未補列，依 AI半導體 固定規則自算；級距：模型尚未補列，依 AI半導體 固定規則自算
A7: 2330 | B7: 台積電 | C7: =價值鏈!A11 | D7: 代工與封測 | E7: 加權目標價（DCF 50%＋Comparable 50%） | F7: 2446.0233 | G7: tsmc/dist/20261025_台積電模型_v0.3.xlsx Val!B94 | J7: 1495.889 | K7: tsmc/dist/20261025_台積電模型_v0.3.xlsx Val!D78 | N7: =價格!H7 | O7: =MIN(F7,H7) | P7: =MIN(J7,L7) | Q7: 0.025586289 | R7: =P7/N7-1 | S7: =IF(Q7>0.5,"強力買進",IF(Q7>0.25,"買進",IF(Q7>=-0.25,"中立",IF(Q7>=-0.5,"放空","強力放空")))) | T7: =3022.97680876707/N7-1 | U7: 舊法：規則值情境加權價（參考，Val!B107） | W7: DCF 目標價 2,150.2（Val!B79）；Comparable 目標價 2,741.9（Val!B95）；市場共識目標價 3,390.4（Val!B96，外部、僅供對照）；價格帶 C～A 情境 DCF 1,495.9～2,769.1 | Z7: =IF(ISNUMBER(價格!C7),價格!H7/價格!C7-1,"") | AA7: =IF(Z7="","",IF(ABS(Z7)>0.2,"模型尚未反映期間變化","")) | AB7: 淨利 | AC7: PL 頁各情境模型年度淨利（不含實績） | AD7: 19 個情境年度淨利（不含實績），全部為正 | AE7: 2206.9659 | AF7: 84.633409 | AG7: [Derived] tsmc/dist/20261025_台積電模型_v0.3.xlsx PL!B12…PL!T12 | AH7: =IF(AB7="淨利",IF(AF7>0,"通過（淨利）","不通過"),IF(AE7<0,"不通過","通過（現金流）")) | AI7: =IF(S7="未上市","未上市",IF(AH7="不通過","收支不足",S7)) | AJ7: =IF(Q7>0.5,"大於 50%",IF(Q7>0.25,"25%–50%",IF(Q7>=0,"0%–25%",IF(Q7>=-0.25,"0%～−25%",IF(Q7>=-0.5,"−25%～−50%","小於 −50%"))))) | AK7: 上檔空間 tsmc/dist/20261025_台積電模型_v0.3.xlsx Val!B97；投資建議：模型尚未補列，依 AI半導體 固定規則自算；級距：模型尚未補列，依 AI半導體 固定規則自算
A8: ANET | B8: Arista | C8: =價值鏈!A7 | D8: 網通 | E8: 加權目標價（DCF 50%＋Comparable 50%） | F8: 99.463038 | G8: arista/dist/20261025_Arista模型_v0.2.xlsx Val!B40 | J8: 66.550487 | K8: arista/dist/20261025_Arista模型_v0.2.xlsx Val!B47 | N8: =價格!H8 | O8: =MIN(F8,H8) | P8: =MIN(J8,L8) | Q8: -0.42296781 | R8: =P8/N8-1 | S8: =IF(Q8>0.5,"強力買進",IF(Q8>0.25,"買進",IF(Q8>=-0.25,"中立",IF(Q8>=-0.5,"放空","強力放空")))) | T8: =174.075889279442/N8-1 | U8: 舊法：規則值情境加權價（參考，Val!B137） | V8: 28.8 ／ 31.3 ／ 34.7 | W8: DCF 目標價 87.2（Val!B23）；Comparable 目標價 111.7（Val!B41）；市場共識目標價 243.6（Val!B42，外部、僅供對照）；價格帶 C～A 情境 DCF 66.6～101.9 | Z8: =IF(ISNUMBER(價格!C8),價格!H8/價格!C8-1,"") | AA8: =IF(Z8="","",IF(ABS(Z8)>0.2,"模型尚未反映期間變化","")) | AB8: 淨利 | AC8: PL 頁各情境模型年度淨利（不含實績） | AD8: 8 個情境年度淨利（不含實績），全部為正 | AE8: 56.290329 | AF8: 5.224907 | AG8: [Derived] arista/dist/20261025_Arista模型_v0.2.xlsx PL!D12…PL!G36 | AH8: =IF(AB8="淨利",IF(AF8>0,"通過（淨利）","不通過"),IF(AE8<0,"不通過","通過（現金流）")) | AI8: =IF(S8="未上市","未上市",IF(AH8="不通過","收支不足",S8)) | AJ8: =IF(Q8>0.5,"大於 50%",IF(Q8>0.25,"25%–50%",IF(Q8>=0,"0%–25%",IF(Q8>=-0.25,"0%～−25%",IF(Q8>=-0.5,"−25%～−50%","小於 −50%"))))) | AK8: 上檔空間 arista/dist/20261025_Arista模型_v0.2.xlsx Val!B43；投資建議：模型尚未補列，依 AI半導體 固定規則自算；級距：模型尚未補列，依 AI半導體 固定規則自算
A9: 300308 | B9: 中際旭創 | C9: =價值鏈!A7 | D9: 網通 | E9: 加權目標價（DCF 50%＋Comparable 50%） | F9: 1355.2557 | G9: innolight/dist/20261025_中際旭創模型_v0.2.xlsx Val!B39 | J9: 498.17609 | K9: innolight/dist/20261025_中際旭創模型_v0.2.xlsx Val!D23 | N9: =價格!H9 | O9: =MIN(F9,H9) | P9: =MIN(J9,L9) | Q9: 1.2121928 | R9: =P9/N9-1 | S9: =IF(Q9>0.5,"強力買進",IF(Q9>0.25,"買進",IF(Q9>=-0.25,"中立",IF(Q9>=-0.5,"放空","強力放空")))) | T9: =2265.72535634618/N9-1 | U9: 舊法：規則值情境加權價（參考，Val!B133） | V9: 12.3 ／ 15.5 ／ 21.0 | W9: DCF 目標價 831.5（Val!B24）；Comparable 目標價 1,879.1（Val!B40）；市場共識目標價 1,321.0（Val!B41，外部、僅供對照）；價格帶 C～A 情境 DCF 498.2～1,049.4 | Z9: =IF(ISNUMBER(價格!C9),價格!H9/價格!C9-1,"") | AA9: =IF(Z9="","",IF(ABS(Z9)>0.2,"模型尚未反映期間變化","")) | AB9: 淨利 | AC9: PL 頁各情境模型年度淨利（不含實績） | AD9: 17 個情境年度淨利（不含實績），全部為正 | AE9: 1034.1628 | AF9: 31.828119 | AG9: [Derived] innolight/dist/20261025_中際旭創模型_v0.2.xlsx PL!D12…PL!J36 | AH9: =IF(AB9="淨利",IF(AF9>0,"通過（淨利）","不通過"),IF(AE9<0,"不通過","通過（現金流）")) | AI9: =IF(S9="未上市","未上市",IF(AH9="不通過","收支不足",S9)) | AJ9: =IF(Q9>0.5,"大於 50%",IF(Q9>0.25,"25%–50%",IF(Q9>=0,"0%–25%",IF(Q9>=-0.25,"0%～−25%",IF(Q9>=-0.5,"−25%～−50%","小於 −50%"))))) | AK9: 上檔空間 innolight/dist/20261025_中際旭創模型_v0.2.xlsx Val!B42；投資建議：模型尚未補列，依 AI半導體 固定規則自算；級距：模型尚未補列，依 AI半導體 固定規則自算
A10: 2308 | B10: 台達電 | C10: =價值鏈!A9 | D10: 電源與散熱 | E10: 加權目標價（DCF 50%＋Comparable 50%） | F10: 1213.7702 | G10: delta/dist/20261025_台達電模型_v0.2.xlsx Val!B119 | J10: 639.32948 | K10: delta/dist/20261025_台達電模型_v0.2.xlsx Val!D104 | N10: =價格!H10 | O10: =MIN(F10,H10) | P10: =MIN(J10,L10) | Q10: -0.24375687 | R10: =P10/N10-1 | S10: =IF(Q10>0.5,"強力買進",IF(Q10>0.25,"買進",IF(Q10>=-0.25,"中立",IF(Q10>=-0.5,"放空","強力放空")))) | T10: =1360.0134167175/N10-1 | U10: 舊法：規則值情境加權價（參考，Val!B42） | V10: 20.8 ／ 24.5 ／ 31.8 | W10: DCF 目標價 999.1（Val!B105）；Comparable 目標價 1,428.4（Val!B120）；市場共識目標價 2,502.4（Val!B121，外部、僅供對照）；價格帶 C～A 情境 DCF 639.3～1,234.7 | Z10: =IF(ISNUMBER(價格!C10),價格!H10/價格!C10-1,"") | AA10: =IF(Z10="","",IF(ABS(Z10)>0.2,"模型尚未反映期間變化","")) | AB10: 淨利 | AC10: PL 頁各情境模型年度淨利（不含實績） | AD10: 8 個情境年度淨利（不含實績），全部為正 | AE10: 1331.0311 | AF10: 98.429236 | AG10: [Derived] delta/dist/20261025_台達電模型_v0.2.xlsx PL!D13…PL!G39 | AH10: =IF(AB10="淨利",IF(AF10>0,"通過（淨利）","不通過"),IF(AE10<0,"不通過","通過（現金流）")) | AI10: =IF(S10="未上市","未上市",IF(AH10="不通過","收支不足",S10)) | AJ10: =IF(Q10>0.5,"大於 50%",IF(Q10>0.25,"25%–50%",IF(Q10>=0,"0%–25%",IF(Q10>=-0.25,"0%～−25%",IF(Q10>=-0.5,"−25%～−50%","小於 −50%"))))) | AK10: 上檔空間 delta/dist/20261025_台達電模型_v0.2.xlsx Val!B122；投資建議：模型尚未補列，依 AI半導體 固定規則自算；級距：模型尚未補列，依 AI半導體 固定規則自算
A11: 2382 | B11: 廣達 | C11: =價值鏈!A10 | D11: 伺服器組裝 | E11: 加權目標價（DCF 50%＋Comparable 50%） | F11: 566.56229 | G11: quanta/dist/20261025_廣達模型_v0.2.xlsx Val!B120 | J11: 404.06783 | K11: quanta/dist/20261025_廣達模型_v0.2.xlsx Val!D104 | N11: =價格!H11 | O11: =MIN(F11,H11) | P11: =MIN(J11,L11) | Q11: 0.75951022 | R11: =P11/N11-1 | S11: =IF(Q11>0.5,"強力買進",IF(Q11>0.25,"買進",IF(Q11>=-0.25,"中立",IF(Q11>=-0.5,"放空","強力放空")))) | T11: =490.548184039647/N11-1 | U11: 舊法：規則值情境加權價（參考，Val!B42） | V11: 6.2 ／ 7.7 ／ 10.2 | W11: DCF 目標價 644.3（Val!B105）；Comparable 目標價 488.9（Val!B121）；市場共識目標價 427.8（Val!B122，外部、僅供對照）；價格帶 C～A 情境 DCF 404.1～808.7 | Z11: =IF(ISNUMBER(價格!C11),價格!H11/價格!C11-1,"") | AA11: =IF(Z11="","",IF(ABS(Z11)>0.2,"模型尚未反映期間變化","")) | AB11: 淨利 | AC11: PL 頁各情境模型年度淨利（不含實績） | AD11: 8 個情境年度淨利（不含實績），全部為正 | AE11: 1294.0293 | AF11: 110.71367 | AG11: [Derived] quanta/dist/20261025_廣達模型_v0.2.xlsx PL!D13…PL!G39 | AH11: =IF(AB11="淨利",IF(AF11>0,"通過（淨利）","不通過"),IF(AE11<0,"不通過","通過（現金流）")) | AI11: =IF(S11="未上市","未上市",IF(AH11="不通過","收支不足",S11)) | AJ11: =IF(Q11>0.5,"大於 50%",IF(Q11>0.25,"25%–50%",IF(Q11>=0,"0%–25%",IF(Q11>=-0.25,"0%～−25%",IF(Q11>=-0.5,"−25%～−50%","小於 −50%"))))) | AK11: 上檔空間 quanta/dist/20261025_廣達模型_v0.2.xlsx Val!B123；投資建議：模型尚未補列，依 AI半導體 固定規則自算；級距：模型尚未補列，依 AI半導體 固定規則自算
A12: 4062 | B12: Ibiden | C12: =價值鏈!A8 | D12: 載板與 PCB | E12: 加權目標價（DCF 50%＋Comparable 50%） | F12: 5236.2411 | G12: ibiden/dist/20261025_Ibiden模型_v0.2.xlsx Val!B96 | J12: 1293.7578 | K12: ibiden/dist/20261025_Ibiden模型_v0.2.xlsx Val!D80 | N12: =價格!H12 | O12: =MIN(F12,H12) | P12: =MIN(J12,L12) | Q12: -0.38484009 | R12: =P12/N12-1 | S12: =IF(Q12>0.5,"強力買進",IF(Q12>0.25,"買進",IF(Q12>=-0.25,"中立",IF(Q12>=-0.5,"放空","強力放空")))) | T12: =9531.45203105499/N12-1 | U12: 舊法：規則值情境加權價（參考，Val!B38） | V12: 38.9 ／ 46.1 ／ 56.8 | W12: DCF 目標價 1,931.2（Val!B81）；Comparable 目標價 8,541.2（Val!B97）；市場共識目標價 12,432.4（Val!B98，外部、僅供對照）；價格帶 C～A 情境 DCF 1,293.8～2,378.3 | Z12: =IF(ISNUMBER(價格!C12),價格!H12/價格!C12-1,"") | AA12: =IF(Z12="","",IF(ABS(Z12)>0.2,"模型尚未反映期間變化","")) | AB12: 淨利 | AC12: PL 頁各情境模型年度淨利（不含實績） | AD12: 8 個情境年度淨利（不含實績），全部為正 | AE12: 854.69359 | AF12: 84 | AG12: [Derived] ibiden/dist/20261025_Ibiden模型_v0.2.xlsx PL!D11…PL!G33 | AH12: =IF(AB12="淨利",IF(AF12>0,"通過（淨利）","不通過"),IF(AE12<0,"不通過","通過（現金流）")) | AI12: =IF(S12="未上市","未上市",IF(AH12="不通過","收支不足",S12)) | AJ12: =IF(Q12>0.5,"大於 50%",IF(Q12>0.25,"25%–50%",IF(Q12>=0,"0%–25%",IF(Q12>=-0.25,"0%～−25%",IF(Q12>=-0.5,"−25%～−50%","小於 −50%"))))) | AK12: 上檔空間 ibiden/dist/20261025_Ibiden模型_v0.2.xlsx Val!B99；投資建議：模型尚未補列，依 AI半導體 固定規則自算；級距：模型尚未補列，依 AI半導體 固定規則自算
A13: 6857 | B13: Advantest | C13: =價值鏈!A12 | D13: 設備與材料 | E13: 加權目標價（DCF 50%＋Comparable 50%） | F13: 23221.592 | G13: advantest/dist/20261025_Advantest模型_v0.3.xlsx Val!B146 | J13: 7893.3663 | K13: advantest/dist/20261025_Advantest模型_v0.3.xlsx Val!D130 | N13: =價格!H13 | O13: =MIN(F13,H13) | P13: =MIN(J13,L13) | Q13: -0.28195449 | R13: =P13/N13-1 | S13: =IF(Q13>0.5,"強力買進",IF(Q13>0.25,"買進",IF(Q13>=-0.25,"中立",IF(Q13>=-0.5,"放空","強力放空")))) | T13: =24494.453736442/N13-1 | U13: 舊法：規則值情境加權價（參考，Val!B102） | W13: DCF 目標價 16,539.5（Val!B131）；Comparable 目標價 29,903.7（Val!B147）；市場共識目標價 42,686.0（Val!B148，外部、僅供對照）；價格帶 C～A 情境 DCF 7,893.4～23,027.5 | Z13: =IF(ISNUMBER(價格!C13),價格!H13/價格!C13-1,"") | AA13: =IF(Z13="","",IF(ABS(Z13)>0.2,"模型尚未反映期間變化","")) | AB13: 淨利 | AC13: PL 頁各情境模型年度淨利（不含實績） | AD13: 10 個情境年度淨利（不含實績），全部為正 | AE13: 7834.3455 | AF13: 574.3864 | AG13: [Derived] advantest/dist/20261025_Advantest模型_v0.3.xlsx PL!D12…PL!G34 | AH13: =IF(AB13="淨利",IF(AF13>0,"通過（淨利）","不通過"),IF(AE13<0,"不通過","通過（現金流）")) | AI13: =IF(S13="未上市","未上市",IF(AH13="不通過","收支不足",S13)) | AJ13: =IF(Q13>0.5,"大於 50%",IF(Q13>0.25,"25%–50%",IF(Q13>=0,"0%–25%",IF(Q13>=-0.25,"0%～−25%",IF(Q13>=-0.5,"−25%～−50%","小於 −50%"))))) | AK13: 上檔空間 advantest/dist/20261025_Advantest模型_v0.3.xlsx Val!B149；投資建議：模型尚未補列，依 AI半導體 固定規則自算；級距：模型尚未補列，依 AI半導體 固定規則自算
A14: 6146 | B14: Disco | C14: =價值鏈!A12 | D14: 設備與材料 | E14: 加權目標價（DCF 50%＋Comparable 50%） | F14: 40374.83 | G14: disco/dist/20261025_Disco模型_v0.2.1.xlsx Val!B107 | J14: 16343.609 | K14: disco/dist/20261025_Disco模型_v0.2.1.xlsx Val!D91 | N14: =價格!H14 | O14: =MIN(F14,H14) | P14: =MIN(J14,L14) | Q14: -0.18087177 | R14: =P14/N14-1 | S14: =IF(Q14>0.5,"強力買進",IF(Q14>0.25,"買進",IF(Q14>=-0.25,"中立",IF(Q14>=-0.5,"放空","強力放空")))) | T14: =45104.6418701108/N14-1 | U14: 舊法：規則值情境加權價（參考，Val!B63） | W14: DCF 目標價 22,991.0（Val!B92）；Comparable 目標價 57,758.6（Val!B108）；市場共識目標價 81,575.0（Val!B109，外部、僅供對照）；價格帶 C～A 情境 DCF 16,343.6～27,699.3 | Z14: =IF(ISNUMBER(價格!C14),價格!H14/價格!C14-1,"") | AA14: =IF(Z14="","",IF(ABS(Z14)>0.2,"模型尚未反映期間變化","")) | AB14: 淨利 | AC14: PL 頁各情境模型年度淨利（不含實績） | AD14: 10 個情境年度淨利（不含實績），全部為正 | AE14: 1803.9672 | AF14: 143.89119 | AG14: [Derived] disco/dist/20261025_Disco模型_v0.2.1.xlsx PL!D16…PL!G52 | AH14: =IF(AB14="淨利",IF(AF14>0,"通過（淨利）","不通過"),IF(AE14<0,"不通過","通過（現金流）")) | AI14: =IF(S14="未上市","未上市",IF(AH14="不通過","收支不足",S14)) | AJ14: =IF(Q14>0.5,"大於 50%",IF(Q14>0.25,"25%–50%",IF(Q14>=0,"0%–25%",IF(Q14>=-0.25,"0%～−25%",IF(Q14>=-0.5,"−25%～−50%","小於 −50%"))))) | AK14: 上檔空間 disco/dist/20261025_Disco模型_v0.2.1.xlsx Val!B110；投資建議：模型尚未補列，依 AI半導體 固定規則自算；級距：模型尚未補列，依 AI半導體 固定規則自算
A15: MSFT | B15: Microsoft | C15: =價值鏈!A3 | D15: AI 雲端平台 | E15: 模型加權目標價 | F15: 359.05884 | G15: microsoft/dist/20261025_Microsoft收支模型_v0_2_2.xlsx 摘要!C7 | J15: 359.05884 | K15: microsoft/dist/20261025_Microsoft收支模型_v0_2_2.xlsx 摘要!C7 | L15: 360.15761 | M15: microsoft/dist/20261025_Microsoft收支模型_v0_2_2.xlsx 摘要!C10 | N15: =價格!H15 | O15: =MIN(F15,H15) | P15: =MIN(J15,L15) | Q15: =O15/N15-1 | R15: =P15/N15-1 | S15: =IF(Q15>0.5,"強力買進",IF(Q15>0.25,"買進",IF(Q15>=-0.25,"中立",IF(Q15>=-0.5,"放空","強力放空")))) | W15: 模型點位 $359.1（模型日現價 $529.76）；情境區間 $360.2–$380.6，方法區間 $353.5–$359.1｜MAG 模型終值占 EV 逾 90%，評價口徑待 MAG v0.3 | Z15: =IF(ISNUMBER(價格!C15),價格!H15/價格!C15-1,"") | AA15: =IF(Z15="","",IF(ABS(Z15)>0.2,"模型尚未反映期間變化","")) | AB15: 現金流 | AC15: 營運缺口＋股利＋回購 | AD15: FY27 -7.8、FY28 27.7、FY29 70.2、FY30 76.7、FY31 11.2 | AE15: 178.04013 | AF15: -7.8317387 | AG15: [Derived] microsoft/dist/20261025_Microsoft收支模型_v0_2_2.xlsx 各期收支!C54＋C23＋C24…各期收支!G54＋G23＋G24 | AH15: =IF(AB15="淨利",IF(AF15>0,"通過（淨利）","不通過"),IF(AE15<0,"不通過","通過（現金流）")) | AI15: =IF(S15="未上市","未上市",IF(AH15="不通過","收支不足",S15)) | AJ15: =IF(Q15>0.5,"大於 50%",IF(Q15>0.25,"25%–50%",IF(Q15>=0,"0%–25%",IF(Q15>=-0.25,"0%～−25%",IF(Q15>=-0.5,"−25%～−50%","小於 −50%"))))) | AK15: 上檔空間＝模型加權目標價 microsoft/dist/20261025_Microsoft收支模型_v0_2_2.xlsx 摘要!C7 ÷ 外部收盤價 − 1，依本地圖五級規則自算（模型自身評等以模型日價計、級距不同，不採用；原值見模型摘要頁）
A16: AMZN | B16: Amazon | C16: =價值鏈!A3 | D16: AI 雲端平台 | E16: 模型加權目標價 | F16: 201.71431 | G16: amazon/dist/20261025_Amazon收支模型_v0_2_2.xlsx 摘要!C7 | J16: 201.71431 | K16: amazon/dist/20261025_Amazon收支模型_v0_2_2.xlsx 摘要!C7 | L16: 201.13616 | M16: amazon/dist/20261025_Amazon收支模型_v0_2_2.xlsx 摘要!C10 | N16: =價格!H16 | O16: =MIN(F16,H16) | P16: =MIN(J16,L16) | Q16: =O16/N16-1 | R16: =P16/N16-1 | S16: =IF(Q16>0.5,"強力買進",IF(Q16>0.25,"買進",IF(Q16>=-0.25,"中立",IF(Q16>=-0.5,"放空","強力放空")))) | W16: 模型點位 $201.7（模型日現價 $259.92）；情境區間 $201.1–$212.3，方法區間 $197.5–$201.7｜MAG 模型終值占 EV 逾 90%，評價口徑待 MAG v0.3 | Z16: =IF(ISNUMBER(價格!C16),價格!H16/價格!C16-1,"") | AA16: =IF(Z16="","",IF(ABS(Z16)>0.2,"模型尚未反映期間變化","")) | AB16: 現金流 | AC16: 營運缺口＋股利＋回購 | AD16: 2026 -122.8、2027 -71.8、2028 -34.2、2029 6.1、2030 -70.1 | AE16: -292.84158 | AF16: -122.81974 | AG16: [Derived] amazon/dist/20261025_Amazon收支模型_v0_2_2.xlsx 各期收支!C54＋C23＋C24…各期收支!G54＋G23＋G24 | AH16: =IF(AB16="淨利",IF(AF16>0,"通過（淨利）","不通過"),IF(AE16<0,"不通過","通過（現金流）")) | AI16: =IF(S16="未上市","未上市",IF(AH16="不通過","收支不足",S16)) | AJ16: =IF(Q16>0.5,"大於 50%",IF(Q16>0.25,"25%–50%",IF(Q16>=0,"0%–25%",IF(Q16>=-0.25,"0%～−25%",IF(Q16>=-0.5,"−25%～−50%","小於 −50%"))))) | AK16: 上檔空間＝模型加權目標價 amazon/dist/20261025_Amazon收支模型_v0_2_2.xlsx 摘要!C7 ÷ 外部收盤價 − 1，依本地圖五級規則自算（模型自身評等以模型日價計、級距不同，不採用；原值見模型摘要頁）
A17: GOOGL | B17: Alphabet | C17: =價值鏈!A3 | D17: AI 雲端平台 | E17: 模型加權目標價 | F17: 146.09287 | G17: alphabet/dist/20261025_Alphabet收支模型_v0_2_2.xlsx 摘要!C7 | J17: 146.09287 | K17: alphabet/dist/20261025_Alphabet收支模型_v0_2_2.xlsx 摘要!C7 | L17: 122.88912 | M17: alphabet/dist/20261025_Alphabet收支模型_v0_2_2.xlsx 摘要!C10 | N17: =價格!H17 | O17: =MIN(F17,H17) | P17: =MIN(J17,L17) | Q17: =O17/N17-1 | R17: =P17/N17-1 | S17: =IF(Q17>0.5,"強力買進",IF(Q17>0.25,"買進",IF(Q17>=-0.25,"中立",IF(Q17>=-0.5,"放空","強力放空")))) | W17: 模型點位 $146.1（模型日現價 $350.50）；情境區間 $122.9–$175.1，方法區間 $144.1–$146.1｜MAG 模型終值占 EV 逾 90%，評價口徑待 MAG v0.3 | Z17: =IF(ISNUMBER(價格!C17),價格!H17/價格!C17-1,"") | AA17: =IF(Z17="","",IF(ABS(Z17)>0.2,"模型尚未反映期間變化","")) | AB17: 現金流 | AC17: 營運缺口＋股利＋回購 | AD17: 2026 -62.0、2027 -11.4、2028 10.9、2029 23.1、2030 -67.6 | AE17: -106.92794 | AF17: -67.601689 | AG17: [Derived] alphabet/dist/20261025_Alphabet收支模型_v0_2_2.xlsx 各期收支!C54＋C23＋C24…各期收支!G54＋G23＋G24 | AH17: =IF(AB17="淨利",IF(AF17>0,"通過（淨利）","不通過"),IF(AE17<0,"不通過","通過（現金流）")) | AI17: =IF(S17="未上市","未上市",IF(AH17="不通過","收支不足",S17)) | AJ17: =IF(Q17>0.5,"大於 50%",IF(Q17>0.25,"25%–50%",IF(Q17>=0,"0%–25%",IF(Q17>=-0.25,"0%～−25%",IF(Q17>=-0.5,"−25%～−50%","小於 −50%"))))) | AK17: 上檔空間＝模型加權目標價 alphabet/dist/20261025_Alphabet收支模型_v0_2_2.xlsx 摘要!C7 ÷ 外部收盤價 − 1，依本地圖五級規則自算（模型自身評等以模型日價計、級距不同，不採用；原值見模型摘要頁）
A18: ORCL | B18: Oracle | C18: =價值鏈!A3 | D18: AI 雲端平台 | E18: 模型加權目標價 | F18: 84.239968 | G18: oracle/dist/20261022_Oracle收支模型_v0_3_1.xlsx 摘要!C7 | J18: 84.239968 | K18: oracle/dist/20261022_Oracle收支模型_v0_3_1.xlsx 摘要!C7 | L18: 77.414689 | M18: oracle/dist/20261022_Oracle收支模型_v0_3_1.xlsx 摘要!C10 | N18: =價格!H18 | O18: =MIN(F18,H18) | P18: =MIN(J18,L18) | Q18: =O18/N18-1 | R18: =P18/N18-1 | S18: =IF(Q18>0.5,"強力買進",IF(Q18>0.25,"買進",IF(Q18>=-0.25,"中立",IF(Q18>=-0.5,"放空","強力放空")))) | W18: 模型點位 $84.2（模型日現價 $129.13）；情境區間 $77.4–$91.9，方法區間 $78.7–$84.2 | Z18: =IF(ISNUMBER(價格!C18),價格!H18/價格!C18-1,"") | AA18: =IF(Z18="","",IF(ABS(Z18)>0.2,"模型尚未反映期間變化","")) | AB18: 現金流 | AC18: 營運缺口＋股利 | AD18: FY27 -25.8、FY28 -21.1、FY29 23.7、FY30 9.7、FY31 8.1 | AE18: -5.4310994 | AF18: -25.803183 | AG18: [Derived] oracle/dist/20261022_Oracle收支模型_v0_3_1.xlsx 各期收支!C50＋C23…各期收支!G50＋G23 | AH18: =IF(AB18="淨利",IF(AF18>0,"通過（淨利）","不通過"),IF(AE18<0,"不通過","通過（現金流）")) | AI18: =IF(S18="未上市","未上市",IF(AH18="不通過","收支不足",S18)) | AJ18: =IF(Q18>0.5,"大於 50%",IF(Q18>0.25,"25%–50%",IF(Q18>=0,"0%–25%",IF(Q18>=-0.25,"0%～−25%",IF(Q18>=-0.5,"−25%～−50%","小於 −50%"))))) | AK18: 上檔空間＝模型加權目標價 oracle/dist/20261022_Oracle收支模型_v0_3_1.xlsx 摘要!C7 ÷ 外部收盤價 − 1，依本地圖五級規則自算（模型自身評等以模型日價計、級距不同，不採用；原值見模型摘要頁）
A19: CRWV | B19: CoreWeave | C19: =價值鏈!A4 | D19: Neocloud（GPU 租賃） | E19: 模型加權目標價 | F19: 31.986519 | G19: coreweave/dist/20261021_CoreWeave收支模型_v4_12.xlsx 摘要!C7 | J19: 31.986519 | K19: coreweave/dist/20261021_CoreWeave收支模型_v4_12.xlsx 摘要!C7 | L19: 14.715809 | M19: coreweave/dist/20261021_CoreWeave收支模型_v4_12.xlsx 摘要!C10 | N19: =價格!H19 | O19: =MIN(F19,H19) | P19: =MIN(J19,L19) | Q19: =O19/N19-1 | R19: =P19/N19-1 | S19: =IF(Q19>0.5,"強力買進",IF(Q19>0.25,"買進",IF(Q19>=-0.25,"中立",IF(Q19>=-0.5,"放空","強力放空")))) | W19: 模型點位 $32.0（模型日現價 $90.13）；情境區間 $14.7–$42.7，方法區間 $19.7–$32.0 | Z19: =IF(ISNUMBER(價格!C19),價格!H19/價格!C19-1,"") | AA19: =IF(Z19="","",IF(ABS(Z19)>0.2,"模型尚未反映期間變化","")) | AB19: 現金流 | AC19: 營運缺口（不含融資、不含還本；無股利與回購） | AD19: FY26 -28.0、FY27 -30.4、FY28 -17.6、FY29 -13.4、FY30 -16.3 | AE19: -105.70556 | AF19: -30.399858 | AG19: [Derived] coreweave/dist/20261021_CoreWeave收支模型_v4_12.xlsx 各期收支!C39…各期收支!G39 | AH19: =IF(AB19="淨利",IF(AF19>0,"通過（淨利）","不通過"),IF(AE19<0,"不通過","通過（現金流）")) | AI19: =IF(S19="未上市","未上市",IF(AH19="不通過","收支不足",S19)) | AJ19: =IF(Q19>0.5,"大於 50%",IF(Q19>0.25,"25%–50%",IF(Q19>=0,"0%–25%",IF(Q19>=-0.25,"0%～−25%",IF(Q19>=-0.5,"−25%～−50%","小於 −50%"))))) | AK19: 上檔空間＝模型加權目標價 coreweave/dist/20261021_CoreWeave收支模型_v4_12.xlsx 摘要!C7 ÷ 外部收盤價 − 1，依本地圖五級規則自算（模型自身評等以模型日價計、級距不同，不採用；原值見模型摘要頁）
A20: NBIS | B20: Nebius | C20: =價值鏈!A4 | D20: Neocloud（GPU 租賃） | E20: 模型加權目標價 | F20: 21.379205 | G20: nebius/dist/20261022_Nebius收支模型_v0_5.xlsx 摘要!C7 | J20: 21.379205 | K20: nebius/dist/20261022_Nebius收支模型_v0_5.xlsx 摘要!C7 | L20: 19.431647 | M20: nebius/dist/20261022_Nebius收支模型_v0_5.xlsx 摘要!C10 | N20: =價格!H20 | O20: =MIN(F20,H20) | P20: =MIN(J20,L20) | Q20: =O20/N20-1 | R20: =P20/N20-1 | S20: =IF(Q20>0.5,"強力買進",IF(Q20>0.25,"買進",IF(Q20>=-0.25,"中立",IF(Q20>=-0.5,"放空","強力放空")))) | W20: 模型點位 $21.4（模型日現價 $249.87）；情境區間 $19.4–$29.5，方法區間 $12.5–$21.4 | Z20: =IF(ISNUMBER(價格!C20),價格!H20/價格!C20-1,"") | AA20: =IF(Z20="","",IF(ABS(Z20)>0.2,"模型尚未反映期間變化","")) | AB20: 現金流 | AC20: 營運缺口（不含融資、不含還本；無股利與回購） | AD20: FY26 -15.1、FY27 -17.9、FY28 -18.2、FY29 -17.2、FY30 -25.5 | AE20: -94.001645 | AF20: -25.540217 | AG20: [Derived] nebius/dist/20261022_Nebius收支模型_v0_5.xlsx 各期收支!C45…各期收支!G45 | AH20: =IF(AB20="淨利",IF(AF20>0,"通過（淨利）","不通過"),IF(AE20<0,"不通過","通過（現金流）")) | AI20: =IF(S20="未上市","未上市",IF(AH20="不通過","收支不足",S20)) | AJ20: =IF(Q20>0.5,"大於 50%",IF(Q20>0.25,"25%–50%",IF(Q20>=0,"0%–25%",IF(Q20>=-0.25,"0%～−25%",IF(Q20>=-0.5,"−25%～−50%","小於 −50%"))))) | AK20: 上檔空間＝模型加權目標價 nebius/dist/20261022_Nebius收支模型_v0_5.xlsx 摘要!C7 ÷ 外部收盤價 − 1，依本地圖五級規則自算（模型自身評等以模型日價計、級距不同，不採用；原值見模型摘要頁）
A21: WYFI | B21: WhiteFiber | C21: =價值鏈!A4 | D21: Neocloud（GPU 租賃） | E21: 模型加權目標價 | F21: 15.248118 | G21: whitefiber/dist/20261022_WhiteFiber收支模型_v0_2.xlsx 摘要!C7 | J21: 15.248118 | K21: whitefiber/dist/20261022_WhiteFiber收支模型_v0_2.xlsx 摘要!C7 | L21: 11.479506 | M21: whitefiber/dist/20261022_WhiteFiber收支模型_v0_2.xlsx 摘要!C10 | N21: =價格!H21 | O21: =MIN(F21,H21) | P21: =MIN(J21,L21) | Q21: =O21/N21-1 | R21: =P21/N21-1 | S21: =IF(Q21>0.5,"強力買進",IF(Q21>0.25,"買進",IF(Q21>=-0.25,"中立",IF(Q21>=-0.5,"放空","強力放空")))) | W21: 模型點位 $15.2（模型日現價 $16.83）；情境區間 $11.5–$25.4，方法區間 $15.1–$15.2 | Z21: =IF(ISNUMBER(價格!C21),價格!H21/價格!C21-1,"") | AA21: =IF(Z21="","",IF(ABS(Z21)>0.2,"模型尚未反映期間變化","")) | AB21: 現金流 | AC21: 營運缺口＋股利 | AD21: FY26 -371.1、FY27 -383.6、FY28 -40.7、FY29 -1.9、FY30 -22.2 | AE21: -819.45109 | AF21: -383.61804 | AG21: [Derived] whitefiber/dist/20261022_WhiteFiber收支模型_v0_2.xlsx 各期收支!C52＋C24…各期收支!G52＋G24 | AH21: =IF(AB21="淨利",IF(AF21>0,"通過（淨利）","不通過"),IF(AE21<0,"不通過","通過（現金流）")) | AI21: =IF(S21="未上市","未上市",IF(AH21="不通過","收支不足",S21)) | AJ21: =IF(Q21>0.5,"大於 50%",IF(Q21>0.25,"25%–50%",IF(Q21>=0,"0%–25%",IF(Q21>=-0.25,"0%～−25%",IF(Q21>=-0.5,"−25%～−50%","小於 −50%"))))) | AK21: 上檔空間＝模型加權目標價 whitefiber/dist/20261022_WhiteFiber收支模型_v0_2.xlsx 摘要!C7 ÷ 外部收盤價 − 1，依本地圖五級規則自算（模型自身評等以模型日價計、級距不同，不採用；原值見模型摘要頁）
A22: 00100 | B22: MiniMax | C22: =價值鏈!A2 | D22: AI 模型商 | E22: 反向檢驗：折現價值 ÷ 市值 | F22: =X22*價格!C22 | G22: minimax/dist/20261022_MiniMax收支模型_v0_2.xlsx Valuation!I21 × 模型現價 | J22: =X22*價格!C22 | K22: 同中心（模型只有一個情境） | N22: =價格!H22 | O22: =MIN(F22,H22) | P22: =MIN(J22,L22) | Q22: =O22/N22-1 | R22: =P22/N22-1 | S22: =IF(Q22>0.5,"強力買進",IF(Q22>0.25,"買進",IF(Q22>=-0.25,"中立",IF(Q22>=-0.5,"放空","強力放空")))) | X22: 0.88197135 | Z22: =IF(ISNUMBER(價格!C22),價格!H22/價格!C22-1,"") | AA22: =IF(Z22="","",IF(ABS(Z22)>0.2,"模型尚未反映期間變化","")) | AB22: 現金流 | AC22: F06 營運燒錢（經調整淨利）＋F07 算力預付與自建資本支出 | AD22: FY2026 -900.3、FY2027 -826.5、FY2028 -1,129.9、FY2029 -1,433.3、FY2030 -1,693.3 | AE22: -5983.1855 | AF22: -1693.2786 | AG22: [Derived] minimax/dist/20261022_MiniMax收支模型_v0_2.xlsx Funding!E13＋E14…Funding!I13＋I14 | AH22: =IF(AB22="淨利",IF(AF22>0,"通過（淨利）","不通過"),IF(AE22<0,"不通過","通過（現金流）")) | AI22: =IF(S22="未上市","未上市",IF(AH22="不通過","收支不足",S22)) | AJ22: =IF(Q22>0.5,"大於 50%",IF(Q22>0.25,"25%–50%",IF(Q22>=0,"0%–25%",IF(Q22>=-0.25,"0%～−25%",IF(Q22>=-0.5,"−25%～−50%","小於 −50%"))))) | AK22: 模型無評等；依 AI半導體 固定規則自算
A23: 02513 | B23: 智譜 | C23: =價值鏈!A2 | D23: AI 模型商 | E23: 未估值（反向模式） | N23: =價格!H23 | S23: 未估值 | W23: 模型未出隱含價；2028 年共識營收需為正向推估的 2.47 倍（最低共識 1.91 倍；zhipu/dist/20261022_智譜收支模型_v0_1_1.xlsx Reverse!G30） | Z23: =IF(ISNUMBER(價格!C23),價格!H23/價格!C23-1,"") | AA23: =IF(Z23="","",IF(ABS(Z23)>0.2,"模型尚未反映期間變化","")) | AB23: 現金流 | AC23: F09 自由現金流 | AD23: 2026 -41.3、2027 -40.9、2028 -40.5、2029 -59.4、2030 -99.1 | AE23: -281.18818 | AF23: -99.053811 | AG23: [Derived] zhipu/dist/20261022_智譜收支模型_v0_1_1.xlsx Funding!E16…Funding!I16 | AH23: =IF(AB23="淨利",IF(AF23>0,"通過（淨利）","不通過"),IF(AE23<0,"不通過","通過（現金流）")) | AI23: =IF(S23="未上市","未上市",IF(AH23="不通過","收支不足",S23))
A24: OpenAI | B24: OpenAI | C24: =價值鏈!A2 | D24: AI 模型商 | E24: 未上市 | N24: =價格!H24 | S24: 未上市 | W24: 未上市：不評估可投資性；收支關卡結果只作參考。 | Z24: =IF(ISNUMBER(價格!C24),價格!H24/價格!C24-1,"") | AA24: =IF(Z24="","",IF(ABS(Z24)>0.2,"模型尚未反映期間變化","")) | AB24: 現金流 | AC24: F06 自由現金流 | AD24: 2026 -39.4、2027 -116.0、2028 -134.9、2029 -137.6、2030 -131.9 | AE24: -559.84481 | AF24: -137.62462 | AG24: [Derived] openai/dist/20261025_OpenAI收支模型_v0_6_3.xlsx Funding!E13…Funding!I13 | AH24: =IF(AB24="淨利",IF(AF24>0,"通過（淨利）","不通過"),IF(AE24<0,"不通過","通過（現金流）")) | AI24: =IF(S24="未上市","未上市",IF(AH24="不通過","收支不足",S24))
A25: Anthropic | B25: Anthropic | C25: =價值鏈!A2 | D25: AI 模型商 | E25: 未上市 | N25: =價格!H25 | S25: 未上市 | W25: 未上市：不評估可投資性；收支關卡結果只作參考。 | Z25: =IF(ISNUMBER(價格!C25),價格!H25/價格!C25-1,"") | AA25: =IF(Z25="","",IF(ABS(Z25)>0.2,"模型尚未反映期間變化","")) | AB25: 現金流 | AC25: F07 自由現金流 | AD25: 2026 -2.6、2027 -18.5、2028 -15.0、2029 47.6、2030 96.1 | AE25: 107.6782 | AF25: -18.503719 | AG25: [Derived] anthropic/dist/20261024_Anthropic收支模型_v0_1_5.xlsx Funding!E14…Funding!I14 | AH25: =IF(AB25="淨利",IF(AF25>0,"通過（淨利）","不通過"),IF(AE25<0,"不通過","通過（現金流）")) | AI25: =IF(S25="未上市","未上市",IF(AH25="不通過","收支不足",S25))
A26: AMD | B26: AMD | C26: =價值鏈!A5 | D26: 運算 | E26: 加權目標價（DCF 50%＋Comparable 50%） | F26: 177.104 | G26: amd/dist/20261025_AMD模型_v0.2.1.xlsx Val!B40 | J26: 120.52124 | K26: amd/dist/20261025_AMD模型_v0.2.1.xlsx Val!B47 | N26: =價格!H26 | O26: =MIN(F26,H26) | P26: =MIN(J26,L26) | Q26: -0.65729986 | R26: =P26/N26-1 | S26: =IF(Q26>0.5,"強力買進",IF(Q26>0.25,"買進",IF(Q26>=-0.25,"中立",IF(Q26>=-0.5,"放空","強力放空")))) | T26: =471.572606000429/N26-1 | U26: 舊法：規則值情境加權價（參考，Val!B57） | V26: 45.4 ／ 46.5 ／ 52.3 | W26: DCF 目標價 152.1（Val!B23）；Comparable 目標價 202.1（Val!B41）；市場共識目標價 637.6（Val!B42，外部、僅供對照）；價格帶 C～A 情境 DCF 120.5～168.7 | Z26: =IF(ISNUMBER(價格!C26),價格!H26/價格!C26-1,"") | AA26: =IF(Z26="","",IF(ABS(Z26)>0.2,"模型尚未反映期間變化","")) | AB26: 淨利 | AC26: PL 頁各情境模型年度淨利（不含實績） | AD26: 8 個情境年度淨利（不含實績），全部為正 | AE26: 150.29729 | AF26: 12.116863 | AG26: [Derived] amd/dist/20261025_AMD模型_v0.2.1.xlsx PL!D15…PL!G47 | AH26: =IF(AB26="淨利",IF(AF26>0,"通過（淨利）","不通過"),IF(AE26<0,"不通過","通過（現金流）")) | AI26: =IF(S26="未上市","未上市",IF(AH26="不通過","收支不足",S26)) | AJ26: =IF(Q26>0.5,"大於 50%",IF(Q26>0.25,"25%–50%",IF(Q26>=0,"0%–25%",IF(Q26>=-0.25,"0%～−25%",IF(Q26>=-0.5,"−25%～−50%","小於 −50%"))))) | AK26: 上檔空間 amd/dist/20261025_AMD模型_v0.2.1.xlsx Val!B43；投資建議：模型尚未補列，依 AI半導體 固定規則自算；級距：模型尚未補列，依 AI半導體 固定規則自算
A27: 2454 | B27: 聯發科 | C27: =價值鏈!A5 | D27: 運算 | E27: 加權目標價（DCF 50%＋Comparable 50%） | F27: 2056.73 | G27: mediatek/dist/20261025_聯發科模型_v0.1.xlsx Val!B39 | J27: 1011.8078 | K27: mediatek/dist/20261025_聯發科模型_v0.1.xlsx Val!D23 | N27: =價格!H27 | O27: =MIN(F27,H27) | P27: =MIN(J27,L27) | Q27: -0.48709975 | R27: =P27/N27-1 | S27: =IF(Q27>0.5,"強力買進",IF(Q27>0.25,"買進",IF(Q27>=-0.25,"中立",IF(Q27>=-0.5,"放空","強力放空")))) | V27: 26.9 ／ 33.6 ／ 47.0 | W27: DCF 目標價 1,845.6（Val!B24）；Comparable 目標價 2,267.9（Val!B40）；市場共識目標價 6,067.0（Val!B41，外部、僅供對照）；價格帶 C～A 情境 DCF 1,011.8～2,466.1 | Z27: =IF(ISNUMBER(價格!C27),價格!H27/價格!C27-1,"") | AA27: =IF(Z27="","",IF(ABS(Z27)>0.2,"模型尚未反映期間變化","")) | AB27: 淨利 | AC27: PL 頁各情境模型年度淨利（不含實績） | AD27: 19 個情境年度淨利（不含實績），全部為正 | AE27: 3774.2803 | AF27: 116.64494 | AG27: [Derived] mediatek/dist/20261025_聯發科模型_v0.1.xlsx PL!D13…PL!J41 | AH27: =IF(AB27="淨利",IF(AF27>0,"通過（淨利）","不通過"),IF(AE27<0,"不通過","通過（現金流）")) | AI27: =IF(S27="未上市","未上市",IF(AH27="不通過","收支不足",S27)) | AJ27: =IF(Q27>0.5,"大於 50%",IF(Q27>0.25,"25%–50%",IF(Q27>=0,"0%–25%",IF(Q27>=-0.25,"0%～−25%",IF(Q27>=-0.5,"−25%～−50%","小於 −50%"))))) | AK27: 上檔空間 mediatek/dist/20261025_聯發科模型_v0.1.xlsx Val!B42；投資建議：模型尚未補列，依 AI半導體 固定規則自算；級距：模型尚未補列，依 AI半導體 固定規則自算
A28: MRVL | B28: Marvell | C28: =價值鏈!A5 | D28: 運算 | E28: 加權目標價（DCF 50%＋Comparable 50%） | F28: 128.033 | G28: mrvl/dist/20261025_邁威爾模型_v0.2.xlsx Val!B40 | J28: 71.038234 | K28: mrvl/dist/20261025_邁威爾模型_v0.2.xlsx Val!B47 | N28: =價格!H28 | O28: =MIN(F28,H28) | P28: =MIN(J28,L28) | Q28: -0.43970503 | R28: =P28/N28-1 | S28: =IF(Q28>0.5,"強力買進",IF(Q28>0.25,"買進",IF(Q28>=-0.25,"中立",IF(Q28>=-0.5,"放空","強力放空")))) | T28: =203.164070486016/N28-1 | U28: 舊法：規則值情境加權價（參考，Val!B57） | V28: 35.1 ／ 35.1 ／ 35.1 | W28: DCF 目標價 116.4（Val!B23）；Comparable 目標價 139.6（Val!B41）；市場共識目標價 341.4（Val!B42，外部、僅供對照）；價格帶 C～A 情境 DCF 71.0～147.4 | Z28: =IF(ISNUMBER(價格!C28),價格!H28/價格!C28-1,"") | AA28: =IF(Z28="","",IF(ABS(Z28)>0.2,"模型尚未反映期間變化","")) | AB28: 淨利 | AC28: PL 頁各情境模型年度淨利（不含實績） | AD28: 8 個情境年度淨利（不含實績），全部為正 | AE28: 52.617935 | AF28: 3.839711 | AG28: [Derived] mrvl/dist/20261025_邁威爾模型_v0.2.xlsx PL!D13…PL!G39 | AH28: =IF(AB28="淨利",IF(AF28>0,"通過（淨利）","不通過"),IF(AE28<0,"不通過","通過（現金流）")) | AI28: =IF(S28="未上市","未上市",IF(AH28="不通過","收支不足",S28)) | AJ28: =IF(Q28>0.5,"大於 50%",IF(Q28>0.25,"25%–50%",IF(Q28>=0,"0%–25%",IF(Q28>=-0.25,"0%～−25%",IF(Q28>=-0.5,"−25%～−50%","小於 −50%"))))) | AK28: 上檔空間 mrvl/dist/20261025_邁威爾模型_v0.2.xlsx Val!B43；投資建議：模型尚未補列，依 AI半導體 固定規則自算；級距：模型尚未補列，依 AI半導體 固定規則自算
A29: 3661 | B29: 世芯-KY | C29: =價值鏈!A5 | D29: 運算 | E29: 加權目標價（DCF 50%＋Comparable 50%） | F29: 5925.8607 | G29: alchip/dist/20261025_世芯-KY模型_v0.1.xlsx Val!B39 | J29: 1226.2441 | K29: alchip/dist/20261025_世芯-KY模型_v0.1.xlsx Val!D23 | N29: =價格!H29 | O29: =MIN(F29,H29) | P29: =MIN(J29,L29) | Q29: 0.69552525 | R29: =P29/N29-1 | S29: =IF(Q29>0.5,"強力買進",IF(Q29>0.25,"買進",IF(Q29>=-0.25,"中立",IF(Q29>=-0.5,"放空","強力放空")))) | V29: 10.3 ／ 17.8 ／ 33.8 | W29: DCF 目標價 3,503.2（Val!B24）；Comparable 目標價 8,348.5（Val!B40）；市場共識目標價 5,803.2（Val!B41，外部、僅供對照）；價格帶 C～A 情境 DCF 1,226.2～5,691.2 | Z29: =IF(ISNUMBER(價格!C29),價格!H29/價格!C29-1,"") | AA29: =IF(Z29="","",IF(ABS(Z29)>0.2,"模型尚未反映期間變化","")) | AB29: 淨利 | AC29: PL 頁各情境模型年度淨利（不含實績） | AD29: 19 個情境年度淨利（不含實績），全部為正 | AE29: 389.36641 | AF29: 8.1798493 | AG29: [Derived] alchip/dist/20261025_世芯-KY模型_v0.1.xlsx PL!D11…PL!J35 | AH29: =IF(AB29="淨利",IF(AF29>0,"通過（淨利）","不通過"),IF(AE29<0,"不通過","通過（現金流）")) | AI29: =IF(S29="未上市","未上市",IF(AH29="不通過","收支不足",S29)) | AJ29: =IF(Q29>0.5,"大於 50%",IF(Q29>0.25,"25%–50%",IF(Q29>=0,"0%–25%",IF(Q29>=-0.25,"0%～−25%",IF(Q29>=-0.5,"−25%～−50%","小於 −50%"))))) | AK29: 上檔空間 alchip/dist/20261025_世芯-KY模型_v0.1.xlsx Val!B42；投資建議：模型尚未補列，依 AI半導體 固定規則自算；級距：模型尚未補列，依 AI半導體 固定規則自算
A30: 3443 | B30: 創意 | C30: =價值鏈!A5 | D30: 運算 | E30: 加權目標價（DCF 50%＋Comparable 50%） | F30: 2879.2041 | G30: guc/dist/20261025_創意模型_v0.1.xlsx Val!B39 | J30: 662.11994 | K30: guc/dist/20261025_創意模型_v0.1.xlsx Val!D23 | N30: =價格!H30 | O30: =MIN(F30,H30) | P30: =MIN(J30,L30) | Q30: -0.62040816 | R30: =P30/N30-1 | S30: =IF(Q30>0.5,"強力買進",IF(Q30>0.25,"買進",IF(Q30>=-0.25,"中立",IF(Q30>=-0.5,"放空","強力放空")))) | V30: 38.4 ／ 66.9 ／ 150.3 | W30: DCF 目標價 2,237.7（Val!B24）；Comparable 目標價 3,520.7（Val!B40）；市場共識目標價 6,722.4（Val!B41，外部、僅供對照）；價格帶 C～A 情境 DCF 662.1～3,747.5 | Z30: =IF(ISNUMBER(價格!C30),價格!H30/價格!C30-1,"") | AA30: =IF(Z30="","",IF(ABS(Z30)>0.2,"模型尚未反映期間變化","")) | AB30: 淨利 | AC30: PL 頁各情境模型年度淨利（不含實績） | AD30: 19 個情境年度淨利（不含實績），全部為正 | AE30: 342.44906 | AF30: 6.091635 | AG30: [Derived] guc/dist/20261025_創意模型_v0.1.xlsx PL!D13…PL!J41 | AH30: =IF(AB30="淨利",IF(AF30>0,"通過（淨利）","不通過"),IF(AE30<0,"不通過","通過（現金流）")) | AI30: =IF(S30="未上市","未上市",IF(AH30="不通過","收支不足",S30)) | AJ30: =IF(Q30>0.5,"大於 50%",IF(Q30>0.25,"25%–50%",IF(Q30>=0,"0%–25%",IF(Q30>=-0.25,"0%～−25%",IF(Q30>=-0.5,"−25%～−50%","小於 −50%"))))) | AK30: 上檔空間 guc/dist/20261025_創意模型_v0.1.xlsx Val!B42；投資建議：模型尚未補列，依 AI半導體 固定規則自算；級距：模型尚未補列，依 AI半導體 固定規則自算
