Workbook

Sheet README
A1: SanDisk（SNDK US）收支與估值模型 v0.1（AI 半導體 Project：記憶體——NAND） 2026-10-25
A2: 模型命題：SanDisk 是純 NAND 公司，盈餘由 NAND 合約價循環與 AI 推論帶動的企業級 SSD 位元決定，產能與 Kioxia 合資（Flash Ventures 49.9%）；問題是 2026 年的高價能維持多久（FY2028 起三情境分歧），以及現價隱含的倍數是否已反映循環見頂。
A3: 重點觀察
A4: ="1. 加權目標價 "&TEXT(Val!B49,"#,##0")&" 美元，相對現價 "&TEXT(px,"#,##0.00")&"（2026-10-23 收盤）"&TEXT(Val!B52,"+0.0%;−0.0%")&"，主因是 Comparable 偏低：同業前瞻 P/B 中位數 "&TEXT(Val!B32,"0.00")&"x，而共識目標價隱含約 "&TEXT(cons_tp/((cons_bv28+cons_bv29)/2),"0.00")&"x（倍數因素 "&TEXT(Val!B59,"+0%;−0%")&"）；DCF 目標價 "&TEXT(Val!B24,"#,##0")&" 高於 Comparable "&TEXT(Val!B34,"#,##0")&"。" -> 1. 加權目標價 930 美元，相對現價 1,238.03（2026-10-23 收盤）−24.9%，主因是 Comparable 偏低：同業前瞻 P/B 中位數 1.49x，而共識目標價隱含約 3.56x（倍數因素 +139%）；DCF 目標價 1,122 高於 Comparable 739。
A5: ="2. 本模型 FY2027 EPS（A）"&TEXT(PL!E14,"0")&" 美元，比共識 217.4 "&TEXT(PL!E14/cons_eps27-1,"+0%;−0%")&"；B、C 到 FY2028 才分歧（"&TEXT(PL!F28,"0")&"／"&TEXT(PL!F42,"0")&"），因為 2026Q3–2027Q2 的價格與位元三情境幾乎相同（markets/nand）。v0.3 已滾入 FQ1 FY27 實績（營收 11.031）；v0.4 對帳：模型 FQ2 FY27 營收 "&TEXT(PL!H60,"0.00")&"，在指引 12.2–12.6 內（v0.3 為 13.59、高 9.6%）。原因是市場層把合約價當實現價：2026Q3 實現 +25%、2026Q4 改 +8.1%（兩季累計不變），SanDisk 2026Q3 份額由 11.6% 降為 10.7%（2026Q4 起取兩季平均 10.65%）；公司稱約一半位元在長約（底價＋浮動），同品項價格溫和上升。" -> 2. 本模型 FY2027 EPS（A）264 美元，比共識 217.4 +21%；B、C 到 FY2028 才分歧（215／190），因為 2026Q3–2027Q2 的價格與位元三情境幾乎相同（markets/nand）。v0.3 已滾入 FQ1 FY27 實績（營收 11.031）；v0.4 對帳：模型 FQ2 FY27 營收 12.45，在指引 12.2–12.6 內（v0.3 為 13.59、高 9.6%）。原因是市場層把合約價當實現價：2026Q3 實現 +25%、2026Q4 改 +8.1%（兩季累計不變），SanDisk 2026Q3 份額由 11.6% 降為 10.7%（2026Q4 起取兩季平均 10.65%）；公司稱約一半位元在長約（底價＋浮動），同品項價格溫和上升。
A6: ="3. 最敏感的是價格而非成本：2027 起季價 ±20% 使 FY2028 EPS（A）變動 "&TEXT(Sens!H5,"+0%;−0%")&"／"&TEXT(Sens!H6,"+0%;−0%")&"，成本年降 ±4pt 只有約 ±1%；情境 C 的 FY2029 毛利率降到 "&TEXT(PL!G38,"0%")&"（CY2028 NAND 價格跌回約 2025 年水準）。追蹤：TrendForce 每季初的 NAND 合約價與 Kioxia 2026-10-30 財報（合資群位元與價格）。" -> 3. 最敏感的是價格而非成本：2027 起季價 ±20% 使 FY2028 EPS（A）變動 −28%／+30%，成本年降 ±4pt 只有約 ±1%；情境 C 的 FY2029 毛利率降到 49%（CY2028 NAND 價格跌回約 2025 年水準）。追蹤：TrendForce 每季初的 NAND 合約價與 Kioxia 2026-10-30 財報（合資群位元與價格）。
A7: ="投資建議："&Val!B55&"（依上檔空間固定規則；上檔空間："&TEXT(Val!B52,"+0.0%;−0.0%")&"，級距："&Val!B54&"）" -> 投資建議：中立（依上檔空間固定規則；上檔空間：−24.9%，級距：0%～−25%）
A9: 驅動因子 → 推導量（因果方向：左邊決定右邊）
A10: Units｜markets/nand 成品：SanDisk 季度營收（市場營收 × 份額；同字母情境）與位元（季度出貨 × 份額）
A11: PL 區塊｜營收＝市場層 × 公司口徑係數；營業成本＝位元 × 每 EB 成本（FQ1 FY27 以實績毛利率校準，之後每年 × (1 − 成本年降)）；營業費用＝固定（FQ1 FY27 實績校準）＋變動
A12: PL 區塊｜淨利＝（營業利益＋淨現金收益）×（1 − 稅率）；自由現金流＝淨利＋折舊 − 資本支出（含合資群分攤）；買回＝回饋比例 × FCF → 股數 → EPS、每股淨值
A13: Val｜第 0 節目標價＝DCF（FY2027–FY2032＋永續）與 Comparable（同業前瞻 P/B × 約 2028 年底每股淨值）各半；第 5–6 節目前倍數、十年倍數規則值（美光 Analogy）
A15: 會計年度：約 6 月底結束（FY2027＝2026-07～2027-06 ≈ CY2026Q3–CY2027Q2）。前瞻 EPS 依月份調整：12 個月後（約 2027-10）的未來 12 月＝8／12 FY2028＋4／12 FY2029。
A16: 情境：A＝順利、B＝平平、C＝不如預期，讀 markets/nand 同字母（價格＝markets/memory NAND_S；顆數＝SCEN_UNITS；合資群份額年變動）；公司特有變數（每位元成本年降 14%／12%／10%）A 最有利、C 最不利。FY2027 的 B、C EPS 略高於 A：上游 markets/memory 的 B、C 價格路徑 2027 上半年漲幅較大、下半年才回落（行業情境，不在公司層調整）。FY2030 起為收斂法，非驅動因子推導。
A17: 十年歷史不足：2025-02 自 WDC 分拆上市，十年 P/B、P/E 與十年平均淨利率以美光為 Analogy。本版未做先驗，無 Andy 合理 P/E 對照。
A19: 2026-10-29：加權目標價中的 Comparable 改用相對倍數調整後的值（Val 第 0.5 節：同業前瞻倍數中位數 × 本公司 10 年相對同業的倍數比，Bloomberg 前瞻倍數；Andy 2026-10-27「照建議做」、10-29 資料取回）。「Comparable 目標價（市場主流同業法）」維持不調整。重點觀察 1 的第一句已改為公式；重點觀察 2、3 與其他說明中的目標價與上檔空間數字為調整前撰寫，以 Val 頁為準。
A21: v0.2.1（2026-10-30）：依個股模型原則第 8 節調整 In 頁呈現（數值不變）。In 頁 D／F 欄名改「敏感度低」「敏感度高」（只用於 Sens 頁、不進目標價）；In 頁最後新增「情境驅動對照」一節，把上方各情境專屬輸入三情境並排（只引用上方各列，純展示）；HTML 驅動因子一節分「情境驅動」與「單一參數」兩張表。

Sheet In
A1: In — 輸入（藍字；基準欄 E，低 D、高 F）。金額：十億美元（$B）；每股：美元；股數：百萬股。每個輸入附標記與來源；找不到者寫「未找到」。【v0.2.1】基準欄 E 進主模型；D／F＝敏感度低／高，只用於 Sens 頁（一次動一個參數）、不進目標價；情境 A／B／C 的驅動見本頁最後一節「情境驅動對照」。
A2: 標記：Verified（公司文件、交易所資料）／Interested-party（寫明是誰、立場）／Analogy（寫明對照與差異）／Assumed（給低／高區間）／Derived（寫明換算）。SemiAnalysis 未使用
A3: 鍵 | B3: 項目 | C3: 單位 | D3: 敏感度低 | E3: 基準 | F3: 敏感度高 | G3: 標記 | H3: 來源1 | I3: 來源2／說明
A4: A. 季度實績與公司指引（$B；EPS 美元）
A5: q1_rev | B5: FQ1 FY26 營收 | C5: $B | E5: 2.308 | G5: Verified | H5: SanDisk FQ2 FY26 新聞稿（8-K，2026-01-29） | I5: FY26 合計 20.248（FQ4 新聞稿）
A6: q1_gm | B6: FQ1 FY26 GAAP 毛利率 | C6: % | E6: 0.298 | G6: Verified | H6: SanDisk FQ2 FY26 新聞稿（8-K，2026-01-29）
A7: q1_op | B7: FQ1 FY26 GAAP 營業利益 | C7: $B | E7: 0.176 | G7: Verified | H7: SanDisk FQ2 FY26 新聞稿（8-K，2026-01-29）
A8: q1_ni | B8: FQ1 FY26 GAAP 淨利 | C8: $B | E8: 0.112 | G8: Verified | H8: SanDisk FQ2 FY26 新聞稿（8-K，2026-01-29）
A9: q1_eps | B9: FQ1 FY26 GAAP 稀釋 EPS | C9: USD | E9: 0.75 | G9: Verified | H9: SanDisk FQ2 FY26 新聞稿（8-K，2026-01-29）
A10: q2_rev | B10: FQ2 FY26 營收 | C10: $B | E10: 3.025 | G10: Verified | H10: SanDisk FQ2 FY26 新聞稿（8-K，2026-01-29） | I10: FY26 合計 20.248（FQ4 新聞稿）
A11: q2_gm | B11: FQ2 FY26 GAAP 毛利率 | C11: % | E11: 0.509 | G11: Verified | H11: SanDisk FQ2 FY26 新聞稿（8-K，2026-01-29）
A12: q2_op | B12: FQ2 FY26 GAAP 營業利益 | C12: $B | E12: 1.065 | G12: Verified | H12: SanDisk FQ2 FY26 新聞稿（8-K，2026-01-29）
A13: q2_ni | B13: FQ2 FY26 GAAP 淨利 | C13: $B | E13: 0.803 | G13: Verified | H13: SanDisk FQ2 FY26 新聞稿（8-K，2026-01-29）
A14: q2_eps | B14: FQ2 FY26 GAAP 稀釋 EPS | C14: USD | E14: 5.15 | G14: Verified | H14: SanDisk FQ2 FY26 新聞稿（8-K，2026-01-29）
A15: q3_rev | B15: FQ3 FY26 營收 | C15: $B | E15: 5.95 | G15: Verified | H15: SanDisk FQ4 FY26 新聞稿（8-K，2026-08-05） | I15: FY26 合計 20.248（FQ4 新聞稿）
A16: q3_gm | B16: FQ3 FY26 GAAP 毛利率 | C16: % | E16: 0.784 | G16: Verified | H16: SanDisk FQ4 FY26 新聞稿（8-K，2026-08-05）
A17: q3_op | B17: FQ3 FY26 GAAP 營業利益 | C17: $B | E17: 4.111 | G17: Verified | H17: SanDisk FQ4 FY26 新聞稿（8-K，2026-08-05）
A18: q3_ni | B18: FQ3 FY26 GAAP 淨利 | C18: $B | E18: 3.615 | G18: Verified | H18: SanDisk FQ4 FY26 新聞稿（8-K，2026-08-05）
A19: q3_eps | B19: FQ3 FY26 GAAP 稀釋 EPS | C19: USD | E19: 23.03 | G19: Verified | H19: SanDisk FQ4 FY26 新聞稿（8-K，2026-08-05）
A20: q4_rev | B20: FQ4 FY26 營收 | C20: $B | E20: 8.965 | G20: Verified | H20: SanDisk FQ4 FY26 新聞稿（8-K，2026-08-05） | I20: FY26 合計 20.248（FQ4 新聞稿）
A21: q4_gm | B21: FQ4 FY26 GAAP 毛利率 | C21: % | E21: 0.846 | G21: Verified | H21: SanDisk FQ4 FY26 新聞稿（8-K，2026-08-05）
A22: q4_op | B22: FQ4 FY26 GAAP 營業利益 | C22: $B | E22: 7.037 | G22: Verified | H22: SanDisk FQ4 FY26 新聞稿（8-K，2026-08-05）
A23: q4_ni | B23: FQ4 FY26 GAAP 淨利 | C23: $B | E23: 6.903 | G23: Verified | H23: SanDisk FQ4 FY26 新聞稿（8-K，2026-08-05）
A24: q4_eps | B24: FQ4 FY26 GAAP 稀釋 EPS | C24: USD | E24: 43.97 | G24: Verified | H24: SanDisk FQ4 FY26 新聞稿（8-K，2026-08-05）
A25: q1_dc | B25: FQ1 FY26 營收：資料中心 | C25: $B | E25: 0.269 | G25: Derived | H25: SanDisk 10-Q（FQ2 FY26，2026-01-02 止；FQ3 FY26，2026-04-03 止）營收依終端市場表：六個月 − FQ2 | I25: 官方分部：Datacenter／Edge／Consumer（依終端市場）
A26: q1_ed | B26: FQ1 FY26 營收：邊緣 | C26: $B | E26: 1.387 | G26: Derived | H26: SanDisk 10-Q（FQ2 FY26，2026-01-02 止；FQ3 FY26，2026-04-03 止）營收依終端市場表：六個月 − FQ2 | I26: Edge＝PC、手機、車用等 OEM 用 client SSD 與嵌入式
A27: q1_cs | B27: FQ1 FY26 營收：消費 | C27: $B | E27: 0.652 | G27: Derived | H27: SanDisk 10-Q（FQ2 FY26，2026-01-02 止；FQ3 FY26，2026-04-03 止）營收依終端市場表：六個月 − FQ2 | I27: Consumer＝記憶卡、隨身碟、零售 SSD
A28: q2_dc | B28: FQ2 FY26 營收：資料中心 | C28: $B | E28: 0.44 | G28: Verified | H28: SanDisk 10-Q（FQ2 FY26，2026-01-02 止；FQ3 FY26，2026-04-03 止）營收依終端市場表 | I28: 官方分部：Datacenter／Edge／Consumer（依終端市場）
A29: q2_ed | B29: FQ2 FY26 營收：邊緣 | C29: $B | E29: 1.678 | G29: Verified | H29: SanDisk 10-Q（FQ2 FY26，2026-01-02 止；FQ3 FY26，2026-04-03 止）營收依終端市場表 | I29: Edge＝PC、手機、車用等 OEM 用 client SSD 與嵌入式
A30: q2_cs | B30: FQ2 FY26 營收：消費 | C30: $B | E30: 0.907 | G30: Verified | H30: SanDisk 10-Q（FQ2 FY26，2026-01-02 止；FQ3 FY26，2026-04-03 止）營收依終端市場表 | I30: Consumer＝記憶卡、隨身碟、零售 SSD
A31: q3_dc | B31: FQ3 FY26 營收：資料中心 | C31: $B | E31: 1.467 | G31: Verified | H31: SanDisk 10-Q（FQ2 FY26，2026-01-02 止；FQ3 FY26，2026-04-03 止）營收依終端市場表 | I31: 官方分部：Datacenter／Edge／Consumer（依終端市場）
A32: q3_ed | B32: FQ3 FY26 營收：邊緣 | C32: $B | E32: 3.663 | G32: Verified | H32: SanDisk 10-Q（FQ2 FY26，2026-01-02 止；FQ3 FY26，2026-04-03 止）營收依終端市場表 | I32: Edge＝PC、手機、車用等 OEM 用 client SSD 與嵌入式
A33: q3_cs | B33: FQ3 FY26 營收：消費 | C33: $B | E33: 0.82 | G33: Verified | H33: SanDisk 10-Q（FQ2 FY26，2026-01-02 止；FQ3 FY26，2026-04-03 止）營收依終端市場表 | I33: Consumer＝記憶卡、隨身碟、零售 SSD
A34: q4_dc | B34: FQ4 FY26 營收：資料中心 | C34: $B | E34: 2.977 | G34: Derived | H34: SanDisk 10-K FY2026（2026-07-03 止） 全年 − 10-Q 九個月 | I34: 官方分部：Datacenter／Edge／Consumer（依終端市場）
A35: q4_ed | B35: FQ4 FY26 營收：邊緣 | C35: $B | E35: 5.432 | G35: Derived | H35: SanDisk 10-K FY2026（2026-07-03 止） 全年 − 10-Q 九個月 | I35: Edge＝PC、手機、車用等 OEM 用 client SSD 與嵌入式
A36: q4_cs | B36: FQ4 FY26 營收：消費 | C36: $B | E36: 0.556 | G36: Derived | H36: SanDisk 10-K FY2026（2026-07-03 止） 全年 − 10-Q 九個月 | I36: Consumer＝記憶卡、隨身碟、零售 SSD
A37: a26_dc | B37: FY2026 營收：資料中心 | C37: $B | E37: 5.153 | G37: Verified | H37: SanDisk 10-K FY2026（2026-07-03 止）；SanDisk FQ4 FY26 新聞稿（8-K，2026-08-05）
A38: a26_ed | B38: FY2026 營收：邊緣 | C38: $B | E38: 12.16 | G38: Verified | H38: SanDisk 10-K FY2026（2026-07-03 止）；SanDisk FQ4 FY26 新聞稿（8-K，2026-08-05）
A39: a26_cs | B39: FY2026 營收：消費 | C39: $B | E39: 2.935 | G39: Verified | H39: SanDisk 10-K FY2026（2026-07-03 止）；SanDisk FQ4 FY26 新聞稿（8-K，2026-08-05）
A40: a26_rev | B40: FY2026 營收（2025-07～2026-07-03） | C40: $B | E40: 20.248 | G40: Verified | H40: SanDisk FQ4 FY26 新聞稿（8-K，2026-08-05）：資料中心 5.153、邊緣 12.160、消費 2.935 | I40: MarketScreener 同值
...

Sheet Q
A1: Q — 季度實績（$B；EPS 美元）與公司指引。會計年度約 6 月底結束；FQ1＝7–9 月
A3: 項目 | B3: FQ1 FY26 | C3: FQ2 FY26 | D3: FQ3 FY26 | E3: FQ4 FY26 | F3: FY2026 | G3: FQ1 FY27 實績 | H3: 標記 | I3: 來源
A4: 營收 | B4: =q1_rev -> 2.308 | C4: =q2_rev -> 3.025 | D4: =q3_rev -> 5.95 | E4: =q4_rev -> 8.965 | F4: =SUM(B4:E4) -> 20.248 | G4: =g_rev -> 11.031 | H4: Verified | I4: SanDisk FQ2 FY26 新聞稿（8-K，2026-01-29）；SanDisk FQ4 FY26 新聞稿（8-K，2026-08-05）
A5: GAAP 毛利率 | B5: =q1_gm -> 0.298 | C5: =q2_gm -> 0.509 | D5: =q3_gm -> 0.784 | E5: =q4_gm -> 0.846 | F5: =SUMPRODUCT(B4:E4,B5:E5)/F4 -> 0.71496933 | G5: =g_gm -> 0.8503 | H5: Verified | I5: SanDisk FQ2 FY26 新聞稿（8-K，2026-01-29）；SanDisk FQ4 FY26 新聞稿（8-K，2026-08-05）
A6: GAAP 營業利益 | B6: =q1_op -> 0.176 | C6: =q2_op -> 1.065 | D6: =q3_op -> 4.111 | E6: =q4_op -> 7.037 | F6: =SUM(B6:E6) -> 12.389 | H6: Verified | I6: SanDisk FQ2 FY26 新聞稿（8-K，2026-01-29）；SanDisk FQ4 FY26 新聞稿（8-K，2026-08-05）
A7: GAAP 淨利 | B7: =q1_ni -> 0.112 | C7: =q2_ni -> 0.803 | D7: =q3_ni -> 3.615 | E7: =q4_ni -> 6.903 | F7: =SUM(B7:E7) -> 11.433 | H7: Verified | I7: SanDisk FQ2 FY26 新聞稿（8-K，2026-01-29）；SanDisk FQ4 FY26 新聞稿（8-K，2026-08-05）
A8: GAAP 稀釋 EPS | B8: =q1_eps -> 0.75 | C8: =q2_eps -> 5.15 | D8: =q3_eps -> 23.03 | E8: =q4_eps -> 43.97 | F8: =a26_eps -> 73.76 | G8: =g_eps -> 49.51 | H8: Verified | I8: SanDisk FQ2 FY26 新聞稿（8-K，2026-01-29）；SanDisk FQ4 FY26 新聞稿（8-K，2026-08-05）
A9: 檢查：四季營收、淨利合計 − FY2026（應約為 0） | B9: =F4-a26_rev -> 0 | C9: =F7-a26_ni -> 0
A10: 季增：營收 | C10: =C4/B4-1 -> 0.31065858 | D10: =D4/C4-1 -> 0.96694215 | E10: =E4/D4-1 -> 0.50672269
A12: v0.3（2026-10-31）：FQ1 FY27（2026-07～09）實績已滾入（2026-10-29 公布：營收 11.031、資料中心 4.802、邊緣 5.832、消費 0.397；GAAP 毛利率 85.0%）；FY2027 第一季＝市場層推導（營收等於實績，為恆等式）。FQ2 FY27 指引：營收 12.2–12.6、non-GAAP 毛利率 84.5–85.5%、non-GAAP EPS 55–57（分割前）、稀釋股數 151。董事會核准一股分八股（2026-11-20 起分割後交易），本版 EPS 與股價仍為分割前

Sheet Units
A1: Units — 市場層 markets/nand 成品的 SanDisk 季度營收與位元（三情境；唯讀抄錄，藍字）。來源：markets/nand/dist/20261031_NAND市場模型_v0.3.xlsx
A2: C..Z＝CY2025Q1..CY2030Q4；營收為 TrendForce 口徑（$B），位元為季度出貨 × 營收份額（EB）。合資群份額＝Kioxia＋SanDisk（與 kioxia/ 模型讀同一列）
A3: 項目 | B3: 單位 | C3: 2025Q1 | D3: 2025Q2 | E3: 2025Q3 | F3: 2025Q4 | G3: 2026Q1 | H3: 2026Q2 | I3: 2026Q3 | J3: 2026Q4 | K3: 2027Q1 | L3: 2027Q2 | M3: 2027Q3 | N3: 2027Q4 | O3: 2028Q1 | P3: 2028Q2 | Q3: 2028Q3 | R3: 2028Q4 | S3: 2029Q1 | T3: 2029Q2 | U3: 2029Q3 | V3: 2029Q4 | W3: 2030Q1 | X3: 2030Q2 | Y3: 2030Q3 | Z3: 2030Q4 | AA3: 來源
A4: SanDisk 營收（情境 A） | B4: $B | C4: 1.69 | D4: 1.9 | E4: 2.31 | F4: 3.03 | G4: 5.95 | H4: 8.97 | I4: 11.037152 | J4: 12.460212 | K4: 13.729628 | L4: 14.517314 | M4: 14.582681 | N4: 14.339957 | O4: 14.404525 | P4: 14.469384 | Q4: 14.534536 | R4: 14.59998 | S4: 14.754735 | T4: 15.041568 | U4: 15.333977 | V4: 15.63207 | W4: 15.425215 | X4: 15.503292 | Y4: 15.581764 | Z4: 15.660633 | AA4: markets/nand/dist/20261031_NAND市場模型_v0.3.xlsx｜Mkt!C44:Z44
A5: SanDisk 營收（情境 B） | B5: $B | C5: 1.69 | D5: 1.9 | E5: 2.31 | F5: 3.03 | G5: 5.95 | H5: 8.97 | I5: 11.037152 | J5: 12.460212 | K5: 13.828805 | L5: 14.914624 | M5: 14.193265 | N5: 12.006041 | O5: 8.3424059 | P5: 6.479135 | Q5: 5.3674927 | R5: 5.0024 | S5: 5.5933415 | T5: 6.1826835 | U5: 6.7039477 | V5: 7.2691598 | W5: 6.9803209 | X5: 6.9805132 | Y5: 6.9807056 | Z5: 6.9808979 | AA5: markets/nand/dist/20261031_NAND市場模型_v0.3.xlsx｜Mkt!C92:Z92
A6: SanDisk 營收（情境 C） | B6: $B | C6: 1.69 | D6: 1.9 | E6: 2.31 | F6: 3.03 | G6: 5.95 | H6: 8.97 | I6: 11.037152 | J6: 12.460212 | K6: 13.661386 | L6: 14.73406 | M6: 14.021435 | N6: 11.86069 | O6: 6.9722938 | P6: 4.5429736 | Q6: 3.415487 | R6: 2.7390112 | S6: 2.9345422 | T6: 3.205746 | U6: 3.6020715 | V6: 4.1223463 | W6: 3.9508706 | X6: 3.9424527 | Y6: 3.9340527 | Z6: 3.9256706 | AA6: markets/nand/dist/20261031_NAND市場模型_v0.3.xlsx｜Mkt!C140:Z140
A7: SanDisk 位元（情境 A） | B7: EB | C7: 31.287396 | D7: 29.615294 | E7: 31.15528 | F7: 33.514723 | G7: 38.069333 | H7: 33.617215 | I7: 33.091489 | J7: 34.558829 | K7: 36.970484 | L7: 39.091528 | M7: 41.334258 | N7: 43.705657 | O7: 46.213105 | P7: 48.86441 | Q7: 51.667822 | R7: 54.632071 | S7: 56.918713 | T7: 59.81981 | U7: 62.868774 | V7: 66.07314 | W7: 67.316109 | X7: 69.853961 | Y7: 72.487491 | Z7: 75.220307 | AA7: markets/nand/dist/20261031_NAND市場模型_v0.3.xlsx｜Mkt!C48:Z48
A8: SanDisk 位元（情境 B） | B8: EB | C8: 31.287396 | D8: 29.615294 | E8: 31.15528 | F8: 33.514723 | G8: 38.069333 | H8: 33.617215 | I8: 33.091489 | J8: 34.558829 | K8: 36.528255 | L8: 38.623927 | M8: 40.839831 | N8: 43.182863 | O8: 42.865204 | P8: 44.388385 | Q8: 45.965691 | R8: 47.599045 | S8: 50.687615 | T8: 53.360297 | U8: 56.173905 | V8: 59.13587 | W8: 58.630216 | X8: 60.535871 | Y8: 62.503465 | Z8: 64.535011 | AA8: markets/nand/dist/20261031_NAND市場模型_v0.3.xlsx｜Mkt!C96:Z96
A9: SanDisk 位元（情境 C） | B9: EB | C9: 31.287396 | D9: 29.615294 | E9: 31.15528 | F9: 33.514723 | G9: 38.069333 | H9: 33.617215 | I9: 33.091489 | J9: 34.558829 | K9: 36.086026 | L9: 38.156327 | M9: 40.345404 | N9: 42.66007 | O9: 38.581041 | P9: 38.674536 | Q9: 38.768258 | R9: 38.862207 | S9: 41.63648 | T9: 43.318506 | U9: 45.068482 | V9: 46.889154 | W9: 46.398085 | X9: 47.802771 | Y9: 49.249983 | Z9: 50.741009 | AA9: markets/nand/dist/20261031_NAND市場模型_v0.3.xlsx｜Mkt!C144:Z144
A10: Kioxia＋SanDisk 合資群份額（情境 A） | B10: % | C10: 0.27907731 | D10: 0.25560769 | E10: 0.27406433 | F10: 0.2689697 | G10: 0.27096015 | H10: 0.25018083 | I10: 0.25187361 | J10: 0.24502666 | K10: 0.24502666 | L10: 0.24502666 | M10: 0.24502666 | N10: 0.24502666 | O10: 0.24502666 | P10: 0.24502666 | Q10: 0.24502666 | R10: 0.24502666 | S10: 0.24502666 | T10: 0.24502666 | U10: 0.24502666 | V10: 0.24502666 | W10: 0.24502666 | X10: 0.24502666 | Y10: 0.24502666 | Z10: 0.24502666 | AA10: markets/nand/dist/20261031_NAND市場模型_v0.3.xlsx｜Mkt!C46:Z46
A11: Kioxia＋SanDisk 合資群份額（情境 B） | B11: % | C11: 0.27907731 | D11: 0.25560769 | E11: 0.27406433 | F11: 0.2689697 | G11: 0.27096015 | H11: 0.25018083 | I11: 0.25187361 | J11: 0.24502666 | K11: 0.24202666 | L11: 0.24202666 | M11: 0.24202666 | N11: 0.24202666 | O11: 0.23902666 | P11: 0.23902666 | Q11: 0.23902666 | R11: 0.23902666 | S11: 0.23602666 | T11: 0.23602666 | U11: 0.23602666 | V11: 0.23602666 | W11: 0.23302666 | X11: 0.23302666 | Y11: 0.23302666 | Z11: 0.23302666 | AA11: markets/nand/dist/20261031_NAND市場模型_v0.3.xlsx｜Mkt!C94:Z94
A12: Kioxia＋SanDisk 合資群份額（情境 C） | B12: % | C12: 0.27907731 | D12: 0.25560769 | E12: 0.27406433 | F12: 0.2689697 | G12: 0.27096015 | H12: 0.25018083 | I12: 0.25187361 | J12: 0.24502666 | K12: 0.23902666 | L12: 0.23902666 | M12: 0.23902666 | N12: 0.23902666 | O12: 0.23302666 | P12: 0.23302666 | Q12: 0.23302666 | R12: 0.23302666 | S12: 0.22702666 | T12: 0.22702666 | U12: 0.22702666 | V12: 0.22702666 | W12: 0.22102666 | X12: 0.22102666 | Y12: 0.22102666 | Z12: 0.22102666 | AA12: markets/nand/dist/20261031_NAND市場模型_v0.3.xlsx｜Mkt!C142:Z142
A14: AI 企業級 SSD 占企業級 SSD 位元需求（日曆年；markets/nand Ann 頁）
A15: 項目 | B15: 單位 | C15: CY2025 | D15: CY2026 | E15: CY2027 | F15: CY2028 | G15: CY2029 | H15: CY2030 | I15: 來源
A16: AI ÷ 企業級 SSD（情境 A） | B16: % | C16: 0.55 | D16: 0.75434243 | E16: 0.83145024 | F16: 0.85505592 | G16: 0.87526234 | H16: 0.8833345 | I16: markets/nand/dist/20261031_NAND市場模型_v0.3.xlsx｜Ann!D6:I6 ÷（同列＋下一列）
A17: AI ÷ 企業級 SSD（情境 B） | B17: % | C17: 0.55 | D17: 0.75434243 | E17: 0.83145024 | F17: 0.82515557 | G17: 0.85641057 | H17: 0.86551525 | I17: markets/nand/dist/20261031_NAND市場模型_v0.3.xlsx｜Ann!D33:I33 ÷（同列＋下一列）
A18: AI ÷ 企業級 SSD（情境 C） | B18: % | C18: 0.55 | D18: 0.75434243 | E18: 0.83145024 | F18: 0.77971276 | G18: 0.80806492 | H18: 0.81958931 | I18: markets/nand/dist/20261031_NAND市場模型_v0.3.xlsx｜Ann!D60:I60 ÷（同列＋下一列）

Sheet PL
A1: PL — SanDisk 損益（$B；FY2026 實績；FY2027–FY2029 由市場層 markets/nand 驅動；FY2030–FY2032 收斂法見底部）。頂端摘要，下方三情境各一個完整推導區塊
A3: 情境／項目 | B3: 單位 | C3: FY2025A | D3: FY2026A | E3: FY2027 | F3: FY2028 | G3: FY2029 | H3: 說明
A4: 情境 A（順利）
A5: 營收 | B5: $B | C5: =C77 -> 7.355 | D5: =D77 -> 20.248 | E5: =E77 -> 51.713658 | F5: =F77 -> 57.762315 | G5: =G77 -> 58.895915
A6: 資料中心 | B6: $B | D6: =D78 -> 5.153 | E6: =E78 -> 19.65119 | F6: =F78 -> 24.260172 | G6: =G78 -> 26.503162
A7: 資料中心：AI 相關 | B7: $B | D7: =D79 -> 3.3606383 | E7: =E79 -> 15.581357 | F7: =F79 -> 20.457465 | G7: =G79 -> 22.929452
A8: 邊緣 | B8: $B | D8: =D80 -> 12.16 | E8: =E80 -> 28.959649 | F8: =F80 -> 30.036404 | G8: =G80 -> 28.858998
A9: 消費 | B9: $B | D9: =D81 -> 2.935 | E9: =E81 -> 3.1028195 | F9: =F81 -> 3.4657389 | G9: =G81 -> 3.5337549
A10: 毛利率 | B10: % | D10: =D84 -> 0.71496933 | E10: =E84 -> 0.86918603 | F10: =F84 -> 0.87376026 | G10: =G84 -> 0.86810242
A11: 營業利益 | B11: $B | D11: =D86 -> 12.389 | E11: =E86 -> 42.475544 | F11: =F86 -> 47.741072 | G11: =G86 -> 48.171835
A12: 營業利益率 | B12: % | D12: =D87 -> 0.6118629 | E12: =E87 -> 0.82136026 | F12: =F87 -> 0.82650898 | G12: =G87 -> 0.81791471
A13: 淨利 | B13: $B | C13: =C88 -> -1.641 | D13: =D88 -> 11.433 | E13: =E88 -> 36.26612 | F13: =F88 -> 41.308315 | G13: =G88 -> 42.320508
A14: EPS | B14: USD | C14: =C96 -> -11.32 | D14: =D96 -> 73.76 | E14: =E96 -> 263.67344 | F14: =F96 -> 338.05574 | G14: =G96 -> 397.50825
A15: 每股淨值 | B15: USD | D15: =D97 -> 107.47166 | E15: =E97 -> 265.79415 | F15: =F97 -> 490.14228 | G15: =G97 -> 790.05784
A16: 自由現金流 | B16: $B | D16: =D91 -> 11.031 | E16: =E91 -> 33.323301 | F16: =F91 -> 38.002577 | G16: =G91 -> 38.946753
A18: 情境 B（平平）
A19: 營收 | B19: $B | C19: =C124 -> 7.355 | D19: =D124 -> 20.248 | E19: =E124 -> 52.209851 | F19: =F124 -> 40.996551 | G19: =G124 -> 22.132801
A20: 資料中心 | B20: $B | D20: =D125 -> 5.153 | E20: =E125 -> 19.839743 | F20: =F125 -> 17.218551 | G20: =G125 -> 9.9597603
A21: 資料中心：AI 相關 | B21: $B | D21: =D126 -> 3.3606383 | E21: =E126 -> 15.73086 | F21: =F126 -> 14.262176 | G21: =G126 -> 8.3739978
A22: 邊緣 | B22: $B | D22: =D127 -> 12.16 | E22: =E127 -> 29.237516 | F22: =F127 -> 21.318206 | G22: =G127 -> 10.845072
A23: 消費 | B23: $B | D23: =D128 -> 2.935 | E23: =E128 -> 3.132591 | F23: =F128 -> 2.459793 | G23: =G128 -> 1.327968
A24: 毛利率 | B24: % | D24: =D131 -> 0.71496933 | E24: =E131 -> 0.87008934 | F24: =F131 -> 0.82518594 | G24: =G131 -> 0.67158716
A25: 營業利益 | B25: $B | D25: =D133 -> 12.389 | E25: =E133 -> 42.949027 | F25: =F133 -> 31.268092 | G25: =G133 -> 12.275885
A26: 營業利益率 | B26: % | D26: =D134 -> 0.6118629 | E26: =E134 -> 0.82262306 | F26: =F134 -> 0.76270056 | G26: =G134 -> 0.55464671
A27: 淨利 | B27: $B | C27: =C135 -> -1.641 | D27: =D135 -> 11.433 | E27: =E135 -> 36.668581 | F27: =F135 -> 27.312618 | G27: =G135 -> 11.59446
A28: EPS | B28: USD | C28: =C143 -> -11.32 | D28: =D143 -> 73.76 | E28: =E143 -> 266.8916 | F28: =F143 -> 214.571 | G28: =G143 -> 94.203781
A29: 每股淨值 | B29: USD | D29: =D144 -> 107.47166 | E29: =E144 -> 267.72262 | F29: =F144 -> 410.42318 | G29: =G144 -> 478.85843
A30: 自由現金流 | B30: $B | D30: =D138 -> 11.031 | E30: =E138 -> 33.69599 | F30: =F138 -> 25.012825 | G30: =G138 -> 10.426492
A32: 情境 C（不如預期）
A33: 營收 | B33: $B | C33: =C171 -> 7.355 | D33: =D171 -> 20.248 | E33: =E171 -> 51.862074 | F33: =F171 -> 37.375241 | G33: =G171 -> 12.287504
A34: 資料中心 | B34: $B | D34: =D172 -> 5.153 | E34: =E172 -> 19.707588 | F34: =F172 -> 15.697601 | G34: =G172 -> 5.5293769
A35: 資料中心：AI 相關 | B35: $B | D35: =D173 -> 3.3606383 | E35: =E173 -> 15.626075 | F35: =F173 -> 12.645697 | G35: =G173 -> 4.3897106
A36: 邊緣 | B36: $B | D36: =D174 -> 12.16 | E36: =E174 -> 29.042762 | F36: =F174 -> 19.435126 | G36: =G174 -> 6.0208771
A37: 消費 | B37: $B | D37: =D175 -> 2.935 | E37: =E175 -> 3.1117245 | F37: =F175 -> 2.2425145 | G37: =G175 -> 0.73725025
A38: 毛利率 | B38: % | D38: =D178 -> 0.71496933 | E38: =E178 -> 0.86890965 | F38: =F178 -> 0.81467111 | G38: =G178 -> 0.48635761
A39: 營業利益 | B39: $B | D39: =D180 -> 12.389 | E39: =E180 -> 42.588727 | F39: =F180 -> 27.923057 | G39: =G180 -> 3.4863544
A40: 營業利益率 | B40: % | D40: =D181 -> 0.6118629 | E40: =E181 -> 0.82119213 | F40: =F181 -> 0.74710039 | G40: =G181 -> 0.2837317
A41: 淨利 | B41: $B | C41: =C182 -> -1.641 | D41: =D182 -> 11.433 | E41: =E182 -> 36.362326 | F41: =F182 -> 24.464487 | G41: =G182 -> 4.073783
A42: EPS | B42: USD | C42: =C190 -> -11.32 | D42: =D190 -> 73.76 | E42: =E190 -> 264.44069 | F42: =F190 -> 190.43373 | G42: =G190 -> 32.063131
A43: 每股淨值 | B43: USD | D43: =D191 -> 107.47166 | E43: =E191 -> 266.26002 | F43: =F191 -> 392.82934 | G43: =G191 -> 416.34634
...

Sheet Val
A1: Val — 估值。第 0 節為目標價（DCF 與 Comparable 加權；Comparable 依記憶體慣例用前瞻 P/B）；第 5–6 節為目前倍數、十年倍數與規則值（舊法參考）
A2: SanDisk 2025-02 自 WDC 分拆上市，無十年自身倍數歷史：十年 P/B、P/E 以美光（同為記憶體循環股）為 Analogy，見第 6 節
A4: 0. 目標價
A5: 0.1 DCF（股東權益現金流，FY2027–FY2032 明確期＋FY2032 後永續）
A6: 項目 | B6: A（順利） | C6: B（平平） | D6: C（不如預期） | E6: 說明
A7: 情境 EPS（FY2027–FY2032） | E7: PL 頁延伸區塊；FY2030 起為收斂法（灰底）
A8: FY2027 | B8: =PL!D205 -> 263.67344 | C8: =PL!D212 -> 266.8916 | D8: =PL!D219 -> 264.44069
A9: FY2028 | B9: =PL!E205 -> 338.05574 | C9: =PL!E212 -> 214.571 | D9: =PL!E219 -> 190.43373
A10: FY2029 | B10: =PL!F205 -> 397.50825 | C10: =PL!F212 -> 94.203781 | D10: =PL!F219 -> 32.063131
A11: FY2030 | B11: =PL!G205 -> 307.29209 | C11: =PL!G212 -> 50.585304 | D11: =PL!G219 -> 14.067064
A12: FY2031 | B12: =PL!H205 -> 213.41599 | C12: =PL!H212 -> 30.222915 | D12: =PL!H219 -> 8.0579466
A13: FY2032 | B13: =PL!I205 -> 111.55225 | C13: =PL!I212 -> 16.921 | D13: =PL!I219 -> 5.1088987
A14: 股東現金流＝EPS ×（1 − tp_g ÷ tp_roe） | E14: 記憶體資本密集：FY2027–FY2029 改用每股（淨利＋折舊－資本支出）＝ PL 區塊每股自由現金流（資本支出含合資群分攤）；收斂期（FY2030 起）用 EPS ×（1 − 再投資率）
A15: 再投資率（tp_g ÷ tp_roe，上限 0.8；FY2030 起用） | B15: =MIN(tp_g/tp_roe,0.8) -> 0.1458548 | E15: ROE 為 FY2025–FY2026 平均（In 頁 tp_roe）
A16: FY2027（淨利＋折舊－資本支出，每股） | B16: =PL!E99 -> 242.27762 | C16: =PL!E146 -> 245.25565 | D16: =PL!E193 -> 242.97463
A17: FY2028（淨利＋折舊－資本支出，每股） | B17: =PL!F99 -> 311.00249 | C17: =PL!F146 -> 196.50356 | D17: =PL!F193 -> 174.22325
A18: FY2029（淨利＋折舊－資本支出，每股） | B18: =PL!G99 -> 365.81923 | C18: =PL!G146 -> 84.714162 | D18: =PL!G193 -> 27.519823
A19: FY2030（EPS ×（1 − 再投資率）） | B19: =B11*(1-$B$15) -> 262.47206 | C19: =C11*(1-$B$15) -> 43.207194 | D19: =D11*(1-$B$15) -> 12.015315
A20: FY2031（EPS ×（1 − 再投資率）） | B20: =B12*(1-$B$15) -> 182.28824 | C20: =C12*(1-$B$15) -> 25.814758 | D20: =D12*(1-$B$15) -> 6.8826564
A21: FY2032（EPS ×（1 − 再投資率）） | B21: =B13*(1-$B$15) -> 95.281821 | C21: =C13*(1-$B$15) -> 14.452991 | D21: =D13*(1-$B$15) -> 4.3637413
A22: DCF 情境每股價值（折現率 tp_r） | B22: =MAX(0,SUMPRODUCT(B16:B21,1/(1+tp_r)^{1;2;3;4;5;6})+B21*(1+tp_g)/(tp_r-tp_g)/(1+tp_r)^6) -> 2030.6251 | C22: =MAX(0,SUMPRODUCT(C16:C21,1/(1+tp_r)^{1;2;3;4;5;6})+C21*(1+tp_g)/(tp_r-tp_g)/(1+tp_r)^6) -> 644.11586 | D22: =MAX(0,SUMPRODUCT(D16:D21,1/(1+tp_r)^{1;2;3;4;5;6})+D21*(1+tp_g)/(tp_r-tp_g)/(1+tp_r)^6) -> 443.18744 | E22: Σ 明確期現金流 ÷ (1＋r)^t ＋ 永續價值 ÷ (1＋r)^6；永續價值＝FY2032 現金流 ×(1＋g)÷(r−g)；基準日 2026 年底，t＝1 對 FY2027（FY2027 於 2027-06 結束，t 以會計年度計，略低估）；負值取 0（股東有限責任）
A23: DCF 情境價值推到 12 個月後（×(1＋tp_r)） | B23: =B22*(1+tp_r) -> 2233.6877 | C23: =C22*(1+tp_r) -> 708.52745 | D23: =D22*(1+tp_r) -> 487.50619
A24: DCF 目標價（情境加權） | B24: =tp_wA*B23+tp_wB*C23+tp_wC*D23 -> 1121.8713 | E24: Σ 權重 × 情境價值 ×(1＋r)；權重見 In 頁 tp_wA／tp_wB／tp_wC
A26: 0.2 Comparable（市場主流同業前瞻 P/B；記憶體慣例）
A27: 同業與前瞻 P/B | B27: 代號 | C27: 前瞻 P/B | D27: 日期 | E27: 來源 | F27: 標記
A28: 美光 | B28: MU | C28: 3.35 | D28: 2026-10-23 | E28: MarketScreener：現價 ÷ FY2027E（2027-09）每股淨值（micron/ 模型同值） | F28: Interested-party
A29: SK 海力士 | B29: 000660.KS | C29: 1.35 | D29: 2026-10-23 | E29: MarketScreener：現價 ÷ 2027E 每股淨值（skhynix/ 模型同值） | F29: Interested-party
A30: 三星電子 | B30: 005930.KS | C30: 1.26 | D30: 2026-10-23 | E30: MarketScreener：現價 ÷ 2027E 每股淨值（samsung/ 模型同值） | F30: Interested-party
A31: Kioxia | B31: 285A.T | C31: =12755/7808 -> 1.6335809 | D31: 2026-10-23 | E31: 現價 ¥12,755（stockanalysis，分割後）÷ MarketScreener FY2028E（2028-03）每股淨值 ¥7,808 | F31: Interested-party
A32: 同業前瞻 P/B 中位數 | B32: =MEDIAN(C28:C31) -> 1.4917905 | E32: 記憶體同業（美光、SK 海力士、三星、Kioxia；無 A 股）。WDC（硬碟）不列入 P/B：僅有落後 P/B 13.5x（stockanalysis），與記憶體不可比；P/E 並列參考見下方。SanDisk 自身現價 ÷ 2027 年底每股淨值（FY27、FY28 共識平均）約 2.9x
A33: 12 個月後的前瞻每股淨值（情境加權） | B33: =tp_wA*(PL!F97+PL!G97)/2+tp_wB*(PL!F144+PL!G144)/2+tp_wC*(PL!F191+PL!G191)/2 -> 495.26799 | E33: 同業倍數＝現價 ÷ 約 14 個月後（約 2027 年底）每股淨值；對應 12 個月後（約 2027-10）用約 2028 年底每股淨值＝（FY2028 年底＋FY2029 年底）÷ 2（會計年度 6 月，依月份調整）
A34: Comparable 目標價 | B34: =B32*B33 -> 738.83607 | E34: 同業中位數 × 前瞻每股淨值
A35: 12 個月後的前瞻 EPS（情境加權） | B35: =tp_wA*(8/12*B9+4/12*B10)+tp_wB*(8/12*C9+4/12*C10)+tp_wC*(8/12*D9+4/12*D10) -> 222.11497 | E35: 約 2027-10 時的未來 12 月（2027-11～2028-10）≈ 8／12 × FY2028（2027-07～2028-06）＋4／12 × FY2029（會計年度 6 月，依月份調整）
A37: 並列參考：同業前瞻 P/E（不進目標價）
A38: 同業與前瞻 P/E | B38: 代號 | C38: 前瞻 P/E | D38: 日期 | E38: 來源 | F38: 標記
A39: 美光 | B39: MU | C39: =877.55/173 -> 5.0725434 | D39: 2026-10-23 | E39: 現價 877.55 ÷ MarketScreener FY2027 共識 EPS 173（micron/ 模型 In 頁） | F39: Interested-party
A40: SK 海力士 | B40: 000660.KS | C40: =1277000/475721 -> 2.6843465 | D40: 2026-10-23 | E40: 現價 ÷ MarketScreener 2027 共識 EPS（skhynix/ 模型 In 頁） | F40: Interested-party
A41: 三星電子 | B41: 005930.KS | C41: =215500/72279 -> 2.9815022 | D41: 2026-10-23 | E41: 現價 ÷ MarketScreener 2027 共識 EPS（samsung/ 模型 In 頁） | F41: Interested-party
A42: Kioxia | B42: 285A.T | C42: =12755/3486 -> 3.6589214 | D42: 2026-10-23 | E42: 現價 ¥12,755 ÷ MarketScreener FY2027（2027-03）共識 EPS ¥3,486 | F42: Interested-party
A43: Western Digital | B43: WDC | C43: 11.91 | D43: 2026-10-23 | E43: stockanalysis 統計頁 Forward P/E（硬碟為主，參考） | F43: Interested-party
...

Sheet Recon
A1: Recon — 本模型 vs 公司實績、指引與共識（共識只作對照，未用於校準）。差距＝模型 ÷ 對照 − 1（百分點列為相減）
A3: 項目 | B3: 對照值 | C3: 模型 A | D3: 差距 A | E3: 模型 B | F3: 差距 B | G3: 模型 C | H3: 差距 C | I3: 對照來源 | J3: 說明
A4: A. 實績與公司指引
A5: FY2026 營收（實績重現） | B5: =a26_rev -> 20.248 | C5: =PL!D5 -> 20.248 | D5: =C5/B5-1 -> 0 | E5: =PL!D19 -> 20.248 | F5: =E5/B5-1 -> 0 | G5: =PL!D33 -> 20.248 | H5: =G5/B5-1 -> 0 | I5: SanDisk FQ4 FY26 新聞稿（8-K，2026-08-05） | J5: 恆等式
A6: FQ1 FY27 營收 vs 公司實績 | B6: =g_rev -> 11.031 | C6: =PL!G60 -> 11.030615 | D6: =C6/B6-1 -> -3.4905955e-05 | E6: =PL!G107 -> 11.030615 | F6: =E6/B6-1 -> -3.4905955e-05 | G6: =PL!G154 -> 11.030615 | H6: =G6/B6-1 -> -3.4905955e-05 | I6: SanDisk FQ4 FY26 新聞稿（8-K，2026-08-05） | J6: 恆等式（市場層份額由指引推得）
A7: FQ1 FY27 毛利率 vs 實績（百分點） | B7: =g_gm -> 0.8503 | C7: =PL!G69 -> 0.8503 | D7: =C7-B7 -> 0 | E7: =PL!G116 -> 0.8503 | F7: =E7-B7 -> 0 | G7: =PL!G163 -> 0.8503 | H7: =G7-B7 -> 0 | I7: SanDisk FQ4 FY26 新聞稿（8-K，2026-08-05） | J7: 恆等式（單位成本以此校準）
A8: FQ1 FY27 EPS vs 實績（non-GAAP 49.51） | B8: =g_eps -> 49.51 | C8: =PL!G74 -> 49.789486 | D8: =C8/B8-1 -> 0.005645041 | E8: =PL!G121 -> 49.789486 | F8: =E8/B8-1 -> 0.005645041 | G8: =PL!G168 -> 49.789486 | H8: =G8/B8-1 -> 0.005645041 | I8: SanDisk FQ4 FY26 新聞稿（8-K，2026-08-05） | J8: 本模型為 GAAP 營業費用＋15% 稅率，近似 non-GAAP（差約 SBC）
A9: B. 共識（MarketScreener 2026-10-23；只作參考）
A10: FY2027 營收 vs 共識 | B10: =cons_rev27 -> 49.135 | C10: =PL!E5 -> 51.713658 | D10: =C10/B10-1 -> 0.052481091 | E10: =PL!E19 -> 52.209851 | F10: =E10/B10-1 -> 0.062579639 | G10: =PL!E33 -> 51.862074 | H10: =G10/B10-1 -> 0.055501668 | I10: MarketScreener 預估頁（2026-10-25 擷取；頁面為 10-23 收盤；會計年度 6 月）
A11: FY2028 營收 vs 共識 | B11: =cons_rev28 -> 58.436 | C11: =PL!F5 -> 57.762315 | D11: =C11/B11-1 -> -0.011528597 | E11: =PL!F19 -> 40.996551 | F11: =E11/B11-1 -> -0.29843674 | G11: =PL!F33 -> 37.375241 | H11: =G11/B11-1 -> -0.36040726 | I11: MarketScreener 預估頁（2026-10-25 擷取；頁面為 10-23 收盤；會計年度 6 月）
A12: FY2027 EPS vs 共識 | B12: =cons_eps27 -> 217.4 | C12: =PL!E14 -> 263.67344 | D12: =C12/B12-1 -> 0.2128493 | E12: =PL!E28 -> 266.8916 | F12: =E12/B12-1 -> 0.22765228 | G12: =PL!E42 -> 264.44069 | H12: =G12/B12-1 -> 0.21637853 | I12: MarketScreener 預估頁（2026-10-25 擷取；頁面為 10-23 收盤；會計年度 6 月） | J12: 差距超過 30% 見 README
A13: FY2028 EPS vs 共識 | B13: =cons_eps28 -> 267.6 | C13: =PL!F14 -> 338.05574 | D13: =C13/B13-1 -> 0.26328751 | E13: =PL!F28 -> 214.571 | F13: =E13/B13-1 -> -0.19816519 | G13: =PL!F42 -> 190.43373 | H13: =G13/B13-1 -> -0.28836425 | I13: MarketScreener 預估頁（2026-10-25 擷取；頁面為 10-23 收盤；會計年度 6 月）
A14: FY2028 年底每股淨值 vs 共識 | B14: =cons_bv28 -> 553.1 | C14: =PL!F15 -> 490.14228 | D14: =C14/B14-1 -> -0.113827 | E14: =PL!F29 -> 410.42318 | F14: =E14/B14-1 -> -0.25795844 | G14: =PL!F43 -> 392.82934 | H14: =G14/B14-1 -> -0.28976795 | I14: MarketScreener 預估頁（2026-10-25 擷取；頁面為 10-23 收盤；會計年度 6 月）
A15: C. 市場層一致性
A16: SanDisk 營收 ÷ 市場層（公司口徑係數 sd_k） | C16: =sd_k -> 0.9994077 | I16: In 頁
A17: Kioxia＋SanDisk 合資群份額 CY2027（市場層 Ann 頁，A／B／C） | C17: 0.24502666 | E17: 0.24202666 | G17: 0.23902666 | I17: markets/nand/dist/20261031_NAND市場模型_v0.3.xlsx｜Ann!F27（kioxia/ 模型讀同一組列）

Sheet Sens
A1: Sens — 一次動一個輸入（情境 A）：對 FY2027、FY2028 營收與 EPS 的影響。每個案例為一個完整推導區塊（本頁下方，與 PL 同一引擎）
A3: 案例 | B3: 設定 | C3: FY2027 營收 $B | D3: FY2027 EPS | E3: 相對基準 | F3: FY2028 營收 $B | G3: FY2028 EPS | H3: 相對基準 | I3: FY2027 毛利率
A4: 基準（情境 A） | B4: PL 區塊 A | C4: =PL!E77 -> 51.713658 | D4: =PL!E96 -> 263.67344 | E4: =D4/D$4-1 -> 0 | F4: =PL!F77 -> 57.762315 | G4: =PL!F96 -> 338.05574 | H4: =G4/G$4-1 -> 0 | I4: =PL!E84 -> 0.86918603
A5: 市場層營收 −20%（價格；FQ2 FY27 起） | B5: 價格係數 0.8 | C5: =E81 -> 43.57705 | D5: =E100 -> 209.97206 | E5: =D5/D$4-1 -> -0.20366625 | F5: =F81 -> 46.209852 | G5: =F100 -> 245.06333 | H5: =G5/G$4-1 -> -0.2750801 | I5: =E88 -> 0.84476074
A6: 市場層營收 +20%（價格） | B6: 價格係數 1.2 | C6: =E131 -> 59.850267 | D6: =E150 -> 319.41833 | E6: =D6/D$4-1 -> 0.21141641 | F6: =F131 -> 69.314778 | G6: =F150 -> 441.08721 | H6: =G6/G$4-1 -> 0.30477657 | I6: =E138 -> 0.88697011
A7: 份額 ×0.9（營收與位元） | B7: 份額係數 0.9 | C7: =E181 -> 46.542293 | D7: =E200 -> 233.83486 | E7: =D7/D$4-1 -> -0.11316491 | F7: =F181 -> 51.986083 | G7: =F200 -> 295.61781 | H7: =G7/G$4-1 -> -0.12553529 | I7: =E188 -> 0.86918603
A8: 份額 ×1.1 | B8: 份額係數 1.1 | C8: =E231 -> 56.885024 | D8: =E250 -> 294.12569 | E8: =D8/D$4-1 -> 0.1154923 | F8: =F231 -> 63.538546 | G8: =F250 -> 382.6274 | H8: =G8/G$4-1 -> 0.13184707 | I8: =E238 -> 0.86918603
A9: 每位元成本年降 10%（C 的值） | B9: cd_C | C9: =E281 -> 51.713658 | D9: =E300 -> 262.86173 | E9: =D9/D$4-1 -> -0.0030784565 | F9: =F281 -> 57.762315 | G9: =F300 -> 334.19404 | H9: =G9/G$4-1 -> -0.01142327 | I9: =E288 -> 0.86688992
A10: 每位元成本年降 18% | B10: cd_A 高 | C10: =E331 -> 51.713658 | D10: =E350 -> 264.50141 | E10: =D10/D$4-1 -> 0.0031401489 | F10: =F331 -> 57.762315 | G10: =F350 -> 341.85736 | H10: =G10/G$4-1 -> 0.011245537 | I10: =E338 -> 0.87152674
A11: 校準毛利率 84.5% | B11: g_gm 低 | C11: =E381 -> 51.713658 | D11: =E400 -> 262.03668 | E11: =D11/D$4-1 -> -0.0062075311 | F11: =F381 -> 57.762315 | G11: =F400 -> 335.75831 | H11: =G11/G$4-1 -> -0.0067959936 | I11: =E388 -> 0.86455467
A12: 校準毛利率 85.5% | B12: g_gm 高 | C12: =E431 -> 51.713658 | D12: =E450 -> 265.12654 | E12: =D12/D$4-1 -> 0.0055110038 | F12: =F431 -> 57.762315 | G12: =F450 -> 340.0985 | H12: =G12/G$4-1 -> 0.0060426842 | I12: =E438 -> 0.87329308
A13: 營業費用變動率 2% | B13: ox_var 高 | C13: =E481 -> 51.713658 | D13: =E500 -> 263.26541 | E13: =D13/D$4-1 -> -0.0015474577 | F13: =F481 -> 57.762315 | G13: =F500 -> 337.40294 | H13: =G13/G$4-1 -> -0.0019310484 | I13: =E488 -> 0.86918603
A14: 稅率 20% | B14: tax 高 | C14: =E531 -> 51.713658 | D14: =E550 -> 246.6184 | E14: =D14/D$4-1 -> -0.06468242 | F14: =F531 -> 57.762315 | G14: =F550 -> 313.13277 | H14: =G14/G$4-1 -> -0.073724422 | I14: =E538 -> 0.86918603
A15: 稅率 12% | B15: tax 低 | C15: =E581 -> 51.713658 | D15: =E600 -> 274.00941 | E15: =D15/D$4-1 -> 0.039199887 | F15: =F581 -> 57.762315 | G15: =F600 -> 353.39574 | H15: =G15/G$4-1 -> 0.045377144 | I15: =E588 -> 0.86918603
A16: 買回 ÷ FCF 80% | B16: payout 高 | C16: =E631 -> 51.713658 | D16: =E650 -> 280.11889 | E16: =D16/D$4-1 -> 0.062370524 | F16: =F631 -> 57.762315 | G16: =F650 -> 389.69397 | H16: =G16/G$4-1 -> 0.15275065 | I16: =E638 -> 0.86918603
A17: 買回 ÷ FCF 30% | B17: payout 低 | C17: =E681 -> 51.713658 | D17: =E700 -> 253.74217 | E17: =D17/D$4-1 -> -0.037665036 | F17: =F681 -> 57.762315 | G17: =F700 -> 310.74733 | H17: =G17/G$4-1 -> -0.08078079 | I17: =E688 -> 0.86918603
A18: 情境 B | B18: markets/nand B；成本年降 12% | C18: =PL!E124 -> 52.209851 | D18: =PL!E143 -> 266.8916 | E18: =D18/D$4-1 -> 0.012205123 | F18: =PL!F124 -> 40.996551 | G18: =PL!F143 -> 214.571 | H18: =G18/G$4-1 -> -0.36527924 | I18: =PL!E131 -> 0.87008934
A19: 情境 C | B19: markets/nand C；成本年降 10% | C19: =PL!E171 -> 51.862074 | D19: =PL!E190 -> 264.44069 | E19: =D19/D$4-1 -> 0.0029098649 | F19: =PL!F171 -> 37.375241 | G19: =PL!F190 -> 190.43373 | H19: =G19/G$4-1 -> -0.4366795 | I19: =PL!E178 -> 0.86890965
A21: 讀法：FQ1 FY27 營收由市場層等於公司指引（恆等式），價格係數只作用在 FQ2 FY27 起；毛利率校準改變單位成本起點，之後每年依成本年降。
A60: 案例區塊：市場層營收 −20%（價格；FQ2 FY27 起）（情境 A）
A61: A. 季度 | B61: 單位 | C61: FQ1 FY26（2025Q3） | D61: FQ2 FY26（2025Q4） | E61: FQ3 FY26（2026Q1） | F61: FQ4 FY26（2026Q2） | G61: FQ1 FY27（2026Q3） | H61: FQ2 FY27（2026Q4） | I61: FQ3 FY27（2027Q1） | J61: FQ4 FY27（2027Q2） | K61: FQ1 FY28（2027Q3） | L61: FQ2 FY28（2027Q4） | M61: FQ3 FY28（2028Q1） | N61: FQ4 FY28（2028Q2） | O61: FQ1 FY29（2028Q3） | P61: FQ2 FY29（2028Q4） | Q61: FQ3 FY29（2029Q1） | R61: FQ4 FY29（2029Q2） | T61: 說明
A62: 市場層營收（TrendForce 口徑，同字母情境） | B62: $B | C62: =Units!E4*1 -> 2.31 | D62: =Units!F4*1 -> 3.03 | E62: =Units!G4*1 -> 5.95 | F62: =Units!H4*1 -> 8.97 | G62: =Units!I4*1 -> 11.037152 | H62: =Units!J4*1*0.8 -> 9.9681695 | I62: =Units!K4*1*0.8 -> 10.983703 | J62: =Units!L4*1*0.8 -> 11.613851 | K62: =Units!M4*1*0.8 -> 11.666145 | L62: =Units!N4*1*0.8 -> 11.471965 | M62: =Units!O4*1*0.8 -> 11.52362 | N62: =Units!P4*1*0.8 -> 11.575508 | O62: =Units!Q4*1*0.8 -> 11.627629 | ... R62: =Units!T4*1*0.8 -> 12.033254 | T62: markets/nand；Sens 可乘份額係數、價格係數（FQ2 FY27 起）
A63: 位元（市場層；同字母） | B63: EB | C63: =Units!E7*1 -> 31.15528 | D63: =Units!F7*1 -> 33.514723 | E63: =Units!G7*1 -> 38.069333 | F63: =Units!H7*1 -> 33.617215 | G63: =Units!I7*1 -> 33.091489 | H63: =Units!J7*1 -> 34.558829 | I63: =Units!K7*1 -> 36.970484 | J63: =Units!L7*1 -> 39.091528 | ... R63: =Units!T7*1 -> 59.81981
A64: 營收 | B64: $B | C64: =q1_rev -> 2.308 | D64: =q2_rev -> 3.025 | E64: =q3_rev -> 5.95 | F64: =q4_rev -> 8.965 | G64: =G62*sd_k -> 11.030615 | H64: =H62*sd_k -> 9.9622653 | I64: =I62*sd_k -> 10.977197 | J64: =J62*sd_k -> 11.606973 | K64: =K62*sd_k -> 11.659235 | L64: =L62*sd_k -> 11.465171 | M64: =M62*sd_k -> 11.516795 | N64: =N62*sd_k -> 11.568651 | ... R64: =R62*sd_k -> 12.026127 | T64: 實績季＝公司財報；之後＝市場層 × 公司口徑係數
A65: 資料中心 | B65: $B | C65: =q1_dc -> 0.269 | D65: =q2_dc -> 0.44 | E65: =q3_dc -> 1.467 | F65: =q4_dc -> 2.977 | G65: =G64*dcsh_27 -> 4.1916337 | H65: =H64*dcsh_27 -> 3.7856608 | I65: =I64*dcsh_27 -> 4.1713348 | J65: =J64*dcsh_27 -> 4.4106496 | K65: =K64*dcsh_28 -> 4.8968788 | L65: =L64*dcsh_28 -> 4.8153716 | M65: =M64*dcsh_28 -> 4.8370538 | N65: =N64*dcsh_28 -> 4.8588336 | O65: =O64*dcsh_29 -> 5.2293337 | P65: =P64*dcsh_29 -> 5.2528798 | Q65: =Q64*dcsh_29 -> 5.3085586 | R65: =R64*dcsh_29 -> 5.4117572 | T65: 官方分部；實績季＝10-Q／10-K；之後＝營收 × 資料中心占比（In）
A66: 資料中心：AI 相關（＝資料中心 × AI 企業級 SSD 占比） | B66: $B | C66: =C65*(Units!C16+Units!D16)/2 -> 0.17543406 | D66: =D65*(Units!C16+Units!D16)/2 -> 0.28695533 | E66: =E65*(Units!C16+Units!D16)/2 -> 0.95673517 | F66: =F65*(Units!C16+Units!D16)/2 -> 1.9415137 | G66: =G65*(Units!D16+Units!E16)/2 -> 3.323531 | H66: =H65*(Units!D16+Units!E16)/2 -> 3.0016366 | I66: =I65*(Units!D16+Units!E16)/2 -> 3.3074361 | J66: =J65*(Units!D16+Units!E16)/2 -> 3.4971879 | K66: =K65*(Units!E16+Units!F16)/2 -> 4.1293081 | L66: =L65*(Units!E16+Units!F16)/2 -> 4.0605769 | M66: =M65*(Units!E16+Units!F16)/2 -> 4.0788605 | N66: =N65*(Units!E16+Units!F16)/2 -> 4.0972264 | O66: =O65*(Units!F16+Units!G16)/2 -> 4.5242058 | P66: =P65*(Units!F16+Units!G16)/2 -> 4.5445769 | Q66: =Q65*(Units!F16+Units!G16)/2 -> 4.5927479 | R66: =R65*(Units!F16+Units!G16)/2 -> 4.6820312 | T66: 命題子列（Derived）：會計年度 ≈ 前後兩個日曆年平均；假設 SanDisk 資料中心組合與產業企業級 SSD 相同
A67: 資料中心：非 AI | B67: $B | C67: =C65-C66 -> 0.093565943 | D67: =D65-D66 -> 0.15304467 | E67: =E65-E66 -> 0.51026483 | F67: =F65-F66 -> 1.0354863 | G67: =G65-G66 -> 0.86810269 | H67: =H65-H66 -> 0.78402423 | I67: =I65-I66 -> 0.86389873 | J67: =J65-J66 -> 0.91346169 | ... R67: =R65-R66 -> 0.72972605
A68: 消費 | B68: $B | C68: =q1_cs -> 0.652 | D68: =q2_cs -> 0.907 | E68: =q3_cs -> 0.82 | F68: =q4_cs -> 0.556 | G68: =G64*cssh_27 -> 0.6618369 | H68: =H64*cssh_27 -> 0.59773592 | I68: =I64*cssh_27 -> 0.65863181 | J68: =J64*cssh_27 -> 0.69641835 | K68: =K64*cssh_28 -> 0.69955412 | L68: =L64*cssh_28 -> 0.68791023 | M68: =M64*cssh_28 -> 0.69100768 | N68: =N64*cssh_28 -> 0.69411908 | O68: =O64*cssh_29 -> 0.69724449 | P68: =P64*cssh_29 -> 0.70038398 | Q68: =Q64*cssh_29 -> 0.70780781 | R68: =R64*cssh_29 -> 0.72156763 | T68: 官方分部
A69: 邊緣 | B69: $B | C69: =q1_ed -> 1.387 | D69: =q2_ed -> 1.678 | E69: =q3_ed -> 3.663 | F69: =q4_ed -> 5.432 | G69: =G64-G65-G68 -> 6.1771444 | H69: =H64-H65-H68 -> 5.5788686 | I69: =I64-I65-I68 -> 6.1472303 | J69: =J64-J65-J68 -> 6.4999046 | K69: =K64-K65-K68 -> 6.0628023 | L69: =L64-L65-L68 -> 5.9618887 | M69: =M64-M65-M68 -> 5.9887333 | N69: =N64-N65-N68 -> 6.0156987 | ... R69: =R64-R65-R68 -> 5.8928023 | T69: 官方分部；預測季＝營收 − 資料中心 − 消費
A70: 檢查：分部合計 − 營收（季） | B70: $B | C70: =C65+C69+C68-C64 -> 0 | D70: =D65+D69+D68-D64 -> 0 | E70: =E65+E69+E68-E64 -> 0 | F70: =F65+F69+F68-F64 -> 0 | G70: =G65+G69+G68-G64 -> 0 | H70: =H65+H69+H68-H64 -> 0 | I70: =I65+I69+I68-I64 -> 0 | J70: =J65+J69+J68-J64 -> 0 | ... R70: =R65+R69+R68-R64 -> 0
A71: 每 EB 營業成本（FQ1 FY27 以實績毛利率校準，之後每年 × (1 − 成本年降)） | B71: $B/EB | C71: =C72/C63 -> 0.052004539 | D71: =D72/D63 -> 0.04431709 | E71: =E72/E63 -> 0.033759457 | F71: =F72/F63 -> 0.041068541 | G71: =(1-g_gm)*G64/G63 -> 0.049900536 | H71: =$G71*(1-cd_A)^(1/4) -> 0.048054031 | I71: =$G71*(1-cd_A)^(2/4) -> 0.046275853 | J71: =$G71*(1-cd_A)^(3/4) -> 0.044563475 | K71: =$G71*(1-cd_A)^(4/4) -> 0.042914461 | L71: =$G71*(1-cd_A)^(5/4) -> 0.041326467 | M71: =$G71*(1-cd_A)^(6/4) -> 0.039797234 | N71: =$G71*(1-cd_A)^(7/4) -> 0.038324588 | O71: =$G71*(1-cd_A)^(8/4) -> 0.036906436 | P71: =$G71*(1-cd_A)^(9/4) -> 0.035540761 | Q71: =$G71*(1-cd_A)^(10/4) -> 0.034225621 | R71: =$G71*(1-cd_A)^(11/4) -> 0.032959146
A72: 營業成本 | B72: $B | C72: =q1_rev*(1-q1_gm) -> 1.620216 | D72: =q2_rev*(1-q2_gm) -> 1.485275 | E72: =q3_rev*(1-q3_gm) -> 1.2852 | F72: =q4_rev*(1-q4_gm) -> 1.38061 | G72: =G63*G71 -> 1.6512831 | H72: =H63*H71 -> 1.660691 | I72: =I63*I71 -> 1.7108407 | J72: =J63*J71 -> 1.7420543 | K72: =K63*K71 -> 1.7738374 | L72: =L63*L71 -> 1.8062004 | M72: =M63*M71 -> 1.8391538 | N72: =N63*N71 -> 1.8727084 | ... R72: =R63*R71 -> 1.9716099
A73: 毛利率 | B73: % | C73: =1-C72/C64 -> 0.298 | D73: =1-D72/D64 -> 0.509 | E73: =1-E72/E64 -> 0.784 | F73: =1-F72/F64 -> 0.846 | G73: =1-G72/G64 -> 0.8503 | H73: =1-H72/H64 -> 0.83330187 | I73: =1-I72/I64 -> 0.84414594 | J73: =1-J72/J64 -> 0.84991312 | ... R73: =1-R72/R64 -> 0.83605613
A74: 營業費用 | B74: $B | C74: =q1_rev-q1_rev*(1-q1_gm)-q1_op -> 0.511784 | D74: =q2_rev-q2_rev*(1-q2_gm)-q2_op -> 0.474725 | E74: =q3_rev-q3_rev*(1-q3_gm)-q3_op -> 0.5538 | F74: =q4_rev-q4_rev*(1-q4_gm)-q4_op -> 0.54739 | G74: =(g_ox-ox_var*g_rev)*(1+ox_g)^(0/4)+ox_var*G64 -> 0.58199615 | H74: =(g_ox-ox_var*g_rev)*(1+ox_g)^(1/4)+ox_var*H64 -> 0.58268684 | I74: =(g_ox-ox_var*g_rev)*(1+ox_g)^(2/4)+ox_var*I64 -> 0.60448461 | J74: =(g_ox-ox_var*g_rev)*(1+ox_g)^(3/4)+ox_var*J64 -> 0.62271172 | K74: =(g_ox-ox_var*g_rev)*(1+ox_g)^(4/4)+ox_var*K64 -> 0.63545135 | L74: =(g_ox-ox_var*g_rev)*(1+ox_g)^(5/4)+ox_var*L64 -> 0.64602231 | M74: =(g_ox-ox_var*g_rev)*(1+ox_g)^(6/4)+ox_var*M64 -> 0.65935186 | N74: =(g_ox-ox_var*g_rev)*(1+ox_g)^(7/4)+ox_var*N64 -> 0.67299271 | O74: =(g_ox-ox_var*g_rev)*(1+ox_g)^(8/4)+ox_var*O64 -> 0.68695232 | P74: =(g_ox-ox_var*g_rev)*(1+ox_g)^(9/4)+ox_var*P64 -> 0.70123833 | Q74: =(g_ox-ox_var*g_rev)*(1+ox_g)^(10/4)+ox_var*Q64 -> 0.71657027 | R74: =(g_ox-ox_var*g_rev)*(1+ox_g)^(11/4)+ox_var*R64 -> 0.73329808 | T74: 固定部分以 FQ1 FY27 營業費用（實績推估）校準（Derived）
A75: 營業利益 | B75: $B | C75: =C64-C72-C74 -> 0.176 | D75: =D64-D72-D74 -> 1.065 | E75: =E64-E72-E74 -> 4.111 | F75: =F64-F72-F74 -> 7.037 | G75: =G64-G72-G74 -> 8.7973357 | H75: =H64-H72-H74 -> 7.7188875 | I75: =I64-I72-I74 -> 8.6618716 | J75: =J64-J72-J74 -> 9.2422065 | ... R75: =R64-R72-R74 -> 9.3212192
A77: 淨利 | B77: $B | C77: =q1_ni -> 0.112 | D77: =q2_ni -> 0.803 | E77: =q3_ni -> 3.615 | F77: =q4_ni -> 6.903 | G77: =(G75+rf*$D98/4)*(1-tax) -> 7.5182124 | H77: =(H75+rf*$D98/4)*(1-tax) -> 6.6015313 | I77: =(I75+rf*$D98/4)*(1-tax) -> 7.4030678 | J77: =(J75+rf*$D98/4)*(1-tax) -> 7.8963525 | K77: =(K75+rf*$E98/4)*(1-tax) -> 8.0175308 | L77: =(L75+rf*$E98/4)*(1-tax) -> 7.816082 | M77: =(M75+rf*$E98/4)*(1-tax) -> 7.8206221 | N77: =(N75+rf*$E98/4)*(1-tax) -> 7.8245841 | O77: =(O75+rf*$F98/4)*(1-tax) -> 7.9506347 | P77: =(P75+rf*$F98/4)*(1-tax) -> 7.953396 | Q77: =(Q75+rf*$F98/4)*(1-tax) -> 8.0400838 | R77: =(R75+rf*$F98/4)*(1-tax) -> 8.2007941 | T77: （營業利益＋上一年底淨現金 × 收益率 ÷ 4）×（1 − 稅率）
A78: 季 EPS（稀釋） | B78: USD | G78: =G77/(sh0+dil)*1000 -> 49.789486 | H78: =H77/(sh0+dil)*1000 -> 43.718751 | I78: =I77/(sh0+dil)*1000 -> 49.026939 | J78: =J77/(sh0+dil)*1000 -> 52.293725 | K78: =K77/(sh0+dil)*1000 -> 53.096231 | L78: =L77/(sh0+dil)*1000 -> 51.762132 | M78: =M77/(sh0+dil)*1000 -> 51.792199 | N78: =N77/(sh0+dil)*1000 -> 51.818438 | ... R78: =R77/(sh0+dil)*1000 -> 54.309895
A80: B. 年度（會計年度） | B80: 單位 | C80: FY2025A | D80: FY2026A | E80: FY2027 | F80: FY2028 | G80: FY2029 | T80: 說明
A81: 營收 | B81: $B | C81: =a25_rev -> 7.355 | D81: =SUM(C64:F64) -> 20.248 | E81: =SUM(G64:J64) -> 43.57705 | F81: =SUM(K64:N64) -> 46.209852 | G81: =SUM(O64:R64) -> 47.116732
A82: 營收：資料中心 | B82: $B | D82: =SUM(C65:F65) -> 5.153 | E82: =SUM(G65:J65) -> 16.559279 | F82: =SUM(K65:N65) -> 19.408138 | G82: =SUM(O65:R65) -> 21.202529
...

Sheet Sources
A1: 來源
A2: SanDisk FQ4 FY26 新聞稿（8-K，2026-08-05） | B2: https://www.sec.gov/Archives/edgar/data/0002023554/000162828026053346/sndkq4-26ex991xpressrelease.htm
A3: SanDisk FQ2 FY26 新聞稿（8-K，2026-01-29） | B3: https://www.sec.gov/Archives/edgar/data/2023554/000162828026004121/sndkq2fy26ex991-pressrelea.htm
A4: SanDisk：FQ1 FY27 財報日 2026-10-29（2026-09-29 公告） | B4: https://investor.sandisk.com/news-releases/news-release-details/sandisk-report-first-quarter-fiscal-year-2027-results-october-29
A5: stockanalysis：歷史股價、統計、共識目標價 | B5: https://stockanalysis.com/stocks/sndk/forecast/
A6: MarketScreener：SanDisk 預估（EPS、每股淨值、股數） | B6: https://uk.marketscreener.com/quote/stock/SANDISK-CORPORATION-182801077/finances/
A7: MarketScreener：Kioxia 預估（同業 P/B、P/E） | B7: https://uk.marketscreener.com/quote/stock/KIOXIA-HOLDINGS-CORPORATI-180030735/finances/
A8: stockanalysis：WDC 統計（Forward P/E） | B8: https://stockanalysis.com/stocks/wdc/statistics/
A9: Motley Fool：SanDisk／Kioxia 日本投資、FY27 毛資本支出約營收 6%（2026-08-29） | B9: https://www.fool.com/investing/2026/08/29/sandisk-and-kioxia-plan-to-invest-more-than-usd31-billion-in-japanese-memory-plants-about-60-of-what-they-have-spent-there-in-25-years/
A10: 市場層：markets/nand/dist/20261031_NAND市場模型_v0.3.xlsx（markets/nand v0.1） | B10: 本 repo
A11: 美光十年倍數與淨利率（Analogy）：micron/dist/20261030_美光個股模型_v0.4.3.xlsx | B11: 本 repo
A12: SemiAnalysis | B12: 未使用
