Workbook

Sheet README
A1: SanDisk（SNDK US）收支與估值模型 v0.1（AI 半導體 Project：記憶體——NAND） 2026-10-25
A2: 模型命題：SanDisk 是純 NAND 公司，盈餘由 NAND 合約價循環與 AI 推論帶動的企業級 SSD 位元決定，產能與 Kioxia 合資（Flash Ventures 49.9%）；問題是 2026 年的高價能維持多久（FY2028 起三情境分歧），以及現價隱含的倍數是否已反映循環見頂。
A3: 重點觀察
A4: ="1. 加權目標價 "&TEXT(Val!B49,"#,##0")&" 美元，相對現價 "&TEXT(px,"#,##0.00")&"（2026-10-23 收盤）"&TEXT(Val!B52,"+0.0%;−0.0%")&"，主因是 Comparable 偏低：同業前瞻 P/B 中位數 "&TEXT(Val!B32,"0.00")&"x，而共識目標價隱含約 "&TEXT(cons_tp/((cons_bv28+cons_bv29)/2),"0.00")&"x（倍數因素 "&TEXT(Val!B59,"+0%;−0%")&"）；DCF 目標價 "&TEXT(Val!B24,"#,##0")&" 高於 Comparable "&TEXT(Val!B34,"#,##0")&"。" -> 1. 加權目標價 953 美元，相對現價 1,238.03（2026-10-23 收盤）−23.0%，主因是 Comparable 偏低：同業前瞻 P/B 中位數 1.49x，而共識目標價隱含約 3.56x（倍數因素 +139%）；DCF 目標價 1,139 高於 Comparable 767。
A5: ="2. 本模型 FY2027 EPS（A）"&TEXT(PL!E10,"0")&" 美元，比共識 217.4 "&TEXT(PL!E10/cons_eps27-1,"+0%;−0%")&"；B、C 到 FY2028 才分歧（"&TEXT(PL!F20,"0")&"／"&TEXT(PL!F30,"0")&"），因為 2026Q3–2027Q2 的價格與位元三情境幾乎相同（markets/nand）。追蹤：2026-10-29 FQ1 FY27 財報與 FQ2 指引。" -> 2. 本模型 FY2027 EPS（A）263 美元，比共識 217.4 +21%；B、C 到 FY2028 才分歧（220／195），因為 2026Q3–2027Q2 的價格與位元三情境幾乎相同（markets/nand）。追蹤：2026-10-29 FQ1 FY27 財報與 FQ2 指引。
A6: ="3. 最敏感的是價格而非成本：2027 起季價 ±20% 使 FY2028 EPS（A）變動 "&TEXT(Sens!H5,"+0%;−0%")&"／"&TEXT(Sens!H6,"+0%;−0%")&"，成本年降 ±4pt 只有約 ±1%；情境 C 的 FY2029 毛利率降到 "&TEXT(PL!G26,"0%")&"（CY2028 NAND 價格跌回約 2025 年水準）。追蹤：TrendForce 每季初的 NAND 合約價與 Kioxia 2026-10-30 財報（合資群位元與價格）。" -> 3. 最敏感的是價格而非成本：2027 起季價 ±20% 使 FY2028 EPS（A）變動 −28%／+31%，成本年降 ±4pt 只有約 ±1%；情境 C 的 FY2029 毛利率降到 49%（CY2028 NAND 價格跌回約 2025 年水準）。追蹤：TrendForce 每季初的 NAND 合約價與 Kioxia 2026-10-30 財報（合資群位元與價格）。
A7: ="投資建議："&Val!B55&"（依上檔空間固定規則；上檔空間："&TEXT(Val!B52,"+0.0%;−0.0%")&"，級距："&Val!B54&"）" -> 投資建議：中立（依上檔空間固定規則；上檔空間：−23.0%，級距：0%～−25%）
A9: 驅動因子 → 推導量（因果方向：左邊決定右邊）
A10: Units｜markets/nand 成品：SanDisk 季度營收（市場營收 × 份額；同字母情境）與位元（季度出貨 × 份額）
A11: PL 區塊｜營收＝市場層 × 公司口徑係數；營業成本＝位元 × 每 EB 成本（FQ1 FY27 以指引毛利率校準，之後每年 × (1 − 成本年降)）；營業費用＝固定（指引校準）＋變動
A12: PL 區塊｜淨利＝（營業利益＋淨現金收益）×（1 − 稅率）；自由現金流＝淨利＋折舊 − 資本支出（含合資群分攤）；買回＝回饋比例 × FCF → 股數 → EPS、每股淨值
A13: Val｜第 0 節目標價＝DCF（FY2027–FY2032＋永續）與 Comparable（同業前瞻 P/B × 約 2028 年底每股淨值）各半；第 5–6 節目前倍數、十年倍數規則值（美光 Analogy）
A15: 會計年度：約 6 月底結束（FY2027＝2026-07～2027-06 ≈ CY2026Q3–CY2027Q2）。前瞻 EPS 依月份調整：12 個月後（約 2027-10）的未來 12 月＝8／12 FY2028＋4／12 FY2029。
A16: 情境：A＝順利、B＝平平、C＝不如預期，讀 markets/nand 同字母（價格＝markets/memory NAND_S；顆數＝SCEN_UNITS；合資群份額年變動）；公司特有變數（每位元成本年降 14%／12%／10%）A 最有利、C 最不利。FY2027 的 B、C EPS 略高於 A：上游 markets/memory 的 B、C 價格路徑 2027 上半年漲幅較大、下半年才回落（行業情境，不在公司層調整）。FY2030 起為收斂法，非驅動因子推導。
A17: 十年歷史不足：2025-02 自 WDC 分拆上市，十年 P/B、P/E 與十年平均淨利率以美光為 Analogy。本版未做先驗，無 Andy 合理 P/E 對照。

Sheet In
A1: In — 輸入（藍字；基準欄 E，低 D、高 F）。金額：十億美元（$B）；每股：美元；股數：百萬股。每個輸入附標記與來源；找不到者寫「未找到」
A2: 標記：Verified（公司文件、交易所資料）／Interested-party（寫明是誰、立場）／Analogy（寫明對照與差異）／Assumed（給低／高區間）／Derived（寫明換算）。SemiAnalysis 未使用
A3: 鍵 | B3: 項目 | C3: 單位 | D3: 低 | E3: 基準 | F3: 高 | G3: 標記 | H3: 來源1 | I3: 來源2／說明
A4: A. 季度實績與公司指引（$B；EPS 美元）
A5: q1_rev | B5: FQ1 FY26 營收 | C5: $B | E5: 2.308 | G5: Verified | H5: SanDisk FQ2 FY26 新聞稿（8-K，2026-01-29） | I5: FY26 合計 20.248（FQ4 新聞稿）
A6: q1_gm | B6: FQ1 FY26 GAAP 毛利率 | C6: % | E6: 0.298 | G6: Verified | H6: SanDisk FQ2 FY26 新聞稿（8-K，2026-01-29）
A7: q1_op | B7: FQ1 FY26 GAAP 營業利益 | C7: $B | E7: 0.176 | G7: Verified | H7: SanDisk FQ2 FY26 新聞稿（8-K，2026-01-29）
A8: q1_ni | B8: FQ1 FY26 GAAP 淨利 | C8: $B | E8: 0.112 | G8: Verified | H8: SanDisk FQ2 FY26 新聞稿（8-K，2026-01-29）
A9: q1_eps | B9: FQ1 FY26 GAAP 稀釋 EPS | C9: USD | E9: 0.75 | G9: Verified | H9: SanDisk FQ2 FY26 新聞稿（8-K，2026-01-29）
A10: q2_rev | B10: FQ2 FY26 營收 | C10: $B | E10: 3.025 | G10: Verified | H10: SanDisk FQ2 FY26 新聞稿（8-K，2026-01-29） | I10: FY26 合計 20.248（FQ4 新聞稿）
A11: q2_gm | B11: FQ2 FY26 GAAP 毛利率 | C11: % | E11: 0.509 | G11: Verified | H11: SanDisk FQ2 FY26 新聞稿（8-K，2026-01-29）
A12: q2_op | B12: FQ2 FY26 GAAP 營業利益 | C12: $B | E12: 1.065 | G12: Verified | H12: SanDisk FQ2 FY26 新聞稿（8-K，2026-01-29）
A13: q2_ni | B13: FQ2 FY26 GAAP 淨利 | C13: $B | E13: 0.803 | G13: Verified | H13: SanDisk FQ2 FY26 新聞稿（8-K，2026-01-29）
A14: q2_eps | B14: FQ2 FY26 GAAP 稀釋 EPS | C14: USD | E14: 5.15 | G14: Verified | H14: SanDisk FQ2 FY26 新聞稿（8-K，2026-01-29）
A15: q3_rev | B15: FQ3 FY26 營收 | C15: $B | E15: 5.95 | G15: Verified | H15: SanDisk FQ4 FY26 新聞稿（8-K，2026-08-05） | I15: FY26 合計 20.248（FQ4 新聞稿）
A16: q3_gm | B16: FQ3 FY26 GAAP 毛利率 | C16: % | E16: 0.784 | G16: Verified | H16: SanDisk FQ4 FY26 新聞稿（8-K，2026-08-05）
A17: q3_op | B17: FQ3 FY26 GAAP 營業利益 | C17: $B | E17: 4.111 | G17: Verified | H17: SanDisk FQ4 FY26 新聞稿（8-K，2026-08-05）
A18: q3_ni | B18: FQ3 FY26 GAAP 淨利 | C18: $B | E18: 3.615 | G18: Verified | H18: SanDisk FQ4 FY26 新聞稿（8-K，2026-08-05）
A19: q3_eps | B19: FQ3 FY26 GAAP 稀釋 EPS | C19: USD | E19: 23.03 | G19: Verified | H19: SanDisk FQ4 FY26 新聞稿（8-K，2026-08-05）
A20: q4_rev | B20: FQ4 FY26 營收 | C20: $B | E20: 8.965 | G20: Verified | H20: SanDisk FQ4 FY26 新聞稿（8-K，2026-08-05） | I20: FY26 合計 20.248（FQ4 新聞稿）
A21: q4_gm | B21: FQ4 FY26 GAAP 毛利率 | C21: % | E21: 0.846 | G21: Verified | H21: SanDisk FQ4 FY26 新聞稿（8-K，2026-08-05）
A22: q4_op | B22: FQ4 FY26 GAAP 營業利益 | C22: $B | E22: 7.037 | G22: Verified | H22: SanDisk FQ4 FY26 新聞稿（8-K，2026-08-05）
A23: q4_ni | B23: FQ4 FY26 GAAP 淨利 | C23: $B | E23: 6.903 | G23: Verified | H23: SanDisk FQ4 FY26 新聞稿（8-K，2026-08-05）
A24: q4_eps | B24: FQ4 FY26 GAAP 稀釋 EPS | C24: USD | E24: 43.97 | G24: Verified | H24: SanDisk FQ4 FY26 新聞稿（8-K，2026-08-05）
A25: a26_rev | B25: FY2026 營收（2025-07～2026-07-03） | C25: $B | E25: 20.248 | G25: Verified | H25: SanDisk FQ4 FY26 新聞稿（8-K，2026-08-05）：資料中心 5.153、邊緣 12.160、消費 2.935 | I25: MarketScreener 同值
A26: a26_ni | B26: FY2026 GAAP 淨利 | C26: $B | E26: 11.433 | G26: Verified | H26: SanDisk FQ4 FY26 新聞稿（8-K，2026-08-05） | I26: MarketScreener 同值
A27: a26_eps | B27: FY2026 GAAP 稀釋 EPS | C27: USD | E27: 73.76 | G27: Verified | H27: SanDisk FQ4 FY26 新聞稿（8-K，2026-08-05）（non-GAAP 70.88） | I27: MarketScreener 73.76
A28: a26_op | B28: FY2026 GAAP 營業利益 | C28: $B | E28: 12.389 | G28: Verified | H28: SanDisk FQ4 FY26 新聞稿（8-K，2026-08-05）
A29: a26_gm | B29: FY2026 GAAP 毛利率 | C29: % | E29: 0.715 | G29: Verified | H29: SanDisk FQ4 FY26 新聞稿（8-K，2026-08-05）
A30: a25_rev | B30: FY2025 營收 | C30: $B | E30: 7.355 | G30: Verified | H30: SanDisk FQ4 FY26 新聞稿（8-K，2026-08-05）（前期欄） | I30: MarketScreener 7,355
A31: a25_ni | B31: FY2025 GAAP 淨利 | C31: $B | E31: -1.641 | G31: Verified | H31: SanDisk FQ4 FY26 新聞稿（8-K，2026-08-05）（含商譽減損） | I31: MarketScreener −1,641
A32: a25_eps | B32: FY2025 GAAP 稀釋 EPS | C32: USD | E32: -11.32 | G32: Verified | H32: SanDisk FQ4 FY26 新聞稿（8-K，2026-08-05）
A33: g_rev | B33: 公司指引：FQ1 FY27（2026-07～09）營收中值 | C33: $B | D33: 10.3 | E33: 10.55 | F33: 10.8 | G33: Interested-party | H33: SanDisk FQ4 FY26 新聞稿（8-K，2026-08-05）：$10.3–10.8B | I33: 公司指引（立場：公司）；市場層 markets/nand 以此推 SanDisk 2026Q3 份額，因此本模型 FQ1 FY27 營收＝指引（恆等式）
A34: g_gm | B34: 公司指引：FQ1 FY27 GAAP 毛利率中值 | C34: % | D34: 0.83 | E34: 0.84 | F34: 0.849 | G34: Interested-party | H34: SanDisk FQ4 FY26 新聞稿（8-K，2026-08-05）：GAAP 83.0–84.9%（non-GAAP 83.0–85.0%） | I34: 用來校準單位成本（FQ1 FY27 為基準季）
A35: g_ox | B35: 公司指引：FQ1 FY27 GAAP 營業費用中值 | C35: $B | D35: 0.574 | E35: 0.594 | F35: 0.614 | G35: Interested-party | H35: SanDisk FQ4 FY26 新聞稿（8-K，2026-08-05）：GAAP $574–614M（non-GAAP $520–540M）
A36: g_eps | B36: 公司指引：FQ1 FY27 non-GAAP 稀釋 EPS 中值 | C36: USD | D36: 44 | E36: 45 | F36: 46 | G36: Interested-party | H36: SanDisk FQ4 FY26 新聞稿（8-K，2026-08-05）：$44.00–46.00；稀釋股數約 155 百萬股、non-GAAP 稅率 15%
A37: g_sh | B37: 公司指引：FQ1 FY27 稀釋股數 | C37: 百萬股 | E37: 155 | G37: Interested-party | H37: SanDisk FQ4 FY26 新聞稿（8-K，2026-08-05）
A38: B. 成本、費用、稅（公司特有；隨情境者 A 最有利、C 最不利）
A39: cd_A | B39: 情境 A：每位元成本年降 | C39: % | D39: 0.1 | E39: 0.14 | F39: 0.18 | G39: Assumed | H39: A：BiCS8→BiCS10（332 層，密度約 +59%）如期量產，每位元成本年降約 14% | I39: 以 FQ1 FY27 指引毛利率校準的單位成本為起點；歷史每位元成本年降約 15–20%（Analogy：產業製程轉換）
A40: cd_B | B40: 情境 B：每位元成本年降 | C40: % | D40: 0.08 | E40: 0.12 | F40: 0.16 | G40: Assumed | H40: B：轉換略延後 | I40: 同上
...

Sheet Q
A1: Q — 季度實績（$B；EPS 美元）與公司指引。會計年度約 6 月底結束；FQ1＝7–9 月
A3: 項目 | B3: FQ1 FY26 | C3: FQ2 FY26 | D3: FQ3 FY26 | E3: FQ4 FY26 | F3: FY2026 | G3: FQ1 FY27 指引 | H3: 標記 | I3: 來源
A4: 營收 | B4: =q1_rev -> 2.308 | C4: =q2_rev -> 3.025 | D4: =q3_rev -> 5.95 | E4: =q4_rev -> 8.965 | F4: =SUM(B4:E4) -> 20.248 | G4: =g_rev -> 10.55 | H4: Verified | I4: SanDisk FQ2 FY26 新聞稿（8-K，2026-01-29）；SanDisk FQ4 FY26 新聞稿（8-K，2026-08-05）
A5: GAAP 毛利率 | B5: =q1_gm -> 0.298 | C5: =q2_gm -> 0.509 | D5: =q3_gm -> 0.784 | E5: =q4_gm -> 0.846 | F5: =SUMPRODUCT(B4:E4,B5:E5)/F4 -> 0.71496933 | G5: =g_gm -> 0.84 | H5: Verified | I5: SanDisk FQ2 FY26 新聞稿（8-K，2026-01-29）；SanDisk FQ4 FY26 新聞稿（8-K，2026-08-05）
A6: GAAP 營業利益 | B6: =q1_op -> 0.176 | C6: =q2_op -> 1.065 | D6: =q3_op -> 4.111 | E6: =q4_op -> 7.037 | F6: =SUM(B6:E6) -> 12.389 | H6: Verified | I6: SanDisk FQ2 FY26 新聞稿（8-K，2026-01-29）；SanDisk FQ4 FY26 新聞稿（8-K，2026-08-05）
A7: GAAP 淨利 | B7: =q1_ni -> 0.112 | C7: =q2_ni -> 0.803 | D7: =q3_ni -> 3.615 | E7: =q4_ni -> 6.903 | F7: =SUM(B7:E7) -> 11.433 | H7: Verified | I7: SanDisk FQ2 FY26 新聞稿（8-K，2026-01-29）；SanDisk FQ4 FY26 新聞稿（8-K，2026-08-05）
A8: GAAP 稀釋 EPS | B8: =q1_eps -> 0.75 | C8: =q2_eps -> 5.15 | D8: =q3_eps -> 23.03 | E8: =q4_eps -> 43.97 | F8: =a26_eps -> 73.76 | G8: =g_eps -> 45 | H8: Verified | I8: SanDisk FQ2 FY26 新聞稿（8-K，2026-01-29）；SanDisk FQ4 FY26 新聞稿（8-K，2026-08-05）
A9: 檢查：四季營收、淨利合計 − FY2026（應約為 0） | B9: =F4-a26_rev -> 0 | C9: =F7-a26_ni -> 0
A10: 季增：營收 | C10: =C4/B4-1 -> 0.31065858 | D10: =D4/C4-1 -> 0.96694215 | E10: =E4/D4-1 -> 0.50672269
A12: FQ1 FY27（2026-07～09）財報 2026-10-29 盤後公布（公司 2026-09-29 公告）；本版 FY2027 第一季＝市場層推導（營收等於公司指引中值，為恆等式）

Sheet Units
A1: Units — 市場層 markets/nand 成品的 SanDisk 季度營收與位元（三情境；唯讀抄錄，藍字）。來源：markets/nand/dist/20261025_NAND市場模型_v0.1.xlsx
A2: C..Z＝CY2025Q1..CY2030Q4；營收為 TrendForce 口徑（$B），位元為季度出貨 × 營收份額（EB）。合資群份額＝Kioxia＋SanDisk（與 kioxia/ 模型讀同一列）
A3: 項目 | B3: 單位 | C3: 2025Q1 | D3: 2025Q2 | E3: 2025Q3 | F3: 2025Q4 | G3: 2026Q1 | H3: 2026Q2 | I3: 2026Q3 | J3: 2026Q4 | K3: 2027Q1 | L3: 2027Q2 | M3: 2027Q3 | N3: 2027Q4 | O3: 2028Q1 | P3: 2028Q2 | Q3: 2028Q3 | R3: 2028Q4 | S3: 2029Q1 | T3: 2029Q2 | U3: 2029Q3 | V3: 2029Q4 | W3: 2030Q1 | X3: 2030Q2 | Y3: 2030Q3 | Z3: 2030Q4 | AA3: 來源
A4: SanDisk 營收（情境 A） | B4: $B | C4: 1.69 | D4: 1.9 | E4: 2.31 | F4: 3.03 | G4: 5.95 | H4: 8.97 | I4: 10.555884 | J4: 13.008548 | K4: 14.333827 | L4: 15.156177 | M4: 15.224421 | N4: 14.971015 | O4: 15.038425 | P4: 15.106138 | Q4: 15.174156 | R4: 15.242481 | S4: 15.369653 | T4: 15.654084 | U4: 15.943779 | V4: 16.238835 | W4: 15.878856 | X4: 15.891708 | Y4: 15.904571 | Z4: 15.917444 | AA4: markets/nand/dist/20261025_NAND市場模型_v0.1.xlsx｜Mkt!C44:Z44
A5: SanDisk 營收（情境 B） | B5: $B | C5: 1.69 | D5: 1.9 | E5: 2.31 | F5: 3.03 | G5: 5.95 | H5: 8.97 | I5: 10.555884 | J5: 13.008548 | K5: 14.444873 | L5: 15.579066 | M5: 14.825571 | N5: 12.540906 | O5: 8.7186957 | P5: 6.7713807 | Q5: 5.609597 | R5: 5.2280366 | S5: 5.7833132 | T5: 6.3632149 | U5: 6.8679068 | V5: 7.4126278 | W5: 7.165894 | X5: 7.1646076 | Y5: 7.1633215 | Z5: 7.1620355 | AA5: markets/nand/dist/20261025_NAND市場模型_v0.1.xlsx｜Mkt!C92:Z92
A6: SanDisk 營收（情境 C） | B6: $B | C6: 1.69 | D6: 1.9 | E6: 2.31 | F6: 3.03 | G6: 5.95 | H6: 8.97 | I6: 10.555884 | J6: 13.008548 | K6: 14.277592 | L6: 15.39865 | M6: 14.653881 | N6: 12.395674 | O6: 7.2948293 | P6: 4.7531296 | Q6: 3.5734861 | R6: 2.8657167 | S6: 3.0446912 | T6: 3.3131741 | U6: 3.7083416 | V6: 4.2275051 | W6: 4.0774623 | X6: 4.0679223 | Y6: 4.0584046 | Z6: 4.0489092 | AA6: markets/nand/dist/20261025_NAND市場模型_v0.1.xlsx｜Mkt!C140:Z140
A7: SanDisk 位元（情境 A） | B7: EB | C7: 31.287396 | D7: 29.615294 | E7: 31.15528 | F7: 33.514723 | G7: 38.069333 | H7: 33.617215 | I7: 34.400604 | J7: 36.079657 | K7: 38.597443 | L7: 40.811827 | M7: 43.153253 | N7: 45.62901 | O7: 48.246803 | P7: 51.014784 | Q7: 53.941566 | R7: 57.036262 | S7: 59.290856 | T7: 62.255767 | U7: 65.368941 | V7: 68.637793 | W7: 69.295811 | X7: 71.604068 | Y7: 73.989213 | Z7: 76.453808 | AA7: markets/nand/dist/20261025_NAND市場模型_v0.1.xlsx｜Mkt!C48:Z48
A8: SanDisk 位元（情境 B） | B8: EB | C8: 31.287396 | D8: 29.615294 | E8: 31.15528 | F8: 33.514723 | G8: 38.069333 | H8: 33.617215 | I8: 34.400604 | J8: 36.079657 | K8: 38.155576 | L8: 40.34461 | M8: 42.659231 | N8: 45.106645 | O8: 44.798668 | P8: 46.390553 | Q8: 48.039004 | R8: 49.746031 | S8: 52.409164 | T8: 54.918392 | U8: 57.547756 | V8: 60.303007 | W8: 60.188911 | X8: 62.13236 | Y8: 64.138561 | Z8: 66.20954 | AA8: markets/nand/dist/20261025_NAND市場模型_v0.1.xlsx｜Mkt!C96:Z96
A9: SanDisk 位元（情境 C） | B9: EB | C9: 31.287396 | D9: 29.615294 | E9: 31.15528 | F9: 33.514723 | G9: 38.069333 | H9: 33.617215 | I9: 34.400604 | J9: 36.079657 | K9: 37.71371 | L9: 39.877393 | M9: 42.16521 | N9: 44.584281 | O9: 40.365784 | P9: 40.463604 | Q9: 40.561662 | R9: 40.659956 | S9: 43.199319 | T9: 44.770157 | U9: 46.398115 | V9: 48.085269 | W9: 47.884748 | X9: 49.324107 | Y9: 50.806731 | Z9: 52.333922 | AA9: markets/nand/dist/20261025_NAND市場模型_v0.1.xlsx｜Mkt!C144:Z144
A10: Kioxia＋SanDisk 合資群份額（情境 A） | B10: % | C10: 0.27907731 | D10: 0.25560769 | E10: 0.27406433 | F10: 0.2689697 | G10: 0.27096015 | H10: 0.25018083 | I10: 0.26205287 | J10: 0.26205287 | K10: 0.26205287 | L10: 0.26205287 | M10: 0.26205287 | N10: 0.26205287 | O10: 0.26205287 | P10: 0.26205287 | Q10: 0.26205287 | R10: 0.26205287 | S10: 0.26205287 | T10: 0.26205287 | U10: 0.26205287 | V10: 0.26205287 | W10: 0.26205287 | X10: 0.26205287 | Y10: 0.26205287 | Z10: 0.26205287 | AA10: markets/nand/dist/20261025_NAND市場模型_v0.1.xlsx｜Mkt!C46:Z46
A11: Kioxia＋SanDisk 合資群份額（情境 B） | B11: % | C11: 0.27907731 | D11: 0.25560769 | E11: 0.27406433 | F11: 0.2689697 | G11: 0.27096015 | H11: 0.25018083 | I11: 0.26205287 | J11: 0.26205287 | K11: 0.25905287 | L11: 0.25905287 | M11: 0.25905287 | N11: 0.25905287 | O11: 0.25605287 | P11: 0.25605287 | Q11: 0.25605287 | R11: 0.25605287 | S11: 0.25305287 | T11: 0.25305287 | U11: 0.25305287 | V11: 0.25305287 | W11: 0.25005287 | X11: 0.25005287 | Y11: 0.25005287 | Z11: 0.25005287 | AA11: markets/nand/dist/20261025_NAND市場模型_v0.1.xlsx｜Mkt!C94:Z94
A12: Kioxia＋SanDisk 合資群份額（情境 C） | B12: % | C12: 0.27907731 | D12: 0.25560769 | E12: 0.27406433 | F12: 0.2689697 | G12: 0.27096015 | H12: 0.25018083 | I12: 0.26205287 | J12: 0.26205287 | K12: 0.25605287 | L12: 0.25605287 | M12: 0.25605287 | N12: 0.25605287 | O12: 0.25005287 | P12: 0.25005287 | Q12: 0.25005287 | R12: 0.25005287 | S12: 0.24405287 | T12: 0.24405287 | U12: 0.24405287 | V12: 0.24405287 | W12: 0.23805287 | X12: 0.23805287 | Y12: 0.23805287 | Z12: 0.23805287 | AA12: markets/nand/dist/20261025_NAND市場模型_v0.1.xlsx｜Mkt!C142:Z142

Sheet PL
A1: PL — SanDisk 損益（$B；FY2026 實績；FY2027–FY2029 由市場層 markets/nand 驅動；FY2030–FY2032 收斂法見底部）。頂端摘要，下方三情境各一個完整推導區塊
A3: 情境／項目 | B3: 單位 | C3: FY2025A | D3: FY2026A | E3: FY2027 | F3: FY2028 | G3: FY2029 | H3: 說明
A4: 情境 A（順利）
A5: 營收 | B5: $B | C5: =C55 -> 7.355 | D5: =D55 -> 20.248 | E5: =E55 -> 53.023012 | F5: =F55 -> 60.304259 | G5: =G55 -> 61.403984
A6: 毛利率 | B6: % | D6: =D57 -> 0.71496933 | E6: =E57 -> 0.86916237 | F6: =F57 -> 0.87586847 | G6: =G57 -> 0.87030465
A7: 營業利益 | B7: $B | D7: =D59 -> 12.389 | E7: =E59 -> 43.529557 | F7: =F59 -> 49.987154 | G7: =G59 -> 50.37489
A8: 營業利益率 | B8: % | D8: =D60 -> 0.6118629 | E8: =E60 -> 0.82095594 | F8: =F60 -> 0.82891582 | G8: =G60 -> 0.82038472
A9: 淨利 | B9: $B | C9: =C61 -> -1.641 | D9: =D61 -> 11.433 | E9: =E61 -> 37.162031 | F9: =F61 -> 43.23138 | G9: =G61 -> 44.237099
A10: EPS | B10: USD | C10: =C69 -> -11.32 | D10: =D69 -> 73.76 | E10: =E69 -> 263.16538 | F10: =F69 -> 345.44029 | G10: =G69 -> 406.94244
A11: 每股淨值 | B11: USD | D11: =D70 -> 107.47166 | E11: =E70 -> 270.12928 | F11: =F70 -> 507.6196 | G11: =G70 -> 829.48648
A12: 自由現金流 | B12: $B | D12: =D64 -> 11.031 | E12: =E64 -> 34.14065 | F12: =F64 -> 39.773124 | G12: =G64 -> 40.71286
A14: 情境 B（平平）
A15: 營收 | B15: $B | C15: =C91 -> 7.355 | D15: =D91 -> 20.248 | E15: =E91 -> 53.55663 | F15: =F91 -> 42.831169 | G15: =G91 -> 22.970548
A16: 毛利率 | B16: % | D16: =D93 -> 0.71496933 | E16: =E93 -> 0.87009133 | F16: =F93 -> 0.82809326 | G16: =G93 -> 0.67696637
A17: 營業利益 | B17: $B | D17: =D95 -> 12.389 | E17: =E95 -> 44.037773 | F17: =F95 -> 32.811488 | G17: =G95 -> 12.869341
A18: 營業利益率 | B18: % | D18: =D96 -> 0.6118629 | E18: =E96 -> 0.82226557 | F18: =F96 -> 0.76606567 | G18: =G96 -> 0.56025396
A19: 淨利 | B19: $B | C19: =C97 -> -1.641 | D19: =D97 -> 11.433 | E19: =E97 -> 37.594015 | F19: =F97 -> 28.638863 | G19: =G97 -> 12.133931
A20: EPS | B20: USD | C20: =C105 -> -11.32 | D20: =D105 -> 73.76 | E20: =E105 -> 266.52938 | F20: =F105 -> 219.527 | G20: =G105 -> 96.26388
A21: 每股淨值 | B21: USD | D21: =D106 -> 107.47166 | E21: =E106 -> 272.21001 | F21: =F106 -> 423.24652 | G21: =G106 -> 495.96348
A22: 自由現金流 | B22: $B | D22: =D100 -> 11.031 | E22: =E100 -> 34.540617 | F22: =F100 -> 26.228993 | G22: =G100 -> 10.915698
A24: 情境 C（不如預期）
A25: 營收 | B25: $B | C25: =C127 -> 7.355 | D25: =D127 -> 20.248 | E25: =E127 -> 53.209139 | F25: =F127 -> 39.074356 | G25: =G127 -> 12.789488
A26: 毛利率 | B26: % | D26: =D129 -> 0.71496933 | E26: =E129 -> 0.86889852 | F26: =F129 -> 0.81773371 | G26: =G129 -> 0.49496873
A27: 營業利益 | B27: $B | D27: =D131 -> 12.389 | E27: =E131 -> 43.675431 | F27: =F131 -> 29.333273 | G27: =G131 -> 3.7512594
A28: 營業利益率 | B28: % | D28: =D132 -> 0.6118629 | E28: =E132 -> 0.82082574 | F28: =F132 -> 0.75070392 | G28: =G132 -> 0.29330801
A29: 淨利 | B29: $B | C29: =C133 -> -1.641 | D29: =D133 -> 11.433 | E29: =E133 -> 37.286024 | F29: =F133 -> 25.677499 | G29: =G133 -> 4.3321693
A30: EPS | B30: USD | C30: =C141 -> -11.32 | D30: =D141 -> 73.76 | E30: =E141 -> 264.12867 | F30: =F141 -> 195.0021 | G30: =G141 -> 33.279902
A31: 每股淨值 | B31: USD | D31: =D142 -> 107.47166 | E31: =E142 -> 270.73182 | F31: =F142 -> 404.76889 | G31: =G142 -> 430.08823
A32: 自由現金流 | B32: $B | D32: =D136 -> 11.031 | E32: =E136 -> 34.253476 | F32: =F136 -> 23.493038 | G32: =G136 -> 3.7247999
A34: 核對：三情境 FY2026 − 實績（應為 0） | D34: =D73+D109+D145 -> 0
A40: 情境 A（順利）：markets/nand 情境 A（價格路徑 A、2028–29 顆數係數 A、合資群份額 A）；每位元成本年降 cd_A
A41: A. 季度 | B41: 單位 | C41: FQ1 FY26（2025Q3） | D41: FQ2 FY26（2025Q4） | E41: FQ3 FY26（2026Q1） | F41: FQ4 FY26（2026Q2） | G41: FQ1 FY27（2026Q3） | H41: FQ2 FY27（2026Q4） | I41: FQ3 FY27（2027Q1） | J41: FQ4 FY27（2027Q2） | K41: FQ1 FY28（2027Q3） | L41: FQ2 FY28（2027Q4） | M41: FQ3 FY28（2028Q1） | N41: FQ4 FY28（2028Q2） | O41: FQ1 FY29（2028Q3） | P41: FQ2 FY29（2028Q4） | Q41: FQ3 FY29（2029Q1） | R41: FQ4 FY29（2029Q2） | T41: 說明
A42: 市場層營收（TrendForce 口徑，同字母情境） | B42: $B | C42: =Units!E4*1 -> 2.31 | D42: =Units!F4*1 -> 3.03 | E42: =Units!G4*1 -> 5.95 | F42: =Units!H4*1 -> 8.97 | G42: =Units!I4*1 -> 10.555884 | H42: =Units!J4*1*1 -> 13.008548 | I42: =Units!K4*1*1 -> 14.333827 | J42: =Units!L4*1*1 -> 15.156177 | K42: =Units!M4*1*1 -> 15.224421 | L42: =Units!N4*1*1 -> 14.971015 | M42: =Units!O4*1*1 -> 15.038425 | N42: =Units!P4*1*1 -> 15.106138 | O42: =Units!Q4*1*1 -> 15.174156 | ... R42: =Units!T4*1*1 -> 15.654084 | T42: markets/nand；Sens 可乘份額係數、價格係數（FQ2 FY27 起）
A43: 位元（市場層；同字母） | B43: EB | C43: =Units!E7*1 -> 31.15528 | D43: =Units!F7*1 -> 33.514723 | E43: =Units!G7*1 -> 38.069333 | F43: =Units!H7*1 -> 33.617215 | G43: =Units!I7*1 -> 34.400604 | H43: =Units!J7*1 -> 36.079657 | I43: =Units!K7*1 -> 38.597443 | J43: =Units!L7*1 -> 40.811827 | ... R43: =Units!T7*1 -> 62.255767
A44: 營收 | B44: $B | C44: =q1_rev -> 2.308 | D44: =q2_rev -> 3.025 | E44: =q3_rev -> 5.95 | F44: =q4_rev -> 8.965 | G44: =G42*sd_k -> 10.549632 | H44: =H42*sd_k -> 13.000843 | I44: =I42*sd_k -> 14.325337 | J44: =J42*sd_k -> 15.1472 | K44: =K42*sd_k -> 15.215403 | L44: =L42*sd_k -> 14.962147 | M44: =M42*sd_k -> 15.029517 | N44: =N42*sd_k -> 15.097191 | ... R44: =R42*sd_k -> 15.644812 | T44: 實績季＝公司財報；之後＝市場層 × 公司口徑係數
A45: 每 EB 營業成本（FQ1 FY27 以指引毛利率校準，之後每年 × (1 − 成本年降)） | B45: $B/EB | C45: =C46/C43 -> 0.052004539 | D45: =D46/D43 -> 0.04431709 | E45: =E46/E43 -> 0.033759457 | F45: =F46/F43 -> 0.041068541 | G45: =(1-g_gm)*G44/G43 -> 0.049067194 | H45: =$G45*(1-cd_A)^(1/4) -> 0.047251525 | I45: =$G45*(1-cd_A)^(2/4) -> 0.045503043 | J45: =$G45*(1-cd_A)^(3/4) -> 0.043819262 | K45: =$G45*(1-cd_A)^(4/4) -> 0.042197787 | L45: =$G45*(1-cd_A)^(5/4) -> 0.040636312 | M45: =$G45*(1-cd_A)^(6/4) -> 0.039132617 | N45: =$G45*(1-cd_A)^(7/4) -> 0.037684565 | O45: =$G45*(1-cd_A)^(8/4) -> 0.036290096 | P45: =$G45*(1-cd_A)^(9/4) -> 0.034947228 | Q45: =$G45*(1-cd_A)^(10/4) -> 0.033654051 | R45: =$G45*(1-cd_A)^(11/4) -> 0.032408726
A46: 營業成本 | B46: $B | C46: =q1_rev*(1-q1_gm) -> 1.620216 | D46: =q2_rev*(1-q2_gm) -> 1.485275 | E46: =q3_rev*(1-q3_gm) -> 1.2852 | F46: =q4_rev*(1-q4_gm) -> 1.38061 | G46: =G43*G45 -> 1.6879411 | H46: =H43*H45 -> 1.7048188 | I46: =I43*I45 -> 1.7563011 | J46: =J43*J45 -> 1.7883441 | K46: =K43*K45 -> 1.8209718 | L46: =L43*L45 -> 1.8541947 | M46: =M43*M45 -> 1.8880237 | N46: =N43*N45 -> 1.9224699 | ... R46: =R43*R45 -> 2.0176301
A47: 毛利率 | B47: % | C47: =1-C46/C44 -> 0.298 | D47: =1-D46/D44 -> 0.509 | E47: =1-E46/E44 -> 0.784 | F47: =1-F46/F44 -> 0.846 | G47: =1-G46/G44 -> 0.84 | H47: =1-H46/H44 -> 0.86886859 | I47: =1-I46/I44 -> 0.87739897 | J47: =1-J46/J44 -> 0.88193566 | ... R47: =1-R46/R44 -> 0.8710352
A48: 營業費用 | B48: $B | C48: =q1_rev-q1_rev*(1-q1_gm)-q1_op -> 0.511784 | D48: =q2_rev-q2_rev*(1-q2_gm)-q2_op -> 0.474725 | E48: =q3_rev-q3_rev*(1-q3_gm)-q3_op -> 0.5538 | F48: =q4_rev-q4_rev*(1-q4_gm)-q4_op -> 0.54739 | G48: =(g_ox-ox_var*g_rev)*(1+ox_g)^(0/4)+ox_var*G44 -> 0.59399632 | H48: =(g_ox-ox_var*g_rev)*(1+ox_g)^(1/4)+ox_var*H44 -> 0.63028797 | I48: =(g_ox-ox_var*g_rev)*(1+ox_g)^(2/4)+ox_var*I44 -> 0.6555965 | J48: =(g_ox-ox_var*g_rev)*(1+ox_g)^(3/4)+ox_var*J44 -> 0.67616961 | K48: =(g_ox-ox_var*g_rev)*(1+ox_g)^(4/4)+ox_var*K44 -> 0.68950403 | L48: =(g_ox-ox_var*g_rev)*(1+ox_g)^(5/4)+ox_var*L44 -> 0.69992896 | M48: =(g_ox-ox_var*g_rev)*(1+ox_g)^(6/4)+ox_var*M44 -> 0.71387261 | N48: =(g_ox-ox_var*g_rev)*(1+ox_g)^(7/4)+ox_var*N44 -> 0.72813927 | O48: =(g_ox-ox_var*g_rev)*(1+ox_g)^(8/4)+ox_var*O44 -> 0.74273669 | P48: =(g_ox-ox_var*g_rev)*(1+ox_g)^(9/4)+ox_var*P44 -> 0.75767277 | Q48: =(g_ox-ox_var*g_rev)*(1+ox_g)^(10/4)+ox_var*Q44 -> 0.77354068 | R48: =(g_ox-ox_var*g_rev)*(1+ox_g)^(11/4)+ox_var*R44 -> 0.79133223 | T48: 固定部分以 FQ1 FY27 指引營業費用校準（Derived）
A49: 營業利益 | B49: $B | C49: =C44-C46-C48 -> 0.176 | D49: =D44-D46-D48 -> 1.065 | E49: =E44-E46-E48 -> 4.111 | F49: =F44-F46-F48 -> 7.037 | G49: =G44-G46-G48 -> 8.2676943 | H49: =H44-H46-H48 -> 10.665736 | I49: =I44-I46-I48 -> 11.91344 | J49: =J44-J46-J48 -> 12.682686 | ... R49: =R44-R46-R48 -> 12.83585
...

Sheet Val
A1: Val — 估值。第 0 節為目標價（DCF 與 Comparable 加權；Comparable 依記憶體慣例用前瞻 P/B）；第 5–6 節為目前倍數、十年倍數與規則值（舊法參考）
A2: SanDisk 2025-02 自 WDC 分拆上市，無十年自身倍數歷史：十年 P/B、P/E 以美光（同為記憶體循環股）為 Analogy，見第 6 節
A4: 0. 目標價
A5: 0.1 DCF（股東權益現金流，FY2027–FY2032 明確期＋FY2032 後永續）
A6: 項目 | B6: A（順利） | C6: B（平平） | D6: C（不如預期） | E6: 說明
A7: 情境 EPS（FY2027–FY2032） | E7: PL 頁延伸區塊；FY2030 起為收斂法（灰底）
A8: FY2027 | B8: =PL!D156 -> 263.16538 | C8: =PL!D163 -> 266.52938 | D8: =PL!D170 -> 264.12867
A9: FY2028 | B9: =PL!E156 -> 345.44029 | C9: =PL!E163 -> 219.527 | D9: =PL!E170 -> 195.0021
A10: FY2029 | B10: =PL!F156 -> 406.94244 | C10: =PL!F163 -> 96.26388 | D10: =PL!F170 -> 33.279902
A11: FY2030 | B11: =PL!G156 -> 314.21453 | C11: =PL!G163 -> 51.465201 | D11: =PL!G170 -> 14.529168
A12: FY2031 | B12: =PL!H156 -> 218.00319 | C12: =PL!H163 -> 30.646596 | D12: =PL!H170 -> 8.2707856
A13: FY2032 | B13: =PL!I156 -> 113.75203 | C13: =PL!I163 -> 17.066727 | D13: =PL!I170 -> 5.1780797
A14: 股東現金流＝EPS ×（1 − tp_g ÷ tp_roe） | E14: 記憶體資本密集：FY2027–FY2029 改用每股（淨利＋折舊－資本支出）＝ PL 區塊每股自由現金流（資本支出含合資群分攤）；收斂期（FY2030 起）用 EPS ×（1 − 再投資率）
A15: 再投資率（tp_g ÷ tp_roe，上限 0.8；FY2030 起用） | B15: =MIN(tp_g/tp_roe,0.8) -> 0.1458548 | E15: ROE 為 FY2025–FY2026 平均（In 頁 tp_roe）
A16: FY2027（淨利＋折舊－資本支出，每股） | B16: =PL!E72 -> 241.76927 | C16: =PL!E108 -> 244.88178 | D16: =PL!E144 -> 242.64655
A17: FY2028（淨利＋折舊－資本支出，每股） | B17: =PL!F72 -> 317.8071 | C17: =PL!F108 -> 201.0545 | D17: =PL!F144 -> 178.41269
A18: FY2029（淨利＋折舊－資本支出，每股） | B18: =PL!G72 -> 374.52253 | C18: =PL!G108 -> 86.599096 | D18: =PL!G144 -> 28.614066
A19: FY2030（EPS ×（1 − 再投資率）） | B19: =B11*(1-$B$15) -> 268.38483 | C19: =C11*(1-$B$15) -> 43.958754 | D19: =D11*(1-$B$15) -> 12.410019
A20: FY2031（EPS ×（1 − 再投資率）） | B20: =B12*(1-$B$15) -> 186.20638 | C20: =C12*(1-$B$15) -> 26.176643 | D20: =D12*(1-$B$15) -> 7.0644518
A21: FY2032（EPS ×（1 − 再投資率）） | B21: =B13*(1-$B$15) -> 97.160752 | C21: =C13*(1-$B$15) -> 14.577463 | D21: =D13*(1-$B$15) -> 4.422832
A22: DCF 情境每股價值（折現率 tp_r） | B22: =MAX(0,SUMPRODUCT(B16:B21,1/(1+tp_r)^{1;2;3;4;5;6})+B21*(1+tp_g)/(tp_r-tp_g)/(1+tp_r)^6) -> 2068.2414 | C22: =MAX(0,SUMPRODUCT(C16:C21,1/(1+tp_r)^{1;2;3;4;5;6})+C21*(1+tp_g)/(tp_r-tp_g)/(1+tp_r)^6) -> 650.97941 | D22: =MAX(0,SUMPRODUCT(D16:D21,1/(1+tp_r)^{1;2;3;4;5;6})+D21*(1+tp_g)/(tp_r-tp_g)/(1+tp_r)^6) -> 448.16764 | E22: Σ 明確期現金流 ÷ (1＋r)^t ＋ 永續價值 ÷ (1＋r)^6；永續價值＝FY2032 現金流 ×(1＋g)÷(r−g)；基準日 2026 年底，t＝1 對 FY2027（FY2027 於 2027-06 結束，t 以會計年度計，略低估）；負值取 0（股東有限責任）
A23: DCF 情境價值推到 12 個月後（×(1＋tp_r)） | B23: =B22*(1+tp_r) -> 2275.0655 | C23: =C22*(1+tp_r) -> 716.07735 | D23: =D22*(1+tp_r) -> 492.9844
A24: DCF 目標價（情境加權） | B24: =tp_wA*B23+tp_wB*C23+tp_wC*D23 -> 1139.1552 | E24: Σ 權重 × 情境價值 ×(1＋r)；權重見 In 頁 tp_wA／tp_wB／tp_wC
A26: 0.2 Comparable（市場主流同業前瞻 P/B；記憶體慣例）
A27: 同業與前瞻 P/B | B27: 代號 | C27: 前瞻 P/B | D27: 日期 | E27: 來源 | F27: 標記
A28: 美光 | B28: MU | C28: 3.35 | D28: 2026-10-23 | E28: MarketScreener：現價 ÷ FY2027E（2027-09）每股淨值（micron/ 模型同值） | F28: Interested-party
A29: SK 海力士 | B29: 000660.KS | C29: 1.35 | D29: 2026-10-23 | E29: MarketScreener：現價 ÷ 2027E 每股淨值（skhynix/ 模型同值） | F29: Interested-party
A30: 三星電子 | B30: 005930.KS | C30: 1.26 | D30: 2026-10-23 | E30: MarketScreener：現價 ÷ 2027E 每股淨值（samsung/ 模型同值） | F30: Interested-party
A31: Kioxia | B31: 285A.T | C31: =12755/7808 -> 1.6335809 | D31: 2026-10-23 | E31: 現價 ¥12,755（stockanalysis，分割後）÷ MarketScreener FY2028E（2028-03）每股淨值 ¥7,808 | F31: Interested-party
A32: 同業前瞻 P/B 中位數 | B32: =MEDIAN(C28:C31) -> 1.4917905 | E32: 記憶體同業（美光、SK 海力士、三星、Kioxia；無 A 股）。WDC（硬碟）不列入 P/B：僅有落後 P/B 13.5x（stockanalysis），與記憶體不可比；P/E 並列參考見下方。SanDisk 自身現價 ÷ 2027 年底每股淨值（FY27、FY28 共識平均）約 2.9x
A33: 12 個月後的前瞻每股淨值（情境加權） | B33: =tp_wA*(PL!F70+PL!G70)/2+tp_wB*(PL!F106+PL!G106)/2+tp_wC*(PL!F142+PL!G142)/2 -> 513.85413 | E33: 同業倍數＝現價 ÷ 約 14 個月後（約 2027 年底）每股淨值；對應 12 個月後（約 2027-10）用約 2028 年底每股淨值＝（FY2028 年底＋FY2029 年底）÷ 2（會計年度 6 月，依月份調整）
A34: Comparable 目標價 | B34: =B32*B33 -> 766.56269 | E34: 同業中位數 × 前瞻每股淨值
A35: 12 個月後的前瞻 EPS（情境加權） | B35: =tp_wA*(8/12*B9+4/12*B10)+tp_wB*(8/12*C9+4/12*C10)+tp_wC*(8/12*D9+4/12*D10) -> 227.22089 | E35: 約 2027-10 時的未來 12 月（2027-11～2028-10）≈ 8／12 × FY2028（2027-07～2028-06）＋4／12 × FY2029（會計年度 6 月，依月份調整）
A37: 並列參考：同業前瞻 P/E（不進目標價）
A38: 同業與前瞻 P/E | B38: 代號 | C38: 前瞻 P/E | D38: 日期 | E38: 來源 | F38: 標記
A39: 美光 | B39: MU | C39: =877.55/173 -> 5.0725434 | D39: 2026-10-23 | E39: 現價 877.55 ÷ MarketScreener FY2027 共識 EPS 173（micron/ 模型 In 頁） | F39: Interested-party
A40: SK 海力士 | B40: 000660.KS | C40: =1277000/475721 -> 2.6843465 | D40: 2026-10-23 | E40: 現價 ÷ MarketScreener 2027 共識 EPS（skhynix/ 模型 In 頁） | F40: Interested-party
A41: 三星電子 | B41: 005930.KS | C41: =215500/72279 -> 2.9815022 | D41: 2026-10-23 | E41: 現價 ÷ MarketScreener 2027 共識 EPS（samsung/ 模型 In 頁） | F41: Interested-party
A42: Kioxia | B42: 285A.T | C42: =12755/3486 -> 3.6589214 | D42: 2026-10-23 | E42: 現價 ¥12,755 ÷ MarketScreener FY2027（2027-03）共識 EPS ¥3,486 | F42: Interested-party
A43: Western Digital | B43: WDC | C43: 11.91 | D43: 2026-10-23 | E43: stockanalysis 統計頁 Forward P/E（硬碟為主，參考） | F43: Interested-party
...

Sheet Recon
A1: Recon — 本模型 vs 公司實績、指引與共識（共識只作對照，未用於校準）。差距＝模型 ÷ 對照 − 1（百分點列為相減）
A3: 項目 | B3: 對照值 | C3: 模型 A | D3: 差距 A | E3: 模型 B | F3: 差距 B | G3: 模型 C | H3: 差距 C | I3: 對照來源 | J3: 說明
A4: A. 實績與公司指引
A5: FY2026 營收（實績重現） | B5: =a26_rev -> 20.248 | C5: =PL!D5 -> 20.248 | D5: =C5/B5-1 -> 0 | E5: =PL!D15 -> 20.248 | F5: =E5/B5-1 -> 0 | G5: =PL!D25 -> 20.248 | H5: =G5/B5-1 -> 0 | I5: SanDisk FQ4 FY26 新聞稿（8-K，2026-08-05） | J5: 恆等式
A6: FQ1 FY27 營收 vs 公司指引中值 | B6: =g_rev -> 10.55 | C6: =PL!G44 -> 10.549632 | D6: =C6/B6-1 -> -3.4905955e-05 | E6: =PL!G80 -> 10.549632 | F6: =E6/B6-1 -> -3.4905955e-05 | G6: =PL!G116 -> 10.549632 | H6: =G6/B6-1 -> -3.4905955e-05 | I6: SanDisk FQ4 FY26 新聞稿（8-K，2026-08-05） | J6: 恆等式（市場層份額由指引推得）
A7: FQ1 FY27 毛利率 vs 指引中值（百分點） | B7: =g_gm -> 0.84 | C7: =PL!G47 -> 0.84 | D7: =C7-B7 -> 0 | E7: =PL!G83 -> 0.84 | F7: =E7-B7 -> 0 | G7: =PL!G119 -> 0.84 | H7: =G7-B7 -> 0 | I7: SanDisk FQ4 FY26 新聞稿（8-K，2026-08-05） | J7: 恆等式（單位成本以此校準）
A8: FQ1 FY27 EPS vs 指引中值（non-GAAP） | B8: =g_eps -> 45 | C8: =PL!G52 -> 45.600111 | D8: =C8/B8-1 -> 0.013335798 | E8: =PL!G88 -> 45.600111 | F8: =E8/B8-1 -> 0.013335798 | G8: =PL!G124 -> 45.600111 | H8: =G8/B8-1 -> 0.013335798 | I8: SanDisk FQ4 FY26 新聞稿（8-K，2026-08-05） | J8: 本模型為 GAAP 營業費用＋15% 稅率，近似 non-GAAP（差約 SBC）
A9: B. 共識（MarketScreener 2026-10-23；只作參考）
A10: FY2027 營收 vs 共識 | B10: =cons_rev27 -> 49.135 | C10: =PL!E5 -> 53.023012 | D10: =C10/B10-1 -> 0.079129178 | E10: =PL!E15 -> 53.55663 | F10: =E10/B10-1 -> 0.08998942 | G10: =PL!E25 -> 53.209139 | H10: =G10/B10-1 -> 0.082917257 | I10: MarketScreener 預估頁（2026-10-25 擷取；頁面為 10-23 收盤；會計年度 6 月）
A11: FY2028 營收 vs 共識 | B11: =cons_rev28 -> 58.436 | C11: =PL!F5 -> 60.304259 | D11: =C11/B11-1 -> 0.031971022 | E11: =PL!F15 -> 42.831169 | F11: =E11/B11-1 -> -0.2670414 | G11: =PL!F25 -> 39.074356 | H11: =G11/B11-1 -> -0.33133075 | I11: MarketScreener 預估頁（2026-10-25 擷取；頁面為 10-23 收盤；會計年度 6 月）
A12: FY2027 EPS vs 共識 | B12: =cons_eps27 -> 217.4 | C12: =PL!E10 -> 263.16538 | D12: =C12/B12-1 -> 0.21051231 | E12: =PL!E20 -> 266.52938 | F12: =E12/B12-1 -> 0.22598613 | G12: =PL!E30 -> 264.12867 | H12: =G12/B12-1 -> 0.2149433 | I12: MarketScreener 預估頁（2026-10-25 擷取；頁面為 10-23 收盤；會計年度 6 月） | J12: 差距超過 30% 見 README
A13: FY2028 EPS vs 共識 | B13: =cons_eps28 -> 267.6 | C13: =PL!F10 -> 345.44029 | D13: =C13/B13-1 -> 0.29088298 | E13: =PL!F20 -> 219.527 | F13: =E13/B13-1 -> -0.17964498 | G13: =PL!F30 -> 195.0021 | H13: =G13/B13-1 -> -0.2712926 | I13: MarketScreener 預估頁（2026-10-25 擷取；頁面為 10-23 收盤；會計年度 6 月）
A14: FY2028 年底每股淨值 vs 共識 | B14: =cons_bv28 -> 553.1 | C14: =PL!F11 -> 507.6196 | D14: =C14/B14-1 -> -0.082228162 | E14: =PL!F21 -> 423.24652 | F14: =E14/B14-1 -> -0.23477396 | G14: =PL!F31 -> 404.76889 | H14: =G14/B14-1 -> -0.26818136 | I14: MarketScreener 預估頁（2026-10-25 擷取；頁面為 10-23 收盤；會計年度 6 月）
A15: C. 市場層一致性
A16: SanDisk 營收 ÷ 市場層（公司口徑係數 sd_k） | C16: =sd_k -> 0.9994077 | I16: In 頁
A17: Kioxia＋SanDisk 合資群份額 CY2027（市場層 Ann 頁，A／B／C） | C17: 0.26205287 | E17: 0.25905287 | G17: 0.25605287 | I17: markets/nand/dist/20261025_NAND市場模型_v0.1.xlsx｜Ann!F27（kioxia/ 模型讀同一組列）

Sheet Sens
A1: Sens — 一次動一個輸入（情境 A）：對 FY2027、FY2028 營收與 EPS 的影響。每個案例為一個完整推導區塊（本頁下方，與 PL 同一引擎）
A3: 案例 | B3: 設定 | C3: FY2027 營收 $B | D3: FY2027 EPS | E3: 相對基準 | F3: FY2028 營收 $B | G3: FY2028 EPS | H3: 相對基準 | I3: FY2027 毛利率
A4: 基準（情境 A） | B4: PL 區塊 A | C4: =PL!E55 -> 53.023012 | D4: =PL!E69 -> 263.16538 | E4: =D4/D$4-1 -> 0 | F4: =PL!F55 -> 60.304259 | G4: =PL!F69 -> 345.44029 | H4: =G4/G$4-1 -> 0 | I4: =PL!E57 -> 0.86916237
A5: 市場層營收 −20%（價格；FQ2 FY27 起） | B5: 價格係數 0.8 | C5: =E75 -> 44.528336 | D5: =E89 -> 208.58416 | E5: =D5/D$4-1 -> -0.20740274 | F5: =F75 -> 48.243407 | G5: =F89 -> 250.37072 | H5: =G5/G$4-1 -> -0.27521272 | I5: =E77 -> 0.84420246
A6: 市場層營收 +20%（價格） | B6: 價格係數 1.2 | C6: =E125 -> 61.517688 | D6: =E139 -> 319.85932 | E6: =D6/D$4-1 -> 0.21543085 | F6: =F125 -> 72.36511 | G6: =F139 -> 450.98277 | H6: =G6/G$4-1 -> 0.30553032 | I6: =E127 -> 0.8872291
A7: 份額 ×0.9（營收與位元） | B7: 份額係數 0.9 | C7: =E175 -> 47.720711 | D7: =E189 -> 233.37193 | E7: =D7/D$4-1 -> -0.11321186 | F7: =F175 -> 54.273833 | G7: =F189 -> 301.99764 | H7: =G7/G$4-1 -> -0.12576022 | I7: =E177 -> 0.86916237
A8: 份額 ×1.1 | B8: 份額係數 1.1 | C8: =E225 -> 58.325313 | D8: =E239 -> 293.57072 | E8: =D8/D$4-1 -> 0.11553702 | F8: =F225 -> 66.334685 | G8: =F239 -> 391.09427 | H8: =G8/G$4-1 -> 0.13216174 | I8: =E227 -> 0.86916237
A9: 每位元成本年降 10%（C 的值） | B9: cd_C | C9: =E275 -> 53.023012 | D9: =E289 -> 262.35391 | E9: =D9/D$4-1 -> -0.0030834972 | F9: =F275 -> 60.304259 | G9: =F289 -> 341.55726 | H9: =G9/G$4-1 -> -0.011240803 | I9: =E277 -> 0.86686346
A10: 每位元成本年降 18% | B10: cd_A 高 | C10: =E325 -> 53.023012 | D10: =E339 -> 263.99311 | E10: =D10/D$4-1 -> 0.0031452904 | F10: =F325 -> 60.304259 | G10: =F339 -> 349.26301 | H10: =G10/G$4-1 -> 0.011066236 | I10: =E327 -> 0.87150595
A11: 指引毛利率 83.0%（校準） | B11: g_gm 低 | C11: =E375 -> 53.023012 | D11: =E389 -> 260.28112 | E11: =D11/D$4-1 -> -0.010959876 | F11: =F375 -> 60.304259 | G11: =F389 -> 341.36161 | H11: =G11/G$4-1 -> -0.011807172 | I11: =E377 -> 0.86098502
A12: 指引毛利率 84.9% | B12: g_gm 高 | C12: =E425 -> 53.023012 | D12: =E439 -> 265.76641 | E12: =D12/D$4-1 -> 0.0098836615 | F12: =F425 -> 60.304259 | G12: =F439 -> 349.12852 | H12: =G12/G$4-1 -> 0.0106769 | I12: =E427 -> 0.87652199
A13: 營業費用變動率 2% | B13: ox_var 高 | C13: =E475 -> 53.023012 | D13: =E489 -> 262.54809 | E13: =D13/D$4-1 -> -0.0023456237 | F13: =F475 -> 60.304259 | G13: =F489 -> 344.39833 | H13: =G13/G$4-1 -> -0.0030163168 | I13: =E477 -> 0.86916237
A14: 稅率 20% | B14: tax 高 | C14: =E525 -> 53.023012 | D14: =E539 -> 246.14616 | E14: =D14/D$4-1 -> -0.064671201 | F14: =F525 -> 60.304259 | G14: =F539 -> 319.92233 | H14: =G14/G$4-1 -> -0.073870804 | I14: =E527 -> 0.86916237
A15: 稅率 12% | B15: tax 低 | C15: =E575 -> 53.023012 | D15: =E589 -> 273.47944 | E15: =D15/D$4-1 -> 0.039192333 | F15: =F575 -> 60.304259 | G15: =F589 -> 361.15057 | H15: =G15/G$4-1 -> 0.04547903 | I15: =E577 -> 0.86916237
A16: 買回 ÷ FCF 80% | B16: payout 高 | C16: =E625 -> 53.023012 | D16: =E639 -> 279.54256 | E16: =D16/D$4-1 -> 0.062231514 | F16: =F625 -> 60.304259 | G16: =F639 -> 399.05092 | H16: =G16/G$4-1 -> 0.1551951 | I16: =E627 -> 0.86916237
A17: 買回 ÷ FCF 30% | B17: payout 低 | C17: =E675 -> 53.023012 | D17: =E689 -> 253.27326 | E17: =D17/D$4-1 -> -0.037588978 | F17: =F675 -> 60.304259 | G17: =F689 -> 317.17586 | H17: =G17/G$4-1 -> -0.081821438 | I17: =E677 -> 0.86916237
A18: 情境 B | B18: markets/nand B；成本年降 12% | C18: =PL!E91 -> 53.55663 | D18: =PL!E105 -> 266.52938 | E18: =D18/D$4-1 -> 0.012782865 | F18: =PL!F91 -> 42.831169 | G18: =PL!F105 -> 219.527 | H18: =G18/G$4-1 -> -0.36450087 | I18: =PL!E93 -> 0.87009133
A19: 情境 C | B19: markets/nand C；成本年降 10% | C19: =PL!E127 -> 53.209139 | D19: =PL!E141 -> 264.12867 | E19: =D19/D$4-1 -> 0.0036604206 | F19: =PL!F127 -> 39.074356 | G19: =PL!F141 -> 195.0021 | H19: =G19/G$4-1 -> -0.43549694 | I19: =PL!E129 -> 0.86889852
A21: 讀法：FQ1 FY27 營收由市場層等於公司指引（恆等式），價格係數只作用在 FQ2 FY27 起；毛利率校準改變單位成本起點，之後每年依成本年降。
A60: 案例區塊：市場層營收 −20%（價格；FQ2 FY27 起）（情境 A）
A61: A. 季度 | B61: 單位 | C61: FQ1 FY26（2025Q3） | D61: FQ2 FY26（2025Q4） | E61: FQ3 FY26（2026Q1） | F61: FQ4 FY26（2026Q2） | G61: FQ1 FY27（2026Q3） | H61: FQ2 FY27（2026Q4） | I61: FQ3 FY27（2027Q1） | J61: FQ4 FY27（2027Q2） | K61: FQ1 FY28（2027Q3） | L61: FQ2 FY28（2027Q4） | M61: FQ3 FY28（2028Q1） | N61: FQ4 FY28（2028Q2） | O61: FQ1 FY29（2028Q3） | P61: FQ2 FY29（2028Q4） | Q61: FQ3 FY29（2029Q1） | R61: FQ4 FY29（2029Q2） | T61: 說明
A62: 市場層營收（TrendForce 口徑，同字母情境） | B62: $B | C62: =Units!E4*1 -> 2.31 | D62: =Units!F4*1 -> 3.03 | E62: =Units!G4*1 -> 5.95 | F62: =Units!H4*1 -> 8.97 | G62: =Units!I4*1 -> 10.555884 | H62: =Units!J4*1*0.8 -> 10.406838 | I62: =Units!K4*1*0.8 -> 11.467062 | J62: =Units!L4*1*0.8 -> 12.124942 | K62: =Units!M4*1*0.8 -> 12.179537 | L62: =Units!N4*1*0.8 -> 11.976812 | M62: =Units!O4*1*0.8 -> 12.03074 | N62: =Units!P4*1*0.8 -> 12.08491 | O62: =Units!Q4*1*0.8 -> 12.139325 | ... R62: =Units!T4*1*0.8 -> 12.523267 | T62: markets/nand；Sens 可乘份額係數、價格係數（FQ2 FY27 起）
A63: 位元（市場層；同字母） | B63: EB | C63: =Units!E7*1 -> 31.15528 | D63: =Units!F7*1 -> 33.514723 | E63: =Units!G7*1 -> 38.069333 | F63: =Units!H7*1 -> 33.617215 | G63: =Units!I7*1 -> 34.400604 | H63: =Units!J7*1 -> 36.079657 | I63: =Units!K7*1 -> 38.597443 | J63: =Units!L7*1 -> 40.811827 | ... R63: =Units!T7*1 -> 62.255767
A64: 營收 | B64: $B | C64: =q1_rev -> 2.308 | D64: =q2_rev -> 3.025 | E64: =q3_rev -> 5.95 | F64: =q4_rev -> 8.965 | G64: =G62*sd_k -> 10.549632 | H64: =H62*sd_k -> 10.400674 | I64: =I62*sd_k -> 11.46027 | J64: =J62*sd_k -> 12.11776 | K64: =K62*sd_k -> 12.172323 | L64: =L62*sd_k -> 11.969718 | M64: =M62*sd_k -> 12.023614 | N64: =N62*sd_k -> 12.077753 | ... R64: =R62*sd_k -> 12.51585 | T64: 實績季＝公司財報；之後＝市場層 × 公司口徑係數
A65: 每 EB 營業成本（FQ1 FY27 以指引毛利率校準，之後每年 × (1 − 成本年降)） | B65: $B/EB | C65: =C66/C63 -> 0.052004539 | D65: =D66/D63 -> 0.04431709 | E65: =E66/E63 -> 0.033759457 | F65: =F66/F63 -> 0.041068541 | G65: =(1-g_gm)*G64/G63 -> 0.049067194 | H65: =$G65*(1-cd_A)^(1/4) -> 0.047251525 | I65: =$G65*(1-cd_A)^(2/4) -> 0.045503043 | J65: =$G65*(1-cd_A)^(3/4) -> 0.043819262 | K65: =$G65*(1-cd_A)^(4/4) -> 0.042197787 | L65: =$G65*(1-cd_A)^(5/4) -> 0.040636312 | M65: =$G65*(1-cd_A)^(6/4) -> 0.039132617 | N65: =$G65*(1-cd_A)^(7/4) -> 0.037684565 | O65: =$G65*(1-cd_A)^(8/4) -> 0.036290096 | P65: =$G65*(1-cd_A)^(9/4) -> 0.034947228 | Q65: =$G65*(1-cd_A)^(10/4) -> 0.033654051 | R65: =$G65*(1-cd_A)^(11/4) -> 0.032408726
A66: 營業成本 | B66: $B | C66: =q1_rev*(1-q1_gm) -> 1.620216 | D66: =q2_rev*(1-q2_gm) -> 1.485275 | E66: =q3_rev*(1-q3_gm) -> 1.2852 | F66: =q4_rev*(1-q4_gm) -> 1.38061 | G66: =G63*G65 -> 1.6879411 | H66: =H63*H65 -> 1.7048188 | I66: =I63*I65 -> 1.7563011 | J66: =J63*J65 -> 1.7883441 | K66: =K63*K65 -> 1.8209718 | L66: =L63*L65 -> 1.8541947 | M66: =M63*M65 -> 1.8880237 | N66: =N63*N65 -> 1.9224699 | ... R66: =R63*R65 -> 2.0176301
A67: 毛利率 | B67: % | C67: =1-C66/C64 -> 0.298 | D67: =1-D66/D64 -> 0.509 | E67: =1-E66/E64 -> 0.784 | F67: =1-F66/F64 -> 0.846 | G67: =1-G66/G64 -> 0.84 | H67: =1-H66/H64 -> 0.83608574 | I67: =1-I66/I64 -> 0.84674871 | J67: =1-J66/J64 -> 0.85241958 | ... R67: =1-R66/R64 -> 0.838794
A68: 營業費用 | B68: $B | C68: =q1_rev-q1_rev*(1-q1_gm)-q1_op -> 0.511784 | D68: =q2_rev-q2_rev*(1-q2_gm)-q2_op -> 0.474725 | E68: =q3_rev-q3_rev*(1-q3_gm)-q3_op -> 0.5538 | F68: =q4_rev-q4_rev*(1-q4_gm)-q4_op -> 0.54739 | G68: =(g_ox-ox_var*g_rev)*(1+ox_g)^(0/4)+ox_var*G64 -> 0.59399632 | H68: =(g_ox-ox_var*g_rev)*(1+ox_g)^(1/4)+ox_var*H64 -> 0.60428628 | I68: =(g_ox-ox_var*g_rev)*(1+ox_g)^(2/4)+ox_var*I64 -> 0.62694582 | J68: =(g_ox-ox_var*g_rev)*(1+ox_g)^(3/4)+ox_var*J64 -> 0.64587521 | K68: =(g_ox-ox_var*g_rev)*(1+ox_g)^(4/4)+ox_var*K64 -> 0.65907323 | L68: =(g_ox-ox_var*g_rev)*(1+ox_g)^(5/4)+ox_var*L64 -> 0.67000467 | M68: =(g_ox-ox_var*g_rev)*(1+ox_g)^(6/4)+ox_var*M64 -> 0.68381357 | N68: =(g_ox-ox_var*g_rev)*(1+ox_g)^(7/4)+ox_var*N64 -> 0.69794489 | O68: =(g_ox-ox_var*g_rev)*(1+ox_g)^(8/4)+ox_var*O64 -> 0.71240635 | P68: =(g_ox-ox_var*g_rev)*(1+ox_g)^(9/4)+ox_var*P64 -> 0.72720586 | Q68: =(g_ox-ox_var*g_rev)*(1+ox_g)^(10/4)+ox_var*Q64 -> 0.74281958 | R68: =(g_ox-ox_var*g_rev)*(1+ox_g)^(11/4)+ox_var*R64 -> 0.7600426 | T68: 固定部分以 FQ1 FY27 指引營業費用校準（Derived）
A69: 營業利益 | B69: $B | C69: =C64-C66-C68 -> 0.176 | D69: =D64-D66-D68 -> 1.065 | E69: =E64-E66-E68 -> 4.111 | F69: =F64-F66-F68 -> 7.037 | G69: =G64-G66-G68 -> 8.2676943 | H69: =H64-H66-H68 -> 8.0915692 | I69: =I64-I66-I68 -> 9.077023 | J69: =J64-J66-J68 -> 9.6835408 | ... R69: =R64-R66-R68 -> 9.7381772
A71: 淨利 | B71: $B | C71: =q1_ni -> 0.112 | D71: =q2_ni -> 0.803 | E71: =q3_ni -> 3.615 | F71: =q4_ni -> 6.903 | G71: =(G69+rf*$D87/4)*(1-tax) -> 7.0680172 | H71: =(H69+rf*$D87/4)*(1-tax) -> 6.9183108 | I71: =(I69+rf*$D87/4)*(1-tax) -> 7.7559466 | J71: =(J69+rf*$D87/4)*(1-tax) -> 8.2714867 | K71: =(K69+rf*$E87/4)*(1-tax) -> 8.3957969 | L71: =(L69+rf*$E87/4)*(1-tax) -> 8.1860514 | M71: =(M69+rf*$E87/4)*(1-tax) -> 8.1913708 | N71: =(N69+rf*$E87/4)*(1-tax) -> 8.1960978 | O71: =(O69+rf*$F87/4)*(1-tax) -> 8.3287148 | P71: =(P69+rf*$F87/4)*(1-tax) -> 8.332211 | Q71: =(Q69+rf*$F87/4)*(1-tax) -> 8.4035646 | R71: =(R69+rf*$F87/4)*(1-tax) -> 8.5633089 | T71: （營業利益＋上一年底淨現金 × 收益率 ÷ 4）×（1 − 稅率）
A72: 季 EPS（稀釋） | B72: USD | G72: =G71/(sh0+dil)*1000 -> 45.600111 | H72: =H71/(sh0+dil)*1000 -> 44.634263 | I72: =I71/(sh0+dil)*1000 -> 50.038365 | J72: =J71/(sh0+dil)*1000 -> 53.36443 | K72: =K71/(sh0+dil)*1000 -> 54.166431 | L72: =L71/(sh0+dil)*1000 -> 52.813235 | M72: =M71/(sh0+dil)*1000 -> 52.847554 | N72: =N71/(sh0+dil)*1000 -> 52.878051 | ... R72: =R71/(sh0+dil)*1000 -> 55.247154
A74: B. 年度（會計年度） | B74: 單位 | C74: FY2025A | D74: FY2026A | E74: FY2027 | F74: FY2028 | G74: FY2029 | T74: 說明
A75: 營收 | B75: $B | C75: =a25_rev -> 7.355 | D75: =SUM(C64:F64) -> 20.248 | E75: =SUM(G64:J64) -> 44.528336 | F75: =SUM(K64:N64) -> 48.243407 | G75: =SUM(O64:R64) -> 49.123187
A76: 營業成本 | B76: $B | D76: =SUM(C66:F66) -> 5.771301 | E76: =SUM(G66:J66) -> 6.9374052 | F76: =SUM(K66:N66) -> 7.4856601 | G76: =SUM(O66:R66) -> 7.9638115
A77: 毛利率 | B77: % | D77: =1-D76/D75 -> 0.71496933 | E77: =1-E76/E75 -> 0.84420246 | F77: =1-F76/F75 -> 0.84483558 | G77: =1-G76/G75 -> 0.83788081
A78: 營業費用 | B78: $B | D78: =SUM(C68:F68) -> 2.087699 | E78: =SUM(G68:J68) -> 2.4711036 | F78: =SUM(K68:N68) -> 2.7108364 | G78: =SUM(O68:R68) -> 2.9424744
A79: 營業利益 | B79: $B | D79: =SUM(C69:F69) -> 12.389 | E79: =SUM(G69:J69) -> 35.119827 | F79: =SUM(K69:N69) -> 38.046911 | G79: =SUM(O69:R69) -> 38.216901
A80: 營業利益率 | B80: % | D80: =D79/D75 -> 0.6118629 | E80: =E79/E75 -> 0.78870738 | F80: =F79/F75 -> 0.78864477 | G80: =G79/G75 -> 0.7779809
A81: 淨利 | B81: $B | C81: =a25_ni -> -1.641 | D81: =SUM(C71:F71) -> 11.433 | E81: =SUM(G71:J71) -> 30.013761 | F81: =SUM(K71:N71) -> 32.969317 | G81: =SUM(O71:R71) -> 33.627799
A82: 折舊攤銷（公司本身） | B82: $B | D82: =da_y -> 0.16 | E82: =da_y -> 0.16 | F82: =da_y -> 0.16 | G82: =da_y -> 0.16
...

Sheet Sources
A1: 來源
A2: SanDisk FQ4 FY26 新聞稿（8-K，2026-08-05） | B2: https://www.sec.gov/Archives/edgar/data/0002023554/000162828026053346/sndkq4-26ex991xpressrelease.htm
A3: SanDisk FQ2 FY26 新聞稿（8-K，2026-01-29） | B3: https://www.sec.gov/Archives/edgar/data/2023554/000162828026004121/sndkq2fy26ex991-pressrelea.htm
A4: SanDisk：FQ1 FY27 財報日 2026-10-29（2026-09-29 公告） | B4: https://investor.sandisk.com/news-releases/news-release-details/sandisk-report-first-quarter-fiscal-year-2027-results-october-29
A5: stockanalysis：歷史股價、統計、共識目標價 | B5: https://stockanalysis.com/stocks/sndk/forecast/
A6: MarketScreener：SanDisk 預估（EPS、每股淨值、股數） | B6: https://uk.marketscreener.com/quote/stock/SANDISK-CORPORATION-182801077/finances/
A7: MarketScreener：Kioxia 預估（同業 P/B、P/E） | B7: https://uk.marketscreener.com/quote/stock/KIOXIA-HOLDINGS-CORPORATI-180030735/finances/
A8: stockanalysis：WDC 統計（Forward P/E） | B8: https://stockanalysis.com/stocks/wdc/statistics/
A9: Motley Fool：SanDisk／Kioxia 日本投資、FY27 毛資本支出約營收 6%（2026-08-29） | B9: https://www.fool.com/investing/2026/08/29/sandisk-and-kioxia-plan-to-invest-more-than-usd31-billion-in-japanese-memory-plants-about-60-of-what-they-have-spent-there-in-25-years/
A10: 市場層：markets/nand/dist/20261025_NAND市場模型_v0.1.xlsx（markets/nand v0.1） | B10: 本 repo
A11: 美光十年倍數與淨利率（Analogy）：micron/dist/20261025_美光模型_v0.4.xlsx | B11: 本 repo
A12: SemiAnalysis | B12: 未使用
