Workbook

Sheet README
A1: Applied Materials（AMAT）收支與估值模型 v0.2（AI 半導體 Project 步驟 5：設備與材料） 2026-10-25
A2: 模型命題：AMAT 的營收約四分之三來自半導體系統，跟著晶圓廠設備支出走；成長集中在先進代工邏輯、DRAM／HBM 與先進封裝，中國約占三成。股價取決於 2028 年設備支出會不會見頂，以及出口管制會不會再收緊。
A4: 會計年度：約 11 月到隔年 10 月底（52／53 週；FY2026＝2025-10-27～2026-10-25）。FY(t) 有 10/12 落在日曆年 t：日曆年轉會計年度用 FY(t)＝2/12×CY(t−1)＋10/12×CY(t)；循環位置把 FY(t) 直接對照日曆年 t。FY2026 已結束但第四季尚未公布（預定 2026-11-12），本版 FY2026＝前三季實績＋第四季公司指引（錨點）。金額為百萬美元；EPS 為 non-GAAP 稀釋（與指引、共識同口徑）。
A6: 驅動因子 → 推導量
A7: 半導體系統＝FY2026 錨點 × Σ（FY2026 終端市場權重 × 各終端市場設備支出的會計年度指數）× 份額係數。設備支出讀 markets/equipment 的三情境（晶圓代工邏輯＝先進邏輯＋其他代工邏輯＋其他前段；DRAM 含 HBM；NAND）。
A8: AGS 服務、其他（含顯示器）：前一年 × 成長率（A 取公司長期 mid-teens）。出口管制：情境 C 假設 BIS 關係企業規則在暫停期（至 2026-11-09）後恢復，每年少 US$600M（公司 2025-09 估計）。
A9: 毛利率：營業成本＝固定＋變動 × 營收；營業費用＝固定＋變動 × 營收（兩者都用 FY2025 實績與 FY2026 錨點兩點推導）；淨利＝營業利益 × FY2025 的 non-GAAP 淨利 ÷ 營業利益。不寫死利益率。
A10: Val：P/E 規則——10 年（2016–2025 年底）non-GAAP P/E 分位，見頂年 25 分位、中段中位數、谷底 75 分位；循環位置依設備股共用規則（各情境見頂年度讀設備市場模型：A 2029、B 2028、C 2027 → FY2027：A 中段、B 中段、C 見頂）。本版未做先驗，無 Andy 合理 P/E 對照。Recon：共識、第四季年化、SEMI、公司說法。Sens：份額、終端權重、會計年度權重、成本與費用的固定／變動拆分、AGS、出口管制、中國
A12: 標記：Verified、Interested-party、Analogy、Assumed、Derived。SemiAnalysis 未使用。
A13: 已知限制：(1) 半導體系統只用終端市場設備指數 × 份額係數，份額變化（環繞式閘極、背面供電、先進封裝、中國國產替代）只在 Sens；(2) FY2025 Q4 的重編分部由 FY2026 Q4 指引年增率（整數百分比）反推；(3) 毛利率與營業費用只有兩點；(4) 第四季終端市場組合、股數為 Assumed；(5) 中國約三成營收，出口管制只以單一金額（公司 2025-09 估計）建模；(6) 設備市場模型 2026 年以後高於 SEMI 約 7–10%，本模型只用成長指數；(7) FY2028 共識未找到。
A14: v0.2（2026-10-25）估值 v2：Val 頁新增「0. 目標價」（放在既有內容之後，不位移既有列）＝0.5 × DCF 目標價（股東現金流＝EPS ×（1 − g／ROE），FY2027–32 明確期＋永續，r 10%、g 4%，情境權重 A 0.3／B 0.5／C 0.2）＋0.5 × Comparable 目標價（同業前瞻 P/E 中位數 × 12 個月後前瞻 EPS）；另列 Comparable 單獨目標價、市場共識目標價與差距拆解、歷史分位檢查。原「0. 目標價與上檔空間」改名「舊法：規則值情境加權（參考）」，不再叫目標價。
A15: 預估期間延伸到 FY2032：FY2027–FY2029 由驅動因子推導；FY2030 起為收斂法，非驅動因子推導（PL 頁底部延伸區塊，灰底）。情境對應：A＝順利、B＝平平、C＝不如預期（原為顆數情境）。本版未做先驗，無 Andy 合理 P/E 對照。

Sheet In
A1: In — 輸入（藍字；基準欄 E，低 D、高 F）。金額：百萬美元（US$M），市場為十億美元（US$B）。每個輸入附兩個來源（來源2 找不到者寫「未找到」）；公司原文算一個
A2: 標記：Verified／Interested-party／Analogy／Assumed／Derived；Analogy、Assumed 給低／高區間。SemiAnalysis 未使用。公司新聞稿與 SEC 8-K 附件以網頁擷取工具讀取（同一份文件的兩個轉載不算兩個獨立來源）
A3: 鍵 | B3: 項目 | C3: 單位 | D3: 低 | E3: 基準 | F3: 高 | G3: 標記 | H3: 來源1 | I3: 來源2／說明
A4: A. 晶圓廠設備市場（日曆年，US$B；讀 markets/equipment 成品，三情境；唯讀，不自行重估）
A5: laA_25 | B5: 先進邏輯設備 CY2025（A） | C5: US$B | E5: 36.032336 | G5: Derived | H5: markets/equipment/dist/20261023_半導體設備市場模型_v0.1.3.xlsx｜Mkt!C120:G120 | I5: markets/equipment Mkt 第 5 節（公司資本支出 × 設備占比，2025 以 SEMI 實績校準）；2028–29 隨情境係數
A6: laA_26 | B6: 先進邏輯設備 CY2026（A） | C6: US$B | E6: 50.324843 | G6: Derived | H6: 同上
A7: laA_27 | B7: 先進邏輯設備 CY2027（A） | C7: US$B | E7: 60.776431 | G7: Derived | H7: 同上
A8: laA_28 | B8: 先進邏輯設備 CY2028（A） | C8: US$B | E8: 70.016145 | G8: Derived | H8: 同上
A9: laA_29 | B9: 先進邏輯設備 CY2029（A） | C9: US$B | E9: 74.209437 | G9: Derived | H9: 同上
A10: loA_25 | B10: 其他代工與邏輯設備 CY2025（A） | C10: US$B | E10: 29.569009 | G10: Derived | H10: markets/equipment/dist/20261023_半導體設備市場模型_v0.1.3.xlsx｜Mkt!C121:G121
A11: loA_26 | B11: 其他代工與邏輯設備 CY2026（A） | C11: US$B | E11: 31.93453 | G11: Derived | H11: 同上
A12: loA_27 | B12: 其他代工與邏輯設備 CY2027（A） | C12: US$B | E12: 34.489292 | G12: Derived | H12: 同上
A13: loA_28 | B13: 其他代工與邏輯設備 CY2028（A） | C13: US$B | E13: 37.248436 | G13: Derived | H13: 同上
A14: loA_29 | B14: 其他代工與邏輯設備 CY2029（A） | C14: US$B | E14: 40.228311 | G14: Derived | H14: 同上
A15: ofA_25 | B15: 其他前段設備（類比、功率、光罩、廠務等） CY2025（A） | C15: US$B | E15: 12.746775 | G15: Derived | H15: markets/equipment/dist/20261023_半導體設備市場模型_v0.1.3.xlsx｜Mkt!C124:G124
A16: ofA_26 | B16: 其他前段設備（類比、功率、光罩、廠務等） CY2026（A） | C16: US$B | E16: 17.027825 | G16: Derived | H16: 同上
A17: ofA_27 | B17: 其他前段設備（類比、功率、光罩、廠務等） CY2027（A） | C17: US$B | E17: 21.022986 | G17: Derived | H17: 同上
... A79: ndC_29 | B79: NAND 設備 CY2029（C） | C79: US$B | E79: 18.598422 | G79: Derived | H79: 同上
A80: fyw | B80: 會計年度落在前一個日曆年的比例（FY(t)＝fyw×CY(t−1)＋(1−fyw)×CY(t)） | C80: % | D80: 0.083333333 | E80: 0.16666667 | F80: 0.25 | G80: Derived | H80: 公司會計年度結束於 10 月最後一個星期日（FY2026：2025-10-27～2026-10-25），約 11–12 月兩個月落在前一年 → 2/12 | I80: 低 1/12、高 3/12（Assumed）：設備出貨與客戶資本支出約差一季，高值等於把市場往前移一季
A81: semi_wfe26 | B81: SEMI 晶圓前段設備（WFE） CY2026（對帳用） | C81: US$B | E81: 143.9 | G81: Interested-party | H81: markets/equipment/dist/20261023_半導體設備市場模型_v0.1.3.xlsx｜Mkt!C44:G44 | I81: SEMI 2026-07 年中預測（設備商協會，傾向樂觀）；只用於 Recon
A82: semi_fl26 | B82: SEMI 代工與邏輯設備 CY2026（對帳用） | C82: US$B | E82: 78 | G82: Interested-party | H82: markets/equipment/dist/20261023_半導體設備市場模型_v0.1.3.xlsx｜Mkt!C43:G43 | I82: SEMI 2026-07 年中預測（設備商協會，傾向樂觀）；只用於 Recon
A83: semi_dr26 | B83: SEMI DRAM 設備 CY2026（對帳用） | C83: US$B | E83: 38.8 | G83: Interested-party | H83: markets/equipment/dist/20261023_半導體設備市場模型_v0.1.3.xlsx｜Mkt!C41:G41 | I83: SEMI 2026-07 年中預測（設備商協會，傾向樂觀）；只用於 Recon
A84: semi_nd26 | B84: SEMI NAND 設備 CY2026（對帳用） | C84: US$B | E84: 13.9 | G84: Interested-party | H84: markets/equipment/dist/20261023_半導體設備市場模型_v0.1.3.xlsx｜Mkt!C42:G42 | I84: SEMI 2026-07 年中預測（設備商協會，傾向樂觀）；只用於 Recon
A85: ai_inc27 | B85: 設備市場模型：AI 相關設備占 2025→2027 增量（情境 A） | C85: % | E85: 0.62686064 | G85: Derived | H85: markets/equipment/dist/20261023_半導體設備市場模型_v0.1.3.xlsx｜Mkt!C10:G10（情境 A） | I85: 先進邏輯＋DRAM／HBM＋先進封裝；只用於 Recon
A86: co_ai27 | B86: 公司說法：先進代工邏輯、DRAM、先進封裝占 CY2026–27 晶圓廠設備成長約 80% | C86: % | E86: 0.8 | G86: Interested-party | H86: AMAT Q3 FY26 法說（2026-08-13；MarketBeat 法說重點） | I86: Nasdaq 法說重點（可能同一來源轉載）；只用於 Recon
A87: B. 半導體系統（Semiconductor Systems）：FY2026 錨點 × 各終端市場設備指數 × 份額係數
A88: q4_dr | B88: FY2026 第四季半導體系統中 DRAM 占比（公司未給） | C88: % | D88: 0.26 | E88: 0.3 | F88: 0.34 | G88: Assumed | H88: 公司：DRAM 營收 2H CY2026「very significant increase」（Q3 FY26 法說，MarketBeat）；Q3 26%、Q1 34% | I88: 低＝Q3 的 26%、高＝Q1 的 34%
A89: q4_nd | B89: FY2026 第四季半導體系統中 NAND（Flash）占比 | C89: % | D89: 0.04 | E89: 0.06 | F89: 0.08 | G89: Assumed | H89: Q1 4%、Q2 4%、Q3 7%（公司新聞稿） | I89: —
A90: m_dr | B90: FY2026 半導體系統 DRAM 權重（前三季實績＋第四季假設，金額加權） | C90: % | D90: =(SUMPRODUCT(Q!G19:I19,Q!G4:I4)+q4_dr_lo*Q!J4)/an_ss -> 0.28266106 | E90: =(SUMPRODUCT(Q!G19:I19,Q!G4:I4)+q4_dr*Q!J4)/an_ss -> 0.29479344 | F90: =(SUMPRODUCT(Q!G19:I19,Q!G4:I4)+q4_dr_hi*Q!J4)/an_ss -> 0.30692582 | G90: Derived | H90: Q 頁：各季營收 × 終端市場占比 | I90: 低／高對應 q4_dr 低／高
A91: m_nd | B91: FY2026 半導體系統 NAND 權重 | C91: % | E91: =(SUMPRODUCT(Q!G20:I20,Q!G4:I4)+q4_nd*Q!J4)/an_ss -> 0.054174921 | G91: Derived | H91: 同上 | I91: —
A92: m_fl | B92: FY2026 半導體系統 晶圓代工、邏輯與其他 權重（＝1 − DRAM − NAND） | C92: % | D92: =1-m_dr_lo-m_nd -> 0.66316402 | E92: =1-m_dr-m_nd -> 0.65103164 | F92: =1-m_dr_hi-m_nd -> 0.63889926 | G92: Derived | H92: 同上；公司「Foundry, logic and other」含 ICAPS（成熟製程、功率、類比等），故對應設備市場的先進邏輯＋其他代工邏輯＋其他前段 | I92: 低／高與 m_dr 對沖
A93: sf | B93: 份額係數（FY2027 起 AMAT 半導體系統營收 ÷ 依市場指數推得的營收） | C93: x | D93: 0.95 | E93: 1 | F93: 1.05 | G93: Assumed | H93: 無：基準假設 AMAT 在三個終端市場的份額維持 FY2026 水準 | I93: 上方＝環繞式閘極、背面供電、先進封裝的份額提升；下方＝中國國產替代、競爭（Lam、TEL、KLA）
A94: C. 出口管制與中國
A95: aff_hit | B95: BIS「關係企業規則」恢復時的年營收影響 | C95: US$M | D95: 300 | E95: 600 | F95: 900 | G95: Interested-party | H95: AMAT 8-K（2025-09-29）：該規則將使 FY2026 營收減少約 US$600M（Q4 FY25 約 US$110M） | I95: Reuters（Yahoo Finance 2025-11-14）：規則暫停後約 US$600M 營收可恢復；Skadden：暫停至 2026-11-09，除非 BIS 延長。低／高 Assumed（±50%）
A96: aff_A | B96: 情境 A：關係企業規則於 FY2027 起恢復（1＝是） | C96: 0/1 | E96: 0 | G96: Assumed | H96: 暫停期至 2026-11-09（Skadden 2025-11）；是否延長未知 | I96: A、B 假設延長；C 假設恢復（與設備市場下修同向的保守組合）
A97: aff_B | B97: 情境 B：關係企業規則於 FY2027 起恢復（1＝是） | C97: 0/1 | E97: 0 | G97: Assumed | H97: 同上 | I97: A、B 假設延長；C 假設恢復（與設備市場下修同向的保守組合）
A98: aff_C | B98: 情境 C：關係企業規則於 FY2027 起恢復（1＝是） | C98: 0/1 | E98: 1 | G98: Assumed | H98: 同上 | I98: A、B 假設延長；C 假設恢復（與設備市場下修同向的保守組合）
A99: cn_sh | B99: 中國占營收（FY2026 前三季，Derived） | C99: % | E99: =SUM(Q!G21:I21)/SUM(Q!G7:I7) -> 0.27823772 | G99: Derived | H99: Q 頁：前三季中國營收 ÷ 營收（公司新聞稿；Q3 為 28%） | I99: 公司：Q3 中國占半導體系統＋AGS 的 26%；預期 CY2026 中國營收增加（28nm 代工邏輯帶動）
A100: cn_cut | B100: 敏感度：中國營收下修比例（國產替代或新管制） | C100: % | D100: 0 | E100: 0 | F100: 0.4 | G100: Assumed | H100: 無；基準 0（市場層的「其他代工邏輯」已含中國擴產的成長假設） | I100: Sens 用高值 20%、40%（只對半導體系統＋AGS）
A101: D. AGS 服務與其他（含顯示器）：前一年 × 成長率
...

Sheet Q
A1: Q — 實績（百萬美元；EPS 為美元）。會計年度約 11 月～隔年 10 月：FY2026＝2025-10-27～2026-10-25。藍字＝輸入；黑字＝公式。損益為 non-GAAP（公司揭露），GAAP EPS 另列。分部自 FY2026 起重編（200mm 設備移入半導體系統、公司費用全數分攤），FY2025 Q1–Q3 用 FY2026 新聞稿的重編比較數
A2: FY2026 第四季（2026-07-27～2026-10-25）已結束、尚未公布：預定 2026-11-12 公布（stockanalysis）。本版 FY2026＝前三季實績＋第四季公司指引（錨點）。公布後更新 J 欄
A3: 項目 | B3: FY25 Q1（11–1月） | C3: FY25 Q2（2–4月） | D3: FY25 Q3（5–7月） | E3: FY25 Q4（8–10月） | F3: FY2025 全年 | G3: FY26 Q1 | H3: FY26 Q2 | I3: FY26 Q3 | J3: FY26 Q4（指引） | K3: FY2026 錨點 | L3: 標記 | M3: 來源1（公司） | N3: 來源2／說明
A4: 半導體系統（重編後） | B4: 5597 | C4: 5401 | D4: 5564 | E4: =J4/(1+q4g_ss) -> 4876.5432 | F4: =SUM(B4:E4) -> 21438.543 | G4: 5141 | H4: 5965 | I4: 7040 | J4: =g_ss_q4 -> 7900 | K4: =SUM(G4:J4) -> 26046 | L4: Verified／Derived | M4: AMAT 各季新聞稿（ir.appliedmaterials.com；SEC 8-K 附件 99.1）：FY25 Q1–Q3 為 FY26 各季新聞稿的重編比較數；FY25 Q4 由 FY26 Q4 指引 ÷ (1＋62%) 反推（Derived） | N4: FY2025 舊口徑 20,798（FY25 Q4 新聞稿）；重編差額主要為 200mm 設備由 AGS 移入
A5: AGS 服務（重編後） | B5: 1353 | C5: 1420 | D5: 1463 | E5: =J5/(1+q4g_ags) -> 1508.1967 | F5: =SUM(B5:E5) -> 5744.1967 | G5: 1559 | H5: 1665 | I5: 1781 | J5: =g_ags_q4 -> 1840 | K5: =SUM(G5:J5) -> 6845 | L5: Verified／Derived | M5: AMAT 各季新聞稿（ir.appliedmaterials.com；SEC 8-K 附件 99.1）：同上；FY25 Q4 由指引 ÷ (1＋22%) 反推 | N5: FY2025 舊口徑 6,385
A6: 其他（含顯示器） | B6: 216 | C6: 279 | D6: 275 | E6: =E7-E4-E5 -> 415.26007 | F6: =SUM(B6:E6) -> 1185.2601 | G6: 312 | H6: 280 | I6: 294 | J6: =g_oth_q4 -> 510 | K6: =SUM(G6:J6) -> 1396 | L6: Verified／Derived | M6: AMAT 各季新聞稿（ir.appliedmaterials.com；SEC 8-K 附件 99.1）；FY25 Q4＝營收 − 半導體系統 − AGS（Derived） | N6: FY2025 舊口徑顯示器 1,060（另含於公司與其他）
A7: 營收 | B7: 7166 | C7: 7100 | D7: 7302 | E7: 6800 | F7: 28368 | G7: 7012 | H7: 7910 | I7: 9115 | J7: =g_rev_q4 -> 10250 | K7: =SUM(G7:J7) -> 34287 | L7: Verified | M7: AMAT 各季新聞稿（ir.appliedmaterials.com；SEC 8-K 附件 99.1）：FY2025 28,368；FY26 前三季 24,037 | N7: stockanalysis 季報表（逐季相同）
A8: 檢查：分部合計 − 營收（應為 0） | B8: =B4+B5+B6-B7 -> 0 | C8: =C4+C5+C6-C7 -> 0 | D8: =D4+D5+D6-D7 -> 0 | E8: =E4+E5+E6-E7 -> 0 | F8: =F4+F5+F6-F7 -> 0 | G8: =G4+G5+G6-G7 -> 0 | H8: =H4+H5+H6-H7 -> 0 | I8: =I4+I5+I6-I7 -> 0 | ... K8: =K4+K5+K6-K7 -> 0 | L8: — | M8: — | N8: FY25 Q1–Q3 與 FY26 各季：公司分部表加總＝營收
A9: non-GAAP 毛利率 | B9: 0.489 | C9: 0.492 | D9: 0.489 | E9: 0.481 | F9: =F10/F7 -> 0.48783319 | G9: 0.491 | H9: 0.5 | I9: 0.504 | J9: =g_gm_q4 -> 0.504 | K9: =K10/K7 -> 0.50041858 | L9: Verified | M9: AMAT 各季新聞稿（ir.appliedmaterials.com；SEC 8-K 附件 99.1）：FY2025 全年 48.8%（四季加權 48.8%，見 F 欄） | N9: GAAP 毛利率：stockanalysis 季報表毛利 ÷ 營收（差 0.1 個百分點內）
A10: non-GAAP 毛利 | B10: =B7*B9 -> 3504.174 | C10: =C7*C9 -> 3493.2 | D10: =D7*D9 -> 3570.678 | E10: =E7*E9 -> 3270.8 | F10: =SUM(B10:E10) -> 13838.852 | G10: =G7*G9 -> 3442.892 | H10: =H7*H9 -> 3955 | I10: =I7*I9 -> 4593.96 | J10: =J7*J9 -> 5166 | K10: =SUM(G10:J10) -> 17157.852 | L10: Derived | M10: 營收 × 毛利率（毛利率為公司公布的一位小數） | N10: —
A11: non-GAAP 營業利益 | B11: 2190 | C11: 2180 | D11: 2245 | E11: 1947 | F11: =SUM(B11:E11) -> 8562 | G11: 2107 | H11: 2536 | I11: 3096 | J11: =J10-J12 -> 3586 | K11: =SUM(G11:J11) -> 11325 | L11: Verified／Derived | M11: AMAT 各季新聞稿（ir.appliedmaterials.com；SEC 8-K 附件 99.1）：FY2025 8,562；FY26 Q4＝指引毛利 − 指引營業費用 | N11: GAAP 營業利益（stockanalysis）：FY26 Q1 2,096 不含 BIS 和解金 253
A12: non-GAAP 營業費用（毛利 − 營業利益） | B12: =B10-B11 -> 1314.174 | C12: =C10-C11 -> 1313.2 | D12: =D10-D11 -> 1325.678 | E12: =E10-E11 -> 1323.8 | F12: =F10-F11 -> 5276.852 | G12: =G10-G11 -> 1335.892 | H12: =H10-H11 -> 1419 | I12: =I10-I11 -> 1497.96 | J12: =g_opx_q4 -> 1580 | K12: =SUM(G12:J12) -> 5832.852 | L12: Derived | M12: — | N12: FY26 Q4 為公司指引約 1,580
A13: non-GAAP 淨利 | B13: 1946 | C13: 1940 | D13: 1989 | E13: 1732 | F13: =SUM(B13:E13) -> 7607 | G13: 1899 | H13: 2286 | I13: 2795 | J13: =J15*J14 -> 3199.92 | K13: =SUM(G13:J13) -> 10179.92 | L13: Verified／Derived | M13: AMAT 各季新聞稿（ir.appliedmaterials.com；SEC 8-K 附件 99.1）：FY2025 7,607；FY26 Q4＝指引 EPS × 假設股數 | N13: —
A14: 稀釋加權股數（百萬股） | B14: 819 | C14: 812 | D14: 802 | E14: 798 | F14: 808 | G14: 799 | H14: 799 | I14: 800 | J14: =sh_q4 -> 796 | K14: =K13/K15 -> 797.79937 | L14: Verified／Derived | M14: AMAT 各季新聞稿（ir.appliedmaterials.com；SEC 8-K 附件 99.1） | N14: FY2026 錨點＝淨利 ÷ EPS（Derived）
A15: non-GAAP 稀釋 EPS（美元） | B15: 2.38 | C15: 2.39 | D15: 2.48 | E15: 2.17 | F15: 9.42 | G15: 2.38 | H15: 2.86 | I15: 3.5 | J15: =g_eps_q4 -> 4.02 | K15: =SUM(G15:J15) -> 12.76 | L15: Verified | M15: AMAT 各季新聞稿（ir.appliedmaterials.com；SEC 8-K 附件 99.1）：FY2025 9.42（四季合計 9.42） | N15: 共識 FY2026 12.79（stockanalysis）
A16: GAAP 稀釋 EPS（美元；參考） | B16: 1.45 | C16: 2.63 | D16: 2.22 | E16: 2.38 | F16: 8.66 | G16: 2.54 | H16: 3.51 | I16: 3.17 | L16: Verified | M16: AMAT 各季新聞稿（ir.appliedmaterials.com；SEC 8-K 附件 99.1）：FY2025 8.66（FY2024 8.61） | N16: stockanalysis 季報表（逐季相同）；FY26 Q1 含 BIS 和解金 253（每股 0.32）、Q2 含投資評價益
A17: GAAP 淨利（參考） | B17: 1185 | C17: 2137 | D17: 1779 | E17: 1897 | F17: 6998 | G17: 2026 | H17: 2806 | I17: 2538 | L17: Verified | M17: AMAT 各季新聞稿（ir.appliedmaterials.com；SEC 8-K 附件 99.1） | N17: stockanalysis 季報表
A18: 半導體系統：晶圓代工、邏輯與其他 占比 | B18: 0.69 | C18: 0.66 | D18: 0.69 | E18: 0.65 | G18: 0.62 | H18: 0.67 | I18: 0.67 | J18: =1-J19-J20 -> 0.64 | K18: =SUMPRODUCT(G18:J18,G4:J4)/K4 -> 0.65103164 | L18: Verified／Assumed | M18: AMAT 各季新聞稿（ir.appliedmaterials.com；SEC 8-K 附件 99.1）（FY25 Q4 為舊口徑：FY25 Q4 新聞稿；FY2025 全年 67%） | N18: FY26 Q4 為 Assumed（In 頁 q4_dr、q4_nd）
A19: 半導體系統：DRAM 占比 | B19: 0.27 | C19: 0.27 | D19: 0.22 | E19: 0.29 | G19: 0.34 | H19: 0.29 | I19: 0.26 | J19: =q4_dr -> 0.3 | K19: =SUMPRODUCT(G19:J19,G4:J4)/K4 -> 0.29479344 | L19: Verified／Assumed | M19: AMAT 各季新聞稿（ir.appliedmaterials.com；SEC 8-K 附件 99.1）（FY2025 全年 26%） | N19: Q3 FY26 DRAM（含 HBM 封裝）年增 52%（法說）
A20: 半導體系統：Flash（NAND）占比 | B20: 0.04 | C20: 0.07 | D20: 0.09 | E20: 0.06 | G20: 0.04 | H20: 0.04 | I20: 0.07 | J20: =q4_nd -> 0.06 | K20: =SUMPRODUCT(G20:J20,G4:J4)/K4 -> 0.054174921 | L20: Verified／Assumed | M20: AMAT 各季新聞稿（ir.appliedmaterials.com；SEC 8-K 附件 99.1）（FY2025 全年 7%） | N20: —
A21: 中國營收 | B21: 2243 | C21: 1774 | D21: 2548 | E21: 1964 | F21: =SUM(B21:E21) -> 8529 | G21: 2095 | H21: 2087 | I21: 2506 | L21: Verified | M21: AMAT 各季新聞稿（ir.appliedmaterials.com；SEC 8-K 附件 99.1）：FY2025 8,529（30%；FY2024 10,117、37%） | N21: Reuters：中國占比降至約 25%（Yahoo Finance 2025-11-14）
A22: 中國占營收 | B22: =B21/B7 -> 0.31300586 | C22: =C21/C7 -> 0.24985915 | D22: =D21/D7 -> 0.34894549 | E22: =E21/E7 -> 0.28882353 | F22: =F21/F7 -> 0.30065567 | G22: =G21/G7 -> 0.29877353 | H22: =H21/H7 -> 0.26384324 | I22: =I21/I7 -> 0.27493143 | L22: Derived | M22: 公司：Q1 30%、Q2 27%、Q3 28% | N22: —
A23: 檢查：四季合計 − 全年公布值（營收、毛利率、營業利益、淨利、EPS、中國 依序在 B–G 欄） | B23: =SUM(B7:E7)-F7 -> 0 | C23: =F9-0.488 -> -0.00016680767 | D23: =F11-8562 -> 0 | E23: =F13-7607 -> 0 | F23: =SUM(B15:E15)-F15 -> 0 | G23: =F21-8529 -> 0 | L23: — | M23: — | N23: 毛利率差為四捨五入（公司公布 48.8%）
A26: FY2026 錨點的組成（前三季實績＋第四季指引）
A27: 項目 | B27: 前三季實績 | C27: 第四季指引 | D27: FY2026 錨點 | E27: FY2025 | F27: 年增 | G27: 第四季 × 4（年化）
A28: 營收 | B28: =SUM(G7:I7) -> 24037 | C28: =J7 -> 10250 | D28: =K7 -> 34287 | E28: =F7 -> 28368 | F28: =D28/E28-1 -> 0.20865059 | G28: =C28*4 -> 41000
A29: 半導體系統 | B29: =SUM(G4:I4) -> 18146 | C29: =J4 -> 7900 | D29: =K4 -> 26046 | E29: =F4 -> 21438.543 | F29: =D29/E29-1 -> 0.21491464 | G29: =C29*4 -> 31600
A30: AGS | B30: =SUM(G5:I5) -> 5005 | C30: =J5 -> 1840 | D30: =K5 -> 6845 | E30: =F5 -> 5744.1967 | F30: =D30/E30-1 -> 0.19163746 | G30: =C30*4 -> 7360
A31: 其他 | B31: =SUM(G6:I6) -> 886 | C31: =J6 -> 510 | D31: =K6 -> 1396 | E31: =F6 -> 1185.2601 | F31: =D31/E31-1 -> 0.17780058 | G31: =C31*4 -> 2040
A32: non-GAAP 營業利益 | B32: =SUM(G11:I11) -> 7739 | C32: =J11 -> 3586 | D32: =K11 -> 11325 | E32: =F11 -> 8562 | F32: =D32/E32-1 -> 0.32270498 | G32: =C32*4 -> 14344
A33: non-GAAP EPS | B33: =SUM(G15:I15) -> 8.74 | C33: =J15 -> 4.02 | D33: =K15 -> 12.76 | E33: =F15 -> 9.42 | F33: =D33/E33-1 -> 0.35456476 | G33: =C33*4 -> 16.08
A35: non-GAAP 營業利益率：FY2025 | B35: =a25_oi/a25_rev -> 0.30181895
A36: non-GAAP 營業利益率：FY2026 錨點 | B36: =an_oi/an_rev -> 0.33030011
A37: 共識 FY2026 營收、EPS（stockanalysis；只作對照） | B37: =cons_rev26 -> 34260 | C37: =cons_eps26 -> 12.79

Sheet Units
A1: Units — 晶圓廠設備市場（US$B；markets/equipment 成品，三情境）：日曆年 → AMAT 會計年度（FY(t)＝fyw×CY(t−1)＋(1−fyw)×CY(t)），以及 AMAT 半導體系統占市場的隱含份額（只作檢驗，不校準）
A3: 項目 | B3: 單位 | C3: 2025 | D3: 2026 | E3: 2027 | F3: 2028 | G3: 2029 | H3: 說明
A4: 情境 A：日曆年（CY）
A5: 晶圓代工、邏輯與其他（先進邏輯＋其他代工邏輯＋其他前段） | B5: US$B | C5: =laA_25+loA_25+ofA_25 -> 78.348121 | D5: =laA_26+loA_26+ofA_26 -> 99.287198 | E5: =laA_27+loA_27+ofA_27 -> 116.28871 | F5: =laA_28+loA_28+ofA_28 -> 130.8864 | G5: =laA_29+loA_29+ofA_29 -> 139.39808
A6: DRAM（含 HBM） | B6: US$B | C6: =drA_25 -> 26.376109 | D6: =drA_26 -> 39.365947 | E6: =drA_27 -> 53.258733 | F6: =drA_28 -> 59.5609 | G6: =drA_29 -> 61.831293
A7: NAND | B7: US$B | C7: =ndA_25 -> 12.172602 | D7: =ndA_26 -> 17.503905 | E7: =ndA_27 -> 23.248027 | F7: =ndA_28 -> 26.181322 | G7: =ndA_29 -> 27.674313
A8: 合計（晶圓前段） | B8: US$B | C8: =SUM(C5:C7) -> 116.89683 | D8: =SUM(D5:D7) -> 156.15705 | E8: =SUM(E5:E7) -> 192.79547 | F8: =SUM(F5:F7) -> 216.62863 | G8: =SUM(G5:G7) -> 228.90369
A9: 情境 A：會計年度（FY；FY2025 需 CY2024，市場層沒有，留空）
A10: 晶圓代工、邏輯與其他 | B10: US$B | D10: =fyw*C5+(1-fyw)*D5 -> 95.797352 | E10: =fyw*D5+(1-fyw)*E5 -> 113.45512 | F10: =fyw*E5+(1-fyw)*F5 -> 128.45346 | G10: =fyw*F5+(1-fyw)*G5 -> 137.97947
A11: DRAM（含 HBM） | B11: US$B | D11: =fyw*C6+(1-fyw)*D6 -> 37.200974 | E11: =fyw*D6+(1-fyw)*E6 -> 50.943268 | F11: =fyw*E6+(1-fyw)*F6 -> 58.510539 | G11: =fyw*F6+(1-fyw)*G6 -> 61.452894
A12: NAND | B12: US$B | D12: =fyw*C7+(1-fyw)*D7 -> 16.615355 | E12: =fyw*D7+(1-fyw)*E7 -> 22.290674 | F12: =fyw*E7+(1-fyw)*F7 -> 25.692439 | G12: =fyw*F7+(1-fyw)*G7 -> 27.425481
A13: 合計（晶圓前段） | B13: US$B | D13: =fyw*C8+(1-fyw)*D8 -> 149.61368 | E13: =fyw*D8+(1-fyw)*E8 -> 186.68907 | F13: =fyw*E8+(1-fyw)*F8 -> 212.65643 | G13: =fyw*F8+(1-fyw)*G8 -> 226.85784
A15: 情境 B：日曆年（CY）
A16: 晶圓代工、邏輯與其他（先進邏輯＋其他代工邏輯＋其他前段） | B16: US$B | C16: =laB_25+loB_25+ofB_25 -> 78.348121 | D16: =laB_26+loB_26+ofB_26 -> 99.287198 | E16: =laB_27+loB_27+ofB_27 -> 116.28871 | F16: =laB_28+loB_28+ofB_28 -> 116.28871 | G16: =laB_29+loB_29+ofB_29 -> 110.47427
A17: DRAM（含 HBM） | B17: US$B | C17: =drB_25 -> 26.376109 | D17: =drB_26 -> 39.365947 | E17: =drB_27 -> 53.258733 | F17: =drB_28 -> 53.258733 | G17: =drB_29 -> 50.595796
A18: NAND | B18: US$B | C18: =ndB_25 -> 12.172602 | D18: =ndB_26 -> 17.503905 | E18: =ndB_27 -> 23.248027 | F18: =ndB_28 -> 23.248027 | G18: =ndB_29 -> 22.085626
A19: 合計（晶圓前段） | B19: US$B | C19: =SUM(C16:C18) -> 116.89683 | D19: =SUM(D16:D18) -> 156.15705 | E19: =SUM(E16:E18) -> 192.79547 | F19: =SUM(F16:F18) -> 192.79547 | G19: =SUM(G16:G18) -> 183.1557
A20: 情境 B：會計年度（FY；FY2025 需 CY2024，市場層沒有，留空）
A21: 晶圓代工、邏輯與其他 | B21: US$B | D21: =fyw*C16+(1-fyw)*D16 -> 95.797352 | E21: =fyw*D16+(1-fyw)*E16 -> 113.45512 | F21: =fyw*E16+(1-fyw)*F16 -> 116.28871 | G21: =fyw*F16+(1-fyw)*G16 -> 111.44335
A22: DRAM（含 HBM） | B22: US$B | D22: =fyw*C17+(1-fyw)*D17 -> 37.200974 | E22: =fyw*D17+(1-fyw)*E17 -> 50.943268 | F22: =fyw*E17+(1-fyw)*F17 -> 53.258733 | G22: =fyw*F17+(1-fyw)*G17 -> 51.039619
A23: NAND | B23: US$B | D23: =fyw*C18+(1-fyw)*D18 -> 16.615355 | E23: =fyw*D18+(1-fyw)*E18 -> 22.290674 | F23: =fyw*E18+(1-fyw)*F18 -> 23.248027 | G23: =fyw*F18+(1-fyw)*G18 -> 22.279359
A24: 合計（晶圓前段） | B24: US$B | D24: =fyw*C19+(1-fyw)*D19 -> 149.61368 | E24: =fyw*D19+(1-fyw)*E19 -> 186.68907 | F24: =fyw*E19+(1-fyw)*F19 -> 192.79547 | G24: =fyw*F19+(1-fyw)*G19 -> 184.76232
A26: 情境 C：日曆年（CY）
A27: 晶圓代工、邏輯與其他（先進邏輯＋其他代工邏輯＋其他前段） | B27: US$B | C27: =laC_25+loC_25+ofC_25 -> 78.348121 | D27: =laC_26+loC_26+ofC_26 -> 99.287198 | E27: =laC_27+loC_27+ofC_27 -> 116.28871 | F27: =laC_28+loC_28+ofC_28 -> 93.030967 | G27: =laC_29+loC_29+ofC_29 -> 93.030967
A28: DRAM（含 HBM） | B28: US$B | C28: =drC_25 -> 26.376109 | D28: =drC_26 -> 39.365947 | E28: =drC_27 -> 53.258733 | F28: =drC_28 -> 42.606986 | G28: =drC_29 -> 42.606986
A29: NAND | B29: US$B | C29: =ndC_25 -> 12.172602 | D29: =ndC_26 -> 17.503905 | E29: =ndC_27 -> 23.248027 | F29: =ndC_28 -> 18.598422 | G29: =ndC_29 -> 18.598422
A30: 合計（晶圓前段） | B30: US$B | C30: =SUM(C27:C29) -> 116.89683 | D30: =SUM(D27:D29) -> 156.15705 | E30: =SUM(E27:E29) -> 192.79547 | F30: =SUM(F27:F29) -> 154.23638 | G30: =SUM(G27:G29) -> 154.23638
A31: 情境 C：會計年度（FY；FY2025 需 CY2024，市場層沒有，留空）
A32: 晶圓代工、邏輯與其他 | B32: US$B | D32: =fyw*C27+(1-fyw)*D27 -> 95.797352 | E32: =fyw*D27+(1-fyw)*E27 -> 113.45512 | F32: =fyw*E27+(1-fyw)*F27 -> 96.907258 | G32: =fyw*F27+(1-fyw)*G27 -> 93.030967
A33: DRAM（含 HBM） | B33: US$B | D33: =fyw*C28+(1-fyw)*D28 -> 37.200974 | E33: =fyw*D28+(1-fyw)*E28 -> 50.943268 | F33: =fyw*E28+(1-fyw)*F28 -> 44.382277 | G33: =fyw*F28+(1-fyw)*G28 -> 42.606986
A34: NAND | B34: US$B | D34: =fyw*C29+(1-fyw)*D29 -> 16.615355 | E34: =fyw*D29+(1-fyw)*E29 -> 22.290674 | F34: =fyw*E29+(1-fyw)*F29 -> 19.373356 | G34: =fyw*F29+(1-fyw)*G29 -> 18.598422
A35: 合計（晶圓前段） | B35: US$B | D35: =fyw*C30+(1-fyw)*D30 -> 149.61368 | E35: =fyw*D30+(1-fyw)*E30 -> 186.68907 | F35: =fyw*E30+(1-fyw)*F30 -> 160.66289 | G35: =fyw*F30+(1-fyw)*G30 -> 154.23638
A37: AMAT 半導體系統 ÷ 會計年度晶圓前段市場（隱含份額；情境 A；FY2027 起份額係數 sf 決定變化）
A38: 情境 A | B38: % | D38: =PL!D65 -> 0.17408836 | E38: =PL!E65 -> 0.1740321 | F38: =PL!F65 -> 0.17396817 | G38: =PL!G65 -> 0.17383613 | H38: AMAT 半導體系統也含先進封裝等後段設備，故份額略高於純前段口徑
A40: 說明：AMAT「Foundry, logic and other」含 ICAPS（成熟製程、功率、類比、物聯網等），故以設備市場的先進邏輯＋其他代工邏輯＋其他前段為對應；設備市場模型 2026 年以後高於 SEMI 約 7–10%（markets/equipment Recon），本模型只用各終端市場的成長指數，水準由 AMAT FY2026 錨點決定。

Sheet PL
A1: PL — Applied Materials 損益（US$M；non-GAAP；FY2025 為實績，FY2026 為錨點（前三季實績＋第四季指引），FY2027–FY2029 為模型）。三情境各一個完整推導區塊（見下方），本頁頂端為摘要
A3: 情境／項目 | B3: 單位 | C3: FY2025A | D3: FY2026（錨點） | E3: FY2027 | F3: FY2028 | G3: FY2029 | H3: 說明
A4: 情境 A
A5: 營收 | B5: US$M | C5: =C56 -> 28368 | D5: =D56 -> 34287 | E5: =E56 -> 41757.639 | F5: =F56 -> 47443.964 | G5: =G56 -> 51242.48
A6: 半導體系統 | B6: US$M | C6: =C52 -> 21438.543 | D6: =D52 -> 26046 | E6: =E52 -> 32489.889 | F6: =F52 -> 36995.451 | G6: =G52 -> 39436.09
A7: AGS 服務 | B7: US$M | C7: =C53 -> 5744.1967 | D7: =D53 -> 6845 | E7: =E53 -> 7871.75 | F7: =F53 -> 9052.5125 | G7: =G53 -> 10410.389
A8: non-GAAP 毛利率 | B8: % | C8: =C57 -> 0.48783319 | D8: =D57 -> 0.50041858 | E8: =E57 -> 0.51120976 | F8: =F57 -> 0.51714573 | G8: =G57 -> 0.52037705
A9: non-GAAP 營業利益 | B9: US$M | C9: =C60 -> 8562 | D9: =D60 -> 11325 | E9: =E60 -> 14812.308 | F9: =F60 -> 17466.695 | G9: =G60 -> 19239.849
A10: non-GAAP 營業利益率 | B10: % | C10: =C61 -> 0.30181895 | D10: =D61 -> 0.33030011 | E10: =E61 -> 0.35472092 | F10: =F61 -> 0.3681542 | G10: =G61 -> 0.37546678
A11: non-GAAP 淨利 | B11: US$M | C11: =C62 -> 7607 | D11: =D62 -> 10179.92 | E11: =E62 -> 13160.153 | F11: =F62 -> 15518.471 | G11: =G62 -> 17093.848
A12: non-GAAP EPS | B12: US$ | C12: =C64 -> 9.42 | D12: =D64 -> 12.76 | E12: =E64 -> 16.662189 | F12: =F64 -> 19.846542 | G12: =G64 -> 22.08211
A14: 情境 B
A15: 營收 | B15: US$M | C15: =C84 -> 28368 | D15: =D84 -> 34287 | E15: =E84 -> 41414.039 | F15: =F84 -> 43244.276 | G15: =G84 -> 42711.047
A16: 半導體系統 | B16: US$M | C16: =C80 -> 21438.543 | D16: =D80 -> 26046 | E16: =E80 -> 32489.889 | F16: =F80 -> 33550.661 | G16: =G80 -> 32152.717
A17: AGS 服務 | B17: US$M | C17: =C81 -> 5744.1967 | D17: =D81 -> 6845 | E17: =E81 -> 7597.95 | F17: =F81 -> 8433.7245 | G17: =G81 -> 9361.4342
A18: non-GAAP 毛利率 | B18: % | C18: =C85 -> 0.48783319 | D18: =D85 -> 0.50041858 | E18: =E85 -> 0.51079886 | F18: =F85 -> 0.51291238 | G18: =G85 -> 0.51231532
A19: non-GAAP 營業利益 | B19: US$M | C19: =C88 -> 8562 | D19: =D88 -> 11325 | E19: =E88 -> 14651.915 | F19: =F88 -> 15506.273 | G19: =G88 -> 15257.36
A20: non-GAAP 營業利益率 | B20: % | C20: =C89 -> 0.30181895 | D20: =D89 -> 0.33030011 | E20: =E89 -> 0.35379101 | F20: =F89 -> 0.35857399 | G20: =G89 -> 0.35722282
A21: non-GAAP 淨利 | B21: US$M | C21: =C90 -> 7607 | D21: =D90 -> 10179.92 | E21: =E90 -> 13017.65 | F21: =F90 -> 13776.713 | G21: =G90 -> 13555.564
A22: non-GAAP EPS | B22: US$ | C22: =C92 -> 9.42 | D22: =D92 -> 12.76 | E22: =E92 -> 16.481764 | F22: =F92 -> 17.619011 | G22: =G92 -> 17.511297
A24: 情境 C
A25: 營收 | B25: US$M | C25: =C112 -> 28368 | D25: =D112 -> 34287 | E25: =E112 -> 40470.439 | F25: =F112 -> 36326.485 | G25: =G112 -> 35643.632
A26: 半導體系統 | B26: US$M | C26: =C108 -> 21438.543 | D26: =D108 -> 26046 | E26: =E108 -> 32489.889 | F26: =F108 -> 27958.884 | G26: =G108 -> 26840.529
A27: AGS 服務 | B27: US$M | C27: =C109 -> 5744.1967 | D27: =D109 -> 6845 | E27: =E109 -> 7324.15 | F27: =F109 -> 7836.8405 | G27: =G109 -> 8385.4193
A28: non-GAAP 毛利率 | B28: % | C28: =C113 -> 0.48783319 | D28: =D113 -> 0.50041858 | E28: =E113 -> 0.50963452 | F28: =F113 -> 0.50380503 | G28: =G113 -> 0.50271435
A29: non-GAAP 營業利益 | B29: US$M | C29: =C116 -> 8562 | D29: =D116 -> 11325 | E29: =E116 -> 14211.441 | F29: =F116 -> 12277.035 | G29: =G116 -> 11958.278
A30: non-GAAP 營業利益率 | B30: % | C30: =C117 -> 0.30181895 | D30: =D117 -> 0.33030011 | E30: =E117 -> 0.35115608 | F30: =F117 -> 0.33796376 | G30: =G117 -> 0.33549551
A31: non-GAAP 淨利 | B31: US$M | C31: =C118 -> 7607 | D31: =D118 -> 10179.92 | E31: =E118 -> 12626.306 | F31: =F118 -> 10907.663 | G31: =G118 -> 10624.46
A32: non-GAAP EPS | B32: US$ | C32: =C120 -> 9.42 | D32: =D120 -> 12.76 | E32: =E120 -> 15.98628 | F32: =F120 -> 13.949788 | G32: =G120 -> 13.724849
A34: 讀法：FY2026 三情境相同（錨點）；FY2027 的 1/6 落在 CY2026、5/6 在 CY2027，設備市場三情境在 CY2027 以前相同，所以 FY2027 只有情境 C 的出口管制調整造成差異；FY2028 起情境差異來自設備市場。
A40: 情境 A：設備市場續增（2028 +12.7%、2029 +5.9%；markets/equipment）
A41: 項目 | B41: 單位 | C41: 2025 | D41: 2026 | E41: 2027 | F41: 2028 | G41: 2029 | H41: 說明
A42: A. 市場（日曆年 CY，US$B；讀 In 頁的設備市場成品）
A43: 晶圓代工、邏輯與其他 CY | B43: US$B | C43: =laA_25+loA_25+ofA_25 -> 78.348121 | D43: =laA_26+loA_26+ofA_26 -> 99.287198 | E43: =laA_27+loA_27+ofA_27 -> 116.28871 | F43: =laA_28+loA_28+ofA_28 -> 130.8864 | G43: =laA_29+loA_29+ofA_29 -> 139.39808
A44: DRAM（含 HBM）CY | B44: US$B | C44: =drA_25 -> 26.376109 | D44: =drA_26 -> 39.365947 | E44: =drA_27 -> 53.258733 | F44: =drA_28 -> 59.5609 | G44: =drA_29 -> 61.831293
A45: NAND CY | B45: US$B | C45: =ndA_25 -> 12.172602 | D45: =ndA_26 -> 17.503905 | E45: =ndA_27 -> 23.248027 | F45: =ndA_28 -> 26.181322 | G45: =ndA_29 -> 27.674313
A46: B. 會計年度（FY；FY(t)＝fyw×CY(t−1)＋(1−fyw)×CY(t)）
A47: 晶圓代工、邏輯與其他 FY | B47: US$B | D47: =fyw*C43+(1-fyw)*D43 -> 95.797352 | E47: =fyw*D43+(1-fyw)*E43 -> 113.45512 | F47: =fyw*E43+(1-fyw)*F43 -> 128.45346 | G47: =fyw*F43+(1-fyw)*G43 -> 137.97947
A48: DRAM（含 HBM）FY | B48: US$B | D48: =fyw*C44+(1-fyw)*D44 -> 37.200974 | E48: =fyw*D44+(1-fyw)*E44 -> 50.943268 | F48: =fyw*E44+(1-fyw)*F44 -> 58.510539 | G48: =fyw*F44+(1-fyw)*G44 -> 61.452894
A49: NAND FY | B49: US$B | D49: =fyw*C45+(1-fyw)*D45 -> 16.615355 | E49: =fyw*D45+(1-fyw)*E45 -> 22.290674 | F49: =fyw*E45+(1-fyw)*F45 -> 25.692439 | G49: =fyw*F45+(1-fyw)*G45 -> 27.425481
...

Sheet Val
A1: Val — P/E 估值（美元；non-GAAP EPS）。跨公司規則：合理倍數＝10 年（2016–2025 年底）P/E 的分位，依循環位置：見頂年 25 分位、中段中位數、谷底 75 分位。循環位置依設備股共用規則（見第 4 節）。本版未做先驗，無 Andy 合理 P/E 對照
A2: P/E 定義（自算）：日曆年底收盤價（未調整股利）÷ 當年 10 月結束的會計年度 FY(t) 的 non-GAAP 稀釋 EPS（FY(t) 有 10/12 落在日曆年 t，與模型對 FY2027 EPS 套用倍數的口徑一致）；GAAP 口徑另列對照
A3: 目標價（DCF 與 Comparable 加權）：見本頁第 102 列起「0. 目標價」（估值 v2 新增，放在既有內容之後以免位移既有列）；原「0. 目標價與上檔空間」改名為「舊法：規則值情境加權（參考）」
A4: 1. 公司公布 EPS（會計年度，美元）— 兩個口徑、兩個來源
A5: 會計年度（10 月底結束） | B5: non-GAAP 稀釋 EPS（公司新聞稿） | C5: GAAP 稀釋 EPS（公司新聞稿） | D5: GAAP EPS（macrotrends） | E5: GAAP 兩來源差距 | F5: 標記 | G5: 說明
A6: FY2016 | B6: 1.75 | C6: 1.54 | D6: 1.54 | E6: =D6/C6-1 -> 0 | F6: Verified | G6: 公司 FY2016 Q4 新聞稿（SEC 8-K 2016-11）
A7: FY2017 | B7: 3.25 | C7: 3.17 | D7: 3.25 | E7: =D7/C7-1 -> 0.025236593 | F7: Verified | G7: 公司 FY2018 Q4 新聞稿（FY2017 比較數）；macrotrends 為 ASC 606 追溯重編後
A8: FY2018 | B8: 4.45 | C8: 3.23 | D8: 2.96 | E8: =D8/C8-1 -> -0.083591331 | F8: Verified | G8: 公司 FY2018 Q4 新聞稿；macrotrends 為 ASC 606 追溯重編後（FY2019 採用）
A9: FY2019 | B9: 3.04 | C9: 2.86 | D9: 2.86 | E9: =D9/C9-1 -> 0 | F9: Verified | G9: 公司 FY2020 Q4 新聞稿（FY2019 比較數）
A10: FY2020 | B10: 4.17 | C10: 3.92 | D10: 3.92 | E10: =D10/C10-1 -> 0 | F10: Verified | G10: 公司 FY2020 Q4 新聞稿
A11: FY2021 | B11: 6.84 | C11: 6.4 | D11: 6.4 | E11: =D11/C11-1 -> 0 | F11: Verified | G11: 公司 FY2021 Q4 新聞稿
A12: FY2022 | B12: 7.7 | C12: 7.44 | D12: 7.44 | E12: =D12/C12-1 -> 0 | F12: Verified | G12: 公司 FY2023 Q4 新聞稿（FY2022 比較數）
A13: FY2023 | B13: 8.05 | C13: 8.11 | D13: 8.11 | E13: =D13/C13-1 -> 0 | F13: Verified | G13: 公司 FY2023 Q4 新聞稿
A14: FY2024 | B14: 8.65 | C14: 8.61 | D14: 8.61 | E14: =D14/C14-1 -> 0 | F14: Verified | G14: 公司 FY2025 Q4 新聞稿（FY2024 比較數）
A15: FY2025 | B15: 9.42 | C15: 8.66 | D15: 8.66 | E15: =D15/C15-1 -> 0 | F15: Verified | G15: 公司 FY2025 Q4 新聞稿；stockanalysis 8.66
A16: 規則用 non-GAAP（模型 EPS、公司指引、共識同口徑）。non-GAAP 的第二來源：未找到（各資料商多列 GAAP）；GAAP 兩來源除 FY2017、FY2018（ASC 606 重編）外相同
A18: 2. 10 年 P/E（年底）
A19: 年底 | B19: 收盤價（未調整） | C19: non-GAAP EPS FY(t) | D19: GAAP EPS FY(t) | E19: P/E non-GAAP（自算） | F19: P/E GAAP（自算） | G19: companiesmarketcap P/E | H19: 自算 GAAP − cmc | I19: 股利調整後收盤（statmuse） | J19: 標記 | K19: 來源／說明 | L19: 輔助：不含 2018
A20: 2016-12 | B20: 32.27 | C20: =B6 -> 1.75 | D20: =C6 -> 1.54 | E20: =B20/C20 -> 18.44 | F20: =B20/D20 -> 20.954545 | G20: 18.6 | H20: =F20-G20 -> 2.3545455 | I20: 29.1 | J20: Verified／Derived | K20: 收盤價：digrin（Real price，未調整） | L20: =IF(A20="2018-12","",E20) -> 18.44
A21: 2017-12 | B21: 51.12 | C21: =B7 -> 3.25 | D21: =C7 -> 3.17 | E21: =B21/C21 -> 15.729231 | F21: =B21/D21 -> 16.126183 | G21: 14.7 | H21: =F21-G21 -> 1.426183 | I21: 46.52 | J21: Verified／Derived | K21: 收盤價：digrin（Real price，未調整） | L21: =IF(A21="2018-12","",E21) -> 15.729231
A22: 2018-12 | B22: 32.74 | C22: =B8 -> 4.45 | D22: =C8 -> 3.23 | E22: =B22/C22 -> 7.3573034 | F22: =B22/D22 -> 10.136223 | G22: 9.2 | H22: =F22-G22 -> 0.93622291 | I22: 30.27 | J22: Verified／Derived | K22: FY2018 non-GAAP EPS 4.45 為當年高峰（稅改後）→ P/E 7.4 為極端低值 | L22: =IF(A22="2018-12","",E22)
A23: 2019-12 | B23: 61.04 | C23: =B9 -> 3.04 | D23: =C9 -> 2.86 | E23: =B23/C23 -> 20.078947 | F23: =B23/D23 -> 21.342657 | G23: 20 | H23: =F23-G23 -> 1.3426573 | I23: 57.47 | J23: Verified／Derived | K23: 收盤價：digrin（Real price，未調整） | L23: =IF(A23="2018-12","",E23) -> 20.078947
A24: 2020-12 | B24: 86.3 | C24: =B10 -> 4.17 | D24: =C10 -> 3.92 | E24: =B24/C24 -> 20.695444 | F24: =B24/D24 -> 22.015306 | G24: 21 | H24: =F24-G24 -> 1.0153061 | I24: 82.31 | J24: Verified／Derived | K24: 收盤價：digrin（Real price，未調整） | L24: =IF(A24="2018-12","",E24) -> 20.695444
A25: 2021-12 | B25: 157.36 | C25: =B11 -> 6.84 | D25: =C11 -> 6.4 | E25: =B25/C25 -> 23.005848 | F25: =B25/D25 -> 24.5875 | G25: 23.5 | H25: =F25-G25 -> 1.0875 | J25: Verified／Derived | K25: 收盤價：digrin（Real price，未調整） | L25: =IF(A25="2018-12","",E25) -> 23.005848
A26: 2022-12 | B26: 97.38 | C26: =B12 -> 7.7 | D26: =C12 -> 7.44 | E26: =B26/C26 -> 12.646753 | F26: =B26/D26 -> 13.08871 | G26: 12.7 | H26: =F26-G26 -> 0.38870968 | J26: Verified／Derived | K26: 收盤價：digrin（Real price，未調整） | L26: =IF(A26="2018-12","",E26) -> 12.646753
A27: 2023-12 | B27: 162.07 | C27: =B13 -> 8.05 | D27: =C13 -> 8.11 | E27: =B27/C27 -> 20.132919 | F27: =B27/D27 -> 19.98397 | G27: 19.6 | H27: =F27-G27 -> 0.38397041 | J27: Verified／Derived | K27: 收盤價：digrin（Real price，未調整） | L27: =IF(A27="2018-12","",E27) -> 20.132919
A28: 2024-12 | B28: 162.63 | C28: =B14 -> 8.65 | D28: =C14 -> 8.61 | E28: =B28/C28 -> 18.801156 | F28: =B28/D28 -> 18.888502 | G28: 18.6 | H28: =F28-G28 -> 0.28850174 | J28: Verified／Derived | K28: 收盤價：digrin（Real price，未調整） | L28: =IF(A28="2018-12","",E28) -> 18.801156
A29: 2025-12 | B29: 256.99 | C29: =B15 -> 9.42 | D29: =C15 -> 8.66 | E29: =B29/C29 -> 27.281316 | F29: =B29/D29 -> 29.67552 | G29: 29.5 | H29: =F29-G29 -> 0.17551963 | I29: 256.08 | J29: Verified／Derived | K29: statmuse 2025-12-31 收盤 256.08（股利調整後）；digrin 未調整 256.99 | L29: =IF(A29="2018-12","",E29) -> 27.281316
A31: 收盤價來源1：digrin（AMAT Price History 的 Real price，未調整股利）；來源2：statmuse 年底收盤（股利調整後，2016–2020、2025）——兩者比值 0.90–1.00 隨年份遞增，符合股利調整，故未調整價可信；2021–2024 第二來源：未找到。companiesmarketcap 的年底 P/E 為 GAAP TTM 口徑，與自算 GAAP 差距見 H 欄（−1.0 至 +2.0）。
A33: 3. 分位（10 年）
A34: 統計 | B34: P/E non-GAAP（自算；規則用） | C34: P/E GAAP（自算；參考） | D34: cmc P/E（參考） | E34: 用途
A35: 25 分位 | B35: =PERCENTILE(E20:E29,0.25) -> 16.406923 | C35: =PERCENTILE(F20:F29,0.25) -> 16.816763 | D35: =PERCENTILE(G20:G29,0.25) -> 15.675 | E35: 見頂年
A36: 中位數 | B36: =PERCENTILE(E20:E29,0.5) -> 19.440052 | C36: =PERCENTILE(F20:F29,0.5) -> 20.469258 | D36: =PERCENTILE(G20:G29,0.5) -> 19.1 | E36: 中段
A37: 75 分位 | B37: =PERCENTILE(E20:E29,0.75) -> 20.554813 | C37: =PERCENTILE(F20:F29,0.75) -> 21.847144 | D37: =PERCENTILE(G20:G29,0.75) -> 20.75 | E37: 谷底
A38: 年數 | B38: =COUNT(E20:E29) -> 10 | C38: =COUNT(F20:F29) -> 10 | D38: =COUNT(G20:G29) -> 10
A40: 敏感度：去掉 2018 年（non-GAAP 極端低值 7.4）後的分位（9 年）
A41: 統計 | B41: P/E non-GAAP（不含 2018）
A42: 25 分位 | B42: =PERCENTILE(L20:L29,0.25) -> 18.44
A43: 中位數 | B43: =PERCENTILE(L20:L29,0.5) -> 20.078947
A44: 75 分位 | B44: =PERCENTILE(L20:L29,0.75) -> 20.695444
...

Sheet Recon
A1: Recon — 本模型 vs 共識、公司說法、SEMI、第四季年化。只作事後對照，不為對上數字而調整參數。差距 > 10% 的原因見 README
A3: 項目 | B3: 對照值 | C3: 模型 A | D3: 差距 A | E3: 模型 B | F3: 差距 B | G3: 模型 C | H3: 差距 C | I3: 對照來源 | J3: 說明
A4: A. 共識（stockanalysis，資料更新 2026-10-16；只作對照）
A5: FY2026 營收（錨點） | B5: =cons_rev26 -> 34260 | C5: =PL!D5 -> 34287 | D5: =C5/B5-1 -> 0.00078809107 | E5: =PL!D15 -> 34287 | F5: =E5/B5-1 -> 0.00078809107 | G5: =PL!D25 -> 34287 | H5: =G5/B5-1 -> 0.00078809107 | I5: stockanalysis | J5: 錨點＝前三季實績＋第四季指引中點，非模型預測
A6: FY2026 non-GAAP EPS（錨點） | B6: =cons_eps26 -> 12.79 | C6: =PL!D12 -> 12.76 | D6: =C6/B6-1 -> -0.0023455825 | E6: =PL!D22 -> 12.76 | F6: =E6/B6-1 -> -0.0023455825 | G6: =PL!D32 -> 12.76 | H6: =G6/B6-1 -> -0.0023455825 | I6: stockanalysis
A7: FY2027 營收 | B7: =cons_rev27 -> 46370 | C7: =PL!E5 -> 41757.639 | D7: =C7/B7-1 -> -0.099468636 | E7: =PL!E15 -> 41414.039 | F7: =E7/B7-1 -> -0.1068786 | G7: =PL!E25 -> 40470.439 | H7: =G7/B7-1 -> -0.12722796 | I7: stockanalysis
A8: FY2027 non-GAAP EPS | B8: =cons_eps27 -> 18.49 | C8: =PL!E12 -> 16.662189 | D8: =C8/B8-1 -> -0.098854056 | E8: =PL!E22 -> 16.481764 | F8: =E8/B8-1 -> -0.10861199 | G8: =PL!E32 -> 15.98628 | H8: =G8/B8-1 -> -0.13540941 | I8: stockanalysis
A9: B. 第四季年化（FY2026 Q4 指引 × 4）vs FY2027 模型
A10: 半導體系統 | B10: =g_ss_q4*4 -> 31600 | C10: =PL!E6 -> 32489.889 | D10: =C10/B10-1 -> 0.028161055 | E10: =PL!E16 -> 32489.889 | F10: =E10/B10-1 -> 0.028161055 | G10: =PL!E26 -> 32489.889 | H10: =G10/B10-1 -> 0.028161055 | I10: 公司 Q4 指引 | J10: FY2027 模型若接近第四季年化，代表 FY2027 各季大致持平於第四季水準
A11: 營收 | B11: =g_rev_q4*4 -> 41000 | C11: =PL!E5 -> 41757.639 | D11: =C11/B11-1 -> 0.018479008 | E11: =PL!E15 -> 41414.039 | F11: =E11/B11-1 -> 0.01009852 | G11: =PL!E25 -> 40470.439 | H11: =G11/B11-1 -> -0.012916114 | I11: 公司 Q4 指引
A12: C. 市場與公司說法
A13: AGS FY2026 年增（重編口徑）vs 公司 CY2026「>20%」 | B13: 0.2 | C13: =PL!D53/PL!C53-1 -> 0.19163746 | D13: =C13-B13 -> -0.0083625384 | E13: =PL!D81/PL!C81-1 -> 0.19163746 | F13: =E13-B13 -> -0.0083625384 | G13: =PL!D109/PL!C109-1 -> 0.19163746 | H13: =G13-B13 -> -0.0083625384 | I13: 公司 Q3 FY26 法說 | J13: FY 與 CY 口徑差一季
A14: AI 相關占 2025→2027 設備增量：設備市場模型 vs 公司「約 80%」 | B14: =co_ai27 -> 0.8 | C14: =ai_inc27 -> 0.62686064 | D14: =C14-B14 -> -0.17313936 | E14: =ai_inc27 -> 0.62686064 | F14: =E14-B14 -> -0.17313936 | G14: =ai_inc27 -> 0.62686064 | H14: =G14-B14 -> -0.17313936 | I14: 公司 Q3 FY26 法說；markets/equipment | J14: 公司口徑含先進封裝與先進代工邏輯、DRAM；模型 63% 較低，代表公司看的成長更集中在 AI 相關（只作對照，不改上游）
A15: D. 其他資訊（非對帳）
A16: AMAT 半導體系統 FY2026 ÷ SEMI 晶圓前段 CY2026（隱含份額） | B16: =semi_wfe26 -> 143.9 | C16: =PL!D52/1000/semi_wfe26 -> 0.18100069 | I16: SEMI 2026-07（equipment 成品） | J16: 對設備市場模型的 FY 口徑為 17.4%（Units 頁）；SEMI 較低，故對 SEMI 的份額較高；AMAT 半導體系統另含先進封裝等
A17: FY2026 前三季營收 ÷ FY2026 錨點 | C17: =SUM(Q!G7:I7)/an_rev -> 0.70105288 | J17: 第四季指引占全年 30%：AI 需求逐季上升
A18: FY2027 營收年增（情境 A） | C18: =PL!E5/PL!D5-1 -> 0.21788548 | J18: 共識隱含 FY2027 年增見下一列
A19: 共識隱含 FY2027 營收年增 | C19: =cons_rev27/cons_rev26-1 -> 0.35347344

Sheet Sens
A1: Sens — 一次動一個輸入（情境 A）：對 FY2027、FY2028 營收與 EPS 的影響。每個案例是一個完整的推導區塊（本頁下方，與 PL 同一引擎）
A3: 案例 | B3: 設定 | C3: FY2027 營收 US$M | D3: FY2027 EPS US$ | E3: 相對基準 | F3: FY2028 營收 US$M | G3: FY2028 EPS US$ | H3: 相對基準
A4: 基準（情境 A） | B4: PL 區塊 A | C4: =PL!E56 -> 41757.639 | D4: =PL!E64 -> 16.662189 | E4: =D4/D$4-1 -> 0 | F4: =PL!F56 -> 47443.964 | G4: =PL!F64 -> 19.846542 | H4: =G4/G$4-1 -> 0
A5: 份額係數 0.95 | B5: AMAT 份額 −5%（中國國產替代、競爭） | C5: =E76 -> 40133.145 | D5: =E84 -> 15.809167 | E5: =D5/D$4-1 -> -0.051195059 | F5: =F76 -> 45594.191 | G5: =F84 -> 18.865415 | H5: =G5/G$4-1 -> -0.049435639
A6: 份額係數 1.05 | B6: 份額 +5%（環繞式閘極、背面供電、先進封裝） | C6: =E108 -> 43382.134 | D6: =E116 -> 17.51521 | E6: =D6/D$4-1 -> 0.051195059 | F6: =F108 -> 49293.736 | G6: =F116 -> 20.827668 | H6: =G6/G$4-1 -> 0.049435639
A7: 第四季 DRAM 占比 26% | B7: FY2026 終端權重偏向代工邏輯 | C7: =E140 -> 41699.153 | D7: =E148 -> 16.631477 | E7: =D7/D$4-1 -> -0.001843158 | F7: =F140 -> 47370.672 | G7: =F148 -> 19.807668 | H7: =G7/G$4-1 -> -0.0019587365
A8: 第四季 DRAM 占比 34% | B8: 權重偏向 DRAM | C8: =E172 -> 41816.125 | D8: =E180 -> 16.6929 | E8: =D8/D$4-1 -> 0.001843158 | F8: =F172 -> 47517.255 | G8: =F180 -> 19.885416 | H8: =G8/G$4-1 -> 0.0019587365
A9: 會計年度權重 1/12 | B9: FY 幾乎等於日曆年 | C9: =E204 -> 41569.87 | D9: =E212 -> 16.563591 | E9: =D9/D$4-1 -> -0.0059174631 | F9: =F204 -> 46975.953 | G9: =F212 -> 19.598307 | H9: =G9/G$4-1 -> -0.012507696
A10: 會計年度權重 3/12 | B10: 設備出貨領先一季 | C10: =E236 -> 41954.036 | D10: =E244 -> 16.765317 | E10: =D10/D$4-1 -> 0.0061893455 | F10: =F236 -> 47935.385 | G10: =F244 -> 20.107193 | H10: =G10/G$4-1 -> 0.013133362
A11: 營業成本變動比例 75% | B11: 固定成本較多 → 毛利率對營收更敏感 | C11: =E268 -> 41757.639 | D11: =E276 -> 17.492673 | E11: =D11/D$4-1 -> 0.04984245 | F11: =F268 -> 47443.964 | G11: =F276 -> 21.041668 | H11: =G11/G$4-1 -> 0.06021837
A12: 營業成本變動比例 95% | B12: 幾乎全變動 → 毛利率接近持平 | C12: =E300 -> 41757.639 | D12: =E308 -> 15.949837 | E12: =D12/D$4-1 -> -0.042752557 | F12: =F300 -> 47443.964 | G12: =F308 -> 18.821417 | H12: =G12/G$4-1 -> -0.051652543
A13: 營業費用變動比例 35% | B13: FY2025 營業費用中變動部分 35% | C13: =E332 -> 41757.639 | D13: =E340 -> 17.096419 | E13: =D13/D$4-1 -> 0.026060803 | F13: =F332 -> 47443.964 | G13: =F340 -> 20.47143 | H13: =G13/G$4-1 -> 0.031485994
A14: 營業費用變動比例 75% | B14: 變動 75%（費用隨營收擴張） | C14: =E364 -> 41757.639 | D14: =E372 -> 15.975731 | E14: =D14/D$4-1 -> -0.041198495 | F14: =F364 -> 47443.964 | G14: =F372 -> 18.858681 | H14: =G14/G$4-1 -> -0.049774965
A15: AGS 成長 11% | B15: 情境 A −4 個百分點 | C15: =E396 -> 41483.839 | D15: =E404 -> 16.518416 | E15: =D15/D$4-1 -> -0.0086286579 | F15: =F396 -> 46825.176 | G15: =F404 -> 19.518334 | H15: =G15/G$4-1 -> -0.016537266
A16: AGS 成長 19% | B16: 情境 A +4 個百分點 | C16: =E428 -> 42031.439 | D16: =E436 -> 16.805961 | E16: =D16/D$4-1 -> 0.0086286579 | F16: =F428 -> 48084.656 | G16: =F436 -> 20.186367 | H16: =G16/G$4-1 -> 0.017122656
A17: 其他 −10%／年 | B17: 顯示器下滑 | C17: =E460 -> 41618.039 | D17: =E468 -> 16.588885 | E17: =D17/D$4-1 -> -0.004399418 | F17: =F460 -> 47178.724 | G17: =F468 -> 19.705857 | H17: =G17/G$4-1 -> -0.007088606
A18: 其他 +10%／年 | C18: =E492 -> 41897.239 | D18: =E500 -> 16.735492 | E18: =D18/D$4-1 -> 0.004399418 | F18: =F492 -> 47737.124 | G18: =F500 -> 20.002035 | H18: =G18/G$4-1 -> 0.007834775
A19: 淨利÷營業利益 0.85 | B19: 稅率上升 | C19: =E524 -> 41757.639 | D19: =E532 -> 15.940898 | E19: =D19/D$4-1 -> -0.043289076 | F19: =F524 -> 47443.964 | G19: =F532 -> 18.987403 | H19: =G19/G$4-1 -> -0.043289076
A20: 淨利÷營業利益 FY2026 錨點值 | B20: 含稅務利益 | C20: =E556 -> 41757.639 | D20: =E564 -> 16.857765 | E20: =D20/D$4-1 -> 0.011737766 | F20: =F556 -> 47443.964 | G20: =F564 -> 20.079496 | H20: =G20/G$4-1 -> 0.011737766
A21: 淨回購 0%／年 | C21: =E588 -> 41757.639 | D21: =E596 -> 16.495567 | E21: =D21/D$4-1 -> -0.01 | F21: =F588 -> 47443.964 | G21: =F596 -> 19.451595 | H21: =G21/G$4-1 -> -0.0199
A22: 淨回購 2.5%／年 | C22: =E620 -> 41757.639 | D22: =E628 -> 16.91853 | E22: =D22/D$4-1 -> 0.015384615 | F22: =F620 -> 47443.964 | G22: =F628 -> 20.461902 | H22: =G22/G$4-1 -> 0.031005917
A23: 關係企業規則恢復（US$600M／年） | B23: 情境 A 加上 C 的出口管制假設 | C23: =E652 -> 41157.639 | D23: =E660 -> 16.347129 | E23: =D23/D$4-1 -> -0.018908673 | F23: =F652 -> 46843.964 | G23: =F660 -> 19.528299 | H23: =G23/G$4-1 -> -0.016035152
A24: 關係企業規則恢復（US$900M／年） | B24: 影響 +50% | C24: =E684 -> 40857.639 | D24: =E692 -> 16.189599 | E24: =D24/D$4-1 -> -0.02836301 | F24: =F684 -> 46543.964 | G24: =F692 -> 19.369178 | H24: =G24/G$4-1 -> -0.024052727
A25: 中國營收 −20% | B25: 半導體系統＋AGS 中的中國部分 −20% | C25: =E716 -> 39511.613 | D25: =E724 -> 15.482801 | E25: =D25/D$4-1 -> -0.070782289 | F25: =F716 -> 44881.508 | G25: =F724 -> 18.487405 | H25: =G25/G$4-1 -> -0.068482285
A26: 中國營收 −40% | C26: =E748 -> 37265.587 | D26: =E756 -> 14.303413 | E26: =D26/D$4-1 -> -0.14156458 | F26: =F748 -> 42319.051 | G26: =F756 -> 17.128269 | H26: =G26/G$4-1 -> -0.13696457
A27: 設備市場情境 B | B27: 2028 持平、2029 −5%；AGS 11%、其他 −5% | C27: =PL!E84 -> 41414.039 | D27: =PL!E92 -> 16.481764 | E27: =D27/D$4-1 -> -0.010828367 | F27: =PL!F84 -> 43244.276 | G27: =PL!F92 -> 17.619011 | H27: =G27/G$4-1 -> -0.11223772
A28: 設備市場情境 C | B28: 2028 −20%、2029 持平；關係企業規則恢復；AGS 7%、其他 −10% | C28: =PL!E112 -> 40470.439 | D28: =PL!E120 -> 15.98628 | E28: =D28/D$4-1 -> -0.040565407 | F28: =PL!F112 -> 36326.485 | G28: =PL!F120 -> 13.949788 | H28: =G28/G$4-1 -> -0.29711743
A30: 讀法：FY2027 有 5/6 落在 CY2027，而設備市場三情境在 CY2027 以前相同，所以市場情境對 FY2027 影響小、對 FY2028 才明顯；對 FY2027 最敏感的是份額、營業成本與營業費用的固定／變動拆分、出口管制。
A60: 案例區塊：份額係數 0.95（情境 A）
A61: 項目 | B61: 單位 | C61: 2025 | D61: 2026 | E61: 2027 | F61: 2028 | G61: 2029 | H61: 說明
A62: A. 市場（日曆年 CY，US$B；讀 In 頁的設備市場成品）
A63: 晶圓代工、邏輯與其他 CY | B63: US$B | C63: =laA_25+loA_25+ofA_25 -> 78.348121 | D63: =laA_26+loA_26+ofA_26 -> 99.287198 | E63: =laA_27+loA_27+ofA_27 -> 116.28871 | F63: =laA_28+loA_28+ofA_28 -> 130.8864 | G63: =laA_29+loA_29+ofA_29 -> 139.39808
A64: DRAM（含 HBM）CY | B64: US$B | C64: =drA_25 -> 26.376109 | D64: =drA_26 -> 39.365947 | E64: =drA_27 -> 53.258733 | F64: =drA_28 -> 59.5609 | G64: =drA_29 -> 61.831293
A65: NAND CY | B65: US$B | C65: =ndA_25 -> 12.172602 | D65: =ndA_26 -> 17.503905 | E65: =ndA_27 -> 23.248027 | F65: =ndA_28 -> 26.181322 | G65: =ndA_29 -> 27.674313
A66: B. 會計年度（FY；FY(t)＝fyw×CY(t−1)＋(1−fyw)×CY(t)）
A67: 晶圓代工、邏輯與其他 FY | B67: US$B | D67: =fyw*C63+(1-fyw)*D63 -> 95.797352 | E67: =fyw*D63+(1-fyw)*E63 -> 113.45512 | F67: =fyw*E63+(1-fyw)*F63 -> 128.45346 | G67: =fyw*F63+(1-fyw)*G63 -> 137.97947
A68: DRAM（含 HBM）FY | B68: US$B | D68: =fyw*C64+(1-fyw)*D64 -> 37.200974 | E68: =fyw*D64+(1-fyw)*E64 -> 50.943268 | F68: =fyw*E64+(1-fyw)*F64 -> 58.510539 | G68: =fyw*F64+(1-fyw)*G64 -> 61.452894
A69: NAND FY | B69: US$B | D69: =fyw*C65+(1-fyw)*D65 -> 16.615355 | E69: =fyw*D65+(1-fyw)*E65 -> 22.290674 | F69: =fyw*E65+(1-fyw)*F65 -> 25.692439 | G69: =fyw*F65+(1-fyw)*G65 -> 27.425481
A70: 半導體系統需求指數（FY2026＝1；以 FY2026 終端市場權重加權） | B70: x | D70: =m_fl*D67/$D67+m_dr*D68/$D68+m_nd*D69/$D69 -> 1 | E70: =m_fl*E67/$D67+m_dr*E68/$D68+m_nd*E69/$D69 -> 1.2474042 | F70: =m_fl*F67/$D67+m_dr*F68/$D68+m_nd*F69/$D69 -> 1.420389 | G70: =m_fl*G67/$D67+m_dr*G68/$D68+m_nd*G69/$D69 -> 1.5140939 | H70: Σ 權重 × FY 市場 ÷ FY2026 市場
A71: C. 損益（US$M；FY2025 實績、FY2026 錨點＝前三季實績＋第四季指引、FY2027 起模型）
...

Sheet Sources
A1: 來源（公司新聞稿與 SEC 文件以網頁擷取工具讀取；10-Q 全文擷取在附註 5 前截斷，地區別與分部重編說明未能讀到）
A2: 公司：Q3 FY2026 新聞稿（2026-08-13） | B2: https://ir.appliedmaterials.com/news-releases/news-release-details/applied-materials-announces-third-quarter-2026-results
A3: 公司：Q2 FY2026 新聞稿（2026-05-14） | B3: https://ir.appliedmaterials.com/news-releases/news-release-details/applied-materials-announces-second-quarter-2026-results
A4: 公司：Q1 FY2026 新聞稿（2026-02-12；BIS 和解金 US$253M、分部重編） | B4: https://ir.appliedmaterials.com/news-releases/news-release-details/applied-materials-announces-first-quarter-2026-results/
A5: 公司：Q4 FY2025 新聞稿（SEC 8-K 附件，2025-11-13） | B5: https://www.sec.gov/Archives/edgar/data/6951/000162828025051998/exhibit991q42025earningsre.htm
A6: 公司：8-K（2025-09-29；BIS 關係企業規則影響 FY2026 約 US$600M） | B6: https://www.sec.gov/Archives/edgar/data/6951/000162828025043753/amat-20250929.htm
A7: 公司：10-Q Q3 FY2026（封面流通股 793,597,443） | B7: https://www.sec.gov/Archives/edgar/data/0000006951/000162828026058235/amat-20260726.htm
A8: 公司：Q1 FY2026 10-Q 分部附註（XBRL R21） | B8: https://www.sec.gov/Archives/edgar/data/6951/000162828026009694/R21.htm
A9: 公司：FY2023 Q4 新聞稿（FY2023、FY2022 EPS） | B9: https://www.sec.gov/Archives/edgar/data/6951/000000695123000035/exhibit991q42023earningsre.htm
A10: 公司：FY2021 Q4 新聞稿（FY2021、FY2020 EPS） | B10: https://investor.appliedmaterials.com/news-releases/news-release-details/applied-materials-announces-fourth-quarter-and-fiscal-year-2021
A11: 公司：FY2020 Q4 新聞稿（FY2020、FY2019 EPS） | B11: https://www.sec.gov/Archives/edgar/data/6951/000000695120000041/exhibit991q42020earnin.htm
A12: 公司：FY2018 Q4 新聞稿（FY2018、FY2017 EPS） | B12: https://www.sec.gov/Archives/edgar/data/0000006951/000000695118000032/exhibit991q42018earningsre.htm
A13: 公司：FY2016 Q4 新聞稿（FY2016 EPS） | B13: https://www.sec.gov/Archives/edgar/data/6951/000000695116000063/exhibit991earningsreleaseq.htm
... A25: companiesmarketcap：年底 P/E（GAAP TTM） | B25: https://companiesmarketcap.com/applied-materials/pe-ratio/
A26: 市場層：markets/equipment 成品（本 repo）；tools/cycle_position.py
A27: SemiAnalysis | B27: 未使用
