Workbook

Sheet README
A1: Ibiden（4062）收支與估值模型 v0.2（AI 半導體 Project：載板與 PCB 樣板） 2026-10-25
A2: 版本：v0.2（2026-10-25：目標價改為 DCF 與 Comparable 加權、三情境延伸到 FY2032；FY2025–FY2029 數值不變）。前版：v0.1（初版）。Ibiden 在 AI 加速器載板的有效金額與份額在本模型 Units 頁建立，為本專案權威資料（規則第 13 條）。
A3: 模型命題：Ibiden 的 AI 伺服器載板營收＝AI 加速器顆數（本專案網通模型）× Ibiden 份額 × 每顆載板金額（面積、層數逐年增加）× 短缺溢價；電子事業的非 AI 部分、陶瓷與其他事業另依成長率推。股價約 54–65 倍前瞻 EPS：2028 年產能擴到 2.5 倍、競爭者同時擴產之後，短缺溢價能否守住電子事業約 29% 的營益率？
A4: 核心問題：短缺溢價回落多少、何時回落，FY2028 EPS 會少多少；現價隱含的溢價路徑合不合理。
A6: 會計年度 4 月至隔年 3 月：FY(t)＝t/4–(t+1)/3，對照 CY(t) 的加速器顆數（重疊 9 個月，不平移）。預測期 FY2027–FY2029（三年）。金額：十億日圓；EPS：日圓（2026-10-01 一拆二後）。
A8: 驅動因子 → 推導量（全部唯讀上游，不修改）
A9: AI 載板：markets/network 的加速器顆數（NVIDIA ＋ 權重 × 非 NVIDIA）× 每顆有效金額（FY2026 校準）× 金額指數（+18%／年，Analogy）× 份額相對值（Assumed）× 溢價指數（Assumed）。
A10: 利潤率：AI 載板營益率 FY2026 校準（非 AI 部分 15%，Assumed），之後＝ 1 −（1 − 校準值）÷ 溢價指數（成本不變）。陶瓷、其他事業營益率沿用 FY2026 預測。淨利 ÷ 營業利益 0.661（FY2026 預測）。
A11: 校準：FY2026 ＝ 公司 2026-08-04 上修後預測（營收 5,500 億、營業利益 1,270 億、淨利 840 億、EPS 149.68）；AI 伺服器載板占電子事業 65%（Assumed，公司未揭露）。
A12: 估值：Val 第 0 節目標價＝0.5 × DCF 目標價（股東現金流＝EPS ×（1 − tp_g ÷ tp_roe），FY2027–FY2032 明確期＋永續，r 10%、g 4%，三情境權重 0.3／0.5／0.2，推到 12 個月後）＋0.5 × Comparable 目標價（欣興、南電、景碩、三星電機、AT&S 前瞻 P/E 中位數 × 12 個月後前瞻 EPS）；另列 Comparable 單獨目標價、市場共識目標價與差距拆解（EPS 因素、倍數因素）、DCF 價格帶、十年 P/E 分位檢查（只作檢查）。會計年度 4 月制：12 個月後前瞻 EPS＝½ FY2027＋½ FY2028。（v0.1.1 原估值說明，保留作參考：現價 ÷ FY2026–FY2028 EPS 與 what must be true；十年 P/E 規則值待 Bloomberg（本版不計）；循環位置以本模型營收最高年判定。）
A13: 標記：Verified、Interested-party、Analogy、Assumed、Derived。SemiAnalysis 未使用。
A15: 已知限制：(1) AI 載板營收公司未揭露，以 Assumed 切分校準；(2) 溢價指數與份額相對值皆為 Assumed，是 FY2028 EPS 最敏感的輸入（Sens）；(3) 未設產能上限（2024 基準面積未找到）；(4) FY2026 錨點為公司預測，Q2 決算後更新；(5) 十年 P/E 規則值待 Bloomberg；(6) CB 轉換稀釋只在 Sens；(7) R4 產業部署路徑未建（Recon 預留列）。
... A19: 先驗：v0.1 的 Andy 合理 P/E 25x 對照（Val 第 4 節）保留不動，不進目標價；本版未新增先驗。

Sheet In
A1: In — 輸入（藍字；基準欄 E，低 D、高 F）。金額：十億日圓（¥B）；顆數：百萬顆；比例：%。每個輸入附兩個來源（找不到者寫「未找到」）；公司原文算一個
A2: 標記：Verified／Interested-party／Analogy／Assumed／Derived；Analogy、Assumed 給低／高區間。SemiAnalysis 未使用。公司原文＝Ibiden 決算短信與補足資料（TDnet）；公司預測為 Interested-party
A3: 鍵 | B3: 項目 | C3: 單位 | D3: 低 | E3: 基準 | F3: 高 | G3: 標記 | H3: 來源1 | I3: 來源2／說明
A4: A. 加速器顆數（讀 markets/network In 頁；CY2026–CY2028 為輸入、CY2029＝CY2028 ×（1＋成長率））
A5: u_bw_26 | B5: NVIDIA Blackwell（B200／B300） 顆數 2026 | C5: 百萬顆 | E5: 5.4 | G5: Derived | H5: markets/network/dist/20261023_AI網通市場模型_v0.2.2.xlsx｜In!E5 | I5: 唯讀上游；不在本模型另訂
A6: u_bw_27 | B6: NVIDIA Blackwell（B200／B300） 顆數 2027 | C6: 百萬顆 | E6: 2.4 | G6: Derived | H6: markets/network/dist/20261023_AI網通市場模型_v0.2.2.xlsx｜In!E6 | I6: 唯讀上游；不在本模型另訂
A7: u_bw_28 | B7: NVIDIA Blackwell（B200／B300） 顆數 2028 | C7: 百萬顆 | E7: 0.5 | G7: Derived | H7: markets/network/dist/20261023_AI網通市場模型_v0.2.2.xlsx｜In!E7 | I7: 唯讀上游；不在本模型另訂
A8: g29_bw | B8: NVIDIA Blackwell（B200／B300） 2029 顆數成長 | C8: % | E8: -0.5 | G8: Derived | H8: markets/network/dist/20261023_AI網通市場模型_v0.2.2.xlsx｜In!E8 | I8: 同上
A9: u_rb_26 | B9: NVIDIA Rubin 顆數 2026 | C9: 百萬顆 | E9: 1.7 | G9: Derived | H9: markets/network/dist/20261023_AI網通市場模型_v0.2.2.xlsx｜In!E9 | I9: 唯讀上游；不在本模型另訂
A10: u_rb_27 | B10: NVIDIA Rubin 顆數 2027 | C10: 百萬顆 | E10: 7 | G10: Derived | H10: markets/network/dist/20261023_AI網通市場模型_v0.2.2.xlsx｜In!E10 | I10: 唯讀上游；不在本模型另訂
A11: u_rb_28 | B11: NVIDIA Rubin 顆數 2028 | C11: 百萬顆 | E11: 7 | G11: Derived | H11: markets/network/dist/20261023_AI網通市場模型_v0.2.2.xlsx｜In!E11 | I11: 唯讀上游；不在本模型另訂
A12: g29_rb | B12: NVIDIA Rubin 2029 顆數成長 | C12: % | E12: 0.15 | G12: Derived | H12: markets/network/dist/20261023_AI網通市場模型_v0.2.2.xlsx｜In!E12 | I12: 同上
A13: u_ru_26 | B13: NVIDIA Rubin Ultra 顆數 2026 | C13: 百萬顆 | E13: 0 | G13: Derived | H13: markets/network/dist/20261023_AI網通市場模型_v0.2.2.xlsx｜In!E13 | I13: 唯讀上游；不在本模型另訂
A14: u_ru_27 | B14: NVIDIA Rubin Ultra 顆數 2027 | C14: 百萬顆 | E14: 0.3 | G14: Derived | H14: markets/network/dist/20261023_AI網通市場模型_v0.2.2.xlsx｜In!E14 | I14: 唯讀上游；不在本模型另訂
A15: u_ru_28 | B15: NVIDIA Rubin Ultra 顆數 2028 | C15: 百萬顆 | E15: 2 | G15: Derived | H15: markets/network/dist/20261023_AI網通市場模型_v0.2.2.xlsx｜In!E15 | I15: 唯讀上游；不在本模型另訂
A16: g29_ru | B16: NVIDIA Rubin Ultra 2029 顆數成長 | C16: % | E16: 0.15 | G16: Derived | H16: markets/network/dist/20261023_AI網通市場模型_v0.2.2.xlsx｜In!E16 | I16: 同上
... A46: um29_C | B46: 情境 C：2029 顆數 ÷ 基準 | C46: x | E46: 0.6 | G46: Assumed | H46: tsmc/dist/20261025_台積電模型_v0.2.2.xlsx｜In!E42 | I46: 同上
A47: B. Ibiden 份額與每顆載板金額（本專案權威：晶片商載板份額，規則第 13 條）
A48: w_ot | B48: 非 NVIDIA 加速器的權重（Ibiden 份額 × 每顆載板金額，相對 NVIDIA） | C48: x | D48: 0.2 | E48: 0.4 | F48: 0.6 | G48: Assumed | H48: 公開資料只有 NVIDIA 份額：BofA（經 thebuildout 2026-03-26）Ibiden 占 GPU 載板 70–80%；高階 FC-BGA 整體約 35%（Data Gravity 2026-06-14） | I48: ASIC 多由欣興、Shinko、AT&S 等分食（第三方研究，Interested-party）；每顆 ASIC 載板金額相對 GPU：未找到
A49: ai_e | B49: FY2026 AI 伺服器載板 ÷ 電子事業營收 | C49: % | D49: 0.55 | E49: 0.65 | F49: 0.75 | G49: Assumed | H49: 公司未揭露：未找到（決算短信只說「生成 AI 伺服器向け・汎用サーバー向け高機能 IC パッケージ基板」帶動） | I49: semi-connect 2026：AI 高階載板營收多數為 NVIDIA 向（估計，Interested-party）
A50: g_asp | B50: 每顆載板金額年增（面積、層數） | C50: % | D50: 0.1 | E50: 0.18 | F50: 0.22 | G50: Analogy | H50: Tom's Hardware：The state of ABF substrates in 2026：Ibiden 路線圖 2026 年 90×90 mm、2028 年 110×110 mm；每片 AI 伺服器載板的 SAP 負荷 2026 年為 2024 年 1.8 倍、2028 年 2.5 倍（→ 2026→2028 年約 +18%／年） | I50: Data Gravity 2026-06-14：ABF 載板平均單價 2024 $65 → 2025 $82（+26%，全品項）
A51: rel_27 | B51: Ibiden 份額 2027 ÷ 2026（相對值） | C51: x | D51: 0.85 | E51: 0.95 | F51: 1 | G51: Assumed | H51: 第三方研究：欣興 2025 年拿到 NVIDIA AI 載板約 30% 顆數（Encyclopedia of Stocks 2026-03-04） | I51: 三星電機獲 NVIDIA 載板擴產合作（Hardware Busters 2026）
A52: rel_28 | B52: Ibiden 份額 2028 ÷ 2026 | C52: x | D52: 0.75 | E52: 0.88 | F52: 1 | G52: Assumed | H52: 同上；競爭者擴產：欣興 2026 資本支出 NT$340 億、景碩 3 年 NT$235 億（Tom's Hardware：The state of ABF substrates in 2026） | I52: —
A53: rel_29 | B53: Ibiden 份額 2029 ÷ 2026 | C53: x | D53: 0.7 | E53: 0.85 | F53: 1 | G53: Assumed | H53: 同上 | I53: —
A54: C. 短缺溢價（價格指數；2026＝1）與 AI 載板利潤率
A55: pp_27 | B55: 價格溢價指數 2027 | C55: x | D55: 0.95 | E55: 1 | F55: 1.05 | G55: Assumed | H55: Tom's Hardware：The state of ABF substrates in 2026（未具名供應鏈分析）：ABF 供需缺口 2026 下半年約 10%、2027 約 21%、2028 超過 40% | I55: BofA：短缺延續到 2028（經 thebuildout）
A56: pp_28 | B56: 價格溢價指數 2028 | C56: x | D56: 0.85 | E56: 0.95 | F56: 1.05 | G56: Assumed | H56: Ibiden 產能 2028 年為 2024 年 2.5–2.8 倍（公司路線圖，Interested-party；Data Gravity 2026-06-14、Tom's Hardware：The state of ABF substrates in 2026） | I56: 欣興、景碩、三星電機同時擴產（同上）
A57: pp_29 | B57: 價格溢價指數 2029 | C57: x | D57: 0.75 | E57: 0.9 | F57: 1 | G57: Assumed | H57: 同上：新產能到位後溢價回落 | I57: —
A58: m_ne | B58: 電子事業非 AI 部分營業利益率 | C58: % | D58: 0.1 | E58: 0.15 | F58: 0.2 | G58: Assumed | H58: FY2024 電子事業營益率 13.6%（26.8 ÷ 197.2，AI 比重較低時；公司：2026 年 3 月期決算短信（Sources 頁）） | I58: FY2025 18.6%（45.2 ÷ 243.3）
A59: g_ne | B59: 電子事業非 AI 營收年增（通用伺服器、PC 載板等） | C59: % | D59: 0 | E59: 0.05 | F59: 0.1 | G59: Assumed | H59: SEMICON.TODAY 2026-08：通用伺服器市場緩步成長 | I59: PC：未找到
A60: D. 陶瓷、其他事業與全公司
A61: g_cer | B61: 陶瓷事業營收年增（DPF、汽車排氣） | C61: % | D61: -0.05 | E61: 0 | F61: 0.03 | G61: Assumed | H61: FY2025 −1.8%（84.1 → 82.6；公司：2026 年 3 月期決算短信（Sources 頁）） | I61: FY2026 預測 84.0（+1.8%；公司：Q1 補足資料（分部門預測、設備投資、匯率前提；Sources 頁））
A62: m_cer | B62: 陶瓷事業營益率 | C62: % | D62: 0.05 | E62: 0.077 | F62: 0.1 | G62: Derived | H62: FY2026 預測 6.5 ÷ 84.0（公司：Q1 補足資料（分部門預測、設備投資、匯率前提；Sources 頁）） | I62: FY2025 9.3%（7.6 ÷ 82.6）
A63: g_oth | B63: 其他事業營收年增（建材等） | C63: % | D63: 0 | E63: 0.03 | F63: 0.05 | G63: Assumed | H63: FY2025 +2.5%（88.1 → 90.3） | I63: FY2026 預測 91.0（+0.7%）
A64: m_oth | B64: 其他事業營益率 | C64: % | D64: 0.09 | E64: 0.115 | F64: 0.13 | G64: Derived | H64: FY2026 預測 10.5 ÷ 91.0（公司：Q1 補足資料（分部門預測、設備投資、匯率前提；Sources 頁）） | I64: FY2025 9.9%（9.0 ÷ 90.3）
A65: ni_oi | B65: 淨利 ÷ 營業利益（稅、非營業、少數股權） | C65: x | D65: 0.62 | E65: 0.661 | F65: 0.7 | G65: Derived | H65: FY2026 預測 84 ÷ 127（公司：Q1 補足資料（分部門預測、設備投資、匯率前提；Sources 頁）） | I65: FY2025 1.03（含政策持股出售利益，不具代表性）
A66: sh_g | B66: 股數年變動（2031 年到期 CB 轉換） | C66: % | D66: 0 | E66: 0 | F66: 0.03 | G66: Assumed | H66: CB 轉換價 ¥2,243.1（分割後；SEMICON.TODAY 2026-08），遠低於現價 | I66: CB 發行額：未找到；FY2025 稀釋 EPS 比基本低 5.8%（214.91 ÷ 228.16）
A67: fx | B67: 匯率（美元換算用） | C67: ¥／US$ | E67: 152 | G67: Interested-party | H67: 公司：Q1 補足資料（分部門預測、設備投資、匯率前提；Sources 頁）：FY2026 前提 ¥152 | I67: —
A68: E. FY2026 錨點（公司 2026-08-04 上修後預測；Q2 決算後更新）
A69: f_rev | B69: FY2026 營收預測 | C69: ¥B | E69: 550 | G69: Interested-party | H69: 公司：Q1 補足資料（分部門預測、設備投資、匯率前提；Sources 頁） | I69: LIMO 2026-08-15：5,500 億（+32.1%）
...

Sheet Q
A1: Q — FY2025 實績與 FY2026 錨點（¥B）。FY2026 錨點＝公司 2026-08-04 上修後的全年預測（Q1 公布時；分部門預測取自 Q1 補足資料）。Q2 決算（預計 10 月底或 11 月初）後更新
A2: 公司未揭露 AI 伺服器載板營收；本模型以 In 頁 ai_e（Assumed）切分電子事業，並據此校準每顆有效金額與 AI 載板營業利益率（Derived）
A3: 項目 | B3: FY2025A | C3: FY2026 錨點 | D3: 年增 | E3: 標記 | F3: 說明
A4: 營收 | B4: =a_rev -> 416.201 | C4: =f_rev -> 550 | D4: =C4/B4-1 -> 0.32147688 | E4: Verified／Interested-party
A5: 電子事業 | B5: =a_e -> 243.316 | C5: =f_e -> 375 | D5: =C5/B5-1 -> 0.54120567 | E5: Verified／Interested-party
A6: 陶瓷事業 | B6: =a_cer -> 82.554 | C6: =f_cer -> 84 | D6: =C6/B6-1 -> 0.017515808 | E6: Verified／Interested-party
A7: 其他事業 | B7: =a_oth -> 90.33 | C7: =f_oth -> 91 | D7: =C7/B7-1 -> 0.0074172479 | E7: Verified／Interested-party
A8: 營業利益 | B8: =a_oi -> 62.027 | C8: =f_oi -> 127 | D8: =C8/B8-1 -> 1.0474954 | E8: Verified／Interested-party
A9: 電子事業 | B9: =a_eoi -> 45.248 | C9: =f_eoi -> 110 | D9: =C9/B9-1 -> 1.4310467 | E9: Verified／Interested-party
A10: 陶瓷事業 | B10: =a_ceroi -> 7.646 | C10: =f_ceroi -> 6.5 | D10: =C10/B10-1 -> -0.14988229 | E10: Verified／Interested-party
A11: 其他事業 | B11: =a_othoi -> 8.964 | C11: =f_othoi -> 10.5 | D11: =C11/B11-1 -> 0.17135207 | E11: Verified／Interested-party
A12: 調整（全公司 − 三事業） | B12: =a_oi-a_eoi-a_ceroi-a_othoi -> 0.169 | C12: =f_oi-f_eoi-f_ceroi-f_othoi -> 0 | D12: =C12/B12-1 -> -1 | E12: Verified／Interested-party
A13: 淨利（歸屬母公司） | B13: =a_ni -> 63.713 | C13: =f_ni -> 84 | D13: =C13/B13-1 -> 0.31841225 | E13: Verified／Interested-party | F13: FY2025 含政策持股出售利益（稅後約 345 億，Quartr 摘要），淨利高於營業利益
A14: EPS（分割後，日圓） | B14: =a_eps -> 114.08 | C14: =f_eps -> 149.68 | D14: =C14/B14-1 -> 0.31206171 | E14: Verified／Interested-party
A16: 比率
A17: 電子事業營益率 | B17: =B9/B5 -> 0.18596393 | C17: =C9/C5 -> 0.29333333 | E17: Derived
A18: 營業利益率 | B18: =B8/B4 -> 0.14903136 | C18: =C8/C4 -> 0.23090909 | E18: Derived
A19: 電子事業 ÷ 營收 | B19: =B5/B4 -> 0.58461176 | C19: =C5/C4 -> 0.68181818 | E19: Derived
A20: 毛利率（FY2026 預測未揭露） | B20: =a_gp/a_rev -> 0.31635676 | E20: Derived
A21: 股數（十億股＝淨利 ÷ EPS） | B21: =B13/B14 -> 0.55849404 | C21: =C13/C14 -> 0.56119722 | E21: Derived | F21: FY2025 股數含政策持股出售前後變動，只作參考；預測期用 FY2026 錨點股數

Sheet Units
A1: Units — Ibiden 在 AI 加速器載板的有效金額與份額（本專案權威，規則第 13 條）。顆數取自 markets/network（情境 A）
A3: 項目 | B3: 單位 | C3: FY2026（CY2026） | D3: FY2027 | E3: FY2028 | F3: FY2029 | G3: 說明
A4: NVIDIA 加速器顆數 | B4: 百萬顆 | C4: =PL!D63 -> 7.6 | D4: =PL!E63 -> 9.7 | E4: =PL!F63 -> 9.5 | F4: =PL!G63 -> 10.6 | G4: markets/network
A5: 非 NVIDIA 加速器顆數 | B5: 百萬顆 | C5: =PL!D64 -> 7.6 | D5: =PL!E64 -> 14 | E5: =PL!F64 -> 17 | F5: =PL!G64 -> 19.55
A6: 有效顆數 | B6: 百萬顆 | C6: =PL!D65 -> 10.64 | D6: =PL!E65 -> 15.3 | E6: =PL!F65 -> 16.3 | F6: =PL!G65 -> 18.42 | G6: 非 NVIDIA × 權重 w_ot
A7: 每顆 NVIDIA 加速器的 Ibiden 營收（美元） | B7: US$ | C7: =PL!$D$67*PL!D68*PL!D69*PL!D70*1000/fx -> 150.71602 | D7: =PL!$D$67*PL!E68*PL!E69*PL!E70*1000/fx -> 168.95266 | E7: =PL!$D$67*PL!F68*PL!F69*PL!F70*1000/fx -> 175.44044 | F7: =PL!$D$67*PL!G68*PL!G69*PL!G70*1000/fx -> 189.4379 | G7: ＝份額 × 每顆載板金額
A8: 每顆 NVIDIA 載板金額（美元；假設 FY2026 份額 70%） | B8: US$ | C8: =PL!$D$67*PL!D68*PL!D70*1000/fx/0.7 -> 215.3086 | D8: =PL!$D$67*PL!E68*PL!E70*1000/fx/0.7 -> 254.06414 | E8: =PL!$D$67*PL!F68*PL!F70*1000/fx/0.7 -> 284.8059 | F8: =PL!$D$67*PL!G68*PL!G70*1000/fx/0.7 -> 318.38302 | G8: BofA：Ibiden 占 GPU 載板 70–80%（Interested-party）；先驗比對推導 $150–300
A9: AI 伺服器載板營收 | B9: ¥B | C9: =PL!D71 -> 243.75 | D9: =PL!E71 -> 392.91629 | E9: =PL!F71 -> 434.67123 | F9: =PL!G71 -> 530.3958
A10: AI 伺服器載板營收（美元） | B10: US$B | C10: =PL!D71/fx -> 1.6036184 | D10: =PL!E71/fx -> 2.5849756 | E10: =PL!F71/fx -> 2.8596791 | F10: =PL!G71/fx -> 3.4894461 | G10: ÷ 匯率 152
A11: AI 載板營收 ÷ AI IT 資本支出 | B11: % | C11: =PL!D71/fx/itc_26 -> 0.0020509963 | D11: =PL!E71/fx/itc_27 -> 0.0016513723 | E11: =PL!F71/fx/itc_28 -> 0.0014411788 | F11: =PL!G71/fx/itc_29 -> 0.0015437361 | G11: × 每 GW IT capex 即每 GW 營收
A12: 每 GW Ibiden 營收（VR200 每 GW IT capex 37.59B） | B12: US$M | C12: =PL!D71/fx/itc_26*37.59*1000 -> 77.096949 | D12: =PL!E71/fx/itc_27*37.59*1000 -> 62.075085 | E12: =PL!F71/fx/itc_28*37.59*1000 -> 54.173912 | F12: =PL!G71/fx/itc_29*37.59*1000 -> 58.02904 | G12: Tokenomics IF_CapexIT（VR200 基準，經橋接表）
A14: 讀法：每顆 NVIDIA 加速器 Ibiden 只分到約 1–2 百美元，每 GW 約數千萬美元；瓶頸反映在利潤率（電子事業營益率）與倍數，不在營收規模。

Sheet PL
A1: PL — Ibiden 損益（¥B；EPS 日圓）。FY2025A 實績、FY2026 錨點（公司上修後預測），FY2027 起為模型。FY(t)＝t/4–(t+1)/3，對照 CY(t) 顆數。三情境各一個完整推導區塊（本頁下方），頂端為摘要。FY2026–FY2027 三情境相同（顆數係數從 CY2028 開始）
A3: 情境／項目 | B3: 單位 | C3: FY2025A | D3: FY2026（錨點） | E3: FY2027 | F3: FY2028 | G3: FY2029 | H3: 說明
A4: 情境 A
A5: 營收 | B5: ¥B | C5: =C82 -> 416.2 | D5: =D82 -> 550 | E5: =E82 -> 708.45879 | F5: =F82 -> 759.91625 | G5: =G82 -> 865.77224
A6: 營收年增 | B6: % | D6: =D83 -> 0.32148006 | E6: =E83 -> 0.2881069 | F6: =F83 -> 0.072632957 | G6: =G83 -> 0.13929955
A7: AI 伺服器載板 | B7: ¥B | D7: =D71 -> 243.75 | E7: =E71 -> 392.91629 | F7: =F71 -> 434.67123 | G7: =G71 -> 530.3958
A8: 電子事業 | B8: ¥B | C8: =C74 -> 243.316 | D8: =D74 -> 375 | E8: =E74 -> 530.72879 | F8: =F74 -> 579.37435 | G8: =G74 -> 682.33408
A9: 電子事業營益率 | B9: % | C9: =C78 -> 0.18596393 | D9: =D78 -> 0.29333333 | E9: =E78 -> 0.31325302 | F9: =F78 -> 0.29058187 | G9: =G78 -> 0.26704177
A10: 營業利益率 | B10: % | C10: =C87 -> 0.14903172 | D10: =D87 -> 0.23090909 | E10: =E87 -> 0.25901203 | F10: =F87 -> 0.24466643 | G10: =G87 -> 0.23114057
A11: 淨利 | B11: ¥B | C11: =C88 -> 63.713 | D11: =D88 -> 84 | E11: =E88 -> 121.29307 | F11: =F88 -> 122.89709 | G11: =G88 -> 132.27608
A12: EPS | B12: ¥ | C12: =C90 -> 114.08 | D12: =D90 -> 149.68 | E12: =E90 -> 216.1327 | F12: =F90 -> 218.9909 | G12: =G90 -> 235.70337
A13: EPS 年增 | B13: % | D13: =D91 -> 0.31206171 | E13: =E91 -> 0.44396512 | F13: =F91 -> 0.013224293 | G13: =G91 -> 0.076315806
A15: 情境 B
A16: 營收 | B16: ¥B | C16: =C116 -> 416.2 | D16: =D116 -> 550 | E16: =E116 -> 708.45879 | F16: =F116 -> 672.98201 | G16: =G116 -> 786.21287
A17: 營收年增 | B17: % | D17: =D117 -> 0.32148006 | E17: =E117 -> 0.2881069 | F17: =F117 -> -0.050076008 | G17: =G117 -> 0.16825244
A18: AI 伺服器載板 | B18: ¥B | D18: =D105 -> 243.75 | E18: =E105 -> 392.91629 | F18: =F105 -> 347.73698 | G18: =G105 -> 450.83643
A19: 電子事業 | B19: ¥B | C19: =C108 -> 243.316 | D19: =D108 -> 375 | E19: =E108 -> 530.72879 | F19: =F108 -> 492.44011 | G19: =G108 -> 602.77471
A20: 電子事業營益率 | B20: % | C20: =C112 -> 0.18596393 | D20: =D112 -> 0.29333333 | E20: =E112 -> 0.31325302 | F20: =F112 -> 0.28231989 | G20: =G112 -> 0.26261646
A21: 營業利益率 | B21: % | C21: =C121 -> 0.14903172 | D21: =D121 -> 0.23090909 | E21: =E121 -> 0.25901203 | F21: =F121 -> 0.23268966 | G21: =G121 -> 0.22411481
A22: 淨利 | B22: ¥B | C22: =C122 -> 63.713 | D22: =D122 -> 84 | E22: =E122 -> 121.29307 | F22: =F122 -> 103.50993 | G22: =G122 -> 116.46949
A23: EPS | B23: ¥ | C23: =C124 -> 114.08 | D23: =D124 -> 149.68 | E23: =E124 -> 216.1327 | F23: =F124 -> 184.44483 | G23: =G124 -> 207.53753
A24: EPS 年增 | B24: % | D24: =D125 -> 0.31206171 | E24: =E125 -> 0.44396512 | F24: =F125 -> -0.14661302 | G24: =G125 -> 0.12520113
A26: 情境 C
A27: 營收 | B27: ¥B | C27: =C150 -> 416.2 | D27: =D150 -> 550 | E27: =E150 -> 708.45879 | F27: =F150 -> 586.04776 | G27: =G150 -> 653.61392
A28: 營收年增 | B28: % | D28: =D151 -> 0.32148006 | E28: =E151 -> 0.2881069 | F28: =F151 -> -0.17278497 | G28: =G151 -> 0.11529122
A29: AI 伺服器載板 | B29: ¥B | D29: =D139 -> 243.75 | E29: =E139 -> 392.91629 | F29: =F139 -> 260.80274 | G29: =G139 -> 318.23748
A30: 電子事業 | B30: ¥B | C30: =C142 -> 243.316 | D30: =D142 -> 375 | E30: =E142 -> 530.72879 | F30: =F142 -> 405.50586 | G30: =G142 -> 470.17576
A31: 電子事業營益率 | B31: % | C31: =C146 -> 0.18596393 | D31: =D146 -> 0.29333333 | E31: =E146 -> 0.31325302 | F31: =F146 -> 0.27051544 | G31: =G146 -> 0.25191285
A32: 營業利益率 | B32: % | C32: =C155 -> 0.14903172 | D32: =D155 -> 0.23090909 | E32: =E155 -> 0.25901203 | F32: =F155 -> 0.21715963 | G32: =G155 -> 0.20860435
A33: 淨利 | B33: ¥B | C33: =C156 -> 63.713 | D33: =D156 -> 84 | E33: =E156 -> 121.29307 | F33: =F156 -> 84.122769 | G33: =G156 -> 90.125173
A34: EPS | B34: ¥ | C34: =C158 -> 114.08 | D34: =D158 -> 149.68 | E34: =E158 -> 216.1327 | F34: =F158 -> 149.89876 | G34: =G158 -> 160.59448
A35: EPS 年增 | B35: % | D35: =D159 -> 0.31206171 | E35: =E159 -> 0.44396512 | F35: =F159 -> -0.30645033 | G35: =G159 -> 0.071352905
A37: 核對（應為 0）：FY2026 模型 − 錨點（校準恆等式）
A38: 情境 A：營收差（¥B） | D38: =D82-q26_rev -> 0
A39: 情境 A：營業利益差（¥B） | D39: =D86-q26_oi -> 0
A40: 情境 A：EPS 差（日圓） | D40: =D90-q26_eps -> 0
A60: 情境 A：基準（顆數係數 1.0）
A61: 項目 | B61: 單位 | C61: FY2025A | D61: FY2026（錨點） | E61: FY2027 | F61: FY2028 | G61: FY2029 | H61: 說明
A62: A. AI 伺服器載板（D 欄＝FY2026 校準年；FY(t) 對照 CY(t) 顆數）
A63: NVIDIA 加速器顆數 × 情境係數 | B63: 百萬顆 | D63: =(u_bw_26+u_rb_26+u_ru_26+u_hp_26)*1 -> 7.6 | E63: =(u_bw_27+u_rb_27+u_ru_27+u_hp_27)*1 -> 9.7 | F63: =(u_bw_28+u_rb_28+u_ru_28+u_hp_28)*um28_A -> 9.5 | G63: =(u_bw_28*(1+g29_bw)+u_rb_28*(1+g29_rb)+u_ru_28*(1+g29_ru)+u_hp_28*(1+g29_hp))*um29_A -> 10.6 | H63: markets/network In：Blackwell、Rubin、Rubin Ultra、Hopper
...

Sheet Val
A1: Val — P/E 估值（日圓）。結論用「現價 ÷ FY2026–FY2028 EPS（模型）」與 what must be true。十年 P/E 規則值待 Bloomberg（10-27 抓取單加 4062）：公開資料商的 Ibiden 十年 P/E 本版未取得，規則值本版不計
A2: 循環位置：Ibiden 不套設備股見頂年；以本模型營收最高的會計年度為見頂年（比照 NVIDIA、Arista）。營收到 FY2029 仍在增加時，見頂年未知，判為中段
A3: 目標價：見第 0 節（本頁第 61 列；v0.2 新增，DCF 與 Comparable 加權）。第 36 列「舊法：規則值情境加權（參考）」不再是目標價，只作參考
A4: 1. 價格與市場隱含倍數
A5: 項目 | B5: A | C5: B | D5: C | E5: 說明
A6: 現價（2026-10-23 收盤，分割後） | B6: =px -> 8512
A7: 現價 ÷ FY2026 EPS（錨點） | B7: =px/PL!D12 -> 56.867985 | C7: =px/PL!D23 -> 56.867985 | D7: =px/PL!D34 -> 56.867985
A8: 現價 ÷ FY2027 EPS（模型） | B8: =px/PL!E12 -> 39.383212 | C8: =px/PL!E23 -> 39.383212 | D8: =px/PL!E34 -> 39.383212 | E8: FY2027 三情境相同（顆數係數從 CY2028 開始）
A9: 現價 ÷ FY2028 EPS（模型） | B9: =px/PL!F12 -> 38.869195 | C9: =px/PL!F23 -> 46.149301 | D9: =px/PL!F34 -> 56.784992
A10: 現價 ÷ FY2029 EPS（模型） | B10: =px/PL!G12 -> 36.113188 | C10: =px/PL!G23 -> 41.014268 | D10: =px/PL!G34 -> 53.003069
A11: 前瞻 P/E（stockanalysis） | B11: =pe_fwd_sa -> 53.97 | E11: 口徑：未來 12 個月
A12: 隱含未來 12 月 EPS ＝ 取得時價格（10-16 9,764）÷ 前瞻 P/E | B12: =cons_feps -> 180.91532
A13: 近 12 月 P/E（stockanalysis） | B13: =pe_ttm -> 83.85
A15: 2. 循環位置（本模型營收最高年）
A16: 情境 | B16: 營收最高年（FY2026–FY2029） | C16: FY2027 判定 | D16: 見頂年是否未知 | E16: 說明
A17: A | B17: =INDEX({2026,2027,2028,2029},MATCH(MAX(PL!D82:G82),PL!D82:G82,0)) -> 2029 | C17: =IF(B17=2029,"中段",IF(2027<B17,"中段",IF(2027=B17,"見頂","谷底"))) -> 中段 | D17: =IF(B17=2029,"是：營收到觀測期末仍在增加","否") -> 是：營收到觀測期末仍在增加 | E17: tools/cycle_position.py excel_rule；營收最高年取代設備市場見頂年；對應倍數待十年 P/E
A18: B | B18: =INDEX({2026,2027,2028,2029},MATCH(MAX(PL!D116:G116),PL!D116:G116,0)) -> 2029 | C18: =IF(B18=2029,"中段",IF(2027<B18,"中段",IF(2027=B18,"見頂","谷底"))) -> 中段 | D18: =IF(B18=2029,"是：營收到觀測期末仍在增加","否") -> 是：營收到觀測期末仍在增加 | E18: 同上
A19: C | B19: =INDEX({2026,2027,2028,2029},MATCH(MAX(PL!D150:G150),PL!D150:G150,0)) -> 2027 | C19: =IF(B19=2029,"中段",IF(2027<B19,"中段",IF(2027=B19,"見頂","谷底"))) -> 見頂 | D19: =IF(B19=2029,"是：營收到觀測期末仍在增加","否") -> 否 | E19: 同上
A21: 3. What must be true：FY2027 年底價 ＝ 現價 ×（1＋報酬）所需的倍數（看 FY2028 EPS）
A22: FY2027 年底價 ÷ 現價 | B22: 所需倍數（÷ FY2028 EPS，A） | C22: 所需倍數（÷ FY2028 EPS，B） | D22: 所需倍數（÷ FY2028 EPS，C） | E22: 對照：Andy 合理 P/E
A23: 0.5 | B23: =px*A23/PL!F12 -> 19.434597 | C23: =px*A23/PL!F23 -> 23.07465 | D23: =px*A23/PL!F34 -> 28.392496 | E23: =pe_fair_andy -> 25
A24: 0.75 | B24: =px*A24/PL!F12 -> 29.151896 | C24: =px*A24/PL!F23 -> 34.611975 | D24: =px*A24/PL!F34 -> 42.588744 | E24: =pe_fair_andy -> 25
A25: 1 | B25: =px*A25/PL!F12 -> 38.869195 | C25: =px*A25/PL!F23 -> 46.149301 | D25: =px*A25/PL!F34 -> 56.784992 | E25: =pe_fair_andy -> 25
A26: 1.21 | B26: =px*A26/PL!F12 -> 47.031726 | C26: =px*A26/PL!F23 -> 55.840654 | D26: =px*A26/PL!F34 -> 68.70984 | E26: =pe_fair_andy -> 25
A27: 1.5 | B27: =px*A27/PL!F12 -> 58.303792 | C27: =px*A27/PL!F23 -> 69.223951 | D27: =px*A27/PL!F34 -> 85.177487 | E27: =pe_fair_andy -> 25
A28: 讀法：1.00＝價格不變、1.21＝一年約 21%。所需倍數愈高，現價愈依賴「短缺溢價延續到 2028 年以後」。
A30: 4. 對照：以 Andy 合理 P/E 25x 計算的隱含價（只作對照，非規則值）
A31: 情境 | B31: FY2027 EPS | C31: × 25x | D31: 相對現價 | E31: FY2028 EPS | F31: × 25x | G31: 相對現價
A32: A | B32: =PL!E12 -> 216.1327 | C32: =B32*pe_fair_andy -> 5403.3175 | D32: =C32/px-1 -> -0.36521176 | E32: =PL!F12 -> 218.9909 | F32: =E32*pe_fair_andy -> 5474.7725 | G32: =F32/px-1 -> -0.35681714
A33: B | B33: =PL!E23 -> 216.1327 | C33: =B33*pe_fair_andy -> 5403.3175 | D33: =C33/px-1 -> -0.36521176 | E33: =PL!F23 -> 184.44483 | F33: =E33*pe_fair_andy -> 4611.1208 | G33: =F33/px-1 -> -0.45827998
A34: C | B34: =PL!E34 -> 216.1327 | C34: =B34*pe_fair_andy -> 5403.3175 | D34: =C34/px-1 -> -0.36521176 | E34: =PL!F34 -> 149.89876 | F34: =E34*pe_fair_andy -> 3747.4691 | G34: =F34/px-1 -> -0.55974282
A36: 舊法：規則值情境加權（參考；v0.1.1 的「0. 目標價與上檔空間」改名，不再是目標價）
A37: 項目 | B37: 數值 | E37: 說明
A38: 舊法隱含價（情境加權，參考） | B38: =tp_wA*B40+tp_wB*B41+tp_wC*B42 -> 9531.452 | E38: 權重 × 各情境隱含價
A39: 舊法隱含價相對現價（÷ 現價 − 1） | B39: =B38/px-1 -> 0.11976645 | E39: 現價＝In 頁 px（2026-10-23 收盤，分割後）
A40: 情境 A 隱含價（樂觀） | B40: =$B$58*PL!E12 -> 9531.452 | E40: 情境 A FY2027 EPS（PL 頁）× 十年 P/E 中位數（第 0a 節）
A41: 情境 B 隱含價（基準） | B41: =$B$58*PL!E23 -> 9531.452 | E41: 情境 B FY2027 EPS（PL 頁）× 十年 P/E 中位數（第 0a 節）
A42: 情境 C 隱含價（下檔） | B42: =$B$58*PL!E34 -> 9531.452 | E42: 情境 C FY2027 EPS（PL 頁）× 十年 P/E 中位數（第 0a 節）
A43: 情境權重 A／B／C | B43: =tp_wA -> 0.3 | C43: =tp_wB -> 0.5 | D43: =tp_wC -> 0.2 | E43: ="合計 "&TEXT(B43+C43+D43,"0%")&"；In 頁 tp_wA／tp_wB／tp_wC（Assumed，Andy 可改）" -> 合計 100%；In 頁 tp_wA／tp_wB／tp_wC（Assumed，Andy 可改）
A44: 舊法說明 | B44: P/E：十年（2016–2025 日曆年年底）P/E 中位數（companiesmarketcap 單一來源，第 0a 節；2017 年虧損不計，9 年）× 各情境 FY2027 EPS（FY2027＝2027-04～2028-03）。本模型無規則值（十年 P/E 待 Bloomberg），依工作單改用此備案；倍數為日曆年年底口徑，與 3 月制會計年度不完全對齊。十年倍數多為 AI 載板需求前的時期（2019 年獲利低谷約 137x 為極值，中位數受影響小），偏誤方向不明確；FY2027 三情境 EPS 相同（情境差從 FY2028 起），故三情境隱含價相同；隱含價約為 FY2027 年底（2028-03）的價格、未折現，當作 12 個月目標價時偏高。
...

Sheet Recon
A1: Recon — 本模型 vs 公司目標、研調份額、先驗。只作事後對照，不為對上數字而調參數。FY2027 以後的共識：未找到（付費）
A3: 項目 | B3: 對照值 | C3: 模型 A | D3: 差距 A | E3: 模型 B | F3: 差距 B | G3: 模型 C | H3: 差距 C | I3: 對照來源 | J3: 說明
A4: A. 公司目標與市場（校準未使用）
A5: FY2029 營收 vs 公司 FY2030 目標 ¥1 兆 | B5: =tgt30_rev -> 1000 | C5: =PL!G82 -> 865.77224 | D5: =C5/B5-1 -> -0.13422776 | E5: =PL!G116 -> 786.21287 | F5: =E5/B5-1 -> -0.21378713 | G5: =PL!G150 -> 653.61392 | H5: =G5/B5-1 -> -0.34638608 | I5: Quartr 摘要（Interested-party） | J5: 模型到 FY2029；目標年晚一年
A6: FY2029 營業利益 vs 公司 FY2030 目標 ¥3,000 億 | B6: =tgt30_oi -> 300 | C6: =PL!G86 -> 200.11509 | D6: =C6/B6-1 -> -0.3329497 | E6: =PL!G120 -> 176.20195 | F6: =E6/B6-1 -> -0.41266018 | G6: =PL!G154 -> 136.34671 | H6: =G6/B6-1 -> -0.54551098 | I6: 同上
A7: FY2027 EPS vs 前瞻 P/E 隱含未來 12 月 EPS | B7: =cons_feps -> 180.91532 | C7: =PL!E90 -> 216.1327 | D7: =C7/B7-1 -> 0.19466221 | E7: =PL!E124 -> 216.1327 | F7: =E7/B7-1 -> 0.19466221 | G7: =PL!E158 -> 216.1327 | H7: =G7/B7-1 -> 0.19466221 | I7: stockanalysis（推導） | J7: 未來 12 月 ≈ ½ FY2026＋½ FY2027，口徑不同，只作量級比較
A8: B. 份額與每顆金額（先驗比對的機制檢查）
A9: FY2026 每顆 NVIDIA 載板金額（美元）vs 先驗比對推導中點 $225 | B9: 225 | C9: =Units!C8 -> 215.3086 | D9: =C9/B9-1 -> -0.043072908 | E9: =Units!C8 -> 215.3086 | F9: =E9/B9-1 -> -0.043072908 | G9: =Units!C8 -> 215.3086 | H9: =G9/B9-1 -> -0.043072908 | I9: 先驗比對_Ibiden（Drive） | J9: 推導區間 $150–300；封裝全部（中介層＋載板＋組裝）B200 約 $1,100（Silicon Analysts）
A10: FY2026 每 GW Ibiden 營收（US$M）vs 先驗比對推導中點 75 | B10: 75 | C10: =Units!C12 -> 77.096949 | D10: =C10/B10-1 -> 0.027959321 | E10: =Units!C12 -> 77.096949 | F10: =E10/B10-1 -> 0.027959321 | G10: =Units!C12 -> 77.096949 | H10: =G10/B10-1 -> 0.027959321 | I10: 先驗比對_Ibiden（Drive）
A11: FY2027 AI 載板 ÷ 營收 | C11: =PL!E84 -> 0.55460712 | E11: =PL!E118 -> 0.55460712 | G11: =PL!E152 -> 0.55460712 | I11: —
A12: FY2028 電子事業營益率 vs FY2026 錨點（百分點） | B12: =q26_eoi/q26_e -> 0.29333333 | C12: =PL!F78 -> 0.29058187 | D12: =C12-B12 -> -0.0027514674 | E12: =PL!F112 -> 0.28231989 | F12: =E12-B12 -> -0.011013441 | G12: =PL!F146 -> 0.27051544 | H12: =G12-B12 -> -0.022817895 | I12: 錨點 | J12: 短缺溢價回落使營益率下滑
A13: C. 預留
A14: 產能上限（Ibiden 2028 年為 2024 年 2.5–2.8 倍）與需求面積的對照：2024 年基準面積未找到，本版不計 | J14: 預留列：本版無數值
A15: R4 產業部署路徑（markets/deploy_path/，尚未建立）：上線後以 AI 載板營收 ÷ 部署 GW 取代 Units 頁的每 GW 換算 | J15: 預留列：本版無數值
A17: E. 目標價對帳（v0.2；模型欄為情境加權值，非情境 A）
A18: 12 個月後的前瞻 EPS（情境加權）vs 共識前瞻 EPS | B18: =cons_feps -> 180.91532 | C18: =Val!B91 -> 202.01607 | D18: =C18/B18-1 -> 0.11663327 | I18: stockanalysis 個股頁 2026-10-16：價格 9,764 ÷ Forward PE 53.97（即 In 頁 pe_fwd_sa） | J18: 共識只作對帳，不作校準
A19: 目標價（DCF 與 Comparable 加權）vs 市場共識目標價 | B19: =cons_tp -> 12432.35 | C19: =Val!B96 -> 5236.2411 | D19: =C19/B19-1 -> -0.57882129 | I19: stockanalysis 個股頁（S&P Global 彙整）18 位分析師平均目標價 12,432（頁面價格日期 2026-10-16；分割後） | J19: 共識只作對帳，不作校準
A20: Comparable 目標價 vs 市場共識目標價 | B20: =cons_tp -> 12432.35 | C20: =Val!B92 -> 8541.2394 | D20: =C20/B20-1 -> -0.31298271 | I20: 同上 | J20: 共識只作對帳，不作校準

Sheet Sens
A1: Sens — 一次動一個輸入（情境 A；每顆有效金額與 AI 載板營益率在每個案例內依 FY2026 錨點重算，FY2026 恆等於錨點）：對 FY2027、FY2028 的營收、AI 載板營收、電子事業營益率與 EPS 的影響。每個案例是一個完整推導區塊（本頁下方）
A3: 案例 | B3: 設定 | C3: FY2027 營收 | D3: FY2027 AI 載板 | E3: FY2027 電子營益率 | F3: FY2027 EPS | G3: FY2027 EPS 相對基準 | H3: FY2028 營收 | I3: FY2028 AI 載板 | J3: FY2028 電子營益率 | K3: FY2028 EPS | L3: FY2028 EPS 相對基準
A4: 基準（情境 A） | B4: PL 區塊 A | C4: =PL!E82 -> 708.45879 | D4: =PL!E71 -> 392.91629 | E4: =PL!E78 -> 0.31325302 | F4: =PL!E90 -> 216.1327 | G4: =F4/F$4-1 -> 0 | H4: =PL!F82 -> 759.91625 | I4: =PL!F71 -> 434.67123 | J4: =PL!F78 -> 0.29058187 | K4: =PL!F90 -> 218.9909 | L4: =K4/K$4-1 -> 0
A5: 溢價快速回落 | B5: 價格溢價 2027 0.95、2028 0.85、2029 0.75（新產能提早到位） | C5: =E62 -> 688.81298 | D5: =E51 -> 373.27048 | E5: =E58 -> 0.28685476 | F5: =E70 -> 192.99309 | G5: =F5/F$4-1 -> -0.10706204 | H5: =F62 -> 714.16139 | I5: =F51 -> 388.91636 | J5: =F58 -> 0.22975326 | K5: =F70 -> 165.09903 | L5: =K5/K$4-1 -> -0.24609181
A6: 溢價延續 | B6: 價格溢價 2027 1.05、2028 1.05、2029 1.00 | C6: =E96 -> 728.10461 | D6: =E85 -> 412.56211 | E6: =E92 -> 0.3377667 | F6: =E104 -> 239.27231 | G6: =F6/F$4-1 -> 0.10706204 | H6: =F96 -> 805.67112 | I6: =F85 -> 480.42609 | J6: =F92 -> 0.34250606 | K6: =F104 -> 272.88277 | L6: =K6/K$4-1 -> 0.24609181
A7: 份額流失（低） | B7: 份額相對值 2027 0.85、2028 0.75、2029 0.70（欣興、三星電機加速） | C7: =E130 -> 667.09918 | D7: =E119 -> 351.55668 | E7: =E126 -> 0.30841364 | F7: =E138 -> 198.08318 | G7: =F7/F$4-1 -> -0.083511281 | H7: =F130 -> 695.70346 | I7: =F119 -> 370.45843 | J7: =F126 -> 0.28474843 | K7: =F138 -> 193.47392 | L7: =K7/K$4-1 -> -0.11652074
A8: 份額持平（高） | B8: 份額相對值 1.00 | C8: =E164 -> 729.1386 | D8: =E153 -> 413.5961 | E8: =E160 -> 0.31540047 | F8: =E172 -> 225.15746 | G8: =F8/F$4-1 -> 0.04175564 | H8: =F164 -> 819.1896 | I8: =F153 -> 493.94458 | J8: =F160 -> 0.29492541 | K8: =F172 -> 242.54504 | L8: =K8/K$4-1 -> 0.10755761
A9: 每顆金額年增 10% | B9: 面積、層數成長較慢 | C9: =E198 -> 681.8204 | D9: =E187 -> 366.2779 | E9: =E194 -> 0.31022716 | F9: =E206 -> 204.50759 | G9: =F9/F$4-1 -> -0.053786927 | H9: =F198 -> 702.97569 | I9: =F187 -> 377.73067 | J9: =F194 -> 0.28548108 | K9: =F206 -> 196.36377 | L9: =K9/K$4-1 -> -0.10332452
A10: 每顆金額年增 22% | B10: 較快 | C10: =E232 -> 721.77799 | D10: =E221 -> 406.23549 | E10: =E228 -> 0.31465484 | F10: =E240 -> 221.94526 | G10: =F10/F$4-1 -> 0.026893463 | H10: =F232 -> 789.88497 | I10: =F221 -> 464.63994 | J10: =F228 -> 0.29288359 | K10: =F240 -> 230.89992 | L10: =K10/K$4-1 -> 0.054381326
A11: 非 NVIDIA 權重 0.2 | B11: ASIC 多由其他載板廠供應 | C11: =E266 -> 690.05422 | D11: =E255 -> 374.51172 | E11: =E262 -> 0.31119604 | F11: =E274 -> 208.10086 | G11: =F11/F$4-1 -> -0.03716161 | H11: =F266 -> 726.58257 | I11: =F255 -> 401.33754 | J11: =F262 -> 0.2877249 | K11: =F274 -> 205.74471 | L11: =K11/K$4-1 -> -0.060487409
A12: 非 NVIDIA 權重 0.6 | B12: Ibiden 在 ASIC 份額較高 | C12: =E300 -> 722.26223 | D12: =E289 -> 406.71973 | E12: =E296 -> 0.31470451 | F12: =E308 -> 222.15658 | G12: =F12/F$4-1 -> 0.027871208 | H12: =F300 -> 784.91651 | I12: =F289 -> 459.67149 | J12: =F296 -> 0.29251777 | K12: =F308 -> 228.92555 | L12: =K12/K$4-1 -> 0.045365556
A13: AI 占電子事業 55% | B13: FY2026 切分較低（校準跟著變） | C13: =E334 -> 687.38513 | D13: =E323 -> 332.46763 | E13: =E330 -> 0.32000335 | F13: =E342 -> 212.40949 | G13: =F13/F$4-1 -> -0.017226487 | H13: =F334 -> 734.38751 | I13: =F323 -> 367.79873 | J13: =F330 -> 0.30246341 | K13: =F342 -> 218.00429 | L13: =K13/K$4-1 -> -0.0045052744
A14: AI 占電子事業 75% | B14: 較高 | C14: =E368 -> 729.53246 | D14: =E357 -> 453.36496 | E14: =E364 -> 0.30701829 | F14: =E376 -> 219.85591 | G14: =F14/F$4-1 -> 0.017226487 | H14: =F368 -> 785.445 | I14: =F357 -> 501.54372 | J14: =F364 -> 0.27970319 | K14: =F376 -> 219.97752 | L14: =K14/K$4-1 -> 0.0045052744
A15: 非 AI 營益率 10% | B15: 校準後 AI 載板營益率較高 | C15: =E402 -> 708.45879 | D15: =E391 -> 392.91629 | E15: =E398 -> 0.32020175 | F15: =E410 -> 220.47644 | G15: =F15/F$4-1 -> 0.020097568 | H15: =F402 -> 759.91625 | I15: =F391 -> 434.67123 | J15: =F398 -> 0.29935592 | K15: =F410 -> 224.9784 | L15: =K15/K$4-1 -> 0.027341316
A16: 非 AI 營益率 20% | B16: 較低 | C16: =E436 -> 708.45879 | D16: =E425 -> 392.91629 | E16: =E432 -> 0.30630429 | F16: =E444 -> 211.78896 | G16: =F16/F$4-1 -> -0.020097568 | H16: =F436 -> 759.91625 | I16: =F425 -> 434.67123 | J16: =F432 -> 0.28180781 | K16: =F444 -> 213.0034 | L16: =K16/K$4-1 -> -0.027341316
A17: 淨利 ÷ 營業利益 0.62 | B17: 稅與非營業較不利 | C17: =E470 -> 708.45879 | D17: =E459 -> 392.91629 | E17: =E466 -> 0.31325302 | F17: =E478 -> 202.72659 | G17: =F17/F$4-1 -> -0.062027231 | H17: =F470 -> 759.91625 | I17: =F459 -> 434.67123 | J17: =F466 -> 0.29058187 | K17: =F478 -> 205.4075 | L17: =K17/K$4-1 -> -0.062027231
A18: CB 轉換：股數 +3%／年 | B18: 2031 年到期 CB 轉換稀釋 | C18: =E504 -> 708.45879 | D18: =E493 -> 392.91629 | E18: =E500 -> 0.31325302 | F18: =E512 -> 209.83757 | G18: =F18/F$4-1 -> -0.029126214 | H18: =F504 -> 759.91625 | I18: =F493 -> 434.67123 | J18: =F500 -> 0.29058187 | K18: =F512 -> 206.41993 | L18: =K18/K$4-1 -> -0.057404091
A19: 顆數情境 B | B19: CY2028 ×0.8、CY2029 ×0.85 | C19: =PL!E116 -> 708.45879 | D19: =PL!E105 -> 392.91629 | E19: =PL!E112 -> 0.31325302 | F19: =PL!E124 -> 216.1327 | G19: =F19/F$4-1 -> 0 | H19: =PL!F116 -> 672.98201 | I19: =PL!F105 -> 347.73698 | J19: =PL!F112 -> 0.28231989 | K19: =PL!F124 -> 184.44483 | L19: =K19/K$4-1 -> -0.15775116
A20: 顆數情境 C | B20: CY2028–29 ×0.6 | C20: =PL!E150 -> 708.45879 | D20: =PL!E139 -> 392.91629 | E20: =PL!E146 -> 0.31325302 | F20: =PL!E158 -> 216.1327 | G20: =F20/F$4-1 -> 0 | H20: =PL!F150 -> 586.04776 | I20: =PL!F139 -> 260.80274 | J20: =PL!F146 -> 0.27051544 | K20: =PL!F158 -> 149.89876 | L20: =K20/K$4-1 -> -0.31550232
A22: 讀法：FY2027 三個顆數情境相同；B、C 的差異從 FY2028 起。溢價指數同時改變營收與 AI 載板營益率（成本不變），所以對 EPS 的影響大於對營收的影響。
A40: 案例區塊：溢價快速回落（情境 A）
A41: 項目 | B41: 單位 | C41: FY2025A | D41: FY2026（錨點） | E41: FY2027 | F41: FY2028 | G41: FY2029 | H41: 說明
A42: A. AI 伺服器載板（D 欄＝FY2026 校準年；FY(t) 對照 CY(t) 顆數）
A43: NVIDIA 加速器顆數 × 情境係數 | B43: 百萬顆 | D43: =(u_bw_26+u_rb_26+u_ru_26+u_hp_26)*1 -> 7.6 | E43: =(u_bw_27+u_rb_27+u_ru_27+u_hp_27)*1 -> 9.7 | F43: =(u_bw_28+u_rb_28+u_ru_28+u_hp_28)*um28_A -> 9.5 | G43: =(u_bw_28*(1+g29_bw)+u_rb_28*(1+g29_rb)+u_ru_28*(1+g29_ru)+u_hp_28*(1+g29_hp))*um29_A -> 10.6 | H43: markets/network In：Blackwell、Rubin、Rubin Ultra、Hopper
A44: 非 NVIDIA 加速器顆數 × 情境係數 | B44: 百萬顆 | D44: =(u_amd_26+u_tpu_26+u_trn_26+u_oth_26)*1 -> 7.6 | E44: =(u_amd_27+u_tpu_27+u_trn_27+u_oth_27)*1 -> 14 | F44: =(u_amd_28+u_tpu_28+u_trn_28+u_oth_28)*um28_A -> 17 | G44: =(u_amd_28*(1+g29_amd)+u_tpu_28*(1+g29_tpu)+u_trn_28*(1+g29_trn)+u_oth_28*(1+g29_oth))*um29_A -> 19.55 | H44: AMD、TPU、Trainium、其他 ASIC
A45: 有效顆數 ＝ NVIDIA ＋ 權重 × 非 NVIDIA | B45: 百萬顆 | D45: =D43+w_ot*D44 -> 10.64 | E45: =E43+w_ot*E44 -> 15.3 | F45: =F43+w_ot*F44 -> 16.3 | G45: =G43+w_ot*G44 -> 18.42
A46: FY2026 AI 載板營收（錨點電子事業 × AI 占比） | B46: ¥B | D46: =q26_e*ai_e -> 243.75 | H46: Assumed 切分；公司未揭露
A47: 每顆有效金額（Ibiden 份額 × 載板金額；FY2026 校準） | B47: 千日圓／顆 | D47: =D46/D45 -> 22.908835 | H47: Derived：¥B ÷ 百萬顆＝千日圓／顆。÷ 匯率即美元／顆（Units 頁）
A48: 每顆載板金額指數（面積、層數；FY2026＝1） | B48: x | D48: =1 -> 1 | E48: =D48*(1+g_asp) -> 1.18 | F48: =E48*(1+g_asp) -> 1.3924 | G48: =F48*(1+g_asp) -> 1.643032
A49: Ibiden 份額相對值（÷ FY2026） | B49: x | D49: =1 -> 1 | E49: =rel_27 -> 0.95 | F49: =rel_28 -> 0.88 | G49: =rel_29 -> 0.85
A50: 短缺溢價指數（FY2026＝1） | B50: x | D50: =1 -> 1 | E50: =PPLO_27 -> 0.95 | F50: =PPLO_28 -> 0.85 | G50: =PPLO_29 -> 0.75
A51: AI 伺服器載板營收 | B51: ¥B | D51: =D46 -> 243.75 | E51: =E45*$D$47*E48*E49*E50 -> 373.27048 | F51: =F45*$D$47*F48*F49*F50 -> 388.91636 | G51: =G45*$D$47*G48*G49*G50 -> 441.9965
A52: B. 電子事業
A53: 電子事業非 AI 營收（通用伺服器、PC 等） | B53: ¥B | D53: =q26_e-D51 -> 131.25 | E53: =D53*(1+g_ne) -> 137.8125 | F53: =E53*(1+g_ne) -> 144.70312 | G53: =F53*(1+g_ne) -> 151.93828
A54: 電子事業營收 | B54: ¥B | C54: =q25_e -> 243.316 | D54: =D51+D53 -> 375 | E54: =E51+E53 -> 511.08298 | F54: =F51+F53 -> 533.61949 | G54: =G51+G53 -> 593.93478
A55: AI 載板營業利益率（FY2026 校準） | B55: % | D55: =(q26_eoi-m_ne*D53)/D51 -> 0.37051282 | H55: Derived：使 FY2026 電子事業營業利益＝錨點；非 AI 營益率為 In 頁 m_ne
A56: AI 載板營業利益率 ＝ 1 −（1 − 校準值）÷ 溢價指數 | B56: % | D56: =D55 -> 0.37051282 | E56: =1-(1-$D$55)/E50 -> 0.33738192 | F56: =1-(1-$D$55)/F50 -> 0.25942685 | G56: =1-(1-$D$55)/G50 -> 0.16068376 | H56: Derived：每單位成本不變，價格隨溢價指數升降，差額全部落在利潤
A57: 電子事業營業利益 | B57: ¥B | C57: =q25_eoi -> 45.248 | D57: =D51*D56+D53*m_ne -> 110 | E57: =E51*E56+E53*m_ne -> 146.60658 | F57: =F51*F56+F53*m_ne -> 122.60081 | G57: =G51*G56+G53*m_ne -> 93.812402
A58: 電子事業營益率 | B58: % | C58: =C57/C54 -> 0.18596393 | D58: =D57/D54 -> 0.29333333 | E58: =E57/E54 -> 0.28685476 | F58: =F57/F54 -> 0.22975326 | G58: =G57/G54 -> 0.15795068
A59: C. 陶瓷、其他事業與全公司
...

Sheet Sources
A1: 來源（公司原文＝決算短信與補足資料；分部門預測取自 Q1 補足資料的轉載）
A2: 公司：2026 年 3 月期決算短信（FY2025 實績、分部門） | B2: https://www.ibiden.com/ir/items/ConsolidatedFinancialResultsFY2025.pdf
A3: 公司：2027 年 3 月期 Q1 決算短信（上修後全年預測） | B3: https://finance.biggo.jp/news/jpx_tdnet_140120260731504718
A4: 公司：Q1 補足資料（分部門全年預測、設備投資 2,100 億、匯率 ¥152） | B4: https://finance.biggo.jp/news/jpx_tdnet_140120260803507041
A5: 二手：SEMICON.TODAY Q1 深掘（分部門 Q1、EPS 分割後 149.68） | B5: https://semicon.today/archives/12352
A6: 二手：LIMO Q1（預收款、股價） | B6: https://finance.limo.media/articles/detail/683
A7: 二手：Quartr FY2025 摘要（FY2030 目標；AI 摘要，營收數字有誤處未採用） | B7: https://quartr.com/events/ibiden-co-ltd-4062-q4-2026_F9Xvd7IW
A8: 研調：Tom's Hardware ABF 2026（供需缺口、Ibiden 路線圖、競爭者擴產、ABF 膜漲價） | B8: https://www.tomshardware.com/tech-industry/semiconductors/the-state-of-abf-substrates-in-data-center-silicon-in-2026-solving-the-supply-crunch-and-material-wall-beneath-every-ai-accelerator
A9: 研調：Data Gravity（高階 FC-BGA 份額、ABF 載板平均單價） | B9: https://www.datagravity.dev/p/the-abf-substrate-bottleneck
A10: 研調：thebuildout（BofA：Ibiden 占 GPU 載板 70–80%、短缺到 2028） | B10: https://thebuildout.ai/intel/229c44f2-da57-4f46-b5fa-e5d03702236c
A11: 研調：Encyclopedia of Stocks（欣興 2025 年 NVIDIA 約 30%） | B11: https://encyclopediaofstocks.substack.com/p/abf-substrate-market-ai-driven-super
A12: 研調：Silicon Analysts（封裝成本，含載板） | B12: https://siliconanalysts.com/data/ai-chip-costs
A13: 市場：stockanalysis（10-16 股價、前瞻與近 12 月 P/E、共識目標價；同業前瞻 P/E、ROE） | B13: https://stockanalysis.com/quote/tyo/4062/
A14: 市場：10-23 收盤（markets/invest_map/data/prices.csv：株探、松井證券） | B14: https://kabutan.jp/stock/?code=4062
A15: 市場層：markets/network、tsmc 成品（本 repo，唯讀）
A16: 待補（人工）：十年 P/E 歷史（Bloomberg）；AI 伺服器載板營收（公司未揭露）；FY2027 以後共識（付費）；CB 發行額；ASIC 載板份額 | B16: 未找到
A17: SemiAnalysis | B17: 未使用
