Workbook

Sheet README
A1: AI 網通市場模型 v0.2.2（AI 半導體 Project 步驟 3） 2026-10-23（Tokenomics v20.1）
A2: v0.2.2：Tokenomics 快照改 v20.1；IF_CapexIT、IF_GPUsPerGW 等五個名稱逐值與 v19.0 相同，只更新版本標籤與說明文字，數值不變。
A3: v0.2.1：ITU 改讀 Tokenomics 快照、不取整（GB300、VR200、Rubin Ultra、Hopper）；網通金額不變。
A4: 模型命題：AI 網通的錢由「加速器顆數 × 每顆網通內容」決定；每顆內容隨 scale-up 域擴大（NVL72 → NVL576）與每 GPU 網卡頻寬倍增而上升，而 scale-up 的頻寬大多由便宜的銅承載，所以金額主體仍在 scale-out（交換器、光模組、網卡）。
A6: 驅動因子 → 推導量
A7: Units：加速器顆數（markets/memory，與 HBM 市場同一份）→ 各年各平台顆數
A8: In B：每顆加速器網通內容（六個元件）；NVIDIA 平台以橋接表 v0.2 為錨，ASIC 為 Assumed
A9: Mkt：Σ 顆數 × 內容 → 依元件、依產品類別的市場；× CPO 占比、scale-up 光學占比 → 光／銅；÷ AI IT capex → 網通占比；× 廠商歸屬 → NVIDIA、Broadcom 推估營收，對照實際
A10: Sens：Rubin 顆數、VR200 內容、ASIC 內容對 2027 市場
A12: 標記：Verified、Interested-party、Analogy、Assumed、Derived。SemiAnalysis 未使用。
A13: 已知限制：(1) AI 網通總市場與 scale-up／scale-out 美元拆分沒有公開資料（Dell'Oro、650 Group 付費），本模型為由下而上推導；(2) ASIC 網通內容為 Assumed；(3) 廠商歸屬為 Assumed，只用來與 NVIDIA、Broadcom 實際營收對帳；(4) 只含 AI 後端網路，不含前端。

Sheet In
A1: In — 輸入（藍字；基準欄 E）。每列具名範圍＝鍵。金額：每顆加速器美元；市場：十億美元
A3: 鍵 | B3: 項目 | C3: 單位 | D3: 低 | E3: 基準 | F3: 高 | G3: 標記 | H3: 來源／說明
A4: A. 加速器顆數（2026–2028 取自 markets/memory；2029 為成長率）
A5: u_bw_26 | B5: NVIDIA Blackwell（B200／B300） 顆數 2026 | C5: 百萬顆 | E5: 5.4 | G5: Interested-party | H5: markets/memory/market.py：顆數：Morgan Stanley 2026-07（2026 5.4M）；AC Research 2027 約 2.4M；2028 Assumed。GB：B200 186、B300 288 組合 [Derived]
A6: u_bw_27 | B6: NVIDIA Blackwell（B200／B300） 顆數 2027 | C6: 百萬顆 | E6: 2.4 | G6: Interested-party | H6: 同上
A7: u_bw_28 | B7: NVIDIA Blackwell（B200／B300） 顆數 2028 | C7: 百萬顆 | E7: 0.5 | G7: Interested-party | H7: 同上
A8: g29_bw | B8: NVIDIA Blackwell（B200／B300） 2029 顆數成長 | C8: % | E8: -0.5 | G8: Assumed | H8: 2029 無顆數預測
A9: u_rb_26 | B9: NVIDIA Rubin 顆數 2026 | C9: 百萬顆 | E9: 1.7 | G9: Interested-party | H9: markets/memory/market.py：2026：TrendForce 組合 Rubin 22% × 約 7.6M [Derived]；2027：Morgan Stanley 約 7.0M；2028 Assumed
A10: u_rb_27 | B10: NVIDIA Rubin 顆數 2027 | C10: 百萬顆 | E10: 7 | G10: Interested-party | H10: 同上
A11: u_rb_28 | B11: NVIDIA Rubin 顆數 2028 | C11: 百萬顆 | E11: 7 | G11: Interested-party | H11: 同上
A12: g29_rb | B12: NVIDIA Rubin 2029 顆數成長 | C12: % | E12: 0.15 | G12: Assumed | H12: 2029 無顆數預測
A13: u_ru_26 | B13: NVIDIA Rubin Ultra 顆數 2026 | C13: 百萬顆 | E13: 0 | G13: Assumed | H13: markets/memory/market.py：時程 Assumed；GB：NVIDIA 1 TB／封裝
A14: u_ru_27 | B14: NVIDIA Rubin Ultra 顆數 2027 | C14: 百萬顆 | E14: 0.3 | G14: Assumed | H14: 同上
A15: u_ru_28 | B15: NVIDIA Rubin Ultra 顆數 2028 | C15: 百萬顆 | E15: 2 | G15: Assumed | H15: 同上
A16: g29_ru | B16: NVIDIA Rubin Ultra 2029 顆數成長 | C16: % | E16: 0.15 | G16: Assumed | H16: 2029 無顆數預測
... A36: g29_oth | B36: 其他 ASIC（MTIA、Maia、Ascend 等） 2029 顆數成長 | C36: % | E36: 0.15 | G36: Assumed | H36: 2029 無顆數預測
A37: B. 每顆加速器網通內容（美元）
A38: c_GB_su_sw | B38: GB300 NVL72（Blackwell）：scale-up 交換晶片 | C38: $/顆 | D38: 1194 | E38: 1493 | F38: 1792 | G38: Derived | H38: 橋接表 v0.2.1 GB300（Tokenomics v20.1，與 v19.0 相同：機架基準價 $4.3M；v0.1 為 $5.0M）：NVLink 交換晶片 0.727、交換匣其他 0.727、機架外 scale-out 2.909、機架內網卡＋DPU 1.278（$B/GW）÷ 每 GW 487,008 顆；機架外依 交換器 45%／光模組 35%／銅 20% 拆——v0.1 初版 35／50／15 使 2026 光學 41.8B，高於 LightCounting 26B 61%，改以 LightCounting 與光模組廠營收加總（約 26–30B）校準 [Derived]。合計約 $11.6K（v0.1 $13.0K）；Bernstein GB200 約 $10.7K（第二來源）
A39: c_GB_su_ic | B39: GB300 NVL72（Blackwell）：scale-up 互連與交換匣其他（銅背板、線纜、電路板、機構） | C39: $/顆 | D39: 1194 | E39: 1493 | F39: 1792 | G39: Derived | H39: 同上
A40: c_GB_so_sw | B40: GB300 NVL72（Blackwell）：scale-out 交換器 | C40: $/顆 | D40: 2150 | E40: 2688 | F40: 3226 | G40: Derived | H40: 同上
A41: c_GB_so_opt | B41: GB300 NVL72（Blackwell）：scale-out 光模組 | C41: $/顆 | D41: 1672 | E41: 2090 | F41: 2508 | G41: Derived | H41: 同上
A42: c_GB_so_cu | B42: GB300 NVL72（Blackwell）：scale-out 銅纜（DAC／AEC） | C42: $/顆 | D42: 956 | E42: 1195 | F42: 1434 | G42: Derived | H42: 同上
A43: c_GB_nic | B43: GB300 NVL72（Blackwell）：網卡／DPU（SuperNIC） | C43: $/顆 | D43: 2099 | E43: 2624 | F43: 3149 | G43: Derived | H43: 同上
A44: c_VR_su_sw | B44: VR200 NVL72（Rubin）：scale-up 交換晶片 | C44: $/顆 | D44: 2334 | E44: 2917 | F44: 3500 | G44: Derived | H44: 橋接表 v0.2 VR200 ÷ 每 GW 291,744 顆；NVLink 6 交換晶片 36 顆（GB300 的 2 倍）、ConnectX-9 每架 144 顆；機架外拆分同上（45／35／20）。合計約 $24.5K
A45: c_VR_su_ic | B45: VR200 NVL72（Rubin）：scale-up 互連與交換匣其他（銅背板、線纜、電路板、機構） | C45: $/顆 | D45: 2334 | E45: 2917 | F45: 3500 | G45: Derived | H45: 同上
A46: c_VR_so_sw | B46: VR200 NVL72（Rubin）：scale-out 交換器 | C46: $/顆 | D46: 4201 | E46: 5251 | F46: 6301 | G46: Derived | H46: 同上
A47: c_VR_so_opt | B47: VR200 NVL72（Rubin）：scale-out 光模組 | C47: $/顆 | D47: 3267 | E47: 4084 | F47: 4901 | G47: Derived | H47: 同上
A48: c_VR_so_cu | B48: VR200 NVL72（Rubin）：scale-out 銅纜（DAC／AEC） | C48: $/顆 | D48: 1867 | E48: 2334 | F48: 2801 | G48: Derived | H48: 同上
A49: c_VR_nic | B49: VR200 NVL72（Rubin）：網卡／DPU（SuperNIC） | C49: $/顆 | D49: 5600 | E49: 7000 | F49: 8400 | G49: Derived | H49: 同上
... A91: c_ASIC_nic | B91: 其他 ASIC：網卡／DPU（SuperNIC） | C91: $/顆 | D91: 240 | E91: 300 | F91: 360 | G91: Assumed | H91: 同上
A92: C. 每顆加速器 IT 資本支出（千美元；算網通 ÷ IT capex）
A93: it_GB | B93: GB300 NVL72（Blackwell） IT capex | C93: $K/顆 | E93: 66.194444 | G93: Derived | H93: Tokenomics v20.1（與 v19.0 相同）IF_CapexIT 32.237 $B ÷ 487,008（v5.27 為 37.445）
A94: it_VR | B94: VR200 NVL72（Rubin） IT capex | C94: $K/顆 | E94: 128.83333 | G94: Derived | H94: 37.586 ÷ 291,744
A95: it_RU | B95: Rubin Ultra（MGX 單架／NVL576） IT capex | C95: $K/顆 | E95: 257.16667 | G95: Derived | H95: 50.086 ÷ 194,760
A96: it_HP | B96: Hopper HGX（8 GPU） IT capex | C96: $K/顆 | E96: 38.3125 | G96: Derived | H96: 27.510 ÷ 718,048
A97: it_AMD8 | B97: AMD MI355（8 GPU 伺服器） IT capex | C97: $K/顆 | E97: 40 | G97: Assumed
A98: it_AMDR | B98: AMD Helios（MI455X 機架） IT capex | C98: $K/顆 | E98: 100 | G98: Assumed | H98: VR200 的約 0.8 倍
A99: it_TPU | B99: Google TPU IT capex | C99: $K/顆 | E99: 25 | G99: Assumed
A100: it_TRN | B100: AWS Trainium IT capex | C100: $K/顆 | E100: 20 | G100: Assumed
A101: it_ASIC | B101: 其他 ASIC IT capex | C101: $K/顆 | E101: 20 | G101: Assumed
...

Sheet Units
A1: Units — 加速器顆數（百萬顆）與對應平台
A3: 類型 | B3: 2026 | C3: 2027 | D3: 2028 | E3: 2029 | F3: 平台（2026／2027+）
A4: NVIDIA Blackwell（B200／B300） | B4: =u_bw_26 -> 5.4 | C4: =u_bw_27 -> 2.4 | D4: =u_bw_28 -> 0.5 | E4: =D4*(1+g29_bw) -> 0.25 | F4: GB／GB
A5: NVIDIA Rubin | B5: =u_rb_26 -> 1.7 | C5: =u_rb_27 -> 7 | D5: =u_rb_28 -> 7 | E5: =D5*(1+g29_rb) -> 8.05 | F5: VR／VR
A6: NVIDIA Rubin Ultra | B6: =u_ru_26 -> 0 | C6: =u_ru_27 -> 0.3 | D6: =u_ru_28 -> 2 | E6: =D6*(1+g29_ru) -> 2.3 | F6: RU／RU
A7: NVIDIA Hopper（H200 等） | B7: =u_hp_26 -> 0.5 | C7: =u_hp_27 -> 0 | D7: =u_hp_28 -> 0 | E7: =D7*(1+g29_hp) -> 0 | F7: HP／HP
A8: AMD Instinct | B8: =u_amd_26 -> 0.75 | C8: =u_amd_27 -> 1.5 | D8: =u_amd_28 -> 2 | E8: =D8*(1+g29_amd) -> 2.3 | F8: AMD8／AMDR
A9: Google TPU | B9: =u_tpu_26 -> 3.85 | C9: =u_tpu_27 -> 5.5 | D9: =u_tpu_28 -> 7 | E9: =D9*(1+g29_tpu) -> 8.05 | F9: TPU／TPU
A10: AWS Trainium | B10: =u_trn_26 -> 2 | C10: =u_trn_27 -> 2.5 | D10: =u_trn_28 -> 3 | E10: =D10*(1+g29_trn) -> 3.45 | F10: TRN／TRN
A11: 其他 ASIC（MTIA、Maia、Ascend 等） | B11: =u_oth_26 -> 1 | C11: =u_oth_27 -> 4.5 | D11: =u_oth_28 -> 5 | E11: =D11*(1+g29_oth) -> 5.75 | F11: ASIC／ASIC
A12: 合計 | B12: =SUM(B4:B11) -> 15.2 | C12: =SUM(C4:C11) -> 23.7 | D12: =SUM(D4:D11) -> 26.5 | E12: =SUM(E4:E11) -> 30.15

Sheet Mkt
A1: Mkt — AI 網通市場（十億美元）＝ Σ 顆數（百萬）× 每顆內容（美元）÷ 1000
A3: 項目 | B3: 單位 | C3: 2026 | D3: 2027 | E3: 2028 | F3: 2029 | G3: 說明
A4: 依元件
A5: scale-up 交換晶片 | B5: $B | C5: =(Units!B4*c_GB_su_sw+Units!B5*c_VR_su_sw+Units!B6*c_RU_su_sw+Units!B7*c_HP_su_sw+Units!B8*c_AMD8_su_sw+Units!B9*c_TPU_su_sw+Units!B10*c_TRN_su_sw+Units!B11*c_ASIC_su_sw)/1000 -> 18.2761 | D5: =(Units!C4*c_GB_su_sw+Units!C5*c_VR_su_sw+Units!C6*c_RU_su_sw+Units!C7*c_HP_su_sw+Units!C8*c_AMDR_su_sw+Units!C9*c_TPU_su_sw+Units!C10*c_TRN_su_sw+Units!C11*c_ASIC_su_sw)/1000 -> 37.4157 | E5: =(Units!D4*c_GB_su_sw+Units!D5*c_VR_su_sw+Units!D6*c_RU_su_sw+Units!D7*c_HP_su_sw+Units!D8*c_AMDR_su_sw+Units!D9*c_TPU_su_sw+Units!D10*c_TRN_su_sw+Units!D11*c_ASIC_su_sw)/1000 -> 44.9835 | F5: =(Units!E4*c_GB_su_sw+Units!E5*c_VR_su_sw+Units!E6*c_RU_su_sw+Units!E7*c_HP_su_sw+Units!E8*c_AMDR_su_sw+Units!E9*c_TPU_su_sw+Units!E10*c_TRN_su_sw+Units!E11*c_ASIC_su_sw)/1000 -> 51.2458
A6: scale-up 互連與交換匣其他（銅背板、線纜、電路板、機構） | B6: $B | C6: =(Units!B4*c_GB_su_ic+Units!B5*c_VR_su_ic+Units!B6*c_RU_su_ic+Units!B7*c_HP_su_ic+Units!B8*c_AMD8_su_ic+Units!B9*c_TPU_su_ic+Units!B10*c_TRN_su_ic+Units!B11*c_ASIC_su_ic)/1000 -> 20.1661 | D6: =(Units!C4*c_GB_su_ic+Units!C5*c_VR_su_ic+Units!C6*c_RU_su_ic+Units!C7*c_HP_su_ic+Units!C8*c_AMDR_su_ic+Units!C9*c_TPU_su_ic+Units!C10*c_TRN_su_ic+Units!C11*c_ASIC_su_ic)/1000 -> 41.0157 | E6: =(Units!D4*c_GB_su_ic+Units!D5*c_VR_su_ic+Units!D6*c_RU_su_ic+Units!D7*c_HP_su_ic+Units!D8*c_AMDR_su_ic+Units!D9*c_TPU_su_ic+Units!D10*c_TRN_su_ic+Units!D11*c_ASIC_su_ic)/1000 -> 49.3835 | F6: =(Units!E4*c_GB_su_ic+Units!E5*c_VR_su_ic+Units!E6*c_RU_su_ic+Units!E7*c_HP_su_ic+Units!E8*c_AMDR_su_ic+Units!E9*c_TPU_su_ic+Units!E10*c_TRN_su_ic+Units!E11*c_ASIC_su_ic)/1000 -> 56.3058
A7: scale-out 交換器 | B7: $B | C7: =(Units!B4*c_GB_so_sw+Units!B5*c_VR_so_sw+Units!B6*c_RU_so_sw+Units!B7*c_HP_so_sw+Units!B8*c_AMD8_so_sw+Units!B9*c_TPU_so_sw+Units!B10*c_TRN_so_sw+Units!B11*c_ASIC_so_sw)/1000 -> 32.0719 | D7: =(Units!C4*c_GB_so_sw+Units!C5*c_VR_so_sw+Units!C6*c_RU_so_sw+Units!C7*c_HP_so_sw+Units!C8*c_AMDR_so_sw+Units!C9*c_TPU_so_sw+Units!C10*c_TRN_so_sw+Units!C11*c_ASIC_so_sw)/1000 -> 61.085 | E7: =(Units!D4*c_GB_so_sw+Units!D5*c_VR_so_sw+Units!D6*c_RU_so_sw+Units!D7*c_HP_so_sw+Units!D8*c_AMDR_so_sw+Units!D9*c_TPU_so_sw+Units!D10*c_TRN_so_sw+Units!D11*c_ASIC_so_sw)/1000 -> 69.005 | F7: =(Units!E4*c_GB_so_sw+Units!E5*c_VR_so_sw+Units!E6*c_RU_so_sw+Units!E7*c_HP_so_sw+Units!E8*c_AMDR_so_sw+Units!E9*c_TPU_so_sw+Units!E10*c_TRN_so_sw+Units!E11*c_ASIC_so_sw)/1000 -> 78.48215
A8: scale-out 光模組 | B8: $B | C8: =(Units!B4*c_GB_so_opt+Units!B5*c_VR_so_opt+Units!B6*c_RU_so_opt+Units!B7*c_HP_so_opt+Units!B8*c_AMD8_so_opt+Units!B9*c_TPU_so_opt+Units!B10*c_TRN_so_opt+Units!B11*c_ASIC_so_opt)/1000 -> 30.0538 | D8: =(Units!C4*c_GB_so_opt+Units!C5*c_VR_so_opt+Units!C6*c_RU_so_opt+Units!C7*c_HP_so_opt+Units!C8*c_AMDR_so_opt+Units!C9*c_TPU_so_opt+Units!C10*c_TRN_so_opt+Units!C11*c_ASIC_so_opt)/1000 -> 56.3797 | E8: =(Units!D4*c_GB_so_opt+Units!D5*c_VR_so_opt+Units!D6*c_RU_so_opt+Units!D7*c_HP_so_opt+Units!D8*c_AMDR_so_opt+Units!D9*c_TPU_so_opt+Units!D10*c_TRN_so_opt+Units!D11*c_ASIC_so_opt)/1000 -> 64.435 | F8: =(Units!E4*c_GB_so_opt+Units!E5*c_VR_so_opt+Units!E6*c_RU_so_opt+Units!E7*c_HP_so_opt+Units!E8*c_AMDR_so_opt+Units!E9*c_TPU_so_opt+Units!E10*c_TRN_so_opt+Units!E11*c_ASIC_so_opt)/1000 -> 73.421
A9: scale-out 銅纜（DAC／AEC） | B9: $B | C9: =(Units!B4*c_GB_so_cu+Units!B5*c_VR_so_cu+Units!B6*c_RU_so_cu+Units!B7*c_HP_so_cu+Units!B8*c_AMD8_so_cu+Units!B9*c_TPU_so_cu+Units!B10*c_TRN_so_cu+Units!B11*c_ASIC_so_cu)/1000 -> 13.8758 | D9: =(Units!C4*c_GB_so_cu+Units!C5*c_VR_so_cu+Units!C6*c_RU_so_cu+Units!C7*c_HP_so_cu+Units!C8*c_AMDR_so_cu+Units!C9*c_TPU_so_cu+Units!C10*c_TRN_so_cu+Units!C11*c_ASIC_so_cu)/1000 -> 26.4567 | E9: =(Units!D4*c_GB_so_cu+Units!D5*c_VR_so_cu+Units!D6*c_RU_so_cu+Units!D7*c_HP_so_cu+Units!D8*c_AMDR_so_cu+Units!D9*c_TPU_so_cu+Units!D10*c_TRN_so_cu+Units!D11*c_ASIC_so_cu)/1000 -> 29.8375 | F9: =(Units!E4*c_GB_so_cu+Units!E5*c_VR_so_cu+Units!E6*c_RU_so_cu+Units!E7*c_HP_so_cu+Units!E8*c_AMDR_so_cu+Units!E9*c_TPU_so_cu+Units!E10*c_TRN_so_cu+Units!E11*c_ASIC_so_cu)/1000 -> 33.92475
A10: 網卡／DPU（SuperNIC） | B10: $B | C10: =(Units!B4*c_GB_nic+Units!B5*c_VR_nic+Units!B6*c_RU_nic+Units!B7*c_HP_nic+Units!B8*c_AMD8_nic+Units!B9*c_TPU_nic+Units!B10*c_TRN_nic+Units!B11*c_ASIC_nic)/1000 -> 31.0096 | D10: =(Units!C4*c_GB_nic+Units!C5*c_VR_nic+Units!C6*c_RU_nic+Units!C7*c_HP_nic+Units!C8*c_AMDR_nic+Units!C9*c_TPU_nic+Units!C10*c_TRN_nic+Units!C11*c_ASIC_nic)/1000 -> 70.0976 | E10: =(Units!D4*c_GB_nic+Units!D5*c_VR_nic+Units!D6*c_RU_nic+Units!D7*c_HP_nic+Units!D8*c_AMDR_nic+Units!D9*c_TPU_nic+Units!D10*c_TRN_nic+Units!D11*c_ASIC_nic)/1000 -> 80.712 | F10: =(Units!E4*c_GB_nic+Units!E5*c_VR_nic+Units!E6*c_RU_nic+Units!E7*c_HP_nic+Units!E8*c_AMDR_nic+Units!E9*c_TPU_nic+Units!E10*c_TRN_nic+Units!E11*c_ASIC_nic)/1000 -> 91.966
A11: AI 網通市場合計 | B11: $B | C11: =SUM(C5:C10) -> 145.4533 | D11: =SUM(D5:D10) -> 292.4504 | E11: =SUM(E5:E10) -> 338.3565 | F11: =SUM(F5:F10) -> 385.3455
A12: 年增 | B12: % | D12: =D11/C11-1 -> 1.0106137 | E12: =E11/D11-1 -> 0.15697055 | F12: =F11/E11-1 -> 0.13887423
A13: scale-up（交換＋互連）÷ 合計 | B13: % | C13: =(C5+C6)/C11 -> 0.26429239 | D13: =(D5+D6)/D11 -> 0.26818702 | E13: =(E5+E6)/E11 -> 0.27889814 | F13: =(F5+F6)/F11 -> 0.27910434 | G13: 先驗 N2：Andy 80%
A14: scale-out（交換、光、銅、網卡）÷ 合計 | B14: % | C14: =1-C13 -> 0.73570761 | D14: =1-D13 -> 0.73181298 | E14: =1-E13 -> 0.72110186 | F14: =1-F13 -> 0.72089566
A16: 依產品類別（廠商視角）
A17: 交換晶片與交換器（scale-up＋scale-out） | B17: $B | C17: =C5+C7 -> 50.348 | D17: =D5+D7 -> 98.5007 | E17: =E5+E7 -> 113.9885 | F17: =F5+F7 -> 129.72795
A18: 光學（可插拔＋CPO＋scale-up 光學） | B18: $B | C18: =C8+C6*suopt_26 -> 30.0538 | D18: =D8+D6*suopt_27 -> 56.3797 | E18: =E8+E6*suopt_28 -> 64.435 | F18: =F8+F6*suopt_29 -> 84.68216
A19: 其中 CPO | B19: $B | C19: =C8*cpo_26 -> 0.300538 | D19: =D8*cpo_27 -> 1.691391 | E19: =E8*cpo_28 -> 3.22175 | F19: =F8*cpo_29 -> 5.87368
A20: 其中可插拔 | B20: $B | C20: =C18-C19 -> 29.753262 | D20: =D18-D19 -> 54.688309 | E20: =E18-E19 -> 61.21325 | F20: =F18-F19 -> 78.80848
A21: 銅（scale-up 背板與線纜＋scale-out DAC／AEC） | B21: $B | C21: =C9+C6*(1-suopt_26)*su_cu -> 25.97546 | D21: =D9+D6*(1-suopt_27)*su_cu -> 51.06612 | E21: =E9+E6*(1-suopt_28)*su_cu -> 59.4676 | F21: =F9+F6*(1-suopt_29)*su_cu -> 60.951534
A22: 交換匣其他（電路板、電源、機構） | B22: $B | C22: =C6*(1-suopt_26)*(1-su_cu) -> 8.06644 | D22: =D6*(1-suopt_27)*(1-su_cu) -> 16.40628 | E22: =E6*(1-suopt_28)*(1-su_cu) -> 19.7534 | F22: =F6*(1-suopt_29)*(1-su_cu) -> 18.017856
A23: 網卡／DPU | B23: $B | C23: =C10 -> 31.0096 | D23: =D10 -> 70.0976 | E23: =E10 -> 80.712 | F23: =F10 -> 91.966
A24: 核對：類別合計 − 合計（應為 0） | B24: $B | C24: =C17+C18+C21+C22+C23-C11 -> 0 | D24: =D17+D18+D21+D22+D23-D11 -> 0 | E24: =E17+E18+E21+E22+E23-E11 -> 0 | F24: =F17+F18+F21+F22+F23-F11 -> 0
A26: 網通 ÷ AI IT 資本支出
A27: AI IT 資本支出（加速器 × 每顆 IT capex） | B27: $B | C27: =(Units!B4*it_GB+Units!B5*it_VR+Units!B6*it_RU+Units!B7*it_HP+Units!B8*it_AMD8+Units!B9*it_TPU+Units!B10*it_TRN+Units!B11*it_ASIC) -> 781.87292 | D27: =(Units!C4*it_GB+Units!C5*it_VR+Units!C6*it_RU+Units!C7*it_HP+Units!C8*it_AMDR+Units!C9*it_TPU+Units!C10*it_TRN+Units!C11*it_ASIC) -> 1565.35 | E27: =(Units!D4*it_GB+Units!D5*it_VR+Units!D6*it_RU+Units!D7*it_HP+Units!D8*it_AMDR+Units!D9*it_TPU+Units!D10*it_TRN+Units!D11*it_ASIC) -> 1984.2639 | F27: =(Units!E4*it_GB+Units!E5*it_VR+Units!E6*it_RU+Units!E7*it_HP+Units!E8*it_AMDR+Units!E9*it_TPU+Units!E10*it_TRN+Units!E11*it_ASIC) -> 2260.3903 | G27: 百萬顆 × 千美元 ＝ 十億美元
A28: 網通 ÷ AI IT capex | B28: % | C28: =C11/C27 -> 0.18603189 | D28: =D11/D27 -> 0.18682748 | E28: =E11/E27 -> 0.17051991 | F28: =F11/F27 -> 0.17047742 | G28: 先驗 N1：Andy 2026 15%、2027 20%；Bernstein 換算約 17%
A29: NVIDIA 平台 ÷ NVIDIA 平台 IT | B29: % | C29: =((Units!B4*c_GB_su_sw+Units!B5*c_VR_su_sw+Units!B6*c_RU_su_sw+Units!B7*c_HP_su_sw)/1000+(Units!B4*c_GB_su_ic+Units!B5*c_VR_su_ic+Units!B6*c_RU_su_ic+Units!B7*c_HP_su_ic)/1000+(Units!B4*c_GB_so_sw+Units!B5*c_VR_so_sw+Units!B6*c_RU_so_sw+Units!B7*c_HP_so_sw)/1000+(Units!B4*c_GB_so_opt+Units!B5*c_VR_so_opt+Units!B6*c_RU_so_opt+Units!B7*c_HP_so_opt)/1000+(Units!B4*c_GB_so_cu+Units!B5*c_VR_so_cu+Units!B6*c_RU_so_cu+Units!B7*c_HP_so_cu)/1000+(Units!B4*c_GB_nic+Units!B5*c_VR_nic+Units!B6*c_RU_nic+Units!B7*c_HP_nic)/1000)/(Units!B4*it_GB+Units!B5*it_VR+Units!B6*it_RU+Units!B7*it_HP) -> 0.1816641 | D29: =((Units!C4*c_GB_su_sw+Units!C5*c_VR_su_sw+Units!C6*c_RU_su_sw+Units!C7*c_HP_su_sw)/1000+(Units!C4*c_GB_su_ic+Units!C5*c_VR_su_ic+Units!C6*c_RU_su_ic+Units!C7*c_HP_su_ic)/1000+(Units!C4*c_GB_so_sw+Units!C5*c_VR_so_sw+Units!C6*c_RU_so_sw+Units!C7*c_HP_so_sw)/1000+(Units!C4*c_GB_so_opt+Units!C5*c_VR_so_opt+Units!C6*c_RU_so_opt+Units!C7*c_HP_so_opt)/1000+(Units!C4*c_GB_so_cu+Units!C5*c_VR_so_cu+Units!C6*c_RU_so_cu+Units!C7*c_HP_so_cu)/1000+(Units!C4*c_GB_nic+Units!C5*c_VR_nic+Units!C6*c_RU_nic+Units!C7*c_HP_nic)/1000)/(Units!C4*it_GB+Units!C5*it_VR+Units!C6*it_RU+Units!C7*it_HP) -> 0.18240181 | E29: =((Units!D4*c_GB_su_sw+Units!D5*c_VR_su_sw+Units!D6*c_RU_su_sw+Units!D7*c_HP_su_sw)/1000+(Units!D4*c_GB_su_ic+Units!D5*c_VR_su_ic+Units!D6*c_RU_su_ic+Units!D7*c_HP_su_ic)/1000+(Units!D4*c_GB_so_sw+Units!D5*c_VR_so_sw+Units!D6*c_RU_so_sw+Units!D7*c_HP_so_sw)/1000+(Units!D4*c_GB_so_opt+Units!D5*c_VR_so_opt+Units!D6*c_RU_so_opt+Units!D7*c_HP_so_opt)/1000+(Units!D4*c_GB_so_cu+Units!D5*c_VR_so_cu+Units!D6*c_RU_so_cu+Units!D7*c_HP_so_cu)/1000+(Units!D4*c_GB_nic+Units!D5*c_VR_nic+Units!D6*c_RU_nic+Units!D7*c_HP_nic)/1000)/(Units!D4*it_GB+Units!D5*it_VR+Units!D6*it_RU+Units!D7*it_HP) -> 0.16018511 | F29: =((Units!E4*c_GB_su_sw+Units!E5*c_VR_su_sw+Units!E6*c_RU_su_sw+Units!E7*c_HP_su_sw)/1000+(Units!E4*c_GB_su_ic+Units!E5*c_VR_su_ic+Units!E6*c_RU_su_ic+Units!E7*c_HP_su_ic)/1000+(Units!E4*c_GB_so_sw+Units!E5*c_VR_so_sw+Units!E6*c_RU_so_sw+Units!E7*c_HP_so_sw)/1000+(Units!E4*c_GB_so_opt+Units!E5*c_VR_so_opt+Units!E6*c_RU_so_opt+Units!E7*c_HP_so_opt)/1000+(Units!E4*c_GB_so_cu+Units!E5*c_VR_so_cu+Units!E6*c_RU_so_cu+Units!E7*c_HP_so_cu)/1000+(Units!E4*c_GB_nic+Units!E5*c_VR_nic+Units!E6*c_RU_nic+Units!E7*c_HP_nic)/1000)/(Units!E4*it_GB+Units!E5*it_VR+Units!E6*it_RU+Units!E7*it_HP) -> 0.15999158
A31: 廠商歸屬與對帳（2026）
A32: NVIDIA 網通（本模型歸屬） | B32: $B | C32: =(Units!B4*c_GB_su_sw+Units!B5*c_VR_su_sw+Units!B6*c_RU_su_sw+Units!B7*c_HP_su_sw)/1000+nv_su_ic*(Units!B4*c_GB_su_ic+Units!B5*c_VR_su_ic+Units!B6*c_RU_su_ic+Units!B7*c_HP_su_ic)/1000+nv_so_sw*(Units!B4*c_GB_so_sw+Units!B5*c_VR_so_sw+Units!B6*c_RU_so_sw+Units!B7*c_HP_so_sw)/1000+(Units!B4*c_GB_nic+Units!B5*c_VR_nic+Units!B6*c_RU_nic+Units!B7*c_HP_nic)/1000+nv_opt*(Units!B4*c_GB_so_opt+Units!B5*c_VR_so_opt+Units!B6*c_RU_so_opt+Units!B7*c_HP_so_opt)/1000 -> 61.733865 | D32: =(Units!C4*c_GB_su_sw+Units!C5*c_VR_su_sw+Units!C6*c_RU_su_sw+Units!C7*c_HP_su_sw)/1000+nv_su_ic*(Units!C4*c_GB_su_ic+Units!C5*c_VR_su_ic+Units!C6*c_RU_su_ic+Units!C7*c_HP_su_ic)/1000+nv_so_sw*(Units!C4*c_GB_so_sw+Units!C5*c_VR_so_sw+Units!C6*c_RU_so_sw+Units!C7*c_HP_so_sw)/1000+(Units!C4*c_GB_nic+Units!C5*c_VR_nic+Units!C6*c_RU_nic+Units!C7*c_HP_nic)/1000+nv_opt*(Units!C4*c_GB_so_opt+Units!C5*c_VR_so_opt+Units!C6*c_RU_so_opt+Units!C7*c_HP_so_opt)/1000 -> 122.48807 | E32: =(Units!D4*c_GB_su_sw+Units!D5*c_VR_su_sw+Units!D6*c_RU_su_sw+Units!D7*c_HP_su_sw)/1000+nv_su_ic*(Units!D4*c_GB_su_ic+Units!D5*c_VR_su_ic+Units!D6*c_RU_su_ic+Units!D7*c_HP_su_ic)/1000+nv_so_sw*(Units!D4*c_GB_so_sw+Units!D5*c_VR_so_sw+Units!D6*c_RU_so_sw+Units!D7*c_HP_so_sw)/1000+(Units!D4*c_GB_nic+Units!D5*c_VR_nic+Units!D6*c_RU_nic+Units!D7*c_HP_nic)/1000+nv_opt*(Units!D4*c_GB_so_opt+Units!D5*c_VR_so_opt+Units!D6*c_RU_so_opt+Units!D7*c_HP_so_opt)/1000 -> 138.6168 | F32: =(Units!E4*c_GB_su_sw+Units!E5*c_VR_su_sw+Units!E6*c_RU_su_sw+Units!E7*c_HP_su_sw)/1000+nv_su_ic*(Units!E4*c_GB_su_ic+Units!E5*c_VR_su_ic+Units!E6*c_RU_su_ic+Units!E7*c_HP_su_ic)/1000+nv_so_sw*(Units!E4*c_GB_so_sw+Units!E5*c_VR_so_sw+Units!E6*c_RU_so_sw+Units!E7*c_HP_so_sw)/1000+(Units!E4*c_GB_nic+Units!E5*c_VR_nic+Units!E6*c_RU_nic+Units!E7*c_HP_nic)/1000+nv_opt*(Units!E4*c_GB_so_opt+Units!E5*c_VR_so_opt+Units!E6*c_RU_so_opt+Units!E7*c_HP_so_opt)/1000 -> 157.29971
A33: 對照：NVIDIA 實際（2026） | B33: $B | C33: =rep_nv26 -> 74
A34: 差距 | B34: % | C34: =C32/C33-1 -> -0.16575858
A35: Broadcom 網通（本模型歸屬） | B35: $B | C35: =avgo_su*(Units!B8*c_AMD8_su_sw+Units!B9*c_TPU_su_sw+Units!B10*c_TRN_su_sw+Units!B11*c_ASIC_su_sw)/1000+avgo_so*((1-nv_so_sw)*(Units!B4*c_GB_so_sw+Units!B5*c_VR_so_sw+Units!B6*c_RU_so_sw+Units!B7*c_HP_so_sw)/1000+(Units!B8*c_AMD8_so_sw+Units!B9*c_TPU_so_sw+Units!B10*c_TRN_so_sw+Units!B11*c_ASIC_so_sw)/1000)+avgo_nic*(Units!B8*c_AMD8_nic+Units!B9*c_TPU_nic+Units!B10*c_TRN_nic+Units!B11*c_ASIC_nic)/1000+avgo_opt*C18 -> 12.607573 | D35: =avgo_su*(Units!C8*c_AMDR_su_sw+Units!C9*c_TPU_su_sw+Units!C10*c_TRN_su_sw+Units!C11*c_ASIC_su_sw)/1000+avgo_so*((1-nv_so_sw)*(Units!C4*c_GB_so_sw+Units!C5*c_VR_so_sw+Units!C6*c_RU_so_sw+Units!C7*c_HP_so_sw)/1000+(Units!C8*c_AMDR_so_sw+Units!C9*c_TPU_so_sw+Units!C10*c_TRN_so_sw+Units!C11*c_ASIC_so_sw)/1000)+avgo_nic*(Units!C8*c_AMDR_nic+Units!C9*c_TPU_nic+Units!C10*c_TRN_nic+Units!C11*c_ASIC_nic)/1000+avgo_opt*D18 -> 26.959549 | E35: =avgo_su*(Units!D8*c_AMDR_su_sw+Units!D9*c_TPU_su_sw+Units!D10*c_TRN_su_sw+Units!D11*c_ASIC_su_sw)/1000+avgo_so*((1-nv_so_sw)*(Units!D4*c_GB_so_sw+Units!D5*c_VR_so_sw+Units!D6*c_RU_so_sw+Units!D7*c_HP_so_sw)/1000+(Units!D8*c_AMDR_so_sw+Units!D9*c_TPU_so_sw+Units!D10*c_TRN_so_sw+Units!D11*c_ASIC_so_sw)/1000)+avgo_nic*(Units!D8*c_AMDR_nic+Units!D9*c_TPU_nic+Units!D10*c_TRN_nic+Units!D11*c_ASIC_nic)/1000+avgo_opt*E18 -> 32.094922 | F35: =avgo_su*(Units!E8*c_AMDR_su_sw+Units!E9*c_TPU_su_sw+Units!E10*c_TRN_su_sw+Units!E11*c_ASIC_su_sw)/1000+avgo_so*((1-nv_so_sw)*(Units!E4*c_GB_so_sw+Units!E5*c_VR_so_sw+Units!E6*c_RU_so_sw+Units!E7*c_HP_so_sw)/1000+(Units!E8*c_AMDR_so_sw+Units!E9*c_TPU_so_sw+Units!E10*c_TRN_so_sw+Units!E11*c_ASIC_so_sw)/1000)+avgo_nic*(Units!E8*c_AMDR_nic+Units!E9*c_TPU_nic+Units!E10*c_TRN_nic+Units!E11*c_ASIC_nic)/1000+avgo_opt*F18 -> 37.832817
A36: 對照：Broadcom 實際（2026） | B36: $B | C36: =rep_avgo26 -> 17.6
A37: 差距 | B37: % | C37: =C35/C36-1 -> -0.28366065
A38: NVIDIA＋Broadcom ÷ 市場 | B38: % | C38: =(C32+C35)/C11 -> 0.51110176 | D38: =(D32+D35)/D11 -> 0.51101867 | E38: =(E32+E35)/E11 -> 0.50453212 | F38: =(F32+F35)/F11 -> 0.50638331 | G38: 先驗 N3：Andy ≥50%
A39: 光學：本模型 vs LightCounting（2026） | B39: $B | C39: =C18 -> 30.0538 | D39: =rep_opt26 -> 26 | G39: C＝本模型、D＝LightCounting AI 叢集光學（含 scale-up）
A40: 差距 | B40: % | C40: =C39/D39-1 -> 0.15591538

Sheet Sens
A1: Sens — 一次動一個輸入；輸出：2027 AI 網通市場（$B）、網通 ÷ IT capex
A3: 輸入 | B3: 2027 市場 | C3: 相對基準 | D3: 說明
A4: 基準 | B4: =Mkt!D11 -> 292.4504 | C4: =B4/B$4-1 -> 0
A5: Rubin 顆數 −30% | B5: =Mkt!D11-0.3*u_rb_27*(c_VR_su_sw+c_VR_su_ic+c_VR_so_sw+c_VR_so_opt+c_VR_so_cu+c_VR_nic)/1000 -> 240.9941 | C5: =B5/B$4-1 -> -0.17594881 | D5: Rubin 是 2027 最大項
A6: Rubin 顆數 +30% | B6: =Mkt!D11+0.3*u_rb_27*(c_VR_su_sw+c_VR_su_ic+c_VR_so_sw+c_VR_so_opt+c_VR_so_cu+c_VR_nic)/1000 -> 343.9067 | C6: =B6/B$4-1 -> 0.17594881
A7: VR200 每顆內容 −20% | B7: =Mkt!D11-0.2*u_rb_27*(c_VR_su_sw+c_VR_su_ic+c_VR_so_sw+c_VR_so_opt+c_VR_so_cu+c_VR_nic)/1000 -> 258.1462 | C7: =B7/B$4-1 -> -0.11729921
A8: VR200 每顆內容 +20% | B8: =Mkt!D11+0.2*u_rb_27*(c_VR_su_sw+c_VR_su_ic+c_VR_so_sw+c_VR_so_opt+c_VR_so_cu+c_VR_nic)/1000 -> 326.7546 | C8: =B8/B$4-1 -> 0.11729921
A9: ASIC（TPU、Trainium、其他）每顆內容 ×2 | B9: =Mkt!D11+(Units!C9*(c_TPU_su_sw+c_TPU_su_ic+c_TPU_so_sw+c_TPU_so_opt+c_TPU_so_cu+c_TPU_nic)+Units!C10*(c_TRN_su_sw+c_TRN_su_ic+c_TRN_so_sw+c_TRN_so_opt+c_TRN_so_cu+c_TRN_nic)+Units!C11*(c_ASIC_su_sw+c_ASIC_su_ic+c_ASIC_so_sw+c_ASIC_so_opt+c_ASIC_so_cu+c_ASIC_nic))/1000 -> 347.9504 | C9: =B9/B$4-1 -> 0.18977577 | D9: ASIC 網通內容為 Assumed，不確定性最大

Sheet Sources
A1: 來源
A2: markets/chip_bridge v0.2.1（每 GW 網通拆分） | B2: 本 repo
A3: markets/memory/market.py（加速器顆數） | B3: 本 repo
A4: NVIDIA Q1 FY27 CFO 書面說明 | B4: https://s201.q4cdn.com/141608511/files/doc_financials/2027/Q127/Q1FY27-CFO-Commentary.pdf
A5: NVIDIA Q2 FY27 法說（Webull） | B5: https://www.webull.com/news/15497781742806016
A6: Broadcom Q3 FY26（MarketBeat） | B6: https://www.marketbeat.com/instant-alerts/transcript-broadcom-q3-earnings-call-highlights-2026-09-02/
A7: Dell'Oro 2026-07（2026–30 約 1 兆） | B7: https://www.delloro.com/news/ai-back-end-switch-sales-to-approach-1-trillion-over-the-next-five-years/
A8: Dell'Oro 2Q26 | B8: https://www.delloro.com/news/ai-back-end-networks-switch-sales-surpass-front-end-networks-for-the-first-time-in-2q2026/
A9: LightCounting 2026-01 AI 叢集光學 | B9: https://lightcounting.com/newsletter/en/january-2026-optics-for-ai-clusters-366
A10: LightCounting 2025-12 CPO | B10: https://lightcounting.com/newsletter/en/december-2025-aocs-dacs-linear-drive-pluggable-and-co-packaged-optics-320
A11: Cignal AI CPO 1Q26 | B11: https://cignal.ai/2026/04/cpo-and-elsfp-1q26-update/
A12: TrendForce 2026-07-27（CPO 放量 2027–28） | B12: https://trendforce.com/presscenter/news/20260727-13151.html
A13: The Register 2026-04-05（NVLink 銅／光） | B13: https://www.theregister.com/2026/04/05/nvidia_optical_scale_up/
A14: Bernstein（Investing.com） | B14: https://www.investing.com/news/stock-market-news/how-much-does-a-gw-of-data-center-capacity-actually-cost-4314046
