Workbook

Sheet README
A1: Broadcom（AVGO）收支與估值模型 v0.2.1（AI 半導體 Project：運算層第二個樣板，ASIC＋網通） 2026-10-25
A2: 版本：v0.1（初版）。ASIC 每顆規格（Broadcom 份額、核心售價、HBM 代購）在本模型 Units 頁建立，為本專案權威資料（規則第 13 條）。
A3: 模型命題：Broadcom 的 AI 營收＝各 XPU 平台的顆數 × Broadcom 份額 × 每顆售價（核心＋代購 HBM）＋網通附掛；2027–28 年的增量集中在 Anthropic、OpenAI 兩家靠融資部署的客戶。股價約 17 倍 FY2027 EPS：這個折價是在定價客戶信用風險，還是低估了營收？
A4: 核心問題：以市場層顆數往前推，Broadcom 的 AI 營收與 EPS 能否支撐公司展望（FY2027 約 115B、FY2028 約 230B）；差距要靠多少額外顆數補上。
A6: 會計年度：FY(t) 於 t 年 10 月底／11 月初結束，10/12 落在日曆年 t，FY(t) 直接對照 CY(t)，不做平移。預測期 FY2027–FY2029（三年）。口徑：公司 non-GAAP（排除股票薪酬、攤銷、重組）。
A8: 驅動因子 → 推導量（全部唯讀上游，不修改）
A9: XPU：Google TPU 與「其他 ASIC」顆數（markets/memory UNITS × 情境係數）× Broadcom 份額（Assumed）×（核心售價＋代購比例 × 每顆 HBM 容量 × HBM 單價）× k_x（FY2026 實績校準）→ XPU 營收。
A10: AI 網通：markets/network 的「Broadcom 網通（本模型歸屬）」× 情境顆數係數 × k_n（FY2026 實際推估校準）。非 AI 半導體、軟體：FY2026 錨點 × Assumed 成長率。
A11: 毛利率：網通、非 AI、軟體、代購 HBM 各用 Assumed 毛利率；XPU 核心毛利率 m_core 為 FY2026 殘差（Derived）。FY2027 起毛利率下滑來自代購 HBM 占比上升（HBM 2027 年 +80%、每顆容量上升）。
A12: 校準：FY2026 ＝ Q1–Q3 實績＋Q4 指引（營收 34.8、AI 21.7、營業利益率 66%）。不用共識、不用公司對 FY2027–28 的展望（只在 Recon 對帳）。
A13: 估值：結論用現價 ÷ FY2027、FY2028 EPS；十年 GAAP P/E 規則值不適用（攤銷扭曲），前瞻 P/E 歷史待 Bloomberg。循環位置（共用規則，不平移）只作紀錄：設備市場見頂年度 A 2029、B 2028、C 2027。
A14: 標記：Verified、Interested-party、Analogy、Assumed、Derived。SemiAnalysis 未使用。公司原文＝SEC EDGAR 8-K；法說內容只經二手轉述（標二手）。
... A19: v0.2.1（2026-10-25）：補上檔空間級距、投資建議、重點觀察（數值不變）。Val 頁末新增「上檔空間級距」「投資建議」兩列（Andy 2026-10-25 14:00、14:17 固定規則），README 頁末新增投資建議與重點觀察三點；既有儲存格位置與數值不變。另依算力收支 2026-10-25 請求，PL 頁末新增「自由現金流（淨利＋折舊 − 資本支出；不含營運資金變動）」一列（三情境 × 各年度），In 頁末新增 da_rev、cx_rev 兩個比率（最近完整會計年度實績）。
A20: ="投資建議："&Val!B113&"（依上檔空間固定規則）" -> 投資建議：中立（依上檔空間固定規則）
A21: ="重點觀察 1：目標價 US$"&TEXT(Val!$B$40,"#,##0.00")&"（DCF "&TEXT(Val!$B$23,"#,##0.00")&"、Comparable（相對倍數調整後）"&TEXT(tp_comp_adj,"#,##0.00")&"；DCF 權重 "&TEXT(tp_w_dcf,"0%")&"），比現價 "&TEXT(px,"#,##0.00")&"（2026-10-23）"&IF(Val!$B$43>=0,"高 "&TEXT(Val!$B$43,"0.0%"),"低 "&TEXT(-Val!$B$43,"0.0%"))&"，級距 "&Val!$B$112&"、投資建議 "&Val!$B$113&"。相對倍數調整係數 "&TEXT(rm_factor,"0.00")&"（本公司 10 年前瞻倍數中位數 ÷ 同業的中位數，夾在 0.5–2.0；Val 第 0.5 節），調整前加權上檔空間 "&TEXT((tp_w_dcf*Val!$B$23+(1-tp_w_dcf)*Val!$B$36)/px-1,"+0.0%;−0.0%")&"；Comparable 單獨（市場主流同業法、未調整）為 "&TEXT(Val!$B$44,"+0.0%;−0.0%")&"。"&"以下為 2026-10-29 相對倍數調整前撰寫的說明，其中數字為調整前：與共識目標價 529.1 的差距主要在倍數：本模型 FY2027 EPS 18.08 只比共識 19.40 低 6.8%，但共識目標價隱含 27.3 倍共識 EPS，比同業（NVIDIA、AMD、Marvell、Qualcomm、台積電 ADR）前瞻 P/E 中位數 19.6 倍高 39.1%；現價隱含 16.6 倍。" -> 重點觀察 1：目標價 US$273.11（DCF 324.56、Comparable（相對倍數調整後）221.65；DCF 權重 50%），比現價 321.68（2026-10-23）低 15.1%，級距 0%～−25%、投資建議 中立。相對倍數調整係數 0.62（本公司 10 年前瞻倍數中位數 ÷ 同業的中位數，夾在 0.5–2.0；Val 第 0.5 節），調整前加權上檔空間 +5.9%；Comparable 單獨（市場主流同業法、未調整）為 +10.9%。以下為 2026-10-29 相對倍數調整前撰寫的說明，其中數字為調整前：與共識目標價 529.1 的差距主要在倍數：本模型 FY2027 EPS 18.08 只比共識 19.40 低 6.8%，但共識目標價隱含 27.3 倍共識 EPS，比同業（NVIDIA、AMD、Marvell、Qualcomm、台積電 ADR）前瞻 P/E 中位數 19.6 倍高 39.1%；現價隱含 16.6 倍。
A22: 重點觀察 2：情境分歧從 FY2028 起：FY2027 EPS 三情境同為 18.08，FY2028 A／B／C 為 21.03／17.84／14.82（B、C 低於 FY2027），DCF 價格帶 222～394；現價約為 B 情境 FY2028 EPS 的 18.0 倍。PL 頁末自由現金流（non-GAAP 淨利＋折舊 − 資本支出）B 情境 FY2027 約 88.8、FY2028 約 87.2 十億美元，與淨利幾乎相同（資本支出約為營收 1%）。
A23: 重點觀察 3：FY2027 EPS 最敏感的是 XPU 核心售價（±20% 對 EPS ±8.2%），其次是 TPU 份額（−15pt 時 −5.7%，聯發科版 TPU 放量）與 AI 網通（×0.8 時 −5.1%）（Sens 頁）。下一個檢驗點是 FY2026 第四季財報（約 2026-12 中旬）的 AI 半導體營收與下一季指引。
A25: 2026-10-29：加權目標價中的 Comparable 改用相對倍數調整後的值（Val 第 0.5 節：同業前瞻倍數中位數 × 本公司 10 年相對同業的倍數比，Bloomberg 前瞻倍數；Andy 2026-10-27「照建議做」、10-29 資料取回）。「Comparable 目標價（市場主流同業法）」維持不調整。重點觀察 1 的第一句已改為公式；重點觀察 2、3 與其他說明中的目標價與上檔空間數字為調整前撰寫，以 Val 頁為準。
A27: v0.3.1（2026-10-30）：依個股模型原則第 8 節調整 In 頁呈現（數值不變）。In 頁 D／F 欄名改「敏感度低」「敏感度高」（只用於 Sens 頁、不進目標價）；In 頁最後新增「情境驅動對照」一節，把上方各情境專屬輸入三情境並排（只引用上方各列，純展示）；HTML 驅動因子一節分「情境驅動」與「單一參數」兩張表。

Sheet In
A1: In — 輸入（藍字；基準欄 E，低 D、高 F）。金額：十億美元（US$B）；每顆價格：千美元（US$K）；顆數：百萬顆；HBM：GB、US$/GB。每個輸入附兩個來源（找不到者寫「未找到」）；公司原文算一個。【v0.3.1】基準欄 E 進主模型；D／F＝敏感度低／高，只用於 Sens 頁（一次動一個參數）、不進目標價；情境 A／B／C 的驅動見本頁最後一節「情境驅動對照」。
A2: 標記：Verified／Interested-party／Analogy／Assumed／Derived；Analogy、Assumed 給低／高區間。SemiAnalysis 未使用。公司原文＝Broadcom 8-K 新聞稿（SEC EDGAR、investors.broadcom.com）；公司對 FY2027、FY2028 的 AI 營收展望為 Interested-party，只放 Recon 對帳，不作校準
A3: 鍵 | B3: 項目 | C3: 單位 | D3: 敏感度低 | E3: 基準 | F3: 敏感度高 | G3: 標記 | H3: 來源1 | I3: 來源2／說明
A4: A. 加速器顆數（markets/memory 與 HBM、台積電、網通、NVIDIA 模型同一份；情境係數讀台積電模型成品，不另訂）
A5: u_bw_26 | B5: NVIDIA Blackwell（B200／B300） 顆數 2026 | C5: 百萬顆 | E5: 5.4 | G5: Interested-party | H5: markets/memory/market.py UNITS：顆數：Morgan Stanley 2026-07（2026 5.4M）；AC Research 2027 約 2.4M；2028 Assumed。GB：B200 186、B300 288 組合 [Derived] | I5: 台積電模型 tsmc/dist/20261030_台積電個股模型_v0.4.1.xlsx｜In!E5（值相同，建置時檢查）
A6: u_bw_27 | B6: NVIDIA Blackwell（B200／B300） 顆數 2027 | C6: 百萬顆 | E6: 2.4 | G6: Interested-party | H6: 同上 | I6: 同上
A7: u_bw_28 | B7: NVIDIA Blackwell（B200／B300） 顆數 2028 | C7: 百萬顆 | E7: 0.5 | G7: Interested-party | H7: 同上 | I7: 同上
A8: g29_bw | B8: NVIDIA Blackwell（B200／B300） 2029 顆數成長 | C8: % | E8: -0.5 | G8: Assumed | H8: tsmc/dist/20261030_台積電個股模型_v0.4.1.xlsx｜In!E8 | I8: markets/memory 無 2029；沿用台積電模型
A9: u_rb_26 | B9: NVIDIA Rubin 顆數 2026 | C9: 百萬顆 | E9: 1.7 | G9: Interested-party | H9: markets/memory/market.py UNITS：2026：TrendForce 組合 Rubin 22% × 約 7.6M [Derived]；2027：Morgan Stanley 約 7.0M；2028 Assumed | I9: 台積電模型 tsmc/dist/20261030_台積電個股模型_v0.4.1.xlsx｜In!E9（值相同，建置時檢查）
A10: u_rb_27 | B10: NVIDIA Rubin 顆數 2027 | C10: 百萬顆 | E10: 7 | G10: Interested-party | H10: 同上 | I10: 同上
A11: u_rb_28 | B11: NVIDIA Rubin 顆數 2028 | C11: 百萬顆 | E11: 7 | G11: Interested-party | H11: 同上 | I11: 同上
A12: g29_rb | B12: NVIDIA Rubin 2029 顆數成長 | C12: % | E12: 0.15 | G12: Assumed | H12: tsmc/dist/20261030_台積電個股模型_v0.4.1.xlsx｜In!E12 | I12: markets/memory 無 2029；沿用台積電模型
A13: u_ru_26 | B13: NVIDIA Rubin Ultra 顆數 2026 | C13: 百萬顆 | E13: 0 | G13: Assumed | H13: markets/memory/market.py UNITS：時程 Assumed；GB：NVIDIA 1 TB／封裝 | I13: 台積電模型 tsmc/dist/20261030_台積電個股模型_v0.4.1.xlsx｜In!E13（值相同，建置時檢查）
A14: u_ru_27 | B14: NVIDIA Rubin Ultra 顆數 2027 | C14: 百萬顆 | E14: 0.3 | G14: Assumed | H14: 同上 | I14: 同上
A15: u_ru_28 | B15: NVIDIA Rubin Ultra 顆數 2028 | C15: 百萬顆 | E15: 2 | G15: Assumed | H15: 同上 | I15: 同上
A16: g29_ru | B16: NVIDIA Rubin Ultra 2029 顆數成長 | C16: % | E16: 0.15 | G16: Assumed | H16: tsmc/dist/20261030_台積電個股模型_v0.4.1.xlsx｜In!E16 | I16: markets/memory 無 2029；沿用台積電模型
... A48: gb_oth_28 | B48: 其他 ASIC（MTIA、Maia、Ascend 等） 每顆 HBM 2028 | C48: GB | E48: 250 | G48: Derived／Assumed | H48: markets/memory/market.py UNITS | I48: 同上
A49: B. ASIC 每顆規格（本專案為權威，規則第 13 條）：Broadcom 在各平台的顆數份額、每顆核心售價（不含 HBM）、HBM 由 Broadcom 代購的比例
A50: sh_tpu_26 | B50: Broadcom 占 Google TPU 顆數 2026 | C50: % | D50: 0.8 | E50: 0.9 | F50: 1 | G50: Assumed | H50: Broadcom 為 TPU 主要設計夥伴（Ironwood／v7、v8i 量產；法說）；Google 與 MediaTek 另有合作（Counterpoint 2026-01，二手） | I50: 各家份額未揭露：未找到
A51: sh_tpu_27 | B51: Broadcom 占 Google TPU 顆數 2027 | C51: % | D51: 0.6 | E51: 0.8 | F51: 0.9 | G51: Assumed | H51: 同上；MediaTek 版 TPU 放量的時點未揭露 | I51: Anthropic 2027 年約 5 GW 的 TPU v8i（公司說法，Interested-party）屬 Broadcom
A52: sh_tpu_28 | B52: Broadcom 占 Google TPU 顆數 2028（2029 沿用） | C52: % | D52: 0.5 | E52: 0.75 | F52: 0.9 | G52: Assumed | H52: 同上 | I52: —
A53: sh_oth_26 | B53: Broadcom 占「其他 ASIC」顆數 2026 | C53: % | D53: 0.2 | E53: 0.35 | F53: 0.5 | G53: Assumed | H53: 其他 ASIC＝MTIA（Broadcom）、OpenAI 客製（Broadcom，2026 Q3 開始出貨）、Maia（非 Broadcom）、昇騰（華為）等 | I53: XPU 客戶 6 家：Google、Anthropic、OpenAI、Meta＋2 家未具名（法說，二手）
A54: sh_oth_27 | B54: Broadcom 占「其他 ASIC」顆數 2027 | C54: % | D54: 0.4 | E54: 0.55 | F54: 0.7 | G54: Assumed | H54: OpenAI 2027 年 1.3 GW、Meta 至 2028 年共 3 GW（公司說法，Interested-party） | I54: —
A55: sh_oth_28 | B55: Broadcom 占「其他 ASIC」顆數 2028（2029 沿用） | C55: % | D55: 0.4 | E55: 0.55 | F55: 0.7 | G55: Assumed | H55: OpenAI 2028 年 5 GW 以上（公司說法） | I55: —
A56: core_tpu | B56: TPU 每顆核心售價（Broadcom 營收，不含 HBM；2026 基準） | C56: US$K | D56: 6 | E56: 8 | F56: 11 | G56: Assumed | H56: 無：每顆 ASP 未揭露。NVIDIA 模型 pa_tpu（含 HBM）8–12–18K；192 GB × 2026 HBM 價約 2.8K | I56: nvidia/dist/20261025_NVIDIA模型_v0.2.1.xlsx｜In!E146（含 HBM 的對照值）
A57: core_oth | B57: 其他 ASIC 每顆核心售價（Broadcom 營收，不含 HBM；2026 基準） | C57: US$K | D57: 4 | E57: 6 | F57: 9 | G57: Assumed | H57: 無：未揭露。Maia 200 約為 NVIDIA 的 30–40%＝$9–12K（二手，含 HBM）作量級參照 | I57: nvidia/dist/20261025_NVIDIA模型_v0.2.1.xlsx｜In!E148（含 HBM 的對照值）
A58: f_hbm | B58: HBM 由 Broadcom 代購並計入營收的比例 | C58: x | D58: 0.3 | E58: 0.6 | F58: 1 | G58: Assumed | H58: 公司：毛利率下滑來自「記憶體含量高的 XPU」占比上升（Q3 FY26 法說，二手）→ 至少部分 HBM 經 Broadcom 轉售 | I58: 第二來源：未找到。客戶自購 HBM（consigned）的比例未揭露
A59: m_hbm | B59: 代購 HBM 的毛利率 | C59: x | D59: 0 | E59: 0.1 | F59: 0.2 | G59: Assumed | H59: 無：未揭露；轉售料件通常低加成 | I59: 第二來源：未找到
A60: pfc | B60: 2027 年起 XPU 核心售價係數（Sens 用；基準 1） | C60: x | D60: 0.8 | E60: 1 | F60: 1.2 | G60: Assumed | H60: 無：新一代（TPU v8、MTIA 新世代）核心單價變化未揭露 | I60: Sens 用 ±20%
A61: C. 記憶體價格路徑（讀 skhynix 成品；唯讀；情境別）
A62: hbm_A_26 | B62: HBM 混合單價 2026（A） | C62: US$/GB | E62: 14.6 | G62: Derived | H62: skhynix/dist/20261030_SK海力士個股模型_v0.6.1.xlsx｜Mkt!C30:G30 | I62: markets/memory：2026 BofA $14.6/GB；2027 +80% 三情境相同；2028–29 依情境
A63: hbm_A_27 | B63: HBM 混合單價 2027（A） | C63: US$/GB | E63: 26.28 | G63: Derived | H63: skhynix/dist/20261030_SK海力士個股模型_v0.6.1.xlsx｜Mkt!C30:G30 | I63: 同上
A64: hbm_A_28 | B64: HBM 混合單價 2028（A） | C64: US$/GB | E64: 28.908 | G64: Derived | H64: skhynix/dist/20261030_SK海力士個股模型_v0.6.1.xlsx｜Mkt!C30:G30 | I64: 同上
A65: hbm_A_29 | B65: HBM 混合單價 2029（A） | C65: US$/GB | E65: 27.4626 | G65: Derived | H65: skhynix/dist/20261030_SK海力士個股模型_v0.6.1.xlsx｜Mkt!C30:G30 | I65: 同上
A66: hbm_B_26 | B66: HBM 混合單價 2026（B） | C66: US$/GB | E66: 14.6 | G66: Derived | H66: skhynix/dist/20261030_SK海力士個股模型_v0.6.1.xlsx｜Mkt!C31:G31 | I66: 同上
A67: hbm_B_27 | B67: HBM 混合單價 2027（B） | C67: US$/GB | E67: 26.28 | G67: Derived | H67: skhynix/dist/20261030_SK海力士個股模型_v0.6.1.xlsx｜Mkt!C31:G31 | I67: 同上
A68: hbm_B_28 | B68: HBM 混合單價 2028（B） | C68: US$/GB | E68: 19.71 | G68: Derived | H68: skhynix/dist/20261030_SK海力士個股模型_v0.6.1.xlsx｜Mkt!C31:G31 | I68: 同上
A69: hbm_B_29 | B69: HBM 混合單價 2029（B） | C69: US$/GB | E69: 19.71 | G69: Derived | H69: skhynix/dist/20261030_SK海力士個股模型_v0.6.1.xlsx｜Mkt!C31:G31 | I69: 同上
A70: hbm_C_26 | B70: HBM 混合單價 2026（C） | C70: US$/GB | E70: 14.6 | G70: Derived | H70: skhynix/dist/20261030_SK海力士個股模型_v0.6.1.xlsx｜Mkt!C32:G32 | I70: 同上
A71: hbm_C_27 | B71: HBM 混合單價 2027（C） | C71: US$/GB | E71: 26.28 | G71: Derived | H71: skhynix/dist/20261030_SK海力士個股模型_v0.6.1.xlsx｜Mkt!C32:G32 | I71: 同上
...

Sheet Q
A1: Q — 實績（十億美元；EPS 為美元；股數為十億股）。口徑：公司 non-GAAP（排除股票薪酬、無形資產攤銷、重組）。藍字＝輸入；黑字＝公式。實績取自 Broadcom 8-K 新聞稿（SEC EDGAR）
A2: FY2026 錨點＝Q1–Q3 實績＋Q4 指引（F 欄；假設見 In 頁 F 節）。AI 營收：Q1 8.4、Q2 10.8、Q3 16.7（公司）、Q4 21.7（公司指引）；AI 網通取 markets/network 的實際推估 rep_avgo26，XPU＝AI − 網通
A3: 項目 | B3: FY2025A | C3: FY26 Q1（～2026-02-01） | D3: FY26 Q2（～05-03） | E3: FY26 Q3（～08-02） | F3: FY26 Q4（指引） | G3: FY2026 錨點 | H3: 標記 | I3: 來源1（公司） | J3: 來源2／說明
A4: 營收 | B4: 63.887 | C4: 19.311 | D4: 22.187 | E4: 29.591 | F4: =q4_rev -> 34.8 | G4: =SUM(C4:F4) -> 105.889 | H4: Verified／Interested-party（Q4 指引） | I4: FY2025、Q4 FY25：https://www.sec.gov/Archives/edgar/data/1730168/000173016825000116/avgo-11022025x8kxex99.htm；Q1 FY26：https://www.sec.gov/Archives/edgar/data/1730168/000173016826000011/avgo-02012026x8kxex99.htm；Q2 FY26：https://www.sec.gov/Archives/edgar/data/1730168/000173016826000051/avgo-05032026x8kxex99.htm；Q3 FY26：https://investors.broadcom.com/news-releases/news-release-details/broadcom-inc-announces-third-quarter-fiscal-year-2026-financial | J4: 交叉：Q3 FY26 稿的九個月合計（營收 71.089、non-GAAP 毛利 54.168、營業利益 47.849、淨利 38.631）＝Q1＋Q2＋Q3（下方檢查列）
A5: 半導體解決方案 | B5: 36.858 | C5: 12.515 | D5: 15.009 | E5: 20.839 | F5: =F4-F6 -> 26.1 | G5: =SUM(C5:F5) -> 74.463 | H5: Verified／Derived（Q4） | I5: FY2025、Q4 FY25：https://www.sec.gov/Archives/edgar/data/1730168/000173016825000116/avgo-11022025x8kxex99.htm；Q1 FY26：https://www.sec.gov/Archives/edgar/data/1730168/000173016826000011/avgo-02012026x8kxex99.htm；Q2 FY26：https://www.sec.gov/Archives/edgar/data/1730168/000173016826000051/avgo-05032026x8kxex99.htm；Q3 FY26：https://investors.broadcom.com/news-releases/news-release-details/broadcom-inc-announces-third-quarter-fiscal-year-2026-financial | J5: 交叉：Q3 FY26 稿的九個月合計（營收 71.089、non-GAAP 毛利 54.168、營業利益 47.849、淨利 38.631）＝Q1＋Q2＋Q3（下方檢查列）
A6: 基礎架構軟體 | B6: 27.029 | C6: 6.796 | D6: 7.178 | E6: 8.752 | F6: =q4_sw -> 8.7 | G6: =SUM(C6:F6) -> 31.426 | H6: Verified／Interested-party（Q4） | I6: FY2025、Q4 FY25：https://www.sec.gov/Archives/edgar/data/1730168/000173016825000116/avgo-11022025x8kxex99.htm；Q1 FY26：https://www.sec.gov/Archives/edgar/data/1730168/000173016826000011/avgo-02012026x8kxex99.htm；Q2 FY26：https://www.sec.gov/Archives/edgar/data/1730168/000173016826000051/avgo-05032026x8kxex99.htm；Q3 FY26：https://investors.broadcom.com/news-releases/news-release-details/broadcom-inc-announces-third-quarter-fiscal-year-2026-financial | J6: 交叉：Q3 FY26 稿的九個月合計（營收 71.089、non-GAAP 毛利 54.168、營業利益 47.849、淨利 38.631）＝Q1＋Q2＋Q3（下方檢查列）
A7: AI 半導體營收 | B7: =co_ai26/(1+1.86) -> 20.27972 | C7: 8.4 | D7: 10.8 | E7: 16.7 | F7: =q4_ai -> 21.7 | G7: =SUM(C7:F7) -> 57.6 | H7: Verified／Interested-party（Q4）／Derived（FY2025） | I7: FY2025、Q4 FY25：https://www.sec.gov/Archives/edgar/data/1730168/000173016825000116/avgo-11022025x8kxex99.htm；Q1 FY26：https://www.sec.gov/Archives/edgar/data/1730168/000173016826000011/avgo-02012026x8kxex99.htm；Q2 FY26：https://www.sec.gov/Archives/edgar/data/1730168/000173016826000051/avgo-05032026x8kxex99.htm；Q3 FY26：https://investors.broadcom.com/news-releases/news-release-details/broadcom-inc-announces-third-quarter-fiscal-year-2026-financial | J7: FY2025＝公司 FY2026 展望 58 ÷（1＋186%）≈ 20.3（JPMorgan：約 20，二手）
A8: AI 網通（實際推估；markets/network rep_avgo26） | G8: =rep_avgo26 -> 17.6 | H8: Derived | I8: markets/network/dist/20261026_AI網通市場模型_v0.2.3.xlsx｜In!D121:F121 | J8: Q3 FY26：XPU 占 AI 73%（法說，二手，單一來源）
A9: XPU（＝AI − 網通） | G9: =G7-G8 -> 40 | H9: Derived | I9: — | J9: FY2026 XPU 占 AI 營收（下一列）
A10: XPU ÷ AI | G10: =G9/G7 -> 0.69444444 | H10: Derived | I10: — | J10: Q3 FY26 73%（法說，二手）
A11: 非 AI 半導體（＝半導體 − AI） | B11: =B5-B7 -> 16.57828 | C11: =C5-C7 -> 4.115 | D11: =D5-D7 -> 4.209 | E11: =E5-E7 -> 4.139 | F11: =F5-F7 -> 4.4 | G11: =SUM(C11:F11) -> 16.863 | H11: Derived | I11: FY2025、Q4 FY25：https://www.sec.gov/Archives/edgar/data/1730168/000173016825000116/avgo-11022025x8kxex99.htm；Q1 FY26：https://www.sec.gov/Archives/edgar/data/1730168/000173016826000011/avgo-02012026x8kxex99.htm；Q2 FY26：https://www.sec.gov/Archives/edgar/data/1730168/000173016826000051/avgo-05032026x8kxex99.htm；Q3 FY26：https://investors.broadcom.com/news-releases/news-release-details/broadcom-inc-announces-third-quarter-fiscal-year-2026-financial | J11: 交叉：Q3 FY26 稿的九個月合計（營收 71.089、non-GAAP 毛利 54.168、營業利益 47.849、淨利 38.631）＝Q1＋Q2＋Q3（下方檢查列）
A12: non-GAAP 毛利 | B12: 50.245 | C12: 14.868 | D12: 17.109 | E12: 22.191 | F12: =F4*q4_gm -> 25.404 | G12: =SUM(C12:F12) -> 79.572 | H12: Verified／Interested-party（Q4） | I12: FY2025、Q4 FY25：https://www.sec.gov/Archives/edgar/data/1730168/000173016825000116/avgo-11022025x8kxex99.htm；Q1 FY26：https://www.sec.gov/Archives/edgar/data/1730168/000173016826000011/avgo-02012026x8kxex99.htm；Q2 FY26：https://www.sec.gov/Archives/edgar/data/1730168/000173016826000051/avgo-05032026x8kxex99.htm；Q3 FY26：https://investors.broadcom.com/news-releases/news-release-details/broadcom-inc-announces-third-quarter-fiscal-year-2026-financial | J12: 交叉：Q3 FY26 稿的九個月合計（營收 71.089、non-GAAP 毛利 54.168、營業利益 47.849、淨利 38.631）＝Q1＋Q2＋Q3（下方檢查列）
A13: 毛利率 | B13: =B12/B4 -> 0.78646673 | C13: =C12/C4 -> 0.76992388 | D13: =D12/D4 -> 0.77112724 | E13: =E12/E4 -> 0.74992396 | F13: =F12/F4 -> 0.73 | G13: =G12/G4 -> 0.75146616 | H13: Derived | I13: — | J13: FY2025 78.6%；Q4 FY26 指引約 73%
A14: non-GAAP 營業費用 | B14: 8.248 | C14: 2.042 | D14: 2.181 | E14: 2.096 | F14: =F12-F15 -> 2.436 | G14: =SUM(C14:F14) -> 8.755 | H14: Verified／Derived（Q4＝毛利 − 營業利益） | I14: FY2025、Q4 FY25：https://www.sec.gov/Archives/edgar/data/1730168/000173016825000116/avgo-11022025x8kxex99.htm；Q1 FY26：https://www.sec.gov/Archives/edgar/data/1730168/000173016826000011/avgo-02012026x8kxex99.htm；Q2 FY26：https://www.sec.gov/Archives/edgar/data/1730168/000173016826000051/avgo-05032026x8kxex99.htm；Q3 FY26：https://investors.broadcom.com/news-releases/news-release-details/broadcom-inc-announces-third-quarter-fiscal-year-2026-financial | J14: 交叉：Q3 FY26 稿的九個月合計（營收 71.089、non-GAAP 毛利 54.168、營業利益 47.849、淨利 38.631）＝Q1＋Q2＋Q3（下方檢查列）
A15: non-GAAP 營業利益 | B15: 41.997 | C15: 12.826 | D15: 14.928 | E15: 20.095 | F15: =F4*q4_oim -> 22.968 | G15: =SUM(C15:F15) -> 70.817 | H15: Verified／Interested-party（Q4） | I15: FY2025、Q4 FY25：https://www.sec.gov/Archives/edgar/data/1730168/000173016825000116/avgo-11022025x8kxex99.htm；Q1 FY26：https://www.sec.gov/Archives/edgar/data/1730168/000173016826000011/avgo-02012026x8kxex99.htm；Q2 FY26：https://www.sec.gov/Archives/edgar/data/1730168/000173016826000051/avgo-05032026x8kxex99.htm；Q3 FY26：https://investors.broadcom.com/news-releases/news-release-details/broadcom-inc-announces-third-quarter-fiscal-year-2026-financial | J15: 交叉：Q3 FY26 稿的九個月合計（營收 71.089、non-GAAP 毛利 54.168、營業利益 47.849、淨利 38.631）＝Q1＋Q2＋Q3（下方檢查列）
A16: 營業利益率 | B16: =B15/B4 -> 0.65736378 | C16: =C15/C4 -> 0.66418104 | D16: =D15/D4 -> 0.67282643 | E16: =E15/E4 -> 0.67909162 | F16: =F15/F4 -> 0.66 | G16: =G15/G4 -> 0.66878524 | H16: Derived | I16: — | J16: —
A17: non-GAAP 利息費用 | B17: 3.072 | C17: 0.746 | D17: 0.745 | E17: 0.703 | F17: =q4_int -> 0.7 | G17: =SUM(C17:F17) -> 2.894 | H17: Verified／Derived（Q4） | I17: FY2025、Q4 FY25：https://www.sec.gov/Archives/edgar/data/1730168/000173016825000116/avgo-11022025x8kxex99.htm；Q1 FY26：https://www.sec.gov/Archives/edgar/data/1730168/000173016826000011/avgo-02012026x8kxex99.htm；Q2 FY26：https://www.sec.gov/Archives/edgar/data/1730168/000173016826000051/avgo-05032026x8kxex99.htm；Q3 FY26：https://investors.broadcom.com/news-releases/news-release-details/broadcom-inc-announces-third-quarter-fiscal-year-2026-financial | J17: 交叉：Q3 FY26 稿的九個月合計（營收 71.089、non-GAAP 毛利 54.168、營業利益 47.849、淨利 38.631）＝Q1＋Q2＋Q3（下方檢查列）
A18: non-GAAP 其他收益 | B18: 0.294 | C18: 0.118 | D18: 0.118 | E18: 0.098 | F18: =q4_oth -> 0.1 | G18: =SUM(C18:F18) -> 0.434 | H18: Verified／Derived（Q4） | I18: FY2025、Q4 FY25：https://www.sec.gov/Archives/edgar/data/1730168/000173016825000116/avgo-11022025x8kxex99.htm；Q1 FY26：https://www.sec.gov/Archives/edgar/data/1730168/000173016826000011/avgo-02012026x8kxex99.htm；Q2 FY26：https://www.sec.gov/Archives/edgar/data/1730168/000173016826000051/avgo-05032026x8kxex99.htm；Q3 FY26：https://investors.broadcom.com/news-releases/news-release-details/broadcom-inc-announces-third-quarter-fiscal-year-2026-financial | J18: 交叉：Q3 FY26 稿的九個月合計（營收 71.089、non-GAAP 毛利 54.168、營業利益 47.849、淨利 38.631）＝Q1＋Q2＋Q3（下方檢查列）
A19: 稅前利益 | B19: =B15-B17+B18 -> 39.219 | C19: =C15-C17+C18 -> 12.198 | D19: =D15-D17+D18 -> 14.301 | E19: =E15-E17+E18 -> 19.49 | F19: =F15-F17+F18 -> 22.368 | G19: =SUM(C19:F19) -> 68.357 | H19: Derived | I19: FY2025、Q4 FY25：https://www.sec.gov/Archives/edgar/data/1730168/000173016825000116/avgo-11022025x8kxex99.htm；Q1 FY26：https://www.sec.gov/Archives/edgar/data/1730168/000173016826000011/avgo-02012026x8kxex99.htm；Q2 FY26：https://www.sec.gov/Archives/edgar/data/1730168/000173016826000051/avgo-05032026x8kxex99.htm；Q3 FY26：https://investors.broadcom.com/news-releases/news-release-details/broadcom-inc-announces-third-quarter-fiscal-year-2026-financial | J19: 交叉：Q3 FY26 稿的九個月合計（營收 71.089、non-GAAP 毛利 54.168、營業利益 47.849、淨利 38.631）＝Q1＋Q2＋Q3（下方檢查列）
A20: non-GAAP 所得稅 | B20: 5.491 | C20: 2.013 | D20: 2.227 | E20: 3.118 | F20: =F19*q4_tx -> 3.57888 | G20: =SUM(C20:F20) -> 10.93688 | H20: Verified／Derived（Q4） | I20: FY2025、Q4 FY25：https://www.sec.gov/Archives/edgar/data/1730168/000173016825000116/avgo-11022025x8kxex99.htm；Q1 FY26：https://www.sec.gov/Archives/edgar/data/1730168/000173016826000011/avgo-02012026x8kxex99.htm；Q2 FY26：https://www.sec.gov/Archives/edgar/data/1730168/000173016826000051/avgo-05032026x8kxex99.htm；Q3 FY26：https://investors.broadcom.com/news-releases/news-release-details/broadcom-inc-announces-third-quarter-fiscal-year-2026-financial | J20: 交叉：Q3 FY26 稿的九個月合計（營收 71.089、non-GAAP 毛利 54.168、營業利益 47.849、淨利 38.631）＝Q1＋Q2＋Q3（下方檢查列）
A21: 有效稅率 | B21: =B20/B19 -> 0.14000867 | C21: =C20/C19 -> 0.16502705 | D21: =D20/D19 -> 0.15572338 | E21: =E20/E19 -> 0.15997948 | F21: =F20/F19 -> 0.16 | G21: =G20/G19 -> 0.15999649 | H21: Derived | I21: — | J21: —
A22: non-GAAP 淨利 | B22: =B19-B20 -> 33.728 | C22: =C19-C20 -> 10.185 | D22: =D19-D20 -> 12.074 | E22: =E19-E20 -> 16.372 | F22: =F19-F20 -> 18.78912 | G22: =SUM(C22:F22) -> 57.42012 | H22: Derived | I22: FY2025、Q4 FY25：https://www.sec.gov/Archives/edgar/data/1730168/000173016825000116/avgo-11022025x8kxex99.htm；Q1 FY26：https://www.sec.gov/Archives/edgar/data/1730168/000173016826000011/avgo-02012026x8kxex99.htm；Q2 FY26：https://www.sec.gov/Archives/edgar/data/1730168/000173016826000051/avgo-05032026x8kxex99.htm；Q3 FY26：https://investors.broadcom.com/news-releases/news-release-details/broadcom-inc-announces-third-quarter-fiscal-year-2026-financial | J22: 交叉：Q3 FY26 稿的九個月合計（營收 71.089、non-GAAP 毛利 54.168、營業利益 47.849、淨利 38.631）＝Q1＋Q2＋Q3（下方檢查列）
A23: 公司揭露 non-GAAP 淨利 | B23: 33.728 | C23: 10.185 | D23: 12.074 | E23: 16.372 | H23: Verified | I23: FY2025、Q4 FY25：https://www.sec.gov/Archives/edgar/data/1730168/000173016825000116/avgo-11022025x8kxex99.htm；Q1 FY26：https://www.sec.gov/Archives/edgar/data/1730168/000173016826000011/avgo-02012026x8kxex99.htm；Q2 FY26：https://www.sec.gov/Archives/edgar/data/1730168/000173016826000051/avgo-05032026x8kxex99.htm；Q3 FY26：https://investors.broadcom.com/news-releases/news-release-details/broadcom-inc-announces-third-quarter-fiscal-year-2026-financial | J23: 交叉：Q3 FY26 稿的九個月合計（營收 71.089、non-GAAP 毛利 54.168、營業利益 47.849、淨利 38.631）＝Q1＋Q2＋Q3（下方檢查列）
A24: non-GAAP 稀釋股數（十億股） | B24: 4.943 | C24: 4.957 | D24: 4.94 | E24: 4.937 | F24: =q4_sh -> 4.94 | G24: =AVERAGE(C24:F24) -> 4.9435 | H24: Verified／Derived（Q4） | I24: FY2025、Q4 FY25：https://www.sec.gov/Archives/edgar/data/1730168/000173016825000116/avgo-11022025x8kxex99.htm；Q1 FY26：https://www.sec.gov/Archives/edgar/data/1730168/000173016826000011/avgo-02012026x8kxex99.htm；Q2 FY26：https://www.sec.gov/Archives/edgar/data/1730168/000173016826000051/avgo-05032026x8kxex99.htm；Q3 FY26：https://investors.broadcom.com/news-releases/news-release-details/broadcom-inc-announces-third-quarter-fiscal-year-2026-financial | J24: 交叉：Q3 FY26 稿的九個月合計（營收 71.089、non-GAAP 毛利 54.168、營業利益 47.849、淨利 38.631）＝Q1＋Q2＋Q3（下方檢查列）
A25: non-GAAP EPS | B25: =B22/B24 -> 6.8233866 | C25: =C22/C24 -> 2.0546702 | D25: =D22/D24 -> 2.4441296 | E25: =E22/E24 -> 3.3161839 | F25: =F22/F24 -> 3.8034656 | G25: =G22/G24 -> 11.615277 | H25: Derived | I25: 淨利 ÷ 稀釋股數 | J25: —
A26: 公司揭露 non-GAAP EPS | B26: 6.82 | C26: 2.05 | D26: 2.44 | E26: 3.32 | H26: Verified | I26: FY2025、Q4 FY25：https://www.sec.gov/Archives/edgar/data/1730168/000173016825000116/avgo-11022025x8kxex99.htm；Q1 FY26：https://www.sec.gov/Archives/edgar/data/1730168/000173016826000011/avgo-02012026x8kxex99.htm；Q2 FY26：https://www.sec.gov/Archives/edgar/data/1730168/000173016826000051/avgo-05032026x8kxex99.htm；Q3 FY26：https://investors.broadcom.com/news-releases/news-release-details/broadcom-inc-announces-third-quarter-fiscal-year-2026-financial | J26: 交叉：Q3 FY26 稿的九個月合計（營收 71.089、non-GAAP 毛利 54.168、營業利益 47.849、淨利 38.631）＝Q1＋Q2＋Q3（下方檢查列）
A27: 檢查：淨利 − 公司揭露（應約為 0；四捨五入） | B27: =B22-B23 -> 0 | C27: =C22-C23 -> 0 | D27: =D22-D23 -> 0 | E27: =E22-E23 -> 0 | H27: — | I27: — | J27: —
A28: 檢查：Q1＋Q2＋Q3 − 九個月合計（營收、毛利、營業利益、淨利；應為 0） | G28: =(C4+D4+E4-71.089)+(C12+D12+E12-54.168)+(C15+D15+E15-47.849)+(C22+D22+E22-38.631) -> 0 | H28: — | I28: https://investors.broadcom.com/news-releases/news-release-details/broadcom-inc-announces-third-quarter-fiscal-year-2026-financial（九個月欄） | J28: —
A30: FY2026 錨點與共識、公司展望的距離（參考；校準未使用共識）
A31: FY2026 營收 ÷ 共識 − 1 | B31: =G4/cons_rev26-1 -> -0.00085865258
A32: FY2026 EPS ÷ 共識 − 1 | B32: =G25/cons_eps26-1 -> -0.0038356239
A33: FY2026 AI 營收 ÷ 公司展望 58 − 1 | B33: =G7/co_ai26-1 -> -0.0068965517
A34: FY2026 營收年增 | B34: =G4/B4-1 -> 0.65744205
A35: FY2026 營業費用年增 | B35: =G14/B14-1 -> 0.061469447
A36: 營業費用彈性（營業費用年增 ÷ 營收年增；In 頁 phi 的依據） | B36: =B35/B34 -> 0.093497895

Sheet Units
A1: Units — ASIC 每顆規格（本專案權威，規則第 13 條）與加速器金額份額。顆數：百萬顆（日曆年；與 HBM、台積電、網通、NVIDIA 模型同一份）；每顆價：US$K
A3: 項目 | B3: 單位 | C3: CY2026（FY2026） | D3: CY2027（FY2027） | E3: CY2028（FY2028） | F3: CY2029（FY2029） | G3: 說明
A4: 1. ASIC 每顆規格（情境 A；Broadcom 營收口徑＝核心售價＋代購 HBM，乘 k_x）
A5: Broadcom 份額：Google TPU | B5: % | C5: =PL!D75 -> 0.9 | D5: =PL!E75 -> 0.8 | E5: =PL!F75 -> 0.75 | F5: =PL!G75 -> 0.75 | G5: In 頁 B 節（Assumed）
A6: Broadcom 顆數：Google TPU | B6: 百萬顆 | C6: =PL!D77 -> 3.465 | D6: =PL!E77 -> 4.4 | E6: =PL!F77 -> 5.25 | F6: =PL!G77 -> 6.0375 | G6: 市場層顆數 × 份額
A7: 每顆 HBM：Google TPU | B7: GB | C7: =PL!D79 -> 192 | D7: =PL!E79 -> 250 | E7: =PL!F79 -> 288 | F7: =PL!G79 -> 288 | G7: markets/memory UNITS
A8: 每顆 HBM 金額：Google TPU | B8: US$K | C8: =PL!D84 -> 2.8032 | D8: =PL!E84 -> 6.57 | E8: =PL!F84 -> 8.325504 | F8: =PL!G84 -> 7.9092288 | G8: 容量 × HBM 單價（情境 A）
A9: 每顆 Broadcom 營收（校準後）：Google TPU | B9: US$K | C9: =PL!D86*PL!$D$89 -> 10.725586 | D9: =PL!E86*PL!$D$89 -> 13.229292 | E9: =PL!F86*PL!$D$89 -> 14.396135 | F9: =PL!G86*PL!$D$89 -> 14.119447 | G9: （核心＋代購比例 × HBM）× k_x
A10: 每顆總價（核心 × k_x ＋ 全部 HBM；金額份額用）：Google TPU | B10: US$K | C10: =PL!D82*PL!$D$89+PL!D84 -> 11.665563 | D10: =PL!E82*PL!$D$89+PL!E84 -> 15.432363 | E10: =PL!F82*PL!$D$89+PL!F84 -> 17.187867 | F10: =PL!G82*PL!$D$89+PL!G84 -> 16.771591 | G10: 與 NVIDIA 模組價同口徑（含全部 HBM，不論誰採購）
A11: Broadcom 份額：其他 ASIC（MTIA、Maia、Ascend 等） | B11: % | C11: =PL!D76 -> 0.35 | D11: =PL!E76 -> 0.55 | E11: =PL!F76 -> 0.55 | F11: =PL!G76 -> 0.55 | G11: In 頁 B 節（Assumed）
A12: Broadcom 顆數：其他 ASIC（MTIA、Maia、Ascend 等） | B12: 百萬顆 | C12: =PL!D78 -> 0.35 | D12: =PL!E78 -> 2.475 | E12: =PL!F78 -> 2.75 | F12: =PL!G78 -> 3.1625 | G12: 市場層顆數 × 份額
A13: 每顆 HBM：其他 ASIC（MTIA、Maia、Ascend 等） | B13: GB | C13: =PL!D80 -> 150 | D13: =PL!E80 -> 200 | E13: =PL!F80 -> 250 | F13: =PL!G80 -> 250 | G13: markets/memory UNITS
A14: 每顆 HBM 金額：其他 ASIC（MTIA、Maia、Ascend 等） | B14: US$K | C14: =PL!D85 -> 2.19 | D14: =PL!E85 -> 5.256 | E14: =PL!F85 -> 7.227 | F14: =PL!G85 -> 6.86565 | G14: 容量 × HBM 單價（情境 A）
A15: 每顆 Broadcom 營收（校準後）：其他 ASIC（MTIA、Maia、Ascend 等） | B15: US$K | C15: =PL!D87*PL!$D$89 -> 8.1024151 | D15: =PL!E87*PL!$D$89 -> 10.140315 | E15: =PL!F87*PL!$D$89 -> 11.450394 | F15: =PL!G87*PL!$D$89 -> 11.210213 | G15: （核心＋代購比例 × HBM）× k_x
A16: 每顆總價（核心 × k_x ＋ 全部 HBM；金額份額用）：其他 ASIC（MTIA、Maia、Ascend 等） | B16: US$K | C16: =PL!D83*PL!$D$89+PL!D85 -> 8.836772 | D16: =PL!E83*PL!$D$89+PL!E85 -> 11.902772 | E16: =PL!F83*PL!$D$89+PL!F85 -> 13.873772 | F16: =PL!G83*PL!$D$89+PL!G85 -> 13.512422 | G16: 與 NVIDIA 模組價同口徑（含全部 HBM，不論誰採購）
A18: 2. 校準值（只用 FY2026 已發生的實績與當季指引；不用共識、不用公司對 FY2027–28 的展望）
A19: XPU 校準係數 k_x | C19: =PL!D89 -> 1.1077953 | G19: FY2026 錨點 XPU ÷ 未校準由下而上；顆數、份額、核心單價的合併係數
A20: 網通校準係數 k_n | C20: =PL!D96 -> 1.3959864 | G20: rep_avgo26 ÷ markets/network 歸屬
A21: XPU 核心毛利率 m_core | C21: =PL!D110 -> 0.78755088 | G21: 讓 FY2026 毛利率等於錨點的殘差（Derived）
A22: FY2026 錨點 XPU | C22: =a26_xpu -> 40 | G22: AI 57.6 − 網通 17.6
A23: FY2026 未校準 XPU | C23: =PL!D88 -> 36.107753
A25: 3. 加速器金額份額（accel_share；各平台每顆總價 × 顆數；ASIC 用本頁第 1 節的 CY2027 每顆總價，其他平台讀 NVIDIA 模型）
A26: 情境 A：基準
A27: 顆數
A28: NVIDIA Blackwell（B200／B300） | B28: 百萬顆 | C28: =u_bw_26 -> 5.4 | D28: =u_bw_27 -> 2.4 | E28: =u_bw_28*um28_A -> 0.5 | F28: =u_bw_28*(1+g29_bw)*um29_A -> 0.25
A29: NVIDIA Rubin | B29: 百萬顆 | C29: =u_rb_26 -> 1.7 | D29: =u_rb_27 -> 7 | E29: =u_rb_28*um28_A -> 7 | F29: =u_rb_28*(1+g29_rb)*um29_A -> 8.05
A30: NVIDIA Rubin Ultra | B30: 百萬顆 | C30: =u_ru_26 -> 0 | D30: =u_ru_27 -> 0.3 | E30: =u_ru_28*um28_A -> 2 | F30: =u_ru_28*(1+g29_ru)*um29_A -> 2.3
A31: NVIDIA Hopper（H200 等） | B31: 百萬顆 | C31: =u_hp_26 -> 0.5 | D31: =u_hp_27 -> 0 | E31: =u_hp_28*um28_A -> 0 | F31: =u_hp_28*(1+g29_hp)*um29_A -> 0
A32: AMD Instinct | B32: 百萬顆 | C32: =u_amd_26 -> 0.75 | D32: =u_amd_27 -> 1.5 | E32: =u_amd_28*um28_A -> 2 | F32: =u_amd_28*(1+g29_amd)*um29_A -> 2.3
A33: Google TPU | B33: 百萬顆 | C33: =u_tpu_26 -> 3.85 | D33: =u_tpu_27 -> 5.5 | E33: =u_tpu_28*um28_A -> 7 | F33: =u_tpu_28*(1+g29_tpu)*um29_A -> 8.05
A34: AWS Trainium | B34: 百萬顆 | C34: =u_trn_26 -> 2 | D34: =u_trn_27 -> 2.5 | E34: =u_trn_28*um28_A -> 3 | F34: =u_trn_28*(1+g29_trn)*um29_A -> 3.45
A35: 其他 ASIC（MTIA、Maia、Ascend 等） | B35: 百萬顆 | C35: =u_oth_26 -> 1 | D35: =u_oth_27 -> 4.5 | E35: =u_oth_28*um28_A -> 5 | F35: =u_oth_28*(1+g29_oth)*um29_A -> 5.75
A36: 合計 | B36: 百萬顆 | C36: =SUM(C28:C35) -> 15.2 | D36: =SUM(D28:D35) -> 23.7 | E36: =SUM(E28:E35) -> 26.5 | F36: =SUM(F28:F35) -> 30.15
A37: 金額（顆數 × 每顆售價）
A38: NVIDIA Blackwell（B200／B300） | B38: US$B | C38: =u_bw_26*(pm_bw) -> 218.16 | D38: =u_bw_27*(pm_bw) -> 96.96 | E38: =u_bw_28*um28_A*(pm_bw) -> 20.2 | F38: =u_bw_28*(1+g29_bw)*um29_A*(pm_bw) -> 10.1
A39: NVIDIA Rubin | B39: US$B | C39: =u_rb_26*(pm_rb) -> 93.5 | D39: =u_rb_27*(pm_rb) -> 385 | E39: =u_rb_28*um28_A*(pm_rb) -> 385 | F39: =u_rb_28*(1+g29_rb)*um29_A*(pm_rb) -> 442.75
A40: NVIDIA Rubin Ultra | B40: US$B | C40: =u_ru_26*(pm_ru) -> 0 | D40: =u_ru_27*(pm_ru) -> 22.5 | E40: =u_ru_28*um28_A*(pm_ru) -> 150 | F40: =u_ru_28*(1+g29_ru)*um29_A*(pm_ru) -> 172.5
A41: NVIDIA Hopper（H200 等） | B41: US$B | C41: =u_hp_26*(pm_hp) -> 15 | D41: =u_hp_27*(pm_hp) -> 0 | E41: =u_hp_28*um28_A*(pm_hp) -> 0 | F41: =u_hp_28*(1+g29_hp)*um29_A*(pm_hp) -> 0
A42: AMD Instinct | B42: US$B | C42: =u_amd_26*(pa_amd) -> 22.5 | D42: =u_amd_27*(pa_amd) -> 45 | E42: =u_amd_28*um28_A*(pa_amd) -> 60 | F42: =u_amd_28*(1+g29_amd)*um29_A*(pa_amd) -> 69
A43: Google TPU | B43: US$B | C43: =u_tpu_26*(Units!$D$10) -> 59.414596 | D43: =u_tpu_27*(Units!$D$10) -> 84.877995 | E43: =u_tpu_28*um28_A*(Units!$D$10) -> 108.02654 | F43: =u_tpu_28*(1+g29_tpu)*um29_A*(Units!$D$10) -> 124.23052
...

Sheet PL
A1: PL — Broadcom 損益（US$B；non-GAAP）。FY2025A 實績、FY2026 錨點（Q1–Q3 實績＋Q4 指引），FY2027 起為由下而上。FY(t)＝CY(t)。三情境各一個完整推導區塊（本頁下方），頂端為摘要。FY2026–FY2027 三情境相同（顆數係數從 CY2028 開始；HBM 價格 2027 三情境相同）
A3: 情境／項目 | B3: 單位 | C3: FY2025A | D3: FY2026（錨點） | E3: FY2027 | F3: FY2028 | G3: FY2029 | H3: 說明
A4: 情境 A
A5: 營收 | B5: US$B | C5: =C103 -> 63.887 | D5: =D103 -> 105.889 | E5: =E103 -> 173.50734 | F5: =F103 -> 207.77522 | G5: =G103 -> 232.99313
A6: 營收年增 | B6: % | D6: =D107 -> 0.65744205 | E6: =E107 -> 0.63857755 | F6: =F107 -> 0.19750102 | G6: =G107 -> 0.12137115
A7: AI 半導體 | B7: US$B | C7: =C98 -> 20.27972 | D7: =D98 -> 57.6 | E7: =E98 -> 120.94133 | F7: =F98 -> 151.87237 | G7: =G98 -> 173.51256
A8: XPU | B8: US$B | D8: =D90 -> 40 | E8: =E90 -> 83.306165 | F8: =F90 -> 107.06829 | G8: =G90 -> 120.69846
A9: AI 網通 | B9: US$B | D9: =D97 -> 17.6 | E9: =E97 -> 37.635164 | F9: =F97 -> 44.804075 | G9: =G97 -> 52.814098
A10: 基礎架構軟體 | B10: US$B | C10: =C101 -> 27.029 | D10: =D101 -> 31.426 | E10: =E101 -> 35.19712 | F10: =F101 -> 38.01289 | G10: =G101 -> 41.053921
A11: 毛利率 | B11: % | C11: =C112 -> 0.78646673 | D11: =D112 -> 0.75146616 | E11: =E112 -> 0.67762206 | F11: =F112 -> 0.64735182 | G11: =G112 -> 0.65021026
A12: 營業利益率 | B12: % | C12: =C117 -> 0.65736378 | D12: =D117 -> 0.66878524 | E12: =E117 -> 0.62394091 | F12: =F117 -> 0.60117934 | G12: =G117 -> 0.60779999
A13: 淨利（non-GAAP） | B13: US$B | C13: =C121 -> 33.728 | D13: =D121 -> 57.42012 | E13: =E121 -> 88.920994 | F13: =F121 -> 102.90854 | G13: =G121 -> 116.93911
A14: EPS（non-GAAP） | B14: US$ | C14: =C123 -> 6.8233866 | D14: =D123 -> 11.615277 | E14: =E123 -> 18.077846 | F14: =F123 -> 21.026681 | G14: =G123 -> 24.01353
A15: EPS 年增 | B15: % | D15: =D124 -> 0.70227444 | E15: =E124 -> 0.55638534 | F15: =F124 -> 0.16311867 | G15: =G124 -> 0.14205043
A17: 情境 B
A18: 營收 | B18: US$B | C18: =C160 -> 63.887 | D18: =D160 -> 105.889 | E18: =E160 -> 173.50734 | F18: =F160 -> 166.64307 | G18: =G160 -> 195.88729
A19: 營收年增 | B19: % | D19: =D164 -> 0.65744205 | E19: =E164 -> 0.63857755 | F19: =F164 -> -0.039561814 | G19: =G164 -> 0.17549015
A20: AI 半導體 | B20: US$B | C20: =C155 -> 20.27972 | D20: =D155 -> 57.6 | E20: =E155 -> 120.94133 | F20: =F155 -> 110.74023 | G20: =G155 -> 136.40672
A21: XPU | B21: US$B | D21: =D147 -> 40 | E21: =E147 -> 83.306165 | F21: =F147 -> 74.896967 | G21: =G147 -> 91.514732
A22: AI 網通 | B22: US$B | D22: =D154 -> 17.6 | E22: =E154 -> 37.635164 | F22: =F154 -> 35.84326 | G22: =G154 -> 44.891983
A23: 基礎架構軟體 | B23: US$B | C23: =C158 -> 27.029 | D23: =D158 -> 31.426 | E23: =E158 -> 35.19712 | F23: =F158 -> 38.01289 | G23: =G158 -> 41.053921
A24: 毛利率 | B24: % | C24: =C169 -> 0.78646673 | D24: =D169 -> 0.75146616 | E24: =E169 -> 0.67762206 | F24: =F169 -> 0.69563801 | G24: =G169 -> 0.69012171
A25: 營業利益率 | B25: % | C25: =C174 -> 0.65736378 | D25: =D174 -> 0.66878524 | E25: =E174 -> 0.62394091 | F25: =F174 -> 0.63806888 | G25: =G174 -> 0.6396779
A26: 淨利（non-GAAP） | B26: US$B | C26: =C178 -> 33.728 | D26: =D178 -> 57.42012 | E26: =E178 -> 88.920994 | F26: =F178 -> 87.300998 | G26: =G178 -> 103.24001
A27: EPS（non-GAAP） | B27: US$ | C27: =C180 -> 6.8233866 | D27: =D180 -> 11.615277 | E27: =E180 -> 18.077846 | F27: =F180 -> 17.837686 | G27: =G180 -> 21.200409
A28: EPS 年增 | B28: % | D28: =D181 -> 0.70227444 | E28: =E181 -> 0.55638534 | F28: =F181 -> -0.013284804 | G28: =G181 -> 0.18851793
A30: 情境 C
A31: 營收 | B31: US$B | C31: =C217 -> 63.887 | D31: =D217 -> 105.889 | E31: =E217 -> 173.50734 | F31: =F217 -> 135.50019 | G31: =G217 -> 152.58647
A32: 營收年增 | B32: % | D32: =D221 -> 0.65744205 | E32: =E221 -> 0.63857755 | F32: =F221 -> -0.21905208 | G32: =G221 -> 0.12609781
A33: AI 半導體 | B33: US$B | C33: =C212 -> 20.27972 | D33: =D212 -> 57.6 | E33: =E212 -> 120.94133 | F33: =F212 -> 79.597349 | G33: =G212 -> 93.105897
A34: XPU | B34: US$B | D34: =D204 -> 40 | E34: =E204 -> 83.306165 | F34: =F204 -> 52.714904 | G34: =G204 -> 61.417438
A35: AI 網通 | B35: US$B | D35: =D211 -> 17.6 | E35: =E211 -> 37.635164 | F35: =F211 -> 26.882445 | G35: =G211 -> 31.688459
A36: 基礎架構軟體 | B36: US$B | C36: =C215 -> 27.029 | D36: =D215 -> 31.426 | E36: =E215 -> 35.19712 | F36: =F215 -> 38.01289 | G36: =G215 -> 41.053921
A37: 毛利率 | B37: % | C37: =C226 -> 0.78646673 | D37: =D226 -> 0.75146616 | E37: =E226 -> 0.67762206 | F37: =F226 -> 0.72576851 | G37: =G226 -> 0.71998218
A38: 營業利益率 | B38: % | C38: =C231 -> 0.65736378 | D38: =D231 -> 0.66878524 | E38: =E231 -> 0.62394091 | F38: =F231 -> 0.6549679 | G38: =G231 -> 0.65522347
A39: 淨利（non-GAAP） | B39: US$B | C39: =C235 -> 33.728 | D39: =D235 -> 57.42012 | E39: =E235 -> 88.920994 | F39: =F235 -> 72.532553 | G39: =G235 -> 81.965721
A40: EPS（non-GAAP） | B40: US$ | C40: =C237 -> 6.8233866 | D40: =D237 -> 11.615277 | E40: =E237 -> 18.077846 | F40: =F237 -> 14.820139 | G40: =G237 -> 16.831719
A41: EPS 年增 | B41: % | D41: =D238 -> 0.70227444 | E41: =E238 -> 0.55638534 | F41: =F238 -> -0.18020441 | G41: =G238 -> 0.13573293
A43: 核對（應為 0）：FY2026 由下而上營收 − 錨點；FY2026 由下而上 XPU − 錨點 XPU（k_x、k_n 校準恆等式）
A44: 情境 A：營收差（US$B） | D44: =D104-a26_rev -> 0
...

Sheet Val
A1: Val — P/E 估值（美元；non-GAAP EPS）。結論用「現價 ÷ FY2027、FY2028 EPS（模型與共識）」。十年 P/E 規則值本版不適用：GAAP 落後 P/E 受無形資產攤銷扭曲（2016 年為負、2018 年 6.5x、2024 年 137x），前瞻 P/E 歷史待 Bloomberg（10-27 抓取單）
A2: 循環位置：共用規則（tools/cycle_position.py classify；AVGO 的 FY(t) 對照日曆年 t，不平移），見頂年度讀設備市場模型；本版只記錄判定，倍數待前瞻 P/E 歷史
A3: 0. 目標價（DCF 與 Comparable 加權；v0.2 新增，Andy 2026-10-25）
A4: 0.1 DCF（股東權益現金流，FY2027–FY2032 明確期＋FY2032 後永續）
A5: 項目 | B5: A | C5: B | D5: C | E5: 說明 | F5: 折現年數 t | G5: 期內占比（基準日後）
A6: 情境 EPS（FY2027–FY2032） | E6: 引用 PL 頁延伸表（上游結束後為收斂法）；三情境欄 B／C／D＝A／B／C
A7: FY2027 | B7: =PL!E250 -> 18.077846 | C7: =PL!E259 -> 18.077846 | D7: =PL!E268 -> 18.077846 | F7: 0.833333 | G7: 0.833333
A8: FY2028 | B8: =PL!F250 -> 21.026681 | C8: =PL!F259 -> 17.837686 | D8: =PL!F268 -> 14.820139 | F8: 1.833333 | G8: 1
A9: FY2029 | B9: =PL!G250 -> 24.01353 | C9: =PL!G259 -> 21.200409 | D9: =PL!G268 -> 16.831719 | F9: 2.833333 | G9: 1
A10: FY2030 | B10: =PL!H250 -> 26.569682 | C10: =PL!H259 -> 23.281016 | D10: =PL!H268 -> 17.221072 | F10: 3.833333 | G10: 1
A11: FY2031 | B11: =PL!I250 -> 28.851658 | C11: =PL!I259 -> 24.515119 | D11: =PL!I268 -> 16.961158 | F11: 4.833333 | G11: 1
A12: FY2032 | B12: =PL!J250 -> 30.73644 | C12: =PL!J259 -> 24.708706 | D12: =PL!J268 -> 16.049832 | F12: 5.833333 | G12: 1
A13: 股東現金流＝EPS ×（1 − tp_g ÷ tp_roe） | B13: =1-MIN(0.8,tp_g/tp_roe) -> 0.87480438 | E13: B 欄＝可發放比例（1 − 再投資率；再投資率＝tp_g ÷ tp_roe，上限 0.8）；下列六列＝EPS × 可發放比例 × 期內占比；FY2027 期內占比 10/12（FY2027 約 2026-11～2027-10，基準日 2026 年底後 10 個月）
A14: FY2027 股東現金流 | B14: =B7*$B$13*$G$7 -> 13.178811 | C14: =C7*$B$13*$G$7 -> 13.178811 | D14: =D7*$B$13*$G$7 -> 13.178811
A15: FY2028 股東現金流 | B15: =B8*$B$13*$G$8 -> 18.394232 | C15: =C8*$B$13*$G$8 -> 15.604486 | D15: =D8*$B$13*$G$8 -> 12.964722
A16: FY2029 股東現金流 | B16: =B9*$B$13*$G$9 -> 21.007141 | C16: =C9*$B$13*$G$9 -> 18.546211 | D16: =D9*$B$13*$G$9 -> 14.724462
A17: FY2030 股東現金流 | B17: =B10*$B$13*$G$10 -> 23.243274 | C17: =C10*$B$13*$G$10 -> 20.366334 | D17: =D10*$B$13*$G$10 -> 15.065069
A18: FY2031 股東現金流 | B18: =B11*$B$13*$G$11 -> 25.239557 | C18: =C11*$B$13*$G$11 -> 21.445933 | D18: =D11*$B$13*$G$11 -> 14.837695
A19: FY2032 股東現金流 | B19: =B12*$B$13*$G$12 -> 26.888372 | C19: =C12*$B$13*$G$12 -> 21.615284 | D19: =D12*$B$13*$G$12 -> 14.040463
A20: 永續價值（FY2032 年底；FY2032 現金流 ×(1＋tp_g) ÷ (tp_r − tp_g)） | B20: =B19*(1+tp_g)/(tp_r-tp_g) -> 466.06512 | C20: =C19*(1+tp_g)/(tp_r-tp_g) -> 374.66492 | D20: =D19*(1+tp_g)/(tp_r-tp_g) -> 243.36802
A21: DCF 情境每股價值（折現率 tp_r） | B21: =MAX(0,B14/(1+tp_r)^$F$7+B15/(1+tp_r)^$F$8+B16/(1+tp_r)^$F$9+B17/(1+tp_r)^$F$10+B18/(1+tp_r)^$F$11+B19/(1+tp_r)^$F$12+B20/(1+tp_r)^$F$12) -> 358.42075 | C21: =MAX(0,C14/(1+tp_r)^$F$7+C15/(1+tp_r)^$F$8+C16/(1+tp_r)^$F$9+C17/(1+tp_r)^$F$10+C18/(1+tp_r)^$F$11+C19/(1+tp_r)^$F$12+C20/(1+tp_r)^$F$12) -> 294.3667 | D21: =MAX(0,D14/(1+tp_r)^$F$7+D15/(1+tp_r)^$F$8+D16/(1+tp_r)^$F$9+D17/(1+tp_r)^$F$10+D18/(1+tp_r)^$F$11+D19/(1+tp_r)^$F$12+D20/(1+tp_r)^$F$12) -> 201.7405 | E21: 基準日 2026 年底；明確期現金流與永續價值依 F 欄年數折現；小於 0 時取 0（Andy 2026-10-25 12:22）
A22: 其中：永續價值現值占比 | B22: =B20/(1+tp_r)^$F$12/B21 -> 0.74575494 | C22: =C20/(1+tp_r)^$F$12/C21 -> 0.72995659 | D22: =D20/(1+tp_r)^$F$12/D21 -> 0.69185186
A23: DCF 目標價（情境加權） | B23: =(tp_wA*B21+tp_wB*C21+tp_wC*D21)*(1+tp_r) -> 324.56344 | E23: Σ 權重 × 情境價值 ×(1＋tp_r)：推到約 12 個月後
A25: 0.2 Comparable（市場主流同業前瞻 P/E）
A26: 同業與前瞻 P/E | B26: 代號 | C26: 前瞻 12 月 P/E | D26: 日期 | E26: 來源 | F26: 標記
A27: NVIDIA | B27: NVDA | C27: 17.44 | D27: 2026-10-23 | E27: stockanalysis.com 統計頁（Forward PE） | F27: Interested-party（資料商彙整賣方預估）
A28: AMD | B28: AMD | C28: 46.49 | D28: 2026-10-23 | E28: 同上 | F28: Interested-party（同上）
A29: Marvell | B29: MRVL | C29: 40.44 | D29: 2026-10-23 | E29: 同上 | F29: Interested-party（同上）
A30: Qualcomm | B30: QCOM | C30: 18.98 | D30: 2026-10-23 | E30: 同上 | F30: Interested-party（同上）
A31: 台積電 ADR | B31: TSM | C31: 19.61 | D31: 2026-10-23 | E31: 同上 | F31: Interested-party（同上）
A32: 同業選擇 | E32: 券商常用的 AI 半導體大型股同業（GPU、客製 ASIC、手機 SoC、代工）；不含 A 股（Andy 11:53）。前瞻 P/E 口徑為資料商的未來 12 個月共識 EPS，各家 GAAP／non-GAAP 口徑不一
A33: 同業前瞻 P/E 中位數 | B33: =MEDIAN(C27:C31) -> 19.61
A34: 各情境 12 個月後的前瞻 EPS | B34: =1*PL!F250 -> 21.026681 | C34: =1*PL!F259 -> 17.837686 | D34: =1*PL!F268 -> 14.820139 | E34: 會計年度 FY(t) 約為 t−1 年 11 月～t 年 10 月：約 12 個月後（2027-10 底）的未來 12 個月＝2027-11～2028-10＝FY2028 全年（1 × FY2028）
A35: 12 個月後的前瞻 EPS（情境加權） | B35: =tp_wA*B34+tp_wB*C34+tp_wC*D34 -> 18.190875
A36: Comparable 目標價 | B36: =B33*B35 -> 356.72305 | E36: 同業前瞻 P/E 中位數 × 12 個月後的前瞻 EPS（情境加權）
A38: 0.3 結論
A39: 項目 | B39: 數值 | C39: 對照 | D39: 對照 | E39: 說明
A40: 目標價（DCF 與 Comparable 加權） | B40: =tp_w_dcf*B23+(1-tp_w_dcf)*tp_comp_adj -> 273.10702 | E40: ="DCF 權重 "&TEXT(tp_w_dcf,"0%")&"、Comparable 權重 "&TEXT(1-tp_w_dcf,"0%")&"（In 頁 tp_w_dcf，Andy 可改）" -> DCF 權重 50%、Comparable 權重 50%（In 頁 tp_w_dcf，Andy 可改）
A41: Comparable 目標價（市場主流同業法） | B41: =B36 -> 356.72305
A42: 市場共識目標價 | B42: =cons_tp -> 529.1 | E42: stockanalysis.com：51 位分析師平均目標價（2026-10-25 頁面）；Interested-party
...

Sheet Recon
A1: Recon — 本模型 vs 公司展望、共識、市場層。只作事後對照，不為對上數字而調參數。公司 FY2027、FY2028 AI 營收展望（115、230）為 Interested-party，不用於校準
A3: 項目 | B3: 對照值 | C3: 模型 A | D3: 差距 A | E3: 模型 B | F3: 差距 B | G3: 模型 C | H3: 差距 C | I3: 對照來源 | J3: 說明
A4: A. AI 營收 vs 公司展望（Interested-party；校準未使用）
A5: FY2026 AI 營收 vs 公司展望 58 | B5: =co_ai26 -> 58 | C5: =PL!D98 -> 57.6 | D5: =C5/B5-1 -> -0.0068965517 | E5: =PL!D155 -> 57.6 | F5: =E5/B5-1 -> -0.0068965517 | G5: =PL!D212 -> 57.6 | H5: =G5/B5-1 -> -0.0068965517 | I5: 公司（法說） | J5: FY2026 為錨點（Q1–Q3 實績＋Q4 指引 57.6）
A6: FY2027 AI 營收 vs 公司展望 115 | B6: =co_ai27 -> 115 | C6: =PL!E98 -> 120.94133 | D6: =C6/B6-1 -> 0.051663727 | E6: =PL!E155 -> 120.94133 | F6: =E6/B6-1 -> 0.051663727 | G6: =PL!E212 -> 120.94133 | H6: =G6/B6-1 -> 0.051663727 | I6: 公司（法說）
A7: FY2027 AI 營收 vs JPMorgan 150 | B7: =jpm_ai27 -> 150 | C7: =PL!E98 -> 120.94133 | D7: =C7/B7-1 -> -0.19372448 | E7: =PL!E155 -> 120.94133 | F7: =E7/B7-1 -> -0.19372448 | G7: =PL!E212 -> 120.94133 | H7: =G7/B7-1 -> -0.19372448 | I7: JPMorgan（KuCoin 轉述）
A8: FY2028 AI 營收 vs 公司展望 230 | B8: =co_ai28 -> 230 | C8: =PL!F98 -> 151.87237 | D8: =C8/B8-1 -> -0.33968535 | E8: =PL!F155 -> 110.74023 | F8: =E8/B8-1 -> -0.51852075 | G8: =PL!F212 -> 79.597349 | H8: =G8/B8-1 -> -0.65392457 | I8: 公司（法說） | J8: 差距主要在顆數：公司說法含 Anthropic 2028 年再加約 10 GW、OpenAI 5 GW 以上
A9: B. What must be true：要達到公司展望，Broadcom XPU 顆數需要是模型的幾倍（網通、核心售價、HBM 不變）
A10: FY2027：所需 XPU 顆數倍數 | C10: =(co_ai27-PL!E97)/PL!E90 -> 0.9286808 | E10: =(co_ai27-PL!E154)/PL!E147 -> 0.9286808 | G10: =(co_ai27-PL!E211)/PL!E204 -> 0.9286808 | I10: — | J10: 倍數 >1＝公司展望需要比市場層更多的 Broadcom 顆數
A11: FY2028：所需 XPU 顆數倍數 | C11: =(co_ai28-PL!F97)/PL!F90 -> 1.729699 | E11: =(co_ai28-PL!F154)/PL!F147 -> 2.5923178 | G11: =(co_ai28-PL!F211)/PL!F204 -> 3.8531334 | I11: —
A12: FY2028：所需 Broadcom XPU 顆數（百萬顆）vs 模型 | B12: =PL!F93 -> 8 | C12: =(co_ai28-PL!F97)/PL!F90*PL!F93 -> 13.837592 | E12: =(co_ai28-PL!F154)/PL!F147*PL!F150 -> 16.590834 | G12: =(co_ai28-PL!F211)/PL!F204*PL!F207 -> 18.49504 | I12: — | J12: 對照值＝模型 A 的 Broadcom XPU 顆數
A13: C. 共識（校準未使用）
A14: FY2026 營收 vs 共識 | B14: =cons_rev26 -> 105.98 | C14: =PL!D103 -> 105.889 | D14: =C14/B14-1 -> -0.00085865258 | E14: =PL!D160 -> 105.889 | F14: =E14/B14-1 -> -0.00085865258 | G14: =PL!D217 -> 105.889 | H14: =G14/B14-1 -> -0.00085865258 | I14: StockAnalysis | J14: 錨點
A15: FY2026 EPS vs 共識 | B15: =cons_eps26 -> 11.66 | C15: =PL!D123 -> 11.615277 | D15: =C15/B15-1 -> -0.0038356239 | E15: =PL!D180 -> 11.615277 | F15: =E15/B15-1 -> -0.0038356239 | G15: =PL!D237 -> 11.615277 | H15: =G15/B15-1 -> -0.0038356239 | I15: StockAnalysis | J15: 錨點（Q4 依指引與 In 頁假設）
A16: FY2027 營收 vs 共識 | B16: =cons_rev27 -> 173.97 | C16: =PL!E103 -> 173.50734 | D16: =C16/B16-1 -> -0.0026594318 | E16: =PL!E160 -> 173.50734 | F16: =E16/B16-1 -> -0.0026594318 | G16: =PL!E217 -> 173.50734 | H16: =G16/B16-1 -> -0.0026594318 | I16: StockAnalysis
A17: FY2027 EPS vs 共識 | B17: =cons_eps27 -> 19.4 | C17: =PL!E123 -> 18.077846 | D17: =C17/B17-1 -> -0.068152252 | E17: =PL!E180 -> 18.077846 | F17: =E17/B17-1 -> -0.068152252 | G17: =PL!E237 -> 18.077846 | H17: =G17/B17-1 -> -0.068152252 | I17: StockAnalysis
A18: FY2027 共識隱含 AI 營收（共識營收 − 模型非 AI − 模型軟體） | C18: =cons_rev27-PL!E100-PL!E101 -> 121.40399 | E18: =cons_rev27-PL!E157-PL!E158 -> 121.40399 | G18: =cons_rev27-PL!E214-PL!E215 -> 121.40399 | I18: 推導 | J18: 與公司展望 115 比較
A19: D. 份額與顆數（先驗比對的機制檢查）
A20: 2027 年 ASIC 金額份額（模組層級）vs 先驗比對推導 14–19% 中點 | B20: 0.165 | C20: =Units!D59 -> 0.22381744 | D20: =C20-B20 -> 0.058817437 | E20: =Units!D97 -> 0.22381744 | F20: =E20-B20 -> 0.058817437 | G20: =Units!D135 -> 0.22381744 | H20: =G20-B20 -> 0.058817437 | I20: 先驗比對_AVGO（Drive）
A21: 2027 年 ASIC 顆數份額 vs JPMorgan 53.6% | B21: =jpm_u27 -> 0.536 | C21: =Units!D60 -> 0.52742616 | D21: =C21-B21 -> -0.0085738397 | E21: =Units!D98 -> 0.52742616 | F21: =E21-B21 -> -0.0085738397 | G21: =Units!D136 -> 0.52742616 | H21: =G21-B21 -> -0.0085738397 | I21: JPMorgan（二手）；市場層同一來源 | J21: 非獨立檢驗（市場層顆數即取自 JPMorgan）
A22: 2027 年 Broadcom ÷ ASIC 顆數 vs Counterpoint 60% | B22: =cp_sh27 -> 0.6 | C22: =Units!D62 -> 0.55 | D22: =C22-B22 -> -0.05 | E22: =Units!D100 -> 0.55 | F22: =E22-B22 -> -0.05 | G22: =Units!D138 -> 0.55 | H22: =G22-B22 -> -0.05 | I22: Counterpoint（二手；口徑未說明）
A23: 2027 年 Broadcom ÷ ASIC 金額 vs Counterpoint 60% | B23: =cp_sh27 -> 0.6 | C23: =Units!D61 -> 0.61450056 | D23: =C23-B23 -> 0.014500558 | E23: =Units!D99 -> 0.61450056 | F23: =E23-B23 -> 0.014500558 | G23: =Units!D137 -> 0.61450056 | H23: =G23-B23 -> 0.014500558 | I23: 同上 | J23: JPMorgan：高階 ASIC 80–85%
A24: 2027 年 NVIDIA 金額份額 | C24: =Units!D54 -> 0.7126143 | E24: =Units!D92 -> 0.7126143 | G24: =Units!D130 -> 0.7126143 | I24: accel_share | J24: NVIDIA 模型同一套價格
A25: 每顆價差：NVIDIA Rubin 模組 ÷ TPU 總價（CY2027） | C25: =pm_rb/Units!D10 -> 3.5639391 | E25: =pm_rb/Units!D10 -> 3.5639391 | G25: =pm_rb/Units!D10 -> 3.5639391 | I25: — | J25: 顆數份額約為金額份額數倍的原因
A26: 近 12 月 non-GAAP P/E vs Andy 先驗「前瞻 35x」 | B26: 35 | C26: =Val!B63 -> 32.959016 | D26: =C26/B26-1 -> -0.058313817 | E26: =Val!B63 -> 32.959016 | F26: =E26/B26-1 -> -0.058313817 | G26: =Val!B63 -> 32.959016 | H26: =G26/B26-1 -> -0.058313817 | I26: 先驗_Andy_AVGO B9a（Drive） | J26: 35x 接近近 12 月倍數；前瞻（FY2027 EPS）倍數見 Val 頁
A27: E. 校準與網通
A28: k_x（XPU 校準係數） | C28: =PL!D89 -> 1.1077953 | E28: =PL!D146 -> 1.1077953 | G28: =PL!D203 -> 1.1077953 | I28: FY2026 錨點 ÷ 未校準 | J28: 接近 1＝市場層顆數 × 份額 × 假設單價與實績一致
A29: k_n（網通校準係數） | C29: =PL!D96 -> 1.3959864 | E29: =PL!D153 -> 1.3959864 | G29: =PL!D210 -> 1.3959864 | I29: rep_avgo26 ÷ markets/network 歸屬 | J29: markets/network 的 Broadcom 歸屬比例偏低（Assumed）
A30: m_core（XPU 核心毛利率，Derived） | C30: =PL!D110 -> 0.78755088 | E30: =PL!D167 -> 0.78755088 | G30: =PL!D224 -> 0.78755088 | I30: FY2026 毛利殘差 | J30: 高＝設計與邏輯晶片加價高；代購 HBM 稀釋整體
A31: FY2027 毛利率 vs FY2026（百分點） | B31: =a26_gp/a26_rev -> 0.75146616 | C31: =PL!E112 -> 0.67762206 | D31: =C31-B31 -> -0.073844094 | E31: =PL!E169 -> 0.67762206 | F31: =E31-B31 -> -0.073844094 | G31: =PL!E226 -> 0.67762206 | H31: =G31-B31 -> -0.073844094 | I31: 錨點 | J31: 公司 Q4 FY26 指引約 73%，續降
A32: FY2027 毛利率 vs 共識隱含（約 72%：EPS 19.40 × 股數 ÷（1−稅）＋利息＋營業費用，÷ 共識營收） | B32: =(cons_eps27*a26_sh/(1-tx_f)+int_f-oth_f+PL!E115)/cons_rev27 -> 0.72360398 | C32: =PL!E112 -> 0.67762206 | D32: =C32-B32 -> -0.045981915 | E32: =PL!E169 -> 0.67762206 | F32: =E32-B32 -> -0.045981915 | G32: =PL!E226 -> 0.67762206 | H32: =G32-B32 -> -0.045981915 | I32: 推導（共識無毛利率）
A33: F. 客戶融資曝險（資訊；不進基準 EPS）
A34: Anthropic 放款＋OpenAI 融資安排（標題值）vs FY2027 AI 營收（模型） | B34: =fin_anth+fin_oai -> 92 | C34: =PL!E98 -> 120.94133 | E34: =PL!E155 -> 120.94133 | G34: =PL!E212 -> 120.94133 | I34: top1markets 引 Reuters、WSJ、Bloomberg | J34: 媒體：約 92B ≈ 公司 FY2027 AI 目標的 80%；非資產負債表曝險，部分在銀行團；另有一家客戶機架租賃擔保約 29B（季報），可能與上列重疊，不加總
A35: 兩家合計 ÷ FY2027 AI 營收（模型） | C35: =(fin_anth+fin_oai)/PL!E98 -> 0.76069943 | E35: =(fin_anth+fin_oai)/PL!E155 -> 0.76069943 | G35: =(fin_anth+fin_oai)/PL!E212 -> 0.76069943 | I35: —
A36: 兩家合計 ÷ FY2027 淨利（模型） | C36: =(fin_anth+fin_oai)/PL!E121 -> 1.0346263 | E36: =(fin_anth+fin_oai)/PL!E178 -> 1.0346263 | G36: =(fin_anth+fin_oai)/PL!E235 -> 1.0346263 | I36: — | J36: 若全數損失的量級（不含回收與銀行團分擔）
A37: G. 預留
A38: R4 產業部署路徑（markets/deploy_path/，尚未建立）：上線後以 Broadcom AI 營收 ÷ 部署 GW 對照 Tokenomics IF_NonNV_Hold_TPU 等比例 | J38: 預留列：本版無數值

Sheet Sens
A1: Sens — 一次動一個輸入（情境 A；k_x、k_n、m_core 在每個案例內依 FY2026 實績重算，FY2026 恆等於錨點）：對 FY2027、FY2028 的營收、AI 營收、毛利率與 EPS 的影響。每個案例是一個完整推導區塊（本頁下方）
A3: 案例 | B3: 設定 | C3: FY2027 營收 | D3: FY2027 AI 營收 | E3: FY2027 毛利率 | F3: FY2027 EPS | G3: FY2027 EPS 相對基準 | H3: FY2028 營收 | I3: FY2028 AI 營收 | J3: FY2028 毛利率 | K3: FY2028 EPS | L3: FY2028 EPS 相對基準
A4: 基準（情境 A） | B4: PL 區塊 A | C4: =PL!E103 -> 173.50734 | D4: =PL!E98 -> 120.94133 | E4: =PL!E112 -> 0.67762206 | F4: =PL!E123 -> 18.077846 | G4: =F4/F$4-1 -> 0 | H4: =PL!F103 -> 207.77522 | I4: =PL!F98 -> 151.87237 | J4: =PL!F112 -> 0.64735182 | K4: =PL!F123 -> 21.026681 | L4: =K4/K$4-1 -> 0
A5: XPU 顆數係數 ×0.9 | B5: FY2027 起 Broadcom XPU 顆數 ×0.9 | C5: =E73 -> 165.17672 | D5: =E68 -> 112.61071 | E5: =E82 -> 0.68367504 | F5: =E93 -> 17.29633 | G5: =F5/F$4-1 -> -0.04323061 | H5: =F73 -> 197.06839 | I5: =F68 -> 141.16554 | J5: =F82 -> 0.65447959 | K5: =F93 -> 20.090345 | L5: =K5/K$4-1 -> -0.044530854
A6: XPU 顆數係數 ×1.1 | B6: ×1.1 | C6: =E130 -> 181.83796 | D6: =E125 -> 129.27195 | E6: =E139 -> 0.6721237 | F6: =E150 -> 18.859363 | G6: =F6/F$4-1 -> 0.04323061 | H6: =F130 -> 218.48204 | I6: =F125 -> 162.5792 | J6: =F139 -> 0.64092265 | K6: =F150 -> 21.963017 | L6: =K6/K$4-1 -> 0.044530854
A7: TPU 份額 −15pt | B7: FY2027 起 Broadcom 占 TPU 顆數 −15 個百分點（MediaTek 版放量） | C7: =E187 -> 162.59317 | D7: =E182 -> 110.02716 | E7: =E196 -> 0.68547768 | F7: =E207 -> 17.048392 | G7: =F7/F$4-1 -> -0.056945644 | H7: =F187 -> 192.65927 | I7: =F182 -> 136.75643 | J7: =F196 -> 0.6570879 | K7: =F207 -> 19.685094 | L7: =K7/K$4-1 -> -0.063804005
A8: TPU 份額 +10pt | B8: +10 個百分點（上限 100%） | C8: =E244 -> 180.78345 | D8: =E239 -> 128.21744 | E8: =E253 -> 0.67291194 | F8: =E264 -> 18.764149 | G8: =F8/F$4-1 -> 0.037963763 | H8: =F244 -> 217.85251 | I8: =F239 -> 161.94966 | J8: =F253 -> 0.64161171 | K8: =F264 -> 21.921072 | L8: =K8/K$4-1 -> 0.042536003
A9: 其他 ASIC 份額 −15pt | B9: FY2027 起 −15 個百分點 | C9: =E301 -> 166.66263 | D9: =E296 -> 114.09662 | E9: =E310 -> 0.68283566 | F9: =E321 -> 17.443827 | G9: =F9/F$4-1 -> -0.035071634 | H9: =F301 -> 199.18742 | I9: =F296 -> 143.28457 | J9: =F310 -> 0.65374304 | K9: =F321 -> 20.301023 | L9: =K9/K$4-1 -> -0.034511295
A10: 其他 ASIC 份額 +15pt | B10: +15 個百分點 | C10: =E358 -> 180.35205 | D10: =E353 -> 127.78604 | E10: =E367 -> 0.6728042 | F10: =E378 -> 18.711866 | G10: =F10/F$4-1 -> 0.035071634 | H10: =F358 -> 216.36301 | I10: =F353 -> 160.46016 | J10: =F367 -> 0.64146796 | K10: =F378 -> 21.752339 | L10: =K10/K$4-1 -> 0.034511295
A11: 核心售價 ×0.8 | B11: FY2027 起 XPU 核心售價 ×0.8 | C11: =E415 -> 162.41831 | D11: =E410 -> 109.8523 | E11: =E424 -> 0.67011673 | F11: =E435 -> 16.602105 | G11: =F11/F$4-1 -> -0.081632608 | H11: =F415 -> 194.81401 | I11: =F410 -> 138.91116 | J11: =F424 -> 0.63802421 | K11: =F435 -> 19.290935 | L11: =K11/K$4-1 -> -0.082549664
A12: 核心售價 ×1.2 | B12: ×1.2 | C12: =E472 -> 184.59637 | D12: =E467 -> 132.03036 | E12: =E481 -> 0.68422568 | F12: =E492 -> 19.553588 | G12: =F12/F$4-1 -> 0.081632608 | H12: =F472 -> 220.73642 | I12: =F467 -> 164.83357 | J12: =F481 -> 0.65558403 | K12: =F492 -> 22.762426 | L12: =K12/K$4-1 -> 0.082549664
A13: HBM 代購比例 0.3 | B13: 代購 30%（k_x、m_core 重算） | C13: =E529 -> 166.19343 | D13: =E524 -> 113.62742 | E13: =E538 -> 0.70304231 | F13: =E549 -> 17.963271 | G13: =F13/F$4-1 -> -0.006337897 | H13: =F529 -> 194.8402 | I13: =F524 -> 138.93735 | J13: =F538 -> 0.68368931 | K13: =F549 -> 20.815364 | L13: =K13/K$4-1 -> -0.010049903
A14: HBM 代購比例 1.0 | B14: 全部代購 | C14: =E586 -> 181.48409 | D14: =E581 -> 128.91808 | E14: =E595 -> 0.65223389 | F14: =E606 -> 18.202806 | G14: =F14/F$4-1 -> 0.0069122842 | H14: =F586 -> 221.8825 | I14: =F581 -> 165.97965 | J14: =F595 -> 0.61255121 | K14: =F606 -> 21.257148 | L14: =K14/K$4-1 -> 0.0109607
A15: 代購 HBM 毛利率 0% | B15: 零加成 | C15: =E643 -> 173.50734 | D15: =E638 -> 120.94133 | E15: =E652 -> 0.66830257 | F15: =E663 -> 17.801705 | G15: =F15/F$4-1 -> -0.015275146 | H15: =F643 -> 207.77522 | I15: =F638 -> 151.87237 | J15: =F652 -> 0.63358816 | K15: =F663 -> 20.535856 | L15: =K15/K$4-1 -> -0.023342936
A16: 代購 HBM 毛利率 20% | B16: 20% | C16: =E700 -> 173.50734 | D16: =E695 -> 120.94133 | E16: =E709 -> 0.68694156 | F16: =E720 -> 18.353988 | G16: =F16/F$4-1 -> 0.015275146 | H16: =F700 -> 207.77522 | I16: =F695 -> 151.87237 | J16: =F709 -> 0.66111548 | K16: =F720 -> 21.517505 | L16: =K16/K$4-1 -> 0.023342936
A17: AI 網通 ×0.8 | B17: FY2027 起網通 ×0.8 | C17: =E757 -> 165.98031 | D17: =E752 -> 113.4143 | E17: =E766 -> 0.67570027 | F17: =E777 -> 17.162971 | G17: =F17/F$4-1 -> -0.050607539 | H17: =F757 -> 198.8144 | I17: =F752 -> 142.91155 | J17: =F766 -> 0.64407747 | K17: =F777 -> 19.930349 | L17: =K17/K$4-1 -> -0.052140045
A18: AI 網通 ×1.2 | B18: ×1.2 | C18: =E814 -> 181.03437 | D18: =E809 -> 128.46836 | E18: =E823 -> 0.67938405 | F18: =E834 -> 18.992722 | G18: =F18/F$4-1 -> 0.050607539 | H18: =F814 -> 216.73603 | I18: =F809 -> 160.83318 | J18: =F823 -> 0.65035541 | K18: =F834 -> 22.123013 | L18: =K18/K$4-1 -> 0.052140045
A19: 軟體成長 低 | B19: FY2027 +8%、之後 +4% | C19: =E871 -> 172.2503 | D19: =E866 -> 120.94133 | E19: =E880 -> 0.67578027 | F19: =E891 -> 17.879978 | G19: =F19/F$4-1 -> -0.010945326 | H19: =F871 -> 205.06001 | I19: =F866 -> 151.87237 | J19: =F880 -> 0.64360926 | K19: =F891 -> 20.595122 | L19: =K19/K$4-1 -> -0.020524312
A20: 軟體成長 高 | B20: FY2027 +18%、之後 +12% | C20: =E928 -> 175.3929 | D20: =E923 -> 120.94133 | E20: =E937 -> 0.68033525 | F20: =E948 -> 18.374648 | G20: =F20/F$4-1 -> 0.016417989 | H20: =F928 -> 211.29493 | I20: =F923 -> 151.87237 | J20: =F937 -> 0.65206012 | K20: =F948 -> 21.585734 | L20: =K20/K$4-1 -> 0.026587789
A21: 營業費用率 +2pt | B21: 營業費用額外 +2% × 營收 | C21: =E985 -> 173.50734 | D21: =E980 -> 120.94133 | E21: =E994 -> 0.67762206 | F21: =E1005 -> 17.485236 | G21: =F21/F$4-1 -> -0.032781047 | H21: =F985 -> 207.77522 | I21: =F980 -> 151.87237 | J21: =F994 -> 0.64735182 | K21: =F1005 -> 20.313463 | L21: =K21/K$4-1 -> -0.033919669
A22: 顆數情境 B | B22: CY2028 ×0.8、CY2029 ×0.85；記憶體 B 路徑 | C22: =PL!E160 -> 173.50734 | D22: =PL!E155 -> 120.94133 | E22: =PL!E169 -> 0.67762206 | F22: =PL!E180 -> 18.077846 | G22: =F22/F$4-1 -> 0 | H22: =PL!F160 -> 166.64307 | I22: =PL!F155 -> 110.74023 | J22: =PL!F169 -> 0.69563801 | K22: =PL!F180 -> 17.837686 | L22: =K22/K$4-1 -> -0.15166421
A23: 顆數情境 C | B23: CY2028–29 ×0.6；記憶體 C 路徑 | C23: =PL!E217 -> 173.50734 | D23: =PL!E212 -> 120.94133 | E23: =PL!E226 -> 0.67762206 | F23: =PL!E237 -> 18.077846 | G23: =F23/F$4-1 -> 0 | H23: =PL!F217 -> 135.50019 | I23: =PL!F212 -> 79.597349 | J23: =PL!F226 -> 0.72576851 | K23: =PL!F237 -> 14.820139 | L23: =K23/K$4-1 -> -0.2951746
A25: 讀法：FY2027 三情境相同；顆數情境 B、C 的差異從 FY2028 起。k_x 隨案例重算，所以 HBM 代購比例只改變營收組合與毛利率，不改 FY2026 水準。
A27: 目標價參數敏感度（v0.2）：加權目標價（Val 第 0 節）一次動一個參數；PL 延伸期的收斂路徑不隨 tp_g 變動，tp_g 只改再投資率與永續成長
A28: 參數 | B28: 設定（低／高） | C28: 低：加權目標價 | D28: 低：相對基準 | E28: 高：加權目標價 | F28: 高：相對基準 | G28: 基準加權目標價
A29: tp_r ±1pt | B29: 折現率 −1pt／＋1pt | C29: =tp_w_dcf*(tp_wA*(MAX(0,Val!B7*Val!$G$7*(1-MIN(0.8,tp_g/tp_roe))/(1+(tp_r-0.01))^Val!$F$7+Val!B8*Val!$G$8*(1-MIN(0.8,tp_g/tp_roe))/(1+(tp_r-0.01))^Val!$F$8+Val!B9*Val!$G$9*(1-MIN(0.8,tp_g/tp_roe))/(1+(tp_r-0.01))^Val!$F$9+Val!B10*Val!$G$10*(1-MIN(0.8,tp_g/tp_roe))/(1+(tp_r-0.01))^Val!$F$10+Val!B11*Val!$G$11*(1-MIN(0.8,tp_g/tp_roe))/(1+(tp_r-0.01))^Val!$F$11+Val!B12*Val!$G$12*(1-MIN(0.8,tp_g/tp_roe))/(1+(tp_r-0.01))^Val!$F$12+Val!B12*(1-MIN(0.8,tp_g/tp_roe))*(1+tp_g)/((tp_r-0.01)-tp_g)/(1+(tp_r-0.01))^Val!$F$12))+tp_wB*(MAX(0,Val!C7*Val!$G$7*(1-MIN(0.8,tp_g/tp_roe))/(1+(tp_r-0.01))^Val!$F$7+Val!C8*Val!$G$8*(1-MIN(0.8,tp_g/tp_roe))/(1+(tp_r-0.01))^Val!$F$8+Val!C9*Val!$G$9*(1-MIN(0.8,tp_g/tp_roe))/(1+(tp_r-0.01))^Val!$F$9+Val!C10*Val!$G$10*(1-MIN(0.8,tp_g/tp_roe))/(1+(tp_r-0.01))^Val!$F$10+Val!C11*Val!$G$11*(1-MIN(0.8,tp_g/tp_roe))/(1+(tp_r-0.01))^Val!$F$11+Val!C12*Val!$G$12*(1-MIN(0.8,tp_g/tp_roe))/(1+(tp_r-0.01))^Val!$F$12+Val!C12*(1-MIN(0.8,tp_g/tp_roe))*(1+tp_g)/((tp_r-0.01)-tp_g)/(1+(tp_r-0.01))^Val!$F$12))+tp_wC*(MAX(0,Val!D7*Val!$G$7*(1-MIN(0.8,tp_g/tp_roe))/(1+(tp_r-0.01))^Val!$F$7+Val!D8*Val!$G$8*(1-MIN(0.8,tp_g/tp_roe))/(1+(tp_r-0.01))^Val!$F$8+Val!D9*Val!$G$9*(1-MIN(0.8,tp_g/tp_roe))/(1+(tp_r-0.01))^Val!$F$9+Val!D10*Val!$G$10*(1-MIN(0.8,tp_g/tp_roe))/(1+(tp_r-0.01))^Val!$F$10+Val!D11*Val!$G$11*(1-MIN(0.8,tp_g/tp_roe))/(1+(tp_r-0.01))^Val!$F$11+Val!D12*Val!$G$12*(1-MIN(0.8,tp_g/tp_roe))/(1+(tp_r-0.01))^Val!$F$12+Val!D12*(1-MIN(0.8,tp_g/tp_roe))*(1+tp_g)/((tp_r-0.01)-tp_g)/(1+(tp_r-0.01))^Val!$F$12)))*(1+(tp_r-0.01))+(1-tp_w_dcf)*tp_comp_adj -> 304.18692 | D29: =C29/G29-1 -> 0.11380116 | E29: =tp_w_dcf*(tp_wA*(MAX(0,Val!B7*Val!$G$7*(1-MIN(0.8,tp_g/tp_roe))/(1+(tp_r+0.01))^Val!$F$7+Val!B8*Val!$G$8*(1-MIN(0.8,tp_g/tp_roe))/(1+(tp_r+0.01))^Val!$F$8+Val!B9*Val!$G$9*(1-MIN(0.8,tp_g/tp_roe))/(1+(tp_r+0.01))^Val!$F$9+Val!B10*Val!$G$10*(1-MIN(0.8,tp_g/tp_roe))/(1+(tp_r+0.01))^Val!$F$10+Val!B11*Val!$G$11*(1-MIN(0.8,tp_g/tp_roe))/(1+(tp_r+0.01))^Val!$F$11+Val!B12*Val!$G$12*(1-MIN(0.8,tp_g/tp_roe))/(1+(tp_r+0.01))^Val!$F$12+Val!B12*(1-MIN(0.8,tp_g/tp_roe))*(1+tp_g)/((tp_r+0.01)-tp_g)/(1+(tp_r+0.01))^Val!$F$12))+tp_wB*(MAX(0,Val!C7*Val!$G$7*(1-MIN(0.8,tp_g/tp_roe))/(1+(tp_r+0.01))^Val!$F$7+Val!C8*Val!$G$8*(1-MIN(0.8,tp_g/tp_roe))/(1+(tp_r+0.01))^Val!$F$8+Val!C9*Val!$G$9*(1-MIN(0.8,tp_g/tp_roe))/(1+(tp_r+0.01))^Val!$F$9+Val!C10*Val!$G$10*(1-MIN(0.8,tp_g/tp_roe))/(1+(tp_r+0.01))^Val!$F$10+Val!C11*Val!$G$11*(1-MIN(0.8,tp_g/tp_roe))/(1+(tp_r+0.01))^Val!$F$11+Val!C12*Val!$G$12*(1-MIN(0.8,tp_g/tp_roe))/(1+(tp_r+0.01))^Val!$F$12+Val!C12*(1-MIN(0.8,tp_g/tp_roe))*(1+tp_g)/((tp_r+0.01)-tp_g)/(1+(tp_r+0.01))^Val!$F$12))+tp_wC*(MAX(0,Val!D7*Val!$G$7*(1-MIN(0.8,tp_g/tp_roe))/(1+(tp_r+0.01))^Val!$F$7+Val!D8*Val!$G$8*(1-MIN(0.8,tp_g/tp_roe))/(1+(tp_r+0.01))^Val!$F$8+Val!D9*Val!$G$9*(1-MIN(0.8,tp_g/tp_roe))/(1+(tp_r+0.01))^Val!$F$9+Val!D10*Val!$G$10*(1-MIN(0.8,tp_g/tp_roe))/(1+(tp_r+0.01))^Val!$F$10+Val!D11*Val!$G$11*(1-MIN(0.8,tp_g/tp_roe))/(1+(tp_r+0.01))^Val!$F$11+Val!D12*Val!$G$12*(1-MIN(0.8,tp_g/tp_roe))/(1+(tp_r+0.01))^Val!$F$12+Val!D12*(1-MIN(0.8,tp_g/tp_roe))*(1+tp_g)/((tp_r+0.01)-tp_g)/(1+(tp_r+0.01))^Val!$F$12)))*(1+(tp_r+0.01))+(1-tp_w_dcf)*tp_comp_adj -> 250.91072 | F29: =E29/G29-1 -> -0.081273288 | G29: =Val!$B$40 -> 273.10702
