Workbook

Sheet README
A1: 京元電子（2449）收支與估值模型 v0.2（AI 半導體 Project：測試代工；AI GPU／ASIC 最終測試與 burn-in） 2026-10-25
A2: 版本：v0.2（2026-10-25：目標價改為 DCF 與 Comparable 加權，取代 v0.1 的短期法／長期法）。驅動邏輯比照 Advantest 模型（測試需求＝加速器顆數 × 每顆測試時間；顆數與情境係數讀台積電模型成品）；台股寫法比照台達電、台光電模型。
A3: 模型命題：京元電的 AI 測試營收＝加速器顆數（NVIDIA、ASIC）× 每顆測試時間（含 burn-in；Rubin 世代加長）× 京元電曝險 × 每加權顆營收（FY2026 校準）× 份額相對值 × 測試單價；非 AI（伺服器 CPU、手機、消費、車用）另依成長率推。毛利率由固定現金成本、變動現金成本與折舊推出，折舊由隨當年營收增量擴產的資本支出累積。股價約 32 倍 FY2026、24 倍 FY2027 EPS（模型）。
A4: 核心問題：2026 年 500 億的擴產（約為營收的一倍）能否在 2027–28 年被 AI 測試量吸收；顆數放緩或份額流失時，累積的折舊會讓毛利率掉多少；現價隱含的路徑合不合理。
A6: 會計年度＝日曆年，FY(t)＝CY(t)，不平移。預測期 FY2027–FY2029 由驅動因子推導；FY2030 起為收斂法，非驅動因子推導（營收年增與淨利率線性收斂，延伸到 FY2032；PL 頁綠底）。金額：十億新台幣。口徑：歸屬母公司淨利；FY2026 起以盈餘配股 5% 後的股數計 EPS。
A8: 驅動因子 → 推導量（全部唯讀上游，不修改）
A9: 需求面：tsmc 成品的加速器顆數（八個平台）× 情境顆數係數 × 每顆測試時間係數（Assumed／Analogy，比照 Advantest 模型並加 burn-in）× 京元電曝險（ASIC、AMD 相對 NVIDIA，Assumed）＝加權顆數；× 每加權顆營收（FY2026 以 AI 占比 35% 校準，Derived）× 份額相對值 × 測試單價指數（Assumed）＝AI 加速器測試營收。
A10: 供給面：資本支出＝維持性比例 × 營收＋κ × 當年營收增量（κ 以 FY2025 現金資本支出與 FY2025 營收增量校準）；FY2026 取公司預算 500 億的現金口徑 420 億（Derived）。折舊＝前一年 ×（1 − 到期）＋折舊率 × 資本支出平均。
A11: 毛利率：營收 − 現金營業成本（固定 F，FY2026 校準；變動 v × 測試量）− 折舊。營業費用：彈性 phi。淨利 ÷ 營業利益 0.84（Assumed：利息費用上升）。
A12: 校準：FY2026 ＝ 1H26 實績＋3Q26 營收實績（月營收）＋假設（4Q 季增 15%、毛利率 38.5％／39.5%、折舊 29.5／31.5 億、營業費用率 12.5%）。3Q26 財報約 11 月上旬公布。不用共識數字（只在 Recon 對帳）。
A13: 估值：現價 ÷ FY2027、FY2028 EPS；十年 P/E 規則值（年底收盤 ÷ 當年 EPS，10 年）× 各情境 FY2027 EPS；循環位置以本模型營收最高年判定（京元電不套設備股見頂年）。目標價（Val 第 0 節）＝0.5 × DCF（股東現金流＝EPS ×（1 − g／ROE），FY2027–32 明確期＋永續，r 10%、g 4%，情境權重 0.3／0.5／0.2）＋0.5 × Comparable（台美封測同業前瞻 P/E 中位數 × 12 個月後前瞻 EPS）；十年 P/E 規則值保留參考。本版未做先驗，無 Andy 合理 P/E 對照。
A14: 標記：Verified、Interested-party、Analogy、Assumed、Derived。SemiAnalysis 未使用。公司原文＝每季 Investor update 與月營收；AI 占比、客戶、資本支出預算多經媒體與券商轉述。
... A17: v0.2（2026-10-25）：Val 頁第 0 節由短期法／長期法改為「0. 目標價」（0.1 DCF、0.2 Comparable、0.3 結論），第 1 節起整體下移 23 列；In 頁 tp_mix 改為 tp_w_dcf，新增共識目標價與共識前瞻 EPS；Recon 的 Morgan Stanley 對照改用加權目標價；Sens 加目標價參數列。PL、FY2026–FY2032 EPS 不變。

Sheet In
A1: In — 輸入（藍字；基準欄 E，低 D、高 F）。金額：十億新台幣（NT$B）；顆數：百萬顆；比例：%。每個輸入附兩個來源（找不到者寫「未找到」）；公司原文算一個
A2: 標記：Verified／Interested-party／Analogy／Assumed／Derived；Analogy、Assumed 給低／高區間。SemiAnalysis 未使用。公司原文＝京元電每季 Investor update（英文簡報）與月營收公告；AI 占比、客戶與券商估計為 Interested-party（媒體、券商轉述）
A3: 鍵 | B3: 項目 | C3: 單位 | D3: 低 | E3: 基準 | F3: 高 | G3: 標記 | H3: 來源1 | I3: 來源2／說明
A4: A. 加速器顆數（讀 tsmc 成品 In 頁，與 HBM、台積電、Advantest 模型同一份；情境係數不另訂）
A5: u_bw_26 | B5: NVIDIA Blackwell 顆數 2026 | C5: 百萬顆 | E5: 5.4 | G5: Derived | H5: tsmc/dist/20261025_台積電模型_v0.3.xlsx｜In!E5 | I5: markets/memory UNITS（經台積電模型；顆數本身多為 Interested-party／Assumed，見上游）
A6: u_bw_27 | B6: NVIDIA Blackwell 顆數 2027 | C6: 百萬顆 | E6: 2.4 | G6: Derived | H6: tsmc/dist/20261025_台積電模型_v0.3.xlsx｜In!E6 | I6: 同上
A7: u_bw_28 | B7: NVIDIA Blackwell 顆數 2028 | C7: 百萬顆 | E7: 0.5 | G7: Derived | H7: tsmc/dist/20261025_台積電模型_v0.3.xlsx｜In!E7 | I7: 同上
A8: g29_bw | B8: NVIDIA Blackwell 2029 顆數成長 | C8: % | E8: -0.5 | G8: Assumed | H8: tsmc/dist/20261025_台積電模型_v0.3.xlsx｜In!E8 | I8: 沿用台積電模型
A9: u_rb_26 | B9: NVIDIA Rubin 顆數 2026 | C9: 百萬顆 | E9: 1.7 | G9: Derived | H9: tsmc/dist/20261025_台積電模型_v0.3.xlsx｜In!E9 | I9: markets/memory UNITS（經台積電模型；顆數本身多為 Interested-party／Assumed，見上游）
A10: u_rb_27 | B10: NVIDIA Rubin 顆數 2027 | C10: 百萬顆 | E10: 7 | G10: Derived | H10: tsmc/dist/20261025_台積電模型_v0.3.xlsx｜In!E10 | I10: 同上
A11: u_rb_28 | B11: NVIDIA Rubin 顆數 2028 | C11: 百萬顆 | E11: 7 | G11: Derived | H11: tsmc/dist/20261025_台積電模型_v0.3.xlsx｜In!E11 | I11: 同上
A12: g29_rb | B12: NVIDIA Rubin 2029 顆數成長 | C12: % | E12: 0.15 | G12: Assumed | H12: tsmc/dist/20261025_台積電模型_v0.3.xlsx｜In!E12 | I12: 沿用台積電模型
A13: u_ru_26 | B13: NVIDIA Rubin Ultra 顆數 2026 | C13: 百萬顆 | E13: 0 | G13: Derived | H13: tsmc/dist/20261025_台積電模型_v0.3.xlsx｜In!E13 | I13: markets/memory UNITS（經台積電模型；顆數本身多為 Interested-party／Assumed，見上游）
A14: u_ru_27 | B14: NVIDIA Rubin Ultra 顆數 2027 | C14: 百萬顆 | E14: 0.3 | G14: Derived | H14: tsmc/dist/20261025_台積電模型_v0.3.xlsx｜In!E14 | I14: 同上
A15: u_ru_28 | B15: NVIDIA Rubin Ultra 顆數 2028 | C15: 百萬顆 | E15: 2 | G15: Derived | H15: tsmc/dist/20261025_台積電模型_v0.3.xlsx｜In!E15 | I15: 同上
A16: g29_ru | B16: NVIDIA Rubin Ultra 2029 顆數成長 | C16: % | E16: 0.15 | G16: Assumed | H16: tsmc/dist/20261025_台積電模型_v0.3.xlsx｜In!E16 | I16: 沿用台積電模型
... A42: um29_C | B42: 情境 C：2029 顆數 ÷ 基準 | C42: x | E42: 0.6 | G42: Assumed | H42: tsmc/dist/20261025_台積電模型_v0.3.xlsx｜In!E42 | I42: 同上
A43: fx | B43: 匯率（新台幣 ÷ 美元；只用於每顆美元換算的顯示） | C43: NT$/US$ | D43: 30.5 | E43: 32 | F43: 33 | G43: Derived | H43: 與台達電、台光電模型相同 | I43: 不影響營收與 EPS
A44: B. 每顆測試時間（含 burn-in）係數與京元電曝險（Blackwell＝1.0；NVIDIA 曝險＝1.0）
A45: tt_bw | B45: 每顆測試時間（含 burn-in）係數：NVIDIA Blackwell | C45: x | E45: 1 | G45: Assumed | H45: 定義：Blackwell＝1.0 | I45: 校準在 FY2026 進行，係數只決定世代與平台間的相對權重
A46: tt_rb | B46: 每顆測試時間（含 burn-in）係數：NVIDIA Rubin | C46: x | D46: 1.2 | E46: 1.5 | F46: 1.8 | G46: Assumed | H46: Advantest 模型 ATE 測試時間 1.3（Analogy）＋ burn-in 加長：Morgan Stanley 估 R 系列 burn-in 增量占 2026 營收 3–5%（2026-06-23） | I46: 公司：GPU 客戶要求更高可靠度，burn-in 後需再做最終測試，總測試時間拉長（理財周刊 2026-09-24）
A47: tt_ru | B47: 每顆測試時間（含 burn-in）係數：NVIDIA Rubin Ultra | C47: x | D47: 1.5 | E47: 2 | F47: 2.6 | G47: Assumed | H47: Advantest 模型 1.7（4 顆光罩尺寸晶粒＋16 疊 HBM4E）＋ burn-in 功耗更高；Assumed | I47: 第二來源：未找到
A48: tt_hp | B48: 每顆測試時間（含 burn-in）係數：NVIDIA Hopper | C48: x | D48: 0.5 | E48: 0.6 | F48: 0.8 | G48: Analogy | H48: Advantest 模型 0.6；上一世代 | I48: 第二來源：未找到
A49: tt_amd | B49: 每顆測試時間（含 burn-in）係數：AMD Instinct | C49: x | D49: 0.9 | E49: 1.1 | F49: 1.4 | G49: Analogy | H49: Advantest 模型 1.1 | I49: 第二來源：未找到
A50: tt_tpu | B50: 每顆測試時間（含 burn-in）係數：Google TPU | C50: x | D50: 0.7 | E50: 0.9 | F50: 1.2 | G50: Assumed | H50: Advantest 模型 1.0；ASIC 的 burn-in 時間短於 GPU（Assumed） | I50: 第二來源：未找到
A51: tt_trn | B51: 每顆測試時間（含 burn-in）係數：AWS Trainium | C51: x | D51: 0.6 | E51: 0.8 | F51: 1.1 | G51: Analogy | H51: Advantest 模型 0.8 | I51: 第二來源：未找到
A52: tt_oth | B52: 每顆測試時間（含 burn-in）係數：其他 ASIC（MTIA、Maia 等） | C52: x | D52: 0.5 | E52: 0.7 | F52: 1 | G52: Analogy | H52: Advantest 模型 0.7 | I52: 第二來源：未找到
A53: ex_amd | B53: 京元電曝險（相對 NVIDIA＝1.0）：AMD Instinct | C53: x | D53: 0.1 | E53: 0.2 | F53: 0.4 | G53: Assumed | H53: AMD 委外測試主要在日月光、Amkor（Assumed）；京元電份額：未找到 | I53: 公司：GPU 測試是較大的營收來源，ASIC 2026–27 由低基期快速成長（富果 2025-11-28 法說摘要）
A54: ex_tpu | B54: 京元電曝險（相對 NVIDIA＝1.0）：Google TPU | C54: x | D54: 0.3 | E54: 0.5 | F54: 0.7 | G54: Assumed | H54: Google 相關（TPU、CPU、最終測試、部分晶圓測試）約占 2026 營收 10%（Morgan Stanley 2026-06-23）；聯發科 TPU 後段測試 9 月起量產（優分析 2026-09-18） | I54: —
A55: ex_trn | B55: 京元電曝險（相對 NVIDIA＝1.0）：AWS Trainium | C55: x | D55: 0.2 | E55: 0.4 | F55: 0.6 | G55: Assumed | H55: AWS ASIC 專案出貨中（優分析 2026-09-18）；份額：未找到 | I55: —
A56: ex_oth | B56: 京元電曝險（相對 NVIDIA＝1.0）：其他 ASIC（MTIA、Maia 等） | C56: x | D56: 0.2 | E56: 0.4 | F56: 0.6 | G56: Assumed | H56: Meta 等 ASIC（理財周刊 2026-09-24）；份額：未找到 | I56: —
A57: C. 份額、價格與 AI 部署係數（FY2027 起）
A58: rel_27 | B58: 京元電份額 2027 ÷ 2026（相對值；對 NVIDIA 與 ASIC 委外測試） | C58: x | D58: 0.88 | E58: 0.95 | F58: 1 | G58: Assumed | H58: NVIDIA 分散測試供應鏈（日月光、矽品、Amkor 擴最終測試與 burn-in）；京元電份額：未找到 | I58: Morgan Stanley：AI GPU 與 ASIC 最終測試市占穩固（2026-06-23，Interested-party）
A59: rel_28 | B59: 京元電份額 2028 ÷ 2026（相對值；對 NVIDIA 與 ASIC 委外測試） | C59: x | D59: 0.8 | E59: 0.92 | F59: 1 | G59: Assumed | H59: 同上 | I59: —
A60: rel_29 | B60: 京元電份額 2029 ÷ 2026（相對值；對 NVIDIA 與 ASIC 委外測試） | C60: x | D60: 0.75 | E60: 0.9 | F60: 1 | G60: Assumed | H60: 同上 | I60: —
A61: pp_27 | B61: 測試單價指數 2027（2026＝1；每單位測試時間的價格） | C61: x | D61: 0.95 | E61: 0.98 | F61: 1.02 | G61: Assumed | H61: 公司未揭露測試單價：未找到；低毛利手機、網通訂單移出，產品組合改善（工商時報 2026-07-28） | I61: 新產能到位後價格競爭（Assumed）
A62: pp_28 | B62: 測試單價指數 2028（2026＝1；每單位測試時間的價格） | C62: x | D62: 0.9 | E62: 0.96 | F62: 1 | G62: Assumed | H62: 同上 | I62: —
A63: pp_29 | B63: 測試單價指數 2029（2026＝1；每單位測試時間的價格） | C63: x | D63: 0.88 | E63: 0.95 | F63: 1 | G63: Assumed | H63: 同上 | I63: —
A64: mf | B64: AI 部署係數（Sens 用；FY2027 起乘在加權顆數上） | C64: x | D64: 0.8 | E64: 1 | F64: 1.2 | G64: Assumed | H64: 無 | I64: ±20%
A65: D. 營收結構錨點（AI 加速器測試＝NVIDIA GPU＋ASIC 的晶圓測試、最終測試、burn-in）
...

Sheet Q
A1: Q — 實績與 FY2026 錨點（十億新台幣；EPS 為新台幣；股數為十億股）。藍字＝輸入；黑字＝公式。季資料取自京元電每季 Investor update（營收、毛利率、推銷管理費用、研發、EBITDA、EPS）；營業利益＝毛利 − 營業費用，折舊攤提＝EBITDA − 營業利益（Derived）
A2: FY2026 錨點＝1H26 實績＋3Q26 營收實績（月營收）＋3Q、4Q 假設（毛利率、折舊、營業費用率、淨利 ÷ 營業利益；4Q 營收＝3Q × (1＋季增)）。3Q26 財報約 11 月上旬公布（確切日期：未找到），公布後更新。FY2025 淨利含 1Q25 出售蘇州京隆科技的處分利益（法人估約每股 2 元，未拆出金額：未找到）
A3: 項目 | B3: FY2025A | C3: 1H26（實績） | D3: 3Q26（營收實績） | E3: 4Q26（模型） | F3: FY2026 錨點 | G3: 標記 | H3: 來源1 | I3: 來源2／說明
A4: 營收 | B4: =SUM(B26:E26) -> 34.9336 | C4: =SUM(F26:G26) -> 21.3335 | D4: =q3_rev -> 12.142258 | E4: =D4*(1+q4g) -> 13.963597 | F4: =SUM(C4:E4) -> 47.439355 | G4: Verified／Assumed（4Q 季增） | H4: 季資料（本頁下方）：公司 Investor update 1Q25–2Q26（https://kyec.com.tw/Upfiles/EDUp/files/關於京元/KYEC(2449TW)_2Q25 Investor update_English.pdf、https://www.kyec.com.tw/Upfiles/EDUp/files/投資人關係/每季營運報告/KYEC(2449)_4Q25 Investor update_English.pdf、https://www.kyec.com.tw/Upfiles/EDUp/files/投資人關係/每季營運報告/KYEC(2449)_2Q26 Investor update_English.pdf） | I4: FY2025 月營收合計 349.34 億（HiStock）、中央社 349.33 億；1H26 213.34 億（HiStock 月營收）；3Q26：https://finance.technews.tw/2026/10/08/kyec-2449-202609-financial-report/
A5: 毛利 | B5: =SUM(B31:E31) -> 12.520816 | C5: =SUM(F31:G31) -> 8.4511931 | D5: =D4*q3_gm -> 4.6747693 | E5: =E4*q4_gm -> 5.5156207 | F5: =SUM(C5:E5) -> 18.641583 | G5: Derived（營收 × 毛利率）／Assumed | H5: 季資料（本頁下方）：公司 Investor update 1Q25–2Q26（https://kyec.com.tw/Upfiles/EDUp/files/關於京元/KYEC(2449TW)_2Q25 Investor update_English.pdf、https://www.kyec.com.tw/Upfiles/EDUp/files/投資人關係/每季營運報告/KYEC(2449)_4Q25 Investor update_English.pdf、https://www.kyec.com.tw/Upfiles/EDUp/files/投資人關係/每季營運報告/KYEC(2449)_2Q26 Investor update_English.pdf） | I5: FY2025：中央社 2026-03-06（營收 349.33 億、毛利率 35.84%、營業利益 90.02 億、淨利 110.15 億、EPS 9.01）；3Q26：月營收
A6: 毛利率 | B6: =B5/B4 -> 0.35841757 | C6: =C5/C4 -> 0.39614658 | D6: =D5/D4 -> 0.385 | E6: =E5/E4 -> 0.395 | F6: =F5/F4 -> 0.39295608 | G6: Derived | H6: — | I6: FY2025 35.84%（中央社 2026-03-06）
A7: 折舊攤提（EBITDA − 營業利益） | B7: =SUM(B35:E35) -> 7.5143841 | C7: =SUM(F35:G35) -> 5.2277069 | D7: =q3_da -> 2.95 | E7: =q4_da -> 3.15 | F7: =SUM(C7:E7) -> 11.327707 | G7: Derived／Assumed | H7: 季資料（本頁下方）：公司 Investor update 1Q25–2Q26（https://kyec.com.tw/Upfiles/EDUp/files/關於京元/KYEC(2449TW)_2Q25 Investor update_English.pdf、https://www.kyec.com.tw/Upfiles/EDUp/files/投資人關係/每季營運報告/KYEC(2449)_4Q25 Investor update_English.pdf、https://www.kyec.com.tw/Upfiles/EDUp/files/投資人關係/每季營運報告/KYEC(2449)_2Q26 Investor update_English.pdf） | I7: 公司未直接揭露折舊金額：未找到；以公司 EBITDA 減營業利益推得
A8: 現金營業成本（營收 − 毛利 − 折舊攤提） | B8: =B4-B5-B7 -> 14.8984 | C8: =C4-C5-C7 -> 7.6546 | D8: =D4-D5-D7 -> 4.5174887 | E8: =E4-E5-E7 -> 5.297976 | F8: =SUM(C8:E8) -> 17.470065 | G8: Derived | H8: — | I8: 假設折舊攤提全部在營業成本（部分在營業費用，Assumed）
A9: 營業費用（推銷管理＋研發） | B9: =SUM(B32:E32) -> 3.5197 | C9: =SUM(F32:G32) -> 2.8509 | D9: =D4*q_opx -> 1.5177822 | E9: =E4*q_opx -> 1.7454496 | F9: =SUM(C9:E9) -> 6.1141318 | G9: Verified／Assumed | H9: 季資料（本頁下方）：公司 Investor update 1Q25–2Q26（https://kyec.com.tw/Upfiles/EDUp/files/關於京元/KYEC(2449TW)_2Q25 Investor update_English.pdf、https://www.kyec.com.tw/Upfiles/EDUp/files/投資人關係/每季營運報告/KYEC(2449)_4Q25 Investor update_English.pdf、https://www.kyec.com.tw/Upfiles/EDUp/files/投資人關係/每季營運報告/KYEC(2449)_2Q26 Investor update_English.pdf） | I9: FY2025：中央社 2026-03-06（營收 349.33 億、毛利率 35.84%、營業利益 90.02 億、淨利 110.15 億、EPS 9.01）；3Q26：月營收
A10: 營業利益 | B10: =B5-B9 -> 9.0011159 | C10: =C5-C9 -> 5.6002931 | D10: =D5-D9 -> 3.1569871 | E10: =E5-E9 -> 3.7701711 | F10: =SUM(C10:E10) -> 12.527451 | G10: Derived | H10: 季資料（本頁下方）：公司 Investor update 1Q25–2Q26（https://kyec.com.tw/Upfiles/EDUp/files/關於京元/KYEC(2449TW)_2Q25 Investor update_English.pdf、https://www.kyec.com.tw/Upfiles/EDUp/files/投資人關係/每季營運報告/KYEC(2449)_4Q25 Investor update_English.pdf、https://www.kyec.com.tw/Upfiles/EDUp/files/投資人關係/每季營運報告/KYEC(2449)_2Q26 Investor update_English.pdf） | I10: FY2025 公司 90.02 億（中央社）；1Q26 營益率 27.2%（科技新報 2026-05-11）
A11: 營業利益率 | B11: =B10/B4 -> 0.25766356 | C11: =C10/C4 -> 0.26251169 | D11: =D10/D4 -> 0.26 | E11: =E10/E4 -> 0.27 | F11: =F10/F4 -> 0.26407297 | G11: Derived | H11: — | I11: —
A12: 歸屬母公司淨利 | B12: 11.015 | C12: =2.286+2.492 -> 4.778 | D12: =D10*q_nir -> 2.683439 | E12: =E10*q_nir -> 3.2046454 | F12: =SUM(C12:E12) -> 10.666084 | G12: Verified／Derived（3Q、4Q） | H12: FY2025 110.15 億（中央社 2026-03-06）；1Q26 22.86 億（科技新報 2026-05-11）、2Q26 24.92 億（理財周刊 2026-09-01） | I12: 1H26 47.78 億（理財周刊）
A13: 淨利 ÷ 營業利益 | B13: =B12/B10 -> 1.2237372 | C13: =C12/C10 -> 0.85316964 | D13: =D12/D10 -> 0.85 | E13: =E12/E10 -> 0.85 | F13: =F12/F10 -> 0.85141696 | G13: Derived | H13: — | I13: FY2025 含處分利益
A14: 股數（十億股） | B14: =11.015/9.01 -> 1.2225305 | C14: =4.778/3.91 -> 1.2219949 | D14: =q_sh -> 1.2826471 | E14: =q_sh -> 1.2826471 | F14: =q_sh -> 1.2826471 | G14: Derived | H14: 淨利 ÷ EPS（FY2025、1H26 為配股前） | I14: FY2026 錨點用配股後 12.83 億股（In 頁 q_sh）
A15: EPS | B15: =B12/B14 -> 9.01 | C15: =C12/C14 -> 3.91 | D15: =D12/D14 -> 2.0921102 | E15: =E12/E14 -> 2.4984624 | F15: =F12/F14 -> 8.3156815 | G15: Derived | H15: 淨利 ÷ 股數 | I15: FY2026 以配股後股數計（1H26 追溯後約 3.72）
A16: 公司揭露 EPS（基本） | B16: 9.01 | C16: 3.91 | G16: Verified | H16: 中央社 2026-03-06；公司簡報 1Q26 1.87、2Q26 2.04 | I16: Yahoo 股市、HiStock 同值
A17: 資本支出（現金） | B17: 32.3554 | C17: =6.7858+7.0978 -> 13.8836 | F17: =capex_26 -> 42 | G17: Verified（單一來源）／Derived | H17: https://poorstock.com/earningcall/2449（AI 摘要公司簡報：2023 77.3、2024 148.6、2025 323.6 億；1Q26 67.9、2Q26 71.0 億） | I17: 預算：2025 約 370 億（雅虎 2026-01-27）、2026 年 500 億（工商時報 2026-07-28）
A18: AI 加速器測試營收（＝營收 × AI 占比） | B18: =B4*ai_25 -> 9.60674 | F18: =F4*ai_26 -> 16.603774 | G18: Derived／Interested-party | H18: In 頁 D 節 | I18: 公司未揭露 AI 營收金額：未找到
A19: 非 AI 營收（＝營收 − AI） | B19: =B4-B18 -> 25.32686 | F19: =F4-F18 -> 30.835581 | G19: Derived | H19: — | I19: 伺服器 CPU、手機、消費、車用、工業、網通
A21: 核對（參考）
A22: FY2025 營業利益（季資料推得）− 公司 90.02 億 | B22: =B10-9.002 -> -0.0008841
A23: FY2025 毛利率（季資料推得）− 公司 35.84% | B23: =B6-0.3584 -> 1.7566469e-05
A24: FY2026 營收年增（錨點） | B24: =F4/B4-1 -> 0.35798643
A25: 季資料（公司 Investor update） | B25: 1Q25 | C25: 2Q25 | D25: 3Q25 | E25: 4Q25 | F25: 1Q26 | G25: 2Q26 | H25: 標記 | I25: 來源
A26: 營收 | B26: 7.3155 | C26: 8.3619 | D26: 9.2905 | E26: 9.9657 | F26: 10.1919 | G26: 11.1416 | H26: Verified | I26: 公司簡報（2Q25、4Q25、2Q26 Investor update）；與 HiStock 月營收合計相符
A27: 毛利率 | B27: 0.335 | C27: 0.355 | D27: 0.36 | E27: 0.377 | F27: 0.3974 | G27: 0.395 | H27: Verified | I27: 公司簡報（四捨五入至 0.1%）；1Q26 39.74%（科技新報 2026-05-11）
A28: 推銷及管理費用 | B28: 0.6851 | C28: 0.5833 | D28: 0.6369 | E28: 0.6841 | F28: 0.9713 | G28: 1.2573 | H28: Verified | I28: 公司簡報
A29: 研發費用 | B29: 0.2426 | C29: 0.2121 | D29: 0.2178 | E29: 0.2578 | F29: 0.3073 | G29: 0.315 | H29: Verified | I29: 公司簡報
A30: EBITDA | B30: 3.1729 | C30: 3.9445 | D30: 4.396 | E30: 5.0021 | F30: 5.2584 | G30: 5.5696 | H30: Verified | I30: 公司簡報（定義未載明；本模型視為營業利益＋折舊攤提）
A31: 毛利（營收 × 毛利率） | B31: =B26*B27 -> 2.4506925 | C31: =C26*C27 -> 2.9684745 | D31: =D26*D27 -> 3.34458 | E31: =E26*E27 -> 3.7570689 | F31: =F26*F27 -> 4.0502611 | G31: =G26*G27 -> 4.400932 | H31: Derived
A32: 營業費用（推銷管理＋研發） | B32: =B28+B29 -> 0.9277 | C32: =C28+C29 -> 0.7954 | D32: =D28+D29 -> 0.8547 | E32: =E28+E29 -> 0.9419 | F32: =F28+F29 -> 1.2786 | G32: =G28+G29 -> 1.5723 | H32: Derived
A33: 營業利益（毛利 − 營業費用） | B33: =B31-B32 -> 1.5229925 | C33: =C31-C32 -> 2.1730745 | D33: =D31-D32 -> 2.48988 | E33: =E31-E32 -> 2.8151689 | F33: =F31-F32 -> 2.7716611 | G33: =G31-G32 -> 2.828632 | H33: Derived
A34: 營業利益率 | B34: =B33/B26 -> 0.20818707 | C34: =C33/C26 -> 0.25987808 | D34: =D33/D26 -> 0.2680028 | E34: =E33/E26 -> 0.28248582 | F34: =F33/F26 -> 0.27194743 | G34: =G33/G26 -> 0.25388023 | H34: Derived
A35: 折舊攤提（EBITDA − 營業利益） | B35: =B30-B33 -> 1.6499075 | C35: =C30-C33 -> 1.7714255 | D35: =D30-D33 -> 1.90612 | E35: =E30-E33 -> 2.1869311 | F35: =F30-F33 -> 2.4867389 | G35: =G30-G33 -> 2.740968 | H35: Derived
A36: 現金營業成本（營收 − 毛利 − 折舊攤提） | B36: =B26-B31-B35 -> 3.2149 | C36: =C26-C31-C35 -> 3.622 | D36: =D26-D31-D35 -> 4.0398 | E36: =E26-E31-E35 -> 4.0217 | F36: =F26-F31-F35 -> 3.6549 | G36: =G26-G31-G35 -> 3.9997 | H36: Derived
A37: EPS（基本，公司揭露） | B37: 3.51 | C37: 1.78 | D37: 1.88 | E37: 1.84 | F37: 1.87 | G37: 2.04 | H37: Verified | I37: 公司簡報；Yahoo 股市、HiStock 同值；1Q25 含處分利益
A38: 現金營業成本季增 ÷ 營收季增（2Q25→2Q26；In 頁 v_cc 的參考） | B38: =(G36-C36)/(G26-C26) -> 0.13587797 | H38: Derived | I38: 同季比較排除季節性；斜率小代表現金成本多為固定（人力、電力基本量）

Sheet Units
A1: Units — 加速器顆數（tsmc 成品）× 每顆測試時間（含 burn-in）× 京元電曝險 → 加權顆數；FY2026 以 AI 占比校準每加權顆營收。情境 A；FY(t)＝CY(t)
A3: 項目 | B3: 單位 | C3: CY2026 | D3: CY2027 | E3: CY2028 | F3: CY2029 | G3: 說明
A4: 加速器顆數合計（未加權） | B4: 百萬顆 | C4: =PL!D71 -> 15.2 | D4: =PL!E71 -> 23.7 | E4: =PL!F71 -> 26.5 | F4: =PL!G71 -> 30.15 | G4: 讀台積電模型 In 頁（與 HBM、Advantest 同一份）
A5: NVIDIA Blackwell：加權顆數 | B5: 百萬顆 | C5: =PL!D63 -> 5.4 | D5: =PL!E63 -> 2.4 | E5: =PL!F63 -> 0.5 | F5: =PL!G63 -> 0.25 | G5: 顆數 × 測試時間係數
A6: NVIDIA Rubin：加權顆數 | B6: 百萬顆 | C6: =PL!D64 -> 2.55 | D6: =PL!E64 -> 10.5 | E6: =PL!F64 -> 10.5 | F6: =PL!G64 -> 12.075 | G6: 顆數 × 測試時間係數
A7: NVIDIA Rubin Ultra：加權顆數 | B7: 百萬顆 | C7: =PL!D65 -> 0 | D7: =PL!E65 -> 0.6 | E7: =PL!F65 -> 4 | F7: =PL!G65 -> 4.6 | G7: 顆數 × 測試時間係數
A8: NVIDIA Hopper：加權顆數 | B8: 百萬顆 | C8: =PL!D66 -> 0.3 | D8: =PL!E66 -> 0 | E8: =PL!F66 -> 0 | F8: =PL!G66 -> 0 | G8: 顆數 × 測試時間係數
A9: AMD Instinct：加權顆數 | B9: 百萬顆 | C9: =PL!D67 -> 0.165 | D9: =PL!E67 -> 0.33 | E9: =PL!F67 -> 0.44 | F9: =PL!G67 -> 0.506 | G9: 顆數 × 測試時間係數 × 曝險
A10: Google TPU：加權顆數 | B10: 百萬顆 | C10: =PL!D68 -> 1.7325 | D10: =PL!E68 -> 2.475 | E10: =PL!F68 -> 3.15 | F10: =PL!G68 -> 3.6225 | G10: 顆數 × 測試時間係數 × 曝險
A11: AWS Trainium：加權顆數 | B11: 百萬顆 | C11: =PL!D69 -> 0.64 | D11: =PL!E69 -> 0.8 | E11: =PL!F69 -> 0.96 | F11: =PL!G69 -> 1.104 | G11: 顆數 × 測試時間係數 × 曝險
A12: 其他 ASIC（MTIA、Maia 等）：加權顆數 | B12: 百萬顆 | C12: =PL!D70 -> 0.28 | D12: =PL!E70 -> 1.26 | E12: =PL!F70 -> 1.4 | F12: =PL!G70 -> 1.61 | G12: 顆數 × 測試時間係數 × 曝險
A13: 加權顆數合計（Blackwell 等值） | B13: 百萬顆 | C13: =PL!D74 -> 11.0675 | D13: =PL!E74 -> 18.365 | E13: =PL!F74 -> 20.95 | F13: =PL!G74 -> 23.7675
A14: NVIDIA ÷ 加權顆數 | B14: % | C14: =PL!D84 -> 0.7454258 | D14: =PL!E84 -> 0.73509393 | E14: =PL!F84 -> 0.71599045 | F14: =PL!G84 -> 0.71210687 | G14: 公司：GPU 為較大的營收來源（富果 2025-11-28 法說摘要）
A15: 京元電 AI 加速器測試營收 | B15: US$B | C15: =PL!D79/fx -> 0.51886794 | D15: =PL!E79/fx -> 0.80158194 | E15: =PL!F79/fx -> 0.86746187 | F15: =PL!G79/fx -> 0.95270167
A16: 每顆 Blackwell 等值的京元電 AI 測試營收 | B16: US$／顆 | C16: =PL!D85 -> 46.882127 | D16: =PL!E85 -> 43.64726 | E16: =PL!F85 -> 41.406295 | F16: =PL!G85 -> 40.084219 | G16: FY2026 校準；之後 × 份額 × 單價
A17: 每顆加速器（未加權）的京元電 AI 測試營收 | B17: US$／顆 | C17: =PL!D79/fx/PL!D71*1000 -> 34.136049 | D17: =PL!E79/fx/PL!E71*1000 -> 33.822023 | E17: =PL!F79/fx/PL!F71*1000 -> 32.73441 | F17: =PL!G79/fx/PL!G71*1000 -> 31.598729 | G17: 世代組合升級使每顆金額上升
A18: 資本支出 | B18: NT$B | C18: =PL!D88 -> 42 | D18: =PL!E88 -> 51.562093 | E18: =PL!F88 -> 22.640712 | F18: =PL!G88 -> 23.275723
A19: 資本支出 ÷ 加權顆數增量 | B19: NT$／顆 | C19: ="—" -> — | D19: =IFERROR(PL!E88/(PL!E74-PL!D74)*1000,"—") -> 7065.7202 | E19: =IFERROR(PL!F88/(PL!F74-PL!E74)*1000,"—") -> 8758.496 | F19: =IFERROR(PL!G88/(PL!G74-PL!F74)*1000,"—") -> 8261.1263 | G19: 顆數下修（增量為負）時數值無意義
A20: 折舊攤提 ÷ 營收 | B20: % | C20: =PL!D91 -> 0.23878291 | D20: =PL!E91 -> 0.2642992 | E20: =PL!F91 -> 0.29659086 | F20: =PL!G91 -> 0.29960364 | G20: 毛利率的主要變數
A22: 讀法：加權顆數的絕對水準與曝險只影響 FY2026 校準出的每加權顆營收，不影響 FY2026 營收；影響成長的是世代組合（Rubin、Rubin Ultra 的測試時間與 burn-in）、ASIC 曝險、份額相對值與單價。京元電的份額無法單獨識別（公司不揭露客戶別營收），以「每顆 Blackwell 等值營收」與份額相對值表示。

Sheet PL
A1: PL — 京元電損益（十億新台幣；EPS 新台幣；歸屬母公司）。FY2025A 實績、FY2026 錨點（1H26 實績＋3Q26 營收實績＋假設），FY2027 起為模型。FY(t)＝CY(t)。三情境各一個完整推導區塊（本頁下方），頂端為摘要。FY2026–FY2027 三情境相同（顆數係數從 CY2028 開始）
A3: 情境／項目 | B3: 單位 | C3: FY2025A | D3: FY2026（錨點） | E3: FY2027 | F3: FY2028 | G3: FY2029 | H3: FY2030（收斂） | I3: FY2031（收斂） | J3: FY2032（收斂） | K3: 說明
A4: 情境 A
A5: 營收 | B5: NT$B | C5: =C81 -> 34.9336 | D5: =D81 -> 47.439355 | E5: =E81 -> 60.186472 | F5: =F81 -> 64.71214 | G5: =G81 -> 69.287481 | H5: =H216 -> 73.939119 | I5: =I216 -> 78.639255 | J5: =J216 -> 83.357611
A6: 營收年增 | B6: % | D6: =D82 -> 0.35798643 | E6: =E82 -> 0.26870343 | F6: =F82 -> 0.075194098 | G6: =G82 -> 0.070702984 | H6: =H215 -> 0.067135323 | I6: =I215 -> 0.063567661 | J6: =J215 -> 0.06
A7: AI 加速器測試營收 | B7: NT$B | C7: =C79 -> 9.60674 | D7: =D79 -> 16.603774 | E7: =E79 -> 25.650622 | F7: =F79 -> 27.75878 | G7: =G79 -> 30.486453
A8: 非 AI 營收 | B8: NT$B | C8: =C80 -> 25.32686 | D8: =D80 -> 30.835581 | E8: =E80 -> 34.53585 | F8: =F80 -> 36.95336 | G8: =G80 -> 38.801028
A9: 資本支出 | B9: NT$B | C9: =C88 -> 32.3554 | D9: =D88 -> 42 | E9: =E88 -> 51.562093 | F9: =F88 -> 22.640712 | G9: =G88 -> 23.275723
A10: 折舊攤提 ÷ 營收 | B10: % | C10: =C91 -> 0.21510477 | D10: =D91 -> 0.23878291 | E10: =E91 -> 0.2642992 | F10: =F91 -> 0.29659086 | G10: =G91 -> 0.29960364
A11: 毛利率 | B11: % | C11: =C97 -> 0.35841757 | D11: =D97 -> 0.39295608 | E11: =E97 -> 0.40133688 | F11: =F97 -> 0.37648524 | G11: =G97 -> 0.3805608
A12: 營業利益率 | B12: % | C12: =C101 -> 0.25766356 | D12: =D101 -> 0.26407297 | E12: =E101 -> 0.28337242 | F12: =F101 -> 0.26182074 | G12: =G101 -> 0.26892501
A13: 淨利率 | B13: % | C13: =C104/C81 -> 0.31531248 | D13: =D104/D81 -> 0.2248362 | E13: =E104/E81 -> 0.23803283 | F13: =F104/F81 -> 0.21992942 | G13: =G104/G81 -> 0.22589701 | H13: =H217 -> 0.22589701 | I13: =I217 -> 0.22589701 | J13: =J217 -> 0.22589701
A14: 歸屬母公司淨利 | B14: NT$B | C14: =C104 -> 11.015 | D14: =D104 -> 10.666084 | E14: =E104 -> 14.326356 | F14: =F104 -> 14.232103 | G14: =G104 -> 15.651835 | H14: =H218 -> 16.702626 | I14: =I218 -> 17.764372 | J14: =J218 -> 18.830235
A15: EPS | B15: NT$ | C15: =C107 -> 9.01 | D15: =D107 -> 8.3156815 | E15: =E107 -> 11.169367 | F15: =F107 -> 11.095884 | G15: =G107 -> 12.20276 | H15: =H220 -> 13.021997 | I15: =I220 -> 13.849774 | J15: =J220 -> 14.680761
A16: EPS 年增 | B16: % | D16: =D108 -> -0.077060873 | E16: =E108 -> 0.34316922 | F16: =F108 -> -0.0065789932 | G16: =G108 -> 0.099755544 | H16: =H15/G15-1 -> 0.067135323 | I16: =I15/H15-1 -> 0.063567661 | J16: =J15/I15-1 -> 0.06
A18: 情境 B
A19: 營收 | B19: NT$B | C19: =C132 -> 34.9336 | D19: =D132 -> 47.439355 | E19: =E132 -> 60.186472 | F19: =F132 -> 59.160384 | G19: =G132 -> 64.714513 | H19: =H225 -> 69.62775 | I19: =I225 -> 73.663434 | J19: =J225 -> 76.609972
A20: 營收年增 | B20: % | D20: =D133 -> 0.35798643 | E20: =E133 -> 0.26870343 | F20: =F133 -> -0.01704849 | G20: =G133 -> 0.093882579 | H20: =H224 -> 0.075921719 | I20: =I224 -> 0.05796086 | J20: =J224 -> 0.04
A21: AI 加速器測試營收 | B21: NT$B | C21: =C130 -> 9.60674 | D21: =D130 -> 16.603774 | E21: =E130 -> 25.650622 | F21: =F130 -> 22.207024 | G21: =G130 -> 25.913485
A22: 非 AI 營收 | B22: NT$B | C22: =C131 -> 25.32686 | D22: =D131 -> 30.835581 | E22: =E131 -> 34.53585 | F22: =F131 -> 36.95336 | G22: =G131 -> 38.801028
A23: 資本支出 | B23: NT$B | C23: =C139 -> 32.3554 | D23: =D139 -> 42 | E23: =E139 -> 51.562093 | F23: =F139 -> 5.9160384 | G23: =G139 -> 26.315482
A24: 折舊攤提 ÷ 營收 | B24: % | C24: =C142 -> 0.21510477 | D24: =D142 -> 0.23878291 | E24: =E142 -> 0.2642992 | F24: =F142 -> 0.30887515 | G24: =G142 -> 0.29564075
A25: 毛利率 | B25: % | C25: =C148 -> 0.35841757 | D25: =D148 -> 0.39295608 | E25: =E148 -> 0.40133688 | F25: =F148 -> 0.35307213 | G25: =G148 -> 0.3767995
A26: 營業利益率 | B26: % | C26: =C152 -> 0.25766356 | D26: =D152 -> 0.26407297 | E26: =E152 -> 0.28337242 | F26: =F152 -> 0.23306167 | G26: =G152 -> 0.260909
A27: 淨利率 | B27: % | C27: =C155/C132 -> 0.31531248 | D27: =D155/D132 -> 0.2248362 | E27: =E155/E132 -> 0.23803283 | F27: =F155/F132 -> 0.1957718 | G27: =G155/G132 -> 0.21916356 | H27: =H226 -> 0.21185811 | I27: =I226 -> 0.20455266 | J27: =J226 -> 0.19724721
A28: 歸屬母公司淨利 | B28: NT$B | C28: =C155 -> 11.015 | D28: =D155 -> 10.666084 | E28: =E155 -> 14.326356 | F28: =F155 -> 11.581935 | G28: =G155 -> 14.183063 | H28: =H227 -> 14.751204 | I28: =I227 -> 15.068051 | J28: =J227 -> 15.111103
A29: EPS | B29: NT$ | C29: =C158 -> 9.01 | D29: =D158 -> 8.3156815 | E29: =E158 -> 11.169367 | F29: =F158 -> 9.0297131 | G29: =G158 -> 11.057651 | H29: =H229 -> 11.500594 | I29: =I229 -> 11.747621 | J29: =J229 -> 11.781186
A30: EPS 年增 | B30: % | D30: =D159 -> -0.077060873 | E30: =E159 -> 0.34316922 | F30: =F159 -> -0.19156451 | G30: =G159 -> 0.22458495 | H30: =H29/G29-1 -> 0.040057662 | I30: =I29/H29-1 -> 0.021479451 | J30: =J29/I29-1 -> 0.0028571429
A32: 情境 C
A33: 營收 | B33: NT$B | C33: =C183 -> 34.9336 | D33: =D183 -> 47.439355 | E33: =E183 -> 60.186472 | F33: =F183 -> 53.608628 | G33: =G183 -> 57.0929 | H33: =H234 -> 59.94734 | I33: =I234 -> 62.045389 | J33: =J234 -> 63.286297
A34: 營收年增 | B34: % | D34: =D184 -> 0.35798643 | E34: =E184 -> 0.26870343 | F34: =F184 -> -0.10929108 | G34: =G184 -> 0.064994613 | H34: =H233 -> 0.049996409 | I34: =I233 -> 0.034998204 | J34: =J233 -> 0.02
A35: AI 加速器測試營收 | B35: NT$B | C35: =C181 -> 9.60674 | D35: =D181 -> 16.603774 | E35: =E181 -> 25.650622 | F35: =F181 -> 16.655268 | G35: =G181 -> 18.291872
A36: 非 AI 營收 | B36: NT$B | C36: =C182 -> 25.32686 | D36: =D182 -> 30.835581 | E36: =E182 -> 34.53585 | F36: =F182 -> 36.95336 | G36: =G182 -> 38.801028
A37: 資本支出 | B37: NT$B | C37: =C190 -> 32.3554 | D37: =D190 -> 42 | E37: =E190 -> 51.562093 | F37: =F190 -> 5.3608628 | G37: =G190 -> 18.158046
A38: 折舊攤提 ÷ 營收 | B38: % | C38: =C193 -> 0.21510477 | D38: =D193 -> 0.23878291 | E38: =E193 -> 0.2642992 | F38: =F193 -> 0.34029294 | G38: =G193 -> 0.32620598
A39: 毛利率 | B39: % | C39: =C199 -> 0.35841757 | D39: =D199 -> 0.39295608 | E39: =E199 -> 0.40133688 | F39: =F199 -> 0.30822048 | G39: =G199 -> 0.33061089
A40: 營業利益率 | B40: % | C40: =C203 -> 0.25766356 | D40: =D203 -> 0.26407297 | E40: =E203 -> 0.28337242 | F40: =F203 -> 0.17578164 | G40: =G203 -> 0.20140504
A41: 淨利率 | B41: % | C41: =C206/C183 -> 0.31531248 | D41: =D206/D183 -> 0.2248362 | E41: =E206/E183 -> 0.23803283 | F41: =F206/F183 -> 0.14765657 | G41: =G206/G183 -> 0.16918024 | H41: =H235 -> 0.15790155 | I41: =I235 -> 0.14662287 | J41: =J235 -> 0.13534419
A42: 歸屬母公司淨利 | B42: NT$B | C42: =C206 -> 11.015 | D42: =D206 -> 10.666084 | E42: =E206 -> 14.326356 | F42: =F206 -> 7.9156664 | G42: =G206 -> 9.6589903 | H42: =H236 -> 9.4657781 | I42: =I236 -> 9.0972731 | J42: =J236 -> 8.5654325
A43: EPS | B43: NT$ | C43: =C209 -> 9.01 | D43: =D209 -> 8.3156815 | E43: =E209 -> 11.169367 | F43: =F209 -> 6.1713519 | G43: =G209 -> 7.5305129 | H43: =H238 -> 7.3798774 | I43: =I238 -> 7.0925771 | J43: =J238 -> 6.6779341
...

Sheet Val
A1: Val — P/E 估值（新台幣）。結論用「現價 ÷ FY2027、FY2028 EPS（模型）」與十年 P/E 規則值（年底落後 P/E，基準為各情境 FY2027 EPS）。本版未做先驗，無 Andy 合理 P/E 對照
A2: 循環位置：京元電是測試代工，不是設備股，不套設備市場見頂年；以本模型營收最高的會計年度為見頂年（比照 NVIDIA、台達電、台光電；FY(t)＝CY(t)）。營收到 FY2029 仍在增加時，見頂年未知，判為中段
A4: 0. 目標價
A5: 0.1 DCF（股東權益現金流，FY2027–FY2032 明確期＋FY2032 後永續）
A6: 項目 | B6: A（順利） | C6: B（平平） | D6: C（不如預期） | E6: 說明
A7: 情境 EPS（FY2027–FY2032） | E7: PL 頁各情境；FY2030 起為收斂法（PL 頁灰底）
A8: FY2027 | B8: =PL!E15 -> 11.169367 | C8: =PL!E29 -> 11.169367 | D8: =PL!E43 -> 11.169367
A9: FY2028 | B9: =PL!F15 -> 11.095884 | C9: =PL!F29 -> 9.0297131 | D9: =PL!F43 -> 6.1713519
A10: FY2029 | B10: =PL!G15 -> 12.20276 | C10: =PL!G29 -> 11.057651 | D10: =PL!G43 -> 7.5305129
A11: FY2030 | B11: =PL!H15 -> 13.021997 | C11: =PL!H29 -> 11.500594 | D11: =PL!H43 -> 7.3798774
A12: FY2031 | B12: =PL!I15 -> 13.849774 | C12: =PL!I29 -> 11.747621 | D12: =PL!I43 -> 7.0925771
A13: FY2032 | B13: =PL!J15 -> 14.680761 | C13: =PL!J29 -> 11.781186 | D13: =PL!J43 -> 6.6779341
A14: 股東現金流＝EPS ×（1 − tp_g ÷ tp_roe）
A15: 再投資率（tp_g ÷ tp_roe，上限 0.8） | B15: =IF(tp_roe<=tp_g,0.8,MIN(tp_g/tp_roe,0.8)) -> 0.21641118 | E15: ROE＝In 頁 tp_roe；tp_roe ≤ tp_g 時取上限 0.8
A16: FY2027 | B16: =B8*(1-$B$15) -> 8.7521915 | C16: =C8*(1-$B$15) -> 8.7521915 | D16: =D8*(1-$B$15) -> 8.7521915
A17: FY2028 | B17: =B9*(1-$B$15) -> 8.6946109 | C17: =C9*(1-$B$15) -> 7.0755822 | D17: =D9*(1-$B$15) -> 4.8358023
A18: FY2029 | B18: =B10*(1-$B$15) -> 9.5619465 | C18: =C10*(1-$B$15) -> 8.6646515 | D18: =D10*(1-$B$15) -> 5.9008257
A19: FY2030 | B19: =B11*(1-$B$15) -> 10.203891 | C19: =C11*(1-$B$15) -> 9.0117372 | D19: =D11*(1-$B$15) -> 5.7827894
A20: FY2031 | B20: =B12*(1-$B$15) -> 10.852528 | C20: =C12*(1-$B$15) -> 9.2053044 | D20: =D12*(1-$B$15) -> 5.5576641
A21: FY2032 | B21: =B13*(1-$B$15) -> 11.50368 | C21: =C13*(1-$B$15) -> 9.2316053 | D21: =D13*(1-$B$15) -> 5.2327545
A22: DCF 情境每股價值（折現率 tp_r） | B22: =SUMPRODUCT(B16:B21,1/(1+tp_r)^{1;2;3;4;5;6})+B21*(1+tp_g)/(tp_r-tp_g)/(1+tp_r)^6 -> 155.08216 | C22: =SUMPRODUCT(C16:C21,1/(1+tp_r)^{1;2;3;4;5;6})+C21*(1+tp_g)/(tp_r-tp_g)/(1+tp_r)^6 -> 127.71992 | D22: =SUMPRODUCT(D16:D21,1/(1+tp_r)^{1;2;3;4;5;6})+D21*(1+tp_g)/(tp_r-tp_g)/(1+tp_r)^6 -> 77.939189 | E22: Σ 明確期現金流 ÷ (1＋r)^t ＋ 永續價值 ÷ (1＋r)^6；永續價值＝FY2032 現金流 ×(1＋g)÷(r−g)；基準日 2026 年底，t＝1 對 FY2027
A23: DCF 情境價值推到 12 個月後（×(1＋tp_r)） | B23: =B22*(1+tp_r) -> 170.59038 | C23: =C22*(1+tp_r) -> 140.49192 | D23: =D22*(1+tp_r) -> 85.733108
A24: DCF 目標價（情境加權） | B24: =tp_wA*B23+tp_wB*C23+tp_wC*D23 -> 138.56969 | E24: Σ 權重 × 情境價值 ×(1＋r)；權重見 In 頁
A26: 0.2 Comparable（市場主流同業前瞻 P/E）
A27: 同業與前瞻 P/E | B27: 代號 | C27: 前瞻 12 月 P/E | D27: 日期 | E27: 來源 | F27: 標記
A28: 日月光投控（ASE Technology） | B28: ASX／3711.TW | C28: 27.37 | D28: 2026-10-23 | E28: stockanalysis forward PE（ASX；分析師共識） | F28: Interested-party
A29: Amkor Technology | B29: AMKR | C29: 14.02 | D29: 2026-10-23 | E29: stockanalysis forward PE（分析師共識） | F29: Interested-party
A30: 力成（Powertech） | B30: 6239.TW | C30: 20.6 | D30: 2026-10-02 | E30: stockanalysis forward PE（頁面價格日期較舊） | F30: Interested-party
A31: 矽格（Sigurd） | B31: 6257.TW | C31: 23.3 | D31: 2026-10-02 | E31: stockanalysis forward PE（頁面價格日期較舊） | F31: Interested-party
A32: 南茂（ChipMOS） | B32: IMOS／8150.TW | C32: 22.08 | D32: 2026-10-08 | E32: stockanalysis forward PE（IMOS；頁面價格日期較舊） | F32: Interested-party
A33: 同業前瞻 P/E 中位數 | B33: =MEDIAN(C28:C32) -> 22.08 | E33: 台美封測同業（不放 A 股：長電、通富等 A 股同業有結構性溢價；工作單 Andy 11:53）
A34: 12 個月後的前瞻 EPS（情境加權） | B34: =tp_wA*(2/12*B8+10/12*B9)+tp_wB*(2/12*C8+10/12*C9)+tp_wC*(2/12*D8+10/12*D9) -> 9.4264714 | E34: 約 2027-10 時的未來 12 月 EPS ≈ 2／12 × FY2027＋10／12 × FY2028（會計年度＝日曆年；配股後股數）
A35: Comparable 目標價 | B35: =B33*B34 -> 208.13649 | E35: 同業中位數 × 前瞻 EPS
A37: 0.3 結論
A38: 項目 | B38: 數值 | E38: 說明
A39: 目標價（DCF 與 Comparable 加權） | B39: =tp_w_dcf*B24+(1-tp_w_dcf)*B35 -> 173.35309 | E39: tp_w_dcf × DCF＋（1 − tp_w_dcf）× Comparable；tp_w_dcf 見 In 頁
A40: Comparable 目標價（市場主流同業法） | B40: =B35 -> 208.13649
A41: 市場共識目標價 | B41: =cons_tp -> 340.73 | E41: stockanalysis：15 位分析師平均 340.73（頁面價格日期 2026-10-06）；法人中位數 348–350、Morgan Stanley 388
A42: 上檔空間：加權目標價 | B42: =B39/px-1 -> -0.33960727 | E42: 現價＝In 頁 px
A43: 上檔空間：Comparable 目標價 | B43: =B40/px-1 -> -0.20709909
...

Sheet Recon
A1: Recon — 本模型 vs 共識、券商估計與公司揭露的結構數字。只作事後對照，不為對上數字而調參數。共識為 FactSet（2026-04-06，經鉅亨網）與媒體轉述的法人估計
A3: 項目 | B3: 對照值 | C3: 模型 A | D3: 差距 A | E3: 模型 B | F3: 差距 B | G3: 模型 C | H3: 差距 C | I3: 對照來源 | J3: 說明
A4: A. 共識與法人估計（校準未使用）
A5: FY2026 營收 vs 法人（近 500 億） | B5: =c_rev26 -> 49.25 | C5: =PL!D81 -> 47.439355 | D5: =C5/B5-1 -> -0.036764372 | E5: =PL!D132 -> 47.439355 | F5: =E5/B5-1 -> -0.036764372 | G5: =PL!D183 -> 47.439355 | H5: =G5/B5-1 -> -0.036764372 | I5: 理財周刊 2026-09-01 | J5: 模型 4Q 季增 15%；法人約 20%
A6: 4Q26 營收 vs 法人估計 | B6: =c_q4rev -> 14.559 | C6: =Q!E4 -> 13.963597 | D6: =C6/B6-1 -> -0.040895893 | E6: =Q!E4 -> 13.963597 | F6: =E6/B6-1 -> -0.040895893 | G6: =Q!E4 -> 13.963597 | H6: =G6/B6-1 -> -0.040895893 | I6: 優分析 2026-09-18
A7: FY2026 EPS vs FactSet 中位數（04-06） | B7: =c_eps26 -> 9.9 | C7: =PL!D107 -> 8.3156815 | D7: =C7/B7-1 -> -0.16003217 | E7: =PL!D158 -> 8.3156815 | F7: =E7/B7-1 -> -0.16003217 | G7: =PL!D209 -> 8.3156815 | H7: =G7/B7-1 -> -0.16003217 | I7: FactSet（鉅亨網） | J7: 模型以配股後股數計；下一列換回配股前口徑
A8: FY2026 EPS（× 1.05，配股前口徑）vs FactSet 中位數 | B8: =c_eps26 -> 9.9 | C8: =PL!D107*1.05 -> 8.7314656 | D8: =C8/B8-1 -> -0.11803378 | E8: =PL!D158*1.05 -> 8.7314656 | F8: =E8/B8-1 -> -0.11803378 | G8: =PL!D209*1.05 -> 8.7314656 | H8: =G8/B8-1 -> -0.11803378 | I8: 同上 | J8: 共識的股數口徑未載明（推定為配股前）
A9: FY2026 EPS（× 1.05）vs 法人中位數區間中點（09-01） | B9: =c_eps26b -> 9.44 | C9: =PL!D107*1.05 -> 8.7314656 | D9: =C9/B9-1 -> -0.075056609 | E9: =PL!D158*1.05 -> 8.7314656 | F9: =E9/B9-1 -> -0.075056609 | G9: =PL!D209*1.05 -> 8.7314656 | H9: =G9/B9-1 -> -0.075056609 | I9: 理財周刊 2026-09-01 | J9: 3Q Rubin 延後後的估計
A10: FY2027 EPS vs FactSet 中位數（04-06） | B10: =c_eps27 -> 14.4 | C10: =PL!E107 -> 11.169367 | D10: =C10/B10-1 -> -0.22434948 | E10: =PL!E158 -> 11.169367 | F10: =E10/B10-1 -> -0.22434948 | G10: =PL!E209 -> 11.169367 | H10: =G10/B10-1 -> -0.22434948 | I10: FactSet（鉅亨網）
A11: FY2027 EPS（× 1.05）vs FactSet 中位數 | B11: =c_eps27 -> 14.4 | C11: =PL!E107*1.05 -> 11.727836 | D11: =C11/B11-1 -> -0.18556695 | E11: =PL!E158*1.05 -> 11.727836 | F11: =E11/B11-1 -> -0.18556695 | G11: =PL!E209*1.05 -> 11.727836 | H11: =G11/B11-1 -> -0.18556695 | I11: 同上 | J11: 高 16.05、低 13.35
A12: FY2028 EPS（× 1.05）vs FactSet 中位數 | B12: =c_eps28 -> 17.72 | C12: =PL!F107*1.05 -> 11.650678 | D12: =C12/B12-1 -> -0.3425125 | E12: =PL!F158*1.05 -> 9.4811988 | F12: =E12/B12-1 -> -0.46494364 | G12: =PL!F209*1.05 -> 6.4799195 | H12: =G12/B12-1 -> -0.63431606 | I12: 同上 | J12: 高 18.77、低 16.67
A13: 目標價（DCF 與 Comparable 加權，Val 第 0 節）vs Morgan Stanley 目標價 | B13: =ms_tp -> 388 | C13: =tp_final -> 173.35309 | D13: =C13/B13-1 -> -0.55321368 | E13: =tp_final -> 173.35309 | F13: =E13/B13-1 -> -0.55321368 | G13: =tp_final -> 173.35309 | H13: =G13/B13-1 -> -0.55321368 | I13: Morgan Stanley 2026-06-23 | J13: 三情境同一個加權目標價；券商目標價多以 25–30 倍前瞻 P/E 計
A14: B. 結構與機制檢查
A15: FY2026 Google TPU 測試 ÷ 營收 vs Morgan Stanley Google 相關 10% | B15: =ms_goog -> 0.1 | C15: =PL!D68/PL!D74*PL!D79/PL!D81 -> 0.054788796 | D15: =C15-B15 -> -0.045211204 | E15: =PL!D119/PL!D125*PL!D130/PL!D132 -> 0.054788796 | F15: =E15-B15 -> -0.045211204 | G15: =PL!D170/PL!D176*PL!D181/PL!D183 -> 0.054788796 | H15: =G15-B15 -> -0.045211204 | I15: Morgan Stanley 2026-06-23 | J15: 對照值含 Google CPU、晶圓測試，口徑較寬；模型應低於對照值
A16: FY2026 AI 加速器測試占比 vs 公司 2Q26 資料處理應用占比 | B16: =dp_26 -> 0.363 | C16: =PL!D83 -> 0.35 | D16: =C16-B16 -> -0.013 | E16: =PL!D134 -> 0.35 | F16: =E16-B16 -> -0.013 | G16: =PL!D185 -> 0.35 | H16: =G16-B16 -> -0.013 | I16: poorstock 摘要公司簡報 | J16: 資料處理含 AI GPU、ASIC 與 CPU；AI 占比應不高於此值
A17: FY2026 折舊公式回測（同一公式 − 錨點，NT$B） | C17: =PL!D92 -> -0.099495045 | E17: =PL!D143 -> -0.099495045 | G17: =PL!D194 -> -0.099495045 | I17: Q 頁、In 頁 dr、ret | J17: 接近 0 表示折舊率與到期比例和 FY2025–26 一致（校準檢查）
A18: FY2026 資本支出：公式值（維持性＋κ × FY2026 營收增量）vs 輸入 capex_26 | B18: =capex_26 -> 42 | C18: =m_cx*PL!D81+PL!C87*MAX(0,PL!D81-PL!C81) -> 49.42503 | D18: =C18/B18-1 -> 0.17678643 | E18: =m_cx*PL!D132+PL!C138*MAX(0,PL!D132-PL!C132) -> 49.42503 | F18: =E18/B18-1 -> 0.17678643 | G18: =m_cx*PL!D183+PL!C189*MAX(0,PL!D183-PL!C183) -> 49.42503 | H18: =G18/B18-1 -> 0.17678643 | I18: In 頁 capex_26（公司預算 500 億的現金口徑） | J18: 公式值接近預算 500 億、高於現金口徑輸入；差距反映預算與現金支出的時間差
A19: FY2027 每顆 Blackwell 等值 AI 測試營收（US$） | C19: =PL!E85 -> 43.64726 | E19: =PL!E136 -> 43.64726 | G19: =PL!E187 -> 43.64726 | I19: —
A20: FY2027 資本支出 ÷ 營收 | C20: =PL!E89 -> 0.85670569 | E20: =PL!E140 -> 0.85670569 | G20: =PL!E191 -> 0.85670569 | I20: — | J20: FY2025 92.6%、FY2026 預算約 105%（現金基準約 88%）
A21: FY2028 折舊攤提 ÷ 營收 | C21: =PL!F91 -> 0.29659086 | E21: =PL!F142 -> 0.30887515 | G21: =PL!F193 -> 0.34029294 | I21: — | J21: FY2025 21.5%
A22: FY2028 EBITDA − 資本支出（NT$B） | C22: =PL!F103 -> 13.495297 | E22: =PL!F154 -> 26.145152 | G22: =PL!F205 -> 22.305187 | I22: — | J22: 負值＝擴產仍需外部資金
A23: Burn-in 占營收（3Q25，公司法說） | B23: =bi_25 -> 0.09 | C23: =bi_25 -> 0.09 | E23: =bi_25 -> 0.09 | G23: =bi_25 -> 0.09 | I23: 富果 2025-11-28（AI 摘要） | J23: 本模型未拆 burn-in；Rubin 世代的 burn-in 加長含在測試時間係數內
A24: C. 預留
A25: 3Q26 財報（約 11 月上旬）：更新 Q 頁 3Q 毛利率、折舊、營業費用與淨利，並檢查 4Q 季增假設 | J25: 預留列：本版無數值
A26: R4 產業部署路徑（markets/deploy_path/，尚未建立）：上線後以部署路徑取代顆數輸入 | J26: 預留列：本版無數值

Sheet Sens
A1: Sens — 一次動一個輸入（情境 A；每加權顆營收、固定現金成本、κ 在每個案例內依 FY2026 錨點重算，FY2026 恆等於錨點）：對 FY2027、FY2028 的營收、AI 測試營收、毛利率與 EPS 的影響。每個案例是一個完整推導區塊（本頁下方）
A3: 案例 | B3: 設定 | C3: FY2027 營收 | D3: FY2027 AI 測試 | E3: FY2027 毛利率 | F3: FY2027 EPS | G3: FY2027 EPS 相對基準 | H3: FY2028 營收 | I3: FY2028 AI 測試 | J3: FY2028 毛利率 | K3: FY2028 EPS | L3: FY2028 EPS 相對基準
A4: 基準（情境 A） | B4: PL 區塊 A | C4: =PL!E81 -> 60.186472 | D4: =PL!E79 -> 25.650622 | E4: =PL!E97 -> 0.40133688 | F4: =PL!E107 -> 11.169367 | G4: =F4/F$4-1 -> 0 | H4: =PL!F81 -> 64.71214 | I4: =PL!F79 -> 27.75878 | J4: =PL!F97 -> 0.37648524 | K4: =PL!F107 -> 11.095884 | L4: =K4/K$4-1 -> 0
A5: 測試時間係數 低 | B5: 全部平台取低值（Rubin 1.2、Rubin Ultra 1.5、TPU 0.7） | C5: =E61 -> 57.983859 | D5: =E59 -> 23.448009 | E5: =E77 -> 0.39402159 | F5: =E87 -> 10.424207 | G5: =F5/F$4-1 -> -0.066714633 | H5: =F61 -> 61.407759 | I5: =F59 -> 24.454399 | J5: =F77 -> 0.37209488 | K5: =F87 -> 10.265139 | L5: =K5/K$4-1 -> -0.074869634
A6: 測試時間係數 高 | B6: 全部平台取高值（Rubin 1.8、Rubin Ultra 2.6、TPU 1.2） | C6: =E112 -> 61.886699 | D6: =E110 -> 27.350849 | E6: =E128 -> 0.40662754 | F6: =E138 -> 11.744567 | G6: =F6/F$4-1 -> 0.051497937 | H6: =F112 -> 67.510096 | I6: =F110 -> 30.556736 | J6: =F128 -> 0.38034866 | K6: =F138 -> 11.822033 | L6: =K6/K$4-1 -> 0.0654431
A7: ASIC 曝險 低 | B7: AMD 0.1、TPU 0.3、Trainium 0.2、其他 0.2 | C7: =E163 -> 59.974447 | D7: =E161 -> 25.438596 | E7: =E179 -> 0.40065607 | F7: =E189 -> 11.097638 | G7: =F7/F$4-1 -> -0.0064220118 | H7: =F163 -> 64.232942 | I7: =F161 -> 27.279582 | J7: =F179 -> 0.37554651 | K7: =F189 -> 10.961126 | L7: =K7/K$4-1 -> -0.012144845
A8: ASIC 曝險 高 | B8: AMD 0.4、TPU 0.7、Trainium 0.6、其他 0.6 | C8: =E214 -> 60.389859 | D8: =E212 -> 25.854009 | E8: =E230 -> 0.40198545 | F8: =E240 -> 11.238175 | G8: =F8/F$4-1 -> 0.0061603551 | H8: =F214 -> 65.168121 | I8: =F212 -> 28.214761 | J8: =F230 -> 0.37736073 | K8: =F240 -> 11.223923 | L8: =K8/K$4-1 -> 0.011539313
A9: 份額流失（低） | B9: 份額相對值 2027 0.88、2028 0.80、2029 0.75（日月光、Amkor 擴 GPU 測試） | C9: =E265 -> 58.296426 | D9: =E263 -> 23.760576 | E9: =E281 -> 0.39509334 | F9: =E291 -> 10.529951 | G9: =F9/F$4-1 -> -0.057247334 | H9: =F265 -> 61.091429 | I9: =F263 -> 24.13807 | J9: =F281 -> 0.36995833 | K9: =F291 -> 10.116526 | L9: =K9/K$4-1 -> -0.088263161
A10: 份額持平（高） | B10: 份額相對值 2027–29 1.00 | C10: =E316 -> 61.536505 | D10: =E314 -> 27.000655 | E10: =E332 -> 0.40556173 | F10: =E342 -> 11.626094 | G10: =F10/F$4-1 -> 0.040890953 | H10: =F316 -> 67.125947 | I10: =F314 -> 30.172587 | J10: =F332 -> 0.38018067 | K10: =F342 -> 11.737761 | L10: =K10/K$4-1 -> 0.057848198
A11: 測試單價下滑快 | B11: 單價指數 2027 0.95、2028 0.90、2029 0.88 | C11: =E367 -> 59.401249 | D11: =E365 -> 24.865399 | E11: =E383 -> 0.39609349 | F11: =E393 -> 10.798774 | G11: =F11/F$4-1 -> -0.03317946 | H11: =F367 -> 62.977216 | I11: =F365 -> 26.023856 | J11: =F383 -> 0.36733468 | K11: =F393 -> 10.373755 | L11: =K11/K$4-1 -> -0.065080823
A12: 測試單價持平 | B12: 單價指數 2027 1.02、2028–29 1.00 | C12: =E418 -> 61.233436 | D12: =E416 -> 26.697586 | E12: =E434 -> 0.40811888 | F12: =E444 -> 11.663492 | G12: =F12/F$4-1 -> 0.04423928 | H12: =F418 -> 65.868756 | I12: =F416 -> 28.915396 | J12: =F434 -> 0.38074897 | K12: =F444 -> 11.508144 | L12: =K12/K$4-1 -> 0.037154309
A13: AI 部署 ×0.8 | B13: FY2027 起加速器顆數 ×0.8 | C13: =E469 -> 55.056348 | D13: =E467 -> 20.520498 | E13: =E485 -> 0.38339282 | F13: =E495 -> 9.4338084 | G13: =F13/F$4-1 -> -0.15538562 | H13: =F469 -> 59.160384 | I13: =F467 -> 22.207024 | J13: =F485 -> 0.37359854 | K13: =F495 -> 9.888452 | L13: =K13/K$4-1 -> -0.10881804
A14: AI 部署 ×1.2 | B14: ×1.2 | C14: =E520 -> 65.316597 | D14: =E518 -> 30.780746 | E14: =E536 -> 0.4164622 | F14: =E546 -> 12.904927 | G14: =F14/F$4-1 -> 0.15538562 | H14: =F520 -> 70.263896 | I14: =F518 -> 33.310536 | J14: =F536 -> 0.37891577 | K14: =F546 -> 12.303415 | L14: =K14/K$4-1 -> 0.1088269
A15: FY2026 AI 占比 28% | B15: 校準用 AI 占比取低值（非 AI 基期較大） | C15: =E571 -> 58.775593 | D15: =E569 -> 20.520498 | E15: =E587 -> 0.39697249 | F15: =E597 -> 10.701998 | G15: =F15/F$4-1 -> -0.04184383 | H15: =F571 -> 63.139976 | I15: =F569 -> 22.207024 | J15: =F587 -> 0.37611358 | K15: =F597 -> 10.77014 | L15: =K15/K$4-1 -> -0.029357217
A16: FY2026 AI 占比 45% | B16: 取高值 | C16: =E622 -> 62.202014 | D16: =E620 -> 32.979371 | E16: =E638 -> 0.40722827 | F16: =E648 -> 11.837038 | G16: =F16/F$4-1 -> 0.0597769 | H16: =F622 -> 66.958087 | I16: =F620 -> 35.68986 | J16: =F638 -> 0.37698591 | K16: =F648 -> 11.561304 | L16: =K16/K$4-1 -> 0.041945281
A17: 變動現金成本 10% | B17: v＝10%（固定成本占比較高） | C17: =E673 -> 60.186472 | D17: =E671 -> 25.650622 | E17: =E689 -> 0.42338602 | F17: =E699 -> 12.038453 | G17: =F17/F$4-1 -> 0.077809761 | H17: =F673 -> 64.71214 | I17: =F671 -> 27.75878 | J17: =F689 -> 0.40496429 | K17: =F699 -> 12.302818 | L17: =K17/K$4-1 -> 0.10877308
A18: 變動現金成本 30% | B18: v＝30% | C18: =E724 -> 60.186472 | D18: =E722 -> 25.650622 | E18: =E740 -> 0.37928774 | F18: =E750 -> 10.300282 | G18: =F18/F$4-1 -> -0.077809761 | H18: =F724 -> 64.71214 | I18: =F722 -> 27.75878 | J18: =F740 -> 0.3480062 | K18: =F750 -> 9.8889508 | L18: =K18/K$4-1 -> -0.10877308
A19: 折舊率 9% | B19: 新增資本支出年折舊率 9% | C19: =E775 -> 60.186472 | D19: =E773 -> 25.650622 | E19: =E791 -> 0.41688225 | F19: =E801 -> 11.782102 | G19: =F19/F$4-1 -> 0.054858442 | H19: =F775 -> 64.71214 | I19: =F773 -> 27.75878 | J19: =F791 -> 0.40168713 | K19: =F801 -> 12.163933 | L19: =K19/K$4-1 -> 0.096256262
A20: 折舊率 14% | B20: 年折舊率 14%（設備占比較高） | C20: =E826 -> 60.186472 | D20: =E824 -> 25.650622 | E20: =E842 -> 0.37801882 | F20: =E852 -> 10.250266 | G20: =F20/F$4-1 -> -0.082287662 | H20: =F826 -> 64.71214 | I20: =F824 -> 27.75878 | J20: =F842 -> 0.33868242 | K20: =F852 -> 9.4938118 | L20: =K20/K$4-1 -> -0.14438439
A21: 維持性資本支出 6% | B21: 營收的 6% | C21: =E877 -> 60.186472 | D21: =E875 -> 25.650622 | E21: =E893 -> 0.40152192 | F21: =E903 -> 11.176661 | G21: =F21/F$4-1 -> 0.00065299934 | H21: =F877 -> 64.71214 | I21: =F875 -> 27.75878 | J21: =F893 -> 0.37835549 | K21: =F903 -> 11.175145 | L21: =K21/K$4-1 -> 0.007143237
A22: 維持性資本支出 15% | B22: 營收的 15% | C22: =E928 -> 60.186472 | D22: =E926 -> 25.650622 | E22: =E944 -> 0.40110558 | F22: =E954 -> 11.16025 | G22: =F22/F$4-1 -> -0.00081624917 | H22: =F928 -> 64.71214 | I22: =F926 -> 27.75878 | J22: =F944 -> 0.37414743 | K22: =F954 -> 10.996809 | L22: =K22/K$4-1 -> -0.0089290462
A23: 營業費用彈性 0.4 | C23: =E979 -> 60.186472 | D23: =E977 -> 25.650622 | E23: =E995 -> 0.40133688 | F23: =E1005 -> 11.384552 | G23: =F23/F$4-1 -> 0.019265556 | H23: =F979 -> 64.71214 | I23: =F977 -> 27.75878 | J23: =F995 -> 0.37648524 | K23: =F1005 -> 11.387466 | L23: =K23/K$4-1 -> 0.02627838
A24: 營業費用彈性 1.0 | B24: 營業費用與營收同步成長 | C24: =E1030 -> 60.186472 | D24: =E1028 -> 25.650622 | E24: =E1046 -> 0.40133688 | F24: =E1056 -> 10.738999 | G24: =F24/F$4-1 -> -0.038531112 | H24: =F1030 -> 64.71214 | I24: =F1028 -> 27.75878 | J24: =F1046 -> 0.37648524 | K24: =F1056 -> 10.493304 | L24: =K24/K$4-1 -> -0.05430666
A25: 淨利 ÷ 營業利益 0.78 | B25: 利息費用上升 | C25: =E1081 -> 60.186472 | D25: =E1079 -> 25.650622 | E25: =E1097 -> 0.40133688 | F25: =E1107 -> 10.371556 | G25: =F25/F$4-1 -> -0.071428571 | H25: =F1081 -> 64.71214 | I25: =F1079 -> 27.75878 | J25: =F1097 -> 0.37648524 | K25: =F1107 -> 10.303321 | L25: =K25/K$4-1 -> -0.071428571
A26: 淨利 ÷ 營業利益 0.90 | B26: 回到 2025 年水準 | C26: =E1132 -> 60.186472 | D26: =E1130 -> 25.650622 | E26: =E1148 -> 0.40133688 | F26: =E1158 -> 11.967179 | G26: =F26/F$4-1 -> 0.071428571 | H26: =F1132 -> 64.71214 | I26: =F1130 -> 27.75878 | J26: =F1148 -> 0.37648524 | K26: =F1158 -> 11.888447 | L26: =K26/K$4-1 -> 0.071428571
A27: 非 AI 成長 低 | B27: 2027 +4%、2028–29 0% | C27: =E1183 -> 57.719626 | D27: =E1181 -> 25.650622 | E27: =E1199 -> 0.39293208 | F27: =E1209 -> 10.328221 | G27: =F27/F$4-1 -> -0.075308331 | H27: =F1183 -> 59.827784 | I27: =F1181 -> 27.75878 | J27: =F1199 -> 0.36654077 | K27: =F1209 -> 9.7375186 | L27: =K27/K$4-1 -> -0.12242068
A28: 非 AI 成長 高 | B28: 2027 +20%、2028 +12%、2029 +10% | C28: =E1234 -> 62.653319 | D28: =E1232 -> 25.650622 | E28: =E1250 -> 0.40907984 | F28: =E1260 -> 12.010514 | G28: =F28/F$4-1 -> 0.075308331 | H28: =F1234 -> 69.2018 | I28: =F1232 -> 27.75878 | J28: =F1250 -> 0.38381926 | K28: =F1260 -> 12.320651 | L28: =K28/K$4-1 -> 0.1103803
A29: 顆數情境 B | B29: CY2028 ×0.8、CY2029 ×0.85 | C29: =PL!E132 -> 60.186472 | D29: =PL!E130 -> 25.650622 | E29: =PL!E148 -> 0.40133688 | F29: =PL!E158 -> 11.169367 | G29: =F29/F$4-1 -> 0 | H29: =PL!F132 -> 59.160384 | I29: =PL!F130 -> 22.207024 | J29: =PL!F148 -> 0.35307213 | K29: =PL!F158 -> 9.0297131 | L29: =K29/K$4-1 -> -0.18621059
A30: 顆數情境 C | B30: CY2028–29 ×0.6 | C30: =PL!E183 -> 60.186472 | D30: =PL!E181 -> 25.650622 | E30: =PL!E199 -> 0.40133688 | F30: =PL!E209 -> 11.169367 | G30: =F30/F$4-1 -> 0 | H30: =PL!F183 -> 53.608628 | I30: =PL!F181 -> 16.655268 | J30: =PL!F199 -> 0.30822048 | K30: =PL!F209 -> 6.1713519 | L30: =K30/K$4-1 -> -0.44381613
A32: 讀法：FY2027 三情境相同；顆數情境 B、C 的差異從 FY2028 起。資本支出隨當年營收增量擴產；FY2028 顆數下修、營收下滑時只剩維持性資本支出，但固定現金成本與既有折舊不降，毛利率跌幅大於營收。測試單價只改營收、不改成本，對 EPS 的影響大於對營收。
A40: 案例區塊：測試時間係數 低（情境 A）
A41: 項目 | B41: 單位 | C41: FY2025A | D41: FY2026（錨點） | E41: FY2027 | F41: FY2028 | G41: FY2029 | H41: 說明
A42: A. AI 加速器測試需求（加權顆數＝顆數 × 每顆測試時間（含 burn-in）× 京元電曝險；FY(t)＝CY(t)）
A43: NVIDIA Blackwell：加權顆數 | B43: 百萬顆 | D43: =u_bw_26*tt_bw_lo -> 5.4 | E43: =u_bw_27*1*tt_bw_lo -> 2.4 | F43: =u_bw_28*um28_A*1*tt_bw_lo -> 0.5 | G43: =u_bw_28*(1+g29_bw)*um29_A*1*tt_bw_lo -> 0.25
A44: NVIDIA Rubin：加權顆數 | B44: 百萬顆 | D44: =u_rb_26*tt_rb_lo -> 2.04 | E44: =u_rb_27*1*tt_rb_lo -> 8.4 | F44: =u_rb_28*um28_A*1*tt_rb_lo -> 8.4 | G44: =u_rb_28*(1+g29_rb)*um29_A*1*tt_rb_lo -> 9.66
A45: NVIDIA Rubin Ultra：加權顆數 | B45: 百萬顆 | D45: =u_ru_26*tt_ru_lo -> 0 | E45: =u_ru_27*1*tt_ru_lo -> 0.45 | F45: =u_ru_28*um28_A*1*tt_ru_lo -> 3 | G45: =u_ru_28*(1+g29_ru)*um29_A*1*tt_ru_lo -> 3.45
A46: NVIDIA Hopper：加權顆數 | B46: 百萬顆 | D46: =u_hp_26*tt_hp_lo -> 0.25 | E46: =u_hp_27*1*tt_hp_lo -> 0 | F46: =u_hp_28*um28_A*1*tt_hp_lo -> 0 | G46: =u_hp_28*(1+g29_hp)*um29_A*1*tt_hp_lo -> 0
A47: AMD Instinct：加權顆數 | B47: 百萬顆 | D47: =u_amd_26*tt_amd_lo*ex_amd -> 0.135 | E47: =u_amd_27*1*tt_amd_lo*ex_amd -> 0.27 | F47: =u_amd_28*um28_A*1*tt_amd_lo*ex_amd -> 0.36 | G47: =u_amd_28*(1+g29_amd)*um29_A*1*tt_amd_lo*ex_amd -> 0.414
A48: Google TPU：加權顆數 | B48: 百萬顆 | D48: =u_tpu_26*tt_tpu_lo*ex_tpu -> 1.3475 | E48: =u_tpu_27*1*tt_tpu_lo*ex_tpu -> 1.925 | F48: =u_tpu_28*um28_A*1*tt_tpu_lo*ex_tpu -> 2.45 | G48: =u_tpu_28*(1+g29_tpu)*um29_A*1*tt_tpu_lo*ex_tpu -> 2.8175
A49: AWS Trainium：加權顆數 | B49: 百萬顆 | D49: =u_trn_26*tt_trn_lo*ex_trn -> 0.48 | E49: =u_trn_27*1*tt_trn_lo*ex_trn -> 0.6 | F49: =u_trn_28*um28_A*1*tt_trn_lo*ex_trn -> 0.72 | G49: =u_trn_28*(1+g29_trn)*um29_A*1*tt_trn_lo*ex_trn -> 0.828
...

Sheet Sources
A1: 來源（公司原文＝京元電每季 Investor update 與月營收；AI 占比、客戶與券商估計皆為 Interested-party）
A2: 公司：2Q26 Investor update（1Q26、2Q26 營收、毛利率、費用、EBITDA、EPS；安裝測試機 5,900 台以上） | B2: https://www.kyec.com.tw/Upfiles/EDUp/files/投資人關係/每季營運報告/KYEC(2449)_2Q26 Investor update_English.pdf
A3: 公司：4Q25 Investor update（3Q25、4Q25 營收、毛利率、費用、EBITDA、EPS） | B3: https://www.kyec.com.tw/Upfiles/EDUp/files/投資人關係/每季營運報告/KYEC(2449)_4Q25 Investor update_English.pdf
A4: 公司：2Q25 Investor update（1Q25、2Q25；不含已出售的中國子公司） | B4: https://kyec.com.tw/Upfiles/EDUp/files/關於京元/KYEC(2449TW)_2Q25 Investor update_English.pdf
A5: 中央社 2026-03-06（FY2025 營收、毛利率、營業利益、淨利、EPS；配股；處分利益） | B5: https://www.cna.com.tw/news/afe/202603060261.aspx
A6: 科技新報 2026-05-11（1Q26 毛利率 39.74%、營益率 27.2%、淨利） | B6: https://finance.technews.tw/2026/05/11/king-yuan-electrics-first-quarter-financial-report-hit-a-new-quarterly-high/
A7: 月營收：科技新報 2026-10-08（9 月 40.71 億、前 9 月 334.76 億） | B7: https://finance.technews.tw/2026/10/08/kyec-2449-202609-financial-report/
A8: 月營收：HiStock（2025-01 至 2026-09） | B8: https://histock.tw/stock/financial.aspx?no=2449
A9: 媒體：理財周刊 2026-09-01（2Q26 淨利、EPS；法人 2026 年營收與 EPS；目標價中位數） | B9: https://www.moneyweekly.com.tw/_Article?AID=246195
A10: 媒體：理財周刊 2026-09-24（資本支出 500 億、美國廠 14 億美元、Rubin 延後、ASIC 客戶） | B10: https://www.moneyweekly.com.tw/_Article?AID=251167
A11: 媒體：優分析 2026-09-18（4Q26 營收估計、Rubin 影響、聯發科 TPU、博通占比） | B11: https://uanalyze.com.tw/articles/5209555591
A12: 券商：Morgan Stanley（經科技新報 2026-06-23；AI 占比、Google 相關、CPU、burn-in、資本支出、目標價） | B12: https://finance.technews.tw/2026/06/23/morgan-stanley-expects-king-yuan-electronics-revenue-to-grow-by-40-in-2026/
A13: 媒體：雅虎新聞 2026-01-27（4Q25 營收、2025 年資本支出約 370 億、2026 年預算 393.72 億） | B13: https://n.yam.com/Article/20260127965778
... A20: 資料商：玩股網年度 EPS（2013–2025）；HiStock 季 EPS 與月本益比；stockanalysis 年度 P/E | B20: https://www.wantgoo.com/stock/2449/profitability/dividend-payout-ratio；https://histock.tw/stock/2449/%E6%9C%AC%E7%9B%8A%E6%AF%94；https://stockanalysis.com/quote/tpe/2449/financials/ratios/
A21: 市場層：tsmc 成品（加速器顆數與情境係數，本 repo，唯讀）
A22: 待補（人工）：3Q26 財報（約 11 月上旬）；10 月營收（11 月上旬）；折舊攤提金額（財報附註）；客戶別營收與 NVIDIA 委外份額；測試單價；處分利益金額；前瞻 P/E 十年歷史（Bloomberg）；FY2027–28 最新共識（付費） | B22: 未找到
A23: SemiAnalysis | B23: 未使用
