Workbook

Sheet README
A1: 台達電（2308）收支與估值模型 v0.1.1（AI 半導體 Project：電源與散熱次產業樣板） 2026-10-25
A2: 版本：v0.1.1（2026-10-25：Val 新增第 0 節「目標價與上檔空間」、In 新增情境權重 tp_wA／tp_wB／tp_wC；其餘數值與 v0.1 相同）。v0.1（初版）：AI 電源每 kW 內容、台達電份額、液冷每 GW 營收在本模型 Units 頁建立，為本專案權威資料（規則第 13 條）；奇鋐等散熱廠之後讀這條液冷線。
A3: 模型命題：台達電的 AI 營收＝部署 GW（AI IT 資本支出 ÷ 每 GW IT 資本支出）×（AI 電源每 kW 內容 × 台達電份額＋液冷每 GW 營收）。800V HVDC 把交流轉直流移到機架外，每 GW 可做的金額變大；同時光寶、Flex、中國廠追趕份額。股價兩週跌約兩成後，約 22–28 倍未來 12 月 EPS。
A4: 核心問題：每 kW 電源內容上升（800V）能不能抵銷份額流失與零組件成本，讓 AI 營收在 2027–28 年維持高成長；現價隱含的路徑合不合理。
A6: 會計年度＝日曆年，FY(t)＝CY(t)，不平移。預測期 FY2027–FY2029（三年）。金額：十億新台幣；市場以美元計、以匯率換算。口徑：歸屬母公司淨利。
A8: 驅動因子 → 推導量（全部唯讀上游，不修改）
A9: AI 電源營收：markets/network 的 AI IT 資本支出 × 情境顆數係數 ÷ 每 GW IT 資本支出（Tokenomics，經橋接表）＝部署 GW；× 每 kW 電源內容（凱基推導、2028 起 Assumed）× 匯率 × 台達電有效份額（FY2026 以公司 AI 相關占比校準）× 份額相對值（Assumed）。
A10: 液冷營收：FY2026 以公司液冷占比校準每 GW 營收 × 相對值（Assumed）。非 AI：FY2026 殘差 × 成長率（Assumed）。毛利率：AI 電源比其他營收高 d_ai（Assumed），其他毛利率為 FY2026 殘差（Derived）。營業費用：彈性 phi（Derived）。
A11: 校準：FY2026 ＝ 1H26 實績＋3Q26 營收實績＋假設（4Q 季增、毛利率、營業費用率）。不用券商數字（只在 Recon 對帳）。
A12: 估值：現價 ÷ FY2027、FY2028 EPS；十年 P/E 規則值（單一資料商來源）× FY2027 EPS；循環位置以本模型營收最高年判定（台達電不套設備股見頂年）。
A13: 標記：Verified、Interested-party、Analogy、Assumed、Derived。SemiAnalysis 未使用。公司原文＝法說簡報與逐字稿；券商皆未具名或單一來源。
A15: 已知限制：(1)「AI 相關」是否含液冷，公司說法不一致（Sens「AI 相關含液冷」）；(2) 2028 年起每 kW 內容（800V）與份額相對值為 Assumed，是 FY2028 EPS 最敏感的輸入；(3) 部署 GW 以 VR200 每 GW IT 資本支出換算，ASIC 機架的每 GW 資本支出較低，GW 可能低估；(4) 十年 P/E 只有一個來源，且 2016–2019 年為 AI 前的低倍數；(5) 未計 Vicor 337 調查（垂直供電）與零組件短缺的下檔；(6) 3Q26 法說（10 月底）後更新錨點；R4 產業部署路徑未建。

Sheet In
A1: In — 輸入（藍字；基準欄 E，低 D、高 F）。金額：十億新台幣（NT$B），市場與每 kW 內容為美元；比例：%。每個輸入附兩個來源（找不到者寫「未找到」）；公司原文算一個
A2: 標記：Verified／Interested-party／Analogy／Assumed／Derived；Analogy、Assumed 給低／高區間。SemiAnalysis 未使用。公司原文＝台達電法說簡報與逐字稿（filecenter.deltaww.com）、月營收公告；公司的 AI 占比與毛利率說法為 Interested-party；券商估計皆為 Interested-party
A3: 鍵 | B3: 項目 | C3: 單位 | D3: 低 | E3: 基準 | F3: 高 | G3: 標記 | H3: 來源1 | I3: 來源2／說明
A4: A. AI 部署規模（讀 markets/network、markets/chip_bridge、tsmc 成品；情境 A 基準，B／C 依顆數係數縮放）
A5: itc_26 | B5: AI IT 資本支出 2026 | C5: US$B | E5: 781.87292 | G5: Derived | H5: markets/network/dist/20261023_AI網通市場模型_v0.2.2.xlsx｜Mkt!C27:F27 | I5: 加速器顆數 × 每顆 IT capex（含 ASIC）；本模型以此除以每 GW IT 資本支出得到部署 GW
A6: itc_27 | B6: AI IT 資本支出 2027 | C6: US$B | E6: 1565.35 | G6: Derived | H6: markets/network/dist/20261023_AI網通市場模型_v0.2.2.xlsx｜Mkt!C27:F27 | I6: 同上
A7: itc_28 | B7: AI IT 資本支出 2028 | C7: US$B | E7: 1984.2639 | G7: Derived | H7: markets/network/dist/20261023_AI網通市場模型_v0.2.2.xlsx｜Mkt!C27:F27 | I7: 同上
A8: itc_29 | B8: AI IT 資本支出 2029 | C8: US$B | E8: 2260.3903 | G8: Derived | H8: markets/network/dist/20261023_AI網通市場模型_v0.2.2.xlsx｜Mkt!C27:F27 | I8: 同上
A9: itpg_gb | B9: 每 GW IT 資本支出（GB300） | C9: US$B | E9: 32.237224 | G9: Derived | H9: markets/chip_bridge/dist/20261023_晶片內容橋接表_v0.2.1.xlsx｜In!E10（GB300）、H10（VR200） | I9: Tokenomics v20.1 IF_CapexIT（經橋接表；唯讀）
A10: itpg_vr | B10: 每 GW IT 資本支出（VR200；2027 起） | C10: US$B | E10: 37.586352 | G10: Derived | H10: markets/chip_bridge/dist/20261023_晶片內容橋接表_v0.2.1.xlsx｜In!E10（GB300）、H10（VR200） | I10: 同上；Rubin Ultra 與 ASIC 機架未另訂（Assumed：同 VR200）
A11: vr26 | B11: 2026 年部署中 Rubin 世代占比（混合每 GW IT 資本支出用） | C11: % | D11: 0.15 | E11: 0.22 | F11: 0.3 | G11: Interested-party | H11: TrendForce 2026 組合 Rubin 22%（經 markets/memory） | I11: 公司 2Q26 法說：2026 年 Blackwell 出貨遠大於 Rubin
A12: racks_vr | B12: 每 GW 機架數（VR200） | C12: 架 | E12: 4052 | G12: Derived | H12: markets/chip_bridge/dist/20261023_晶片內容橋接表_v0.2.1.xlsx｜In!E6（GB300）、H6（VR200） | I12: Recon 用：每架內容換算
A13: cool_vr | B13: VR200 每架機架內液冷（冷板等，橋接表） | C13: US$K | E13: 56 | G13: Interested-party | H13: markets/chip_bridge/dist/20261023_晶片內容橋接表_v0.2.1.xlsx｜In!E33（GB300）、H33（VR200） | I13: Morgan Stanley（經 Tom's Hardware 2025-11-05）：VR NVL144 機架內冷卻 BOM US$55.7K；不含 CDU、分歧管
A14: um28_A | B14: 情境 A：2028 顆數 ÷ 基準 | C14: x | E14: 1 | G14: Assumed | H14: tsmc/dist/20261025_台積電模型_v0.2.2.xlsx｜In!E37 | I14: A＝基準；B＝AI 資本支出消化；C＝明顯下修（與台積電、NVIDIA、Arista 模型相同）
A15: um29_A | B15: 情境 A：2029 顆數 ÷ 基準 | C15: x | E15: 1 | G15: Assumed | H15: tsmc/dist/20261025_台積電模型_v0.2.2.xlsx｜In!E38 | I15: 同上
A16: um28_B | B16: 情境 B：2028 顆數 ÷ 基準 | C16: x | E16: 0.8 | G16: Assumed | H16: tsmc/dist/20261025_台積電模型_v0.2.2.xlsx｜In!E39 | I16: A＝基準；B＝AI 資本支出消化；C＝明顯下修（與台積電、NVIDIA、Arista 模型相同）
A17: um29_B | B17: 情境 B：2029 顆數 ÷ 基準 | C17: x | E17: 0.85 | G17: Assumed | H17: tsmc/dist/20261025_台積電模型_v0.2.2.xlsx｜In!E40 | I17: 同上
A18: um28_C | B18: 情境 C：2028 顆數 ÷ 基準 | C18: x | E18: 0.6 | G18: Assumed | H18: tsmc/dist/20261025_台積電模型_v0.2.2.xlsx｜In!E41 | I18: A＝基準；B＝AI 資本支出消化；C＝明顯下修（與台積電、NVIDIA、Arista 模型相同）
A19: um29_C | B19: 情境 C：2029 顆數 ÷ 基準 | C19: x | E19: 0.6 | G19: Assumed | H19: tsmc/dist/20261025_台積電模型_v0.2.2.xlsx｜In!E42 | I19: 同上
A20: fx | B20: 匯率（新台幣 ÷ 美元） | C20: NT$/US$ | D20: 30.5 | E20: 32 | F20: 33 | G20: Derived | H20: 公司 2Q26 法說換算 NT$183.2B ≈ US$5.6B（隱含約 32.7） | I20: 2026 年初 31.4（〈台幣〉開紅盤，uanalyze）；10-23 收盤：未找到
A21: B. AI 電源內容與台達電份額（本專案為權威：每架電源與液冷內容、台達電份額，規則第 13 條）
A22: pkw_26 | B22: AI 電源內容（機架電源櫃、PSU、BBU、HVDC 電源櫃）2026 | C22: US$/kW | D22: 380 | E22: 450 | F22: 520 | G22: Derived | H22: https://www.kgi.com.hk/en/-/media/files/kgishk/research-reports/tw-reports/power-supply-industry_01072025.pdf：GB300 每架 PSU US$60–70K ÷ 136kW＝440–515；GB200 35–40K ÷ 120kW＝290–330（Interested-party） | I22: 2026 年以 GB300 為主（公司：Blackwell 遠大於 Rubin）
A23: pkw_27 | B23: AI 電源內容 2027（VR200） | C23: US$/kW | D23: 500 | E23: 600 | F23: 700 | G23: Derived | H23: https://www.kgi.com.hk/en/-/media/files/kgishk/research-reports/tw-reports/power-supply-industry_01072025.pdf：VR200 每架 PSU 超過 US$150K ÷ 約 250kW＝600 以上 | I23: 每 GW 4,052 架（Tokenomics）→ 每架約 247kW，與 250kW 相符
A24: pkw_28 | B24: AI 電源內容 2028（800V HVDC 放量） | C24: US$/kW | D24: 550 | E24: 680 | F24: 800 | G24: Assumed | H24: 公司：±400V、800V 3Q26 量產、2027 才有量；券商估 ±400V、800V 電源櫃占 2027 營收 5–10%（旺得富 2026-10-01，Interested-party） | I24: 800V 把交流轉直流移到機架外電源櫃與 SST：每 kW 內容上升（Assumed）
A25: pkw_29 | B25: AI 電源內容 2029 | C25: US$/kW | D25: 550 | E25: 720 | F25: 850 | G25: Assumed | H25: 同上 | I25: —
A26: rel_27 | B26: 台達電 AI 電源份額 2027 ÷ 2026（相對值） | C26: x | D26: 0.85 | E26: 0.95 | F26: 1 | G26: Assumed | H26: https://www.kgi.com.hk/en/-/media/files/kgishk/research-reports/tw-reports/power-supply-industry_01072025.pdf：Blackwell 平台 AI 伺服器 PSU 台達電約 70%；光寶、Flex 追趕（Interested-party） | I26: 公司 2Q26 法說：Rubin 110kW PSU「領先」；對手：麥格米特、歐陸通（中國）、Vertiv、Flex（BigGo 摘要）
A27: rel_28 | B27: 台達電 AI 電源份額 2028 ÷ 2026 | C27: x | D27: 0.7 | E27: 0.9 | F27: 1 | G27: Assumed | H27: 同上 | I27: —
A28: rel_29 | B28: 台達電 AI 電源份額 2029 ÷ 2026 | C28: x | D28: 0.65 | E28: 0.85 | F28: 1 | G28: Assumed | H28: 同上 | I28: —
A29: lcr_27 | B29: 台達電液冷每 GW 營收 2027 ÷ 2026 | C29: x | D29: 0.9 | E29: 1.1 | F29: 1.3 | G29: Assumed | H29: 橋接表：機架內液冷 GB300 US$50K → VR200 US$56K／架（每 kW 下降：架數 6,764 → 4,052） | I29: 公司：液冷占營收 2025 約 10% → 2026 超過 12%；Liquid-to-Air 使用期比市場預期長（2Q26 法說）
A30: lcr_28 | B30: 台達電液冷每 GW 營收 2028 ÷ 2026 | C30: x | D30: 0.85 | E30: 1.15 | F30: 1.4 | G30: Assumed | H30: 同上 | I30: —
A31: lcr_29 | B31: 台達電液冷每 GW 營收 2029 ÷ 2026 | C31: x | D31: 0.8 | E31: 1.2 | F31: 1.5 | G31: Assumed | H31: 同上 | I31: —
A32: C. 營收結構錨點（公司揭露比例 × 營收）
A33: ai_25 | B33: 2025 年 AI 相關營收 ÷ 營收（讀為不含液冷） | C33: % | E33: 0.18 | G33: Interested-party | H33: https://finance.technews.tw/2026/10/12/delta-electronics-q3-revenue-nears-200-billion-record-high-q4-double-digit-growth：AI 相關營收 2025 年 18%、2026 年超過 25%（公司） | I33: 數位時代 2026-02-26：AI 電源超過 20%、液冷約 9%、合計約 30%（口徑不同，未採用）
A34: ai_26 | B34: 2026 年 AI 相關營收 ÷ 營收（讀為不含液冷） | C34: % | D34: 0.25 | E34: 0.26 | F34: 0.28 | G34: Interested-party | H34: https://filecenter.deltaww.com/IR/download/calendar/2Q26_Transcript.pdf：CFO「一定超過 25%」；BigGo 摘要：朝 28% 目標 | I34: 讀法（Assumed）：AI 相關＝AI 電源，不含液冷；另一讀法見 Sens「AI 相關含液冷」
A35: lc_25 | B35: 2025 年液冷營收 ÷ 營收 | C35: % | E35: 0.1 | G35: Interested-party | H35: https://filecenter.deltaww.com/IR/download/calendar/2Q26_Transcript.pdf：液冷約占 2025 年營收 10% | I35: 數位時代：約 9%
A36: lc_26 | B36: 2026 年液冷營收 ÷ 營收 | C36: % | D36: 0.12 | E36: 0.125 | F36: 0.13 | G36: Interested-party | H36: https://filecenter.deltaww.com/IR/download/calendar/2Q26_Transcript.pdf：2026 年超過 12% | I36: https://finance.technews.tw/2026/10/12/delta-electronics-q3-revenue-nears-200-billion-record-high-q4-double-digit-growth：液冷產品可望超過 12%
A37: g_nai27 | B37: 非 AI 營收年增 2027 | C37: % | D37: 0 | E37: 0.06 | F37: 0.1 | G37: Assumed | H37: 2026 錨點非 AI 約 +15%（Q 頁；含非 AI 資料中心、電源零組件）；自動化 2Q26 +15% 但虧損、交通衰退（2Q26 法說） | I37: 2025：自動化 +5%、交通 −16%（4Q25 法說簡報）
A38: g_nai28 | B38: 非 AI 營收年增 2028 | C38: % | D38: 0 | E38: 0.05 | F38: 0.1 | G38: Assumed | H38: 同上 | I38: —
A39: g_nai29 | B39: 非 AI 營收年增 2029 | C39: % | D39: 0 | E39: 0.04 | F39: 0.08 | G39: Assumed | H39: 同上 | I39: —
A40: D. 毛利率
...

Sheet Q
A1: Q — 實績與 FY2026 錨點（十億新台幣；EPS 為新台幣；股數為十億股）。藍字＝輸入；黑字＝公式。實績取自台達電法說簡報、逐字稿與月營收
A2: FY2026 錨點＝1H26 實績＋3Q26 營收實績（月營收）＋3Q、4Q 假設（毛利率、營業費用率、業外、淨利 ÷ 稅前；4Q 營收＝3Q × (1＋季增)）。1H26 營業利益＝2Q26 30.6＋1Q26（2Q26 ÷ 1.08；公司稱季增 8%）。部門別損益只有年度簡報數字，季度部門數字只在簡報畫面：未找到
A3: 項目 | B3: FY2025A | C3: 1H26（實績） | D3: 3Q26（營收實績） | E3: 4Q26（模型） | F3: FY2026 錨點 | G3: 標記 | H3: 來源1（公司） | I3: 來源2／說明
A4: 營收 | B4: 554.885 | C4: 342.6 | D4: =q3_rev -> 197.059 | E4: =D4*(1+q4g) -> 216.7649 | F4: =SUM(C4:E4) -> 756.4239 | G4: Verified／Interested-party（4Q 季增） | H4: FY2025：https://filecenter.deltaww.com/ir/download/calendar/4Q25_Analyst Meeting.pdf；1H26：https://filecenter.deltaww.com/IR/download/calendar/2Q26_Transcript.pdf | I4: 3Q26 營收：月營收公告（TechNews 2026-10-12）
A5: 毛利 | B5: 190.2 | C5: 124.3 | D5: =D4*q_gm -> 70.94124 | E5: =E4*q_gm -> 78.035364 | F5: =SUM(C5:E5) -> 273.2766 | G5: Verified／Interested-party | H5: FY2025：https://filecenter.deltaww.com/ir/download/calendar/4Q25_Analyst Meeting.pdf；1H26：https://filecenter.deltaww.com/IR/download/calendar/2Q26_Transcript.pdf | I5: 3Q26 營收：月營收公告（TechNews 2026-10-12）
A6: 毛利率 | B6: =B5/B4 -> 0.34277373 | C6: =C5/C4 -> 0.36281378 | D6: =D5/D4 -> 0.36 | E6: =E5/E4 -> 0.36 | F6: =F5/F4 -> 0.36127442 | G6: Derived | H6: — | I6: FY2025 34.3%；1H26 36.3%
A7: 營業費用 | B7: =B5-B8 -> 106.3 | C7: =C5-C8 -> 65.366667 | D7: =D4*q_opx -> 36.455915 | E7: =E4*q_opx -> 40.101506 | F7: =SUM(C7:E7) -> 141.92409 | G7: Derived（毛利 − 營業利益）／Assumed | H7: FY2025：https://filecenter.deltaww.com/ir/download/calendar/4Q25_Analyst Meeting.pdf；1H26：https://filecenter.deltaww.com/IR/download/calendar/2Q26_Transcript.pdf | I7: 3Q26 營收：月營收公告（TechNews 2026-10-12）
A8: 營業利益 | B8: 83.9 | C8: =30.6+30.6/1.08 -> 58.933333 | D8: =D5-D7 -> 34.485325 | E8: =E5-E7 -> 37.933858 | F8: =SUM(C8:E8) -> 131.35252 | G8: Verified／Derived | H8: FY2025：https://filecenter.deltaww.com/ir/download/calendar/4Q25_Analyst Meeting.pdf；1H26：https://filecenter.deltaww.com/IR/download/calendar/2Q26_Transcript.pdf | I8: 3Q26 營收：月營收公告（TechNews 2026-10-12）
A9: 營業利益率 | B9: =B8/B4 -> 0.1512025 | C9: =C8/C4 -> 0.1720179 | D9: =D8/D4 -> 0.175 | E9: =E8/E4 -> 0.175 | F9: =F8/F4 -> 0.17364935 | G9: Derived | H9: — | I9: FY2025 15.1%；1H26 17.2%（公司）
A10: 業外收益 | B10: 3.934 | C10: =C11-C8 -> 7.1666667 | D10: =q_nop -> 2 | E10: =q_nop -> 2 | F10: =SUM(C10:E10) -> 11.166667 | G10: Verified／Derived | H10: FY2025：https://filecenter.deltaww.com/ir/download/calendar/4Q25_Analyst Meeting.pdf；1H26：https://filecenter.deltaww.com/IR/download/calendar/2Q26_Transcript.pdf | I10: 3Q26 營收：月營收公告（TechNews 2026-10-12）
A11: 稅前利益 | B11: =B8+B10 -> 87.834 | C11: 66.1 | D11: =D8+D10 -> 36.485325 | E11: =E8+E10 -> 39.933858 | F11: =SUM(C11:E11) -> 142.51918 | G11: Verified／Derived | H11: FY2025：https://filecenter.deltaww.com/ir/download/calendar/4Q25_Analyst Meeting.pdf；1H26：https://filecenter.deltaww.com/IR/download/calendar/2Q26_Transcript.pdf | I11: FY2025 公司揭露 87.9（四捨五入差）
A12: 歸屬母公司淨利 | B12: 60.108 | C12: 45.7 | D12: =D11*q_nir -> 25.174874 | E12: =E11*q_nir -> 27.554362 | F12: =SUM(C12:E12) -> 98.429236 | G12: Verified／Derived（3Q、4Q） | H12: FY2025：https://filecenter.deltaww.com/ir/download/calendar/4Q25_Analyst Meeting.pdf；1H26：https://filecenter.deltaww.com/IR/download/calendar/2Q26_Transcript.pdf | I12: 3Q26 營收：月營收公告（TechNews 2026-10-12）
A13: 淨利 ÷ 稅前（含稅與非控制權益） | B13: =B12/B11 -> 0.68433636 | C13: =C12/C11 -> 0.6913767 | D13: =D12/D11 -> 0.69 | E13: =E12/E11 -> 0.69 | F13: =F12/F11 -> 0.69063851 | G13: Derived | H13: — | I13: —
A14: 股數（十億股） | B14: =60.108/23.14 -> 2.5975799 | C14: =q_sh -> 2.5980671 | D14: =q_sh -> 2.5980671 | E14: =q_sh -> 2.5980671 | F14: =q_sh -> 2.5980671 | G14: Derived | H14: FY2025：https://filecenter.deltaww.com/ir/download/calendar/4Q25_Analyst Meeting.pdf；1H26：https://filecenter.deltaww.com/IR/download/calendar/2Q26_Transcript.pdf | I14: 淨利 ÷ EPS
A15: EPS | B15: =B12/B14 -> 23.14 | C15: =C12/C14 -> 17.59 | D15: =D12/D14 -> 9.6898477 | E15: =E12/E14 -> 10.605716 | F15: =F12/F14 -> 37.885564 | G15: Derived | H15: 淨利 ÷ 股數 | I15: —
A16: 公司揭露 EPS | B16: 23.14 | C16: 17.59 | G16: Verified | H16: FY2025：https://filecenter.deltaww.com/ir/download/calendar/4Q25_Analyst Meeting.pdf；1H26：https://filecenter.deltaww.com/IR/download/calendar/2Q26_Transcript.pdf | I16: 2Q26 9.68
A17: AI 電源營收（＝營收 × AI 相關占比） | B17: =B4*ai_25 -> 99.8793 | F17: =F4*ai_26 -> 196.67021 | G17: Derived／Interested-party | H17: 公司 AI 相關占比（In 頁 C 節） | I17: 各季 AI 營收未揭露：未找到
A18: 液冷營收（＝營收 × 液冷占比） | B18: =B4*lc_25 -> 55.4885 | F18: =F4*lc_26 -> 94.552988 | G18: Derived／Interested-party | H18: 公司液冷占比 | I18: —
A19: 非 AI 營收（＝營收 − AI 電源 − 液冷） | B19: =B4-B17-B18 -> 399.5172 | F19: =F4-F17-F18 -> 465.2007 | G19: Derived | H19: — | I19: 含非 AI 資料中心、電源零組件、自動化、交通
A20: AI 電源（另一讀法：AI 相關含液冷 → AI 電源＝營收 ×（AI 相關 − 液冷）） | B20: =B4*(ai_25-lc_25) -> 44.3908 | F20: =F4*(ai_26-lc_26) -> 102.11723 | G20: Derived | H20: Sens 用 | I20: —
A21: 非 AI（另一讀法） | B21: =B4-B20-B18 -> 455.0057 | F21: =F4-F20-F18 -> 559.75369 | G21: Derived | H21: Sens 用 | I21: —
A23: FY2026 錨點的檢查（參考；校準未使用券商數字）
A24: FY2026 營收年增 | B24: =F4/B4-1 -> 0.36320841
A25: FY2026 營業費用年增 | B25: =F7/B7-1 -> 0.33512783
A26: 營業費用彈性（營業費用年增 ÷ 營收年增；In 頁 phi 的依據） | B26: =B25/B24 -> 0.92268741
A27: FY2026 營收 ÷ 券商（10-01，3Q 前）− 1 | B27: =F4/b_rev26-1 -> -0.058002615
A28: FY2026 EPS ÷ 券商（本土 10-01）− 1 | B28: =F15/b_eps26a-1 -> -0.1209846
A29: 非 AI 營收 FY2026 年增 | B29: =F19/B19-1 -> 0.16440719

Sheet Units
A1: Units — AI 電源市場、台達電份額、每架內容（本專案權威，規則第 13 條）。部署 GW＝AI IT 資本支出（markets/network）÷ 每 GW IT 資本支出（Tokenomics，經橋接表）
A3: 項目 | B3: 單位 | C3: CY2026 | D3: CY2027 | E3: CY2028 | F3: CY2029 | G3: 說明
A4: 部署 GW（情境 A） | B4: GW | C4: =PL!D65 -> 23.399538 | D4: =PL!E65 -> 41.646766 | E4: =PL!F65 -> 52.792138 | F4: =PL!G65 -> 60.138592 | G4: AI IT 資本支出 ÷ 每 GW IT 資本支出
A5: AI 電源內容 | B5: US$/kW | C5: =PL!D66 -> 450 | D5: =PL!E66 -> 600 | E5: =PL!F66 -> 680 | F5: =PL!G66 -> 720 | G5: In 頁 B 節（2026–27 Derived，2028 起 Assumed）
A6: 每架 AI 電源內容（以 VR200 每 GW 架數換算） | B6: US$K/架 | C6: =PL!D66*1000000/racks_vr/1000 -> 111.05627 | D6: =PL!E66*1000000/racks_vr/1000 -> 148.07502 | E6: =PL!F66*1000000/racks_vr/1000 -> 167.81836 | F6: =PL!G66*1000000/racks_vr/1000 -> 177.69003 | G6: 1 GW ÷ 4,052 架 ≈ 247 kW／架
A7: AI 電源市場 | B7: US$B | C7: =PL!D67 -> 10.529792 | D7: =PL!E67 -> 24.988059 | E7: =PL!F67 -> 35.898654 | F7: =PL!G67 -> 43.299786 | G7: 含 ASIC 機架（假設每 kW 內容相同）
A8: 台達電有效份額 | B8: % | C8: =PL!D71 -> 0.58367194 | D8: =PL!E71 -> 0.55448834 | E8: =PL!F71 -> 0.52530475 | F8: =PL!G71 -> 0.49612115 | G8: FY2026 以公司 AI 相關占比校準
A9: 台達電 AI 電源營收 | B9: US$B | C9: =PL!D72/fx -> 6.1459442 | D9: =PL!E72/fx -> 13.855588 | E9: =PL!F72/fx -> 18.857733 | F9: =PL!G72/fx -> 21.48194
A10: 台達電液冷營收 | B10: US$B | C10: =PL!D76/fx -> 2.9547809 | D10: =PL!E76/fx -> 5.7848481 | E10: =PL!F76/fx -> 7.6662872 | F10: =PL!G76/fx -> 9.1128137 | G10: FY2026 以公司液冷占比校準
A11: 台達電液冷每架營收（以 VR200 架數換算） | B11: US$K/架 | C11: =PL!D76/fx/PL!D65/racks_vr*1000000 -> 31.163667 | D11: =PL!E76/fx/PL!E65/racks_vr*1000000 -> 34.280034 | E11: =PL!F76/fx/PL!F65/racks_vr*1000000 -> 35.838217 | F11: =PL!G76/fx/PL!G65/racks_vr*1000000 -> 37.396401 | G11: 對照：橋接表機架內液冷 VR200 US$56K（台達電多做機架外 CDU、Liquid-to-Air）
A12: 每 GW 台達電 AI 營收（電源＋液冷） | B12: US$M/GW | C12: =PL!D82 -> 388.92755 | D12: =PL!E82 -> 471.5957 | E12: =PL!F82 -> 502.42368 | F12: =PL!G82 -> 508.73744
A13: 其他廠商 AI 電源（光寶、Flex、麥格米特、Vertiv 等）＝ 市場 − 台達電 | B13: US$B | C13: =PL!D67-PL!D72/fx -> 4.3838479 | D13: =PL!E67-PL!E72/fx -> 11.132472 | E13: =PL!F67-PL!F72/fx -> 17.040921 | F13: =PL!G67-PL!G72/fx -> 21.817846
A15: 讀法：FY2026 有效份額低於凱基的 Blackwell PSU 約 70%，因為本模型分母含 ASIC 機架與 HVDC、BBU；份額路徑（相對值）與 2028 年起的每 kW 內容是 Assumed，是最需要每季檢查的輸入。

Sheet PL
A1: PL — 台達電損益（十億新台幣；EPS 新台幣；歸屬母公司）。FY2025A 實績、FY2026 錨點（1H26 實績＋3Q26 營收實績＋假設），FY2027 起為模型。FY(t)＝CY(t)。三情境各一個完整推導區塊（本頁下方），頂端為摘要。FY2026–FY2027 三情境相同（顆數係數從 CY2028 開始）
A3: 情境／項目 | B3: 單位 | C3: FY2025A | D3: FY2026（錨點） | E3: FY2027 | F3: FY2028 | G3: FY2029 | H3: 說明
A4: 情境 A
A5: 營收 | B5: NT$B | C5: =C78 -> 554.885 | D5: =D78 -> 756.4239 | E5: =E78 -> 1121.6067 | F5: =F78 -> 1366.537 | G5: =G78 -> 1517.5112
A6: 營收年增 | B6: % | D6: =D79 -> 0.36320841 | E6: =E79 -> 0.48277531 | F6: =F79 -> 0.21837454 | G6: =G79 -> 0.1104794
A7: AI 電源營收 | B7: NT$B | C7: =C72 -> 99.8793 | D7: =D72 -> 196.67021 | E7: =E72 -> 443.37881 | F7: =F72 -> 603.44747 | G7: =G72 -> 687.42207
A8: 液冷營收 | B8: NT$B | C8: =C76 -> 55.4885 | D8: =D76 -> 94.552988 | E8: =E76 -> 185.11514 | F8: =F76 -> 245.32119 | G8: =G76 -> 291.61004
A9: 非 AI 營收 | B9: NT$B | C9: =C77 -> 399.5172 | D9: =D77 -> 465.2007 | E9: =E77 -> 493.11274 | F9: =F77 -> 517.76838 | G9: =G77 -> 538.47911
A10: AI 電源＋液冷 ÷ 營收 | B10: % | C10: =C81 -> 0.28 | D10: =D81 -> 0.385 | E10: =E81 -> 0.56035146 | F10: =F81 -> 0.62110915 | G10: =G81 -> 0.64515642
A11: 毛利率 | B11: % | C11: =C86 -> 0.34277373 | D11: =D86 -> 0.36127442 | E11: =E86 -> 0.37209897 | F11: =F86 -> 0.37580152 | G11: =G86 -> 0.37671386
A12: 營業利益率 | B12: % | C12: =C90 -> 0.1512025 | D12: =D90 -> 0.17364935 | E12: =E90 -> 0.19669163 | F12: =F90 -> 0.20668199 | G12: =G90 -> 0.2109594
A13: 歸屬母公司淨利 | B13: NT$B | C13: =C93 -> 60.108 | D13: =D93 -> 98.429236 | E13: =E93 -> 157.74134 | F13: =F93 -> 200.40263 | G13: =G93 -> 226.41195
A14: EPS | B14: NT$ | C14: =C95 -> 23.14 | D14: =D95 -> 37.885564 | E14: =E95 -> 60.714885 | F14: =F95 -> 77.135278 | G14: =G95 -> 87.146305
A15: EPS 年增 | B15: % | D15: =D96 -> 0.63723266 | E15: =E96 -> 0.60258628 | F15: =F96 -> 0.27045086 | G15: =G96 -> 0.12978533
A17: 情境 B
A18: 營收 | B18: NT$B | C18: =C117 -> 554.885 | D18: =D117 -> 756.4239 | E18: =E117 -> 1121.6067 | F18: =F117 -> 1196.7833 | G18: =G117 -> 1370.6564
A19: 營收年增 | B19: % | D19: =D118 -> 0.36320841 | E19: =E118 -> 0.48277531 | F19: =F118 -> 0.067025828 | G19: =G118 -> 0.1452837
A20: AI 電源營收 | B20: NT$B | C20: =C111 -> 99.8793 | D20: =D111 -> 196.67021 | E20: =E111 -> 443.37881 | F20: =F111 -> 482.75797 | G20: =G111 -> 584.30876
A21: 液冷營收 | B21: NT$B | C21: =C115 -> 55.4885 | D21: =D115 -> 94.552988 | E21: =E115 -> 185.11514 | F21: =F115 -> 196.25695 | G21: =G115 -> 247.86853
A22: 非 AI 營收 | B22: NT$B | C22: =C116 -> 399.5172 | D22: =D116 -> 465.2007 | E22: =E116 -> 493.11274 | F22: =F116 -> 517.76838 | G22: =G116 -> 538.47911
A23: AI 電源＋液冷 ÷ 營收 | B23: % | C23: =C120 -> 0.28 | D23: =D120 -> 0.385 | E23: =E120 -> 0.56035146 | F23: =F120 -> 0.56736664 | G23: =G120 -> 0.60713778
A24: 毛利率 | B24: % | C24: =C125 -> 0.34277373 | D24: =D125 -> 0.36127442 | E24: =E125 -> 0.37209897 | F24: =F125 -> 0.37274479 | G24: =G125 -> 0.3745783
A25: 營業利益率 | B25: % | C25: =C129 -> 0.1512025 | D25: =D129 -> 0.17364935 | E25: =E129 -> 0.19669163 | F25: =F129 -> 0.19954111 | G25: =G129 -> 0.20576893
A26: 歸屬母公司淨利 | B26: NT$B | C26: =C132 -> 60.108 | D26: =D132 -> 98.429236 | E26: =E132 -> 157.74134 | F26: =F132 -> 170.29715 | G26: =G132 -> 200.12657
A27: EPS | B27: NT$ | C27: =C134 -> 23.14 | D27: =D134 -> 37.885564 | E27: =E134 -> 60.714885 | F27: =F134 -> 65.547635 | G27: =G134 -> 77.029022
A28: EPS 年增 | B28: % | D28: =D135 -> 0.63723266 | E28: =E135 -> 0.60258628 | F28: =F135 -> 0.079597448 | G28: =G135 -> 0.17516098
A30: 情境 C
A31: 營收 | B31: NT$B | C31: =C156 -> 554.885 | D31: =D156 -> 756.4239 | E31: =E156 -> 1121.6067 | F31: =F156 -> 1027.0296 | G31: =G156 -> 1125.8984
A32: 營收年增 | B32: % | D32: =D157 -> 0.36320841 | E32: =E157 -> 0.48277531 | F32: =F157 -> -0.084322888 | G32: =G157 -> 0.096266756
A33: AI 電源營收 | B33: NT$B | C33: =C150 -> 99.8793 | D33: =D150 -> 196.67021 | E33: =E150 -> 443.37881 | F33: =F150 -> 362.06848 | G33: =G150 -> 412.45324
A34: 液冷營收 | B34: NT$B | C34: =C154 -> 55.4885 | D34: =D154 -> 94.552988 | E34: =E154 -> 185.11514 | F34: =F154 -> 147.19271 | G34: =G154 -> 174.96602
A35: 非 AI 營收 | B35: NT$B | C35: =C155 -> 399.5172 | D35: =D155 -> 465.2007 | E35: =E155 -> 493.11274 | F35: =F155 -> 517.76838 | G35: =G155 -> 538.47911
A36: AI 電源＋液冷 ÷ 營收 | B36: % | C36: =C159 -> 0.28 | D36: =D159 -> 0.385 | E36: =E159 -> 0.56035146 | F36: =F159 -> 0.49585835 | G36: =G159 -> 0.52173382
A37: 毛利率 | B37: % | C37: =C164 -> 0.34277373 | D37: =D164 -> 0.36127442 | E37: =E164 -> 0.37209897 | F37: =F164 -> 0.36867758 | G37: =G164 -> 0.36978102
A38: 營業利益率 | B38: % | C38: =C168 -> 0.1512025 | D38: =D168 -> 0.17364935 | E38: =E168 -> 0.19669163 | F38: =F168 -> 0.17711732 | G38: =G168 -> 0.18158508
A39: 歸屬母公司淨利 | B39: NT$B | C39: =C171 -> 60.108 | D39: =D171 -> 98.429236 | E39: =E171 -> 157.74134 | F39: =F171 -> 131.03426 | G39: =G171 -> 146.58798
A40: EPS | B40: NT$ | C40: =C173 -> 23.14 | D40: =D173 -> 37.885564 | E40: =E173 -> 60.714885 | F40: =F173 -> 50.435288 | G40: =G173 -> 56.421936
A41: EPS 年增 | B41: % | D41: =D174 -> 0.63723266 | E41: =E174 -> 0.60258628 | F41: =F174 -> -0.16930933 | G41: =G174 -> 0.11869959
A43: 核對（應為 0）：FY2026 模型營收 − 錨點；FY2026 模型 AI 電源 − 錨點；FY2026 毛利 − 錨點
A44: 情境 A：營收差（NT$B） | D44: =D78-a26_rev -> 0
...

Sheet Val
A1: Val — P/E 估值（新台幣）。結論用「現價 ÷ FY2027、FY2028 EPS（模型）」與十年 P/E 規則值（年底落後 P/E，基準為 FY2027 EPS）
A2: 循環位置：台達電不是設備股，不套設備市場見頂年；以本模型營收最高的會計年度為見頂年（比照 NVIDIA、Arista；FY(t)＝CY(t)）。營收到 FY2029 仍在增加時，見頂年未知，判為中段
A3: 目標價與上檔空間：見第 0 節（本頁第 41 列；v0.1.1 新增，為了不位移既有列而放在空白列）
A4: 1. 價格與市場隱含倍數
A5: 項目 | B5: A | C5: B | D5: C | E5: 說明
A6: 現價（2026-10-23 收盤） | B6: =px -> 1605
A7: 現價 ÷ FY2026 EPS（錨點） | B7: =px/PL!D14 -> 42.364422 | C7: =px/PL!D27 -> 42.364422 | D7: =px/PL!D40 -> 42.364422
A8: 現價 ÷ FY2027 EPS（模型） | B8: =px/PL!E14 -> 26.435033 | C8: =px/PL!E27 -> 26.435033 | D8: =px/PL!E40 -> 26.435033 | E8: FY2027 三情境相同（顆數係數從 CY2028 開始）
A9: 現價 ÷ FY2028 EPS（模型） | B9: =px/PL!F14 -> 20.8076 | C9: =px/PL!F27 -> 24.486009 | D9: =px/PL!F40 -> 31.822957
A10: 現價 ÷ FY2029 EPS（模型） | B10: =px/PL!G14 -> 18.417304 | C10: =px/PL!G27 -> 20.836302 | D10: =px/PL!G40 -> 28.446383
A11: 未來 12 月 EPS（模型 A）≈ ¼ FY2026＋¾ FY2027 | B11: =0.25*PL!D14+0.75*PL!E14 -> 55.007554
A12: 現價 ÷ 未來 12 月 EPS（模型 A） | B12: =px/B11 -> 29.177811 | E12: Andy 先驗 D10a 答 30x（未來 12 月）
A13: 近 12 月 P/E（Goodinfo，10-22） | B13: =pe_ttm -> 49.65
A15: 2. 循環位置（本模型營收最高年；FY(t)＝CY(t)）
A16: 情境 | B16: 營收最高年（FY2026–FY2029） | C16: FY2027 判定 | D16: 規則倍數（P/E） | E16: 見頂年是否未知 | F16: 說明
A17: A | B17: =INDEX({2026,2027,2028,2029},MATCH(MAX(PL!D78:G78),PL!D78:G78,0)) -> 2029 | C17: =IF(B17=2029,"中段",IF(2027<B17,"中段",IF(2027=B17,"見頂","谷底"))) -> 中段 | D17: =IF(C17="見頂",pe_peak,IF(C17="谷底",pe_trough,pe_mid)) -> 22.4 | E17: =IF(B17=2029,"是：營收到觀測期末仍在增加","否") -> 是：營收到觀測期末仍在增加 | F17: tools/cycle_position.py excel_rule；營收最高年取代設備市場見頂年
A18: B | B18: =INDEX({2026,2027,2028,2029},MATCH(MAX(PL!D117:G117),PL!D117:G117,0)) -> 2029 | C18: =IF(B18=2029,"中段",IF(2027<B18,"中段",IF(2027=B18,"見頂","谷底"))) -> 中段 | D18: =IF(C18="見頂",pe_peak,IF(C18="谷底",pe_trough,pe_mid)) -> 22.4 | E18: =IF(B18=2029,"是：營收到觀測期末仍在增加","否") -> 是：營收到觀測期末仍在增加 | F18: 同上
A19: C | B19: =INDEX({2026,2027,2028,2029},MATCH(MAX(PL!D156:G156),PL!D156:G156,0)) -> 2029 | C19: =IF(B19=2029,"中段",IF(2027<B19,"中段",IF(2027=B19,"見頂","谷底"))) -> 中段 | D19: =IF(C19="見頂",pe_peak,IF(C19="谷底",pe_trough,pe_mid)) -> 22.4 | E19: =IF(B19=2029,"是：營收到觀測期末仍在增加","否") -> 是：營收到觀測期末仍在增加 | F19: 同上
A21: 3. 規則值隱含股價（新台幣；約 FY2027 年底，未折現）＝ FY2027 EPS × 規則倍數
A22: 情境 | B22: FY2027 EPS | C22: （同左） | D22: 規則倍數 | E22: 隱含股價 | F22: 相對現價 | G22: 現價 ÷ FY2027 EPS
A23: A | B23: =PL!E14 -> 60.714885 | C23: =B23 -> 60.714885 | D23: =D17 -> 22.4 | E23: =C23*D23 -> 1360.0134 | F23: =E23/px-1 -> -0.15263962 | G23: =px/C23 -> 26.435033
A24: B | B24: =PL!E27 -> 60.714885 | C24: =B24 -> 60.714885 | D24: =D18 -> 22.4 | E24: =C24*D24 -> 1360.0134 | F24: =E24/px-1 -> -0.15263962 | G24: =px/C24 -> 26.435033
A25: C | B25: =PL!E40 -> 60.714885 | C25: =B25 -> 60.714885 | D25: =D19 -> 22.4 | E25: =C25*D25 -> 1360.0134 | F25: =E25/px-1 -> -0.15263962 | G25: =px/C25 -> 26.435033
A26: 4. What must be true：FY2027 年底價 ＝ 現價 ×（1＋報酬）所需的倍數（FY2028 EPS；約 2027 年底的價格看下一年 EPS）
A27: FY2027 年底價 ÷ 現價 | B27: 所需倍數（÷ FY2028 EPS，A） | C27: 所需倍數（÷ FY2028 EPS，C） | D27: 對照：Andy 合理 P/E | E27: 對照：十年中位數
A28: 1 | B28: =px*A28/PL!F14 -> 20.8076 | C28: =px*A28/PL!F40 -> 31.822957 | D28: =pe_fair_andy -> 25 | E28: =pe_mid -> 22.4
A29: 1.1 | B29: =px*A29/PL!F14 -> 22.88836 | C29: =px*A29/PL!F40 -> 35.005252 | D29: =pe_fair_andy -> 25 | E29: =pe_mid -> 22.4
A30: 1.21 | B30: =px*A30/PL!F14 -> 25.177196 | C30: =px*A30/PL!F40 -> 38.505778 | D30: =pe_fair_andy -> 25 | E30: =pe_mid -> 22.4
A31: 1.5 | B31: =px*A31/PL!F14 -> 31.2114 | C31: =px*A31/PL!F40 -> 47.734435 | D31: =pe_fair_andy -> 25 | E31: =pe_mid -> 22.4
A32: 2 | B32: =px*A32/PL!F14 -> 41.6152 | C32: =px*A32/PL!F40 -> 63.645913 | D32: =pe_fair_andy -> 25 | E32: =pe_mid -> 22.4
A33: 讀法：1.00＝價格不變、1.21＝一年約 21%。所需倍數低於歷史中位數時，現價相對便宜；倍數是否合理，另看前瞻 P/E 歷史（Bloomberg）。
A35: 5. 對照：以 Andy 合理 P/E 25x 計算的隱含價（只作對照，非規則值）
A36: 情境 | B36: FY2027 EPS | C36: × 25x | D36: 相對現價 | E36: FY2028 EPS | F36: × 25x | G36: 相對現價
A37: A | B37: =PL!E14 -> 60.714885 | C37: =B37*pe_fair_andy -> 1517.8721 | D37: =C37/px-1 -> -0.054285285 | E37: =PL!F14 -> 77.135278 | F37: =E37*pe_fair_andy -> 1928.3819 | G37: =F37/px-1 -> 0.20148408
A38: B | B38: =PL!E27 -> 60.714885 | C38: =B38*pe_fair_andy -> 1517.8721 | D38: =C38/px-1 -> -0.054285285 | E38: =PL!F27 -> 65.547635 | F38: =E38*pe_fair_andy -> 1638.6909 | G38: =F38/px-1 -> 0.020991193
A39: C | B39: =PL!E40 -> 60.714885 | C39: =B39*pe_fair_andy -> 1517.8721 | D39: =C39/px-1 -> -0.054285285 | E39: =PL!F40 -> 50.435288 | F39: =E39*pe_fair_andy -> 1260.8822 | G39: =F39/px-1 -> -0.21440361
A41: 0. 目標價與上檔空間（12 個月，情境加權；權重為 In 頁 tp_wA／tp_wB／tp_wC，Andy 可改）
A42: 目標價（12 個月，情境加權） | B42: =tp_wA*B44+tp_wB*B45+tp_wC*B46 -> 1360.0134 | E42: ＝權重 A × 情境 A 隱含價＋權重 B × 情境 B 隱含價＋權重 C × 情境 C 隱含價（NT$）
A43: 上檔空間（目標價 ÷ 現價 − 1） | B43: =B42/px-1 -> -0.15263962 | E43: 相對「現價（2026-10-23 收盤）」
A44: 情境 A 隱含價（樂觀） | B44: =E23 -> 1360.0134 | E44: ＝規則值隱含股價 E23（情境 A：基準（顆數係數 1.0））
...

Sheet Recon
A1: Recon — 本模型 vs 券商估計、研調市場與份額。只作事後對照，不為對上數字而調參數。券商皆未具名或單一來源；2027 共識（付費）未找到
A3: 項目 | B3: 對照值 | C3: 模型 A | D3: 差距 A | E3: 模型 B | F3: 差距 B | G3: 模型 C | H3: 差距 C | I3: 對照來源 | J3: 說明
A4: A. 券商估計（校準未使用）
A5: FY2026 營收 vs 券商（10-01，3Q 前） | B5: =b_rev26 -> 803 | C5: =PL!D78 -> 756.4239 | D5: =C5/B5-1 -> -0.058002615 | E5: =PL!D117 -> 756.4239 | F5: =E5/B5-1 -> -0.058002615 | G5: =PL!D156 -> 756.4239 | H5: =G5/B5-1 -> -0.058002615 | I5: 旺得富 2026-10-01 | J5: 券商 3Q 估 2,093 億，實際 1,971 億
A6: FY2026 EPS vs 本土券商（10-01） | B6: =b_eps26a -> 43.1 | C6: =PL!D95 -> 37.885564 | D6: =C6/B6-1 -> -0.1209846 | E6: =PL!D134 -> 37.885564 | F6: =E6/B6-1 -> -0.1209846 | G6: =PL!D173 -> 37.885564 | H6: =G6/B6-1 -> -0.1209846 | I6: 旺得富 2026-10-01
A7: FY2026 EPS vs 美系券商（05-04） | B7: =b_eps26b -> 41.5 | C7: =PL!D95 -> 37.885564 | D7: =C7/B7-1 -> -0.087094851 | E7: =PL!D134 -> 37.885564 | F7: =E7/B7-1 -> -0.087094851 | G7: =PL!D173 -> 37.885564 | H7: =G7/B7-1 -> -0.087094851 | I7: CMoney 2026-05-04
A8: FY2027 營收 vs 投顧研究團隊 | B8: =b_rev27 -> 1050 | C8: =PL!E78 -> 1121.6067 | D8: =C8/B8-1 -> 0.068196844 | E8: =PL!E117 -> 1121.6067 | F8: =E8/B8-1 -> 0.068196844 | G8: =PL!E156 -> 1121.6067 | H8: =G8/B8-1 -> 0.068196844 | I8: Yahoo 新聞 2026-10-12
A9: FY2027 EPS vs 投顧研究團隊（10-12） | B9: =b_eps27c -> 62.68 | C9: =PL!E95 -> 60.714885 | D9: =C9/B9-1 -> -0.031351553 | E9: =PL!E134 -> 60.714885 | F9: =E9/B9-1 -> -0.031351553 | G9: =PL!E173 -> 60.714885 | H9: =G9/B9-1 -> -0.031351553 | I9: Yahoo 新聞 2026-10-12
A10: FY2027 EPS vs 美系券商（05-04） | B10: =b_eps27b -> 65.1 | C10: =PL!E95 -> 60.714885 | D10: =C10/B10-1 -> -0.067359682 | E10: =PL!E134 -> 60.714885 | F10: =E10/B10-1 -> -0.067359682 | G10: =PL!E173 -> 60.714885 | H10: =G10/B10-1 -> -0.067359682 | I10: CMoney 2026-05-04
A11: FY2027 EPS vs 本土券商（10-01） | B11: =b_eps27a -> 80.8 | C11: =PL!E95 -> 60.714885 | D11: =C11/B11-1 -> -0.24857816 | E11: =PL!E134 -> 60.714885 | F11: =E11/B11-1 -> -0.24857816 | G11: =PL!E173 -> 60.714885 | H11: =G11/B11-1 -> -0.24857816 | I11: 旺得富 2026-10-01 | J11: 三家區間 62.7–80.8
A12: FY2027 營收年增（模型） | C12: =PL!E79 -> 0.48277531 | E12: =PL!E118 -> 0.48277531 | G12: =PL!E157 -> 0.48277531 | I12: —
A13: B. 市場與份額（先驗比對的機制檢查）
A14: CY2026 AI 電源市場（US$B）vs UBS | B14: =ubs_26 -> 17.7 | C14: =PL!D67 -> 10.529792 | D14: =C14/B14-1 -> -0.40509649 | E14: =PL!D106 -> 10.529792 | F14: =E14/B14-1 -> -0.40509649 | G14: =PL!D145 -> 10.529792 | H14: =G14/B14-1 -> -0.40509649 | I14: UBS（經 TechNews 2026-10-12） | J14: 口徑未知（是否含 BBU、HVDC、非 NVIDIA）
A15: CY2027 AI 電源市場（US$B）vs UBS | B15: =ubs_27 -> 38.2 | C15: =PL!E67 -> 24.988059 | D15: =C15/B15-1 -> -0.34586232 | E15: =PL!E106 -> 24.988059 | F15: =E15/B15-1 -> -0.34586232 | G15: =PL!E145 -> 24.988059 | H15: =G15/B15-1 -> -0.34586232 | I15: 同上
A16: FY2026 台達電有效份額 vs 凱基 Blackwell PSU 份額 | B16: =kgi_sh -> 0.7 | C16: =PL!D69 -> 0.58367194 | D16: =C16-B16 -> -0.11632806 | E16: =PL!D108 -> 0.58367194 | F16: =E16-B16 -> -0.11632806 | G16: =PL!D147 -> 0.58367194 | H16: =G16-B16 -> -0.11632806 | I16: 凱基 2025-07 | J16: 口徑不同：本模型分母含 ASIC 機架、HVDC、BBU
A17: FY2027 每 GW 台達電 AI 營收（US$M） | C17: =PL!E82 -> 471.5957 | E17: =PL!E121 -> 471.5957 | G17: =PL!E160 -> 471.5957 | I17: — | J17: 先驗比對推導約 300–550
A18: FY2027 台達電液冷每架（US$K，VR200 架數）vs 橋接表機架內液冷 | B18: =cool_vr -> 56 | C18: =Units!D11 -> 34.280034 | D18: =C18/B18-1 -> -0.38785654 | E18: =Units!D11 -> 34.280034 | F18: =E18/B18-1 -> -0.38785654 | G18: =Units!D11 -> 34.280034 | H18: =G18/B18-1 -> -0.38785654 | I18: 橋接表 v0.2.1（Morgan Stanley） | J18: 台達電液冷多在機架外（CDU、Liquid-to-Air），所以兩者不是同一個東西
A19: FY2027 AI 電源＋液冷 ÷ 營收 | C19: =PL!E81 -> 0.56035146 | E19: =PL!E120 -> 0.56035146 | G19: =PL!E159 -> 0.56035146 | I19: —
A20: C. 校準
A21: 其他營收毛利率（Derived） | C21: =PL!D84 -> 0.34047442 | E21: =PL!D123 -> 0.34047442 | G21: =PL!D162 -> 0.34047442 | I21: FY2026 錨點 | J21: AI 電源毛利率＝此值＋d_ai
A22: FY2027 毛利率 vs FY2026（百分點） | B22: =a26_gp/a26_rev -> 0.36127442 | C22: =PL!E86 -> 0.37209897 | D22: =C22-B22 -> 0.010824548 | E22: =PL!E125 -> 0.37209897 | F22: =E22-B22 -> 0.010824548 | G22: =PL!E164 -> 0.37209897 | H22: =G22-B22 -> 0.010824548 | I22: 錨點 | J22: AI 電源占比上升使毛利率上升
A23: 4Q26 EPS（模型） | C23: =Q!E15 -> 10.605716 | E23: =Q!E15 -> 10.605716 | G23: =Q!E15 -> 10.605716 | I23: — | J23: 券商 10-01 估 14.7（以 4Q 營收 2,511 億為基礎）
A24: D. 預留
A25: R4 產業部署路徑（markets/deploy_path/，尚未建立）：上線後以部署路徑取代「AI IT 資本支出 ÷ 每 GW IT 資本支出」 | J25: 預留列：本版無數值

Sheet Sens
A1: Sens — 一次動一個輸入（情境 A；有效份額、液冷每 GW、其他營收毛利率在每個案例內依 FY2026 錨點重算，FY2026 恆等於錨點）：對 FY2027、FY2028 的營收、AI 電源營收、毛利率與 EPS 的影響。每個案例是一個完整推導區塊（本頁下方）
A3: 案例 | B3: 設定 | C3: FY2027 營收 | D3: FY2027 AI 電源營收 | E3: FY2027 毛利率 | F3: FY2027 EPS | G3: FY2027 EPS 相對基準 | H3: FY2028 營收 | I3: FY2028 AI 電源營收 | J3: FY2028 毛利率 | K3: FY2028 EPS | L3: FY2028 EPS 相對基準
A4: 基準（情境 A） | B4: PL 區塊 A | C4: =PL!E78 -> 1121.6067 | D4: =PL!E72 -> 443.37881 | E4: =PL!E86 -> 0.37209897 | F4: =PL!E95 -> 60.714885 | G4: =F4/F$4-1 -> 0 | H4: =PL!F78 -> 1366.537 | I4: =PL!F72 -> 603.44747 | J4: =PL!F86 -> 0.37580152 | K4: =PL!F95 -> 77.135278 | L4: =K4/K$4-1 -> 0
A5: 份額流失（低） | B5: 份額相對值 2027 0.85、2028 0.70、2029 0.65（光寶、Flex、中國廠追趕） | C5: =E58 -> 1074.9352 | D5: =E52 -> 396.70735 | E5: =E66 -> 0.3699986 | F5: =E75 -> 57.363567 | G5: =F5/F$4-1 -> -0.055197624 | H5: =F58 -> 1232.4376 | I5: =F52 -> 469.34803 | J5: =F66 -> 0.37094074 | K5: =F75 -> 67.242336 | L5: =K5/K$4-1 -> -0.12825443
A6: 份額持平（高） | B6: 份額相對值 1.0 | C6: =E97 -> 1144.9424 | D6: =E91 -> 466.71453 | E6: =E105 -> 0.37308493 | F6: =E114 -> 62.390543 | G6: =F6/F$4-1 -> 0.027598812 | H6: =F97 -> 1433.5868 | I6: =F91 -> 670.49718 | J6: =F105 -> 0.3778909 | K6: =F114 -> 82.094996 | L6: =K6/K$4-1 -> 0.064298963
A7: 電源內容 低 | B7: 每 kW：2026 380、2027 500、2028–29 550 | C7: =E136 -> 1115.7728 | D7: =E130 -> 437.54487 | E7: =E144 -> 0.37184603 | F7: =E153 -> 60.29597 | G7: =F7/F$4-1 -> -0.006899703 | H7: =F136 -> 1341.082 | I7: =F130 -> 577.99244 | J7: =F144 -> 0.37495359 | K7: =F153 -> 75.250172 | L7: =K7/K$4-1 -> -0.024438956
A8: 電源內容 高 | B8: 每 kW：2026 520、2027 700、2028 800、2029 850 | C8: =E175 -> 1125.8699 | D8: =E169 -> 447.64206 | E8: =E183 -> 0.37228215 | F8: =E192 -> 61.021015 | G8: =F8/F$4-1 -> 0.0050420907 | H8: =F175 -> 1377.4592 | I8: =F169 -> 614.36959 | J8: =F183 -> 0.37615574 | K8: =F192 -> 77.941966 | L8: =K8/K$4-1 -> 0.010458099
A9: 液冷每 GW 低 | B9: 相對值 0.9／0.85／0.8 | C9: =E214 -> 1087.9494 | D9: =E208 -> 443.37881 | E9: =E222 -> 0.37307732 | F9: =E231 -> 59.013171 | G9: =F9/F$4-1 -> -0.028027945 | H9: =F214 -> 1302.5402 | I9: =F208 -> 603.44747 | J9: =F222 -> 0.37753723 | K9: =F231 -> 73.785144 | L9: =K9/K$4-1 -> -0.043431921
A10: 液冷每 GW 高 | B10: 相對值 1.3／1.4／1.5 | C10: =E253 -> 1155.264 | D10: =E247 -> 443.37881 | E10: =E261 -> 0.37117762 | F10: =E270 -> 62.416598 | G10: =F10/F$4-1 -> 0.028027945 | H10: =F253 -> 1419.8677 | I10: =F247 -> 603.44747 | J10: =F261 -> 0.37447463 | K10: =F270 -> 79.924198 | L10: =K10/K$4-1 -> 0.036156221
A11: AI 部署 ×0.8 | B11: FY2027 起 AI IT 資本支出 ×0.8 | C11: =E292 -> 995.9079 | D11: =E286 -> 354.70304 | E11: =E300 -> 0.36896726 | F11: =E309 -> 52.475497 | G11: =F11/F$4-1 -> -0.13570623 | H11: =F292 -> 1196.7833 | I11: =F286 -> 482.75797 | J11: =F300 -> 0.37274479 | K11: =F309 -> 65.737605 | L11: =K11/K$4-1 -> -0.14776212
A12: AI 部署 ×1.2 | B12: ×1.2 | C12: =E331 -> 1247.3055 | D12: =E325 -> 532.05457 | E12: =E339 -> 0.37459947 | F12: =E348 -> 68.954273 | G12: =F12/F$4-1 -> 0.13570623 | H12: =F331 -> 1536.2908 | I12: =F325 -> 724.13696 | J12: =F339 -> 0.37818275 | K12: =F348 -> 88.553217 | L12: =K12/K$4-1 -> 0.14802487
A13: 非 AI 成長 低 | B13: 2027–29 0% | C13: =E370 -> 1093.6946 | D13: =E364 -> 443.37881 | E13: =E378 -> 0.37290605 | F13: =E387 -> 59.303651 | G13: =F13/F$4-1 -> -0.023243612 | H13: =F370 -> 1313.9694 | I13: =F364 -> 603.44747 | J13: =F378 -> 0.37721485 | K13: =F387 -> 74.383226 | L13: =K13/K$4-1 -> -0.035678252
A14: 非 AI 成長 高 | B14: 2027 +10%、2028 +10%、2029 +8% | C14: =E409 -> 1140.2147 | D14: =E403 -> 443.37881 | E14: =E417 -> 0.37158286 | F14: =E426 -> 61.655707 | G14: =F14/F$4-1 -> 0.015495742 | H14: =F409 -> 1411.6615 | I14: =F403 -> 603.44747 | J14: =F417 -> 0.37467227 | K14: =F426 -> 79.509424 | L14: =K14/K$4-1 -> 0.030778989
A15: AI 毛利率差距 4pt | B15: AI 電源毛利率只高 4 個百分點 | C15: =E448 -> 1121.6067 | D15: =E442 -> 443.37881 | E15: =E456 -> 0.36668669 | F15: =E465 -> 59.102684 | G15: =F15/F$4-1 -> -0.026553631 | H15: =F448 -> 1366.537 | I15: =F442 -> 603.44747 | J15: =F456 -> 0.36853797 | K15: =F465 -> 74.499133 | L15: =K15/K$4-1 -> -0.034175602
A16: AI 毛利率差距 12pt | B16: 高 12 個百分點 | C16: =E487 -> 1121.6067 | D16: =E481 -> 443.37881 | E16: =E495 -> 0.37751124 | F16: =E504 -> 62.327085 | G16: =F16/F$4-1 -> 0.026553631 | H16: =F487 -> 1366.537 | I16: =F481 -> 603.44747 | J16: =F495 -> 0.38306508 | K16: =F504 -> 79.771422 | L16: =K16/K$4-1 -> 0.034175602
A17: 營業費用率 +2pt | B17: 營業費用額外 +2% × 營收 | C17: =E526 -> 1121.6067 | D17: =E520 -> 443.37881 | E17: =E534 -> 0.37209897 | F17: =E543 -> 54.757312 | G17: =F17/F$4-1 -> -0.098123751 | H17: =F526 -> 1366.537 | I17: =F520 -> 603.44747 | J17: =F534 -> 0.37580152 | K17: =F543 -> 69.876723 | L17: =K17/K$4-1 -> -0.094101617
A18: AI 相關含液冷（讀法） | B18: FY2026 AI 電源＝營收 ×（26% − 12.5%）；份額分子變小 | C18: =E565 -> 1008.67 | D18: =E559 -> 230.21592 | E18: =E573 -> 0.36873339 | F18: =E582 -> 53.15467 | G18: =F18/F$4-1 -> -0.12451996 | H18: =F565 -> 1181.6555 | I18: =F559 -> 313.32849 | J18: =F573 -> 0.37168727 | K18: =F582 -> 64.470999 | L18: =K18/K$4-1 -> -0.1641827
A19: 顆數情境 B | B19: CY2028 ×0.8、CY2029 ×0.85 | C19: =PL!E117 -> 1121.6067 | D19: =PL!E111 -> 443.37881 | E19: =PL!E125 -> 0.37209897 | F19: =PL!E134 -> 60.714885 | G19: =F19/F$4-1 -> 0 | H19: =PL!F117 -> 1196.7833 | I19: =PL!F111 -> 482.75797 | J19: =PL!F125 -> 0.37274479 | K19: =PL!F134 -> 65.547635 | L19: =K19/K$4-1 -> -0.15022495
A20: 顆數情境 C | B20: CY2028–29 ×0.6 | C20: =PL!E156 -> 1121.6067 | D20: =PL!E150 -> 443.37881 | E20: =PL!E164 -> 0.37209897 | F20: =PL!E173 -> 60.714885 | G20: =F20/F$4-1 -> 0 | H20: =PL!F156 -> 1027.0296 | I20: =PL!F150 -> 362.06848 | J20: =PL!F164 -> 0.36867758 | K20: =PL!F173 -> 50.435288 | L20: =K20/K$4-1 -> -0.34614498
A22: 讀法：FY2027 三情境相同；顆數情境 B、C 的差異從 FY2028 起。每個案例的 FY2026 有效份額與液冷每 GW 依該案例重算，所以 FY2026 恆等於錨點。「電源內容」案例的 FY2026 份額會反向調整（內容低 → 份額高），所以只影響 FY2027 起的成長路徑。
A40: 案例區塊：份額流失（低）（情境 A）
A41: 項目 | B41: 單位 | C41: FY2025A | D41: FY2026（錨點） | E41: FY2027 | F41: FY2028 | G41: FY2029 | H41: 說明
A42: A. AI 部署與電源市場（D 欄＝FY2026 校準年；E–G＝FY2027–FY2029）
A43: AI IT 資本支出 × 情境顆數係數 | B43: US$B | D43: =itc_26*1 -> 781.87292 | E43: =itc_27*1*1 -> 1565.35 | F43: =itc_28*um28_A*1 -> 1984.2639 | G43: =itc_29*um29_A*1 -> 2260.3903
A44: 每 GW IT 資本支出 | B44: US$B | D44: =itpg_gb*(1-vr26)+itpg_vr*vr26 -> 33.414032 | E44: =itpg_vr -> 37.586352 | F44: =itpg_vr -> 37.586352 | G44: =itpg_vr -> 37.586352
A45: 部署 GW（IT 電力） | B45: GW | D45: =D43/D44 -> 23.399538 | E45: =E43/E44 -> 41.646766 | F45: =F43/F44 -> 52.792138 | G45: =G43/G44 -> 60.138592
A46: AI 電源內容 | B46: US$/kW | D46: =pkw_26 -> 450 | E46: =pkw_27 -> 600 | F46: =pkw_28 -> 680 | G46: =pkw_29 -> 720
A47: AI 電源市場（美元） | B47: US$B | D47: =D45*D46/1000 -> 10.529792 | E47: =E45*E46/1000 -> 24.988059 | F47: =F45*F46/1000 -> 35.898654 | G47: =G45*G46/1000 -> 43.299786
A48: AI 電源市場（新台幣） | B48: NT$B | D48: =D47*fx -> 336.95335 | E48: =E47*fx -> 799.6179 | F48: =F47*fx -> 1148.7569 | G48: =G47*fx -> 1385.5932
A49: 台達電有效份額（FY2026 校準）＝ AI 電源營收 ÷ 市場 | B49: % | D49: =a26_aip/D48 -> 0.58367194 | H49: Derived：分子為公司 AI 相關占比 × 營收；分母為本模型的 AI 電源市場（含 ASIC 機架）
A50: 份額相對值（÷ FY2026） | B50: x | D50: =1 -> 1 | E50: =RLO_27 -> 0.85 | F50: =RLO_28 -> 0.7 | G50: =RLO_29 -> 0.65
A51: 台達電有效份額 | B51: % | D51: =$D$49*D50 -> 0.58367194 | E51: =$D$49*E50 -> 0.49612115 | F51: =$D$49*F50 -> 0.40857036 | G51: =$D$49*G50 -> 0.37938676
A52: AI 電源營收 | B52: NT$B | C52: =a25_aip -> 99.8793 | D52: =D48*D51 -> 196.67021 | E52: =E48*E51 -> 396.70735 | F52: =F48*F51 -> 469.34803 | G52: =G48*G51 -> 525.6757
A53: B. 液冷、非 AI 與合計
A54: 液冷每 GW 營收（FY2026 校準） | B54: NT$B/GW | D54: =a26_lc/D45 -> 4.0408057
A55: 液冷每 GW 相對值（÷ FY2026） | B55: x | D55: =1 -> 1 | E55: =lcr_27 -> 1.1 | F55: =lcr_28 -> 1.15 | G55: =lcr_29 -> 1.2
A56: 液冷營收 | B56: NT$B | C56: =a25_lc -> 55.4885 | D56: =D45*$D$54*D55 -> 94.552988 | E56: =E45*$D$54*E55 -> 185.11514 | F56: =F45*$D$54*F55 -> 245.32119 | G56: =G45*$D$54*G55 -> 291.61004
A57: 非 AI 營收 | B57: NT$B | C57: =a25_nai -> 399.5172 | D57: =a26_nai -> 465.2007 | E57: =D57*(1+g_nai27) -> 493.11274 | F57: =E57*(1+g_nai28) -> 517.76838 | G57: =F57*(1+g_nai29) -> 538.47911
A58: 營收 | B58: NT$B | C58: =C52+C56+C57 -> 554.885 | D58: =D52+D56+D57 -> 756.4239 | E58: =E52+E56+E57 -> 1074.9352 | F58: =F52+F56+F57 -> 1232.4376 | G58: =G52+G56+G57 -> 1355.7649
A59: 營收年增 | B59: % | D59: =D58/C58-1 -> 0.36320841 | E59: =E58/D58-1 -> 0.42107518 | F59: =F58/E58-1 -> 0.14652266 | G59: =G58/F58-1 -> 0.10006775
...

Sheet Sources
A1: 來源（公司原文＝台達電法說簡報與逐字稿，已逐份抓取；券商與研調皆為 Interested-party）
A2: 公司：4Q25 法說簡報（FY2025 損益、部門營收與利益） | B2: https://filecenter.deltaww.com/ir/download/calendar/4Q25_Analyst Meeting.pdf
A3: 公司：2Q26 法說逐字稿（1H26 損益、AI 占比、液冷占比、800V 時程、資本支出、零組件短缺） | B3: https://filecenter.deltaww.com/IR/download/calendar/2Q26_Transcript.pdf
A4: 二手：BigGo 2Q26 法說摘要（AI 相關朝 28%；對手名單） | B4: https://finance.biggo.com/news/TW_2308.TW_2026-07-30
A5: 二手：數位時代 2026-02-26（2025 部門營收比重 50／33／10／7） | B5: https://www.bnext.com.tw/article/90178/2026-delta-earnings-call
A6: 二手：TechNews 2026-10-12（3Q26 營收、AI 相關 2025 年 18%、UBS AI 伺服器電源市場） | B6: https://finance.technews.tw/2026/10/12/delta-electronics-q3-revenue-nears-200-billion-record-high-q4-double-digit-growth
A7: 券商：凱基 Power supply sector 2025-07-01（每架 PSU 內容、Blackwell 份額約 70%） | B7: https://www.kgi.com.hk/en/-/media/files/kgishk/research-reports/tw-reports/power-supply-industry_01072025.pdf
A8: 券商：旺得富 2026-10-01（本土投顧 EPS、4Q26 估計、HVDC 占 2027 營收 5–10%、18kW 與 HVDC 毛利率約 50%） | B8: https://wantrich.chinatimes.com/news/20261001900208-420101
A9: 券商：CMoney 2026-05-04（美系 EPS 2026–28） | B9: https://www.cmoney.tw/notes/note-detail.aspx?nid=1180676
A10: 券商：Yahoo 新聞 2026-10-12（投顧 2027 營收 1.05 兆、EPS 62.68；Vicor 337 調查） | B10: https://tw.news.yahoo.com/%E5%8F%B0%E9%81%94%E9%9B%BBq3%E7%87%9F%E6%94%B6%E5%89%B5%E6%96%B0%E9%AB%98-337%E8%AA%BF%E6%9F%A5%E8%A1%9D%E6%93%8A-%E6%B3%95%E4%BA%BA%E9%80%99%E6%A8%A3%E7%9C%8B-035400801.html
A11: 研調：Morgan Stanley NVL72 冷卻 BOM（經 Tom's Hardware 2025-11-05） | B11: https://finance.yahoo.com/news/cooling-system-single-nvidia-blackwell-154500100.html
A12: 資料商：Yahoo 股市（10-23 收盤）、Goodinfo（10-22 收盤、近 12 月 P/E） | B12: https://tw.stock.yahoo.com/quote/2308.TW
A13: 資料商：companiesmarketcap 年底 P/E | B13: https://companiesmarketcap.com/delta-electronics/pe-ratio/
A14: 市場層：markets/network、markets/chip_bridge、tsmc 成品（本 repo，唯讀）
A15: 待補（人工）：3Q26 法說（10 月底）；部門季度損益；AI 電源與液冷的季度金額；P/E 第二來源；前瞻 P/E 十年歷史（Bloomberg）；券商共識（付費） | B15: 未找到
A16: SemiAnalysis | B16: 未使用
