Workbook

Sheet README
A1: 金像電（2368.TW）收支與估值模型 v0.1.1（AI 半導體 Project：載板與 PCB 次產業；伺服器與交換器 PCB、高層數板） 2026-10-25
A2: 版本：v0.1.1（2026-10-25：補上檔空間級距、投資建議、重點觀察，數值不變）。前版：v0.1（初版）。每 GW AI 高速 PCB 金額沿用勝宏模型（victory_giant/dist Units 頁，本專案權威，口徑一致），本模型只加金像電對中板／背板的參與係數；金像電份額與產值產能在本模型 Units 頁建立；Recon 頁對照勝宏模型與台光電每 GW CCL 金額。
A3: 模型命題：金像電的 AI 營收＝部署 GW（AI IT 資本支出 ÷ 每 GW IT 資本支出）× 每 GW 可參與 AI 高速 PCB 金額（勝宏模型三項，中板／背板 × 參與係數）× 金像電份額 × 價格指數，但受產值產能（FY2026 營收 × 擴產指數）限制（全產全銷）。非 AI（一般伺服器、網通、筆電）另設成長率。
A4: 核心問題：2026 年約 190 億元資本支出（台灣、蘇州、泰國二廠 2027 下半年開出）能讓產能在 2027–29 年擴大多少；ASIC 主板改 HDI＋HLC 混壓後份額守不守得住；現價約 20 倍前瞻 P/E 隱含什麼路徑。
A6: 會計年度＝日曆年，FY(t)＝CY(t)，不平移。預測期 FY2027–FY2029 由驅動因子推導，FY2030–FY2032 為收斂法。金額：十億新台幣；每 GW 金額以美元計、以匯率 32.0 換算。口徑：歸屬母公司淨利（IFRS）。
A8: 驅動因子 → 推導量（全部唯讀上游，不修改）
A9: 需求面：markets/network 的 AI IT 資本支出 × 同字母顆數係數（tsmc；＝markets/memory SCEN_UNITS）÷ 每 GW IT 資本支出（Tokenomics，經橋接表）＝部署 GW；× 每 GW PCB 金額（勝宏模型，US$450M → 682M）× 匯率 × 有效份額（FY2026 以錨點 AI 營收校準）× 份額相對值 × 價格指數（Assumed）。
A10: 產能面：FY2026 營收（產能吃緊、滿載）× 產值產能指數（2027 1.45、2028 1.90、2029 2.30；Assumed，依 2026 年約 190 億元資本支出與各廠時程）× 價格指數。AI 相關營收＝MIN（需求面、產能上限 − 非 AI）。
A11: 毛利率：AI 相關比其他營收高 d_ai 10pt（Assumed），其他毛利率為 FY2026 殘差（Derived）；價格指數變動全部落在 AI 毛利；另加新廠爬坡完成的額外改善（Assumed）。營業費用：彈性 phi 0.6（Assumed）。淨利 ÷ 稅前 0.685（1Q26 實績）。
A12: 校準：FY2026 ＝ 1H26 財報＋3Q26 月營收實績（297.19 億）＋假設（3Q、4Q 毛利率 35%、營業費用率 8%、4Q 季增 8%）。3Q26 財報與法說預計 2026-11 上旬，截至 2026-10-25 尚未公布。不用券商數字（只在 Recon 對帳）。
A13: 估值：Val 第 0 節目標價＝0.5 × DCF 目標價（股東現金流＝EPS ×（1 − g／ROE），FY2027–32 明確期＋永續，r 10%、g 4%，三情境權重 0.3／0.5／0.2，負值取 0）＋0.5 × Comparable 目標價（臺美同業健鼎、華通、臻鼎-KY、博智、TTM 前瞻 P/E 中位數 × 12 個月後前瞻 EPS；不放 A 股）；另列 Comparable 單獨目標價、市場共識目標價與差距拆解。十年 P/E 規則值 × FY2027 EPS 保留為參考（不是目標價）。本版未做先驗，無 Andy 合理 P/E 對照。
A14: 預估期間：FY2027–FY2029 由驅動因子推導；FY2030 起為收斂法，非驅動因子推導（營收年增由 FY2029 線性收斂到 fade_g、淨利率收斂到 fade_m，FY2032 達到；PL 頁灰底）。十年平均淨利率未找到（2016–2020 營收與淨利缺），依工作單以情境 C FY2029 淨利率 × 0.8 替代（Assumed）。
... A19: v0.1.1：補上檔空間級距、投資建議、重點觀察（數值不變）。Val 頁最後新增「上檔空間級距」「投資建議」兩列（第 118、119 列，依「上檔空間：加權目標價」的固定規則）；重點觀察見下方三列。
A20: ="投資建議："&Val!B119&"（依上檔空間固定規則）" -> 投資建議：強力買進（依上檔空間固定規則）
A21: ="重點觀察 1：目標價 NT$"&TEXT(Val!$B$40,"0.00")&"（DCF "&TEXT(Val!$B$24,"0.00")&"、Comparable（相對倍數調整後）"&TEXT(tp_comp_adj,"0.00")&"；DCF 權重 "&TEXT(tp_w_dcf,"0%")&"），比現價 "&TEXT(px,"0.00")&"（2026-10-22）"&IF(Val!$B$43>=0,"高 "&TEXT(Val!$B$43,"0.0%"),"低 "&TEXT(-Val!$B$43,"0.0%"))&"，級距 "&Val!$B$118&"、投資建議 "&Val!$B$119&"。相對倍數調整係數 "&TEXT(rm_factor,"0.00")&"（本公司 10 年前瞻倍數中位數 ÷ 同業的中位數，夾在 0.5–2.0；Val 第 0.5 節），調整前加權上檔空間 "&TEXT((tp_w_dcf*Val!$B$24+(1-tp_w_dcf)*Val!$B$36)/px-1,"+0.0%;−0.0%")&"；Comparable 單獨（市場主流同業法、未調整）為 "&TEXT(Val!$B$44,"+0.0%;−0.0%")&"。"&"以下為 2026-10-29 相對倍數調整前撰寫的說明，其中數字為調整前：兩法接近；與共識目標價 1,554 的差距在倍數：本模型前瞻 EPS 72.00 比共識前瞻 EPS 56.97 高 26.4%（期間約晚一年），但同業（健鼎、華通、臻鼎-KY、博智、TTM）前瞻 P/E 中位數只有 18.5 倍，共識目標價隱含 27.3 倍。" -> 重點觀察 1：目標價 NT$1724.02（DCF 1203.07、Comparable（相對倍數調整後）2244.96；DCF 權重 50%），比現價 1115.00（2026-10-22）高 54.6%，級距 大於 50%、投資建議 強力買進。相對倍數調整係數 1.69（本公司 10 年前瞻倍數中位數 ÷ 同業的中位數，夾在 0.5–2.0；Val 第 0.5 節），調整前加權上檔空間 +13.7%；Comparable 單獨（市場主流同業法、未調整）為 +19.4%。以下為 2026-10-29 相對倍數調整前撰寫的說明，其中數字為調整前：兩法接近；與共識目標價 1,554 的差距在倍數：本模型前瞻 EPS 72.00 比共識前瞻 EPS 56.97 高 26.4%（期間約晚一年），但同業（健鼎、華通、臻鼎-KY、博智、TTM）前瞻 P/E 中位數只有 18.5 倍，共識目標價隱含 27.3 倍。
A22: 重點觀察 2：擴產進度最敏感：擴產延遲（2028 年產能指數 1.60）使 FY2028 EPS −18.3%、價格回落快 −13.5%、份額流失 −10.7%；情境 C 的 FY2028 EPS 45.31 比情境 B 76.56 低 40.8%，DCF 價格帶 559～1,723。
A23: 重點觀察 3：本模型情境 B 的 FY2027 EPS 60.15 比共識 62.80 低 4.2%、FY2028 EPS 76.56 比共識 95.35 低 19.7%。下一個檢驗點是 3Q26 財報與法說（預計 2026-11 上旬，stockanalysis 估 11-11）與 10 月營收（11-10 前後）。
A25: 2026-10-29：加權目標價中的 Comparable 改用相對倍數調整後的值（Val 第 0.5 節：同業前瞻倍數中位數 × 本公司 10 年相對同業的倍數比，Bloomberg 前瞻倍數；Andy 2026-10-27「照建議做」、10-29 資料取回）。「Comparable 目標價（市場主流同業法）」維持不調整。重點觀察 1 的第一句已改為公式；重點觀察 2、3 與其他說明中的目標價與上檔空間數字為調整前撰寫，以 Val 頁為準。
A27: 2026-10-31：依個股模型原則第 8 節第 3 點，主模型的情境 A／C 改讀 In 頁「情境專屬列」一節（由原敏感度高／低欄拆出、數值不變）；敏感度低／高欄只留給 Sens 頁。
A29: v0.2.1（2026-10-30）：依個股模型原則第 8 節調整 In 頁呈現（數值不變）。In 頁 D／F 欄名改「敏感度低」「敏感度高」（只用於 Sens 頁、不進目標價）；In 頁最後新增「情境驅動對照」一節，把上方各情境專屬輸入三情境並排（只引用上方各列，純展示）；HTML 驅動因子一節分「情境驅動」與「單一參數」兩張表。

Sheet In
A1: In — 輸入（藍字；基準欄 E，低 D、高 F）。金額：十億新台幣（NT$B），每 GW PCB 金額為百萬美元；比例：%。每個輸入附兩個來源（找不到者寫「未找到」）；公司原文算一個。【v0.2.1】基準欄 E 進主模型；D／F＝敏感度低／高，只用於 Sens 頁（一次動一個參數）、不進目標價；情境 A／B／C 的驅動見本頁最後一節「情境驅動對照」。
A2: 標記：Verified／Interested-party／Analogy／Assumed／Derived；Analogy、Assumed 給低／高區間。SemiAnalysis 未使用。公司原文＝金像電財報（公開資訊觀測站）、月營收公告與法說會（經媒體轉述）；公司的訂單、產品組合與產能說法為 Interested-party；券商與媒體估計皆為 Interested-party
A3: 鍵 | B3: 項目 | C3: 單位 | D3: 敏感度低 | E3: 基準 | F3: 敏感度高 | G3: 標記 | H3: 來源1 | I3: 來源2／說明
A4: A. AI 部署規模（讀 markets/network、markets/chip_bridge、tsmc 成品；情境 A 基準，B／C 依同字母顆數係數縮放）
A5: itc_26 | B5: AI IT 資本支出 2026 | C5: US$B | E5: 781.87292 | G5: Derived | H5: markets/network/dist/20261026_AI網通市場模型_v0.2.3.xlsx｜Mkt!C27:F27 | I5: 加速器顆數 × 每顆 IT capex（含 ASIC）；本模型以此除以每 GW IT 資本支出得到部署 GW（與勝宏、台光電模型相同）
A6: itc_27 | B6: AI IT 資本支出 2027 | C6: US$B | E6: 1565.35 | G6: Derived | H6: markets/network/dist/20261026_AI網通市場模型_v0.2.3.xlsx｜Mkt!C27:F27 | I6: 同上
A7: itc_28 | B7: AI IT 資本支出 2028 | C7: US$B | E7: 1984.2639 | G7: Derived | H7: markets/network/dist/20261026_AI網通市場模型_v0.2.3.xlsx｜Mkt!C27:F27 | I7: 同上
A8: itc_29 | B8: AI IT 資本支出 2029 | C8: US$B | E8: 2260.3903 | G8: Derived | H8: markets/network/dist/20261026_AI網通市場模型_v0.2.3.xlsx｜Mkt!C27:F27 | I8: 同上
A9: itpg_gb | B9: 每 GW IT 資本支出（GB300） | C9: US$B | E9: 32.237224 | G9: Derived | H9: markets/chip_bridge/dist/20261027_晶片內容橋接表_v0.2.2.xlsx｜In!E10（GB300）、H10（VR200） | I9: Tokenomics IF_CapexIT（經橋接表；唯讀）
A10: itpg_vr | B10: 每 GW IT 資本支出（VR200；2027 起） | C10: US$B | E10: 37.586352 | G10: Derived | H10: markets/chip_bridge/dist/20261027_晶片內容橋接表_v0.2.2.xlsx｜In!E10（GB300）、H10（VR200） | I10: 同上；Rubin Ultra 與 ASIC 機架未另訂（Assumed：同 VR200）
A11: vr26 | B11: 2026 年部署中 Rubin 世代占比（混合每 GW IT 資本支出用） | C11: % | D11: 0.15 | E11: 0.22 | F11: 0.3 | G11: Interested-party | H11: TrendForce 2026 組合 Rubin 22%（經 markets/memory；與勝宏、台光電模型相同） | I11: —
A12: racks_gb | B12: 每 GW 機架數（GB300） | C12: 架 | E12: 6764 | G12: Derived | H12: markets/chip_bridge/dist/20261027_晶片內容橋接表_v0.2.2.xlsx｜In!E6（GB300）、H6（VR200） | I12: Recon 用
A13: racks_vr | B13: 每 GW 機架數（VR200） | C13: 架 | E13: 4052 | G13: Derived | H13: markets/chip_bridge/dist/20261027_晶片內容橋接表_v0.2.2.xlsx｜In!E6（GB300）、H6（VR200） | I13: Units 頁每架等值金額用
A14: um28_A | B14: 情境 A：2028 顆數 ÷ 基準 | C14: x | E14: 1 | G14: Assumed | H14: tsmc/dist/20261030_台積電個股模型_v0.4.1.xlsx｜In!E37 | I14: A＝順利（基準）；B＝平平；C＝不如預期；與台積電、勝宏模型相同（＝markets/memory SCEN_UNITS，建置時核對）
A15: um29_A | B15: 情境 A：2029 顆數 ÷ 基準 | C15: x | E15: 1 | G15: Assumed | H15: tsmc/dist/20261030_台積電個股模型_v0.4.1.xlsx｜In!E38 | I15: 同上
A16: um28_B | B16: 情境 B：2028 顆數 ÷ 基準 | C16: x | E16: 0.8 | G16: Assumed | H16: tsmc/dist/20261030_台積電個股模型_v0.4.1.xlsx｜In!E39 | I16: A＝順利（基準）；B＝平平；C＝不如預期；與台積電、勝宏模型相同（＝markets/memory SCEN_UNITS，建置時核對）
A17: um29_B | B17: 情境 B：2029 顆數 ÷ 基準 | C17: x | E17: 0.85 | G17: Assumed | H17: tsmc/dist/20261030_台積電個股模型_v0.4.1.xlsx｜In!E40 | I17: 同上
A18: um28_C | B18: 情境 C：2028 顆數 ÷ 基準 | C18: x | E18: 0.6 | G18: Assumed | H18: tsmc/dist/20261030_台積電個股模型_v0.4.1.xlsx｜In!E41 | I18: A＝順利（基準）；B＝平平；C＝不如預期；與台積電、勝宏模型相同（＝markets/memory SCEN_UNITS，建置時核對）
A19: um29_C | B19: 情境 C：2029 顆數 ÷ 基準 | C19: x | E19: 0.6 | G19: Assumed | H19: tsmc/dist/20261030_台積電個股模型_v0.4.1.xlsx｜In!E42 | I19: 同上
A20: fx | B20: 匯率（新台幣 ÷ 美元） | C20: NT$/US$ | D20: 30.5 | E20: 32 | F20: 33 | G20: Derived | H20: 與台光電、台達電、廣達模型相同（emc/dist In 頁 fx＝32.0） | I20: 10-23 收盤：未找到
A21: B. 每 GW AI 高速 PCB 金額（口徑與勝宏一致：唯讀 victory_giant/dist Units 頁）與金像電份額
A22: vg_cmp26 | B22: 每 GW PCB：加速器卡／運算板（GPU／ASIC 模組、運算匣主板） 2026（勝宏模型） | C22: US$M/GW | E22: 280 | G22: Derived | H22: victory_giant/dist/20261031_勝宏科技個股模型_v0.2.xlsx｜Units!C5:F5 | I22: 唯讀勝宏模型成品（本專案每 GW PCB 金額權威；2026 Assumed、之後 × 世代指數 Analogy／Assumed）
A23: vg_cmp27 | B23: 每 GW PCB：加速器卡／運算板（GPU／ASIC 模組、運算匣主板） 2027（勝宏模型） | C23: US$M/GW | E23: 420 | G23: Derived | H23: victory_giant/dist/20261031_勝宏科技個股模型_v0.2.xlsx｜Units!C5:F5 | I23: 同上
A24: vg_cmp28 | B24: 每 GW PCB：加速器卡／運算板（GPU／ASIC 模組、運算匣主板） 2028（勝宏模型） | C24: US$M/GW | E24: 462 | G24: Derived | H24: victory_giant/dist/20261031_勝宏科技個股模型_v0.2.xlsx｜Units!C5:F5 | I24: 同上
A25: vg_cmp29 | B25: 每 GW PCB：加速器卡／運算板（GPU／ASIC 模組、運算匣主板） 2029（勝宏模型） | C25: US$M/GW | E25: 504 | G25: Derived | H25: victory_giant/dist/20261031_勝宏科技個股模型_v0.2.xlsx｜Units!C5:F5 | I25: 同上
A26: vg_sw26 | B26: 每 GW PCB：交換器板（NVLink 交換匣＋scale-out 800G／1.6T 交換器） 2026（勝宏模型） | C26: US$M/GW | E26: 120 | G26: Derived | H26: victory_giant/dist/20261031_勝宏科技個股模型_v0.2.xlsx｜Units!C6:F6 | I26: 唯讀勝宏模型成品（本專案每 GW PCB 金額權威；2026 Assumed、之後 × 世代指數 Analogy／Assumed）
A27: vg_sw27 | B27: 每 GW PCB：交換器板（NVLink 交換匣＋scale-out 800G／1.6T 交換器） 2027（勝宏模型） | C27: US$M/GW | E27: 162 | G27: Derived | H27: victory_giant/dist/20261031_勝宏科技個股模型_v0.2.xlsx｜Units!C6:F6 | I27: 同上
A28: vg_sw28 | B28: 每 GW PCB：交換器板（NVLink 交換匣＋scale-out 800G／1.6T 交換器） 2028（勝宏模型） | C28: US$M/GW | E28: 180 | G28: Derived | H28: victory_giant/dist/20261031_勝宏科技個股模型_v0.2.xlsx｜Units!C6:F6 | I28: 同上
A29: vg_sw29 | B29: 每 GW PCB：交換器板（NVLink 交換匣＋scale-out 800G／1.6T 交換器） 2029（勝宏模型） | C29: US$M/GW | E29: 198 | G29: Derived | H29: victory_giant/dist/20261031_勝宏科技個股模型_v0.2.xlsx｜Units!C6:F6 | I29: 同上
A30: vg_mid26 | B30: 每 GW PCB：中板／正交背板／CPX 與其他 2026（勝宏模型） | C30: US$M/GW | E30: 50 | G30: Derived | H30: victory_giant/dist/20261031_勝宏科技個股模型_v0.2.xlsx｜Units!C7:F7 | I30: 唯讀勝宏模型成品（本專案每 GW PCB 金額權威；2026 Assumed、之後 × 世代指數 Analogy／Assumed）
A31: vg_mid27 | B31: 每 GW PCB：中板／正交背板／CPX 與其他 2027（勝宏模型） | C31: US$M/GW | E31: 100 | G31: Derived | H31: victory_giant/dist/20261031_勝宏科技個股模型_v0.2.xlsx｜Units!C7:F7 | I31: 同上
A32: vg_mid28 | B32: 每 GW PCB：中板／正交背板／CPX 與其他 2028（勝宏模型） | C32: US$M/GW | E32: 150 | G32: Derived | H32: victory_giant/dist/20261031_勝宏科技個股模型_v0.2.xlsx｜Units!C7:F7 | I32: 同上
A33: vg_mid29 | B33: 每 GW PCB：中板／正交背板／CPX 與其他 2029（勝宏模型） | C33: US$M/GW | E33: 175 | G33: Derived | H33: victory_giant/dist/20261031_勝宏科技個股模型_v0.2.xlsx｜Units!C7:F7 | I33: 同上
A34: w_mid | B34: 金像電對中板／背板／其他的參與係數（1＝與加速器卡、交換器板相同） | C34: x | D34: 0 | E34: 0.5 | F34: 1 | G34: Assumed | H34: 金像電以 ASIC 伺服器主板（Trainium、TPU）與 800G 交換器板為主（優分析 2026-09-09；Interested-party）；NVIDIA VR200 中板、Kyber 正交背板的參與度：未找到 | I34: 低＝不參與、高＝與其他兩項相同
A35: pgwf | B35: 每 GW 金額成長倍率（套在勝宏模型 2027–29 每 GW 金額相對 2026 的增量上；Sens 用） | C35: x | D35: 0.7 | E35: 1 | F35: 1.3 | G35: Assumed | H35: 勝宏模型的世代升級主要來自 NVIDIA VR200 中板與 CPX、Kyber 背板；ASIC 主板改 HDI＋HLC 混壓也提高每 GW 金額（優分析 2026-09-09） | I35: 基準＝與勝宏模型相同
A36: rel_27 | B36: 金像電份額 2027 ÷ 2026（相對值；情境 A 取高、B 基準、C 取低） | C36: x | D36: 0.85 | E36: 1 | F36: 1.08 | G36: Assumed | H36: 風險：ASIC 主板設計由高層數（HLC）轉 HDI＋HLC 混壓（Trainium4、TPU 新世代），2026-06 股價修正逾五成；公司以 3–4 階 HDI 混壓因應（優分析 2026-09-09，Interested-party） | I36: 利多：另一家美國雲端業者 ASIC 主板訂單、Amazon 私募入股（2026-09-29）；對手健鼎、TTM、勝宏、沪电擴產
A37: rel_28 | B37: 金像電份額 2028 ÷ 2026（相對值；情境 A 取高、B 基準、C 取低） | C37: x | D37: 0.75 | E37: 0.95 | F37: 1.08 | G37: Assumed | H37: 同上 | I37: —
A38: rel_29 | B38: 金像電份額 2029 ÷ 2026（相對值；情境 A 取高、B 基準、C 取低） | C38: x | D38: 0.7 | E38: 0.9 | F38: 1.05 | G38: Assumed | H38: 同上 | I38: —
A39: pp_27 | B39: PCB 價格指數 2027（2026＝1；同規格降價或漲價，不含世代升級；情境 A 取高、C 取低） | C39: x | D39: 0.96 | E39: 1 | F39: 1.03 | G39: Assumed | H39: 分析師：3Q26 成長動能含價格改善、產能吃緊（優分析 2026-09-09，Interested-party） | I39: 新產能（中壢、蘇州二廠、泰國二廠）2027 年下半年起開出後價格回落（Assumed）
A40: pp_28 | B40: PCB 價格指數 2028（2026＝1；同規格降價或漲價，不含世代升級；情境 A 取高、C 取低） | C40: x | D40: 0.92 | E40: 0.97 | F40: 1.02 | G40: Assumed | H40: 同上 | I40: —
...

Sheet Q
A1: Q — 實績與 FY2026 錨點（十億新台幣；EPS 為新台幣；股數為十億股）。藍字＝輸入；黑字＝公式。實績取自金像電財報與月營收公告（經 stockanalysis、優分析、technews 轉述）
A2: FY2026 錨點＝1H26 財報＋3Q26 月營收實績（7–9 月）＋假設（3Q 毛利率、營業費用率、營業外；4Q 營收季增）。1H26 毛利與營業利益＝1Q26（stockanalysis）＋2Q26（營收 × 毛利率 34.65%、營業利益率 26.43%）；1H26 稅前＝1Q26 稅前＋2Q26 淨利 ÷ q_nir（Derived）。3Q26 財報與法說預計 2026-11 上旬（stockanalysis 估 11-11；截至 2026-10-25 尚未公布），公布後更新
A3: 項目 | B3: FY2025A | C3: 1H26（實績） | D3: 3Q26（營收實績） | E3: 4Q26（模型） | F3: FY2026 錨點 | G3: 標記 | H3: 來源1 | I3: 來源2／說明
A4: 營收 | B4: 60.004 | C4: 43.592 | D4: =q3_rev -> 29.719 | E4: =D4*(1+q4g) -> 32.09652 | F4: =SUM(C4:E4) -> 105.40752 | G4: Verified／Assumed（4Q 季增） | H4: FY2025：stockanalysis 年度損益（營收 600.04 億、毛利 196.83 億、營業利益 140.43 億、淨利 96.07 億）；1H26：優分析 2026-08-11（營收 435.92 億、毛利率 34.72%、淨利 82.67 億、EPS 16.14） | I4: 3Q26＝7–9 月月營收合計（technews、優分析）；月營收與財報營收口徑可能略有差異
A5: 毛利 | B5: 19.683 | C5: =6.722+24.279*0.3465 -> 15.134673 | D5: =D4*q_gm -> 10.40165 | E5: =E4*q_gm -> 11.233782 | F5: =SUM(C5:E5) -> 36.770105 | G5: Verified／Assumed | H5: FY2025：stockanalysis 年度損益（營收 600.04 億、毛利 196.83 億、營業利益 140.43 億、淨利 96.07 億）；1H26：優分析 2026-08-11（營收 435.92 億、毛利率 34.72%、淨利 82.67 億、EPS 16.14） | I5: 2Q26 毛利率 34.65%（優分析）；1Q26 毛利 67.22 億（stockanalysis）
A6: 毛利率 | B6: =B5/B4 -> 0.32802813 | C6: =C5/C4 -> 0.34718924 | D6: =D5/D4 -> 0.35 | E6: =E5/E4 -> 0.35 | F6: =F5/F4 -> 0.34883759 | G6: Derived | H6: — | I6: 1H26 34.72%（優分析）；FY2025 32.8%
A7: 營業費用 | B7: =B5-B8 -> 5.64 | C7: =C5-C8 -> 3.5327338 | D7: =D4*q_opx -> 2.37752 | E7: =E4*q_opx -> 2.5677216 | F7: =SUM(C7:E7) -> 8.4779754 | G7: Derived／Assumed | H7: FY2025：stockanalysis 年度損益（營收 600.04 億、毛利 196.83 億、營業利益 140.43 億、淨利 96.07 億）；1H26：優分析 2026-08-11（營收 435.92 億、毛利率 34.72%、淨利 82.67 億、EPS 16.14） | I7: 毛利 − 營業利益
A8: 營業利益（毛利 − 營業費用） | B8: 14.043 | C8: =5.185+24.279*0.2643 -> 11.60194 | D8: =D5-D7 -> 8.02413 | E8: =E5-E7 -> 8.6660604 | F8: =SUM(C8:E8) -> 28.29213 | G8: Interested-party（stockanalysis）／Derived | H8: FY2025：stockanalysis 年度損益（營收 600.04 億、毛利 196.83 億、營業利益 140.43 億、淨利 96.07 億）；1H26：優分析 2026-08-11（營收 435.92 億、毛利率 34.72%、淨利 82.67 億、EPS 16.14） | I8: 1Q26 營業利益 51.85 億（stockanalysis）；2Q26 營業利益率 26.43%（理財周刊 2026-10-14）
A9: 營業利益率 | B9: =B8/B4 -> 0.2340344 | C9: =C8/C4 -> 0.26614837 | D9: =D8/D4 -> 0.27 | E9: =E8/E4 -> 0.27 | F9: =F8/F4 -> 0.26840713 | G9: Derived | H9: — | I9: —
A10: 營業外淨額 | B10: =B11-B8 -> 0.1299448 | C10: =C11-C8 -> 0.4688394 | D10: =q_nop -> 0 | E10: =q_nop -> 0 | F10: =SUM(C10:E10) -> 0.4688394 | G10: Derived／Assumed | H10: 稅前 − 營業利益 | I10: —
A11: 稅前利益 | B11: =60.004*0.2362 -> 14.172945 | C11: =19.313*0.2634+4.783/q_nir -> 12.070779 | D11: =D8+D10 -> 8.02413 | E11: =E8+E10 -> 8.6660604 | F11: =SUM(C11:E11) -> 28.76097 | G11: Derived | H11: FY2025＝營收 × 稅前淨利率 23.62%（stockanalysis）；1H26＝1Q26 營收 × 26.34%＋2Q26 淨利 47.83 億 ÷ q_nir | I11: 2Q26 稅前：未找到
A12: 歸屬母公司淨利 | B12: 9.607 | C12: 8.267 | D12: =D11*q_nir -> 5.4955428 | E12: =E11*q_nir -> 5.9351862 | F12: =SUM(C12:E12) -> 19.697729 | G12: Verified／Derived（3Q、4Q） | H12: FY2025：stockanalysis 年度損益（營收 600.04 億、毛利 196.83 億、營業利益 140.43 億、淨利 96.07 億）；1H26：優分析 2026-08-11（營收 435.92 億、毛利率 34.72%、淨利 82.67 億、EPS 16.14） | I12: FY2025 96.07 億（年增 71%）；1H26 82.67 億（2Q26 47.83 億）
A13: 淨利 ÷ 營業利益 | B13: =B12/B8 -> 0.68411308 | C13: =C12/C8 -> 0.71255326 | D13: =D12/D8 -> 0.68487708 | E13: =E12/E8 -> 0.68487708 | F13: =F12/F8 -> 0.69622644 | G13: Derived | H13: — | I13: —
A14: 股數（十億股；加權） | B14: =9.607/19.47 -> 0.49342578 | C14: =sh_1h -> 0.5122057 | D14: =sh_h2 -> 0.513756 | E14: =sh_h2 -> 0.513756 | F14: =(sh_1h+sh_h2)/2 -> 0.51298085 | G14: Derived | H14: FY2025：stockanalysis 年度損益（營收 600.04 億、毛利 196.83 億、營業利益 140.43 億、淨利 96.07 億）；1H26：優分析 2026-08-11（營收 435.92 億、毛利率 34.72%、淨利 82.67 億、EPS 16.14） | I14: 淨利 ÷ EPS；FY2026＝上半年與下半年平均
A15: EPS | B15: =B12/B14 -> 19.47 | C15: =C12/C14 -> 16.14 | D15: =D12/D14 -> 10.696795 | E15: =E12/E14 -> 11.552539 | F15: =F12/F14 -> 38.398566 | G15: Derived | H15: 淨利 ÷ 股數 | I15: —
A16: 公司揭露 EPS | B16: 19.47 | C16: 16.14 | G16: Verified | H16: FY2025：stockanalysis 年度損益（營收 600.04 億、毛利 196.83 億、營業利益 140.43 億、淨利 96.07 億）；1H26：優分析 2026-08-11（營收 435.92 億、毛利率 34.72%、淨利 82.67 億、EPS 16.14） | I16: FY2025 19.47（stockanalysis 列 19.00，口徑未載明）；1H26 16.14
A17: AI 相關營收（FY2025＝營收 × AI 占比；FY2026＝營收 − 非 AI） | B17: =B4*ai_25 -> 18.0012 | F17: =F4-F18 -> 55.00416 | G17: Interested-party／Derived | H17: AI 占比（In 頁 D 節） | I17: 各季 AI 營收金額未揭露：未找到
A18: 非 AI 營收（FY2026＝FY2025 ×（1＋g_nai26）） | B18: =B4-B17 -> 42.0028 | F18: =B18*(1+g_nai26) -> 50.40336 | G18: Derived／Assumed | H18: — | I18: 一般伺服器、網通、筆電、其他
A23: FY2026 錨點的檢查（參考；校準未使用券商數字）
A24: FY2026 營收年增 | B24: =F4/B4-1 -> 0.75667489
A25: FY2026 AI 相關 ÷ 營收 | B25: =F17/F4 -> 0.52182387
A26: FY2026 營業費用 ÷ 營收 | B26: =F7/F4 -> 0.080430461
A27: FY2026 營收 ÷ 共識（MarketScreener）− 1 | B27: =F4/cons_rev26-1 -> -0.0090577319
A28: FY2026 EPS ÷ 共識（MarketScreener）− 1 | B28: =F15/cons_eps26-1 -> -0.068448185
A29: 4Q26 年化營收 ÷ FY2026 營收 | B29: =E4*4/F4 -> 1.2179973

Sheet Units
A1: Units — 每 GW AI 高速 PCB 金額（口徑與勝宏模型一致，唯讀 victory_giant/dist；本專案權威在勝宏模型）、金像電參與係數、份額與產能。部署 GW＝AI IT 資本支出（markets/network）÷ 每 GW IT 資本支出（Tokenomics，經橋接表）
A3: 項目 | B3: 單位 | C3: CY2026 | D3: CY2027 | E3: CY2028 | F3: CY2029 | G3: 說明
A4: 部署 GW（情境 B） | B4: GW | C4: =PL!D119 -> 23.399538 | D4: =PL!E119 -> 41.646766 | E4: =PL!F119 -> 42.233711 | F4: =PL!G119 -> 51.117803 | G4: AI IT 資本支出 × 顆數係數 B ÷ 每 GW IT 資本支出
A5: 勝宏模型：每 GW AI 高速 PCB 金額（合計） | B5: US$M/GW | C5: =vg_pgw26 -> 450 | D5: =vg_pgw27 -> 682 | E5: =vg_pgw28 -> 792 | F5: =vg_pgw29 -> 877 | G5: 唯讀 victory_giant/dist（口徑來源）
A6: 每 GW PCB：加速器卡／運算板 | B6: US$M/GW | C6: =PL!D120 -> 280 | D6: =PL!E120 -> 420 | E6: =PL!F120 -> 462 | F6: =PL!G120 -> 504 | G6: 勝宏模型值；成長倍率 pgwf＝1 時相同
A7: 每 GW PCB：交換器板 | B7: US$M/GW | C7: =PL!D121 -> 120 | D7: =PL!E121 -> 162 | E7: =PL!F121 -> 180 | F7: =PL!G121 -> 198 | G7: 同上
A8: 每 GW PCB：中板／背板／其他 × 參與係數 | B8: US$M/GW | C8: =PL!D122 -> 25 | D8: =PL!E122 -> 50 | E8: =PL!F122 -> 75 | F8: =PL!G122 -> 87.5 | G8: 參與係數 w_mid（Assumed）
A9: 每 GW 金像電可參與 AI 高速 PCB 金額（不含價格指數） | B9: US$M/GW | C9: =PL!D123 -> 425 | D9: =PL!E123 -> 632 | E9: =PL!F123 -> 717 | F9: =PL!G123 -> 789.5
A10: 每架等值可參與金額（以 VR200 每 GW 架數換算） | B10: US$K/架 | C10: =PL!D123*1000/racks_vr -> 104.88648 | D10: =PL!E123*1000/racks_vr -> 155.97236 | E10: =PL!F123*1000/racks_vr -> 176.94965 | F10: =PL!G123*1000/racks_vr -> 194.84205
A11: 每 GW 可參與 PCB 金額 ÷ 台光電模型每 GW CCL 金額 | B11: x | C11: =PL!D123/emc_ccl26 -> 1.2142857 | D11: =PL!E123/emc_ccl27 -> 1.1981043 | E11: =PL!F123/emc_ccl28 -> 1.1773399 | F11: =PL!G123/emc_ccl29 -> 1.1916981 | G11: 見 Recon B 節
A12: 可參與 AI 高速 PCB 市場（含價格指數） | B12: US$B | C12: =PL!D124*PL!D126 -> 9.9448037 | D12: =PL!E124*PL!E126 -> 26.320756 | E12: =PL!F124*PL!F126 -> 29.373123 | F12: =PL!G124*PL!G126 -> 37.936055 | G12: 含 ASIC 部署（假設每 GW 金額相同）
A13: 金像電有效份額 | B13: % | C13: =PL!D129 -> 0.17284202 | D13: =PL!E129 -> 0.17284202 | E13: =PL!F129 -> 0.16419992 | F13: =PL!G129 -> 0.15555782 | G13: FY2026 以錨點 AI 相關營收校準
A14: 金像電 AI 相關營收（需求面） | B14: US$B | C14: =PL!D130/fx -> 1.71888 | D14: =PL!E130/fx -> 4.5493328 | E14: =PL!F130/fx -> 4.8230646 | F14: =PL!G130/fx -> 5.9012501
A15: 金像電 AI 相關營收（實際＝MIN 需求面、產能） | B15: US$B | C15: =PL!D135/fx -> 1.71888 | D15: =PL!E135/fx -> 3.122418 | E15: =PL!F135/fx -> 4.3673383 | F15: =PL!G135/fx -> 5.3670152
A16: 每 GW 金像電 AI 相關營收 | B16: US$M/GW | C16: =PL!D149 -> 73.45786 | D16: =PL!E149 -> 74.973841 | E16: =PL!F149 -> 103.40882 | F16: =PL!G149 -> 104.99307 | G16: 對照勝宏、台光電（Recon）
A17: 平均產值產能指數（FY2026＝1） | B17: x | C17: =PL!D132 -> 1 | D17: =PL!E132 -> 1.45 | E17: =PL!F132 -> 1.9 | F17: =PL!G132 -> 2.3 | G17: 公司擴產計畫（Assumed）
A18: 產能上限營收（含價格指數） | B18: NT$B | C18: =PL!D133 -> 105.40752 | D18: =PL!E133 -> 152.8409 | E18: =PL!F133 -> 194.26606 | F18: =PL!G133 -> 227.89106 | G18: FY2026 校準
A19: 需求面 ÷ 產能上限 | B19: % | C19: =PL!D148 -> 1 | D19: =PL!E148 -> 1.2987503 | E19: =PL!F148 -> 1.0750684 | F19: =PL!G148 -> 1.0750162 | G19: 大於 100%＝產能受限
A20: 其他廠商（健鼎、TTM、勝宏、沪电、華通等）＝ 可參與市場 − 金像電 | B20: US$B | C20: =PL!D124*PL!D126-PL!D135/fx -> 8.2259237 | D20: =PL!E124*PL!E126-PL!E135/fx -> 23.198338 | E20: =PL!F124*PL!F126-PL!F135/fx -> 25.005785 | F20: =PL!G124*PL!G126-PL!G135/fx -> 32.56904 | G20: 產能受限時，未滿足需求計入其他廠商
A22: 讀法：每 GW 金額的絕對水準只影響 FY2026 校準出的份額（金額高 → 份額低），不影響營收；影響營收的是金額成長（勝宏模型世代指數 × pgwf）、參與係數與份額相對值。產能受限的年度，營收由產值產能指數決定；擴產趕上需求後，份額與每 GW 金額重新成為主要變數。

Sheet PL
A1: PL — 金像電損益（十億新台幣；EPS 新台幣；歸屬母公司）。FY2025A 實績、FY2026 錨點（1H26 財報＋3Q26 月營收＋假設），FY2027 起為模型。FY(t)＝CY(t)。三情境各一個完整推導區塊（本頁下方），頂端為摘要。顆數係數從 CY2028 開始；份額、價格、AI 毛利率改善從 FY2027 起依情境取高／基準／低值
A2: 灰底＝FY2030–FY2032 收斂法（上游只到 2029）：營收年增線性收斂到 fade_g、淨利率線性收斂到 fade_m（In 頁 J 節），非驅動因子推導
A3: 情境／項目 | B3: 單位 | C3: FY2025A | D3: FY2026（錨點） | E3: FY2027 | F3: FY2028 | G3: FY2029 | H3: FY2030（收斂） | I3: FY2031（收斂） | J3: FY2032（收斂） | K3: 說明
A4: 情境 A
A5: 營收 | B5: NT$B | C5: =C83 -> 60.004 | D5: =D83 -> 105.40752 | E5: =E83 -> 157.42613 | F5: =F83 -> 204.27977 | G5: =G83 -> 242.4373 | H5: =H83 -> 277.47603 | I5: =I83 -> 305.8517 | J5: =J83 -> 324.2028
A6: 營收年增 | B6: % | D6: =D84 -> 0.75667489 | E6: =E84 -> 0.4935 | F6: =F84 -> 0.29762303 | G6: =G84 -> 0.18679051 | H6: =H84 -> 0.144527 | I6: =I84 -> 0.1022635 | J6: =J84 -> 0.06
A7: AI 相關營收（AI 伺服器主板、800G 交換器） | B7: NT$B | C7: =C81 -> 18.0012 | D7: =D81 -> 55.00416 | E7: =E81 -> 104.5026 | F7: =F81 -> 149.76854 | G7: =G81 -> 186.29073
A8: 非 AI 營收 | B8: NT$B | C8: =C80 -> 42.0028 | D8: =D80 -> 50.40336 | E8: =E80 -> 52.923528 | F8: =F80 -> 54.511234 | G8: =G80 -> 56.146571
A9: 需求面 ÷ 產能上限 | B9: % | D9: =D94 -> 1 | E9: =E94 -> 1.3648637 | F9: =F94 -> 1.3958261 | G9: =G94 -> 1.3689433
A10: 毛利率 | B10: % | C10: =C100 -> 0.32802813 | D10: =D100 -> 0.34883759 | E10: =E100 -> 0.387979 | F10: =F100 -> 0.40063865 | G10: =G100 -> 0.40039027
A11: 營業利益率 | B11: % | C11: =C104 -> 0.2340344 | D11: =D104 -> 0.26840713 | E11: =E104 -> 0.31817926 | F11: =F104 -> 0.33724262 | G11: =G104 -> 0.34098543
A12: 歸屬母公司淨利 | B12: NT$B | C12: =C106 -> 9.607 | D12: =D106 -> 19.697729 | E12: =E106 -> 34.311465 | F12: =F106 -> 47.190915 | G12: =G106 -> 56.627296 | H12: =H106 -> 64.811469 | I12: =I106 -> 71.439317 | J12: =J106 -> 75.725676
A13: 淨利率 | B13: % | C13: =C111 -> 0.16010599 | D13: =D111 -> 0.18687214 | E13: =E111 -> 0.21795279 | F13: =F111 -> 0.2310112 | G13: =G111 -> 0.23357502 | H13: =H111 -> 0.23357502 | I13: =I111 -> 0.23357502 | J13: =J111 -> 0.23357502
A14: EPS | B14: NT$ | C14: =C109 -> 19.47 | D14: =D109 -> 38.398566 | E14: =E109 -> 66.124283 | F14: =F109 -> 90.044822 | G14: =G109 -> 106.98054 | H14: =H109 -> 121.22982 | I14: =I109 -> 132.30417 | J14: =J109 -> 138.85388
A15: EPS 年增 | B15: % | D15: =D110 -> 0.97219136 | E15: =E110 -> 0.72205086 | F15: =F110 -> 0.36175119 | G15: =G110 -> 0.18808101 | H15: =H110 -> 0.13319505 | I15: =I110 -> 0.091350002 | J15: =J110 -> 0.04950495
A17: 情境 B
A18: 營收 | B18: NT$B | C18: =C137 -> 60.004 | D18: =D137 -> 105.40752 | E18: =E137 -> 152.8409 | F18: =F137 -> 194.26606 | G18: =G137 -> 227.89106 | H18: =H137 -> 257.22631 | I18: =I137 -> 278.92656 | J18: =J137 -> 290.08362
A19: 營收年增 | B19: % | D19: =D138 -> 0.75667489 | E19: =E138 -> 0.45 | F19: =F138 -> 0.27103448 | G19: =G138 -> 0.17308736 | H19: =H138 -> 0.12872491 | I19: =I138 -> 0.084362453 | J19: =J138 -> 0.04
A20: AI 相關營收（AI 伺服器主板、800G 交換器） | B20: NT$B | C20: =C135 -> 18.0012 | D20: =D135 -> 55.00416 | E20: =E135 -> 99.917376 | F20: =F135 -> 139.75483 | G20: =G135 -> 171.74449
A21: 非 AI 營收 | B21: NT$B | C21: =C134 -> 42.0028 | D21: =D134 -> 50.40336 | E21: =E134 -> 52.923528 | F21: =F134 -> 54.511234 | G21: =G134 -> 56.146571
A22: 需求面 ÷ 產能上限 | B22: % | D22: =D148 -> 1 | E22: =E148 -> 1.2987503 | F22: =F148 -> 1.0750684 | G22: =G148 -> 1.0750162
A23: 毛利率 | B23: % | C23: =C154 -> 0.32802813 | D23: =D154 -> 0.34883759 | E23: =E154 -> 0.368566 | F23: =F154 -> 0.36596201 | G23: =G154 -> 0.35806711
A24: 營業利益率 | B24: % | C24: =C158 -> 0.2340344 | D24: =D158 -> 0.26840713 | E24: =E158 -> 0.29812001 | F24: =F158 -> 0.30152476 | G24: =G158 -> 0.29743291
A25: 歸屬母公司淨利 | B25: NT$B | C25: =C160 -> 9.607 | D25: =D160 -> 19.697729 | E25: =E160 -> 31.211979 | F25: =F160 -> 40.124578 | G25: =G160 -> 46.430875 | H25: =H160 -> 49.069616 | I25: =I160 -> 49.589573 | J25: =J160 -> 47.808692
A26: 淨利率 | B26: % | C26: =C165 -> 0.16010599 | D26: =D165 -> 0.18687214 | E26: =E165 -> 0.20421221 | F26: =F165 -> 0.20654446 | G26: =G165 -> 0.20374154 | H26: =H165 -> 0.19076437 | I26: =I165 -> 0.1777872 | J26: =J165 -> 0.16481004
A27: EPS | B27: NT$ | C27: =C163 -> 19.47 | D27: =D163 -> 38.398566 | E27: =E163 -> 60.151023 | F27: =F163 -> 76.561569 | G27: =G163 -> 87.717419 | H27: =H163 -> 91.784693 | I27: =I163 -> 91.838882 | J27: =J163 -> 87.664086
A28: EPS 年增 | B28: % | D28: =D164 -> 0.97219136 | E28: =E164 -> 0.56649141 | F28: =F164 -> 0.27282238 | G28: =G164 -> 0.14571083 | H28: =H164 -> 0.04636792 | I28: =I164 -> 0.00059039546 | J28: =J164 -> -0.04545783
A30: 情境 C
A31: 營收 | B31: NT$B | C31: =C191 -> 60.004 | D31: =D191 -> 105.40752 | E31: =E191 -> 146.72727 | F31: =F191 -> 141.18508 | G31: =G191 -> 153.20576 | H31: =H191 -> 162.92323 | I31: =I191 -> 169.71937 | J31: =J191 -> 173.11376
A32: 營收年增 | B32: % | D32: =D192 -> 0.75667489 | E32: =E192 -> 0.392 | F32: =F192 -> -0.037772033 | G32: =G192 -> 0.08514131 | H32: =H192 -> 0.06342754 | I32: =I192 -> 0.04171377 | J32: =J192 -> 0.02
A33: AI 相關營收（AI 伺服器主板、800G 交換器） | B33: NT$B | C33: =C189 -> 18.0012 | D33: =D189 -> 55.00416 | E33: =E189 -> 93.80374 | F33: =F189 -> 86.673847 | G33: =G189 -> 97.059193
A34: 非 AI 營收 | B34: NT$B | C34: =C188 -> 42.0028 | D34: =D188 -> 50.40336 | E34: =E188 -> 52.923528 | F34: =F188 -> 54.511234 | G34: =G188 -> 56.146571
A35: 需求面 ÷ 產能上限 | B35: % | D35: =D202 -> 1 | E35: =E202 -> 1.1703053 | F35: =F202 -> 0.76625934 | G35: =G202 -> 0.71811335
A36: 毛利率 | B36: % | C36: =C208 -> 0.32802813 | D36: =D208 -> 0.34883759 | E36: =E208 -> 0.33812105 | F36: =F208 -> 0.31969817 | G36: =G208 -> 0.30154961
A37: 營業利益率 | B37: % | C37: =C212 -> 0.2340344 | D37: =D212 -> 0.26840713 | E37: =E212 -> 0.26675057 | F37: =F212 -> 0.24552606 | G37: =G212 -> 0.22970535
A38: 歸屬母公司淨利 | B38: NT$B | C38: =C214 -> 9.607 | D38: =D214 -> 19.697729 | E38: =E214 -> 26.810614 | F38: =F214 -> 23.745263 | G38: =G214 -> 24.106646 | H38: =H214 -> 23.926626 | I38: =I214 -> 23.144361 | J38: =J214 -> 21.791306
A39: 淨利率 | B39: % | C39: =C219 -> 0.16010599 | D39: =D219 -> 0.18687214 | E39: =E219 -> 0.18272414 | F39: =F219 -> 0.16818535 | G39: =G219 -> 0.15734816 | H39: =H219 -> 0.14685829 | I39: =I219 -> 0.13636841 | J39: =J219 -> 0.12587853
A40: EPS | B40: NT$ | C40: =C217 -> 19.47 | D40: =D217 -> 38.398566 | E40: =E217 -> 51.668812 | F40: =F217 -> 45.308254 | G40: =G217 -> 45.542384 | H40: =H217 -> 44.754743 | I40: =I217 -> 42.862886 | J40: =J217 -> 39.957481
A41: EPS 年增 | B41: % | D41: =D218 -> 0.97219136 | E41: =E218 -> 0.34559225 | F41: =F218 -> -0.12310247 | G41: =G218 -> 0.0051674866 | H41: =H218 -> -0.017294682 | I41: =I218 -> -0.04227164 | J41: =J218 -> -0.067783701
A43: 核對（應為 0）：FY2026 模型 − 錨點
...

Sheet Val
A1: Val — P/E 估值（新台幣）。結論用「現價 ÷ FY2027、FY2028 EPS（模型）」；目標價＝DCF 與 Comparable 加權（第 0 節）；十年 P/E 規則值（第 3 節，年底落後 P/E）只作參考。本版未做先驗，無 Andy 合理 P/E 對照
A2: 循環位置：金像電不是設備股，不套設備市場見頂年；以本模型營收最高的會計年度為見頂年（比照勝宏、台光電；FY(t)＝CY(t)）。營收到 FY2029 仍在增加時，見頂年未知，判為中段
A4: 0. 目標價
A5: 0.1 DCF（股東權益現金流，FY2027–FY2032 明確期＋FY2032 後永續）
A6: 項目 | B6: A（順利） | C6: B（平平） | D6: C（不如預期） | E6: 說明
A7: 情境 EPS（FY2027–FY2032） | E7: PL 頁各情境；FY2030 起為收斂法
A8: FY2027 | B8: =PL!E14 -> 66.124283 | C8: =PL!E27 -> 60.151023 | D8: =PL!E40 -> 51.668812
A9: FY2028 | B9: =PL!F14 -> 90.044822 | C9: =PL!F27 -> 76.561569 | D9: =PL!F40 -> 45.308254
A10: FY2029 | B10: =PL!G14 -> 106.98054 | C10: =PL!G27 -> 87.717419 | D10: =PL!G40 -> 45.542384
A11: FY2030 | B11: =PL!H14 -> 121.22982 | C11: =PL!H27 -> 91.784693 | D11: =PL!H40 -> 44.754743
A12: FY2031 | B12: =PL!I14 -> 132.30417 | C12: =PL!I27 -> 91.838882 | D12: =PL!I40 -> 42.862886
A13: FY2032 | B13: =PL!J14 -> 138.85388 | C13: =PL!J27 -> 87.664086 | D13: =PL!J40 -> 39.957481
A14: 股東現金流＝EPS ×（1 − tp_g ÷ tp_roe）
A15: 再投資率（tp_g ÷ tp_roe，上限 0.8） | B15: =MIN(tp_g/tp_roe,0.8) -> 0.13766204 | E15: ROE 為近三年平均（In 頁 tp_roe）
A16: FY2027 | B16: =B8*(1-$B$15) -> 57.02148 | C16: =C8*(1-$B$15) -> 51.870511 | D16: =D8*(1-$B$15) -> 44.555978
A17: FY2028 | B17: =B9*(1-$B$15) -> 77.649068 | C17: =C9*(1-$B$15) -> 66.021947 | D17: =D9*(1-$B$15) -> 39.071027
A18: FY2029 | B18: =B10*(1-$B$15) -> 92.253382 | C18: =C10*(1-$B$15) -> 75.64206 | D18: =D10*(1-$B$15) -> 39.272926
A19: FY2030 | B19: =B11*(1-$B$15) -> 104.54108 | C19: =C11*(1-$B$15) -> 79.149425 | D19: =D11*(1-$B$15) -> 38.593713
A20: FY2031 | B20: =B12*(1-$B$15) -> 114.0909 | C20: =C12*(1-$B$15) -> 79.196154 | D20: =D12*(1-$B$15) -> 36.962294
A21: FY2032 | B21: =B13*(1-$B$15) -> 119.73897 | C21: =C13*(1-$B$15) -> 75.596069 | D21: =D13*(1-$B$15) -> 34.456853
A22: DCF 情境每股價值（折現率 tp_r） | B22: =MAX(0,SUMPRODUCT(B16:B21,1/(1+tp_r)^{1;2;3;4;5;6})+B21*(1+tp_g)/(tp_r-tp_g)/(1+tp_r)^6) -> 1566.7076 | C22: =MAX(0,SUMPRODUCT(C16:C21,1/(1+tp_r)^{1;2;3;4;5;6})+C21*(1+tp_g)/(tp_r-tp_g)/(1+tp_r)^6) -> 1044.1045 | D22: =MAX(0,SUMPRODUCT(D16:D21,1/(1+tp_r)^{1;2;3;4;5;6})+D21*(1+tp_g)/(tp_r-tp_g)/(1+tp_r)^6) -> 508.19582 | E22: Σ 明確期現金流 ÷ (1＋r)^t ＋ 永續價值 ÷ (1＋r)^6；永續價值＝FY2032 現金流 ×(1＋g)÷(r−g)；基準日 2026 年底；負值取 0（Andy 12:22）
A23: DCF 情境價值推到 12 個月後（×(1＋tp_r)） | B23: =B22*(1+tp_r) -> 1723.3783 | C23: =C22*(1+tp_r) -> 1148.5149 | D23: =D22*(1+tp_r) -> 559.0154
A24: DCF 目標價（情境加權） | B24: =tp_wA*B23+tp_wB*C23+tp_wC*D23 -> 1203.0741 | E24: Σ 權重 × 情境價值 ×(1＋r)；權重見 In 頁
A26: 0.2 Comparable（市場主流同業前瞻 P/E；非 A 股公司，同業不放 A 股）
A27: 同業與前瞻 P/E | B27: 代號 | C27: 前瞻 12 月 P/E | D27: 日期 | E27: 來源 | F27: 標記
A28: 健鼎（Tripod Technology） | B28: 3044.TW | C28: 13.96 | D28: 2026-09-10 | E28: stockanalysis.com forward PE（分析師共識；價格日期如左，臺股頁面為快取日期） | F28: Interested-party
A29: 華通（Compeq） | B29: 2313.TW | C29: 20.76 | D29: 2026-08-20 | E29: stockanalysis.com forward PE（分析師共識；價格日期如左，臺股頁面為快取日期） | F29: Interested-party
A30: 臻鼎-KY（Zhen Ding） | B30: 4958.TW | C30: 25.13 | D30: 2026-08-31 | E30: stockanalysis.com forward PE（分析師共識；價格日期如左，臺股頁面為快取日期） | F30: Interested-party
A31: 博智（Allied Circuit） | B31: 8155.TWO | C31: 18.49 | D31: 2026-08-14 | E31: stockanalysis.com forward PE（分析師共識；價格日期如左，臺股頁面為快取日期） | F31: Interested-party
A32: TTM Technologies | B32: TTMI | C32: 10.31 | D32: 2026-10-23 | E32: stockanalysis.com forward PE（分析師共識；價格日期如左，臺股頁面為快取日期） | F32: Interested-party
A33: 並列參考（A 股，不進目標價）：勝宏科技 300476.SZ 前瞻 P/E 14.8x（10-23）、沪电股份 002463.SZ 20.7x（10-22）；stockanalysis，Interested-party
A34: 同業前瞻 P/E 中位數 | B34: =MEDIAN(C28:C32) -> 18.49 | E34: 臺美伺服器、網通 PCB 同業：健鼎、華通、臻鼎-KY、博智、TTM（臺股媒體與券商常用比較組）；定穎投控、瀚宇博前瞻 P/E 未找到
A35: 12 個月後的前瞻 EPS（情境加權） | B35: =tp_wA*(2/12*B8+10/12*B9)+tp_wB*(2/12*C8+10/12*C9)+tp_wC*(2/12*D8+10/12*D9) -> 72.004328 | E35: 約 2027-10 時的未來 12 月 EPS ≈ 2／12 × FY2027＋10／12 × FY2028（會計年度＝日曆年）
A36: Comparable 目標價 | B36: =B34*B35 -> 1331.36 | E36: 同業中位數 × 前瞻 EPS
A38: 0.3 結論
A39: 項目 | B39: 數值 | E39: 說明
A40: 目標價（DCF 與 Comparable 加權） | B40: =tp_w_dcf*B24+(1-tp_w_dcf)*tp_comp_adj -> 1724.0156 | E40: tp_w_dcf × DCF＋（1 − tp_w_dcf）× Comparable；tp_w_dcf 見 In 頁
A41: Comparable 目標價（市場主流同業法） | B41: =B36 -> 1331.36
A42: 市場共識目標價 | B42: =cons_tp -> 1554 | E42: stockanalysis（S&P Global）：9 位分析師平均 1,554、中位數 1,610（頁面時間 2026-09-04）
A43: 上檔空間：加權目標價 | B43: =B40/px-1 -> 0.54620231 | E43: 現價＝In 頁 px（2026-10-22 收盤）
...

Sheet Recon
A1: Recon — 本模型 vs 共識、券商估計與勝宏模型的每 GW PCB 金額、台光電模型的每 GW CCL 金額。只作事後對照，不為對上數字而調參數。共識取自 MarketScreener 與 FactSet（理財周刊轉引）；券商多為單一來源
A3: 項目 | B3: 對照值 | C3: 模型 A | D3: 差距 A | E3: 模型 B | F3: 差距 B | G3: 模型 C | H3: 差距 C | I3: 對照來源 | J3: 說明
A4: A. 共識與券商估計（校準未使用）
A5: FY2026 營收 vs 共識（MarketScreener） | B5: =cons_rev26 -> 106.371 | C5: =PL!D83 -> 105.40752 | D5: =C5/B5-1 -> -0.0090577319 | E5: =PL!D137 -> 105.40752 | F5: =E5/B5-1 -> -0.0090577319 | G5: =PL!D191 -> 105.40752 | H5: =G5/B5-1 -> -0.0090577319 | I5: MarketScreener（2026-10-25 擷取） | J5: stockanalysis 8 家 1,063 億；共識隱含 4Q26 約 327 億
A6: FY2026 EPS vs 共識（MarketScreener） | B6: =cons_eps26 -> 41.22 | C6: =PL!D109 -> 38.398566 | D6: =C6/B6-1 -> -0.068448185 | E6: =PL!D163 -> 38.398566 | F6: =E6/B6-1 -> -0.068448185 | G6: =PL!D217 -> 38.398566 | H6: =G6/B6-1 -> -0.068448185 | I6: MarketScreener | J6: 3Q26 財報（11 月上旬）前
A7: FY2026 EPS vs FactSet 中位數（2026-09） | B7: =fs_eps26 -> 41.57 | C7: =PL!D109 -> 38.398566 | D7: =C7/B7-1 -> -0.076291416 | E7: =PL!D163 -> 38.398566 | F7: =E7/B7-1 -> -0.076291416 | G7: =PL!D217 -> 38.398566 | H7: =G7/B7-1 -> -0.076291416 | I7: FactSet（理財周刊 2026-10-14 轉引）
A8: FY2027 營收 vs 共識（MarketScreener） | B8: =cons_rev27 -> 159.967 | C8: =PL!E83 -> 157.42613 | D8: =C8/B8-1 -> -0.015883707 | E8: =PL!E137 -> 152.8409 | F8: =E8/B8-1 -> -0.044547288 | G8: =PL!E191 -> 146.72727 | H8: =G8/B8-1 -> -0.082765396 | I8: MarketScreener
A9: FY2027 EPS vs 共識（MarketScreener） | B9: =cons_eps27 -> 62.8 | C9: =PL!E109 -> 66.124283 | D9: =C9/B9-1 -> 0.052934447 | E9: =PL!E163 -> 60.151023 | F9: =E9/B9-1 -> -0.042181156 | G9: =PL!E217 -> 51.668812 | H9: =G9/B9-1 -> -0.17724821 | I9: MarketScreener
A10: FY2027 EPS vs FactSet 中位數 | B10: =fs_eps27 -> 69.1 | C10: =PL!E109 -> 66.124283 | D10: =C10/B10-1 -> -0.043063918 | E10: =PL!E163 -> 60.151023 | F10: =E10/B10-1 -> -0.12950762 | G10: =PL!E217 -> 51.668812 | H10: =G10/B10-1 -> -0.25226031 | I10: FactSet（理財周刊轉引）
A11: FY2027 EPS vs 外資（2026-05-13） | B11: =fb_eps27 -> 65.39 | C11: =PL!E109 -> 66.124283 | D11: =C11/B11-1 -> 0.01122929 | E11: =PL!E163 -> 60.151023 | F11: =E11/B11-1 -> -0.080118926 | G11: =PL!E217 -> 51.668812 | H11: =G11/B11-1 -> -0.20983618 | I11: technews 2026-05-13（外資，名稱未載明） | J11: 目標價 1,310
A12: FY2028 營收 vs 共識（MarketScreener） | B12: =cons_rev28 -> 214.339 | C12: =PL!F83 -> 204.27977 | D12: =C12/B12-1 -> -0.046931386 | E12: =PL!F137 -> 194.26606 | F12: =E12/B12-1 -> -0.093650435 | G12: =PL!F191 -> 141.18508 | H12: =G12/B12-1 -> -0.34130009 | I12: MarketScreener
A13: FY2028 EPS vs 共識（MarketScreener） | B13: =cons_eps28 -> 95.35 | C13: =PL!F109 -> 90.044822 | D13: =C13/B13-1 -> -0.055638998 | E13: =PL!F163 -> 76.561569 | F13: =E13/B13-1 -> -0.19704699 | G13: =PL!F217 -> 45.308254 | H13: =G13/B13-1 -> -0.52482167 | I13: MarketScreener
A14: FY2028 EPS vs FactSet 中位數 | B14: =fs_eps28 -> 95.07 | C14: =PL!F109 -> 90.044822 | D14: =C14/B14-1 -> -0.052857668 | E14: =PL!F163 -> 76.561569 | F14: =E14/B14-1 -> -0.19468214 | G14: =PL!F217 -> 45.308254 | H14: =G14/B14-1 -> -0.52342218 | I14: FactSet（理財周刊轉引）
A15: B. 每 GW PCB 金額 vs 勝宏模型、台光電每 GW CCL 金額（機制檢查）
A16: CY2026 每 GW 可參與 PCB 金額（本模型）vs 勝宏模型每 GW PCB 金額 | B16: =vg_pgw26 -> 450 | C16: =PL!D69 -> 425 | D16: =C16/B16-1 -> -0.055555556 | E16: =PL!D123 -> 425 | F16: =E16/B16-1 -> -0.055555556 | G16: =PL!D177 -> 425 | H16: =G16/B16-1 -> -0.055555556 | I16: victory_giant/dist Units 頁（唯讀） | J16: 差距只來自中板／背板參與係數 w_mid（與成長倍率 pgwf）
A17: CY2027 每 GW 可參與 PCB 金額（本模型）vs 勝宏模型每 GW PCB 金額 | B17: =vg_pgw27 -> 682 | C17: =PL!E69 -> 632 | D17: =C17/B17-1 -> -0.073313783 | E17: =PL!E123 -> 632 | F17: =E17/B17-1 -> -0.073313783 | G17: =PL!E177 -> 632 | H17: =G17/B17-1 -> -0.073313783 | I17: victory_giant/dist Units 頁（唯讀） | J17: —
A18: CY2028 每 GW 可參與 PCB 金額（本模型）vs 勝宏模型每 GW PCB 金額 | B18: =vg_pgw28 -> 792 | C18: =PL!F69 -> 717 | D18: =C18/B18-1 -> -0.09469697 | E18: =PL!F123 -> 717 | F18: =E18/B18-1 -> -0.09469697 | G18: =PL!F177 -> 717 | H18: =G18/B18-1 -> -0.09469697 | I18: victory_giant/dist Units 頁（唯讀） | J18: —
A19: CY2026 每 GW 可參與 PCB 金額（本模型）vs 台光電模型每 GW CCL 金額 | B19: =emc_ccl26 -> 350 | C19: =PL!D69 -> 425 | D19: =C19/B19-1 -> 0.21428571 | E19: =PL!D123 -> 425 | F19: =E19/B19-1 -> 0.21428571 | G19: =PL!D177 -> 425 | H19: =G19/B19-1 -> 0.21428571 | I19: emc/dist Units 頁（唯讀） | J19: 差距＝PCB ÷ CCL − 1；勝宏模型已註明 PCB ÷ CCL 只有約 1.3 倍，低於 Morgan Stanley 每架口徑 5.2 倍（範圍不同）
A20: CY2027 每 GW 可參與 PCB 金額（本模型）vs 台光電模型每 GW CCL 金額 | B20: =emc_ccl27 -> 527.5 | C20: =PL!E69 -> 632 | D20: =C20/B20-1 -> 0.19810427 | E20: =PL!E123 -> 632 | F20: =E20/B20-1 -> 0.19810427 | G20: =PL!E177 -> 632 | H20: =G20/B20-1 -> 0.19810427 | I20: emc/dist Units 頁（唯讀） | J20: —
A21: CY2027 每 GW 金額指數（÷ CY2026）：本模型 vs 台光電 CCL | B21: =emc_ccl27/emc_ccl26 -> 1.5071429 | C21: =PL!E69/PL!D69 -> 1.4870588 | D21: =C21/B21-1 -> -0.013325899 | E21: =PL!E123/PL!D123 -> 1.4870588 | F21: =E21/B21-1 -> -0.013325899 | G21: =PL!E177/PL!D177 -> 1.4870588 | H21: =G21/B21-1 -> -0.013325899 | I21: emc/dist | J21: 世代升級幅度的對照
A22: CY2026 每 GW 金像電 AI 營收 vs 每 GW 勝宏 AI 營收（US$M） | B22: =vg_pge26 -> 104.22055 | C22: =PL!D95 -> 73.45786 | D22: =C22/B22-1 -> -0.29516916 | E22: =PL!D149 -> 73.45786 | F22: =E22/B22-1 -> -0.29516916 | G22: =PL!D203 -> 73.45786 | H22: =G22/B22-1 -> -0.29516916 | I22: victory_giant/dist | J22: 同為 AI 高速 PCB 廠；勝宏較偏 NVIDIA GPU 加速卡與 HDI
A23: CY2026 每 GW 金像電 AI 營收 vs 每 GW 台光電 AI 營收（US$M） | B23: =emc_pg26 -> 160.75716 | C23: =PL!D95 -> 73.45786 | D23: =C23/B23-1 -> -0.54305076 | E23: =PL!D149 -> 73.45786 | F23: =E23/B23-1 -> -0.54305076 | G23: =PL!D203 -> 73.45786 | H23: =G23/B23-1 -> -0.54305076 | I23: emc/dist | J23: 下游 PCB 廠 ÷ 上游 CCL 廠
A24: CY2027 每 GW 金像電 AI 營收 vs 每 GW 勝宏 AI 營收（US$M） | B24: =vg_pge27 -> 126.0862 | C24: =PL!E95 -> 78.414405 | D24: =C24/B24-1 -> -0.37808894 | E24: =PL!E149 -> 74.973841 | F24: =E24/B24-1 -> -0.40537633 | G24: =PL!E203 -> 70.386423 | H24: =G24/B24-1 -> -0.44175952 | I24: victory_giant/dist | J24: —
A25: CY2027 每 GW 金像電 AI 營收 vs 每 GW 台光電 AI 營收（US$M） | B25: =emc_pg27 -> 180.40841 | C25: =PL!E95 -> 78.414405 | D25: =C25/B25-1 -> -0.56535062 | E25: =PL!E149 -> 74.973841 | F25: =E25/B25-1 -> -0.58442159 | G25: =PL!E203 -> 70.386423 | H25: =G25/B25-1 -> -0.60984955 | I25: emc/dist | J25: 下游 PCB 廠 ÷ 上游 CCL 廠
A26: FY2026 金像電有效份額 vs 勝宏有效份額（勝宏模型） | B26: =vg_sh26 -> 0.23160123 | C26: =PL!D73 -> 0.17284202 | D26: =C26-B26 -> -0.058759205 | E26: =PL!D127 -> 0.17284202 | F26: =E26-B26 -> -0.058759205 | G26: =PL!D181 -> 0.17284202 | H26: =G26-B26 -> -0.058759205 | I26: victory_giant/dist | J26: 分母不同：本模型為可參與市場（中板 × w_mid）
A27: C. 產能與校準
A28: FY2027 需求面 ÷ 產能上限 | C28: =PL!E94 -> 1.3648637 | E28: =PL!E148 -> 1.2987503 | G28: =PL!E202 -> 1.1703053 | I28: — | J28: 大於 100%＝產能受限
A29: FY2028 需求面 ÷ 產能上限 | C29: =PL!F94 -> 1.3958261 | E29: =PL!F148 -> 1.0750684 | G29: =PL!F202 -> 0.76625934 | I29: —
A30: 其他營收毛利率（Derived） | C30: =PL!D97 -> 0.29665521 | E30: =PL!D151 -> 0.29665521 | G30: =PL!D205 -> 0.29665521 | I30: FY2026 錨點 | J30: AI 相關毛利率＝此值＋d_ai
A31: FY2027 毛利率 vs FY2026（百分點） | B31: =a26_gp/a26_rev -> 0.34883759 | C31: =PL!E100 -> 0.387979 | D31: =C31-B31 -> 0.039141411 | E31: =PL!E154 -> 0.368566 | F31: =E31-B31 -> 0.019728411 | G31: =PL!E208 -> 0.33812105 | H31: =G31-B31 -> -0.010716543 | I31: 錨點
A32: FY2027 營業利益率 vs 2Q26 實績 26.43%（百分點） | B32: =0.2643 -> 0.2643 | C32: =PL!E104 -> 0.31817926 | D32: =C32-B32 -> 0.053879258 | E32: =PL!E158 -> 0.29812001 | F32: =E32-B32 -> 0.033820014 | G32: =PL!E212 -> 0.26675057 | H32: =G32-B32 -> 0.0024505716 | I32: 理財周刊 2026-10-14
A33: 4Q26 EPS（模型） | C33: =Q!E15 -> 11.552539 | E33: =Q!E15 -> 11.552539 | G33: =Q!E15 -> 11.552539 | I33: — | J33: 3Q26 財報 11 月上旬公布
A34: D. 預留
A35: R4 產業部署路徑（markets/deploy_path/，尚未建立）：上線後以部署路徑取代「AI IT 資本支出 ÷ 每 GW IT 資本支出」 | J35: 預留列：本版無數值

Sheet Sens
A1: Sens — 一次動一個輸入（情境 B＝基準輸入；有效份額、其他營收毛利率在每個案例內依 FY2026 錨點重算，FY2026 恆等於錨點）：對 FY2027、FY2028 的營收、AI 相關營收、毛利率與 EPS 的影響。每個案例是一個完整推導區塊（本頁下方）
A3: 案例 | B3: 設定 | C3: FY2027 營收 | D3: FY2027 AI 相關 | E3: FY2027 毛利率 | F3: FY2027 EPS | G3: FY2027 EPS 相對基準 | H3: FY2028 營收 | I3: FY2028 AI 相關 | J3: FY2028 毛利率 | K3: FY2028 EPS | L3: FY2028 EPS 相對基準
A4: 基準（情境 B） | B4: PL 區塊 B | C4: =PL!E137 -> 152.8409 | D4: =PL!E135 -> 99.917376 | E4: =PL!E154 -> 0.368566 | F4: =PL!E163 -> 60.151023 | G4: =F4/F$4-1 -> 0 | H4: =PL!F137 -> 194.26606 | I4: =PL!F135 -> 139.75483 | J4: =PL!F154 -> 0.36596201 | K4: =PL!F163 -> 76.561569 | L4: =K4/K$4-1 -> 0
A5: 每 GW 金額成長 低 | B5: 勝宏模型每 GW 金額增量 ×0.7 | C5: =E73 -> 152.8409 | D5: =E71 -> 99.917376 | E5: =E90 -> 0.368566 | F5: =E99 -> 60.151023 | G5: =F5/F$4-1 -> 0 | H5: =F73 -> 189.99293 | I5: =F71 -> 135.4817 | J5: =F90 -> 0.36535401 | K5: =F99 -> 74.602696 | L5: =K5/K$4-1 -> -0.025585589
A6: 每 GW 金額成長 高 | B6: 增量 ×1.3 | C6: =E127 -> 152.8409 | D6: =E125 -> 99.917376 | E6: =E144 -> 0.368566 | F6: =E153 -> 60.151023 | G6: =F6/F$4-1 -> 0 | H6: =F127 -> 194.26606 | I6: =F125 -> 139.75483 | J6: =F144 -> 0.36596201 | K6: =F153 -> 76.561569 | L6: =K6/K$4-1 -> 0
A7: 中板／背板不參與 | B7: 參與係數 0 | C7: =E181 -> 152.8409 | D7: =E179 -> 99.917376 | E7: =E198 -> 0.368566 | F7: =E207 -> 60.151023 | G7: =F7/F$4-1 -> 0 | H7: =F181 -> 194.26606 | I7: =F179 -> 139.75483 | J7: =F198 -> 0.36596201 | K7: =F207 -> 76.561569 | L7: =K7/K$4-1 -> 0
A8: 中板／背板全參與 | B8: 參與係數 1 | C8: =E235 -> 152.8409 | D8: =E233 -> 99.917376 | E8: =E252 -> 0.368566 | F8: =E261 -> 60.151023 | G8: =F8/F$4-1 -> 0 | H8: =F235 -> 194.26606 | I8: =F233 -> 139.75483 | J8: =F252 -> 0.36596201 | K8: =F261 -> 76.561569 | L8: =K8/K$4-1 -> 0
A9: 份額流失（低） | B9: 份額相對值 2027 0.85、2028 0.75、2029 0.70（ASIC 改 HDI 混壓情境） | C9: =E289 -> 152.8409 | D9: =E287 -> 99.917376 | E9: =E306 -> 0.368566 | F9: =E315 -> 60.151023 | G9: =F9/F$4-1 -> 0 | H9: =F289 -> 176.35708 | I9: =F287 -> 121.84584 | J9: =F306 -> 0.36321681 | K9: =F315 -> 68.351787 | L9: =K9/K$4-1 -> -0.10723111
A10: 份額提升（高） | B10: 份額相對值 2027–28 1.08、2029 1.05 | C10: =E343 -> 152.8409 | D10: =E341 -> 99.917376 | E10: =E360 -> 0.368566 | F10: =E369 -> 60.151023 | G10: =F10/F$4-1 -> 0 | H10: =F343 -> 194.26606 | I10: =F341 -> 139.75483 | J10: =F360 -> 0.36596201 | K10: =F369 -> 76.561569 | L10: =K10/K$4-1 -> 0
A11: 價格回落快 | B11: 價格指數 2027 0.96、2028 0.92、2029 0.88 | C11: =E397 -> 146.72727 | D11: =E395 -> 93.80374 | E11: =E414 -> 0.35090719 | F11: =E423 -> 54.14545 | G11: =F11/F$4-1 -> -0.099841584 | H11: =F397 -> 184.25234 | I11: =F395 -> 129.74111 | J11: =F414 -> 0.34068933 | K11: =F423 -> 66.25927 | L11: =K11/K$4-1 -> -0.13456227
A12: 價格延續 | B12: 價格指數 2027 1.03、2028 1.02、2029 1.00 | C12: =E451 -> 157.42613 | D12: =E449 -> 104.5026 | E12: =E468 -> 0.3813408 | F12: =E477 -> 64.744727 | G12: =F12/F$4-1 -> 0.076369501 | H12: =F451 -> 204.27977 | I12: =F449 -> 149.76854 | J12: =F468 -> 0.38964134 | K12: =F477 -> 87.108506 | L12: =K12/K$4-1 -> 0.13775758
A13: 擴產延遲 | B13: 產能指數 2027 1.30、2028 1.60、2029 1.90 | C13: =E505 -> 137.02978 | D13: =E503 -> 84.106248 | E13: =E522 -> 0.3641711 | F13: =E531 -> 52.670372 | G13: =F13/F$4-1 -> -0.12436449 | H13: =F505 -> 163.59247 | I13: =F503 -> 109.08124 | J13: =F522 -> 0.36089331 | K13: =F531 -> 62.570748 | L13: =K13/K$4-1 -> -0.18273948
A14: 擴產提前 | B14: 產能指數 2027 1.60、2028 2.15、2029 2.60 | C14: =E559 -> 168.65203 | D14: =E557 -> 115.7285 | E14: =E576 -> 0.37213687 | F14: =E585 -> 67.631675 | G14: =F14/F$4-1 -> 0.12436449 | H14: =F559 -> 208.8493 | I14: =F557 -> 154.33807 | J14: =F576 -> 0.36784963 | K14: =F585 -> 83.188545 | L14: =K14/K$4-1 -> 0.086557467
A15: AI 毛利率未改善 | B15: 額外改善 2027–29 皆 −1pt | C15: =E613 -> 152.8409 | D15: =E611 -> 99.917376 | E15: =E630 -> 0.35549131 | F15: =E639 -> 57.512972 | G15: =F15/F$4-1 -> -0.043857138 | H15: =F613 -> 194.26606 | I15: =F611 -> 139.75483 | J15: =F630 -> 0.34797703 | K15: =F639 -> 71.994919 | L15: =K15/K$4-1 -> -0.059646768
A16: AI 毛利率改善 快 | B16: 額外改善 2027 +2pt、2028 +3pt、2029 +3.5pt | C16: =E667 -> 152.8409 | D16: =E665 -> 99.917376 | E16: =E684 -> 0.37510335 | F16: =E693 -> 61.470049 | G16: =F16/F$4-1 -> 0.021928569 | H16: =F667 -> 194.26606 | I16: =F665 -> 139.75483 | J16: =F684 -> 0.37675299 | K16: =F693 -> 79.301559 | L16: =K16/K$4-1 -> 0.035788061
A17: AI 部署 ×0.8 | B17: FY2027 起 AI IT 資本支出 ×0.8 | C17: =E721 -> 152.8409 | D17: =E719 -> 99.917376 | E17: =E738 -> 0.368566 | F17: =E747 -> 60.151023 | G17: =F17/F$4-1 -> 0 | H17: =F721 -> 177.98169 | I17: =F719 -> 123.47045 | J17: =F738 -> 0.36348863 | K17: =F747 -> 69.096537 | L17: =K17/K$4-1 -> -0.09750365
A18: AI 部署 ×1.2 | B18: ×1.2 | C18: =E775 -> 152.8409 | D18: =E773 -> 99.917376 | E18: =E792 -> 0.368566 | F18: =E801 -> 60.151023 | G18: =F18/F$4-1 -> 0 | H18: =F775 -> 194.26606 | I18: =F773 -> 139.75483 | J18: =F792 -> 0.36596201 | K18: =F801 -> 76.561569 | L18: =K18/K$4-1 -> 0
A19: AI 毛利率差距 6pt | B19: AI 相關毛利率只高 6 個百分點 | C19: =E829 -> 152.8409 | D19: =E827 -> 99.917376 | E19: =E846 -> 0.36328958 | F19: =E855 -> 59.08641 | G19: =F19/F$4-1 -> -0.017699 | H19: =F829 -> 194.26606 | I19: =F827 -> 139.75483 | J19: =F846 -> 0.35763343 | K19: =F855 -> 74.446821 | L19: =K19/K$4-1 -> -0.02762153
A20: AI 毛利率差距 14pt | B20: 高 14 個百分點 | C20: =E883 -> 152.8409 | D20: =E881 -> 99.917376 | E20: =E900 -> 0.37384243 | F20: =E909 -> 61.215636 | G20: =F20/F$4-1 -> 0.017699 | H20: =F883 -> 194.26606 | I20: =F881 -> 139.75483 | J20: =F900 -> 0.37429058 | K20: =F909 -> 78.676317 | L20: =K20/K$4-1 -> 0.02762153
A21: 非 AI 成長 低 | B21: 2027–29 −5% | C21: =E937 -> 152.8409 | D21: =E935 -> 104.95771 | E21: =E954 -> 0.37219355 | F21: =E963 -> 60.882945 | G21: =F21/F$4-1 -> 0.012168063 | H21: =F937 -> 194.26606 | I21: =F935 -> 148.77703 | J21: =F954 -> 0.37043627 | K21: =F963 -> 77.69765 | L21: =K21/K$4-1 -> 0.014838793
A22: 非 AI 成長 高 | B22: 2027 +10%、2028–29 +8% | C22: =E991 -> 152.8409 | D22: =E989 -> 97.397208 | E22: =E1008 -> 0.36675223 | F22: =E1017 -> 59.785063 | G22: =F22/F$4-1 -> -0.0060840314 | H22: =F991 -> 194.26606 | I22: =F989 -> 134.38687 | J22: =F1008 -> 0.36329994 | K22: =F1017 -> 75.885632 | L22: =K22/K$4-1 -> -0.0088286675
A23: 營業費用彈性 1.0 | B23: 基準 0.6 | C23: =E1045 -> 152.8409 | D23: =E1043 -> 99.917376 | E23: =E1062 -> 0.368566 | F23: =E1071 -> 58.136479 | G23: =F23/F$4-1 -> -0.033491448 | H23: =F1045 -> 194.26606 | I23: =F1043 -> 139.75483 | J23: =F1062 -> 0.36596201 | K23: =F1071 -> 72.500657 | L23: =K23/K$4-1 -> -0.053041124
A24: 淨利 ÷ 稅前 0.65 | B24: 基準 0.685 | C24: =E1099 -> 152.8409 | D24: =E1097 -> 99.917376 | E24: =E1116 -> 0.368566 | F24: =E1125 -> 57.077613 | G24: =F24/F$4-1 -> -0.051094891 | H24: =F1099 -> 194.26606 | I24: =F1097 -> 139.75483 | J24: =F1116 -> 0.36596201 | K24: =F1125 -> 72.649664 | L24: =K24/K$4-1 -> -0.051094891
A25: 淨利 ÷ 稅前 0.75 | C25: =E1153 -> 152.8409 | D25: =E1151 -> 99.917376 | E25: =E1170 -> 0.368566 | F25: =E1179 -> 65.858785 | G25: =F25/F$4-1 -> 0.094890511 | H25: =F1153 -> 194.26606 | I25: =F1151 -> 139.75483 | J25: =F1170 -> 0.36596201 | K25: =F1179 -> 83.826535 | L25: =K25/K$4-1 -> 0.094890511
A26: 情境 A（全部） | B26: 顆數係數 A＋份額、價格、AI 毛利率改善高值 | C26: =PL!E83 -> 157.42613 | D26: =PL!E81 -> 104.5026 | E26: =PL!E100 -> 0.387979 | F26: =PL!E109 -> 66.124283 | G26: =F26/F$4-1 -> 0.099304377 | H26: =PL!F83 -> 204.27977 | I26: =PL!F81 -> 149.76854 | J26: =PL!F100 -> 0.40063865 | K26: =PL!F109 -> 90.044822 | L26: =K26/K$4-1 -> 0.17610993
A27: 情境 C（全部） | B27: 顆數係數 C＋份額、價格、AI 毛利率改善低值 | C27: =PL!E191 -> 146.72727 | D27: =PL!E189 -> 93.80374 | E27: =PL!E208 -> 0.33812105 | F27: =PL!E217 -> 51.668812 | G27: =F27/F$4-1 -> -0.14101524 | H27: =PL!F191 -> 141.18508 | I27: =PL!F189 -> 86.673847 | J27: =PL!F208 -> 0.31969817 | K27: =PL!F217 -> 45.308254 | L27: =K27/K$4-1 -> -0.40821153
A29: 讀法：基準為情境 B（顆數係數 B 從 CY2028 起）。產能受限的年度，需求面輸入（每 GW 金額、份額、AI 部署）對營收的影響被產能上限截斷，只有產能與價格會改變營收；價格指數同時改變產能上限營收與 AI 毛利率（成本不變），所以對 EPS 的影響大於對營收。
A31: 目標價參數（只改 DCF 參數；PL 收斂法的 fade_g 不隨 tp_g 變動）
A32: 案例 | B32: 設定 | C32: DCF 目標價 | D32: Comparable 目標價（相對倍數調整後） | E32: 加權目標價 | F32: 相對基準
A33: 基準 | B33: r 10%、g 4%、DCF 權重 0.5 | C33: =(tp_wA*MAX(0,Val!B8*(1-MIN(tp_g/tp_roe,0.8))/(1+tp_r)^1+Val!B9*(1-MIN(tp_g/tp_roe,0.8))/(1+tp_r)^2+Val!B10*(1-MIN(tp_g/tp_roe,0.8))/(1+tp_r)^3+Val!B11*(1-MIN(tp_g/tp_roe,0.8))/(1+tp_r)^4+Val!B12*(1-MIN(tp_g/tp_roe,0.8))/(1+tp_r)^5+Val!B13*(1-MIN(tp_g/tp_roe,0.8))/(1+tp_r)^6+Val!B13*(1-MIN(tp_g/tp_roe,0.8))*(1+tp_g)/(tp_r-tp_g)/(1+tp_r)^6)+tp_wB*MAX(0,Val!C8*(1-MIN(tp_g/tp_roe,0.8))/(1+tp_r)^1+Val!C9*(1-MIN(tp_g/tp_roe,0.8))/(1+tp_r)^2+Val!C10*(1-MIN(tp_g/tp_roe,0.8))/(1+tp_r)^3+Val!C11*(1-MIN(tp_g/tp_roe,0.8))/(1+tp_r)^4+Val!C12*(1-MIN(tp_g/tp_roe,0.8))/(1+tp_r)^5+Val!C13*(1-MIN(tp_g/tp_roe,0.8))/(1+tp_r)^6+Val!C13*(1-MIN(tp_g/tp_roe,0.8))*(1+tp_g)/(tp_r-tp_g)/(1+tp_r)^6)+tp_wC*MAX(0,Val!D8*(1-MIN(tp_g/tp_roe,0.8))/(1+tp_r)^1+Val!D9*(1-MIN(tp_g/tp_roe,0.8))/(1+tp_r)^2+Val!D10*(1-MIN(tp_g/tp_roe,0.8))/(1+tp_r)^3+Val!D11*(1-MIN(tp_g/tp_roe,0.8))/(1+tp_r)^4+Val!D12*(1-MIN(tp_g/tp_roe,0.8))/(1+tp_r)^5+Val!D13*(1-MIN(tp_g/tp_roe,0.8))/(1+tp_r)^6+Val!D13*(1-MIN(tp_g/tp_roe,0.8))*(1+tp_g)/(tp_r-tp_g)/(1+tp_r)^6))*(1+tp_r) -> 1203.0741 | D33: =tp_comp_adj -> 2244.9571 | E33: =tp_w_dcf*C33+(1-tp_w_dcf)*D33 -> 1724.0156 | F33: =E33/E$33-1 -> 0
A34: 折現率 +1pt | B34: r 11% | C34: =(tp_wA*MAX(0,Val!B8*(1-MIN(tp_g/tp_roe,0.8))/(1+(tp_r+0.01))^1+Val!B9*(1-MIN(tp_g/tp_roe,0.8))/(1+(tp_r+0.01))^2+Val!B10*(1-MIN(tp_g/tp_roe,0.8))/(1+(tp_r+0.01))^3+Val!B11*(1-MIN(tp_g/tp_roe,0.8))/(1+(tp_r+0.01))^4+Val!B12*(1-MIN(tp_g/tp_roe,0.8))/(1+(tp_r+0.01))^5+Val!B13*(1-MIN(tp_g/tp_roe,0.8))/(1+(tp_r+0.01))^6+Val!B13*(1-MIN(tp_g/tp_roe,0.8))*(1+tp_g)/((tp_r+0.01)-tp_g)/(1+(tp_r+0.01))^6)+tp_wB*MAX(0,Val!C8*(1-MIN(tp_g/tp_roe,0.8))/(1+(tp_r+0.01))^1+Val!C9*(1-MIN(tp_g/tp_roe,0.8))/(1+(tp_r+0.01))^2+Val!C10*(1-MIN(tp_g/tp_roe,0.8))/(1+(tp_r+0.01))^3+Val!C11*(1-MIN(tp_g/tp_roe,0.8))/(1+(tp_r+0.01))^4+Val!C12*(1-MIN(tp_g/tp_roe,0.8))/(1+(tp_r+0.01))^5+Val!C13*(1-MIN(tp_g/tp_roe,0.8))/(1+(tp_r+0.01))^6+Val!C13*(1-MIN(tp_g/tp_roe,0.8))*(1+tp_g)/((tp_r+0.01)-tp_g)/(1+(tp_r+0.01))^6)+tp_wC*MAX(0,Val!D8*(1-MIN(tp_g/tp_roe,0.8))/(1+(tp_r+0.01))^1+Val!D9*(1-MIN(tp_g/tp_roe,0.8))/(1+(tp_r+0.01))^2+Val!D10*(1-MIN(tp_g/tp_roe,0.8))/(1+(tp_r+0.01))^3+Val!D11*(1-MIN(tp_g/tp_roe,0.8))/(1+(tp_r+0.01))^4+Val!D12*(1-MIN(tp_g/tp_roe,0.8))/(1+(tp_r+0.01))^5+Val!D13*(1-MIN(tp_g/tp_roe,0.8))/(1+(tp_r+0.01))^6+Val!D13*(1-MIN(tp_g/tp_roe,0.8))*(1+tp_g)/((tp_r+0.01)-tp_g)/(1+(tp_r+0.01))^6))*(1+(tp_r+0.01)) -> 1038.8516 | D34: =tp_comp_adj -> 2244.9571 | E34: =tp_w_dcf*C34+(1-tp_w_dcf)*D34 -> 1641.9043 | F34: =E34/E$33-1 -> -0.047627893
A35: 折現率 −1pt | B35: r 9% | C35: =(tp_wA*MAX(0,Val!B8*(1-MIN(tp_g/tp_roe,0.8))/(1+(tp_r-0.01))^1+Val!B9*(1-MIN(tp_g/tp_roe,0.8))/(1+(tp_r-0.01))^2+Val!B10*(1-MIN(tp_g/tp_roe,0.8))/(1+(tp_r-0.01))^3+Val!B11*(1-MIN(tp_g/tp_roe,0.8))/(1+(tp_r-0.01))^4+Val!B12*(1-MIN(tp_g/tp_roe,0.8))/(1+(tp_r-0.01))^5+Val!B13*(1-MIN(tp_g/tp_roe,0.8))/(1+(tp_r-0.01))^6+Val!B13*(1-MIN(tp_g/tp_roe,0.8))*(1+tp_g)/((tp_r-0.01)-tp_g)/(1+(tp_r-0.01))^6)+tp_wB*MAX(0,Val!C8*(1-MIN(tp_g/tp_roe,0.8))/(1+(tp_r-0.01))^1+Val!C9*(1-MIN(tp_g/tp_roe,0.8))/(1+(tp_r-0.01))^2+Val!C10*(1-MIN(tp_g/tp_roe,0.8))/(1+(tp_r-0.01))^3+Val!C11*(1-MIN(tp_g/tp_roe,0.8))/(1+(tp_r-0.01))^4+Val!C12*(1-MIN(tp_g/tp_roe,0.8))/(1+(tp_r-0.01))^5+Val!C13*(1-MIN(tp_g/tp_roe,0.8))/(1+(tp_r-0.01))^6+Val!C13*(1-MIN(tp_g/tp_roe,0.8))*(1+tp_g)/((tp_r-0.01)-tp_g)/(1+(tp_r-0.01))^6)+tp_wC*MAX(0,Val!D8*(1-MIN(tp_g/tp_roe,0.8))/(1+(tp_r-0.01))^1+Val!D9*(1-MIN(tp_g/tp_roe,0.8))/(1+(tp_r-0.01))^2+Val!D10*(1-MIN(tp_g/tp_roe,0.8))/(1+(tp_r-0.01))^3+Val!D11*(1-MIN(tp_g/tp_roe,0.8))/(1+(tp_r-0.01))^4+Val!D12*(1-MIN(tp_g/tp_roe,0.8))/(1+(tp_r-0.01))^5+Val!D13*(1-MIN(tp_g/tp_roe,0.8))/(1+(tp_r-0.01))^6+Val!D13*(1-MIN(tp_g/tp_roe,0.8))*(1+tp_g)/((tp_r-0.01)-tp_g)/(1+(tp_r-0.01))^6))*(1+(tp_r-0.01)) -> 1432.9292 | D35: =tp_comp_adj -> 2244.9571 | E35: =tp_w_dcf*C35+(1-tp_w_dcf)*D35 -> 1838.9431 | F35: =E35/E$33-1 -> 0.066662717
A36: 長期成長 +1pt | B36: g 5% | C36: =(tp_wA*MAX(0,Val!B8*(1-MIN((tp_g+0.01)/tp_roe,0.8))/(1+tp_r)^1+Val!B9*(1-MIN((tp_g+0.01)/tp_roe,0.8))/(1+tp_r)^2+Val!B10*(1-MIN((tp_g+0.01)/tp_roe,0.8))/(1+tp_r)^3+Val!B11*(1-MIN((tp_g+0.01)/tp_roe,0.8))/(1+tp_r)^4+Val!B12*(1-MIN((tp_g+0.01)/tp_roe,0.8))/(1+tp_r)^5+Val!B13*(1-MIN((tp_g+0.01)/tp_roe,0.8))/(1+tp_r)^6+Val!B13*(1-MIN((tp_g+0.01)/tp_roe,0.8))*(1+(tp_g+0.01))/(tp_r-(tp_g+0.01))/(1+tp_r)^6)+tp_wB*MAX(0,Val!C8*(1-MIN((tp_g+0.01)/tp_roe,0.8))/(1+tp_r)^1+Val!C9*(1-MIN((tp_g+0.01)/tp_roe,0.8))/(1+tp_r)^2+Val!C10*(1-MIN((tp_g+0.01)/tp_roe,0.8))/(1+tp_r)^3+Val!C11*(1-MIN((tp_g+0.01)/tp_roe,0.8))/(1+tp_r)^4+Val!C12*(1-MIN((tp_g+0.01)/tp_roe,0.8))/(1+tp_r)^5+Val!C13*(1-MIN((tp_g+0.01)/tp_roe,0.8))/(1+tp_r)^6+Val!C13*(1-MIN((tp_g+0.01)/tp_roe,0.8))*(1+(tp_g+0.01))/(tp_r-(tp_g+0.01))/(1+tp_r)^6)+tp_wC*MAX(0,Val!D8*(1-MIN((tp_g+0.01)/tp_roe,0.8))/(1+tp_r)^1+Val!D9*(1-MIN((tp_g+0.01)/tp_roe,0.8))/(1+tp_r)^2+Val!D10*(1-MIN((tp_g+0.01)/tp_roe,0.8))/(1+tp_r)^3+Val!D11*(1-MIN((tp_g+0.01)/tp_roe,0.8))/(1+tp_r)^4+Val!D12*(1-MIN((tp_g+0.01)/tp_roe,0.8))/(1+tp_r)^5+Val!D13*(1-MIN((tp_g+0.01)/tp_roe,0.8))/(1+tp_r)^6+Val!D13*(1-MIN((tp_g+0.01)/tp_roe,0.8))*(1+(tp_g+0.01))/(tp_r-(tp_g+0.01))/(1+tp_r)^6))*(1+tp_r) -> 1331.2636 | D36: =tp_comp_adj -> 2244.9571 | E36: =tp_w_dcf*C36+(1-tp_w_dcf)*D36 -> 1788.1104 | F36: =E36/E$33-1 -> 0.037177609
A37: 長期成長 −1pt | B37: g 3% | C37: =(tp_wA*MAX(0,Val!B8*(1-MIN((tp_g-0.01)/tp_roe,0.8))/(1+tp_r)^1+Val!B9*(1-MIN((tp_g-0.01)/tp_roe,0.8))/(1+tp_r)^2+Val!B10*(1-MIN((tp_g-0.01)/tp_roe,0.8))/(1+tp_r)^3+Val!B11*(1-MIN((tp_g-0.01)/tp_roe,0.8))/(1+tp_r)^4+Val!B12*(1-MIN((tp_g-0.01)/tp_roe,0.8))/(1+tp_r)^5+Val!B13*(1-MIN((tp_g-0.01)/tp_roe,0.8))/(1+tp_r)^6+Val!B13*(1-MIN((tp_g-0.01)/tp_roe,0.8))*(1+(tp_g-0.01))/(tp_r-(tp_g-0.01))/(1+tp_r)^6)+tp_wB*MAX(0,Val!C8*(1-MIN((tp_g-0.01)/tp_roe,0.8))/(1+tp_r)^1+Val!C9*(1-MIN((tp_g-0.01)/tp_roe,0.8))/(1+tp_r)^2+Val!C10*(1-MIN((tp_g-0.01)/tp_roe,0.8))/(1+tp_r)^3+Val!C11*(1-MIN((tp_g-0.01)/tp_roe,0.8))/(1+tp_r)^4+Val!C12*(1-MIN((tp_g-0.01)/tp_roe,0.8))/(1+tp_r)^5+Val!C13*(1-MIN((tp_g-0.01)/tp_roe,0.8))/(1+tp_r)^6+Val!C13*(1-MIN((tp_g-0.01)/tp_roe,0.8))*(1+(tp_g-0.01))/(tp_r-(tp_g-0.01))/(1+tp_r)^6)+tp_wC*MAX(0,Val!D8*(1-MIN((tp_g-0.01)/tp_roe,0.8))/(1+tp_r)^1+Val!D9*(1-MIN((tp_g-0.01)/tp_roe,0.8))/(1+tp_r)^2+Val!D10*(1-MIN((tp_g-0.01)/tp_roe,0.8))/(1+tp_r)^3+Val!D11*(1-MIN((tp_g-0.01)/tp_roe,0.8))/(1+tp_r)^4+Val!D12*(1-MIN((tp_g-0.01)/tp_roe,0.8))/(1+tp_r)^5+Val!D13*(1-MIN((tp_g-0.01)/tp_roe,0.8))/(1+tp_r)^6+Val!D13*(1-MIN((tp_g-0.01)/tp_roe,0.8))*(1+(tp_g-0.01))/(tp_r-(tp_g-0.01))/(1+tp_r)^6))*(1+tp_r) -> 1114.7648 | D37: =tp_comp_adj -> 2244.9571 | E37: =tp_w_dcf*C37+(1-tp_w_dcf)*D37 -> 1679.861 | F37: =E37/E$33-1 -> -0.025611501
A38: DCF 權重 0.3 | C38: =(tp_wA*MAX(0,Val!B8*(1-MIN(tp_g/tp_roe,0.8))/(1+tp_r)^1+Val!B9*(1-MIN(tp_g/tp_roe,0.8))/(1+tp_r)^2+Val!B10*(1-MIN(tp_g/tp_roe,0.8))/(1+tp_r)^3+Val!B11*(1-MIN(tp_g/tp_roe,0.8))/(1+tp_r)^4+Val!B12*(1-MIN(tp_g/tp_roe,0.8))/(1+tp_r)^5+Val!B13*(1-MIN(tp_g/tp_roe,0.8))/(1+tp_r)^6+Val!B13*(1-MIN(tp_g/tp_roe,0.8))*(1+tp_g)/(tp_r-tp_g)/(1+tp_r)^6)+tp_wB*MAX(0,Val!C8*(1-MIN(tp_g/tp_roe,0.8))/(1+tp_r)^1+Val!C9*(1-MIN(tp_g/tp_roe,0.8))/(1+tp_r)^2+Val!C10*(1-MIN(tp_g/tp_roe,0.8))/(1+tp_r)^3+Val!C11*(1-MIN(tp_g/tp_roe,0.8))/(1+tp_r)^4+Val!C12*(1-MIN(tp_g/tp_roe,0.8))/(1+tp_r)^5+Val!C13*(1-MIN(tp_g/tp_roe,0.8))/(1+tp_r)^6+Val!C13*(1-MIN(tp_g/tp_roe,0.8))*(1+tp_g)/(tp_r-tp_g)/(1+tp_r)^6)+tp_wC*MAX(0,Val!D8*(1-MIN(tp_g/tp_roe,0.8))/(1+tp_r)^1+Val!D9*(1-MIN(tp_g/tp_roe,0.8))/(1+tp_r)^2+Val!D10*(1-MIN(tp_g/tp_roe,0.8))/(1+tp_r)^3+Val!D11*(1-MIN(tp_g/tp_roe,0.8))/(1+tp_r)^4+Val!D12*(1-MIN(tp_g/tp_roe,0.8))/(1+tp_r)^5+Val!D13*(1-MIN(tp_g/tp_roe,0.8))/(1+tp_r)^6+Val!D13*(1-MIN(tp_g/tp_roe,0.8))*(1+tp_g)/(tp_r-tp_g)/(1+tp_r)^6))*(1+tp_r) -> 1203.0741 | D38: =tp_comp_adj -> 2244.9571 | E38: =0.3*C38+(1-0.3)*D38 -> 1932.3922 | F38: =E38/E$33-1 -> 0.12086701
A39: DCF 權重 0.7 | C39: =(tp_wA*MAX(0,Val!B8*(1-MIN(tp_g/tp_roe,0.8))/(1+tp_r)^1+Val!B9*(1-MIN(tp_g/tp_roe,0.8))/(1+tp_r)^2+Val!B10*(1-MIN(tp_g/tp_roe,0.8))/(1+tp_r)^3+Val!B11*(1-MIN(tp_g/tp_roe,0.8))/(1+tp_r)^4+Val!B12*(1-MIN(tp_g/tp_roe,0.8))/(1+tp_r)^5+Val!B13*(1-MIN(tp_g/tp_roe,0.8))/(1+tp_r)^6+Val!B13*(1-MIN(tp_g/tp_roe,0.8))*(1+tp_g)/(tp_r-tp_g)/(1+tp_r)^6)+tp_wB*MAX(0,Val!C8*(1-MIN(tp_g/tp_roe,0.8))/(1+tp_r)^1+Val!C9*(1-MIN(tp_g/tp_roe,0.8))/(1+tp_r)^2+Val!C10*(1-MIN(tp_g/tp_roe,0.8))/(1+tp_r)^3+Val!C11*(1-MIN(tp_g/tp_roe,0.8))/(1+tp_r)^4+Val!C12*(1-MIN(tp_g/tp_roe,0.8))/(1+tp_r)^5+Val!C13*(1-MIN(tp_g/tp_roe,0.8))/(1+tp_r)^6+Val!C13*(1-MIN(tp_g/tp_roe,0.8))*(1+tp_g)/(tp_r-tp_g)/(1+tp_r)^6)+tp_wC*MAX(0,Val!D8*(1-MIN(tp_g/tp_roe,0.8))/(1+tp_r)^1+Val!D9*(1-MIN(tp_g/tp_roe,0.8))/(1+tp_r)^2+Val!D10*(1-MIN(tp_g/tp_roe,0.8))/(1+tp_r)^3+Val!D11*(1-MIN(tp_g/tp_roe,0.8))/(1+tp_r)^4+Val!D12*(1-MIN(tp_g/tp_roe,0.8))/(1+tp_r)^5+Val!D13*(1-MIN(tp_g/tp_roe,0.8))/(1+tp_r)^6+Val!D13*(1-MIN(tp_g/tp_roe,0.8))*(1+tp_g)/(tp_r-tp_g)/(1+tp_r)^6))*(1+tp_r) -> 1203.0741 | D39: =tp_comp_adj -> 2244.9571 | E39: =0.7*C39+(1-0.7)*D39 -> 1515.639 | F39: =E39/E$33-1 -> -0.12086701
A50: 案例區塊：每 GW 金額成長 低（情境 B）
A51: 項目 | B51: 單位 | C51: FY2025A | D51: FY2026（錨點） | E51: FY2027 | F51: FY2028 | G51: FY2029 | H51: FY2030（收斂） | I51: FY2031（收斂） | J51: FY2032（收斂） | K51: 說明
A52: A. AI 部署與每 GW AI 高速 PCB 金額（需求面；D 欄＝FY2026 校準年；每 GW 金額取自勝宏模型）
A53: AI IT 資本支出 × 情境顆數係數 | B53: US$B | D53: =itc_26*1 -> 781.87292 | E53: =itc_27*1*1 -> 1565.35 | F53: =itc_28*um28_B*1 -> 1587.4111 | G53: =itc_29*um29_B*1 -> 1921.3317
...

Sheet Sources
A1: 來源（公司原文＝金像電財報、月營收公告與法說會，經資料商與媒體轉述；券商與媒體估計皆為 Interested-party）
A2: 二手：優分析 2026-08-11（1H26、2Q26 營收、毛利率、淨利、EPS；7 月營收） | B2: https://uanalyze.com.tw/articles/7465753217
A3: 資料商：stockanalysis 季度損益（1Q25–1Q26 營收、毛利、營業利益、稅前淨利率、淨利） | B3: https://stockanalysis.com/quote/tpe/2368/financials/?p=quarterly
A4: 二手：technews 2026-10-08（9 月營收 93.20 億、前 9 月 733.79 億） | B4: https://finance.technews.tw/2026/10/08/gce-2368-202609-financial-report/
A5: 二手：優分析 2026-09-09（8 月營收、AI 占比約五成、泰國廠產值、2026 資本支出、中壢新廠、ASIC 設計風險） | B5: https://uanalyze.com.tw/articles/6187254928
A6: 二手：優分析 2026-10-05（Amazon 私募、79 億元資本支出） | B6: https://uanalyze.com.tw/articles/9313556134
A7: 二手：理財周刊 2026-10-14（3Q26 營收、2Q26 營業利益率與淨利率、FactSet EPS 中位數、Amazon 私募股數） | B7: https://www.moneyweekly.com.tw/_Article?AID=255441
A8: 二手：理財周刊 2026-09-23（2026 資本支出 190 億、各廠擴產時程、產能年增） | B8: https://www.moneyweekly.com.tw/_Article?AID=250910
A9: 二手：優分析 2026-03-10（FY2025 營收、毛利率、淨利、EPS 19.47、股利、擴產） | B9: https://uanalyze.com.tw/articles/8548248766
A10: 二手：經濟日報 2026-03-11（FY2025 淨利、4Q25） | B10: https://money.udn.com/money/amp/story/5607/9371693
A11: 公司法說（富果整理 2025-11-28；3Q25 產品組合、資本支出、生產基地） | B11: https://blog.fugle.tw/post/earnings-call-2368-2025-11-28
A12: 二手：鉅亨 2025-09-26（可轉債逾 90 億元、泰國一二期） | B12: https://m.cnyes.com/news/id/6169890
A13: 券商：外資（technews 2026-05-13；FY2027 EPS 65.39、目標價 1,310） | B13: https://finance.technews.tw/2026/05/13/three-pillars/
... A19: 資料商：HiStock（12 月 P/E 2021–2025；年度 EPS 2018–2025） | B19: https://histock.tw/stock/2368/%E6%9C%AC%E7%9B%8A%E6%AF%94
A20: 市場層：markets/network、markets/chip_bridge、tsmc 成品；victory_giant 成品（每 GW PCB 金額）、emc 成品（台光電每 GW CCL，Recon 用）（本 repo，唯讀）
A21: 無法取得：companiesmarketcap 金像電 P/E 頁（網站錯誤）；10-23 收盤 | B21: 未找到
A22: 待補（人工）：3Q26 財報與法說（11 月上旬）；10 月營收（11-10 前後）；分產品（AI 伺服器、交換器）營收與毛利率；2016–2020 營收與淨利；產能（萬㎡）與產值的公司原文；可轉債轉換價；資本支出與折舊路徑；前瞻 P/E 十年歷史（Bloomberg） | B22: 未找到
A23: SemiAnalysis | B23: 未使用
