Workbook

Sheet README
A1: 創意電子（3443.TW）收支與估值模型 v0.1.2（AI 半導體 Project：運算層，ASIC 設計服務＋量產；台積電體系） 2026-10-25
A2: 版本：v0.1（初版）。CPU 顆數＝台積電模型的 Google TPU 顆數 × CPU 對 TPU 配比；其他 ASIC 顆數讀台積電模型、每顆核心售價讀 Broadcom 模型，份額與 Broadcom、Marvell、聯發科合計不超過 100%；車用與其他營收用簡化成長。本版未做先驗。
A3: 模型命題：創意的營收由 NRE 轉為 Google 自研 Arm CPU（Axion）的 turnkey 量產（晶圓與封裝轉售、毛利率低）。FY2026 營收約翻倍、3Q26 單季 187.5 億元；以 TPU 顆數 × CPU 配比推 CPU 顆數，再加其他 ASIC、車用與 NRE，FY2027–28 的營收與 EPS 有多少？現價約 90 倍前瞻 P/E 需要哪一條路徑？
A4: 核心問題：在市場層 TPU 顆數（CY2027 5.5 百萬顆）與 CPU 對 TPU 配比口徑下，創意 FY2027–28 的 CPU 顆數與 EPS 離法人估計（CPU 400 萬顆、FY2027 EPS 94–139 元）多遠；差距靠配比、份額還是車用；現價隱含的倍數與同業差多少。
A6: 會計年度＝日曆年，FY(t)＝CY(t)，不平移。FY2025A 實績、FY2026 錨點、FY2027–FY2029 驅動因子推導、FY2030–FY2032 收斂法。金額：十億新台幣；EPS：新台幣（基本）。口徑：歸屬母公司淨利（TIFRS）。3Q26 財報 2026-10-29 公布，本版只納入 3Q26 營收實績。
A8: 驅動因子 → 推導量（全部唯讀上游，不修改）
A9: Google CPU 量產：tsmc 成品的 Google TPU 顆數 × 情境係數（CY2028–29；tsmc／markets/memory 同字母）× CPU 對 TPU 配比（CY2026 0.325 校準；CY2027 起 A／B／C 0.6／0.5／0.4）× 創意份額（CY2028 起 100%／90%／70%）× 每顆營收 1.0K（CY2028 起 ×1.2／1.1／1.0）× k_c（FY2026 以錨點 CPU 拆分 48% 校準）× 匯率 32。
A10: AI ASIC 量產：tsmc 成品的其他 ASIC 顆數 × 創意份額（CY2026 3%；CY2027 6%／4%／2%；CY2028 起 8%／5%／2%）× Broadcom 模型核心售價 6K × k_o。車用：FY2026 錨點（營收 5%）× FY2027 ×4.0／3.0／2.0、FY2028 ×2.0／1.6／1.2。其他（NRE＋其他量產）：FY2027 +15%／+8%／−5%、之後 +10%／+5%／0%。
A11: 毛利：AI 量產（CPU、AI ASIC）毛利率 13%（Assumed；情境 A +1pt、C −2pt）、車用 16%；其他營收毛利率為 FY2026 殘差（Derived，含 NRE）後沿用。營業費用彈性 0.3、年增下限 8%；營業外 0.5、稅率 15%、股數 134.01M。
A12: 校準：FY2026 ＝ 1H26 實績＋3Q26 營收實績（月營收）＋公司方向性說法（3Q 毛利率較 2Q 下滑、費用持平）＋4Q26 假設（營收季增 35%、毛利率 18.5%）。營收拆分（CPU 48%、AI ASIC 3%、車用 5%）為 Assumed。不用券商數字（只在 Recon 對帳）。
A13: 估值：Val 第 0 節目標價＝0.5 × DCF 目標價（股東現金流＝EPS ×（1 − g／ROE），FY2027–32 明確期＋永續，r 10%、g 4%，三情境權重 0.3／0.5／0.2，情境價值負值取 0）＋0.5 × Comparable 目標價（世芯、聯發科、博通、邁威爾前瞻 P/E 中位數 × 12 個月後前瞻 EPS；不含 A 股）；另列 Comparable 單獨目標價、市場共識目標價與差距拆解。十年 P/E 規則值 × FY2027 EPS 保留為參考（不是目標價）。本版未做先驗，無 Andy 合理 P/E 對照。
A14: 預估期間：FY2027–FY2029 由驅動因子推導；FY2030 起為收斂法，非驅動因子推導（營收年增由 FY2029 線性收斂到 fade_g、淨利率收斂到 fade_m，FY2032 達到；PL 頁灰底）。十年平均淨利率未找到，B、C 依工作單以 FY2029 × 0.8 代替。
... A22: v0.1.1（2026-10-25）：補上檔空間級距、投資建議、重點觀察（數值不變）。Val 頁末新增「上檔空間級距」「投資建議」兩列（Andy 2026-10-25 14:00、14:17 固定規則），README 頁末新增投資建議與重點觀察三點；既有儲存格位置與數值不變。
A23: ="投資建議："&Val!B135&"（依上檔空間固定規則）" -> 投資建議：放空（依上檔空間固定規則）
A24: ="重點觀察 1：目標價 NT$"&TEXT(Val!$B$39,"#,##0.00")&"（DCF "&TEXT(Val!$B$24,"#,##0.00")&"、Comparable（相對倍數調整後）"&TEXT(tp_comp_adj,"#,##0.00")&"；DCF 權重 "&TEXT(tp_w_dcf,"0%")&"），比現價 "&TEXT(px,"#,##0.00")&"（2026-10-22）"&IF(Val!$B$42>=0,"高 "&TEXT(Val!$B$42,"0.0%"),"低 "&TEXT(-Val!$B$42,"0.0%"))&"，級距 "&Val!$B$134&"、投資建議 "&Val!$B$135&"。相對倍數調整係數 "&TEXT(rm_factor,"0.00")&"（本公司 10 年前瞻倍數中位數 ÷ 同業的中位數，夾在 0.5–2.0；Val 第 0.5 節），調整前加權上檔空間 "&TEXT((tp_w_dcf*Val!$B$24+(1-tp_w_dcf)*Val!$B$35)/px-1,"+0.0%;−0.0%")&"；Comparable 單獨（市場主流同業法、未調整）為 "&TEXT(Val!$B$43,"+0.0%;−0.0%")&"。"&"以下為 2026-10-29 相對倍數調整前撰寫的說明，其中數字為調整前：目標價 NT$3,968（DCF 2,268、Comparable 相對倍數調整後 5,668 各半），比現價 7,585（2026-10-22）低 47.7%，級距 −25%～−50%，投資建議維持放空。v0.2 滾入 3Q26 實績（營收 187.5 億、毛利率 20.58%、EPS 16.95；前三季 EPS 40.8"&"4）：毛利率與營業外收入高於原假設，FY2026 EPS 60.7 → 62.2，加權目標價 3,911 → 3,968（+1.5%）。" -> 重點觀察 1：目標價 NT$3,968.04（DCF 2,267.79、Comparable（相對倍數調整後）5,668.29；DCF 權重 50%），比現價 7,585.00（2026-10-22）低 47.7%，級距 −25%～−50%、投資建議 放空。相對倍數調整係數 1.59（本公司 10 年前瞻倍數中位數 ÷ 同業的中位數，夾在 0.5–2.0；Val 第 0.5 節），調整前加權上檔空間 −61.5%；Comparable 單獨（市場主流同業法、未調整）為 −52.9%。以下為 2026-10-29 相對倍數調整前撰寫的說明，其中數字為調整前：目標價 NT$3,968（DCF 2,268、Comparable 相對倍數調整後 5,668 各半），比現價 7,585（2026-10-22）低 47.7%，級距 −25%～−50%，投資建議維持放空。v0.2 滾入 3Q26 實績（營收 187.5 億、毛利率 20.58%、EPS 16.95；前三季 EPS 40.84）：毛利率與營業外收入高於原假設，FY2026 EPS 60.7 → 62.2，加權目標價 3,911 → 3,968（+1.5%）。
A25: 重點觀察 2：情境分歧最大：FY2028 EPS A／B／C 為 199.7／115.2／52.0，DCF 情境價值 3,785／1,992／682；即使 A 情境 DCF 也只有現價的 50%。12 個月後前瞻 EPS 124.8，同業前瞻 P/E 中位數下的 Comparable 為 3,573（未調整），市場給創意的 Google CPU 成長溢價本模型只以相對倍數調整部分反映。
A26: 重點觀察 3：4Q26 仍為假設（營收季增 35%、毛利率 18.5%；公司未給季度區間指引）；CPU 對 TPU 配比是 FY2027 EPS 最敏感的變數（Sens 頁）。下一個檢驗點是 10–12 月月營收與 4Q26 財報（2027-02）。
A27: v0.1.2（2026-10-28）：分部原則重建（數值不變）。創意為單一應報導部門；Q 頁第 33 列起追加 FY2025 部門營收、營收類別（NRE 約 34%、Turnkey 約 64%，經濟日報轉述）與核對列「分部合計 − 合併營收」。推估年仍以 Google CPU／AI ASIC／車用／其他拆分，不拆 NRE／Turnkey。
A29: 2026-10-29：加權目標價中的 Comparable 改用相對倍數調整後的值（Val 第 0.5 節：同業前瞻倍數中位數 × 本公司 10 年相對同業的倍數比，Bloomberg 前瞻倍數；Andy 2026-10-27「照建議做」、10-29 資料取回）。「Comparable 目標價（市場主流同業法）」維持不調整。重點觀察 1 的第一句已改為公式；重點觀察 2、3 與其他說明中的目標價與上檔空間數字為調整前撰寫，以 Val 頁為準。
A31: v0.2（2026-10-31）：滾入 3Q26 實績（2026-10-29 財報：前三季營收 440.99 億、毛利 99.68 億、營業利益 60.52 億、淨利 54.73 億、EPS 40.84；3Q26＝前三季 − 上半年：營收 187.5 億、毛利率 20.58%、營業利益 25.54 億、EPS 16.95）；FY2026 EPS 60.7 → 62.2，加權目標價 3,911 → 3,968，投資建議維持放空。
A33: v0.1.3（2026-10-30）：依個股模型原則第 8 節調整 In 頁呈現（數值不變）。In 頁 D／F 欄名改「敏感度低」「敏感度高」（只用於 Sens 頁、不進目標價）；In 頁最後新增「情境驅動對照」一節，把上方各情境專屬輸入三情境並排（只引用上方各列，純展示）；HTML 驅動因子一節分「情境驅動」與「單一參數」兩張表。

Sheet In
A1: In — 輸入（藍字；基準欄 E，低 D、高 F）。金額：十億新台幣（NT$B）；每顆價格：千美元（US$K）；顆數：百萬顆；匯率：新台幣／美元。每個輸入附兩個來源（找不到者寫「未找到」）；公司原文算一個。【v0.1.3】基準欄 E 進主模型；D／F＝敏感度低／高，只用於 Sens 頁（一次動一個參數）、不進目標價；情境 A／B／C 的驅動見本頁最後一節「情境驅動對照」。
A2: 標記：Verified／Interested-party／Analogy／Assumed／Derived；Analogy、Assumed 給低／高區間，不當點估計（放情境或 Sens）。SemiAnalysis 未使用。公司財報與法說內容多取自媒體轉述（公司自 2026 年起不再給季度區間指引）；公司說法為 Interested-party；券商、資料商、媒體為 Interested-party
A3: 鍵 | B3: 項目 | C3: 單位 | D3: 敏感度低 | E3: 基準 | F3: 敏感度高 | G3: 標記 | H3: 來源1 | I3: 來源2／說明
A4: A. AI 加速器顆數（tsmc 成品；與 HBM、台積電、Broadcom、Marvell、聯發科模型同一份；情境係數讀台積電模型＝markets/memory SCEN_UNITS，不另訂）
A5: u_tpu_26 | B5: Google TPU 顆數 CY2026 | C5: 百萬顆 | E5: 3.85 | G5: Interested-party | H5: tsmc/dist/20261030_台積電個股模型_v0.4.1.xlsx｜In!E25 | I5: avgo 成品同值、markets/memory UNITS 同值（建置時檢查）
A6: u_tpu_27 | B6: Google TPU 顆數 CY2027 | C6: 百萬顆 | E6: 5.5 | G6: Interested-party | H6: tsmc/dist/20261030_台積電個股模型_v0.4.1.xlsx｜In!E26 | I6: 同上
A7: u_tpu_28 | B7: Google TPU 顆數 CY2028 | C7: 百萬顆 | E7: 7 | G7: Interested-party | H7: tsmc/dist/20261030_台積電個股模型_v0.4.1.xlsx｜In!E27 | I7: 同上
A8: g29_tpu | B8: Google TPU CY2029 顆數成長 | C8: % | E8: 0.15 | G8: Assumed | H8: tsmc/dist/20261030_台積電個股模型_v0.4.1.xlsx｜In!E28 | I8: markets/memory 無 2029；沿用台積電模型
A9: u_oth_26 | B9: 其他 ASIC（MTIA、Maia、Ascend 等） 顆數 CY2026 | C9: 百萬顆 | E9: 1 | G9: Derived／Assumed | H9: tsmc/dist/20261030_台積電個股模型_v0.4.1.xlsx｜In!E33 | I9: avgo 成品同值、markets/memory UNITS 同值（建置時檢查）
A10: u_oth_27 | B10: 其他 ASIC（MTIA、Maia、Ascend 等） 顆數 CY2027 | C10: 百萬顆 | E10: 4.5 | G10: Derived／Assumed | H10: tsmc/dist/20261030_台積電個股模型_v0.4.1.xlsx｜In!E34 | I10: 同上
A11: u_oth_28 | B11: 其他 ASIC（MTIA、Maia、Ascend 等） 顆數 CY2028 | C11: 百萬顆 | E11: 5 | G11: Derived／Assumed | H11: tsmc/dist/20261030_台積電個股模型_v0.4.1.xlsx｜In!E35 | I11: 同上
A12: g29_oth | B12: 其他 ASIC（MTIA、Maia、Ascend 等） CY2029 顆數成長 | C12: % | E12: 0.15 | G12: Assumed | H12: tsmc/dist/20261030_台積電個股模型_v0.4.1.xlsx｜In!E36 | I12: markets/memory 無 2029；沿用台積電模型
A13: um28_A | B13: 情境 A：CY2028 顆數 ÷ 基準 | C13: x | E13: 1 | G13: Assumed | H13: tsmc/dist/20261030_台積電個股模型_v0.4.1.xlsx｜In!E37 | I13: A＝基準；B＝AI 資本支出消化；C＝明顯下修（與台積電、Broadcom、Marvell、聯發科模型相同；markets/memory SCEN_UNITS，建置時檢查）
A14: um29_A | B14: 情境 A：CY2029 顆數 ÷ 基準 | C14: x | E14: 1 | G14: Assumed | H14: tsmc/dist/20261030_台積電個股模型_v0.4.1.xlsx｜In!E38 | I14: 同上
A15: um28_B | B15: 情境 B：CY2028 顆數 ÷ 基準 | C15: x | E15: 0.8 | G15: Assumed | H15: tsmc/dist/20261030_台積電個股模型_v0.4.1.xlsx｜In!E39 | I15: 同上
A16: um29_B | B16: 情境 B：CY2029 顆數 ÷ 基準 | C16: x | E16: 0.85 | G16: Assumed | H16: tsmc/dist/20261030_台積電個股模型_v0.4.1.xlsx｜In!E40 | I16: 同上
... A18: um29_C | B18: 情境 C：CY2029 顆數 ÷ 基準 | C18: x | E18: 0.6 | G18: Assumed | H18: tsmc/dist/20261030_台積電個股模型_v0.4.1.xlsx｜In!E42 | I18: 同上
A19: B. Google 自研 Arm CPU（Axion）量產：CPU 顆數＝TPU 顆數 × CPU 對 TPU 配比 × 創意份額（CPU 不占 TPU 加速器份額）
A20: att26 | B20: CY2026 CPU 對 TPU 配比（CPU 顆數 ÷ TPU 顆數；校準年） | C20: x | D20: 0.25 | E20: 0.325 | F20: 0.4 | G20: Interested-party | H20: 經濟日報 2026-10-07（3Q26 營收、CPU 出貨估計）：2026 年 CPU 出貨約 125 萬顆（法人估計）÷ 市場層 TPU 3.85 百萬顆 | I20: CY2026 只用於校準（k_c 吸收）；公司未揭露客戶與顆數
A21: att_A | B21: CY2027 起 CPU 對 TPU 配比（情境 A） | C21: x | D21: 0.25 | E21: 0.6 | F21: 0.75 | G21: Assumed | H21: 經濟日報 2026-10-07（3Q26 營收、CPU 出貨估計）：新平台 CPU 對 TPU 配置由 1:4 提升到 1:2（法人） | I21: 經濟日報 2026-04-28（本國投顧：2027 營收結構）：第八代 AI ASIC 伺服器由每顆 x86 CPU 配 4 或 8 顆 ASIC 改為每顆 Arm CPU 配 2 顆（本國投顧）；A 另含一般運算 Axion 執行個體
A22: att_B | B22: CY2027 起 CPU 對 TPU 配比（情境 B） | C22: x | E22: 0.5 | G22: Assumed | H22: 同上 | I22: A 最有利、C 最不利
A23: att_C | B23: CY2027 起 CPU 對 TPU 配比（情境 C） | C23: x | E23: 0.4 | G23: Assumed | H23: 同上 | I23: A 最有利、C 最不利
A24: gsh26 | B24: 創意占 Google 自研 CPU 顆數 CY2026–27 | C24: % | D24: 0.8 | E24: 1 | F24: 1 | G24: Assumed | H24: 公司：最大 CPU 客戶產能已確保（2026-01-30 法說，工商時報轉述） | I24: 二手：Google Arm CPU 專案為創意（經濟日報 2026-01-31）；客戶名稱公司未揭露
A25: gsh28_A | B25: 創意占 Google 自研 CPU 顆數 CY2028 起（情境 A；下一代 CPU） | C25: % | D25: 0.5 | E25: 1 | F25: 1 | G25: Assumed | H25: 下一代 CPU 的設計夥伴：未找到 | I25: C＝下一代 CPU 部分轉給其他夥伴或客戶自行設計（COT）
A26: gsh28_B | B26: 創意占 Google 自研 CPU 顆數 CY2028 起（情境 B；下一代 CPU） | C26: % | E26: 0.9 | G26: Assumed | H26: 同上 | I26: A 最有利、C 最不利
A27: gsh28_C | B27: 創意占 Google 自研 CPU 顆數 CY2028 起（情境 C；下一代 CPU） | C27: % | E27: 0.7 | G27: Assumed | H27: 同上 | I27: A 最有利、C 最不利
A28: pc_cpu | B28: 每顆 CPU 營收（turnkey：晶圓＋封裝測試轉售；未校準） | C28: US$K | D28: 0.7 | E28: 1 | F28: 1.5 | G28: Assumed | H28: 公司未揭露；3 奈米大型 Arm CPU 晶圓與封裝成本（Assumed） | I28: 校準係數 k_c 以 FY2026 CPU 營收吸收單價誤差
A29: pfc_A | B29: CY2028 起每顆 CPU 營收係數（下一代 CPU；情境 A） | C29: x | D29: 0.8 | E29: 1.2 | F29: 1.5 | G29: Assumed | H29: 公司：第四季開始出貨下一代 CPU 產品（經濟日報 2026-10-07 轉述法人） | I29: 下一代製程與單價：未找到
A30: pfc_B | B30: CY2028 起每顆 CPU 營收係數（下一代 CPU；情境 B） | C30: x | E30: 1.1 | G30: Assumed | H30: 同上 | I30: A 最有利、C 最不利
A31: pfc_C | B31: CY2028 起每顆 CPU 營收係數（下一代 CPU；情境 C） | C31: x | E31: 1 | G31: Assumed | H31: 同上 | I31: A 最有利、C 最不利
A32: uf | B32: 創意 CPU 與 AI ASIC 顆數係數（Sens 用；CY2027 起） | C32: x | D32: 0.8 | E32: 1 | F32: 1.2 | G32: Assumed | H32: 無 | I32: ±20%
A33: C. AI ASIC 量產（其他 ASIC：Maia 等）：每顆規格讀 Broadcom 模型（唯讀）；份額與 Broadcom、Marvell、聯發科合計 ≤ 100%
A34: core_oth | B34: 其他 ASIC 每顆核心售價（不含 HBM） | C34: US$K | D34: 4 | E34: 6 | F34: 9 | G34: Assumed | H34: avgo/dist/20261030_Broadcom個股模型_v0.3.1.xlsx｜In!E57 | I34: Broadcom 模型的 ASIC 每顆規格（本專案權威）；創意 turnkey 只含晶圓與封裝轉售，以 k_o 校準
A35: av_oth_26 | B35: Broadcom 占其他 ASIC 顆數 CY2026（份額加總檢查用） | C35: % | E35: 0.35 | G35: Assumed | H35: avgo/dist/20261030_Broadcom個股模型_v0.3.1.xlsx｜In!E53 | I35: Broadcom 模型
A36: mv_oth_26 | B36: Marvell 占其他 ASIC 顆數 CY2026（份額加總檢查用） | C36: % | E36: 0.05 | G36: Assumed | H36: mrvl/dist/20261030_邁威爾個股模型_v0.2.4.xlsx｜In!E48 | I36: Marvell 模型
A37: mk_oth_26 | B37: 聯發科占其他 ASIC 顆數 CY2026（高值；份額加總檢查用） | C37: % | E37: 0.02 | G37: Assumed | H37: mediatek/dist/20261030_聯發科個股模型_v0.1.3.xlsx｜In!F45 | I37: 聯發科模型高值（基準 0）；世芯模型只有 Trainium 份額，其他 ASIC 為 0
A38: av_oth_27 | B38: Broadcom 占其他 ASIC 顆數 CY2027（份額加總檢查用） | C38: % | E38: 0.55 | G38: Assumed | H38: avgo/dist/20261030_Broadcom個股模型_v0.3.1.xlsx｜In!E54 | I38: Broadcom 模型
A39: mv_oth_27 | B39: Marvell 占其他 ASIC 顆數 CY2027（份額加總檢查用） | C39: % | E39: 0.06 | G39: Assumed | H39: mrvl/dist/20261030_邁威爾個股模型_v0.2.4.xlsx｜In!E49 | I39: Marvell 模型
A40: mk_oth_27 | B40: 聯發科占其他 ASIC 顆數 CY2027（高值；份額加總檢查用） | C40: % | E40: 0.03 | G40: Assumed | H40: mediatek/dist/20261030_聯發科個股模型_v0.1.3.xlsx｜In!F46 | I40: 聯發科模型高值（基準 0）；世芯模型只有 Trainium 份額，其他 ASIC 為 0
A41: av_oth_28 | B41: Broadcom 占其他 ASIC 顆數 CY2028（份額加總檢查用） | C41: % | E41: 0.55 | G41: Assumed | H41: avgo/dist/20261030_Broadcom個股模型_v0.3.1.xlsx｜In!E55 | I41: Broadcom 模型
...

Sheet Q
A1: Q — 實績與 FY2026 錨點（十億新台幣；EPS 為新台幣、基本；股數為十億股）。藍字＝輸入（媒體轉述公司財報、stockanalysis）；黑字＝公式。CPU、AI ASIC、車用、其他的拆分為 Assumed（公司未揭露金額）
A2: v0.2（2026-10-31）：FY2026 錨點＝1Q、2Q、3Q26 實績（3Q26＝前三季財報 − 上半年；2026-10-29 公布）＋4Q26 假設；公司自 2026 年起不給季度區間指引
A3: 項目 | B3: FY2025A | C3: 1Q26（實績） | D3: 2Q26（實績） | E3: 3Q26（實績） | F3: 4Q26（模型） | G3: FY2026 錨點 | H3: 標記 | I3: 來源1 | J3: 來源2／說明
A4: 營收 | B4: 34.141 | C4: 11.448 | D4: 13.897 | E4: =q3_rev -> 18.754 | F4: =E4*(1+q4_g) -> 25.3179 | G4: =SUM(C4:F4) -> 69.4169 | H4: Verified／Assumed（4Q） | I4: FY2025：stockanalysis 財報頁、經濟日報 2026-01-31；1Q26：科技新報 2026-05-05／05-08；2Q26：經濟日報 2026-07-30 | J4: 3Q26：月營收實績（科技新報）；1H26 253.4 億（經濟日報）
A5: Google CPU 量產（年度拆分） | B5: =B4*cpu_sh25 -> 6.14538 | G5: =G4*cpu_sh26 -> 33.320112 | H5: Assumed | I5: In 頁 E 節 | J5: 季度拆分未揭露；只在年度欄拆分
A6: AI ASIC 量產（其他 ASIC） | B6: =B4*asic_sh25 -> 1.70705 | G6: =G4*asic_sh26 -> 2.082507 | H6: Assumed | I6: In 頁 E 節 | J6: —
A7: 車用 | B7: =B4*auto_sh25 -> 1.02423 | G7: =G4*auto_sh26 -> 3.470845 | H7: Interested-party／Assumed | I7: In 頁 E 節 | J7: 公司：2026 年車用占營收個位數
A8: 其他（NRE＋BMC、SSD 控制器、加密貨幣等量產） | B8: =B4-B5-B6-B7 -> 25.26434 | G8: =G4-G5-G6-G7 -> 30.543436 | H8: Derived | I8: — | J8: FY2025 NRE 約占 34%（經濟日報 2026-01-31）；公司：FY2026 NRE 年增 15–19%
A9: 毛利 | B9: 8.454 | C9: =25.345*0.241-D9 -> 3.106393 | D9: =13.897*0.216 -> 3.001752 | E9: =9.967659-C9-D9 -> 3.859514 | F9: =F4*q4_gm -> 4.6838115 | G9: =SUM(C9:F9) -> 14.651471 | H9: Verified（毛利率 × 營收）／Interested-party（3Q）／Assumed（4Q） | I9: FY2025：stockanalysis 財報頁、經濟日報 2026-01-31；1Q26：科技新報 2026-05-05／05-08；2Q26：經濟日報 2026-07-30 | J9: 2Q26 毛利率 21.6%、1H26 24.1%（經濟日報；工商時報 2Q26 為 21.5%）；1Q26＝1H26 − 2Q26
A10: 毛利率 | B10: =B9/B4 -> 0.24762016 | C10: =C9/C4 -> 0.2713481 | D10: =D9/D4 -> 0.216 | E10: =E9/E4 -> 0.20579684 | F10: =F9/F4 -> 0.185 | G10: =G9/G4 -> 0.21106489 | H10: Derived | I10: — | J10: 公司：1Q26 約 27.2%、2Q26 21.6%
A11: 營業費用 | B11: =B9-B12 -> 4.104 | C11: =C9-C12 -> 1.284783 | D11: =D9-D12 -> 1.325752 | E11: =E9-E12 -> 1.305437 | F11: =q4_opx -> 1.45 | G11: =SUM(C11:F11) -> 5.365972 | H11: Derived／Interested-party／Assumed | I11: FY2025：stockanalysis 財報頁、經濟日報 2026-01-31；1Q26：科技新報 2026-05-05／05-08；2Q26：經濟日報 2026-07-30 | J11: 毛利 − 營業利益
A12: 營業利益 | B12: 4.35 | C12: =25.345*0.138-D12 -> 1.82161 | D12: 1.676 | E12: =6.051687-C12-D12 -> 2.554077 | F12: =F9-F11 -> 3.2338115 | G12: =SUM(C12:F12) -> 9.2854985 | H12: Verified／Derived | I12: FY2025：stockanalysis 財報頁、經濟日報 2026-01-31；1Q26：科技新報 2026-05-05／05-08；2Q26：經濟日報 2026-07-30 | J12: 2Q26 16.76 億；1H26 營業利益率 13.8%（經濟日報）
A13: 營業外淨額 | B13: =B14-B12 -> 0.092 | C13: =C14-C12 -> 0.082876228 | D13: =D14-D12 -> 0.12319568 | E13: =6.306235-6.051687-C13-D13 -> 0.048476095 | F13: =q_nonop -> 0.13 | G13: =SUM(C13:F13) -> 0.384548 | H13: Derived／Assumed | I13: FY2025：stockanalysis 財報頁、經濟日報 2026-01-31；1Q26：科技新報 2026-05-05／05-08；2Q26：經濟日報 2026-07-30 | J13: 稅前 − 營業利益
A14: 稅前利益 | B14: 4.442 | C14: =C17/(1-t_h1) -> 1.9044862 | D14: =D17/(1-t_h1) -> 1.7991957 | E14: =E12+E13 -> 2.6025531 | F14: =F12+F13 -> 3.3638115 | G14: =SUM(C14:F14) -> 9.6700465 | H14: Derived | I14: FY2025：stockanalysis 財報頁、經濟日報 2026-01-31；1Q26：科技新報 2026-05-05／05-08；2Q26：經濟日報 2026-07-30 | J14: FY2025：stockanalysis 稅前淨利率推得約 44.42 億；1Q、2Q26＝淨利 ÷（1 − 近 12 月稅率）
A15: 所得稅 | B15: =B14-B17 -> 0.672 | C15: =C14-C17 -> 0.25848623 | D15: =D14-D17 -> 0.24419568 | E15: =E14-E17 -> 0.33010809 | F15: =F14*q_tax -> 0.50457173 | G15: =SUM(C15:F15) -> 1.3373617 | H15: Derived／Assumed | I15: FY2025：stockanalysis 財報頁、經濟日報 2026-01-31；1Q26：科技新報 2026-05-05／05-08；2Q26：經濟日報 2026-07-30 | J15: 稅前 − 淨利
A16: 有效稅率 | B16: =B15/B14 -> 0.15128321 | C16: =C15/C14 -> 0.13572491 | D16: =D15/D14 -> 0.13572491 | E16: =E15/E14 -> 0.1268401 | F16: =F15/F14 -> 0.15 | G16: =G15/G14 -> 0.13829941 | H16: Derived | I16: — | J16: —
A17: 歸屬母公司淨利 | B17: 3.77 | C17: 1.646 | D17: 1.555 | E17: =5.473445-C17-D17 -> 2.272445 | F17: =F14-F15 -> 2.8592398 | G17: =SUM(C17:F17) -> 8.3326848 | H17: Verified／Derived | I17: FY2025：stockanalysis 財報頁、經濟日報 2026-01-31；1Q26：科技新報 2026-05-05／05-08；2Q26：經濟日報 2026-07-30 | J17: 無重大非控制權益（假設）
A18: 加權股數（十億股） | B18: =3.77/28.13 -> 0.13402062 | C18: =1.646/12.28 -> 0.13403909 | D18: =1.555/11.61 -> 0.13393626 | E18: =q_sh -> 0.13401 | F18: =q_sh -> 0.13401 | G18: =AVERAGE(C18:F18) -> 0.13399884 | H18: Derived | I18: 淨利 ÷ EPS（公司） | J18: —
A19: EPS（基本） | B19: =B17/B18 -> 28.13 | C19: =C17/C18 -> 12.28 | D19: =D17/D18 -> 11.61 | E19: =E17/E18 -> 16.957279 | F19: =F17/F18 -> 21.336018 | G19: =G17/G18 -> 62.184754 | H19: Derived | I19: 淨利 ÷ 股數 | J19: —
A20: 公司揭露 EPS | B20: 28.13 | C20: 12.28 | D20: 11.61 | E20: =40.84-C20-D20 -> 16.95 | H20: Verified | I20: FY2025：stockanalysis 財報頁、經濟日報 2026-01-31；1Q26：科技新報 2026-05-05／05-08；2Q26：經濟日報 2026-07-30 | J20: HiStock：FY2025 28.13（stockanalysis 28.01）、1Q26 12.28、2Q26 11.61；3Q26＝前三季 40.84 − 上半年（中央社：16.95）
A22: FY2026 錨點的檢查（參考；校準未使用券商數字）
A23: FY2026 營收年增 | B23: =G4/B4-1 -> 1.0332416
A24: 3Q26 營收季增 | B24: =E4/D4-1 -> 0.34949989
A25: FY2026 毛利率（公司：20% 以上） | B25: =G10 -> 0.21106489
A26: FY2026 營業利益率（公司：雙位數） | B26: =G12/G4 -> 0.13376423
A27: FY2026 其他營收年增 | B27: =G8/B8-1 -> 0.20895444
A28: 核對：FY2026 其他營收毛利率（以 m_tk、m_auto 推得） | B28: =(G9-m_tk*(G5+G6)-m_auto*G7)/G8 -> 0.3108293
A29: 檢查：1H26 營收 自算 − 公司 25.34（應約為 0） | B29: =C4+D4-25.34 -> 0.005
A30: 檢查：1H26 歸屬淨利 自算 − 公司 3.2（應約為 0） | B30: =C17+D17-3.2 -> 0.001
A31: 檢查：FY2025 營業費用 ÷ 營收 | B31: =B11/B4 -> 0.12020738
A33: 官方報告分部與營收類別（FY2025；分部原則第 3 條）
A34: 單一營運部門（ASIC 設計服務）營收 | B34: 34.141 | H34: Verified | I34: 公司 FY2025 財報：單一應報導部門 | J34: 與第 4 列 FY2025 營收同一數字（公司揭露）
A35: 委託設計（NRE） | B35: =B34*0.34 -> 11.60794 | H35: Interested-party | I35: 經濟日報 2026-01-31（萬寶週刊）：NRE 約占 34% | J35: 比重為媒體轉述公司數字；金額為推得
A36: 量產（Turnkey） | B36: =B34*0.64 -> 21.85024 | H36: Interested-party | I36: 同上：Turnkey 約占 64% | J36: 本模型的 Google CPU、AI ASIC、車用量產皆屬 Turnkey；推估年不拆 NRE／Turnkey
A37: 其他（差額） | B37: =B34-B35-B36 -> 0.68282 | H37: Derived | I37: — | J37: 原文未說明其餘約 2%
A38: 檢查：分部合計 − 合併營收 | B38: =B34-B4 -> 0 | H38: Derived | I38: — | J38: 應為 0

Sheet Units
A1: Units — 創意 CPU 與 AI ASIC 量產（情境 A）。顆數：百萬顆（日曆年；TPU、其他 ASIC 顆數與 HBM、台積電、Broadcom、Marvell、聯發科模型同一份）；其他 ASIC 每顆核心售價取自 Broadcom 模型（本專案權威，唯讀）；每顆價：US$K
A3: 項目 | B3: 單位 | C3: CY2026 | D3: CY2027 | E3: CY2028 | F3: CY2029 | G3: 說明
A4: 1. Google 自研 Arm CPU 與其他 ASIC（情境 A；創意營收口徑＝晶圓與封裝轉售，乘校準係數）
A5: Google TPU 市場顆數 | B5: 百萬顆 | C5: =PL!D63 -> 3.85 | D5: =PL!E63 -> 5.5 | E5: =PL!F63 -> 7 | F5: =PL!G63 -> 8.05 | G5: tsmc 成品 In 頁
A6: CPU 對 TPU 配比 | B6: x | C6: =PL!D64 -> 0.325 | D6: =PL!E64 -> 0.6 | E6: =PL!F64 -> 0.6 | F6: =PL!G64 -> 0.6 | G6: In 頁 B 節（CY2026 法人估計；CY2027 起 Assumed）
A7: 創意 CPU 顆數 | B7: 百萬顆 | C7: =PL!D66 -> 1.25125 | D7: =PL!E66 -> 3.3 | E7: =PL!F66 -> 4.2 | F7: =PL!G66 -> 4.83 | G7: TPU 顆數 × 配比 × 創意份額
A8: 每顆創意 CPU 營收（校準後） | B8: US$K | C8: =PL!D73 -> 0.84270443 | D8: =PL!E73 -> 0.84270443 | E8: =PL!F73 -> 1.0112453 | F8: =PL!G73 -> 1.0112453 | G8: 每顆營收 × k_c
A9: 創意 CPU 營收（美元） | B9: US$B | C9: =PL!D70 -> 1.0544339 | D9: =PL!E70 -> 2.7809246 | E9: =PL!F70 -> 4.2472304 | F9: =PL!G70 -> 4.8843149 | G9: —
A10: 其他 ASIC 市場顆數 | B10: 百萬顆 | C10: =PL!D75 -> 1 | D10: =PL!E75 -> 4.5 | E10: =PL!F75 -> 5 | F10: =PL!G75 -> 5.75 | G10: tsmc 成品 In 頁（含 Ascend 等非台積電產品，份額分母偏大）
A11: 創意份額：其他 ASIC | B11: % | C11: =PL!D76 -> 0.03 | D11: =PL!E76 -> 0.06 | E11: =PL!F76 -> 0.08 | F11: =PL!G76 -> 0.08 | G11: In 頁 C 節（Assumed）
A12: 創意 AI ASIC 顆數 | B12: 百萬顆 | C12: =PL!D77 -> 0.03 | D12: =PL!E77 -> 0.27 | E12: =PL!F77 -> 0.4 | F12: =PL!G77 -> 0.46 | G12: 市場層顆數 × 份額
A13: 創意 AI ASIC 營收（美元） | B13: US$B | C13: =PL!D80 -> 0.06590212 | D13: =PL!E80 -> 0.59311908 | E13: =PL!F80 -> 0.87869494 | F13: =PL!G80 -> 1.0104992 | G13: 顆數 × 每顆核心售價 × k_o
A15: 2. 份額加總檢查（Broadcom＋Marvell＋聯發科＋創意 ≤ 100%；各公司份額讀各自成品 In 頁；世芯只有 Trainium 份額）
A16: Broadcom＋Marvell＋聯發科（高）＋創意：其他 ASIC（情境 A） | B16: % | C16: =av_oth_26+mv_oth_26+mk_oth_26+PL!D76 -> 0.45 | D16: =av_oth_27+mv_oth_27+mk_oth_27+PL!E76 -> 0.7 | E16: =av_oth_28+mv_oth_28+mk_oth_28+PL!F76 -> 0.83 | F16: =av_oth_28+mv_oth_28+mk_oth_28+PL!G76 -> 0.83 | G16: 其餘為客戶自行設計（COT）或其他夥伴
A17: Broadcom＋Marvell＋聯發科（高）＋創意：其他 ASIC（情境 B） | B17: % | C17: =av_oth_26+mv_oth_26+mk_oth_26+PL!D124 -> 0.45 | D17: =av_oth_27+mv_oth_27+mk_oth_27+PL!E124 -> 0.68 | E17: =av_oth_28+mv_oth_28+mk_oth_28+PL!F124 -> 0.8 | F17: =av_oth_28+mv_oth_28+mk_oth_28+PL!G124 -> 0.8 | G17: 同上
A18: Broadcom＋Marvell＋聯發科（高）＋創意：其他 ASIC（情境 C） | B18: % | C18: =av_oth_26+mv_oth_26+mk_oth_26+PL!D172 -> 0.45 | D18: =av_oth_27+mv_oth_27+mk_oth_27+PL!E172 -> 0.66 | E18: =av_oth_28+mv_oth_28+mk_oth_28+PL!F172 -> 0.77 | F18: =av_oth_28+mv_oth_28+mk_oth_28+PL!G172 -> 0.77 | G18: 同上
A19: 創意其他 ASIC 份額上限（1 − Broadcom − Marvell − 聯發科高值） | B19: % | C19: =1-av_oth_26-mv_oth_26-mk_oth_26 -> 0.58 | D19: =1-av_oth_27-mv_oth_27-mk_oth_27 -> 0.36 | E19: =1-av_oth_28-mv_oth_28-mk_oth_28 -> 0.25 | F19: =1-av_oth_28-mv_oth_28-mk_oth_28 -> 0.25 | G19: In 頁份額高值受此上限限制（建置時檢查）
A20: Broadcom＋Marvell＋聯發科：Google TPU（基準；創意不占） | B20: % | C20: =av_tpu_26 -> 0.95 | D20: =av_tpu_27 -> 0.95 | E20: =av_tpu_28 -> 0.98 | F20: =av_tpu_28 -> 0.98 | G20: 創意的 Google 營收為 CPU，不占 TPU 加速器份額
A22: 3. 校準值（只用 FY2026 已發生的實績與錨點拆分；不用共識、不用 FY2027 起的目標）
A23: CPU 校準係數 k_c | C23: =PL!D69 -> 0.84270443 | G23: FY2026 CPU 營收 ÷ 未校準由下而上
A24: AI ASIC 校準係數 k_o | C24: =PL!D79 -> 0.36612289 | G24: FY2026 AI ASIC ÷（顆數 × Broadcom 核心售價）
A25: 其他營收毛利率（FY2026 殘差） | C25: =PL!D92 -> 0.3108293 | G25: 讓 FY2026 毛利等於錨點
A27: 讀法：創意的 AI 營收以 Google 自研 CPU 為主，顆數隨 TPU 顆數與 CPU 對 TPU 配比變動，不占 TPU 加速器份額；其他 ASIC 份額受 Broadcom、Marvell、聯發科份額共同限制。

Sheet PL
A1: PL — 創意損益（十億新台幣；EPS 新台幣、基本；歸屬母公司）。FY2025A 實績、FY2026 錨點（三情境相同），FY2027–FY2029 由驅動因子推導，FY2030–FY2032 為收斂法。FY(t)＝CY(t)。三情境各一個完整推導區塊（本頁下方），頂端為摘要
A2: 灰底＝FY2030–FY2032 收斂法（上游顆數只到 CY2029）：營收年增線性收斂到 fade_g、淨利率線性收斂到 fade_m（In 頁 I 節），非驅動因子推導
A3: 情境／項目 | B3: 單位 | C3: FY2025A | D3: FY2026（錨點） | E3: FY2027 | F3: FY2028 | G3: FY2029 | H3: FY2030（收斂） | I3: FY2031（收斂） | J3: FY2032（收斂） | K3: 說明
A4: 情境 A
A5: 營收 | B5: NT$B | C5: =C85 -> 34.141 | D5: =D85 -> 69.4169 | E5: =E85 -> 156.97773 | F5: =F85 -> 230.43382 | G5: =G85 -> 264.45535 | H5: =H85 -> 295.77414 | I5: =I85 -> 322.16126 | J5: =J85 -> 341.49094
A6: 營收年增 | B6: % | D6: =D86 -> 1.0332416 | E6: =E86 -> 1.2613763 | F6: =F86 -> 0.46793953 | G6: =G86 -> 0.14764126 | H6: =H86 -> 0.1184275 | I6: =I86 -> 0.089213752 | J6: =J86 -> 0.06
A7: Google CPU 量產 | B7: NT$B | C7: =C72 -> 6.14538 | D7: =D72 -> 33.320112 | E7: =E72 -> 88.989588 | F7: =F72 -> 135.91137 | G7: =G72 -> 156.29808
A8: AI ASIC 量產（其他 ASIC） | B8: NT$B | C8: =C81 -> 1.70705 | D8: =D81 -> 2.082507 | E8: =E81 -> 18.979811 | F8: =F81 -> 28.118238 | G8: =G81 -> 32.335974
A9: 車用 | B9: NT$B | C9: =C83 -> 1.02423 | D9: =D83 -> 3.470845 | E9: =E83 -> 13.88338 | F9: =F83 -> 27.76676 | G9: =G83 -> 33.320112
A10: 其他（NRE＋其他量產） | B10: NT$B | C10: =C84 -> 25.26434 | D10: =D84 -> 30.543436 | E10: =E84 -> 35.124951 | F10: =F84 -> 38.637447 | G10: =G84 -> 42.501191
A11: 毛利率 | B11: % | C11: =C94 -> 0.24762016 | D11: =D94 -> 0.21106489 | E11: =E94 -> 0.17999318 | F11: =F94 -> 0.17105336 | G11: =G94 -> 0.16997425
A12: 營業利益率 | B12: % | C12: =C97 -> 0.12741279 | D12: =D97 -> 0.13376423 | E12: =E97 -> 0.13287487 | F12: =F97 -> 0.13444908 | G12: =G97 -> 0.13552741
A13: 歸屬母公司淨利 | B13: NT$B | C13: =C101 -> 3.77 | D13: =D101 -> 8.3326848 | E13: =E101 -> 18.154636 | F13: =F101 -> 26.759372 | G13: =G101 -> 30.889806 | H13: =H101 -> 34.548009 | I13: =I101 -> 37.630167 | J13: =J101 -> 39.887977
A14: 淨利率 | B14: % | C14: =C105 -> 0.11042442 | D14: =D105 -> 0.12003827 | E14: =E105 -> 0.11565103 | F14: =F105 -> 0.11612607 | G14: =G105 -> 0.11680537 | H14: =H105 -> 0.11680537 | I14: =I105 -> 0.11680537 | J14: =J105 -> 0.11680537
A15: EPS | B15: NT$ | C15: =C103 -> 28.13 | D15: =D103 -> 62.184754 | E15: =E103 -> 135.47225 | F15: =F103 -> 199.68191 | G15: =G103 -> 230.50374 | H15: =H103 -> 257.80172 | I15: =I103 -> 280.80118 | J15: =J103 -> 297.64925
A16: EPS 年增 | B16: % | D16: =D104 -> 1.2106205 | E16: =E104 -> 1.1785445 | F16: =F104 -> 0.47396906 | G16: =G104 -> 0.15435467 | H16: =H104 -> 0.1184275 | I16: =I104 -> 0.089213752 | J16: =J104 -> 0.06
A18: 情境 B
A19: 營收 | B19: NT$B | C19: =C133 -> 34.141 | D19: =D133 -> 69.4169 | E19: =E133 -> 130.21064 | F19: =F133 -> 140.10669 | G19: =G133 -> 163.20931 | H19: =H133 -> 183.32682 | I19: =I133 -> 198.29197 | J19: =J133 -> 206.22365
A20: 營收年增 | B20: % | D20: =D134 -> 1.0332416 | E20: =E134 -> 0.87577727 | F20: =F134 -> 0.076000257 | G20: =G134 -> 0.16489306 | H20: =H134 -> 0.12326204 | I20: =I134 -> 0.08163102 | J20: =J134 -> 0.04
A21: Google CPU 量產 | B21: NT$B | C21: =C120 -> 6.14538 | D21: =D120 -> 33.320112 | E21: =E120 -> 74.15799 | F21: =F120 -> 74.751254 | G21: =G120 -> 91.336689
A22: AI ASIC 量產（其他 ASIC） | B22: NT$B | C22: =C129 -> 1.70705 | D22: =D129 -> 2.082507 | E22: =E129 -> 12.653207 | F22: =F129 -> 14.059119 | G22: =G129 -> 17.178486
A23: 車用 | B23: NT$B | C23: =C131 -> 1.02423 | D23: =D131 -> 3.470845 | E23: =E131 -> 10.412535 | F23: =F131 -> 16.660056 | G23: =G131 -> 18.326062
A24: 其他（NRE＋其他量產） | B24: NT$B | C24: =C132 -> 25.26434 | D24: =D132 -> 30.543436 | E24: =E132 -> 32.986911 | F24: =F132 -> 34.636256 | G24: =G132 -> 36.368069
A25: 毛利率 | B25: % | C25: =C142 -> 0.24762016 | D25: =D142 -> 0.21106489 | E25: =E142 -> 0.17820939 | F25: =F142 -> 0.17827073 | G25: =G142 -> 0.17366292
A26: 營業利益率 | B26: % | C26: =C145 -> 0.12741279 | D26: =D145 -> 0.13376423 | E26: =E145 -> 0.12617224 | F26: =F145 -> 0.12604014 | G26: =G145 -> 0.1252387
A27: 歸屬母公司淨利 | B27: NT$B | C27: =C149 -> 3.77 | D27: =D149 -> 8.3326848 | E27: =E149 -> 14.389623 | F27: =F149 -> 15.435207 | G27: =G149 -> 17.799103 | H27: =H149 -> 19.326622 | I27: =I149 -> 20.183437 | J27: =J149 -> 20.241104
A28: 淨利率 | B28: % | C28: =C153 -> 0.11042442 | D28: =D153 -> 0.12003827 | E28: =E153 -> 0.11051035 | F28: =F153 -> 0.11016752 | G28: =G153 -> 0.10905691 | H28: =H153 -> 0.10542168 | I28: =I153 -> 0.10178645 | J28: =J153 -> 0.098151223
A29: EPS | B29: NT$ | C29: =C151 -> 28.13 | D29: =D151 -> 62.184754 | E29: =E151 -> 107.37724 | F29: =F151 -> 115.17951 | G29: =G151 -> 132.81922 | H29: =H151 -> 144.21776 | I29: =I151 -> 150.61142 | J29: =J151 -> 151.04174
A30: EPS 年增 | B30: % | D30: =D152 -> 1.2106205 | E30: =E152 -> 0.72674537 | F30: =F152 -> 0.072662303 | G30: =G152 -> 0.15314966 | H30: =H152 -> 0.085819971 | I30: =I152 -> 0.044333398 | J30: =J152 -> 0.0028571429
A32: 情境 C
A33: 營收 | B33: NT$B | C33: =C181 -> 34.141 | D33: =D181 -> 69.4169 | E33: =E181 -> 101.61095 | F33: =F181 -> 73.276681 | G33: =G181 -> 78.66624 | H33: =H181 -> 83.047991 | I33: =I181 -> 86.191379 | J33: =J181 -> 87.915207
A34: 營收年增 | B34: % | D34: =D182 -> 1.0332416 | E34: =E182 -> 0.46377827 | F34: =F182 -> -0.27885054 | G34: =G182 -> 0.073550798 | H34: =H182 -> 0.055700532 | I34: =I182 -> 0.037850266 | J34: =J182 -> 0.02
A35: Google CPU 量產 | B35: NT$B | C35: =C168 -> 6.14538 | D35: =D168 -> 33.320112 | E35: =E168 -> 59.326392 | F35: =F168 -> 31.712653 | G35: =G168 -> 36.469551
A36: AI ASIC 量產（其他 ASIC） | B36: NT$B | C36: =C177 -> 1.70705 | D36: =D177 -> 2.082507 | E36: =E177 -> 6.3266035 | F36: =F177 -> 4.2177357 | G36: =G177 -> 4.8503961
A37: 車用 | B37: NT$B | C37: =C179 -> 1.02423 | D37: =D179 -> 3.470845 | E37: =E179 -> 6.94169 | F37: =F179 -> 8.330028 | G37: =G179 -> 8.330028
A38: 其他（NRE＋其他量產） | B38: NT$B | C38: =C180 -> 25.26434 | D38: =D180 -> 30.543436 | E38: =E180 -> 29.016264 | F38: =F180 -> 29.016264 | G38: =G180 -> 29.016264
A39: 毛利率 | B39: % | C39: =C190 -> 0.24762016 | D39: =D190 -> 0.21106489 | E39: =E190 -> 0.17076511 | F39: =F190 -> 0.19520879 | G39: =G190 -> 0.18937099
A40: 營業利益率 | B40: % | C40: =C193 -> 0.12741279 | D40: =D193 -> 0.13376423 | E40: =E193 -> 0.11060862 | F40: =F193 -> 0.10511788 | G40: =G193 -> 0.098738871
A41: 歸屬母公司淨利 | B41: NT$B | C41: =C197 -> 3.77 | D41: =D197 -> 8.3326848 | E41: =E197 -> 9.9781897 | F41: =F197 -> 6.9722859 | G41: =G197 -> 7.0273033 | H41: =H197 -> 6.924146 | I41: =I197 -> 6.6729249 | J41: =J197 -> 6.2828154
A42: 淨利率 | B42: % | C42: =C201 -> 0.11042442 | D42: =D201 -> 0.12003827 | E42: =E201 -> 0.098199945 | F42: =F201 -> 0.095150132 | G42: =G201 -> 0.089330612 | H42: =H201 -> 0.083375238 | I42: =I201 -> 0.077419864 | J42: =J201 -> 0.07146449
...

Sheet Val
A1: Val — P/E 估值（新台幣）。結論用「現價 ÷ FY2027、FY2028 EPS（模型）」；目標價＝DCF 與 Comparable 加權（第 0 節）；十年 P/E 規則值（第 3 節，年底落後 P/E）只作參考
A2: 循環位置：創意不是設備股，不套設備市場見頂年；以本模型營收最高的會計年度為見頂年（比照聯發科、世芯；FY(t)＝CY(t)）。營收到 FY2029 仍在增加時，見頂年未知，判為中段
A4: 0. 目標價
A5: 0.1 DCF（股東權益現金流，FY2027–FY2032 明確期＋FY2032 後永續）
A6: 項目 | B6: A（順利） | C6: B（平平） | D6: C（不如預期） | E6: 說明
A7: 情境 EPS（FY2027–FY2032） | E7: PL 頁各情境；FY2030 起為收斂法
A8: FY2027 | B8: =PL!E15 -> 135.47225 | C8: =PL!E29 -> 107.37724 | D8: =PL!E43 -> 74.458545
A9: FY2028 | B9: =PL!F15 -> 199.68191 | C9: =PL!F29 -> 115.17951 | D9: =PL!F43 -> 52.028102
A10: FY2029 | B10: =PL!G15 -> 230.50374 | C10: =PL!G29 -> 132.81922 | D10: =PL!G43 -> 52.438649
A11: FY2030 | B11: =PL!H15 -> 257.80172 | C11: =PL!H29 -> 144.21776 | D11: =PL!H43 -> 51.668876
A12: FY2031 | B12: =PL!I15 -> 280.80118 | C12: =PL!I29 -> 150.61142 | D12: =PL!I43 -> 49.794231
A13: FY2032 | B13: =PL!J15 -> 297.64925 | C13: =PL!J29 -> 151.04174 | D13: =PL!J43 -> 46.883183
A14: 股東現金流＝EPS ×（1 − tp_g ÷ tp_roe）
A15: 再投資率（tp_g ÷ tp_roe，上限 0.8） | B15: =MIN(tp_g/tp_roe,0.8) -> 0.11585248 | E15: ROE 為近三年平均（In 頁 tp_roe）
A16: FY2027 | B16: =B8*(1-$B$15) -> 119.77745 | C16: =C8*(1-$B$15) -> 94.937317 | D16: =D8*(1-$B$15) -> 65.832338
A17: FY2028 | B17: =B9*(1-$B$15) -> 176.54826 | C17: =C9*(1-$B$15) -> 101.83568 | D17: =D9*(1-$B$15) -> 46.000517
A18: FY2029 | B18: =B10*(1-$B$15) -> 203.79931 | C18: =C10*(1-$B$15) -> 117.43178 | D18: =D10*(1-$B$15) -> 46.363501
A19: FY2030 | B19: =B11*(1-$B$15) -> 227.93475 | C19: =C11*(1-$B$15) -> 127.50977 | D19: =D11*(1-$B$15) -> 45.682908
A20: FY2031 | B20: =B12*(1-$B$15) -> 248.26967 | C20: =C12*(1-$B$15) -> 133.16272 | D20: =D12*(1-$B$15) -> 44.025446
A21: FY2032 | B21: =B13*(1-$B$15) -> 263.16585 | C21: =C13*(1-$B$15) -> 133.54318 | D21: =D13*(1-$B$15) -> 41.45165
A22: DCF 情境每股價值（折現率 tp_r） | B22: =MAX(0,SUMPRODUCT(B16:B21,1/(1+tp_r)^{1;2;3;4;5;6})+B21*(1+tp_g)/(tp_r-tp_g)/(1+tp_r)^6) -> 3441.1736 | C22: =MAX(0,SUMPRODUCT(C16:C21,1/(1+tp_r)^{1;2;3;4;5;6})+C21*(1+tp_g)/(tp_r-tp_g)/(1+tp_r)^6) -> 1810.4679 | D22: =MAX(0,SUMPRODUCT(D16:D21,1/(1+tp_r)^{1;2;3;4;5;6})+D21*(1+tp_g)/(tp_r-tp_g)/(1+tp_r)^6) -> 620.20673 | E22: Σ 明確期現金流 ÷ (1＋r)^t ＋ 永續價值 ÷ (1＋r)^6；永續價值＝FY2032 現金流 ×(1＋g)÷(r−g)；基準日 2026 年底；負值取 0
A23: DCF 情境價值推到 12 個月後（×(1＋tp_r)） | B23: =B22*(1+tp_r) -> 3785.2909 | C23: =C22*(1+tp_r) -> 1991.5147 | D23: =D22*(1+tp_r) -> 682.2274
A24: DCF 目標價（情境加權） | B24: =tp_wA*B23+tp_wB*C23+tp_wC*D23 -> 2267.7901 | E24: Σ 權重 × 情境價值 ×(1＋r)；權重見 In 頁
A26: 0.2 Comparable（市場主流同業前瞻 P/E）
A27: 同業與前瞻 P/E | B27: 代號 | C27: 前瞻 12 月 P/E | D27: 日期 | E27: 來源 | F27: 標記
A28: 世芯-KY（Alchip） | B28: 3661.TW | C28: 17.15 | D28: 2026-10-22 | E28: stockanalysis.com forward PE（分析師共識；價格日期如左；與聯發科、世芯模型同日擷取） | F28: Interested-party
A29: 聯發科（MediaTek） | B29: 2454.TW | C29: 38.75 | D29: 2026-10-22 | E29: stockanalysis.com forward PE（分析師共識；價格日期如左；與聯發科、世芯模型同日擷取） | F29: Interested-party
A30: 博通（Broadcom） | B30: AVGO | C30: 18.52 | D30: 2026-10-23 | E30: stockanalysis.com forward PE（分析師共識；價格日期如左；與聯發科、世芯模型同日擷取） | F30: Interested-party
A31: 邁威爾（Marvell） | B31: MRVL | C31: 40.44 | D31: 2026-10-23 | E31: stockanalysis.com forward PE（分析師共識；價格日期如左；與聯發科、世芯模型同日擷取） | F31: Interested-party
A33: 同業前瞻 P/E 中位數 | B33: =MEDIAN(C28:C31) -> 28.635 | E33: ASIC 設計服務與 ASIC 對手（世芯、聯發科、博通、邁威爾）；不含 A 股（非 A 股公司，Andy 2026-10-25 11:53）；智原資料日 2026-09-04 過舊，未列
A34: 12 個月後的前瞻 EPS（情境加權） | B34: =tp_wA*(2/12*B8+10/12*B9)+tp_wB*(2/12*C8+10/12*C9)+tp_wC*(2/12*D8+10/12*D9) -> 124.78696 | E34: 約 2027-10 時的未來 12 月 EPS ≈ 2／12 × FY2027＋10／12 × FY2028（會計年度＝日曆年）
A35: Comparable 目標價 | B35: =B33*B34 -> 3573.2745 | E35: 同業中位數 × 前瞻 EPS
A37: 0.3 結論
A38: 項目 | B38: 數值 | E38: 說明
A39: 目標價（DCF 與 Comparable 加權） | B39: =tp_w_dcf*B24+(1-tp_w_dcf)*tp_comp_adj -> 3968.0419 | E39: tp_w_dcf × DCF＋（1 − tp_w_dcf）× Comparable；tp_w_dcf 見 In 頁
A40: Comparable 目標價（市場主流同業法） | B40: =B35 -> 3573.2745
A41: 市場共識目標價 | B41: =cons_tp -> 6722.37 | E41: stockanalysis：19 位分析師平均 6,722，2026-10-08 擷取
A42: 上檔空間：加權目標價 | B42: =B39/px-1 -> -0.4768567 | E42: 現價＝In 頁 px（2026-10-22 收盤）
A43: 上檔空間：Comparable 目標價 | B43: =B40/px-1 -> -0.5289025
A44: 與市場共識目標價的差距：EPS 因素 | B44: =B34/cons_feps-1 -> 0.53520797 | E44: 本模型前瞻 EPS ÷ 共識前瞻 EPS − 1；共識前瞻 EPS＝2026-10-08 股價 ÷ 前瞻 P/E（In 頁 cons_feps）
...

Sheet Recon
A1: Recon — 本模型 vs 公司說法、共識、券商。只作事後對照，不為對上數字而調參數。券商 FY2027–28 估計與法人 CPU 出貨估計為 Interested-party，不用於校準
A3: 項目 | B3: 對照值 | C3: 模型 A | D3: 差距 A | E3: 模型 B | F3: 差距 B | G3: 模型 C | H3: 差距 C | I3: 對照來源 | J3: 說明
A4: A. FY2026 錨點 vs 公司說法與共識
A5: FY2026 營收 vs 共識 | B5: =cons_rev26 -> 59.5 | C5: =PL!D85 -> 69.4169 | D5: =C5/B5-1 -> 0.16667059 | E5: =PL!D133 -> 69.4169 | F5: =E5/B5-1 -> 0.16667059 | G5: =PL!D181 -> 69.4169 | H5: =G5/B5-1 -> 0.16667059 | I5: stockanalysis（17 位；2026-09-04） | J5: 共識資料日在 3Q26 營收公布前；3Q26 營收季增 34.9%，遠高於公司說的高個位數至低雙位數
A6: FY2026 EPS vs 共識 | B6: =cons_eps26 -> 51.74 | C6: =PL!D103 -> 62.184754 | D6: =C6/B6-1 -> 0.20187001 | E6: =PL!D151 -> 62.184754 | F6: =E6/B6-1 -> 0.20187001 | G6: =PL!D199 -> 62.184754 | H6: =G6/B6-1 -> 0.20187001 | I6: stockanalysis（2026-09-04） | J6: 共識區間 45.73–60.51；外資 52.96；優分析 58.23
A7: FY2026 毛利率 vs 公司 20% 以上（百分點） | B7: =co_gm26 -> 0.2 | C7: =PL!D94 -> 0.21106489 | D7: =C7-B7 -> 0.011064892 | E7: =PL!D142 -> 0.21106489 | F7: =E7-B7 -> 0.011064892 | G7: =PL!D190 -> 0.21106489 | H7: =G7-B7 -> 0.011064892 | I7: 優分析 2026-09-22（法說）
A8: FY2026 營業利益率 vs 公司雙位數下限（百分點） | B8: =co_opm26 -> 0.1 | C8: =PL!D97 -> 0.13376423 | D8: =C8-B8 -> 0.033764235 | E8: =PL!D145 -> 0.13376423 | F8: =E8-B8 -> 0.033764235 | G8: =PL!D193 -> 0.13376423 | H8: =G8-B8 -> 0.033764235 | I8: 優分析 2026-09-22（法說）
A9: B. CPU 與車用 vs 法人（市場層 TPU 顆數 × 配比口徑）
A10: CY2027 創意 CPU 顆數 vs 法人約 400 萬顆 | B10: =cpu_u27 -> 4 | C10: =PL!E66 -> 3.3 | D10: =C10/B10-1 -> -0.175 | E10: =PL!E114 -> 2.75 | F10: =E10/B10-1 -> -0.3125 | G10: =PL!E162 -> 2.2 | H10: =G10/B10-1 -> -0.45 | I10: 經濟日報 2026-10-07 | J10: 法人另一說 350 萬顆（2026-09-08）；達到 400 萬顆需配比約 0.73（含一般運算 Axion）
A11: CY2027 達到法人 CPU 顆數所需配比（＝400 萬 ÷ TPU 顆數） | C11: =cpu_u27/PL!E63 -> 0.72727273 | E11: =cpu_u27/PL!E111 -> 0.72727273 | G11: =cpu_u27/PL!E159 -> 0.72727273 | I11: 推導 | J11: 市場層 CY2027 TPU 5.5 百萬顆
A12: FY2027 CPU ÷ 營收 vs 本國投顧 50.3%（百分點） | B12: =dom_cpu27 -> 0.503 | C12: =PL!E87 -> 0.56689308 | D12: =C12-B12 -> 0.063893075 | E12: =PL!E135 -> 0.56952326 | F12: =E12-B12 -> 0.066523262 | G12: =PL!E183 -> 0.58385826 | H12: =G12-B12 -> 0.080858258 | I12: 經濟日報 2026-04-28
A13: FY2027 車用 ÷ 營收 vs 公司雙位數下限（百分點） | B13: =co_auto27 -> 0.1 | C13: =PL!E88 -> 0.088441717 | D13: =C13-B13 -> -0.011558283 | E13: =PL!E136 -> 0.07996685 | F13: =E13-B13 -> -0.02003315 | G13: =PL!E184 -> 0.068316358 | H13: =G13-B13 -> -0.031683642 | I13: 優分析 2026-09-22（法說）
A14: FY2027 車用 ÷ 營收 vs 本國投顧北美車用 34.9%（百分點） | B14: =dom_ts27 -> 0.349 | C14: =PL!E88 -> 0.088441717 | D14: =C14-B14 -> -0.26055828 | E14: =PL!E136 -> 0.07996685 | F14: =E14-B14 -> -0.26903315 | G14: =PL!E184 -> 0.068316358 | H14: =G14-B14 -> -0.28068364 | I14: 經濟日報 2026-04-28 | J14: 本國投顧比重遠高於公司說法；北美專案主要在 2H27 後貢獻
A15: FY2027 每顆創意 CPU 營收（校準後） | C15: =PL!E73 -> 0.84270443 | E15: =PL!E121 -> 0.84270443 | G15: =PL!E169 -> 0.84270443 | I15: 推導 | J15: US$K；k_c × 每顆營收
A16: C. EPS vs 券商與共識（校準未使用）
A17: FY2027 EPS vs 市場共識（Visible Alpha） | B17: =va_eps27 -> 94.24 | C17: =PL!E103 -> 135.47225 | D17: =C17/B17-1 -> 0.43752389 | E17: =PL!E151 -> 107.37724 | F17: =E17/B17-1 -> 0.13940192 | G17: =PL!E199 -> 74.458545 | H17: =G17/B17-1 -> -0.20990508 | I17: 工商時報 2026-07-31 | J17: 資料日在 3Q26 營收公布前
A18: FY2027 EPS vs 外資 | B18: =fb_eps27 -> 104.14 | C18: =PL!E103 -> 135.47225 | D18: =C18/B18-1 -> 0.30086664 | E18: =PL!E151 -> 107.37724 | F18: =E18/B18-1 -> 0.031085428 | G18: =PL!E199 -> 74.458545 | H18: =G18/B18-1 -> -0.28501493 | I18: 工商時報 2026-07-31
A19: FY2027 EPS vs 優分析資料庫 | B19: =ua_eps27 -> 139.12 | C19: =PL!E103 -> 135.47225 | D19: =C19/B19-1 -> -0.026220159 | E19: =PL!E151 -> 107.37724 | F19: =E19/B19-1 -> -0.22816823 | G19: =PL!E199 -> 74.458545 | H19: =G19/B19-1 -> -0.46478906 | I19: 優分析 2026-09-22
A20: FY2028 EPS vs 外資 | B20: =fb_eps28 -> 155.25 | C20: =PL!F103 -> 199.68191 | D20: =C20/B20-1 -> 0.28619586 | E20: =PL!F151 -> 115.17951 | F20: =E20/B20-1 -> -0.25810297 | G20: =PL!F199 -> 52.028102 | H20: =G20/B20-1 -> -0.66487535 | I20: 工商時報 2026-07-31
A21: 共識前瞻 12 月 EPS vs 模型（情境加權 2／12 × FY2027＋10／12 × FY2028） | B21: =cons_feps -> 81.283422 | C21: =Val!B34 -> 124.78696 | D21: =C21/B21-1 -> 0.53520797 | E21: =Val!B34 -> 124.78696 | F21: =E21/B21-1 -> 0.53520797 | G21: =Val!B34 -> 124.78696 | H21: =G21/B21-1 -> 0.53520797 | I21: stockanalysis 前瞻 P/E 推得 | J21: 三欄同值（情境加權）
A22: D. 校準與份額
A23: k_c（CPU 校準係數） | C23: =PL!D69 -> 0.84270443 | E23: =PL!D117 -> 0.84270443 | G23: =PL!D165 -> 0.84270443 | I23: FY2026 CPU 營收 ÷ 未校準 | J23: 接近 1＝法人 CPU 顆數 × 每顆 1,000 美元與 FY2026 CPU 拆分一致
A24: k_o（AI ASIC 校準係數） | C24: =PL!D79 -> 0.36612289 | E24: =PL!D127 -> 0.36612289 | G24: =PL!D175 -> 0.36612289 | I24: FY2026 AI ASIC ÷ 未校準 | J24: < 1：創意 turnkey 只含晶圓與封裝轉售
A25: 其他營收毛利率（FY2026 殘差） | C25: =PL!D92 -> 0.3108293 | E25: =PL!D140 -> 0.3108293 | G25: =PL!D188 -> 0.3108293 | I25: FY2026 毛利殘差 | J25: 含 NRE（毛利率高）；FY2025 NRE 約占營收 34%
A26: CY2028 Broadcom＋Marvell＋聯發科（高）＋創意 其他 ASIC 份額 | B26: 1 | C26: =Units!E16 -> 0.83 | D26: =C26-B26 -> -0.17 | E26: =Units!E17 -> 0.8 | F26: =E26-B26 -> -0.2 | G26: =Units!E18 -> 0.77 | H26: =G26-B26 -> -0.23 | I26: avgo、mrvl、mediatek 成品 | J26: 應 ≤ 100%
A27: E. 預留
A28: R4 產業部署路徑（markets/deploy_path/，尚未建立）：上線後以創意 AI 量產營收 ÷ 部署 GW 對照 Tokenomics 非 NVIDIA 加速器比例 | J28: 預留列：本版無數值

Sheet Sens
A1: Sens — 一次動一個輸入（情境 A；FY2026 恆等於錨點，k_c、k_o 與其他營收毛利率在每個案例內重算）：對 FY2027、FY2028 營收、毛利率與 EPS 的影響。每個案例是一個完整推導區塊（本頁下方）
A3: 案例 | B3: 設定 | C3: FY2027 營收 | D3: FY2027 毛利率 | E3: FY2027 EPS | F3: FY2027 EPS 相對基準 | G3: FY2028 營收 | H3: FY2028 毛利率 | I3: FY2028 EPS | J3: FY2028 EPS 相對基準
A4: 基準（情境 A） | B4: PL 區塊 A | C4: =PL!E85 -> 156.97773 | D4: =PL!E94 -> 0.17999318 | E4: =PL!E103 -> 135.47225 | F4: =E4/E$4-1 -> 0 | G4: =PL!F85 -> 230.43382 | H4: =PL!F94 -> 0.17105336 | I4: =PL!F103 -> 199.68191 | J4: =I4/I$4-1 -> 0
A5: CPU 對 TPU 配比 −0.2 | B5: CY2027 起配比 0.6 → 0.4 | C5: =E65 -> 127.31453 | D5: =E74 -> 0.18931125 | E5: =E83 -> 113.49472 | F5: =E5/E$4-1 -> -0.16222904 | G5: =F65 -> 185.13003 | H5: =F74 -> 0.17865253 | I5: =F83 -> 164.60461 | J5: =I5/I$4-1 -> -0.17566586
A6: CPU 對 TPU 配比 +0.15 | B6: CY2027 起 0.75（含一般運算 Axion） | C6: =E113 -> 179.22513 | D6: =E122 -> 0.17502879 | E6: =E131 -> 151.9554 | F6: =E6/E$4-1 -> 0.12167178 | G6: =F113 -> 264.41166 | H6: =F122 -> 0.16706289 | I6: =F131 -> 226.01134 | J6: =I6/I$4-1 -> 0.13185689
A7: 下一代 CPU 份額 50% | B7: CY2028 起（基準 100%） | C7: =E161 -> 156.97773 | D7: =E170 -> 0.17999318 | E7: =E179 -> 135.47225 | F7: =E7/E$4-1 -> 0 | G7: =F161 -> 162.47813 | H7: =F170 -> 0.18404127 | I7: =F179 -> 142.1705 | J7: =I7/I$4-1 -> -0.28801509
A8: CPU 與 ASIC 顆數 ×0.8 | B8: CY2027 起 | C8: =E209 -> 135.38385 | D8: =E218 -> 0.18637214 | E8: =E227 -> 119.47329 | F8: =E8/E$4-1 -> -0.11809767 | G8: =F209 -> 197.62789 | H8: =F218 -> 0.17620816 | I8: =F227 -> 174.27995 | J8: =I8/I$4-1 -> -0.12721211
A9: CPU 與 ASIC 顆數 ×1.2 | B9: CY2027 起 | C9: =E257 -> 178.57161 | D9: =E266 -> 0.17515698 | E9: =E275 -> 151.47121 | F9: =E9/E$4-1 -> 0.11809767 | G9: =F257 -> 263.23974 | H9: =F266 -> 0.16718337 | I9: =F275 -> 225.098 | J9: =I9/I$4-1 -> 0.12728292
A10: 下一代 CPU 單價 ×1.5 | B10: CY2028 起（基準 ×1.2） | C10: =E305 -> 156.97773 | D10: =E314 -> 0.17999318 | E10: =E323 -> 135.47225 | F10: =E10/E$4-1 -> 0 | G10: =F305 -> 264.41166 | H10: =F314 -> 0.16706289 | I10: =F323 -> 226.8076 | J10: =I10/I$4-1 -> 0.13584451
A11: 下一代 CPU 單價 ×0.8 | B11: CY2028 起 | C11: =E353 -> 156.97773 | D11: =E362 -> 0.17999318 | E11: =E371 -> 135.47225 | F11: =E11/E$4-1 -> 0 | G11: =F353 -> 185.13003 | H11: =F362 -> 0.17865253 | I11: =F371 -> 162.28524 | J11: =I11/I$4-1 -> -0.18728121
A12: 其他 ASIC 份額 +4pt | B12: CY2027 起（Maia 等放量） | C12: =E401 -> 169.63094 | D12: =E410 -> 0.17700999 | E12: =E419 -> 144.84704 | F12: =E12/E$4-1 -> 0.069200826 | G12: =F401 -> 244.49293 | H12: =F410 -> 0.16926769 | I12: =F419 -> 210.43334 | J12: =I12/I$4-1 -> 0.053842806
A13: 其他 ASIC 份額 0 | B13: CY2027 起 | C13: =E449 -> 137.99792 | D13: =E458 -> 0.18549372 | E13: =E467 -> 121.41006 | F13: =E13/E$4-1 -> -0.10380124 | G13: =F449 -> 202.31558 | H13: =F458 -> 0.17536921 | I13: =F467 -> 177.92142 | J13: =I13/I$4-1 -> -0.10897575
A14: 量產毛利率 10% | B14: 基準 13%（＋情境 A 調整 1pt） | C14: =E497 -> 156.97773 | D14: =E506 -> 0.16713982 | E14: =E515 -> 122.67442 | F14: =E14/E$4-1 -> -0.094468313 | G14: =F497 -> 230.43382 | H14: =F506 -> 0.1555289 | I14: =F515 -> 176.9914 | J14: =I14/I$4-1 -> -0.11363327
A15: 量產毛利率 16% | C15: =E545 -> 156.97773 | D15: =E554 -> 0.19284654 | E15: =E563 -> 148.27009 | F15: =E15/E$4-1 -> 0.094468313 | G15: =F545 -> 230.43382 | H15: =F554 -> 0.18657781 | I15: =F563 -> 222.37242 | J15: =I15/I$4-1 -> 0.11363327
A16: 車用 情境 C 路徑 | B16: FY2027 ×2.0、FY2028 ×1.2 | C16: =E593 -> 150.03604 | D16: =E602 -> 0.1809182 | E16: =E611 -> 129.44854 | F16: =E16/E$4-1 -> -0.04446454 | G16: =F593 -> 210.99708 | H16: =F602 -> 0.17207157 | I16: =F611 -> 181.96948 | J16: =I16/I$4-1 -> -0.088703233
A17: 其他營收 情境 C 路徑 | B17: FY2027 −5%、之後 0% | C17: =E641 -> 150.86904 | D17: =E650 -> 0.17469562 | E17: =E659 -> 124.32732 | F17: =E17/E$4-1 -> -0.082267288 | G17: =F641 -> 220.81263 | H17: =F650 -> 0.16496308 | I17: =F659 -> 181.79796 | J17: =I17/I$4-1 -> -0.089562189
A18: 其他營收毛利率 −3pt | B18: FY2027 起 | C18: =E689 -> 156.97773 | D18: =E698 -> 0.17328045 | E18: =E707 -> 128.78852 | F18: =E18/E$4-1 -> -0.049336502 | G18: =F689 -> 230.43382 | H18: =F698 -> 0.16602318 | I18: =F707 -> 192.32981 | J18: =I18/I$4-1 -> -0.036819058
A19: 營業費用彈性 0.6 | B19: 基準 0.3 | C19: =E737 -> 156.97773 | D19: =E746 -> 0.17999318 | E19: =E755 -> 122.59284 | F19: =E19/E$4-1 -> -0.095070479 | G19: =F737 -> 230.43382 | H19: =F746 -> 0.17105336 | I19: =F755 -> 176.60044 | J19: =I19/I$4-1 -> -0.11559116
A20: 營業費用率 +2pt | B20: 營業費用額外 +2% × 營收 | C20: =E785 -> 156.97773 | D20: =E794 -> 0.17999318 | E20: =E803 -> 115.55865 | F20: =E20/E$4-1 -> -0.14699393 | G20: =F785 -> 230.43382 | H20: =F794 -> 0.17105336 | I20: =F803 -> 147.74084 | J20: =I20/I$4-1 -> -0.26011904
A21: 匯率 30 | B21: 基準 32（CPU、ASIC 美元營收換算） | C21: =E833 -> 150.22964 | D21: =E842 -> 0.18178961 | E21: =E851 -> 130.47258 | F21: =E21/E$4-1 -> -0.036905523 | G21: =F833 -> 220.18197 | H21: =F842 -> 0.17249922 | I21: =F851 -> 191.74199 | J21: =I21/I$4-1 -> -0.039762825
A22: 稅率 20% | B22: 基準 15% | C22: =E881 -> 156.97773 | D22: =E890 -> 0.17999318 | E22: =E899 -> 127.5033 | F22: =E22/E$4-1 -> -0.058823529 | G22: =F881 -> 230.43382 | H22: =F890 -> 0.17105336 | I22: =F899 -> 187.93591 | J22: =I22/I$4-1 -> -0.058823529
A23: 情境 B | B23: 顆數 B；配比 0.5；下一代 CPU 份額 90%；其他營收 +8% | C23: =PL!E133 -> 130.21064 | D23: =PL!E142 -> 0.17820939 | E23: =PL!E151 -> 107.37724 | F23: =E23/E$4-1 -> -0.20738575 | G23: =PL!F133 -> 140.10669 | H23: =PL!F142 -> 0.17827073 | I23: =PL!F151 -> 115.17951 | J23: =I23/I$4-1 -> -0.42318503
A24: 情境 C | B24: 顆數 C；配比 0.4；下一代 CPU 份額 70%；量產毛利率 −2pt | C24: =PL!E181 -> 101.61095 | D24: =PL!E190 -> 0.17076511 | E24: =PL!E199 -> 74.458545 | F24: =E24/E$4-1 -> -0.45037789 | G24: =PL!F181 -> 73.276681 | H24: =PL!F190 -> 0.19520879 | I24: =PL!F199 -> 52.028102 | J24: =I24/I$4-1 -> -0.73944509
A26: 讀法：FY2027 最大的單一變數是 CPU 對 TPU 配比（CPU 顆數）與量產毛利率；FY2028 再加上 TPU 顆數情境與下一代 CPU 份額。車用與其他營收的情境差異較小。
A28: 目標價參數（只改 DCF 參數；PL 收斂法的 fade_g 不隨 tp_g 變動）
A29: 案例 | B29: 設定 | C29: DCF 目標價 | D29: Comparable 目標價（相對倍數調整後） | E29: 加權目標價 | F29: 相對基準
A30: 基準 | B30: r 10%、g 4%、DCF 權重 0.5 | C30: =(tp_wA*MAX(0,Val!B8*(1-MIN(tp_g/tp_roe,0.8))/(1+tp_r)^1+Val!B9*(1-MIN(tp_g/tp_roe,0.8))/(1+tp_r)^2+Val!B10*(1-MIN(tp_g/tp_roe,0.8))/(1+tp_r)^3+Val!B11*(1-MIN(tp_g/tp_roe,0.8))/(1+tp_r)^4+Val!B12*(1-MIN(tp_g/tp_roe,0.8))/(1+tp_r)^5+Val!B13*(1-MIN(tp_g/tp_roe,0.8))/(1+tp_r)^6+Val!B13*(1-MIN(tp_g/tp_roe,0.8))*(1+tp_g)/(tp_r-tp_g)/(1+tp_r)^6)+tp_wB*MAX(0,Val!C8*(1-MIN(tp_g/tp_roe,0.8))/(1+tp_r)^1+Val!C9*(1-MIN(tp_g/tp_roe,0.8))/(1+tp_r)^2+Val!C10*(1-MIN(tp_g/tp_roe,0.8))/(1+tp_r)^3+Val!C11*(1-MIN(tp_g/tp_roe,0.8))/(1+tp_r)^4+Val!C12*(1-MIN(tp_g/tp_roe,0.8))/(1+tp_r)^5+Val!C13*(1-MIN(tp_g/tp_roe,0.8))/(1+tp_r)^6+Val!C13*(1-MIN(tp_g/tp_roe,0.8))*(1+tp_g)/(tp_r-tp_g)/(1+tp_r)^6)+tp_wC*MAX(0,Val!D8*(1-MIN(tp_g/tp_roe,0.8))/(1+tp_r)^1+Val!D9*(1-MIN(tp_g/tp_roe,0.8))/(1+tp_r)^2+Val!D10*(1-MIN(tp_g/tp_roe,0.8))/(1+tp_r)^3+Val!D11*(1-MIN(tp_g/tp_roe,0.8))/(1+tp_r)^4+Val!D12*(1-MIN(tp_g/tp_roe,0.8))/(1+tp_r)^5+Val!D13*(1-MIN(tp_g/tp_roe,0.8))/(1+tp_r)^6+Val!D13*(1-MIN(tp_g/tp_roe,0.8))*(1+tp_g)/(tp_r-tp_g)/(1+tp_r)^6))*(1+tp_r) -> 2267.7901 | D30: =tp_comp_adj -> 5668.2937 | E30: =tp_w_dcf*C30+(1-tp_w_dcf)*D30 -> 3968.0419 | F30: =E30/E$30-1 -> 0
A31: 折現率 +1pt | B31: r 11% | C31: =(tp_wA*MAX(0,Val!B8*(1-MIN(tp_g/tp_roe,0.8))/(1+(tp_r+0.01))^1+Val!B9*(1-MIN(tp_g/tp_roe,0.8))/(1+(tp_r+0.01))^2+Val!B10*(1-MIN(tp_g/tp_roe,0.8))/(1+(tp_r+0.01))^3+Val!B11*(1-MIN(tp_g/tp_roe,0.8))/(1+(tp_r+0.01))^4+Val!B12*(1-MIN(tp_g/tp_roe,0.8))/(1+(tp_r+0.01))^5+Val!B13*(1-MIN(tp_g/tp_roe,0.8))/(1+(tp_r+0.01))^6+Val!B13*(1-MIN(tp_g/tp_roe,0.8))*(1+tp_g)/((tp_r+0.01)-tp_g)/(1+(tp_r+0.01))^6)+tp_wB*MAX(0,Val!C8*(1-MIN(tp_g/tp_roe,0.8))/(1+(tp_r+0.01))^1+Val!C9*(1-MIN(tp_g/tp_roe,0.8))/(1+(tp_r+0.01))^2+Val!C10*(1-MIN(tp_g/tp_roe,0.8))/(1+(tp_r+0.01))^3+Val!C11*(1-MIN(tp_g/tp_roe,0.8))/(1+(tp_r+0.01))^4+Val!C12*(1-MIN(tp_g/tp_roe,0.8))/(1+(tp_r+0.01))^5+Val!C13*(1-MIN(tp_g/tp_roe,0.8))/(1+(tp_r+0.01))^6+Val!C13*(1-MIN(tp_g/tp_roe,0.8))*(1+tp_g)/((tp_r+0.01)-tp_g)/(1+(tp_r+0.01))^6)+tp_wC*MAX(0,Val!D8*(1-MIN(tp_g/tp_roe,0.8))/(1+(tp_r+0.01))^1+Val!D9*(1-MIN(tp_g/tp_roe,0.8))/(1+(tp_r+0.01))^2+Val!D10*(1-MIN(tp_g/tp_roe,0.8))/(1+(tp_r+0.01))^3+Val!D11*(1-MIN(tp_g/tp_roe,0.8))/(1+(tp_r+0.01))^4+Val!D12*(1-MIN(tp_g/tp_roe,0.8))/(1+(tp_r+0.01))^5+Val!D13*(1-MIN(tp_g/tp_roe,0.8))/(1+(tp_r+0.01))^6+Val!D13*(1-MIN(tp_g/tp_roe,0.8))*(1+tp_g)/((tp_r+0.01)-tp_g)/(1+(tp_r+0.01))^6))*(1+(tp_r+0.01)) -> 1954.585 | D31: =tp_comp_adj -> 5668.2937 | E31: =tp_w_dcf*C31+(1-tp_w_dcf)*D31 -> 3811.4394 | F31: =E31/E$30-1 -> -0.039465953
A32: 折現率 −1pt | B32: r 9% | C32: =(tp_wA*MAX(0,Val!B8*(1-MIN(tp_g/tp_roe,0.8))/(1+(tp_r-0.01))^1+Val!B9*(1-MIN(tp_g/tp_roe,0.8))/(1+(tp_r-0.01))^2+Val!B10*(1-MIN(tp_g/tp_roe,0.8))/(1+(tp_r-0.01))^3+Val!B11*(1-MIN(tp_g/tp_roe,0.8))/(1+(tp_r-0.01))^4+Val!B12*(1-MIN(tp_g/tp_roe,0.8))/(1+(tp_r-0.01))^5+Val!B13*(1-MIN(tp_g/tp_roe,0.8))/(1+(tp_r-0.01))^6+Val!B13*(1-MIN(tp_g/tp_roe,0.8))*(1+tp_g)/((tp_r-0.01)-tp_g)/(1+(tp_r-0.01))^6)+tp_wB*MAX(0,Val!C8*(1-MIN(tp_g/tp_roe,0.8))/(1+(tp_r-0.01))^1+Val!C9*(1-MIN(tp_g/tp_roe,0.8))/(1+(tp_r-0.01))^2+Val!C10*(1-MIN(tp_g/tp_roe,0.8))/(1+(tp_r-0.01))^3+Val!C11*(1-MIN(tp_g/tp_roe,0.8))/(1+(tp_r-0.01))^4+Val!C12*(1-MIN(tp_g/tp_roe,0.8))/(1+(tp_r-0.01))^5+Val!C13*(1-MIN(tp_g/tp_roe,0.8))/(1+(tp_r-0.01))^6+Val!C13*(1-MIN(tp_g/tp_roe,0.8))*(1+tp_g)/((tp_r-0.01)-tp_g)/(1+(tp_r-0.01))^6)+tp_wC*MAX(0,Val!D8*(1-MIN(tp_g/tp_roe,0.8))/(1+(tp_r-0.01))^1+Val!D9*(1-MIN(tp_g/tp_roe,0.8))/(1+(tp_r-0.01))^2+Val!D10*(1-MIN(tp_g/tp_roe,0.8))/(1+(tp_r-0.01))^3+Val!D11*(1-MIN(tp_g/tp_roe,0.8))/(1+(tp_r-0.01))^4+Val!D12*(1-MIN(tp_g/tp_roe,0.8))/(1+(tp_r-0.01))^5+Val!D13*(1-MIN(tp_g/tp_roe,0.8))/(1+(tp_r-0.01))^6+Val!D13*(1-MIN(tp_g/tp_roe,0.8))*(1+tp_g)/((tp_r-0.01)-tp_g)/(1+(tp_r-0.01))^6))*(1+(tp_r-0.01)) -> 2706.3712 | D32: =tp_comp_adj -> 5668.2937 | E32: =tp_w_dcf*C32+(1-tp_w_dcf)*D32 -> 4187.3325 | F32: =E32/E$30-1 -> 0.055264171
A33: 長期成長 +1pt | B33: g 5% | C33: =(tp_wA*MAX(0,Val!B8*(1-MIN((tp_g+0.01)/tp_roe,0.8))/(1+tp_r)^1+Val!B9*(1-MIN((tp_g+0.01)/tp_roe,0.8))/(1+tp_r)^2+Val!B10*(1-MIN((tp_g+0.01)/tp_roe,0.8))/(1+tp_r)^3+Val!B11*(1-MIN((tp_g+0.01)/tp_roe,0.8))/(1+tp_r)^4+Val!B12*(1-MIN((tp_g+0.01)/tp_roe,0.8))/(1+tp_r)^5+Val!B13*(1-MIN((tp_g+0.01)/tp_roe,0.8))/(1+tp_r)^6+Val!B13*(1-MIN((tp_g+0.01)/tp_roe,0.8))*(1+(tp_g+0.01))/(tp_r-(tp_g+0.01))/(1+tp_r)^6)+tp_wB*MAX(0,Val!C8*(1-MIN((tp_g+0.01)/tp_roe,0.8))/(1+tp_r)^1+Val!C9*(1-MIN((tp_g+0.01)/tp_roe,0.8))/(1+tp_r)^2+Val!C10*(1-MIN((tp_g+0.01)/tp_roe,0.8))/(1+tp_r)^3+Val!C11*(1-MIN((tp_g+0.01)/tp_roe,0.8))/(1+tp_r)^4+Val!C12*(1-MIN((tp_g+0.01)/tp_roe,0.8))/(1+tp_r)^5+Val!C13*(1-MIN((tp_g+0.01)/tp_roe,0.8))/(1+tp_r)^6+Val!C13*(1-MIN((tp_g+0.01)/tp_roe,0.8))*(1+(tp_g+0.01))/(tp_r-(tp_g+0.01))/(1+tp_r)^6)+tp_wC*MAX(0,Val!D8*(1-MIN((tp_g+0.01)/tp_roe,0.8))/(1+tp_r)^1+Val!D9*(1-MIN((tp_g+0.01)/tp_roe,0.8))/(1+tp_r)^2+Val!D10*(1-MIN((tp_g+0.01)/tp_roe,0.8))/(1+tp_r)^3+Val!D11*(1-MIN((tp_g+0.01)/tp_roe,0.8))/(1+tp_r)^4+Val!D12*(1-MIN((tp_g+0.01)/tp_roe,0.8))/(1+tp_r)^5+Val!D13*(1-MIN((tp_g+0.01)/tp_roe,0.8))/(1+tp_r)^6+Val!D13*(1-MIN((tp_g+0.01)/tp_roe,0.8))*(1+(tp_g+0.01))/(tp_r-(tp_g+0.01))/(1+tp_r)^6))*(1+tp_r) -> 2532.6551 | D33: =tp_comp_adj -> 5668.2937 | E33: =tp_w_dcf*C33+(1-tp_w_dcf)*D33 -> 4100.4744 | F33: =E33/E$30-1 -> 0.033374771
A34: 長期成長 −1pt | B34: g 3% | C34: =(tp_wA*MAX(0,Val!B8*(1-MIN((tp_g-0.01)/tp_roe,0.8))/(1+tp_r)^1+Val!B9*(1-MIN((tp_g-0.01)/tp_roe,0.8))/(1+tp_r)^2+Val!B10*(1-MIN((tp_g-0.01)/tp_roe,0.8))/(1+tp_r)^3+Val!B11*(1-MIN((tp_g-0.01)/tp_roe,0.8))/(1+tp_r)^4+Val!B12*(1-MIN((tp_g-0.01)/tp_roe,0.8))/(1+tp_r)^5+Val!B13*(1-MIN((tp_g-0.01)/tp_roe,0.8))/(1+tp_r)^6+Val!B13*(1-MIN((tp_g-0.01)/tp_roe,0.8))*(1+(tp_g-0.01))/(tp_r-(tp_g-0.01))/(1+tp_r)^6)+tp_wB*MAX(0,Val!C8*(1-MIN((tp_g-0.01)/tp_roe,0.8))/(1+tp_r)^1+Val!C9*(1-MIN((tp_g-0.01)/tp_roe,0.8))/(1+tp_r)^2+Val!C10*(1-MIN((tp_g-0.01)/tp_roe,0.8))/(1+tp_r)^3+Val!C11*(1-MIN((tp_g-0.01)/tp_roe,0.8))/(1+tp_r)^4+Val!C12*(1-MIN((tp_g-0.01)/tp_roe,0.8))/(1+tp_r)^5+Val!C13*(1-MIN((tp_g-0.01)/tp_roe,0.8))/(1+tp_r)^6+Val!C13*(1-MIN((tp_g-0.01)/tp_roe,0.8))*(1+(tp_g-0.01))/(tp_r-(tp_g-0.01))/(1+tp_r)^6)+tp_wC*MAX(0,Val!D8*(1-MIN((tp_g-0.01)/tp_roe,0.8))/(1+tp_r)^1+Val!D9*(1-MIN((tp_g-0.01)/tp_roe,0.8))/(1+tp_r)^2+Val!D10*(1-MIN((tp_g-0.01)/tp_roe,0.8))/(1+tp_r)^3+Val!D11*(1-MIN((tp_g-0.01)/tp_roe,0.8))/(1+tp_r)^4+Val!D12*(1-MIN((tp_g-0.01)/tp_roe,0.8))/(1+tp_r)^5+Val!D13*(1-MIN((tp_g-0.01)/tp_roe,0.8))/(1+tp_r)^6+Val!D13*(1-MIN((tp_g-0.01)/tp_roe,0.8))*(1+(tp_g-0.01))/(tp_r-(tp_g-0.01))/(1+tp_r)^6))*(1+tp_r) -> 2083.4171 | D34: =tp_comp_adj -> 5668.2937 | E34: =tp_w_dcf*C34+(1-tp_w_dcf)*D34 -> 3875.8554 | F34: =E34/E$30-1 -> -0.023232236
A35: DCF 權重 0.3 | C35: =(tp_wA*MAX(0,Val!B8*(1-MIN(tp_g/tp_roe,0.8))/(1+tp_r)^1+Val!B9*(1-MIN(tp_g/tp_roe,0.8))/(1+tp_r)^2+Val!B10*(1-MIN(tp_g/tp_roe,0.8))/(1+tp_r)^3+Val!B11*(1-MIN(tp_g/tp_roe,0.8))/(1+tp_r)^4+Val!B12*(1-MIN(tp_g/tp_roe,0.8))/(1+tp_r)^5+Val!B13*(1-MIN(tp_g/tp_roe,0.8))/(1+tp_r)^6+Val!B13*(1-MIN(tp_g/tp_roe,0.8))*(1+tp_g)/(tp_r-tp_g)/(1+tp_r)^6)+tp_wB*MAX(0,Val!C8*(1-MIN(tp_g/tp_roe,0.8))/(1+tp_r)^1+Val!C9*(1-MIN(tp_g/tp_roe,0.8))/(1+tp_r)^2+Val!C10*(1-MIN(tp_g/tp_roe,0.8))/(1+tp_r)^3+Val!C11*(1-MIN(tp_g/tp_roe,0.8))/(1+tp_r)^4+Val!C12*(1-MIN(tp_g/tp_roe,0.8))/(1+tp_r)^5+Val!C13*(1-MIN(tp_g/tp_roe,0.8))/(1+tp_r)^6+Val!C13*(1-MIN(tp_g/tp_roe,0.8))*(1+tp_g)/(tp_r-tp_g)/(1+tp_r)^6)+tp_wC*MAX(0,Val!D8*(1-MIN(tp_g/tp_roe,0.8))/(1+tp_r)^1+Val!D9*(1-MIN(tp_g/tp_roe,0.8))/(1+tp_r)^2+Val!D10*(1-MIN(tp_g/tp_roe,0.8))/(1+tp_r)^3+Val!D11*(1-MIN(tp_g/tp_roe,0.8))/(1+tp_r)^4+Val!D12*(1-MIN(tp_g/tp_roe,0.8))/(1+tp_r)^5+Val!D13*(1-MIN(tp_g/tp_roe,0.8))/(1+tp_r)^6+Val!D13*(1-MIN(tp_g/tp_roe,0.8))*(1+tp_g)/(tp_r-tp_g)/(1+tp_r)^6))*(1+tp_r) -> 2267.7901 | D35: =tp_comp_adj -> 5668.2937 | E35: =0.3*C35+(1-0.3)*D35 -> 4648.1426 | F35: =E35/E$30-1 -> 0.17139454
A36: DCF 權重 0.7 | C36: =(tp_wA*MAX(0,Val!B8*(1-MIN(tp_g/tp_roe,0.8))/(1+tp_r)^1+Val!B9*(1-MIN(tp_g/tp_roe,0.8))/(1+tp_r)^2+Val!B10*(1-MIN(tp_g/tp_roe,0.8))/(1+tp_r)^3+Val!B11*(1-MIN(tp_g/tp_roe,0.8))/(1+tp_r)^4+Val!B12*(1-MIN(tp_g/tp_roe,0.8))/(1+tp_r)^5+Val!B13*(1-MIN(tp_g/tp_roe,0.8))/(1+tp_r)^6+Val!B13*(1-MIN(tp_g/tp_roe,0.8))*(1+tp_g)/(tp_r-tp_g)/(1+tp_r)^6)+tp_wB*MAX(0,Val!C8*(1-MIN(tp_g/tp_roe,0.8))/(1+tp_r)^1+Val!C9*(1-MIN(tp_g/tp_roe,0.8))/(1+tp_r)^2+Val!C10*(1-MIN(tp_g/tp_roe,0.8))/(1+tp_r)^3+Val!C11*(1-MIN(tp_g/tp_roe,0.8))/(1+tp_r)^4+Val!C12*(1-MIN(tp_g/tp_roe,0.8))/(1+tp_r)^5+Val!C13*(1-MIN(tp_g/tp_roe,0.8))/(1+tp_r)^6+Val!C13*(1-MIN(tp_g/tp_roe,0.8))*(1+tp_g)/(tp_r-tp_g)/(1+tp_r)^6)+tp_wC*MAX(0,Val!D8*(1-MIN(tp_g/tp_roe,0.8))/(1+tp_r)^1+Val!D9*(1-MIN(tp_g/tp_roe,0.8))/(1+tp_r)^2+Val!D10*(1-MIN(tp_g/tp_roe,0.8))/(1+tp_r)^3+Val!D11*(1-MIN(tp_g/tp_roe,0.8))/(1+tp_r)^4+Val!D12*(1-MIN(tp_g/tp_roe,0.8))/(1+tp_r)^5+Val!D13*(1-MIN(tp_g/tp_roe,0.8))/(1+tp_r)^6+Val!D13*(1-MIN(tp_g/tp_roe,0.8))*(1+tp_g)/(tp_r-tp_g)/(1+tp_r)^6))*(1+tp_r) -> 2267.7901 | D36: =tp_comp_adj -> 5668.2937 | E36: =0.7*C36+(1-0.7)*D36 -> 3287.9412 | F36: =E36/E$30-1 -> -0.17139454
A40: 案例區塊：CPU 對 TPU 配比 −0.2（情境 A）
A41: 項目 | B41: 單位 | C41: FY2025A | D41: FY2026（錨點） | E41: FY2027 | F41: FY2028 | G41: FY2029 | H41: FY2030（收斂） | I41: FY2031（收斂） | J41: FY2032（收斂） | K41: 說明
A42: A. Google 自研 Arm CPU 量產（由下而上；D 欄＝FY2026 校準年；FY(t)＝CY(t)）
A43: Google TPU 市場顆數（含情境係數） | B43: 百萬顆 | D43: =u_tpu_26 -> 3.85 | E43: =u_tpu_27 -> 5.5 | F43: =u_tpu_28*um28_A -> 7 | G43: =u_tpu_28*(1+g29_tpu)*um29_A -> 8.05
A44: CPU 對 TPU 配比 | B44: x | D44: =att26 -> 0.325 | E44: =MAX(0,att_A+(-0.2)) -> 0.4 | F44: =MAX(0,att_A+(-0.2)) -> 0.4 | G44: =MAX(0,att_A+(-0.2)) -> 0.4
A45: 創意占 Google 自研 CPU | B45: % | D45: =gsh26 -> 1 | E45: =gsh26 -> 1 | F45: =MIN(1,gsh28_A) -> 1 | G45: =MIN(1,gsh28_A) -> 1
A46: 創意 CPU 顆數 | B46: 百萬顆 | D46: =D43*D44*D45 -> 1.25125 | E46: =E43*E44*E45*1 -> 2.2 | F46: =F43*F44*F45*1 -> 2.8 | G46: =G43*G44*G45*1 -> 3.22
...

Sheet Sources
A1: 來源（公司財報與法說內容多為媒體轉述；券商、資料商、媒體皆為 Interested-party）
A2: 媒體：經濟日報 2026-07-30（2Q26 營收、營業利益、淨利、EPS、毛利率、turnkey 占 83%；1H26） | B2: https://udn.com/news/story/7252/9661575
A3: 媒體：工商時報 2026-07-31（2Q26 EPS；外資 FY2026–28 EPS、目標價 6,500；Visible Alpha 共識） | B3: https://www.ctee.com.tw/news/20260731701051-430201
A4: 媒體：優分析 2026-09-22（法說轉述：3Q26 營收、毛利率、費用方向；全年毛利率 20% 以上；NRE、turnkey 成長；車用占比） | B4: https://uanalyze.com.tw/articles/3528855768
A5: 媒體：優分析 2026-01-30（4Q25 法說：不再給季度區間指引；北美 68%；加密貨幣降為個位數） | B5: https://uanalyze.com.tw/articles/5074646989
A6: 媒體：科技新報（2026 年 9 月營收、前 9 月累計） | B6: https://finance.technews.tw/2026/10/05/guc-3443-202609-financial-report/
A7: 媒體：經濟日報 2026-10-07（3Q26 營收 187.5 億；CPU 出貨 2026 約 125 萬、2027 約 400 萬顆；CPU 對 TPU 1:2） | B7: https://money.udn.com/money/amp/story/5607/9800312
A8: 媒體：經濟日報 2026-09-08（CPU 2027 出貨由 250 萬上修至 350 萬顆；HBM4 PHY、COUPE） | B8: https://money.udn.com/money/amp/story/5607/9741296
A9: 媒體：經濟日報 2026-04-28（本國投顧：2027 CSP CPU 50.3%、北美車用 34.9%；每顆 Arm CPU 配 2 顆 ASIC） | B9: https://money.udn.com/money/amp/story/5607/9468975
A10: 媒體：經濟日報 2026-01-31（FY2025 營收 341.4 億；turnkey 約 64%、NRE 約 34%；AI 約 25%） | B10: https://money.udn.com/money/story/5607/9296878
A11: 券商轉述：科技新報 2026-05-05（摩根士丹利：Google CPU 占營收約一半、北美車用 AI 晶片毛利率高於 15%） | B11: https://technews.tw/2026/05/05/ms-see-guc-2026-q1/
A12: 券商轉述：科技新報 2026-05-08（美銀：1Q26 營收與淨利、Maia 200、Axion 3 奈米） | B12: https://technews.tw/2026/05/08/bofa-see-guc-2026/
A13: 資料商：stockanalysis（股數、近 12 月 EPS、前瞻 P/E、共識目標價） | B13: https://stockanalysis.com/quote/tpe/3443/
... A24: SemiAnalysis | B24: 未使用
