Workbook

Sheet README
A1: Alphabet（GOOGL）個股模型 v0.3（2026-10-27）— 命題模組＋官方營收分部 → 損益表
A3: 命題：AI 改變搜尋之後，Google Search 的變現能否守住，同時 Google Cloud（含 TPU）能否把翻倍的資本支出變成營收；資本支出與 2026 年股權發行後的每股價值是否高於現價。
A4: 核心問題：Search & other 在 C 情境（AI 助理分流、每次查詢變現下降）下 FY2028 營收與利益率會掉多少，Cloud 的 AI 營收能否抵銷；加計 AI 折舊與股權發行後的每股價值。
A5: ="投資建議："&Val!B14&"（加權目標價 US$"&TEXT(Val!B8,"0.00")&"，上檔空間 "&TEXT(Val!B11,"+0.0%;-0.0%")&"；現價 "&TEXT(px,"0.00")&"，2026-10-26）" -> 投資建議：中立（加權目標價 US$248.94，上檔空間 -21.4%；現價 316.80，2026-10-26）
A6: ="重點觀察 1：目標價 "&TEXT(Val!B8,"0")&"＝DCF "&TEXT(Val!B6,"0")&"、分部加總 "&TEXT(Val!B7,"0")&" 各半；情境 A／B／C 為 "&TEXT(Val!B17,"0")&"／"&TEXT(Val!C17,"0")&"／"&TEXT(Val!D17,"0")&"，DCF 終值占 EV "&TEXT(Val!C19,"0%")&"（B）。市場共識目標價 "&TEXT(cons_tp,"0")&"。" -> 重點觀察 1：目標價 249＝DCF 180、分部加總 318 各半；情境 A／B／C 為 273／253／216，DCF 終值占 EV 74%（B）。市場共識目標價 429。
A7: ="重點觀察 2：C 情境 FY2028 Search & other "&TEXT(PL!I131,"0.0")&"（比 B 少 "&TEXT(1-PL!I131/PL!I72,"0.0%")&"），Google Services 營業利益率 "&TEXT(PL!I169,"0.0%")&"（B "&TEXT(PL!I110,"0.0%")&"）；同年 Cloud AI 營收 "&TEXT(PL!I77,"0.0")&"、Google Cloud 營業利益 "&TEXT(PL!I94,"0.0")&"，Cloud 營業利益比 FY2025 增加 "&TEXT(PL!I94-PL!D94,"0.0")&"，是 C 情境 Services 營業利益損失 "&TEXT(PL!I91-PL!I150,"0.0")&" 的 "&TEXT((PL!I94-PL!D94)/(PL!I91-PL!I150),"0%")&"（Cloud 的成長足以抵銷搜尋被侵蝕的利潤）。" -> 重點觀察 2：C 情境 FY2028 Search & other 290.1（比 B 少 14.5%），Google Services 營業利益率 32.1%（B 35.8%）；同年 Cloud AI 營收 56.7、Google Cloud 營業利益 62.1，Cloud 營業利益比 FY2025 增加 48.2，是 C 情境 Services 營業利益損失 34.2 的 141%（Cloud 的成長足以抵銷搜尋被侵蝕的利潤）。
A8: ="重點觀察 3：AI 折舊進損益——情境 B 新增 AI 折舊 FY2028 "&TEXT(PL!I104,"0.0")&"，合併營業利益率由 FY2025 "&TEXT(PL!D109,"0.0%")&" 變為 FY2028 "&TEXT(PL!I109,"0.0%")&"；收支關卡（FY2026–2030 自由現金流扣股利合計）B "&TEXT(CF!C6,"0.0")&"，"&CF!C9&"。" -> 重點觀察 3：AI 折舊進損益——情境 B 新增 AI 折舊 FY2028 62.0，合併營業利益率由 FY2025 32.0% 變為 FY2028 24.2%；收支關卡（FY2026–2030 自由現金流扣股利合計）B 180.0，不需舉債，回購照目標。
A10: 驅動 → 推導對照表（每頁輸入、推導量、因果方向）
A11: 頁 | B11: 輸入（In 頁鍵） | C11: 推導量 | D11: 因果方向
A12: Thesis | B12: pace、ext_sh、mw_tot0、k（kl_px、ks_px、long_sh）、Tokenomics IF_HoldEcon／OpexGW／CapexIT | C12: Cloud AI 營收與 EBITDA、AI 資本支出、新增 AI 折舊、自用 AI 增量成本 | D12: MW → 收入（× 每 MW 持有成本 × k）；MW → 資本支出 → 折舊 → 分部營業利益
A13: Seg | B13: g0（Q 頁近四季）、gl_*、conv_n、dA／mA／dC／mC、tpu_*、ob_rev_* | C13: 四條產品線、三個分部、合併營收；非 AI 資本支出與折舊 | D13: 近四季年增 → 長期值；Search＝B 路徑 ×(1 − 分流)×(1＋變現變動)
A14: PL | B14: m_svc、inc_m、m_co、tpu_m、abc_rate、svc_sh、da_base、tax | C14: 分部 EBITDA、分部營業利益、合併營業利益、淨利、EPS | D14: 分部營收 → 分部 EBITDA − 折舊 → 營業利益 → 業外、稅 → EPS
A15: CF | B15: sbc_r、wc_*、dps、bb_t、min_cash、mat_*、anth_* | C15: 自由現金流、股利、回購、新債、淨現金、收支關卡 | D15: 淨利＋折舊 − 資本支出 → 自由現金流 → 股利 → 回購／舉債
A16: Val | B16: rf、beta、erp、kd、g_tv、ronic、同業倍數、持股、tp_w*、w_dcf | C16: DCF、分部加總、目標價、上檔空間、投資建議 | D16: 無槓桿 FCF 折現＋分部 EBITDA × 倍數 → 情境加權 → 50／50
A17: Sens | B17: In 頁低／高值 | C17: 加權目標價變動 | D17: 一次改一個輸入、整本重算
A19: 與 v0.2.2 的差異
A20: 營收主軸由「AI 雲端 MW × 每 MW 收入＋其餘成長率線」改為官方分部（Google Services 四條產品線、Google Cloud、Other Bets、Alphabet 層級）；Cloud AI 只是 Google Cloud 的子列。
A21: 情境軸由「AI 容量（保守／基準／積極）」改為 Search（A 擴大變現／B 近四季成長收斂／C 查詢分流）；AI 容量三情境相同，改列 Sens。
A22: AI 資本支出接到折舊與分部營業利益（對外 → Cloud、自用 → Services 與 Alphabet 層級），不只接現金。
A23: 評價由 DCF 45%＋EV/EBITDA 55%（錨定 2029）改為 DCF 50%＋分部加總 50%（各分部同業倍數）；評等改五級（上檔空間）。
A24: 融資瀑布、站點、租賃承諾、RPO 等 CRWV 頁面移除（舊引擎保留在 legacy_v0.2/）。
A25: 修正一（獨立核對後）：自用 AI 讀法 2 為主值（影子效益進評價口徑）、分部加總 SBC 加回同口徑、Cloud AI 用自身 DCF、搜尋／YouTube 用 META 倍數、Blume β 與 10 年期 kd、MW 新增 FY2029 起收斂、基礎折舊隨汰換遞減、Other Bets 以 0 計（Waymo 估值未找到）。
A27: 工作表：README → In → Q → Thesis → Seg → PL → CF → Val → Recon → Sens → Sources。藍字＝輸入、黑字＝公式；黃底＝判斷題。建置：bash alphabet/make_v03.sh
A28: 數字標記：Verified（經查核）／Interested-party（公司或賣方自述）／Analogy／Assumed（給區間）／Derived（換算）。本模型是研究整理，不是投資建議以外的保證。

Sheet In
A1: In — 輸入（藍字；基準欄 E，低 D、高 F）。金額 US$B；每股 US$；股數十億股；MW＝IT MW。標記：Verified／Interested-party／Analogy／Assumed／Derived（Analogy、Assumed 一律給低／高區間）
A2: 「沿用 v0.2.2」＝MAG v0.2.2 已核准的參數（原出處：alphabet/legacy_v0.2/company.json、kspec.py、data/kevidence_alphabet_20261008.json、data/tokenomics_snapshot_v21.4.json；對照表 r1 C1–C23）。Tokenomics 維持 v21.4。黃底＝判斷題（Andy 可改）
A3: 鍵 | B3: 項目 | C3: 單位 | D3: 低 | E3: 基準 | F3: 高 | G3: 標記 | H3: 來源 | I3: 說明
A4: A. 現價、股數與資產負債（評價日 2026-06-30，2026Q2 10-Q）
A5: px | B5: 現價（2026-10-26 收盤） | C5: US$ | E5: 316.8 | G5: Verified | H5: StockAnalysis 歷史股價頁 https://stockanalysis.com/stocks/googl/history/（2026-10-27 讀取：10-26 收盤 316.80、10-23 收盤 320.21） | I5: 第二來源：markets/invest_map/data/prices.csv 2026-10-23 收盤 320.21（stockscan、bullfincher）與同頁 10-23 值相同。v0.2.2 現價 350.50（2026-10-07）
A6: sh_out | B6: 流通股數（2026-07-15，10-Q 封面） | C6: 十億股 | E6: 12.23 | G6: Verified | H6: Alphabet Form 10-Q 2026Q2（期末 2026-06-30，核閱數）（2026-07-23；事實總帳 sh.out.20260715）
A7: sh_dil_q2 | B7: 2026Q2 稀釋加權股數 | C7: 十億股 | E7: 12.309 | G7: Interested-party | H7: Alphabet 2026Q2 財報新聞稿（8-K 附件 99.1）（2026-07-22；事實總帳 sh.dilW.2026q2）
A8: sh_basic_q2 | B8: 2026Q2 基本加權股數 | C8: 十億股 | E8: 12.151 | G8: Interested-party | H8: Alphabet 2026Q2 10-Q（2026-07-23）；legacy_v0.2/company.json latestQuarter.basicWaso | I8: 2026-06 股權發行（6/4）只在 Q2 部分期間加權；期末稀釋股數＝Q2 稀釋加權＋(流通股 − Q2 基本加權)
A9: conv_sh | B9: 強制轉換特別股 2029-05-15 轉換股數（上限） | C9: 十億股 | D9: 0.0436 | E9: 0.0546 | F9: 0.0546 | G9: Interested-party | H9: 8-K 2026-06-05：A 系列每股轉 2.2520–2.8160 股、B 系列 2.2740–2.8420 股 → 43.6–54.6M 股；沿用 v0.2.2（legacy_v0.2/company.json） debt.convertibles | I9: 取稀釋最大（保守）；評價時直接加入股數，特別股股利照付至轉換
A10: cash_0 | B10: 現金＋債權類有價證券（2026-06-30） | C10: US$B | E10: 155.411 | G10: Derived | H10: 10-Q 2026Q2：現金 55.911＋有價證券 186.563 − 有價權益證券 87.063（事實總帳 bs.cash、bs.mktsec、bs.mktEq） | I10: 沿用 v0.2.2（legacy_v0.2/company.json） defaults.cash（權益證券改列持股）
A11: cash_ye25 | B11: 現金＋債權類有價證券（2025-12-31） | C11: US$B | E11: 120.53 | G11: Derived | H11: 10-K 2025：30.708＋96.135 − 6.313（沿用 v0.2.2（legacy_v0.2/company.json） ytdActual.cash1231）
A12: debt_0 | B12: 債務面額（2026-06-30） | C12: US$B | E12: 101.085 | G12: Interested-party | H12: 10-Q 2026Q2 附註 6（事實總帳 debt.face）
A13: fines | B13: 應計罰款與和解（類債） | C13: US$B | E13: 17.356 | G13: Interested-party | H13: 10-Q 2026Q2（事實總帳 bs.accruedFines） | I13: 2026-07 已付 Android 案 5.2B（仍以 6/30 餘額扣除，與 v0.2.2 同）
A14: nci | B14: 非控制權益（類債） | C14: US$B | E14: 7.1 | G14: Interested-party | H14: 10-Q 2026Q2（事實總帳 bs.nci；Waymo 等少數股權）
A15: B. 持股（分部加總與 DCF 皆加入；非上市 × (1 − 流動性折價)；上市不折價）
A16: ant_val | B16: Anthropic 最近一輪投後估值（Series H） | C16: US$B | E16: 965 | G16: Interested-party | H16: TechCrunch〈Anthropic raises $65 billion, nears $1T valuation ahead of IPO〉（經 anthropic/ SRC_ANT_299）（2026-05-28；事實總帳 rp.anthropic.val.seriesH）
A17: ant_stake | B17: Anthropic 持股比例 | C17: % | D17: 0.11 | E17: 0.125 | F17: 0.14 | G17: Assumed | H17: 一手不存在：2025 法院文件約 14%；非上市證券帳面 124.3B ÷ 965B 隱含上限 12.9%（沿用 v0.2.2（legacy_v0.2/company.json） valuation.holdings）
A18: illiq | B18: 非上市持股流動性折價 | C18: % | D18: 0 | E18: 0.2 | F18: 0.4 | G18: Assumed | H18: 工作單第 2 節 Val 0.2（1 − 流動性折價 20%）；對照表 r1 第 5 節第 9 條
A19: spacex | B19: SpaceX 持股公允價值（上市、限售） | C19: US$B | E19: 94.1 | G19: Interested-party | H19: 10-Q 2026Q2 附註 3：短期 80.0＋長期限售 14.1（事實總帳 rp.spacex.holding） | I19: 評價日公允價值；之後股價變動未更新（資料缺口）
A20: oth_eq | B20: 其他有價權益證券 | C20: US$B | E20: 7.089 | G20: Derived | H20: 有價權益證券 87.063＋14.126 − SpaceX 94.1（沿用 v0.2.2（legacy_v0.2/company.json））
A21: C. 折現率與目標價規則
A22: rf | B22: 無風險利率（10 年美債，2026-10-07） | C22: % | E22: 0.0528 | G22: Verified | H22: U.S. Treasury〈Daily Treasury Par Yield Curve Rates〉（2026-10）（2026-10-07；事實總帳 val.rf.10y） | I22: 沿用 v0.2.2（legacy_v0.2/company.json）
A23: beta_sa | B23: 原始 β：StockAnalysis 5 年月資料（Yahoo、MarketBeat 同值） | C23: x | E23: 1.21 | G23: Verified | H23: StockAnalysis〈GOOGL statistics〉（2026-10-07；事實總帳 val.beta.sa） | I23: 沿用 v0.2.2（legacy_v0.2/company.json）
A24: beta_gf | B24: 原始 β：GuruFocus 3 年 | C24: x | E24: 1.3669 | G24: Verified | H24: GuruFocus〈GOOGL Beta〉（2026-10-08；事實總帳 val.beta.gurufocus） | I24: 與 StockAnalysis 不同資料商、不同期間（C13）
A25: blume_a | B25: Blume 調整係數（β 調整＝a × 原始 β＋(1 − a)） | C25: x | E25: 0.67 | G25: Derived | H25: Blume（1971）；Bloomberg 調整 β 同式（修正一 F4）
A26: beta | B26: β（Blume 調整後兩個獨立來源的中位數） | C26: x | D26: 1.1407 | E26: =MEDIAN(blume_a*beta_sa+1-blume_a,blume_a*beta_gf+1-blume_a) -> 1.1932615 | F26: 1.2458 | G26: Derived | H26: 修正一 F4：Blume 調整（0.67 × 原始 β＋0.33），兩個獨立來源取中位數 | I26: 低／高＝兩個來源各自的調整值；v0.3 修正前用原始 β 平均 1.288
A27: erp | B27: 股權風險溢酬 | C27: % | D27: 0.04 | E27: 0.05 | F27: 0.06 | G27: Assumed | H27: 沿用 v0.2.2（legacy_v0.2/company.json）（val.erp）
A28: kd_sp | B28: 約 10 年期 AA 公司債利差（相對 10 年美債） | C28: % | D28: 0.004 | E28: 0.006 | F28: 0.009 | G28: Assumed | H28: 判斷：Aa2／AA+（事實總帳 debt.rating）10 年期利差約 50–90bp；2066 長債發行利差 T＋130bp 為 40 年期，不採（修正一 F4）
A29: kd | B29: 稅前債務成本（約 10 年期）＝rf＋利差 | C29: % | E29: =rf+kd_sp -> 0.0588 | G29: Derived | H29: 修正一 F4：kd＝約 10 年期公司債殖利率 | I29: v0.3 修正前用 2066 票據 6.527%（Alphabet 定價條款 FWP（2026-08-06；US$25B 票據）（2026-08-06；事實總帳 val.kd.2066））
A30: fin_lease | B30: 融資租賃負債（2026-06-30） | C30: US$B | E30: 2.59 | G30: Interested-party | H30: 10-Q 2026Q2 附註 4（事實總帳 lease.finLiab） | I30: 計入 WACC 負債與 DCF、分部加總的淨負債（修正一 F6）
A31: wacc_adj | B31: WACC 調整（Sens 格：±1pt） | C31: % | D31: -0.01 | E31: 0 | F31: 0.01 | G31: Assumed | H31: 修正一 F4：WACC ±1 個百分點的目標價格
A32: tax_w | B32: WACC 用稅率（2025 有效稅率） | C32: % | E32: 0.168 | G32: Derived | H32: 10-K 2025：所得稅 26.656 ÷ 稅前 158.826 | I32: 沿用 v0.2.2（legacy_v0.2/company.json）
A33: g_tv | B33: 永續成長率（FY2032 後） | C33: % | D33: 0.02 | E33: 0.03 | F33: 0.04 | G33: Assumed | H33: 工作單第 2 節 Val 0.1（g 3%）
A34: ronic_sp | B34: 永續期新投資報酬率 RONIC 相對 WACC 的差 | C34: % | E34: 0 | F34: 0.05 | G34: Assumed | H34: 修正一 F5：RONIC＝WACC（判斷；終值＝NOPAT(FY2033) ×(1 − g ÷ RONIC) ÷ (WACC − g)） | I34: Sens：WACC＋5pt；修正前固定 12%
A35: mid | B35: 期中慣例：年度現金流距年初 | C35: 年 | E35: 0.5 | G35: Derived | H35: 年度現金流平均發生在年中；2H26 為評價日後 0.25 年
A36: t_2h | B36: 2H26 現金流折現年數（評價日 2026-06-30 起，期中） | C36: 年 | E36: 0.25 | G36: Derived | H36: 2026-07-01～12-31 的中點
A37: tp_wA | B37: 情境權重 A | C37: % | E37: 0.25 | G37: Assumed | H37: 工作單第 2 節 Val 0.3（A 25%／B 50%／C 25%）
A38: tp_wB | B38: 情境權重 B | C38: % | E38: 0.5 | G38: Assumed | H38: 同上
A39: tp_wC | B39: 情境權重 C | C39: % | E39: 0.25 | G39: Assumed | H39: 同上
A40: w_dcf | B40: 目標價中 DCF 的權重（其餘＝分部加總 SOTP） | C40: % | D40: 0.3 | E40: 0.5 | F40: 0.7 | G40: Assumed | H40: 工作單第 2 節 Val 0.3（DCF 50%＋分部加總 50%；與 AI半導體「DCF＋Comparable 各半」一致）
...

Sheet Q
A1: Q — 實績（US$B；EPS 美元；股數十億股）。資料取自 data/alphabet_facts_20261008.json（MAG v0.1a 起的 SEC 一手資料；季度數＝財報新聞稿 [Interested-party，10-Q 核閱]，年度＝10-K [Verified]）
A2: 核對列（實績必須為 0）：產品線合計＝Google Services、分部合計＝合併營收、分部營業利益合計＝合併營業利益（Alphabet-level activities 含避險損益營收與未分攤費用）、營收 − 成本費用＝營業利益、FY2025 四季合計＝年報
A3: 項目 | B3: 2024Q3 | C3: 2024Q4 | D3: 2025Q1 | E3: 2025Q2 | F3: 2025Q3 | G3: 2025Q4 | H3: 2026Q1 | I3: 2026Q2 | J3: FY2024 | K3: FY2025 | L3: 1H26 | M3: 近四季 TTM | N3: 前四季 | O3: 標記 | P3: 來源
A4: 營收（官方分部與產品線）
A5: Google Search & other | B5: 49.385 | C5: 54.034 | D5: 50.702 | E5: 54.19 | F5: 56.567 | G5: 63.073 | H5: 60.399 | I5: 63.271 | J5: 198.084 | K5: 224.532 | L5: =H5+I5 -> 123.67 | M5: =SUM(F5:I5) -> 243.31 | N5: =SUM(B5:E5) -> 208.311 | O5: Verified（年）／Interested-party（季） | P5: 季：Alphabet 財報新聞稿（8-K 附件 99.1，各季；事實總帳 is.*.2024q3–2026q2）；年：Form 10-K FY2024、FY2025（經查核）；例：2026Q2 https://www.sec.gov/Archives/edgar/data/1652044/000165204426000066/googexhibit991q22026.htm
A6: YouTube ads | B6: 8.921 | C6: 10.473 | D6: 8.927 | E6: 9.796 | F6: 10.261 | G6: 11.383 | H6: 9.883 | I6: 11.055 | J6: 36.147 | K6: 40.367 | L6: =H6+I6 -> 20.938 | M6: =SUM(F6:I6) -> 42.582 | N6: =SUM(B6:E6) -> 38.117 | O6: Verified（年）／Interested-party（季） | P6: 季：Alphabet 財報新聞稿（8-K 附件 99.1，各季；事實總帳 is.*.2024q3–2026q2）；年：Form 10-K FY2024、FY2025（經查核）；例：2026Q2 https://www.sec.gov/Archives/edgar/data/1652044/000165204426000066/googexhibit991q22026.htm
A7: Google Network | B7: 7.548 | C7: 7.954 | D7: 7.256 | E7: 7.354 | F7: 7.354 | G7: 7.828 | H7: 6.971 | I7: 7.303 | J7: 30.359 | K7: 29.792 | L7: =H7+I7 -> 14.274 | M7: =SUM(F7:I7) -> 29.456 | N7: =SUM(B7:E7) -> 30.112 | O7: Verified（年）／Interested-party（季） | P7: 季：Alphabet 財報新聞稿（8-K 附件 99.1，各季；事實總帳 is.*.2024q3–2026q2）；年：Form 10-K FY2024、FY2025（經查核）；例：2026Q2 https://www.sec.gov/Archives/edgar/data/1652044/000165204426000066/googexhibit991q22026.htm
A8: Google subscriptions, platforms, and devices | B8: 10.656 | C8: 11.633 | D8: 10.379 | E8: 11.203 | F8: 12.87 | G8: 13.578 | H8: 12.384 | I8: 12.911 | J8: 40.34 | K8: 48.03 | L8: =H8+I8 -> 25.295 | M8: =SUM(F8:I8) -> 51.743 | N8: =SUM(B8:E8) -> 43.871 | O8: Verified（年）／Interested-party（季） | P8: 季：Alphabet 財報新聞稿（8-K 附件 99.1，各季；事實總帳 is.*.2024q3–2026q2）；年：Form 10-K FY2024、FY2025（經查核）；例：2026Q2 https://www.sec.gov/Archives/edgar/data/1652044/000165204426000066/googexhibit991q22026.htm
A9: Google Services（分部） | B9: 76.51 | C9: 84.094 | D9: 77.264 | E9: 82.543 | F9: 87.052 | G9: 95.862 | H9: 89.637 | I9: 94.54 | J9: 304.93 | K9: 342.721 | L9: =H9+I9 -> 184.177 | M9: =SUM(F9:I9) -> 367.091 | N9: =SUM(B9:E9) -> 320.411 | O9: Verified（年）／Interested-party（季） | P9: 季：Alphabet 財報新聞稿（8-K 附件 99.1，各季；事實總帳 is.*.2024q3–2026q2）；年：Form 10-K FY2024、FY2025（經查核）；例：2026Q2 https://www.sec.gov/Archives/edgar/data/1652044/000165204426000066/googexhibit991q22026.htm
A10: 檢查：產品線合計 − Google Services | B10: =B5+B6+B7+B8-B9 -> 0 | C10: =C5+C6+C7+C8-C9 -> 0 | D10: =D5+D6+D7+D8-D9 -> 0 | E10: =E5+E6+E7+E8-E9 -> 0 | F10: =F5+F6+F7+F8-F9 -> 0 | G10: =G5+G6+G7+G8-G9 -> 0 | H10: =H5+H6+H7+H8-H9 -> 0 | I10: =I5+I6+I7+I8-I9 -> 0 | ... K10: =K5+K6+K7+K8-K9 -> 0 | L10: =H10+I10 -> 0 | M10: =SUM(F10:I10) -> 0 | N10: =SUM(B10:E10) -> 0 | O10: — | P10: —
A11: Google Cloud（分部） | B11: 11.353 | C11: 11.955 | D11: 12.26 | E11: 13.624 | F11: 15.157 | G11: 17.664 | H11: 20.028 | I11: 24.768 | J11: 43.229 | K11: 58.705 | L11: =H11+I11 -> 44.796 | M11: =SUM(F11:I11) -> 77.617 | N11: =SUM(B11:E11) -> 49.192 | O11: Verified（年）／Interested-party（季） | P11: 季：Alphabet 財報新聞稿（8-K 附件 99.1，各季；事實總帳 is.*.2024q3–2026q2）；年：Form 10-K FY2024、FY2025（經查核）；例：2026Q2 https://www.sec.gov/Archives/edgar/data/1652044/000165204426000066/googexhibit991q22026.htm
A12: Other Bets（分部） | B12: 0.388 | C12: 0.4 | D12: 0.45 | E12: 0.373 | F12: 0.344 | G12: 0.37 | H12: 0.411 | I12: 0.382 | J12: 1.648 | K12: 1.537 | L12: =H12+I12 -> 0.793 | M12: =SUM(F12:I12) -> 1.507 | N12: =SUM(B12:E12) -> 1.611 | O12: Verified（年）／Interested-party（季） | P12: 季：Alphabet 財報新聞稿（8-K 附件 99.1，各季；事實總帳 is.*.2024q3–2026q2）；年：Form 10-K FY2024、FY2025（經查核）；例：2026Q2 https://www.sec.gov/Archives/edgar/data/1652044/000165204426000066/googexhibit991q22026.htm
A13: Hedging gains (losses)（Alphabet-level） | B13: 0.017 | C13: 0.02 | D13: 0.26 | E13: -0.112 | F13: -0.207 | G13: -0.068 | H13: -0.18 | I13: 0.106 | J13: 0.211 | K13: -0.127 | L13: =H13+I13 -> -0.074 | M13: =SUM(F13:I13) -> -0.349 | N13: =SUM(B13:E13) -> 0.185 | O13: Verified（年）／Interested-party（季） | P13: 季：Alphabet 財報新聞稿（8-K 附件 99.1，各季；事實總帳 is.*.2024q3–2026q2）；年：Form 10-K FY2024、FY2025（經查核）；例：2026Q2 https://www.sec.gov/Archives/edgar/data/1652044/000165204426000066/googexhibit991q22026.htm
A14: 合併營收 | B14: 88.268 | C14: 96.469 | D14: 90.234 | E14: 96.428 | F14: 102.346 | G14: 113.828 | H14: 109.896 | I14: 119.796 | J14: 350.018 | K14: 402.836 | L14: =H14+I14 -> 229.692 | M14: =SUM(F14:I14) -> 445.866 | N14: =SUM(B14:E14) -> 371.399 | O14: Verified（年）／Interested-party（季） | P14: 季：Alphabet 財報新聞稿（8-K 附件 99.1，各季；事實總帳 is.*.2024q3–2026q2）；年：Form 10-K FY2024、FY2025（經查核）；例：2026Q2 https://www.sec.gov/Archives/edgar/data/1652044/000165204426000066/googexhibit991q22026.htm
A15: 檢查：分部合計＋避險 − 合併營收 | B15: =B9+B11+B12+B13-B14 -> 0 | C15: =C9+C11+C12+C13-C14 -> 0 | D15: =D9+D11+D12+D13-D14 -> 0 | E15: =E9+E11+E12+E13-E14 -> 0 | F15: =F9+F11+F12+F13-F14 -> 0 | G15: =G9+G11+G12+G13-G14 -> 0 | H15: =H9+H11+H12+H13-H14 -> 0 | I15: =I9+I11+I12+I13-I14 -> 0 | ... K15: =K9+K11+K12+K13-K14 -> 0 | L15: =H15+I15 -> 0 | M15: =SUM(F15:I15) -> 0 | N15: =SUM(B15:E15) -> 0 | O15: — | P15: —
A17: 分部營業利益
A18: Google Services 營業利益 | B18: 30.856 | C18: 32.836 | D18: 32.682 | E18: 33.063 | F18: 33.527 | G18: 40.132 | H18: 40.589 | I18: 39.544 | J18: 121.263 | K18: 139.404 | L18: =H18+I18 -> 80.133 | M18: =SUM(F18:I18) -> 153.792 | N18: =SUM(B18:E18) -> 129.437 | O18: Verified（年）／Interested-party（季） | P18: 季：Alphabet 財報新聞稿（8-K 附件 99.1，各季；事實總帳 is.*.2024q3–2026q2）；年：Form 10-K FY2024、FY2025（經查核）；例：2026Q2 https://www.sec.gov/Archives/edgar/data/1652044/000165204426000066/googexhibit991q22026.htm
A19: Google Cloud 營業利益 | B19: 1.947 | C19: 2.093 | D19: 2.177 | E19: 2.826 | F19: 3.594 | G19: 5.313 | H19: 6.598 | I19: 8.814 | J19: 6.112 | K19: 13.91 | L19: =H19+I19 -> 15.412 | M19: =SUM(F19:I19) -> 24.319 | N19: =SUM(B19:E19) -> 9.043 | O19: Verified（年）／Interested-party（季） | P19: 季：Alphabet 財報新聞稿（8-K 附件 99.1，各季；事實總帳 is.*.2024q3–2026q2）；年：Form 10-K FY2024、FY2025（經查核）；例：2026Q2 https://www.sec.gov/Archives/edgar/data/1652044/000165204426000066/googexhibit991q22026.htm
A20: Other Bets 營業利益 | B20: -1.116 | C20: -1.174 | D20: -1.226 | E20: -1.246 | F20: -1.426 | G20: -3.617 | H20: -2.1 | I20: -1.799 | J20: -4.444 | K20: -7.515 | L20: =H20+I20 -> -3.899 | M20: =SUM(F20:I20) -> -8.942 | N20: =SUM(B20:E20) -> -4.762 | O20: Verified（年）／Interested-party（季） | P20: 季：Alphabet 財報新聞稿（8-K 附件 99.1，各季；事實總帳 is.*.2024q3–2026q2）；年：Form 10-K FY2024、FY2025（經查核）；例：2026Q2 https://www.sec.gov/Archives/edgar/data/1652044/000165204426000066/googexhibit991q22026.htm
A21: Alphabet-level activities（避險營收 − 未分攤費用） | B21: -3.166 | C21: -2.783 | D21: -3.027 | E21: -3.372 | F21: -4.467 | G21: -5.894 | H21: -5.391 | I21: -5.789 | J21: -10.541 | K21: -16.76 | L21: =H21+I21 -> -11.18 | M21: =SUM(F21:I21) -> -21.541 | N21: =SUM(B21:E21) -> -12.348 | O21: Verified（年）／Interested-party（季） | P21: 季：Alphabet 財報新聞稿（8-K 附件 99.1，各季；事實總帳 is.*.2024q3–2026q2）；年：Form 10-K FY2024、FY2025（經查核）；例：2026Q2 https://www.sec.gov/Archives/edgar/data/1652044/000165204426000066/googexhibit991q22026.htm
A22: 合併營業利益 | B22: 28.521 | C22: 30.972 | D22: 30.606 | E22: 31.271 | F22: 31.228 | G22: 35.934 | H22: 39.696 | I22: 40.77 | J22: 112.39 | K22: 129.039 | L22: =H22+I22 -> 80.466 | M22: =SUM(F22:I22) -> 147.628 | N22: =SUM(B22:E22) -> 121.37 | O22: Verified（年）／Interested-party（季） | P22: 季：Alphabet 財報新聞稿（8-K 附件 99.1，各季；事實總帳 is.*.2024q3–2026q2）；年：Form 10-K FY2024、FY2025（經查核）；例：2026Q2 https://www.sec.gov/Archives/edgar/data/1652044/000165204426000066/googexhibit991q22026.htm
A23: 檢查：分部營業利益合計 − 合併營業利益 | B23: =B18+B19+B20+B21-B22 -> 0 | C23: =C18+C19+C20+C21-C22 -> 0 | D23: =D18+D19+D20+D21-D22 -> 0 | E23: =E18+E19+E20+E21-E22 -> 0 | F23: =F18+F19+F20+F21-F22 -> 0 | G23: =G18+G19+G20+G21-G22 -> 0 | H23: =H18+H19+H20+H21-H22 -> 0 | I23: =I18+I19+I20+I21-I22 -> 0 | ... K23: =K18+K19+K20+K21-K22 -> 0 | L23: =H23+I23 -> 0 | M23: =SUM(F23:I23) -> 0 | N23: =SUM(B23:E23) -> 0 | O23: — | P23: —
A25: 合併損益
A26: 營業成本 | B26: 36.474 | C26: 40.613 | D26: 36.361 | E26: 39.039 | F26: 41.369 | G26: 45.766 | H26: 41.271 | I26: 45.943 | J26: 146.306 | K26: 162.535 | L26: =H26+I26 -> 87.214 | M26: =SUM(F26:I26) -> 174.349 | N26: =SUM(B26:E26) -> 152.487 | O26: Verified（年）／Interested-party（季） | P26: 季：Alphabet 財報新聞稿（8-K 附件 99.1，各季；事實總帳 is.*.2024q3–2026q2）；年：Form 10-K FY2024、FY2025（經查核）；例：2026Q2 https://www.sec.gov/Archives/edgar/data/1652044/000165204426000066/googexhibit991q22026.htm
A27: 其中：流量獲取成本 TAC | B27: 13.719 | C27: 14.848 | D27: 13.748 | E27: 14.705 | F27: 14.876 | G27: 16.597 | H27: 15.228 | I27: 16.179 | L27: =H27+I27 -> 31.407 | M27: =SUM(F27:I27) -> 62.88 | N27: =SUM(B27:E27) -> 57.02 | O27: Verified（年）／Interested-party（季） | P27: 季：Alphabet 財報新聞稿（8-K 附件 99.1，各季；事實總帳 is.*.2024q3–2026q2）；年：Form 10-K FY2024、FY2025（經查核）；例：2026Q2 https://www.sec.gov/Archives/edgar/data/1652044/000165204426000066/googexhibit991q22026.htm
A28: 研發費用 | B28: 12.447 | C28: 13.116 | D28: 13.556 | E28: 13.808 | F28: 15.151 | G28: 18.572 | H28: 17.032 | I28: 18.219 | J28: 49.326 | K28: 61.087 | L28: =H28+I28 -> 35.251 | M28: =SUM(F28:I28) -> 68.974 | N28: =SUM(B28:E28) -> 52.927 | O28: Verified（年）／Interested-party（季） | P28: 季：Alphabet 財報新聞稿（8-K 附件 99.1，各季；事實總帳 is.*.2024q3–2026q2）；年：Form 10-K FY2024、FY2025（經查核）；例：2026Q2 https://www.sec.gov/Archives/edgar/data/1652044/000165204426000066/googexhibit991q22026.htm
A29: 行銷費用 | B29: 7.227 | C29: 7.363 | D29: 6.172 | E29: 7.101 | F29: 7.205 | G29: 8.215 | H29: 7.606 | I29: 8.403 | J29: 27.808 | K29: 28.693 | L29: =H29+I29 -> 16.009 | M29: =SUM(F29:I29) -> 31.429 | N29: =SUM(B29:E29) -> 27.863 | O29: Verified（年）／Interested-party（季） | P29: 季：Alphabet 財報新聞稿（8-K 附件 99.1，各季；事實總帳 is.*.2024q3–2026q2）；年：Form 10-K FY2024、FY2025（經查核）；例：2026Q2 https://www.sec.gov/Archives/edgar/data/1652044/000165204426000066/googexhibit991q22026.htm
A30: 管理費用 | B30: 3.599 | C30: 4.405 | D30: 3.539 | E30: 5.209 | F30: 7.393 | G30: 5.341 | H30: 4.291 | I30: 6.461 | J30: 14.188 | K30: 21.482 | L30: =H30+I30 -> 10.752 | M30: =SUM(F30:I30) -> 23.486 | N30: =SUM(B30:E30) -> 16.752 | O30: Verified（年）／Interested-party（季） | P30: 季：Alphabet 財報新聞稿（8-K 附件 99.1，各季；事實總帳 is.*.2024q3–2026q2）；年：Form 10-K FY2024、FY2025（經查核）；例：2026Q2 https://www.sec.gov/Archives/edgar/data/1652044/000165204426000066/googexhibit991q22026.htm
A31: 檢查：營收 − 成本費用 − 營業利益 | B31: =B14-B26-B28-B29-B30-B22 -> 0 | C31: =C14-C26-C28-C29-C30-C22 -> 0 | D31: =D14-D26-D28-D29-D30-D22 -> 0 | E31: =E14-E26-E28-E29-E30-E22 -> 0 | F31: =F14-F26-F28-F29-F30-F22 -> 0 | G31: =G14-G26-G28-G29-G30-G22 -> 0 | H31: =H14-H26-H28-H29-H30-H22 -> 0 | I31: =I14-I26-I28-I29-I30-I22 -> 0 | ... K31: =K14-K26-K28-K29-K30-K22 -> 0 | L31: =H31+I31 -> 0 | M31: =SUM(F31:I31) -> 0 | N31: =SUM(B31:E31) -> 0 | O31: — | P31: —
A32: 其他收益淨額（含權益證券損益） | B32: 3.185 | C32: 1.271 | D32: 11.183 | E32: 2.662 | F32: 12.759 | G32: 3.183 | H32: 37.716 | I32: 97.983 | J32: 7.425 | K32: 29.787 | L32: =H32+I32 -> 135.699 | M32: =SUM(F32:I32) -> 151.641 | N32: =SUM(B32:E32) -> 18.301 | O32: Verified（年）／Interested-party（季） | P32: 季：Alphabet 財報新聞稿（8-K 附件 99.1，各季；事實總帳 is.*.2024q3–2026q2）；年：Form 10-K FY2024、FY2025（經查核）；例：2026Q2 https://www.sec.gov/Archives/edgar/data/1652044/000165204426000066/googexhibit991q22026.htm
A33: 其中：權益證券淨損益 | B33: 1.821 | C33: 0.364 | D33: 9.758 | E33: 1.286 | F33: 10.734 | G33: 2.302 | H33: 36.915 | I33: 99.031 | L33: =H33+I33 -> 135.946 | M33: =SUM(F33:I33) -> 148.982 | N33: =SUM(B33:E33) -> 13.229 | O33: Verified（年）／Interested-party（季） | P33: 季：Alphabet 財報新聞稿（8-K 附件 99.1，各季；事實總帳 is.*.2024q3–2026q2）；年：Form 10-K FY2024、FY2025（經查核）；例：2026Q2 https://www.sec.gov/Archives/edgar/data/1652044/000165204426000066/googexhibit991q22026.htm
A34: 稅前利益 | B34: 31.706 | C34: 32.243 | D34: 41.789 | E34: 33.933 | F34: 43.987 | G34: 39.117 | H34: 77.412 | I34: 138.753 | J34: 119.815 | K34: 158.826 | L34: =H34+I34 -> 216.165 | M34: =SUM(F34:I34) -> 299.269 | N34: =SUM(B34:E34) -> 139.671 | O34: Verified（年）／Interested-party（季） | P34: 季：Alphabet 財報新聞稿（8-K 附件 99.1，各季；事實總帳 is.*.2024q3–2026q2）；年：Form 10-K FY2024、FY2025（經查核）；例：2026Q2 https://www.sec.gov/Archives/edgar/data/1652044/000165204426000066/googexhibit991q22026.htm
A35: 檢查：營業利益＋其他收益 − 稅前利益 | B35: =B22+B32-B34 -> 0 | C35: =C22+C32-C34 -> 0 | D35: =D22+D32-D34 -> 0 | E35: =E22+E32-E34 -> 0 | F35: =F22+F32-F34 -> 0 | G35: =G22+G32-G34 -> 0 | H35: =H22+H32-H34 -> 0 | I35: =I22+I32-I34 -> 0 | ... K35: =K22+K32-K34 -> 0 | L35: =H35+I35 -> 0 | M35: =SUM(F35:I35) -> 0 | N35: =SUM(B35:E35) -> 0 | O35: — | P35: —
A36: 所得稅 | B36: 5.405 | C36: 5.707 | D36: 7.249 | E36: 5.737 | F36: 9.008 | G36: 4.662 | H36: 14.834 | I36: 26.56 | J36: 19.697 | K36: 26.656 | L36: =H36+I36 -> 41.394 | M36: =SUM(F36:I36) -> 55.064 | N36: =SUM(B36:E36) -> 24.098 | O36: Verified（年）／Interested-party（季） | P36: 季：Alphabet 財報新聞稿（8-K 附件 99.1，各季；事實總帳 is.*.2024q3–2026q2）；年：Form 10-K FY2024、FY2025（經查核）；例：2026Q2 https://www.sec.gov/Archives/edgar/data/1652044/000165204426000066/googexhibit991q22026.htm
A37: 淨利 | B37: 26.301 | C37: 26.536 | D37: 34.54 | E37: 28.196 | F37: 34.979 | G37: 34.455 | H37: 62.578 | I37: 112.193 | J37: 100.118 | K37: 132.17 | L37: =H37+I37 -> 174.771 | M37: =SUM(F37:I37) -> 244.205 | N37: =SUM(B37:E37) -> 115.573 | O37: Verified（年）／Interested-party（季） | P37: 季：Alphabet 財報新聞稿（8-K 附件 99.1，各季；事實總帳 is.*.2024q3–2026q2）；年：Form 10-K FY2024、FY2025（經查核）；例：2026Q2 https://www.sec.gov/Archives/edgar/data/1652044/000165204426000066/googexhibit991q22026.htm
A38: 檢查：稅前 − 所得稅 − 淨利 | B38: =B34-B36-B37 -> 0 | C38: =C34-C36-C37 -> 0 | D38: =D34-D36-D37 -> 0 | E38: =E34-E36-E37 -> 0 | F38: =F34-F36-F37 -> 0 | G38: =G34-G36-G37 -> 0 | H38: =H34-H36-H37 -> 0 | I38: =I34-I36-I37 -> 0 | ... K38: =K34-K36-K37 -> 0 | L38: =H38+I38 -> 0 | M38: =SUM(F38:I38) -> 0 | N38: =SUM(B38:E38) -> 0 | O38: — | P38: —
A39: 稀釋加權股數（十億股） | B39: 12.419 | C39: 12.348 | D39: 12.291 | E39: 12.198 | F39: 12.203 | G39: 12.228 | H39: 12.238 | I39: 12.309 | J39: 12.447 | K39: 12.23 | L39: =AVERAGE(H39:I39) -> 12.2735 | O39: Verified（年）／Interested-party（季） | P39: 季：Alphabet 財報新聞稿（8-K 附件 99.1，各季；事實總帳 is.*.2024q3–2026q2）；年：Form 10-K FY2024、FY2025（經查核）；例：2026Q2 https://www.sec.gov/Archives/edgar/data/1652044/000165204426000066/googexhibit991q22026.htm
A40: EPS（GAAP 稀釋，美元） | B40: 2.12 | C40: 2.15 | D40: 2.81 | E40: 2.31 | F40: 2.87 | G40: 2.82 | H40: 5.11 | I40: 9.11 | J40: 8.04 | K40: 10.81 | L40: =H40+I40 -> 14.22 | M40: =SUM(F40:I40) -> 19.91 | N40: =SUM(B40:E40) -> 9.39 | O40: Verified（年）／Interested-party（季） | P40: 季：Alphabet 財報新聞稿（8-K 附件 99.1，各季；事實總帳 is.*.2024q3–2026q2）；年：Form 10-K FY2024、FY2025（經查核）；例：2026Q2 https://www.sec.gov/Archives/edgar/data/1652044/000165204426000066/googexhibit991q22026.htm
A42: 現金流、資本支出與股東回饋
A43: 折舊（不動產與設備） | B43: 3.985 | C43: 4.205 | D43: 4.487 | E43: 4.998 | F43: 5.611 | G43: 6.04 | H43: 6.482 | I43: 7.104 | J43: 15.311 | K43: 21.136 | L43: =H43+I43 -> 13.586 | M43: =SUM(F43:I43) -> 25.237 | N43: =SUM(B43:E43) -> 17.675 | O43: Verified（年）／Interested-party（季） | P43: 季：Alphabet 財報新聞稿（8-K 附件 99.1，各季；事實總帳 is.*.2024q3–2026q2）；年：Form 10-K FY2024、FY2025（經查核）；例：2026Q2 https://www.sec.gov/Archives/edgar/data/1652044/000165204426000066/googexhibit991q22026.htm
...

Sheet Thesis
A1: Thesis — 命題模組：AI 容量（MW）× 每 MW 收入（Tokenomics 持有成本 × k）→ Google Cloud 的 Cloud AI 子列；同一套 MW 推出 AI 資本支出、AI 折舊與營運成本，接到分部營業利益（對外 → Google Cloud；自用 → Google Services／Alphabet 層級）
A2: 三情境共用（本版的情境軸是 Search，見 Seg 頁）；MW 速度、對外比例、k 的區間在 Sens 頁。沿用 v0.2.2：k 規格（kspec.py）、C10 基準速度、對外比例 30%、Tokenomics v21.4 快照。不以 Cloud 營收、RPO 反推 k 或每 MW 價格（工作單第 4 節）
A4: A. 價格與起始值（單一數值，C 欄）
A5: 項目 | B5: 單位 | C5: 數值 | N5: 說明
A6: k_長約＝長約證據價格 ÷ IF_HoldEcon｜VR200 | B6: x | C6: =kl_px/he_vr -> 0.78291462 | N6: kspec.py（v0.2.2）：證據價格不變、分母隨 Tokenomics 快照
A7: k_現貨＝H100 現貨指數 ÷ IF_GPUhrEcon｜H100 | B7: x | C7: =ks_px/gpuhr_h -> 1.8280865 | N7: C1：MAG 三家一致
A8: 混合 k＝長約占比 × k_長約＋(1 − 長約占比) × k_現貨 | B8: x | C8: =long_sh*k_long+(1-long_sh)*k_spot -> 1.2009834 | N8: v0.2.2 為 1.201
A9: TPU 收入錨調整＝1 − TPU 占比 ×(1 − TPU 係數) | B9: x | C9: =1-tpu_sh*(1-tpu_f) -> 1 | N9: 基準 1（C2：TPU × 1.0）
A10: TPU IT 資本支出調整 | B10: x | C10: =1-tpu_sh*(1-tpu_cf) -> 1
A11: 期初機隊每 MW 年收入（對外） | B11: US$m/MW-年 | C11: =k_blend*tpu_adj*(mix0_h*he_h+mix0_b2*he_b2+mix0_b3*he_b3) -> 11.606747
A12: 期初機隊每 MW 年營運費用（Tokenomics IF_OpexGW 加權） | B12: US$m/MW-年 | C12: =mix0_h*opx_h+mix0_b2*opx_b2+mix0_b3*opx_b3 -> 1.881462
A13: 近四季 Cloud AI 營收估計（近四季平均對外 MW × 期初每 MW 收入） | B13: US$B | C13: =ai_mw_ttm*permw0/1000 -> 16.80541 | N13: 只用於拆 Cloud 其他的起始成長率與利潤率
A14: 前四季 Cloud AI 營收估計 | B14: US$B | C14: =ai_mw_pttm*permw0/1000 -> 7.6291151
A15: 近四季 Cloud AI EBITDA 估計 | B15: US$B | C15: =ai_mw_ttm*(permw0-opex0)/1000 -> 14.081241
A16: Cloud 其他近四季年增（Cloud − Cloud AI 估計） | B16: % | C16: =(cloud_ttm-ai_ttm)/(cloud_pttm-ai_pttm)-1 -> 0.46312246 | N16: [Derived]；Cloud 其他＝Workspace、非 AI 雲端、Wiz（2026-03 併入）
A17: Cloud 其他 EBITDA 率（近四季：Cloud EBITDA − Cloud AI EBITDA 估計）÷ Cloud 其他營收 | B17: % | C17: =(cloud_ebitda_ttm-ai_ttm_e)/(cloud_ttm-ai_ttm) -> 0.24053995 | N17: [Derived]；mb_ttm＝1 時採用
A18: Cloud 其他 EBITDA 率（1H26） | B18: % | C18: =(Q!L19+Q!L43*sh1_cloud-E41)/(Q!L11-E38) -> 0.28210362 | N18: [Derived]；(1H26 Cloud 營業利益＋分攤折舊 − Cloud AI 1H EBITDA) ÷ Cloud 其他 1H
A19: Cloud 其他 EBITDA 率（預測期採用，固定） | B19: % | C19: =IF(mb_ttm=1,m_co_ttm,m_co_1h) -> 0.28210362 | N19: 預設 1H26（同 m_svc）
A21: B. AI 容量（AI 總 IT MW；期末）— 依 Tokenomics 世代錨分桶
A22: 項目 | B22: 單位 | C22: FY2024A | D22: FY2025A | E22: 1H26A | F22: 2H26E | G22: FY2026E | H22: FY2027E | I22: FY2028E | J22: FY2029E | K22: FY2030E | L22: FY2031E | M22: FY2032E | N22: 說明
A23: AI 總 MW 新增（FY2029 起收斂到 g × 期初 MW） | B23: MW | F23: =pace*0.5 -> 2079.835 | G23: =F23 -> 2079.835 | H23: =pace -> 4159.67 | I23: =pace -> 4159.67 | J23: =pace+(g_tv*I28-pace)*MIN(1,(2029-2028)/conv_mw) -> 3245.2738 | K23: =pace+(g_tv*J28-pace)*MIN(1,(2030-2028)/conv_mw) -> 2379.5567 | L23: =pace+(g_tv*K28-pace)*MIN(1,(2031-2028)/conv_mw) -> 1543.0401 | M23: =pace+(g_tv*L28-pace)*MIN(1,(2032-2028)/conv_mw) -> 717.12137 | N23: 三情境相同；修正一 F5：FY2029–FY2032 線性收斂，FY2032 只剩與永續成長 g 一致的增量（另加汰換）
A24: 期末 MW：Hopper 錨 | B24: MW | E24: =mw_tot0*mix0_h -> 1584.25 | F24: =E24+F23*0 -> 1584.25 | G24: =F24 -> 1584.25 | H24: =F24+H23*0 -> 1584.25 | I24: =H24+I23*0 -> 1584.25 | J24: =I24+J23*0 -> 1584.25 | K24: =J24+K23*0 -> 1584.25 | L24: =K24+L23*0 -> 1584.25 | M24: =L24+M23*0 -> 1584.25 | N24: 期初（2026-06-30）＝AI 在役 MW × 期初機隊占比；新增依年度世代組合（2026 GB300 錨；2027 GB300／VR200 各半；2028 起 VR200 錨）
A25: 期末 MW：GB200 錨 | B25: MW | E25: =mw_tot0*mix0_b2 -> 2851.65 | F25: =E25+F23*0 -> 2851.65 | G25: =F25 -> 2851.65 | H25: =F25+H23*0 -> 2851.65 | I25: =H25+I23*0 -> 2851.65 | J25: =I25+J23*0 -> 2851.65 | K25: =J25+K23*0 -> 2851.65 | L25: =K25+L23*0 -> 2851.65 | M25: =L25+M23*0 -> 2851.65
A26: 期末 MW：GB300 錨 | B26: MW | E26: =mw_tot0*mix0_b3 -> 1901.1 | F26: =E26+F23*am_26 -> 3980.935 | G26: =F26 -> 3980.935 | H26: =F26+H23*am_27 -> 6060.77 | I26: =H26+I23*(1-am_28) -> 6060.77 | J26: =I26+J23*(1-am_28) -> 6060.77 | K26: =J26+K23*(1-am_28) -> 6060.77 | L26: =K26+L23*(1-am_28) -> 6060.77 | M26: =L26+M23*(1-am_28) -> 6060.77
A27: 期末 MW：VR200 錨 | B27: MW | E27: =mw_tot0*0 -> 0 | F27: =E27+F23*(1-am_26) -> 0 | G27: =F27 -> 0 | H27: =F27+H23*(1-am_27) -> 2079.835 | I27: =H27+I23*am_28 -> 6239.505 | J27: =I27+J23*am_28 -> 9484.7788 | K27: =J27+K23*am_28 -> 11864.336 | L27: =K27+L23*am_28 -> 13407.376 | M27: =L27+M23*am_28 -> 14124.497
A28: 期末 AI 總 MW | B28: MW | E28: =E24+E25+E26+E27 -> 6337 | F28: =F24+F25+F26+F27 -> 8416.835 | G28: =G24+G25+G26+G27 -> 8416.835 | H28: =H24+H25+H26+H27 -> 12576.505 | I28: =I24+I25+I26+I27 -> 16736.175 | J28: =J24+J25+J26+J27 -> 19981.449 | K28: =K24+K25+K26+K27 -> 22361.006 | L28: =L24+L25+L26+L27 -> 23904.046 | M28: =M24+M25+M26+M27 -> 24621.167
A29: 期末對外 MW（＝總 MW × 對外比例） | B29: MW | E29: =E28*ext_sh -> 1901.1 | F29: =F28*ext_sh -> 2525.0505 | G29: =G28*ext_sh -> 2525.0505 | H29: =H28*ext_sh -> 3772.9515 | I29: =I28*ext_sh -> 5020.8525 | J29: =J28*ext_sh -> 5994.4346 | K29: =K28*ext_sh -> 6708.3017 | L29: =L28*ext_sh -> 7171.2137 | M29: =M28*ext_sh -> 7386.3501 | N29: 評價日 1,901（v0.2.2 defaults.billableOpen）
A30: 平均在役 MW：Hopper 錨 | B30: MW | E30: =(mw_ye25+mw_tot0)/2*mix0_h -> 1401.25 | F30: =(E24+F24)/2 -> 1584.25 | G30: =(E30+F30)/2 -> 1492.75 | H30: =(F24+H24)/2 -> 1584.25 | I30: =(H24+I24)/2 -> 1584.25 | J30: =(I24+J24)/2 -> 1584.25 | K30: =(J24+K24)/2 -> 1584.25 | L30: =(K24+L24)/2 -> 1584.25 | M30: =(L24+M24)/2 -> 1584.25
A31: 平均在役 MW：GB200 錨 | B31: MW | E31: =(mw_ye25+mw_tot0)/2*mix0_b2 -> 2522.25 | F31: =(E25+F25)/2 -> 2851.65 | G31: =(E31+F31)/2 -> 2686.95 | H31: =(F25+H25)/2 -> 2851.65 | I31: =(H25+I25)/2 -> 2851.65 | J31: =(I25+J25)/2 -> 2851.65 | K31: =(J25+K25)/2 -> 2851.65 | L31: =(K25+L25)/2 -> 2851.65 | M31: =(L25+M25)/2 -> 2851.65
A32: 平均在役 MW：GB300 錨 | B32: MW | E32: =(mw_ye25+mw_tot0)/2*mix0_b3 -> 1681.5 | F32: =(E26+F26)/2 -> 2941.0175 | G32: =(E32+F32)/2 -> 2311.2587 | H32: =(F26+H26)/2 -> 5020.8525 | I32: =(H26+I26)/2 -> 6060.77 | J32: =(I26+J26)/2 -> 6060.77 | K32: =(J26+K26)/2 -> 6060.77 | L32: =(K26+L26)/2 -> 6060.77 | M32: =(L26+M26)/2 -> 6060.77
A33: 平均在役 MW：VR200 錨 | B33: MW | E33: =(mw_ye25+mw_tot0)/2*0 -> 0 | F33: =(E27+F27)/2 -> 0 | G33: =(E33+F33)/2 -> 0 | H33: =(F27+H27)/2 -> 1039.9175 | I33: =(H27+I27)/2 -> 4159.67 | J33: =(I27+J27)/2 -> 7862.1419 | K33: =(J27+K27)/2 -> 10674.557 | L33: =(K27+L27)/2 -> 12635.856 | M33: =(L27+M27)/2 -> 13765.936
A34: 平均在役 AI 總 MW | B34: MW | E34: =E30+E31+E32+E33 -> 5605 | F34: =F30+F31+F32+F33 -> 7376.9175 | G34: =G30+G31+G32+G33 -> 6490.9587 | H34: =H30+H31+H32+H33 -> 10496.67 | I34: =I30+I31+I32+I33 -> 14656.34 | J34: =J30+J31+J32+J33 -> 18358.812 | K34: =K30+K31+K32+K33 -> 21171.227 | L34: =L30+L31+L32+L33 -> 23132.526 | M34: =M30+M31+M32+M33 -> 24262.606
A35: 平均在役對外 MW | B35: MW | E35: =E34*ext_sh -> 1681.5 | F35: =F34*ext_sh -> 2213.0752 | G35: =G34*ext_sh -> 1947.2876 | H35: =H34*ext_sh -> 3149.001 | I35: =I34*ext_sh -> 4396.902 | J35: =J34*ext_sh -> 5507.6436 | K35: =K34*ext_sh -> 6351.3682 | L35: =L34*ext_sh -> 6939.7577 | M35: =M34*ext_sh -> 7278.7819
A37: C. Cloud AI（對外 AI 雲端；Google Cloud 的命題子列）
A38: Cloud AI 營收＝對外比例 × Σ 平均 MW × IF_HoldEcon × k × TPU 調整 | B38: US$B | E38: =ext_sh*k_blend*tpu_adj*(E30*he_h+E31*he_b2+E32*he_b3+E33*he_vr)/1000*0.5 -> 9.7583729 | F38: =ext_sh*k_blend*tpu_adj*(F30*he_h+F31*he_b2+F32*he_b3+F33*he_vr)/1000*0.5 -> 13.072238 | G38: =E38+F38 -> 22.830611 | H38: =ext_sh*k_blend*tpu_adj*(H30*he_h+H31*he_b2+H32*he_b3+H33*he_vr)/1000*1 -> 38.882858 | I38: =ext_sh*k_blend*tpu_adj*(I30*he_h+I31*he_b2+I32*he_b3+I33*he_vr)/1000*1 -> 56.703559 | J38: =ext_sh*k_blend*tpu_adj*(J30*he_h+J31*he_b2+J32*he_b3+J33*he_vr)/1000*1 -> 73.012119 | K38: =ext_sh*k_blend*tpu_adj*(K30*he_h+K31*he_b2+K32*he_b3+K33*he_vr)/1000*1 -> 85.400179 | L38: =ext_sh*k_blend*tpu_adj*(L30*he_h+L31*he_b2+L32*he_b3+L33*he_vr)/1000*1 -> 94.03926 | M38: =ext_sh*k_blend*tpu_adj*(M30*he_h+M31*he_b2+M32*he_b3+M33*he_vr)/1000*1 -> 99.017013 | N38: 收入端不乘 IF_Util（MW-year 計價）；1H26 為模型估計（公司未揭露 AI 營收），Cloud 其他＝實際 Cloud − 本列
A39: 每 MW 年收入（對外） | B39: US$m/MW-年 | E39: =E38/(E35*0.5)*1000 -> 11.606747 | F39: =F38/(F35*0.5)*1000 -> 11.813641 | H39: =H38/(H35*1)*1000 -> 12.34768 | I39: =I38/(I35*1)*1000 -> 12.896253 | J39: =J38/(J35*1)*1000 -> 13.256508 | K39: =K38/(K35*1)*1000 -> 13.44595 | L39: =L38/(L35*1)*1000 -> 13.550799 | M39: =M38/(M35*1)*1000 -> 13.603514
A40: Cloud AI 營運費用（Tokenomics IF_OpexGW，含電費） | B40: US$B | E40: =ext_sh*(E30*opx_h+E31*opx_b2+E32*opx_b3+E33*opx_vr)/1000*0.5 -> 1.5818392 | F40: =ext_sh*(F30*opx_h+F31*opx_b2+F32*opx_b3+F33*opx_vr)/1000*0.5 -> 2.0976902 | G40: =E40+F40 -> 3.6795295 | H40: =ext_sh*(H30*opx_h+H31*opx_b2+H32*opx_b3+H33*opx_vr)/1000*1 -> 6.0855653 | I40: =ext_sh*(I30*opx_h+I31*opx_b2+I32*opx_b3+I33*opx_vr)/1000*1 -> 8.6634547 | J40: =ext_sh*(J30*opx_h+J31*opx_b2+J32*opx_b3+J33*opx_vr)/1000*1 -> 10.988787 | K40: =ext_sh*(K30*opx_h+K31*opx_b2+K32*opx_b3+K33*opx_vr)/1000*1 -> 12.755121 | L40: =ext_sh*(L30*opx_h+L31*opx_b2+L32*opx_b3+L33*opx_vr)/1000*1 -> 13.986912 | M40: =ext_sh*(M30*opx_h+M31*opx_b2+M32*opx_b3+M33*opx_vr)/1000*1 -> 14.696657
A41: Cloud AI EBITDA | B41: US$B | E41: =E38-E40 -> 8.1765337 | F41: =F38-F40 -> 10.974548 | G41: =G38-G40 -> 19.151082 | H41: =H38-H40 -> 32.797293 | I41: =I38-I40 -> 48.040104 | J41: =J38-J40 -> 62.023332 | K41: =K38-K40 -> 72.645058 | L41: =L38-L40 -> 80.052348 | M41: =M38-M40 -> 84.320356
A42: Cloud AI EBITDA 率 | B42: % | E42: =E41/E38 -> 0.83789929 | F42: =F41/F38 -> 0.8395309 | G42: =G41/G38 -> 0.83883351 | H42: =H41/H38 -> 0.84348976 | I42: =I41/I38 -> 0.84721497 | J42: =J41/J38 -> 0.84949366 | K42: =K41/K38 -> 0.85064293 | L42: =L41/L38 -> 0.85126519 | M42: =M41/M38 -> 0.85157442
A43: 上限檢查：每 MW 收入 ÷ 在役世代加權 IFW_RevGWFleet_Util（> 50% 示警；不得作預測） | B43: % | E43: =E39/((E30*cap_h+E31*cap_b2+E32*cap_b3+E33*cap_vr)/E34) -> 0.40541575 | F43: =F39/((F30*cap_h+F31*cap_b2+F32*cap_b3+F33*cap_vr)/F34) -> 0.39027147 | H43: =H39/((H30*cap_h+H31*cap_b2+H32*cap_b3+H33*cap_vr)/H34) -> 0.34465881 | I43: =I39/((I30*cap_h+I31*cap_b2+I32*cap_b3+I33*cap_vr)/I34) -> 0.30246186 | J43: =J39/((J30*cap_h+J31*cap_b2+J32*cap_b3+J33*cap_vr)/J34) -> 0.27956196 | K43: =K39/((K30*cap_h+K31*cap_b2+K32*cap_b3+K33*cap_vr)/K34) -> 0.26927931 | L43: =L39/((L30*cap_h+L31*cap_b2+L32*cap_b3+L33*cap_vr)/L34) -> 0.26402136 | M43: =M39/((M30*cap_h+M31*cap_b2+M32*cap_b3+M33*cap_vr)/M34) -> 0.26148405 | N43: v0.2.2 基準最高 38.0%
...

Sheet Seg
A1: Seg — 營收分部層：官方分部（Google Services、Google Cloud、Other Bets）＋Alphabet 層級避險；產品線為子列。情境差異只在 Google Search & other（A 擴大變現／B 近四季成長收斂／C 查詢分流、變現下降），其餘三情境相同
A2: 成長路徑：2H26 年增＝近四季年增（Q 頁），之後線性收斂到長期值（conv_n 年，FY2030 到達）。Search 情境：Search＝B 路徑 ×(1 − 分流) ×(1＋每次查詢變現變動)，分流與變現變動自 FY2026 的 0 線性到 FY2030 的 In 頁值。Cloud AI 由 Thesis 頁帶入
A4: 情境 A（AI 搜尋擴大變現）
A5: 項目 | B5: 單位 | C5: FY2024A | D5: FY2025A | E5: 1H26A | F5: 2H26E | G5: FY2026E | H5: FY2027E | I5: FY2028E | J5: FY2029E | K5: FY2030E | L5: FY2031E | M5: FY2032E | N5: 說明
A6: Search B 路徑年增 | B6: % | F6: =g0_search -> 0.16801321 | H6: =g0_search+(gl_search-g0_search)*MIN(1,(2027-2026)/conv_n) -> 0.14600991 | I6: =g0_search+(gl_search-g0_search)*MIN(1,(2028-2026)/conv_n) -> 0.12400661 | J6: =g0_search+(gl_search-g0_search)*MIN(1,(2029-2026)/conv_n) -> 0.1020033 | K6: =g0_search+(gl_search-g0_search)*MIN(1,(2030-2026)/conv_n) -> 0.08 | L6: =g0_search+(gl_search-g0_search)*MIN(1,(2031-2026)/conv_n) -> 0.08 | M6: =g0_search+(gl_search-g0_search)*MIN(1,(2032-2026)/conv_n) -> 0.08 | N6: 2H26 年增＝近四季 +16.8%（Q 頁），FY2030 收斂到 gl_search
A7: Google Search & other：B 路徑 | B7: US$B | C7: =Q!J5 -> 198.084 | D7: =Q!K5 -> 224.532 | E7: =Q!L5 -> 123.67 | F7: =(Q!F5+Q!G5)*(1+F6) -> 139.7411 | G7: =E7+F7 -> 263.4111 | H7: =G7*(1+H6) -> 301.87173 | I7: =H7*(1+I6) -> 339.30582 | J7: =I7*(1+J6) -> 373.91613 | K7: =J7*(1+K6) -> 403.82942 | L7: =K7*(1+L6) -> 436.13578 | M7: =L7*(1+M6) -> 471.02664
A8: 情境爬坡（FY2026 0 → FY2030 1） | B8: x | F8: 0 | H8: =MIN(1,(2027-2026)/conv_n) -> 0.25 | I8: =MIN(1,(2028-2026)/conv_n) -> 0.5 | J8: =MIN(1,(2029-2026)/conv_n) -> 0.75 | K8: =MIN(1,(2030-2026)/conv_n) -> 1 | L8: =MIN(1,(2031-2026)/conv_n) -> 1 | M8: =MIN(1,(2032-2026)/conv_n) -> 1
A9: 查詢分流（相對 B 路徑） | B9: % | F9: =dA*F8 -> 0 | H9: =dA*H8 -> -0.0125 | I9: =dA*I8 -> -0.025 | J9: =dA*J8 -> -0.0375 | K9: =dA*K8 -> -0.05 | L9: =dA*L8 -> -0.05 | M9: =dA*M8 -> -0.05 | N9: In 頁 dA（負值＝AI 模式吸引查詢回流）
A10: 每次查詢變現變動（相對 B 路徑） | B10: % | F10: =mA*F8 -> 0 | H10: =mA*H8 -> 0.025 | I10: =mA*I8 -> 0.05 | J10: =mA*J8 -> 0.075 | K10: =mA*K8 -> 0.1 | L10: =mA*L8 -> 0.1 | M10: =mA*M8 -> 0.1
A11: Google Search & other | B11: US$B | C11: =C7 -> 198.084 | D11: =D7 -> 224.532 | E11: =E7 -> 123.67 | F11: =F7*(1-F9)*(1+F10) -> 139.7411 | G11: =E11+F11 -> 263.4111 | H11: =H7*(1-H9)*(1+H10) -> 313.28626 | I11: =I7*(1-I9)*(1+I10) -> 365.17789 | J11: =J7*(1-J9)*(1+J10) -> 417.03334 | K11: =K7*(1-K9)*(1+K10) -> 466.42299 | L11: =L7*(1-L9)*(1+L10) -> 503.73682 | M11: =M7*(1-M9)*(1+M10) -> 544.03577
A12: YouTube ads 年增 | B12: % | F12: =g0_yt -> 0.11713933 | H12: =g0_yt+(gl_yt-g0_yt)*MIN(1,(2027-2026)/conv_n) -> 0.1078545 | I12: =g0_yt+(gl_yt-g0_yt)*MIN(1,(2028-2026)/conv_n) -> 0.098569667 | J12: =g0_yt+(gl_yt-g0_yt)*MIN(1,(2029-2026)/conv_n) -> 0.089284834 | K12: =g0_yt+(gl_yt-g0_yt)*MIN(1,(2030-2026)/conv_n) -> 0.08 | L12: =g0_yt+(gl_yt-g0_yt)*MIN(1,(2031-2026)/conv_n) -> 0.08 | M12: =g0_yt+(gl_yt-g0_yt)*MIN(1,(2032-2026)/conv_n) -> 0.08 | N12: 三情境相同
A13: YouTube ads | B13: US$B | C13: =Q!J6 -> 36.147 | D13: =Q!K6 -> 40.367 | E13: =Q!L6 -> 20.938 | F13: =(Q!F6+Q!G6)*(1+F12) -> 24.179364 | G13: =E13+F13 -> 45.117364 | H13: =G13*(1+H12) -> 49.983474 | I13: =H13*(1+I12) -> 54.910329 | J13: =I13*(1+J12) -> 59.812989 | K13: =J13*(1+K12) -> 64.598028 | L13: =K13*(1+L12) -> 69.76587 | M13: =L13*(1+M12) -> 75.347139
A14: Google Network 年增 | B14: % | F14: =g0_net -> -0.021785335 | H14: =g0_net+(gl_net-g0_net)*MIN(1,(2027-2026)/conv_n) -> -0.016339001 | I14: =g0_net+(gl_net-g0_net)*MIN(1,(2028-2026)/conv_n) -> -0.010892667 | J14: =g0_net+(gl_net-g0_net)*MIN(1,(2029-2026)/conv_n) -> -0.0054463337 | K14: =g0_net+(gl_net-g0_net)*MIN(1,(2030-2026)/conv_n) -> 0 | L14: =g0_net+(gl_net-g0_net)*MIN(1,(2031-2026)/conv_n) -> 0 | M14: =g0_net+(gl_net-g0_net)*MIN(1,(2032-2026)/conv_n) -> 0 | N14: 三情境相同
A15: Google Network | B15: US$B | C15: =Q!J7 -> 30.359 | D15: =Q!K7 -> 29.792 | E15: =Q!L7 -> 14.274 | F15: =(Q!F7+Q!G7)*(1+F14) -> 14.851255 | G15: =E15+F15 -> 29.125255 | H15: =G15*(1+H14) -> 28.649377 | I15: =H15*(1+I14) -> 28.337309 | J15: =I15*(1+J14) -> 28.182975 | K15: =J15*(1+K14) -> 28.182975 | L15: =K15*(1+L14) -> 28.182975 | M15: =L15*(1+M14) -> 28.182975
A16: Google subscriptions, platforms, and devices 年增 | B16: % | F16: =g0_subs -> 0.17943516 | H16: =g0_subs+(gl_subs-g0_subs)*MIN(1,(2027-2026)/conv_n) -> 0.15957637 | I16: =g0_subs+(gl_subs-g0_subs)*MIN(1,(2028-2026)/conv_n) -> 0.13971758 | J16: =g0_subs+(gl_subs-g0_subs)*MIN(1,(2029-2026)/conv_n) -> 0.11985879 | K16: =g0_subs+(gl_subs-g0_subs)*MIN(1,(2030-2026)/conv_n) -> 0.1 | L16: =g0_subs+(gl_subs-g0_subs)*MIN(1,(2031-2026)/conv_n) -> 0.1 | M16: =g0_subs+(gl_subs-g0_subs)*MIN(1,(2032-2026)/conv_n) -> 0.1 | N16: 三情境相同
A17: Google subscriptions, platforms, and devices | B17: US$B | C17: =Q!J8 -> 40.34 | D17: =Q!K8 -> 48.03 | E17: =Q!L8 -> 25.295 | F17: =(Q!F8+Q!G8)*(1+F16) -> 31.193701 | G17: =E17+F17 -> 56.488701 | H17: =G17*(1+H16) -> 65.502963 | I17: =H17*(1+I16) -> 74.654879 | J17: =I17*(1+J16) -> 83.602922 | K17: =J17*(1+K16) -> 91.963214 | L17: =K17*(1+L16) -> 101.15954 | M17: =L17*(1+M16) -> 111.27549
A18: Google Services | B18: US$B | C18: =Q!J9 -> 304.93 | D18: =Q!K9 -> 342.721 | E18: =Q!L9 -> 184.177 | F18: =F11+F13+F15+F17 -> 209.96542 | G18: =E18+F18 -> 394.14242 | H18: =H11+H13+H15+H17 -> 457.42207 | I18: =I11+I13+I15+I17 -> 523.08041 | J18: =J11+J13+J15+J17 -> 588.63222 | K18: =K11+K13+K15+K17 -> 651.1672 | L18: =L11+L13+L15+L17 -> 702.84521 | M18: =M11+M13+M15+M17 -> 758.84137
A19: Cloud AI（命題子列） | B19: US$B | E19: =Thesis!E38 -> 9.7583729 | F19: =Thesis!F38 -> 13.072238 | G19: =Thesis!G38 -> 22.830611 | H19: =Thesis!H38 -> 38.882858 | I19: =Thesis!I38 -> 56.703559 | J19: =Thesis!J38 -> 73.012119 | K19: =Thesis!K38 -> 85.400179 | L19: =Thesis!L38 -> 94.03926 | M19: =Thesis!M38 -> 99.017013 | N19: Thesis 頁：對外 MW × 每 MW 收入（1H26 為模型估計）
A20: TPU 系統銷售（命題子列） | B20: US$B | E20: 0 | F20: =tpu_2h -> 1 | G20: =E20+F20 -> 1 | H20: =tpu_yr -> 13 | I20: =tpu_yr -> 13 | J20: =tpu_yr -> 13 | K20: =tpu_yr -> 13 | L20: =tpu_yr -> 13 | M20: =tpu_yr -> 13 | N20: C8 b：不走 MW × 每 MW；1H26 金額未揭露 → 0
A21: Cloud 其他年增 | B21: % | F21: =g0_co -> 0.46312246 | H21: =g0_co+(gl_co-g0_co)*MIN(1,(2027-2026)/conv_n) -> 0.36734184 | I21: =g0_co+(gl_co-g0_co)*MIN(1,(2028-2026)/conv_n) -> 0.27156123 | J21: =g0_co+(gl_co-g0_co)*MIN(1,(2029-2026)/conv_n) -> 0.17578061 | K21: =g0_co+(gl_co-g0_co)*MIN(1,(2030-2026)/conv_n) -> 0.08 | L21: =g0_co+(gl_co-g0_co)*MIN(1,(2031-2026)/conv_n) -> 0.08 | M21: =g0_co+(gl_co-g0_co)*MIN(1,(2032-2026)/conv_n) -> 0.08 | N21: 起始＝Cloud 其他近四季年增（Thesis 頁 g0_co），FY2030 收斂到 gl_co
A22: Cloud 其他（命題子列） | B22: US$B | E22: =Q!L11-E19-E20 -> 35.037627 | F22: =E22*(1+F21)^0.5 -> 42.381373 | G22: =E22+F22 -> 77.419 | H22: =G22*(1+H21) -> 105.85824 | I22: =H22*(1+I21) -> 134.60523 | J22: =I22*(1+J21) -> 158.26622 | K22: =J22*(1+K21) -> 170.92752 | L22: =K22*(1+L21) -> 184.60172 | M22: =L22*(1+M21) -> 199.36986 | N22: 1H26＝Google Cloud 實績 − Cloud AI 估計 − TPU；2H26＝1H26 ×(1＋年增)^0.5
A23: Google Cloud | B23: US$B | C23: =Q!J11 -> 43.229 | D23: =Q!K11 -> 58.705 | E23: =Q!L11 -> 44.796 | F23: =F19+F20+F22 -> 56.453611 | G23: =E23+F23 -> 101.24961 | H23: =H19+H20+H22 -> 157.7411 | I23: =I19+I20+I22 -> 204.30879 | J23: =J19+J20+J22 -> 244.27834 | K23: =K19+K20+K22 -> 269.3277 | L23: =L19+L20+L22 -> 291.64098 | M23: =M19+M20+M22 -> 311.38687
A24: Other Bets | B24: US$B | C24: =Q!J12 -> 1.648 | D24: =Q!K12 -> 1.537 | E24: =Q!L12 -> 0.793 | F24: =ob_rev_2H -> 0.75 | G24: =E24+F24 -> 1.543 | H24: =ob_rev_27 -> 1.6 | I24: =ob_rev_28 -> 1.8 | J24: =ob_rev_29 -> 2 | K24: =ob_rev_30 -> 2.2 | L24: =ob_rev_31 -> 2.4 | M24: =ob_rev_32 -> 2.6
A25: Hedging gains (losses) | B25: US$B | C25: =Q!J13 -> 0.211 | D25: =Q!K13 -> -0.127 | E25: =Q!L13 -> -0.074 | F25: 0 | G25: =E25+F25 -> -0.074 | H25: 0 | I25: 0 | J25: 0 | K25: 0 | L25: 0 | M25: 0 | N25: Alphabet-level activities；預測期 0 [Assumed]
A26: 合併營收 | B26: US$B | C26: =Q!J14 -> 350.018 | D26: =Q!K14 -> 402.836 | E26: =Q!L14 -> 229.692 | F26: =F18+F23+F24+F25 -> 267.16903 | G26: =E26+F26 -> 496.86103 | H26: =H18+H23+H24+H25 -> 616.76317 | I26: =I18+I23+I24+I25 -> 729.1892 | J26: =J18+J23+J24+J25 -> 834.91057 | K26: =K18+K23+K24+K25 -> 922.6949 | L26: =L18+L23+L24+L25 -> 996.88619 | M26: =M18+M23+M24+M25 -> 1072.8282
A27: 檢查：產品線合計 − Google Services | B27: US$B | C27: =C11+C13+C15+C17-C18 -> 0 | D27: =D11+D13+D15+D17-D18 -> 0 | E27: =E11+E13+E15+E17-E18 -> 0 | F27: =F11+F13+F15+F17-F18 -> 0 | G27: =G11+G13+G15+G17-G18 -> 0 | H27: =H11+H13+H15+H17-H18 -> 0 | I27: =I11+I13+I15+I17-I18 -> 0 | J27: =J11+J13+J15+J17-J18 -> 0 | ... M27: =M11+M13+M15+M17-M18 -> 0
A28: 檢查：Cloud 子列合計 − Google Cloud | B28: US$B | E28: =E19+E20+E22-E23 -> 0 | F28: =F19+F20+F22-F23 -> 0 | G28: =G19+G20+G22-G23 -> 0 | H28: =H19+H20+H22-H23 -> 0 | I28: =I19+I20+I22-I23 -> 0 | J28: =J19+J20+J22-J23 -> 0 | K28: =K19+K20+K22-K23 -> 0 | L28: =L19+L20+L22-L23 -> 0 | M28: =M19+M20+M22-M23 -> 0
A29: 檢查：分部合計＋避險 − 合併營收 | B29: US$B | C29: =C18+C23+C24+C25-C26 -> 0 | D29: =D18+D23+D24+D25-D26 -> 0 | E29: =E18+E23+E24+E25-E26 -> 0 | F29: =F18+F23+F24+F25-F26 -> 0 | G29: =G18+G23+G24+G25-G26 -> 0 | H29: =H18+H23+H24+H25-H26 -> 0 | I29: =I18+I23+I24+I25-I26 -> 0 | J29: =J18+J23+J24+J25-J26 -> 0 | ... M29: =M18+M23+M24+M25-M26 -> 0
A30: 檢查：實績欄合併營收 − Q 頁（FY2024、FY2025、1H26） | B30: US$B | C30: =C26-Q!J14 -> 0 | D30: =D26-Q!K14 -> 0 | E30: =E26-Q!L14 -> 0
A31: 非 AI 資本支出：Google Services（營收 × cx_svc） | B31: US$B | F31: =F18*cx_svc -> 12.597925 | G31: =F31 -> 12.597925 | H31: =H18*cx_svc -> 27.445324 | I31: =I18*cx_svc -> 31.384824 | J31: =J18*cx_svc -> 35.317933 | K31: =K18*cx_svc -> 39.070032 | L31: =L18*cx_svc -> 42.170712 | M31: =M18*cx_svc -> 45.530482
A32: 非 AI 資本支出：Cloud 其他（營收 × cx_co） | B32: US$B | F32: =F22*cx_co -> 8.4762747 | G32: =F32 -> 8.4762747 | H32: =H22*cx_co -> 21.171648 | I32: =I22*cx_co -> 26.921046 | J32: =J22*cx_co -> 31.653245 | K32: =K22*cx_co -> 34.185504 | L32: =L22*cx_co -> 36.920344 | M32: =M22*cx_co -> 39.873972
A33: 非 AI 資本支出：Other Bets（營收 × cx_ob） | B33: US$B | F33: =F24*cx_ob -> 0.045 | G33: =F33 -> 0.045 | H33: =H24*cx_ob -> 0.096 | I33: =I24*cx_ob -> 0.108 | J33: =J24*cx_ob -> 0.12 | K33: =K24*cx_ob -> 0.132 | L33: =L24*cx_ob -> 0.144 | M33: =M24*cx_ob -> 0.156
A34: 非 AI 資本支出合計 | B34: US$B | F34: =F31+F32+F33 -> 21.1192 | G34: =G31+G32+G33 -> 21.1192 | H34: =H31+H32+H33 -> 48.712972 | I34: =I31+I32+I33 -> 58.413871 | J34: =J31+J32+J33 -> 67.091178 | K34: =K31+K32+K33 -> 73.387536 | L34: =L31+L32+L33 -> 79.235057 | M34: =M31+M32+M33 -> 85.560454
A35: 新增非 AI 折舊：Google Services（年限 life_na） | B35: US$B | F35: =$F$31/life_na*IF(0=0,phi_0,IF(0<life_na,1,IF(0=life_na,1-phi_0,0))) -> 0.31494813 | G35: =F35 -> 0.31494813 | H35: =$F$31/life_na*IF(1=0,phi_0,IF(1<life_na,1,IF(1=life_na,1-phi_0,0)))+$H$31/life_na*IF(0=0,phi_0,IF(0<life_na,1,IF(0=life_na,1-phi_0,0))) -> 1.9459256 | I35: =$F$31/life_na*IF(2=0,phi_0,IF(2<life_na,1,IF(2=life_na,1-phi_0,0)))+$H$31/life_na*IF(1=0,phi_0,IF(1<life_na,1,IF(1=life_na,1-phi_0,0)))+$I$31/life_na*IF(0=0,phi_0,IF(0<life_na,1,IF(0=life_na,1-phi_0,0))) -> 4.7889456 | J35: =$F$31/life_na*IF(3=0,phi_0,IF(3<life_na,1,IF(3=life_na,1-phi_0,0)))+$H$31/life_na*IF(2=0,phi_0,IF(2<life_na,1,IF(2=life_na,1-phi_0,0)))+$I$31/life_na*IF(1=0,phi_0,IF(1<life_na,1,IF(1=life_na,1-phi_0,0)))+$J$31/life_na*IF(0=0,phi_0,IF(0<life_na,1,IF(0=life_na,1-phi_0,0))) -> 8.0257557 | K35: =$F$31/life_na*IF(4=0,phi_0,IF(4<life_na,1,IF(4=life_na,1-phi_0,0)))+$H$31/life_na*IF(3=0,phi_0,IF(3<life_na,1,IF(3=life_na,1-phi_0,0)))+$I$31/life_na*IF(2=0,phi_0,IF(2<life_na,1,IF(2=life_na,1-phi_0,0)))+$J$31/life_na*IF(1=0,phi_0,IF(1<life_na,1,IF(1=life_na,1-phi_0,0)))+$K$31/life_na*IF(0=0,phi_0,IF(0<life_na,1,IF(0=life_na,1-phi_0,0))) -> 11.651352 | L35: =$F$31/life_na*IF(5=0,phi_0,IF(5<life_na,1,IF(5=life_na,1-phi_0,0)))+$H$31/life_na*IF(4=0,phi_0,IF(4<life_na,1,IF(4=life_na,1-phi_0,0)))+$I$31/life_na*IF(3=0,phi_0,IF(3<life_na,1,IF(3=life_na,1-phi_0,0)))+$J$31/life_na*IF(2=0,phi_0,IF(2<life_na,1,IF(2=life_na,1-phi_0,0)))+$K$31/life_na*IF(1=0,phi_0,IF(1<life_na,1,IF(1=life_na,1-phi_0,0)))+$L$31/life_na*IF(0=0,phi_0,IF(0<life_na,1,IF(0=life_na,1-phi_0,0))) -> 15.635872 | M35: =$F$31/life_na*IF(6=0,phi_0,IF(6<life_na,1,IF(6=life_na,1-phi_0,0)))+$H$31/life_na*IF(5=0,phi_0,IF(5<life_na,1,IF(5=life_na,1-phi_0,0)))+$I$31/life_na*IF(4=0,phi_0,IF(4<life_na,1,IF(4=life_na,1-phi_0,0)))+$J$31/life_na*IF(3=0,phi_0,IF(3<life_na,1,IF(3=life_na,1-phi_0,0)))+$K$31/life_na*IF(2=0,phi_0,IF(2<life_na,1,IF(2=life_na,1-phi_0,0)))+$L$31/life_na*IF(1=0,phi_0,IF(1<life_na,1,IF(1=life_na,1-phi_0,0)))+$M$31/life_na*IF(0=0,phi_0,IF(0<life_na,1,IF(0=life_na,1-phi_0,0))) -> 19.936937
A36: 新增非 AI 折舊：Cloud 其他（年限 life_na） | B36: US$B | F36: =$F$32/life_na*IF(0=0,phi_0,IF(0<life_na,1,IF(0=life_na,1-phi_0,0))) -> 0.21190687 | G36: =F36 -> 0.21190687 | H36: =$F$32/life_na*IF(1=0,phi_0,IF(1<life_na,1,IF(1=life_na,1-phi_0,0)))+$H$32/life_na*IF(0=0,phi_0,IF(0<life_na,1,IF(0=life_na,1-phi_0,0))) -> 1.3769187 | I36: =$F$32/life_na*IF(2=0,phi_0,IF(2<life_na,1,IF(2=life_na,1-phi_0,0)))+$H$32/life_na*IF(1=0,phi_0,IF(1<life_na,1,IF(1=life_na,1-phi_0,0)))+$I$32/life_na*IF(0=0,phi_0,IF(0<life_na,1,IF(0=life_na,1-phi_0,0))) -> 3.6378184 | J36: =$F$32/life_na*IF(3=0,phi_0,IF(3<life_na,1,IF(3=life_na,1-phi_0,0)))+$H$32/life_na*IF(2=0,phi_0,IF(2<life_na,1,IF(2=life_na,1-phi_0,0)))+$I$32/life_na*IF(1=0,phi_0,IF(1<life_na,1,IF(1=life_na,1-phi_0,0)))+$J$32/life_na*IF(0=0,phi_0,IF(0<life_na,1,IF(0=life_na,1-phi_0,0))) -> 6.448228 | K36: =$F$32/life_na*IF(4=0,phi_0,IF(4<life_na,1,IF(4=life_na,1-phi_0,0)))+$H$32/life_na*IF(3=0,phi_0,IF(3<life_na,1,IF(3=life_na,1-phi_0,0)))+$I$32/life_na*IF(2=0,phi_0,IF(2<life_na,1,IF(2=life_na,1-phi_0,0)))+$J$32/life_na*IF(1=0,phi_0,IF(1<life_na,1,IF(1=life_na,1-phi_0,0)))+$K$32/life_na*IF(0=0,phi_0,IF(0<life_na,1,IF(0=life_na,1-phi_0,0))) -> 9.6768589 | L36: =$F$32/life_na*IF(5=0,phi_0,IF(5<life_na,1,IF(5=life_na,1-phi_0,0)))+$H$32/life_na*IF(4=0,phi_0,IF(4<life_na,1,IF(4=life_na,1-phi_0,0)))+$I$32/life_na*IF(3=0,phi_0,IF(3<life_na,1,IF(3=life_na,1-phi_0,0)))+$J$32/life_na*IF(2=0,phi_0,IF(2<life_na,1,IF(2=life_na,1-phi_0,0)))+$K$32/life_na*IF(1=0,phi_0,IF(1<life_na,1,IF(1=life_na,1-phi_0,0)))+$L$32/life_na*IF(0=0,phi_0,IF(0<life_na,1,IF(0=life_na,1-phi_0,0))) -> 13.16378 | M36: =$F$32/life_na*IF(6=0,phi_0,IF(6<life_na,1,IF(6=life_na,1-phi_0,0)))+$H$32/life_na*IF(5=0,phi_0,IF(5<life_na,1,IF(5=life_na,1-phi_0,0)))+$I$32/life_na*IF(4=0,phi_0,IF(4<life_na,1,IF(4=life_na,1-phi_0,0)))+$J$32/life_na*IF(3=0,phi_0,IF(3<life_na,1,IF(3=life_na,1-phi_0,0)))+$K$32/life_na*IF(2=0,phi_0,IF(2<life_na,1,IF(2=life_na,1-phi_0,0)))+$L$32/life_na*IF(1=0,phi_0,IF(1<life_na,1,IF(1=life_na,1-phi_0,0)))+$M$32/life_na*IF(0=0,phi_0,IF(0<life_na,1,IF(0=life_na,1-phi_0,0))) -> 16.929655
A37: 新增非 AI 折舊：Other Bets（年限 life_na） | B37: US$B | F37: =$F$33/life_na*IF(0=0,phi_0,IF(0<life_na,1,IF(0=life_na,1-phi_0,0))) -> 0.001125 | G37: =F37 -> 0.001125 | H37: =$F$33/life_na*IF(1=0,phi_0,IF(1<life_na,1,IF(1=life_na,1-phi_0,0)))+$H$33/life_na*IF(0=0,phi_0,IF(0<life_na,1,IF(0=life_na,1-phi_0,0))) -> 0.0069 | I37: =$F$33/life_na*IF(2=0,phi_0,IF(2<life_na,1,IF(2=life_na,1-phi_0,0)))+$H$33/life_na*IF(1=0,phi_0,IF(1<life_na,1,IF(1=life_na,1-phi_0,0)))+$I$33/life_na*IF(0=0,phi_0,IF(0<life_na,1,IF(0=life_na,1-phi_0,0))) -> 0.0168 | J37: =$F$33/life_na*IF(3=0,phi_0,IF(3<life_na,1,IF(3=life_na,1-phi_0,0)))+$H$33/life_na*IF(2=0,phi_0,IF(2<life_na,1,IF(2=life_na,1-phi_0,0)))+$I$33/life_na*IF(1=0,phi_0,IF(1<life_na,1,IF(1=life_na,1-phi_0,0)))+$J$33/life_na*IF(0=0,phi_0,IF(0<life_na,1,IF(0=life_na,1-phi_0,0))) -> 0.0279 | K37: =$F$33/life_na*IF(4=0,phi_0,IF(4<life_na,1,IF(4=life_na,1-phi_0,0)))+$H$33/life_na*IF(3=0,phi_0,IF(3<life_na,1,IF(3=life_na,1-phi_0,0)))+$I$33/life_na*IF(2=0,phi_0,IF(2<life_na,1,IF(2=life_na,1-phi_0,0)))+$J$33/life_na*IF(1=0,phi_0,IF(1<life_na,1,IF(1=life_na,1-phi_0,0)))+$K$33/life_na*IF(0=0,phi_0,IF(0<life_na,1,IF(0=life_na,1-phi_0,0))) -> 0.0402 | L37: =$F$33/life_na*IF(5=0,phi_0,IF(5<life_na,1,IF(5=life_na,1-phi_0,0)))+$H$33/life_na*IF(4=0,phi_0,IF(4<life_na,1,IF(4=life_na,1-phi_0,0)))+$I$33/life_na*IF(3=0,phi_0,IF(3<life_na,1,IF(3=life_na,1-phi_0,0)))+$J$33/life_na*IF(2=0,phi_0,IF(2<life_na,1,IF(2=life_na,1-phi_0,0)))+$K$33/life_na*IF(1=0,phi_0,IF(1<life_na,1,IF(1=life_na,1-phi_0,0)))+$L$33/life_na*IF(0=0,phi_0,IF(0<life_na,1,IF(0=life_na,1-phi_0,0))) -> 0.0537 | M37: =$F$33/life_na*IF(6=0,phi_0,IF(6<life_na,1,IF(6=life_na,1-phi_0,0)))+$H$33/life_na*IF(5=0,phi_0,IF(5<life_na,1,IF(5=life_na,1-phi_0,0)))+$I$33/life_na*IF(4=0,phi_0,IF(4<life_na,1,IF(4=life_na,1-phi_0,0)))+$J$33/life_na*IF(3=0,phi_0,IF(3<life_na,1,IF(3=life_na,1-phi_0,0)))+$K$33/life_na*IF(2=0,phi_0,IF(2<life_na,1,IF(2=life_na,1-phi_0,0)))+$L$33/life_na*IF(1=0,phi_0,IF(1<life_na,1,IF(1=life_na,1-phi_0,0)))+$M$33/life_na*IF(0=0,phi_0,IF(0<life_na,1,IF(0=life_na,1-phi_0,0))) -> 0.0684
A38: 新增非 AI 折舊合計 | B38: US$B | F38: =F35+F36+F37 -> 0.52798 | G38: =G35+G36+G37 -> 0.52798 | H38: =H35+H36+H37 -> 3.3297443 | I38: =I35+I36+I37 -> 8.443564 | J38: =J35+J36+J37 -> 14.501884 | K38: =K35+K36+K37 -> 21.36841 | L38: =L35+L36+L37 -> 28.853352 | M38: =M35+M36+M37 -> 36.934993
A40: 情境 B（近四季成長收斂；基準）
A41: 項目 | B41: 單位 | C41: FY2024A | D41: FY2025A | E41: 1H26A | F41: 2H26E | G41: FY2026E | H41: FY2027E | I41: FY2028E | J41: FY2029E | K41: FY2030E | L41: FY2031E | M41: FY2032E | N41: 說明
A42: Search B 路徑年增 | B42: % | F42: =g0_search -> 0.16801321 | H42: =g0_search+(gl_search-g0_search)*MIN(1,(2027-2026)/conv_n) -> 0.14600991 | I42: =g0_search+(gl_search-g0_search)*MIN(1,(2028-2026)/conv_n) -> 0.12400661 | J42: =g0_search+(gl_search-g0_search)*MIN(1,(2029-2026)/conv_n) -> 0.1020033 | K42: =g0_search+(gl_search-g0_search)*MIN(1,(2030-2026)/conv_n) -> 0.08 | L42: =g0_search+(gl_search-g0_search)*MIN(1,(2031-2026)/conv_n) -> 0.08 | M42: =g0_search+(gl_search-g0_search)*MIN(1,(2032-2026)/conv_n) -> 0.08 | N42: 2H26 年增＝近四季 +16.8%（Q 頁），FY2030 收斂到 gl_search
...

Sheet PL
A1: PL — 分部營收 → 分部營業利益 → 合併營業利益 → 業外 → 稅 → 淨利 → EPS（三情境；US$B，EPS 美元）。實績欄（FY2024A、FY2025A、1H26A）取自 Q 頁；FY2026E＝1H 實績＋2H 模型
A2: 分部營業利益＝分部 EBITDA − 分攤折舊。分部 EBITDA：Google Services＝B 路徑營收 × 近四季 EBITDA 率＋Search 情境差額 × 增量 EBITDA 率 − 自用 AI 增量營運成本 × svc_sh；Google Cloud＝Cloud AI EBITDA（Thesis）＋TPU × tpu_m＋Cloud 其他 × m_co。折舊＝評價日在役資產基礎折舊（按近四季營收分攤）＋新增 AI 折舊（對外→Cloud、自用→Services／Alphabet 層級）＋新增非 AI 折舊。持股評價損益預測期設 0
A4: 分部對帳彙總（三情境 × 全部年度取絕對值最大者；實績欄同列）
A5: 項目 | B5: 單位 | C5: FY2024A | D5: FY2025A | E5: 1H26A | F5: 2H26E | G5: FY2026E | H5: FY2027E | I5: FY2028E | J5: FY2029E | K5: FY2030E | L5: FY2031E | M5: FY2032E | N5: 說明
A6: 檢查：產品線合計 − Google Services | B6: US$B | C6: =MAX(ABS(C26),ABS(C85),ABS(C144)) -> 0 | D6: =MAX(ABS(D26),ABS(D85),ABS(D144)) -> 0 | E6: =MAX(ABS(E26),ABS(E85),ABS(E144)) -> 0 | F6: =MAX(ABS(F26),ABS(F85),ABS(F144)) -> 0 | G6: =MAX(ABS(G26),ABS(G85),ABS(G144)) -> 0 | H6: =MAX(ABS(H26),ABS(H85),ABS(H144)) -> 0 | I6: =MAX(ABS(I26),ABS(I85),ABS(I144)) -> 0 | J6: =MAX(ABS(J26),ABS(J85),ABS(J144)) -> 0 | ... M6: =MAX(ABS(M26),ABS(M85),ABS(M144)) -> 0 | N6: 三情境各區塊同名核對列的最大絕對值；必須為 0（tools/segment_check 讀本列）
A7: 檢查：Cloud 子列合計 − Google Cloud | B7: US$B | E7: =MAX(ABS(E27),ABS(E86),ABS(E145)) -> 0 | F7: =MAX(ABS(F27),ABS(F86),ABS(F145)) -> 0 | G7: =MAX(ABS(G27),ABS(G86),ABS(G145)) -> 0 | H7: =MAX(ABS(H27),ABS(H86),ABS(H145)) -> 0 | I7: =MAX(ABS(I27),ABS(I86),ABS(I145)) -> 0 | J7: =MAX(ABS(J27),ABS(J86),ABS(J145)) -> 0 | K7: =MAX(ABS(K27),ABS(K86),ABS(K145)) -> 0 | L7: =MAX(ABS(L27),ABS(L86),ABS(L145)) -> 0 | M7: =MAX(ABS(M27),ABS(M86),ABS(M145)) -> 0 | N7: 三情境各區塊同名核對列的最大絕對值；必須為 0（tools/segment_check 讀本列）
A8: 檢查：分部合計＋避險 − 合併營收 | B8: US$B | C8: =MAX(ABS(C28),ABS(C87),ABS(C146)) -> 0 | D8: =MAX(ABS(D28),ABS(D87),ABS(D146)) -> 0 | E8: =MAX(ABS(E28),ABS(E87),ABS(E146)) -> 0 | F8: =MAX(ABS(F28),ABS(F87),ABS(F146)) -> 0 | G8: =MAX(ABS(G28),ABS(G87),ABS(G146)) -> 0 | H8: =MAX(ABS(H28),ABS(H87),ABS(H146)) -> 0 | I8: =MAX(ABS(I28),ABS(I87),ABS(I146)) -> 0 | J8: =MAX(ABS(J28),ABS(J87),ABS(J146)) -> 0 | ... M8: =MAX(ABS(M28),ABS(M87),ABS(M146)) -> 0 | N8: 三情境各區塊同名核對列的最大絕對值；必須為 0（tools/segment_check 讀本列）
A9: 檢查：分部營業利益合計 − 合併營業利益 | B9: US$B | C9: =MAX(ABS(C47),ABS(C106),ABS(C165)) -> 0 | D9: =MAX(ABS(D47),ABS(D106),ABS(D165)) -> 0 | E9: =MAX(ABS(E47),ABS(E106),ABS(E165)) -> 0 | F9: =MAX(ABS(F47),ABS(F106),ABS(F165)) -> 0 | G9: =MAX(ABS(G47),ABS(G106),ABS(G165)) -> 0 | H9: =MAX(ABS(H47),ABS(H106),ABS(H165)) -> 0 | I9: =MAX(ABS(I47),ABS(I106),ABS(I165)) -> 0 | J9: =MAX(ABS(J47),ABS(J106),ABS(J165)) -> 0 | ... M9: =MAX(ABS(M47),ABS(M106),ABS(M165)) -> 0 | N9: 三情境各區塊同名核對列的最大絕對值；必須為 0（tools/segment_check 讀本列）
A11: 情境 A（AI 搜尋擴大變現）
A12: 項目 | B12: 單位 | C12: FY2024A | D12: FY2025A | E12: 1H26A | F12: 2H26E | G12: FY2026E | H12: FY2027E | I12: FY2028E | J12: FY2029E | K12: FY2030E | L12: FY2031E | M12: FY2032E | N12: 說明
A13: Google Search & other | B13: US$B | C13: =Seg!C11 -> 198.084 | D13: =Seg!D11 -> 224.532 | E13: =Seg!E11 -> 123.67 | F13: =Seg!F11 -> 139.7411 | G13: =Seg!G11 -> 263.4111 | H13: =Seg!H11 -> 313.28626 | I13: =Seg!I11 -> 365.17789 | J13: =Seg!J11 -> 417.03334 | ... M13: =Seg!M11 -> 544.03577
A14: YouTube ads | B14: US$B | C14: =Seg!C13 -> 36.147 | D14: =Seg!D13 -> 40.367 | E14: =Seg!E13 -> 20.938 | F14: =Seg!F13 -> 24.179364 | G14: =Seg!G13 -> 45.117364 | H14: =Seg!H13 -> 49.983474 | I14: =Seg!I13 -> 54.910329 | J14: =Seg!J13 -> 59.812989 | ... M14: =Seg!M13 -> 75.347139
A15: Google Network | B15: US$B | C15: =Seg!C15 -> 30.359 | D15: =Seg!D15 -> 29.792 | E15: =Seg!E15 -> 14.274 | F15: =Seg!F15 -> 14.851255 | G15: =Seg!G15 -> 29.125255 | H15: =Seg!H15 -> 28.649377 | I15: =Seg!I15 -> 28.337309 | J15: =Seg!J15 -> 28.182975 | ... M15: =Seg!M15 -> 28.182975
A16: Google subscriptions, platforms, and devices | B16: US$B | C16: =Seg!C17 -> 40.34 | D16: =Seg!D17 -> 48.03 | E16: =Seg!E17 -> 25.295 | F16: =Seg!F17 -> 31.193701 | G16: =Seg!G17 -> 56.488701 | H16: =Seg!H17 -> 65.502963 | I16: =Seg!I17 -> 74.654879 | J16: =Seg!J17 -> 83.602922 | ... M16: =Seg!M17 -> 111.27549
A17: Google Services | B17: US$B | C17: =Seg!C18 -> 304.93 | D17: =Seg!D18 -> 342.721 | E17: =Seg!E18 -> 184.177 | F17: =Seg!F18 -> 209.96542 | G17: =Seg!G18 -> 394.14242 | H17: =Seg!H18 -> 457.42207 | I17: =Seg!I18 -> 523.08041 | J17: =Seg!J18 -> 588.63222 | ... M17: =Seg!M18 -> 758.84137
A18: Cloud AI（命題子列） | B18: US$B | E18: =Seg!E19 -> 9.7583729 | F18: =Seg!F19 -> 13.072238 | G18: =Seg!G19 -> 22.830611 | H18: =Seg!H19 -> 38.882858 | I18: =Seg!I19 -> 56.703559 | J18: =Seg!J19 -> 73.012119 | K18: =Seg!K19 -> 85.400179 | L18: =Seg!L19 -> 94.03926 | M18: =Seg!M19 -> 99.017013
A19: TPU 系統銷售（命題子列） | B19: US$B | E19: =Seg!E20 -> 0 | F19: =Seg!F20 -> 1 | G19: =Seg!G20 -> 1 | H19: =Seg!H20 -> 13 | I19: =Seg!I20 -> 13 | J19: =Seg!J20 -> 13 | K19: =Seg!K20 -> 13 | L19: =Seg!L20 -> 13 | M19: =Seg!M20 -> 13
A20: Cloud 其他（命題子列） | B20: US$B | E20: =Seg!E22 -> 35.037627 | F20: =Seg!F22 -> 42.381373 | G20: =Seg!G22 -> 77.419 | H20: =Seg!H22 -> 105.85824 | I20: =Seg!I22 -> 134.60523 | J20: =Seg!J22 -> 158.26622 | K20: =Seg!K22 -> 170.92752 | L20: =Seg!L22 -> 184.60172 | M20: =Seg!M22 -> 199.36986
A21: Google Cloud | B21: US$B | C21: =Seg!C23 -> 43.229 | D21: =Seg!D23 -> 58.705 | E21: =Seg!E23 -> 44.796 | F21: =Seg!F23 -> 56.453611 | G21: =Seg!G23 -> 101.24961 | H21: =Seg!H23 -> 157.7411 | I21: =Seg!I23 -> 204.30879 | J21: =Seg!J23 -> 244.27834 | ... M21: =Seg!M23 -> 311.38687
A22: Other Bets | B22: US$B | C22: =Seg!C24 -> 1.648 | D22: =Seg!D24 -> 1.537 | E22: =Seg!E24 -> 0.793 | F22: =Seg!F24 -> 0.75 | G22: =Seg!G24 -> 1.543 | H22: =Seg!H24 -> 1.6 | I22: =Seg!I24 -> 1.8 | J22: =Seg!J24 -> 2 | ... M22: =Seg!M24 -> 2.6
A23: Hedging gains (losses) | B23: US$B | C23: =Seg!C25 -> 0.211 | D23: =Seg!D25 -> -0.127 | E23: =Seg!E25 -> -0.074 | F23: =Seg!F25 -> 0 | G23: =Seg!G25 -> -0.074 | H23: =Seg!H25 -> 0 | I23: =Seg!I25 -> 0 | J23: =Seg!J25 -> 0 | ... M23: =Seg!M25 -> 0
