Workbook

Sheet 導覽
A1: Alphabet 收支與評價模型 — Excel 版 v0.2（更新 2026-10-09；與 HTML v0.2 同步；市價截至 2026-10-07 收盤）
A3: 這個活頁簿在回答什麼
A4: 一句話：AI 資本支出有沒有賺到資金成本：每 MW 收入能否覆蓋每 MW 全成本——Alphabet 用客戶預付款支應多少擴張資本支出，剩下的缺口要靠多少債務與新股。
A5: 所有分頁用同一組數字，改任何一個輸入，後面全部會跟著動。
A7: 分頁結構（依模組分組，分頁標籤顏色相同者為同一模組）
A8: 摘要 一頁摘要：結論、與市場共識的差異、現價隱含什麼、驗證點（全部活公式）。
A9: 輸入與假設 所有可調參數（A 情境 → B 產能與收入 → C 利潤率 → D 支出 → E 融資 → F 評價 → G 1H 實際 → H 情境區間運算表 → I 市場共識 → J 季度追蹤輸入）。
A10: 各期收支 類現金流量：來源（含客戶預付）、用途、融資前缺口、期前融資瀑布。
A11: 季度追蹤 焦點季的模型／共識／指引／實際與差距（由年度模型拆分，只用於追蹤；實際數填在輸入與假設 J 區）。
A12: 運營_產能與收入 已連網 MW → 在役 MW → 營收（MW × 每 MW 年收入 × 利用率）；RPO 排程只作對照與產能瓶頸旗標。
A13: 資產負債_既有債務／新債與新股／租賃承諾 類資產負債表：季報債務明細、每期現金與總債務與股數、租賃承諾。
A14: 損益 類損益表（2026＝1H 實際＋下半年模型）。
... A42: DCF 以融資後股數計每股，並加回新股募得現金的現值；EV/EBITDA 用錨定年末淨負債與錨定年末股數。

Sheet 摘要
A1: 一頁摘要 — 結論、與市場的差異、現價隱含什麼、驗證點（全部依輸入連動）
A2: ="模型端＝目前情境：" & CHOOSE(輸入與假設!$C$5,"保守 已交付＋已公開在建","基準 依資本支出指引","積極 依 2027 擴張幅度") & "（預設＝基準）；共識＝data/consensus_googl_20261008.json（2026-10-08）" -> 模型端＝目前情境：基準 依資本支出指引（預設＝基準）；共識＝data/consensus_googl_20261008.json（2026-10-08）
A4: 1｜結論
A5: 結論｜評等代碼（1＝買進、0＝中立、−1＝賣出） | C5: =評價_DCF與目標價!C99 -> -1
A6: 結論｜評等 | C6: =CHOOSE(C5+2,"賣出","中立","買進") -> 賣出
A7: 結論｜點位（加權目標價） | B7: US$ | C7: =評價_DCF與目標價!C51 -> 145.84769
A8: 結論｜現價 | B8: US$ | C8: =輸入與假設!$C$366 -> 350.5
A9: 結論｜空間 | B9: % | C9: =C7/C8-1 -> -0.58388676
A10: 結論｜情境區間（下緣／上緣） | B10: US$ | C10: =評價_DCF與目標價!C104 -> 121.98879 | D10: =評價_DCF與目標價!D104 -> 175.76831
A11: 結論｜方法區間（下緣／上緣） | B11: US$ | C11: =評價_DCF與目標價!C106 -> 143.98668 | D11: =評價_DCF與目標價!D106 -> 145.84769
A12: 結論｜賣出門檻價 | B12: US$ | C12: =評價_DCF與目標價!$C$100 -> 297.925
A13: 結論｜點位 − 賣出門檻 | B13: US$ | C13: =C7-C12 -> -152.07731
A14: 結論｜結論句 | C14: =C6&"：點位 $"&TEXT(C7,"0.0")&"，較現價 $"&TEXT(C8,"0.00")&" "&IF(C9>=0,"高","低")&" "&TEXT(ABS(C9)*100,"0")&"%；情境區間 $"&TEXT(C10,"0.0")&"–$"&TEXT(D10,"0.0")&"，方法區間 $"&TEXT(C11,"0.0")&"–$"&TEXT(D11,"0.0")&"；點位"&IF(C13<0,"低於","高於")&"賣出門檻 $"&TEXT(C12,"0.0")&" 達 $"&TEXT(ABS(C13),"0.0")&"。" -> 賣出：點位 $145.8，較現價 $350.50 低 58%；情境區間 $122.0–$175.8，方法區間 $144.0–$145.8；點位低於賣出門檻 $297.9 達 $152.1。
A15: 結論｜情境判斷句 | C15: =評價_DCF與目標價!C129 -> 情境區間上緣 $175.8 低於現價 $350.50：賣出在三個擴張情境下都成立。
A16: 結論｜投資級句 | C16: =IF(OR(輸入與假設!$C$334="ebitda",輸入與假設!$C$334="leaseAdj"),"需失去投資級才能融資的金額："&IF(SUM(各期收支!C93:G93)>0.05,"$"&TEXT(SUM(各期收支!C93:G93),"0.0")&"bn（五期高息債溢出）","$0")&"；投資級上限＝"&IF(輸入與假設!$C$334="leaseAdj","(總債務＋租賃負債) ≤ "&IF(輸入與假設!$C$335=INT(輸入與假設!$C$335),TEXT(輸入與假設!$C$335,"0"),TEXT(輸入與假設!$C$335,"0.0"))&"×(EBITDA＋租金)","總債務 ≤ "&IF(輸入與假設!$C$335=INT(輸入與假設!$C$335),TEXT(輸入與假設!$C$335,"0"),TEXT(輸入與假設!$C$335,"0.0"))&"× 當期 EBITDA")&"，股權每年 ≤ 現市值 "&IF(ROUND(ABS(輸入與假設!$C$345)*100,4)=INT(ROUND(ABS(輸入與假設!$C$345)*100,4)),TEXT(ROUND(ABS(輸入與假設!$C$345)*100,4),"0"),TEXT(ROUND(ABS(輸入與假設!$C$345)*100,4),"0.0"))&"%"&"。","") -> 需失去投資級才能融資的金額：$0；投資級上限＝(總債務＋租賃負債) ≤ 3×(EBITDA＋租金)，股權每年 ≤ 現市值 5%。
A17: 結論｜調整後槓桿句 | C17: ="調整後槓桿（(債務＋租賃負債) ÷ (EBITDA＋租金)）路徑 "&TEXT(資產負債_新債與新股!C37,"0.0")&"／"&TEXT(資產負債_新債與新股!D37,"0.0")&"／"&TEXT(資產負債_新債與新股!E37,"0.0")&"／"&TEXT(資產負債_新債與新股!F37,"0.0")&"／"&TEXT(資產負債_新債與新股!G37,"0.0")&"×；上限 "&IF(輸入與假設!$C$335=INT(輸入與假設!$C$335),TEXT(輸入與假設!$C$335,"0"),TEXT(輸入與假設!$C$335,"0.0"))&"×，"&IF(MAX(資產負債_新債與新股!$C$37:$G$37)>輸入與假設!$C$335+0.000000001,CHOOSE(MATCH(MAX(資產負債_新債與新股!$C$37:$G$37),資產負債_新債與新股!$C$37:$G$37,0),"2026","2027","2028","2029","2030")&" 超過 "&TEXT(MAX(資產負債_新債與新股!$C$37:$G$37)-輸入與假設!$C$335,"0.0")&"×：需股權或失去投資級。","最小空間 "&TEXT(輸入與假設!$C$335-MAX(資產負債_新債與新股!$C$37:$G$37),"0.0")&"×（"&CHOOSE(MATCH(MAX(資產負債_新債與新股!$C$37:$G$37),資產負債_新債與新股!$C$37:$G$37,0),"2026","2027","2028","2029","2030")&"）。") -> 調整後槓桿（(債務＋租賃負債) ÷ (EBITDA＋租金)）路徑 0.6／0.6／0.5／0.5／0.7×；上限 3×，最小空間 2.3×（2030）。
A18: 結論｜評價口徑敏感度句 | C18: ="評價口徑敏感度："&"WACC 9% $"&TEXT(評價_DCF與目標價!C114,"0.00")&"（"&CHOOSE(評價_DCF與目標價!D114+2,"賣出","中立","買進")&"）"&"、"&"WACC 10% $"&TEXT(評價_DCF與目標價!C115,"0.00")&"（"&CHOOSE(評價_DCF與目標價!D115+2,"賣出","中立","買進")&"）"&"、"&"WACC 11% $"&TEXT(評價_DCF與目標價!C116,"0.00")&"（"&CHOOSE(評價_DCF與目標價!D116+2,"賣出","中立","買進")&"）"&"；"&"非 AI 分部改用公司自身 NTM EV/EBITDA 14.68× $"&TEXT(評價_DCF與目標價!C119,"0.00")&"（"&CHOOSE(評價_DCF與目標價!D119+2,"賣出","中立","買進")&"）"&"、"&"AI 雲端 15× $"&TEXT(評價_DCF與目標價!C120,"0.00")&"（"&CHOOSE(評價_DCF與目標價!D120+2,"賣出","中立","買進")&"）"&"、"&"組合：WACC 9%＋非 AI 自身倍數＋AI 15× $"&TEXT(評價_DCF與目標價!C121,"0.00")&"（"&CHOOSE(評價_DCF與目標價!D121+2,"賣出","中立","買進")&"）"&"；評等翻轉點："&"WACC 約 "&TEXT(評價_DCF與目標價!C122*100,"0.0")&"%（ERP "&TEXT(評價_DCF與目標價!D122*100,"0.00")&"%）以下由「賣出」轉為「中立」"&"。" -> 評價口徑敏感度：WACC 9% $177.51（賣出）、WACC 10% $162.81（賣出）、WACC 11% $151.39（賣出）；非 AI 分部改用公司自身 NTM EV/EBITDA 14.68× $180.99（賣出）、AI 雲端 15× $161.17（賣出）、組合：WACC 9%＋非 AI 自身倍數＋AI 15× $232.52（賣出）；評等翻轉點：WACC 約 5.7%（ERP 0.29%）以下由「賣出」轉為「中立」。
A19: 結論｜終值占比規則句 | C19: ="評等規則：買進須空間 ≥ +"&IF(ROUND(ABS(輸入與假設!$C$457)*100,4)=INT(ROUND(ABS(輸入與假設!$C$457)*100,4)),TEXT(ROUND(ABS(輸入與假設!$C$457)*100,4),"0"),TEXT(ROUND(ABS(輸入與假設!$C$457)*100,4),"0.0"))&"%"&" 且終值占 EV < "&IF(ROUND(ABS(輸入與假設!$C$458)*100,4)=INT(ROUND(ABS(輸入與假設!$C$458)*100,4)),TEXT(ROUND(ABS(輸入與假設!$C$458)*100,4),"0"),TEXT(ROUND(ABS(輸入與假設!$C$458)*100,4),"0.0"))&"%"&"；目前終值占 EV "&TEXT(評價_DCF與目標價!C97*100,"0")&"%"&IF(評價_DCF與目標價!C97>=輸入與假設!$C$458,"，此規則下只可能「賣出」或「中立」","")&"（規則是否修改待 Andy 決定）。" -> 評等規則：買進須空間 ≥ +25% 且終值占 EV < 90%；目前終值占 EV 116%，此規則下只可能「賣出」或「中立」（規則是否修改待 Andy 決定）。
A20: 結論｜兩種讀法句 | C20: ="兩種讀法（自用 AI）：讀法 1（影子收入不進評價）$"&TEXT(評價_DCF與目標價!C51,"0.00")&"；讀法 2（自用 AI 價值中性：自用 MW 以 k＝1 計影子收入並進評價）$"&TEXT(評價_DCF與目標價!C73,"0.00")&"；差額 "&IF(評價_DCF與目標價!C73-評價_DCF與目標價!C51<0,"−","+")&"$"&TEXT(ABS(評價_DCF與目標價!C73-評價_DCF與目標價!C51),"0.00")&"。主值取哪一個是 Andy 的判斷（待決）。" -> 兩種讀法（自用 AI）：讀法 1（影子收入不進評價）$145.85；讀法 2（自用 AI 價值中性：自用 MW 以 k＝1 計影子收入並進評價）$218.47；差額 +$72.62。主值取哪一個是 Andy 的判斷（待決）。
A21: 結論｜對外比例句 | C21: ="對外比例無揭露（目前 "&TEXT(輸入與假設!$C$263*100,"0")&"%，[Assumed]），是最大不確定："&TEXT(評價_DCF與目標價!C112*100,"0")&"% → $"&TEXT(評價_DCF與目標價!D112,"0.00")&"、"&TEXT(評價_DCF與目標價!C113*100,"0")&"% → $"&TEXT(評價_DCF與目標價!D113,"0.00")&"（基準 $"&TEXT(評價_DCF與目標價!C51,"0.00")&"）。" -> 對外比例無揭露（目前 30%，[Assumed]），是最大不確定：10% → $99.72、50% → $179.43（基準 $145.85）。
A22: 結論｜主命題句 | C22: ="主命題（AI 資本支出有沒有賺到資金成本）：2029 對外 AI ROIC "&TEXT(AI增量報酬!F23*100,"0.0")&"% vs WACC "&TEXT(輸入與假設!$C$393*100,"0.0")&"%（"&IF(AI增量報酬!F25<0,"−","+")&TEXT(ABS(AI增量報酬!F25)*100,"0.0")&"pt）；打平 k "&TEXT(AI增量報酬!C29,"0.00")&"（目前 "&TEXT(輸入與假設!$C$58,"0.00")&"）；全 AI（含影子收入）"&TEXT(AI增量報酬!F27*100,"0.0")&"%。" -> 主命題（AI 資本支出有沒有賺到資金成本）：2029 對外 AI ROIC 12.7% vs WACC 11.6%（+1.1pt）；打平 k 1.12（目前 1.15）；全 AI（含影子收入）12.7%。
A23: 結論｜股東回饋與 FCF 句 | C23: ="股東回饋與 FCF：FCF "&IF(各期收支!C44<0,"首次為負 2026（−$"&TEXT(-各期收支!C44,"0.0")&"bn）",IF(各期收支!D44<0,"首次為負 2027（−$"&TEXT(-各期收支!D44,"0.0")&"bn）",IF(各期收支!E44<0,"首次為負 2028（−$"&TEXT(-各期收支!E44,"0.0")&"bn）",IF(各期收支!F44<0,"首次為負 2029（−$"&TEXT(-各期收支!F44,"0.0")&"bn）",IF(各期收支!G44<0,"首次為負 2030（−$"&TEXT(-各期收支!G44,"0.0")&"bn）","五期皆為正")))))&"；"&IF(SUM(各期收支!C75:G75)<=0.05,"無回購計畫（減少回購步驟不適用）",IF(SUM(各期收支!C77:G77)>0,"回購被迫減少："&MID(IF(各期收支!C77>0.05,"、2026 $"&TEXT(各期收支!C77,"0.0"),"")&IF(各期收支!D77>0.05,"、2027 $"&TEXT(各期收支!D77,"0.0"),"")&IF(各期收支!E77>0.05,"、2028 $"&TEXT(各期收支!E77,"0.0"),"")&IF(各期收支!F77>0.05,"、2029 $"&TEXT(各期收支!F77,"0.0"),"")&IF(各期收支!G77>0.05,"、2030 $"&TEXT(各期收支!G77,"0.0"),""),2,999)&"bn","回購未被迫減少"))&"；五期新債 $"&TEXT(SUM(各期收支!C86:G86)+SUM(各期收支!C93:G93),"0.0")&"bn、股權 $"&TEXT(SUM(各期收支!C92:G92),"0.0")&"bn。" -> 股東回饋與 FCF：FCF 首次為負 2026（−$4.2bn）；回購被迫減少：2030 $17.0bn；五期新債 $85.8bn、股權 $0.0bn。
A24: 結論｜延誤句 | C24: =IF(運營_產能與收入!$C$50>0,"建設延誤 "&IF(運營_產能與收入!$C$50=INT(運營_產能與收入!$C$50),TEXT(運營_產能與收入!$C$50,"0"),TEXT(運營_產能與收入!$C$50,"0.0"))&" 個月（GPU 資本支出照原時程）：閒置資本（已支出、尚未產生收入）峰值 $"&TEXT(MAX(運營_產能與收入!$C$55:$G$55),"0.0")&"bn（"&CHOOSE(MATCH(MAX(運營_產能與收入!$C$55:$G$55),運營_產能與收入!$C$55:$G$55,0),"2026","2027","2028","2029","2030")&" 末）。","建設延誤：本情境 0 個月（無閒置資本）。") -> 建設延誤：本情境 0 個月（無閒置資本）。
A26: 2｜與市場的差異（模型：目前情境 vs 共識；2026–2028）
A27: 項目 | B27: 單位 | C27: 2026 | D27: 2027 | E27: 2028
A28: 差異｜營收｜模型 | B28: US$bn | C28: =損益!C29 -> 492.26831 | D28: =損益!D29 -> 599.07596 | E28: =損益!E29 -> 695.23465
A29: 差異｜營收｜共識 | B29: US$bn | C29: =輸入與假設!$C$516 -> 498.69 | D29: =輸入與假設!$D$516 -> 615.038 | E29: =輸入與假設!$E$516 -> 734.199
A30: 差異｜營收｜差距 | B30: % | C30: =C28/C29-1 -> -0.012877118 | D30: =D28/D29-1 -> -0.025952941 | E30: =E28/E29-1 -> -0.053070554
A31: 差異｜調整後 EBITDA｜模型 | B31: US$bn | C31: =輸入與假設!$C$486+損益!C22 -> 194.47928 | D31: =損益!D34 -> 220.64084 | E31: =損益!E34 -> 256.85321
A32: 差異｜調整後 EBITDA｜共識 | B32: US$bn | C32: =輸入與假設!$C$517 -> 233.431 | D32: =輸入與假設!$D$517 -> 298.668 | E32: =輸入與假設!$E$517 -> 382.826
A33: 差異｜調整後 EBITDA｜差距 | B33: % | C33: =C31/C32-1 -> -0.16686611 | D33: =D31/D32-1 -> -0.26125048 | E33: =E31/E32-1 -> -0.32906018 | I33: 2026 模型＝1H 實際調整後 EBITDA（輸入與假設 G 區，報導轉述 [Verified]）＋2H 模型
A34: 差異｜調整後 EBITDA｜差距（金額） | B34: US$bn | C34: =C31-C32 -> -38.951723 | D34: =D31-D32 -> -78.027158 | E34: =E31-E32 -> -125.97279 | I34: 與 HTML 一頁摘要、市場共識分頁同一呈現；判斷門檻仍用上一列比例
A35: 差異｜EBITDA 率｜模型 | B35: % | C35: =C31/C28 -> 0.39506764 | D35: =D31/D28 -> 0.36830195 | E35: =E31/E28 -> 0.36944823
A36: 差異｜EBITDA 率｜共識 | B36: % | C36: =輸入與假設!$C$518 -> 0.46808839 | D36: =輸入與假設!$D$518 -> 0.48560902 | E36: =輸入與假設!$E$518 -> 0.52141994
A37: 差異｜EBITDA 率｜差距（百分點） | B37: pt | C37: =C35-C36 -> -0.073020756 | D37: =D35-D36 -> -0.11730707 | E37: =E35-E36 -> -0.15197172 | I37: EBITDA 率以百分點列差距，不納入判斷
A38: 差異｜CapEx（毛額）｜模型 | B38: US$bn | C38: =輸入與假設!$C$469+輸入與假設!C$323 -> 200.00479 | D38: =輸入與假設!D$323 -> 236.83502 | E38: =輸入與假設!E$323 -> 256.54578
A39: 差異｜CapEx（毛額）｜共識 | B39: US$bn | C39: =輸入與假設!$C$522 -> 201.748 | D39: =輸入與假設!$D$522 -> 300.979 | E39: =輸入與假設!$E$522 -> 339.451
A40: 差異｜CapEx（毛額）｜差距 | B40: % | C40: =C38/C39-1 -> -0.0086405296 | D40: =D38/D39-1 -> -0.21311778 | E40: =E38/E39-1 -> -0.24423325 | I40: 共識 CapEx 口徑未揭露；2026＝1H 實際毛額＋2H 模型毛額
A41: 差異｜淨負債｜模型 | B41: US$bn | C41: =資產負債_新債與新股!C25 -> -29.037907 | D41: =資產負債_新債與新股!D25 -> 12.149493 | E41: =資產負債_新債與新股!E25 -> 31.968035
A42: 差異｜淨負債｜共識 | B42: US$bn | C42: =輸入與假設!$C$524 -> -131.323 | D42: =輸入與假設!$D$524 -> -79.012 | E42: =輸入與假設!$E$524 -> -56.291
...

Sheet 輸入與假設
A1: 輸入（依類別排序；點左側 ＋／− 展開或收合。藍字可改；黃底為最關鍵假設）
A2: A 情境 → B 產能與收入 → C 利潤率 → D 支出（CapEx／折舊／租賃／JV）→ E 融資 → F 評價 → G 參考：1H26 實際 → H 情境區間運算表 → I 市場共識 → J 季度追蹤輸入。灰底『▸』為明細子區，預設收合
A4: A｜情境與規模（管理層擴張力道）
A5: 情境選擇（1＝保守 已交付＋已公開在建、2＝基準 依資本支出指引、3＝積極 依 2027 擴張幅度） | C5: 2 | D5: =CHOOSE(C5,"保守 已交付＋已公開在建","基準 依資本支出指引","積極 依 2027 擴張幅度") -> 基準 依資本支出指引 | I5: 三情境只改容量軸（對外 AI MW 路徑；世代組合隨新增 MW 改變每 MW 年收入）；價格軸另見 B0（對照表 r1 第 5 節第 1 條）
A6: ▸ 情境路徑明細（已連網 MW、在役比例、表外租金基準）
A7: 已連網 MW 路徑 | B7: 單位 | C7: 2026 | D7: 2027 | E7: 2028 | F7: 2029 | G7: 2030 | I7: 2031 新增 MW
A8: 評價日在役 MW（期初計費，三情境共用） | B8: MW | C8: 1901 | I8: company.json → defaults.billableOpen；來源見 scenarios.mwPath.note（第三方估計，不以營收校準）[Derived／Assumed]
A9: 保守 已交付＋已公開在建｜合約 MW 上限 | B9: MW | C9: 3171 | D9: 3171 | E9: 3171 | F9: 3171 | G9: 3171 | I9: company.json → scenarios.mwPath.contracted
A10: 保守 已交付＋已公開在建｜併網速度 | B10: MW／年 | C10: 850 | I10: company.json → scenarios.mwPath.pace
A11: 保守 已交付＋已公開在建 | B11: MW | C11: =MIN(C9,輸入與假設!$C$8+輸入與假設!$C$10*C$34) -> 2326 | D11: =MIN(D9,C11+輸入與假設!$C$10*D$34) -> 3171 | E11: =MIN(E9,D11+輸入與假設!$C$10*E$34) -> 3171 | F11: =MIN(F9,E11+輸入與假設!$C$10*F$34) -> 3171 | G11: =MIN(G9,F11+輸入與假設!$C$10*G$34) -> 3171 | I11: 0 | J11: 對外 AI MW-IT 只加已公開在建：Anthropic 於 Google Cloud 的 TPU 由約 0.77 GW 擴到 1.54 GW（anthropic/ 模型供給路徑）＋Google–Blackstone TPU 合資 0.5 GW（2027）＝+1,270，每年 +850、上限 3,171 [Derived／Interested-party]；I 欄＝2031 新增 MW
A12: 基準 依資本支出指引｜合約 MW 上限 | B12: MW | C12: 99999 | D12: 99999 | E12: 99999 | F12: 99999 | G12: 99999 | I12: company.json → scenarios.mwPath.contracted
A13: 基準 依資本支出指引｜併網速度 | B13: MW／年 | C13: 1246.1 | I13: company.json → scenarios.mwPath.pace
A14: 基準 依資本支出指引 | B14: MW | C14: =MIN(C12,輸入與假設!$C$8+輸入與假設!$C$13*C$34) -> 2524.05 | D14: =MIN(D12,C14+輸入與假設!$C$13*D$34) -> 3770.15 | E14: =MIN(E12,D14+輸入與假設!$C$13*E$34) -> 5016.25 | F14: =MIN(F12,E14+輸入與假設!$C$13*F$34) -> 6262.35 | G14: =MIN(G12,F14+輸入與假設!$C$13*G$34) -> 7508.45 | I14: 1246.1 | J14: 對外 AI MW 新增速度＝近端資本支出隱含的建置量：2026 全年指引中點 $200bn −（非 AI 公式值＋GPU 汰換）÷ 每 MW 全成本（Tokenomics IT＋自建 85% × 設施）× 對外 30%，依 λ 遞延上線（scripts/calib_pace.js 解，對帳落差＝0）；之後各年資本支出＝MW 路徑 × 每 MW 成本（同一套數字）[Derived]；I 欄＝2031 新增 MW
A15: 積極 依 2027 擴張幅度｜合約 MW 上限 | B15: MW | C15: 99999 | D15: 99999 | E15: 99999 | F15: 99999 | G15: 99999 | I15: company.json → scenarios.mwPath.contracted
A16: 積極 依 2027 擴張幅度｜併網速度 | B16: MW／年 | C16: 1869.1 | I16: company.json → scenarios.mwPath.pace
A17: 積極 依 2027 擴張幅度 | B17: MW | C17: =MIN(C15,輸入與假設!$C$8+輸入與假設!$C$16*C$34) -> 2835.55 | D17: =MIN(D15,C17+輸入與假設!$C$16*D$34) -> 4704.65 | E17: =MIN(E15,D17+輸入與假設!$C$16*E$34) -> 6573.75 | F17: =MIN(F15,E17+輸入與假設!$C$16*F$34) -> 8442.85 | G17: =MIN(G15,F17+輸入與假設!$C$16*G$34) -> 10311.95 | I17: 1869.1 | J17: 公司無 MW／GW 目標（只有「serving 容量每 6 個月倍增」的內部說法）→ 以 2027 擴張幅度代替：共識資本支出 2027 ÷ 2026＝1.49、Morgan Stanley TPU 產量 2027 ÷ 2026＝1.56，取 1.5 × 基準速度 [Derived；共識與賣方為 Interested-party]；I 欄＝2031 新增 MW
A18: 在役／已連網比例 | B18: % | C18: 1 | D18: 1 | E18: 1 | F18: 1 | G18: 1 | I18: 對外 AI MW 依 MW-year 計價：已連網即計費（在役比例 100%）；期初計費 MW＝第三方估計 1,901，不以 Google Cloud 營收校準（Cloud 營收含非 AI 與 Workspace）[Assumed]
A19: 未起租租賃總額（未折現） | B19: US$bn | C19: 85.2 | I19: 季報附註已簽約未起租租賃（company.json → leases.facts.notCommenced）[Interested-party]
A20: 未起租：評價日後第幾季開始起租（0＝首期第一季） | B20: 季 | C20: 0 | I20: company.json → leases.uncommenced.startQ
A21: 未起租：平均分攤起租的季數 | B21: 季 | C21: 22 | I21: company.json → leases.uncommenced.quarters（起租時程見該欄說明）[Assumed]
A22: 未起租：每筆租期 | B22: 年 | C22: 15 | I22: 季報 15–19 年取中點；敏感度 15／19 年見報告 [Assumed]
A23: B｜產能與收入（MW、每 MW 年收入、利用率、信用；RPO 只作對照）
A24: 6/30 RPO | B24: US$bn | C24: 0 | I24: 季報 RPO 519.5（只作對照與債務上限的 backlog）[Interested-party]
A25: 評價日後新增承諾 | B25: US$bn | C25: 0 | I25: 評價日後新簽、尚未進 RPO 的承諾；未揭露，取 0 [Assumed]
A26: 五期認列比例（至 2030 末） | B26: % | C26: 0 | I26: 季報 RPO 桶線性分攤後五期合計 0% [Derived]
A27: RPO 桶權重合計 | B27: % | C27: 0.725 | I27: 下方權重列的合計，用於歸一化
A28: 2025-12-31 主動電力 | B28: MW | C28: 1462 | I28: 2025 年底對外 AI MW-IT 估 1462（Epoch：TPU 2,223＋NVIDIA 730 MW TDP × 1.65 × 30%＝AI 在役 4,873 × 30%，[Derived／Assumed]）
A29: 6/30 Billable MW | B29: MW | C29: =輸入與假設!$C$8 -> 1901 | I29: 季末在役 MW 未揭露 [Derived]
A30: 收入用平均在役 MW（1=是） | C30: 1 | I30: 0＝用期末存量全期化；建議 1
A31: 營收驅動（mw＝MW × 每 MW 年收入；rpo＝RPO 排程） | C31: mw | I31: mw：新產能簽約率固定 100%，營收＝容量上限；RPO 只作對照與產能瓶頸旗標（company.json → defaults.revenueDriver）
A32: 每 MW 年收入倍數（整體） | B32: % | C32: 1 | I32: 反向 DCF 與壓力測試用；預設 100%。以『目標搜尋』調整此格即可反解市價隱含單價
A33: 項目 | B33: 單位 | C33: 2026 | D33: 2027 | E33: 2028 | F33: 2029 | G33: 2030 | I33: 來源／標籤
A34: 模型期長度（年） | C34: 0.5 | D34: 1 | E34: 1 | F34: 1 | G34: 1 | I34: 勿改。由 calendar_q.py 推算；只用於容量上限、電力、維護等年率換算 [Derived]
A35: RPO 桶權重 | B35: % | C35: 0.125 | D35: 0.25 | E35: 0.17 | F35: 0.09 | G35: 0.09 | H35: =SUM(C35:G35) -> 0.725 | I35: 季報 RPO 桶（RPO 519.5B（Cloud 513.9B；24 個月內略多於 50%，其後未分桶）含 Cloud 非 AI 與 Workspace，只作對照（模型排程歸 0：AI 雲端收入＝MW × 每 MW））桶內線性分攤 [Derived]
A36: Accepted MW（期末主動電力） | B36: MW | C36: =CHOOSE(輸入與假設!$C$5,C11,C14,C17) -> 2524.05 | D36: =CHOOSE(輸入與假設!$C$5,D11,D14,D17) -> 3770.15 | E36: =CHOOSE(輸入與假設!$C$5,E11,E14,E17) -> 5016.25 | F36: =CHOOSE(輸入與假設!$C$5,F11,F14,F17) -> 6262.35 | G36: =CHOOSE(輸入與假設!$C$5,G11,G14,G17) -> 7508.45 | I36: ＝依 A 區情境選擇器（已連網 MW-IT）
A37: Billable MW | B37: MW | C37: =ROUND(C36*C18,0) -> 2524 | D37: =ROUND(D36*D18,0) -> 3770 | E37: =ROUND(E36*E18,0) -> 5016 | F37: =ROUND(F36*F18,0) -> 6262 | G37: =ROUND(G36*G18,0) -> 7508 | I37: ＝已連網 × 在役比例（A 區）
A38: 利用率 | B38: % | C38: 1 | D38: 1 | E38: 1 | F38: 1 | G38: 1 | I38: 100%：按 MW-year 計價，收入端不乘 IF_Util（Tokenomics 下游契約第 3 條）
A39: 每 MW 年收入 | B39: US$bn/MW | C39: =C120*輸入與假設!$C$58/1000 -> 0.011500793 | D39: =D120*輸入與假設!$C$58/1000 -> 0.012107214 | E39: =E120*輸入與假設!$C$58/1000 -> 0.012604282 | F39: =F120*輸入與假設!$C$58/1000 -> 0.012903535 | G39: =G120*輸入與假設!$C$58/1000 -> 0.01310346 | I39: ＝加權每 MW 年持有成本 × 採用 k ÷ 1000（B0；Tokenomics × k，不以公司營收反推）
A40: 新產能簽約率 | B40: % | C40: 1 | D40: 1 | E40: 1 | F40: 1 | G40: 1 | I40: MW 驅動：100%（RPO 只作對照）
A41: 客戶違約率 | B41: % | C41: 0 | D41: 0 | E41: 0 | F41: 0 | G41: 0 | I41: 前三大客戶約 59% 營收的定價，非預測 [Assumed]
...

Sheet 各期收支
A1: 支出與資金 — 五層支出、四層來源、現金橋
A2: 2026 欄＝1H 實際（季報現金流量表口徑）＋下半年模型；2027 以後為純模型。瀑布以「融資前現金」決定需求並直接由各支出列加總，因此沒有循環參照
A4: 項目 | B4: 單位 | C4: 2026 | D4: 2027 | E4: 2028 | F4: 2029 | G4: 2030 | I4: 公式／來源說明
A5: 支出（五層）
A6: ① 毛 CapEx（認列，備忘） | B6: US$bn | C6: =輸入與假設!$C$469+輸入與假設!C$323 -> 200.00479 | D6: =輸入與假設!D$323 -> 236.83502 | E6: =輸入與假設!E$323 -> 256.54578 | F6: =輸入與假設!F$323 -> 287.92653 | G6: =輸入與假設!G$323 -> 412.79175 | I6: 2026＝1H 實際認列 80.598＋2H 模型；對照公司全年指引 195–205。備忘列：用途合計採現金口徑，不用這一列
A7: 客戶預付率 | B7: % | C7: =輸入與假設!C$279 -> 0 | D7: =輸入與假設!D$279 -> 0 | E7: =輸入與假設!E$279 -> 0 | F7: =輸入與假設!F$279 -> 0 | G7: =輸入與假設!G$279 -> 0
A8: 客戶預付金額（抵減，2H 起） | B8: US$bn | C8: =輸入與假設!C$299*C7 -> 0 | D8: =輸入與假設!D$299*D7 -> 0 | E8: =輸入與假設!E$299*E7 -> 0 | F8: =輸入與假設!F$299*F7 -> 0 | G8: =輸入與假設!G$299*G7 -> 0 | I8: ＝成長型 CapEx × 預付比率（汰換 CapEx 不計）；1H 的預付已含在實際 CFO 內，不重複計入
A9: 合約負債期初（客戶預付餘額） | B9: US$bn | C9: =輸入與假設!$C$276 -> 0 | D9: =C12 -> 0 | E9: =D12 -> 0 | F9: =E12 -> 0 | G9: =F12 -> 0 | I9: 2026 期初＝6/30 季報遞延營收
A10: 合約負債利息累積（重大財務組成，非現金） | B10: US$bn | C10: =輸入與假設!$C$277*(C9+0.5*C8)*運營_產能與收入!C7 -> 0 | D10: =輸入與假設!$C$277*(D9+0.5*D8)*運營_產能與收入!D7 -> 0 | E10: =輸入與假設!$C$277*(E9+0.5*E8)*運營_產能與收入!E7 -> 0 | F10: =輸入與假設!$C$277*(F9+0.5*F8)*運營_產能與收入!F7 -> 0 | G10: =輸入與假設!$C$277*(G9+0.5*G8)*運營_產能與收入!G7 -> 0 | I10: ＝隱含利率 ×(期初合約負債＋本期預付流入 × ½)× 期間長度；進損益利息、不進現金（v0.1b）
A11: 預付認列（非現金營收） | B11: US$bn | C11: =MIN(C9+C10,(C9+C10)/輸入與假設!$C$275*運營_產能與收入!C7) -> 0 | D11: =MIN(D9+D10,(D9+D10)/輸入與假設!$C$275*運營_產能與收入!D7) -> 0 | E11: =MIN(E9+E10,(E9+E10)/輸入與假設!$C$275*運營_產能與收入!E7) -> 0 | F11: =MIN(F9+F10,(F9+F10)/輸入與假設!$C$275*運營_產能與收入!F7) -> 0 | G11: =MIN(G9+G10,(G9+G10)/輸入與假設!$C$275*運營_產能與收入!G7) -> 0 | I11: ＝(期初合約負債＋累積利息) ÷ 認列年數 × 期間長度；這部分營收已在預付時收現，自營運來源扣除
A12: 合約負債期末 | B12: US$bn | C12: =C9+C8+C10-C11 -> 0 | D12: =D9+D8+D10-D11 -> 0 | E12: =E9+E8+E10-E11 -> 0 | F12: =F9+F8+F10-F11 -> 0 | G12: =G9+G8+G10-G11 -> 0 | I12: ＝期初＋預付流入＋累積利息−認列
A13: ① CapEx（用途用：1H 現金／2H 毛額） | B13: US$bn | C13: =輸入與假設!$C$468+輸入與假設!C$323 -> 200.00479 | D13: =輸入與假設!D$323 -> 236.83502 | E13: =輸入與假設!E$323 -> 256.54578 | F13: =輸入與假設!F$323 -> 287.92653 | G13: =輸入與假設!G$323 -> 412.79175 | I13: 1H 採現金流量表的現金購置 80.598；2H 起採毛額，客戶預付在來源端抵回（避免重複計入）
A14: ② 在帳現金租金（備忘，1H 已含在 CFO） | B14: US$bn | C14: =輸入與假設!C$280 -> 2.042 | D14: =輸入與假設!D$280 -> 3.885 | E14: =輸入與假設!E$280 -> 3.356 | F14: =輸入與假設!F$280 -> 2.932 | G14: =輸入與假設!G$280 -> 2.331 | I14: 見『租賃與承諾』頁；2030 後尚有 9.707。2026 欄僅 2H：1H 租金 2.692 已含在實際 CFO 內
A15: ② 表外現金租金（未起租） | B15: US$bn | C15: =運營_產能與收入!C59 -> 0.19363636 | D15: =運營_產能與收入!D59 -> 1.1618182 | E15: =運營_產能與收入!E59 -> 2.1945455 | F15: =運營_產能與收入!F59 -> 3.2272727 | G15: =運營_產能與收入!G59 -> 4.26 | I15: 已簽約未起租租賃 85.2 的現金路徑
A16: 租金合計 | B16: US$bn | C16: =輸入與假設!C$283+C15*輸入與假設!$C$284 -> 0.23031376 | D16: =輸入與假設!D$283+D15*輸入與假設!$C$284 -> 0.53288254 | E16: =輸入與假設!E$283+E15*輸入與假設!$C$284 -> 0.65255591 | F16: =輸入與假設!F$283+F15*輸入與假設!$C$284 -> 0.76122927 | G16: =輸入與假設!G$283+G15*輸入與假設!$C$284 -> 0.81990264 | I16: ＝在帳融資租賃現金＋未起租 × 融資部分比例（MAG v0.1b：營業租賃已含在分部 EBITDA，不重複扣除；AI 雲端 EBITDA 由 Tokenomics 推得、未扣租金）
A17: ③ 存量債務利息（備忘，1H 已含在 CFO） | B17: US$bn | C17: =輸入與假設!C$363 -> 2.0126826 | D17: =輸入與假設!D$363 -> 3.9650359 | E17: =輸入與假設!E$363 -> 3.8911126 | F17: =輸入與假設!F$363 -> 3.8018253 | G17: =輸入與假設!G$363 -> 3.6218432 | I17: ="6/30 債務餘額的利息。2026 全年利息＝1H 實際 1.811＋2H "&TEXT(C17,"0.0")&"＝"&TEXT(1.811+C17,"0.00")&"（見下方備忘）" -> 6/30 債務餘額的利息。2026 全年利息＝1H 實際 1.811＋2H 2.0＝3.82（見下方備忘）
A18: 期初累積現金 | B18: US$bn | C18: =輸入與假設!$C$466 -> 120.53 | D18: =C56 -> 128.12291 | E18: =D56 -> 85.935507 | F18: =E56 -> 63.440965 | G18: =F56 -> 53.700182 | I18: 2026 自 2025-12-31 起算；之後＝前期期末累積現金
A19: 新債利率 | B19: % | C19: =IF(輸入與假設!$C$356=1,輸入與假設!C$362+MAX(0,輸入與假設!$C$355-450)/100*0.004,輸入與假設!C$362) -> 0.05 | D19: =IF(輸入與假設!$C$356=1,輸入與假設!D$362+MAX(0,輸入與假設!$C$355-450)/100*0.004,輸入與假設!D$362) -> 0.05 | E19: =IF(輸入與假設!$C$356=1,輸入與假設!E$362+MAX(0,輸入與假設!$C$355-450)/100*0.004,輸入與假設!E$362) -> 0.05 | F19: =IF(輸入與假設!$C$356=1,輸入與假設!F$362+MAX(0,輸入與假設!$C$355-450)/100*0.004,輸入與假設!F$362) -> 0.05 | G19: =IF(輸入與假設!$C$356=1,輸入與假設!G$362+MAX(0,輸入與假設!$C$355-450)/100*0.004,輸入與假設!G$362) -> 0.05 | I19: CDS 開關：＋MAX(0,CDS−450)×0.4bp/bp
A20: ③ 新債利息（瀑布） | B20: US$bn | C20: =C94 -> 0 | D20: =D94 -> 0 | E20: =E94 -> 0 | F20: =F94 -> 0 | G20: =G94 -> 4.2903038 | I20: ＝新債利率×期間長度×(期初新債＋本期舉借)；見下方「期前融資瀑布」
A21: 利息合計 | B21: US$bn | C21: =C17+C20 -> 2.0126826 | D21: =D17+D20 -> 3.9650359 | E21: =E17+E20 -> 3.8911126 | F21: =F17+F20 -> 3.8018253 | G21: =G17+G20 -> 7.912147
A22: ④ JV／策略投資出資 | B22: US$bn | C22: =輸入與假設!$C$470+輸入與假設!C$287 -> 57.662222 | D22: =輸入與假設!D$287 -> 4.444444 | E22: =輸入與假設!E$287 -> 4.444444 | F22: =輸入與假設!F$287 -> 4.444444 | G22: =輸入與假設!G$287 -> 4.444444 | I22: 2026＝1H 實際 55.44（JV 0.000＋策略投資 55.440）＋2H 模型。GOOGL 不發股息
A23: ⑧ 股利（普通股＋特別股） | B23: US$bn | C23: =輸入與假設!$C$485+4*輸入與假設!$C$337*(1+輸入與假設!$C$338)^0*運營_產能與收入!C7*(輸入與假設!$C$339+0+SUMPRODUCT(資產負債_既有債務!$D$27:$D$27*資產負債_既有債務!$H$23:$H$23*(資產負債_既有債務!$G$23:$G$23<0)))+輸入與假設!C$360 -> 11.1472 | D23: =4*輸入與假設!$C$337*(1+輸入與假設!$C$338)^1*運營_產能與收入!D7*(輸入與假設!$C$339+C97+SUMPRODUCT(資產負債_既有債務!$D$27:$D$27*資產負債_既有債務!$H$23:$H$23*(資產負債_既有債務!$G$23:$G$23<1)))+輸入與假設!D$360 -> 12.481108 | E23: =4*輸入與假設!$C$337*(1+輸入與假設!$C$338)^2*運營_產能與收入!E7*(輸入與假設!$C$339+D97+SUMPRODUCT(資產負債_既有債務!$D$27:$D$27*資產負債_既有債務!$H$23:$H$23*(資產負債_既有債務!$G$23:$G$23<2)))+輸入與假設!E$360 -> 12.997948 | F23: =4*輸入與假設!$C$337*(1+輸入與假設!$C$338)^3*運營_產能與收入!F7*(輸入與假設!$C$339+E97+SUMPRODUCT(資產負債_既有債務!$D$27:$D$27*資產負債_既有債務!$H$23:$H$23*(資產負債_既有債務!$G$23:$G$23<3)))+輸入與假設!F$360 -> 12.937277 | G23: =4*輸入與假設!$C$337*(1+輸入與假設!$C$338)^4*運營_產能與收入!G7*(輸入與假設!$C$339+F97+SUMPRODUCT(資產負債_既有債務!$D$27:$D$27*資產負債_既有債務!$H$23:$H$23*(資產負債_既有債務!$G$23:$G$23<4)))+輸入與假設!G$360 -> 12.958555 | I23: 普通股＝每股每季 × 4 × 期間長度 ×(基礎股數＋前期累計瀑布新股＋已強制轉換特別股)＋特別股股利；2026＝1H 實際＋2H 模型（v0.1b）
A24: ⑨ 回購（瀑布：現金不足時先減） | B24: US$bn | C24: =輸入與假設!$C$487+C76 -> 8.5015 | D24: =D76 -> 17.003 | E24: =E76 -> 17.003 | F24: =F76 -> 17.003 | G24: =G76 -> 0 | I24: 2026＝1H 實際＋2H 瀑布後實際回購；計畫與被迫減少見下方「期前融資瀑布」（MAG v0.1b）
A25: 電力（overlay） | B25: US$bn | C25: =IF(輸入與假設!$C$253=1,運營_產能與收入!C9*8760*輸入與假設!C$255*輸入與假設!C$254/1000000000*運營_產能與收入!C7,0) -> 0 | D25: =IF(輸入與假設!$C$253=1,運營_產能與收入!D9*8760*輸入與假設!D$255*輸入與假設!D$254/1000000000*運營_產能與收入!D7,0) -> 0 | E25: =IF(輸入與假設!$C$253=1,運營_產能與收入!E9*8760*輸入與假設!E$255*輸入與假設!E$254/1000000000*運營_產能與收入!E7,0) -> 0 | F25: =IF(輸入與假設!$C$253=1,運營_產能與收入!F9*8760*輸入與假設!F$255*輸入與假設!F$254/1000000000*運營_產能與收入!F7,0) -> 0 | G25: =IF(輸入與假設!$C$253=1,運營_產能與收入!G9*8760*輸入與假設!G$255*輸入與假設!G$254/1000000000*運營_產能與收入!G7,0) -> 0 | I25: ＝已連網 MW×8760×PUE×電價÷1e9×期間係數。EBITDA 率已含電費，預設關閉
A26: 維護（overlay） | B26: US$bn | C26: =IF(輸入與假設!$C$253=1,運營_產能與收入!C9*輸入與假設!C$256/1000*運營_產能與收入!C7,0) -> 0 | D26: =IF(輸入與假設!$C$253=1,運營_產能與收入!D9*輸入與假設!D$256/1000*運營_產能與收入!D7,0) -> 0 | E26: =IF(輸入與假設!$C$253=1,運營_產能與收入!E9*輸入與假設!E$256/1000*運營_產能與收入!E7,0) -> 0 | F26: =IF(輸入與假設!$C$253=1,運營_產能與收入!F9*輸入與假設!F$256/1000*運營_產能與收入!F7,0) -> 0 | G26: =IF(輸入與假設!$C$253=1,運營_產能與收入!G9*輸入與假設!G$256/1000*運營_產能與收入!G7,0) -> 0
A27: ⑤ 排程還本（季報到期表） | B27: US$bn | C27: =輸入與假設!$C$472+IF(輸入與假設!$C$332=1,輸入與假設!C$361,0)+資產負債_既有債務!C38 -> 7.253 | D27: =IF(輸入與假設!$C$332=1,輸入與假設!D$361,0)+資產負債_既有債務!D38 -> 1 | E27: =IF(輸入與假設!$C$332=1,輸入與假設!E$361,0)+資產負債_既有債務!E38 -> 2.676 | F27: =IF(輸入與假設!$C$332=1,輸入與假設!F$361,0)+資產負債_既有債務!F38 -> 1.764 | G27: =IF(輸入與假設!$C$332=1,輸入與假設!G$361,0)+資產負債_既有債務!G38 -> 7.186 | I27: 2026＝1H 實際還款 5.253＋2H 到期表 2.0
A28: ⑥ capped call 支出（1H 實際） | B28: US$bn | C28: =輸入與假設!$C$473 -> 1.011 | D28: =0 -> 0 | E28: =0 -> 0 | F28: =0 -> 0 | G28: =0 -> 0 | I28: 可轉債配套 capped call 現金支出（未見揭露，0）
A29: ⑦ 現金稅（2H 起） | B29: US$bn | C29: =輸入與假設!$C$354*MAX(0,運營_產能與收入!C38*輸入與假設!C$250+輸入與假設!C$48+輸入與假設!C$241-輸入與假設!C$242-運營_產能與收入!C62-輸入與假設!C$324-輸入與假設!C$363) -> 12.491842 | D29: =輸入與假設!$C$354*MAX(0,運營_產能與收入!D38*輸入與假設!D$250+輸入與假設!D$48+輸入與假設!D$241-輸入與假設!D$242-運營_產能與收入!D62-輸入與假設!D$324-輸入與假設!D$363) -> 24.385814 | E29: =輸入與假設!$C$354*MAX(0,運營_產能與收入!E38*輸入與假設!E$250+輸入與假設!E$48+輸入與假設!E$241-輸入與假設!E$242-運營_產能與收入!E62-輸入與假設!E$324-輸入與假設!E$363) -> 25.02638 | F29: =輸入與假設!$C$354*MAX(0,運營_產能與收入!F38*輸入與假設!F$250+輸入與假設!F$48+輸入與假設!F$241-輸入與假設!F$242-運營_產能與收入!F62-輸入與假設!F$324-輸入與假設!F$363) -> 25.729302 | G29: =輸入與假設!$C$354*MAX(0,運營_產能與收入!G38*輸入與假設!G$250+輸入與假設!G$48+輸入與假設!G$241-輸入與假設!G$242-運營_產能與收入!G62-輸入與假設!G$324-輸入與假設!G$363) -> 25.420532 | I29: ＝稅率 × MAX(0, 損益 EBITDA − 車隊 D&A − 存量利息)；1H 的稅已含在 CFO 內（v0.1b）
A30: 用途合計（現金口徑） | B30: US$bn | C30: =C13+C16+C21+C22+C25+C26+C27+C28+C29+C23+C24 -> 300.31455 | D30: =D13+D16+D21+D22+D25+D26+D27+D28+D29+D23+D24 -> 300.64731 | E30: =E13+E16+E21+E22+E25+E26+E27+E28+E29+E23+E24 -> 323.23722 | F30: =F13+F16+F21+F22+F25+F26+F27+F28+F29+F23+F24 -> 354.36761 | G30: =G13+G16+G21+G22+G25+G26+G27+G28+G29+G23+G24 -> 471.53333 | I30: 2026 的 1H 部分採季報現金流量表口徑（現金購置、還款、JV、capped call）；1H 的利息與租金已含在 CFO 內，不重複列
A31: 來源（四層）
A32: Ⓐ0 1H26 實際營運現金流（CFO） | B32: US$bn | C32: =輸入與假設!$C$467 -> 84.859 | D32: =0 -> 0 | E32: =0 -> 0 | F32: =0 -> 0 | G32: =0 -> 0 | I32: 季報實際值，取代模型推算；已含 1H 的利息、租金與客戶預付
A33: Ⓐ RPO 現金（2H 起） | B33: US$bn | C33: =運營_產能與收入!C40 -> 0 | D33: =運營_產能與收入!D40 -> 0 | E33: =運營_產能與收入!E40 -> 0 | F33: =運營_產能與收入!F40 -> 0 | G33: =運營_產能與收入!G40 -> 0
A34: Ⓑ 新簽約現金 | B34: US$bn | C34: =運營_產能與收入!C41 -> 10.613757 | D34: =運營_產能與收入!D41 -> 31.964935 | E34: =運營_產能與收入!E41 -> 46.647862 | F34: =運營_產能與收入!F41 -> 61.445159 | G34: =運營_產能與收入!G41 -> 76.299883
A35: Ⓒ 非算力服務現金 | B35: US$bn | C35: =輸入與假設!C$251 -> 0 | D35: =輸入與假設!D$251 -> 0 | E35: =輸入與假設!E$251 -> 0 | F35: =輸入與假設!F$251 -> 0 | G35: =輸入與假設!G$251 -> 0
A36: Ⓒ2 其他事業 EBITDA（2H 起） | B36: US$bn | C36: =輸入與假設!C$48 -> -2.76 | D36: =輸入與假設!D$48 -> -11.04 | E36: =輸入與假設!E$48 -> -11.04 | F36: =輸入與假設!F$48 -> -5.52 | G36: =輸入與假設!G$48 -> 0 | I36: 非核心事業 EBITDA（負值＝燒錢），視為現金（v0.1b）
A37: Ⓒ3 非 AI 事業 EBITDA（2H 起） | B37: US$bn | C37: =輸入與假設!C$241-輸入與假設!C$242 -> 92.57352 | D37: =輸入與假設!D$241-輸入與假設!D$242 -> 199.71591 | E37: =輸入與假設!E$241-輸入與假設!E$242 -> 221.24535 | F37: =輸入與假設!F$241-輸入與假設!F$242 -> 239.22461 | G37: =輸入與假設!G$241-輸入與假設!G$242 -> 251.65726 | I37: 各線 EBITDA − 其他攤銷（視為等額現金支出），視為現金（現金稅另列於用途；MAG v0.1b）
A38: Ⓒ4 減：延誤罰則（營業費用） | B38: US$bn | C38: =-運營_產能與收入!C62 -> 0 | D38: =-運營_產能與收入!D62 -> 0 | E38: =-運營_產能與收入!E62 -> 0 | F38: =-運營_產能與收入!F62 -> 0 | G38: =-運營_產能與收入!G62 -> 0 | I38: 建設延誤期間應計費而未計費營收 × 罰則比例（預設 0；v0.2）
A39: Ⓒ5 加回：股權報酬（非現金） | B39: US$bn | C39: =輸入與假設!$C$49*(運營_產能與收入!C38+輸入與假設!C$240) -> 16.57618 | D39: =輸入與假設!$C$49*(運營_產能與收入!D38+輸入與假設!D$240) -> 37.819066 | E39: =輸入與假設!$C$49*(運營_產能與收入!E38+輸入與假設!E$240) -> 43.889468 | F39: =輸入與假設!$C$49*(運營_產能與收入!F38+輸入與假設!F$240) -> 49.477061 | G39: =輸入與假設!$C$49*(運營_產能與收入!G38+輸入與假設!G$240) -> 54.069926 | I39: ＝SBC 占營收 × 模型期總營收（分部營業利益已扣 SBC；1H 已含在實際 CFO；MAG v0.1b）
A40: Ⓒ6 首期營運資金變動（上年同期實際） | B40: US$bn | C40: =IF(ISBLANK(輸入與假設!$C$50),0,輸入與假設!$C$50) -> 8.49 | D40: =0 -> 0 | E40: =0 -> 0 | F40: =0 -> 0 | G40: =0 -> 0 | I40: 2026 剩餘季度＝上一年度同期實際（流入為正；10-Q／10-K 現金流量表 [Derived]）；之後年度資金模型不計營運資金（MAG v0.1b r2 C14）
A41: Ⓓ 客戶預付（2H 起） | B41: US$bn | C41: =C8 -> 0 | D41: =D8 -> 0 | E41: =E8 -> 0 | F41: =F8 -> 0 | G41: =G8 -> 0
...

Sheet 季度追蹤
A1: 季度追蹤 — 焦點季的模型／共識／指引／實際與差距（由年度模型拆分；只用於追蹤，不影響年度數字與目標價）
A2: 設定與實際數在『輸入與假設』J 區，共識在 I 區；缺資料顯示「不適用」，實際數空白＝待公布。差距超過門檻的項目附差異原因（拆法＝所屬期間合計差距在門檻內）。第 2 區為 6 季路徑與拆分明細（預設收合）。
A4: 1｜焦點季（『輸入與假設』J 區選擇）：模型／共識／指引／實際與差距
A5: 指標 | B5: 單位 | C5: 模型 | D5: 共識 | E5: 模型 vs 共識 | F5: 指引（低） | G5: 指引（高） | H5: 模型 vs 指引中點 | I5: 實際 | J5: 實際 vs 模型 | K5: 實際 vs 共識 | L5: 實際 vs 指引中點 | M5: 利潤率 pt：模型 vs 共識 | N5: 模型 vs 指引 | O5: 實際 vs 模型 | P5: 實際 vs 共識 | Q5: 實際 vs 指引
A6: 焦點｜營收 | B6: US$bn | C6: =INDEX($C$22:$H$22,輸入與假設!$C$551) -> 127.45744 | D6: =INDEX($C$33:$H$33,輸入與假設!$C$551) -> 不適用 | E6: =INDEX($C$43:$H$43,輸入與假設!$C$551) -> 不適用 | F6: 不適用 | G6: 不適用 | H6: =INDEX($C$44:$H$44,輸入與假設!$C$551) -> 不適用 | I6: =IF(ISNUMBER(INDEX($C$37:$H$37,輸入與假設!$C$551)),INDEX($C$37:$H$37,輸入與假設!$C$551),"待公布") -> 待公布 | J6: =INDEX($C$45:$H$45,輸入與假設!$C$551) | K6: =INDEX($C$46:$H$46,輸入與假設!$C$551) | L6: =INDEX($C$47:$H$47,輸入與假設!$C$551)
A7: 焦點｜調整後 EBITDA | B7: US$bn | C7: =INDEX($C$28:$H$28,輸入與假設!$C$551) -> 49.047364 | D7: =INDEX($C$34:$H$34,輸入與假設!$C$551) -> 不適用 | E7: =INDEX($C$48:$H$48,輸入與假設!$C$551) -> 不適用 | F7: 不適用 | G7: 不適用 | H7: =INDEX($C$49:$H$49,輸入與假設!$C$551) -> 不適用 | I7: =IF(ISNUMBER(INDEX($C$38:$H$38,輸入與假設!$C$551)),INDEX($C$38:$H$38,輸入與假設!$C$551),"待公布") -> 待公布 | J7: =INDEX($C$50:$H$50,輸入與假設!$C$551) | K7: =INDEX($C$51:$H$51,輸入與假設!$C$551) | L7: =INDEX($C$52:$H$52,輸入與假設!$C$551) | M7: =INDEX($C$53:$H$53,輸入與假設!$C$551) -> 不適用 | N7: =INDEX($C$54:$H$54,輸入與假設!$C$551) -> 不適用 | O7: =INDEX($C$55:$H$55,輸入與假設!$C$551) | P7: =INDEX($C$56:$H$56,輸入與假設!$C$551) | Q7: =INDEX($C$57:$H$57,輸入與假設!$C$551)
A8: 焦點｜EBITDA 率 | B8: % | C8: =INDEX($C$27:$H$27,輸入與假設!$C$551) -> 0.38481367 | D8: =INDEX($C$35:$H$35,輸入與假設!$C$551) -> 不適用 | E8: =INDEX($C$58:$H$58,輸入與假設!$C$551) -> 不適用 | F8: 不適用 | G8: 不適用 | H8: =INDEX($C$59:$H$59,輸入與假設!$C$551) -> 不適用 | I8: =IF(ISNUMBER(INDEX($C$39:$H$39,輸入與假設!$C$551)),INDEX($C$39:$H$39,輸入與假設!$C$551),"待公布") -> 待公布 | J8: =INDEX($C$60:$H$60,輸入與假設!$C$551) | K8: =INDEX($C$61:$H$61,輸入與假設!$C$551) | L8: =INDEX($C$62:$H$62,輸入與假設!$C$551)
A9: 焦點｜調整後營業利益 | B9: US$bn | C9: =INDEX($C$31:$H$31,輸入與假設!$C$551) -> 37.018168 | D9: 不適用 | E9: =INDEX($C$63:$H$63,輸入與假設!$C$551) -> 不適用 | F9: 不適用 | G9: 不適用 | H9: =INDEX($C$64:$H$64,輸入與假設!$C$551) -> 不適用 | I9: =IF(ISNUMBER(INDEX($C$40:$H$40,輸入與假設!$C$551)),INDEX($C$40:$H$40,輸入與假設!$C$551),"待公布") -> 待公布 | J9: =INDEX($C$65:$H$65,輸入與假設!$C$551) | K9: =INDEX($C$66:$H$66,輸入與假設!$C$551) | L9: =INDEX($C$67:$H$67,輸入與假設!$C$551) | M9: =INDEX($C$68:$H$68,輸入與假設!$C$551) -> 不適用 | N9: =INDEX($C$69:$H$69,輸入與假設!$C$551) -> 不適用 | O9: =INDEX($C$70:$H$70,輸入與假設!$C$551) | P9: =INDEX($C$71:$H$71,輸入與假設!$C$551) | Q9: =INDEX($C$72:$H$72,輸入與假設!$C$551)
A10: 焦點｜CapEx（毛額） | B10: US$bn | C10: =INDEX($C$32:$H$32,輸入與假設!$C$551) -> 59.703395 | D10: 不適用 | E10: =INDEX($C$73:$H$73,輸入與假設!$C$551) -> 不適用 | F10: 不適用 | G10: 不適用 | H10: =INDEX($C$74:$H$74,輸入與假設!$C$551) -> 不適用 | I10: =IF(ISNUMBER(INDEX($C$41:$H$41,輸入與假設!$C$551)),INDEX($C$41:$H$41,輸入與假設!$C$551),"待公布") -> 待公布 | J10: =INDEX($C$75:$H$75,輸入與假設!$C$551) | K10: =INDEX($C$76:$H$76,輸入與假設!$C$551) | L10: =INDEX($C$77:$H$77,輸入與假設!$C$551)
A11: 焦點｜季末已連網 MW-IT | B11: MW | C11: =INDEX($C$19:$H$19,輸入與假設!$C$551) -> 2212.525 | D11: 不適用 | E11: =INDEX($C$78:$H$78,輸入與假設!$C$551) -> 不適用 | F11: 不適用 | G11: 不適用 | H11: =INDEX($C$79:$H$79,輸入與假設!$C$551) -> 不適用 | I11: =IF(ISNUMBER(INDEX($C$42:$H$42,輸入與假設!$C$551)),INDEX($C$42:$H$42,輸入與假設!$C$551),"待公布") -> 待公布 | J11: =INDEX($C$80:$H$80,輸入與假設!$C$551) | K11: =INDEX($C$81:$H$81,輸入與假設!$C$551) | L11: =INDEX($C$82:$H$82,輸入與假設!$C$551)
A12: 焦點｜季度 | C12: =INDEX($C$16:$H$16,輸入與假設!$C$551) -> Q3 2026
A13: 焦點｜差異原因 | C13: =IF(INDEX($C$119:$H$119,輸入與假設!$C$551)="","無（差距皆在 "&IF(ROUND(ABS(輸入與假設!$C$545)*100,4)=INT(ROUND(ABS(輸入與假設!$C$545)*100,4)),TEXT(ROUND(ABS(輸入與假設!$C$545)*100,4),"0"),TEXT(ROUND(ABS(輸入與假設!$C$545)*100,4),"0.0"))&"%"&" 以內）",INDEX($C$119:$H$119,輸入與假設!$C$551)) -> 無（差距皆在 5% 以內）
A15: 2｜6 季路徑、共識、指引、實際與差距（明細；第 1 區以焦點季引用本區）
A16: 項目 | B16: 單位 | C16: Q3 2026 | D16: Q4 2026 | E16: Q1 2027 | F16: Q2 2027 | G16: Q3 2027 | H16: Q4 2027
A17: 所屬期間 | C17: =輸入與假設!C$550 -> 1 | D17: =輸入與假設!D$550 -> 1 | E17: =輸入與假設!E$550 -> 2 | F17: =輸入與假設!F$550 -> 2 | G17: =輸入與假設!G$550 -> 2 | H17: =輸入與假設!H$550 -> 2 | J17: 1＝2H26、2＝2027
A18: 季序 | C18: 1 | D18: 2 | E18: 3 | F18: 4 | G18: 5 | H18: 6 | J18: EBITDA 率直線的 x 軸
A19: 季末已連網 MW-IT（模型） | B19: MW | C19: =輸入與假設!$C$553+(輸入與假設!C$36-輸入與假設!$C$553)*1/2 -> 2212.525 | D19: =輸入與假設!$C$553+(輸入與假設!C$36-輸入與假設!$C$553)*2/2 -> 2524.05 | E19: =輸入與假設!C$36+(輸入與假設!D$36-輸入與假設!C$36)*1/4 -> 2835.575 | F19: =輸入與假設!C$36+(輸入與假設!D$36-輸入與假設!C$36)*2/4 -> 3147.1 | G19: =輸入與假設!C$36+(輸入與假設!D$36-輸入與假設!C$36)*3/4 -> 3458.625 | H19: =輸入與假設!C$36+(輸入與假設!D$36-輸入與假設!C$36)*4/4 -> 3770.15 | J19: 期初與期末 Accepted 之間線性內插；第 1 期起點見 J 區
A20: 平均在役 MW（Billable，拆分依據） | B20: MW | C20: =輸入與假設!$C$29+(運營_產能與收入!C$11-輸入與假設!$C$29)*1/4 -> 2056.75 | D20: =輸入與假設!$C$29+(運營_產能與收入!C$11-輸入與假設!$C$29)*3/4 -> 2368.25 | E20: =運營_產能與收入!C$11+(運營_產能與收入!D$11-運營_產能與收入!C$11)*1/8 -> 2679.75 | F20: =運營_產能與收入!C$11+(運營_產能與收入!D$11-運營_產能與收入!C$11)*3/8 -> 2991.25 | G20: =運營_產能與收入!C$11+(運營_產能與收入!D$11-運營_產能與收入!C$11)*5/8 -> 3302.75 | H20: =運營_產能與收入!C$11+(運營_產能與收入!D$11-運營_產能與收入!C$11)*7/8 -> 3614.25 | J20: 期初與期末 Billable 之間線性內插的季平均
A21: 季內新增 Accepted MW | B21: MW | C21: =C19-輸入與假設!$C$553 -> 311.525 | D21: =D19-C19 -> 311.525 | E21: =E19-輸入與假設!C$36 -> 311.525 | F21: =F19-E19 -> 311.525 | G21: =G19-F19 -> 311.525 | H21: =H19-G19 -> 311.525 | J21: CapEx 拆分依據
A22: 營收（模型） | B22: US$bn | C22: =輸入與假設!$C$552+1*(損益!C9-2*輸入與假設!$C$552)/3 -> 127.45744 | D22: =輸入與假設!$C$552+2*(損益!C9-2*輸入與假設!$C$552)/3 -> 135.11887 | E22: =損益!D9*E20/(E20+F20+G20+H20) -> 127.53208 | F22: =損益!D9*F20/(E20+F20+G20+H20) -> 142.35669 | G22: =損益!D9*G20/(E20+F20+G20+H20) -> 157.18129 | H22: =損益!D9*H20/(E20+F20+G20+H20) -> 172.0059 | J22: 拆分方法見『輸入與假設』J 區與 HTML「拆分方法」
A23: EBITDA 率直線｜各期營收合計 S | C23: =C22+D22 -> 262.57631 | D23: =E22+F22+G22+H22 -> 599.07596 | J23: 欄＝期間（2H26、2027）
A24: EBITDA 率直線｜營收 × 季序合計 T | C24: =C22*C18+D22*D18 -> 397.69518 | D24: =E22*E18+F22*F18+G22*G18+H22*H18 -> 2769.9648 | J24: 欄＝期間（2H26、2027）
A25: EBITDA 率直線｜年度 EBITDA E | C25: =損益!C22 -> 100.42728 | D25: =損益!D22 -> 220.64084 | J25: 欄＝期間（2H26、2027）
A26: EBITDA 率直線｜截距 a／斜率 b | C26: =(C25*D24-C24*D25)/(C23*D24-C24*D23) -> 0.38937023 | D26: =(C23*D25-D23*C25)/(C23*D24-C24*D23) -> -0.0045565556 | J26: 解兩式：Σ營收×(a＋b×季序)＝各期年度 EBITDA
A27: EBITDA 率（模型） | B27: % | C27: =$C$26+$D$26*C18 -> 0.38481367 | D27: =$C$26+$D$26*D18 -> 0.38025712 | E27: =$C$26+$D$26*E18 -> 0.37570056 | F27: =$C$26+$D$26*F18 -> 0.371144 | G27: =$C$26+$D$26*G18 -> 0.36658745 | H27: =$C$26+$D$26*H18 -> 0.36203089 | J27: 跨季一條直線，季度 EBITDA 加總＝年度
A28: 調整後 EBITDA（模型） | B28: US$bn | C28: =C22*C27 -> 49.047364 | D28: =D22*D27 -> 51.379913 | E28: =E22*E27 -> 47.913873 | F28: =F22*F27 -> 52.83483 | G28: =G22*G27 -> 57.620689 | H28: =H22*H27 -> 62.27145
A29: 車隊折舊（模型） | B29: US$bn | C29: =輸入與假設!C$324/2 -> 12.029197 | D29: =輸入與假設!C$324/2 -> 12.029197 | E29: =輸入與假設!D$324/4 -> 17.880538 | F29: =輸入與假設!D$324/4 -> 17.880538 | G29: =輸入與假設!D$324/4 -> 17.880538 | H29: =輸入與假設!D$324/4 -> 17.880538 | J29: ＝期間 D&A（AI＋非 AI 分池）÷ 期內季數
A30: 其他攤銷（模型） | B30: US$bn | C30: =輸入與假設!C$242*C22/MAX(0.000000001,C23) -> 0 | D30: =輸入與假設!C$242*D22/MAX(0.000000001,C23) -> 0 | E30: =輸入與假設!D$242*E22/MAX(0.000000001,D23) -> 0 | F30: =輸入與假設!D$242*F22/MAX(0.000000001,D23) -> 0 | G30: =輸入與假設!D$242*G22/MAX(0.000000001,D23) -> 0 | H30: =輸入與假設!D$242*H22/MAX(0.000000001,D23) -> 0 | J30: ＝期間非 AI 事業其他攤銷 × 季營收占比（MAG v0.1b）
A31: 調整後營業利益（模型） | B31: US$bn | C31: =C28-C29-C30 -> 37.018168 | D31: =D28-D29-D30 -> 39.350716 | E31: =E28-E29-E30 -> 30.033335 | F31: =F28-F29-F30 -> 34.954293 | G31: =G28-G29-G30 -> 39.740152 | H31: =H28-H29-H30 -> 44.390912 | J31: ＝調整後 EBITDA − 車隊折舊 − 其他攤銷（未扣 SBC）
A32: CapEx（毛額）（模型） | B32: US$bn | C32: =IF((C21+D21)>0,輸入與假設!C$323*C21/(C21+D21),輸入與假設!C$323/2) -> 59.703395 | D32: =IF((C21+D21)>0,輸入與假設!C$323*D21/(C21+D21),輸入與假設!C$323/2) -> 59.703395 | E32: =IF((E21+F21+G21+H21)>0,輸入與假設!D$323*E21/(E21+F21+G21+H21),輸入與假設!D$323/4) -> 59.208756 | F32: =IF((E21+F21+G21+H21)>0,輸入與假設!D$323*F21/(E21+F21+G21+H21),輸入與假設!D$323/4) -> 59.208756 | G32: =IF((E21+F21+G21+H21)>0,輸入與假設!D$323*G21/(E21+F21+G21+H21),輸入與假設!D$323/4) -> 59.208756 | H32: =IF((E21+F21+G21+H21)>0,輸入與假設!D$323*H21/(E21+F21+G21+H21),輸入與假設!D$323/4) -> 59.208756 | J32: 依季內新增 Accepted MW
A33: 共識｜營收 | B33: US$bn | C33: 不適用 | D33: 不適用 | E33: 不適用 | F33: 不適用 | G33: 不適用 | H33: 不適用 | J33: I 區季度共識 [Interested-party]
A34: 共識｜調整後 EBITDA | B34: US$bn | C34: 不適用 | D34: 不適用 | E34: 不適用 | F34: 不適用 | G34: 不適用 | H34: 不適用 | J34: I 區季度共識 [Interested-party]
A35: 共識｜EBITDA 率 [Derived] | B35: % | C35: 不適用 | D35: 不適用 | E35: 不適用 | F35: 不適用 | G35: 不適用 | H35: 不適用 | J35: ＝共識 EBITDA ÷ 共識營收
A36: 共識 EBIT（供應商口徑） | B36: US$bn | C36: 不適用 | D36: 不適用 | E36: 不適用 | F36: 不適用 | G36: 不適用 | H36: 不適用 | J36: 口徑未揭露：只列不比較
A37: 實際｜營收 | B37: US$bn | C37: =IF(ISNUMBER(輸入與假設!C$554),輸入與假設!C$554,"") | D37: =IF(ISNUMBER(輸入與假設!D$554),輸入與假設!D$554,"") | E37: =IF(ISNUMBER(輸入與假設!E$554),輸入與假設!E$554,"") | F37: =IF(ISNUMBER(輸入與假設!F$554),輸入與假設!F$554,"") | G37: =IF(ISNUMBER(輸入與假設!G$554),輸入與假設!G$554,"") | H37: =IF(ISNUMBER(輸入與假設!H$554),輸入與假設!H$554,"")
A38: 實際｜調整後 EBITDA | B38: US$bn | C38: =IF(ISNUMBER(輸入與假設!C$555),輸入與假設!C$555,"") | D38: =IF(ISNUMBER(輸入與假設!D$555),輸入與假設!D$555,"") | E38: =IF(ISNUMBER(輸入與假設!E$555),輸入與假設!E$555,"") | F38: =IF(ISNUMBER(輸入與假設!F$555),輸入與假設!F$555,"") | G38: =IF(ISNUMBER(輸入與假設!G$555),輸入與假設!G$555,"") | H38: =IF(ISNUMBER(輸入與假設!H$555),輸入與假設!H$555,"")
A39: 實際｜EBITDA 率 | B39: % | C39: =IF(AND(ISNUMBER(輸入與假設!C$555),ISNUMBER(輸入與假設!C$554)),輸入與假設!C$555/輸入與假設!C$554,"") | D39: =IF(AND(ISNUMBER(輸入與假設!D$555),ISNUMBER(輸入與假設!D$554)),輸入與假設!D$555/輸入與假設!D$554,"") | E39: =IF(AND(ISNUMBER(輸入與假設!E$555),ISNUMBER(輸入與假設!E$554)),輸入與假設!E$555/輸入與假設!E$554,"") | F39: =IF(AND(ISNUMBER(輸入與假設!F$555),ISNUMBER(輸入與假設!F$554)),輸入與假設!F$555/輸入與假設!F$554,"") | G39: =IF(AND(ISNUMBER(輸入與假設!G$555),ISNUMBER(輸入與假設!G$554)),輸入與假設!G$555/輸入與假設!G$554,"") | H39: =IF(AND(ISNUMBER(輸入與假設!H$555),ISNUMBER(輸入與假設!H$554)),輸入與假設!H$555/輸入與假設!H$554,"") | J39: ＝實際 EBITDA ÷ 實際營收
A40: 實際｜調整後營業利益 | B40: US$bn | C40: =IF(ISNUMBER(輸入與假設!C$556),輸入與假設!C$556,"") | D40: =IF(ISNUMBER(輸入與假設!D$556),輸入與假設!D$556,"") | E40: =IF(ISNUMBER(輸入與假設!E$556),輸入與假設!E$556,"") | F40: =IF(ISNUMBER(輸入與假設!F$556),輸入與假設!F$556,"") | G40: =IF(ISNUMBER(輸入與假設!G$556),輸入與假設!G$556,"") | H40: =IF(ISNUMBER(輸入與假設!H$556),輸入與假設!H$556,"")
A41: 實際｜CapEx（毛額） | B41: US$bn | C41: =IF(ISNUMBER(輸入與假設!C$557),輸入與假設!C$557,"") | D41: =IF(ISNUMBER(輸入與假設!D$557),輸入與假設!D$557,"") | E41: =IF(ISNUMBER(輸入與假設!E$557),輸入與假設!E$557,"") | F41: =IF(ISNUMBER(輸入與假設!F$557),輸入與假設!F$557,"") | G41: =IF(ISNUMBER(輸入與假設!G$557),輸入與假設!G$557,"") | H41: =IF(ISNUMBER(輸入與假設!H$557),輸入與假設!H$557,"")
A42: 實際｜季末對外 AI MW（未揭露） | B42: MW | C42: =IF(ISNUMBER(輸入與假設!C$558),輸入與假設!C$558,"") | D42: =IF(ISNUMBER(輸入與假設!D$558),輸入與假設!D$558,"") | E42: =IF(ISNUMBER(輸入與假設!E$558),輸入與假設!E$558,"") | F42: =IF(ISNUMBER(輸入與假設!F$558),輸入與假設!F$558,"") | G42: =IF(ISNUMBER(輸入與假設!G$558),輸入與假設!G$558,"") | H42: =IF(ISNUMBER(輸入與假設!H$558),輸入與假設!H$558,"")
...

Sheet 運營_產能與收入
A1: 產能與收入 — 合約排程 vs 機房產能
A2: 兩條線獨立產生後相減：排程>容量→瓶頸（收不到）；容量>排程→剩餘產能（要靠新簽約賣掉）
A3: 2026 欄口徑：MW 為年底存量；標示「（模型期）」的收入列只含 2026 下半年——RPO 桶自 2026-06-30 起算，1H 收入已實現、不再受產能約束。1H 實際單列，兩者相加即 2026 全年（見本頁「FY26 全年」列）。
A5: 項目 | B5: 單位 | C5: 2026 | D5: 2027 | E5: 2028 | F5: 2029 | G5: 2030 | I5: 公式／來源說明
A6: 模型期間 | C6: ="2026-07-01~12-31" -> 2026-07-01~12-31 | D6: ="2027 全年" -> 2027 全年 | E6: ="2028 全年" -> 2028 全年 | F6: ="2029 全年" -> 2029 全年 | G6: ="2030 全年" -> 2030 全年 | I6: 2026 的模型期只有下半年；1H 已實現的營收單列於下方
A7: 模型期長度（年） | C7: =輸入與假設!C$34 -> 0.5 | D7: =輸入與假設!D$34 -> 1 | E7: =輸入與假設!E$34 -> 1 | F7: =輸入與假設!F$34 -> 1 | G7: =輸入與假設!G$34 -> 1 | I7: 只用於下方三處：容量上限、電力、維護——把年率換算成該期金額
A8: （A）機房：容量上限
A9: Accepted MW（已驗收，單調不減） | B9: MW | C9: =MAX(0,輸入與假設!C$36) -> 2524.05 | D9: =MAX(輸入與假設!D$36,C9) -> 3770.15 | E9: =MAX(輸入與假設!E$36,D9) -> 5016.25 | F9: =MAX(輸入與假設!F$36,E9) -> 6262.35 | G9: =MAX(輸入與假設!G$36,F9) -> 7508.45 | I9: 引擎規則：不得低於前期（產能不會消失）
A10: Billable MW（上限為 Accepted） | B10: MW | C10: =MIN(MAX(0,輸入與假設!C$37),C9) -> 2524 | D10: =MIN(MAX(0,輸入與假設!D$37),D9) -> 3770 | E10: =MIN(MAX(0,輸入與假設!E$37),E9) -> 5016 | F10: =MIN(MAX(0,輸入與假設!F$37),F9) -> 6262 | G10: =MIN(MAX(0,輸入與假設!G$37),G9) -> 7508 | I10: 引擎規則：可計費不得超過已驗收
A11: Billable MW（延誤後，計費用） | B11: MW | C11: =IF($C$50<=0,$C$10,輸入與假設!$C$29+($C$10-輸入與假設!$C$29)*MAX(0,MIN(1,($C$51-$C$50/12-0)/$C$7))+($D$10-$C$10)*MAX(0,MIN(1,($C$51-$C$50/12-$C$51)/$D$7))+($E$10-$D$10)*MAX(0,MIN(1,($C$51-$C$50/12-$D$51)/$E$7))+($F$10-$E$10)*MAX(0,MIN(1,($C$51-$C$50/12-$E$51)/$F$7))+($G$10-$F$10)*MAX(0,MIN(1,($C$51-$C$50/12-$F$51)/$G$7))) -> 2524 | D11: =IF($C$50<=0,$D$10,輸入與假設!$C$29+($C$10-輸入與假設!$C$29)*MAX(0,MIN(1,($D$51-$C$50/12-0)/$C$7))+($D$10-$C$10)*MAX(0,MIN(1,($D$51-$C$50/12-$C$51)/$D$7))+($E$10-$D$10)*MAX(0,MIN(1,($D$51-$C$50/12-$D$51)/$E$7))+($F$10-$E$10)*MAX(0,MIN(1,($D$51-$C$50/12-$E$51)/$F$7))+($G$10-$F$10)*MAX(0,MIN(1,($D$51-$C$50/12-$F$51)/$G$7))) -> 3770 | E11: =IF($C$50<=0,$E$10,輸入與假設!$C$29+($C$10-輸入與假設!$C$29)*MAX(0,MIN(1,($E$51-$C$50/12-0)/$C$7))+($D$10-$C$10)*MAX(0,MIN(1,($E$51-$C$50/12-$C$51)/$D$7))+($E$10-$D$10)*MAX(0,MIN(1,($E$51-$C$50/12-$D$51)/$E$7))+($F$10-$E$10)*MAX(0,MIN(1,($E$51-$C$50/12-$E$51)/$F$7))+($G$10-$F$10)*MAX(0,MIN(1,($E$51-$C$50/12-$F$51)/$G$7))) -> 5016 | F11: =IF($C$50<=0,$F$10,輸入與假設!$C$29+($C$10-輸入與假設!$C$29)*MAX(0,MIN(1,($F$51-$C$50/12-0)/$C$7))+($D$10-$C$10)*MAX(0,MIN(1,($F$51-$C$50/12-$C$51)/$D$7))+($E$10-$D$10)*MAX(0,MIN(1,($F$51-$C$50/12-$D$51)/$E$7))+($F$10-$E$10)*MAX(0,MIN(1,($F$51-$C$50/12-$E$51)/$F$7))+($G$10-$F$10)*MAX(0,MIN(1,($F$51-$C$50/12-$F$51)/$G$7))) -> 6262 | G11: =IF($C$50<=0,$G$10,輸入與假設!$C$29+($C$10-輸入與假設!$C$29)*MAX(0,MIN(1,($G$51-$C$50/12-0)/$C$7))+($D$10-$C$10)*MAX(0,MIN(1,($G$51-$C$50/12-$C$51)/$D$7))+($E$10-$D$10)*MAX(0,MIN(1,($G$51-$C$50/12-$D$51)/$E$7))+($F$10-$E$10)*MAX(0,MIN(1,($G$51-$C$50/12-$E$51)/$F$7))+($G$10-$F$10)*MAX(0,MIN(1,($G$51-$C$50/12-$F$51)/$G$7))) -> 7508 | I11: ＝上列往後平移建設延誤月數（以期間長度線性內插；評價日之前取期初校準值）；延誤 0 時＝上列；見（E）區（v0.2）
A12: 期初在役 MW | B12: MW | C12: =輸入與假設!$C$29 -> 1901 | D12: =C11 -> 2524 | E12: =D11 -> 3770 | F12: =E11 -> 5016 | G12: =F11 -> 6262 | I12: 前期期末＝本期期初（延誤後）
A13: 平均在役 MW（2026 欄為下半年平均） | B13: MW | C13: =IF(輸入與假設!$C$30=1,(C12+C11)/2,C11) -> 2212.5 | D13: =IF(輸入與假設!$C$30=1,(D12+D11)/2,D11) -> 3147 | E13: =IF(輸入與假設!$C$30=1,(E12+E11)/2,E11) -> 4393 | F13: =IF(輸入與假設!$C$30=1,(F12+F11)/2,F11) -> 5639 | G13: =IF(輸入與假設!$C$30=1,(G12+G11)/2,G11) -> 6885 | I13: 開關在輸入頁：1＝(期初+期末)/2，0＝期末全期化
A14: 利用率 | B14: % | C14: =輸入與假設!C$38 -> 1 | D14: =輸入與假設!D$38 -> 1 | E14: =輸入與假設!E$38 -> 1 | F14: =輸入與假設!F$38 -> 1 | G14: =輸入與假設!G$38 -> 1
A15: 每 MW 年收入 | B15: US$bn/MW | C15: =輸入與假設!C$39 -> 0.011500793 | D15: =輸入與假設!D$39 -> 0.012107214 | E15: =輸入與假設!E$39 -> 0.012604282 | F15: =輸入與假設!F$39 -> 0.012903535 | G15: =輸入與假設!G$39 -> 0.01310346
A16: 容量上限（模型期最多能交付的收入） | B16: US$bn | C16: =C13*輸入與假設!C$39*輸入與假設!$C$32*輸入與假設!C$38*C7 -> 12.722752 | D16: =D13*輸入與假設!D$39*輸入與假設!$C$32*輸入與假設!D$38*D7 -> 38.101402 | E16: =E13*輸入與假設!E$39*輸入與假設!$C$32*輸入與假設!E$38*E7 -> 55.370613 | F16: =F13*輸入與假設!F$39*輸入與假設!$C$32*輸入與假設!F$38*F7 -> 72.763033 | G16: =G13*輸入與假設!G$39*輸入與假設!$C$32*輸入與假設!G$38*G7 -> 90.21732 | I16: ＝平均在役 MW × 每 MW 年收入 × 利用率 × 期間係數。只看機房，不看合約
A17: （B）合約：排程 RPO
A18: 排程 RPO（模型期，依季報桶分攤） | B18: US$bn | C18: =(輸入與假設!$C$24+輸入與假設!$C$25)*(輸入與假設!C$35/輸入與假設!$C$27)*輸入與假設!$C$26 -> 0 | D18: =(輸入與假設!$C$24+輸入與假設!$C$25)*(輸入與假設!D$35/輸入與假設!$C$27)*輸入與假設!$C$26 -> 0 | E18: =(輸入與假設!$C$24+輸入與假設!$C$25)*(輸入與假設!E$35/輸入與假設!$C$27)*輸入與假設!$C$26 -> 0 | F18: =(輸入與假設!$C$24+輸入與假設!$C$25)*(輸入與假設!F$35/輸入與假設!$C$27)*輸入與假設!$C$26 -> 0 | G18: =(輸入與假設!$C$24+輸入與假設!$C$25)*(輸入與假設!G$35/輸入與假設!$C$27)*輸入與假設!$C$26 -> 0 | I18: ＝(6/30 RPO＋評價日後新增)×本期權重÷權重合計×五期認列比例。只看合約，不看機房
A19: （C）兩條線相減
A20: 產能瓶頸（模型期：排程 − 容量） | B20: US$bn | C20: =MAX(0,C18-C16) -> 0 | D20: =MAX(0,D18-D16) -> 0 | E20: =MAX(0,E18-E16) -> 0 | F20: =MAX(0,F18-F16) -> 0 | G20: =MAX(0,G18-G16) -> 0 | I20: 合約有、機房沒有 → 本期收不到，且不遞延到下期（保守處理）
A21: 期初 RPO 轉換收入（模型期） | B21: US$bn | C21: =C18-C20 -> 0 | D21: =D18-D20 -> 0 | E21: =E18-E20 -> 0 | F21: =F18-F20 -> 0 | G21: =G18-G20 -> 0 | I21: ＝排程 − 瓶頸。當瓶頸>0 時，此值恆等於容量上限
A22: 未被期初 RPO 占用的產能 | B22: US$bn | C22: =MAX(0,C16-C18) -> 12.722752 | D22: =MAX(0,D16-D18) -> 38.101402 | E22: =MAX(0,E16-E18) -> 55.370613 | F22: =MAX(0,F16-F18) -> 72.763033 | G22: =MAX(0,G16-G18) -> 90.21732 | I22: 容量 − 排程。機房有、期初合約沒占滿 → 要靠新簽約
A23: 新產能簽約率 | B23: % | C23: =IF(輸入與假設!$C$31="mw",1,輸入與假設!C$40) -> 1 | D23: =IF(輸入與假設!$C$31="mw",1,輸入與假設!D$40) -> 1 | E23: =IF(輸入與假設!$C$31="mw",1,輸入與假設!E$40) -> 1 | F23: =IF(輸入與假設!$C$31="mw",1,輸入與假設!F$40) -> 1 | G23: =IF(輸入與假設!$C$31="mw",1,輸入與假設!G$40) -> 1 | I23: MW 驅動時固定 100%
A24: 新簽約收入 | B24: US$bn | C24: =C22*C23 -> 12.722752 | D24: =D22*D23 -> 38.101402 | E24: =E22*E23 -> 55.370613 | F24: =F22*F23 -> 72.763033 | G24: =G22*G23 -> 90.21732 | I24: 超出期初 RPO 的產能收入（MW 驅動，簽約率 100%）
A25: 未售產能（浪費） | B25: US$bn | C25: =MAX(0,C16-C21-C24) -> 0 | D25: =MAX(0,D16-D21-D24) -> 0 | E25: =MAX(0,E16-E21-E24) -> 0 | F25: =MAX(0,F16-F21-F24) -> 0 | G25: =MAX(0,G16-G21-G24) -> 0 | I25: 蓋好但賣不掉（MW 驅動時為 0）
A26: 損益用算力收入（模型期＝RPO 轉換＋新簽約） | B26: US$bn | C26: =C21+C24 -> 12.722752 | D26: =D21+D24 -> 38.101402 | E26: =E21+E24 -> 55.370613 | F26: =F21+F24 -> 72.763033 | G26: =G21+G24 -> 90.21732 | I26: 損益與評價頁的算力收入由此連結，確保現金與損益同一組數字
A27: 核對：算力收入 − 平均在役 MW × 每 MW × 利用率 × 期間 | B27: US$bn | C27: =C26-C13*輸入與假設!C$39*輸入與假設!$C$32*輸入與假設!C$38*C7 -> 0 | D27: =D26-D13*輸入與假設!D$39*輸入與假設!$C$32*輸入與假設!D$38*D7 -> 0 | E27: =E26-E13*輸入與假設!E$39*輸入與假設!$C$32*輸入與假設!E$38*E7 -> 0 | F27: =F26-F13*輸入與假設!F$39*輸入與假設!$C$32*輸入與假設!F$38*F7 -> 0 | G27: =G26-G13*輸入與假設!G$39*輸入與假設!$C$32*輸入與假設!G$38*G7 -> 0 | I27: MW 驅動時應為 0：營收可追溯為 MW × 每 MW 年收入 × 利用率（v0.1b）
A28: 對照：評價日起 36 個月營收權重 | B28: % | C28: 1 | D28: 1 | E28: 1 | F28: 0.5 | G28: 0 | I28: RPO 36 個月內轉換的對照用（只作對照，不驅動營收）
A29: 對照：評價日起 36 個月 MW 驅動營收 | B29: US$bn | C29: =C26*C28 -> 12.722752 | D29: =D26*D28 -> 38.101402 | E29: =E26*E28 -> 55.370613 | F29: =F26*F28 -> 36.381517 | G29: =G26*G28 -> 0 | I29: 合計對照季報 RPO 519.5 × 36 個月內 59%（含非 AI 事業 RPO）；差額不回推每 MW 單價
A30: 1H26 實際營收（季報，已實現） | B30: US$bn | C30: =輸入與假設!$C$477 -> 229.692 | D30: =0 -> 0 | E30: =0 -> 0 | F30: =0 -> 0 | G30: =0 -> 0 | I30: 2026-01-01 至 06-30 已認列營收。已實現，不受下半年產能約束，故不進入上方的瓶頸計算
A31: 2026 全年總營收（1H 實際＋模型期算力＋服務＋非 AI 事業） | B31: US$bn | C31: =C30+C26+輸入與假設!C$43+輸入與假設!C$240 -> 492.26831 | D31: =D30+D26+輸入與假設!D$43+輸入與假設!D$240 -> 599.07596 | E31: =E30+E26+輸入與假設!E$43+輸入與假設!E$240 -> 695.23465 | F31: =F30+F26+輸入與假設!F$43+輸入與假設!F$240 -> 783.74537 | G31: =G30+G26+輸入與假設!G$43+輸入與假設!G$240 -> 856.49901 | I31: 2026 欄對照公司全年指引 未給全年營收指引；2027 以後即為該年度總營收
A32: （D）收入 → 現金：三道折扣
A33: 客戶違約率 | B33: % | C33: =輸入與假設!C$41 -> 0 | D33: =輸入與假設!D$41 -> 0 | E33: =輸入與假設!E$41 -> 0 | F33: =輸入與假設!F$41 -> 0 | G33: =輸入與假設!G$41 -> 0
A34: 回收率 | B34: % | C34: =輸入與假設!C$42 -> 0.5 | D34: =輸入與假設!D$42 -> 0.5 | E34: =輸入與假設!E$42 -> 0.5 | F34: =輸入與假設!F$42 -> 0.5 | G34: =輸入與假設!G$42 -> 0.5
A35: 信用損失（期初 RPO 部分） | B35: US$bn | C35: =C21*輸入與假設!C$41*(1-輸入與假設!C$42) -> 0 | D35: =D21*輸入與假設!D$41*(1-輸入與假設!D$42) -> 0 | E35: =E21*輸入與假設!E$41*(1-輸入與假設!E$42) -> 0 | F35: =F21*輸入與假設!F$41*(1-輸入與假設!F$42) -> 0 | G35: =G21*輸入與假設!G$41*(1-輸入與假設!G$42) -> 0 | I35: ＝收入 × 違約率 × (1−回收率)
A36: 收現（期初 RPO 部分） | B36: US$bn | C36: =C21-C35 -> 0 | D36: =D21-D35 -> 0 | E36: =E21-E35 -> 0 | F36: =F21-F35 -> 0 | G36: =G21-G35 -> 0
A37: EBITDA 率（損益與資金共用） | B37: % | C37: =輸入與假設!C$250 -> 0.83423438 | D37: =輸入與假設!D$250 -> 0.83894381 | E37: =輸入與假設!E$250 -> 0.84246605 | F37: =輸入與假設!F$250 -> 0.84445571 | G37: =輸入與假設!G$250 -> 0.84573431 | I37: 起始→穩態線性爬升
A38: 模型期總營收（算力＋服務） | B38: US$bn | C38: =C26+輸入與假設!C$43 -> 12.722752 | D38: =D26+輸入與假設!D$43 -> 38.101402 | E38: =E26+輸入與假設!E$43 -> 55.370613 | F38: =F26+輸入與假設!F$43 -> 72.763033 | G38: =G26+輸入與假設!G$43 -> 90.21732
A39: EBITDAR 率（EBITDA 率＋租金÷營收） | B39: % | C39: =輸入與假設!C$250 -> 0.83423438 | D39: =輸入與假設!D$250 -> 0.83894381 | E39: =輸入與假設!E$250 -> 0.84246605 | F39: =輸入與假設!F$250 -> 0.84445571 | G39: =輸入與假設!G$250 -> 0.84573431 | I39: 租金前的 EBITDA 率。EBITDA 已扣租金，而資金模型把租金列在支出端，所以要加回，避免重複扣除
A40: RPO 現金（可支應資本用途） | B40: US$bn | C40: =C36*C39 -> 0 | D40: =D36*D39 -> 0 | E40: =E36*E39 -> 0 | F40: =F36*F39 -> 0 | G40: =G36*G39 -> 0 | I40: ×EBITDAR 率。租金與利息在支出頁單獨列示
A41: 新簽約現金 | B41: US$bn | C41: =C24*(1-輸入與假設!C$41*(1-輸入與假設!C$42))*C39 -> 10.613757 | D41: =D24*(1-輸入與假設!D$41*(1-輸入與假設!D$42))*D39 -> 31.964935 | E41: =E24*(1-輸入與假設!E$41*(1-輸入與假設!E$42))*E39 -> 46.647862 | F41: =F24*(1-輸入與假設!F$41*(1-輸入與假設!F$42))*F39 -> 61.445159 | G41: =G24*(1-輸入與假設!G$41*(1-輸入與假設!G$42))*G39 -> 76.299883 | I41: 同樣扣信用損失、乘 EBITDAR 率
...

Sheet 運營_站點
A1: 站點租賃 — 公司揭露 vs 季報總額（檢驗租金路徑用）
A2: 季報不揭露逐站租金；下表為具名站點（company.json → defaults.sites），有租約金額者用來檢驗『每 MW 年租金』與模型租金路徑是否一致
A4: 站點 | B4: 營運方 | C4: 契約 MW | D4: 已驗收 MW | E4: 合約總值 $bn | F4: 年期 | G4: 年租金 $bn | H4: 每 MW 年租金 $m | I4: 時程 | J4: 季報對應 | K4: 說明
A5: Mesa, AZ | B5: Google 自建 | C5: 183 | D5: 183 | E5: 未揭露 | F5: 未揭露 | I5: 2026 | J5: — | K5: Epoch AI 資料中心目錄：IT 電力 183 MW（估計 2026-08-15 營運；事實總帳 mw.site.mesa）[第三方]
A6: 具名站點合計 | C6: =SUM(C5:C5) -> 183 | D6: =SUM(D5:D5) -> 183 | E6: =SUM(E5:E5) -> 0 | G6: =SUM(G5:G5) -> 0 | H6: =IF(I6>0,G6/I6*1000,0) -> 0 | I6: =SUMPRODUCT(ISNUMBER(G5:G5)*C5:C5) -> 0 | K6: 加權每 MW 年租金＝具名站點的市場基準（I 欄＝有租約金額站點的契約 MW；沒有時為 0，不適用）
A8: 對帳：具名站點 vs 季報租賃承諾總額
A9: 季報在帳租賃（未折現，已起租） | E9: 24.253 | K9: company.json → leases.facts.onBal
A10: 季報未起租租賃（未折現） | E10: 85.2 | K10: company.json → leases.facts.notCommenced
A11: 季報單站按造價計租上限 | E11: 0 | K11: company.json → leases.facts.singleCap（無則 0）
A12: 季報已揭露租賃承諾合計 | E12: =SUM(E9:E11) -> 109.453 | K12: 未折現金額
A13: 減：具名站點合約總值 | E13: =-E6 -> 0
A14: ＝ 未具名站點（殘差） | E14: =E12+E13 -> 109.453 | K14: 未具名站點；公司不揭露逐站租金，殘差大是必然
A15: 殘差占季報總額 | E15: =IF(E12<>0,E14/E12,0) -> 1
A17: 檢驗：模型租金路徑 ÷ 在役 MW vs 市場基準
A18: 項目 | B18: 單位 | C18: 2026 | D18: 2027 | E18: 2028 | F18: 2029 | G18: 2030
A19: 模型租金（在帳＋表外） | B19: US$bn | C19: =各期收支!C16 -> 0.23031376 | D19: =各期收支!D16 -> 0.53288254 | E19: =各期收支!E16 -> 0.65255591 | F19: =各期收支!F16 -> 0.76122927 | G19: =各期收支!G16 -> 0.81990264
A20: 平均在役 MW（已連網） | B20: MW | C20: =(輸入與假設!C$289+輸入與假設!C$36)/2 -> 1993.025 | D20: =(輸入與假設!D$289+輸入與假設!D$36)/2 -> 3147.1 | E20: =(輸入與假設!E$289+輸入與假設!E$36)/2 -> 4393.2 | F20: =(輸入與假設!F$289+輸入與假設!F$36)/2 -> 5639.3 | G20: =(輸入與假設!G$289+輸入與假設!G$36)/2 -> 6885.4
A21: 模型期長度（年） | B21: 年 | C21: =輸入與假設!C$34 -> 0.5 | D21: =輸入與假設!D$34 -> 1 | E21: =輸入與假設!E$34 -> 1 | F21: =輸入與假設!F$34 -> 1 | G21: =輸入與假設!G$34 -> 1
A22: 模型每 MW 年租金 | B22: US$m/MW | C22: =C19/C21/C20*1000 -> 0.23111979 | D22: =D19/D21/D20*1000 -> 0.16932495 | E22: =E19/E21/E20*1000 -> 0.14853772 | F22: =F19/F21/F20*1000 -> 0.13498648 | G22: =G19/G21/G20*1000 -> 0.11907843 | K22: 2026 欄只含下半年租金、MW 取全期平均，略有低估
A23: 第三方租賃占比 | C23: 1 | K23: 其餘為自建，成本走 CapEx（company.json → leases.facts.share）[Assumed]
A24: 基準租金（MW×市場基準×占比） | B24: US$bn | C24: =C20*運營_站點!$H$6/1000*$C$23*C21 -> 0 | D24: =D20*運營_站點!$H$6/1000*$C$23*D21 -> 0 | E24: =E20*運營_站點!$H$6/1000*$C$23*E21 -> 0 | F24: =F20*運營_站點!$H$6/1000*$C$23*F21 -> 0 | G24: =G20*運營_站點!$H$6/1000*$C$23*G21 -> 0 | K24: 具名站點有租約金額時才有意義；否則為 0
A25: 差額（基準 − 模型） | B25: US$bn | C25: =C24-C19 -> -0.23031376 | D25: =D24-D19 -> -0.53288254 | E25: =E24-E19 -> -0.65255591 | F25: =F24-F19 -> -0.76122927 | G25: =G24-G19 -> -0.81990264 | K25: 正值＝模型租金可能低估的金額
A26: 五期差額合計 | C26: =SUM(C25:G25) -> -2.9968841

Sheet 資產負債_既有債務
A1: 債務明細 — 季報（2026-06-30）逐筆＋存量利息推導
A2: 有效利率為現金票息口徑（可轉債＝票息 ÷ 到期累積倍數，本金以到期累積本金計）。本頁算出的存量利息連回『輸入』頁，再進入支出與資金頁
A4: 工具 | B4: 類別 | C4: 到期 | D4: 有效利率 | E4: 6/30 本金 | F4: 年化利息 | I4: 備註
A5: 2016 美元票據（2.0B） | B5: 無擔保 | C5: 2026-08 | D5: 0.0223 | E5: 2 | F5: =D5*E5 -> 0.0446 | I5: 10-Q 2026Q2 附註 6：面額 2,000、票面 2.00%、有效利率 2.23%、2026 到期 [Interested-party]
A6: 2020 美元票據（9.0B） | B6: 無擔保 | C6: 2040-08 | D6: 0.0163 | E6: 9 | F6: =D6*E6 -> 0.1467 | I6: 10-Q 附註 6：面額 9,000、有效利率 0.93%–2.33%（取中點）、到期 2027–2060；到期日取區間中段 [Assumed]
A7: 2025 美元票據（22.5B；含浮動 0.5B） | B7: 無擔保 | C7: 2045-05 | D7: 0.04895 | E7: 22.5 | F7: =D7*E7 -> 1.101375 | I7: 10-Q 附註 6：面額 22,500、有效利率 4.00%–5.79%（取中點）、到期 2028–2075；到期日取區間中段 [Assumed]
A8: 2025 歐元票據 | B8: 無擔保 | C8: 2042-11 | D8: 0.0354 | E8: 15.074 | F8: =D8*E8 -> 0.5336196 | I8: 10-Q 附註 6：面額 15,074（含匯率）、有效利率 2.57%–4.51%（取中點）、到期 2028–2064 [Assumed 到期日]
A9: 2026 美元票據（20.0B） | B9: 無擔保 | C9: 2041-02 | D9: 0.048 | E9: 20 | F9: =D9*E9 -> 0.96 | I9: 10-Q 附註 6：面額 20,000、加權票面 4.80%、加權年限 15 年（2026Q1 發行）[Interested-party]
A10: 2026 英鎊票據（£5.5B） | B10: 無擔保 | C10: 2057-02 | D10: 0.0531 | E10: 7.263 | F10: =D10*E10 -> 0.3856653 | I10: 10-Q 附註 6：面額 7,263、加權票面 5.31%、加權年限 31 年 [Interested-party]
A11: 2026 瑞士法郎票據（CHF3.1B） | B11: 無擔保 | C11: 2036-02 | D11: 0.0106 | E11: 3.772 | F11: =D11*E11 -> 0.0399832 | I11: 10-Q 附註 6：面額 3,772、加權票面 1.06%、加權年限 10 年 [Interested-party]
A12: 2026 歐元票據（€9.0B） | B12: 無擔保 | C12: 2039-05 | D12: 0.039 | E12: 10.239 | F12: =D12*E12 -> 0.399321 | I12: 10-Q 附註 6：面額 10,239、加權票面 3.90%、加權年限 13 年 [Interested-party]
A13: 2026 加幣票據（C$8.5B） | B13: 無擔保 | C13: 2041-05 | D13: 0.0435 | E13: 5.985 | F13: =D13*E13 -> 0.2603475 | I13: 10-Q 附註 6：面額 5,985、加權票面 4.35%、加權年限 15 年 [Interested-party]
A14: 2026 日圓票據（¥576.5B） | B14: 無擔保 | C14: 2034-05 | D14: 0.0265 | E14: 3.566 | F14: =D14*E14 -> 0.094499 | I14: 10-Q 附註 6：面額 3,566、加權票面 2.65%、加權年限 8 年 [Interested-party]
A15: 其他長期債（含信用額度動用 1.3B） | B15: 無擔保 | C15: 2030-04 | D15: 0.059 | E15: 1.686 | F15: =D15*E15 -> 0.099474 | I15: 10-Q 附註 6：其他長期債 1,686；信用額度動用 1,300 利率 SOFR＋1.5%–2.25%（約 5.9%，[Derived]）、至 2030-04 到期
A16: 合計（6/30） | E16: =SUM(E5:E15) -> 101.085 | F16: =SUM(F5:F15) -> 4.0655846 | I16: 應等於最新季報本金合計 101.085（company.json → latestQuarter.debtPrincipal）
A17: 加權有效利率 | D17: =F16/E16 -> 0.040219465 | I17: ＝年化利息 ÷ 本金（company.json → debt.instruments 的有效利率）
A19: 評價日後新發可轉債 | D19: 0 | E19: 0 | F19: =D19*E19 -> 0 | I19: company.json → debt.convertible（期後新發；不在五期還本表內，只計利息）
A21: 可轉債逐檔（若轉換法：有效轉換價 < 判斷價 → 視為轉股，不計利息與還本）
A22: 可轉債 | B22: 到期 | C22: 票息 | D22: 原始本金 | E22: 到期累積倍數 | F22: 轉換價 | G22: 到期所屬模型期 | H22: 強制轉換（1＝是） | I22: 備註
A23: 6.25% 強制轉換特別股（A、B 系列，2026-06） | B23: 2029-05 | C23: 0.0625 | D23: 19.25 | E23: 1 | F23: 352.56 | G23: 3 | H23: 1 | I23: 清算價 $19.25B（19.25M 股 × $1,000；385M 存託股）；2029-05-15 強制轉換：A 系列每股轉 2.2520–2.8160 股 A 股、B 系列 2.2740–2.8420 股 C 股 → 43.6–54.6M 股，一律轉股，取稀釋最大 54.6M 股（轉換價下限約 $352.56；8-K 2026-06-05 [Interested-party]）；6.25% 股利列於 defaults.dividend.preferred；權益，不列債務本金；capped call 上限 532.67（A）／527.80（C）未建模
I24: 到期所屬模型期：0＝首期 … 4＝末期、5＝模型期後（建置時依期末日推算）
A26: 可轉債（推導） | C26: 到期本金 | D26: 若轉換股數 | E26: 有效轉換價 | F26: 融資分類 | G26: 評價第一輪 | H26: 評價第二輪 | I26: 說明
A27: =A23 -> 6.25% 強制轉換特別股（A、B 系列，2026-06） | C27: =D23*E23 -> 19.25 | D27: =D23/F23 -> 0.054600635 | E27: =F23*E23 -> 352.56 | F27: =IF(OR(H23=1,E27<輸入與假設!$C$343),1,0) -> 1 | G27: =IF(OR(H23=1,E27<輸入與假設!$C$366),1,0) -> 1 | H27: =IF(OR(H23=1,E27<評價_DCF與目標價!$C$87),1,0) -> 1
A28: 合計 | C28: =SUM(C27:C27) -> 19.25 | D28: =SUM(D27:D27) -> 0.054600635 | I28: 分類 1＝轉股（若轉換法）、0＝債務。強制轉換者一律為 1。融資分類判斷價＝股權發行價；評價第一輪＝現價；第二輪＝MIN(現價, 第一輪加權目標價)
A30: 存量利息推導（本金依季報到期表遞減）
A31: 項目 | B31: 單位 | C31: 2026 | D31: 2027 | E31: 2028 | F31: 2029 | G31: 2030 | I31: 公式／來源說明
A32: 期初本金 | B32: US$bn | C32: =E16 -> 101.085 | D32: =C34 -> 99.085 | E32: =D34 -> 98.085 | F32: =E34 -> 95.409 | G32: =F34 -> 93.645 | I32: 2026 期初為 6/30 本金（模型期起點）
A33: 排程還本 | B33: US$bn | C33: =輸入與假設!C$361 -> 2 | D33: =輸入與假設!D$361 -> 1 | E33: =輸入與假設!E$361 -> 2.676 | F33: =輸入與假設!F$361 -> 1.764 | G33: =輸入與假設!G$361 -> 7.186 | I33: 季報到期表
A34: 期末本金 | B34: US$bn | C34: =C32-C33 -> 99.085 | D34: =D32-D33 -> 98.085 | E34: =E32-E33 -> 95.409 | F34: =F32-F33 -> 93.645 | G34: =G32-G33 -> 86.459
A35: 平均本金 | B35: US$bn | C35: =(C32+C34)/2 -> 100.085 | D35: =(D32+D34)/2 -> 98.585 | E35: =(E32+E34)/2 -> 96.747 | F35: =(F32+F34)/2 -> 94.527 | G35: =(G32+G34)/2 -> 90.052
A36: 存量債務利息 | B36: US$bn | C36: =C35*資產負債_既有債務!$D$17*輸入與假設!C$34 -> 2.0126826 | D36: =D35*資產負債_既有債務!$D$17*輸入與假設!D$34 -> 3.9650359 | E36: =E35*資產負債_既有債務!$D$17*輸入與假設!E$34 -> 3.8911126 | F36: =F35*資產負債_既有債務!$D$17*輸入與假設!F$34 -> 3.8018253 | G36: =G35*資產負債_既有債務!$D$17*輸入與假設!G$34 -> 3.6218432 | I36: ＝平均本金×加權有效利率×期間長度。限制：假設利率組合不變；可轉債折價攤銷（非現金）不計
A37: 期後新發可轉債利息 | B37: US$bn | C37: =資產負債_既有債務!$F$19*輸入與假設!C$34 -> 0 | D37: =資產負債_既有債務!$F$19*輸入與假設!D$34 -> 0 | E37: =資產負債_既有債務!$F$19*輸入與假設!E$34 -> 0 | F37: =資產負債_既有債務!$F$19*輸入與假設!F$34 -> 0 | G37: =資產負債_既有債務!$F$19*輸入與假設!G$34 -> 0
A38: 可轉債到期還本（債務處理） | B38: US$bn | C38: =IF(輸入與假設!$C$332=1,SUMPRODUCT((1-資產負債_既有債務!$F$27:$F$27)*資產負債_既有債務!$C$27:$C$27*(資產負債_既有債務!$G$23:$G$23=0)),0) -> 0 | D38: =IF(輸入與假設!$C$332=1,SUMPRODUCT((1-資產負債_既有債務!$F$27:$F$27)*資產負債_既有債務!$C$27:$C$27*(資產負債_既有債務!$G$23:$G$23=1)),0) -> 0 | E38: =IF(輸入與假設!$C$332=1,SUMPRODUCT((1-資產負債_既有債務!$F$27:$F$27)*資產負債_既有債務!$C$27:$C$27*(資產負債_既有債務!$G$23:$G$23=2)),0) -> 0 | F38: =IF(輸入與假設!$C$332=1,SUMPRODUCT((1-資產負債_既有債務!$F$27:$F$27)*資產負債_既有債務!$C$27:$C$27*(資產負債_既有債務!$G$23:$G$23=3)),0) -> 0 | G38: =IF(輸入與假設!$C$332=1,SUMPRODUCT((1-資產負債_既有債務!$F$27:$F$27)*資產負債_既有債務!$C$27:$C$27*(資產負債_既有債務!$G$23:$G$23=4)),0) -> 0 | I38: 融資分類為債務的可轉債，到期當期以到期累積本金現金還本
A39: 可轉債期末餘額（債務處理） | B39: US$bn | C39: =IF(輸入與假設!$C$332=1,SUMPRODUCT((1-資產負債_既有債務!$F$27:$F$27)*資產負債_既有債務!$C$27:$C$27*(資產負債_既有債務!$G$23:$G$23>0)),SUMPRODUCT((1-資產負債_既有債務!$F$27:$F$27)*資產負債_既有債務!$C$27:$C$27)) -> 0 | D39: =IF(輸入與假設!$C$332=1,SUMPRODUCT((1-資產負債_既有債務!$F$27:$F$27)*資產負債_既有債務!$C$27:$C$27*(資產負債_既有債務!$G$23:$G$23>1)),SUMPRODUCT((1-資產負債_既有債務!$F$27:$F$27)*資產負債_既有債務!$C$27:$C$27)) -> 0 | E39: =IF(輸入與假設!$C$332=1,SUMPRODUCT((1-資產負債_既有債務!$F$27:$F$27)*資產負債_既有債務!$C$27:$C$27*(資產負債_既有債務!$G$23:$G$23>2)),SUMPRODUCT((1-資產負債_既有債務!$F$27:$F$27)*資產負債_既有債務!$C$27:$C$27)) -> 0 | F39: =IF(輸入與假設!$C$332=1,SUMPRODUCT((1-資產負債_既有債務!$F$27:$F$27)*資產負債_既有債務!$C$27:$C$27*(資產負債_既有債務!$G$23:$G$23>3)),SUMPRODUCT((1-資產負債_既有債務!$F$27:$F$27)*資產負債_既有債務!$C$27:$C$27)) -> 0 | G39: =IF(輸入與假設!$C$332=1,SUMPRODUCT((1-資產負債_既有債務!$F$27:$F$27)*資產負債_既有債務!$C$27:$C$27*(資產負債_既有債務!$G$23:$G$23>4)),SUMPRODUCT((1-資產負債_既有債務!$F$27:$F$27)*資產負債_既有債務!$C$27:$C$27)) -> 0 | I39: 到期累積本金；關閉攤還時維持全額
A40: 可轉債票息（債務處理） | B40: US$bn | C40: =IF(輸入與假設!$C$332=1,SUMPRODUCT((1-資產負債_既有債務!$F$27:$F$27)*資產負債_既有債務!$D$23:$D$23*資產負債_既有債務!$C$23:$C$23*((資產負債_既有債務!$G$23:$G$23>0)+0.5*(資產負債_既有債務!$G$23:$G$23=0))),SUMPRODUCT((1-資產負債_既有債務!$F$27:$F$27)*資產負債_既有債務!$D$23:$D$23*資產負債_既有債務!$C$23:$C$23))*輸入與假設!C$34 -> 0 | D40: =IF(輸入與假設!$C$332=1,SUMPRODUCT((1-資產負債_既有債務!$F$27:$F$27)*資產負債_既有債務!$D$23:$D$23*資產負債_既有債務!$C$23:$C$23*((資產負債_既有債務!$G$23:$G$23>1)+0.5*(資產負債_既有債務!$G$23:$G$23=1))),SUMPRODUCT((1-資產負債_既有債務!$F$27:$F$27)*資產負債_既有債務!$D$23:$D$23*資產負債_既有債務!$C$23:$C$23))*輸入與假設!D$34 -> 0 | E40: =IF(輸入與假設!$C$332=1,SUMPRODUCT((1-資產負債_既有債務!$F$27:$F$27)*資產負債_既有債務!$D$23:$D$23*資產負債_既有債務!$C$23:$C$23*((資產負債_既有債務!$G$23:$G$23>2)+0.5*(資產負債_既有債務!$G$23:$G$23=2))),SUMPRODUCT((1-資產負債_既有債務!$F$27:$F$27)*資產負債_既有債務!$D$23:$D$23*資產負債_既有債務!$C$23:$C$23))*輸入與假設!E$34 -> 0 | F40: =IF(輸入與假設!$C$332=1,SUMPRODUCT((1-資產負債_既有債務!$F$27:$F$27)*資產負債_既有債務!$D$23:$D$23*資產負債_既有債務!$C$23:$C$23*((資產負債_既有債務!$G$23:$G$23>3)+0.5*(資產負債_既有債務!$G$23:$G$23=3))),SUMPRODUCT((1-資產負債_既有債務!$F$27:$F$27)*資產負債_既有債務!$D$23:$D$23*資產負債_既有債務!$C$23:$C$23))*輸入與假設!F$34 -> 0 | G40: =IF(輸入與假設!$C$332=1,SUMPRODUCT((1-資產負債_既有債務!$F$27:$F$27)*資產負債_既有債務!$D$23:$D$23*資產負債_既有債務!$C$23:$C$23*((資產負債_既有債務!$G$23:$G$23>4)+0.5*(資產負債_既有債務!$G$23:$G$23=4))),SUMPRODUCT((1-資產負債_既有債務!$F$27:$F$27)*資產負債_既有債務!$D$23:$D$23*資產負債_既有債務!$C$23:$C$23))*輸入與假設!G$34 -> 0 | I40: ＝原始本金 × 票息 × 期間長度；到期當期計半期
A41: 首期新增借款利息校準 | B41: US$bn | C41: =0 -> 0 | D41: =0 -> 0 | E41: =0 -> 0 | F41: =0 -> 0 | G41: =0 -> 0 | I41: 讓首期模型利息對上公司季度利息指引的校準值（company.json → defaults.intCal）；無指引時為 0
A42: 存量利息合計（連回輸入頁） | B42: US$bn | C42: =C36+C37+C40+C41 -> 2.0126826 | D42: =D36+D37+D40+D41 -> 3.9650359 | E42: =E36+E37+E40+E41 -> 3.8911126 | F42: =F36+F37+F40+F41 -> 3.8018253 | G42: =G36+G37+G40+G41 -> 3.6218432 | I42: ＝存量債務利息＋期後新發可轉債利息＋可轉債票息＋首期校準

Sheet 資產負債_新債與新股
A1: 新債與新股（類資產負債表：現金、債務、股本、槓桿）
A2: 全部為連結公式。2026 欄的現金自 2026-06-30 起算（模型期），與 HTML『資產與負債 → 新債與新股』同口徑
A4: 項目 | B4: 單位 | C4: 2026 | D4: 2027 | E4: 2028 | F4: 2029 | G4: 2030 | I4: 公式／來源說明
A5: 現金
A6: 期初現金 | B6: US$bn | C6: =輸入與假設!$C$327 -> 155.411 | D6: =各期收支!C56 -> 128.12291 | E6: =各期收支!D56 -> 85.935507 | F6: =各期收支!E56 -> 63.440965 | G6: =各期收支!F56 -> 53.700182 | I6: 2026＝6/30 現金（模型期起點）
A7: 營運收支淨額（含期後股權／可轉債，不含瀑布） | B7: US$bn | C7: =各期收支!C103-輸入與假設!$C$327 -> -18.786593 | D7: =各期收支!D103-各期收支!C103 -> -25.184399 | E7: =各期收支!E103-各期收支!D103 -> -5.4915424 | F7: =各期收支!F103-各期收支!E103 -> 7.2622166 | G7: =各期收支!G103-各期收支!F103 -> -85.215953 | I7: ＝融資前累積現金的當期變動；負值即當期外部資金需求
A8: ＋ 瀑布：新債（額度＋資產層） | B8: US$bn | C8: =各期收支!C86 -> 0 | D8: =各期收支!D86 -> 0 | E8: =各期收支!E86 -> 0 | F8: =各期收支!F86 -> 0 | G8: =各期收支!G86 -> 85.806075
A9: ＋ 瀑布：可轉債 | B9: US$bn | C9: =各期收支!C89 -> 0 | D9: =各期收支!D89 -> 0 | E9: =各期收支!E89 -> 0 | F9: =各期收支!F89 -> 0 | G9: =各期收支!G89 -> 0
A10: ＋ 瀑布：高息債 | B10: US$bn | C10: =各期收支!C93 -> 0 | D10: =各期收支!D93 -> 0 | E10: =各期收支!E93 -> 0 | F10: =各期收支!F93 -> 0 | G10: =各期收支!G93 -> 0
A11: ＋ 瀑布：股權募資 | B11: US$bn | C11: =各期收支!C92 -> 0 | D11: =各期收支!D92 -> 0 | E11: =各期收支!E92 -> 0 | F11: =各期收支!F92 -> 0 | G11: =各期收支!G92 -> 0
A12: − 回購（瀑布第二步） | B12: US$bn | C12: =-各期收支!C76 -> -8.5015 | D12: =-各期收支!D76 -> -17.003 | E12: =-各期收支!E76 -> -17.003 | F12: =-各期收支!F76 -> -17.003 | G12: =-各期收支!G76 -> 0
A13: − 新融資利息（新債＋可轉債＋高息債） | B13: US$bn | C13: =-各期收支!C94 -> 0 | D13: =-各期收支!D94 -> 0 | E13: =-各期收支!E94 -> 0 | F13: =-各期收支!F94 -> 0 | G13: =-各期收支!G94 -> -4.2903038
A14: 期末現金 | B14: US$bn | C14: =SUM(C6:C13) -> 128.12291 | D14: =SUM(D6:D13) -> 85.935507 | E14: =SUM(E6:E13) -> 63.440965 | F14: =SUM(F6:F13) -> 53.700182 | G14: =SUM(G6:G13) -> 50 | I14: 應等於『各期收支』期末累積現金（見下列驗算）
