Workbook

Sheet README
A1: Alphabet（GOOGL）個股模型 v0.3.1（2026-10-29；2026Q3 季度滾動）— 命題模組＋官方營收分部 → 損益表
A3: 命題：AI 改變搜尋之後，Google Search 的變現能否守住，同時 Google Cloud（含 TPU）能否把翻倍的資本支出變成營收；資本支出與 2026 年股權發行後的每股價值是否高於現價。
A4: 核心問題：Search & other 在 C 情境（AI 助理分流、每次查詢變現下降）下 FY2028 營收與利益率會掉多少，Cloud 的 AI 營收能否抵銷；加計 AI 折舊與股權發行後的每股價值。
A5: ="投資建議："&Val!B14&"（加權目標價 US$"&TEXT(Val!B8,"0.00")&"，上檔空間 "&TEXT(Val!B11,"+0.0%;-0.0%")&"；現價 "&TEXT(px,"0.00")&"，2026-10-28 收盤）" -> 投資建議：中立（加權目標價 US$258.21，上檔空間 -20.5%；現價 324.89，2026-10-28 收盤）
A6: ="重點觀察 1：目標價 "&TEXT(Val!B8,"0")&"＝DCF "&TEXT(Val!B6,"0")&"、分部加總 "&TEXT(Val!B7,"0")&" 各半；情境 A／B／C 為 "&TEXT(Val!B17,"0")&"／"&TEXT(Val!C17,"0")&"／"&TEXT(Val!D17,"0")&"，DCF 終值占 EV "&TEXT(Val!C19,"0%")&"（B）。市場共識目標價 "&TEXT(cons_tp,"0")&"。" -> 重點觀察 1：目標價 258＝DCF 189、分部加總 327 各半；情境 A／B／C 為 282／262／226，DCF 終值占 EV 79%（B）。市場共識目標價 429。
A7: ="重點觀察 2：C 情境 FY2028 Search & other "&TEXT(PL!I131,"0.0")&"（比 B 少 "&TEXT(1-PL!I131/PL!I72,"0.0%")&"），Google Services 營業利益率 "&TEXT(PL!I169,"0.0%")&"（B "&TEXT(PL!I110,"0.0%")&"）；同年 Cloud AI 營收 "&TEXT(PL!I77,"0.0")&"、Google Cloud 營業利益 "&TEXT(PL!I94,"0.0")&"，Cloud 營業利益比 FY2025 增加 "&TEXT(PL!I94-PL!D94,"0.0")&"，是 C 情境 Services 營業利益損失 "&TEXT(PL!I91-PL!I150,"0.0")&" 的 "&TEXT((PL!I94-PL!D94)/(PL!I91-PL!I150),"0%")&"（Cloud 的成長足以抵銷搜尋被侵蝕的利潤）。" -> 重點觀察 2：C 情境 FY2028 Search & other 284.2（比 B 少 14.5%），Google Services 營業利益率 30.4%（B 34.3%）；同年 Cloud AI 營收 57.3、Google Cloud 營業利益 85.8，Cloud 營業利益比 FY2025 增加 71.9，是 C 情境 Services 營業利益損失 33.5 的 214%（Cloud 的成長足以抵銷搜尋被侵蝕的利潤）。
A8: ="重點觀察 3：AI 折舊進損益——情境 B 新增 AI 折舊 FY2028 "&TEXT(PL!I104,"0.0")&"，合併營業利益率由 FY2025 "&TEXT(PL!D109,"0.0%")&" 變為 FY2028 "&TEXT(PL!I109,"0.0%")&"；收支關卡（FY2026–2030 自由現金流扣股利合計）B "&TEXT(CF!C6,"0.0")&"，"&CF!C9&"。" -> 重點觀察 3：AI 折舊進損益——情境 B 新增 AI 折舊 FY2028 65.1，合併營業利益率由 FY2025 32.0% 變為 FY2028 22.4%；收支關卡（FY2026–2030 自由現金流扣股利合計）B -0.6，需要舉債且減少回購。
A10: 驅動 → 推導對照表（每頁輸入、推導量、因果方向）
A11: 頁 | B11: 輸入（In 頁鍵） | C11: 推導量 | D11: 因果方向
A12: Thesis | B12: pace、ext_sh、mw_tot0、k（kl_px、ks_px、long_sh）、Tokenomics IF_HoldEcon／OpexGW／CapexIT | C12: Cloud AI 營收與 EBITDA、AI 資本支出、新增 AI 折舊、自用 AI 增量成本 | D12: MW → 收入（× 每 MW 持有成本 × k）；MW → 資本支出 → 折舊 → 分部營業利益
A13: Seg | B13: g0（Q 頁近四季）、gl_*、conv_n、dA／mA／dC／mC、tpu_*、ob_rev_* | C13: 四條產品線、三個分部、合併營收；非 AI 資本支出與折舊 | D13: 近四季年增 → 長期值；Search＝B 路徑 ×(1 − 分流)×(1＋變現變動)
A14: PL | B14: m_svc、inc_m、m_co、tpu_m、abc_rate、svc_sh、da_base、tax | C14: 分部 EBITDA、分部營業利益、合併營業利益、淨利、EPS | D14: 分部營收 → 分部 EBITDA − 折舊 → 營業利益 → 業外、稅 → EPS
A15: CF | B15: sbc_r、wc_*、dps、bb_t、min_cash、mat_*、anth_* | C15: 自由現金流、股利、回購、新債、淨現金、收支關卡 | D15: 淨利＋折舊 − 資本支出 → 自由現金流 → 股利 → 回購／舉債
A16: Val | B16: rf、beta、erp、kd、g_tv、ronic、同業倍數、持股、tp_w*、w_dcf | C16: DCF、分部加總、目標價、上檔空間、投資建議 | D16: 無槓桿 FCF 折現＋分部 EBITDA × 倍數 → 情境加權 → 50／50
A17: Sens | B17: In 頁低／高值 | C17: 加權目標價變動 | D17: 一次改一個輸入、整本重算
A19: 與 v0.3 的差異（v0.3.1：2026Q3 季度滾動）
A20: Q 頁加入 2026Q3（保留 2024Q4–2026Q3 八季）；FY2026＝9M 實績＋Q4 模型；評價日 2026-06-30 → 2026-09-30，目標日 2027-10-29（約 12 個月後）。
A21: Tokenomics v21.4 → v21.7（快照重取；契約名稱只有 IF_NonNV_Hold_TPU 改變）；TPU 係數由「同期 NVIDIA 世代 × 1.0」改讀 IF_NonNV_Hold_TPU（0.70），舊口徑列 Sens。
A22: C10：2026 資本支出指引維持 195–205 → AI MW 速度以 9M 實績 131.95＋Q4 公式＝200 重解。
A23: WACC 權益權重與回購價改用評價日股價（2026-09-30 收盤 344.08），現價只影響上檔空間與評等。
A24: 架構與 v0.3 相同（命題＋官方分部 → 損益表；讀法 2 主值）；v0.2.2 → v0.3 的差異見 dist/_待刪除/ 的 v0.3 成品與 docs/reports/20261027_alphabet_v0.3_分部架構.md。
A26: 工作表：README → In → Q → Thesis → Seg → PL → CF → Val → Recon → Sens → Sources。藍字＝輸入、黑字＝公式；黃底＝判斷題。建置：bash alphabet/make_v03.sh
A27: 數字標記：Verified（經查核）／Interested-party（公司或賣方自述）／Analogy／Assumed（給區間）／Derived（換算）。本模型是研究整理，不是投資建議以外的保證。

Sheet In
A1: In — 輸入（藍字；基準欄 E 進主模型；D／F＝敏感度低／高，只用於 Sens 頁、不進目標價；情境 A／B／C 的驅動見本頁最後一節「情境驅動對照」〔v0.3.3〕）。金額 US$B；每股 US$；股數十億股；MW＝IT MW。標記：Verified／Interested-party／Analogy／Assumed／Derived（Analogy、Assumed 一律給低／高區間）
A2: 「沿用 v0.2.2」＝MAG v0.2.2 已核准的參數（原出處：alphabet/legacy_v0.2/company.json、kspec.py、data/kevidence_alphabet_20261008.json；對照表 r1 C1–C23）。v0.3.1：Tokenomics 升級 v21.7（data/tokenomics_snapshot_v21.7.json）、2026Q3 實績（data/alphabet_facts_2026q3.json）、評價日 2026-09-30。黃底＝判斷題（Andy 可改）
A3: 鍵 | B3: 項目 | C3: 單位 | D3: 敏感度低 | E3: 基準 | F3: 敏感度高 | G3: 標記 | H3: 來源 | I3: 說明
A4: A. 現價、股數與資產負債（評價日 2026-09-30；2026Q3 財報新聞稿，10-Q 尚未提供）
A5: px | B5: 現價（2026-10-28 收盤） | C5: US$ | E5: 324.89 | G5: Verified | H5: BigGo Finance https://finance.biggo.com/news/747b8ed4-8d02-4fc5-84ac-f68ab61a7d20（10-28 收盤 324.89、盤後 294.20）；Investing.com GOOGL 報價 324.89（+1.34%）https://www.investing.com/news/company-news/alphabet-q3-2026-slides-128b-revenue-overshadowed-by-profit-miss-93CH-4981067（2026-10-29 讀取） | I5: 只影響上檔空間與評等（v0.3.1 起與 WACC、回購價脫鉤，見 px_val）。財報後盤後約 288–294（−9%～−11%）；10-29 收盤尚未產生。v0.3 現價 316.80（2026-10-26）
A6: px_val | B6: 評價日股價（2026-09-30 收盤；WACC 權益權重與回購價用） | C6: US$ | E6: 344.08 | G6: Verified | H6: FinancialContent GOOGL 歷史股價 https://www.financialcontent.com/quote/NQ%3AGOOGL/historical（2026-10-29 讀取：9/30 收盤 344.08；同頁 10/07 350.50、10/23 320.21 與 StockAnalysis 相同） | I6: v0.3.1 新增：評價日市值權重（與評價日一致）；v0.3 以現價代用
A7: sh_out | B7: 流通股數（2026-09-30，資產負債表股本說明） | C7: 十億股 | E7: 12.294 | G7: Interested-party | H7: mag/extract/docs/2026Q3/alphabet_2026Q3_新聞稿.pdf 第 4 頁資產負債表股本說明（2026-10-28；事實總帳 sh.out.20260930） | I7: 10-Q 封面股數尚未提供；Class A 5,888＋B 828＋C 5,578 百萬股
A8: sh_dil_q2 | B8: 2026Q3 稀釋加權股數 | C8: 十億股 | E8: 12.368 | G8: Interested-party | H8: mag/extract/docs/2026Q3/alphabet_2026Q3_新聞稿.pdf 第 5 頁（2026-10-28；事實總帳 sh.dilW.2026q3）
A9: sh_basic_q2 | B9: 2026Q3 基本加權股數 | C9: 十億股 | E9: 12.256 | G9: Interested-party | H9: mag/extract/docs/2026Q3/alphabet_2026Q3_新聞稿.pdf 第 5 頁（2026-10-28；事實總帳 sh.basicW.2026q3） | I9: Q3 ATM 發行 36M 股（在季內加權）；期末稀釋股數＝Q3 稀釋加權＋(9/30 流通股 − Q3 基本加權)
A10: conv_sh | B10: 強制轉換特別股 2029-05-15 轉換股數（上限） | C10: 十億股 | D10: 0.0436 | E10: 0.0546 | F10: 0.0546 | G10: Interested-party | H10: 8-K 2026-06-05：A 系列每股轉 2.2520–2.8160 股、B 系列 2.2740–2.8420 股 → 43.6–54.6M 股；沿用 v0.2.2（legacy_v0.2/company.json） debt.convertibles | I10: 取稀釋最大（保守）；評價時直接加入股數，特別股股利照付至轉換
A11: cash_0 | B11: 現金＋債權類有價證券（2026-09-30） | C11: US$B | E11: 174.698 | G11: Derived | H11: 新聞稿資產負債表：現金 56.334＋有價證券 208.764＝265.098 − 其中權益證券 90.4（法說；事實總帳 bs.cashTotal.2026q3、mkt.eqsec.2026q3） | I11: 10-Q 附註 3 尚未提供：權益證券以法說 90.4 代用（資料缺口）；2026-06-30 為 155.411
A12: cash_ye25 | B12: 現金＋債權類有價證券（2025-12-31） | C12: US$B | E12: 120.53 | G12: Derived | H12: 10-K 2025：30.708＋96.135 − 6.313（沿用 v0.2.2（legacy_v0.2/company.json） ytdActual.cash1231）
A13: debt_0 | B13: 債務面額（2026-09-30） | C13: US$B | E13: 126.455 | G13: Derived | H13: 2026-06-30 面額 101.085（10-Q 附註 6）＋Q3 發債淨額 28.996 − Q3 償還 3.626（新聞稿現金流量表） | I13: 10-Q 附註 6 尚未提供（資料缺口）；對照：資產負債表長期債務帳面 125.102（不含一年內到期）
A14: fines | B14: 應計罰款與和解（類債） | C14: US$B | E14: 12.156 | G14: Derived | H14: 2026-06-30 餘額 17.356（10-Q 2026Q2）− Q3 已付歐盟罰款 5.2（法說） | I14: 10-Q 尚未提供；v0.3 以 6/30 餘額扣除（付款在 Q3）
A15: nci | B15: 非控制權益（類債） | C15: US$B | E15: 7.1 | G15: Interested-party | H15: 10-Q 2026Q2（事實總帳 bs.nci；Waymo 等少數股權） | I15: 沿用 2026Q2（10-Q 尚未提供）
A16: B. 持股（分部加總與 DCF 皆加入；非上市 × (1 − 流動性折價)；上市不折價）
A17: ant_val | B17: Anthropic 最近一輪投後估值（Series H） | C17: US$B | E17: 965 | G17: Interested-party | H17: TechCrunch〈Anthropic raises $65 billion, nears $1T valuation ahead of IPO〉（經 anthropic/ SRC_ANT_299）（2026-05-28；事實總帳 rp.anthropic.val.seriesH）
A18: ant_stake | B18: Anthropic 持股比例 | C18: % | D18: 0.11 | E18: 0.125 | F18: 0.14 | G18: Assumed | H18: 一手不存在：2025 法院文件約 14%；非上市證券帳面 124.3B ÷ 965B 隱含上限 12.9%（沿用 v0.2.2（legacy_v0.2/company.json） valuation.holdings）
A19: illiq | B19: 非上市持股流動性折價 | C19: % | D19: 0 | E19: 0.2 | F19: 0.4 | G19: Assumed | H19: 工作單第 2 節 Val 0.2（1 − 流動性折價 20%）；對照表 r1 第 5 節第 9 條
A20: spacex | B20: SpaceX 持股公允價值（上市、限售；2026-09-30） | C20: US$B | E20: 85.436 | G20: Derived | H20: 2026-06-30 94.1（10-Q 附註 3：短期 80.0＋長期限售 14.1）＋Q3 權益證券淨損益 −8.664（新聞稿第 8 頁；法說：主要為 SpaceX 未實現損失） | I20: 假設 Q3 權益證券損失全數來自 SpaceX；10-Q 附註 3 尚未提供（資料缺口）
A21: oth_eq | B21: 其他有價權益證券 | C21: US$B | E21: 7.089 | G21: Derived | H21: 有價權益證券 87.063＋14.126 − SpaceX 94.1（沿用 v0.2.2（legacy_v0.2/company.json））
A22: C. 折現率與目標價規則
A23: rf | B23: 無風險利率（10 年美債，2026-10-27） | C23: % | E23: 0.0499 | G23: Verified | H23: 美國財政部每日殖利率曲線（Daily Treasury Par Yield Curve Rates，10 Yr）https://home.treasury.gov/resource-center/data-chart-center/interest-rates/TextView?type=daily_treasury_yield_curve&field_tdr_date_value_month=202610（2026-10-29 讀取）：10-27 4.99%、10-26 5.00%（最新公布日 10-27） | I23: v0.3 為 5.00%（10-26）
A24: beta_sa | B24: 原始 β：StockAnalysis 5 年月資料（Yahoo、MarketBeat 同值） | C24: x | E24: 1.21 | G24: Verified | H24: StockAnalysis〈GOOGL statistics〉（2026-10-07；事實總帳 val.beta.sa） | I24: 沿用 v0.2.2（legacy_v0.2/company.json）
A25: beta_gf | B25: 原始 β：GuruFocus 3 年 | C25: x | E25: 1.3669 | G25: Verified | H25: GuruFocus〈GOOGL Beta〉（2026-10-08；事實總帳 val.beta.gurufocus） | I25: 與 StockAnalysis 不同資料商、不同期間（C13）
A26: blume_a | B26: Blume 調整係數（β 調整＝a × 原始 β＋(1 − a)） | C26: x | E26: 0.67 | G26: Derived | H26: Blume（1971）；Bloomberg 調整 β 同式（修正一 F4）
A27: beta | B27: β（Blume 調整後兩個獨立來源的中位數） | C27: x | D27: 1.1407 | E27: =MEDIAN(blume_a*beta_sa+1-blume_a,blume_a*beta_gf+1-blume_a) -> 1.1932615 | F27: 1.2458 | G27: Derived | H27: 修正一 F4：Blume 調整（0.67 × 原始 β＋0.33），兩個獨立來源取中位數 | I27: 低／高＝兩個來源各自的調整值；v0.3 修正前用原始 β 平均 1.288
A28: erp | B28: 股權風險溢酬 | C28: % | D28: 0.04 | E28: 0.05 | F28: 0.06 | G28: Assumed | H28: 沿用 v0.2.2（legacy_v0.2/company.json）（val.erp）
A29: kd_sp | B29: 約 10 年期 AA 公司債利差（相對 10 年美債） | C29: % | D29: 0.004 | E29: 0.006 | F29: 0.009 | G29: Assumed | H29: 判斷：Aa2／AA+（事實總帳 debt.rating）10 年期利差約 50–90bp；2066 長債發行利差 T＋130bp 為 40 年期，不採（修正一 F4）
A30: kd | B30: 稅前債務成本（約 10 年期）＝rf＋利差 | C30: % | E30: =rf+kd_sp -> 0.0559 | G30: Derived | H30: 修正一 F4：kd＝約 10 年期公司債殖利率 | I30: v0.3 修正前用 2066 票據 6.527%（Alphabet 定價條款 FWP（2026-08-06；US$25B 票據）（2026-08-06；事實總帳 val.kd.2066））
A31: fin_lease | B31: 融資租賃負債（2026-06-30） | C31: US$B | E31: 2.59 | G31: Interested-party | H31: 10-Q 2026Q2 附註 4（事實總帳 lease.finLiab） | I31: 計入 WACC 負債與 DCF、分部加總的淨負債（修正一 F6）
A32: wacc_adj | B32: WACC 調整（Sens 格：±1pt） | C32: % | D32: -0.01 | E32: 0 | F32: 0.01 | G32: Assumed | H32: 修正一 F4：WACC ±1 個百分點的目標價格
A33: tax_w | B33: WACC 用稅率（2025 有效稅率） | C33: % | E33: 0.168 | G33: Derived | H33: 10-K 2025：所得稅 26.656 ÷ 稅前 158.826 | I33: 沿用 v0.2.2（legacy_v0.2/company.json）
A34: g_tv | B34: 永續成長率（FY2032 後） | C34: % | D34: 0.02 | E34: 0.03 | F34: 0.04 | G34: Assumed | H34: 工作單第 2 節 Val 0.1（g 3%）
A35: ronic_sp | B35: 永續期新投資報酬率 RONIC 相對 WACC 的差 | C35: % | E35: 0 | F35: 0.05 | G35: Assumed | H35: 修正一 F5：RONIC＝WACC（判斷；終值＝NOPAT(FY2033) ×(1 − g ÷ RONIC) ÷ (WACC − g)） | I35: Sens：WACC＋5pt；修正前固定 12%
A36: mid | B36: 期中慣例：年度現金流距年初 | C36: 年 | E36: 0.5 | G36: Derived | H36: 年度現金流平均發生在年中；Q4 26 為評價日後 0.125 年
A37: t_val | B37: 評價日（2026-09-30）的年份小數 | C37: 年 | E37: 2026.75 | G37: Derived | H37: v0.3.1：評價日由 2026-06-30（2026.5）滾到 2026-09-30；年度折現年數＝年度＋mid − t_val
A38: t_q4 | B38: Q4 26 現金流折現年數（評價日 2026-09-30 起，期中） | C38: 年 | E38: 0.125 | G38: Derived | H38: 2026-10-01～12-31 的中點
A39: tp_wA | B39: 情境權重 A | C39: % | E39: 0.25 | G39: Assumed | H39: 工作單第 2 節 Val 0.3（A 25%／B 50%／C 25%）
A40: tp_wB | B40: 情境權重 B | C40: % | E40: 0.5 | G40: Assumed | H40: 同上
...

Sheet Q
A1: Q — 實績（US$B；EPS 美元；股數十億股）。資料取自 data/alphabet_facts_20261008.json（MAG v0.1a 起的 SEC 一手資料）與 data/alphabet_facts_2026q3.json（2026Q3 新聞稿，v0.3.1）；季度數＝財報新聞稿 [Interested-party，10-Q 核閱]，年度＝10-K [Verified]
A2: 核對列（實績必須為 0）：產品線合計＝Google Services、分部合計＝合併營收、分部營業利益合計＝合併營業利益（Alphabet-level activities 含避險損益營收與未分攤費用）、營收 − 成本費用＝營業利益、FY2025 四季合計＝年報
A3: 項目 | B3: 2024Q4 | C3: 2025Q1 | D3: 2025Q2 | E3: 2025Q3 | F3: 2025Q4 | G3: 2026Q1 | H3: 2026Q2 | I3: 2026Q3 | J3: FY2024 | K3: FY2025 | L3: 9M26 | M3: 近四季 TTM | N3: 前四季 | O3: 標記 | P3: 來源
A4: 營收（官方分部與產品線）
A5: Google Search & other | B5: 54.034 | C5: 50.702 | D5: 54.19 | E5: 56.567 | F5: 63.073 | G5: 60.399 | H5: 63.271 | I5: 63.35 | J5: 198.084 | K5: 224.532 | L5: =G5+H5+I5 -> 187.02 | M5: =SUM(F5:I5) -> 250.093 | N5: =SUM(B5:E5) -> 215.493 | O5: Verified（年）／Interested-party（季） | P5: 季：Alphabet 財報新聞稿（8-K 附件 99.1，各季；事實總帳 is.*.2024q4–2026q2；2026Q3＝mag/extract/docs/2026Q3/alphabet_2026Q3_新聞稿.pdf，事實總帳 alphabet_facts_2026q3.json）；年：Form 10-K FY2024、FY2025（經查核）
A6: YouTube ads | B6: 10.473 | C6: 8.927 | D6: 9.796 | E6: 10.261 | F6: 11.383 | G6: 9.883 | H6: 11.055 | I6: 11.207 | J6: 36.147 | K6: 40.367 | L6: =G6+H6+I6 -> 32.145 | M6: =SUM(F6:I6) -> 43.528 | N6: =SUM(B6:E6) -> 39.457 | O6: Verified（年）／Interested-party（季） | P6: 季：Alphabet 財報新聞稿（8-K 附件 99.1，各季；事實總帳 is.*.2024q4–2026q2；2026Q3＝mag/extract/docs/2026Q3/alphabet_2026Q3_新聞稿.pdf，事實總帳 alphabet_facts_2026q3.json）；年：Form 10-K FY2024、FY2025（經查核）
A7: Google Network | B7: 7.954 | C7: 7.256 | D7: 7.354 | E7: 7.354 | F7: 7.828 | G7: 6.971 | H7: 7.303 | I7: 7.455 | J7: 30.359 | K7: 29.792 | L7: =G7+H7+I7 -> 21.729 | M7: =SUM(F7:I7) -> 29.557 | N7: =SUM(B7:E7) -> 29.918 | O7: Verified（年）／Interested-party（季） | P7: 季：Alphabet 財報新聞稿（8-K 附件 99.1，各季；事實總帳 is.*.2024q4–2026q2；2026Q3＝mag/extract/docs/2026Q3/alphabet_2026Q3_新聞稿.pdf，事實總帳 alphabet_facts_2026q3.json）；年：Form 10-K FY2024、FY2025（經查核）
A8: Google subscriptions, platforms, and devices | B8: 11.633 | C8: 10.379 | D8: 11.203 | E8: 12.87 | F8: 13.578 | G8: 12.384 | H8: 12.911 | I8: 14.29 | J8: 40.34 | K8: 48.03 | L8: =G8+H8+I8 -> 39.585 | M8: =SUM(F8:I8) -> 53.163 | N8: =SUM(B8:E8) -> 46.085 | O8: Verified（年）／Interested-party（季） | P8: 季：Alphabet 財報新聞稿（8-K 附件 99.1，各季；事實總帳 is.*.2024q4–2026q2；2026Q3＝mag/extract/docs/2026Q3/alphabet_2026Q3_新聞稿.pdf，事實總帳 alphabet_facts_2026q3.json）；年：Form 10-K FY2024、FY2025（經查核）
A9: Google Services（分部） | B9: 84.094 | C9: 77.264 | D9: 82.543 | E9: 87.052 | F9: 95.862 | G9: 89.637 | H9: 94.54 | I9: 96.302 | J9: 304.93 | K9: 342.721 | L9: =G9+H9+I9 -> 280.479 | M9: =SUM(F9:I9) -> 376.341 | N9: =SUM(B9:E9) -> 330.953 | O9: Verified（年）／Interested-party（季） | P9: 季：Alphabet 財報新聞稿（8-K 附件 99.1，各季；事實總帳 is.*.2024q4–2026q2；2026Q3＝mag/extract/docs/2026Q3/alphabet_2026Q3_新聞稿.pdf，事實總帳 alphabet_facts_2026q3.json）；年：Form 10-K FY2024、FY2025（經查核）
A10: 檢查：產品線合計 − Google Services | B10: =B5+B6+B7+B8-B9 -> 0 | C10: =C5+C6+C7+C8-C9 -> 0 | D10: =D5+D6+D7+D8-D9 -> 0 | E10: =E5+E6+E7+E8-E9 -> 0 | F10: =F5+F6+F7+F8-F9 -> 0 | G10: =G5+G6+G7+G8-G9 -> 0 | H10: =H5+H6+H7+H8-H9 -> 0 | I10: =I5+I6+I7+I8-I9 -> 0 | ... K10: =K5+K6+K7+K8-K9 -> 0 | L10: =G10+H10+I10 -> 0 | M10: =SUM(F10:I10) -> 0 | N10: =SUM(B10:E10) -> 0 | O10: — | P10: —
A11: Google Cloud（分部） | B11: 11.955 | C11: 12.26 | D11: 13.624 | E11: 15.157 | F11: 17.664 | G11: 20.028 | H11: 24.768 | I11: 30.709 | J11: 43.229 | K11: 58.705 | L11: =G11+H11+I11 -> 75.505 | M11: =SUM(F11:I11) -> 93.169 | N11: =SUM(B11:E11) -> 52.996 | O11: Verified（年）／Interested-party（季） | P11: 季：Alphabet 財報新聞稿（8-K 附件 99.1，各季；事實總帳 is.*.2024q4–2026q2；2026Q3＝mag/extract/docs/2026Q3/alphabet_2026Q3_新聞稿.pdf，事實總帳 alphabet_facts_2026q3.json）；年：Form 10-K FY2024、FY2025（經查核）
A12: Other Bets（分部） | B12: 0.4 | C12: 0.45 | D12: 0.373 | E12: 0.344 | F12: 0.37 | G12: 0.411 | H12: 0.382 | I12: 0.372 | J12: 1.648 | K12: 1.537 | L12: =G12+H12+I12 -> 1.165 | M12: =SUM(F12:I12) -> 1.535 | N12: =SUM(B12:E12) -> 1.567 | O12: Verified（年）／Interested-party（季） | P12: 季：Alphabet 財報新聞稿（8-K 附件 99.1，各季；事實總帳 is.*.2024q4–2026q2；2026Q3＝mag/extract/docs/2026Q3/alphabet_2026Q3_新聞稿.pdf，事實總帳 alphabet_facts_2026q3.json）；年：Form 10-K FY2024、FY2025（經查核）
A13: Hedging gains (losses)（Alphabet-level） | B13: 0.02 | C13: 0.26 | D13: -0.112 | E13: -0.207 | F13: -0.068 | G13: -0.18 | H13: 0.106 | I13: 0.194 | J13: 0.211 | K13: -0.127 | L13: =G13+H13+I13 -> 0.12 | M13: =SUM(F13:I13) -> 0.052 | N13: =SUM(B13:E13) -> -0.039 | O13: Verified（年）／Interested-party（季） | P13: 季：Alphabet 財報新聞稿（8-K 附件 99.1，各季；事實總帳 is.*.2024q4–2026q2；2026Q3＝mag/extract/docs/2026Q3/alphabet_2026Q3_新聞稿.pdf，事實總帳 alphabet_facts_2026q3.json）；年：Form 10-K FY2024、FY2025（經查核）
A14: 合併營收 | B14: 96.469 | C14: 90.234 | D14: 96.428 | E14: 102.346 | F14: 113.828 | G14: 109.896 | H14: 119.796 | I14: 127.577 | J14: 350.018 | K14: 402.836 | L14: =G14+H14+I14 -> 357.269 | M14: =SUM(F14:I14) -> 471.097 | N14: =SUM(B14:E14) -> 385.477 | O14: Verified（年）／Interested-party（季） | P14: 季：Alphabet 財報新聞稿（8-K 附件 99.1，各季；事實總帳 is.*.2024q4–2026q2；2026Q3＝mag/extract/docs/2026Q3/alphabet_2026Q3_新聞稿.pdf，事實總帳 alphabet_facts_2026q3.json）；年：Form 10-K FY2024、FY2025（經查核）
A15: 檢查：分部合計＋避險 − 合併營收 | B15: =B9+B11+B12+B13-B14 -> 0 | C15: =C9+C11+C12+C13-C14 -> 0 | D15: =D9+D11+D12+D13-D14 -> 0 | E15: =E9+E11+E12+E13-E14 -> 0 | F15: =F9+F11+F12+F13-F14 -> 0 | G15: =G9+G11+G12+G13-G14 -> 0 | H15: =H9+H11+H12+H13-H14 -> 0 | I15: =I9+I11+I12+I13-I14 -> 0 | ... K15: =K9+K11+K12+K13-K14 -> 0 | L15: =G15+H15+I15 -> 0 | M15: =SUM(F15:I15) -> 0 | N15: =SUM(B15:E15) -> 0 | O15: — | P15: —
A17: 分部營業利益
A18: Google Services 營業利益 | B18: 32.836 | C18: 32.682 | D18: 33.063 | E18: 33.527 | F18: 40.132 | G18: 40.589 | H18: 39.544 | I18: 39.157 | J18: 121.263 | K18: 139.404 | L18: =G18+H18+I18 -> 119.29 | M18: =SUM(F18:I18) -> 159.422 | N18: =SUM(B18:E18) -> 132.108 | O18: Verified（年）／Interested-party（季） | P18: 季：Alphabet 財報新聞稿（8-K 附件 99.1，各季；事實總帳 is.*.2024q4–2026q2；2026Q3＝mag/extract/docs/2026Q3/alphabet_2026Q3_新聞稿.pdf，事實總帳 alphabet_facts_2026q3.json）；年：Form 10-K FY2024、FY2025（經查核）
A19: Google Cloud 營業利益 | B19: 2.093 | C19: 2.177 | D19: 2.826 | E19: 3.594 | F19: 5.313 | G19: 6.598 | H19: 8.814 | I19: 11.121 | J19: 6.112 | K19: 13.91 | L19: =G19+H19+I19 -> 26.533 | M19: =SUM(F19:I19) -> 31.846 | N19: =SUM(B19:E19) -> 10.69 | O19: Verified（年）／Interested-party（季） | P19: 季：Alphabet 財報新聞稿（8-K 附件 99.1，各季；事實總帳 is.*.2024q4–2026q2；2026Q3＝mag/extract/docs/2026Q3/alphabet_2026Q3_新聞稿.pdf，事實總帳 alphabet_facts_2026q3.json）；年：Form 10-K FY2024、FY2025（經查核）
A20: Other Bets 營業利益 | B20: -1.174 | C20: -1.226 | D20: -1.246 | E20: -1.426 | F20: -3.617 | G20: -2.1 | H20: -1.799 | I20: -2.047 | J20: -4.444 | K20: -7.515 | L20: =G20+H20+I20 -> -5.946 | M20: =SUM(F20:I20) -> -9.563 | N20: =SUM(B20:E20) -> -5.072 | O20: Verified（年）／Interested-party（季） | P20: 季：Alphabet 財報新聞稿（8-K 附件 99.1，各季；事實總帳 is.*.2024q4–2026q2；2026Q3＝mag/extract/docs/2026Q3/alphabet_2026Q3_新聞稿.pdf，事實總帳 alphabet_facts_2026q3.json）；年：Form 10-K FY2024、FY2025（經查核）
A21: Alphabet-level activities（避險營收 − 未分攤費用） | B21: -2.783 | C21: -3.027 | D21: -3.372 | E21: -4.467 | F21: -5.894 | G21: -5.391 | H21: -5.789 | I21: -7.655 | J21: -10.541 | K21: -16.76 | L21: =G21+H21+I21 -> -18.835 | M21: =SUM(F21:I21) -> -24.729 | N21: =SUM(B21:E21) -> -13.649 | O21: Verified（年）／Interested-party（季） | P21: 季：Alphabet 財報新聞稿（8-K 附件 99.1，各季；事實總帳 is.*.2024q4–2026q2；2026Q3＝mag/extract/docs/2026Q3/alphabet_2026Q3_新聞稿.pdf，事實總帳 alphabet_facts_2026q3.json）；年：Form 10-K FY2024、FY2025（經查核）
A22: 合併營業利益 | B22: 30.972 | C22: 30.606 | D22: 31.271 | E22: 31.228 | F22: 35.934 | G22: 39.696 | H22: 40.77 | I22: 40.576 | J22: 112.39 | K22: 129.039 | L22: =G22+H22+I22 -> 121.042 | M22: =SUM(F22:I22) -> 156.976 | N22: =SUM(B22:E22) -> 124.077 | O22: Verified（年）／Interested-party（季） | P22: 季：Alphabet 財報新聞稿（8-K 附件 99.1，各季；事實總帳 is.*.2024q4–2026q2；2026Q3＝mag/extract/docs/2026Q3/alphabet_2026Q3_新聞稿.pdf，事實總帳 alphabet_facts_2026q3.json）；年：Form 10-K FY2024、FY2025（經查核）
A23: 檢查：分部營業利益合計 − 合併營業利益 | B23: =B18+B19+B20+B21-B22 -> 0 | C23: =C18+C19+C20+C21-C22 -> 0 | D23: =D18+D19+D20+D21-D22 -> 0 | E23: =E18+E19+E20+E21-E22 -> 0 | F23: =F18+F19+F20+F21-F22 -> 0 | G23: =G18+G19+G20+G21-G22 -> 0 | H23: =H18+H19+H20+H21-H22 -> 0 | I23: =I18+I19+I20+I21-I22 -> 0 | ... K23: =K18+K19+K20+K21-K22 -> 0 | L23: =G23+H23+I23 -> 0 | M23: =SUM(F23:I23) -> 0 | N23: =SUM(B23:E23) -> 0 | O23: — | P23: —
A25: 合併損益
A26: 營業成本 | B26: 40.613 | C26: 36.361 | D26: 39.039 | E26: 41.369 | F26: 45.766 | G26: 41.271 | H26: 45.943 | I26: 51.419 | J26: 146.306 | K26: 162.535 | L26: =G26+H26+I26 -> 138.633 | M26: =SUM(F26:I26) -> 184.399 | N26: =SUM(B26:E26) -> 157.382 | O26: Verified（年）／Interested-party（季） | P26: 季：Alphabet 財報新聞稿（8-K 附件 99.1，各季；事實總帳 is.*.2024q4–2026q2；2026Q3＝mag/extract/docs/2026Q3/alphabet_2026Q3_新聞稿.pdf，事實總帳 alphabet_facts_2026q3.json）；年：Form 10-K FY2024、FY2025（經查核）
A27: 其中：流量獲取成本 TAC | B27: 14.848 | C27: 13.748 | D27: 14.705 | E27: 14.876 | F27: 16.597 | G27: 15.228 | H27: 16.179 | I27: 16.366 | L27: =G27+H27+I27 -> 47.773 | M27: =SUM(F27:I27) -> 64.37 | N27: =SUM(B27:E27) -> 58.177 | O27: Verified（年）／Interested-party（季） | P27: 季：Alphabet 財報新聞稿（8-K 附件 99.1，各季；事實總帳 is.*.2024q4–2026q2；2026Q3＝mag/extract/docs/2026Q3/alphabet_2026Q3_新聞稿.pdf，事實總帳 alphabet_facts_2026q3.json）；年：Form 10-K FY2024、FY2025（經查核）
A28: 研發費用 | B28: 13.116 | C28: 13.556 | D28: 13.808 | E28: 15.151 | F28: 18.572 | G28: 17.032 | H28: 18.219 | I28: 20.64 | J28: 49.326 | K28: 61.087 | L28: =G28+H28+I28 -> 55.891 | M28: =SUM(F28:I28) -> 74.463 | N28: =SUM(B28:E28) -> 55.631 | O28: Verified（年）／Interested-party（季） | P28: 季：Alphabet 財報新聞稿（8-K 附件 99.1，各季；事實總帳 is.*.2024q4–2026q2；2026Q3＝mag/extract/docs/2026Q3/alphabet_2026Q3_新聞稿.pdf，事實總帳 alphabet_facts_2026q3.json）；年：Form 10-K FY2024、FY2025（經查核）
A29: 行銷費用 | B29: 7.363 | C29: 6.172 | D29: 7.101 | E29: 7.205 | F29: 8.215 | G29: 7.606 | H29: 8.403 | I29: 8.804 | J29: 27.808 | K29: 28.693 | L29: =G29+H29+I29 -> 24.813 | M29: =SUM(F29:I29) -> 33.028 | N29: =SUM(B29:E29) -> 27.841 | O29: Verified（年）／Interested-party（季） | P29: 季：Alphabet 財報新聞稿（8-K 附件 99.1，各季；事實總帳 is.*.2024q4–2026q2；2026Q3＝mag/extract/docs/2026Q3/alphabet_2026Q3_新聞稿.pdf，事實總帳 alphabet_facts_2026q3.json）；年：Form 10-K FY2024、FY2025（經查核）
A30: 管理費用 | B30: 4.405 | C30: 3.539 | D30: 5.209 | E30: 7.393 | F30: 5.341 | G30: 4.291 | H30: 6.461 | I30: 6.138 | J30: 14.188 | K30: 21.482 | L30: =G30+H30+I30 -> 16.89 | M30: =SUM(F30:I30) -> 22.231 | N30: =SUM(B30:E30) -> 20.546 | O30: Verified（年）／Interested-party（季） | P30: 季：Alphabet 財報新聞稿（8-K 附件 99.1，各季；事實總帳 is.*.2024q4–2026q2；2026Q3＝mag/extract/docs/2026Q3/alphabet_2026Q3_新聞稿.pdf，事實總帳 alphabet_facts_2026q3.json）；年：Form 10-K FY2024、FY2025（經查核）
A31: 檢查：營收 − 成本費用 − 營業利益 | B31: =B14-B26-B28-B29-B30-B22 -> 0 | C31: =C14-C26-C28-C29-C30-C22 -> 0 | D31: =D14-D26-D28-D29-D30-D22 -> 0 | E31: =E14-E26-E28-E29-E30-E22 -> 0 | F31: =F14-F26-F28-F29-F30-F22 -> 0 | G31: =G14-G26-G28-G29-G30-G22 -> 0 | H31: =H14-H26-H28-H29-H30-H22 -> 0 | I31: =I14-I26-I28-I29-I30-I22 -> 0 | ... K31: =K14-K26-K28-K29-K30-K22 -> 0 | L31: =G31+H31+I31 -> 0 | M31: =SUM(F31:I31) -> 0 | N31: =SUM(B31:E31) -> 0 | O31: — | P31: —
A32: 其他收益淨額（含權益證券損益） | B32: 1.271 | C32: 11.183 | D32: 2.662 | E32: 12.759 | F32: 3.183 | G32: 37.716 | H32: 97.983 | I32: -8.221 | J32: 7.425 | K32: 29.787 | L32: =G32+H32+I32 -> 127.478 | M32: =SUM(F32:I32) -> 130.661 | N32: =SUM(B32:E32) -> 27.875 | O32: Verified（年）／Interested-party（季） | P32: 季：Alphabet 財報新聞稿（8-K 附件 99.1，各季；事實總帳 is.*.2024q4–2026q2；2026Q3＝mag/extract/docs/2026Q3/alphabet_2026Q3_新聞稿.pdf，事實總帳 alphabet_facts_2026q3.json）；年：Form 10-K FY2024、FY2025（經查核）
A33: 其中：權益證券淨損益 | B33: 0.364 | C33: 9.758 | D33: 1.286 | E33: 10.734 | F33: 2.302 | G33: 36.915 | H33: 99.031 | I33: -8.664 | L33: =G33+H33+I33 -> 127.282 | M33: =SUM(F33:I33) -> 129.584 | N33: =SUM(B33:E33) -> 22.142 | O33: Verified（年）／Interested-party（季） | P33: 季：Alphabet 財報新聞稿（8-K 附件 99.1，各季；事實總帳 is.*.2024q4–2026q2；2026Q3＝mag/extract/docs/2026Q3/alphabet_2026Q3_新聞稿.pdf，事實總帳 alphabet_facts_2026q3.json）；年：Form 10-K FY2024、FY2025（經查核）
A34: 稅前利益 | B34: 32.243 | C34: 41.789 | D34: 33.933 | E34: 43.987 | F34: 39.117 | G34: 77.412 | H34: 138.753 | I34: 32.355 | J34: 119.815 | K34: 158.826 | L34: =G34+H34+I34 -> 248.52 | M34: =SUM(F34:I34) -> 287.637 | N34: =SUM(B34:E34) -> 151.952 | O34: Verified（年）／Interested-party（季） | P34: 季：Alphabet 財報新聞稿（8-K 附件 99.1，各季；事實總帳 is.*.2024q4–2026q2；2026Q3＝mag/extract/docs/2026Q3/alphabet_2026Q3_新聞稿.pdf，事實總帳 alphabet_facts_2026q3.json）；年：Form 10-K FY2024、FY2025（經查核）
A35: 檢查：營業利益＋其他收益 − 稅前利益 | B35: =B22+B32-B34 -> 0 | C35: =C22+C32-C34 -> 0 | D35: =D22+D32-D34 -> 0 | E35: =E22+E32-E34 -> 0 | F35: =F22+F32-F34 -> 0 | G35: =G22+G32-G34 -> 0 | H35: =H22+H32-H34 -> 0 | I35: =I22+I32-I34 -> 0 | ... K35: =K22+K32-K34 -> 0 | L35: =G35+H35+I35 -> 0 | M35: =SUM(F35:I35) -> 0 | N35: =SUM(B35:E35) -> 0 | O35: — | P35: —
A36: 所得稅 | B36: 5.707 | C36: 7.249 | D36: 5.737 | E36: 9.008 | F36: 4.662 | G36: 14.834 | H36: 26.56 | I36: 5.887 | J36: 19.697 | K36: 26.656 | L36: =G36+H36+I36 -> 47.281 | M36: =SUM(F36:I36) -> 51.943 | N36: =SUM(B36:E36) -> 27.701 | O36: Verified（年）／Interested-party（季） | P36: 季：Alphabet 財報新聞稿（8-K 附件 99.1，各季；事實總帳 is.*.2024q4–2026q2；2026Q3＝mag/extract/docs/2026Q3/alphabet_2026Q3_新聞稿.pdf，事實總帳 alphabet_facts_2026q3.json）；年：Form 10-K FY2024、FY2025（經查核）
A37: 淨利 | B37: 26.536 | C37: 34.54 | D37: 28.196 | E37: 34.979 | F37: 34.455 | G37: 62.578 | H37: 112.193 | I37: 26.468 | J37: 100.118 | K37: 132.17 | L37: =G37+H37+I37 -> 201.239 | M37: =SUM(F37:I37) -> 235.694 | N37: =SUM(B37:E37) -> 124.251 | O37: Verified（年）／Interested-party（季） | P37: 季：Alphabet 財報新聞稿（8-K 附件 99.1，各季；事實總帳 is.*.2024q4–2026q2；2026Q3＝mag/extract/docs/2026Q3/alphabet_2026Q3_新聞稿.pdf，事實總帳 alphabet_facts_2026q3.json）；年：Form 10-K FY2024、FY2025（經查核）
A38: 檢查：稅前 − 所得稅 − 淨利 | B38: =B34-B36-B37 -> 0 | C38: =C34-C36-C37 -> 0 | D38: =D34-D36-D37 -> 0 | E38: =E34-E36-E37 -> 0 | F38: =F34-F36-F37 -> 0 | G38: =G34-G36-G37 -> 0 | H38: =H34-H36-H37 -> 0 | I38: =I34-I36-I37 -> 0 | ... K38: =K34-K36-K37 -> 0 | L38: =G38+H38+I38 -> 0 | M38: =SUM(F38:I38) -> 0 | N38: =SUM(B38:E38) -> 0 | O38: — | P38: —
A39: 稀釋加權股數（十億股） | B39: 12.348 | C39: 12.291 | D39: 12.198 | E39: 12.203 | F39: 12.228 | G39: 12.238 | H39: 12.309 | I39: 12.368 | J39: 12.447 | K39: 12.23 | L39: =12.324 -> 12.324 | O39: Verified（年）／Interested-party（季） | P39: 季：Alphabet 財報新聞稿（8-K 附件 99.1，各季；事實總帳 is.*.2024q4–2026q2；2026Q3＝mag/extract/docs/2026Q3/alphabet_2026Q3_新聞稿.pdf，事實總帳 alphabet_facts_2026q3.json）；年：Form 10-K FY2024、FY2025（經查核）
A40: EPS（GAAP 稀釋，美元） | B40: 2.15 | C40: 2.81 | D40: 2.31 | E40: 2.87 | F40: 2.82 | G40: 5.11 | H40: 9.11 | I40: 2.12 | J40: 8.04 | K40: 10.81 | L40: =G40+H40+I40 -> 16.34 | M40: =SUM(F40:I40) -> 19.16 | N40: =SUM(B40:E40) -> 10.14 | O40: Verified（年）／Interested-party（季） | P40: 季：Alphabet 財報新聞稿（8-K 附件 99.1，各季；事實總帳 is.*.2024q4–2026q2；2026Q3＝mag/extract/docs/2026Q3/alphabet_2026Q3_新聞稿.pdf，事實總帳 alphabet_facts_2026q3.json）；年：Form 10-K FY2024、FY2025（經查核）
A42: 現金流、資本支出與股東回饋
A43: 折舊（不動產與設備） | B43: 4.205 | C43: 4.487 | D43: 4.998 | E43: 5.611 | F43: 6.04 | G43: 6.482 | H43: 7.104 | I43: 8.369 | J43: 15.311 | K43: 21.136 | L43: =G43+H43+I43 -> 21.955 | M43: =SUM(F43:I43) -> 27.995 | N43: =SUM(B43:E43) -> 19.301 | O43: Verified（年）／Interested-party（季） | P43: 季：Alphabet 財報新聞稿（8-K 附件 99.1，各季；事實總帳 is.*.2024q4–2026q2；2026Q3＝mag/extract/docs/2026Q3/alphabet_2026Q3_新聞稿.pdf，事實總帳 alphabet_facts_2026q3.json）；年：Form 10-K FY2024、FY2025（經查核）
...

Sheet Thesis
A1: Thesis — 命題模組：AI 容量（MW）× 每 MW 收入（Tokenomics 持有成本 × k）→ Google Cloud 的 Cloud AI 子列；同一套 MW 推出 AI 資本支出、AI 折舊與營運成本，接到分部營業利益（對外 → Google Cloud；自用 → Google Services／Alphabet 層級）
A2: 三情境共用（本版的情境軸是 Search，見 Seg 頁）；MW 速度、對外比例、k 的區間在 Sens 頁。沿用 v0.2.2：k 規格（kspec.py）、對外比例 30%；v0.3.1：Tokenomics v21.7 快照、TPU 係數改讀 IF_NonNV_Hold_TPU、C10 速度依 2026 指引重解。不以 Cloud 營收、RPO 反推 k 或每 MW 價格（工作單第 4 節）
A4: A. 價格與起始值（單一數值，C 欄）
A5: 項目 | B5: 單位 | C5: 數值 | N5: 說明
A6: k_長約＝長約證據價格 ÷ IF_HoldEcon｜VR200 | B6: x | C6: =kl_px/he_vr -> 0.78291462 | N6: kspec.py（v0.2.2）：證據價格不變、分母隨 Tokenomics 快照
A7: k_現貨＝H100 現貨指數 ÷ IF_GPUhrEcon｜H100 | B7: x | C7: =ks_px/gpuhr_h -> 1.8280865 | N7: C1：MAG 三家一致
A8: 混合 k＝長約占比 × k_長約＋(1 − 長約占比) × k_現貨 | B8: x | C8: =long_sh*k_long+(1-long_sh)*k_spot -> 1.2009834 | N8: v0.2.2 為 1.201
A9: TPU 收入錨調整＝1 − TPU 占比 ×(1 − TPU 係數) | B9: x | C9: =1-tpu_sh*(1-tpu_f) -> 0.775 | N9: 基準 1（C2：TPU × 1.0）
A10: TPU IT 資本支出調整 | B10: x | C10: =1-tpu_sh*(1-tpu_cf) -> 0.775
A11: 期初機隊每 MW 年收入（對外） | B11: US$m/MW-年 | C11: =k_blend*tpu_adj*(mix0_h*he_h+mix0_b2*he_b2+mix0_b3*he_b3) -> 8.9952293
A12: 期初機隊每 MW 年營運費用（Tokenomics IF_OpexGW 加權） | B12: US$m/MW-年 | C12: =mix0_h*opx_h+mix0_b2*opx_b2+mix0_b3*opx_b3 -> 1.881462
A13: 近四季 Cloud AI 營收估計（近四季平均對外 MW × 期初每 MW 收入） | B13: US$B | C13: =ai_mw_ttm*permw0/1000 -> 15.227487 | N13: 只用於拆 Cloud 其他的起始成長率與利潤率
A14: 前四季 Cloud AI 營收估計 | B14: US$B | C14: =ai_mw_pttm*permw0/1000 -> 7.4449015
A15: 近四季 Cloud AI EBITDA 估計 | B15: US$B | C15: =ai_mw_ttm*(permw0-opex0)/1000 -> 12.042472
A16: Cloud 其他近四季年增（Cloud − Cloud AI 估計） | B16: % | C16: =(cloud_ttm-ai_ttm)/(cloud_pttm-ai_pttm)-1 -> 0.71107868 | N16: [Derived]；Cloud 其他＝Workspace、非 AI 雲端、Wiz（2026-03 併入）
A17: Cloud 其他 EBITDA 率（近四季：Cloud EBITDA − Cloud AI EBITDA 估計）÷ Cloud 其他營收 | B17: % | C17: =(cloud_ebitda_ttm-ai_ttm_e)/(cloud_ttm-ai_ttm) -> 0.3251248 | N17: [Derived]；mb_ttm＝1 時採用
A18: Cloud 其他 EBITDA 率（9M26） | B18: % | C18: =(Q!L19+Q!L43*sh1_cloud-E41)/(Q!L11-E38) -> 0.333016 | N18: [Derived]；(9M26 Cloud 營業利益＋分攤折舊 − Cloud AI 9M EBITDA) ÷ Cloud 其他 9M
A19: Cloud 其他 EBITDA 率（預測期採用，固定） | B19: % | C19: =IF(mb_ttm=1,m_co_ttm,m_co_1h) -> 0.333016 | N19: 預設 9M26（同 m_svc）
A21: B. AI 容量（AI 總 IT MW；期末）— 依 Tokenomics 世代錨分桶
A22: 項目 | B22: 單位 | C22: FY2024A | D22: FY2025A | E22: 9M26A | F22: Q4 26E | G22: FY2026E | H22: FY2027E | I22: FY2028E | J22: FY2029E | K22: FY2030E | L22: FY2031E | M22: FY2032E | N22: 說明
A23: AI 總 MW 新增（FY2029 起收斂到 g × 期初 MW） | B23: MW | F23: =pace*0.25 -> 1557.075 | G23: =F23 -> 1557.075 | H23: =pace -> 6228.3 | I23: =pace -> 6228.3 | J23: =pace+(g_tv*I28-pace)*MIN(1,(2029-2028)/conv_mw) -> 4835.5331 | K23: =pace+(g_tv*J28-pace)*MIN(1,(2030-2028)/conv_mw) -> 3515.2992 | L23: =pace+(g_tv*K28-pace)*MIN(1,(2031-2028)/conv_mw) -> 2237.8931 | M23: =pace+(g_tv*L28-pace)*MIN(1,(2032-2028)/conv_mw) -> 974.89426 | N23: 三情境相同；修正一 F5：FY2029–FY2032 線性收斂，FY2032 只剩與永續成長 g 一致的增量（另加汰換）
A24: 期末 MW：Hopper 錨 | B24: MW | E24: =mw_q2*mix0_h+pace*0.25*0 -> 1584.25 | F24: =E24+F23*0 -> 1584.25 | G24: =F24 -> 1584.25 | H24: =F24+H23*0 -> 1584.25 | I24: =H24+I23*0 -> 1584.25 | J24: =I24+J23*0 -> 1584.25 | K24: =J24+K23*0 -> 1584.25 | L24: =K24+L23*0 -> 1584.25 | M24: =L24+M23*0 -> 1584.25 | N24: 評價日（2026-09-30）＝6/30 機隊 × 期初占比＋Q3 新增（pace × 0.25，2026 世代組合）；新增依年度世代組合（2026 GB300 錨；2027 GB300／VR200 各半；2028 起 VR200 錨）
A25: 期末 MW：GB200 錨 | B25: MW | E25: =mw_q2*mix0_b2+pace*0.25*0 -> 2851.65 | F25: =E25+F23*0 -> 2851.65 | G25: =F25 -> 2851.65 | H25: =F25+H23*0 -> 2851.65 | I25: =H25+I23*0 -> 2851.65 | J25: =I25+J23*0 -> 2851.65 | K25: =J25+K23*0 -> 2851.65 | L25: =K25+L23*0 -> 2851.65 | M25: =L25+M23*0 -> 2851.65
A26: 期末 MW：GB300 錨 | B26: MW | E26: =mw_q2*mix0_b3+pace*0.25*am_26 -> 3458.175 | F26: =E26+F23*am_26 -> 5015.25 | G26: =F26 -> 5015.25 | H26: =F26+H23*am_27 -> 8129.4 | I26: =H26+I23*(1-am_28) -> 8129.4 | J26: =I26+J23*(1-am_28) -> 8129.4 | K26: =J26+K23*(1-am_28) -> 8129.4 | L26: =K26+L23*(1-am_28) -> 8129.4 | M26: =L26+M23*(1-am_28) -> 8129.4
A27: 期末 MW：VR200 錨 | B27: MW | E27: =mw_q2*0+pace*0.25*(1-am_26) -> 0 | F27: =E27+F23*(1-am_26) -> 0 | G27: =F27 -> 0 | H27: =F27+H23*(1-am_27) -> 3114.15 | I27: =H27+I23*am_28 -> 9342.45 | J27: =I27+J23*am_28 -> 14177.983 | K27: =J27+K23*am_28 -> 17693.282 | L27: =K27+L23*am_28 -> 19931.175 | M27: =L27+M23*am_28 -> 20906.07
A28: 期末 AI 總 MW | B28: MW | E28: =E24+E25+E26+E27 -> 7894.075 | F28: =F24+F25+F26+F27 -> 9451.15 | G28: =G24+G25+G26+G27 -> 9451.15 | H28: =H24+H25+H26+H27 -> 15679.45 | I28: =I24+I25+I26+I27 -> 21907.75 | J28: =J24+J25+J26+J27 -> 26743.283 | K28: =K24+K25+K26+K27 -> 30258.582 | L28: =L24+L25+L26+L27 -> 32496.475 | M28: =M24+M25+M26+M27 -> 33471.37
A29: 期末對外 MW（＝總 MW × 對外比例） | B29: MW | E29: =E28*ext_sh -> 2368.2225 | F29: =F28*ext_sh -> 2835.345 | G29: =G28*ext_sh -> 2835.345 | H29: =H28*ext_sh -> 4703.835 | I29: =I28*ext_sh -> 6572.325 | J29: =J28*ext_sh -> 8022.9849 | K29: =K28*ext_sh -> 9077.5747 | L29: =L28*ext_sh -> 9748.9426 | M29: =M28*ext_sh -> 10041.411 | N29: 2026-06-30 1,901（v0.2.2 defaults.billableOpen）＋Q3 新增 × 30%
A30: 平均在役 MW：Hopper 錨 | B30: MW | E30: =(mw_ye25*mix0_h+E24)/2 -> 1401.25 | F30: =(E24+F24)/2 -> 1584.25 | G30: =(E30+F30)/2 -> 1492.75 | H30: =(F24+H24)/2 -> 1584.25 | I30: =(H24+I24)/2 -> 1584.25 | J30: =(I24+J24)/2 -> 1584.25 | K30: =(J24+K24)/2 -> 1584.25 | L30: =(K24+L24)/2 -> 1584.25 | M30: =(L24+M24)/2 -> 1584.25
A31: 平均在役 MW：GB200 錨 | B31: MW | E31: =(mw_ye25*mix0_b2+E25)/2 -> 2522.25 | F31: =(E25+F25)/2 -> 2851.65 | G31: =(E31+F31)/2 -> 2686.95 | H31: =(F25+H25)/2 -> 2851.65 | I31: =(H25+I25)/2 -> 2851.65 | J31: =(I25+J25)/2 -> 2851.65 | K31: =(J25+K25)/2 -> 2851.65 | L31: =(K25+L25)/2 -> 2851.65 | M31: =(L25+M25)/2 -> 2851.65
A32: 平均在役 MW：GB300 錨 | B32: MW | E32: =(mw_ye25*mix0_b3+E26)/2 -> 2460.0375 | F32: =(E26+F26)/2 -> 4236.7125 | G32: =(E32+F32)/2 -> 3348.375 | H32: =(F26+H26)/2 -> 6572.325 | I32: =(H26+I26)/2 -> 8129.4 | J32: =(I26+J26)/2 -> 8129.4 | K32: =(J26+K26)/2 -> 8129.4 | L32: =(K26+L26)/2 -> 8129.4 | M32: =(L26+M26)/2 -> 8129.4
A33: 平均在役 MW：VR200 錨 | B33: MW | E33: =(mw_ye25*0+E27)/2 -> 0 | F33: =(E27+F27)/2 -> 0 | G33: =(E33+F33)/2 -> 0 | H33: =(F27+H27)/2 -> 1557.075 | I33: =(H27+I27)/2 -> 6228.3 | J33: =(I27+J27)/2 -> 11760.217 | K33: =(J27+K27)/2 -> 15935.633 | L33: =(K27+L27)/2 -> 18812.229 | M33: =(L27+M27)/2 -> 20418.623
A34: 平均在役 AI 總 MW | B34: MW | E34: =E30+E31+E32+E33 -> 6383.5375 | F34: =F30+F31+F32+F33 -> 8672.6125 | G34: =G30+G31+G32+G33 -> 7528.075 | H34: =H30+H31+H32+H33 -> 12565.3 | I34: =I30+I31+I32+I33 -> 18793.6 | J34: =J30+J31+J32+J33 -> 24325.517 | K34: =K30+K31+K32+K33 -> 28500.933 | L34: =L30+L31+L32+L33 -> 31377.529 | M34: =M30+M31+M32+M33 -> 32983.923
A35: 平均在役對外 MW | B35: MW | E35: =E34*ext_sh -> 1915.0612 | F35: =F34*ext_sh -> 2601.7838 | G35: =G34*ext_sh -> 2258.4225 | H35: =H34*ext_sh -> 3769.59 | I35: =I34*ext_sh -> 5638.08 | J35: =J34*ext_sh -> 7297.655 | K35: =K34*ext_sh -> 8550.2798 | L35: =L34*ext_sh -> 9413.2587 | M35: =M34*ext_sh -> 9895.1768
A37: C. Cloud AI（對外 AI 雲端；Google Cloud 的命題子列）
A38: Cloud AI 營收＝對外比例 × Σ 平均 MW × IF_HoldEcon × k × TPU 調整 | B38: US$B | E38: =ext_sh*k_blend*tpu_adj*(E30*he_h+E31*he_b2+E32*he_b3+E33*he_vr)/1000*0.75 -> 13.119056 | F38: =ext_sh*k_blend*tpu_adj*(F30*he_h+F31*he_b2+F32*he_b3+F33*he_vr)/1000*0.25 -> 6.050155 | G38: =E38+F38 -> 19.169211 | H38: =ext_sh*k_blend*tpu_adj*(H30*he_h+H31*he_b2+H32*he_b3+H33*he_vr)/1000*1 -> 36.615799 | I38: =ext_sh*k_blend*tpu_adj*(I30*he_h+I31*he_b2+I32*he_b3+I33*he_vr)/1000*1 -> 57.29516 | J38: =ext_sh*k_blend*tpu_adj*(J30*he_h+J31*he_b2+J32*he_b3+J33*he_vr)/1000*1 -> 76.179473 | K38: =ext_sh*k_blend*tpu_adj*(K30*he_h+K31*he_b2+K32*he_b3+K33*he_vr)/1000*1 -> 90.433098 | L38: =ext_sh*k_blend*tpu_adj*(L30*he_h+L31*he_b2+L32*he_b3+L33*he_vr)/1000*1 -> 100.25294 | M38: =ext_sh*k_blend*tpu_adj*(M30*he_h+M31*he_b2+M32*he_b3+M33*he_vr)/1000*1 -> 105.73669 | N38: 收入端不乘 IF_Util（MW-year 計價）；9M26 為模型估計（公司未揭露 AI 營收），Cloud 其他＝實際 Cloud − 本列
A39: 每 MW 年收入（對外） | B39: US$m/MW-年 | E39: =E38/(E35*0.75)*1000 -> 9.1339504 | F39: =F38/(F35*0.25)*1000 -> 9.3015493 | H39: =H38/(H35*1)*1000 -> 9.7134699 | I39: =I38/(I35*1)*1000 -> 10.162176 | J39: =J38/(J35*1)*1000 -> 10.438898 | K39: =K38/(K35*1)*1000 -> 10.576624 | L39: =L38/(L35*1)*1000 -> 10.650184 | M39: =M38/(M35*1)*1000 -> 10.68568
A40: Cloud AI 營運費用（Tokenomics IF_OpexGW，含電費） | B40: US$B | E40: =ext_sh*(E30*opx_h+E31*opx_b2+E32*opx_b3+E33*opx_vr)/1000*0.75 -> 2.7200588 | F40: =ext_sh*(F30*opx_h+F31*opx_b2+F32*opx_b3+F33*opx_vr)/1000*0.25 -> 1.2415119 | G40: =E40+F40 -> 3.9615707 | H40: =ext_sh*(H30*opx_h+H31*opx_b2+H32*opx_b3+H33*opx_vr)/1000*1 -> 7.3331664 | I40: =ext_sh*(I30*opx_h+I31*opx_b2+I32*opx_b3+I33*opx_vr)/1000*1 -> 11.193056 | J40: =ext_sh*(J30*opx_h+J31*opx_b2+J32*opx_b3+J33*opx_vr)/1000*1 -> 14.667369 | K40: =ext_sh*(K30*opx_h+K31*opx_b2+K32*opx_b3+K33*opx_vr)/1000*1 -> 17.289734 | L40: =ext_sh*(L30*opx_h+L31*opx_b2+L32*opx_b3+L33*opx_vr)/1000*1 -> 19.096376 | M40: =ext_sh*(M30*opx_h+M31*opx_b2+M32*opx_b3+M33*opx_vr)/1000*1 -> 20.105269
A41: Cloud AI EBITDA | B41: US$B | E41: =E38-E40 -> 10.398997 | F41: =F38-F40 -> 4.8086431 | G41: =G38-G40 -> 15.20764 | H41: =H38-H40 -> 29.282633 | I41: =I38-I40 -> 46.102104 | J41: =J38-J40 -> 61.512104 | K41: =K38-K40 -> 73.143364 | L41: =L38-L40 -> 81.156563 | M41: =M38-M40 -> 85.631418
A42: Cloud AI EBITDA 率 | B42: % | E42: =E41/E38 -> 0.79266352 | F42: =F41/F38 -> 0.79479668 | G42: =G41/G38 -> 0.79333679 | H42: =H41/H38 -> 0.79972671 | I42: =I41/I38 -> 0.8046422 | J42: =J41/J38 -> 0.80746297 | K42: =K41/K38 -> 0.80881188 | L42: =L41/L38 -> 0.80951804 | M42: =M41/M38 -> 0.80985531
A43: 上限檢查：每 MW 收入 ÷ 在役世代加權 IFW_RevGWFleet_Util（> 50% 示警；不得作預測） | B43: % | E43: =E39/((E30*cap_h+E31*cap_b2+E32*cap_b3+E33*cap_vr)/E34) -> 0.30396826 | F43: =F39/((F30*cap_h+F31*cap_b2+F32*cap_b3+F33*cap_vr)/F34) -> 0.29282969 | H43: =H39/((H30*cap_h+H31*cap_b2+H32*cap_b3+H33*cap_vr)/H34) -> 0.25812596 | I43: =I39/((I30*cap_h+I31*cap_b2+I32*cap_b3+I33*cap_vr)/I34) -> 0.22589326 | J43: =J39/((J30*cap_h+J31*cap_b2+J32*cap_b3+J33*cap_vr)/J34) -> 0.20943181 | K43: =K39/((K30*cap_h+K31*cap_b2+K32*cap_b3+K33*cap_vr)/K34) -> 0.20237927 | L43: =L39/((L30*cap_h+L31*cap_b2+L32*cap_b3+L33*cap_vr)/L34) -> 0.19887337 | M43: =M39/((M30*cap_h+M31*cap_b2+M32*cap_b3+M33*cap_vr)/M34) -> 0.19724142 | N43: v0.2.2 基準最高 38.0%
...

Sheet Seg
A1: Seg — 營收分部層：官方分部（Google Services、Google Cloud、Other Bets）＋Alphabet 層級避險；產品線為子列。情境差異只在 Google Search & other（A 擴大變現／B 近四季成長收斂／C 查詢分流、變現下降），其餘三情境相同
A2: 成長路徑：Q4 26 年增＝近四季年增（Q 頁，2025Q4–2026Q3），之後線性收斂到長期值（conv_n 年，FY2030 到達）。Search 情境：Search＝B 路徑 ×(1 − 分流) ×(1＋每次查詢變現變動)，分流與變現變動自 FY2026 的 0 線性到 FY2030 的 In 頁值。Cloud AI 由 Thesis 頁帶入
A4: 情境 A（AI 搜尋擴大變現）
A5: 項目 | B5: 單位 | C5: FY2024A | D5: FY2025A | E5: 9M26A | F5: Q4 26E | G5: FY2026E | H5: FY2027E | I5: FY2028E | J5: FY2029E | K5: FY2030E | L5: FY2031E | M5: FY2032E | N5: 說明
A6: Search B 路徑年增 | B6: % | F6: =g0_search -> 0.16056206 | H6: =g0_search+(gl_search-g0_search)*MIN(1,(2027-2026)/conv_n) -> 0.14042155 | I6: =g0_search+(gl_search-g0_search)*MIN(1,(2028-2026)/conv_n) -> 0.12028103 | J6: =g0_search+(gl_search-g0_search)*MIN(1,(2029-2026)/conv_n) -> 0.10014052 | K6: =g0_search+(gl_search-g0_search)*MIN(1,(2030-2026)/conv_n) -> 0.08 | L6: =g0_search+(gl_search-g0_search)*MIN(1,(2031-2026)/conv_n) -> 0.08 | M6: =g0_search+(gl_search-g0_search)*MIN(1,(2032-2026)/conv_n) -> 0.08 | N6: Q4 26 年增＝近四季年增（Q 頁），FY2030 收斂到 gl_search
A7: Google Search & other：B 路徑 | B7: US$B | C7: =Q!J5 -> 198.084 | D7: =Q!K5 -> 224.532 | E7: =Q!L5 -> 187.02 | F7: =Q!F5*(1+F6) -> 73.200131 | G7: =E7+F7 -> 260.22013 | H7: =G7*(1+H6) -> 296.76064 | I7: =H7*(1+I6) -> 332.45532 | J7: =I7*(1+J6) -> 365.74757 | K7: =J7*(1+K6) -> 395.00737 | L7: =K7*(1+L6) -> 426.60796 | M7: =L7*(1+M6) -> 460.7366
A8: 情境爬坡（FY2026 0 → FY2030 1） | B8: x | F8: 0 | H8: =MIN(1,(2027-2026)/conv_n) -> 0.25 | I8: =MIN(1,(2028-2026)/conv_n) -> 0.5 | J8: =MIN(1,(2029-2026)/conv_n) -> 0.75 | K8: =MIN(1,(2030-2026)/conv_n) -> 1 | L8: =MIN(1,(2031-2026)/conv_n) -> 1 | M8: =MIN(1,(2032-2026)/conv_n) -> 1
A9: 查詢分流（相對 B 路徑） | B9: % | F9: =dA*F8 -> 0 | H9: =dA*H8 -> -0.0125 | I9: =dA*I8 -> -0.025 | J9: =dA*J8 -> -0.0375 | K9: =dA*K8 -> -0.05 | L9: =dA*L8 -> -0.05 | M9: =dA*M8 -> -0.05 | N9: In 頁 dA（負值＝AI 模式吸引查詢回流）
A10: 每次查詢變現變動（相對 B 路徑） | B10: % | F10: =mA*F8 -> 0 | H10: =mA*H8 -> 0.025 | I10: =mA*I8 -> 0.05 | J10: =mA*J8 -> 0.075 | K10: =mA*K8 -> 0.1 | L10: =mA*L8 -> 0.1 | M10: =mA*M8 -> 0.1
A11: Google Search & other | B11: US$B | C11: =C7 -> 198.084 | D11: =D7 -> 224.532 | E11: =E7 -> 187.02 | F11: =F7*(1-F9)*(1+F10) -> 73.200131 | G11: =E11+F11 -> 260.22013 | H11: =H7*(1-H9)*(1+H10) -> 307.98191 | I11: =I7*(1-I9)*(1+I10) -> 357.80504 | J11: =J7*(1-J9)*(1+J10) -> 407.92283 | K11: =K7*(1-K9)*(1+K10) -> 456.23351 | L11: =L7*(1-L9)*(1+L10) -> 492.7322 | M11: =M7*(1-M9)*(1+M10) -> 532.15077
A12: YouTube ads 年增 | B12: % | F12: =g0_yt -> 0.10317561 | H12: =g0_yt+(gl_yt-g0_yt)*MIN(1,(2027-2026)/conv_n) -> 0.097381707 | I12: =g0_yt+(gl_yt-g0_yt)*MIN(1,(2028-2026)/conv_n) -> 0.091587804 | J12: =g0_yt+(gl_yt-g0_yt)*MIN(1,(2029-2026)/conv_n) -> 0.085793902 | K12: =g0_yt+(gl_yt-g0_yt)*MIN(1,(2030-2026)/conv_n) -> 0.08 | L12: =g0_yt+(gl_yt-g0_yt)*MIN(1,(2031-2026)/conv_n) -> 0.08 | M12: =g0_yt+(gl_yt-g0_yt)*MIN(1,(2032-2026)/conv_n) -> 0.08 | N12: 三情境相同
A13: YouTube ads | B13: US$B | C13: =Q!J6 -> 36.147 | D13: =Q!K6 -> 40.367 | E13: =Q!L6 -> 32.145 | F13: =Q!F6*(1+F12) -> 12.557448 | G13: =E13+F13 -> 44.702448 | H13: =G13*(1+H12) -> 49.055649 | I13: =H13*(1+I12) -> 53.548548 | J13: =I13*(1+J12) -> 58.142687 | K13: =J13*(1+K12) -> 62.794102 | L13: =K13*(1+L12) -> 67.81763 | M13: =L13*(1+M12) -> 73.24304
A14: Google Network 年增 | B14: % | F14: =g0_net -> -0.012066315 | H14: =g0_net+(gl_net-g0_net)*MIN(1,(2027-2026)/conv_n) -> -0.0090497359 | I14: =g0_net+(gl_net-g0_net)*MIN(1,(2028-2026)/conv_n) -> -0.0060331573 | J14: =g0_net+(gl_net-g0_net)*MIN(1,(2029-2026)/conv_n) -> -0.0030165786 | K14: =g0_net+(gl_net-g0_net)*MIN(1,(2030-2026)/conv_n) -> 0 | L14: =g0_net+(gl_net-g0_net)*MIN(1,(2031-2026)/conv_n) -> 0 | M14: =g0_net+(gl_net-g0_net)*MIN(1,(2032-2026)/conv_n) -> 0 | N14: 三情境相同
A15: Google Network | B15: US$B | C15: =Q!J7 -> 30.359 | D15: =Q!K7 -> 29.792 | E15: =Q!L7 -> 21.729 | F15: =Q!F7*(1+F14) -> 7.7335449 | G15: =E15+F15 -> 29.462545 | H15: =G15*(1+H14) -> 29.195917 | I15: =H15*(1+I14) -> 29.019773 | J15: =I15*(1+J14) -> 28.932233 | K15: =J15*(1+K14) -> 28.932233 | L15: =K15*(1+L14) -> 28.932233 | M15: =L15*(1+M14) -> 28.932233
A16: Google subscriptions, platforms, and devices 年增 | B16: % | F16: =g0_subs -> 0.15358577 | H16: =g0_subs+(gl_subs-g0_subs)*MIN(1,(2027-2026)/conv_n) -> 0.14018932 | I16: =g0_subs+(gl_subs-g0_subs)*MIN(1,(2028-2026)/conv_n) -> 0.12679288 | J16: =g0_subs+(gl_subs-g0_subs)*MIN(1,(2029-2026)/conv_n) -> 0.11339644 | K16: =g0_subs+(gl_subs-g0_subs)*MIN(1,(2030-2026)/conv_n) -> 0.1 | L16: =g0_subs+(gl_subs-g0_subs)*MIN(1,(2031-2026)/conv_n) -> 0.1 | M16: =g0_subs+(gl_subs-g0_subs)*MIN(1,(2032-2026)/conv_n) -> 0.1 | N16: 三情境相同
A17: Google subscriptions, platforms, and devices | B17: US$B | C17: =Q!J8 -> 40.34 | D17: =Q!K8 -> 48.03 | E17: =Q!L8 -> 39.585 | F17: =Q!F8*(1+F16) -> 15.663388 | G17: =E17+F17 -> 55.248388 | H17: =G17*(1+H16) -> 62.993622 | I17: =H17*(1+I16) -> 70.980765 | J17: =I17*(1+J16) -> 79.029731 | K17: =J17*(1+K16) -> 86.932704 | L17: =K17*(1+L16) -> 95.625974 | M17: =L17*(1+M16) -> 105.18857
A18: Google Services | B18: US$B | C18: =Q!J9 -> 304.93 | D18: =Q!K9 -> 342.721 | E18: =Q!L9 -> 280.479 | F18: =F11+F13+F15+F17 -> 109.15451 | G18: =E18+F18 -> 389.63351 | H18: =H11+H13+H15+H17 -> 449.22709 | I18: =I11+I13+I15+I17 -> 511.35412 | J18: =J11+J13+J15+J17 -> 574.02748 | K18: =K11+K13+K15+K17 -> 634.89255 | L18: =L11+L13+L15+L17 -> 685.10803 | M18: =M11+M13+M15+M17 -> 739.51462
A19: Cloud AI（命題子列） | B19: US$B | E19: =Thesis!E38 -> 13.119056 | F19: =Thesis!F38 -> 6.050155 | G19: =Thesis!G38 -> 19.169211 | H19: =Thesis!H38 -> 36.615799 | I19: =Thesis!I38 -> 57.29516 | J19: =Thesis!J38 -> 76.179473 | K19: =Thesis!K38 -> 90.433098 | L19: =Thesis!L38 -> 100.25294 | M19: =Thesis!M38 -> 105.73669 | N19: Thesis 頁：對外 MW × 每 MW 收入（9M26 為模型估計）
A20: TPU 系統銷售（命題子列） | B20: US$B | E20: 0 | F20: =tpu_2h -> 1 | G20: =E20+F20 -> 1 | H20: =tpu_yr -> 13 | I20: =tpu_yr -> 13 | J20: =tpu_yr -> 13 | K20: =tpu_yr -> 13 | L20: =tpu_yr -> 13 | M20: =tpu_yr -> 13 | N20: C8 b：不走 MW × 每 MW；9M26 已認列但金額未揭露 → 0（含在 Cloud 其他）
A21: Cloud 其他年增 | B21: % | F21: =g0_co -> 0.71107868 | H21: =g0_co+(gl_co-g0_co)*MIN(1,(2027-2026)/conv_n) -> 0.55330901 | I21: =g0_co+(gl_co-g0_co)*MIN(1,(2028-2026)/conv_n) -> 0.39553934 | J21: =g0_co+(gl_co-g0_co)*MIN(1,(2029-2026)/conv_n) -> 0.23776967 | K21: =g0_co+(gl_co-g0_co)*MIN(1,(2030-2026)/conv_n) -> 0.08 | L21: =g0_co+(gl_co-g0_co)*MIN(1,(2031-2026)/conv_n) -> 0.08 | M21: =g0_co+(gl_co-g0_co)*MIN(1,(2032-2026)/conv_n) -> 0.08 | N21: 起始＝Cloud 其他近四季年增（Thesis 頁 g0_co），FY2030 收斂到 gl_co
A22: Cloud 其他（命題子列） | B22: US$B | E22: =Q!L11-E19-E20 -> 62.385944 | F22: =E22*q3sh_cloud*(1+F21)^0.25 -> 29.019786 | G22: =E22+F22 -> 91.40573 | H22: =G22*(1+H21) -> 141.98134 | I22: =H22*(1+I21) -> 198.14055 | J22: =I22*(1+J21) -> 245.25236 | K22: =J22*(1+K21) -> 264.87255 | L22: =K22*(1+L21) -> 286.06236 | M22: =L22*(1+M21) -> 308.94735 | N22: 9M26＝Google Cloud 實績 − Cloud AI 估計 − TPU；Q4 26＝9M26 × Q3 占 9M 比例（Q 頁 q3sh_cloud）×(1＋年增)^0.25
A23: Google Cloud | B23: US$B | C23: =Q!J11 -> 43.229 | D23: =Q!K11 -> 58.705 | E23: =Q!L11 -> 75.505 | F23: =F19+F20+F22 -> 36.069941 | G23: =E23+F23 -> 111.57494 | H23: =H19+H20+H22 -> 191.59714 | I23: =I19+I20+I22 -> 268.43571 | J23: =J19+J20+J22 -> 334.43184 | K23: =K19+K20+K22 -> 368.30565 | L23: =L19+L20+L22 -> 399.3153 | M23: =M19+M20+M22 -> 427.68403
A24: Other Bets | B24: US$B | C24: =Q!J12 -> 1.648 | D24: =Q!K12 -> 1.537 | E24: =Q!L12 -> 1.165 | F24: =ob_rev_2H -> 0.38 | G24: =E24+F24 -> 1.545 | H24: =ob_rev_27 -> 1.6 | I24: =ob_rev_28 -> 1.8 | J24: =ob_rev_29 -> 2 | K24: =ob_rev_30 -> 2.2 | L24: =ob_rev_31 -> 2.4 | M24: =ob_rev_32 -> 2.6
A25: Hedging gains (losses) | B25: US$B | C25: =Q!J13 -> 0.211 | D25: =Q!K13 -> -0.127 | E25: =Q!L13 -> 0.12 | F25: 0 | G25: =E25+F25 -> 0.12 | H25: 0 | I25: 0 | J25: 0 | K25: 0 | L25: 0 | M25: 0 | N25: Alphabet-level activities；預測期 0 [Assumed]
A26: 合併營收 | B26: US$B | C26: =Q!J14 -> 350.018 | D26: =Q!K14 -> 402.836 | E26: =Q!L14 -> 357.269 | F26: =F18+F23+F24+F25 -> 145.60445 | G26: =E26+F26 -> 502.87345 | H26: =H18+H23+H24+H25 -> 642.42424 | I26: =I18+I23+I24+I25 -> 781.58983 | J26: =J18+J23+J24+J25 -> 910.45932 | K26: =K18+K23+K24+K25 -> 1005.3982 | L26: =L18+L23+L24+L25 -> 1086.8233 | M26: =M18+M23+M24+M25 -> 1169.7986
A27: 檢查：產品線合計 − Google Services | B27: US$B | C27: =C11+C13+C15+C17-C18 -> 0 | D27: =D11+D13+D15+D17-D18 -> 0 | E27: =E11+E13+E15+E17-E18 -> 0 | F27: =F11+F13+F15+F17-F18 -> 0 | G27: =G11+G13+G15+G17-G18 -> 0 | H27: =H11+H13+H15+H17-H18 -> 0 | I27: =I11+I13+I15+I17-I18 -> 0 | J27: =J11+J13+J15+J17-J18 -> 0 | ... M27: =M11+M13+M15+M17-M18 -> 0
A28: 檢查：Cloud 子列合計 − Google Cloud | B28: US$B | E28: =E19+E20+E22-E23 -> 0 | F28: =F19+F20+F22-F23 -> 0 | G28: =G19+G20+G22-G23 -> 0 | H28: =H19+H20+H22-H23 -> 0 | I28: =I19+I20+I22-I23 -> 0 | J28: =J19+J20+J22-J23 -> 0 | K28: =K19+K20+K22-K23 -> 0 | L28: =L19+L20+L22-L23 -> 0 | M28: =M19+M20+M22-M23 -> 0
A29: 檢查：分部合計＋避險 − 合併營收 | B29: US$B | C29: =C18+C23+C24+C25-C26 -> 0 | D29: =D18+D23+D24+D25-D26 -> 0 | E29: =E18+E23+E24+E25-E26 -> 0 | F29: =F18+F23+F24+F25-F26 -> 0 | G29: =G18+G23+G24+G25-G26 -> 0 | H29: =H18+H23+H24+H25-H26 -> 0 | I29: =I18+I23+I24+I25-I26 -> 0 | J29: =J18+J23+J24+J25-J26 -> 0 | ... M29: =M18+M23+M24+M25-M26 -> 0
A30: 檢查：實績欄合併營收 − Q 頁（FY2024、FY2025、9M26） | B30: US$B | C30: =C26-Q!J14 -> 0 | D30: =D26-Q!K14 -> 0 | E30: =E26-Q!L14 -> 0
A31: 非 AI 資本支出：Google Services（營收 × cx_svc） | B31: US$B | F31: =F18*cx_svc -> 6.5492707 | G31: =F31 -> 6.5492707 | H31: =H18*cx_svc -> 26.953626 | I31: =I18*cx_svc -> 30.681247 | J31: =J18*cx_svc -> 34.441649 | K31: =K18*cx_svc -> 38.093553 | L31: =L18*cx_svc -> 41.106482 | M31: =M18*cx_svc -> 44.370877
A32: 非 AI 資本支出：Cloud 其他（營收 × cx_co） | B32: US$B | F32: =F22*cx_co -> 5.8039572 | G32: =F32 -> 5.8039572 | H32: =H22*cx_co -> 28.396269 | I32: =I22*cx_co -> 39.62811 | J32: =J22*cx_co -> 49.050473 | K32: =K22*cx_co -> 52.974511 | L32: =L22*cx_co -> 57.212472 | M32: =M22*cx_co -> 61.789469
A33: 非 AI 資本支出：Other Bets（營收 × cx_ob） | B33: US$B | F33: =F24*cx_ob -> 0.0228 | G33: =F33 -> 0.0228 | H33: =H24*cx_ob -> 0.096 | I33: =I24*cx_ob -> 0.108 | J33: =J24*cx_ob -> 0.12 | K33: =K24*cx_ob -> 0.132 | L33: =L24*cx_ob -> 0.144 | M33: =M24*cx_ob -> 0.156
A34: 非 AI 資本支出合計 | B34: US$B | F34: =F31+F32+F33 -> 12.376028 | G34: =G31+G32+G33 -> 12.376028 | H34: =H31+H32+H33 -> 55.445894 | I34: =I31+I32+I33 -> 70.417358 | J34: =J31+J32+J33 -> 83.612122 | K34: =K31+K32+K33 -> 91.200064 | L34: =L31+L32+L33 -> 98.462953 | M34: =M31+M32+M33 -> 106.31635
A35: 新增非 AI 折舊：Google Services（年限 life_na） | B35: US$B | F35: =$F$31/life_na*IF((0)<0,0,IF((0)=0,phi_0,IF((0)<life_na,1,IF((0)=life_na,1-phi_0,0)))) -> 0.16373177 | G35: =F35 -> 0.16373177 | H35: =$F$31/life_na*IF((1)<0,0,IF((1)=0,phi_0,IF((1)<life_na,1,IF((1)=life_na,1-phi_0,0))))+$H$31/life_na*IF((0)<0,0,IF((0)=0,phi_0,IF((0)<life_na,1,IF((0)=life_na,1-phi_0,0)))) -> 1.3287677 | I35: =$F$31/life_na*IF((2)<0,0,IF((2)=0,phi_0,IF((2)<life_na,1,IF((2)=life_na,1-phi_0,0))))+$H$31/life_na*IF((1)<0,0,IF((1)=0,phi_0,IF((1)<life_na,1,IF((1)=life_na,1-phi_0,0))))+$I$31/life_na*IF((0)<0,0,IF((0)=0,phi_0,IF((0)<life_na,1,IF((0)=life_na,1-phi_0,0)))) -> 4.1173208 | J35: =$F$31/life_na*IF((3)<0,0,IF((3)=0,phi_0,IF((3)<life_na,1,IF((3)=life_na,1-phi_0,0))))+$H$31/life_na*IF((2)<0,0,IF((2)=0,phi_0,IF((2)<life_na,1,IF((2)=life_na,1-phi_0,0))))+$I$31/life_na*IF((1)<0,0,IF((1)=0,phi_0,IF((1)<life_na,1,IF((1)=life_na,1-phi_0,0))))+$J$31/life_na*IF((0)<0,0,IF((0)=0,phi_0,IF((0)<life_na,1,IF((0)=life_na,1-phi_0,0)))) -> 7.2794556 | K35: =$F$31/life_na*IF((4)<0,0,IF((4)=0,phi_0,IF((4)<life_na,1,IF((4)=life_na,1-phi_0,0))))+$H$31/life_na*IF((3)<0,0,IF((3)=0,phi_0,IF((3)<life_na,1,IF((3)=life_na,1-phi_0,0))))+$I$31/life_na*IF((2)<0,0,IF((2)=0,phi_0,IF((2)<life_na,1,IF((2)=life_na,1-phi_0,0))))+$J$31/life_na*IF((1)<0,0,IF((1)=0,phi_0,IF((1)<life_na,1,IF((1)=life_na,1-phi_0,0))))+$K$31/life_na*IF((0)<0,0,IF((0)=0,phi_0,IF((0)<life_na,1,IF((0)=life_na,1-phi_0,0)))) -> 10.814918 | L35: =$F$31/life_na*IF((5)<0,0,IF((5)=0,phi_0,IF((5)<life_na,1,IF((5)=life_na,1-phi_0,0))))+$H$31/life_na*IF((4)<0,0,IF((4)=0,phi_0,IF((4)<life_na,1,IF((4)=life_na,1-phi_0,0))))+$I$31/life_na*IF((3)<0,0,IF((3)=0,phi_0,IF((3)<life_na,1,IF((3)=life_na,1-phi_0,0))))+$J$31/life_na*IF((2)<0,0,IF((2)=0,phi_0,IF((2)<life_na,1,IF((2)=life_na,1-phi_0,0))))+$K$31/life_na*IF((1)<0,0,IF((1)=0,phi_0,IF((1)<life_na,1,IF((1)=life_na,1-phi_0,0))))+$L$31/life_na*IF((0)<0,0,IF((0)=0,phi_0,IF((0)<life_na,1,IF((0)=life_na,1-phi_0,0)))) -> 14.699597 | M35: =$F$31/life_na*IF((6)<0,0,IF((6)=0,phi_0,IF((6)<life_na,1,IF((6)=life_na,1-phi_0,0))))+$H$31/life_na*IF((5)<0,0,IF((5)=0,phi_0,IF((5)<life_na,1,IF((5)=life_na,1-phi_0,0))))+$I$31/life_na*IF((4)<0,0,IF((4)=0,phi_0,IF((4)<life_na,1,IF((4)=life_na,1-phi_0,0))))+$J$31/life_na*IF((3)<0,0,IF((3)=0,phi_0,IF((3)<life_na,1,IF((3)=life_na,1-phi_0,0))))+$K$31/life_na*IF((2)<0,0,IF((2)=0,phi_0,IF((2)<life_na,1,IF((2)=life_na,1-phi_0,0))))+$L$31/life_na*IF((1)<0,0,IF((1)=0,phi_0,IF((1)<life_na,1,IF((1)=life_na,1-phi_0,0))))+$M$31/life_na*IF((0)<0,0,IF((0)=0,phi_0,IF((0)<life_na,1,IF((0)=life_na,1-phi_0,0)))) -> 18.891855
A36: 新增非 AI 折舊：Cloud 其他（年限 life_na） | B36: US$B | F36: =$F$32/life_na*IF((0)<0,0,IF((0)=0,phi_0,IF((0)<life_na,1,IF((0)=life_na,1-phi_0,0)))) -> 0.14509893 | G36: =F36 -> 0.14509893 | H36: =$F$32/life_na*IF((1)<0,0,IF((1)=0,phi_0,IF((1)<life_na,1,IF((1)=life_na,1-phi_0,0))))+$H$32/life_na*IF((0)<0,0,IF((0)=0,phi_0,IF((0)<life_na,1,IF((0)=life_na,1-phi_0,0)))) -> 1.2903024 | I36: =$F$32/life_na*IF((2)<0,0,IF((2)=0,phi_0,IF((2)<life_na,1,IF((2)=life_na,1-phi_0,0))))+$H$32/life_na*IF((1)<0,0,IF((1)=0,phi_0,IF((1)<life_na,1,IF((1)=life_na,1-phi_0,0))))+$I$32/life_na*IF((0)<0,0,IF((0)=0,phi_0,IF((0)<life_na,1,IF((0)=life_na,1-phi_0,0)))) -> 4.4107254 | J36: =$F$32/life_na*IF((3)<0,0,IF((3)=0,phi_0,IF((3)<life_na,1,IF((3)=life_na,1-phi_0,0))))+$H$32/life_na*IF((2)<0,0,IF((2)=0,phi_0,IF((2)<life_na,1,IF((2)=life_na,1-phi_0,0))))+$I$32/life_na*IF((1)<0,0,IF((1)=0,phi_0,IF((1)<life_na,1,IF((1)=life_na,1-phi_0,0))))+$J$32/life_na*IF((0)<0,0,IF((0)=0,phi_0,IF((0)<life_na,1,IF((0)=life_na,1-phi_0,0)))) -> 8.6090955 | K36: =$F$32/life_na*IF((4)<0,0,IF((4)=0,phi_0,IF((4)<life_na,1,IF((4)=life_na,1-phi_0,0))))+$H$32/life_na*IF((3)<0,0,IF((3)=0,phi_0,IF((3)<life_na,1,IF((3)=life_na,1-phi_0,0))))+$I$32/life_na*IF((2)<0,0,IF((2)=0,phi_0,IF((2)<life_na,1,IF((2)=life_na,1-phi_0,0))))+$J$32/life_na*IF((1)<0,0,IF((1)=0,phi_0,IF((1)<life_na,1,IF((1)=life_na,1-phi_0,0))))+$K$32/life_na*IF((0)<0,0,IF((0)=0,phi_0,IF((0)<life_na,1,IF((0)=life_na,1-phi_0,0)))) -> 13.612244 | L36: =$F$32/life_na*IF((5)<0,0,IF((5)=0,phi_0,IF((5)<life_na,1,IF((5)=life_na,1-phi_0,0))))+$H$32/life_na*IF((4)<0,0,IF((4)=0,phi_0,IF((4)<life_na,1,IF((4)=life_na,1-phi_0,0))))+$I$32/life_na*IF((3)<0,0,IF((3)=0,phi_0,IF((3)<life_na,1,IF((3)=life_na,1-phi_0,0))))+$J$32/life_na*IF((2)<0,0,IF((2)=0,phi_0,IF((2)<life_na,1,IF((2)=life_na,1-phi_0,0))))+$K$32/life_na*IF((1)<0,0,IF((1)=0,phi_0,IF((1)<life_na,1,IF((1)=life_na,1-phi_0,0))))+$L$32/life_na*IF((0)<0,0,IF((0)=0,phi_0,IF((0)<life_na,1,IF((0)=life_na,1-phi_0,0)))) -> 19.015644 | M36: =$F$32/life_na*IF((6)<0,0,IF((6)=0,phi_0,IF((6)<life_na,1,IF((6)=life_na,1-phi_0,0))))+$H$32/life_na*IF((5)<0,0,IF((5)=0,phi_0,IF((5)<life_na,1,IF((5)=life_na,1-phi_0,0))))+$I$32/life_na*IF((4)<0,0,IF((4)=0,phi_0,IF((4)<life_na,1,IF((4)=life_na,1-phi_0,0))))+$J$32/life_na*IF((3)<0,0,IF((3)=0,phi_0,IF((3)<life_na,1,IF((3)=life_na,1-phi_0,0))))+$K$32/life_na*IF((2)<0,0,IF((2)=0,phi_0,IF((2)<life_na,1,IF((2)=life_na,1-phi_0,0))))+$L$32/life_na*IF((1)<0,0,IF((1)=0,phi_0,IF((1)<life_na,1,IF((1)=life_na,1-phi_0,0))))+$M$32/life_na*IF((0)<0,0,IF((0)=0,phi_0,IF((0)<life_na,1,IF((0)=life_na,1-phi_0,0)))) -> 24.851316
A37: 新增非 AI 折舊：Other Bets（年限 life_na） | B37: US$B | F37: =$F$33/life_na*IF((0)<0,0,IF((0)=0,phi_0,IF((0)<life_na,1,IF((0)=life_na,1-phi_0,0)))) -> 0.00057 | G37: =F37 -> 0.00057 | H37: =$F$33/life_na*IF((1)<0,0,IF((1)=0,phi_0,IF((1)<life_na,1,IF((1)=life_na,1-phi_0,0))))+$H$33/life_na*IF((0)<0,0,IF((0)=0,phi_0,IF((0)<life_na,1,IF((0)=life_na,1-phi_0,0)))) -> 0.00468 | I37: =$F$33/life_na*IF((2)<0,0,IF((2)=0,phi_0,IF((2)<life_na,1,IF((2)=life_na,1-phi_0,0))))+$H$33/life_na*IF((1)<0,0,IF((1)=0,phi_0,IF((1)<life_na,1,IF((1)=life_na,1-phi_0,0))))+$I$33/life_na*IF((0)<0,0,IF((0)=0,phi_0,IF((0)<life_na,1,IF((0)=life_na,1-phi_0,0)))) -> 0.01458 | J37: =$F$33/life_na*IF((3)<0,0,IF((3)=0,phi_0,IF((3)<life_na,1,IF((3)=life_na,1-phi_0,0))))+$H$33/life_na*IF((2)<0,0,IF((2)=0,phi_0,IF((2)<life_na,1,IF((2)=life_na,1-phi_0,0))))+$I$33/life_na*IF((1)<0,0,IF((1)=0,phi_0,IF((1)<life_na,1,IF((1)=life_na,1-phi_0,0))))+$J$33/life_na*IF((0)<0,0,IF((0)=0,phi_0,IF((0)<life_na,1,IF((0)=life_na,1-phi_0,0)))) -> 0.02568 | K37: =$F$33/life_na*IF((4)<0,0,IF((4)=0,phi_0,IF((4)<life_na,1,IF((4)=life_na,1-phi_0,0))))+$H$33/life_na*IF((3)<0,0,IF((3)=0,phi_0,IF((3)<life_na,1,IF((3)=life_na,1-phi_0,0))))+$I$33/life_na*IF((2)<0,0,IF((2)=0,phi_0,IF((2)<life_na,1,IF((2)=life_na,1-phi_0,0))))+$J$33/life_na*IF((1)<0,0,IF((1)=0,phi_0,IF((1)<life_na,1,IF((1)=life_na,1-phi_0,0))))+$K$33/life_na*IF((0)<0,0,IF((0)=0,phi_0,IF((0)<life_na,1,IF((0)=life_na,1-phi_0,0)))) -> 0.03798 | L37: =$F$33/life_na*IF((5)<0,0,IF((5)=0,phi_0,IF((5)<life_na,1,IF((5)=life_na,1-phi_0,0))))+$H$33/life_na*IF((4)<0,0,IF((4)=0,phi_0,IF((4)<life_na,1,IF((4)=life_na,1-phi_0,0))))+$I$33/life_na*IF((3)<0,0,IF((3)=0,phi_0,IF((3)<life_na,1,IF((3)=life_na,1-phi_0,0))))+$J$33/life_na*IF((2)<0,0,IF((2)=0,phi_0,IF((2)<life_na,1,IF((2)=life_na,1-phi_0,0))))+$K$33/life_na*IF((1)<0,0,IF((1)=0,phi_0,IF((1)<life_na,1,IF((1)=life_na,1-phi_0,0))))+$L$33/life_na*IF((0)<0,0,IF((0)=0,phi_0,IF((0)<life_na,1,IF((0)=life_na,1-phi_0,0)))) -> 0.05148 | M37: =$F$33/life_na*IF((6)<0,0,IF((6)=0,phi_0,IF((6)<life_na,1,IF((6)=life_na,1-phi_0,0))))+$H$33/life_na*IF((5)<0,0,IF((5)=0,phi_0,IF((5)<life_na,1,IF((5)=life_na,1-phi_0,0))))+$I$33/life_na*IF((4)<0,0,IF((4)=0,phi_0,IF((4)<life_na,1,IF((4)=life_na,1-phi_0,0))))+$J$33/life_na*IF((3)<0,0,IF((3)=0,phi_0,IF((3)<life_na,1,IF((3)=life_na,1-phi_0,0))))+$K$33/life_na*IF((2)<0,0,IF((2)=0,phi_0,IF((2)<life_na,1,IF((2)=life_na,1-phi_0,0))))+$L$33/life_na*IF((1)<0,0,IF((1)=0,phi_0,IF((1)<life_na,1,IF((1)=life_na,1-phi_0,0))))+$M$33/life_na*IF((0)<0,0,IF((0)=0,phi_0,IF((0)<life_na,1,IF((0)=life_na,1-phi_0,0)))) -> 0.06618
A38: 新增非 AI 折舊合計 | B38: US$B | F38: =F35+F36+F37 -> 0.3094007 | G38: =G35+G36+G37 -> 0.3094007 | H38: =H35+H36+H37 -> 2.6237502 | I38: =I35+I36+I37 -> 8.5426262 | J38: =J35+J36+J37 -> 15.914231 | K38: =K35+K36+K37 -> 24.465142 | L38: =L35+L36+L37 -> 33.76672 | M38: =M35+M36+M37 -> 43.809351
A40: 情境 B（近四季成長收斂；基準）
A41: 項目 | B41: 單位 | C41: FY2024A | D41: FY2025A | E41: 9M26A | F41: Q4 26E | G41: FY2026E | H41: FY2027E | I41: FY2028E | J41: FY2029E | K41: FY2030E | L41: FY2031E | M41: FY2032E | N41: 說明
A42: Search B 路徑年增 | B42: % | F42: =g0_search -> 0.16056206 | H42: =g0_search+(gl_search-g0_search)*MIN(1,(2027-2026)/conv_n) -> 0.14042155 | I42: =g0_search+(gl_search-g0_search)*MIN(1,(2028-2026)/conv_n) -> 0.12028103 | J42: =g0_search+(gl_search-g0_search)*MIN(1,(2029-2026)/conv_n) -> 0.10014052 | K42: =g0_search+(gl_search-g0_search)*MIN(1,(2030-2026)/conv_n) -> 0.08 | L42: =g0_search+(gl_search-g0_search)*MIN(1,(2031-2026)/conv_n) -> 0.08 | M42: =g0_search+(gl_search-g0_search)*MIN(1,(2032-2026)/conv_n) -> 0.08 | N42: Q4 26 年增＝近四季年增（Q 頁），FY2030 收斂到 gl_search
...

Sheet PL
A1: PL — 分部營收 → 分部營業利益 → 合併營業利益 → 業外 → 稅 → 淨利 → EPS（三情境；US$B，EPS 美元）。實績欄（FY2024A、FY2025A、9M26A）取自 Q 頁；FY2026E＝9M 實績＋Q4 模型
A2: 分部營業利益＝分部 EBITDA − 分攤折舊。分部 EBITDA：Google Services＝B 路徑營收 × 近四季 EBITDA 率＋Search 情境差額 × 增量 EBITDA 率 − 自用 AI 增量營運成本 × svc_sh；Google Cloud＝Cloud AI EBITDA（Thesis）＋TPU × tpu_m＋Cloud 其他 × m_co。折舊＝評價日在役資產基礎折舊（按近四季營收分攤）＋新增 AI 折舊（對外→Cloud、自用→Services／Alphabet 層級）＋新增非 AI 折舊。持股評價損益預測期設 0
A4: 分部對帳彙總（三情境 × 全部年度取絕對值最大者；實績欄同列）
A5: 項目 | B5: 單位 | C5: FY2024A | D5: FY2025A | E5: 9M26A | F5: Q4 26E | G5: FY2026E | H5: FY2027E | I5: FY2028E | J5: FY2029E | K5: FY2030E | L5: FY2031E | M5: FY2032E | N5: 說明
A6: 檢查：產品線合計 − Google Services | B6: US$B | C6: =MAX(ABS(C26),ABS(C85),ABS(C144)) -> 0 | D6: =MAX(ABS(D26),ABS(D85),ABS(D144)) -> 0 | E6: =MAX(ABS(E26),ABS(E85),ABS(E144)) -> 0 | F6: =MAX(ABS(F26),ABS(F85),ABS(F144)) -> 0 | G6: =MAX(ABS(G26),ABS(G85),ABS(G144)) -> 0 | H6: =MAX(ABS(H26),ABS(H85),ABS(H144)) -> 0 | I6: =MAX(ABS(I26),ABS(I85),ABS(I144)) -> 0 | J6: =MAX(ABS(J26),ABS(J85),ABS(J144)) -> 0 | ... M6: =MAX(ABS(M26),ABS(M85),ABS(M144)) -> 0 | N6: 三情境各區塊同名核對列的最大絕對值；必須為 0（tools/segment_check 讀本列）
A7: 檢查：Cloud 子列合計 − Google Cloud | B7: US$B | E7: =MAX(ABS(E27),ABS(E86),ABS(E145)) -> 0 | F7: =MAX(ABS(F27),ABS(F86),ABS(F145)) -> 0 | G7: =MAX(ABS(G27),ABS(G86),ABS(G145)) -> 0 | H7: =MAX(ABS(H27),ABS(H86),ABS(H145)) -> 0 | I7: =MAX(ABS(I27),ABS(I86),ABS(I145)) -> 0 | J7: =MAX(ABS(J27),ABS(J86),ABS(J145)) -> 0 | K7: =MAX(ABS(K27),ABS(K86),ABS(K145)) -> 0 | L7: =MAX(ABS(L27),ABS(L86),ABS(L145)) -> 0 | M7: =MAX(ABS(M27),ABS(M86),ABS(M145)) -> 0 | N7: 三情境各區塊同名核對列的最大絕對值；必須為 0（tools/segment_check 讀本列）
A8: 檢查：分部合計＋避險 − 合併營收 | B8: US$B | C8: =MAX(ABS(C28),ABS(C87),ABS(C146)) -> 0 | D8: =MAX(ABS(D28),ABS(D87),ABS(D146)) -> 0 | E8: =MAX(ABS(E28),ABS(E87),ABS(E146)) -> 0 | F8: =MAX(ABS(F28),ABS(F87),ABS(F146)) -> 0 | G8: =MAX(ABS(G28),ABS(G87),ABS(G146)) -> 0 | H8: =MAX(ABS(H28),ABS(H87),ABS(H146)) -> 0 | I8: =MAX(ABS(I28),ABS(I87),ABS(I146)) -> 0 | J8: =MAX(ABS(J28),ABS(J87),ABS(J146)) -> 0 | ... M8: =MAX(ABS(M28),ABS(M87),ABS(M146)) -> 0 | N8: 三情境各區塊同名核對列的最大絕對值；必須為 0（tools/segment_check 讀本列）
A9: 檢查：分部營業利益合計 − 合併營業利益 | B9: US$B | C9: =MAX(ABS(C47),ABS(C106),ABS(C165)) -> 0 | D9: =MAX(ABS(D47),ABS(D106),ABS(D165)) -> 0 | E9: =MAX(ABS(E47),ABS(E106),ABS(E165)) -> 0 | F9: =MAX(ABS(F47),ABS(F106),ABS(F165)) -> 0 | G9: =MAX(ABS(G47),ABS(G106),ABS(G165)) -> 0 | H9: =MAX(ABS(H47),ABS(H106),ABS(H165)) -> 0 | I9: =MAX(ABS(I47),ABS(I106),ABS(I165)) -> 0 | J9: =MAX(ABS(J47),ABS(J106),ABS(J165)) -> 0 | ... M9: =MAX(ABS(M47),ABS(M106),ABS(M165)) -> 0 | N9: 三情境各區塊同名核對列的最大絕對值；必須為 0（tools/segment_check 讀本列）
A11: 情境 A（AI 搜尋擴大變現）
A12: 項目 | B12: 單位 | C12: FY2024A | D12: FY2025A | E12: 9M26A | F12: Q4 26E | G12: FY2026E | H12: FY2027E | I12: FY2028E | J12: FY2029E | K12: FY2030E | L12: FY2031E | M12: FY2032E | N12: 說明
A13: Google Search & other | B13: US$B | C13: =Seg!C11 -> 198.084 | D13: =Seg!D11 -> 224.532 | E13: =Seg!E11 -> 187.02 | F13: =Seg!F11 -> 73.200131 | G13: =Seg!G11 -> 260.22013 | H13: =Seg!H11 -> 307.98191 | I13: =Seg!I11 -> 357.80504 | J13: =Seg!J11 -> 407.92283 | ... M13: =Seg!M11 -> 532.15077
A14: YouTube ads | B14: US$B | C14: =Seg!C13 -> 36.147 | D14: =Seg!D13 -> 40.367 | E14: =Seg!E13 -> 32.145 | F14: =Seg!F13 -> 12.557448 | G14: =Seg!G13 -> 44.702448 | H14: =Seg!H13 -> 49.055649 | I14: =Seg!I13 -> 53.548548 | J14: =Seg!J13 -> 58.142687 | ... M14: =Seg!M13 -> 73.24304
