Workbook

Sheet README
A1: 世界先進（5347.TWO；VIS）個股模型 v0.1（AI 半導體 Project：代工層，8 吋成熟製程與特殊製程晶圓代工；樣板 guc/、營收結構參考 tsmc/） 2026-10-31
A2: 版本：v0.1（初版）。營收＝8 吋晶圓（產能 × 稼動率 × 美元售價 × 匯率）＋VSMC 新加坡 12 吋廠（FY2027 第一季量產；產能 × 稼動率 × 售價）。滾入 3Q26 營收實績（月營收）與 3Q26 毛利率指引；3Q26 財報 2026-11-05 公布後更新。本版未做先驗。
A3: 模型命題：世界先進以 8 吋成熟與特殊製程為主（2Q26 電源管理 IC 77%、面板驅動 IC 約 19%），獲利由 8 吋稼動率與價格循環決定；AI 伺服器電源帶動電源管理 IC 與分離式元件，稼動率回到 90% 以上，AI 相關占營收由上半年個位數升到下半年雙位數。新加坡 VSMC 12 吋廠（與 NXP 合資，持股 60%）2027 年第一季量產，初期折舊重；中國成熟製程擴產是價格的下行風險。
A4: 核心問題：8 吋稼動率與售價回升能走多遠（情境 A 稼動率 95%、售價 +6%），VSMC 量產初期的毛利率與非控制權益讓 EPS 增加多少；現價約 25 倍 FY2026 EPS、24 倍未來 12 月 EPS（模型 B），與同業前瞻 P/E 中位數 27.4 倍差多少。
A6: 會計年度＝日曆年，FY(t)＝CY(t)，不平移。FY2025A 實績、FY2026 錨點（1Q、2Q26 實績＋3Q26 營收實績與毛利率指引＋4Q26 假設）、FY2027–FY2029 驅動因子推導、FY2030–FY2032 收斂法。金額：十億新台幣；EPS：新台幣（基本）；口徑：歸屬母公司淨利（TIFRS）。晶圓：千片 8 吋；VSMC：千片 12 吋。
A8: 驅動因子 → 推導量（行業變數讀 Siliconomics；8 吋稼動率與售價為公司層級，待併入 Siliconomics）
A9: 8 吋晶圓：產能（FY2026 330.6 萬片，公司；FY2027–29 持平，粗線寬轉細線寬）× 稼動率（A／B／C：FY2027 95%／90%／80%、FY2028 94%／86%／74%、FY2029 93%／87%／78%）× 美元售價（FY2026 約 643 美元／片；FY2027 +6%／+3%／−3%、FY2028 +2%／0／−5%、FY2029 +1%／0／−2%）× 匯率 32（Siliconomics fx_twd）。
A10: VSMC 12 吋：產能 FY2027 144、FY2028 360、FY2029 504 千片（2029 年滿載月產能約 4.4 萬片）× 稼動率 90%／80%／65% × 售價 1,800 美元（Assumed）；毛利率 FY2027 5%／−5%／−20%、FY2028 20%／12%／0、FY2029 25%／18%／5%（Assumed，含折舊）；NXP 非控制權益 40%。AI 相關占營收只作記憶列（FY2026 10%、FY2027 起 25%／20%／15%），不進營收加總。
A11: 成本：8 吋銷貨成本內折舊（FY2026 約 86.6 億元＝公司預估折舊 96.2 億 × 0.9；年增 3%／2%／0）＋每片現金成本（FY2026 殘差，年增 2%）；營業費用彈性 0.5、年增下限 3%；營業外每年 15 億元、稅率 15%、股數 19.07 億股。
A12: 校準：FY2026 ＝ 1Q、2Q26 實績＋3Q26 營收實績（月營收 157.0 億元）與毛利率指引中點 33.5%＋4Q26 假設（營收季增 3%、毛利率 34%）。8 吋售價與每片現金成本以 FY2026 校準；不用券商數字（只在 Recon 對帳）。
A13: 估值：Val 第 0 節目標價＝0.5 × DCF 目標價（股東現金流＝EPS ×（1 − g／ROE），FY2027–32 明確期＋永續，r 10%、g 4%，三情境權重 0.3／0.5／0.2，情境價值負值取 0）＋0.5 × Comparable 目標價（聯電、格芯、中芯港股、高塔前瞻 P/E 中位數 × 12 個月後前瞻 EPS；不含 A 股；世界先進本身 Bloomberg 前瞻倍數待取，相對倍數調整係數自動取 1.0）；另列 Comparable 單獨目標價、市場共識目標價與差距拆解。十年 P/E 規則值 × FY2027 EPS 保留為參考（不是目標價）。本版未做先驗，無 Andy 合理 P/E 對照。
A14: 預估期間：FY2027–FY2029 由驅動因子推導；FY2030 起為收斂法，非驅動因子推導（營收年增由 FY2029 線性收斂到 fade_g、淨利率收斂到 fade_m，FY2032 達到；PL 頁灰底）。十年平均淨利率未找到，B、C 依工作單以 FY2029 × 0.8 代替。
... A21: 公司特有：8 吋稼動率 FY2027 95%／90%／80%、FY2028 94%／86%／74%、FY2029 93%／87%／78%；售價 FY2027 +6%／+3%／−3%、FY2028 +2%／0／−5%、FY2029 +1%／0／−2%（C＝中國成熟製程擴產的價格壓力）；VSMC 稼動率 90%／80%／65%、毛利率 FY2027 5%／−5%／−20%；AI 相關占比（記憶列）25%／20%／15%。
A23: ="投資建議："&Val!B135&"（依上檔空間固定規則）" -> 投資建議：中立（依上檔空間固定規則）
A24: ="重點觀察 1：目標價 NT$"&TEXT(Val!$B$39,"#,##0.00")&"（DCF "&TEXT(Val!$B$24,"#,##0.00")&"、Comparable（相對倍數調整後）"&TEXT(tp_comp_adj,"#,##0.00")&"；DCF 權重 "&TEXT(tp_w_dcf,"0%")&"），比現價 "&TEXT(px,"#,##0.00")&"（2026-10-22）"&IF(Val!$B$42>=0,"高 "&TEXT(Val!$B$42,"0.0%"),"低 "&TEXT(-Val!$B$42,"0.0%"))&"，級距 "&Val!$B$134&"、投資建議 "&Val!$B$135&"。相對倍數調整係數 "&TEXT(rm_factor,"0.00")&"（本公司 10 年前瞻倍數中位數 ÷ 同業的中位數，夾在 0.5–2.0；Val 第 0.5 節），調整前加權上檔空間 "&TEXT((tp_w_dcf*Val!$B$24+(1-tp_w_dcf)*Val!$B$35)/px-1,"+0.0%;−0.0%")&"；Comparable 單獨（市場主流同業法、未調整）為 "&TEXT(Val!$B$43,"+0.0%;−0.0%")&"。" -> 重點觀察 1：目標價 NT$126.59（DCF 77.48、Comparable（相對倍數調整後）175.69；DCF 權重 50%），比現價 161.00（2026-10-22）低 21.4%，級距 0%～−25%、投資建議 中立。相對倍數調整係數 1.00（本公司 10 年前瞻倍數中位數 ÷ 同業的中位數，夾在 0.5–2.0；Val 第 0.5 節），調整前加權上檔空間 −21.4%；Comparable 單獨（市場主流同業法、未調整）為 +9.1%。
A25: 重點觀察 2：DCF 與 Comparable 差距大：DCF 77.5 只有現價的 48%，因 ROE 近三年平均 12.9%、再投資率 31%，且情境 B 的 FY2028 EPS 6.37 低於 FY2027 的 6.88（8 吋稼動率 86%、售價持平，VSMC 量產初期毛利率 12%）；Comparable 用同業前瞻 P/E 中位數 27.4 倍，世界先進本身 Bloomberg 前瞻倍數待取，未做相對倍數調整。DCF 權重 0.3／0.7 使加權目標價 +15.5%／−15.5%，是最大的單一敏感度；上檔空間 −21.4% 距放空門檻 −25% 只差 3.6 個百分點。
A26: 重點觀察 3：VSMC 新加坡 12 吋廠 2027 年第一季量產：模型 FY2027 12 吋占營收 9.8%（情境 A；研究機構 12%）、FY2029 27%；8 吋售價 ±3% 使加權目標價 ±11.9%、匯率 30.5 使 −18.8%，VSMC 產能 ±20% 只有 ±1.2%。下一個檢驗點是 2026-11-05 的 3Q26 財報與法說（3Q26 毛利率 vs 指引 32.5–34.5%、4Q26 指引、VSMC 認證與量產時程）。
A28: 相對倍數調整（tools/relative_multiple.py；Val 第 0.5 節）已含在加權目標價：Comparable（相對倍數調整後）＝同業前瞻倍數中位數 × 本公司 10 年相對同業的倍數比（Bloomberg 前瞻倍數）。「Comparable 目標價（市場主流同業法）」維持不調整。重點觀察的數字以本版重算值撰寫（第 1 點第一句為公式）。
A30: v0.1（2026-10-31）：依個股模型原則第 8 節調整 In 頁呈現（數值不變）。In 頁 D／F 欄名改「敏感度低」「敏感度高」（只用於 Sens 頁、不進目標價）；In 頁最後新增「情境驅動對照」一節，把上方各情境專屬輸入三情境並排（只引用上方各列，純展示）；HTML 驅動因子一節分「情境驅動」與「單一參數」兩張表。

Sheet In
A1: In — 輸入（藍字；基準欄 E，低 D、高 F）。金額：十億新台幣（NT$B）；晶圓：千片（8 吋）；售價：美元／片；匯率：新台幣／美元。公司財報與法說為 Interested-party（公司說法）或 Verified（財報數字）；券商、資料商、媒體為 Interested-party。【v0.1】基準欄 E 進主模型；D／F＝敏感度低／高，只用於 Sens 頁（一次動一個參數）、不進目標價；情境 A／B／C 的驅動見本頁最後一節「情境驅動對照」。
A2: 標記：Verified／Interested-party／Analogy／Assumed／Derived；Analogy、Assumed 以情境或 Sens 區間呈現，不當點估計。行業變數讀 Siliconomics v0.10（siliconomics/data/siliconomics_snapshot_v0.10.json）；成熟製程稼動率與售價屬公司層級，說明欄標「待併入 Siliconomics」。SemiAnalysis 未使用
A3: 鍵 | B3: 項目 | C3: 單位 | D3: 敏感度低 | E3: 基準 | F3: 敏感度高 | G3: 標記 | H3: 來源1 | I3: 來源2／說明
A4: A. 行業變數（Siliconomics v0.10（siliconomics/data/siliconomics_snapshot_v0.10.json）；A／B／C 讀同字母上游，不自訂行業路徑）
A5: fx | B5: 匯率（FY2027 起；美元售價換算） | C5: NT$/US$ | D5: 30.5 | E5: 32 | F5: 33 | G5: Assumed | H5: Siliconomics v0.10（siliconomics/data/siliconomics_snapshot_v0.10.json）｜fx_twd | I5: Siliconomics 共用匯率（2026–2029）；與台積電、聯發科等台股模型同值
A6: B. 產能與稼動率（8 吋；公司層級，待併入 Siliconomics：Siliconomics 尚無成熟製程稼動率）
A7: cap_26 | B7: FY2026 產能（8 吋，千片／年） | C7: 千片 | E7: =Q!G7 -> 3306 | G7: Derived | H7: 科技新報 2026-05-05（1Q26 法說）：2026 年 8 吋產能約 330.6 萬片、年減約 4%（粗線寬淘汰並升級為細線寬） | I7: 季度產能以全年 ÷ 4 計（1Q26 歲修使月產能季減 9%，未拆分）
A8: capg27 | B8: FY2027 產能年增 | C8: % | E8: 0 | G8: Assumed | H8: Assumed：8 吋不新建廠；粗線寬轉細線寬、去瓶頸（公司 2Q26 法說） | I8: 三情境相同（產能為公司已核准的擴產；待併入 Siliconomics）
A9: capg28 | B9: FY2028 產能年增 | C9: % | E9: 0 | G9: Assumed | H9: 同上 | I9: 三情境相同（產能為公司已核准的擴產；待併入 Siliconomics）
A10: capg29 | B10: FY2029 產能年增 | C10: % | E10: 0 | G10: Assumed | H10: 同上 | I10: 三情境相同（產能為公司已核准的擴產；待併入 Siliconomics）
A11: cap_adj | B11: 產能係數（Sens 用；FY2027 起各年同乘） | C11: x | D11: 0.95 | E11: 1 | F11: 1.05 | G11: Assumed | H11: 無 | I11: ±5%：擴產時程提前或延後
A12: ut27_A | B12: FY2027 平均稼動率（情境 A） | C12: % | E12: 0.95 | G12: Assumed | H12: 優分析 2026-08-04（2Q26 法說轉述）：3Q26 稼動率約 90%、4Q26 可能超過 90%；出貨受設備與產能瓶頸限制 | I12: A 最有利、C 最不利（C＝中國成熟製程擴產的價格與份額壓力）；待併入 Siliconomics
A13: ut27_B | B13: FY2027 平均稼動率（情境 B） | C13: % | E13: 0.9 | G13: Assumed | H13: 同上 | I13: 待併入 Siliconomics
A14: ut27_C | B14: FY2027 平均稼動率（情境 C） | C14: % | E14: 0.8 | G14: Assumed | H14: 同上 | I14: 待併入 Siliconomics
A15: ut28_A | B15: FY2028 平均稼動率（情境 A） | C15: % | E15: 0.94 | G15: Assumed | H15: 同上 | I15: A 最有利、C 最不利（C＝中國成熟製程擴產的價格與份額壓力）；待併入 Siliconomics
A16: ut28_B | B16: FY2028 平均稼動率（情境 B） | C16: % | E16: 0.86 | G16: Assumed | H16: 同上 | I16: 待併入 Siliconomics
A17: ut28_C | B17: FY2028 平均稼動率（情境 C） | C17: % | E17: 0.74 | G17: Assumed | H17: 同上 | I17: 待併入 Siliconomics
A18: ut29_A | B18: FY2029 平均稼動率（情境 A） | C18: % | E18: 0.93 | G18: Assumed | H18: 同上 | I18: A 最有利、C 最不利（C＝中國成熟製程擴產的價格與份額壓力）；待併入 Siliconomics
A19: ut29_B | B19: FY2029 平均稼動率（情境 B） | C19: % | E19: 0.87 | G19: Assumed | H19: 同上 | I19: 待併入 Siliconomics
A20: ut29_C | B20: FY2029 平均稼動率（情境 C） | C20: % | E20: 0.78 | G20: Assumed | H20: 同上 | I20: 待併入 Siliconomics
A21: ut_adj | B21: 稼動率調整（Sens 用；FY2027 起各年加減，上限 98%） | C21: pt | D21: -0.03 | E21: 0 | F21: 0.03 | G21: Assumed | H21: 無 | I21: ±3 個百分點
A22: C. 平均售價（美元，每片 8 吋；公司層級，待併入 Siliconomics：Siliconomics 尚無成熟製程價格）
A23: asp_26 | B23: FY2026 平均售價（8 吋晶圓；美元／片） | C23: US$/片 | E23: =a26_rev/a26_ship/fx_26*1000000 -> 643.46941 | G23: Derived | H23: FY2026 營收 ÷ 出貨 ÷ 匯率（VSMC 尚未量產） | I23: 校準年；FY2027 起依情境年增
A24: asp27_A | B24: FY2027 平均售價年增（美元；情境 A） | C24: % | E24: 0.06 | G24: Assumed | H24: 工商時報 2026-08-06（法人）：花旗：產能吃緊、漲價空間增加；公司 2026 年長約到期影響低個位數（NOWnews 2026-02-03） | I24: A＝漲價延續；C＝中國成熟製程擴產造成價格壓力；待併入 Siliconomics
A25: asp27_B | B25: FY2027 平均售價年增（美元；情境 B） | C25: % | E25: 0.03 | G25: Assumed | H25: 同上 | I25: 待併入 Siliconomics
A26: asp27_C | B26: FY2027 平均售價年增（美元；情境 C） | C26: % | E26: -0.03 | G26: Assumed | H26: 同上 | I26: 待併入 Siliconomics
A27: asp28_A | B27: FY2028 平均售價年增（美元；情境 A） | C27: % | E27: 0.02 | G27: Assumed | H27: 同上 | I27: A＝漲價延續；C＝中國成熟製程擴產造成價格壓力；待併入 Siliconomics
A28: asp28_B | B28: FY2028 平均售價年增（美元；情境 B） | C28: % | E28: 0 | G28: Assumed | H28: 同上 | I28: 待併入 Siliconomics
A29: asp28_C | B29: FY2028 平均售價年增（美元；情境 C） | C29: % | E29: -0.05 | G29: Assumed | H29: 同上 | I29: 待併入 Siliconomics
A30: asp29_A | B30: FY2029 平均售價年增（美元；情境 A） | C30: % | E30: 0.01 | G30: Assumed | H30: 同上 | I30: A＝漲價延續；C＝中國成熟製程擴產造成價格壓力；待併入 Siliconomics
A31: asp29_B | B31: FY2029 平均售價年增（美元；情境 B） | C31: % | E31: 0 | G31: Assumed | H31: 同上 | I31: 待併入 Siliconomics
A32: asp29_C | B32: FY2029 平均售價年增（美元；情境 C） | C32: % | E32: -0.02 | G32: Assumed | H32: 同上 | I32: 待併入 Siliconomics
A33: asp_adj | B33: 售價水準調整（Sens 用；FY2027 起各年同乘 1＋x） | C33: % | D33: -0.03 | E33: 0 | F33: 0.03 | G33: Assumed | H33: 無 | I33: ±3%
A34: D. VSMC（新加坡 12 吋廠，與 NXP 合資，世界先進持股 60%、合併報表）：產能 × 稼動率 × 售價；毛利率路徑；非控制權益 40%
A35: vcap27 | B35: FY2027 VSMC 產能（12 吋，千片／年） | C35: 千片 | E35: 144 | G35: Assumed | H35: 公司：VSMC 2027 年第一季量產、良率 99%（工商時報 2026-08-06 轉述） | I35: 三情境相同（產能為公司規劃）
A36: vcap28 | B36: FY2028 VSMC 產能（12 吋，千片／年） | C36: 千片 | E36: 360 | G36: Assumed | H36: Assumed：月產能爬坡到約 3 萬片 | I36: 三情境相同（產能為公司規劃）
A37: vcap29 | B37: FY2029 VSMC 產能（12 吋，千片／年） | C37: 千片 | E37: 504 | G37: Assumed | H37: 公司：2029 年滿載月產能約 4.4 萬片（原 5.5 萬片；科技新報 2026-05-05） | I37: 三情境相同（產能為公司規劃）
A38: vcap_adj | B38: VSMC 產能係數（Sens 用） | C38: x | D38: 0.8 | E38: 1 | F38: 1.2 | G38: Assumed | H38: 無 | I38: ±20%：量產爬坡快慢
A39: vut_A | B39: VSMC 稼動率（FY2027 起；情境 A） | C39: % | E39: 0.9 | G39: Assumed | H39: 公司：2027 年量產時稼動率「會令人滿意」（NOWnews 2026-02-03） | I39: A 最有利、C 最不利
A40: vut_B | B40: VSMC 稼動率（FY2027 起；情境 B） | C40: % | E40: 0.8 | G40: Assumed | H40: 同上 | I40: —
...

Sheet Q
A1: Q — 實績與 FY2026 錨點（十億新台幣；EPS 為新台幣、基本；股數為十億股；晶圓為千片 8 吋）。藍字＝輸入（公司法說、媒體轉述、stockanalysis）；黑字＝公式
A2: FY2026 錨點＝1Q、2Q26 實績＋3Q26 營收實績（月營收）與公司指引（毛利率 32.5–34.5% 中點）＋4Q26 假設；3Q26 財報與法說 2026-11-05（stockanalysis），公布後更新
A3: 項目 | B3: FY2025A | C3: 1Q26（實績） | D3: 2Q26（實績） | E3: 3Q26（營收實績＋指引） | F3: 4Q26（模型） | G3: FY2026 錨點 | H3: 標記 | I3: 來源1 | J3: 來源2／說明
A4: 營收 | B4: 48.591 | C4: 12.532 | D4: 14.245 | E4: =42.479-26.777 -> 15.702 | F4: =E4*(1+q4_g) -> 16.17306 | G4: =SUM(C4:F4) -> 58.65206 | H4: Verified／Assumed（4Q） | I4: FY2025：stockanalysis 財報頁、科技新報 2026-02-03；1Q26：科技新報 2026-05-05；2Q26：優分析 2026-08-04；3Q26 營收：科技新報 2026-10-08（月營收） | J4: 3Q26：前 9 月 424.79 億 − 1H26 267.77 億（月營收）；4Q26＝3Q26 ×（1＋季增）
A5: 晶圓出貨（千片，8 吋） | C5: =C7*C6 -> 661.2 | D5: =D7*D6 -> 719.055 | E5: =E7*E6 -> 743.85 | F5: =F7*F6 -> 760.38 | G5: =SUM(C5:F5) -> 2884.485 | H5: Derived | I5: 產能 × 稼動率 | J5: 公司只揭露出貨季增率（1Q26 約 +3%、2Q26 指引 +11–13%）
A6: 稼動率 | C6: =ut_q1 -> 0.8 | D6: 0.87 | E6: 0.9 | F6: =q4_ut -> 0.92 | G6: =G5/G7 -> 0.8725 | H6: Interested-party／Assumed | I6: https://www.ctee.com.tw/news/20260806700216-430201：2Q26 約 87%；公司：3Q26 約 90%（指引） | J6: FY2026 欄＝出貨合計 ÷ 產能合計
A7: 產能（千片，8 吋） | C7: =3306/4 -> 826.5 | D7: =3306/4 -> 826.5 | E7: =3306/4 -> 826.5 | F7: =3306/4 -> 826.5 | G7: =SUM(C7:F7) -> 3306 | H7: Derived | I7: 公司：2026 年 8 吋產能約 330.6 萬片 ÷ 4 | J7: 季度產能未揭露（Assumed 平均分配）
A8: 平均售價（全部營收 ÷ 出貨；美元／片） | C8: =C4/C5/fx_26*1000000 -> 599.79171 | D8: =D4/D5/fx_26*1000000 -> 626.92164 | E8: =E4/E5/fx_26*1000000 -> 668.00932 | F8: =F4/F5/fx_26*1000000 -> 673.092 | G8: =G4/G5/fx_26*1000000 -> 643.46941 | H8: Derived | I8: 營收 ÷ 出貨 ÷ 匯率 | J8: 公司：1Q26 平均售價季減約 4%；2Q26、3Q26 指引季增 2–4%
A9: 毛利 | B9: 13.654 | C9: =C4*0.293 -> 3.671876 | D9: =D4*0.323 -> 4.601135 | E9: =E4*q3_gm -> 5.26017 | F9: =F4*q4_gm -> 5.4988404 | G9: =SUM(C9:F9) -> 19.032021 | H9: Verified（毛利率 × 營收）／Interested-party（3Q 指引）／Assumed（4Q） | I9: FY2025：stockanalysis 財報頁、科技新報 2026-02-03；1Q26：科技新報 2026-05-05；2Q26：優分析 2026-08-04；3Q26 營收：科技新報 2026-10-08（月營收） | J9: 毛利率 1Q26 29.3%、2Q26 32.3%（公司法說）
A10: 毛利率 | B10: =B9/B4 -> 0.28099854 | C10: =C9/C4 -> 0.293 | D10: =D9/D4 -> 0.323 | E10: =E9/E4 -> 0.335 | F10: =F9/F4 -> 0.34 | G10: =G9/G4 -> 0.32449025 | H10: Derived | I10: — | J10: 公司：4Q25 27.5%、1Q26 29.3%、2Q26 32.3%
A11: 營業費用 | B11: =B9-B12 -> 5.881 | C11: =C9-C12 -> 1.579032 | D11: =D9-D12 -> 1.695155 | E11: =q3_opx -> 1.75 | F11: =q4_opx -> 1.8 | G11: =SUM(C11:F11) -> 6.824187 | H11: Derived／Assumed | I11: FY2025：stockanalysis 財報頁、科技新報 2026-02-03；1Q26：科技新報 2026-05-05；2Q26：優分析 2026-08-04；3Q26 營收：科技新報 2026-10-08（月營收） | J11: 毛利 − 營業利益
A12: 營業利益 | B12: 7.773 | C12: =C4*0.167 -> 2.092844 | D12: =D4*0.204 -> 2.90598 | E12: =E9-E11 -> 3.51017 | F12: =F9-F11 -> 3.6988404 | G12: =SUM(C12:F12) -> 12.207834 | H12: Verified（營業利益率 × 營收）／Derived | I12: FY2025：stockanalysis 財報頁、科技新報 2026-02-03；1Q26：科技新報 2026-05-05；2Q26：優分析 2026-08-04；3Q26 營收：科技新報 2026-10-08（月營收） | J12: 營業利益率 1Q26 16.7%、2Q26 20.4%
A13: 營業外淨額 | B13: =B14-B12 -> 1.479 | C13: =C14-C12 -> 0.53487375 | D13: =D14-D12 -> 0.57463457 | E13: =q3_nonop -> 0.5 | F13: =q4_nonop -> 0.5 | G13: =SUM(C13:F13) -> 2.1095083 | H13: Derived／Assumed | I13: FY2025：stockanalysis 財報頁、科技新報 2026-02-03；1Q26：科技新報 2026-05-05；2Q26：優分析 2026-08-04；3Q26 營收：科技新報 2026-10-08（月營收） | J13: 稅前 − 營業利益
A14: 稅前利益 | B14: 9.252 | C14: =C17/(1-t_h1) -> 2.6277178 | D14: =D17/(1-t_h1) -> 3.4806146 | E14: =E12+E13 -> 4.01017 | F14: =F12+F13 -> 4.1988404 | G14: =SUM(C14:F14) -> 14.317343 | H14: Derived | I14: FY2025：stockanalysis 財報頁、科技新報 2026-02-03；1Q26：科技新報 2026-05-05；2Q26：優分析 2026-08-04；3Q26 營收：科技新報 2026-10-08（月營收） | J14: FY2025 由 stockanalysis 稅前淨利率推得；1Q、2Q26＝淨利 ÷（1 − FY2025 稅率）
A15: 所得稅 | B15: =B14-B17-B18 -> 1.344 | C15: =C14-C17-C18 -> 0.38171775 | D15: =D14-D17-D18 -> 0.50561457 | E15: =E14*q3_tax -> 0.58254091 | F15: =F14*q4_tax -> 0.60994828 | G15: =SUM(C15:F15) -> 2.0798215 | H15: Derived／Assumed | I15: FY2025：stockanalysis 財報頁、科技新報 2026-02-03；1Q26：科技新報 2026-05-05；2Q26：優分析 2026-08-04；3Q26 營收：科技新報 2026-10-08（月營收） | J15: 稅前 −（歸屬母公司淨利＋非控制權益）
A16: 有效稅率 | B16: =B15/B14 -> 0.14526589 | C16: =C15/C14 -> 0.14526589 | D16: =D15/D14 -> 0.14526589 | E16: =E15/E14 -> 0.14526589 | F16: =F15/F14 -> 0.14526589 | G16: =G15/G14 -> 0.14526589 | H16: Derived | I16: — | J16: —
A17: 歸屬母公司淨利 | B17: 7.908 | C17: 2.246 | D17: 2.975 | E17: =E14-E15-E18 -> 3.4276291 | F17: =F14-F15-F18 -> 3.5888921 | G17: =SUM(C17:F17) -> 12.237521 | H17: Verified／Derived | I17: FY2025：stockanalysis 財報頁、科技新報 2026-02-03；1Q26：科技新報 2026-05-05；2Q26：優分析 2026-08-04；3Q26 營收：科技新報 2026-10-08（月營收） | J17: 公司：1Q26 22.46 億、2Q26 29.75 億
A18: 非控制權益 | B18: 0 | C18: 0 | D18: 0 | E18: 0 | F18: 0 | G18: =SUM(C18:F18) -> 0 | H18: Derived／Assumed | I18: FY2025：stockanalysis 財報頁、科技新報 2026-02-03；1Q26：科技新報 2026-05-05；2Q26：優分析 2026-08-04；3Q26 營收：科技新報 2026-10-08（月營收） | J18: VSMC 量產前費用的非控制權益：未拆分（取 0）
A19: 加權股數（十億股） | B19: =7.908/4.22 -> 1.8739336 | C19: =2.246/1.18 -> 1.9033898 | D19: =2.975/1.56 -> 1.9070513 | E19: =q_sh -> 1.9070513 | F19: =q_sh -> 1.9070513 | G19: =AVERAGE(C19:F19) -> 1.9061359 | H19: Derived | I19: 淨利 ÷ EPS（公司） | J19: —
A20: EPS（基本） | B20: =B17/B19 -> 4.22 | C20: =C17/C19 -> 1.18 | D20: =D17/D19 -> 1.56 | E20: =E17/E19 -> 1.797345 | F20: =F17/F19 -> 1.8819065 | G20: =G17/G19 -> 6.4200675 | H20: Derived | I20: 淨利 ÷ 股數 | J20: —
A21: 公司揭露 EPS | B21: 4.22 | C21: 1.18 | D21: 1.56 | H21: Verified | I21: 公司：FY2025 4.22（stockanalysis）、1Q26 1.18、2Q26 1.56 | J21: 3Q26 EPS：2026-11-05 公布
A23: FY2026 錨點的檢查（參考；校準未使用券商數字）
A24: FY2026 營收年增 | B24: =G4/B4-1 -> 0.20705604
A25: 3Q26 營收季增 | B25: =E4/D4-1 -> 0.1022815
A26: FY2026 毛利率 | B26: =G10 -> 0.32449025
A27: FY2026 營業利益率 | B27: =G12/G4 -> 0.20813991
A28: 檢查：1H26 營收 自算 − 公司 267.77（應約為 0） | B28: =C4+D4-26.777 -> 0
A29: 檢查：1H26 EPS 自算 − 公司 2.74（應約為 0） | B29: =C20+D20-2.74 -> 0
A30: FY2026 平均售價（美元／8 吋片） | B30: =G8 -> 643.46941
A34: 官方報告分部與產品別（最近完整年度＋最近四季 3Q25–2Q26；分部原則第 3 條）
A35: 項目 | B35: FY2025A | C35: 3Q25 | D35: 4Q25 | E35: 1Q26 | F35: 2Q26 | G35: 最近四季合計 | H35: 標記 | I35: 來源1 | J35: 來源2／說明
A36: 晶圓代工營收（單一營運部門） | B36: 48.591 | C36: =12.594/1.02 -> 12.347059 | D36: 12.594 | E36: =C4 -> 12.532 | F36: =D4 -> 14.245 | G36: =SUM(C36:F36) -> 51.718059 | H36: Verified | I36: 公司：單一營運部門（晶圓代工）；4Q25 125.94 億（季增 2%） | J36: 3Q25＝4Q25 ÷ 1.02（Derived，四捨五入誤差另註）
A37: 電源管理 IC | F37: =F36*0.77 -> 10.96865 | H37: Interested-party | I37: https://uanalyze.com.tw/articles/8378052767：2Q26 電源管理 IC 77% | J37: 其他季比重：未找到
A38: 大尺寸面板驅動 IC | F38: =F36*0.12 -> 1.7094 | H38: Interested-party | I38: https://uanalyze.com.tw/articles/8378052767：2Q26 12% | J38: —
A39: 中小尺寸面板驅動 IC | F39: =F36*0.07 -> 0.99715 | H39: Interested-party | I39: https://uanalyze.com.tw/articles/8378052767：2Q26 約 7% | J39: —
A40: 其他（含分離式元件） | F40: =F36-F37-F38-F39 -> 0.5698 | H40: Derived | I40: 差額（公司：其他約 4%） | J40: 分離式元件未單獨揭露
A41: 檢查：分部合計 − 合併營收 | B41: =B36-B4 -> 0 | D41: =D36-12.594 -> 0 | E41: =E36-C4 -> 0 | F41: =F36-D4 -> 0 | H41: Derived | I41: — | J41: 應為 0（3Q25 為推得，不列核對）
A42: 檢查：子列合計 − 分部（2Q26） | F42: =F37+F38+F39+F40-F36 -> 0 | H42: Derived | I42: — | J42: 應為 0

Sheet Units
A1: Units — 世界先進 8 吋晶圓（千片）、稼動率、售價，與 VSMC 12 吋廠（三情境）。8 吋產能 FY2026 為公司揭露；VSMC 產能為公司規劃與 Assumed 爬坡
A3: 項目 | B3: 單位 | C3: FY2026 | D3: FY2027 | E3: FY2028 | F3: FY2029 | G3: 說明
A4: 1. 8 吋晶圓：三情境稼動率、出貨與售價
A5: 稼動率（情境 A） | B5: % | C5: =PL!D64 -> 0.8725 | D5: =PL!E64 -> 0.95 | E5: =PL!F64 -> 0.94 | F5: =PL!G64 -> 0.93 | G5: PL 頁各情境推導區塊
A6: 稼動率（情境 B） | B6: % | C6: =PL!D105 -> 0.8725 | D6: =PL!E105 -> 0.9 | E6: =PL!F105 -> 0.86 | F6: =PL!G105 -> 0.87 | G6: 同上
A7: 稼動率（情境 C） | B7: % | C7: =PL!D146 -> 0.8725 | D7: =PL!E146 -> 0.8 | E7: =PL!F146 -> 0.74 | F7: =PL!G146 -> 0.78 | G7: 同上
A8: 晶圓出貨（情境 A） | B8: 千片 | C8: =PL!D65 -> 2884.485 | D8: =PL!E65 -> 3140.7 | E8: =PL!F65 -> 3107.64 | F8: =PL!G65 -> 3074.58 | G8: PL 頁各情境推導區塊
A9: 晶圓出貨（情境 B） | B9: 千片 | C9: =PL!D106 -> 2884.485 | D9: =PL!E106 -> 2975.4 | E9: =PL!F106 -> 2843.16 | F9: =PL!G106 -> 2876.22 | G9: 同上
A10: 晶圓出貨（情境 C） | B10: 千片 | C10: =PL!D147 -> 2884.485 | D10: =PL!E147 -> 2644.8 | E10: =PL!F147 -> 2446.44 | F10: =PL!G147 -> 2578.68 | G10: 同上
A11: 平均售價（美元）（情境 A） | B11: US$/片 | C11: =PL!D66 -> 643.46941 | D11: =PL!E66 -> 682.07757 | E11: =PL!F66 -> 695.71912 | F11: =PL!G66 -> 702.67631 | G11: PL 頁各情境推導區塊
A12: 平均售價（美元）（情境 B） | B12: US$/片 | C12: =PL!D107 -> 643.46941 | D12: =PL!E107 -> 662.77349 | E12: =PL!F107 -> 662.77349 | F12: =PL!G107 -> 662.77349 | G12: 同上
A13: 平均售價（美元）（情境 C） | B13: US$/片 | C13: =PL!D148 -> 643.46941 | D13: =PL!E148 -> 624.16532 | E13: =PL!F148 -> 592.95706 | F13: =PL!G148 -> 581.09792 | G13: 同上
A14: 晶圓營收（情境 A） | B14: NT$B | C14: =PL!D69 -> 58.65206 | D14: =PL!E69 -> 68.550433 | E14: =PL!F69 -> 69.185426 | F14: =PL!G69 -> 69.133905 | G14: PL 頁各情境推導區塊
A15: 晶圓營收（情境 B） | B15: NT$B | C15: =PL!D110 -> 58.65206 | D15: =PL!E110 -> 63.10452 | E15: =PL!F110 -> 60.299874 | F15: =PL!G110 -> 61.001036 | G15: 同上
A16: 晶圓營收（情境 C） | B16: NT$B | C16: =PL!D151 -> 58.65206 | D16: =PL!E151 -> 52.825358 | E16: =PL!F151 -> 46.420284 | F16: =PL!G151 -> 47.950898 | G16: 同上
A18: 2. VSMC 12 吋廠與 AI 相關（三情境）
A19: VSMC 出貨（12 吋）（情境 A） | B19: 千片 | C19: =PL!D73 -> 0 | D19: =PL!E73 -> 129.6 | E19: =PL!F73 -> 324 | F19: =PL!G73 -> 453.6 | G19: PL 頁各情境推導區塊
A20: VSMC 出貨（12 吋）（情境 B） | B20: 千片 | C20: =PL!D114 -> 0 | D20: =PL!E114 -> 115.2 | E20: =PL!F114 -> 288 | F20: =PL!G114 -> 403.2 | G20: 同上
A21: VSMC 出貨（12 吋）（情境 C） | B21: 千片 | C21: =PL!D155 -> 0 | D21: =PL!E155 -> 93.6 | E21: =PL!F155 -> 234 | F21: =PL!G155 -> 327.6 | G21: 同上
A22: VSMC 營收（情境 A） | B22: NT$B | C22: =PL!D74 -> 0 | D22: =PL!E74 -> 7.46496 | E22: =PL!F74 -> 18.6624 | F22: =PL!G74 -> 26.12736 | G22: PL 頁各情境推導區塊
A23: VSMC 營收（情境 B） | B23: NT$B | C23: =PL!D115 -> 0 | D23: =PL!E115 -> 6.63552 | E23: =PL!F115 -> 16.5888 | F23: =PL!G115 -> 23.22432 | G23: 同上
A24: VSMC 營收（情境 C） | B24: NT$B | C24: =PL!D156 -> 0 | D24: =PL!E156 -> 5.39136 | E24: =PL!F156 -> 13.4784 | F24: =PL!G156 -> 18.86976 | G24: 同上
A25: 12 吋（VSMC）÷ 營收（情境 A） | B25: % | C25: =PL!D76 -> 0 | D25: =PL!E76 -> 0.098203268 | E25: =PL!F76 -> 0.21244009 | F25: =PL!G76 -> 0.27427055 | G25: PL 頁各情境推導區塊
A26: 12 吋（VSMC）÷ 營收（情境 B） | B26: % | C26: =PL!D117 -> 0 | D26: =PL!E117 -> 0.09514649 | E26: =PL!F117 -> 0.21575089 | F26: =PL!G117 -> 0.27574024 | G26: 同上
A27: 12 吋（VSMC）÷ 營收（情境 C） | B27: % | C27: =PL!D158 -> 0 | D27: =PL!E158 -> 0.092608449 | E27: =PL!F158 -> 0.22501997 | F27: =PL!G158 -> 0.2823941 | G27: 同上
A28: AI 相關 ÷ 營收（記憶列）（情境 A） | B28: % | C28: =PL!D77 -> 0.1 | D28: =PL!E77 -> 0.25 | E28: =PL!F77 -> 0.25 | F28: =PL!G77 -> 0.25 | G28: PL 頁各情境推導區塊
A29: AI 相關 ÷ 營收（記憶列）（情境 B） | B29: % | C29: =PL!D118 -> 0.1 | D29: =PL!E118 -> 0.2 | E29: =PL!F118 -> 0.2 | F29: =PL!G118 -> 0.2 | G29: 同上
A30: AI 相關 ÷ 營收（記憶列）（情境 C） | B30: % | C30: =PL!D159 -> 0.1 | D30: =PL!E159 -> 0.15 | E30: =PL!F159 -> 0.15 | F30: =PL!G159 -> 0.15 | G30: 同上
A32: 3. 校準值（只用 FY2026 已發生的實績與錨點；不用共識、不用 FY2027 起的目標）
A33: FY2026 平均售價（美元／片） | C33: =PL!D66 -> 643.46941 | G33: 晶圓營收 ÷ 出貨 ÷ 匯率
A34: FY2026 每片現金成本（NT$K） | C34: =PL!D81 -> 10.733992 | G34: 讓 FY2026 毛利等於錨點
A35: FY2026 銷貨成本內折舊（NT$B） | C35: =PL!D80 -> 8.658 | G35: 全公司折舊 × da_sh
A37: 讀法：8 吋稼動率與售價決定 FY2027 的大部分 EPS；VSMC 從 FY2027 起放量，量產初期毛利率為負（折舊重），FY2028 起的毛利率是 C 情境下修的主因之一。

Sheet PL
A1: PL — 世界先進損益（十億新台幣；EPS 新台幣、基本；歸屬母公司）。FY2025A 實績、FY2026 錨點（三情境相同），FY2027–FY2029 由驅動因子推導，FY2030–FY2032 為收斂法。FY(t)＝CY(t)。三情境各一個完整推導區塊（本頁下方），頂端為摘要
A2: 灰底＝FY2030–FY2032 收斂法（上游顆數只到 CY2029）：營收年增線性收斂到 fade_g、淨利率線性收斂到 fade_m（In 頁 I 節），非驅動因子推導
A3: 情境／項目 | B3: 單位 | C3: FY2025A | D3: FY2026（錨點） | E3: FY2027 | F3: FY2028 | G3: FY2029 | H3: FY2030（收斂） | I3: FY2031（收斂） | J3: FY2032（收斂） | K3: 說明
A4: 情境 A
A5: 營收 | B5: NT$B | C5: =C75 -> 48.591 | D5: =D75 -> 58.65206 | E5: =E75 -> 76.015393 | F5: =F75 -> 87.847826 | G5: =G75 -> 95.261265 | H5: =H75 -> 102.52586 | I5: =I75 -> 109.51093 | J5: =J75 -> 116.08159
A6: 營收年增 | B6: % | D6: =D78 -> 0.20705604 | E6: =E78 -> 0.29603961 | F6: =F78 -> 0.15565839 | G6: =G78 -> 0.084389555 | H6: =H78 -> 0.076259703 | I6: =I78 -> 0.068129852 | J6: =J78 -> 0.06
A7: 8 吋晶圓營收 | B7: NT$B | D7: =D69 -> 58.65206 | E7: =E69 -> 68.550433 | F7: =F69 -> 69.185426 | G7: =G69 -> 69.133905
A8: VSMC 營收（12 吋） | B8: NT$B | D8: =D74 -> 0 | E8: =E74 -> 7.46496 | F8: =F74 -> 18.6624 | G8: =G74 -> 26.12736
A9: AI 相關 ÷ 營收（記憶列） | B9: % | D9: =D77 -> 0.1 | E9: =E77 -> 0.25 | F9: =F77 -> 0.25 | G9: =G77 -> 0.25
A10: 稼動率 | B10: % | D10: =D64 -> 0.8725 | E10: =E64 -> 0.95 | F10: =F64 -> 0.94 | G10: =G64 -> 0.93
A11: 平均售價（美元） | B11: US$/片 | D11: =D66 -> 643.46941 | E11: =E66 -> 682.07757 | F11: =F66 -> 695.71912 | G11: =G66 -> 702.67631
A12: 毛利率 | B12: % | C12: =C86 -> 0.28099854 | D12: =D86 -> 0.32449025 | E12: =E86 -> 0.33702973 | F12: =F86 -> 0.33144577 | G12: =G86 -> 0.33116415
A13: 營業利益率 | B13: % | C13: =C89 -> 0.1599679 | D13: =D89 -> 0.20813991 | E13: =E89 -> 0.23396769 | F13: =F89 -> 0.23532456 | G13: =G89 -> 0.23878312
A14: 歸屬母公司淨利 | B14: NT$B | C14: =C94 -> 7.908 | D14: =D94 -> 12.237521 | E14: =E94 -> 16.265469 | F14: =F94 -> 17.577795 | G14: =G94 -> 18.388939 | H14: =H94 -> 19.791274 | I14: =I94 -> 21.139651 | J14: =J94 -> 22.40803
A15: 淨利率 | B15: % | C15: =C98 -> 0.16274619 | D15: =D98 -> 0.20864606 | E15: =E98 -> 0.213976 | F15: =F98 -> 0.20009369 | G15: =G98 -> 0.1930369 | H15: =H98 -> 0.1930369 | I15: =I98 -> 0.1930369 | J15: =J98 -> 0.1930369
A16: EPS | B16: NT$ | C16: =C96 -> 4.22 | D16: =D96 -> 6.4200675 | E16: =E96 -> 8.5291201 | F16: =F96 -> 9.2172642 | G16: =G96 -> 9.6426033 | H16: =H96 -> 10.377945 | I16: =I96 -> 11.084993 | J16: =J96 -> 11.750093
A17: EPS 年增 | B17: % | D17: =D97 -> 0.521343 | E17: =E97 -> 0.32850942 | F17: =F97 -> 0.080681718 | G17: =G97 -> 0.046145922 | H17: =H97 -> 0.076259703 | I17: =I97 -> 0.068129852 | J17: =J97 -> 0.06
A19: 情境 B
A20: 營收 | B20: NT$B | C20: =C116 -> 48.591 | D20: =D116 -> 58.65206 | E20: =E116 -> 69.74004 | F20: =F116 -> 76.888674 | G20: =G116 -> 84.225356 | H20: =H116 -> 90.70619 | I20: =I116 -> 96.010069 | J20: =J116 -> 99.850472
A21: 營收年增 | B21: % | D21: =D119 -> 0.20705604 | E21: =E119 -> 0.18904672 | F21: =F119 -> 0.10250402 | G21: =G119 -> 0.095419532 | H21: =H119 -> 0.076946355 | I21: =I119 -> 0.058473177 | J21: =J119 -> 0.04
A22: 8 吋晶圓營收 | B22: NT$B | D22: =D110 -> 58.65206 | E22: =E110 -> 63.10452 | F22: =F110 -> 60.299874 | G22: =G110 -> 61.001036
A23: VSMC 營收（12 吋） | B23: NT$B | D23: =D115 -> 0 | E23: =E115 -> 6.63552 | F23: =F115 -> 16.5888 | G23: =G115 -> 23.22432
A24: AI 相關 ÷ 營收（記憶列） | B24: % | D24: =D118 -> 0.1 | E24: =E118 -> 0.2 | F24: =F118 -> 0.2 | G24: =G118 -> 0.2
A25: 稼動率 | B25: % | D25: =D105 -> 0.8725 | E25: =E105 -> 0.9 | F25: =F105 -> 0.86 | G25: =G105 -> 0.87
A26: 平均售價（美元） | B26: US$/片 | D26: =D107 -> 643.46941 | E26: =E107 -> 662.77349 | F26: =F107 -> 662.77349 | G26: =G107 -> 662.77349
A27: 毛利率 | B27: % | C27: =C127 -> 0.28099854 | D27: =D127 -> 0.32449025 | E27: =E127 -> 0.30510917 | F27: =F127 -> 0.27888416 | G27: =G127 -> 0.27690357
A28: 營業利益率 | B28: % | C28: =C130 -> 0.1599679 | D28: =D130 -> 0.20813991 | E28: =E130 -> 0.19800811 | F28: =F130 -> 0.1767619 | G28: =G130 -> 0.17922913
A29: 歸屬母公司淨利 | B29: NT$B | C29: =C135 -> 7.908 | D29: =D135 -> 12.237521 | E29: =E135 -> 13.125533 | F29: =F135 -> 12.150517 | G29: =G135 -> 12.684963 | H29: =H135 -> 13.205658 | I29: =I135 -> 13.49584 | J29: =J135 -> 13.5344
A30: 淨利率 | B30: % | C30: =C139 -> 0.16274619 | D30: =D139 -> 0.20864606 | E30: =E139 -> 0.18820657 | F30: =F139 -> 0.15802739 | G30: =G139 -> 0.15060742 | H30: =H139 -> 0.14558717 | I30: =I139 -> 0.14056692 | J30: =J139 -> 0.13554668
A31: EPS | B31: NT$ | C31: =C137 -> 4.22 | D31: =D137 -> 6.4200675 | E31: =E137 -> 6.8826326 | F31: =F137 -> 6.3713635 | G31: =G137 -> 6.6516111 | H31: =H137 -> 6.9246473 | I31: =I137 -> 7.0768102 | J31: =J137 -> 7.0970297
A32: EPS 年增 | B32: % | D32: =D138 -> 0.521343 | E32: =E138 -> 0.072049891 | F32: =F138 -> -0.074283953 | G32: =G138 -> 0.043985497 | H32: =H138 -> 0.041048143 | I32: =I138 -> 0.021974102 | J32: =J138 -> 0.0028571429
A34: 情境 C
A35: 營收 | B35: NT$B | C35: =C157 -> 48.591 | D35: =D157 -> 58.65206 | E35: =E157 -> 58.216718 | F35: =F157 -> 59.898684 | G35: =G157 -> 66.820658 | H35: =H157 -> 72.414055 | I35: =I157 -> 76.168998 | J35: =J157 -> 77.692378
A36: 營收年增 | B36: % | D36: =D160 -> 0.20705604 | E36: =E160 -> -0.007422445 | F36: =F160 -> 0.028891448 | G36: =G160 -> 0.11556138 | H36: =H160 -> 0.083707589 | I36: =I160 -> 0.051853795 | J36: =J160 -> 0.02
A37: 8 吋晶圓營收 | B37: NT$B | D37: =D151 -> 58.65206 | E37: =E151 -> 52.825358 | F37: =F151 -> 46.420284 | G37: =G151 -> 47.950898
A38: VSMC 營收（12 吋） | B38: NT$B | D38: =D156 -> 0 | E38: =E156 -> 5.39136 | F38: =F156 -> 13.4784 | G38: =G156 -> 18.86976
A39: AI 相關 ÷ 營收（記憶列） | B39: % | D39: =D159 -> 0.1 | E39: =E159 -> 0.15 | F39: =F159 -> 0.15 | G39: =G159 -> 0.15
A40: 稼動率 | B40: % | D40: =D146 -> 0.8725 | E40: =E146 -> 0.8 | F40: =F146 -> 0.74 | G40: =G146 -> 0.78
A41: 平均售價（美元） | B41: US$/片 | D41: =D148 -> 643.46941 | E41: =E148 -> 624.16532 | F41: =F148 -> 592.95706 | G41: =G148 -> 581.09792
A42: 毛利率 | B42: % | C42: =C168 -> 0.28099854 | D42: =D168 -> 0.32449025 | E42: =E168 -> 0.23828721 | F42: =F168 -> 0.16700225 | G42: =G168 -> 0.15600793
...

Sheet Val
A1: Val — P/E 估值（新台幣）。結論用「現價 ÷ FY2027、FY2028 EPS（模型）」；目標價＝DCF 與 Comparable 加權（第 0 節）；十年 P/E 規則值（第 3 節，年底落後 P/E）只作參考
A2: 循環位置：世界先進不是設備股，不套設備市場見頂年；以本模型營收最高的會計年度為見頂年（比照創意、聯發科；FY(t)＝CY(t)）。營收到 FY2029 仍在增加時，見頂年未知，判為中段
A4: 0. 目標價
A5: 0.1 DCF（股東權益現金流，FY2027–FY2032 明確期＋FY2032 後永續）
A6: 項目 | B6: A（順利） | C6: B（平平） | D6: C（不如預期） | E6: 說明
A7: 情境 EPS（FY2027–FY2032） | E7: PL 頁各情境；FY2030 起為收斂法
A8: FY2027 | B8: =PL!E16 -> 8.5291201 | C8: =PL!E31 -> 6.8826326 | D8: =PL!E46 -> 3.9110071
A9: FY2028 | B9: =PL!F16 -> 9.2172642 | C9: =PL!F31 -> 6.3713635 | D9: =PL!F46 -> 1.9002739
A10: FY2029 | B10: =PL!G16 -> 9.6426033 | C10: =PL!G31 -> 6.6516111 | D10: =PL!G46 -> 1.7334087
A11: FY2030 | B11: =PL!H16 -> 10.377945 | C11: =PL!H31 -> 6.9246473 | D11: =PL!H46 -> 1.7532743
A12: FY2031 | B12: =PL!I16 -> 11.084993 | C12: =PL!I31 -> 7.0768102 | D12: =PL!I46 -> 1.7124605
A13: FY2032 | B13: =PL!J16 -> 11.750093 | C13: =PL!J31 -> 7.0970297 | D13: =PL!J46 -> 1.6123474
A14: 股東現金流＝EPS ×（1 − tp_g ÷ tp_roe）
A15: 再投資率（tp_g ÷ tp_roe，上限 0.8） | B15: =MIN(tp_g/tp_roe,0.8) -> 0.30991736 | E15: ROE 為近三年平均（In 頁 tp_roe）
A16: FY2027 | B16: =B8*(1-$B$15) -> 5.8857978 | C16: =C8*(1-$B$15) -> 4.7495853 | D16: =D8*(1-$B$15) -> 2.6989182
A17: FY2028 | B17: =B9*(1-$B$15) -> 6.3606741 | C17: =C9*(1-$B$15) -> 4.3967674 | D17: =D9*(1-$B$15) -> 1.311346
A18: FY2029 | B18: =B10*(1-$B$15) -> 6.6541932 | C18: =C10*(1-$B$15) -> 4.5901613 | D18: =D10*(1-$B$15) -> 1.1961953
A19: FY2030 | B19: =B11*(1-$B$15) -> 7.16164 | C19: =C11*(1-$B$15) -> 4.7785789 | D19: =D11*(1-$B$15) -> 1.2099042
A20: FY2031 | B20: =B12*(1-$B$15) -> 7.6495615 | C20: =C12*(1-$B$15) -> 4.8835839 | D20: =D12*(1-$B$15) -> 1.1817393
A21: FY2032 | B21: =B13*(1-$B$15) -> 8.1085352 | C21: =C13*(1-$B$15) -> 4.897537 | D21: =D13*(1-$B$15) -> 1.112653
A22: DCF 情境每股價值（折現率 tp_r） | B22: =MAX(0,SUMPRODUCT(B16:B21,1/(1+tp_r)^{1;2;3;4;5;6})+B21*(1+tp_g)/(tp_r-tp_g)/(1+tp_r)^6) -> 109.16085 | C22: =MAX(0,SUMPRODUCT(C16:C21,1/(1+tp_r)^{1;2;3;4;5;6})+C21*(1+tp_g)/(tp_r-tp_g)/(1+tp_r)^6) -> 68.379394 | D22: =MAX(0,SUMPRODUCT(D16:D21,1/(1+tp_r)^{1;2;3;4;5;6})+D21*(1+tp_g)/(tp_r-tp_g)/(1+tp_r)^6) -> 17.510685 | E22: Σ 明確期現金流 ÷ (1＋r)^t ＋ 永續價值 ÷ (1＋r)^6；永續價值＝FY2032 現金流 ×(1＋g)÷(r−g)；基準日 2026 年底；負值取 0
A23: DCF 情境價值推到 12 個月後（×(1＋tp_r)） | B23: =B22*(1+tp_r) -> 120.07694 | C23: =C22*(1+tp_r) -> 75.217334 | D23: =D22*(1+tp_r) -> 19.261754
A24: DCF 目標價（情境加權） | B24: =tp_wA*B23+tp_wB*C23+tp_wC*D23 -> 77.484099 | E24: Σ 權重 × 情境價值 ×(1＋r)；權重見 In 頁
A26: 0.2 Comparable（市場主流同業前瞻 P/E）
A27: 同業與前瞻 P/E | B27: 代號 | C27: 前瞻 12 月 P/E | D27: 日期 | E27: 來源 | F27: 標記
A28: 聯電（UMC） | B28: 2303.TW | C28: 20.22 | D28: 2026-10-22 | E28: stockanalysis.com forward PE（分析師共識；價格日期如左） | F28: Interested-party
A29: 格芯（GlobalFoundries） | B29: GFS | C29: 20.04 | D29: 2026-10-22 | E29: stockanalysis.com forward PE（抄自台積電模型 Val 頁同業表） | F29: Interested-party
A30: 中芯國際（SMIC，港股） | B30: 0981.HK | C30: 37.14 | D30: 2026-10-16 | E30: stockanalysis.com forward PE（抄自台積電模型 Val 頁同業表） | F30: Interested-party
A31: 高塔半導體（Tower） | B31: TSEM | C31: 34.63 | D31: 2026-10-26 | E31: stockanalysis.com forward PE（分析師共識；價格日期如左） | F31: Interested-party
A33: 同業前瞻 P/E 中位數 | B33: =MEDIAN(C28:C31) -> 27.425 | E33: 成熟與特殊製程晶圓代工同業（聯電、格芯、中芯港股、高塔）；不含 A 股（非 A 股公司，Andy 2026-10-25 11:53）；力積電、華虹前瞻 P/E 未取得或資料日過舊，未列
A34: 12 個月後的前瞻 EPS（情境加權） | B34: =tp_wA*(2/12*B8+10/12*B9)+tp_wB*(2/12*C8+10/12*C9)+tp_wC*(2/12*D8+10/12*D9) -> 6.4061388 | E34: 約 2027-10 時的未來 12 月 EPS ≈ 2／12 × FY2027＋10／12 × FY2028（會計年度＝日曆年）
A35: Comparable 目標價 | B35: =B33*B34 -> 175.68836 | E35: 同業中位數 × 前瞻 EPS
A37: 0.3 結論
A38: 項目 | B38: 數值 | E38: 說明
A39: 目標價（DCF 與 Comparable 加權） | B39: =tp_w_dcf*B24+(1-tp_w_dcf)*tp_comp_adj -> 126.58623 | E39: tp_w_dcf × DCF＋（1 − tp_w_dcf）× Comparable（相對倍數調整後，見第 0.5 節）
A40: Comparable 目標價（市場主流同業法） | B40: =B35 -> 175.68836
A41: 市場共識目標價 | B41: =cons_tp -> 183.18 | E41: stockanalysis：17 位分析師平均 183.18（2026-09-21 擷取；中位數 187、區間 89–220）
A42: 上檔空間：加權目標價 | B42: =B39/px-1 -> -0.21375014 | E42: 現價＝In 頁 px（2026-10-22 收盤）
A43: 上檔空間：Comparable 目標價 | B43: =B40/px-1 -> 0.091232024
A44: 與市場共識目標價的差距：EPS 因素 | B44: =B34/cons_feps-1 -> -0.047824072 | E44: 本模型前瞻 EPS ÷ 共識前瞻 EPS − 1；共識前瞻 EPS 見 In 頁 cons_feps
...

Sheet Recon
A1: Recon — 本模型 vs 公司說法、共識、券商。只作事後對照，不為對上數字而調參數。券商與資料商數字為 Interested-party，不用於校準
A3: 項目 | B3: 對照值 | C3: 模型 A | D3: 差距 A | E3: 模型 B | F3: 差距 B | G3: 模型 C | H3: 差距 C | I3: 對照來源 | J3: 說明
A4: A. FY2026 錨點 vs 共識
A5: FY2026 營收 vs 共識 | B5: =cons_rev26 -> 58.5 | C5: =PL!D75 -> 58.65206 | D5: =C5/B5-1 -> 0.0025993162 | E5: =PL!D116 -> 58.65206 | F5: =E5/B5-1 -> 0.0025993162 | G5: =PL!D157 -> 58.65206 | H5: =G5/B5-1 -> 0.0025993162 | I5: stockanalysis（15 位；2026-09-21） | J5: 共識資料日早於 3Q26 營收公布
A6: FY2026 EPS vs 共識 | B6: =cons_eps26 -> 6.05 | C6: =PL!D96 -> 6.4200675 | D6: =C6/B6-1 -> 0.061168177 | E6: =PL!D137 -> 6.4200675 | F6: =E6/B6-1 -> 0.061168177 | G6: =PL!D178 -> 6.4200675 | H6: =G6/B6-1 -> 0.061168177 | I6: stockanalysis（2026-09-21） | J6: 共識區間 5.46–6.50
A7: 3Q26 毛利率 vs 公司指引中點（百分點） | B7: =co_q3_gm -> 0.335 | C7: =Q!E10 -> 0.335 | D7: =C7-B7 -> 0 | E7: =Q!E10 -> 0.335 | F7: =E7-B7 -> 0 | G7: =Q!E10 -> 0.335 | H7: =G7-B7 -> 0 | I7: 優分析 2026-08-04（法說） | J7: 三欄同值（FY2026 錨點）；3Q26 財報 2026-11-05
A8: B. FY2027 vs 研究機構（校準未使用）
A9: FY2027 EPS vs 研究機構約 8 元 | B9: =an_eps27 -> 8 | C9: =PL!E96 -> 8.5291201 | D9: =C9/B9-1 -> 0.066140016 | E9: =PL!E137 -> 6.8826326 | F9: =E9/B9-1 -> -0.13967092 | G9: =PL!E178 -> 3.9110071 | H9: =G9/B9-1 -> -0.51112411 | I9: 工商時報 2026-08-06 | J9: FY2027 共識：未找到
A10: FY2027 毛利率 vs 研究機構 35%（百分點） | B10: =an_gm27 -> 0.35 | C10: =PL!E86 -> 0.33702973 | D10: =C10-B10 -> -0.012970268 | E10: =PL!E127 -> 0.30510917 | F10: =E10-B10 -> -0.044890829 | G10: =PL!E168 -> 0.23828721 | H10: =G10-B10 -> -0.11171279 | I10: 工商時報 2026-08-06
A11: FY2027 12 吋（VSMC）占營收 vs 研究機構 12%（百分點） | B11: =an_12sh27 -> 0.12 | C11: =PL!E76 -> 0.098203268 | D11: =C11-B11 -> -0.021796732 | E11: =PL!E117 -> 0.09514649 | F11: =E11-B11 -> -0.02485351 | G11: =PL!E158 -> 0.092608449 | H11: =G11-B11 -> -0.027391551 | I11: 工商時報 2026-08-06
A12: 共識前瞻 12 月 EPS vs 模型（情境加權 2／12 × FY2027＋10／12 × FY2028） | B12: =cons_feps -> 6.7278941 | C12: =Val!B34 -> 6.4061388 | D12: =C12/B12-1 -> -0.047824072 | E12: =Val!B34 -> 6.4061388 | F12: =E12/B12-1 -> -0.047824072 | G12: =Val!B34 -> 6.4061388 | H12: =G12/B12-1 -> -0.047824072 | I12: stockanalysis 前瞻 P/E 推得 | J12: 三欄同值（情境加權）
A13: 預留
A14: 成熟製程稼動率與價格的行業層（Siliconomics）尚未建立：上線後以本模型稼動率、售價情境對照行業路徑 | J14: 預留列：本版無數值

Sheet Sens
A1: Sens — 一次動一個輸入（In 頁敏感度低／高值），三情境都在本頁下方逐案重算（FY2026 恆等於錨點，每片現金成本在每個案例內重算），表內為情境加權後的 DCF、Comparable（相對倍數調整後）與加權目標價；另列 FY2027、FY2028 情境 A 的 EPS
A2: 相對基準＝案例加權目標價 ÷ 基準加權目標價 − 1。目標價參數（tp_r、tp_g、tp_w_dcf）三案只改 DCF 參數，PL 收斂法的 fade_g 不隨 tp_g 變動
A3: 案例 | B3: 設定 | C3: 鍵 | D3: FY2027 EPS（A） | E3: FY2028 EPS（A） | F3: FY2028 EPS 相對基準（A） | G3: DCF 目標價 | H3: Comparable（調整後）目標價 | I3: 加權目標價 | J3: 相對基準
A4: 基準（三情境加權） | B4: PL 頁三個推導區塊 | C4: — | D4: =PL!E96 -> 8.5291201 | E4: =PL!F96 -> 9.2172642 | F4: =E4/E$4-1 -> 0 | G4: =(tp_wA*MAX(0,PL!E96*(1-MIN(tp_g/tp_roe,0.8))/(1+tp_r)^1+PL!F96*(1-MIN(tp_g/tp_roe,0.8))/(1+tp_r)^2+PL!G96*(1-MIN(tp_g/tp_roe,0.8))/(1+tp_r)^3+PL!H96*(1-MIN(tp_g/tp_roe,0.8))/(1+tp_r)^4+PL!I96*(1-MIN(tp_g/tp_roe,0.8))/(1+tp_r)^5+PL!J96*(1-MIN(tp_g/tp_roe,0.8))/(1+tp_r)^6+PL!J96*(1-MIN(tp_g/tp_roe,0.8))*(1+tp_g)/(tp_r-tp_g)/(1+tp_r)^6)+tp_wB*MAX(0,PL!E137*(1-MIN(tp_g/tp_roe,0.8))/(1+tp_r)^1+PL!F137*(1-MIN(tp_g/tp_roe,0.8))/(1+tp_r)^2+PL!G137*(1-MIN(tp_g/tp_roe,0.8))/(1+tp_r)^3+PL!H137*(1-MIN(tp_g/tp_roe,0.8))/(1+tp_r)^4+PL!I137*(1-MIN(tp_g/tp_roe,0.8))/(1+tp_r)^5+PL!J137*(1-MIN(tp_g/tp_roe,0.8))/(1+tp_r)^6+PL!J137*(1-MIN(tp_g/tp_roe,0.8))*(1+tp_g)/(tp_r-tp_g)/(1+tp_r)^6)+tp_wC*MAX(0,PL!E178*(1-MIN(tp_g/tp_roe,0.8))/(1+tp_r)^1+PL!F178*(1-MIN(tp_g/tp_roe,0.8))/(1+tp_r)^2+PL!G178*(1-MIN(tp_g/tp_roe,0.8))/(1+tp_r)^3+PL!H178*(1-MIN(tp_g/tp_roe,0.8))/(1+tp_r)^4+PL!I178*(1-MIN(tp_g/tp_roe,0.8))/(1+tp_r)^5+PL!J178*(1-MIN(tp_g/tp_roe,0.8))/(1+tp_r)^6+PL!J178*(1-MIN(tp_g/tp_roe,0.8))*(1+tp_g)/(tp_r-tp_g)/(1+tp_r)^6))*(1+tp_r) -> 77.484099 | H4: =Val!$B$33*(tp_wA*(2/12*PL!E96+10/12*PL!F96)+tp_wB*(2/12*PL!E137+10/12*PL!F137)+tp_wC*(2/12*PL!E178+10/12*PL!F178))*rm_factor -> 175.68836 | I4: =tp_w_dcf*G4+(1-tp_w_dcf)*H4 -> 126.58623 | J4: =I4/I$4-1 -> 0
A5: 匯率：低 | B5: =TEXT(fx_lo,"0.0")&"（基準 "&TEXT(fx,"0.0")&"）" -> 30.5（基準 32.0） | C5: fx | D5: =E74 -> 7.1846194 | E5: =F74 -> 7.8245771 | F5: =E5/E$4-1 -> -0.1510955 | G5: =(tp_wA*MAX(0,E74*(1-MIN(tp_g/tp_roe,0.8))/(1+tp_r)^1+F74*(1-MIN(tp_g/tp_roe,0.8))/(1+tp_r)^2+G74*(1-MIN(tp_g/tp_roe,0.8))/(1+tp_r)^3+H74*(1-MIN(tp_g/tp_roe,0.8))/(1+tp_r)^4+I74*(1-MIN(tp_g/tp_roe,0.8))/(1+tp_r)^5+J74*(1-MIN(tp_g/tp_roe,0.8))/(1+tp_r)^6+J74*(1-MIN(tp_g/tp_roe,0.8))*(1+tp_g)/(tp_r-tp_g)/(1+tp_r)^6)+tp_wB*MAX(0,E115*(1-MIN(tp_g/tp_roe,0.8))/(1+tp_r)^1+F115*(1-MIN(tp_g/tp_roe,0.8))/(1+tp_r)^2+G115*(1-MIN(tp_g/tp_roe,0.8))/(1+tp_r)^3+H115*(1-MIN(tp_g/tp_roe,0.8))/(1+tp_r)^4+I115*(1-MIN(tp_g/tp_roe,0.8))/(1+tp_r)^5+J115*(1-MIN(tp_g/tp_roe,0.8))/(1+tp_r)^6+J115*(1-MIN(tp_g/tp_roe,0.8))*(1+tp_g)/(tp_r-tp_g)/(1+tp_r)^6)+tp_wC*MAX(0,E156*(1-MIN(tp_g/tp_roe,0.8))/(1+tp_r)^1+F156*(1-MIN(tp_g/tp_roe,0.8))/(1+tp_r)^2+G156*(1-MIN(tp_g/tp_roe,0.8))/(1+tp_r)^3+H156*(1-MIN(tp_g/tp_roe,0.8))/(1+tp_r)^4+I156*(1-MIN(tp_g/tp_roe,0.8))/(1+tp_r)^5+J156*(1-MIN(tp_g/tp_roe,0.8))/(1+tp_r)^6+J156*(1-MIN(tp_g/tp_roe,0.8))*(1+tp_g)/(tp_r-tp_g)/(1+tp_r)^6))*(1+tp_r) -> 63.113274 | H5: =Val!$B$33*(tp_wA*(2/12*E74+10/12*F74)+tp_wB*(2/12*E115+10/12*F115)+tp_wC*(2/12*E156+10/12*F156))*rm_factor -> 142.39339 | I5: =tp_w_dcf*G5+(1-tp_w_dcf)*H5 -> 102.75333 | J5: =I5/I$4-1 -> -0.188274
A6: 匯率：高 | B6: =TEXT(fx_hi,"0.0")&"（基準 "&TEXT(fx,"0.0")&"）" -> 33.0（基準 32.0） | C6: fx | D6: =E197 -> 9.425454 | E6: =F197 -> 10.145722 | F6: =E6/E$4-1 -> 0.10073033 | G6: =(tp_wA*MAX(0,E197*(1-MIN(tp_g/tp_roe,0.8))/(1+tp_r)^1+F197*(1-MIN(tp_g/tp_roe,0.8))/(1+tp_r)^2+G197*(1-MIN(tp_g/tp_roe,0.8))/(1+tp_r)^3+H197*(1-MIN(tp_g/tp_roe,0.8))/(1+tp_r)^4+I197*(1-MIN(tp_g/tp_roe,0.8))/(1+tp_r)^5+J197*(1-MIN(tp_g/tp_roe,0.8))/(1+tp_r)^6+J197*(1-MIN(tp_g/tp_roe,0.8))*(1+tp_g)/(tp_r-tp_g)/(1+tp_r)^6)+tp_wB*MAX(0,E238*(1-MIN(tp_g/tp_roe,0.8))/(1+tp_r)^1+F238*(1-MIN(tp_g/tp_roe,0.8))/(1+tp_r)^2+G238*(1-MIN(tp_g/tp_roe,0.8))/(1+tp_r)^3+H238*(1-MIN(tp_g/tp_roe,0.8))/(1+tp_r)^4+I238*(1-MIN(tp_g/tp_roe,0.8))/(1+tp_r)^5+J238*(1-MIN(tp_g/tp_roe,0.8))/(1+tp_r)^6+J238*(1-MIN(tp_g/tp_roe,0.8))*(1+tp_g)/(tp_r-tp_g)/(1+tp_r)^6)+tp_wC*MAX(0,E279*(1-MIN(tp_g/tp_roe,0.8))/(1+tp_r)^1+F279*(1-MIN(tp_g/tp_roe,0.8))/(1+tp_r)^2+G279*(1-MIN(tp_g/tp_roe,0.8))/(1+tp_r)^3+H279*(1-MIN(tp_g/tp_roe,0.8))/(1+tp_r)^4+I279*(1-MIN(tp_g/tp_roe,0.8))/(1+tp_r)^5+J279*(1-MIN(tp_g/tp_roe,0.8))/(1+tp_r)^6+J279*(1-MIN(tp_g/tp_roe,0.8))*(1+tp_g)/(tp_r-tp_g)/(1+tp_r)^6))*(1+tp_r) -> 87.064649 | H6: =Val!$B$33*(tp_wA*(2/12*E197+10/12*F197)+tp_wB*(2/12*E238+10/12*F238)+tp_wC*(2/12*E279+10/12*F279))*rm_factor -> 197.885 | I6: =tp_w_dcf*G6+(1-tp_w_dcf)*H6 -> 142.47482 | J6: =I6/I$4-1 -> 0.125516
A7: 8 吋產能係數：低 | B7: =TEXT(cap_adj_lo,"0.00")&"（基準 "&TEXT(cap_adj,"0.00")&"）" -> 0.95（基準 1.00） | C7: cap_adj | D7: =E320 -> 7.8566263 | E7: =F320 -> 8.5328729 | F7: =E7/E$4-1 -> -0.074251026 | G7: =(tp_wA*MAX(0,E320*(1-MIN(tp_g/tp_roe,0.8))/(1+tp_r)^1+F320*(1-MIN(tp_g/tp_roe,0.8))/(1+tp_r)^2+G320*(1-MIN(tp_g/tp_roe,0.8))/(1+tp_r)^3+H320*(1-MIN(tp_g/tp_roe,0.8))/(1+tp_r)^4+I320*(1-MIN(tp_g/tp_roe,0.8))/(1+tp_r)^5+J320*(1-MIN(tp_g/tp_roe,0.8))/(1+tp_r)^6+J320*(1-MIN(tp_g/tp_roe,0.8))*(1+tp_g)/(tp_r-tp_g)/(1+tp_r)^6)+tp_wB*MAX(0,E361*(1-MIN(tp_g/tp_roe,0.8))/(1+tp_r)^1+F361*(1-MIN(tp_g/tp_roe,0.8))/(1+tp_r)^2+G361*(1-MIN(tp_g/tp_roe,0.8))/(1+tp_r)^3+H361*(1-MIN(tp_g/tp_roe,0.8))/(1+tp_r)^4+I361*(1-MIN(tp_g/tp_roe,0.8))/(1+tp_r)^5+J361*(1-MIN(tp_g/tp_roe,0.8))/(1+tp_r)^6+J361*(1-MIN(tp_g/tp_roe,0.8))*(1+tp_g)/(tp_r-tp_g)/(1+tp_r)^6)+tp_wC*MAX(0,E402*(1-MIN(tp_g/tp_roe,0.8))/(1+tp_r)^1+F402*(1-MIN(tp_g/tp_roe,0.8))/(1+tp_r)^2+G402*(1-MIN(tp_g/tp_roe,0.8))/(1+tp_r)^3+H402*(1-MIN(tp_g/tp_roe,0.8))/(1+tp_r)^4+I402*(1-MIN(tp_g/tp_roe,0.8))/(1+tp_r)^5+J402*(1-MIN(tp_g/tp_roe,0.8))/(1+tp_r)^6+J402*(1-MIN(tp_g/tp_roe,0.8))*(1+tp_g)/(tp_r-tp_g)/(1+tp_r)^6))*(1+tp_r) -> 71.078346 | H7: =Val!$B$33*(tp_wA*(2/12*E320+10/12*F320)+tp_wB*(2/12*E361+10/12*F361)+tp_wC*(2/12*E402+10/12*F402))*rm_factor -> 159.8576 | I7: =tp_w_dcf*G7+(1-tp_w_dcf)*H7 -> 115.46797 | J7: =I7/I$4-1 -> -0.087831475
A8: 8 吋產能係數：高 | B8: =TEXT(cap_adj_hi,"0.00")&"（基準 "&TEXT(cap_adj,"0.00")&"）" -> 1.05（基準 1.00） | C8: cap_adj | D8: =E443 -> 9.201614 | E8: =F443 -> 9.9012019 | F8: =E8/E$4-1 -> 0.074201818 | G8: =(tp_wA*MAX(0,E443*(1-MIN(tp_g/tp_roe,0.8))/(1+tp_r)^1+F443*(1-MIN(tp_g/tp_roe,0.8))/(1+tp_r)^2+G443*(1-MIN(tp_g/tp_roe,0.8))/(1+tp_r)^3+H443*(1-MIN(tp_g/tp_roe,0.8))/(1+tp_r)^4+I443*(1-MIN(tp_g/tp_roe,0.8))/(1+tp_r)^5+J443*(1-MIN(tp_g/tp_roe,0.8))/(1+tp_r)^6+J443*(1-MIN(tp_g/tp_roe,0.8))*(1+tp_g)/(tp_r-tp_g)/(1+tp_r)^6)+tp_wB*MAX(0,E484*(1-MIN(tp_g/tp_roe,0.8))/(1+tp_r)^1+F484*(1-MIN(tp_g/tp_roe,0.8))/(1+tp_r)^2+G484*(1-MIN(tp_g/tp_roe,0.8))/(1+tp_r)^3+H484*(1-MIN(tp_g/tp_roe,0.8))/(1+tp_r)^4+I484*(1-MIN(tp_g/tp_roe,0.8))/(1+tp_r)^5+J484*(1-MIN(tp_g/tp_roe,0.8))/(1+tp_r)^6+J484*(1-MIN(tp_g/tp_roe,0.8))*(1+tp_g)/(tp_r-tp_g)/(1+tp_r)^6)+tp_wC*MAX(0,E525*(1-MIN(tp_g/tp_roe,0.8))/(1+tp_r)^1+F525*(1-MIN(tp_g/tp_roe,0.8))/(1+tp_r)^2+G525*(1-MIN(tp_g/tp_roe,0.8))/(1+tp_r)^3+H525*(1-MIN(tp_g/tp_roe,0.8))/(1+tp_r)^4+I525*(1-MIN(tp_g/tp_roe,0.8))/(1+tp_r)^5+J525*(1-MIN(tp_g/tp_roe,0.8))/(1+tp_r)^6+J525*(1-MIN(tp_g/tp_roe,0.8))*(1+tp_g)/(tp_r-tp_g)/(1+tp_r)^6))*(1+tp_r) -> 83.865734 | H8: =Val!$B$33*(tp_wA*(2/12*E443+10/12*F443)+tp_wB*(2/12*E484+10/12*F484)+tp_wC*(2/12*E525+10/12*F525))*rm_factor -> 191.51076 | I8: =tp_w_dcf*G8+(1-tp_w_dcf)*H8 -> 137.68825 | J8: =I8/I$4-1 -> 0.087703236
A9: 8 吋稼動率調整：低 | B9: =TEXT(ut_adj_lo,"0.0%")&"（基準 "&TEXT(ut_adj,"0.0%")&"）" -> -3.0%（基準 0.0%） | C9: ut_adj | D9: =E566 -> 8.1043872 | E9: =F566 -> 8.7804515 | F9: =E9/E$4-1 -> -0.04739071 | G9: =(tp_wA*MAX(0,E566*(1-MIN(tp_g/tp_roe,0.8))/(1+tp_r)^1+F566*(1-MIN(tp_g/tp_roe,0.8))/(1+tp_r)^2+G566*(1-MIN(tp_g/tp_roe,0.8))/(1+tp_r)^3+H566*(1-MIN(tp_g/tp_roe,0.8))/(1+tp_r)^4+I566*(1-MIN(tp_g/tp_roe,0.8))/(1+tp_r)^5+J566*(1-MIN(tp_g/tp_roe,0.8))/(1+tp_r)^6+J566*(1-MIN(tp_g/tp_roe,0.8))*(1+tp_g)/(tp_r-tp_g)/(1+tp_r)^6)+tp_wB*MAX(0,E607*(1-MIN(tp_g/tp_roe,0.8))/(1+tp_r)^1+F607*(1-MIN(tp_g/tp_roe,0.8))/(1+tp_r)^2+G607*(1-MIN(tp_g/tp_roe,0.8))/(1+tp_r)^3+H607*(1-MIN(tp_g/tp_roe,0.8))/(1+tp_r)^4+I607*(1-MIN(tp_g/tp_roe,0.8))/(1+tp_r)^5+J607*(1-MIN(tp_g/tp_roe,0.8))/(1+tp_r)^6+J607*(1-MIN(tp_g/tp_roe,0.8))*(1+tp_g)/(tp_r-tp_g)/(1+tp_r)^6)+tp_wC*MAX(0,E648*(1-MIN(tp_g/tp_roe,0.8))/(1+tp_r)^1+F648*(1-MIN(tp_g/tp_roe,0.8))/(1+tp_r)^2+G648*(1-MIN(tp_g/tp_roe,0.8))/(1+tp_r)^3+H648*(1-MIN(tp_g/tp_roe,0.8))/(1+tp_r)^4+I648*(1-MIN(tp_g/tp_roe,0.8))/(1+tp_r)^5+J648*(1-MIN(tp_g/tp_roe,0.8))/(1+tp_r)^6+J648*(1-MIN(tp_g/tp_roe,0.8))*(1+tp_g)/(tp_r-tp_g)/(1+tp_r)^6))*(1+tp_r) -> 73.11507 | H9: =Val!$B$33*(tp_wA*(2/12*E566+10/12*F566)+tp_wB*(2/12*E607+10/12*F607)+tp_wC*(2/12*E648+10/12*F648))*rm_factor -> 164.78031 | I9: =tp_w_dcf*G9+(1-tp_w_dcf)*H9 -> 118.94769 | J9: =I9/I$4-1 -> -0.060342555
A10: 8 吋稼動率調整：高 | B10: =TEXT(ut_adj_hi,"0.0%")&"（基準 "&TEXT(ut_adj,"0.0%")&"）" -> 3.0%（基準 0.0%） | C10: ut_adj | D10: =E689 -> 8.9538531 | E10: =F689 -> 9.6539094 | F10: =E10/E$4-1 -> 0.047372543 | G10: =(tp_wA*MAX(0,E689*(1-MIN(tp_g/tp_roe,0.8))/(1+tp_r)^1+F689*(1-MIN(tp_g/tp_roe,0.8))/(1+tp_r)^2+G689*(1-MIN(tp_g/tp_roe,0.8))/(1+tp_r)^3+H689*(1-MIN(tp_g/tp_roe,0.8))/(1+tp_r)^4+I689*(1-MIN(tp_g/tp_roe,0.8))/(1+tp_r)^5+J689*(1-MIN(tp_g/tp_roe,0.8))/(1+tp_r)^6+J689*(1-MIN(tp_g/tp_roe,0.8))*(1+tp_g)/(tp_r-tp_g)/(1+tp_r)^6)+tp_wB*MAX(0,E730*(1-MIN(tp_g/tp_roe,0.8))/(1+tp_r)^1+F730*(1-MIN(tp_g/tp_roe,0.8))/(1+tp_r)^2+G730*(1-MIN(tp_g/tp_roe,0.8))/(1+tp_r)^3+H730*(1-MIN(tp_g/tp_roe,0.8))/(1+tp_r)^4+I730*(1-MIN(tp_g/tp_roe,0.8))/(1+tp_r)^5+J730*(1-MIN(tp_g/tp_roe,0.8))/(1+tp_r)^6+J730*(1-MIN(tp_g/tp_roe,0.8))*(1+tp_g)/(tp_r-tp_g)/(1+tp_r)^6)+tp_wC*MAX(0,E771*(1-MIN(tp_g/tp_roe,0.8))/(1+tp_r)^1+F771*(1-MIN(tp_g/tp_roe,0.8))/(1+tp_r)^2+G771*(1-MIN(tp_g/tp_roe,0.8))/(1+tp_r)^3+H771*(1-MIN(tp_g/tp_roe,0.8))/(1+tp_r)^4+I771*(1-MIN(tp_g/tp_roe,0.8))/(1+tp_r)^5+J771*(1-MIN(tp_g/tp_roe,0.8))/(1+tp_r)^6+J771*(1-MIN(tp_g/tp_roe,0.8))*(1+tp_g)/(tp_r-tp_g)/(1+tp_r)^6))*(1+tp_r) -> 81.840072 | H10: =Val!$B$33*(tp_wA*(2/12*E689+10/12*F689)+tp_wB*(2/12*E730+10/12*F730)+tp_wC*(2/12*E771+10/12*F771))*rm_factor -> 186.59363 | I10: =tp_w_dcf*G10+(1-tp_w_dcf)*H10 -> 134.21685 | J10: =I10/I$4-1 -> 0.060280041
A11: 8 吋售價水準調整：低 | B11: =TEXT(asp_adj_lo,"0.0%")&"（基準 "&TEXT(asp_adj,"0.0%")&"）" -> -3.0%（基準 0.0%） | C11: asp_adj | D11: =E812 -> 7.6658273 | E11: =F812 -> 8.3426322 | F11: =E11/E$4-1 -> -0.094890634 | G11: =(tp_wA*MAX(0,E812*(1-MIN(tp_g/tp_roe,0.8))/(1+tp_r)^1+F812*(1-MIN(tp_g/tp_roe,0.8))/(1+tp_r)^2+G812*(1-MIN(tp_g/tp_roe,0.8))/(1+tp_r)^3+H812*(1-MIN(tp_g/tp_roe,0.8))/(1+tp_r)^4+I812*(1-MIN(tp_g/tp_roe,0.8))/(1+tp_r)^5+J812*(1-MIN(tp_g/tp_roe,0.8))/(1+tp_r)^6+J812*(1-MIN(tp_g/tp_roe,0.8))*(1+tp_g)/(tp_r-tp_g)/(1+tp_r)^6)+tp_wB*MAX(0,E853*(1-MIN(tp_g/tp_roe,0.8))/(1+tp_r)^1+F853*(1-MIN(tp_g/tp_roe,0.8))/(1+tp_r)^2+G853*(1-MIN(tp_g/tp_roe,0.8))/(1+tp_r)^3+H853*(1-MIN(tp_g/tp_roe,0.8))/(1+tp_r)^4+I853*(1-MIN(tp_g/tp_roe,0.8))/(1+tp_r)^5+J853*(1-MIN(tp_g/tp_roe,0.8))/(1+tp_r)^6+J853*(1-MIN(tp_g/tp_roe,0.8))*(1+tp_g)/(tp_r-tp_g)/(1+tp_r)^6)+tp_wC*MAX(0,E894*(1-MIN(tp_g/tp_roe,0.8))/(1+tp_r)^1+F894*(1-MIN(tp_g/tp_roe,0.8))/(1+tp_r)^2+G894*(1-MIN(tp_g/tp_roe,0.8))/(1+tp_r)^3+H894*(1-MIN(tp_g/tp_roe,0.8))/(1+tp_r)^4+I894*(1-MIN(tp_g/tp_roe,0.8))/(1+tp_r)^5+J894*(1-MIN(tp_g/tp_roe,0.8))/(1+tp_r)^6+J894*(1-MIN(tp_g/tp_roe,0.8))*(1+tp_g)/(tp_r-tp_g)/(1+tp_r)^6))*(1+tp_r) -> 68.605652 | H11: =Val!$B$33*(tp_wA*(2/12*E812+10/12*F812)+tp_wB*(2/12*E853+10/12*F853)+tp_wC*(2/12*E894+10/12*F894))*rm_factor -> 154.508 | I11: =tp_w_dcf*G11+(1-tp_w_dcf)*H11 -> 111.55682 | J11: =I11/I$4-1 -> -0.11872858
A12: 8 吋售價水準調整：高 | B12: =TEXT(asp_adj_hi,"0.0%")&"（基準 "&TEXT(asp_adj,"0.0%")&"）" -> 3.0%（基準 0.0%） | C12: asp_adj | D12: =E935 -> 9.392413 | E12: =F935 -> 10.091733 | F12: =E12/E$4-1 -> 0.094872941 | G12: =(tp_wA*MAX(0,E935*(1-MIN(tp_g/tp_roe,0.8))/(1+tp_r)^1+F935*(1-MIN(tp_g/tp_roe,0.8))/(1+tp_r)^2+G935*(1-MIN(tp_g/tp_roe,0.8))/(1+tp_r)^3+H935*(1-MIN(tp_g/tp_roe,0.8))/(1+tp_r)^4+I935*(1-MIN(tp_g/tp_roe,0.8))/(1+tp_r)^5+J935*(1-MIN(tp_g/tp_roe,0.8))/(1+tp_r)^6+J935*(1-MIN(tp_g/tp_roe,0.8))*(1+tp_g)/(tp_r-tp_g)/(1+tp_r)^6)+tp_wB*MAX(0,E976*(1-MIN(tp_g/tp_roe,0.8))/(1+tp_r)^1+F976*(1-MIN(tp_g/tp_roe,0.8))/(1+tp_r)^2+G976*(1-MIN(tp_g/tp_roe,0.8))/(1+tp_r)^3+H976*(1-MIN(tp_g/tp_roe,0.8))/(1+tp_r)^4+I976*(1-MIN(tp_g/tp_roe,0.8))/(1+tp_r)^5+J976*(1-MIN(tp_g/tp_roe,0.8))/(1+tp_r)^6+J976*(1-MIN(tp_g/tp_roe,0.8))*(1+tp_g)/(tp_r-tp_g)/(1+tp_r)^6)+tp_wC*MAX(0,E1017*(1-MIN(tp_g/tp_roe,0.8))/(1+tp_r)^1+F1017*(1-MIN(tp_g/tp_roe,0.8))/(1+tp_r)^2+G1017*(1-MIN(tp_g/tp_roe,0.8))/(1+tp_r)^3+H1017*(1-MIN(tp_g/tp_roe,0.8))/(1+tp_r)^4+I1017*(1-MIN(tp_g/tp_roe,0.8))/(1+tp_r)^5+J1017*(1-MIN(tp_g/tp_roe,0.8))/(1+tp_r)^6+J1017*(1-MIN(tp_g/tp_roe,0.8))*(1+tp_g)/(tp_r-tp_g)/(1+tp_r)^6))*(1+tp_r) -> 86.338608 | H12: =Val!$B$33*(tp_wA*(2/12*E935+10/12*F935)+tp_wB*(2/12*E976+10/12*F976)+tp_wC*(2/12*E1017+10/12*F1017))*rm_factor -> 196.86571 | I12: =tp_w_dcf*G12+(1-tp_w_dcf)*H12 -> 141.60216 | J12: =I12/I$4-1 -> 0.11862217
A13: 折舊年增調整：低 | B13: =TEXT(dag_adj_lo,"0.0%")&"（基準 "&TEXT(dag_adj,"0.0%")&"）" -> -5.0%（基準 0.0%） | C13: dag_adj | D13: =E1058 -> 8.7220698 | E13: =F1058 -> 9.6031636 | F13: =E13/E$4-1 -> 0.041867025 | G13: =(tp_wA*MAX(0,E1058*(1-MIN(tp_g/tp_roe,0.8))/(1+tp_r)^1+F1058*(1-MIN(tp_g/tp_roe,0.8))/(1+tp_r)^2+G1058*(1-MIN(tp_g/tp_roe,0.8))/(1+tp_r)^3+H1058*(1-MIN(tp_g/tp_roe,0.8))/(1+tp_r)^4+I1058*(1-MIN(tp_g/tp_roe,0.8))/(1+tp_r)^5+J1058*(1-MIN(tp_g/tp_roe,0.8))/(1+tp_r)^6+J1058*(1-MIN(tp_g/tp_roe,0.8))*(1+tp_g)/(tp_r-tp_g)/(1+tp_r)^6)+tp_wB*MAX(0,E1099*(1-MIN(tp_g/tp_roe,0.8))/(1+tp_r)^1+F1099*(1-MIN(tp_g/tp_roe,0.8))/(1+tp_r)^2+G1099*(1-MIN(tp_g/tp_roe,0.8))/(1+tp_r)^3+H1099*(1-MIN(tp_g/tp_roe,0.8))/(1+tp_r)^4+I1099*(1-MIN(tp_g/tp_roe,0.8))/(1+tp_r)^5+J1099*(1-MIN(tp_g/tp_roe,0.8))/(1+tp_r)^6+J1099*(1-MIN(tp_g/tp_roe,0.8))*(1+tp_g)/(tp_r-tp_g)/(1+tp_r)^6)+tp_wC*MAX(0,E1140*(1-MIN(tp_g/tp_roe,0.8))/(1+tp_r)^1+F1140*(1-MIN(tp_g/tp_roe,0.8))/(1+tp_r)^2+G1140*(1-MIN(tp_g/tp_roe,0.8))/(1+tp_r)^3+H1140*(1-MIN(tp_g/tp_roe,0.8))/(1+tp_r)^4+I1140*(1-MIN(tp_g/tp_roe,0.8))/(1+tp_r)^5+J1140*(1-MIN(tp_g/tp_roe,0.8))/(1+tp_r)^6+J1140*(1-MIN(tp_g/tp_roe,0.8))*(1+tp_g)/(tp_r-tp_g)/(1+tp_r)^6))*(1+tp_r) -> 83.633848 | H13: =Val!$B$33*(tp_wA*(2/12*E1058+10/12*F1058)+tp_wB*(2/12*E1099+10/12*F1099)+tp_wC*(2/12*E1140+10/12*F1140))*rm_factor -> 185.38971 | I13: =tp_w_dcf*G13+(1-tp_w_dcf)*H13 -> 134.51178 | J13: =I13/I$4-1 -> 0.06260989
A14: 折舊年增調整：高 | B14: =TEXT(dag_adj_hi,"0.0%")&"（基準 "&TEXT(dag_adj,"0.0%")&"）" -> 5.0%（基準 0.0%） | C14: dag_adj | D14: =E1181 -> 8.3361704 | E14: =F1181 -> 8.8120698 | F14: =E14/E$4-1 -> -0.043960376 | G14: =(tp_wA*MAX(0,E1181*(1-MIN(tp_g/tp_roe,0.8))/(1+tp_r)^1+F1181*(1-MIN(tp_g/tp_roe,0.8))/(1+tp_r)^2+G1181*(1-MIN(tp_g/tp_roe,0.8))/(1+tp_r)^3+H1181*(1-MIN(tp_g/tp_roe,0.8))/(1+tp_r)^4+I1181*(1-MIN(tp_g/tp_roe,0.8))/(1+tp_r)^5+J1181*(1-MIN(tp_g/tp_roe,0.8))/(1+tp_r)^6+J1181*(1-MIN(tp_g/tp_roe,0.8))*(1+tp_g)/(tp_r-tp_g)/(1+tp_r)^6)+tp_wB*MAX(0,E1222*(1-MIN(tp_g/tp_roe,0.8))/(1+tp_r)^1+F1222*(1-MIN(tp_g/tp_roe,0.8))/(1+tp_r)^2+G1222*(1-MIN(tp_g/tp_roe,0.8))/(1+tp_r)^3+H1222*(1-MIN(tp_g/tp_roe,0.8))/(1+tp_r)^4+I1222*(1-MIN(tp_g/tp_roe,0.8))/(1+tp_r)^5+J1222*(1-MIN(tp_g/tp_roe,0.8))/(1+tp_r)^6+J1222*(1-MIN(tp_g/tp_roe,0.8))*(1+tp_g)/(tp_r-tp_g)/(1+tp_r)^6)+tp_wC*MAX(0,E1263*(1-MIN(tp_g/tp_roe,0.8))/(1+tp_r)^1+F1263*(1-MIN(tp_g/tp_roe,0.8))/(1+tp_r)^2+G1263*(1-MIN(tp_g/tp_roe,0.8))/(1+tp_r)^3+H1263*(1-MIN(tp_g/tp_roe,0.8))/(1+tp_r)^4+I1263*(1-MIN(tp_g/tp_roe,0.8))/(1+tp_r)^5+J1263*(1-MIN(tp_g/tp_roe,0.8))/(1+tp_r)^6+J1263*(1-MIN(tp_g/tp_roe,0.8))*(1+tp_g)/(tp_r-tp_g)/(1+tp_r)^6))*(1+tp_r) -> 70.725342 | H14: =Val!$B$33*(tp_wA*(2/12*E1181+10/12*F1181)+tp_wB*(2/12*E1222+10/12*F1222)+tp_wC*(2/12*E1263+10/12*F1263))*rm_factor -> 165.54603 | I14: =tp_w_dcf*G14+(1-tp_w_dcf)*H14 -> 118.13569 | J14: =I14/I$4-1 -> -0.066757177
A15: 每片現金成本年增：低 | B15: =TEXT(cc_g_lo,"0.0%")&"（基準 "&TEXT(cc_g,"0.0%")&"）" -> 0.0%（基準 2.0%） | C15: cc_g | D15: =E1304 -> 8.8296407 | E15: =F1304 -> 9.8179258 | F15: =E15/E$4-1 -> 0.065167018 | G15: =(tp_wA*MAX(0,E1304*(1-MIN(tp_g/tp_roe,0.8))/(1+tp_r)^1+F1304*(1-MIN(tp_g/tp_roe,0.8))/(1+tp_r)^2+G1304*(1-MIN(tp_g/tp_roe,0.8))/(1+tp_r)^3+H1304*(1-MIN(tp_g/tp_roe,0.8))/(1+tp_r)^4+I1304*(1-MIN(tp_g/tp_roe,0.8))/(1+tp_r)^5+J1304*(1-MIN(tp_g/tp_roe,0.8))/(1+tp_r)^6+J1304*(1-MIN(tp_g/tp_roe,0.8))*(1+tp_g)/(tp_r-tp_g)/(1+tp_r)^6)+tp_wB*MAX(0,E1345*(1-MIN(tp_g/tp_roe,0.8))/(1+tp_r)^1+F1345*(1-MIN(tp_g/tp_roe,0.8))/(1+tp_r)^2+G1345*(1-MIN(tp_g/tp_roe,0.8))/(1+tp_r)^3+H1345*(1-MIN(tp_g/tp_roe,0.8))/(1+tp_r)^4+I1345*(1-MIN(tp_g/tp_roe,0.8))/(1+tp_r)^5+J1345*(1-MIN(tp_g/tp_roe,0.8))/(1+tp_r)^6+J1345*(1-MIN(tp_g/tp_roe,0.8))*(1+tp_g)/(tp_r-tp_g)/(1+tp_r)^6)+tp_wC*MAX(0,E1386*(1-MIN(tp_g/tp_roe,0.8))/(1+tp_r)^1+F1386*(1-MIN(tp_g/tp_roe,0.8))/(1+tp_r)^2+G1386*(1-MIN(tp_g/tp_roe,0.8))/(1+tp_r)^3+H1386*(1-MIN(tp_g/tp_roe,0.8))/(1+tp_r)^4+I1386*(1-MIN(tp_g/tp_roe,0.8))/(1+tp_r)^5+J1386*(1-MIN(tp_g/tp_roe,0.8))/(1+tp_r)^6+J1386*(1-MIN(tp_g/tp_roe,0.8))*(1+tp_g)/(tp_r-tp_g)/(1+tp_r)^6))*(1+tp_r) -> 86.608583 | H15: =Val!$B$33*(tp_wA*(2/12*E1304+10/12*F1304)+tp_wB*(2/12*E1345+10/12*F1345)+tp_wC*(2/12*E1386+10/12*F1386))*rm_factor -> 189.54177 | I15: =tp_w_dcf*G15+(1-tp_w_dcf)*H15 -> 138.07518 | J15: =I15/I$4-1 -> 0.090759874
A16: 每片現金成本年增：高 | B16: =TEXT(cc_g_hi,"0.0%")&"（基準 "&TEXT(cc_g,"0.0%")&"）" -> 4.0%（基準 2.0%） | C16: cc_g | D16: =E1427 -> 8.2285995 | E16: =F1427 -> 8.6047083 | F16: =E16/E$4-1 -> -0.066457454 | G16: =(tp_wA*MAX(0,E1427*(1-MIN(tp_g/tp_roe,0.8))/(1+tp_r)^1+F1427*(1-MIN(tp_g/tp_roe,0.8))/(1+tp_r)^2+G1427*(1-MIN(tp_g/tp_roe,0.8))/(1+tp_r)^3+H1427*(1-MIN(tp_g/tp_roe,0.8))/(1+tp_r)^4+I1427*(1-MIN(tp_g/tp_roe,0.8))/(1+tp_r)^5+J1427*(1-MIN(tp_g/tp_roe,0.8))/(1+tp_r)^6+J1427*(1-MIN(tp_g/tp_roe,0.8))*(1+tp_g)/(tp_r-tp_g)/(1+tp_r)^6)+tp_wB*MAX(0,E1468*(1-MIN(tp_g/tp_roe,0.8))/(1+tp_r)^1+F1468*(1-MIN(tp_g/tp_roe,0.8))/(1+tp_r)^2+G1468*(1-MIN(tp_g/tp_roe,0.8))/(1+tp_r)^3+H1468*(1-MIN(tp_g/tp_roe,0.8))/(1+tp_r)^4+I1468*(1-MIN(tp_g/tp_roe,0.8))/(1+tp_r)^5+J1468*(1-MIN(tp_g/tp_roe,0.8))/(1+tp_r)^6+J1468*(1-MIN(tp_g/tp_roe,0.8))*(1+tp_g)/(tp_r-tp_g)/(1+tp_r)^6)+tp_wC*MAX(0,E1509*(1-MIN(tp_g/tp_roe,0.8))/(1+tp_r)^1+F1509*(1-MIN(tp_g/tp_roe,0.8))/(1+tp_r)^2+G1509*(1-MIN(tp_g/tp_roe,0.8))/(1+tp_r)^3+H1509*(1-MIN(tp_g/tp_roe,0.8))/(1+tp_r)^4+I1509*(1-MIN(tp_g/tp_roe,0.8))/(1+tp_r)^5+J1509*(1-MIN(tp_g/tp_roe,0.8))/(1+tp_r)^6+J1509*(1-MIN(tp_g/tp_roe,0.8))*(1+tp_g)/(tp_r-tp_g)/(1+tp_r)^6))*(1+tp_r) -> 68.009459 | H16: =Val!$B$33*(tp_wA*(2/12*E1427+10/12*F1427)+tp_wB*(2/12*E1468+10/12*F1468)+tp_wC*(2/12*E1509+10/12*F1509))*rm_factor -> 161.58624 | I16: =tp_w_dcf*G16+(1-tp_w_dcf)*H16 -> 114.79785 | J16: =I16/I$4-1 -> -0.093125279
A17: 營業費用彈性：低 | B17: =TEXT(phi_lo,"0.00")&"（基準 "&TEXT(phi,"0.00")&"）" -> 0.30（基準 0.50） | C17: phi | D17: =E1550 -> 8.7092092 | E17: =F1550 -> 9.5144704 | F17: =E17/E$4-1 -> 0.032244516 | G17: =(tp_wA*MAX(0,E1550*(1-MIN(tp_g/tp_roe,0.8))/(1+tp_r)^1+F1550*(1-MIN(tp_g/tp_roe,0.8))/(1+tp_r)^2+G1550*(1-MIN(tp_g/tp_roe,0.8))/(1+tp_r)^3+H1550*(1-MIN(tp_g/tp_roe,0.8))/(1+tp_r)^4+I1550*(1-MIN(tp_g/tp_roe,0.8))/(1+tp_r)^5+J1550*(1-MIN(tp_g/tp_roe,0.8))/(1+tp_r)^6+J1550*(1-MIN(tp_g/tp_roe,0.8))*(1+tp_g)/(tp_r-tp_g)/(1+tp_r)^6)+tp_wB*MAX(0,E1591*(1-MIN(tp_g/tp_roe,0.8))/(1+tp_r)^1+F1591*(1-MIN(tp_g/tp_roe,0.8))/(1+tp_r)^2+G1591*(1-MIN(tp_g/tp_roe,0.8))/(1+tp_r)^3+H1591*(1-MIN(tp_g/tp_roe,0.8))/(1+tp_r)^4+I1591*(1-MIN(tp_g/tp_roe,0.8))/(1+tp_r)^5+J1591*(1-MIN(tp_g/tp_roe,0.8))/(1+tp_r)^6+J1591*(1-MIN(tp_g/tp_roe,0.8))*(1+tp_g)/(tp_r-tp_g)/(1+tp_r)^6)+tp_wC*MAX(0,E1632*(1-MIN(tp_g/tp_roe,0.8))/(1+tp_r)^1+F1632*(1-MIN(tp_g/tp_roe,0.8))/(1+tp_r)^2+G1632*(1-MIN(tp_g/tp_roe,0.8))/(1+tp_r)^3+H1632*(1-MIN(tp_g/tp_roe,0.8))/(1+tp_r)^4+I1632*(1-MIN(tp_g/tp_roe,0.8))/(1+tp_r)^5+J1632*(1-MIN(tp_g/tp_roe,0.8))/(1+tp_r)^6+J1632*(1-MIN(tp_g/tp_roe,0.8))*(1+tp_g)/(tp_r-tp_g)/(1+tp_r)^6))*(1+tp_r) -> 80.266141 | H17: =Val!$B$33*(tp_wA*(2/12*E1550+10/12*F1550)+tp_wB*(2/12*E1591+10/12*F1591)+tp_wC*(2/12*E1632+10/12*F1632))*rm_factor -> 180.3703 | I17: =tp_w_dcf*G17+(1-tp_w_dcf)*H17 -> 130.31822 | J17: =I17/I$4-1 -> 0.029481838
A18: 營業費用彈性：高 | B18: =TEXT(phi_hi,"0.00")&"（基準 "&TEXT(phi,"0.00")&"）" -> 0.80（基準 0.50） | C18: phi | D18: =E1673 -> 8.2589866 | E18: =F1673 -> 8.7504306 | F18: =E18/E$4-1 -> -0.050647741 | G18: =(tp_wA*MAX(0,E1673*(1-MIN(tp_g/tp_roe,0.8))/(1+tp_r)^1+F1673*(1-MIN(tp_g/tp_roe,0.8))/(1+tp_r)^2+G1673*(1-MIN(tp_g/tp_roe,0.8))/(1+tp_r)^3+H1673*(1-MIN(tp_g/tp_roe,0.8))/(1+tp_r)^4+I1673*(1-MIN(tp_g/tp_roe,0.8))/(1+tp_r)^5+J1673*(1-MIN(tp_g/tp_roe,0.8))/(1+tp_r)^6+J1673*(1-MIN(tp_g/tp_roe,0.8))*(1+tp_g)/(tp_r-tp_g)/(1+tp_r)^6)+tp_wB*MAX(0,E1714*(1-MIN(tp_g/tp_roe,0.8))/(1+tp_r)^1+F1714*(1-MIN(tp_g/tp_roe,0.8))/(1+tp_r)^2+G1714*(1-MIN(tp_g/tp_roe,0.8))/(1+tp_r)^3+H1714*(1-MIN(tp_g/tp_roe,0.8))/(1+tp_r)^4+I1714*(1-MIN(tp_g/tp_roe,0.8))/(1+tp_r)^5+J1714*(1-MIN(tp_g/tp_roe,0.8))/(1+tp_r)^6+J1714*(1-MIN(tp_g/tp_roe,0.8))*(1+tp_g)/(tp_r-tp_g)/(1+tp_r)^6)+tp_wC*MAX(0,E1755*(1-MIN(tp_g/tp_roe,0.8))/(1+tp_r)^1+F1755*(1-MIN(tp_g/tp_roe,0.8))/(1+tp_r)^2+G1755*(1-MIN(tp_g/tp_roe,0.8))/(1+tp_r)^3+H1755*(1-MIN(tp_g/tp_roe,0.8))/(1+tp_r)^4+I1755*(1-MIN(tp_g/tp_roe,0.8))/(1+tp_r)^5+J1755*(1-MIN(tp_g/tp_roe,0.8))/(1+tp_r)^6+J1755*(1-MIN(tp_g/tp_roe,0.8))*(1+tp_g)/(tp_r-tp_g)/(1+tp_r)^6))*(1+tp_r) -> 72.934574 | H18: =Val!$B$33*(tp_wA*(2/12*E1673+10/12*F1673)+tp_wB*(2/12*E1714+10/12*F1714)+tp_wC*(2/12*E1755+10/12*F1755))*rm_factor -> 168.42026 | I18: =tp_w_dcf*G18+(1-tp_w_dcf)*H18 -> 120.67742 | J18: =I18/I$4-1 -> -0.046678156
A19: 營業外淨額：低 | B19: =TEXT(nonop_f_lo,"0.0")&"（基準 "&TEXT(nonop_f,"0.0")&"）" -> 0.5（基準 1.5） | C19: nonop_f | D19: =E1796 -> 8.0834058 | E19: =F1796 -> 8.7715499 | F19: =E19/E$4-1 -> -0.048356462 | G19: =(tp_wA*MAX(0,E1796*(1-MIN(tp_g/tp_roe,0.8))/(1+tp_r)^1+F1796*(1-MIN(tp_g/tp_roe,0.8))/(1+tp_r)^2+G1796*(1-MIN(tp_g/tp_roe,0.8))/(1+tp_r)^3+H1796*(1-MIN(tp_g/tp_roe,0.8))/(1+tp_r)^4+I1796*(1-MIN(tp_g/tp_roe,0.8))/(1+tp_r)^5+J1796*(1-MIN(tp_g/tp_roe,0.8))/(1+tp_r)^6+J1796*(1-MIN(tp_g/tp_roe,0.8))*(1+tp_g)/(tp_r-tp_g)/(1+tp_r)^6)+tp_wB*MAX(0,E1837*(1-MIN(tp_g/tp_roe,0.8))/(1+tp_r)^1+F1837*(1-MIN(tp_g/tp_roe,0.8))/(1+tp_r)^2+G1837*(1-MIN(tp_g/tp_roe,0.8))/(1+tp_r)^3+H1837*(1-MIN(tp_g/tp_roe,0.8))/(1+tp_r)^4+I1837*(1-MIN(tp_g/tp_roe,0.8))/(1+tp_r)^5+J1837*(1-MIN(tp_g/tp_roe,0.8))/(1+tp_r)^6+J1837*(1-MIN(tp_g/tp_roe,0.8))*(1+tp_g)/(tp_r-tp_g)/(1+tp_r)^6)+tp_wC*MAX(0,E1878*(1-MIN(tp_g/tp_roe,0.8))/(1+tp_r)^1+F1878*(1-MIN(tp_g/tp_roe,0.8))/(1+tp_r)^2+G1878*(1-MIN(tp_g/tp_roe,0.8))/(1+tp_r)^3+H1878*(1-MIN(tp_g/tp_roe,0.8))/(1+tp_r)^4+I1878*(1-MIN(tp_g/tp_roe,0.8))/(1+tp_r)^5+J1878*(1-MIN(tp_g/tp_roe,0.8))/(1+tp_r)^6+J1878*(1-MIN(tp_g/tp_roe,0.8))*(1+tp_g)/(tp_r-tp_g)/(1+tp_r)^6))*(1+tp_r) -> 72.376086 | H19: =Val!$B$33*(tp_wA*(2/12*E1796+10/12*F1796)+tp_wB*(2/12*E1837+10/12*F1837)+tp_wC*(2/12*E1878+10/12*F1878))*rm_factor -> 163.46464 | I19: =tp_w_dcf*G19+(1-tp_w_dcf)*H19 -> 117.92036 | J19: =I19/I$4-1 -> -0.068458187
A20: 營業外淨額：高 | B20: =TEXT(nonop_f_hi,"0.0")&"（基準 "&TEXT(nonop_f,"0.0")&"）" -> 2.5（基準 1.5） | C20: nonop_f | D20: =E1919 -> 8.9748344 | E20: =F1919 -> 9.6629785 | F20: =E20/E$4-1 -> 0.048356462 | G20: =(tp_wA*MAX(0,E1919*(1-MIN(tp_g/tp_roe,0.8))/(1+tp_r)^1+F1919*(1-MIN(tp_g/tp_roe,0.8))/(1+tp_r)^2+G1919*(1-MIN(tp_g/tp_roe,0.8))/(1+tp_r)^3+H1919*(1-MIN(tp_g/tp_roe,0.8))/(1+tp_r)^4+I1919*(1-MIN(tp_g/tp_roe,0.8))/(1+tp_r)^5+J1919*(1-MIN(tp_g/tp_roe,0.8))/(1+tp_r)^6+J1919*(1-MIN(tp_g/tp_roe,0.8))*(1+tp_g)/(tp_r-tp_g)/(1+tp_r)^6)+tp_wB*MAX(0,E1960*(1-MIN(tp_g/tp_roe,0.8))/(1+tp_r)^1+F1960*(1-MIN(tp_g/tp_roe,0.8))/(1+tp_r)^2+G1960*(1-MIN(tp_g/tp_roe,0.8))/(1+tp_r)^3+H1960*(1-MIN(tp_g/tp_roe,0.8))/(1+tp_r)^4+I1960*(1-MIN(tp_g/tp_roe,0.8))/(1+tp_r)^5+J1960*(1-MIN(tp_g/tp_roe,0.8))/(1+tp_r)^6+J1960*(1-MIN(tp_g/tp_roe,0.8))*(1+tp_g)/(tp_r-tp_g)/(1+tp_r)^6)+tp_wC*MAX(0,E2001*(1-MIN(tp_g/tp_roe,0.8))/(1+tp_r)^1+F2001*(1-MIN(tp_g/tp_roe,0.8))/(1+tp_r)^2+G2001*(1-MIN(tp_g/tp_roe,0.8))/(1+tp_r)^3+H2001*(1-MIN(tp_g/tp_roe,0.8))/(1+tp_r)^4+I2001*(1-MIN(tp_g/tp_roe,0.8))/(1+tp_r)^5+J2001*(1-MIN(tp_g/tp_roe,0.8))/(1+tp_r)^6+J2001*(1-MIN(tp_g/tp_roe,0.8))*(1+tp_g)/(tp_r-tp_g)/(1+tp_r)^6))*(1+tp_r) -> 82.592112 | H20: =Val!$B$33*(tp_wA*(2/12*E1919+10/12*F1919)+tp_wB*(2/12*E1960+10/12*F1960)+tp_wC*(2/12*E2001+10/12*F2001))*rm_factor -> 187.91207 | I20: =tp_w_dcf*G20+(1-tp_w_dcf)*H20 -> 135.25209 | J20: =I20/I$4-1 -> 0.068458187
A21: 稅率：低 | B21: =TEXT(tax_lo,"0%")&"（基準 "&TEXT(tax,"0%")&"）" -> 12%（基準 15%） | C21: tax | D21: =E2042 -> 8.8301479 | E21: =F2042 -> 9.5425794 | F21: =E21/E$4-1 -> 0.035294118 | G21: =(tp_wA*MAX(0,E2042*(1-MIN(tp_g/tp_roe,0.8))/(1+tp_r)^1+F2042*(1-MIN(tp_g/tp_roe,0.8))/(1+tp_r)^2+G2042*(1-MIN(tp_g/tp_roe,0.8))/(1+tp_r)^3+H2042*(1-MIN(tp_g/tp_roe,0.8))/(1+tp_r)^4+I2042*(1-MIN(tp_g/tp_roe,0.8))/(1+tp_r)^5+J2042*(1-MIN(tp_g/tp_roe,0.8))/(1+tp_r)^6+J2042*(1-MIN(tp_g/tp_roe,0.8))*(1+tp_g)/(tp_r-tp_g)/(1+tp_r)^6)+tp_wB*MAX(0,E2083*(1-MIN(tp_g/tp_roe,0.8))/(1+tp_r)^1+F2083*(1-MIN(tp_g/tp_roe,0.8))/(1+tp_r)^2+G2083*(1-MIN(tp_g/tp_roe,0.8))/(1+tp_r)^3+H2083*(1-MIN(tp_g/tp_roe,0.8))/(1+tp_r)^4+I2083*(1-MIN(tp_g/tp_roe,0.8))/(1+tp_r)^5+J2083*(1-MIN(tp_g/tp_roe,0.8))/(1+tp_r)^6+J2083*(1-MIN(tp_g/tp_roe,0.8))*(1+tp_g)/(tp_r-tp_g)/(1+tp_r)^6)+tp_wC*MAX(0,E2124*(1-MIN(tp_g/tp_roe,0.8))/(1+tp_r)^1+F2124*(1-MIN(tp_g/tp_roe,0.8))/(1+tp_r)^2+G2124*(1-MIN(tp_g/tp_roe,0.8))/(1+tp_r)^3+H2124*(1-MIN(tp_g/tp_roe,0.8))/(1+tp_r)^4+I2124*(1-MIN(tp_g/tp_roe,0.8))/(1+tp_r)^5+J2124*(1-MIN(tp_g/tp_roe,0.8))/(1+tp_r)^6+J2124*(1-MIN(tp_g/tp_roe,0.8))*(1+tp_g)/(tp_r-tp_g)/(1+tp_r)^6))*(1+tp_r) -> 80.218832 | H21: =Val!$B$33*(tp_wA*(2/12*E2042+10/12*F2042)+tp_wB*(2/12*E2083+10/12*F2083)+tp_wC*(2/12*E2124+10/12*F2124))*rm_factor -> 181.88912 | I21: =tp_w_dcf*G21+(1-tp_w_dcf)*H21 -> 131.05398 | J21: =I21/I$4-1 -> 0.035294118
