Workbook

Sheet README
A1: Microsoft（MSFT）個股模型 v0.3.1 — 命題＋官方營收分部 → 損益表（2026-10-29；資料截至 FY27Q1〔2026-09-30〕；評價日 2026-09-30、目標價時點 2027-10-29）
A2: 工作表：README → In → Q → Thesis → Seg → PL → CF → Val → Recon → Sens → Sources。金額十億美元；財年 6 月結束（FY2027＝2026-07～2027-06）
A3: 命題：AI 能否同時在 Azure（算力）與 Microsoft 365（Copilot 應用）變現，撐住翻倍的資本支出。
A4: 核心問題：FY2029 的 AI 增量營業利益能否覆蓋 AI 資本支出的資金成本（AI 增量 ROIC 對 WACC），且自由現金流不需停止回購。
A5: ="① 命題答案（FY2029，基準情境 B）：讀法 2（主值；自用 AI 價值中性）AI 增量 ROIC "&TEXT(Thesis!H102,"0.0%")&"，讀法 1（自用 AI 只計成本）"&TEXT(Thesis!H103,"0.0%")&"，WACC "&TEXT(wacc,"0.0%")&"；對外 Azure AI 本身 "&TEXT(Thesis!H105,"0.0%")&"。讀法 1 下 AI 容量越大、目標價越低（自用算力只有成本）；讀法 2 下容量增加對目標價中性偏正（敏感度：MW 速度改 Epoch 可辨識站點 "&TEXT(Sens!D9,"+0.0;-0.0")&"、+20% "&TEXT(Sens!D10,"+0.0;-0.0")&"）。AI 折舊 FY2026 "&TEXT(Thesis!E95,"0.0")&" → FY2029 "&TEXT(Thesis!H95,"0.0")&" 十億美元，財報口徑營業利益率 FY2029 "&TEXT(PL!H76,"0.0%")&"（FY2026 "&TEXT(PL!E76,"0.0%")&"）。" -> ① 命題答案（FY2029，基準情境 B）：讀法 2（主值；自用 AI 價值中性）AI 增量 ROIC 8.6%，讀法 1（自用 AI 只計成本）1.0%，WACC 10.3%；對外 Azure AI 本身 13.1%。讀法 1 下 AI 容量越大、目標價越低（自用算力只有成本）；讀法 2 下容量增加對目標價中性偏正（敏感度：MW 速度改 Epoch 可辨識站點 -28.5、+20% +2.8）。AI 折舊 FY2026 16.3 → FY2029 89.1 十億美元，財報口徑營業利益率 FY2029 39.1%（FY2026 46.8%）。
A6: ="② 收支關卡：基準情境首年起五年（FY2027–FY2031）自由現金流扣股利合計 "&TEXT(CF!C5,"#,##0.0")&" 十億美元（樂觀 "&TEXT(CF!B5,"#,##0.0")&"、保守 "&TEXT(CF!D5,"#,##0.0")&"）；"&CF!C6&"。" -> ② 收支關卡：基準情境首年起五年（FY2027–FY2031）自由現金流扣股利合計 259.6 十億美元（樂觀 363.2、保守 137.9）；需要舉債 8.1 十億美元；回購較每年 22.3 的目標少 44.3 十億美元（2 年減少）。
A7: ="③ 評價：加權目標價 "&TEXT(Val!$B$36,"#,##0")&" 美元（讀法 2），較現價 "&TEXT(px,"#,##0.00")&" "&TEXT(Val!$B$40,"+0.0%;-0.0%")&"；DCF "&TEXT(Val!$B$14,"#,##0")&"、分部加總 "&TEXT(Val!$B$31,"#,##0")&"；讀法 1 目標價 "&TEXT(Val!$B$47,"#,##0")&"（"&Val!$B$49&"）；市場共識 "&TEXT(cons_tp,"#,##0")&"。WACC "&TEXT(wacc,"0.0%")&"（−1pt 時目標價 "&TEXT(Sens!C27,"#,##0")&"）；非 AI 各線改用 Microsoft 自身 NTM EV/EBITDA "&TEXT(m_own,"0.0")&"× 時目標價 "&TEXT(Sens!C94,"#,##0")&"。" -> ③ 評價：加權目標價 384 美元（讀法 2），較現價 531.01 -27.7%；DCF 324、分部加總 444；讀法 1 目標價 311（放空）；市場共識 605。WACC 10.3%（−1pt 時目標價 406）；非 AI 各線改用 Microsoft 自身 NTM EV/EBITDA 15.7× 時目標價 450。
A8: ="投資建議："&Val!$B$43&"（讀法 2 主值；上檔空間 "&TEXT(Val!$B$40,"+0.0%;-0.0%")&"；讀法 1："&Val!$B$49&"；五級固定規則：≥ +50% 強力買進、+25%～+50% 買進、−25%～+25% 中立、−50%～−25% 放空、≤ −50% 強力放空）" -> 投資建議：放空（讀法 2 主值；上檔空間 -27.7%；讀法 1：放空；五級固定規則：≥ +50% 強力買進、+25%～+50% 買進、−25%～+25% 中立、−50%～−25% 放空、≤ −50% 強力放空）
A9: ="收支關卡（地圖）：CF 頁「收支關卡：自由現金流扣股利（五年合計）」基準 "&TEXT(CF!C5,"#,##0.0")&" 十億美元（財報現金，不含影子效益）" -> 收支關卡（地圖）：CF 頁「收支關卡：自由現金流扣股利（五年合計）」基準 259.6 十億美元（財報現金，不含影子效益）
A11: 驅動 → 推導對照表（每頁輸入、推導量、因果方向）
A12: 頁 | B12: 輸入（In 頁鍵） | C12: 推導量 | D12: 因果方向 | E12: 基準值（FY2029，情境 B）
A13: Thesis | B13: pace、mw_ext_26、ext_sh、rent_ext_f | C13: 在役對外 AI MW、自有 AI MW（含自用） | D13: MW 越多 → Azure AI 營收↑、AI 資本支出與折舊↑ | E13: =Thesis!H60 -> 11429.605
A14: Thesis | B14: tk_hold_*、p_long、p_spot、ls_*（k） | C14: 每 MW 年收入（US$M/MW-年） | D14: k 越高 → Azure AI 營收與 EBITDA↑（三情境主要差異） | E14: =Thesis!H76 -> 12.735046
A15: Thesis | B15: tk_cxit_*、tk_cxfac、self_build、capex_floor27、life_it | C15: AI 資本支出、AI 折舊 | D15: 資本支出 → 折舊 → Agents and Infra 營業利益↓；→ 自由現金流↓ | E15: =Thesis!H95 -> 89.100091
A16: Seg | B16: cop_s26、cop_add_*、cop_px | C16: Copilot 營收（M365 cloud 子列） | D16: 座席 × 月費 → M365 cloud↑ | E16: =Seg!H38 -> 24
A17: Seg | B17: glt_*、n_conv | C17: 非命題產品線營收 | D17: 近一年年增收斂到長期值 | E17: =Seg!H56 -> 555.72683
A18: PL | B18: （FY2026 校準）、dm_seg | C18: Agents and Infra 核心利益率、分部營業利益 | D18: 核心利益率 ×（分部 − Azure AI）＋ Azure AI − AI 成本 − AI 折舊 | E18: =PL!H71 -> 196.76369
A19: PL | B19: internal_ai_reading、tax_f、oie_f | C19: 自用 AI 影子效益、淨利、EPS（評價口徑） | D19: 讀法 2：自用 MW × 持有成本（扣 Copilot）進評價口徑營業利益 | E19: =PL!H88 -> 27.37464
A20: CF | B20: sbc_r、wc27、cx_*、fl_pay_*、bb_target、dps_* | C20: 自由現金流、回購、舉債、股數 | D20: 自由現金流扣股利 → 回購（不足先減）→ 舉債 | E20: =CF!H62 -> 62.211875
A21: Val | B21: rf、beta、erp、kd、g_tv、m_*、al_*、w_* | C21: DCF、SOTP（AI 模組 DCF）、加權目標價 | D21: WACC↑ → DCF↓；倍數↑ → SOTP↑ | E21: =Val!$B$36 -> 384.10456
A23: 結果摘要（三情境）
A24: 項目 | B24: 情境 A（樂觀） | C24: 情境 B（基準） | D24: 情境 C（保守） | E24: 說明
A25: 營收 FY2029（US$B） | B25: =Seg!H29 -> 587.29479 | C25: =Seg!H56 -> 555.72683 | D25: =Seg!H83 -> 519.25825
A26: Azure AI 營收 FY2029 | B26: =Thesis!H25 -> 153.81672 | C26: =Thesis!H77 -> 128.19527 | D26: =Thesis!H129 -> 97.449538
A27: Copilot 營收 FY2029 | B27: =Seg!H11 -> 31.5 | C27: =Seg!H38 -> 24 | D27: =Seg!H65 -> 16.5
A28: 營業利益率 FY2029（財報口徑） | B28: =PL!H37 -> 0.41909125 | C28: =PL!H76 -> 0.39069071 | D28: =PL!H115 -> 0.35262622
A29: EPS FY2029（財報口徑，US$） | B29: =PL!H47 -> 26.005415 | C29: =PL!H86 -> 22.891665 | D29: =PL!H125 -> 19.240201
A30: EPS FY2029（評價口徑，US$） | B30: =PL!H49 -> 30.040255 | C30: =PL!H88 -> 27.37464 | D30: =PL!H127 -> 24.165561
A31: 自由現金流 FY2029（財報現金） | B31: =CF!H30 -> 86.187278 | C31: =CF!H62 -> 62.211875 | D31: =CF!H94 -> 34.022608
A32: AI 增量 ROIC FY2029（讀法 2） | B32: =Thesis!H50 -> 0.13195104 | C32: =Thesis!H102 -> 0.08595571 | D32: =Thesis!H154 -> 0.030761308
A33: AI 增量 ROIC FY2029（讀法 1） | B33: =Thesis!H51 -> 0.063730556 | C33: =Thesis!H103 -> 0.010047899 | D33: =Thesis!H155 -> -0.052833824
A35: 情境目標價（US$；讀法 2） | B35: =Val!B44 -> 423.24787 | C35: =Val!C44 -> 386.05217 | D35: =Val!D44 -> 341.06603
A37: 與 v0.2.2 的差異：v0.2.2 沿用 CoreWeave 架構（對外 AI MW × 每 MW 收入＋其餘業務成長率線、融資瀑布）；v0.3 改為官方兩分部、八條產品線，命題只驅動 Azure AI 與 Copilot 兩條子列，AI 資本支出經折舊進分部營業利益；評價改 DCF 50%＋SOTP 50%、情境 25／50／25。拆解見 Recon 第 5 節。
A38: 已知限制：AI 在役 MW、對外比例、Copilot 營收與座席歷史、產品線利潤、Maia 部署量公司皆未揭露（Assumed，給區間）；非命題產品線依 FY2026 年增收斂，未套用 FY27Q2 季度指引（Windows 指引 mid-thirties 衰退，只列 Recon 對照）；共識為財報前（2026-10-27）。
A39: 建置：bash microsoft/make_v03.sh（build_microsoft.py → LibreOffice 重算 → check_v03.py → segment_check → HTML）；變動拆解與 C10 重解：python3 microsoft/attrib_v031.py
A40: v0.3.1（2026-10-29，季度滾動）：Q 頁加入 FY27Q1（八季 FY25Q2–FY27Q1）；FY2027＝Q1 實績＋Q2–Q4 模型（首期營運資金依 C14 用 FY2026 同期）；評價日 2026-09-30、目標價時點 2027-10-29；C10 依新的資本支出指引重解 MW 速度；Tokenomics v21.4 → v21.7，Maia 改讀 IF_NonNV_*；現價、共識、OpenAI 持股 24% 更新。變動拆解見 Recon 第 5 節。v0.3 修正一（2026-10-27，獨立核對後）：收支關卡範圍公式誤加 FY2032（改為首年起五年並加核對列）；自用 AI 讀法 2 為主值；DCF 扣股票薪酬、減融資租賃負債、扣期間股利；SOTP 的 AI 腿改用模組 DCF；WACC 改 Blume β、10 年期 kd、負債含融資租賃；FY2029 後 MW 新增速度收斂；汰換時更新在役世代。修正二（2026-10-27，第二次核對後；Andy 2026-10-27 15:03 決定讀法 2 為主值）：影子效益只計評價日後新增的自用 MW、只扣 Copilot 增量；SOTP 的 AI 模組改以 FY2028 起現金流折到 FY2027 年底（避免與 FY2027 年底淨現金重複）並扣 FY2028 第一季股利、改用稀釋股數；FY2027 補足到指引下限的資本支出改列其他資本支出（不增 AI MW）；FY2032 MW 增量＝g × 前一年在役 MW；加 ERP 敏感度。修正三（第三次核對後）：影子效益基準改 FY2026 平均自用 MW；SOTP 補加 FY2027 年底到目標價時點的非 AI 自由現金流；FY2027 補足差額的折舊由營業利益扣除。前後對照見報告第 9、10、11 節。

Sheet In
A1: In — 輸入（v0.3.1：FY27Q1 實績滾入；v0.3.2：加「情境驅動對照」、欄名改敏感度低／高；v0.3.3：IF_HoldEcon 四列補低／高、Sens 頁補鍵欄與案例；數值不變）（藍字＝輸入、黑字＝由其他輸入推得）。基準欄 E 進主模型；D／F＝敏感度低／高，只用於 Sens 頁、不進目標價；情境 A／B／C 的驅動見本頁最後一節「情境驅動對照」；金額十億美元（US$B），MW＝IT 關鍵電力。標記：Verified／Interested-party／Analogy／Assumed／Derived；Analogy、Assumed 一律給區間
A2: 「沿用 v0.2.2」＝MAG v0.2.2（2026-10-25，PR #105）已核准的參數與證據，原出處見來源欄；SEC 一手數字取自 microsoft/data/microsoft_facts_20261008.json（v0.1a 起的事實總帳）；FY27Q1 取自 microsoft/data/microsoft_facts_FY27Q1_20261029.json（財報新聞稿與 IR 財務報表兩次讀取核對）
A3: 鍵 | B3: 項目 | C3: 單位 | D3: 敏感度低 | E3: 基準 | F3: 敏感度高 | G3: 標記 | H3: 來源1 | I3: 來源2／說明
A4: A. 股價、股數與資本結構（評價日 2026-09-30＝FY27Q1 季底〔v0.3：2026-06-30〕；目標價時點＝今日 2026-10-29 後 12 個月）
A5: px | B5: 現價（2026-10-28 收盤） | C5: US$ | E5: 531.01 | G5: Verified | H5: https://www.marketbeat.com/stocks/nasdaq/msft/chart（2026-10-28 收盤 531.01，−0.32／−0.06%；前日 531.33；擷取 2026-10-29） | I5: https://247wallst.com/investing/2026/10/28/live-will-microsoft-crush-q1-earnings-tonight-after-the-bell/（報價 531.01，−0.06%）兩來源一致；財報後盤後 544.93（+2.6%）不採用
A6: sh_dil26 | B6: FY2026 稀釋加權股數 | C6: 十億股 | E6: 7.453 | G6: Verified | H6: 事實總帳 microsoft/data/microsoft_facts_20261008.json｜is.sharesDilW.fy2026（10-K FY2026） | I6: v0.3 DCF 每股的分母（評價日 2026-06-30）
A7: sh_basic26 | B7: FY2026 基本加權股數 | C7: 十億股 | E7: 7.429 | G7: Verified | H7: 事實總帳 microsoft/data/microsoft_facts_20261008.json｜is.sharesBasicW.fy2026 | I7: —
A8: dil_gap | B8: 稀釋與基本股數差 | C8: 十億股 | E8: =sh_dil26-sh_basic26 -> 0.024 | G8: Derived | H8: FY2026 稀釋 − 基本 | I8: 預測期稀釋股數＝期間平均流通股數＋此差額
A9: sh_out26 | B9: 流通股數（2026-06-30） | C9: 十億股 | E9: 7.427 | G9: Verified | H9: 事實總帳 microsoft/data/microsoft_facts_20261008.json｜sh.out.fy2026（10-K 附註 15） | I9: —
A10: cash_open | B10: 現金與短期投資（2026-06-30） | C10: US$B | E10: 76.843 | G10: Verified | H10: 事實總帳 microsoft/data/microsoft_facts_20261008.json｜bs.cashSti.fy2026 | I10: CF 頁 FY2027 期初
A11: debt_face | B11: 債務面額（2026-06-30） | C11: US$B | E11: 46.136 | G11: Verified | H11: 事實總帳 microsoft/data/microsoft_facts_20261008.json｜debt.face.fy2026（附註 10） | I11: 帳面值 40.294；CF 頁 FY2027 期初
A12: sh_dil_q1 | B12: FY27Q1 稀釋加權股數 | C12: 十億股 | E12: 7.446 | G12: Interested-party | H12: 事實總帳 microsoft/data/microsoft_facts_FY27Q1_20261029.json｜q.sharesDilW.fy27q1（新聞稿損益表；10-Q 同值） | I12: v0.3.1 DCF 每股的分母（評價日 2026-09-30）
A13: sh_out_q1 | B13: 流通股數（2026-09-30） | C13: 十億股 | E13: 7.427 | G13: Interested-party | H13: 事實總帳 microsoft/data/microsoft_facts_FY27Q1_20261029.json｜sh.out.fy27q1（資產負債表；10-Q 同值） | I13: WACC 股權市值
A14: cash_q1 | B14: 現金與短期投資（2026-09-30） | C14: US$B | E14: 64.509 | G14: Interested-party | H14: 事實總帳 microsoft/data/microsoft_facts_FY27Q1_20261029.json｜bs.cashSti.fy27q1（新聞稿與 IR 財務報表兩讀一致） | I14: DCF 權益橋（評價日）
A15: debt_q1 | B15: 債務面額（2026-09-30） | C15: US$B | E15: 41.269 | G15: Interested-party | H15: 事實總帳 microsoft/data/microsoft_facts_FY27Q1_20261029.json｜debt.face.fy27q1（10-Q 附註 9 到期表合計） | I15: 帳面值 35.481；FY2026 面額 − 本季償還 4.850＝41.286（差 0.017 推定匯率）
A16: fl_liab_q1 | B16: 融資租賃負債（2026-09-30，在帳） | C16: US$B | E16: 70.973 | G16: Interested-party | H16: 事實總帳 microsoft/data/microsoft_facts_FY27Q1_20261029.json｜lease.finLiab.fy27q1（10-Q 附註 12；付款 95.246 − 設算利息 24.273 核對） | I16: 含本季新起租；DCF 權益橋（評價日）
A17: sh_val | B17: 評價日流通股數（WACC） | C17: 十億股 | E17: =sh_out_q1 -> 7.427 | G17: Derived | H17: ＝sh_out_q1（v0.3.1：評價日 2026-09-30） | I17: —
A18: shd_val | B18: 評價日稀釋股數（DCF 每股分母） | C18: 十億股 | E18: =sh_dil_q1 -> 7.446 | G18: Derived | H18: ＝sh_dil_q1（v0.3.1：評價日 2026-09-30） | I18: —
A19: cash_val | B19: 評價日現金與短期投資 | C19: US$B | E19: =cash_q1 -> 64.509 | G19: Derived | H19: ＝cash_q1（v0.3.1：評價日 2026-09-30） | I19: —
A20: debt_val | B20: 評價日債務面額 | C20: US$B | E20: =debt_q1 -> 41.269 | G20: Derived | H20: ＝debt_q1（v0.3.1：評價日 2026-09-30） | I20: —
A21: fl_val | B21: 評價日在帳融資租賃負債 | C21: US$B | E21: =fl_liab_q1 -> 70.973 | G21: Derived | H21: ＝fl_liab_q1（v0.3.1：評價日 2026-09-30） | I21: —
A22: debt_mat_27 | B22: 債務到期 FY2027 | C22: US$B | E22: 9.25 | G22: Verified | H22: 事實總帳 microsoft/data/microsoft_facts_20261008.json｜debt.maturity.fy2027（附註 10 到期表） | I22: FY2027：Q1 已還 4.850＋10-Q 剩餘三季 4.400＝9.250（10-K 9.227）
A23: debt_mat_28 | B23: 債務到期 FY2028 | C23: US$B | E23: 0 | G23: Verified | H23: 事實總帳 microsoft/data/microsoft_facts_20261008.json｜debt.maturity.fy2028（附註 10 到期表） | I23: 10-Q 2026-09-30 到期表同值
A24: debt_mat_29 | B24: 債務到期 FY2029 | C24: US$B | E24: 2.001 | G24: Verified | H24: 事實總帳 microsoft/data/microsoft_facts_20261008.json｜debt.maturity.fy2029（附註 10 到期表） | I24: 10-Q 2026-09-30 到期表同值
A25: debt_mat_30 | B25: 債務到期 FY2030 | C25: US$B | E25: 0 | G25: Verified | H25: 事實總帳 microsoft/data/microsoft_facts_20261008.json｜debt.maturity.fy2030（附註 10 到期表） | I25: 10-Q 2026-09-30 到期表同值
A26: debt_mat_31 | B26: 債務到期 FY2031 | C26: US$B | E26: 0.5 | G26: Verified | H26: 事實總帳 microsoft/data/microsoft_facts_20261008.json｜debt.maturity.fy2031（附註 10 到期表） | I26: 10-Q 2026-09-30 到期表同值
A27: debt_mat_32 | B27: 債務到期 FY2032 | C27: US$B | E27: 0 | G27: Assumed | H27: 事實總帳 microsoft/data/microsoft_facts_20261008.json｜到期表只列 FY2031 以後合計 34.385；FY2032 取 0 | I27: —
A28: fl_liab | B28: 融資租賃負債（2026-06-30，在帳） | C28: US$B | E28: 66.594 | G28: Verified | H28: 事實總帳 microsoft/data/microsoft_facts_20261008.json｜lease.finLiab.fy2026（附註 13） | I28: 在帳融資租賃的資產已在過去的資本支出（公司口徑）內，其本金在預測期照付（CF 頁）
A29: fl_rate | B29: 融資租賃加權利率 | C29: % | E29: 0.045 | G29: Verified | H29: 事實總帳 microsoft/data/microsoft_facts_20261008.json｜lease.wtdRate.fin | I29: 10-Q 2026-09-30 同為 4.5%
A30: fl_pay_27 | B30: 在帳融資租賃付款 FY2027（未折現，含息） | C30: US$B | E30: 7.121 | G30: Verified | H30: 事實總帳 microsoft/data/microsoft_facts_20261008.json｜lease.maturity.fin.fy2027 | I30: 2026-06-30 在帳租賃的付款表（收支關卡用；FY27Q1 新起租者已在資本支出內）
A31: fl_pay_28 | B31: 在帳融資租賃付款 FY2028（未折現，含息） | C31: US$B | E31: 7.294 | G31: Verified | H31: 事實總帳 microsoft/data/microsoft_facts_20261008.json｜lease.maturity.fin.fy2028 | I31: 2026-06-30 在帳租賃的付款表（收支關卡用；FY27Q1 新起租者已在資本支出內）
A32: fl_pay_29 | B32: 在帳融資租賃付款 FY2029（未折現，含息） | C32: US$B | E32: 6.668 | G32: Verified | H32: 事實總帳 microsoft/data/microsoft_facts_20261008.json｜lease.maturity.fin.fy2029 | I32: 2026-06-30 在帳租賃的付款表（收支關卡用；FY27Q1 新起租者已在資本支出內）
A33: fl_pay_30 | B33: 在帳融資租賃付款 FY2030（未折現，含息） | C33: US$B | E33: 6.57 | G33: Verified | H33: 事實總帳 microsoft/data/microsoft_facts_20261008.json｜lease.maturity.fin.fy2030 | I33: 2026-06-30 在帳租賃的付款表（收支關卡用；FY27Q1 新起租者已在資本支出內）
A34: fl_pay_31 | B34: 在帳融資租賃付款 FY2031（未折現，含息） | C34: US$B | E34: 6.543 | G34: Verified | H34: 事實總帳 microsoft/data/microsoft_facts_20261008.json｜lease.maturity.fin.fy2031 | I34: 2026-06-30 在帳租賃的付款表（收支關卡用；FY27Q1 新起租者已在資本支出內）
A35: fl_pay_32 | B35: 在帳融資租賃付款 FY2032（未折現，含息） | C35: US$B | E35: =fl_pay_31 -> 6.543 | G35: Assumed | H35: 事實總帳 microsoft/data/microsoft_facts_20261008.json｜FY2032 比照 FY2031（之後合計 55.490 分多年） | I35: 2026-06-30 在帳租賃的付款表（收支關卡用；FY27Q1 新起租者已在資本支出內）
A36: min_cash | B36: 最低現金 | C36: US$B | D36: 30 | E36: 50 | F36: 70 | G36: Assumed | H36: 沿用 v0.2.2（microsoft/legacy_v0.2/company.json；交接檔 docs/handoff/20261025_Microsoft收支模型_交接檔_v0_2_2.md）（defaults.minCash 50） | I36: 低於此水準先停回購、再舉債
A37: bb_target | B37: 回購目標（每年） | C37: US$B | E37: 22.271 | G37: Verified | H37: 事實總帳 microsoft/data/microsoft_facts_20261008.json｜cf.buyback.fy2026（含員工扣稅買回 5.6） | I37: 現金不足時先減回購
A38: bb_g | B38: 回購價格年增（以現價起算） | C38: % | D38: 0 | E38: 0.08 | F38: 0.12 | G38: Assumed | H38: 無：約等於股東權益成本扣股利率 | I38: 只影響股數
A39: sh_iss | B39: 員工股票發行（每年） | C39: 十億股 | D39: 0.035 | E39: 0.045 | F39: 0.055 | G39: Derived | H39: 事實總帳 microsoft/data/microsoft_facts_20261008.json｜FY2026 回購約 0.048 十億股（計畫 0.036＋扣稅買回 5.6 ÷ 約 470 美元），基本加權股數 7.433 → 7.429 幾乎不變 → 發行約 0.045 | I39: 低／高 Assumed
A40: dps_q0 | B40: 每季股利（FY2027 第一季付，舊額） | C40: US$ | E40: 0.91 | G40: Verified | H40: 事實總帳 microsoft/data/microsoft_facts_20261008.json｜sh.dps.fy2026（每季 0.91） | I40: —
...

Sheet Q
A1: Q — 實績（十億美元）。分部與產品線為 FY2027 起的報導口徑（FY25Q2–FY26Q4：8-K 2026-09-02「Segment History／Products and Service Offerings — As Restated」，未經查核；FY27Q1：2026-10-28 財報新聞稿與 IR 財務報表，兩次讀取核對一致）；合併損益、現金流量取自 10-K／財報新聞稿（事實總帳）
A2: 最近八季 FY25Q2–FY27Q1（v0.3.1 加入 FY27Q1、移出 FY25Q1）；J 欄＝FY2026 四季合計（公式）、K 欄＝FY2027 年初至今（Q1）；L、M 欄＝公司揭露的年度值（輸入）；核對列實績必須為 0。舊三分部（PBP／IC／MPC）列在下方對照（FY2026 以前口徑）
A3: 項目 | B3: FY25Q2（～2024-12） | C3: FY25Q3（～2025-03） | D3: FY25Q4（～06） | E3: FY26Q1（～2025-09） | F3: FY26Q2（～12） | G3: FY26Q3（～2026-03） | H3: FY26Q4（～06） | I3: FY27Q1（～2026-09） | J3: FY2026（四季合計） | K3: FY2027 年初至今（Q1） | L3: FY2025（公司年度值） | M3: FY2026（公司年度值） | N3: 標記 | O3: 來源（事實總帳 id）
A4: 1. 官方分部與產品線營收（FY2027 起報導口徑）
A5: Agents and Infra | B5: 52.766 | C5: 54.763 | D5: 60.778 | E5: 61.672 | F5: 64.441 | G5: 67.438 | H5: 74.576 | I5: 76.795 | J5: =SUM(E5:H5) -> 268.127 | K5: =I5 -> 76.795 | L5: 218.783 | M5: 268.127 | N5: Verified | O5: 8-K 2026-09-02 附件 99.1（As Restated）；FY27Q1：2026-10-28 新聞稿／IR 財務報表｜q.seg27.ai.rev.*、seg27.ai.rev.*
A6: Azure | B6: 17.337 | C6: 18.54 | D6: 20.712 | E6: 22.384 | F6: 24.129 | G6: 26.008 | H6: 29.417 | I6: 33.165 | J6: =SUM(E6:H6) -> 101.938 | K6: =I6 -> 33.165 | L6: 72.61 | M6: 101.938 | N6: Verified | O6: 8-K 2026-09-02 附件 99.1（As Restated）；FY27Q1：2026-10-28 新聞稿／IR 財務報表｜q.prod27.azure.*
A7: Microsoft 365 cloud | B7: 20.686 | C7: 20.967 | D7: 22.935 | E7: 23.694 | F7: 24.466 | G7: 25.418 | H7: 26.721 | I7: 27.778 | J7: =SUM(E7:H7) -> 100.299 | K7: =I7 -> 27.778 | L7: 84.605 | M7: 100.299 | N7: Verified | O7: 8-K 2026-09-02 附件 99.1（As Restated）；FY27Q1：2026-10-28 新聞稿／IR 財務報表｜q.prod27.m365cloud.*
A8: Productivity and server licensing | B8: 8.307 | C8: 8.731 | D8: 10.302 | E8: 8.678 | F8: 8.814 | G8: 8.76 | H8: 11.033 | I8: 8.407 | J8: =SUM(E8:H8) -> 37.285 | K8: =I8 -> 8.407 | L8: 35.391 | M8: 37.285 | N8: Verified | O8: 8-K 2026-09-02 附件 99.1（As Restated）；FY27Q1：2026-10-28 新聞稿／IR 財務報表｜q.prod27.licensing.*
A9: Industry solutions | B9: 4.544 | C9: 4.579 | D9: 4.835 | E9: 4.894 | F9: 4.994 | G9: 5.165 | H9: 5.292 | I9: 5.337 | J9: =SUM(E9:H9) -> 20.345 | K9: =I9 -> 5.337 | L9: 18.417 | M9: 20.345 | N9: Verified | O9: 8-K 2026-09-02 附件 99.1（As Restated）；FY27Q1：2026-10-28 新聞稿／IR 財務報表｜q.prod27.industry.*
A10: Frontier and support services | B10: 1.892 | C10: 1.946 | D10: 1.994 | E10: 2.022 | F10: 2.038 | G10: 2.087 | H10: 2.113 | I10: 2.108 | J10: =SUM(E10:H10) -> 8.26 | K10: =I10 -> 2.108 | L10: 7.76 | M10: 8.26 | N10: Verified | O10: 8-K 2026-09-02 附件 99.1（As Restated）；FY27Q1：2026-10-28 新聞稿／IR 財務報表｜q.prod27.frontier.*
A11: 檢查：Agents and Infra 產品線合計 − 分部 | B11: =SUM(B6:B10)-B5 -> 0 | C11: =SUM(C6:C10)-C5 -> 0 | D11: =SUM(D6:D10)-D5 -> 0 | E11: =SUM(E6:E10)-E5 -> 0 | F11: =SUM(F6:F10)-F5 -> 0 | G11: =SUM(G6:G10)-G5 -> 0 | H11: =SUM(H6:H10)-H5 -> 0 | I11: =SUM(I6:I10)-I5 -> 0 | ... M11: =SUM(M6:M10)-M5 -> 0 | N11: 核對
A12: Devices and Consumer | B12: 16.866 | C12: 15.303 | D12: 15.663 | E12: 16.001 | F12: 16.832 | G12: 15.448 | H12: 15.431 | I12: 15.484 | J12: =SUM(E12:H12) -> 63.712 | K12: =I12 -> 15.484 | L12: 62.941 | M12: 63.712 | N12: Verified | O12: 8-K 2026-09-02 附件 99.1（As Restated）；FY27Q1：2026-10-28 新聞稿／IR 財務報表｜q.seg27.dc.rev.*
A13: Search and advertising | B13: 5.773 | C13: 5.437 | D13: 5.802 | E13: 5.942 | F13: 6.393 | G13: 6.065 | H13: 6.435 | I13: 6.554 | J13: =SUM(E13:H13) -> 24.835 | K13: =I13 -> 6.554 | L13: 22.171 | M13: 24.835 | N13: Verified | O13: 8-K 2026-09-02 附件 99.1（As Restated）；FY27Q1：2026-10-28 新聞稿／IR 財務報表｜q.prod27.searchads.*
A14: XBOX | B14: 6.581 | C14: 5.721 | D14: 5.532 | E14: 5.508 | F14: 5.958 | G14: 5.341 | H14: 4.983 | I14: 5.379 | J14: =SUM(E14:H14) -> 21.79 | K14: =I14 -> 5.379 | L14: 23.455 | M14: 21.79 | N14: Verified | O14: 8-K 2026-09-02 附件 99.1（As Restated）；FY27Q1：2026-10-28 新聞稿／IR 財務報表｜q.prod27.xbox.*
A15: Windows OEM and devices | B15: 4.512 | C15: 4.145 | D15: 4.329 | E15: 4.551 | F15: 4.481 | G15: 4.042 | H15: 4.013 | I15: 3.551 | J15: =SUM(E15:H15) -> 17.087 | K15: =I15 -> 3.551 | L15: 17.315 | M15: 17.087 | N15: Verified | O15: 8-K 2026-09-02 附件 99.1（As Restated）；FY27Q1：2026-10-28 新聞稿／IR 財務報表｜q.prod27.windows.*
A16: 檢查：Devices and Consumer 產品線合計 − 分部 | B16: =SUM(B13:B15)-B12 -> 0 | C16: =SUM(C13:C15)-C12 -> 0 | D16: =SUM(D13:D15)-D12 -> 0 | E16: =SUM(E13:E15)-E12 -> 0 | F16: =SUM(F13:F15)-F12 -> 0 | G16: =SUM(G13:G15)-G12 -> 0 | H16: =SUM(H13:H15)-H12 -> 0 | I16: =SUM(I13:I15)-I12 -> 0 | ... M16: =SUM(M13:M15)-M12 -> 0 | N16: 核對
A17: 分部合計（營收） | B17: =B5+B12 -> 69.632 | C17: =C5+C12 -> 70.066 | D17: =D5+D12 -> 76.441 | E17: =E5+E12 -> 77.673 | F17: =F5+F12 -> 81.273 | G17: =G5+G12 -> 82.886 | H17: =H5+H12 -> 90.007 | I17: =I5+I12 -> 92.279 | J17: =SUM(E17:H17) -> 331.839 | K17: =I17 -> 92.279 | L17: =L5+L12 -> 281.724 | M17: =M5+M12 -> 331.839 | N17: Derived
A18: 合併營收（公司損益表） | B18: 69.632 | C18: 70.066 | D18: 76.441 | E18: 77.673 | F18: 81.273 | G18: 82.886 | H18: 90.007 | I18: 92.279 | J18: =SUM(E18:H18) -> 331.839 | K18: =I18 -> 92.279 | L18: 281.724 | M18: 331.839 | N18: Verified | O18: 財報新聞稿／10-K｜q.rev.*、is.rev.*
A19: 檢查：分部合計 − 合併營收 | B19: =B17-B18 -> 0 | C19: =C17-C18 -> 0 | D19: =D17-D18 -> 0 | E19: =E17-E18 -> 0 | F19: =F17-F18 -> 0 | G19: =G17-G18 -> 0 | H19: =H17-H18 -> 0 | I19: =I17-I18 -> 0 | ... M19: =M17-M18 -> 0 | N19: 核對
A20: 2. 分部營業利益（Microsoft 無未分攤項：分部合計＝合併營業利益）
A21: Agents and Infra 營業利益 | B21: 26.718 | C21: 27.704 | D21: 30.221 | E21: 32.718 | F21: 33.167 | G21: 33.748 | H21: 36.732 | I21: 40.558 | J21: =SUM(E21:H21) -> 136.365 | K21: =I21 -> 40.558 | L21: 110.814 | M21: 136.365 | N21: Verified | O21: 8-K 2026-09-02 附件 99.1（As Restated）；FY27Q1：2026-10-28 新聞稿／IR 財務報表｜q.seg27.ai.oi.*
A22: Devices and Consumer 營業利益 | B22: 4.935 | C22: 4.296 | D22: 4.102 | E22: 5.243 | F22: 5.108 | G22: 4.65 | H22: 3.871 | I22: 5.357 | J22: =SUM(E22:H22) -> 18.872 | K22: =I22 -> 5.357 | L22: 17.714 | M22: 18.872 | N22: Verified | O22: 8-K 2026-09-02 附件 99.1（As Restated）；FY27Q1：2026-10-28 新聞稿／IR 財務報表｜q.seg27.dc.oi.*
A23: 合併營業利益（公司損益表） | B23: 31.653 | C23: 32 | D23: 34.323 | E23: 37.961 | F23: 38.275 | G23: 38.398 | H23: 40.603 | I23: 45.915 | J23: =SUM(E23:H23) -> 155.237 | K23: =I23 -> 45.915 | L23: 128.528 | M23: 155.237 | N23: Verified | O23: 財報新聞稿／10-K｜q.oi.*、is.oi.*
A24: 檢查：分部營業利益合計 − 合併營業利益（未分攤＝0） | B24: =B21+B22-B23 -> 0 | C24: =C21+C22-C23 -> 0 | D24: =D21+D22-D23 -> 0 | E24: =E21+E22-E23 -> 0 | F24: =F21+F22-F23 -> 0 | G24: =G21+G22-G23 -> 0 | H24: =H21+H22-H23 -> 0 | I24: =I21+I22-I23 -> 0 | ... M24: =M21+M22-M23 -> 0 | N24: 核對
A25: 3. 合併損益主要列（年度值；淨利另列各季；FY27Q1 單季另填 I 欄）
A26: 淨利（GAAP，含 OpenAI 等持股損益） | B26: 24.108 | C26: 25.824 | D26: 27.233 | E26: 27.747 | F26: 38.458 | G26: 31.778 | H26: 35.766 | I26: 36.629 | J26: =SUM(E26:H26) -> 133.749 | K26: =I26 -> 36.629 | L26: 101.832 | M26: 133.749 | N26: Verified | O26: 財報新聞稿／10-K｜q.ni.*、is.ni.*
A27: 業外收支（other income (expense), net） | I27: 0.038 | K27: =I27 -> 0.038 | L27: -4.901 | M27: 10.697 | N27: Verified | O27: 10-K｜is.oie.*；FY27Q1：q.oie.fy27q1
A28: 稅前淨利 | I28: 45.953 | K28: =I28 -> 45.953 | L28: 123.627 | M28: 165.934 | N28: Verified | O28: 10-K｜is.pretax.*；FY27Q1：q.pretax.fy27q1
A29: 所得稅 | I29: 9.324 | K29: =I29 -> 9.324 | L29: 21.795 | M29: 32.185 | N29: Verified | O29: 10-K｜is.tax.*；FY27Q1：q.tax.fy27q1
A30: 其中：OpenAI 等持股損益（公司非 GAAP 調節；FY27Q1 為稅前 OpenAI 淨利得） | I30: 0.272 | K30: =I30 -> 0.272 | L30: -4.763 | M30: 6.53 | N30: Verified | O30: 10-K｜is.openaiGain.*；FY27Q1：q.openaiGain.fy27q1
A31: 稀釋加權股數（十億股） | I31: 7.446 | K31: =I31 -> 7.446 | L31: 7.465 | M31: 7.453 | N31: Verified | O31: 10-K｜is.sharesDilW.*；FY27Q1：q.sharesDilW.fy27q1
A32: 稀釋 EPS（US$） | I32: 4.92 | K32: =I32 -> 4.92 | L32: 13.64 | M32: 17.95 | N32: Verified | O32: 10-K｜is.epsDil.*；FY27Q1：q.epsDil.fy27q1
A33: 檢查：營業利益＋業外 − 稅前；稅前 − 稅 − 淨利（年度與 FY27Q1，應為 0） | I33: =(I23+I27-I28)+(I28-I29-I26) -> 0 | L33: =(L23+L27-L28)+(L28-L29-L26) -> 0 | M33: =(M23+M27-M28)+(M28-M29-M26) -> 0 | N33: 核對
A34: 4. 現金流量（各季為新聞稿單季值；資本支出為現金 PP&E）
A35: 營業現金流 | B35: 22.291 | C35: 37.044 | D35: 42.647 | E35: 45.057 | F35: 35.758 | G35: 46.679 | H35: 55.441 | I35: 58 | J35: =SUM(E35:H35) -> 182.935 | K35: =I35 -> 58 | L35: 136.162 | M35: 182.935 | N35: Verified | O35: 新聞稿現金流量表｜q.cf.ocf.*
A36: 資本支出（現金 PP&E，正值） | B36: 15.804 | C36: 16.745 | D36: 17.079 | E36: 19.394 | F36: 29.876 | G36: 30.876 | H36: 35.802 | I36: 39.367 | J36: =SUM(E36:H36) -> 115.948 | K36: =I36 -> 39.367 | L36: 64.551 | M36: 115.948 | N36: Verified | O36: 新聞稿現金流量表｜q.cf.capex.*
A37: 自由現金流（營業現金流 − 現金資本支出） | B37: =B35-B36 -> 6.487 | C37: =C35-C36 -> 20.299 | D37: =D35-D36 -> 25.568 | E37: =E35-E36 -> 25.663 | F37: =F35-F36 -> 5.882 | G37: =G35-G36 -> 15.803 | H37: =H35-H36 -> 19.639 | I37: =I35-I36 -> 18.633 | J37: =SUM(E37:H37) -> 66.987 | K37: =I37 -> 18.633 | L37: =L35-L36 -> 71.611 | M37: =M35-M36 -> 66.987 | N37: Derived
A38: 折舊、攤銷及其他（現金流量表） | B38: 5.667 | C38: 7.734 | D38: 9.317 | E38: 8.147 | F38: 9.198 | G38: 10.167 | H38: 11.022 | I38: 11.744 | J38: =SUM(E38:H38) -> 38.534 | K38: =I38 -> 11.744 | L38: 29.433 | M38: 38.534 | N38: Verified | O38: 新聞稿現金流量表｜q.cf.da.*（Q1 由年初至今推得）
A39: 股票薪酬 | B39: 3.089 | C39: 2.98 | D39: 3.073 | E39: 2.983 | F39: 3.219 | G39: 3.081 | H39: 3.122 | I39: 3.134 | J39: =SUM(E39:H39) -> 12.405 | K39: =I39 -> 3.134 | L39: 11.974 | M39: 12.405 | N39: Verified | O39: 新聞稿現金流量表｜q.cf.sbc.*
A40: 回購（正值） | B40: 4.986 | C40: 4.781 | D40: 4.546 | E40: 5.65 | F40: 7.415 | G40: 4.627 | H40: 4.579 | I40: 4.379 | J40: =SUM(E40:H40) -> 22.271 | K40: =I40 -> 4.379 | L40: 18.42 | M40: 22.271 | N40: Verified | O40: 新聞稿現金流量表｜q.cf.buyback.*
...

Sheet Thesis
A1: Thesis — 命題模組：AI 在役 MW → Azure AI 營收（MW × Tokenomics 每 MW 持有成本 × k）；AI 資本支出（MW × Tokenomics 每 MW 成本）→ AI 折舊與營運成本 → Agents and Infra 營業利益；AI 增量 ROIC 對 WACC
A2: 三情境的 MW 路徑相同（資本支出依公司指引），差在變現：k（長約／現貨組合）與 Copilot 座席。命題模組只驅動 Azure 的「Azure AI」子列與 M365 cloud 的「Copilot」子列，不取代官方分部
A3: 核心問題的答案列：「AI 增量 ROIC − WACC」（FY2029 欄）
A4: 情境 A（樂觀）｜命題模組（Thesis）
A5: 項目 | B5: 單位 | C5: FY2024A | D5: FY2025A | E5: FY2026A | F5: FY2027 | G5: FY2028 | H5: FY2029 | I5: FY2030 | J5: FY2031 | K5: FY2032 | L5: 說明
A6: 會計年度（數值；公式以「年度 − base_fy」計年數） | B6: 年 | C6: 2024 | D6: 2025 | E6: 2026 | F6: 2027 | G6: 2028 | H6: 2029 | I6: 2030 | J6: 2031 | K6: 2032
A7: 在役對外 AI MW 每年新增 | B7: MW | F7: =pace -> 2726.5351 | G7: =pace -> 2726.5351 | H7: =pace -> 2726.5351 | I7: =pace+(g_tv*Thesis!H8-pace)*MIN(1,(Thesis!I6-pace_y0)/(pace_y1-pace_y0)) -> 1931.9861 | J7: =pace+(g_tv*Thesis!I8-pace)*MIN(1,(Thesis!J6-pace_y0)/(pace_y1-pace_y0)) -> 1176.0769 | K7: =pace+(g_tv*Thesis!J8-pace)*MIN(1,(Thesis!K6-pace_y0)/(pace_y1-pace_y0)) -> 436.13005 | L7: FY2029 以前＝依資本支出指引的速度；之後逐年線性收斂到 g_tv × 前一年在役 MW，FY2032 的在役 MW 年增＝g（修正二 F5）
A8: 在役對外 AI MW（年底，含租用） | B8: MW | C8: =mw_ext_24 -> 640 | D8: =mw_ext_25 -> 1630 | E8: =mw_ext_26 -> 3250 | F8: =Thesis!E8+Thesis!F7 -> 5976.5351 | G8: =Thesis!F8+Thesis!G7 -> 8703.0702 | H8: =Thesis!G8+Thesis!H7 -> 11429.605 | I8: =Thesis!H8+Thesis!I7 -> 13361.591 | J8: =Thesis!I8+Thesis!J7 -> 14537.668 | K8: =Thesis!J8+Thesis!K7 -> 14973.798 | L8: 三情境速度相同（變現驅動不同）
A9: 其中租用 neocloud 的對外 MW | B9: MW | C9: =rent_ext_24 -> 150 | D9: =rent_ext_25 -> 400 | E9: =rent_ext_26 -> 550 | F9: =rent_ext_f -> 756 | G9: =rent_ext_f -> 756 | H9: =rent_ext_f -> 756 | I9: =rent_ext_f -> 756 | J9: =rent_ext_f -> 756 | K9: =rent_ext_f -> 756 | L9: 收入照算，不計資本支出與折舊（C20）
A10: 自有對外 MW | B10: MW | C10: =Thesis!C8-Thesis!C9 -> 490 | D10: =Thesis!D8-Thesis!D9 -> 1230 | E10: =Thesis!E8-Thesis!E9 -> 2700 | F10: =Thesis!F8-Thesis!F9 -> 5220.5351 | G10: =Thesis!G8-Thesis!G9 -> 7947.0702 | H10: =Thesis!H8-Thesis!H9 -> 10673.605 | I10: =Thesis!I8-Thesis!I9 -> 12605.591 | J10: =Thesis!J8-Thesis!J9 -> 13781.668 | K10: =Thesis!K8-Thesis!K9 -> 14217.798
A11: 自有 AI MW（對外 ÷ 對外比例） | B11: MW | C11: =Thesis!C10/ext_sh -> 816.66667 | D11: =Thesis!D10/ext_sh -> 2050 | E11: =Thesis!E10/ext_sh -> 4500 | F11: =Thesis!F10/ext_sh -> 8700.8918 | G11: =Thesis!G10/ext_sh -> 13245.117 | H11: =Thesis!H10/ext_sh -> 17789.342 | I11: =Thesis!I10/ext_sh -> 21009.319 | J11: =Thesis!J10/ext_sh -> 22969.447 | K11: =Thesis!K10/ext_sh -> 23696.331 | L11: 含自用（M365／GitHub Copilot、MAI 研發）
A12: 其中自用 AI MW | B12: MW | C12: =Thesis!C11-Thesis!C10 -> 326.66667 | D12: =Thesis!D11-Thesis!D10 -> 820 | E12: =Thesis!E11-Thesis!E10 -> 1800 | F12: =Thesis!F11-Thesis!F10 -> 3480.3567 | G12: =Thesis!G11-Thesis!G10 -> 5298.0468 | H12: =Thesis!H11-Thesis!H10 -> 7115.7369 | I12: =Thesis!I11-Thesis!I10 -> 8403.7276 | J12: =Thesis!J11-Thesis!J10 -> 9187.7789 | K12: =Thesis!K11-Thesis!K10 -> 9478.5322
A13: 自有 AI MW 新增（FY2024 欄含以前全部） | B13: MW | C13: =Thesis!C11 -> 816.66667 | D13: =Thesis!D11-Thesis!C11 -> 1233.3333 | E13: =Thesis!E11-Thesis!D11 -> 2450 | F13: =Thesis!F11-Thesis!E11 -> 4200.8918 | G13: =Thesis!G11-Thesis!F11 -> 4544.2252 | H13: =Thesis!H11-Thesis!G11 -> 4544.2252 | I13: =Thesis!I11-Thesis!H11 -> 3219.9769 | J13: =Thesis!J11-Thesis!I11 -> 1960.1281 | K13: =Thesis!K11-Thesis!J11 -> 726.88341
A14: 在役對外 MW 新增 | B14: MW | D14: =Thesis!D8-Thesis!C8 -> 990 | E14: =Thesis!E8-Thesis!D8 -> 1620 | F14: =Thesis!F8-Thesis!E8 -> 2726.5351 | G14: =Thesis!G8-Thesis!F8 -> 2726.5351 | H14: =Thesis!H8-Thesis!G8 -> 2726.5351 | I14: =Thesis!I8-Thesis!H8 -> 1931.9861 | J14: =Thesis!J8-Thesis!I8 -> 1176.0769 | K14: =Thesis!K8-Thesis!J8 -> 436.13005
A15: 其中汰換為新世代的對外 MW（汰換 MW × 對外比例） | B15: MW | F15: =Thesis!F34*ext_sh -> 0 | G15: =Thesis!G34*ext_sh -> 0 | H15: =Thesis!H34*ext_sh -> 0 | I15: =Thesis!I34*ext_sh -> 490 | J15: =Thesis!J34*ext_sh -> 740 | K15: =Thesis!K34*ext_sh -> 1470 | L15: 修正一：汰換時在役世代占比同步更新（舊世代依期初占比移出、新世代依當年新增占比移入）
A16: 在役對外 MW：Hopper | B16: MW | C16: =mix_h*Thesis!C8 -> 128 | D16: =mix_h*Thesis!D8 -> 326 | E16: =mix_h*Thesis!E8 -> 650 | F16: =Thesis!E16-Thesis!F15*mix_h -> 650 | G16: =Thesis!F16-Thesis!G15*mix_h -> 650 | H16: =Thesis!G16-Thesis!H15*mix_h -> 650 | I16: =Thesis!H16-Thesis!I15*mix_h -> 552 | J16: =Thesis!I16-Thesis!J15*mix_h -> 404 | K16: =Thesis!J16-Thesis!K15*mix_h -> 110
A17: 在役對外 MW：GB200 | B17: MW | C17: =mix_g2*Thesis!C8 -> 288 | D17: =mix_g2*Thesis!D8 -> 733.5 | E17: =mix_g2*Thesis!E8 -> 1462.5 | F17: =Thesis!E17-Thesis!F15*mix_g2 -> 1462.5 | G17: =Thesis!F17-Thesis!G15*mix_g2 -> 1462.5 | H17: =Thesis!G17-Thesis!H15*mix_g2 -> 1462.5 | I17: =Thesis!H17-Thesis!I15*mix_g2 -> 1242 | J17: =Thesis!I17-Thesis!J15*mix_g2 -> 909 | K17: =Thesis!J17-Thesis!K15*mix_g2 -> 247.5
A18: 在役對外 MW：GB300（nonnv＝0 時含 Maia 200） | B18: MW | C18: =mix_g3*Thesis!C8 -> 224 | D18: =mix_g3*Thesis!D8 -> 570.5 | E18: =mix_g3*Thesis!E8 -> 1137.5 | F18: =Thesis!E18+(Thesis!F14+Thesis!F15)*(a_g3_27-nonnv*a_mai)-Thesis!F15*mix_g3 -> 2773.4211 | G18: =Thesis!F18+(Thesis!G14+Thesis!G15)*(a_g3_28-nonnv*a_mai)-Thesis!G15*mix_g3 -> 3318.7281 | H18: =Thesis!G18+(Thesis!H14+Thesis!H15)*(a_g3_29-nonnv*a_mai)-Thesis!H15*mix_g3 -> 3318.7281 | I18: =Thesis!H18+(Thesis!I14+Thesis!I15)*(a_g3_29-nonnv*a_mai)-Thesis!I15*mix_g3 -> 3147.2281 | J18: =Thesis!I18+(Thesis!J14+Thesis!J15)*(a_g3_29-nonnv*a_mai)-Thesis!J15*mix_g3 -> 2888.2281 | K18: =Thesis!J18+(Thesis!K14+Thesis!K15)*(a_g3_29-nonnv*a_mai)-Thesis!K15*mix_g3 -> 2373.7281
A19: 在役對外 MW：Maia 200（nonnv＝1；Tokenomics IF_NonNV_*） | B19: MW | C19: 0 | D19: 0 | E19: 0 | F19: =Thesis!E19+(Thesis!F14+Thesis!F15)*nonnv*a_mai -> 272.65351 | G19: =Thesis!F19+(Thesis!G14+Thesis!G15)*nonnv*a_mai -> 545.30702 | H19: =Thesis!G19+(Thesis!H14+Thesis!H15)*nonnv*a_mai -> 817.96053 | I19: =Thesis!H19+(Thesis!I14+Thesis!I15)*nonnv*a_mai -> 1060.1591 | J19: =Thesis!I19+(Thesis!J14+Thesis!J15)*nonnv*a_mai -> 1251.7668 | K19: =Thesis!J19+(Thesis!K14+Thesis!K15)*nonnv*a_mai -> 1442.3798 | L19: v0.3.1：Maia 改讀 Tokenomics 產出比與持有成本比（÷ VR200）；v0.3 以 GB300 × 1.0 計
A20: 在役對外 MW：VR200 | B20: MW | C20: 0 | D20: 0 | E20: 0 | F20: =Thesis!E20+(Thesis!F14+Thesis!F15)*(1-a_g3_27) -> 817.96053 | G20: =Thesis!F20+(Thesis!G14+Thesis!G15)*(1-a_g3_28) -> 2726.5351 | H20: =Thesis!G20+(Thesis!H14+Thesis!H15)*(1-a_g3_29) -> 5180.4167 | I20: =Thesis!H20+(Thesis!I14+Thesis!I15)*(1-a_g3_29) -> 7360.2042 | J20: =Thesis!I20+(Thesis!J14+Thesis!J15)*(1-a_g3_29) -> 9084.6734 | K20: =Thesis!J20+(Thesis!K14+Thesis!K15)*(1-a_g3_29) -> 10800.19
A21: 在役世代加權持有成本（IF_HoldEcon；Maia＝持有成本比 × VR200） | B21: US$M/MW-年 | C21: =(Thesis!C16*tk_hold_h100+Thesis!C17*tk_hold_gb200+Thesis!C18*tk_hold_gb300+Thesis!C20*tk_hold_vr200+Thesis!C19*nv_hold_mai*tk_hold_vr200)/Thesis!C8 -> 9.7235358 | D21: =(Thesis!D16*tk_hold_h100+Thesis!D17*tk_hold_gb200+Thesis!D18*tk_hold_gb300+Thesis!D20*tk_hold_vr200+Thesis!D19*nv_hold_mai*tk_hold_vr200)/Thesis!D8 -> 9.7235358 | E21: =(Thesis!E16*tk_hold_h100+Thesis!E17*tk_hold_gb200+Thesis!E18*tk_hold_gb300+Thesis!E20*tk_hold_vr200+Thesis!E19*nv_hold_mai*tk_hold_vr200)/Thesis!E8 -> 9.7235358 | F21: =(Thesis!F16*tk_hold_h100+Thesis!F17*tk_hold_gb200+Thesis!F18*tk_hold_gb300+Thesis!F20*tk_hold_vr200+Thesis!F19*nv_hold_mai*tk_hold_vr200)/Thesis!F8 -> 10.219535 | G21: =(Thesis!G16*tk_hold_h100+Thesis!G17*tk_hold_gb200+Thesis!G18*tk_hold_gb300+Thesis!G20*tk_hold_vr200+Thesis!G19*nv_hold_mai*tk_hold_vr200)/Thesis!G8 -> 10.57256 | H21: =(Thesis!H16*tk_hold_h100+Thesis!H17*tk_hold_gb200+Thesis!H18*tk_hold_gb300+Thesis!H20*tk_hold_vr200+Thesis!H19*nv_hold_mai*tk_hold_vr200)/Thesis!H8 -> 10.821043 | I21: =(Thesis!I16*tk_hold_h100+Thesis!I17*tk_hold_gb200+Thesis!I18*tk_hold_gb300+Thesis!I20*tk_hold_vr200+Thesis!I19*nv_hold_mai*tk_hold_vr200)/Thesis!I8 -> 11.005062 | J21: =(Thesis!J16*tk_hold_h100+Thesis!J17*tk_hold_gb200+Thesis!J18*tk_hold_gb300+Thesis!J20*tk_hold_vr200+Thesis!J19*nv_hold_mai*tk_hold_vr200)/Thesis!J8 -> 11.150579 | K21: =(Thesis!K16*tk_hold_h100+Thesis!K17*tk_hold_gb200+Thesis!K18*tk_hold_gb300+Thesis!K20*tk_hold_vr200+Thesis!K19*nv_hold_mai*tk_hold_vr200)/Thesis!K8 -> 11.349691 | L21: 影子效益（k＝1）用此成本口徑
A22: 在役世代加權收入錨（IF_HoldEcon；Maia＝產出比 × VR200） | B22: US$M/MW-年 | C22: =(Thesis!C16*tk_hold_h100+Thesis!C17*tk_hold_gb200+Thesis!C18*tk_hold_gb300+Thesis!C20*tk_hold_vr200+Thesis!C19*nv_out_mai*tk_hold_vr200)/Thesis!C8 -> 9.7235358 | D22: =(Thesis!D16*tk_hold_h100+Thesis!D17*tk_hold_gb200+Thesis!D18*tk_hold_gb300+Thesis!D20*tk_hold_vr200+Thesis!D19*nv_out_mai*tk_hold_vr200)/Thesis!D8 -> 9.7235358 | E22: =(Thesis!E16*tk_hold_h100+Thesis!E17*tk_hold_gb200+Thesis!E18*tk_hold_gb300+Thesis!E20*tk_hold_vr200+Thesis!E19*nv_out_mai*tk_hold_vr200)/Thesis!E8 -> 9.7235358 | F22: =(Thesis!F16*tk_hold_h100+Thesis!F17*tk_hold_gb200+Thesis!F18*tk_hold_gb300+Thesis!F20*tk_hold_vr200+Thesis!F19*nv_out_mai*tk_hold_vr200)/Thesis!F8 -> 10.247422 | G22: =(Thesis!G16*tk_hold_h100+Thesis!G17*tk_hold_gb200+Thesis!G18*tk_hold_gb300+Thesis!G20*tk_hold_vr200+Thesis!G19*nv_out_mai*tk_hold_vr200)/Thesis!G8 -> 10.61086 | H22: =(Thesis!H16*tk_hold_h100+Thesis!H17*tk_hold_gb200+Thesis!H18*tk_hold_gb300+Thesis!H20*tk_hold_vr200+Thesis!H19*nv_out_mai*tk_hold_vr200)/Thesis!H8 -> 10.864789 | I22: =(Thesis!I16*tk_hold_h100+Thesis!I17*tk_hold_gb200+Thesis!I18*tk_hold_gb300+Thesis!I20*tk_hold_vr200+Thesis!I19*nv_out_mai*tk_hold_vr200)/Thesis!I8 -> 11.053563 | J22: =(Thesis!J16*tk_hold_h100+Thesis!J17*tk_hold_gb200+Thesis!J18*tk_hold_gb300+Thesis!J20*tk_hold_vr200+Thesis!J19*nv_out_mai*tk_hold_vr200)/Thesis!J8 -> 11.203213 | K22: =(Thesis!K16*tk_hold_h100+Thesis!K17*tk_hold_gb200+Thesis!K18*tk_hold_gb300+Thesis!K20*tk_hold_vr200+Thesis!K19*nv_out_mai*tk_hold_vr200)/Thesis!K8 -> 11.408574 | L22: nonnv＝0 時與持有成本列相同
A23: k（長約占比 × k_長約＋其餘 × k_現貨） | B23: x | C23: =k_B -> 1.1721393 | D23: =k_B -> 1.1721393 | E23: =k_B -> 1.1721393 | F23: =(k_B+((ls_A*k_long+(1-ls_A)*k_spot)-k_B)*MIN(1,(Thesis!F6-base_fy)/k_ramp)) -> 1.2502283 | G23: =(k_B+((ls_A*k_long+(1-ls_A)*k_spot)-k_B)*MIN(1,(Thesis!G6-base_fy)/k_ramp)) -> 1.3283172 | H23: =(k_B+((ls_A*k_long+(1-ls_A)*k_spot)-k_B)*MIN(1,(Thesis!H6-base_fy)/k_ramp)) -> 1.4064062 | I23: =(k_B+((ls_A*k_long+(1-ls_A)*k_spot)-k_B)*MIN(1,(Thesis!I6-base_fy)/k_ramp)) -> 1.4064062 | J23: =(k_B+((ls_A*k_long+(1-ls_A)*k_spot)-k_B)*MIN(1,(Thesis!J6-base_fy)/k_ramp)) -> 1.4064062 | K23: =(k_B+((ls_A*k_long+(1-ls_A)*k_spot)-k_B)*MIN(1,(Thesis!K6-base_fy)/k_ramp)) -> 1.4064062 | L23: 實績期三情境同用基準 k（拆分是估計，不是情境）；FY2027 起 k_ramp 年線性移到情境 k
A24: 每 MW 年收入（對外） | B24: US$M/MW-年 | C24: =Thesis!C22*Thesis!C23*chip_f -> 11.397339 | D24: =Thesis!D22*Thesis!D23*chip_f -> 11.397339 | E24: =Thesis!E22*Thesis!E23*chip_f -> 11.397339 | F24: =Thesis!F22*Thesis!F23*chip_f -> 12.811617 | G24: =Thesis!G22*Thesis!G23*chip_f -> 14.094589 | H24: =Thesis!H22*Thesis!H23*chip_f -> 15.280306 | I24: =Thesis!I22*Thesis!I23*chip_f -> 15.545799 | J24: =Thesis!J22*Thesis!J23*chip_f -> 15.756268 | K24: =Thesis!K22*Thesis!K23*chip_f -> 16.045089 | L24: 按 MW-year 計價，不乘利用率（v0.2.2 口徑）
A25: Azure AI 營收（期間平均在役對外 MW × 每 MW 年收入） | B25: US$B | D25: =(Thesis!C8+Thesis!D8)/2*Thesis!D24/1000 -> 12.935979 | E25: =(Thesis!D8+Thesis!E8)/2*Thesis!E24/1000 -> 27.809506 | F25: =(Thesis!E8+Thesis!F8)/2*Thesis!F24/1000 -> 59.103417 | G25: =(Thesis!F8+Thesis!G8)/2*Thesis!G24/1000 -> 103.4515 | H25: =(Thesis!G8+Thesis!H8)/2*Thesis!H24/1000 -> 153.81672 | I25: =(Thesis!H8+Thesis!I8)/2*Thesis!I24/1000 -> 192.69948 | J25: =(Thesis!I8+Thesis!J8)/2*Thesis!J24/1000 -> 219.7941 | K25: =(Thesis!J8+Thesis!K8)/2*Thesis!K24/1000 -> 236.75705 | L25: FY2025、FY2026 為模型估計（用於拆出 Azure 其他）
A26: 在役世代加權 IF_OpexGW | B26: US$M/MW-年 | C26: =(Thesis!C16*tk_opex_h100+Thesis!C17*tk_opex_gb200+Thesis!C18*tk_opex_gb300+(Thesis!C20+Thesis!C19)*tk_opex_vr200)/Thesis!C8 -> 1.8863604 | D26: =(Thesis!D16*tk_opex_h100+Thesis!D17*tk_opex_gb200+Thesis!D18*tk_opex_gb300+(Thesis!D20+Thesis!D19)*tk_opex_vr200)/Thesis!D8 -> 1.8863604 | E26: =(Thesis!E16*tk_opex_h100+Thesis!E17*tk_opex_gb200+Thesis!E18*tk_opex_gb300+(Thesis!E20+Thesis!E19)*tk_opex_vr200)/Thesis!E8 -> 1.8863604 | F26: =(Thesis!F16*tk_opex_h100+Thesis!F17*tk_opex_gb200+Thesis!F18*tk_opex_gb300+(Thesis!F20+Thesis!F19)*tk_opex_vr200)/Thesis!F8 -> 1.9505116 | G26: =(Thesis!G16*tk_opex_h100+Thesis!G17*tk_opex_gb200+Thesis!G18*tk_opex_gb300+(Thesis!G20+Thesis!G19)*tk_opex_vr200)/Thesis!G8 -> 1.98836 | H26: =(Thesis!H16*tk_opex_h100+Thesis!H17*tk_opex_gb200+Thesis!H18*tk_opex_gb300+(Thesis!H20+Thesis!H19)*tk_opex_vr200)/Thesis!H8 -> 2.0134401 | I26: =(Thesis!I16*tk_opex_h100+Thesis!I17*tk_opex_gb200+Thesis!I18*tk_opex_gb300+(Thesis!I20+Thesis!I19)*tk_opex_vr200)/Thesis!I8 -> 2.0326117 | J26: =(Thesis!J16*tk_opex_h100+Thesis!J17*tk_opex_gb200+Thesis!J18*tk_opex_gb300+(Thesis!J20+Thesis!J19)*tk_opex_vr200)/Thesis!J8 -> 2.0480807 | K26: =(Thesis!K16*tk_opex_h100+Thesis!K17*tk_opex_gb200+Thesis!K18*tk_opex_gb300+(Thesis!K20+Thesis!K19)*tk_opex_vr200)/Thesis!K8 -> 2.0697383 | L26: Maia 的每 MW 營運成本以 VR200 計（電力相同；Assumed）
A27: AI 營運成本：自有 AI MW（平均 × IF_OpexGW） | B27: US$B | D27: =(Thesis!C11+Thesis!D11)/2*Thesis!D26/1000 -> 2.7037833 | E27: =(Thesis!D11+Thesis!E11)/2*Thesis!E26/1000 -> 6.1778304 | F27: =(Thesis!E11+Thesis!F11)/2*Thesis!F26/1000 -> 12.874246 | G27: =(Thesis!F11+Thesis!G11)/2*Thesis!G26/1000 -> 21.818283 | H27: =(Thesis!G11+Thesis!H11)/2*Thesis!H26/1000 -> 31.243013 | I27: =(Thesis!H11+Thesis!I11)/2*Thesis!I26/1000 -> 39.431306 | J27: =(Thesis!I11+Thesis!J11)/2*Thesis!J26/1000 -> 45.036032 | K27: =(Thesis!J11+Thesis!K11)/2*Thesis!K26/1000 -> 48.292973
A28: AI 營運成本：租用 neocloud 租金 | B28: US$B | D28: =(Thesis!C9+Thesis!D9)/2*rent_mw/1000 -> 2.44475 | E28: =(Thesis!D9+Thesis!E9)/2*rent_mw/1000 -> 4.22275 | F28: =(Thesis!E9+Thesis!F9)/2*rent_mw/1000 -> 5.80517 | G28: =(Thesis!F9+Thesis!G9)/2*rent_mw/1000 -> 6.72084 | H28: =(Thesis!G9+Thesis!H9)/2*rent_mw/1000 -> 6.72084 | I28: =(Thesis!H9+Thesis!I9)/2*rent_mw/1000 -> 6.72084 | J28: =(Thesis!I9+Thesis!J9)/2*rent_mw/1000 -> 6.72084 | K28: =(Thesis!J9+Thesis!K9)/2*rent_mw/1000 -> 6.72084
A29: AI 營運成本：租用機房租金（1 − 自建比例） | B29: US$B | D29: =(Thesis!C11+Thesis!D11)/2*(1-self_build)*fac_rent/1000 -> 0.85324238 | E29: =(Thesis!D11+Thesis!E11)/2*(1-self_build)*fac_rent/1000 -> 1.9495596 | F29: =(Thesis!E11+Thesis!F11)/2*(1-self_build)*fac_rent/1000 -> 3.9291489 | G29: =(Thesis!F11+Thesis!G11)/2*(1-self_build)*fac_rent/1000 -> 6.5320691 | H29: =(Thesis!G11+Thesis!H11)/2*(1-self_build)*fac_rent/1000 -> 9.2371799 | I29: =(Thesis!H11+Thesis!I11)/2*(1-self_build)*fac_rent/1000 -> 11.548138 | J29: =(Thesis!I11+Thesis!J11)/2*(1-self_build)*fac_rent/1000 -> 13.089958 | K29: =(Thesis!J11+Thesis!K11)/2*(1-self_build)*fac_rent/1000 -> 13.889728 | L29: C22
A30: 自有 AI 中對外的比重（期間平均） | B30: % | D30: =(Thesis!C10+Thesis!D10)/(Thesis!C11+Thesis!D11) -> 0.6 | E30: =(Thesis!D10+Thesis!E10)/(Thesis!D11+Thesis!E11) -> 0.6 | F30: =(Thesis!E10+Thesis!F10)/(Thesis!E11+Thesis!F11) -> 0.6 | G30: =(Thesis!F10+Thesis!G10)/(Thesis!F11+Thesis!G11) -> 0.6 | H30: =(Thesis!G10+Thesis!H10)/(Thesis!G11+Thesis!H11) -> 0.6 | I30: =(Thesis!H10+Thesis!I10)/(Thesis!H11+Thesis!I11) -> 0.6 | J30: =(Thesis!I10+Thesis!J10)/(Thesis!I11+Thesis!J11) -> 0.6 | K30: =(Thesis!J10+Thesis!K10)/(Thesis!J11+Thesis!K11) -> 0.6
A31: Azure AI EBITDA（營收 − 對外營運成本 − 租金） | B31: US$B | D31: =Thesis!D25-Thesis!D30*(Thesis!D27+Thesis!D29)-Thesis!D28 -> 8.3570141 | E31: =Thesis!E25-Thesis!E30*(Thesis!E27+Thesis!E29)-Thesis!E28 -> 18.710322 | F31: =Thesis!F25-Thesis!F30*(Thesis!F27+Thesis!F29)-Thesis!F28 -> 43.216209 | G31: =Thesis!G25-Thesis!G30*(Thesis!G27+Thesis!G29)-Thesis!G28 -> 79.720447 | H31: =Thesis!H25-Thesis!H30*(Thesis!H27+Thesis!H29)-Thesis!H28 -> 122.80776 | I31: =Thesis!I25-Thesis!I30*(Thesis!I27+Thesis!I29)-Thesis!I28 -> 155.39097 | J31: =Thesis!J25-Thesis!J30*(Thesis!J27+Thesis!J29)-Thesis!J28 -> 178.19767 | K31: =Thesis!K25-Thesis!K30*(Thesis!K27+Thesis!K29)-Thesis!K28 -> 192.72659
A32: 自用 AI 營運成本（服務 Copilot 等自有產品） | B32: US$B | D32: =(1-Thesis!D30)*(Thesis!D27+Thesis!D29) -> 1.4228103 | E32: =(1-Thesis!E30)*(Thesis!E27+Thesis!E29) -> 3.250956 | F32: =(1-Thesis!F30)*(Thesis!F27+Thesis!F29) -> 6.7213581 | G32: =(1-Thesis!G30)*(Thesis!G27+Thesis!G29) -> 11.340141 | H32: =(1-Thesis!H30)*(Thesis!H27+Thesis!H29) -> 16.192077 | I32: =(1-Thesis!I30)*(Thesis!I27+Thesis!I29) -> 20.391777 | J32: =(1-Thesis!J30)*(Thesis!J27+Thesis!J29) -> 23.250396 | K32: =(1-Thesis!K30)*(Thesis!K27+Thesis!K29) -> 24.87308
A33: 新增與汰換 MW 的 IT 資本支出（世代加權） | B33: US$M/MW | C33: =cxit_open -> 27.5919 | D33: =cxit_open -> 27.5919 | E33: =cxit_open -> 27.5919 | F33: =((a_g3_27-nonnv*a_mai)*tk_cxit_gb300+nonnv*a_mai*nv_hold_mai*tk_cxit_vr200+(1-a_g3_27)*tk_cxit_vr200) -> 32.497558 | G33: =((a_g3_28-nonnv*a_mai)*tk_cxit_gb300+nonnv*a_mai*nv_hold_mai*tk_cxit_vr200+(1-a_g3_28)*tk_cxit_vr200) -> 34.637209 | H33: =((a_g3_29-nonnv*a_mai)*tk_cxit_gb300+nonnv*a_mai*nv_hold_mai*tk_cxit_vr200+(1-a_g3_29)*tk_cxit_vr200) -> 35.707034 | I33: =((a_g3_29-nonnv*a_mai)*tk_cxit_gb300+nonnv*a_mai*nv_hold_mai*tk_cxit_vr200+(1-a_g3_29)*tk_cxit_vr200) -> 35.707034 | J33: =((a_g3_29-nonnv*a_mai)*tk_cxit_gb300+nonnv*a_mai*nv_hold_mai*tk_cxit_vr200+(1-a_g3_29)*tk_cxit_vr200) -> 35.707034 | K33: =((a_g3_29-nonnv*a_mai)*tk_cxit_gb300+nonnv*a_mai*nv_hold_mai*tk_cxit_vr200+(1-a_g3_29)*tk_cxit_vr200) -> 35.707034 | L33: FY2026 以前用期初世代加權（估計）
A34: GPU 汰換 MW（自有 AI MW 滿 IT 年限者） | B34: MW | F34: =Thesis!C13*IF(Thesis!F6-Thesis!C6=life_it,1,0)+Thesis!D13*IF(Thesis!F6-Thesis!D6=life_it,1,0)+Thesis!E13*IF(Thesis!F6-Thesis!E6=life_it,1,0) -> 0 | G34: =Thesis!C13*IF(Thesis!G6-Thesis!C6=life_it,1,0)+Thesis!D13*IF(Thesis!G6-Thesis!D6=life_it,1,0)+Thesis!E13*IF(Thesis!G6-Thesis!E6=life_it,1,0)+Thesis!F13*IF(Thesis!G6-Thesis!F6=life_it,1,0) -> 0 | H34: =Thesis!C13*IF(Thesis!H6-Thesis!C6=life_it,1,0)+Thesis!D13*IF(Thesis!H6-Thesis!D6=life_it,1,0)+Thesis!E13*IF(Thesis!H6-Thesis!E6=life_it,1,0)+Thesis!F13*IF(Thesis!H6-Thesis!F6=life_it,1,0)+Thesis!G13*IF(Thesis!H6-Thesis!G6=life_it,1,0) -> 0 | I34: =Thesis!C13*IF(Thesis!I6-Thesis!C6=life_it,1,0)+Thesis!D13*IF(Thesis!I6-Thesis!D6=life_it,1,0)+Thesis!E13*IF(Thesis!I6-Thesis!E6=life_it,1,0)+Thesis!F13*IF(Thesis!I6-Thesis!F6=life_it,1,0)+Thesis!G13*IF(Thesis!I6-Thesis!G6=life_it,1,0)+Thesis!H13*IF(Thesis!I6-Thesis!H6=life_it,1,0) -> 816.66667 | J34: =Thesis!C13*IF(Thesis!J6-Thesis!C6=life_it,1,0)+Thesis!D13*IF(Thesis!J6-Thesis!D6=life_it,1,0)+Thesis!E13*IF(Thesis!J6-Thesis!E6=life_it,1,0)+Thesis!F13*IF(Thesis!J6-Thesis!F6=life_it,1,0)+Thesis!G13*IF(Thesis!J6-Thesis!G6=life_it,1,0)+Thesis!H13*IF(Thesis!J6-Thesis!H6=life_it,1,0)+Thesis!I13*IF(Thesis!J6-Thesis!I6=life_it,1,0) -> 1233.3333 | K34: =Thesis!C13*IF(Thesis!K6-Thesis!C6=life_it,1,0)+Thesis!D13*IF(Thesis!K6-Thesis!D6=life_it,1,0)+Thesis!E13*IF(Thesis!K6-Thesis!E6=life_it,1,0)+Thesis!F13*IF(Thesis!K6-Thesis!F6=life_it,1,0)+Thesis!G13*IF(Thesis!K6-Thesis!G6=life_it,1,0)+Thesis!H13*IF(Thesis!K6-Thesis!H6=life_it,1,0)+Thesis!I13*IF(Thesis!K6-Thesis!I6=life_it,1,0)+Thesis!J13*IF(Thesis!K6-Thesis!J6=life_it,1,0) -> 2450 | L34: 只換 IT、機房不換；FY2024 欄含 FY2024 以前全部（視同 FY2024 投入）；舊機隊在年限到期後停止折舊，汰換後的新 IT 另計折舊（不重複）
A35: AI IT 資本支出（公式） | B35: US$B | C35: =Thesis!C13*Thesis!C33/1000 -> 22.533385 | D35: =Thesis!D13*Thesis!D33/1000 -> 34.030009 | E35: =Thesis!E13*Thesis!E33/1000 -> 67.600154 | F35: =(Thesis!F13+Thesis!F34)*Thesis!F33/1000 -> 136.51872 | G35: =(Thesis!G13+Thesis!G34)*Thesis!G33/1000 -> 157.39928 | H35: =(Thesis!H13+Thesis!H34)*Thesis!H33/1000 -> 162.2608 | I35: =(Thesis!I13+Thesis!I34)*Thesis!I33/1000 -> 144.13657 | J35: =(Thesis!J13+Thesis!J34)*Thesis!J33/1000 -> 114.02904 | K35: =(Thesis!K13+Thesis!K34)*Thesis!K33/1000 -> 113.43709
A36: AI 機房資本支出（自建比例 × IF_CapexFacility） | B36: US$B | C36: =Thesis!C13*self_build*tk_cxfac/1000 -> 6.2083 | D36: =Thesis!D13*self_build*tk_cxfac/1000 -> 9.3758 | E36: =Thesis!E13*self_build*tk_cxfac/1000 -> 18.6249 | F36: =Thesis!F13*self_build*tk_cxfac/1000 -> 31.93518 | G36: =Thesis!G13*self_build*tk_cxfac/1000 -> 34.5452 | H36: =Thesis!H13*self_build*tk_cxfac/1000 -> 34.5452 | I36: =Thesis!I13*self_build*tk_cxfac/1000 -> 24.478264 | J36: =Thesis!J13*self_build*tk_cxfac/1000 -> 14.900894 | K36: =Thesis!K13*self_build*tk_cxfac/1000 -> 5.5257677
A37: C10 對帳落差：FY2027 公司指引推估 − 模型資本支出（AI IT＋AI 機房＋非 AI；正負） | B37: US$B | F37: =capex_floor27-Thesis!F35-Thesis!F36-CF!F25 -> 0.047577445 | L37: v0.3.1：基準情境以 MW 速度重解使此列 ≈ 0（A、C 情境 Azure 其他略有不同，殘差見報告）
A38: FY2027 補足到公司指引的差額（落差為正時補足） | B38: US$B | F38: =MAX(0,Thesis!F37) -> 0.047577445
A39: AI IT 資本支出 | B39: US$B | C39: =Thesis!C35 -> 22.533385 | D39: =Thesis!D35 -> 34.030009 | E39: =Thesis!E35 -> 67.600154 | F39: =Thesis!F35 -> 136.51872 | G39: =Thesis!G35 -> 157.39928 | H39: =Thesis!H35 -> 162.2608 | I39: =Thesis!I35 -> 144.13657 | J39: =Thesis!J35 -> 114.02904 | K39: =Thesis!K35 -> 113.43709
A40: AI 資本支出合計 | B40: US$B | C40: =Thesis!C39+Thesis!C36 -> 28.741685 | D40: =Thesis!D39+Thesis!D36 -> 43.405809 | E40: =Thesis!E39+Thesis!E36 -> 86.225054 | F40: =Thesis!F39+Thesis!F36 -> 168.4539 | G40: =Thesis!G39+Thesis!G36 -> 191.94448 | H40: =Thesis!H39+Thesis!H36 -> 196.806 | I40: =Thesis!I39+Thesis!I36 -> 168.61483 | J40: =Thesis!J39+Thesis!J36 -> 128.92993 | K40: =Thesis!K39+Thesis!K36 -> 118.96285 | L40: FY2026 以前為依 MW 估計的值（非公司揭露）
...

Sheet Seg
A1: Seg — 營收分部層：官方分部 Agents and Infra、Devices and Consumer（8-K 2026-09-02 重編）→ 八條產品線；Azure ＝ Azure AI（命題）＋ Azure 其他；Microsoft 365 cloud ＝ 基礎 ＋ Copilot（命題）
A2: 非命題產品線：FY2026 對 FY2025 年增線性收斂到長期值（FY2032 到達；In 頁 F 節）；三情境相同。FY2025、FY2026 欄為實績（Azure、M365 cloud 的子列為模型拆分）
A4: 情境 A（樂觀）｜營收分部層（Seg）
A5: 項目 | B5: 單位 | C5: FY2024A | D5: FY2025A | E5: FY2026A | F5: FY2027 | G5: FY2028 | H5: FY2029 | I5: FY2030 | J5: FY2031 | K5: FY2032 | L5: 說明
A6: Azure AI（命題子列） | B6: US$B | D6: =Thesis!D25 -> 12.935979 | E6: =Thesis!E25 -> 27.809506 | F6: =Thesis!F25 -> 59.103417 | G6: =Thesis!G25 -> 103.4515 | H6: =Thesis!H25 -> 153.81672 | I6: =Thesis!I25 -> 192.69948 | J6: =Thesis!J25 -> 219.7941 | K6: =Thesis!K25 -> 236.75705
A7: Azure 其他（非 AI 雲端；FY2025–26＝Azure 實績 − Azure AI 估計；FY2027＝Azure（Q1 實績＋Q2–Q4 模型）− Azure AI） | B7: US$B | D7: =Q!L6-Seg!D6 -> 59.674021 | E7: =Q!M6-Seg!E6 -> 74.128494 | F7: =Q!$I$6+(Seg!F6+Seg!E7*(1+Seg!F8))*(1-Q!$E$6/Q!M6)-Seg!F6 -> 90.486602 | G7: =Seg!F7*(1+Seg!G8) -> 107.51159 | H7: =Seg!G7*(1+Seg!H8) -> 124.83299 | I7: =Seg!H7*(1+Seg!I8) -> 141.56993 | J7: =Seg!I7*(1+Seg!J8) -> 156.72319 | K7: =Seg!J7*(1+Seg!K8) -> 169.26105 | L7: v0.3.1：FY2027 Azure＝Q1 實績＋（Azure AI＋Azure 其他的全年模型）×（1 − FY26Q1 占 FY2026 比重）；Q1 實績與模型的差額歸 Azure 其他（不回推 k，C3）
A8: 年增（近一年 → 長期值） | B8: % | E8: =Seg!E7/Seg!D7-1 -> 0.24222388 | F8: =Seg!$E$8+(glt_azo-Seg!$E$8)*MIN(1,(Thesis!F6-base_fy)/n_conv) -> 0.21518657 | G8: =Seg!$E$8+(glt_azo-Seg!$E$8)*MIN(1,(Thesis!G6-base_fy)/n_conv) -> 0.18814926 | H8: =Seg!$E$8+(glt_azo-Seg!$E$8)*MIN(1,(Thesis!H6-base_fy)/n_conv) -> 0.16111194 | I8: =Seg!$E$8+(glt_azo-Seg!$E$8)*MIN(1,(Thesis!I6-base_fy)/n_conv) -> 0.13407463 | J8: =Seg!$E$8+(glt_azo-Seg!$E$8)*MIN(1,(Thesis!J6-base_fy)/n_conv) -> 0.10703731 | K8: =Seg!$E$8+(glt_azo-Seg!$E$8)*MIN(1,(Thesis!K6-base_fy)/n_conv) -> 0.08
A9: Azure | B9: US$B | D9: =Seg!D6+Seg!D7 -> 72.61 | E9: =Seg!E6+Seg!E7 -> 101.938 | F9: =Seg!F6+Seg!F7 -> 149.59002 | G9: =Seg!G6+Seg!G7 -> 210.96309 | H9: =Seg!H6+Seg!H7 -> 278.64971 | I9: =Seg!I6+Seg!I7 -> 334.2694 | J9: =Seg!J6+Seg!J7 -> 376.51729 | K9: =Seg!K6+Seg!K7 -> 406.01809
A10: Copilot 付費座席（年底） | B10: 百萬席 | C10: =cop_s24 -> 1 | D10: =cop_s25 -> 5 | E10: =cop_s26 -> 30 | F10: =Seg!E10+cop_add_A -> 60 | G10: =Seg!F10+cop_add_A -> 90 | H10: =Seg!G10+cop_add_A -> 120 | I10: =Seg!H10+cop_add_A*cop_tail -> 135 | J10: =Seg!I10+cop_add_A*cop_tail -> 150 | K10: =Seg!J10+cop_add_A*cop_tail -> 165 | L10: FY2027–FY2029 每年淨增 cop_add；FY2030 起 × cop_tail
A11: Copilot（命題子列：平均座席 × 月費 × 12） | B11: US$B | D11: =(Seg!C10+Seg!D10)/2*cop_px*12/1000 -> 0.9 | E11: =(Seg!D10+Seg!E10)/2*cop_px*12/1000 -> 5.25 | F11: =(Seg!E10+Seg!F10)/2*cop_px*12/1000 -> 13.5 | G11: =(Seg!F10+Seg!G10)/2*cop_px*12/1000 -> 22.5 | H11: =(Seg!G10+Seg!H10)/2*cop_px*12/1000 -> 31.5 | I11: =(Seg!H10+Seg!I10)/2*cop_px*12/1000 -> 38.25 | J11: =(Seg!I10+Seg!J10)/2*cop_px*12/1000 -> 42.75 | K11: =(Seg!J10+Seg!K10)/2*cop_px*12/1000 -> 47.25 | L11: 實績期用基準月費（拆分是估計）；敏感度只改預測期
A12: M365 基礎（不含 Copilot；FY2025–26＝實績 − Copilot 估計；FY2027＝M365 cloud（Q1 實績＋Q2–Q4 模型）− Copilot） | B12: US$B | D12: =Q!L7-Seg!D11 -> 83.705 | E12: =Q!M7-Seg!E11 -> 95.049 | F12: =Q!$I$7+(Seg!E12*(1+Seg!F13)+Seg!F11)*(1-Q!$E$7/Q!M7)-Seg!F11 -> 106.22965 | G12: =Seg!F12*(1+Seg!G13) -> 118.30609 | H12: =Seg!G12*(1+Seg!H13) -> 130.46344 | I12: =Seg!H12*(1+Seg!I13) -> 142.44535 | J12: =Seg!I12*(1+Seg!J13) -> 153.97212 | K12: =Seg!J12*(1+Seg!K13) -> 164.75017 | L12: Q1 實績與模型的差額歸 M365 基礎
A13: 年增（近一年 → 長期值） | B13: % | E13: =Seg!E12/Seg!D12-1 -> 0.13552356 | F13: =Seg!$E$13+(glt_m365b-Seg!$E$13)*MIN(1,(Thesis!F6-base_fy)/n_conv) -> 0.12460297 | G13: =Seg!$E$13+(glt_m365b-Seg!$E$13)*MIN(1,(Thesis!G6-base_fy)/n_conv) -> 0.11368238 | H13: =Seg!$E$13+(glt_m365b-Seg!$E$13)*MIN(1,(Thesis!H6-base_fy)/n_conv) -> 0.10276178 | I13: =Seg!$E$13+(glt_m365b-Seg!$E$13)*MIN(1,(Thesis!I6-base_fy)/n_conv) -> 0.091841188 | J13: =Seg!$E$13+(glt_m365b-Seg!$E$13)*MIN(1,(Thesis!J6-base_fy)/n_conv) -> 0.080920594 | K13: =Seg!$E$13+(glt_m365b-Seg!$E$13)*MIN(1,(Thesis!K6-base_fy)/n_conv) -> 0.07
A14: Microsoft 365 cloud | B14: US$B | D14: =Seg!D12+Seg!D11 -> 84.605 | E14: =Seg!E12+Seg!E11 -> 100.299 | F14: =Seg!F12+Seg!F11 -> 119.72965 | G14: =Seg!G12+Seg!G11 -> 140.80609 | H14: =Seg!H12+Seg!H11 -> 161.96344 | I14: =Seg!I12+Seg!I11 -> 180.69535 | J14: =Seg!J12+Seg!J11 -> 196.72212 | K14: =Seg!K12+Seg!K11 -> 212.00017
A15: Productivity and server licensing | B15: US$B | D15: =Q!L8 -> 35.391 | E15: =Q!M8 -> 37.285 | F15: =Q!$I$8+(Q!M8-Q!$E$8)*(1+Seg!F16) -> 38.385144 | G15: =Seg!F15*(1+Seg!G16) -> 40.010535 | H15: =Seg!G15*(1+Seg!H16) -> 41.481251 | I15: =Seg!H15*(1+Seg!I16) -> 42.774311 | J15: =Seg!I15*(1+Seg!J16) -> 43.868737 | K15: =Seg!J15*(1+Seg!K16) -> 44.746112 | L15: FY2027＝Q1 實績＋FY2026 第二至第四季 ×（1＋年增）
A16: 年增（近一年 → 長期值） | B16: % | E16: =Seg!E15/Seg!D15-1 -> 0.053516431 | F16: =Seg!$E$16+(glt_lic-Seg!$E$16)*MIN(1,(Thesis!F6-base_fy)/n_conv) -> 0.047930359 | G16: =Seg!$E$16+(glt_lic-Seg!$E$16)*MIN(1,(Thesis!G6-base_fy)/n_conv) -> 0.042344287 | H16: =Seg!$E$16+(glt_lic-Seg!$E$16)*MIN(1,(Thesis!H6-base_fy)/n_conv) -> 0.036758215 | I16: =Seg!$E$16+(glt_lic-Seg!$E$16)*MIN(1,(Thesis!I6-base_fy)/n_conv) -> 0.031172144 | J16: =Seg!$E$16+(glt_lic-Seg!$E$16)*MIN(1,(Thesis!J6-base_fy)/n_conv) -> 0.025586072 | K16: =Seg!$E$16+(glt_lic-Seg!$E$16)*MIN(1,(Thesis!K6-base_fy)/n_conv) -> 0.02
A17: Industry solutions | B17: US$B | D17: =Q!L9 -> 18.417 | E17: =Q!M9 -> 20.345 | F17: =Q!$I$9+(Q!M9-Q!$E$9)*(1+Seg!F18) -> 22.31618 | G17: =Seg!F17*(1+Seg!G18) -> 24.39435 | H17: =Seg!G17*(1+Seg!H18) -> 26.525024 | I17: =Seg!H17*(1+Seg!I18) -> 28.688457 | J17: =Seg!I17*(1+Seg!J18) -> 30.862497 | K17: =Seg!J17*(1+Seg!K18) -> 33.022872 | L17: FY2027＝Q1 實績＋FY2026 第二至第四季 ×（1＋年增）
A18: 年增（近一年 → 長期值） | B18: % | E18: =Seg!E17/Seg!D17-1 -> 0.10468589 | F18: =Seg!$E$18+(glt_ind-Seg!$E$18)*MIN(1,(Thesis!F6-base_fy)/n_conv) -> 0.098904907 | G18: =Seg!$E$18+(glt_ind-Seg!$E$18)*MIN(1,(Thesis!G6-base_fy)/n_conv) -> 0.093123925 | H18: =Seg!$E$18+(glt_ind-Seg!$E$18)*MIN(1,(Thesis!H6-base_fy)/n_conv) -> 0.087342944 | I18: =Seg!$E$18+(glt_ind-Seg!$E$18)*MIN(1,(Thesis!I6-base_fy)/n_conv) -> 0.081561963 | J18: =Seg!$E$18+(glt_ind-Seg!$E$18)*MIN(1,(Thesis!J6-base_fy)/n_conv) -> 0.075780981 | K18: =Seg!$E$18+(glt_ind-Seg!$E$18)*MIN(1,(Thesis!K6-base_fy)/n_conv) -> 0.07
A19: Frontier and support services | B19: US$B | D19: =Q!L10 -> 7.76 | E19: =Q!M10 -> 8.26 | F19: =Q!$I$10+(Q!M10-Q!$E$10)*(1+Seg!F20) -> 8.7537208 | G19: =Seg!F19*(1+Seg!G20) -> 9.3339932 | H19: =Seg!G19*(1+Seg!H20) -> 9.9613916 | I19: =Seg!H19*(1+Seg!I20) -> 10.640204 | J19: =Seg!I19*(1+Seg!J20) -> 11.375146 | K19: =Seg!J19*(1+Seg!K20) -> 12.171406 | L19: FY2027＝Q1 實績＋FY2026 第二至第四季 ×（1＋年增）
A20: 年增（近一年 → 長期值） | B20: % | E20: =Seg!E19/Seg!D19-1 -> 0.06443299 | F20: =Seg!$E$20+(glt_fro-Seg!$E$20)*MIN(1,(Thesis!F6-base_fy)/n_conv) -> 0.065360825 | G20: =Seg!$E$20+(glt_fro-Seg!$E$20)*MIN(1,(Thesis!G6-base_fy)/n_conv) -> 0.06628866 | H20: =Seg!$E$20+(glt_fro-Seg!$E$20)*MIN(1,(Thesis!H6-base_fy)/n_conv) -> 0.067216495 | I20: =Seg!$E$20+(glt_fro-Seg!$E$20)*MIN(1,(Thesis!I6-base_fy)/n_conv) -> 0.06814433 | J20: =Seg!$E$20+(glt_fro-Seg!$E$20)*MIN(1,(Thesis!J6-base_fy)/n_conv) -> 0.069072165 | K20: =Seg!$E$20+(glt_fro-Seg!$E$20)*MIN(1,(Thesis!K6-base_fy)/n_conv) -> 0.07
A21: Agents and Infra | B21: US$B | D21: =Seg!D9+Seg!D14+Seg!D15+Seg!D17+Seg!D19 -> 218.783 | E21: =Seg!E9+Seg!E14+Seg!E15+Seg!E17+Seg!E19 -> 268.127 | F21: =Seg!F9+Seg!F14+Seg!F15+Seg!F17+Seg!F19 -> 338.77472 | G21: =Seg!G9+Seg!G14+Seg!G15+Seg!G17+Seg!G19 -> 425.50806 | H21: =Seg!H9+Seg!H14+Seg!H15+Seg!H17+Seg!H19 -> 518.58081 | I21: =Seg!I9+Seg!I14+Seg!I15+Seg!I17+Seg!I19 -> 597.06773 | J21: =Seg!J9+Seg!J14+Seg!J15+Seg!J17+Seg!J19 -> 659.34579 | K21: =Seg!K9+Seg!K14+Seg!K15+Seg!K17+Seg!K19 -> 707.95865
A22: Search and advertising | B22: US$B | D22: =Q!L13 -> 22.171 | E22: =Q!M13 -> 24.835 | F22: =Q!$I$13+(Q!M13-Q!$E$13)*(1+Seg!F23) -> 27.55919 | G22: =Seg!F22*(1+Seg!G23) -> 30.409856 | H22: =Seg!G22*(1+Seg!H23) -> 33.301179 | I22: =Seg!H22*(1+Seg!I23) -> 36.189024 | J22: =Seg!I22*(1+Seg!J23) -> 39.024777 | K22: =Seg!J22*(1+Seg!K23) -> 41.756512 | L22: FY2027＝Q1 實績＋FY2026 第二至第四季 ×（1＋年增）
A23: 年增（近一年 → 長期值） | B23: % | E23: =Seg!E22/Seg!D22-1 -> 0.12015696 | F23: =Seg!$E$23+(glt_srch-Seg!$E$23)*MIN(1,(Thesis!F6-base_fy)/n_conv) -> 0.11179747 | G23: =Seg!$E$23+(glt_srch-Seg!$E$23)*MIN(1,(Thesis!G6-base_fy)/n_conv) -> 0.10343797 | H23: =Seg!$E$23+(glt_srch-Seg!$E$23)*MIN(1,(Thesis!H6-base_fy)/n_conv) -> 0.095078481 | I23: =Seg!$E$23+(glt_srch-Seg!$E$23)*MIN(1,(Thesis!I6-base_fy)/n_conv) -> 0.086718987 | J23: =Seg!$E$23+(glt_srch-Seg!$E$23)*MIN(1,(Thesis!J6-base_fy)/n_conv) -> 0.078359494 | K23: =Seg!$E$23+(glt_srch-Seg!$E$23)*MIN(1,(Thesis!K6-base_fy)/n_conv) -> 0.07
A24: XBOX | B24: US$B | D24: =Q!L14 -> 23.455 | E24: =Q!M14 -> 21.79 | F24: =Q!$I$14+(Q!M14-Q!$E$14)*(1+Seg!F25) -> 20.752098 | G24: =Seg!F24*(1+Seg!G25) -> 19.908359 | H24: =Seg!G24*(1+Seg!H25) -> 19.400826 | I24: =Seg!H24*(1+Seg!I25) -> 19.200435 | J24: =Seg!I24*(1+Seg!J25) -> 19.293278 | K24: =Seg!J24*(1+Seg!K25) -> 19.679144 | L24: FY2027＝Q1 實績＋FY2026 第二至第四季 ×（1＋年增）
A25: 年增（近一年 → 長期值） | B25: % | E25: =Seg!E24/Seg!D24-1 -> -0.070986996 | F25: =Seg!$E$25+(glt_xbox-Seg!$E$25)*MIN(1,(Thesis!F6-base_fy)/n_conv) -> -0.055822497 | G25: =Seg!$E$25+(glt_xbox-Seg!$E$25)*MIN(1,(Thesis!G6-base_fy)/n_conv) -> -0.040657998 | H25: =Seg!$E$25+(glt_xbox-Seg!$E$25)*MIN(1,(Thesis!H6-base_fy)/n_conv) -> -0.025493498 | I25: =Seg!$E$25+(glt_xbox-Seg!$E$25)*MIN(1,(Thesis!I6-base_fy)/n_conv) -> -0.010328999 | J25: =Seg!$E$25+(glt_xbox-Seg!$E$25)*MIN(1,(Thesis!J6-base_fy)/n_conv) -> 0.0048355006 | K25: =Seg!$E$25+(glt_xbox-Seg!$E$25)*MIN(1,(Thesis!K6-base_fy)/n_conv) -> 0.02
A26: Windows OEM and devices | B26: US$B | D26: =Q!L15 -> 17.315 | E26: =Q!M15 -> 17.087 | F26: =Q!$I$15+(Q!M15-Q!$E$15)*(1+Seg!F27) -> 15.991227 | G26: =Seg!F26*(1+Seg!G27) -> 15.957456 | H26: =Seg!G26*(1+Seg!H27) -> 16.011969 | I26: =Seg!H26*(1+Seg!I27) -> 16.155181 | J26: =Seg!I26*(1+Seg!J27) -> 16.388979 | K26: =Seg!J26*(1+Seg!K27) -> 16.716759 | L26: FY2027＝Q1 實績＋FY2026 第二至第四季 ×（1＋年增）
A27: 年增（近一年 → 長期值） | B27: % | E27: =Seg!E26/Seg!D26-1 -> -0.013167774 | F27: =Seg!$E$27+(glt_win-Seg!$E$27)*MIN(1,(Thesis!F6-base_fy)/n_conv) -> -0.0076398113 | G27: =Seg!$E$27+(glt_win-Seg!$E$27)*MIN(1,(Thesis!G6-base_fy)/n_conv) -> -0.0021118491 | H27: =Seg!$E$27+(glt_win-Seg!$E$27)*MIN(1,(Thesis!H6-base_fy)/n_conv) -> 0.0034161132 | I27: =Seg!$E$27+(glt_win-Seg!$E$27)*MIN(1,(Thesis!I6-base_fy)/n_conv) -> 0.0089440755 | J27: =Seg!$E$27+(glt_win-Seg!$E$27)*MIN(1,(Thesis!J6-base_fy)/n_conv) -> 0.014472038 | K27: =Seg!$E$27+(glt_win-Seg!$E$27)*MIN(1,(Thesis!K6-base_fy)/n_conv) -> 0.02
A28: Devices and Consumer | B28: US$B | D28: =Seg!D22+Seg!D24+Seg!D26 -> 62.941 | E28: =Seg!E22+Seg!E24+Seg!E26 -> 63.712 | F28: =Seg!F22+Seg!F24+Seg!F26 -> 64.302515 | G28: =Seg!G22+Seg!G24+Seg!G26 -> 66.275672 | H28: =Seg!H22+Seg!H24+Seg!H26 -> 68.713974 | I28: =Seg!I22+Seg!I24+Seg!I26 -> 71.544639 | J28: =Seg!J22+Seg!J24+Seg!J26 -> 74.707035 | K28: =Seg!K22+Seg!K24+Seg!K26 -> 78.152415
A29: 合併營收（分部合計） | B29: US$B | D29: =Seg!D21+Seg!D28 -> 281.724 | E29: =Seg!E21+Seg!E28 -> 331.839 | F29: =Seg!F21+Seg!F28 -> 403.07723 | G29: =Seg!G21+Seg!G28 -> 491.78373 | H29: =Seg!H21+Seg!H28 -> 587.29479 | I29: =Seg!I21+Seg!I28 -> 668.61237 | J29: =Seg!J21+Seg!J28 -> 734.05283 | K29: =Seg!K21+Seg!K28 -> 786.11106
A30: 檢查：產品線合計 − 分部；實績期另比對公司分部值 | B30: US$B | D30: =(Seg!D9+Seg!D14+Seg!D15+Seg!D17+Seg!D19-Seg!D21)+(Seg!D22+Seg!D24+Seg!D26-Seg!D28)+(Seg!D21-Q!L5)+(Seg!D28-Q!L12)+(Seg!D9-Q!L6)+(Seg!D14-Q!L7) -> 0 | E30: =(Seg!E9+Seg!E14+Seg!E15+Seg!E17+Seg!E19-Seg!E21)+(Seg!E22+Seg!E24+Seg!E26-Seg!E28)+(Seg!E21-Q!M5)+(Seg!E28-Q!M12)+(Seg!E9-Q!M6)+(Seg!E14-Q!M7) -> 0 | F30: =(Seg!F9+Seg!F14+Seg!F15+Seg!F17+Seg!F19-Seg!F21)+(Seg!F22+Seg!F24+Seg!F26-Seg!F28) -> 0 | G30: =(Seg!G9+Seg!G14+Seg!G15+Seg!G17+Seg!G19-Seg!G21)+(Seg!G22+Seg!G24+Seg!G26-Seg!G28) -> 0 | H30: =(Seg!H9+Seg!H14+Seg!H15+Seg!H17+Seg!H19-Seg!H21)+(Seg!H22+Seg!H24+Seg!H26-Seg!H28) -> 0 | I30: =(Seg!I9+Seg!I14+Seg!I15+Seg!I17+Seg!I19-Seg!I21)+(Seg!I22+Seg!I24+Seg!I26-Seg!I28) -> 0 | J30: =(Seg!J9+Seg!J14+Seg!J15+Seg!J17+Seg!J19-Seg!J21)+(Seg!J22+Seg!J24+Seg!J26-Seg!J28) -> 0 | K30: =(Seg!K9+Seg!K14+Seg!K15+Seg!K17+Seg!K19-Seg!K21)+(Seg!K22+Seg!K24+Seg!K26-Seg!K28) -> 0
A31: 情境 B（基準）｜營收分部層（Seg）
A32: 項目 | B32: 單位 | C32: FY2024A | D32: FY2025A | E32: FY2026A | F32: FY2027 | G32: FY2028 | H32: FY2029 | I32: FY2030 | J32: FY2031 | K32: FY2032 | L32: 說明
A33: Azure AI（命題子列） | B33: US$B | D33: =Thesis!D77 -> 12.935979 | E33: =Thesis!E77 -> 27.809506 | F33: =Thesis!F77 -> 55.411832 | G33: =Thesis!G77 -> 91.28811 | H33: =Thesis!H77 -> 128.19527 | I33: =Thesis!I77 -> 160.60128 | J33: =Thesis!J77 -> 183.18272 | K33: =Thesis!K77 -> 197.32012
A34: Azure 其他（非 AI 雲端；FY2025–26＝Azure 實績 − Azure AI 估計；FY2027＝Azure（Q1 實績＋Q2–Q4 模型）− Azure AI） | B34: US$B | D34: =Q!L6-Seg!D33 -> 59.674021 | E34: =Q!M6-Seg!E33 -> 74.128494 | F34: =Q!$I$6+(Seg!F33+Seg!E34*(1+Seg!F35))*(1-Q!$E$6/Q!M6)-Seg!F33 -> 91.297216 | G34: =Seg!F34*(1+Seg!G35) -> 108.47472 | H34: =Seg!G34*(1+Seg!H35) -> 125.95129 | I34: =Seg!H34*(1+Seg!I35) -> 142.83817 | J34: =Seg!I34*(1+Seg!J35) -> 158.12718 | K34: =Seg!J34*(1+Seg!K35) -> 170.77735 | L34: v0.3.1：FY2027 Azure＝Q1 實績＋（Azure AI＋Azure 其他的全年模型）×（1 − FY26Q1 占 FY2026 比重）；Q1 實績與模型的差額歸 Azure 其他（不回推 k，C3）
A35: 年增（近一年 → 長期值） | B35: % | E35: =Seg!E34/Seg!D34-1 -> 0.24222388 | F35: =Seg!$E$35+(glt_azo-Seg!$E$35)*MIN(1,(Thesis!F58-base_fy)/n_conv) -> 0.21518657 | G35: =Seg!$E$35+(glt_azo-Seg!$E$35)*MIN(1,(Thesis!G58-base_fy)/n_conv) -> 0.18814926 | H35: =Seg!$E$35+(glt_azo-Seg!$E$35)*MIN(1,(Thesis!H58-base_fy)/n_conv) -> 0.16111194 | I35: =Seg!$E$35+(glt_azo-Seg!$E$35)*MIN(1,(Thesis!I58-base_fy)/n_conv) -> 0.13407463 | J35: =Seg!$E$35+(glt_azo-Seg!$E$35)*MIN(1,(Thesis!J58-base_fy)/n_conv) -> 0.10703731 | K35: =Seg!$E$35+(glt_azo-Seg!$E$35)*MIN(1,(Thesis!K58-base_fy)/n_conv) -> 0.08
A36: Azure | B36: US$B | D36: =Seg!D33+Seg!D34 -> 72.61 | E36: =Seg!E33+Seg!E34 -> 101.938 | F36: =Seg!F33+Seg!F34 -> 146.70905 | G36: =Seg!G33+Seg!G34 -> 199.76283 | H36: =Seg!H33+Seg!H34 -> 254.14657 | I36: =Seg!I33+Seg!I34 -> 303.43945 | J36: =Seg!J33+Seg!J34 -> 341.3099 | K36: =Seg!K33+Seg!K34 -> 368.09748
A37: Copilot 付費座席（年底） | B37: 百萬席 | C37: =cop_s24 -> 1 | D37: =cop_s25 -> 5 | E37: =cop_s26 -> 30 | F37: =Seg!E37+cop_add_B -> 50 | G37: =Seg!F37+cop_add_B -> 70 | H37: =Seg!G37+cop_add_B -> 90 | I37: =Seg!H37+cop_add_B*cop_tail -> 100 | J37: =Seg!I37+cop_add_B*cop_tail -> 110 | K37: =Seg!J37+cop_add_B*cop_tail -> 120 | L37: FY2027–FY2029 每年淨增 cop_add；FY2030 起 × cop_tail
