Workbook

Sheet README
A1: 廣達電腦（2382）收支與估值模型 v0.2.1（AI 半導體 Project：伺服器組裝次產業樣板） 2026-10-25
A2: 版本：v0.2.1（2026-10-25：補上檔空間級距、投資建議、重點觀察；PL 頁最後新增三情境自由現金流列（淨利＋折舊 − 資本支出，不含營運資金變動）、In 頁最後新增折舊 ÷ 營收、資本支出 ÷ 營收（數值不變））。v0.2（2026-10-25：目標價改為 DCF 與 Comparable 加權、三情境延伸到 FY2032；FY2025–FY2029 數值不變）。前版：v0.1.1（2026-10-25：Val 新增第 0 節「目標價與上檔空間」、In 新增情境權重 tp_wA／tp_wB／tp_wC；其餘數值與 v0.1 相同）。v0.1（初版）：AI 伺服器組裝市場、廣達有效份額、ODM 每櫃價格與客供比例在本模型 Units 頁建立，為本專案權威資料（規則第 13 條）；鴻海、緯創之後讀這條組裝線。
A3: 模型命題：廣達的 AI 伺服器營收＝部署 GW（AI IT 資本支出 ÷ 每 GW IT 資本支出）× 每 GW ODM 整櫃價值 × 廣達有效份額 ×（1 − 客供比例）。組裝營收含轉手的 GPU，營收大、毛利率約 5%；客供比例上升時營收成長放慢、毛利率回升，毛利金額大致不變。市場約 10 倍未來 12 月 EPS。
A4: 核心問題：客供比例上升與 VR 每櫃價格上升之下，每櫃毛利金額能不能撐住 EPS 成長；約 10 倍未來 12 月 P/E 隱含什麼路徑。
A6: 會計年度＝日曆年，FY(t)＝CY(t)，不平移。預測期 FY2027–FY2029（三年）。金額：十億新台幣；整櫃價格與市場以美元計、以匯率換算。口徑：歸屬母公司淨利。
A8: 驅動因子 → 推導量（全部唯讀上游，不修改）
A9: AI 伺服器營收：markets/network 的 AI IT 資本支出 × 情境顆數係數 ÷ 每 GW IT 資本支出（Tokenomics，經橋接表）＝部署 GW；× 每 GW 架數（Tokenomics）× ODM 每櫃價格（法人）＝組裝市場；× 廣達有效份額（FY2026 以公司伺服器與 AI 占比校準）× 份額相對值（Assumed）×（1 − 客供比例，Assumed）。
A10: 非 AI：FY2026 殘差 × 成長率（Assumed）。毛利率：AI 伺服器（毛額基礎）比其他營收低 d_ai（Assumed），FY2027 起再加 VR 稀釋 vrd（Assumed），其他毛利率為 FY2026 殘差（Derived）；客供部分不計營收、保留 keep 比例的毛利。營業費用：彈性 phi（Derived）。淨利：營業利益 × 淨利係數（業外與稅前未找到）。
A11: 校準：FY2026 ＝ 1H26 實績＋3Q26 營收實績＋假設（4Q 季增、毛利率、營業費用率）。不用券商數字（只在 Recon 對帳）。
A12: 估值：Val 第 0 節目標價＝0.5 × DCF 目標價（股東現金流＝EPS ×（1 − tp_g ÷ tp_roe），FY2027–FY2032 明確期＋永續，r 10%、g 4%，三情境權重 0.3／0.5／0.2，推到 12 個月後）＋0.5 × Comparable 目標價（緯創、緯穎、鴻海、英業達、Super Micro 前瞻 P/E 中位數 × 12 個月後前瞻 EPS）；另列 Comparable 單獨目標價、市場共識目標價與差距拆解（EPS 因素、倍數因素）、DCF 價格帶、十年 P/E 分位檢查（只作檢查）。（v0.1.1 原估值說明，保留作參考：現價 ÷ FY2027、FY2028 EPS；十年 P/E 規則值（兩個資料商來源）× FY2027 EPS；循環位置以本模型營收最高年判定（不套設備股見頂年）。）
A13: 標記：Verified、Interested-party、Analogy、Assumed、Derived。SemiAnalysis 未使用。公司原文只經法說摘要與新聞；券商多未具名或單一來源。
A15: 已知限制：(1) 客供比例與保留毛利比例是 Assumed，公司只說「比重仍低」；(2) 份額只有一個量化來源（單月櫃數調查），且有效份額的分母含 ASIC、HGX 與其他廠，與櫃數份額不同口徑；(3) 2028 年起每 GW ODM 價值（Rubin Ultra）是 Assumed；(4) 部署 GW 以 VR200 每 GW IT 資本支出換算，ASIC 機架每 GW 資本支出較低，GW 可能低估；(5) 業外與稅前利益未找到，以淨利 ÷ 營業利益涵蓋；(6) 十年 P/E 兩來源在 2016–2021 年差距大，且 AI 前為低倍數；(7) 3Q26 法說（11 月中）後更新錨點；R4 產業部署路徑未建。
... A18: 先驗：v0.1 的 Andy 合理 P/E 對照保留不動，不進目標價；本版未新增先驗。
A19: ="投資建議："&Val!B136&"（依上檔空間固定規則）" -> 投資建議：強力買進（依上檔空間固定規則）
A20: 重點觀察 1：目標價 NT$566.6（DCF 644.3、Comparable 488.9 各半），比現價 322（2026-10-22）高 76.0%，級距大於 50%；Comparable 單獨為 51.8%。主因是 EPS 不是倍數：本模型 12 個月後前瞻 EPS 43.00 比共識前瞻 EPS 28.56 高 50.6%（兩者期間差約一年；FY2027 EPS 43.61 也比法人 10-08 的 32.09 高 35.9%），同業（緯創、緯穎、鴻海、英業達、Super Micro）前瞻 P/E 中位數 11.4 倍與現價隱含 11.3 倍幾乎相同；DCF（ROE 27.2%、再投資率 14.7%）比 Comparable 高 31.8%，再把目標價往上拉。
A21: 重點觀察 2：EPS 高於法人來自營收與淨利係數：FY2027 營收 5.71 兆元比法人 5.30 兆元高 7.7%，淨利 ÷ 營業利益約 0.87；改用券商隱含的 0.75 時 FY2027 EPS 降 13.3% 到 37.81，是 FY2027 最敏感的變數。3Q26 法說（11 月中）的業外與稅率是第一個檢驗點。
A22: 重點觀察 3：情境分歧從 FY2028 起：FY2028 EPS A／B／C＝51.92／41.96／31.56（B、C 比 A 低 19.2%、39.2%）；份額相對值 0.75（鴻海、緯創搶單）時 FY2028 EPS −18.2%。追蹤三家 ODM 的 Vera Rubin 櫃數份額（本模型 FY2026 有效份額 13.4%）與 2027 年客供比例。

Sheet In
A1: In — 輸入（藍字；基準欄 E，低 D、高 F）。金額：十億新台幣（NT$B），整櫃價格與市場為美元；比例：%。每個輸入附兩個來源（找不到者寫「未找到」）；公司原文算一個
A2: 標記：Verified／Interested-party／Analogy／Assumed／Derived；Analogy、Assumed 給低／高區間。SemiAnalysis 未使用。公司原文＝廣達法說（經富果、優分析、Taipei Times 摘要）、月營收公告；公司的 AI 占比與展望為 Interested-party；券商估計皆為 Interested-party
A3: 鍵 | B3: 項目 | C3: 單位 | D3: 低 | E3: 基準 | F3: 高 | G3: 標記 | H3: 來源1 | I3: 來源2／說明
A4: A. AI 部署規模（讀 markets/network、markets/chip_bridge、tsmc 成品；情境 A 基準，B／C 依顆數係數縮放）
A5: itc_26 | B5: AI IT 資本支出 2026 | C5: US$B | E5: 781.87292 | G5: Derived | H5: markets/network/dist/20261026_AI網通市場模型_v0.2.3.xlsx｜Mkt!C27:F27 | I5: 加速器顆數 × 每顆 IT capex（含 ASIC）；本模型以此除以每 GW IT 資本支出得到部署 GW（與台達電模型同口徑）
A6: itc_27 | B6: AI IT 資本支出 2027 | C6: US$B | E6: 1565.35 | G6: Derived | H6: markets/network/dist/20261026_AI網通市場模型_v0.2.3.xlsx｜Mkt!C27:F27 | I6: 同上
A7: itc_28 | B7: AI IT 資本支出 2028 | C7: US$B | E7: 1984.2639 | G7: Derived | H7: markets/network/dist/20261026_AI網通市場模型_v0.2.3.xlsx｜Mkt!C27:F27 | I7: 同上
A8: itc_29 | B8: AI IT 資本支出 2029 | C8: US$B | E8: 2260.3903 | G8: Derived | H8: markets/network/dist/20261026_AI網通市場模型_v0.2.3.xlsx｜Mkt!C27:F27 | I8: 同上
A9: itpg_gb | B9: 每 GW IT 資本支出（GB300） | C9: US$B | E9: 32.237224 | G9: Derived | H9: markets/chip_bridge/dist/20261027_晶片內容橋接表_v0.2.2.xlsx｜In!E10（GB300）、H10（VR200） | I9: Tokenomics v20.1 IF_CapexIT（經橋接表；唯讀）
A10: itpg_vr | B10: 每 GW IT 資本支出（VR200；2027 起） | C10: US$B | E10: 37.586352 | G10: Derived | H10: markets/chip_bridge/dist/20261027_晶片內容橋接表_v0.2.2.xlsx｜In!E10（GB300）、H10（VR200） | I10: 同上；Rubin Ultra 與 ASIC 機架未另訂（Assumed：同 VR200）
A11: vr26 | B11: 2026 年部署中 Rubin 世代占比（混合用） | C11: % | D11: 0.15 | E11: 0.22 | F11: 0.3 | G11: Interested-party | H11: TrendForce 2026 組合 Rubin 22%（經 markets/memory） | I11: 廣達：Vera Rubin 4Q26 小量、1Q27 放量（財報狗 2026-10-08）
A12: racks_gb | B12: 每 GW 機架數（GB300） | C12: 架 | E12: 6764 | G12: Derived | H12: markets/chip_bridge/dist/20261027_晶片內容橋接表_v0.2.2.xlsx｜In!E6（GB300）、H6（VR200） | I12: Tokenomics IF_RacksPerGW（經橋接表）
A13: racks_vr | B13: 每 GW 機架數（VR200） | C13: 架 | E13: 4052 | G13: Derived | H13: markets/chip_bridge/dist/20261027_晶片內容橋接表_v0.2.2.xlsx｜In!E6（GB300）、H6（VR200） | I13: 同上
A14: rack_gb | B14: 整櫃買方價格（GB300，Tokenomics） | C14: US$M/架 | E14: 4.3 | G14: Derived | H14: markets/chip_bridge/dist/20261027_晶片內容橋接表_v0.2.2.xlsx｜In!E5（GB300）、H5（VR200） | I14: Recon 用：ODM 價 ÷ 買方價
A15: rack_vr | B15: 整櫃買方價格（VR200，Tokenomics） | C15: US$M/架 | E15: 8.4 | G15: Derived | H15: markets/chip_bridge/dist/20261027_晶片內容橋接表_v0.2.2.xlsx｜In!E5（GB300）、H5（VR200） | I15: 同上
A16: um28_A | B16: 情境 A：2028 顆數 ÷ 基準 | C16: x | E16: 1 | G16: Assumed | H16: tsmc/dist/20261028_台積電個股模型_v0.4.xlsx｜In!E37 | I16: A＝基準；B＝AI 資本支出消化；C＝明顯下修（與台積電、NVIDIA、Arista、台達電模型相同）
A17: um29_A | B17: 情境 A：2029 顆數 ÷ 基準 | C17: x | E17: 1 | G17: Assumed | H17: tsmc/dist/20261028_台積電個股模型_v0.4.xlsx｜In!E38 | I17: 同上
A18: um28_B | B18: 情境 B：2028 顆數 ÷ 基準 | C18: x | E18: 0.8 | G18: Assumed | H18: tsmc/dist/20261028_台積電個股模型_v0.4.xlsx｜In!E39 | I18: A＝基準；B＝AI 資本支出消化；C＝明顯下修（與台積電、NVIDIA、Arista、台達電模型相同）
A19: um29_B | B19: 情境 B：2029 顆數 ÷ 基準 | C19: x | E19: 0.85 | G19: Assumed | H19: tsmc/dist/20261028_台積電個股模型_v0.4.xlsx｜In!E40 | I19: 同上
A20: um28_C | B20: 情境 C：2028 顆數 ÷ 基準 | C20: x | E20: 0.6 | G20: Assumed | H20: tsmc/dist/20261028_台積電個股模型_v0.4.xlsx｜In!E41 | I20: A＝基準；B＝AI 資本支出消化；C＝明顯下修（與台積電、NVIDIA、Arista、台達電模型相同）
A21: um29_C | B21: 情境 C：2029 顆數 ÷ 基準 | C21: x | E21: 0.6 | G21: Assumed | H21: tsmc/dist/20261028_台積電個股模型_v0.4.xlsx｜In!E42 | I21: 同上
A22: fx | B22: 匯率（新台幣 ÷ 美元） | C22: NT$/US$ | D22: 30.5 | E22: 32 | F22: 33 | G22: Derived | H22: 與台達電模型相同（公司換算隱含約 32.7） | I22: 先驗比對用 32.7（只影響美元換算的市場與每 GW）
A23: B. 組裝價格、廣達份額與客供（本專案為權威：NVIDIA 整櫃組裝份額、每櫃 ODM 價格、客供比例，規則第 13 條）
A24: odm_gb | B24: ODM 每櫃價格 GB300 | C24: US$M/架 | D24: 3.6 | E24: 4 | F24: 4.3 | G24: Interested-party | H24: https://www.ctee.com.tw/news/20261008700747-430201：GB300 ASP 約 US$4M（法人，未具名） | I24: FTNN 2026-10-09 同值；上限＝Tokenomics 買方價 4.3
A25: odm_vr | B25: ODM 每櫃價格 VR200 | C25: US$M/架 | D25: 6.5 | E25: 6.75 | F25: 7 | G25: Interested-party | H25: https://www.ctee.com.tw/news/20261008700747-430201：VR ASP 估 US$6.5–7M（法人） | I25: FTNN 2026-10-09 同值；Tokenomics 買方價 8.4
A26: vpg_28 | B26: 每 GW ODM 整櫃價值 2028 ÷ 2027（Rubin Ultra） | C26: x | D26: 0.85 | E26: 1 | F26: 1.2 | G26: Assumed | H26: Rubin Ultra（Kyber）每櫃價格與每 GW 架數：未找到 | I26: 每 GW 價值 GB300 約 27.1B → VR200 約 27.4B（4.0 × 6,764 vs 6.75 × 4,052）：換世代時每 GW 大致持平
A27: vpg_29 | B27: 每 GW ODM 整櫃價值 2029 ÷ 2027 | C27: x | D27: 0.85 | E27: 1 | F27: 1.2 | G27: Assumed | H27: 同上 | I27: —
A28: rel_27 | B28: 廣達 AI 伺服器有效份額 2027 ÷ 2026（相對值） | C28: x | D28: 0.85 | E28: 1 | F28: 1.1 | G28: Assumed | H28: https://money.udn.com/money/amp/story/5607/9745501：美系券商 8 月調查 鴻海約 2,600 櫃、廣達 2,500–2,550、緯創 2,300–2,400（Interested-party，單一來源） | I28: 公司：前五大 CSP 為主，Neocloud GPU 與 CSP ASIC 專案小量出貨（2Q26 法說）；Neocloud 繞過 OEM 找 ODM（FTNN 2026-10-09）
A29: rel_28 | B29: 廣達份額 2028 ÷ 2026 | C29: x | D29: 0.75 | E29: 0.95 | F29: 1.1 | G29: Assumed | H29: 同上；台灣組裝產能 2028 再翻倍（公司） | I29: —
A30: rel_29 | B30: 廣達份額 2029 ÷ 2026 | C30: x | D30: 0.7 | E30: 0.9 | F30: 1.1 | G30: Assumed | H30: 同上 | I30: —
A31: cs_27 | B31: 客供比例 2027（AI 毛額價值中改為客戶供料、不計營收的比例） | C31: % | D31: 0 | E31: 0.1 | F31: 0.25 | G31: Assumed | H31: https://blog.fugle.tw/post/earnings-call-2382-2026-08-13：3Q26 起部分高價關鍵料件改客供，GPU 與 ASIC 客戶都有；比重仍低（公司） | I31: https://www.kgi.com.hk/zh-cn/-/media/files/kgishk/research-reports/tw-reports/quanta-computer-2382-tt-20260813en.pdf：2H26 客供比重小，營益率持平 1H26
A32: cs_28 | B32: 客供比例 2028 | C32: % | D32: 0 | E32: 0.2 | F32: 0.4 | G32: Assumed | H32: 同上；公司與客戶協商轉換以提高利潤率（Taipei Times 2026-05-15） | I32: —
A33: cs_29 | B33: 客供比例 2029 | C33: % | D33: 0 | E33: 0.25 | F33: 0.5 | G33: Assumed | H33: 同上 | I33: —
A34: keep | B34: 客供部分保留的毛利比例（相對買賣模式） | C34: x | D34: 0.7 | E34: 0.9 | F34: 1 | G34: Assumed | H34: 公司：客供可減輕毛利率稀釋與營運資金壓力（2Q26 法說） | I34: 買賣模式下轉手 GPU 的加價很薄；客供後少掉這部分加價：未找到量化
A35: C. 營收結構錨點（公司揭露比例 × 營收）
A36: srv_26 | B36: 2026 年伺服器營收 ÷ 營收 | C36: % | D36: 0.82 | E36: 0.85 | F36: 0.88 | G36: Interested-party | H36: https://blog.fugle.tw/post/earnings-call-2382-2026-08-13：伺服器自 1Q26 起超過 80%（公司） | I36: https://www.kgi.com.hk/zh-cn/-/media/files/kgishk/research-reports/tw-reports/quanta-computer-2382-tt-20260813en.pdf：雲端伺服器 2026F 85%、2027F 88%
A37: ais_26 | B37: 2026 年 AI 伺服器 ÷ 伺服器營收 | C37: % | D37: 0.75 | E37: 0.8 | F37: 0.82 | G37: Interested-party | H37: https://uanalyze.com.tw/articles/5252953366：1H26 75–80%，全年約 80%（公司） | I37: https://www.kgi.com.hk/zh-cn/-/media/files/kgishk/research-reports/tw-reports/quanta-computer-2382-tt-20260813en.pdf：同
A38: g_nai26 | B38: 2026 年非 AI 營收年增（反推 FY2025 AI 營收） | C38: % | D38: -0.05 | E38: 0.05 | F38: 0.15 | G38: Assumed | H38: 公司：筆電雙位數衰退、一般伺服器雙位數成長（2Q26 法說、財報狗 10-08） | I38: https://statementdog.com/news/17848：公司維持 AI 伺服器「三位數年增」；若只倍增，非 AI 須 +67%，與筆電衰退不符，所以倍增讀為下限
A39: g_nai27 | B39: 非 AI 營收年增 2027 | C39: % | D39: -0.05 | E39: 0.03 | F39: 0.08 | G39: Assumed | H39: 筆電 2026 年雙位數衰退、低於 20%（公司，財報狗 10-08）；一般伺服器雙位數成長（公司） | I39: 筆電約占 2026 營收 11–13%
A40: srv_25 | B40: 2025 年雲端伺服器營收 ÷ 營收 | C40: % | D40: 0.68 | E40: 0.71 | F40: 0.73 | G40: Interested-party | H40: 凱基 2026-08-13 廣達報告：2025 雲端伺服器 71%、筆電 22%、EV 3%、穿戴物聯網等 3%（公司簡介：伺服器約 70%、筆電 20–25%） | I40: 分部原則 v0.3：營收列改為雲端伺服器（AI＋一般）／筆電／其他
...

Sheet Q
A1: Q — 實績與 FY2026 錨點（十億新台幣；EPS 為新台幣；股數為十億股）。藍字＝輸入；黑字＝公式。實績取自廣達法說摘要、財報新聞與月營收
A2: FY2026 錨點＝1H26 實績＋3Q26 營收實績（月營收）＋3Q、4Q 假設（毛利率、營業費用率、淨利 ÷ 營業利益；4Q 營收＝3Q × (1＋季增)）。FY2025 與 1H26 毛利由公司揭露的毛利率 × 營收推得；FY2025 營業利益同。業外與稅前：未找到
A3: 項目 | B3: FY2025A | C3: 1H26（實績） | D3: 3Q26（營收實績） | E3: 4Q26（模型） | F3: FY2026 錨點 | G3: 標記 | H3: 來源1（公司） | I3: 來源2／說明
A4: 營收 | B4: 2123.689 | C4: 1845.8 | D4: =q3_rev -> 1115.5 | E4: =D4*(1+q4g) -> 1037.415 | F4: =SUM(C4:E4) -> 3998.715 | G4: Verified／Interested-party（4Q 季增） | H4: FY2025：https://uanalyze.com.tw/articles/3341848159；1H26：https://blog.fugle.tw/post/earnings-call-2382-2026-08-13 | I4: FY2025 2,123.689（凱基）；1H26 1.8458 兆（公司）
A5: 毛利 | B5: =B4*0.0698 -> 148.23349 | C5: =C4*0.0492 -> 90.81336 | D5: =D4*q_gm -> 55.775 | E5: =E4*q_gm -> 51.87075 | F5: =SUM(C5:E5) -> 198.45911 | G5: Derived（毛利率 × 營收）／Interested-party | H5: FY2025：https://uanalyze.com.tw/articles/3341848159；1H26：https://blog.fugle.tw/post/earnings-call-2382-2026-08-13 | I5: FY2025 毛利率 6.98%；1H26 4.92%（公司）
A6: 毛利率 | B6: =B5/B4 -> 0.0698 | C6: =C5/C4 -> 0.0492 | D6: =D5/D4 -> 0.05 | E6: =E5/E4 -> 0.05 | F6: =F5/F4 -> 0.049630721 | G6: Derived | H6: — | I6: —
A7: 營業費用 | B7: =B5-B8 -> 60.737505 | C7: =C5-C8 -> 33.51336 | D7: =D4*q_opx -> 19.52125 | E7: =E4*q_opx -> 18.154763 | F7: =SUM(C7:E7) -> 71.189373 | G7: Derived（毛利 − 營業利益）／Assumed | H7: FY2025：https://uanalyze.com.tw/articles/3341848159；1H26：https://blog.fugle.tw/post/earnings-call-2382-2026-08-13 | I7: 3Q26 營收：月營收公告（財報狗 2026-10-08）
A8: 營業利益 | B8: =B4*0.0412 -> 87.495987 | C8: 57.3 | D8: =D5-D7 -> 36.25375 | E8: =E5-E7 -> 33.715987 | F8: =SUM(C8:E8) -> 127.26974 | G8: Derived／Verified | H8: FY2025：https://uanalyze.com.tw/articles/3341848159；1H26：https://blog.fugle.tw/post/earnings-call-2382-2026-08-13 | I8: FY2025 營益率 4.12%；1H26 573 億、營益率 3.1%（公司）
A9: 營業利益率 | B9: =B8/B4 -> 0.0412 | C9: =C8/C4 -> 0.03104345 | D9: =D8/D4 -> 0.0325 | E9: =E8/E4 -> 0.0325 | F9: =F8/F4 -> 0.031827659 | G9: Derived | H9: — | I9: —
A10: 歸屬母公司淨利 | B10: 74.98 | C10: 49.84 | D10: =D8*q_nio -> 31.540762 | E10: =E8*q_nio -> 29.332909 | F10: =SUM(C10:E10) -> 110.71367 | G10: Verified／Derived（3Q、4Q） | H10: FY2025：https://uanalyze.com.tw/articles/3341848159；1H26：https://blog.fugle.tw/post/earnings-call-2382-2026-08-13 | I10: 2Q26 28.65、2Q26 EPS 7.43
A11: 淨利 ÷ 營業利益（含業外、稅、非控制權益） | B11: =B10/B8 -> 0.85695359 | C11: =C10/C8 -> 0.86980803 | D11: =D10/D8 -> 0.87 | E11: =E10/E8 -> 0.87 | F11: =F10/F8 -> 0.86991357 | G11: Derived | H11: — | I11: —
A12: 股數（十億股） | B12: =74.98/19.45 -> 3.8550129 | C12: =q_sh -> 3.8546017 | D12: =q_sh -> 3.8546017 | E12: =q_sh -> 3.8546017 | F12: =q_sh -> 3.8546017 | G12: Derived | H12: FY2025：https://uanalyze.com.tw/articles/3341848159；1H26：https://blog.fugle.tw/post/earnings-call-2382-2026-08-13 | I12: 淨利 ÷ EPS
A13: EPS | B13: =B10/B12 -> 19.45 | C13: =C10/C12 -> 12.93 | D13: =D10/D12 -> 8.1826256 | E13: =E10/E12 -> 7.6098418 | F13: =F10/F12 -> 28.722467 | G13: Derived | H13: 淨利 ÷ 股數 | I13: —
A14: 公司揭露 EPS | B14: 19.45 | C14: 12.93 | G14: Verified | H14: FY2025：https://uanalyze.com.tw/articles/3341848159；1H26：https://blog.fugle.tw/post/earnings-call-2382-2026-08-13 | I14: 2Q26 7.43
A15: AI 伺服器營收（＝營收 × 伺服器占比 × AI 占伺服器） | B15: =B4-F16/(1+g_nai26) -> 905.033 | F15: =F4*srv_26*ais_26 -> 2719.1262 | G15: Derived／Interested-party | H15: 公司比例（In 頁 C 節）；FY2025＝營收 − FY2026 非 AI ÷（1＋非 AI 年增） | I15: 各季與年度 AI 營收金額未揭露：未找到
A16: 非 AI 營收（一般伺服器、筆電、其他） | B16: =F16/(1+g_nai26) -> 1218.656 | F16: =F4-F15 -> 1279.5888 | G16: Derived／Assumed（FY2025） | H16: — | I16: —
A18: FY2026 錨點的檢查（參考；校準未使用券商數字）
A19: FY2026 營收年增 | B19: =F4/B4-1 -> 0.88290988
A20: FY2026 營業費用年增 | B20: =F7/B7-1 -> 0.17208259
A21: 營業費用彈性（營業費用年增 ÷ 營收年增；In 頁 phi 的依據） | B21: =B20/B19 -> 0.19490391
A22: FY2026 營收 ÷ 凱基（08-13，3Q 前）− 1 | B22: =F4/b_rev26-1 -> -0.052256638
A23: FY2026 EPS ÷ 凱基 − 1 | B23: =F13/b_eps26-1 -> 0.061436341
A24: AI 伺服器營收 FY2026 年增（隱含；公司說三位數） | B24: =F15/B15-1 -> 2.0044498

Sheet Units
A1: Units — AI 伺服器組裝市場、廣達份額、客供比例（本專案權威，規則第 13 條）。部署 GW＝AI IT 資本支出（markets/network）÷ 每 GW IT 資本支出（Tokenomics，經橋接表）
A3: 項目 | B3: 單位 | C3: CY2026 | D3: CY2027 | E3: CY2028 | F3: CY2029 | G3: 說明
A4: 部署 GW（情境 A） | B4: GW | C4: =PL!D77 -> 23.399538 | D4: =PL!E77 -> 41.646766 | E4: =PL!F77 -> 52.792138 | F4: =PL!G77 -> 60.138592 | G4: AI IT 資本支出 ÷ 每 GW IT 資本支出
A5: 每 GW ODM 整櫃價值 | B5: US$B/GW | C5: =PL!D78 -> 27.1209 | D5: =PL!E78 -> 27.351 | E5: =PL!F78 -> 27.351 | F5: =PL!G78 -> 27.351 | G5: 架數 × ODM 每櫃價格（GB300 4.0、VR200 6.75 百萬美元）
A6: AI 伺服器組裝市場（ODM 價） | B6: US$B | C6: =PL!D79 -> 634.61653 | D6: =PL!E79 -> 1139.0807 | E6: =PL!F79 -> 1443.9178 | F6: =PL!G79 -> 1644.8506 | G6: 含 ASIC 機架（假設每 GW 價值相同）
A7: 廣達有效份額 | B7: % | C7: =PL!D83 -> 0.13389612 | D7: =PL!E83 -> 0.13389612 | E7: =PL!F83 -> 0.12720132 | F7: =PL!G83 -> 0.12050651 | G7: FY2026 以公司伺服器與 AI 占比校準
A8: 廣達 AI 伺服器毛額價值 | B8: US$B | C8: =PL!D84/fx -> 84.972694 | D8: =PL!E84/fx -> 152.51849 | E8: =PL!F84/fx -> 183.66824 | F8: =PL!G84/fx -> 198.21521 | G8: 買賣模式下的營收
A9: 客供比例 | B9: % | C9: =PL!D85 -> 0 | D9: =PL!E85 -> 0.1 | E9: =PL!F85 -> 0.2 | F9: =PL!G85 -> 0.25 | G9: Assumed（FY2027 起）
A10: 廣達 AI 伺服器營收 | B10: US$B | C10: =PL!D86/fx -> 84.972694 | D10: =PL!E86/fx -> 137.26664 | E10: =PL!F86/fx -> 146.93459 | F10: =PL!G86/fx -> 148.66141
A11: 隱含廣達出貨櫃數（NVL72 等值） | B11: 千櫃 | C11: =PL!D98 -> 18.452268 | D11: =PL!E98 -> 22.595332 | E11: =PL!F98 -> 27.21011 | F11: =PL!G98 -> 29.365216 | G11: 毛額價值 ÷ ODM 每櫃價格
A12: 每 GW 廣達 AI 伺服器營收 | B12: US$B/GW | C12: =PL!D97 -> 3.6313834 | D12: =PL!E97 -> 3.2959736 | E12: =PL!F97 -> 2.7832666 | F12: =PL!G97 -> 2.4719802 | G12: 先驗比對推導 2026 約 3.4–4.2
A13: 廣達 AI 伺服器毛利率（營收基礎） | B13: % | C13: =PL!D104 -> 0.043230721 | D13: =PL!E104 -> 0.044253794 | E13: =PL!F104 -> 0.049282634 | F13: =PL!G104 -> 0.052299938 | G13: 客供上升 → 毛利率上升、毛利金額大致不變
A14: 其他廠商（鴻海、緯創、英業達、Dell、Supermicro 等）＝ 市場 − 廣達毛額 | B14: US$B | C14: =PL!D79-PL!D84/fx -> 549.64384 | D14: =PL!E79-PL!E84/fx -> 986.5622 | E14: =PL!F79-PL!F84/fx -> 1260.2495 | F14: =PL!G79-PL!G84/fx -> 1446.6354
A16: 讀法：FY2026 有效份額遠低於整櫃櫃數份額（三家中約三分之一），因為本模型分母是全部 AI IT 資本支出換算的組裝市場（含 ASIC、HGX 與其他組裝廠），且公司部分出貨為運算托盤而非整櫃。客供比例與份額相對值是 Assumed，是最需要每季檢查的輸入。

Sheet PL
A1: PL — 廣達損益（十億新台幣；EPS 新台幣；歸屬母公司）。FY2025A 實績、FY2026 錨點（1H26 實績＋3Q26 營收實績＋假設），FY2027 起為模型。FY(t)＝CY(t)。三情境各一個完整推導區塊（本頁下方），頂端為摘要。FY2026–FY2027 三情境相同（顆數係數從 CY2028 開始）
A3: 情境／項目 | B3: 單位 | C3: FY2025A | D3: FY2026（錨點） | E3: FY2027 | F3: FY2028 | G3: FY2029 | H3: 說明
A4: 情境 A
A5: 營收 | B5: NT$B | C5: =C89 -> 2123.689 | D5: =D89 -> 3998.715 | E5: =E89 -> 5710.509 | F5: =F89 -> 6046.243 | G5: =G89 -> 6128.3878
A6: 營收年增 | B6: % | D6: =D95 -> 0.88290988 | E6: =E95 -> 0.42808601 | F6: =F95 -> 0.058792318 | G6: =G95 -> 0.013586081
A7: 雲端伺服器 | B7: NT$B | C7: =C91 -> 1507.8192 | D7: =D91 -> 3398.9077 | E7: =E91 -> 5140.2922 | F7: =F91 -> 5487.0547 | G7: =G91 -> 5581.5701
A8: AI 伺服器營收 | B8: NT$B | C8: =C86 -> 905.033 | D8: =D86 -> 2719.1262 | E8: =E86 -> 4392.5325 | F8: =F86 -> 4701.907 | G8: =G86 -> 4757.1651
A9: 筆電 | B9: NT$B | C9: =C92 -> 467.21158 | D9: =D92 -> 439.85865 | E9: =E92 -> 395.87279 | F9: =F92 -> 376.07915 | G9: =G92 -> 364.79677
A10: 其他 | B10: NT$B | C10: =C93 -> 148.65823 | D10: =D93 -> 159.9486 | E10: =E93 -> 174.34397 | F10: =F93 -> 183.10916 | G10: =G93 -> 182.02087
A11: 非 AI 營收（一般伺服器＋筆電＋其他） | B11: NT$B | C11: =C88 -> 1218.656 | D11: =D88 -> 1279.5888 | E11: =E88 -> 1317.9765 | F11: =F88 -> 1344.336 | G11: =G88 -> 1371.2227
A12: AI 伺服器 ÷ 營收 | B12: % | C12: =C96 -> 0.4261608 | D12: =D96 -> 0.68 | E12: =E96 -> 0.76920158 | F12: =F96 -> 0.77765763 | G12: =G96 -> 0.77625066
A13: 毛利 | B13: NT$B | C13: =C102 -> 148.23349 | D13: =D102 -> 198.45911 | E13: =E102 -> 277.72283 | F13: =F102 -> 316.7257 | G13: =G102 -> 335.50284
A14: 毛利率 | B14: % | C14: =C103 -> 0.0698 | D14: =D103 -> 0.049630721 | E14: =E103 -> 0.048633639 | F14: =F103 -> 0.052383885 | G14: =G103 -> 0.054745693
A15: 營業利益率 | B15: % | C15: =C108 -> 0.0412 | D15: =D108 -> 0.031827659 | E15: =E108 -> 0.034032586 | F15: =F108 -> 0.03826929 | G15: =G108 -> 0.040744614
A16: 歸屬母公司淨利 | B16: NT$B | C16: =C110 -> 74.98 | D16: =D110 -> 110.71367 | E16: =E110 -> 168.10703 | F16: =F110 -> 200.14839 | G16: =G110 -> 215.98945
A17: EPS | B17: NT$ | C17: =C112 -> 19.45 | D17: =D112 -> 28.722467 | E17: =E112 -> 43.612036 | F17: =F112 -> 51.924533 | G17: =G112 -> 56.034182
A18: EPS 年增 | B18: % | D18: =D113 -> 0.47673354 | E18: =E113 -> 0.51839449 | F18: =F113 -> 0.19060098 | G18: =G113 -> 0.079146581
A20: 情境 B
A21: 營收 | B21: NT$B | C21: =C133 -> 2123.689 | D21: =D133 -> 3998.715 | E21: =E133 -> 5710.509 | F21: =F133 -> 5105.8616 | G21: =G133 -> 5414.813
A22: 營收年增 | B22: % | D22: =D139 -> 0.88290988 | E22: =E139 -> 0.42808601 | F22: =F139 -> -0.10588327 | G22: =G139 -> 0.060509159
A23: 雲端伺服器 | B23: NT$B | C23: =C135 -> 1507.8192 | D23: =D135 -> 3398.9077 | E23: =E135 -> 5140.2922 | F23: =F135 -> 4546.6733 | G23: =G135 -> 4867.9954
A24: AI 伺服器營收 | B24: NT$B | C24: =C130 -> 905.033 | D24: =D130 -> 2719.1262 | E24: =E130 -> 4392.5325 | F24: =F130 -> 3761.5256 | G24: =G130 -> 4043.5903
A25: 筆電 | B25: NT$B | C25: =C136 -> 467.21158 | D25: =D136 -> 439.85865 | E25: =E136 -> 395.87279 | F25: =F136 -> 376.07915 | G25: =G136 -> 364.79677
A26: 其他 | B26: NT$B | C26: =C137 -> 148.65823 | D26: =D137 -> 159.9486 | E26: =E137 -> 174.34397 | F26: =F137 -> 183.10916 | G26: =G137 -> 182.02087
A27: 非 AI 營收（一般伺服器＋筆電＋其他） | B27: NT$B | C27: =C132 -> 1218.656 | D27: =D132 -> 1279.5888 | E27: =E132 -> 1317.9765 | F27: =F132 -> 1344.336 | G27: =G132 -> 1371.2227
A28: AI 伺服器 ÷ 營收 | B28: % | C28: =C140 -> 0.4261608 | D28: =D140 -> 0.68 | E28: =E140 -> 0.76920158 | F28: =F140 -> 0.73670732 | G28: =G140 -> 0.74676453
A29: 毛利 | B29: NT$B | C29: =C146 -> 148.23349 | D29: =D146 -> 198.45911 | E29: =E146 -> 277.72283 | F29: =F146 -> 270.38122 | G29: =G146 -> 298.18292
A30: 毛利率 | B30: % | C30: =C147 -> 0.0698 | D30: =D147 -> 0.049630721 | E30: =E147 -> 0.048633639 | F30: =F147 -> 0.052955063 | G30: =G147 -> 0.055068
A31: 營業利益率 | B31: % | C31: =C152 -> 0.0412 | D31: =D152 -> 0.031827659 | E31: =E152 -> 0.034032586 | F31: =F152 -> 0.036624922 | G31: =G152 -> 0.039296905
A32: 歸屬母公司淨利 | B32: NT$B | C32: =C154 -> 74.98 | D32: =D154 -> 110.71367 | E32: =E154 -> 168.10703 | F32: =F154 -> 161.75654 | G32: =G154 -> 184.05936
A33: EPS | B33: NT$ | C33: =C156 -> 19.45 | D33: =D156 -> 28.722467 | E33: =E156 -> 43.612036 | F33: =F156 -> 41.964528 | G33: =G156 -> 47.750553
A34: EPS 年增 | B34: % | D34: =D157 -> 0.47673354 | E34: =E157 -> 0.51839449 | F34: =F157 -> -0.037776458 | G34: =G157 -> 0.13787896
A36: 情境 C
A37: 營收 | B37: NT$B | C37: =C177 -> 2123.689 | D37: =D177 -> 3998.715 | E37: =E177 -> 5710.509 | F37: =F177 -> 4165.4802 | G37: =G177 -> 4225.5217
A38: 營收年增 | B38: % | D38: =D183 -> 0.88290988 | E38: =E183 -> 0.42808601 | F38: =F183 -> -0.27055885 | G38: =G183 -> 0.014414073
A39: 雲端伺服器 | B39: NT$B | C39: =C179 -> 1507.8192 | D39: =D179 -> 3398.9077 | E39: =E179 -> 5140.2922 | F39: =F179 -> 3606.2919 | G39: =G179 -> 3678.7041
A40: AI 伺服器營收 | B40: NT$B | C40: =C174 -> 905.033 | D40: =D174 -> 2719.1262 | E40: =E174 -> 4392.5325 | F40: =F174 -> 2821.1442 | G40: =G174 -> 2854.299
A41: 筆電 | B41: NT$B | C41: =C180 -> 467.21158 | D41: =D180 -> 439.85865 | E41: =E180 -> 395.87279 | F41: =F180 -> 376.07915 | G41: =G180 -> 364.79677
A42: 其他 | B42: NT$B | C42: =C181 -> 148.65823 | D42: =D181 -> 159.9486 | E42: =E181 -> 174.34397 | F42: =F181 -> 183.10916 | G42: =G181 -> 182.02087
A43: 非 AI 營收（一般伺服器＋筆電＋其他） | B43: NT$B | C43: =C176 -> 1218.656 | D43: =D176 -> 1279.5888 | E43: =E176 -> 1317.9765 | F43: =F176 -> 1344.336 | G43: =G176 -> 1371.2227
...

Sheet Val
A1: Val — P/E 估值（新台幣）。結論用「現價 ÷ FY2027、FY2028 EPS（模型）」與十年 P/E 規則值（年底落後 P/E，基準為 FY2027 EPS）
A2: 循環位置：廣達不是設備股，不套設備市場見頂年；以本模型營收最高的會計年度為見頂年（比照 NVIDIA、Arista、台達電；FY(t)＝CY(t)）。營收到 FY2029 仍在增加時，見頂年未知，判為中段
A3: 目標價：見第 0 節（本頁第 85 列；v0.2 新增，DCF 與 Comparable 加權）。第 41 列「舊法：規則值情境加權（參考）」不再是目標價，只作參考
A4: 1. 價格與市場隱含倍數
A5: 項目 | B5: A | C5: B | D5: C | E5: 說明
A6: 現價（2026-10-22 收盤） | B6: =px -> 322
A7: 現價 ÷ FY2026 EPS（錨點） | B7: =px/PL!D17 -> 11.210736 | C7: =px/PL!D33 -> 11.210736 | D7: =px/PL!D49 -> 11.210736
A8: 現價 ÷ FY2027 EPS（模型） | B8: =px/PL!E17 -> 7.3832829 | C8: =px/PL!E33 -> 7.3832829 | D8: =px/PL!E49 -> 7.3832829 | E8: FY2027 三情境相同（顆數係數從 CY2028 開始）
A9: 現價 ÷ FY2028 EPS（模型） | B9: =px/PL!F17 -> 6.2013076 | C9: =px/PL!F33 -> 7.6731472 | D9: =px/PL!F49 -> 10.201334
A10: 現價 ÷ FY2029 EPS（模型） | B10: =px/PL!G17 -> 5.7464924 | C10: =px/PL!G33 -> 6.7433774 | D10: =px/PL!G49 -> 9.4324545
A11: 未來 12 月 EPS（模型 A）≈ 0.2 × FY2026＋0.8 × FY2027 | B11: =0.2*PL!D17+0.8*PL!E17 -> 40.634122
A12: 現價 ÷ 未來 12 月 EPS（模型 A） | B12: =px/B11 -> 7.9243744 | E12: Andy 先驗 Q9a 答 20x（未來 12 月）
A13: 近 12 月 P/E（Yahoo，10-22） | B13: =pe_ttm -> 14.31
A15: 2. 循環位置（本模型營收最高年；FY(t)＝CY(t)）
A16: 情境 | B16: 營收最高年（FY2026–FY2029） | C16: FY2027 判定 | D16: 規則倍數（P/E） | E16: 見頂年是否未知 | F16: 說明
A17: A | B17: =INDEX({2026,2027,2028,2029},MATCH(MAX(PL!D89:G89),PL!D89:G89,0)) -> 2029 | C17: =IF(B17=2029,"中段",IF(2027<B17,"中段",IF(2027=B17,"見頂","谷底"))) -> 中段 | D17: =IF(C17="見頂",pe_peak,IF(C17="谷底",pe_trough,pe_mid)) -> 12.27 | E17: =IF(B17=2029,"是：營收到觀測期末仍在增加","否") -> 是：營收到觀測期末仍在增加 | F17: tools/cycle_position.py excel_rule；營收最高年取代設備市場見頂年
A18: B | B18: =INDEX({2026,2027,2028,2029},MATCH(MAX(PL!D133:G133),PL!D133:G133,0)) -> 2027 | C18: =IF(B18=2029,"中段",IF(2027<B18,"中段",IF(2027=B18,"見頂","谷底"))) -> 見頂 | D18: =IF(C18="見頂",pe_peak,IF(C18="谷底",pe_trough,pe_mid)) -> 10.81 | E18: =IF(B18=2029,"是：營收到觀測期末仍在增加","否") -> 否 | F18: 同上
A19: C | B19: =INDEX({2026,2027,2028,2029},MATCH(MAX(PL!D177:G177),PL!D177:G177,0)) -> 2027 | C19: =IF(B19=2029,"中段",IF(2027<B19,"中段",IF(2027=B19,"見頂","谷底"))) -> 見頂 | D19: =IF(C19="見頂",pe_peak,IF(C19="谷底",pe_trough,pe_mid)) -> 10.81 | E19: =IF(B19=2029,"是：營收到觀測期末仍在增加","否") -> 否 | F19: 同上
A21: 3. 規則值隱含股價（新台幣；約 FY2027 年底，未折現）＝ FY2027 EPS × 規則倍數
A22: 情境 | B22: FY2027 EPS | C22: （同左） | D22: 規則倍數 | E22: 隱含股價 | F22: 相對現價 | G22: 現價 ÷ FY2027 EPS
A23: A | B23: =PL!E17 -> 43.612036 | C23: =B23 -> 43.612036 | D23: =D17 -> 12.27 | E23: =C23*D23 -> 535.11969 | F23: =E23/px-1 -> 0.66186238 | G23: =px/C23 -> 7.3832829
A24: B | B24: =PL!E33 -> 43.612036 | C24: =B24 -> 43.612036 | D24: =D18 -> 10.81 | E24: =C24*D24 -> 471.44611 | F24: =E24/px-1 -> 0.46411836 | G24: =px/C24 -> 7.3832829
A25: C | B25: =PL!E49 -> 43.612036 | C25: =B25 -> 43.612036 | D25: =D19 -> 10.81 | E25: =C25*D25 -> 471.44611 | F25: =E25/px-1 -> 0.46411836 | G25: =px/C25 -> 7.3832829
A26: 4. What must be true：FY2027 年底價 ＝ 現價 ×（1＋報酬）所需的倍數（FY2028 EPS；約 2027 年底的價格看下一年 EPS）
A27: FY2027 年底價 ÷ 現價 | B27: 所需倍數（÷ FY2028 EPS，A） | C27: 所需倍數（÷ FY2028 EPS，C） | D27: 對照：Andy 合理 P/E | E27: 對照：十年中位數
A28: 1 | B28: =px*A28/PL!F17 -> 6.2013076 | C28: =px*A28/PL!F49 -> 10.201334 | D28: =pe_fair_andy -> 15 | E28: =pe_mid -> 12.27
A29: 1.1 | B29: =px*A29/PL!F17 -> 6.8214383 | C29: =px*A29/PL!F49 -> 11.221467 | D29: =pe_fair_andy -> 15 | E29: =pe_mid -> 12.27
A30: 1.21 | B30: =px*A30/PL!F17 -> 7.5035822 | C30: =px*A30/PL!F49 -> 12.343614 | D30: =pe_fair_andy -> 15 | E30: =pe_mid -> 12.27
A31: 1.5 | B31: =px*A31/PL!F17 -> 9.3019614 | C31: =px*A31/PL!F49 -> 15.302001 | D31: =pe_fair_andy -> 15 | E31: =pe_mid -> 12.27
A32: 2 | B32: =px*A32/PL!F17 -> 12.402615 | C32: =px*A32/PL!F49 -> 20.402668 | D32: =pe_fair_andy -> 15 | E32: =pe_mid -> 12.27
A33: 讀法：1.00＝價格不變、1.21＝一年約 21%。所需倍數低於歷史中位數時，現價相對便宜；倍數是否合理，另看前瞻 P/E 歷史（Bloomberg）。
A35: 5. 對照：以 Andy 合理 P/E 15x 計算的隱含價（只作對照，非規則值）
A36: 情境 | B36: FY2027 EPS | C36: × 15x | D36: 相對現價 | E36: FY2028 EPS | F36: × 15x | G36: 相對現價
A37: A | B37: =PL!E17 -> 43.612036 | C37: =B37*pe_fair_andy -> 654.18054 | D37: =C37/px-1 -> 1.0316166 | E37: =PL!F17 -> 51.924533 | F37: =E37*pe_fair_andy -> 778.86799 | G37: =F37/px-1 -> 1.4188447
A38: B | B38: =PL!E33 -> 43.612036 | C38: =B38*pe_fair_andy -> 654.18054 | D38: =C38/px-1 -> 1.0316166 | E38: =PL!F33 -> 41.964528 | F38: =E38*pe_fair_andy -> 629.46792 | G38: =F38/px-1 -> 0.95486932
A39: C | B39: =PL!E49 -> 43.612036 | C39: =B39*pe_fair_andy -> 654.18054 | D39: =C39/px-1 -> 1.0316166 | E39: =PL!F49 -> 31.564499 | F39: =E39*pe_fair_andy -> 473.46749 | G39: =F39/px-1 -> 0.47039593
A41: 舊法：規則值情境加權（參考；v0.1.1 的「0. 目標價與上檔空間」改名，不再是目標價；權重為 In 頁 tp_wA／tp_wB／tp_wC）
A42: 舊法隱含價（情境加權，參考） | B42: =tp_wA*B44+tp_wB*B45+tp_wC*B46 -> 490.54818 | E42: ＝權重 A × 情境 A 隱含價＋權重 B × 情境 B 隱含價＋權重 C × 情境 C 隱含價（NT$）
A43: 舊法隱含價相對現價（÷ 現價 − 1） | B43: =B42/px-1 -> 0.52344157 | E43: 相對「現價（2026-10-22 收盤）」
A44: 情境 A 隱含價（樂觀） | B44: =E23 -> 535.11969 | E44: ＝規則值隱含股價 E23（情境 A：基準（顆數係數 1.0））
...

Sheet Recon
A1: Recon — 本模型 vs 券商估計與櫃數份額。只作事後對照，不為對上數字而調參數。券商多未具名或單一來源；2027 共識（付費）未找到
A3: 項目 | B3: 對照值 | C3: 模型 A | D3: 差距 A | E3: 模型 B | F3: 差距 B | G3: 模型 C | H3: 差距 C | I3: 對照來源 | J3: 說明
A4: A. 券商估計（校準未使用）
A5: FY2026 營收 vs 凱基（08-13，3Q 前） | B5: =b_rev26 -> 4219.196 | C5: =PL!D89 -> 3998.715 | D5: =C5/B5-1 -> -0.052256638 | E5: =PL!D133 -> 3998.715 | F5: =E5/B5-1 -> -0.052256638 | G5: =PL!D177 -> 3998.715 | H5: =G5/B5-1 -> -0.052256638 | I5: 凱基 2026-08-13 | J5: 3Q 只達法人預期 92%
A6: FY2026 EPS vs 凱基 | B6: =b_eps26 -> 27.06 | C6: =PL!D112 -> 28.722467 | D6: =C6/B6-1 -> 0.061436341 | E6: =PL!D156 -> 28.722467 | F6: =E6/B6-1 -> 0.061436341 | G6: =PL!D200 -> 28.722467 | H6: =G6/B6-1 -> 0.061436341 | I6: 凱基 2026-08-13
A7: FY2027 營收 vs 凱基 | B7: =b_rev27a -> 5220.407 | C7: =PL!E89 -> 5710.509 | D7: =C7/B7-1 -> 0.093881945 | E7: =PL!E133 -> 5710.509 | F7: =E7/B7-1 -> 0.093881945 | G7: =PL!E177 -> 5710.509 | H7: =G7/B7-1 -> 0.093881945 | I7: 凱基 2026-08-13
A8: FY2027 營收 vs 法人（10-08） | B8: =b_rev27b -> 5300 | C8: =PL!E89 -> 5710.509 | D8: =C8/B8-1 -> 0.077454521 | E8: =PL!E133 -> 5710.509 | F8: =E8/B8-1 -> 0.077454521 | G8: =PL!E177 -> 5710.509 | H8: =G8/B8-1 -> 0.077454521 | I8: 工商時報 2026-10-08
A9: FY2027 EPS vs 凱基 | B9: =b_eps27a -> 31.75 | C9: =PL!E112 -> 43.612036 | D9: =C9/B9-1 -> 0.37360744 | E9: =PL!E156 -> 43.612036 | F9: =E9/B9-1 -> 0.37360744 | G9: =PL!E200 -> 43.612036 | H9: =G9/B9-1 -> 0.37360744 | I9: 凱基 2026-08-13
A10: FY2027 EPS vs 法人（10-08） | B10: =b_eps27b -> 32.09 | C10: =PL!E112 -> 43.612036 | D10: =C10/B10-1 -> 0.35905379 | E10: =PL!E156 -> 43.612036 | F10: =E10/B10-1 -> 0.35905379 | G10: =PL!E200 -> 43.612036 | H10: =G10/B10-1 -> 0.35905379 | I10: 工商時報 2026-10-08 | J10: 兩家區間 31.75–32.09
A11: FY2027 毛利率 vs 凱基（百分點） | B11: =b_gm27 -> 0.047 | C11: =PL!E103 -> 0.048633639 | D11: =C11-B11 -> 0.0016336385 | E11: =PL!E147 -> 0.048633639 | F11: =E11-B11 -> 0.0016336385 | G11: =PL!E191 -> 0.048633639 | H11: =G11-B11 -> 0.0016336385 | I11: 凱基 2026-08-13 | J11: 模型含客供 10%，毛利率較高
A12: FY2027 營收年增（模型） | C12: =PL!E95 -> 0.42808601 | E12: =PL!E139 -> 0.42808601 | G12: =PL!E183 -> 0.42808601 | I12: —
A13: B. 份額與每 GW（先驗比對的機制檢查）
A14: FY2026 有效份額 vs 三家 ODM 中的 NVL72 櫃數份額 | B14: =rk_sh -> 0.33779264 | C14: =PL!D81 -> 0.13389612 | D14: =C14-B14 -> -0.20389652 | E14: =PL!D125 -> 0.13389612 | F14: =E14-B14 -> -0.20389652 | G14: =PL!D169 -> 0.13389612 | H14: =G14-B14 -> -0.20389652 | I14: 經濟日報 2026-09-10（美系券商） | J14: 口徑不同：本模型分母為全部 AI 組裝市場（含 ASIC、HGX、其他廠）
A15: FY2026 每 GW 廣達 AI 伺服器營收（US$B） | C15: =PL!D97 -> 3.6313834 | E15: =PL!D141 -> 3.6313834 | G15: =PL!D185 -> 3.6313834 | I15: — | J15: 先驗比對推導約 3.4–4.2
A16: FY2026 隱含廣達出貨櫃數（千櫃，NVL72 等值） | C16: =PL!D98 -> 18.452268 | E16: =PL!D142 -> 18.452268 | G16: =PL!D186 -> 18.452268 | I16: — | J16: 三家調查單月約 2.5 千櫃 × 12 ≈ 30 千櫃（Interested-party；含運算托盤口徑不明）
A17: FY2027 AI 伺服器 ÷ 營收 | C17: =PL!E96 -> 0.76920158 | E17: =PL!E140 -> 0.76920158 | G17: =PL!E184 -> 0.76920158 | I17: —
A18: C. 校準
A19: 其他營收毛利率（Derived） | C19: =PL!D100 -> 0.063230721 | E19: =PL!D144 -> 0.063230721 | G19: =PL!D188 -> 0.063230721 | I19: FY2026 錨點 | J19: AI 毛利率（毛額基礎）＝此值＋d_ai
A20: FY2027 毛利率 vs FY2026（百分點） | B20: =a26_gp/a26_rev -> 0.049630721 | C20: =PL!E103 -> 0.048633639 | D20: =C20-B20 -> -0.00099708284 | E20: =PL!E147 -> 0.048633639 | F20: =E20-B20 -> -0.00099708284 | G20: =PL!E191 -> 0.048633639 | H20: =G20-B20 -> -0.00099708284 | I20: 錨點 | J20: 客供使毛利率上升
A21: 4Q26 EPS（模型） | C21: =Q!E13 -> 7.6098418 | E21: =Q!E13 -> 7.6098418 | G21: =Q!E13 -> 7.6098418 | I21: —
A22: D. 預留
A23: R4 產業部署路徑（markets/deploy_path/，尚未建立）：上線後以部署路徑取代「AI IT 資本支出 ÷ 每 GW IT 資本支出」 | J23: 預留列：本版無數值
A25: E. 目標價對帳（v0.2；模型欄為情境加權值，非情境 A）
A26: 12 個月後的前瞻 EPS（情境加權）vs 共識前瞻 EPS | B26: =cons_feps -> 28.558798 | C26: =Val!B115 -> 42.995776 | D26: =C26/B26-1 -> 0.50551772 | I26: stockanalysis 個股頁 2026-10-14：價格 323 ÷ Forward PE 11.31 | J26: 共識只作對帳，不作校準
A27: 目標價（DCF 與 Comparable 加權）vs 市場共識目標價 | B27: =cons_tp -> 427.84 | C27: =Val!B120 -> 566.56229 | D27: =C27/B27-1 -> 0.32423872 | I27: stockanalysis 個股頁（S&P Global）19 位分析師平均 427.84，頁面時間 2026-10-14 | J27: 共識只作對帳，不作校準
A28: Comparable 目標價 vs 市場共識目標價 | B28: =cons_tp -> 427.84 | C28: =Val!B116 -> 488.86197 | D28: =C28/B28-1 -> 0.14262802 | I28: 同上 | J28: 共識只作對帳，不作校準

Sheet Sens
A1: Sens — 一次動一個輸入（情境 A；有效份額、其他營收毛利率在每個案例內依 FY2026 錨點重算，FY2026 恆等於錨點）：對 FY2027、FY2028 的營收、AI 伺服器營收、毛利率與 EPS 的影響。每個案例是一個完整推導區塊（本頁下方）
A3: 案例 | B3: 設定 | C3: FY2027 營收 | D3: FY2027 AI 伺服器營收 | E3: FY2027 毛利率 | F3: FY2027 EPS | G3: FY2027 EPS 相對基準 | H3: FY2028 營收 | I3: FY2028 AI 伺服器營收 | J3: FY2028 毛利率 | K3: FY2028 EPS | L3: FY2028 EPS 相對基準
A4: 基準（情境 A） | B4: PL 區塊 A | C4: =PL!E89 -> 5710.509 | D4: =PL!E86 -> 4392.5325 | E4: =PL!E103 -> 0.048633639 | F4: =PL!E112 -> 43.612036 | G4: =F4/F$4-1 -> 0 | H4: =PL!F89 -> 6046.243 | I4: =PL!F86 -> 4701.907 | J4: =PL!F103 -> 0.052383885 | K4: =PL!F112 -> 51.924533 | L4: =K4/K$4-1 -> 0
A5: 份額流失（低） | B5: 份額相對值 2027 0.85、2028 0.75、2029 0.70（鴻海、緯創搶單） | C5: =E57 -> 5051.6291 | D5: =E54 -> 3733.6526 | E5: =E71 -> 0.049204898 | F5: =E80 -> 38.121714 | G5: =F5/F$4-1 -> -0.12589007 | H5: =F57 -> 5056.3679 | I5: =F54 -> 3712.0319 | J5: =F71 -> 0.05299101 | K5: =F80 -> 42.463458 | L5: =K5/K$4-1 -> -0.18220819
A6: 份額上升（高） | B6: 份額相對值 1.1（Neocloud、ASIC 專案） | C6: =E101 -> 6149.7622 | D6: =E98 -> 4831.7857 | E6: =E115 -> 0.048320803 | F6: =E124 -> 47.272251 | G6: =F6/F$4-1 -> 0.083926712 | H6: =F101 -> 6788.6494 | I6: =F98 -> 5444.3134 | J6: =F115 -> 0.052044732 | K6: =F124 -> 59.066448 | L6: =K6/K$4-1 -> 0.13754414
A7: 客供 0（維持買賣） | B7: 客供比例 2027–29 皆 0 | C7: =E145 -> 6198.5681 | D7: =E142 -> 4880.5917 | E7: =E159 -> 0.045121118 | F7: =E168 -> 43.272714 | G7: =F7/F$4-1 -> -0.0077804648 | H7: =F145 -> 7221.7198 | I7: =F142 -> 5877.3838 | J7: =F159 -> 0.044512212 | K7: =F168 -> 51.358953 | L7: =K7/K$4-1 -> -0.01089234
A8: 客供 高 | B8: 客供比例 25%／40%／50% | C8: =E189 -> 4978.4202 | D8: =E186 -> 3660.4437 | E8: =E203 -> 0.05519373 | F8: =E212 -> 44.121019 | G8: =F8/F$4-1 -> 0.011670697 | H8: =F189 -> 4870.7663 | I8: =F186 -> 3526.4303 | J8: =F203 -> 0.064054946 | K8: =F212 -> 52.473246 | L8: =K8/K$4-1 -> 0.010567516
A9: 客供保留毛利 0.7 | B9: 客供部分只保留 70% 毛利 | C9: =E233 -> 5710.509 | D9: =E230 -> 4392.5325 | E9: =E247 -> 0.04794596 | F9: =E256 -> 42.730791 | G9: =F9/F$4-1 -> -0.020206473 | H9: =F233 -> 6046.243 | I9: =F230 -> 4701.907 | J9: =F247 -> 0.050819598 | K9: =F256 -> 49.802078 | L9: =K9/K$4-1 -> -0.040875762
A10: 客供保留毛利 1.0 | B10: 毛利金額完全保留 | C10: =E277 -> 5710.509 | D10: =E274 -> 4392.5325 | E10: =E291 -> 0.048977478 | F10: =E300 -> 44.052659 | G10: =F10/F$4-1 -> 0.010103237 | H10: =F277 -> 6046.243 | I10: =F274 -> 4701.907 | J10: =F291 -> 0.053166028 | K10: =F300 -> 52.98576 | L10: =K10/K$4-1 -> 0.020437881
A11: 每 GW 價值 低 | B11: 2028–29 每 GW ODM 價值 ×0.85（Rubin Ultra 降價或客供更深） | C11: =E321 -> 5710.509 | D11: =E318 -> 4392.5325 | E11: =E335 -> 0.048633639 | F11: =E344 -> 43.612036 | G11: =F11/F$4-1 -> 0 | H11: =F321 -> 5340.957 | I11: =F318 -> 3996.621 | J11: =F335 -> 0.052793412 | K11: =F344 -> 44.564535 | L11: =K11/K$4-1 -> -0.14174413
A12: 每 GW 價值 高 | B12: ×1.2 | C12: =E365 -> 5710.509 | D12: =E362 -> 4392.5325 | E12: =E379 -> 0.048633639 | F12: =E388 -> 43.612036 | G12: =F12/F$4-1 -> 0 | H12: =F365 -> 6986.6244 | I12: =F362 -> 5642.2884 | J12: =F379 -> 0.051966464 | K12: =F388 -> 61.092068 | L12: =K12/K$4-1 -> 0.17655498
A13: AI 部署 ×0.8 | B13: FY2027 起 AI IT 資本支出 ×0.8 | C13: =E409 -> 4832.0025 | D13: =E406 -> 3514.026 | E13: =E423 -> 0.049429938 | F13: =E432 -> 36.291607 | G13: =F13/F$4-1 -> -0.16785342 | H13: =F409 -> 5105.8616 | I13: =F406 -> 3761.5256 | J13: =F423 -> 0.052955063 | K13: =F432 -> 42.97607 | L13: =K13/K$4-1 -> -0.17233594
A14: AI 部署 ×1.2 | B14: ×1.2 | C14: =E453 -> 6589.0155 | D14: =E450 -> 5271.039 | E14: =E467 -> 0.048049678 | F14: =E476 -> 50.932466 | G14: =F14/F$4-1 -> 0.16785342 | H14: =F453 -> 6986.6244 | I14: =F450 -> 5642.2884 | J14: =F467 -> 0.051966464 | K14: =F476 -> 60.87516 | L14: =K14/K$4-1 -> 0.1723776
A15: 非 AI 成長 低 | B15: 2027–29 −5% | C15: =E497 -> 5608.1419 | D15: =E494 -> 4392.5325 | E15: =E511 -> 0.048367194 | F15: =E520 -> 42.323094 | G15: =F15/F$4-1 -> -0.029554732 | H15: =F497 -> 5856.7359 | I15: =F494 -> 4701.907 | J15: =F511 -> 0.052032912 | K15: =F520 -> 49.510287 | L15: =K15/K$4-1 -> -0.046495295
A16: 非 AI 成長 高 | B16: 2027 +8%、2028–29 +6% | C16: =E541 -> 5774.4884 | D16: =E538 -> 4392.5325 | E16: =E555 -> 0.048795369 | F16: =E564 -> 44.417625 | G16: =F16/F$4-1 -> 0.018471707 | H16: =F541 -> 6166.7803 | I16: =F538 -> 4701.907 | J16: =F555 -> 0.052595899 | K16: =F564 -> 53.461436 | L16: =K16/K$4-1 -> 0.029598792
A17: AI 毛利率差距 −3.5pt | B17: AI 毛利率（毛額基礎）比其他低 3.5 個百分點 | C17: =E585 -> 5710.509 | D17: =E582 -> 4392.5325 | E17: =E599 -> 0.046926398 | F17: =E608 -> 41.424244 | G17: =F17/F$4-1 -> -0.050164875 | H17: =F585 -> 6046.243 | I17: =F582 -> 4701.907 | J17: =F599 -> 0.05007915 | K17: =F608 -> 48.797423 | L17: =K17/K$4-1 -> -0.060224131
A18: AI 毛利率差距 −0.5pt | B18: 只低 0.5 個百分點 | C18: =E629 -> 5710.509 | D18: =E626 -> 4392.5325 | E18: =E643 -> 0.050340879 | F18: =E652 -> 45.799829 | G18: =F18/F$4-1 -> 0.050164875 | H18: =F629 -> 6046.243 | I18: =F626 -> 4701.907 | J18: =F643 -> 0.054688619 | K18: =F652 -> 55.051643 | L18: =K18/K$4-1 -> 0.060224131
A19: VR 稀釋 −0.6pt | B19: FY2027 起 AI 毛利率（毛額基礎）−0.6 個百分點 | C19: =E673 -> 5710.509 | D19: =E670 -> 4392.5325 | E19: =E687 -> 0.046095273 | F19: =E696 -> 40.359175 | G19: =F19/F$4-1 -> -0.074586316 | H19: =F673 -> 6046.243 | I19: =F670 -> 4701.907 | J19: =F687 -> 0.049525993 | K19: =F696 -> 48.046889 | L19: =K19/K$4-1 -> -0.074678465
A20: VR 不稀釋 | B20: FY2027 起不變 | C20: =E717 -> 5710.509 | D20: =E714 -> 4392.5325 | E20: =E731 -> 0.051172004 | F20: =E740 -> 46.864897 | G20: =F20/F$4-1 -> 0.074586316 | H20: =F717 -> 6046.243 | I20: =F714 -> 4701.907 | J20: =F731 -> 0.055241776 | K20: =F740 -> 55.802177 | L20: =K20/K$4-1 -> 0.074678465
A21: 營業費用率 +0.2pt | B21: 營業費用額外 +0.2% × 營收 | C21: =E761 -> 5710.509 | D21: =E758 -> 4392.5325 | E21: =E775 -> 0.048633639 | F21: =E784 -> 41.049079 | G21: =F21/F$4-1 -> -0.058767207 | H21: =F761 -> 6046.243 | I21: =F758 -> 4701.907 | J21: =F775 -> 0.052383885 | K21: =F784 -> 49.210893 | L21: =K21/K$4-1 -> -0.052261226
A22: 淨利 ÷ 營業利益 0.75 | B22: FY2027 起 0.75（券商隱含約 0.73–0.77） | C22: =E805 -> 5710.509 | D22: =E802 -> 4392.5325 | E22: =E819 -> 0.048633639 | F22: =E828 -> 37.813904 | G22: =F22/F$4-1 -> -0.13294798 | H22: =F805 -> 6046.243 | I22: =F802 -> 4701.907 | J22: =F819 -> 0.052383885 | K22: =F828 -> 45.021271 | L22: =K22/K$4-1 -> -0.13294798
A23: 顆數情境 B | B23: CY2028 ×0.8、CY2029 ×0.85 | C23: =PL!E133 -> 5710.509 | D23: =PL!E130 -> 4392.5325 | E23: =PL!E147 -> 0.048633639 | F23: =PL!E156 -> 43.612036 | G23: =F23/F$4-1 -> 0 | H23: =PL!F133 -> 5105.8616 | I23: =PL!F130 -> 3761.5256 | J23: =PL!F147 -> 0.052955063 | K23: =PL!F156 -> 41.964528 | L23: =K23/K$4-1 -> -0.19181694
A24: 顆數情境 C | B24: CY2028–29 ×0.6 | C24: =PL!E177 -> 5710.509 | D24: =PL!E174 -> 4392.5325 | E24: =PL!E191 -> 0.048633639 | F24: =PL!E200 -> 43.612036 | G24: =F24/F$4-1 -> 0 | H24: =PL!F177 -> 4165.4802 | I24: =PL!F174 -> 2821.1442 | J24: =PL!F191 -> 0.053784135 | K24: =PL!F200 -> 31.564499 | L24: =K24/K$4-1 -> -0.39210817
A26: 讀法：FY2027 三情境相同；顆數情境 B、C 的差異從 FY2028 起。每個案例的 FY2026 有效份額與其他營收毛利率依該案例重算，所以 FY2026 恆等於錨點。「客供」案例同時改變營收與毛利率，EPS 只受保留毛利比例影響：客供比例高、保留比例低時 EPS 才明顯下降。
A40: 案例區塊：份額流失（低）（情境 A）
A41: 項目 | B41: 單位 | C41: FY2025A | D41: FY2026（錨點） | E41: FY2027 | F41: FY2028 | G41: FY2029 | H41: 說明
A42: A. AI 部署與整櫃組裝市場（D 欄＝FY2026 校準年；E–G＝FY2027–FY2029）
A43: AI IT 資本支出 × 情境顆數係數 | B43: US$B | D43: =itc_26*1 -> 781.87292 | E43: =itc_27*1*1 -> 1565.35 | F43: =itc_28*um28_A*1 -> 1984.2639 | G43: =itc_29*um29_A*1 -> 2260.3903
A44: 每 GW IT 資本支出 | B44: US$B | D44: =itpg_gb*(1-vr26)+itpg_vr*vr26 -> 33.414032 | E44: =itpg_vr -> 37.586352 | F44: =itpg_vr -> 37.586352 | G44: =itpg_vr -> 37.586352
A45: 部署 GW（IT 電力） | B45: GW | D45: =D43/D44 -> 23.399538 | E45: =E43/E44 -> 41.646766 | F45: =F43/F44 -> 52.792138 | G45: =G43/G44 -> 60.138592
A46: 每 GW ODM 整櫃價值 | B46: US$B/GW | D46: =(racks_gb*odm_gb*(1-vr26)+racks_vr*odm_vr*vr26)/1000 -> 27.1209 | E46: =racks_vr*odm_vr/1000 -> 27.351 | F46: =$E46*vpg_28 -> 27.351 | G46: =$E46*vpg_29 -> 27.351 | H46: 架數 × ODM 每櫃價格；含 ASIC 機架（Assumed：每 GW 價值相同）
A47: AI 伺服器組裝市場（ODM 價，美元） | B47: US$B | D47: =D45*D46 -> 634.61653 | E47: =E45*E46 -> 1139.0807 | F47: =F45*F46 -> 1443.9178 | G47: =G45*G46 -> 1644.8506
A48: AI 伺服器組裝市場（新台幣） | B48: NT$B | D48: =D47*fx -> 20307.729 | E48: =E47*fx -> 36450.582 | F48: =F47*fx -> 46205.369 | G48: =G47*fx -> 52635.22
A49: 廣達有效份額（FY2026 校準）＝ AI 伺服器營收 ÷ 市場 | B49: % | D49: =a26_ai/D48 -> 0.13389612 | H49: Derived：分子為公司伺服器占比 × AI 占比 × 營收；分母含 ASIC、HGX 機架，所以低於整櫃櫃數份額
A50: 份額相對值（÷ FY2026） | B50: x | D50: =1 -> 1 | E50: =RLO_27 -> 0.85 | F50: =RLO_28 -> 0.75 | G50: =RLO_29 -> 0.7
A51: 廣達有效份額 | B51: % | D51: =$D$49*D50 -> 0.13389612 | E51: =$D$49*E50 -> 0.11381171 | F51: =$D$49*F50 -> 0.10042209 | G51: =$D$49*G50 -> 0.093727287
A52: AI 伺服器毛額價值（買賣模式下的營收） | B52: NT$B | D52: =D48*D51 -> 2719.1262 | E52: =E48*E51 -> 4148.5029 | F52: =F48*F51 -> 4640.0398 | G52: =G48*G51 -> 4933.3564
A53: 客供比例 | B53: % | D53: =0 -> 0 | E53: =cs_27 -> 0.1 | F53: =cs_28 -> 0.2 | G53: =cs_29 -> 0.25 | H53: FY2026 的少量客供已含在錨點與校準份額內，記為 0
A54: AI 伺服器營收 | B54: NT$B | C54: =a25_ai -> 905.033 | D54: =D52*(1-D53) -> 2719.1262 | E54: =E52*(1-E53) -> 3733.6526 | F54: =F52*(1-F53) -> 3712.0319 | G54: =G52*(1-G53) -> 3700.0173
A55: B. 非 AI 與合計
...

Sheet Sources
A1: 來源（公司原文只經法說摘要與新聞轉述，原始簡報待人工複核；券商與資料商皆為 Interested-party）
A2: 公司（摘要）：富果 2Q26 法說摘要 2026-08-13（1H26 損益、伺服器與 AI 占比、客供、產能、資本支出） | B2: https://blog.fugle.tw/post/earnings-call-2382-2026-08-13
A3: 公司（摘要）：優分析 2Q26 法說（AI 占伺服器 75–80%、全年約 80%、毛利率、能見度至 2028） | B3: https://uanalyze.com.tw/articles/5252953366
A4: 公司（摘要）：Taipei Times 2026-05-15（1Q26 毛利率 4.78%、客供轉換協商） | B4: https://www.taipeitimes.com/News/biz/archives/2026/05/15/2003857345
A5: 二手：優分析 2025 年財報（毛利率 6.98%、營益率 4.12%、淨利 749.8 億、EPS 19.45） | B5: https://uanalyze.com.tw/articles/3341848159
A6: 二手：財報狗 2026-10-08（3Q26 營收 1.1155 兆、前三季 2.9614 兆、VR 時程、筆電占比） | B6: https://statementdog.com/news/17848
A7: 券商：凱基 2026-08-13（2025A–2027F 營收、EPS、毛利率、營益率） | B7: https://www.kgi.com.hk/zh-cn/-/media/files/kgishk/research-reports/tw-reports/quanta-computer-2382-tt-20260813en.pdf
A8: 券商：工商時報 2026-10-08（法人 2027 營收 5.3 兆、EPS 32.09、GB300 與 VR 每櫃價格） | B8: https://www.ctee.com.tw/news/20261008700747-430201
A9: 券商：FTNN 2026-10-09（同上；Neocloud 繞過 OEM） | B9: https://www.ftnn.com.tw/news/585951
A10: 券商：經濟日報 2026-09-10（美系券商 NVL72 櫃數調查） | B10: https://money.udn.com/money/amp/story/5607/9745501
A11: 資料商：Yahoo 股市（10-22 收盤、近 12 月 P/E） | B11: https://tw.stock.yahoo.com/quote/2382.TW
A12: 資料商：companiesmarketcap 年底 P/E | B12: https://companiesmarketcap.com/quanta-computer/pe-ratio/
A13: 資料商：Goodinfo 歷年經營績效（年底收盤、EPS） | B13: https://goodinfo.tw/tw/StockBzPerformance.asp?STOCK_ID=2382&RPT_CAT=M_YEAR
A14: 市場層：markets/network、markets/chip_bridge、tsmc 成品（本 repo，唯讀）
A15: 待補（人工）：3Q26 法說（11 月中）；客戶占比（年報 10% 以上客戶，MOPS）；業外與稅前利益；客供比例的量化；前瞻 P/E 十年歷史（Bloomberg）；券商共識（付費） | B15: 未找到
A16: SemiAnalysis | B16: 未使用
A17: [Verified] 廣達 FY2025 年報：折舊與攤銷 120.81 億元、資本支出 147.57 億元、營業現金流 −103.65 億元（資料商轉載合併現金流量表） | B17: https://stockanalysis.com/quote/tpe/2382/financials/cash-flow-statement/
A18: [Assumed] FY2026 起折舊 ÷ 營收、資本支出 ÷ 營收沿用 FY2025 實績比率（In 頁 da_r、cx_r）；自由現金流不含營運資金變動 | B18: 本模型假設
