Workbook

Sheet README
A1: 旺矽（6223.TWO；MPI）個股模型 v0.1（AI 半導體 Project：測試介面） 2026-10-31
A2: 版本：v0.1（2026-10-31：初版）。探針卡（懸臂 CPC、垂直 VPC、MEMS）約占營收七成五，設備（AST 先進半導體測試、溫控、光電／CPO 測試）約兩成五。樣板 kyec/；行業變數讀 Siliconomics 快照 v0.10（20261031_Siliconomics_v0.10.xlsx）。
A3: 模型命題：AI 加速器（GPU、ASIC、HBM 相關）用的垂直與 MEMS 探針卡需求＝晶圓測試量（Siliconomics 加速器顆數 × 每顆測試時間係數，NVIDIA 部分再乘旺矽曝險）× 每顆探針卡內容 × 旺矽份額與價格相對值；其他探針卡依 Siliconomics 非 AI SoC 成長；設備分部依 Siliconomics SEMI 測試設備路徑與設備情境係數，另加 CPO 測試設備（Siliconomics 同字母 CPO 滲透率）。
A4: 核心問題：AI 探針卡的量（晶圓測試量）與價（MEMS 溢價、份額）能否支撐約 36 倍法人 FY2027 本益比；Technoprobe、FormFactor 擴產後份額與價格是否下滑。
A6: 會計年度＝日曆年，FY(t)＝CY(t)。預測期 FY2027–FY2029（三年）由驅動因子推導，FY2030–32 為收斂法。金額：十億新台幣；EPS：新台幣。口徑：歸屬母公司淨利。現價 4,610.00（2026-10-30 收盤）；其他模型仍用 10-22／10-23 收盤。
A8: 驅動因子 → 推導量（全部唯讀上游，不修改）
A9: AI／HPC 探針卡：FY2026 ＝ 探針卡 × 60%（Assumed）；之後 × 晶圓測試量指數（顆數 × 測試時間 × 曝險，Siliconomics）× 份額與價格相對值（Assumed，情境專屬）×（1＋每顆內容年增 5%）^年數。其他探針卡：非 AI SoC 年增 4%（Siliconomics）＋超額 3%。
A10: 設備：不含 CPO 的設備 FY2027 隨 SEMI 測試設備成長（Siliconomics），FY2028–29 依設備情境係數（A＝SEMI 路徑、B 持平、C 下滑兩成）；CPO 測試設備 FY2027 情境 A 為 12 億元（Assumed），依 Siliconomics 同字母 CPO 滲透率縮放。
A11: 毛利率：情境專屬（A 60%／61%、B 59.5%、C 58%／56.5%）；營業費用彈性 0.6；淨利 ÷ 營業利益 0.85；股數持平。
A12: 校準：FY2026 ＝ 1Q、2Q26 實績＋3Q26 營收實績（月營收）＋3Q26 毛利率 59.4%（公司說法）＋4Q26 營收季增 7.5%（指引 5–10%）。不用券商數字（只在 Recon 對帳）。
A13: 估值：Val 第 0 節目標價＝0.5 × DCF 目標價（股東現金流＝EPS ×（1 − g／ROE），FY2027–32 明確期＋永續，r 10%、g 4%，三情境權重 0.3／0.5／0.2）＋0.5 × Comparable 目標價（FormFactor、Advantest、泰瑞達、京元電前瞻 P/E 中位數 × 12 個月後前瞻 EPS；旺矽 Bloomberg 前瞻倍數待取，相對倍數係數＝1）。十年 P/E 規則值保留為參考。本版未做先驗，無 Andy 合理 P/E 對照。
A14: 預估期間：FY2027–FY2029 由驅動因子推導；FY2030 起為收斂法，非驅動因子推導（營收年增由 FY2029 線性收斂到 fade_g、淨利率收斂到 fade_m，FY2032 達到；PL 頁灰底）。
... A17: 已知限制：(1) AI 營收、VPC／MEMS 拆分與份額公司未揭露，AI 占探針卡六成為 Assumed；(2) 3Q26 損益尚未公布（約 11 月中），3Q26 只有營收是實績；(3) FY2025 營業利益未找到；(4) 產能（針數）未建模，情境 A 的成長可能超過公司擴產計畫；(5) CPO 測試設備金額為 Assumed；(6) 賣方共識未找到，以法人與 ALETHEIA 對照；(7) 十年 P/E 只有 2021–2025 五年、單一來源；(8) Bloomberg 前瞻倍數待取。
A19: ="投資建議："&Val!B50&"（依上檔空間固定規則）" -> 投資建議：放空（依上檔空間固定規則）
A20: ="重點觀察 1：目標價 NT$"&TEXT(Val!$B$39,"0.00")&"（DCF "&TEXT(Val!$B$24,"0.00")&"、Comparable（相對倍數調整後）"&TEXT(tp_comp_adj,"0.00")&"；DCF 權重 "&TEXT(tp_w_dcf,"0%")&"），比現價 "&TEXT(px,"0.00")&"（2026-10-30）"&IF(Val!$B$42>=0,"高 "&TEXT(Val!$B$42,"0.0%"),"低 "&TEXT(-Val!$B$42,"0.0%"))&"，級距 "&Val!$B$49&"、投資建議 "&Val!$B$50&"。相對倍數調整係數 "&TEXT(rm_factor,"0.00")&"（本公司 10 年前瞻倍數中位數 ÷ 同業的中位數，夾在 0.5–2.0；Val 第 0.5 節），調整前加權上檔空間 "&TEXT((tp_w_dcf*Val!$B$24+(1-tp_w_dcf)*Val!$B$35)/px-1,"+0.0%;−0.0%")&"；Comparable 單獨（市場主流同業法、未調整）為 "&TEXT(Val!$B$43,"+0.0%;−0.0%")&"。" -> 重點觀察 1：目標價 NT$2641.37（DCF 1994.80、Comparable（相對倍數調整後）3287.93；DCF 權重 50%），比現價 4610.00（2026-10-30）低 42.7%，級距 −25%～−50%、投資建議 放空。相對倍數調整係數 1.00（本公司 10 年前瞻倍數中位數 ÷ 同業的中位數，夾在 0.5–2.0；Val 第 0.5 節），調整前加權上檔空間 −42.7%；Comparable 單獨（市場主流同業法、未調整）為 −28.7%。
A21: 重點觀察 2：上檔空間低於 −25% 的主因是 EPS，不是倍數：本模型 12 個月後前瞻 EPS 108.4 比 ALETHEIA 同口徑 269.8 低 59.8%（FY2027 情境 B 102.3 也比法人 128.95 低 21%），而 ALETHEIA 目標價 10,000 隱含 37.1 倍、只比同業中位數 30.3 倍高 22%；現價 ÷ FY2027 EPS 42.3／45.1／49.9 倍（A／B／C），情境 B 的 FY2028 EPS 只比 FY2027 多 3%（顆數 ×0.8）。
A22: 重點觀察 3：AI／HPC 探針卡 FY2027 需較 FY2026 成長 85%／77%／63%（A／B／C；晶圓測試量指數 1.68 × 份額與價格相對值 × 內容），已高於公司「2027 產能增幅不低於 2026 約五成」的計畫，產能是上檔的瓶頸；最敏感的是 AI 部署 ±20%（加權目標價 ±12.4%）與每顆內容成長（−7.1%／+7.8%）。下一個檢驗點是 3Q26 財報與法說（約 11 月中）的毛利率是否回到 59.4%，以及 10 月營收（11-10 前）。
A24: 相對倍數調整（Val 第 0.5 節）：旺矽本身沒有 Bloomberg 前瞻倍數（tools/data/fwd_mult_hist.csv 無 6223），調整係數自動取 1.0（不調整）；Bloomberg 前瞻倍數待取。重點觀察 1 的第一句為公式。
A26: v0.1（2026-10-31）：依個股模型原則第 8 節調整 In 頁呈現（數值不變）。In 頁 D／F 欄名改「敏感度低」「敏感度高」（只用於 Sens 頁、不進目標價）；In 頁最後新增「情境驅動對照」一節，把上方各情境專屬輸入三情境並排（只引用上方各列，純展示）；HTML 驅動因子一節分「情境驅動」與「單一參數」兩張表。

Sheet In
A1: In — 輸入（藍字；基準欄 E，低 D、高 F）。金額：十億新台幣（NT$B）；顆數：百萬顆；比例：%。每個輸入附兩個來源（找不到者寫「未找到」）；公司原文算一個。【v0.1】基準欄 E 進主模型；D／F＝敏感度低／高，只用於 Sens 頁（一次動一個參數）、不進目標價；情境 A／B／C 的驅動見本頁最後一節「情境驅動對照」。
A2: 標記：Verified／Interested-party／Analogy／Assumed／Derived；Analogy、Assumed 給低／高區間（放 Sens），情境專屬列不給區間。SemiAnalysis 未使用。公司原文＝公開資訊觀測站月營收與季報；法說內容經富果、口袋學堂等摘要；公司指引與說法為 Interested-party；券商與媒體為 Interested-party
A3: 鍵 | B3: 項目 | C3: 單位 | D3: 敏感度低 | E3: 基準 | F3: 敏感度高 | G3: 標記 | H3: 來源1 | I3: 來源2／說明
A4: A. AI 加速器顆數、情境係數與晶圓測試量（讀 Siliconomics 快照 v0.10（20261031_Siliconomics_v0.10.xlsx）；唯讀，不自行重估）
A5: units_26 | B5: AI 加速器顆數 2026（情境 A 基準） | C5: 百萬顆 | E5: 15.2 | G5: Derived | H5: Siliconomics SIF_UnitsPlat_Total_A（八類加速器合計） | I5: 與台積電、日月光、京元電模型同一份
A6: units_27 | B6: AI 加速器顆數 2027（情境 A 基準） | C6: 百萬顆 | E6: 23.7 | G6: Derived | H6: 同上 | I6: 同上
A7: units_28 | B7: AI 加速器顆數 2028（情境 A 基準） | C7: 百萬顆 | E7: 26.5 | G7: Derived | H7: 同上 | I7: 同上
A8: units_29 | B8: AI 加速器顆數 2029（情境 A 基準） | C8: 百萬顆 | E8: 30.15 | G8: Derived | H8: 同上 | I8: 同上
A9: um28_A | B9: 情境 A：2028 顆數 ÷ 基準 | C9: x | E9: 1 | G9: Assumed | H9: Siliconomics um28_A（同字母行業情境） | I9: A＝基準；B＝AI 資本支出消化；C＝明顯下修
A10: um29_A | B10: 情境 A：2029 顆數 ÷ 基準 | C10: x | E10: 1 | G10: Assumed | H10: Siliconomics um29_A（同字母行業情境） | I10: 同上
A11: um28_B | B11: 情境 B：2028 顆數 ÷ 基準 | C11: x | E11: 0.8 | G11: Assumed | H11: Siliconomics um28_B（同字母行業情境） | I11: 同上
A12: um29_B | B12: 情境 B：2029 顆數 ÷ 基準 | C12: x | E12: 0.85 | G12: Assumed | H12: Siliconomics um29_B（同字母行業情境） | I12: 同上
A13: um28_C | B13: 情境 C：2028 顆數 ÷ 基準 | C13: x | E13: 0.6 | G13: Assumed | H13: Siliconomics um28_C（同字母行業情境） | I13: 同上
A14: um29_C | B14: 情境 C：2029 顆數 ÷ 基準 | C14: x | E14: 0.6 | G14: Assumed | H14: Siliconomics um29_C（同字母行業情境） | I14: 同上
A15: nvtt_26 | B15: NVIDIA 加速器的測試時間加權顆數 ÷ 總顆數 2026 | C15: x | E15: 0.520395 | G15: Derived | H15: Siliconomics 平台顆數 SIF_UnitsPlat_bw／rb／ru／hp × 每顆測試時間係數 ts_tt_*（Blackwell＝1） | I15: 晶圓測試量的代理：測試時間越長、探針卡耗用越多（Analogy：京元電、Advantest 模型同係數）
A16: astt_26 | B16: ASIC 與 AMD 的測試時間 × 旺矽曝險加權顆數 ÷ 總顆數 2026 | C16: x | E16: 0.399836 | G16: Derived | H16: Siliconomics 平台顆數 × ts_tt_*；旺矽曝險 AMD 0.3、TPU 1.0、Trainium 0.8、其他 ASIC 1.0（Assumed，本模型） | I16: 媒體：旺矽為多數 CSP 委外 AI ASIC 探針卡主要供應商，平均份額逾六成（傳聞；財訊 2026-10-12）
... A22: astt_29 | B22: ASIC 與 AMD 的測試時間 × 旺矽曝險加權顆數 ÷ 總顆數 2029 | C22: x | E22: 0.498905 | G22: Derived | H22: 同上 | I22: 同上
A23: ex_nv | B23: 旺矽對 NVIDIA 加速器的曝險（ASIC＝1） | C23: x | D23: 0.2 | E23: 0.4 | F23: 0.7 | G23: Assumed | H23: 財訊 2026-10-12：客戶含 Broadcom、Marvell、NVIDIA（媒體） | I23: NVIDIA 探針卡主力為 FormFactor、Technoprobe（產業常識；量化：未找到）
A24: g_nonai | B24: 非 AI SoC 市場年增（其他探針卡的行業成長） | C24: % | D24: 0 | E24: 0.04 | F24: 0.08 | G24: Assumed | H24: Siliconomics ts_g_nonai（v0.10） | I24: 其他探針卡＝CPC、手機 AP、網通、車用
A25: cpo_A_27 | B25: 情境 A：CPO 占 scale-out 光學金額 2027 | C25: % | E25: 0.05 | G25: Assumed | H25: Siliconomics cpo_A_27（技術替代屬行業情境，同字母） | I25: 旺矽 CPO 測試設備營收依此滲透率相對 2027 情境 A 縮放
A26: cpo_A_28 | B26: 情境 A：CPO 占 scale-out 光學金額 2028 | C26: % | E26: 0.1 | G26: Assumed | H26: Siliconomics cpo_A_28（技術替代屬行業情境，同字母） | I26: 同上
A27: cpo_A_29 | B27: 情境 A：CPO 占 scale-out 光學金額 2029 | C27: % | E27: 0.16 | G27: Assumed | H27: Siliconomics cpo_A_29（技術替代屬行業情境，同字母） | I27: 同上
A28: cpo_B_27 | B28: 情境 B：CPO 占 scale-out 光學金額 2027 | C28: % | E28: 0.03 | G28: Assumed | H28: Siliconomics cpo_B_27（技術替代屬行業情境，同字母） | I28: 同上
A29: cpo_B_28 | B29: 情境 B：CPO 占 scale-out 光學金額 2028 | C29: % | E29: 0.05 | G29: Assumed | H29: Siliconomics cpo_B_28（技術替代屬行業情境，同字母） | I29: 同上
A30: cpo_B_29 | B30: 情境 B：CPO 占 scale-out 光學金額 2029 | C30: % | E30: 0.08 | G30: Assumed | H30: Siliconomics cpo_B_29（技術替代屬行業情境，同字母） | I30: 同上
A31: cpo_C_27 | B31: 情境 C：CPO 占 scale-out 光學金額 2027 | C31: % | E31: 0.02 | G31: Assumed | H31: Siliconomics cpo_C_27（技術替代屬行業情境，同字母） | I31: 同上
A32: cpo_C_28 | B32: 情境 C：CPO 占 scale-out 光學金額 2028 | C32: % | E32: 0.03 | G32: Assumed | H32: Siliconomics cpo_C_28（技術替代屬行業情境，同字母） | I32: 同上
A33: cpo_C_29 | B33: 情境 C：CPO 占 scale-out 光學金額 2029 | C33: % | E33: 0.05 | G33: Assumed | H33: Siliconomics cpo_C_29（技術替代屬行業情境，同字母） | I33: 同上
A34: cpo_A_26 | B34: 情境 A：CPO 占 scale-out 光學金額 2026（三情境相同） | C34: % | E34: 0.01 | G34: Assumed | H34: Siliconomics cpo_A_26（B、C 同值） | I34: —
A35: semi_27 | B35: SEMI 測試設備 2027 ÷ 2026（情境 A 設備路徑） | C35: x | E35: 1.165966 | G35: Derived | H35: Siliconomics SIF_SEMI_Test（2025–2029） | I35: 設備分部的行業成長（SoC、記憶體測試設備合計）
A36: semi_28 | B36: SEMI 測試設備 2028 ÷ 2026（情境 A 設備路徑） | C36: x | E36: 1.359477 | G36: Derived | H36: 同上 | I36: 同上
... A43: eqk29_C | B43: 情境 C：設備水準 2029 ÷ 2027 | C43: x | E43: 1 | G43: Assumed | H43: Siliconomics eq_ck_C_29（設備情境係數，套用於 2027 水準；與 markets/equipment 同口徑） | I43: —
A44: B. 探針卡分部：AI／HPC 探針卡（VPC、MEMS）＝ AI_26 × 晶圓測試量指數 × 旺矽份額與價格相對值 × 每顆內容成長；其他探針卡依非 AI SoC 成長
A45: ai_sh25 | B45: AI／HPC 探針卡 ÷ 探針卡營收 FY2025 | C45: % | E45: 0.55 | G45: Assumed | H45: 公司：VPC 需求主要來自 AI／HPC；VPC 產能 2H25 起滿載（2025-03 法說，富果） | I45: AI 占比公司未揭露：未找到
A46: ai_sh26 | B46: AI／HPC 探針卡 ÷ 探針卡營收 FY2026（校準） | C46: % | D46: 0.45 | E46: 0.6 | F46: 0.7 | G46: Assumed | H46: 財訊 2026-10-12：法人預估 VPC 逾探針卡營收六成、高階探針卡約占營收五成（媒體，2026-10-12） | I46: FY2026 只影響拆分；AI 與其他的成長差異使 FY2027 起受影響
A47: rel27_A | B47: 情境 A：旺矽份額與價格相對值 2027（2026＝1） | C47: x | E47: 1.05 | G47: Assumed | H47: 數位時代 2026-06-13（ALETHEIA）：AI／HPC 客戶的垂直 MEMS 探針卡單價可高出平均五成以上；ALETHEIA 估旺矽需擴產約四倍（媒體轉述券商，2026-06-13） | I47: A＝新客戶（美系 CPU、NVIDIA）與價格；B＝維持；C＝Technoprobe、FormFactor 兩年內針產能倍增（同上）後份額與價格下滑
A48: rel28_A | B48: 情境 A：旺矽份額與價格相對值 2028（2026＝1） | C48: x | E48: 1.08 | G48: Assumed | H48: 同上 | I48: 同上
A49: rel29_A | B49: 情境 A：旺矽份額與價格相對值 2029（2026＝1） | C49: x | E49: 1.1 | G49: Assumed | H49: 同上 | I49: 同上
A50: rel27_B | B50: 情境 B：旺矽份額與價格相對值 2027（2026＝1） | C50: x | E50: 1 | G50: Assumed | H50: 同上 | I50: 同上
A51: rel28_B | B51: 情境 B：旺矽份額與價格相對值 2028（2026＝1） | C51: x | E51: 1 | G51: Assumed | H51: 同上 | I51: 同上
...

Sheet Q
A1: Q — 實績與 FY2026 錨點（十億新台幣；EPS 為新台幣；股數為百萬股）。藍字＝輸入（公司月營收、季報與法說）；黑字＝公式。事業別＝公司法說揭露的探針卡、設備、其他占比 × 營收
A2: v0.1（2026-10-31）：FY2026 錨點＝1Q、2Q26 實績＋3Q26 營收實績（月營收：前三季 15.068 − 1H26 9.166）＋3Q26 損益依公司說法（毛利率回到 59.4%）＋4Q26 依指引（季增 5–10% 取 7.5%）。3Q26 財報約 11 月中公布
A3: 項目 | B3: FY2025A | C3: 1Q26（實績） | D3: 2Q26（實績） | E3: 3Q26（營收實績） | F3: 4Q26（模型） | G3: FY2026 錨點 | H3: 標記 | I3: 來源1（公司） | J3: 來源2／說明
A4: 營收 | B4: 13.377 | C4: 3.933 | D4: 5.233 | E4: =15.068-9.166 -> 5.902 | F4: =E4*(1+q4_g) -> 6.34465 | G4: =SUM(C4:F4) -> 21.41265 | H4: Verified／Interested-party（4Q） | I4: FY2025、1Q26：公司法說（富果 2026-03、2026-05）；2Q26：口袋學堂 2026-09-08；3Q26 營收：公司月營收（科技新報 2026-10-08） | J4: FY2025 13.377（+31.5%）；1H26 9.166；前三季 15.068（+58.0%）
A5: 探針卡 | B5: =B4*0.738 -> 9.872226 | C5: =C4*0.711 -> 2.796363 | D5: =D4*0.747 -> 3.909051 | E5: =E4*q3_pcsh -> 4.4265 | F5: =F4*q4_pcsh -> 4.7584875 | G5: =SUM(C5:F5) -> 15.890401 | H5: Derived（占比 × 營收） | I5: FY2025、1Q26：公司法說（富果 2026-03、2026-05）；2Q26：口袋學堂 2026-09-08；3Q26 營收：公司月營收（科技新報 2026-10-08） | J5: 占比：FY2025 73.8%（富果；口袋學堂另載 72.2%）、1Q26 71.1%、2Q26 74.7%
A6: AI／HPC 探針卡（VPC、MEMS；命題子列） | B6: =B5*ai_sh25 -> 5.4297243 | C6: =C5*ai_sh26 -> 1.6778178 | D6: =D5*ai_sh26 -> 2.3454306 | E6: =E5*ai_sh26 -> 2.6559 | F6: =F5*ai_sh26 -> 2.8550925 | G6: =SUM(C6:F6) -> 9.5342409 | H6: Assumed（占比） | I6: FY2025、1Q26：公司法說（富果 2026-03、2026-05）；2Q26：口袋學堂 2026-09-08；3Q26 營收：公司月營收（科技新報 2026-10-08） | J6: AI 占比公司未揭露
A7: 其他探針卡（CPC 等） | B7: =B5-B6 -> 4.4425017 | C7: =C5-C6 -> 1.1185452 | D7: =D5-D6 -> 1.5636204 | E7: =E5-E6 -> 1.7706 | F7: =F5-F6 -> 1.903395 | G7: =SUM(C7:F7) -> 6.3561606 | H7: Derived | I7: — | J7: —
A8: 設備 | B8: =B4*0.246 -> 3.290742 | C8: =C4*0.269 -> 1.057977 | D8: =D4*0.233 -> 1.219289 | E8: =E4*(1-q3_pcsh-q3_oth) -> 1.35746 | F8: =F4*(1-q4_pcsh-q3_oth) -> 1.4592695 | G8: =SUM(C8:F8) -> 5.0939955 | H8: Derived（占比 × 營收） | I8: FY2025、1Q26：公司法說（富果 2026-03、2026-05）；2Q26：口袋學堂 2026-09-08；3Q26 營收：公司月營收（科技新報 2026-10-08） | J8: 占比：FY2025 24.6%、1Q26 26.9%、2Q26 23.3%（含 AST、溫控、光電）
A9: 其他 | B9: =B4-B5-B8 -> 0.214032 | C9: =C4*0.02 -> 0.07866 | D9: =D4-D5-D8 -> 0.10466 | E9: =E4*q3_oth -> 0.11804 | F9: =F4*q3_oth -> 0.126893 | G9: =SUM(C9:F9) -> 0.428253 | H9: Derived | I9: FY2025、1Q26：公司法說（富果 2026-03、2026-05）；2Q26：口袋學堂 2026-09-08；3Q26 營收：公司月營收（科技新報 2026-10-08） | J9: FY2025 約 1.6%、1Q26 2.0%
A10: 毛利 | B10: =B4*0.574 -> 7.678398 | C10: 2.338 | D10: =D4*0.5837 -> 3.0545021 | E10: =E4*q3_gm -> 3.505788 | F10: =F4*q4_gm -> 3.80679 | G10: =SUM(C10:F10) -> 12.70508 | H10: Verified／Interested-party | I10: FY2025、1Q26：公司法說（富果 2026-03、2026-05）；2Q26：口袋學堂 2026-09-08；3Q26 營收：公司月營收（科技新報 2026-10-08） | J10: FY2025 毛利率 57.4%（高盛，財訊 2026-10-12）；2Q26 58.37%（公司）
A11: 毛利率 | B11: =B10/B4 -> 0.574 | C11: =C10/C4 -> 0.59445716 | D11: =D10/D4 -> 0.5837 | E11: =E10/E4 -> 0.594 | F11: =F10/F4 -> 0.6 | G11: =G10/G4 -> 0.59334459 | H11: Derived | I11: — | J11: —
A12: 營業費用（毛利 − 營業利益） | C12: =C10-C13 -> 1.065 | D12: =D10-D13 -> 1.2535021 | E12: =D12*(1+q_opx) -> 1.3287122 | F12: =E12*(1+q_opx) -> 1.408435 | G12: =SUM(C12:F12) -> 5.0556493 | H12: Derived | I12: — | J12: FY2025 營業利益：未找到
A13: 營業利益 | C13: 1.273 | D13: 1.801 | E13: =E10-E12 -> 2.1770758 | F13: =F10-F12 -> 2.398355 | G13: =SUM(C13:F13) -> 7.6494308 | H13: Verified／Derived | I13: FY2025、1Q26：公司法說（富果 2026-03、2026-05）；2Q26：口袋學堂 2026-09-08；3Q26 營收：公司月營收（科技新報 2026-10-08） | J13: —
A14: 淨利 ÷ 營業利益 | C14: =C15/C13 -> 0.96386489 | D14: =D15/D13 -> 0.84619656 | E14: =q_nioi -> 0.87 | F14: =q_nioi -> 0.87 | G14: =G15/G13 -> 0.88001643 | H14: Derived | I14: — | J14: —
A15: 歸屬母公司淨利 | B15: 3.18 | C15: 1.227 | D15: 1.524 | E15: =E13*E14 -> 1.8940559 | F15: =F13*F14 -> 2.0865689 | G15: =SUM(C15:F15) -> 6.7316248 | H15: Verified／Interested-party（FY2025） | I15: FY2025、1Q26：公司法說（富果 2026-03、2026-05）；2Q26：口袋學堂 2026-09-08；3Q26 營收：公司月營收（科技新報 2026-10-08） | J15: FY2025 3.18（+38.1%；富果摘要）；1H26 2.751
A16: 股數（百萬股） | B16: =B15/B18*1000 -> 94.953718 | C16: =C15/C18*1000 -> 97.92498 | D16: =D15/D18*1000 -> 98.006431 | E16: =D16 -> 98.006431 | F16: =D16 -> 98.006431 | G16: =AVERAGE(C16:F16) -> 97.986068 | H16: Derived | I16: 淨利 ÷ 公司揭露 EPS | J16: —
A17: EPS | B17: =B15/B16*1000 -> 33.49 | C17: =C15/C16*1000 -> 12.53 | D17: =D15/D16*1000 -> 15.55 | E17: =E15/E16*1000 -> 19.325833 | F17: =F15/F16*1000 -> 21.290122 | G17: =SUM(C17:F17) -> 68.695955 | H17: Derived | I17: 淨利 ÷ 股數；FY2026＝四季加總 | J17: —
A18: 公司揭露 EPS | B18: 33.49 | C18: 12.53 | D18: 15.55 | H18: Verified | I18: FY2025、1Q26：公司法說（富果 2026-03、2026-05）；2Q26：口袋學堂 2026-09-08；3Q26 營收：公司月營收（科技新報 2026-10-08） | J18: 1H26 28.08；4Q25 9.81
A20: FY2026 錨點的檢查（參考；校準未使用券商數字）
A21: FY2026 營收年增 | B21: =G4/B4-1 -> 0.60070644
A22: 3Q26 營收季增（指引 0–5%） | B22: =E4/D4-1 -> 0.12784254
A23: FY2026 探針卡年增 | B23: =G5/B5-1 -> 0.60960674
A24: FY2026 設備年增 | B24: =G8/B8-1 -> 0.54797778
A25: FY2026 營收 ÷ 券商區間中點 − 1 | B25: =G4/cons_rev26-1 -> -0.030663196
A26: 1H26 EPS 自算 − 公司 28.08（應約 0） | B26: =C17+D17-28.08 -> 0
A28: 檢查：分部合計 − 合併營收 | B28: =ROUND(B5+B8+B9-B4,6) -> 0 | C28: =ROUND(C5+C8+C9-C4,6) -> 0 | D28: =ROUND(D5+D8+D9-D4,6) -> 0 | E28: =ROUND(E5+E8+E9-E4,6) -> 0 | F28: =ROUND(F5+F8+F9-F4,6) -> 0 | G28: =ROUND(G5+G8+G9-G4,6) -> 0
A29: 分部原則第 3 條：事業別＝探針卡、設備、其他（公司法說揭露占比 × 營收）；分部宣告見 segments.json
A30: 檢查：AI＋其他探針卡 − 探針卡（命題子列合計） | B30: =ROUND(B6+B7-B5,6) -> 0 | C30: =ROUND(C6+C7-C5,6) -> 0 | D30: =ROUND(D6+D7-D5,6) -> 0 | E30: =ROUND(E6+E7-E5,6) -> 0 | F30: =ROUND(F6+F7-F5,6) -> 0 | G30: =ROUND(G6+G7-G5,6) -> 0

Sheet Units
A1: Units — AI 加速器顆數（Siliconomics）× 每顆測試時間 → 晶圓測試量 → 旺矽 AI／HPC 探針卡（情境 A）。SoC 測試機市場（Siliconomics SIF_TestSoCMkt_A）只作 Recon
A3: 項目 | B3: 單位 | C3: CY2026 | D3: CY2027 | E3: CY2028 | F3: CY2029 | G3: 說明
A4: AI 加速器顆數（情境 A） | B4: 百萬顆 | C4: =PL!D73 -> 15.2 | D4: =PL!E73 -> 23.7 | E4: =PL!F73 -> 26.5 | F4: =PL!G73 -> 30.15 | G4: Siliconomics（台積電、日月光、京元電模型同一份）
A5: 每顆加權係數（測試時間 × 曝險） | B5: x | C5: =PL!D74 -> 0.607994 | D5: =PL!E74 -> 0.6560764 | E5: =PL!F74 -> 0.6898114 | F5: =PL!G74 -> 0.692935 | G5: Siliconomics ts_tt_*；曝險為本模型 Assumed
A6: 晶圓測試量指數（2026＝1） | B6: x | C6: =PL!D75 -> 1 | D6: =PL!E75 -> 1.6825186 | E6: =PL!F75 -> 1.9780322 | F6: =PL!G75 -> 2.2606688 | G6: 顆數 × 係數
A7: 份額與價格相對值 | B7: x | C7: =PL!D76 -> 1 | D7: =PL!E76 -> 1.05 | E7: =PL!F76 -> 1.08 | F7: =PL!G76 -> 1.1 | G7: Assumed（情境 A）
A8: 每顆探針卡內容指數 | B8: x | C8: =PL!D77 -> 1 | D8: =PL!E77 -> 1.05 | E8: =PL!F77 -> 1.1025 | F8: =PL!G77 -> 1.157625 | G8: Assumed
A9: 旺矽 AI／HPC 探針卡營收 | B9: NT$B | C9: =PL!D79 -> 9.5342409 | D9: =PL!E79 -> 17.685796 | E9: =PL!F79 -> 22.455454 | F9: =PL!G79 -> 27.446289 | G9: FY2026 × 指數 × 相對值 × 內容
A10: 每顆加速器的旺矽 AI 探針卡營收 | B10: NT$／顆 | C10: =PL!D79/PL!D73*1000 -> 627.25269 | D10: =PL!E79/PL!E73*1000 -> 746.2361 | E10: =PL!F79/PL!F73*1000 -> 847.37561 | F10: =PL!G79/PL!G73*1000 -> 910.32469 | G10: 十億元 ÷ 百萬顆 × 1,000
A11: SoC 測試機市場（Siliconomics SIF_TestSoCMkt_A） | B11: US$B | C11: 11.5 | D11: 16.230952 | E11: 18.243087 | F11: 20.310748 | G11: Siliconomics 推導值（唯讀）
A12: 旺矽 AI 探針卡年增 | B12: % | D12: =D9/C9-1 -> 0.85497678 | E12: =E9/D9-1 -> 0.26968864 | F12: =F9/E9-1 -> 0.22225494 | G12: 對照下列 SoC 測試機市場年增
A13: SoC 測試機市場年增 | B13: % | C13: 0.66666667 | D13: =D11/C11-1 -> 0.41138713 | E13: =E11/D11-1 -> 0.123969 | F13: =F11/E11-1 -> 0.11333943 | G13: 測試機（設備）與探針卡（耗材）同受晶圓測試量驅動
A15: 讀法：AI／HPC 探針卡 FY2026 以 AI 占探針卡六成（Assumed）校準，不是公司揭露數字；晶圓測試量用 Siliconomics 的每顆測試時間係數加權，NVIDIA 部分再乘旺矽曝險 ex_nv。份額與價格相對值是 Assumed，只有相對變化影響 FY2027 起的營收。

Sheet PL
A1: PL — 旺矽損益（十億新台幣；EPS 新台幣；歸屬母公司）。FY2025A 實績、FY2026 錨點（1Q、2Q26 實績＋3Q26 營收實績＋假設；三情境相同），FY2027 起為模型。FY(t)＝CY(t)。三情境各一個完整推導區塊（本頁下方），頂端為摘要
A2: 灰底＝FY2030–FY2032 收斂法（上游只到 2029）：營收年增線性收斂到 fade_g、淨利率線性收斂到 fade_m（In 頁 H 節），非驅動因子推導
A3: 情境／項目 | B3: 單位 | C3: FY2025A | D3: FY2026（錨點） | E3: FY2027 | F3: FY2028 | G3: FY2029 | H3: FY2030（收斂） | I3: FY2031（收斂） | J3: FY2032（收斂） | K3: 說明
A4: 情境 A
A5: 營收 | B5: NT$B | C5: =C86 -> 13.377 | D5: =D86 -> 21.41265 | E5: =E86 -> 31.796147 | F5: =F86 -> 39.203665 | G5: =G86 -> 46.695419 | H5: =H86 -> 53.578272 | I5: =I86 -> 59.134309 | J5: =J86 -> 62.682368
A6: 營收年增 | B6: % | D6: =D87 -> 0.60070644 | E6: =E87 -> 0.48492348 | F6: =F87 -> 0.23296905 | G6: =G87 -> 0.19109833 | H6: =H87 -> 0.14739888 | I6: =I87 -> 0.10369944 | J6: =J87 -> 0.06
A7: 探針卡 | B7: NT$B | C7: =C81 -> 9.872226 | D7: =D81 -> 15.890401 | E7: =E81 -> 24.486887 | F7: =F81 -> 29.732622 | G7: =G81 -> 35.232859
A8: AI／HPC 探針卡 | B8: NT$B | C8: =C79 -> 5.4297243 | D8: =D79 -> 9.5342409 | E8: =E79 -> 17.685796 | F8: =F79 -> 22.455454 | G8: =G79 -> 27.446289
A9: AI／HPC 探針卡 ÷ 營收 | B9: % | C9: =C88 -> 0.4059 | D9: =D88 -> 0.44526207 | E9: =E88 -> 0.55622449 | F9: =F88 -> 0.57278966 | G9: =G88 -> 0.58777262
A10: 設備 | B10: NT$B | C10: =C84 -> 3.290742 | D10: =D84 -> 5.0939955 | E10: =E84 -> 6.8595937 | F10: =F84 -> 8.9988938 | G10: =G84 -> 10.966804
A11: CPO 測試設備 | B11: NT$B | D11: =D82 -> 0.24 | E11: =E82 -> 1.2 | F11: =F82 -> 2.4 | G11: =G82 -> 3.84
A12: 毛利率 | B12: % | C12: =C91 -> 0.574 | D12: =D91 -> 0.59334459 | E12: =E91 -> 0.6 | F12: =F91 -> 0.61 | G12: =G91 -> 0.61
A13: 營業利益率 | B13: % | D13: =D95 -> 0.35723887 | E13: =E95 -> 0.39473578 | F13: =F95 -> 0.42024962 | G13: =G95 -> 0.43242695
A14: 歸屬母公司淨利 | B14: NT$B | C14: =C96 -> 3.18 | D14: =D96 -> 6.7316248 | E14: =E96 -> 10.668415 | F14: =F96 -> 14.004027 | G14: =G96 -> 17.163504 | H14: =H96 -> 19.693385 | I14: =I96 -> 21.735579 | J14: =J96 -> 23.039713
A15: 淨利率 | B15: % | C15: =C100 -> 0.23772146 | D15: =D100 -> 0.31437607 | E15: =E100 -> 0.33552542 | F15: =F100 -> 0.35721218 | G15: =G100 -> 0.36756291 | H15: =H100 -> 0.36756291 | I15: =I100 -> 0.36756291 | J15: =J100 -> 0.36756291
A16: EPS | B16: NT$ | C16: =C98 -> 33.49 | D16: =D98 -> 68.695955 | E16: =E98 -> 108.87686 | F16: =F98 -> 142.91855 | G16: =G98 -> 175.1627 | H16: =H98 -> 200.98148 | I16: =I98 -> 221.82315 | J16: =J98 -> 235.13254
A17: EPS 年增 | B17: % | D17: =D99 -> 1.0512378 | E17: =E99 -> 0.58490932 | F17: =F99 -> 0.31266229 | G17: =G99 -> 0.22561208 | H17: =H99 -> 0.14739888 | I17: =I99 -> 0.10369944 | J17: =J99 -> 0.06
A19: 情境 B
A20: 營收 | B20: NT$B | C20: =C119 -> 13.377 | D20: =D119 -> 21.41265 | E20: =E119 -> 30.473966 | F20: =F119 -> 31.24258 | G20: =G119 -> 36.787437 | H20: =H119 -> 41.630565 | I20: =I119 -> 45.203544 | J20: =J119 -> 47.011685
A21: 營收年增 | B21: % | D21: =D120 -> 0.60070644 | E21: =E120 -> 0.42317583 | F21: =F120 -> 0.025221999 | G21: =G120 -> 0.17747754 | H21: =H120 -> 0.1316517 | I21: =I120 -> 0.085825848 | J21: =J120 -> 0.04
A22: 探針卡 | B22: NT$B | C22: =C114 -> 9.872226 | D22: =D114 -> 15.890401 | E22: =E114 -> 23.644707 | F22: =F114 -> 23.910838 | G22: =G114 -> 28.995066
A23: AI／HPC 探針卡 | B23: NT$B | C23: =C112 -> 5.4297243 | D23: =D112 -> 9.5342409 | E23: =E112 -> 16.843615 | F23: =F112 -> 16.633669 | G23: =G112 -> 21.208496
A24: AI／HPC 探針卡 ÷ 營收 | B24: % | C24: =C121 -> 0.4059 | D24: =D121 -> 0.44526207 | E24: =E121 -> 0.55272145 | F24: =F121 -> 0.53240383 | G24: =G121 -> 0.57651465
A25: 設備 | B25: NT$B | C25: =C117 -> 3.290742 | D25: =D117 -> 5.0939955 | E25: =E117 -> 6.3795937 | F25: =F117 -> 6.8595937 | G25: =G117 -> 7.296614
A26: CPO 測試設備 | B26: NT$B | D26: =D115 -> 0.24 | E26: =E115 -> 0.72 | F26: =F115 -> 1.2 | G26: =G115 -> 1.92
A27: 毛利率 | B27: % | C27: =C124 -> 0.574 | D27: =D124 -> 0.59334459 | E27: =E124 -> 0.595 | F27: =F124 -> 0.595 | G27: =G124 -> 0.595
A28: 營業利益率 | B28: % | D28: =D128 -> 0.35723887 | E28: =E128 -> 0.38697632 | F28: =F128 -> 0.3890234 | G28: =G128 -> 0.40144189
A29: 歸屬母公司淨利 | B29: NT$B | C29: =C129 -> 3.18 | D29: =D129 -> 6.7316248 | E29: =E129 -> 10.023798 | F29: =F129 -> 10.330981 | G29: =G129 -> 12.552815 | H29: =H129 -> 13.731901 | I29: =I129 -> 14.396299 | J29: =J129 -> 14.437432
A30: 淨利率 | B30: % | C30: =C133 -> 0.23772146 | D30: =D133 -> 0.31437607 | E30: =E133 -> 0.32892987 | F30: =F133 -> 0.33066989 | G30: =G133 -> 0.3412256 | H30: =H133 -> 0.32985142 | I30: =I133 -> 0.31847723 | J30: =J133 -> 0.30710304
A31: EPS | B31: NT$ | C31: =C131 -> 33.49 | D31: =D131 -> 68.695955 | E31: =E131 -> 102.29819 | F31: =F131 -> 105.43316 | G31: =G131 -> 128.10816 | H31: =H131 -> 140.14136 | I31: =I131 -> 146.9219 | J31: =J131 -> 147.34168
A32: EPS 年增 | B32: % | D32: =D132 -> 1.0512378 | E32: =E132 -> 0.48914436 | F32: =F132 -> 0.030645352 | G32: =G132 -> 0.21506523 | H32: =H132 -> 0.093929972 | I32: =I132 -> 0.048383577 | J32: =J132 -> 0.0028571429
A34: 情境 C
A35: 營收 | B35: NT$B | C35: =C152 -> 13.377 | D35: =D152 -> 21.41265 | E35: =E152 -> 28.886477 | F35: =F152 -> 23.975214 | G35: =G152 -> 27.867018 | H35: =H152 -> 31.068495 | I35: =I152 -> 33.163818 | J35: =J152 -> 33.827094
A36: 營收年增 | B36: % | D36: =D153 -> 0.60070644 | E36: =E153 -> 0.34903792 | F36: =F153 -> -0.17001945 | G36: =G153 -> 0.16232614 | H36: =H153 -> 0.11488409 | I36: =I153 -> 0.067442046 | J36: =J153 -> 0.02
A37: 探針卡 | B37: NT$B | C37: =C147 -> 9.872226 | D37: =D147 -> 15.890401 | E37: =E147 -> 22.297217 | F37: =F147 -> 18.25539 | G37: =G147 -> 20.511668
A38: AI／HPC 探針卡 | B38: NT$B | C38: =C145 -> 5.4297243 | D38: =D145 -> 9.5342409 | E38: =E145 -> 15.496126 | F38: =F145 -> 10.978222 | G38: =G145 -> 12.725098
A39: AI／HPC 探針卡 ÷ 營收 | B39: % | C39: =C154 -> 0.4059 | D39: =D154 -> 0.44526207 | E39: =E154 -> 0.53644914 | F39: =F154 -> 0.4578988 | G39: =G154 -> 0.45663651
A40: 設備 | B40: NT$B | C40: =C150 -> 3.290742 | D40: =D150 -> 5.0939955 | E40: =E150 -> 6.1395937 | F40: =F150 -> 5.247675 | G40: =G150 -> 6.8595937
A41: CPO 測試設備 | B41: NT$B | D41: =D148 -> 0.24 | E41: =E148 -> 0.48 | F41: =F148 -> 0.72 | G41: =G148 -> 1.2
A42: 毛利率 | B42: % | C42: =C157 -> 0.574 | D42: =D157 -> 0.59334459 | E42: =E157 -> 0.58 | F42: =F157 -> 0.565 | G42: =G157 -> 0.565
...

Sheet Val
A1: Val — P/E 估值（新台幣）。結論用「現價 ÷ FY2027、FY2028 EPS（模型）」；目標價＝DCF 與 Comparable 加權（第 0 節）；十年 P/E 規則值（第 3 節，年底落後 P/E）只作參考
A2: 循環位置：旺矽以探針卡（耗材）為主、設備約占四分之一，不套設備市場見頂年；比照京元電，以本模型營收最高的會計年度為見頂年（FY(t)＝CY(t)）。營收到 FY2029 仍在增加時，見頂年未知，判為中段
A4: 0. 目標價
A5: 0.1 DCF（股東權益現金流，FY2027–FY2032 明確期＋FY2032 後永續）
A6: 項目 | B6: A（順利） | C6: B（平平） | D6: C（不如預期） | E6: 說明
A7: 情境 EPS（FY2027–FY2032） | E7: PL 頁各情境；FY2030 起為收斂法
A8: FY2027 | B8: =PL!E16 -> 108.87686 | C8: =PL!E31 -> 102.29819 | D8: =PL!E46 -> 92.296574
A9: FY2028 | B9: =PL!F16 -> 142.91855 | C9: =PL!F31 -> 105.43316 | D9: =PL!F46 -> 69.87751
A10: FY2029 | B10: =PL!G16 -> 175.1627 | C10: =PL!G31 -> 128.10816 | D10: =PL!G46 -> 84.313092
A11: FY2030 | B11: =PL!H16 -> 200.98148 | C11: =PL!H31 -> 140.14136 | D11: =PL!H46 -> 87.732704
A12: FY2031 | B12: =PL!I16 -> 221.82315 | C12: =PL!I31 -> 146.9219 | D12: =PL!I46 -> 86.960321
A13: FY2032 | B13: =PL!J16 -> 235.13254 | C13: =PL!J31 -> 147.34168 | D13: =PL!J46 -> 81.876487
A14: 股東現金流＝EPS ×（1 − tp_g ÷ tp_roe）
A15: 再投資率（tp_g ÷ tp_roe，上限 0.8） | B15: =MIN(tp_g/tp_roe,0.8) -> 0.15433455 | E15: ROE 為近三年平均（In 頁 tp_roe）
A16: FY2027 | B16: =B8*(1-$B$15) -> 92.073398 | C16: =C8*(1-$B$15) -> 86.510048 | D16: =D8*(1-$B$15) -> 78.052023
A17: FY2028 | B17: =B9*(1-$B$15) -> 120.86128 | C17: =C9*(1-$B$15) -> 89.161179 | D17: =D9*(1-$B$15) -> 59.092996
A18: FY2029 | B18: =B10*(1-$B$15) -> 148.12904 | C18: =C10*(1-$B$15) -> 108.33665 | D18: =D10*(1-$B$15) -> 71.300669
A19: FY2030 | B19: =B11*(1-$B$15) -> 169.9631 | C19: =C11*(1-$B$15) -> 118.51271 | D19: =D11*(1-$B$15) -> 74.192516
A20: FY2031 | B20: =B12*(1-$B$15) -> 187.58818 | C20: =C12*(1-$B$15) -> 124.24677 | D20: =D12*(1-$B$15) -> 73.539339
A21: FY2032 | B21: =B13*(1-$B$15) -> 198.84347 | C21: =C13*(1-$B$15) -> 124.60177 | D21: =D13*(1-$B$15) -> 69.240116
A22: DCF 情境每股價值（折現率 tp_r） | B22: =MAX(0,SUMPRODUCT(B16:B21,1/(1+tp_r)^{1;2;3;4;5;6})+B21*(1+tp_g)/(tp_r-tp_g)/(1+tp_r)^6) -> 2585.2137 | C22: =MAX(0,SUMPRODUCT(C16:C21,1/(1+tp_r)^{1;2;3;4;5;6})+C21*(1+tp_g)/(tp_r-tp_g)/(1+tp_r)^6) -> 1681.2855 | D22: =MAX(0,SUMPRODUCT(D16:D21,1/(1+tp_r)^{1;2;3;4;5;6})+D21*(1+tp_g)/(tp_r-tp_g)/(1+tp_r)^6) -> 986.24386 | E22: Σ 明確期現金流 ÷ (1＋r)^t ＋ 永續價值 ÷ (1＋r)^6；永續價值＝FY2032 現金流 ×(1＋g)÷(r−g)；基準日 2026 年底；下限 0
A23: DCF 情境價值推到 12 個月後（×(1＋tp_r)） | B23: =B22*(1+tp_r) -> 2843.7351 | C23: =C22*(1+tp_r) -> 1849.414 | D23: =D22*(1+tp_r) -> 1084.8682
A24: DCF 目標價（情境加權） | B24: =tp_wA*B23+tp_wB*C23+tp_wC*D23 -> 1994.8012 | E24: Σ 權重 × 情境價值 ×(1＋r)；權重見 In 頁
A26: 0.2 Comparable（市場主流同業前瞻 P/E）
A27: 同業與前瞻 P/E | B27: 代號 | C27: 前瞻 12 月 P/E | D27: 日期 | E27: 來源 | F27: 標記
A28: FormFactor | B28: FORM | C28: 28.17 | D28: 2026-10-23 | E28: stockanalysis.com forward PE（分析師共識；價格日期如左；與泰瑞達、Amkor 模型同一組數字） | F28: Interested-party
A29: Advantest | B29: 6857.T | C29: 37.69 | D29: 2026-10-21 | E29: stockanalysis.com forward PE（分析師共識；價格日期如左；與泰瑞達、Amkor 模型同一組數字） | F29: Interested-party
A30: 泰瑞達（Teradyne） | B30: TER | C30: 32.52 | D30: 2026-10-23 | E30: stockanalysis.com forward PE（分析師共識；價格日期如左；與泰瑞達、Amkor 模型同一組數字） | F30: Interested-party
A31: 京元電子（KYEC） | B31: 2449.TW | C31: 26.13 | D31: 2026-10-06 | E31: stockanalysis.com forward PE（分析師共識；價格日期如左；與泰瑞達、Amkor 模型同一組數字） | F31: Interested-party
A33: 同業前瞻 P/E 中位數 | B33: =MEDIAN(C28:C31) -> 30.345 | E33: 測試介面與測試同業：FormFactor（探針卡）、Advantest、泰瑞達（測試機）、京元電（測試）；Technoprobe、精測不在 Bloomberg 檔，未納入
A34: 12 個月後的前瞻 EPS（情境加權） | B34: =tp_wA*(2/12*B8+10/12*B9)+tp_wB*(2/12*C8+10/12*C9)+tp_wC*(2/12*D8+10/12*D9) -> 108.35162 | E34: 約 2027-10 時的未來 12 月 EPS ≈ 2／12 × FY2027＋10／12 × FY2028（會計年度＝日曆年）
A35: Comparable 目標價 | B35: =B33*B34 -> 3287.9298 | E35: 同業中位數 × 前瞻 EPS
A37: 0.3 結論
A38: 項目 | B38: 數值 | E38: 說明
A39: 目標價（DCF 與 Comparable 加權） | B39: =tp_w_dcf*B24+(1-tp_w_dcf)*tp_comp_adj -> 2641.3655 | E39: tp_w_dcf × DCF＋（1 − tp_w_dcf）× Comparable（相對倍數調整後，Val 第 0.5 節）；tp_w_dcf 見 In 頁
A40: Comparable 目標價（市場主流同業法） | B40: =B35 -> 3287.9298
A41: 市場共識目標價 | B41: =cons_tp -> 10000 | E41: 賣方平均：未找到；以 ALETHEIA 10,000（2026-06-13，單一券商）代替
A42: 上檔空間：加權目標價 | B42: =B39/px-1 -> -0.42703569 | E42: 現價＝In 頁 px（2026-10-30 收盤）
A43: 上檔空間：Comparable 目標價 | B43: =B40/px-1 -> -0.28678312
A44: 與市場共識目標價的差距：EPS 因素 | B44: =B34/cons_feps-1 -> -0.59844985 | E44: 本模型 12 個月後前瞻 EPS ÷ ALETHEIA 同口徑前瞻 EPS − 1（In 頁 cons_feps）
...

Sheet Recon
A1: Recon — 本模型 vs 公司指引、券商預估與市場口徑。只作事後對照，不為對上數字而調參數。賣方共識未找到，以法人（財訊 2026-10-12 轉述）與 ALETHEIA（單一券商）對照
A3: 項目 | B3: 對照值 | C3: 模型 A | D3: 差距 A | E3: 模型 B | F3: 差距 B | G3: 模型 C | H3: 差距 C | I3: 對照來源 | J3: 說明
A4: A. FY2026 錨點 vs 公司指引與券商
A5: 3Q26 營收季增 vs 公司指引中點 2.5%（百分點） | B5: 0.025 | C5: =Q!E4/Q!D4-1 -> 0.12784254 | D5: =C5-B5 -> 0.10284254 | E5: =Q!E4/Q!D4-1 -> 0.12784254 | F5: =E5-B5 -> 0.10284254 | G5: =Q!E4/Q!D4-1 -> 0.12784254 | H5: =G5-B5 -> 0.10284254 | I5: 2Q26 法說（口袋學堂）：0–5% | J5: 5 月法說曾為 +10–15%
A6: FY2026 營收 vs 券商區間中點 | B6: =cons_rev26 -> 22.09 | C6: =PL!D86 -> 21.41265 | D6: =C6/B6-1 -> -0.030663196 | E6: =PL!D119 -> 21.41265 | F6: =E6/B6-1 -> -0.030663196 | G6: =PL!D152 -> 21.41265 | H6: =G6/B6-1 -> -0.030663196 | I6: 券商 20.38–23.80（8/17）
A7: FY2026 EPS vs 法人 | B7: =cons_eps26 -> 64.79 | C7: =PL!D98 -> 68.695955 | D7: =C7/B7-1 -> 0.06028639 | E7: =PL!D131 -> 68.695955 | F7: =E7/B7-1 -> 0.06028639 | G7: =PL!D164 -> 68.695955 | H7: =G7/B7-1 -> 0.06028639 | I7: 財訊 2026-10-12 | J7: 口袋學堂：券商 60.89–70.84
A8: FY2027 EPS vs 法人 | B8: =cons_eps27 -> 128.95 | C8: =PL!E98 -> 108.87686 | D8: =C8/B8-1 -> -0.15566607 | E8: =PL!E131 -> 102.29819 | F8: =E8/B8-1 -> -0.20668326 | G8: =PL!E164 -> 92.296574 | H8: =G8/B8-1 -> -0.28424526 | I8: 財訊 2026-10-12
A9: FY2027 EPS vs ALETHEIA | B9: =al_eps27 -> 186.5 | C9: =PL!E98 -> 108.87686 | D9: =C9/B9-1 -> -0.41620987 | E9: =PL!E131 -> 102.29819 | F9: =E9/B9-1 -> -0.45148421 | G9: =PL!E164 -> 92.296574 | H9: =G9/B9-1 -> -0.5051122 | I9: 數位時代 2026-06-13 | J9: 看多券商；差距超過 30% 時 README 說明
A10: FY2028 EPS vs ALETHEIA | B10: =al_eps28 -> 286.5 | C10: =PL!F98 -> 142.91855 | D10: =C10/B10-1 -> -0.5011569 | E10: =PL!F131 -> 105.43316 | F10: =E10/B10-1 -> -0.63199596 | G10: =PL!F164 -> 69.87751 | H10: =G10/B10-1 -> -0.75609944 | I10: 同上
A11: B. 晶圓測試量與 SoC 測試機市場（Siliconomics）
A12: FY2027 AI 探針卡年增 vs SoC 測試機市場年增（同字母情境，百分點） | C12: =PL!E79/PL!D79-1-(16.2309519650655/11.5-1) -> 0.44358966 | E12: =PL!E112/PL!D112-1-(16.2309519650655/11.5-1) -> 0.35525743 | G12: =PL!E145/PL!D145-1-(16.2309519650655/11.5-1) -> 0.21392586 | I12: Siliconomics SIF_TestSoCMkt_A／B／C | J12: 正值＝探針卡成長快於測試機市場
A13: FY2028 AI 探針卡年增 vs SoC 測試機市場年增（同字母情境，百分點） | C13: =PL!F79/PL!E79-1-(18.2430869197178/16.2309519650655-1) -> 0.14571964 | E13: =PL!F112/PL!E112-1-(15.5246455357743/16.2309519650655-1) -> 0.031051631 | G13: =PL!F145/PL!E145-1-(12.8062041518307/16.2309519650655-1) -> -0.080549496 | I13: Siliconomics SIF_TestSoCMkt_A／B／C | J13: 正值＝探針卡成長快於測試機市場
A14: FY2029 AI 探針卡年增 vs SoC 測試機市場年增（同字母情境，百分點） | C14: =PL!G79/PL!F79-1-(20.3107479175008/18.2430869197178-1) -> 0.10891552 | E14: =PL!G112/PL!F112-1-(17.9896730098757/15.5246455357743-1) -> 0.11625257 | G14: =PL!G145/PL!F145-1-(14.1212148305005/12.8062041518307-1) -> 0.056436501 | I14: Siliconomics SIF_TestSoCMkt_A／B／C | J14: 正值＝探針卡成長快於測試機市場
A15: FY2026 每顆加速器的旺矽 AI 探針卡營收（NT$） | C15: =Units!C10 -> 627.25269 | E15: =Units!C10 -> 627.25269 | G15: =Units!C10 -> 627.25269 | I15: — | J15: 對照：京元電每顆 Blackwell 等值測試營收 US$46.9（京元電模型）
A16: C. 產能
A17: FY2027 AI 探針卡 ÷ FY2026（公司：2027 產能增幅不低於 2026 的約五成） | B17: 1.5 | C17: =PL!E79/PL!D79 -> 1.8549768 | D17: =C17/B17-1 -> 0.23665119 | E17: =PL!E112/PL!D112 -> 1.7666446 | F17: =E17/B17-1 -> 0.17776304 | G17: =PL!E145/PL!D145 -> 1.625313 | H17: =G17/B17-1 -> 0.083541995 | I17: 2026-05 法說（富果）：VPC 月產能 200 萬針、MEMS 350 萬針（2026 年底） | J17: 比值高於 1.5 表示需要比公司計畫更多的產能或漲價

Sheet Sens
A1: Sens — 一次動一個輸入（三情境同時重算，再依情境權重求 DCF 與 Comparable 目標價）：對 FY2027、FY2028 EPS（情境 B）與加權目標價的影響。每個案例的三情境推導區塊在本頁下方
A2: 註：情境專屬列（份額與價格相對值、毛利率、CPO 滲透率、設備情境係數、顆數係數）不給敏感度區間，差異見情境 B、C。ai_sh26（AI 占探針卡）改的是 FY2026 錨點拆分，案例區塊以 FY2026 探針卡 × 低／高占比重算拆分（錨點合計不變）；Comparable 欄已乘相對倍數調整係數（rm_factor）。
A3: 案例 | B3: 鍵 | C3: 設定 | D3: FY2027 EPS（B） | E3: FY2028 EPS（B） | F3: FY2028 EPS（B）相對基準 | G3: DCF 目標價 | H3: Comparable 目標價 | I3: 加權目標價 | J3: 加權目標價相對基準
A4: 基準 | B4: — | C4: PL 三情境 | D4: =PL!E131 -> 102.29819 | E4: =PL!F131 -> 105.43316 | F4: =E4/E$4-1 -> 0 | G4: =(tp_wA*MAX(0,PL!E98*(1-MIN(tp_g/tp_roe,0.8))/(1+tp_r)^1+PL!F98*(1-MIN(tp_g/tp_roe,0.8))/(1+tp_r)^2+PL!G98*(1-MIN(tp_g/tp_roe,0.8))/(1+tp_r)^3+PL!H98*(1-MIN(tp_g/tp_roe,0.8))/(1+tp_r)^4+PL!I98*(1-MIN(tp_g/tp_roe,0.8))/(1+tp_r)^5+PL!J98*(1-MIN(tp_g/tp_roe,0.8))/(1+tp_r)^6+PL!J98*(1-MIN(tp_g/tp_roe,0.8))*(1+tp_g)/(tp_r-tp_g)/(1+tp_r)^6)+tp_wB*MAX(0,PL!E131*(1-MIN(tp_g/tp_roe,0.8))/(1+tp_r)^1+PL!F131*(1-MIN(tp_g/tp_roe,0.8))/(1+tp_r)^2+PL!G131*(1-MIN(tp_g/tp_roe,0.8))/(1+tp_r)^3+PL!H131*(1-MIN(tp_g/tp_roe,0.8))/(1+tp_r)^4+PL!I131*(1-MIN(tp_g/tp_roe,0.8))/(1+tp_r)^5+PL!J131*(1-MIN(tp_g/tp_roe,0.8))/(1+tp_r)^6+PL!J131*(1-MIN(tp_g/tp_roe,0.8))*(1+tp_g)/(tp_r-tp_g)/(1+tp_r)^6)+tp_wC*MAX(0,PL!E164*(1-MIN(tp_g/tp_roe,0.8))/(1+tp_r)^1+PL!F164*(1-MIN(tp_g/tp_roe,0.8))/(1+tp_r)^2+PL!G164*(1-MIN(tp_g/tp_roe,0.8))/(1+tp_r)^3+PL!H164*(1-MIN(tp_g/tp_roe,0.8))/(1+tp_r)^4+PL!I164*(1-MIN(tp_g/tp_roe,0.8))/(1+tp_r)^5+PL!J164*(1-MIN(tp_g/tp_roe,0.8))/(1+tp_r)^6+PL!J164*(1-MIN(tp_g/tp_roe,0.8))*(1+tp_g)/(tp_r-tp_g)/(1+tp_r)^6))*(1+tp_r) -> 1994.8012 | H4: =Val!$B$33*(tp_wA*(2/12*PL!E98+10/12*PL!F98)+tp_wB*(2/12*PL!E131+10/12*PL!F131)+tp_wC*(2/12*PL!E164+10/12*PL!F164))*rm_factor -> 3287.9298 | I4: =tp_w_dcf*G4+(1-tp_w_dcf)*H4 -> 2641.3655 | J4: =I4/I$4-1 -> 0
A5: AI 部署 ×0.8 | B5: mf | C5: FY2027 起顆數 ×0.8（三情境） | D5: =E181 -> 89.050489 | E5: =F181 -> 92.321919 | F5: =E5/E$4-1 -> -0.12435594 | G5: =(tp_wA*MAX(0,E148*(1-MIN(tp_g/tp_roe,0.8))/(1+tp_r)^1+F148*(1-MIN(tp_g/tp_roe,0.8))/(1+tp_r)^2+G148*(1-MIN(tp_g/tp_roe,0.8))/(1+tp_r)^3+H148*(1-MIN(tp_g/tp_roe,0.8))/(1+tp_r)^4+I148*(1-MIN(tp_g/tp_roe,0.8))/(1+tp_r)^5+J148*(1-MIN(tp_g/tp_roe,0.8))/(1+tp_r)^6+J148*(1-MIN(tp_g/tp_roe,0.8))*(1+tp_g)/(tp_r-tp_g)/(1+tp_r)^6)+tp_wB*MAX(0,E181*(1-MIN(tp_g/tp_roe,0.8))/(1+tp_r)^1+F181*(1-MIN(tp_g/tp_roe,0.8))/(1+tp_r)^2+G181*(1-MIN(tp_g/tp_roe,0.8))/(1+tp_r)^3+H181*(1-MIN(tp_g/tp_roe,0.8))/(1+tp_r)^4+I181*(1-MIN(tp_g/tp_roe,0.8))/(1+tp_r)^5+J181*(1-MIN(tp_g/tp_roe,0.8))/(1+tp_r)^6+J181*(1-MIN(tp_g/tp_roe,0.8))*(1+tp_g)/(tp_r-tp_g)/(1+tp_r)^6)+tp_wC*MAX(0,E214*(1-MIN(tp_g/tp_roe,0.8))/(1+tp_r)^1+F214*(1-MIN(tp_g/tp_roe,0.8))/(1+tp_r)^2+G214*(1-MIN(tp_g/tp_roe,0.8))/(1+tp_r)^3+H214*(1-MIN(tp_g/tp_roe,0.8))/(1+tp_r)^4+I214*(1-MIN(tp_g/tp_roe,0.8))/(1+tp_r)^5+J214*(1-MIN(tp_g/tp_roe,0.8))/(1+tp_r)^6+J214*(1-MIN(tp_g/tp_roe,0.8))*(1+tp_g)/(tp_r-tp_g)/(1+tp_r)^6))*(1+tp_r) -> 1752.9523 | H5: =Val!$B$33*(tp_wA*(2/12*E148+10/12*F148)+tp_wB*(2/12*E181+10/12*F181)+tp_wC*(2/12*E214+10/12*F214))*rm_factor -> 2874.4781 | I5: =tp_w_dcf*G5+(1-tp_w_dcf)*H5 -> 2313.7152 | J5: =I5/I$4-1 -> -0.12404579
A6: AI 部署 ×1.2 | B6: mf | C6: ×1.2 | D6: =E280 -> 115.5459 | E6: =F280 -> 118.53458 | F6: =E6/E$4-1 -> 0.12426285 | G6: =(tp_wA*MAX(0,E247*(1-MIN(tp_g/tp_roe,0.8))/(1+tp_r)^1+F247*(1-MIN(tp_g/tp_roe,0.8))/(1+tp_r)^2+G247*(1-MIN(tp_g/tp_roe,0.8))/(1+tp_r)^3+H247*(1-MIN(tp_g/tp_roe,0.8))/(1+tp_r)^4+I247*(1-MIN(tp_g/tp_roe,0.8))/(1+tp_r)^5+J247*(1-MIN(tp_g/tp_roe,0.8))/(1+tp_r)^6+J247*(1-MIN(tp_g/tp_roe,0.8))*(1+tp_g)/(tp_r-tp_g)/(1+tp_r)^6)+tp_wB*MAX(0,E280*(1-MIN(tp_g/tp_roe,0.8))/(1+tp_r)^1+F280*(1-MIN(tp_g/tp_roe,0.8))/(1+tp_r)^2+G280*(1-MIN(tp_g/tp_roe,0.8))/(1+tp_r)^3+H280*(1-MIN(tp_g/tp_roe,0.8))/(1+tp_r)^4+I280*(1-MIN(tp_g/tp_roe,0.8))/(1+tp_r)^5+J280*(1-MIN(tp_g/tp_roe,0.8))/(1+tp_r)^6+J280*(1-MIN(tp_g/tp_roe,0.8))*(1+tp_g)/(tp_r-tp_g)/(1+tp_r)^6)+tp_wC*MAX(0,E313*(1-MIN(tp_g/tp_roe,0.8))/(1+tp_r)^1+F313*(1-MIN(tp_g/tp_roe,0.8))/(1+tp_r)^2+G313*(1-MIN(tp_g/tp_roe,0.8))/(1+tp_r)^3+H313*(1-MIN(tp_g/tp_roe,0.8))/(1+tp_r)^4+I313*(1-MIN(tp_g/tp_roe,0.8))/(1+tp_r)^5+J313*(1-MIN(tp_g/tp_roe,0.8))/(1+tp_r)^6+J313*(1-MIN(tp_g/tp_roe,0.8))*(1+tp_g)/(tp_r-tp_g)/(1+tp_r)^6))*(1+tp_r) -> 2236.8441 | H6: =Val!$B$33*(tp_wA*(2/12*E247+10/12*F247)+tp_wB*(2/12*E280+10/12*F280)+tp_wC*(2/12*E313+10/12*F313))*rm_factor -> 3701.1802 | I6: =tp_w_dcf*G6+(1-tp_w_dcf)*H6 -> 2969.0121 | J6: =I6/I$4-1 -> 0.12404441
A7: NVIDIA 曝險 0.2 | B7: ex_nv | C7: 基準 0.4（ASIC＝1） | D7: =E379 -> 103.63325 | E7: =F379 -> 107.75732 | F7: =E7/E$4-1 -> 0.022043978 | G7: =(tp_wA*MAX(0,E346*(1-MIN(tp_g/tp_roe,0.8))/(1+tp_r)^1+F346*(1-MIN(tp_g/tp_roe,0.8))/(1+tp_r)^2+G346*(1-MIN(tp_g/tp_roe,0.8))/(1+tp_r)^3+H346*(1-MIN(tp_g/tp_roe,0.8))/(1+tp_r)^4+I346*(1-MIN(tp_g/tp_roe,0.8))/(1+tp_r)^5+J346*(1-MIN(tp_g/tp_roe,0.8))/(1+tp_r)^6+J346*(1-MIN(tp_g/tp_roe,0.8))*(1+tp_g)/(tp_r-tp_g)/(1+tp_r)^6)+tp_wB*MAX(0,E379*(1-MIN(tp_g/tp_roe,0.8))/(1+tp_r)^1+F379*(1-MIN(tp_g/tp_roe,0.8))/(1+tp_r)^2+G379*(1-MIN(tp_g/tp_roe,0.8))/(1+tp_r)^3+H379*(1-MIN(tp_g/tp_roe,0.8))/(1+tp_r)^4+I379*(1-MIN(tp_g/tp_roe,0.8))/(1+tp_r)^5+J379*(1-MIN(tp_g/tp_roe,0.8))/(1+tp_r)^6+J379*(1-MIN(tp_g/tp_roe,0.8))*(1+tp_g)/(tp_r-tp_g)/(1+tp_r)^6)+tp_wC*MAX(0,E412*(1-MIN(tp_g/tp_roe,0.8))/(1+tp_r)^1+F412*(1-MIN(tp_g/tp_roe,0.8))/(1+tp_r)^2+G412*(1-MIN(tp_g/tp_roe,0.8))/(1+tp_r)^3+H412*(1-MIN(tp_g/tp_roe,0.8))/(1+tp_r)^4+I412*(1-MIN(tp_g/tp_roe,0.8))/(1+tp_r)^5+J412*(1-MIN(tp_g/tp_roe,0.8))/(1+tp_r)^6+J412*(1-MIN(tp_g/tp_roe,0.8))*(1+tp_g)/(tp_r-tp_g)/(1+tp_r)^6))*(1+tp_r) -> 2041.9012 | H7: =Val!$B$33*(tp_wA*(2/12*E346+10/12*F346)+tp_wB*(2/12*E379+10/12*F379)+tp_wC*(2/12*E412+10/12*F412))*rm_factor -> 3356.032 | I7: =tp_w_dcf*G7+(1-tp_w_dcf)*H7 -> 2698.9666 | J7: =I7/I$4-1 -> 0.021807312
A8: NVIDIA 曝險 0.7 | B8: ex_nv | D8: =E478 -> 100.97754 | E8: =F478 -> 103.13582 | F8: =E8/E$4-1 -> -0.021789528 | G8: =(tp_wA*MAX(0,E445*(1-MIN(tp_g/tp_roe,0.8))/(1+tp_r)^1+F445*(1-MIN(tp_g/tp_roe,0.8))/(1+tp_r)^2+G445*(1-MIN(tp_g/tp_roe,0.8))/(1+tp_r)^3+H445*(1-MIN(tp_g/tp_roe,0.8))/(1+tp_r)^4+I445*(1-MIN(tp_g/tp_roe,0.8))/(1+tp_r)^5+J445*(1-MIN(tp_g/tp_roe,0.8))/(1+tp_r)^6+J445*(1-MIN(tp_g/tp_roe,0.8))*(1+tp_g)/(tp_r-tp_g)/(1+tp_r)^6)+tp_wB*MAX(0,E478*(1-MIN(tp_g/tp_roe,0.8))/(1+tp_r)^1+F478*(1-MIN(tp_g/tp_roe,0.8))/(1+tp_r)^2+G478*(1-MIN(tp_g/tp_roe,0.8))/(1+tp_r)^3+H478*(1-MIN(tp_g/tp_roe,0.8))/(1+tp_r)^4+I478*(1-MIN(tp_g/tp_roe,0.8))/(1+tp_r)^5+J478*(1-MIN(tp_g/tp_roe,0.8))/(1+tp_r)^6+J478*(1-MIN(tp_g/tp_roe,0.8))*(1+tp_g)/(tp_r-tp_g)/(1+tp_r)^6)+tp_wC*MAX(0,E511*(1-MIN(tp_g/tp_roe,0.8))/(1+tp_r)^1+F511*(1-MIN(tp_g/tp_roe,0.8))/(1+tp_r)^2+G511*(1-MIN(tp_g/tp_roe,0.8))/(1+tp_r)^3+H511*(1-MIN(tp_g/tp_roe,0.8))/(1+tp_r)^4+I511*(1-MIN(tp_g/tp_roe,0.8))/(1+tp_r)^5+J511*(1-MIN(tp_g/tp_roe,0.8))/(1+tp_r)^6+J511*(1-MIN(tp_g/tp_roe,0.8))*(1+tp_g)/(tp_r-tp_g)/(1+tp_r)^6))*(1+tp_r) -> 1948.2444 | H8: =Val!$B$33*(tp_wA*(2/12*E445+10/12*F445)+tp_wB*(2/12*E478+10/12*F478)+tp_wC*(2/12*E511+10/12*F511))*rm_factor -> 3220.6083 | I8: =tp_w_dcf*G8+(1-tp_w_dcf)*H8 -> 2584.4264 | J8: =I8/I$4-1 -> -0.021556695
A9: AI 占探針卡 45% | B9: ai_sh26 | C9: FY2026 校準；基準 60% | D9: =E577 -> 95.768201 | E9: =F577 -> 99.825514 | F9: =E9/E$4-1 -> -0.053186725 | G9: =(tp_wA*MAX(0,E544*(1-MIN(tp_g/tp_roe,0.8))/(1+tp_r)^1+F544*(1-MIN(tp_g/tp_roe,0.8))/(1+tp_r)^2+G544*(1-MIN(tp_g/tp_roe,0.8))/(1+tp_r)^3+H544*(1-MIN(tp_g/tp_roe,0.8))/(1+tp_r)^4+I544*(1-MIN(tp_g/tp_roe,0.8))/(1+tp_r)^5+J544*(1-MIN(tp_g/tp_roe,0.8))/(1+tp_r)^6+J544*(1-MIN(tp_g/tp_roe,0.8))*(1+tp_g)/(tp_r-tp_g)/(1+tp_r)^6)+tp_wB*MAX(0,E577*(1-MIN(tp_g/tp_roe,0.8))/(1+tp_r)^1+F577*(1-MIN(tp_g/tp_roe,0.8))/(1+tp_r)^2+G577*(1-MIN(tp_g/tp_roe,0.8))/(1+tp_r)^3+H577*(1-MIN(tp_g/tp_roe,0.8))/(1+tp_r)^4+I577*(1-MIN(tp_g/tp_roe,0.8))/(1+tp_r)^5+J577*(1-MIN(tp_g/tp_roe,0.8))/(1+tp_r)^6+J577*(1-MIN(tp_g/tp_roe,0.8))*(1+tp_g)/(tp_r-tp_g)/(1+tp_r)^6)+tp_wC*MAX(0,E610*(1-MIN(tp_g/tp_roe,0.8))/(1+tp_r)^1+F610*(1-MIN(tp_g/tp_roe,0.8))/(1+tp_r)^2+G610*(1-MIN(tp_g/tp_roe,0.8))/(1+tp_r)^3+H610*(1-MIN(tp_g/tp_roe,0.8))/(1+tp_r)^4+I610*(1-MIN(tp_g/tp_roe,0.8))/(1+tp_r)^5+J610*(1-MIN(tp_g/tp_roe,0.8))/(1+tp_r)^6+J610*(1-MIN(tp_g/tp_roe,0.8))*(1+tp_g)/(tp_r-tp_g)/(1+tp_r)^6))*(1+tp_r) -> 1834.3506 | H9: =Val!$B$33*(tp_wA*(2/12*E544+10/12*F544)+tp_wB*(2/12*E577+10/12*F577)+tp_wC*(2/12*E610+10/12*F610))*rm_factor -> 3093.8542 | I9: =tp_w_dcf*G9+(1-tp_w_dcf)*H9 -> 2464.1024 | J9: =I9/I$4-1 -> -0.067110387
A10: AI 占探針卡 70% | B10: ai_sh26 | D10: =E676 -> 106.65152 | E10: =F676 -> 109.16576 | F10: =E10/E$4-1 -> 0.035402579 | G10: =(tp_wA*MAX(0,E643*(1-MIN(tp_g/tp_roe,0.8))/(1+tp_r)^1+F643*(1-MIN(tp_g/tp_roe,0.8))/(1+tp_r)^2+G643*(1-MIN(tp_g/tp_roe,0.8))/(1+tp_r)^3+H643*(1-MIN(tp_g/tp_roe,0.8))/(1+tp_r)^4+I643*(1-MIN(tp_g/tp_roe,0.8))/(1+tp_r)^5+J643*(1-MIN(tp_g/tp_roe,0.8))/(1+tp_r)^6+J643*(1-MIN(tp_g/tp_roe,0.8))*(1+tp_g)/(tp_r-tp_g)/(1+tp_r)^6)+tp_wB*MAX(0,E676*(1-MIN(tp_g/tp_roe,0.8))/(1+tp_r)^1+F676*(1-MIN(tp_g/tp_roe,0.8))/(1+tp_r)^2+G676*(1-MIN(tp_g/tp_roe,0.8))/(1+tp_r)^3+H676*(1-MIN(tp_g/tp_roe,0.8))/(1+tp_r)^4+I676*(1-MIN(tp_g/tp_roe,0.8))/(1+tp_r)^5+J676*(1-MIN(tp_g/tp_roe,0.8))/(1+tp_r)^6+J676*(1-MIN(tp_g/tp_roe,0.8))*(1+tp_g)/(tp_r-tp_g)/(1+tp_r)^6)+tp_wC*MAX(0,E709*(1-MIN(tp_g/tp_roe,0.8))/(1+tp_r)^1+F709*(1-MIN(tp_g/tp_roe,0.8))/(1+tp_r)^2+G709*(1-MIN(tp_g/tp_roe,0.8))/(1+tp_r)^3+H709*(1-MIN(tp_g/tp_roe,0.8))/(1+tp_r)^4+I709*(1-MIN(tp_g/tp_roe,0.8))/(1+tp_r)^5+J709*(1-MIN(tp_g/tp_roe,0.8))/(1+tp_r)^6+J709*(1-MIN(tp_g/tp_roe,0.8))*(1+tp_g)/(tp_r-tp_g)/(1+tp_r)^6))*(1+tp_r) -> 2102.347 | H10: =Val!$B$33*(tp_wA*(2/12*E643+10/12*F643)+tp_wB*(2/12*E676+10/12*F676)+tp_wC*(2/12*E709+10/12*F709))*rm_factor -> 3417.2336 | I10: =tp_w_dcf*G10+(1-tp_w_dcf)*H10 -> 2759.7903 | J10: =I10/I$4-1 -> 0.044834683
A11: 每顆內容年增 0% | B11: g_ct | C11: 基準 5% | D11: =E775 -> 99.143979 | E11: =F775 -> 99.242663 | F11: =E11/E$4-1 -> -0.058714884 | G11: =(tp_wA*MAX(0,E742*(1-MIN(tp_g/tp_roe,0.8))/(1+tp_r)^1+F742*(1-MIN(tp_g/tp_roe,0.8))/(1+tp_r)^2+G742*(1-MIN(tp_g/tp_roe,0.8))/(1+tp_r)^3+H742*(1-MIN(tp_g/tp_roe,0.8))/(1+tp_r)^4+I742*(1-MIN(tp_g/tp_roe,0.8))/(1+tp_r)^5+J742*(1-MIN(tp_g/tp_roe,0.8))/(1+tp_r)^6+J742*(1-MIN(tp_g/tp_roe,0.8))*(1+tp_g)/(tp_r-tp_g)/(1+tp_r)^6)+tp_wB*MAX(0,E775*(1-MIN(tp_g/tp_roe,0.8))/(1+tp_r)^1+F775*(1-MIN(tp_g/tp_roe,0.8))/(1+tp_r)^2+G775*(1-MIN(tp_g/tp_roe,0.8))/(1+tp_r)^3+H775*(1-MIN(tp_g/tp_roe,0.8))/(1+tp_r)^4+I775*(1-MIN(tp_g/tp_roe,0.8))/(1+tp_r)^5+J775*(1-MIN(tp_g/tp_roe,0.8))/(1+tp_r)^6+J775*(1-MIN(tp_g/tp_roe,0.8))*(1+tp_g)/(tp_r-tp_g)/(1+tp_r)^6)+tp_wC*MAX(0,E808*(1-MIN(tp_g/tp_roe,0.8))/(1+tp_r)^1+F808*(1-MIN(tp_g/tp_roe,0.8))/(1+tp_r)^2+G808*(1-MIN(tp_g/tp_roe,0.8))/(1+tp_r)^3+H808*(1-MIN(tp_g/tp_roe,0.8))/(1+tp_r)^4+I808*(1-MIN(tp_g/tp_roe,0.8))/(1+tp_r)^5+J808*(1-MIN(tp_g/tp_roe,0.8))/(1+tp_r)^6+J808*(1-MIN(tp_g/tp_roe,0.8))*(1+tp_g)/(tp_r-tp_g)/(1+tp_r)^6))*(1+tp_r) -> 1796.8043 | H11: =Val!$B$33*(tp_wA*(2/12*E742+10/12*F742)+tp_wB*(2/12*E775+10/12*F775)+tp_wC*(2/12*E808+10/12*F808))*rm_factor -> 3108.5951 | I11: =tp_w_dcf*G11+(1-tp_w_dcf)*H11 -> 2452.6997 | J11: =I11/I$4-1 -> -0.071427374
A12: 每顆內容年增 10% | B12: g_ct | D12: =E874 -> 105.45241 | E12: =F874 -> 111.94518 | F12: =E12/E$4-1 -> 0.061764459 | G12: =(tp_wA*MAX(0,E841*(1-MIN(tp_g/tp_roe,0.8))/(1+tp_r)^1+F841*(1-MIN(tp_g/tp_roe,0.8))/(1+tp_r)^2+G841*(1-MIN(tp_g/tp_roe,0.8))/(1+tp_r)^3+H841*(1-MIN(tp_g/tp_roe,0.8))/(1+tp_r)^4+I841*(1-MIN(tp_g/tp_roe,0.8))/(1+tp_r)^5+J841*(1-MIN(tp_g/tp_roe,0.8))/(1+tp_r)^6+J841*(1-MIN(tp_g/tp_roe,0.8))*(1+tp_g)/(tp_r-tp_g)/(1+tp_r)^6)+tp_wB*MAX(0,E874*(1-MIN(tp_g/tp_roe,0.8))/(1+tp_r)^1+F874*(1-MIN(tp_g/tp_roe,0.8))/(1+tp_r)^2+G874*(1-MIN(tp_g/tp_roe,0.8))/(1+tp_r)^3+H874*(1-MIN(tp_g/tp_roe,0.8))/(1+tp_r)^4+I874*(1-MIN(tp_g/tp_roe,0.8))/(1+tp_r)^5+J874*(1-MIN(tp_g/tp_roe,0.8))/(1+tp_r)^6+J874*(1-MIN(tp_g/tp_roe,0.8))*(1+tp_g)/(tp_r-tp_g)/(1+tp_r)^6)+tp_wC*MAX(0,E907*(1-MIN(tp_g/tp_roe,0.8))/(1+tp_r)^1+F907*(1-MIN(tp_g/tp_roe,0.8))/(1+tp_r)^2+G907*(1-MIN(tp_g/tp_roe,0.8))/(1+tp_r)^3+H907*(1-MIN(tp_g/tp_roe,0.8))/(1+tp_r)^4+I907*(1-MIN(tp_g/tp_roe,0.8))/(1+tp_r)^5+J907*(1-MIN(tp_g/tp_roe,0.8))/(1+tp_r)^6+J907*(1-MIN(tp_g/tp_roe,0.8))*(1+tp_g)/(tp_r-tp_g)/(1+tp_r)^6))*(1+tp_r) -> 2220.9478 | H12: =Val!$B$33*(tp_wA*(2/12*E841+10/12*F841)+tp_wB*(2/12*E874+10/12*F874)+tp_wC*(2/12*E907+10/12*F907))*rm_factor -> 3475.7363 | I12: =tp_w_dcf*G12+(1-tp_w_dcf)*H12 -> 2848.3421 | J12: =I12/I$4-1 -> 0.078359693
A13: 非 AI SoC 年增 0% | B13: g_nonai | C13: Siliconomics ts_g_nonai 低 | D13: =E973 -> 101.29835 | E13: =F973 -> 103.2912 | F13: =E13/E$4-1 -> -0.020315816 | G13: =(tp_wA*MAX(0,E940*(1-MIN(tp_g/tp_roe,0.8))/(1+tp_r)^1+F940*(1-MIN(tp_g/tp_roe,0.8))/(1+tp_r)^2+G940*(1-MIN(tp_g/tp_roe,0.8))/(1+tp_r)^3+H940*(1-MIN(tp_g/tp_roe,0.8))/(1+tp_r)^4+I940*(1-MIN(tp_g/tp_roe,0.8))/(1+tp_r)^5+J940*(1-MIN(tp_g/tp_roe,0.8))/(1+tp_r)^6+J940*(1-MIN(tp_g/tp_roe,0.8))*(1+tp_g)/(tp_r-tp_g)/(1+tp_r)^6)+tp_wB*MAX(0,E973*(1-MIN(tp_g/tp_roe,0.8))/(1+tp_r)^1+F973*(1-MIN(tp_g/tp_roe,0.8))/(1+tp_r)^2+G973*(1-MIN(tp_g/tp_roe,0.8))/(1+tp_r)^3+H973*(1-MIN(tp_g/tp_roe,0.8))/(1+tp_r)^4+I973*(1-MIN(tp_g/tp_roe,0.8))/(1+tp_r)^5+J973*(1-MIN(tp_g/tp_roe,0.8))/(1+tp_r)^6+J973*(1-MIN(tp_g/tp_roe,0.8))*(1+tp_g)/(tp_r-tp_g)/(1+tp_r)^6)+tp_wC*MAX(0,E1006*(1-MIN(tp_g/tp_roe,0.8))/(1+tp_r)^1+F1006*(1-MIN(tp_g/tp_roe,0.8))/(1+tp_r)^2+G1006*(1-MIN(tp_g/tp_roe,0.8))/(1+tp_r)^3+H1006*(1-MIN(tp_g/tp_roe,0.8))/(1+tp_r)^4+I1006*(1-MIN(tp_g/tp_roe,0.8))/(1+tp_r)^5+J1006*(1-MIN(tp_g/tp_roe,0.8))/(1+tp_r)^6+J1006*(1-MIN(tp_g/tp_roe,0.8))*(1+tp_g)/(tp_r-tp_g)/(1+tp_r)^6))*(1+tp_r) -> 1942.7684 | H13: =Val!$B$33*(tp_wA*(2/12*E940+10/12*F940)+tp_wB*(2/12*E973+10/12*F973)+tp_wC*(2/12*E1006+10/12*F1006))*rm_factor -> 3228.8557 | I13: =tp_w_dcf*G13+(1-tp_w_dcf)*H13 -> 2585.8121 | J13: =I13/I$4-1 -> -0.02103209
A14: 非 AI SoC 年增 8% | B14: g_nonai | C14: Siliconomics 高 | D14: =E1072 -> 103.29803 | E14: =F1072 -> 107.65971 | F14: =E14/E$4-1 -> 0.021118155 | G14: =(tp_wA*MAX(0,E1039*(1-MIN(tp_g/tp_roe,0.8))/(1+tp_r)^1+F1039*(1-MIN(tp_g/tp_roe,0.8))/(1+tp_r)^2+G1039*(1-MIN(tp_g/tp_roe,0.8))/(1+tp_r)^3+H1039*(1-MIN(tp_g/tp_roe,0.8))/(1+tp_r)^4+I1039*(1-MIN(tp_g/tp_roe,0.8))/(1+tp_r)^5+J1039*(1-MIN(tp_g/tp_roe,0.8))/(1+tp_r)^6+J1039*(1-MIN(tp_g/tp_roe,0.8))*(1+tp_g)/(tp_r-tp_g)/(1+tp_r)^6)+tp_wB*MAX(0,E1072*(1-MIN(tp_g/tp_roe,0.8))/(1+tp_r)^1+F1072*(1-MIN(tp_g/tp_roe,0.8))/(1+tp_r)^2+G1072*(1-MIN(tp_g/tp_roe,0.8))/(1+tp_r)^3+H1072*(1-MIN(tp_g/tp_roe,0.8))/(1+tp_r)^4+I1072*(1-MIN(tp_g/tp_roe,0.8))/(1+tp_r)^5+J1072*(1-MIN(tp_g/tp_roe,0.8))/(1+tp_r)^6+J1072*(1-MIN(tp_g/tp_roe,0.8))*(1+tp_g)/(tp_r-tp_g)/(1+tp_r)^6)+tp_wC*MAX(0,E1105*(1-MIN(tp_g/tp_roe,0.8))/(1+tp_r)^1+F1105*(1-MIN(tp_g/tp_roe,0.8))/(1+tp_r)^2+G1105*(1-MIN(tp_g/tp_roe,0.8))/(1+tp_r)^3+H1105*(1-MIN(tp_g/tp_roe,0.8))/(1+tp_r)^4+I1105*(1-MIN(tp_g/tp_roe,0.8))/(1+tp_r)^5+J1105*(1-MIN(tp_g/tp_roe,0.8))/(1+tp_r)^6+J1105*(1-MIN(tp_g/tp_roe,0.8))*(1+tp_g)/(tp_r-tp_g)/(1+tp_r)^6))*(1+tp_r) -> 2052.0654 | H14: =Val!$B$33*(tp_wA*(2/12*E1039+10/12*F1039)+tp_wB*(2/12*E1072+10/12*F1072)+tp_wC*(2/12*E1105+10/12*F1105))*rm_factor -> 3349.136 | I14: =tp_w_dcf*G14+(1-tp_w_dcf)*H14 -> 2700.6007 | J14: =I14/I$4-1 -> 0.022425995
A15: 其他探針卡超額成長 0% | B15: d_npc | C15: 基準 3% | D15: =E1171 -> 101.54831 | E15: =F1171 -> 103.81876 | F15: =E15/E$4-1 -> -0.015312011 | G15: =(tp_wA*MAX(0,E1138*(1-MIN(tp_g/tp_roe,0.8))/(1+tp_r)^1+F1138*(1-MIN(tp_g/tp_roe,0.8))/(1+tp_r)^2+G1138*(1-MIN(tp_g/tp_roe,0.8))/(1+tp_r)^3+H1138*(1-MIN(tp_g/tp_roe,0.8))/(1+tp_r)^4+I1138*(1-MIN(tp_g/tp_roe,0.8))/(1+tp_r)^5+J1138*(1-MIN(tp_g/tp_roe,0.8))/(1+tp_r)^6+J1138*(1-MIN(tp_g/tp_roe,0.8))*(1+tp_g)/(tp_r-tp_g)/(1+tp_r)^6)+tp_wB*MAX(0,E1171*(1-MIN(tp_g/tp_roe,0.8))/(1+tp_r)^1+F1171*(1-MIN(tp_g/tp_roe,0.8))/(1+tp_r)^2+G1171*(1-MIN(tp_g/tp_roe,0.8))/(1+tp_r)^3+H1171*(1-MIN(tp_g/tp_roe,0.8))/(1+tp_r)^4+I1171*(1-MIN(tp_g/tp_roe,0.8))/(1+tp_r)^5+J1171*(1-MIN(tp_g/tp_roe,0.8))/(1+tp_r)^6+J1171*(1-MIN(tp_g/tp_roe,0.8))*(1+tp_g)/(tp_r-tp_g)/(1+tp_r)^6)+tp_wC*MAX(0,E1204*(1-MIN(tp_g/tp_roe,0.8))/(1+tp_r)^1+F1204*(1-MIN(tp_g/tp_roe,0.8))/(1+tp_r)^2+G1204*(1-MIN(tp_g/tp_roe,0.8))/(1+tp_r)^3+H1204*(1-MIN(tp_g/tp_roe,0.8))/(1+tp_r)^4+I1204*(1-MIN(tp_g/tp_roe,0.8))/(1+tp_r)^5+J1204*(1-MIN(tp_g/tp_roe,0.8))/(1+tp_r)^6+J1204*(1-MIN(tp_g/tp_roe,0.8))*(1+tp_g)/(tp_r-tp_g)/(1+tp_r)^6))*(1+tp_r) -> 1955.3028 | H15: =Val!$B$33*(tp_wA*(2/12*E1138+10/12*F1138)+tp_wB*(2/12*E1171+10/12*F1171)+tp_wC*(2/12*E1204+10/12*F1204))*rm_factor -> 3243.4245 | I15: =tp_w_dcf*G15+(1-tp_w_dcf)*H15 -> 2599.3637 | J15: =I15/I$4-1 -> -0.015901553
A16: 其他探針卡超額成長 6% | B16: d_npc | D16: =E1270 -> 103.04807 | E16: =F1270 -> 107.09514 | F16: =E16/E$4-1 -> 0.015763327 | G16: =(tp_wA*MAX(0,E1237*(1-MIN(tp_g/tp_roe,0.8))/(1+tp_r)^1+F1237*(1-MIN(tp_g/tp_roe,0.8))/(1+tp_r)^2+G1237*(1-MIN(tp_g/tp_roe,0.8))/(1+tp_r)^3+H1237*(1-MIN(tp_g/tp_roe,0.8))/(1+tp_r)^4+I1237*(1-MIN(tp_g/tp_roe,0.8))/(1+tp_r)^5+J1237*(1-MIN(tp_g/tp_roe,0.8))/(1+tp_r)^6+J1237*(1-MIN(tp_g/tp_roe,0.8))*(1+tp_g)/(tp_r-tp_g)/(1+tp_r)^6)+tp_wB*MAX(0,E1270*(1-MIN(tp_g/tp_roe,0.8))/(1+tp_r)^1+F1270*(1-MIN(tp_g/tp_roe,0.8))/(1+tp_r)^2+G1270*(1-MIN(tp_g/tp_roe,0.8))/(1+tp_r)^3+H1270*(1-MIN(tp_g/tp_roe,0.8))/(1+tp_r)^4+I1270*(1-MIN(tp_g/tp_roe,0.8))/(1+tp_r)^5+J1270*(1-MIN(tp_g/tp_roe,0.8))/(1+tp_r)^6+J1270*(1-MIN(tp_g/tp_roe,0.8))*(1+tp_g)/(tp_r-tp_g)/(1+tp_r)^6)+tp_wC*MAX(0,E1303*(1-MIN(tp_g/tp_roe,0.8))/(1+tp_r)^1+F1303*(1-MIN(tp_g/tp_roe,0.8))/(1+tp_r)^2+G1303*(1-MIN(tp_g/tp_roe,0.8))/(1+tp_r)^3+H1303*(1-MIN(tp_g/tp_roe,0.8))/(1+tp_r)^4+I1303*(1-MIN(tp_g/tp_roe,0.8))/(1+tp_r)^5+J1303*(1-MIN(tp_g/tp_roe,0.8))/(1+tp_r)^6+J1303*(1-MIN(tp_g/tp_roe,0.8))*(1+tp_g)/(tp_r-tp_g)/(1+tp_r)^6))*(1+tp_r) -> 2037.2419 | H16: =Val!$B$33*(tp_wA*(2/12*E1237+10/12*F1237)+tp_wB*(2/12*E1270+10/12*F1270)+tp_wC*(2/12*E1303+10/12*F1303))*rm_factor -> 3333.6344 | I16: =tp_w_dcf*G16+(1-tp_w_dcf)*H16 -> 2685.4382 | J16: =I16/I$4-1 -> 0.01668556
A17: CPO 測試設備 0.5 | B17: k_cpo | C17: FY2027 情境 A；基準 1.2 | D17: =E1369 -> 101.28845 | E17: =F1369 -> 103.27994 | F17: =E17/E$4-1 -> -0.020422598 | G17: =(tp_wA*MAX(0,E1336*(1-MIN(tp_g/tp_roe,0.8))/(1+tp_r)^1+F1336*(1-MIN(tp_g/tp_roe,0.8))/(1+tp_r)^2+G1336*(1-MIN(tp_g/tp_roe,0.8))/(1+tp_r)^3+H1336*(1-MIN(tp_g/tp_roe,0.8))/(1+tp_r)^4+I1336*(1-MIN(tp_g/tp_roe,0.8))/(1+tp_r)^5+J1336*(1-MIN(tp_g/tp_roe,0.8))/(1+tp_r)^6+J1336*(1-MIN(tp_g/tp_roe,0.8))*(1+tp_g)/(tp_r-tp_g)/(1+tp_r)^6)+tp_wB*MAX(0,E1369*(1-MIN(tp_g/tp_roe,0.8))/(1+tp_r)^1+F1369*(1-MIN(tp_g/tp_roe,0.8))/(1+tp_r)^2+G1369*(1-MIN(tp_g/tp_roe,0.8))/(1+tp_r)^3+H1369*(1-MIN(tp_g/tp_roe,0.8))/(1+tp_r)^4+I1369*(1-MIN(tp_g/tp_roe,0.8))/(1+tp_r)^5+J1369*(1-MIN(tp_g/tp_roe,0.8))/(1+tp_r)^6+J1369*(1-MIN(tp_g/tp_roe,0.8))*(1+tp_g)/(tp_r-tp_g)/(1+tp_r)^6)+tp_wC*MAX(0,E1402*(1-MIN(tp_g/tp_roe,0.8))/(1+tp_r)^1+F1402*(1-MIN(tp_g/tp_roe,0.8))/(1+tp_r)^2+G1402*(1-MIN(tp_g/tp_roe,0.8))/(1+tp_r)^3+H1402*(1-MIN(tp_g/tp_roe,0.8))/(1+tp_r)^4+I1402*(1-MIN(tp_g/tp_roe,0.8))/(1+tp_r)^5+J1402*(1-MIN(tp_g/tp_roe,0.8))/(1+tp_r)^6+J1402*(1-MIN(tp_g/tp_roe,0.8))*(1+tp_g)/(tp_r-tp_g)/(1+tp_r)^6))*(1+tp_r) -> 1911.9129 | H17: =Val!$B$33*(tp_wA*(2/12*E1336+10/12*F1336)+tp_wB*(2/12*E1369+10/12*F1369)+tp_wC*(2/12*E1402+10/12*F1402))*rm_factor -> 3210.6237 | I17: =tp_w_dcf*G17+(1-tp_w_dcf)*H17 -> 2561.2683 | J17: =I17/I$4-1 -> -0.030324151
A18: CPO 測試設備 2.0 | B18: k_cpo | D18: =E1468 -> 103.45219 | E18: =F1468 -> 107.89593 | F18: =E18/E$4-1 -> 0.02335858 | G18: =(tp_wA*MAX(0,E1435*(1-MIN(tp_g/tp_roe,0.8))/(1+tp_r)^1+F1435*(1-MIN(tp_g/tp_roe,0.8))/(1+tp_r)^2+G1435*(1-MIN(tp_g/tp_roe,0.8))/(1+tp_r)^3+H1435*(1-MIN(tp_g/tp_roe,0.8))/(1+tp_r)^4+I1435*(1-MIN(tp_g/tp_roe,0.8))/(1+tp_r)^5+J1435*(1-MIN(tp_g/tp_roe,0.8))/(1+tp_r)^6+J1435*(1-MIN(tp_g/tp_roe,0.8))*(1+tp_g)/(tp_r-tp_g)/(1+tp_r)^6)+tp_wB*MAX(0,E1468*(1-MIN(tp_g/tp_roe,0.8))/(1+tp_r)^1+F1468*(1-MIN(tp_g/tp_roe,0.8))/(1+tp_r)^2+G1468*(1-MIN(tp_g/tp_roe,0.8))/(1+tp_r)^3+H1468*(1-MIN(tp_g/tp_roe,0.8))/(1+tp_r)^4+I1468*(1-MIN(tp_g/tp_roe,0.8))/(1+tp_r)^5+J1468*(1-MIN(tp_g/tp_roe,0.8))/(1+tp_r)^6+J1468*(1-MIN(tp_g/tp_roe,0.8))*(1+tp_g)/(tp_r-tp_g)/(1+tp_r)^6)+tp_wC*MAX(0,E1501*(1-MIN(tp_g/tp_roe,0.8))/(1+tp_r)^1+F1501*(1-MIN(tp_g/tp_roe,0.8))/(1+tp_r)^2+G1501*(1-MIN(tp_g/tp_roe,0.8))/(1+tp_r)^3+H1501*(1-MIN(tp_g/tp_roe,0.8))/(1+tp_r)^4+I1501*(1-MIN(tp_g/tp_roe,0.8))/(1+tp_r)^5+J1501*(1-MIN(tp_g/tp_roe,0.8))/(1+tp_r)^6+J1501*(1-MIN(tp_g/tp_roe,0.8))*(1+tp_g)/(tp_r-tp_g)/(1+tp_r)^6))*(1+tp_r) -> 2090.1697 | H18: =Val!$B$33*(tp_wA*(2/12*E1435+10/12*F1435)+tp_wB*(2/12*E1468+10/12*F1468)+tp_wC*(2/12*E1501+10/12*F1501))*rm_factor -> 3376.3645 | I18: =tp_w_dcf*G18+(1-tp_w_dcf)*H18 -> 2733.2671 | J18: =I18/I$4-1 -> 0.034793228
A19: 毛利率 −2pt | B19: gm_adj | C19: 三情境、FY2027 起 | D19: =E1567 -> 97.011142 | E19: =F1567 -> 100.01276 | F19: =E19/E$4-1 -> -0.051410789 | G19: =(tp_wA*MAX(0,E1534*(1-MIN(tp_g/tp_roe,0.8))/(1+tp_r)^1+F1534*(1-MIN(tp_g/tp_roe,0.8))/(1+tp_r)^2+G1534*(1-MIN(tp_g/tp_roe,0.8))/(1+tp_r)^3+H1534*(1-MIN(tp_g/tp_roe,0.8))/(1+tp_r)^4+I1534*(1-MIN(tp_g/tp_roe,0.8))/(1+tp_r)^5+J1534*(1-MIN(tp_g/tp_roe,0.8))/(1+tp_r)^6+J1534*(1-MIN(tp_g/tp_roe,0.8))*(1+tp_g)/(tp_r-tp_g)/(1+tp_r)^6)+tp_wB*MAX(0,E1567*(1-MIN(tp_g/tp_roe,0.8))/(1+tp_r)^1+F1567*(1-MIN(tp_g/tp_roe,0.8))/(1+tp_r)^2+G1567*(1-MIN(tp_g/tp_roe,0.8))/(1+tp_r)^3+H1567*(1-MIN(tp_g/tp_roe,0.8))/(1+tp_r)^4+I1567*(1-MIN(tp_g/tp_roe,0.8))/(1+tp_r)^5+J1567*(1-MIN(tp_g/tp_roe,0.8))/(1+tp_r)^6+J1567*(1-MIN(tp_g/tp_roe,0.8))*(1+tp_g)/(tp_r-tp_g)/(1+tp_r)^6)+tp_wC*MAX(0,E1600*(1-MIN(tp_g/tp_roe,0.8))/(1+tp_r)^1+F1600*(1-MIN(tp_g/tp_roe,0.8))/(1+tp_r)^2+G1600*(1-MIN(tp_g/tp_roe,0.8))/(1+tp_r)^3+H1600*(1-MIN(tp_g/tp_roe,0.8))/(1+tp_r)^4+I1600*(1-MIN(tp_g/tp_roe,0.8))/(1+tp_r)^5+J1600*(1-MIN(tp_g/tp_roe,0.8))/(1+tp_r)^6+J1600*(1-MIN(tp_g/tp_roe,0.8))*(1+tp_g)/(tp_r-tp_g)/(1+tp_r)^6))*(1+tp_r) -> 1976.6853 | H19: =Val!$B$33*(tp_wA*(2/12*E1534+10/12*F1534)+tp_wB*(2/12*E1567+10/12*F1567)+tp_wC*(2/12*E1600+10/12*F1600))*rm_factor -> 3119.9513 | I19: =tp_w_dcf*G19+(1-tp_w_dcf)*H19 -> 2548.3183 | J19: =I19/I$4-1 -> -0.035226932
A20: 毛利率 +2pt | B20: gm_adj | D20: =E1666 -> 107.58525 | E20: =F1666 -> 110.85356 | F20: =E20/E$4-1 -> 0.051410789 | G20: =(tp_wA*MAX(0,E1633*(1-MIN(tp_g/tp_roe,0.8))/(1+tp_r)^1+F1633*(1-MIN(tp_g/tp_roe,0.8))/(1+tp_r)^2+G1633*(1-MIN(tp_g/tp_roe,0.8))/(1+tp_r)^3+H1633*(1-MIN(tp_g/tp_roe,0.8))/(1+tp_r)^4+I1633*(1-MIN(tp_g/tp_roe,0.8))/(1+tp_r)^5+J1633*(1-MIN(tp_g/tp_roe,0.8))/(1+tp_r)^6+J1633*(1-MIN(tp_g/tp_roe,0.8))*(1+tp_g)/(tp_r-tp_g)/(1+tp_r)^6)+tp_wB*MAX(0,E1666*(1-MIN(tp_g/tp_roe,0.8))/(1+tp_r)^1+F1666*(1-MIN(tp_g/tp_roe,0.8))/(1+tp_r)^2+G1666*(1-MIN(tp_g/tp_roe,0.8))/(1+tp_r)^3+H1666*(1-MIN(tp_g/tp_roe,0.8))/(1+tp_r)^4+I1666*(1-MIN(tp_g/tp_roe,0.8))/(1+tp_r)^5+J1666*(1-MIN(tp_g/tp_roe,0.8))/(1+tp_r)^6+J1666*(1-MIN(tp_g/tp_roe,0.8))*(1+tp_g)/(tp_r-tp_g)/(1+tp_r)^6)+tp_wC*MAX(0,E1699*(1-MIN(tp_g/tp_roe,0.8))/(1+tp_r)^1+F1699*(1-MIN(tp_g/tp_roe,0.8))/(1+tp_r)^2+G1699*(1-MIN(tp_g/tp_roe,0.8))/(1+tp_r)^3+H1699*(1-MIN(tp_g/tp_roe,0.8))/(1+tp_r)^4+I1699*(1-MIN(tp_g/tp_roe,0.8))/(1+tp_r)^5+J1699*(1-MIN(tp_g/tp_roe,0.8))/(1+tp_r)^6+J1699*(1-MIN(tp_g/tp_roe,0.8))*(1+tp_g)/(tp_r-tp_g)/(1+tp_r)^6))*(1+tp_r) -> 2012.917 | H20: =Val!$B$33*(tp_wA*(2/12*E1633+10/12*F1633)+tp_wB*(2/12*E1666+10/12*F1666)+tp_wC*(2/12*E1699+10/12*F1699))*rm_factor -> 3455.9083 | I20: =tp_w_dcf*G20+(1-tp_w_dcf)*H20 -> 2734.4127 | J20: =I20/I$4-1 -> 0.035226932
A21: 營業費用彈性 0.4 | B21: phi | C21: 基準 0.6 | D21: =E1765 -> 106.00998 | E21: =F1765 -> 109.45979 | F21: =E21/E$4-1 -> 0.038191291 | G21: =(tp_wA*MAX(0,E1732*(1-MIN(tp_g/tp_roe,0.8))/(1+tp_r)^1+F1732*(1-MIN(tp_g/tp_roe,0.8))/(1+tp_r)^2+G1732*(1-MIN(tp_g/tp_roe,0.8))/(1+tp_r)^3+H1732*(1-MIN(tp_g/tp_roe,0.8))/(1+tp_r)^4+I1732*(1-MIN(tp_g/tp_roe,0.8))/(1+tp_r)^5+J1732*(1-MIN(tp_g/tp_roe,0.8))/(1+tp_r)^6+J1732*(1-MIN(tp_g/tp_roe,0.8))*(1+tp_g)/(tp_r-tp_g)/(1+tp_r)^6)+tp_wB*MAX(0,E1765*(1-MIN(tp_g/tp_roe,0.8))/(1+tp_r)^1+F1765*(1-MIN(tp_g/tp_roe,0.8))/(1+tp_r)^2+G1765*(1-MIN(tp_g/tp_roe,0.8))/(1+tp_r)^3+H1765*(1-MIN(tp_g/tp_roe,0.8))/(1+tp_r)^4+I1765*(1-MIN(tp_g/tp_roe,0.8))/(1+tp_r)^5+J1765*(1-MIN(tp_g/tp_roe,0.8))/(1+tp_r)^6+J1765*(1-MIN(tp_g/tp_roe,0.8))*(1+tp_g)/(tp_r-tp_g)/(1+tp_r)^6)+tp_wC*MAX(0,E1798*(1-MIN(tp_g/tp_roe,0.8))/(1+tp_r)^1+F1798*(1-MIN(tp_g/tp_roe,0.8))/(1+tp_r)^2+G1798*(1-MIN(tp_g/tp_roe,0.8))/(1+tp_r)^3+H1798*(1-MIN(tp_g/tp_roe,0.8))/(1+tp_r)^4+I1798*(1-MIN(tp_g/tp_roe,0.8))/(1+tp_r)^5+J1798*(1-MIN(tp_g/tp_roe,0.8))/(1+tp_r)^6+J1798*(1-MIN(tp_g/tp_roe,0.8))*(1+tp_g)/(tp_r-tp_g)/(1+tp_r)^6))*(1+tp_r) -> 2010.9756 | H21: =Val!$B$33*(tp_wA*(2/12*E1732+10/12*F1732)+tp_wB*(2/12*E1765+10/12*F1765)+tp_wC*(2/12*E1798+10/12*F1798))*rm_factor -> 3418.3732 | I21: =tp_w_dcf*G21+(1-tp_w_dcf)*H21 -> 2714.6744 | J21: =I21/I$4-1 -> 0.027754162
A22: 營業費用彈性 0.9 | B22: phi | D22: =E1864 -> 96.730522 | E22: =F1864 -> 99.323002 | F22: =E22/E$4-1 -> -0.057952893 | G22: =(tp_wA*MAX(0,E1831*(1-MIN(tp_g/tp_roe,0.8))/(1+tp_r)^1+F1831*(1-MIN(tp_g/tp_roe,0.8))/(1+tp_r)^2+G1831*(1-MIN(tp_g/tp_roe,0.8))/(1+tp_r)^3+H1831*(1-MIN(tp_g/tp_roe,0.8))/(1+tp_r)^4+I1831*(1-MIN(tp_g/tp_roe,0.8))/(1+tp_r)^5+J1831*(1-MIN(tp_g/tp_roe,0.8))/(1+tp_r)^6+J1831*(1-MIN(tp_g/tp_roe,0.8))*(1+tp_g)/(tp_r-tp_g)/(1+tp_r)^6)+tp_wB*MAX(0,E1864*(1-MIN(tp_g/tp_roe,0.8))/(1+tp_r)^1+F1864*(1-MIN(tp_g/tp_roe,0.8))/(1+tp_r)^2+G1864*(1-MIN(tp_g/tp_roe,0.8))/(1+tp_r)^3+H1864*(1-MIN(tp_g/tp_roe,0.8))/(1+tp_r)^4+I1864*(1-MIN(tp_g/tp_roe,0.8))/(1+tp_r)^5+J1864*(1-MIN(tp_g/tp_roe,0.8))/(1+tp_r)^6+J1864*(1-MIN(tp_g/tp_roe,0.8))*(1+tp_g)/(tp_r-tp_g)/(1+tp_r)^6)+tp_wC*MAX(0,E1897*(1-MIN(tp_g/tp_roe,0.8))/(1+tp_r)^1+F1897*(1-MIN(tp_g/tp_roe,0.8))/(1+tp_r)^2+G1897*(1-MIN(tp_g/tp_roe,0.8))/(1+tp_r)^3+H1897*(1-MIN(tp_g/tp_roe,0.8))/(1+tp_r)^4+I1897*(1-MIN(tp_g/tp_roe,0.8))/(1+tp_r)^5+J1897*(1-MIN(tp_g/tp_roe,0.8))/(1+tp_r)^6+J1897*(1-MIN(tp_g/tp_roe,0.8))*(1+tp_g)/(tp_r-tp_g)/(1+tp_r)^6))*(1+tp_r) -> 1969.2329 | H22: =Val!$B$33*(tp_wA*(2/12*E1831+10/12*F1831)+tp_wB*(2/12*E1864+10/12*F1864)+tp_wC*(2/12*E1897+10/12*F1897))*rm_factor -> 3087.7134 | I22: =tp_w_dcf*G22+(1-tp_w_dcf)*H22 -> 2528.4732 | J22: =I22/I$4-1 -> -0.042740135
A23: 淨利 ÷ 營業利益 0.80 | B23: ni_oi | C23: 基準 0.85 | D23: =E1963 -> 96.280653 | E23: =F1963 -> 99.231208 | F23: =E23/E$4-1 -> -0.058823529 | G23: =(tp_wA*MAX(0,E1930*(1-MIN(tp_g/tp_roe,0.8))/(1+tp_r)^1+F1930*(1-MIN(tp_g/tp_roe,0.8))/(1+tp_r)^2+G1930*(1-MIN(tp_g/tp_roe,0.8))/(1+tp_r)^3+H1930*(1-MIN(tp_g/tp_roe,0.8))/(1+tp_r)^4+I1930*(1-MIN(tp_g/tp_roe,0.8))/(1+tp_r)^5+J1930*(1-MIN(tp_g/tp_roe,0.8))/(1+tp_r)^6+J1930*(1-MIN(tp_g/tp_roe,0.8))*(1+tp_g)/(tp_r-tp_g)/(1+tp_r)^6)+tp_wB*MAX(0,E1963*(1-MIN(tp_g/tp_roe,0.8))/(1+tp_r)^1+F1963*(1-MIN(tp_g/tp_roe,0.8))/(1+tp_r)^2+G1963*(1-MIN(tp_g/tp_roe,0.8))/(1+tp_r)^3+H1963*(1-MIN(tp_g/tp_roe,0.8))/(1+tp_r)^4+I1963*(1-MIN(tp_g/tp_roe,0.8))/(1+tp_r)^5+J1963*(1-MIN(tp_g/tp_roe,0.8))/(1+tp_r)^6+J1963*(1-MIN(tp_g/tp_roe,0.8))*(1+tp_g)/(tp_r-tp_g)/(1+tp_r)^6)+tp_wC*MAX(0,E1996*(1-MIN(tp_g/tp_roe,0.8))/(1+tp_r)^1+F1996*(1-MIN(tp_g/tp_roe,0.8))/(1+tp_r)^2+G1996*(1-MIN(tp_g/tp_roe,0.8))/(1+tp_r)^3+H1996*(1-MIN(tp_g/tp_roe,0.8))/(1+tp_r)^4+I1996*(1-MIN(tp_g/tp_roe,0.8))/(1+tp_r)^5+J1996*(1-MIN(tp_g/tp_roe,0.8))/(1+tp_r)^6+J1996*(1-MIN(tp_g/tp_roe,0.8))*(1+tp_g)/(tp_r-tp_g)/(1+tp_r)^6))*(1+tp_r) -> 1973.6226 | H23: =Val!$B$33*(tp_wA*(2/12*E1930+10/12*F1930)+tp_wB*(2/12*E1963+10/12*F1963)+tp_wC*(2/12*E1996+10/12*F1996))*rm_factor -> 3094.5222 | I23: =tp_w_dcf*G23+(1-tp_w_dcf)*H23 -> 2534.0724 | J23: =I23/I$4-1 -> -0.040620324
A24: 淨利 ÷ 營業利益 0.90 | B24: ni_oi | D24: =E2062 -> 108.31573 | E24: =F2062 -> 111.63511 | F24: =E24/E$4-1 -> 0.058823529 | G24: =(tp_wA*MAX(0,E2029*(1-MIN(tp_g/tp_roe,0.8))/(1+tp_r)^1+F2029*(1-MIN(tp_g/tp_roe,0.8))/(1+tp_r)^2+G2029*(1-MIN(tp_g/tp_roe,0.8))/(1+tp_r)^3+H2029*(1-MIN(tp_g/tp_roe,0.8))/(1+tp_r)^4+I2029*(1-MIN(tp_g/tp_roe,0.8))/(1+tp_r)^5+J2029*(1-MIN(tp_g/tp_roe,0.8))/(1+tp_r)^6+J2029*(1-MIN(tp_g/tp_roe,0.8))*(1+tp_g)/(tp_r-tp_g)/(1+tp_r)^6)+tp_wB*MAX(0,E2062*(1-MIN(tp_g/tp_roe,0.8))/(1+tp_r)^1+F2062*(1-MIN(tp_g/tp_roe,0.8))/(1+tp_r)^2+G2062*(1-MIN(tp_g/tp_roe,0.8))/(1+tp_r)^3+H2062*(1-MIN(tp_g/tp_roe,0.8))/(1+tp_r)^4+I2062*(1-MIN(tp_g/tp_roe,0.8))/(1+tp_r)^5+J2062*(1-MIN(tp_g/tp_roe,0.8))/(1+tp_r)^6+J2062*(1-MIN(tp_g/tp_roe,0.8))*(1+tp_g)/(tp_r-tp_g)/(1+tp_r)^6)+tp_wC*MAX(0,E2095*(1-MIN(tp_g/tp_roe,0.8))/(1+tp_r)^1+F2095*(1-MIN(tp_g/tp_roe,0.8))/(1+tp_r)^2+G2095*(1-MIN(tp_g/tp_roe,0.8))/(1+tp_r)^3+H2095*(1-MIN(tp_g/tp_roe,0.8))/(1+tp_r)^4+I2095*(1-MIN(tp_g/tp_roe,0.8))/(1+tp_r)^5+J2095*(1-MIN(tp_g/tp_roe,0.8))/(1+tp_r)^6+J2095*(1-MIN(tp_g/tp_roe,0.8))*(1+tp_g)/(tp_r-tp_g)/(1+tp_r)^6))*(1+tp_r) -> 2015.9798 | H24: =Val!$B$33*(tp_wA*(2/12*E2029+10/12*F2029)+tp_wB*(2/12*E2062+10/12*F2062)+tp_wC*(2/12*E2095+10/12*F2095))*rm_factor -> 3481.3374 | I24: =tp_w_dcf*G24+(1-tp_w_dcf)*H24 -> 2748.6586 | J24: =I24/I$4-1 -> 0.040620324
