Workbook

Sheet README
A1: 勝宏科技（300476.SZ／02476.HK）收支與估值模型 v0.1.2（AI 半導體 Project：載板與 PCB 次產業；AI 加速卡與伺服器高層數 PCB、HDI） 2026-10-25
A2: 版本：v0.1.1（2026-10-25：補上檔空間級距、投資建議、重點觀察，數值不變）。前版：v0.1（初版）。每 GW AI 高速 PCB 金額（加速器卡／運算板、交換器板、中板／背板／其他）、勝宏份額與產值產能在本模型 Units 頁建立，為本專案權威資料（規則第 13 條）；與台光電模型的每 GW CCL 金額口徑分開，Recon 頁對照。
A3: 模型命題：勝宏的 AI 營收＝部署 GW（AI IT 資本支出 ÷ 每 GW IT 資本支出）× 每 GW AI 高速 PCB 金額（VR200 中板、CPX、Kyber 正交背板使每 GW 金額上升）× 勝宏份額 × 價格指數，但受產值產能（FY2026 營收 × 擴產指數）限制（全產全銷）。非 AI（汽車、手機、PC、消費）依公司說法持平。
A4: 核心問題：勝宏 2026 年 180 億元固定資產投資能讓產能在 2027–29 年擴大多少，擴產趕上需求後份額（沪电、深南、鹏鼎追趕；Rubin 份額傳聞）與價格守不守得住；現價約 15 倍前瞻 P/E 隱含什麼路徑。
A6: 會計年度＝日曆年，FY(t)＝CY(t)，不平移。預測期 FY2027–FY2029 由驅動因子推導，FY2030–FY2032 為收斂法。金額：十億人民幣；每 GW 金額以美元計、以匯率換算。口徑：歸屬母公司淨利（中國企業會計準則）。A 股與 H 股同股。
A8: 驅動因子 → 推導量（全部唯讀上游，不修改）
A9: 需求面：markets/network 的 AI IT 資本支出 × 情境顆數係數 ÷ 每 GW IT 資本支出（Tokenomics，經橋接表）＝部署 GW；× 每 GW PCB 金額（2026 年三項合計 US$450M，Assumed；之後 × 世代指數，Analogy／Assumed）× 匯率 × 有效份額（FY2026 以錨點 AI 營收校準）× 份額相對值 × 價格指數（Assumed）。
A10: 產能面：FY2026 營收（公司稱在產產能滿載）× 產值產能指數（2027 1.70、2028 2.40、2029 3.00；Assumed，依公司各廠計畫與 2030 年千億產值目標）× 價格指數。AI 相關營收＝MIN（需求面、產能上限 − 非 AI）。
A11: 毛利率：AI 相關比其他營收高 d_ai 15pt（Assumed），其他毛利率為 FY2026 殘差（Derived）；價格指數變動全部落在 AI 毛利；另加新廠爬坡完成的額外改善（Assumed）。營業費用：彈性 phi 0.6（Assumed）。淨利 ÷ 稅前 0.867（1H26 實績）。
A12: 校準：FY2026 ＝ 1H26 實績＋假設（3Q 季增 20%、4Q 季增 25%、毛利率 33%、營業費用率 6.5%）。3Q26 季報預計 2026-10-29 公布，截至 2026-10-25 尚未公布。不用券商數字（只在 Recon 對帳）。
A13: 估值：Val 第 0 節目標價＝0.5 × DCF 目標價（股東現金流＝EPS ×（1 − g／ROE），FY2027–32 明確期＋永續，r 10%、g 4%，三情境權重 0.3／0.5／0.2）＋0.5 × Comparable 目標價（A 股同業沪电、深南、生益电子、鹏鼎前瞻 P/E 中位數 × 12 個月後前瞻 EPS）；另列 Comparable 單獨目標價、市場共識目標價與差距拆解。十年 P/E 規則值 × FY2027 EPS 保留為參考（不是目標價）。情境對應：A＝順利、B＝平平、C＝不如預期（原為顆數情境）。本版未做先驗，無 Andy 合理 P/E 對照。
A14: 預估期間：FY2027–FY2029 由驅動因子推導；FY2030 起為收斂法，非驅動因子推導（營收年增由 FY2029 線性收斂到 fade_g、淨利率收斂到 fade_m，FY2032 達到；PL 頁灰底）。
... A18: v0.1.1：補上檔空間級距、投資建議、重點觀察（數值不變）。Val 頁最後新增「上檔空間級距」「投資建議」兩列（第 118、119 列，依「上檔空間：加權目標價」的固定規則）；重點觀察見下方三列。
A19: ="投資建議："&Val!B119&"（依上檔空間固定規則）" -> 投資建議：強力買進（依上檔空間固定規則）
A20: ="重點觀察 1：目標價 人民幣"&TEXT(Val!$B$39,"0.00")&"（DCF "&TEXT(Val!$B$24,"0.00")&"、Comparable（相對倍數調整後）"&TEXT(tp_comp_adj,"0.00")&"；DCF 權重 "&TEXT(tp_w_dcf,"0%")&"），比現價 "&TEXT(px,"0.00")&"（2026-10-23）"&IF(Val!$B$42>=0,"高 "&TEXT(Val!$B$42,"0.0%"),"低 "&TEXT(-Val!$B$42,"0.0%"))&"，級距 "&Val!$B$118&"、投資建議 "&Val!$B$119&"。相對倍數調整係數 "&TEXT(rm_factor,"0.00")&"（本公司 10 年前瞻倍數中位數 ÷ 同業的中位數，夾在 0.5–2.0；Val 第 0.5 節），調整前加權上檔空間 "&TEXT((tp_w_dcf*Val!$B$24+(1-tp_w_dcf)*Val!$B$35)/px-1,"+0.0%;−0.0%")&"；Comparable 單獨（市場主流同業法、未調整）為 "&TEXT(Val!$B$43,"+0.0%;−0.0%")&"。"&"以下為 2026-10-29 相對倍數調整前撰寫的說明，其中數字為調整前：主因是倍數不是 EPS：本模型前瞻 EPS 14.39 比共識前瞻 EPS 12.36 高 16.4%，但 A 股 PCB 同業（沪电、深南、生益电子、鹏鼎）前瞻 P/E 中位數 30.8 倍、共識目標價 388.30 隱含 31.4 倍，現價只隱含 14.8 倍；DCF 單獨僅 +10.5%，上檔空間主要來自 Compar"&"able，市場對份額（Rubin 份額傳聞）與擴產的折價未計入 Comparable。" -> 重點觀察 1：目標價 人民幣303.24（DCF 202.71、Comparable（相對倍數調整後）403.77；DCF 權重 50%），比現價 183.48（2026-10-23）高 65.3%，級距 大於 50%、投資建議 強力買進。相對倍數調整係數 0.91（本公司 10 年前瞻倍數中位數 ÷ 同業的中位數，夾在 0.5–2.0；Val 第 0.5 節），調整前加權上檔空間 +76.0%；Comparable 單獨（市場主流同業法、未調整）為 +141.4%。以下為 2026-10-29 相對倍數調整前撰寫的說明，其中數字為調整前：主因是倍數不是 EPS：本模型前瞻 EPS 14.39 比共識前瞻 EPS 12.36 高 16.4%，但 A 股 PCB 同業（沪电、深南、生益电子、鹏鼎）前瞻 P/E 中位數 30.8 倍、共識目標價 388.30 隱含 31.4 倍，現價只隱含 14.8 倍；DCF 單獨僅 +10.5%，上檔空間主要來自 Comparable，市場對份額（Rubin 份額傳聞）與擴產的折價未計入 Comparable。
A21: 重點觀察 2：份額、每 GW 金額與擴產最敏感：份額流失（2028 年相對值 0.60）使 FY2028 EPS −23.7%、每 GW 金額成長低值 −20.9%、擴產延遲 −20.0%；顆數情境 C 的 FY2028 EPS 10.86 比情境 A 17.78 低 38.9%，DCF 價格帶 98.55～287.37。
A22: 重點觀察 3：上檔空間不靠比共識樂觀：本模型 FY2027 EPS 12.81（三情境相同）比共識 14.77 低 13.3%、情境 A 的 FY2028 EPS 17.78 比共識 22.13 低 19.7%。下一個檢驗點是 3Q26 季報（2026-10-29）。
A23: v0.1.2（2026-10-28）：分部原則重建（數值不變）。Q 頁最後追加核對列「檢查：分部合計 − 合併營收」；官方分部與子列宣告見 segments.json。
A25: 2026-10-29：加權目標價中的 Comparable 改用相對倍數調整後的值（Val 第 0.5 節：同業前瞻倍數中位數 × 本公司 10 年相對同業的倍數比，Bloomberg 前瞻倍數；Andy 2026-10-27「照建議做」、10-29 資料取回）。「Comparable 目標價（市場主流同業法）」維持不調整。重點觀察 1 的第一句已改為公式；重點觀察 2、3 與其他說明中的目標價與上檔空間數字為調整前撰寫，以 Val 頁為準。
A27: v0.1.3（2026-10-30）：依個股模型原則第 8 節調整 In 頁呈現（數值不變）。In 頁 D／F 欄名改「敏感度低」「敏感度高」（只用於 Sens 頁、不進目標價）；In 頁最後新增「情境驅動對照」一節，把上方各情境專屬輸入三情境並排（只引用上方各列，純展示）；HTML 驅動因子一節分「情境驅動」與「單一參數」兩張表。

Sheet In
A1: In — 輸入（藍字；基準欄 E，低 D、高 F）。金額：十億人民幣（RMB B），每 GW PCB 金額為百萬美元；比例：%。每個輸入附兩個來源（找不到者寫「未找到」）；公司原文算一個。【v0.1.3】基準欄 E 進主模型；D／F＝敏感度低／高，只用於 Sens 頁（一次動一個參數）、不進目標價；情境 A／B／C 的驅動見本頁最後一節「情境驅動對照」。
A2: 標記：Verified／Interested-party／Analogy／Assumed／Derived；Analogy、Assumed 給低／高區間。SemiAnalysis 未使用。公司原文＝勝宏科技定期報告（深交所、巨潮）與業績交流會（經媒體轉述）；公司的訂單、產品組合與產能說法為 Interested-party；券商估計皆為 Interested-party
A3: 鍵 | B3: 項目 | C3: 單位 | D3: 敏感度低 | E3: 基準 | F3: 敏感度高 | G3: 標記 | H3: 來源1 | I3: 來源2／說明
A4: A. AI 部署規模（讀 markets/network、markets/chip_bridge、tsmc 成品；情境 A 基準，B／C 依顆數係數縮放）
A5: itc_26 | B5: AI IT 資本支出 2026 | C5: US$B | E5: 781.87292 | G5: Derived | H5: markets/network/dist/20261026_AI網通市場模型_v0.2.3.xlsx｜Mkt!C27:F27 | I5: 加速器顆數 × 每顆 IT capex（含 ASIC）；本模型以此除以每 GW IT 資本支出得到部署 GW（與台光電、台達電模型相同）
A6: itc_27 | B6: AI IT 資本支出 2027 | C6: US$B | E6: 1565.35 | G6: Derived | H6: markets/network/dist/20261026_AI網通市場模型_v0.2.3.xlsx｜Mkt!C27:F27 | I6: 同上
A7: itc_28 | B7: AI IT 資本支出 2028 | C7: US$B | E7: 1984.2639 | G7: Derived | H7: markets/network/dist/20261026_AI網通市場模型_v0.2.3.xlsx｜Mkt!C27:F27 | I7: 同上
A8: itc_29 | B8: AI IT 資本支出 2029 | C8: US$B | E8: 2260.3903 | G8: Derived | H8: markets/network/dist/20261026_AI網通市場模型_v0.2.3.xlsx｜Mkt!C27:F27 | I8: 同上
A9: itpg_gb | B9: 每 GW IT 資本支出（GB300） | C9: US$B | E9: 32.237224 | G9: Derived | H9: markets/chip_bridge/dist/20261027_晶片內容橋接表_v0.2.2.xlsx｜In!E10（GB300）、H10（VR200） | I9: Tokenomics IF_CapexIT（經橋接表；唯讀）
A10: itpg_vr | B10: 每 GW IT 資本支出（VR200；2027 起） | C10: US$B | E10: 37.586352 | G10: Derived | H10: markets/chip_bridge/dist/20261027_晶片內容橋接表_v0.2.2.xlsx｜In!E10（GB300）、H10（VR200） | I10: 同上；Rubin Ultra 與 ASIC 機架未另訂（Assumed：同 VR200）
A11: vr26 | B11: 2026 年部署中 Rubin 世代占比（混合每 GW IT 資本支出與每 GW PCB 金額用） | C11: % | D11: 0.15 | E11: 0.22 | F11: 0.3 | G11: Interested-party | H11: TrendForce 2026 組合 Rubin 22%（經 markets/memory；與台光電、台達電模型相同） | I11: VR200 自 2026 Q3 起出貨（國金證券 2026-05，Interested-party）
A12: racks_gb | B12: 每 GW 機架數（GB300） | C12: 架 | E12: 6764 | G12: Derived | H12: markets/chip_bridge/dist/20261027_晶片內容橋接表_v0.2.2.xlsx｜In!E6（GB300）、H6（VR200） | I12: Recon 用：每架 PCB 金額換算
A13: racks_vr | B13: 每 GW 機架數（VR200） | C13: 架 | E13: 4052 | G13: Derived | H13: markets/chip_bridge/dist/20261027_晶片內容橋接表_v0.2.2.xlsx｜In!E6（GB300）、H6（VR200） | I13: 同上
A14: um28_A | B14: 情境 A：2028 顆數 ÷ 基準 | C14: x | E14: 1 | G14: Assumed | H14: tsmc/dist/20261030_台積電個股模型_v0.4.1.xlsx｜In!E37 | I14: A＝順利（基準）；B＝平平（AI 資本支出消化）；C＝不如預期（明顯下修）；與台積電、台光電模型相同
A15: um29_A | B15: 情境 A：2029 顆數 ÷ 基準 | C15: x | E15: 1 | G15: Assumed | H15: tsmc/dist/20261030_台積電個股模型_v0.4.1.xlsx｜In!E38 | I15: 同上
A16: um28_B | B16: 情境 B：2028 顆數 ÷ 基準 | C16: x | E16: 0.8 | G16: Assumed | H16: tsmc/dist/20261030_台積電個股模型_v0.4.1.xlsx｜In!E39 | I16: A＝順利（基準）；B＝平平（AI 資本支出消化）；C＝不如預期（明顯下修）；與台積電、台光電模型相同
A17: um29_B | B17: 情境 B：2029 顆數 ÷ 基準 | C17: x | E17: 0.85 | G17: Assumed | H17: tsmc/dist/20261030_台積電個股模型_v0.4.1.xlsx｜In!E40 | I17: 同上
A18: um28_C | B18: 情境 C：2028 顆數 ÷ 基準 | C18: x | E18: 0.6 | G18: Assumed | H18: tsmc/dist/20261030_台積電個股模型_v0.4.1.xlsx｜In!E41 | I18: A＝順利（基準）；B＝平平（AI 資本支出消化）；C＝不如預期（明顯下修）；與台積電、台光電模型相同
A19: um29_C | B19: 情境 C：2029 顆數 ÷ 基準 | C19: x | E19: 0.6 | G19: Assumed | H19: tsmc/dist/20261030_台積電個股模型_v0.4.1.xlsx｜In!E42 | I19: 同上
A20: fx | B20: 匯率（人民幣 ÷ 美元） | C20: RMB/US$ | D20: 6.5 | E20: 6.72 | F20: 7 | G20: Verified | H20: 中國經濟網 2026-10-16：中間價 6.7220（網址見 Sources 頁） | I20: 10-09 中間價 6.7330（中國經濟網）；10-23 中間價：未找到
A21: B. 每 GW AI 高速 PCB 金額與勝宏份額（本專案權威：每 GW PCB 金額、勝宏份額，規則第 13 條；與台光電的每 GW CCL 金額口徑分開）
A22: cmp_26 | B22: 每 GW PCB：加速器卡／運算板（GPU／ASIC 模組 HDI、運算匣主板）2026 | C22: US$M/GW | D22: 200 | E22: 280 | F22: 360 | G22: Assumed | H22: 由上而下（Assumed）：三項合計 2026 年約 US$450M／GW；量級檢查：Morgan Stanley 每架 PCB GB300 US$35.1K、VR200 US$116.7K（國金證券 2026-05 轉引，Interested-party）× 每 GW 架數＝237／473 百萬美元（只含 NVL72 機架內，不含 scale-out 交換器、光模組、ASIC 伺服器）；Prismark AI／HPC PCB 2024 年 US$6B（摩根大通 2026-06-11 轉引） | I22: 國金證券：VR200 運算匣約 US$3,000、26 層（Morgan Stanley）或 24 層 6 階 HDI（TPCA），較 GB200／GB300 增加近 300%（Interested-party）
A23: sw_26 | B23: 每 GW PCB：交換器板（NVLink 交換匣＋scale-out 800G／1.6T 交換器、光模組板）2026 | C23: US$M/GW | D23: 80 | E23: 120 | F23: 160 | G23: Assumed | H23: 同上；交換匣 24 層 → 32 層（GB300 → VR200，國金證券轉引 Morgan Stanley） | I23: 公司：800G 交換器、1.6T 光模組 PCB 已量產（公司業績交流會，Interested-party）
A24: mid_26 | B24: 每 GW PCB：中板／正交背板／CPX 與其他（電源板等）2026 | C24: US$M/GW | D24: 30 | E24: 50 | F24: 80 | G24: Assumed | H24: 同上；VR200 新增 44 層（22＋22）中板、4 片 22 層 5 階 HDI CPX 板、ConnectX／BlueField 子卡；Kyber（Rubin Ultra）78 層 M9 正交背板（國金證券） | I24: 2026 年以 GB300 為主（無中板）；中板與 CPX 金額多數從 VR200 開始
A25: cmpx_27 | B25: 每 GW PCB 金額指數：加速器卡／運算板 2027（2026＝1） | C25: x | D25: 1.25 | E25: 1.5 | F25: 1.75 | G25: Analogy | H25: Morgan Stanley 每架 PCB（國金證券轉引）：VR200 ÷ GB300＝3.3 倍；× 每 GW 架數（4,052 ÷ 6,764）＝每 GW 2.0 倍；2026 年已含 22% Rubin → 2027 ÷ 2026 約 1.64 倍（含交換匣，本列取 1.50） | I25: Bernstein：AI 伺服器 PCB 含量較前一代約倍增（國金證券轉引，Interested-party）
A26: cmpx_28 | B26: 每 GW PCB 金額指數：加速器卡／運算板 2028（2026＝1） | C26: x | D26: 1.35 | E26: 1.65 | F26: 2 | G26: Analogy | H26: 同上 | I26: —
A27: cmpx_29 | B27: 每 GW PCB 金額指數：加速器卡／運算板 2029（2026＝1） | C27: x | D27: 1.4 | E27: 1.8 | F27: 2.2 | G27: Analogy | H27: 同上 | I27: —
A28: swx_27 | B28: 每 GW PCB 金額指數：交換器板 2027（2026＝1） | C28: x | D28: 1.15 | E28: 1.35 | F28: 1.6 | G28: Assumed | H28: 交換匣 24 層 → 32 層、1.6T 2027 年放量（國金證券、公司） | I28: 網通模型：交換器市場 ÷ AI IT 資本支出 2026–27 持平；本列的上升來自層數與材料等級
A29: swx_28 | B29: 每 GW PCB 金額指數：交換器板 2028（2026＝1） | C29: x | D29: 1.25 | E29: 1.5 | F29: 1.85 | G29: Assumed | H29: 同上 | I29: —
A30: swx_29 | B30: 每 GW PCB 金額指數：交換器板 2029（2026＝1） | C30: x | D30: 1.3 | E30: 1.65 | F30: 2.1 | G30: Assumed | H30: 同上 | I30: —
A31: midx_27 | B31: 每 GW PCB 金額指數：中板／背板／其他 2027（2026＝1） | C31: x | D31: 1.4 | E31: 2 | F31: 2.6 | G31: Assumed | H31: VR200 中板與 CPX（2026 Q3 起）、Kyber 78 層正交背板（2027 起）；國金證券：Kyber 每架 PCB「十萬美元級」以上 | I31: 台光電模型 UBB／中板指數 2027 1.80、2028 2.30、2029 2.60（CCL 口徑）
A32: midx_28 | B32: 每 GW PCB 金額指數：中板／背板／其他 2028（2026＝1） | C32: x | D32: 1.8 | E32: 3 | F32: 4 | G32: Assumed | H32: 同上 | I32: —
A33: midx_29 | B33: 每 GW PCB 金額指數：中板／背板／其他 2029（2026＝1） | C33: x | D33: 2 | E33: 3.5 | F33: 5 | G33: Assumed | H33: 同上 | I33: —
... A39: pp_29 | B39: PCB 價格指數 2029（2026＝1；同規格降價或漲價，不含世代升級） | C39: x | D39: 0.85 | E39: 0.94 | F39: 1 | G39: Assumed | H39: 同上 | I39: 新產能到位後價格回落（Assumed）
A40: C. 產能（全產全銷：營收上限＝FY2026 營收 × 產值產能指數 × 價格指數）
A41: cx_27 | B41: 平均產值產能 2027 ÷ FY2026 營收（產能指數；以 FY2026 產品價格計） | C41: x | D41: 1.45 | E41: 1.7 | F41: 1.9 | G41: Assumed | H41: 公司：2030 年千億（1,000 億元）產值目標；在產＋在建＋規劃產能約等於該目標（界面 2026-03）；2026 年固定資產投資不超過 180 億元（公司 2026-08-28） | I41: 東方財富財富號（2026-01-05，產能整理，Interested-party）：惠州廠房 10、11 各約 100 萬㎡、產值各逾 150 億（2026 年底投產）、廠房 12 約 120 億（2027）、越南一期 30–35 億（2026 年中）、泰國 A2 36 億（2026）、泰國二期 45 萬㎡（2027）
A42: cx_28 | B42: 平均產值產能 2028 ÷ FY2026 營收（產能指數；以 FY2026 產品價格計） | C42: x | D42: 1.95 | E42: 2.4 | F42: 2.8 | G42: Assumed | H42: 同上 | I42: 新廠爬坡：4Q25、1Q26 低於預期主因新產能爬坡慢、原料上漲（財信證券，經界面 2026-03）；低值反映延遲
A43: cx_29 | B43: 平均產值產能 2029 ÷ FY2026 營收（產能指數；以 FY2026 產品價格計） | C43: x | D43: 2.4 | E43: 3 | F43: 3.4 | G43: Assumed | H43: 同上；2029 年 × FY2026 營收約 840 億，向 2030 年千億收斂 | I43: —
A44: D. 營收結構錨點（公司揭露比例 × 營收）
A45: ai_25 | B45: 2025 年 AI 相關營收（AI 算力、資料中心、HPC）÷ 營收 | C45: % | D45: 0.4 | E45: 0.45 | F45: 0.5 | G45: Interested-party | H45: 摩根大通 2026-06-11：AI／HPC 占營收 2024 年 6.6% → 2025 年 43.2%（招股書口徑） | I45: 公司：2025 前三季 AI 相關超過 40%、全年更高（界面 2026-03）；業績交流會：去年 AI 產品約占一半（同花順 2026-08-28）
...

Sheet Q
A1: Q — 實績與 FY2026 錨點（十億人民幣；EPS 為人民幣；股數為十億股）。藍字＝輸入；黑字＝公式。實績取自勝宏科技定期報告（深交所）與年報摘要（經轉述）
A2: FY2026 錨點＝1H26 實績＋3Q、4Q 假設（營收季增、毛利率、營業費用率、營業外、淨利 ÷ 稅前）。1H26 營業外淨額＝稅前 − 營業利益（含公允價值變動 +5.95 億，不外推）。FY2025 營業費用＝毛利 − 營業利益（stockanalysis，含財務費用；1H26 起不含財務費用，口徑不同）。3Q26 季報預計 2026-10-29 公布（截至 2026-10-25 尚未公布），公布後更新
A3: 項目 | B3: FY2025A | C3: 1H26（實績） | D3: 3Q26（模型） | E3: 4Q26（模型） | F3: FY2026 錨點 | G3: 標記 | H3: 來源1 | I3: 來源2／說明
A4: 營收 | B4: 19.292 | C4: 11.629 | D4: =(C4-q1_rev)*(1+q3g) -> 7.332 | E4: =D4*(1+q4g) -> 9.165 | F4: =SUM(C4:E4) -> 28.126 | G4: Verified／Assumed（3Q、4Q 季增） | H4: FY2025：證券之星 2026-03-14 年報簡析（營收 192.92 億、歸母 43.12 億、毛利率 35.22%、EPS 5.01）；stockanalysis（營業利益 51.48 億）；1H26：公司半年報（深交所 2026-08-28） | I4: 1H26 116.29 億（年增 28.77%）；2Q26＝116.29 − 1Q26 55.19＝61.10 億
A5: 毛利 | B5: =B4*0.3522 -> 6.7946424 | C5: =11.629-7.766 -> 3.863 | D5: =D4*q_gm -> 2.41956 | E5: =E4*q_gm -> 3.02445 | F5: =SUM(C5:E5) -> 9.30701 | G5: Verified／Assumed | H5: FY2025：證券之星 2026-03-14 年報簡析（營收 192.92 億、歸母 43.12 億、毛利率 35.22%、EPS 5.01）；stockanalysis（營業利益 51.48 億）；1H26：公司半年報（深交所 2026-08-28） | I5: 1H26 營業成本 77.66 億（公司半年報）；FY2025 毛利率 35.22%（證券之星）
A6: 毛利率 | B6: =B5/B4 -> 0.3522 | C6: =C5/C4 -> 0.33218677 | D6: =D5/D4 -> 0.33 | E6: =E5/E4 -> 0.33 | F6: =F5/F4 -> 0.33090415 | G6: Derived | H6: — | I6: 1H26 33.2%；1Q26 34.5%（營業成本 36.18 億）
A7: 營業費用 | B7: =B5-B8 -> 1.6466424 | C7: =0.1047+0.2917+0.3592 -> 0.7556 | D7: =D4*q_opx -> 0.47658 | E7: =E4*q_opx -> 0.595725 | F7: =SUM(C7:E7) -> 1.827905 | G7: Derived／Verified／Assumed | H7: FY2025：證券之星 2026-03-14 年報簡析（營收 192.92 億、歸母 43.12 億、毛利率 35.22%、EPS 5.01）；stockanalysis（營業利益 51.48 億）；1H26：公司半年報（深交所 2026-08-28） | I7: 1H26：銷售 1.047＋管理 2.917＋研發投入 3.592 億（不含財務費用）；FY2025＝毛利 − 營業利益（含財務費用）
A8: 營業利益（毛利 − 營業費用） | B8: 5.148 | C8: =C5-C7 -> 3.1074 | D8: =D5-D7 -> 1.94298 | E8: =E5-E7 -> 2.428725 | F8: =SUM(C8:E8) -> 7.479105 | G8: Interested-party（stockanalysis）／Derived | H8: FY2025：證券之星 2026-03-14 年報簡析（營收 192.92 億、歸母 43.12 億、毛利率 35.22%、EPS 5.01）；stockanalysis（營業利益 51.48 億）；1H26：公司半年報（深交所 2026-08-28） | I8: FY2025 stockanalysis 營業利益 51.48 億
A9: 營業利益率 | B9: =B8/B4 -> 0.26684636 | C9: =C8/C4 -> 0.26721128 | D9: =D8/D4 -> 0.265 | E9: =E8/E4 -> 0.265 | F9: =F8/F4 -> 0.26591428 | G9: Derived | H9: — | I9: —
A10: 營業外與財務淨額 | C10: =C11-C8 -> 0.1866 | D10: =q_nop -> -0.06 | E10: =q_nop -> -0.06 | F10: =SUM(C10:E10) -> 0.0666 | G10: Derived／Assumed | H10: 1H26＝稅前 − 營業利益（含公允價值變動 +5.95 億、財務費用 −2.97 億） | I10: FY2025：未找到
A11: 稅前利益 | C11: =2.8568+0.4372 -> 3.294 | D11: =D8+D10 -> 1.88298 | E11: =E8+E10 -> 2.368725 | F11: =SUM(C11:E11) -> 7.545705 | G11: Derived | H11: 1H26＝歸母淨利 28.57＋所得稅 4.37 億（少數股東損益未載明） | I11: FY2025：未找到
A12: 歸屬母公司淨利 | B12: 4.312 | C12: 2.8568 | D12: =D11*q_nir -> 1.6330593 | E12: =E11*q_nir -> 2.0543332 | F12: =SUM(C12:E12) -> 6.5441925 | G12: Verified／Derived（3Q、4Q） | H12: FY2025：證券之星 2026-03-14 年報簡析（營收 192.92 億、歸母 43.12 億、毛利率 35.22%、EPS 5.01）；stockanalysis（營業利益 51.48 億）；1H26：公司半年報（深交所 2026-08-28） | I12: FY2025 43.12 億（公司年報）；1H26 28.57 億（年增 33.30%；扣非 24.18 億、+12.50%）
A13: 淨利 ÷ 營業利益 | B13: =B12/B8 -> 0.83760684 | C13: =C12/C8 -> 0.9193538 | D13: =D12/D8 -> 0.84049207 | E13: =E12/E8 -> 0.84584842 | F13: =F12/F8 -> 0.87499674 | G13: Derived | H13: — | I13: —
A14: 股數（十億股；加權） | B14: =4.312/5.01 -> 0.86067864 | C14: =sh_1h -> 0.90980892 | D14: =sh_h2 -> 0.98234 | E14: =sh_h2 -> 0.98234 | F14: =(sh_1h+sh_h2)/2 -> 0.94607446 | G14: Derived | H14: FY2025：證券之星 2026-03-14 年報簡析（營收 192.92 億、歸母 43.12 億、毛利率 35.22%、EPS 5.01）；stockanalysis（營業利益 51.48 億）；1H26：公司半年報（深交所 2026-08-28） | I14: 淨利 ÷ EPS；FY2026＝上半年與下半年平均（H 股 4 月下旬上市，Assumed）
A15: EPS | B15: =B12/B14 -> 5.01 | C15: =C12/C14 -> 3.14 | D15: =D12/D14 -> 1.6624176 | E15: =E12/E14 -> 2.0912649 | F15: =F12/F14 -> 6.9172066 | G15: Derived | H15: 淨利 ÷ 股數 | I15: —
A16: 公司揭露 EPS | B16: 5.01 | C16: 3.14 | G16: Verified | H16: FY2025：證券之星 2026-03-14 年報簡析（營收 192.92 億、歸母 43.12 億、毛利率 35.22%、EPS 5.01）；stockanalysis（營業利益 51.48 億）；1H26：公司半年報（深交所 2026-08-28） | I16: FY2025 基本 5.01；1H26 基本 3.14（公司）
A17: AI 相關營收（FY2025＝營收 × AI 占比；FY2026＝營收 − 非 AI） | B17: =B4*ai_25 -> 8.6814 | F17: =F4-F18 -> 17.5154 | G17: Interested-party／Derived | H17: AI 占比（In 頁 D 節） | I17: 各季 AI 營收金額未揭露：未找到
A18: 非 AI 營收（FY2026＝FY2025 ×（1＋g_nai26）） | B18: =B4-B17 -> 10.6106 | F18: =B18*(1+g_nai26) -> 10.6106 | G18: Derived／Interested-party | H18: — | I18: 公司：非 AI 金額大致持平（2026-08-28）
A23: FY2026 錨點的檢查（參考；校準未使用券商數字）
A24: FY2026 營收年增 | B24: =F4/B4-1 -> 0.45791001
A25: FY2026 AI 相關 ÷ 營收 | B25: =F17/F4 -> 0.62274764
A26: FY2026 營業費用 ÷ 營收（不含財務費用） | B26: =F7/F4 -> 0.064989867
A27: FY2026 營收 ÷ 共識（同花順）− 1 | B27: =F4/cons_rev26-1 -> -0.11004936
A28: FY2026 EPS ÷ 共識（同花順）− 1 | B28: =F15/cons_eps26-1 -> -0.19660783
A29: 下半年營收 ÷ 上半年 − 1 | B29: =(D4+E4)/C4-1 -> 0.41860865
A31: 檢查：分部合計 − 合併營收 | B31: =ROUND(B17+B18-B4,6) -> 0
A32: 分部原則第 3 條（2026-10-28 追加）；分部宣告見 segments.json

Sheet Units
A1: Units — 每 GW AI 高速 PCB 金額（加速器卡／運算板、交換器板、中板／背板／其他）、勝宏份額與產能（本專案權威，規則第 13 條；與台光電模型的每 GW CCL 金額口徑分開）。部署 GW＝AI IT 資本支出（markets/network）÷ 每 GW IT 資本支出（Tokenomics，經橋接表）
A3: 項目 | B3: 單位 | C3: CY2026 | D3: CY2027 | E3: CY2028 | F3: CY2029 | G3: 說明
A4: 部署 GW（情境 A） | B4: GW | C4: =PL!D65 -> 23.399538 | D4: =PL!E65 -> 41.646766 | E4: =PL!F65 -> 52.792138 | F4: =PL!G65 -> 60.138592 | G4: AI IT 資本支出 ÷ 每 GW IT 資本支出
A5: 每 GW PCB：加速器卡／運算板 | B5: US$M/GW | C5: =PL!D66 -> 280 | D5: =PL!E66 -> 420 | E5: =PL!F66 -> 462 | F5: =PL!G66 -> 504 | G5: 2026 Assumed、之後 × 指數（Analogy）
A6: 每 GW PCB：交換器板 | B6: US$M/GW | C6: =PL!D67 -> 120 | D6: =PL!E67 -> 162 | E6: =PL!F67 -> 180 | F6: =PL!G67 -> 198 | G6: Assumed
A7: 每 GW PCB：中板／背板／其他 | B7: US$M/GW | C7: =PL!D68 -> 50 | D7: =PL!E68 -> 100 | E7: =PL!F68 -> 150 | F7: =PL!G68 -> 175 | G7: Assumed；VR200 中板與 CPX、Kyber 正交背板
A8: 每 GW AI 高速 PCB 金額（合計，不含價格指數） | B8: US$M/GW | C8: =PL!D69 -> 450 | D8: =PL!E69 -> 682 | E8: =PL!F69 -> 792 | F8: =PL!G69 -> 877
A9: 每架等值 PCB 金額（以 VR200 每 GW 架數換算） | B9: US$K/架 | C9: =PL!D69*1000/racks_vr -> 111.05627 | D9: =PL!E69*1000/racks_vr -> 168.31194 | E9: =PL!F69*1000/racks_vr -> 195.45903 | F9: =PL!G69*1000/racks_vr -> 216.43633 | G9: 對照 Morgan Stanley VR200 每架 US$116.7K（只含機架內）
A10: 對照：台光電模型每 GW 高速 CCL 金額（CCL 口徑） | B10: US$M/GW | C10: =emc_ccl26 -> 350 | D10: =emc_ccl27 -> 527.5 | E10: =emc_ccl28 -> 609 | F10: =emc_ccl29 -> 662.5 | G10: 唯讀 emc/dist；PCB ÷ CCL 見下一列
A11: 每 GW PCB 金額 ÷ 每 GW CCL 金額 | B11: x | C11: =PL!D69/emc_ccl26 -> 1.2857143 | D11: =PL!E69/emc_ccl27 -> 1.292891 | E11: =PL!F69/emc_ccl28 -> 1.3004926 | F11: =PL!G69/emc_ccl29 -> 1.3237736 | G11: PCB 售價含 CCL、銅箔以外的製程價值；兩模型範圍不同（見 Recon）
A12: AI 高速 PCB 市場（含價格指數） | B12: US$B | C12: =PL!D70*PL!D72 -> 10.529792 | D12: =PL!E70*PL!E72 -> 28.403094 | E12: =PL!F70*PL!F72 -> 40.557032 | F12: =PL!G70*PL!G72 -> 49.577052 | G12: 含 ASIC 部署（假設每 GW 金額相同）
A13: 勝宏有效份額 | B13: % | C13: =PL!D75 -> 0.24753179 | D13: =PL!E75 -> 0.22277861 | E13: =PL!F75 -> 0.19802544 | F13: =PL!G75 -> 0.18564885 | G13: FY2026 以錨點 AI 相關營收校準
A14: 勝宏 AI 相關營收（需求面） | B14: US$B | C14: =PL!D76/fx -> 2.6064583 | D14: =PL!E76/fx -> 6.327602 | E14: =PL!F76/fx -> 8.031324 | F14: =PL!G76/fx -> 9.2039225
A15: 勝宏 AI 相關營收（實際＝MIN 需求面、產能） | B15: US$B | C15: =PL!D81/fx -> 2.6064583 | D15: =PL!E81/fx -> 5.53625 | E15: =PL!F81/fx -> 8.031324 | F15: =PL!G81/fx -> 9.2039225
A16: 每 GW 勝宏 AI 相關營收 | B16: US$M/GW | C16: =PL!D87 -> 111.38931 | D16: =PL!E87 -> 132.93349 | E16: =PL!F87 -> 152.13106 | F16: =PL!G87 -> 153.0452
A17: 平均產值產能指數（FY2026＝1） | B17: x | C17: =PL!D78 -> 1 | D17: =PL!E78 -> 1.7 | E17: =PL!F78 -> 2.4 | F17: =PL!G78 -> 3 | G17: 公司擴產計畫（Assumed）
A18: 產能上限營收（含價格指數） | B18: RMB B | C18: =PL!D79 -> 28.126 | D18: =PL!E79 -> 47.8142 | E18: =PL!F79 -> 65.477328 | F18: =PL!G79 -> 79.31532 | G18: FY2026 校準
A19: 需求面 ÷ 產能上限 | B19: % | C19: =PL!D86 -> 1 | D19: =PL!E86 -> 1.1112198 | E19: =PL!F86 -> 0.98631235 | F19: =PL!G86 -> 0.91358087 | G19: 大於 100%＝產能受限
A20: 其他廠商 AI 高速 PCB（沪电、深南、生益电子、鹏鼎、臺美廠等）＝ 市場 − 勝宏 | B20: US$B | C20: =PL!D70*PL!D72-PL!D81/fx -> 7.9233338 | D20: =PL!E70*PL!E72-PL!E81/fx -> 22.866844 | E20: =PL!F70*PL!F72-PL!F81/fx -> 32.525708 | F20: =PL!G70*PL!G72-PL!G81/fx -> 40.37313 | G20: 產能受限時，未滿足需求計入其他廠商
A22: 讀法：每 GW PCB 金額的絕對水準只影響 FY2026 校準出的份額（金額高 → 份額低），不影響營收；影響營收的是金額指數（世代升級）與份額相對值。FY2027 需求面高於產能時，營收由產值產能指數決定，擴產進度比需求更關鍵；FY2029 起擴產趕上需求，份額與每 GW 金額重新成為主要變數。

Sheet PL
A1: PL — 勝宏科技損益（十億人民幣；EPS 人民幣；歸屬母公司）。FY2025A 實績、FY2026 錨點（1H26 實績＋3Q、4Q 假設），FY2027 起為模型。FY(t)＝CY(t)。三情境各一個完整推導區塊（本頁下方），頂端為摘要。FY2026–FY2027 三情境相同（顆數係數從 CY2028 開始）
A2: 灰底＝FY2030–FY2032 收斂法（上游只到 2029）：營收年增線性收斂到 fade_g、淨利率線性收斂到 fade_m（In 頁 J 節），非驅動因子推導
A3: 情境／項目 | B3: 單位 | C3: FY2025A | D3: FY2026（錨點） | E3: FY2027 | F3: FY2028 | G3: FY2029 | H3: FY2030（收斂） | I3: FY2031（收斂） | J3: FY2032（收斂） | K3: 說明
A4: 情境 A
A5: 營收 | B5: RMB B | C5: =C83 -> 19.292 | D5: =D83 -> 28.126 | E5: =E83 -> 47.8142 | F5: =F83 -> 64.581097 | G5: =G83 -> 72.460959 | H5: =H83 -> 79.804394 | I5: =I83 -> 86.242348 | J5: =J83 -> 91.416888
A6: 營收年增 | B6: % | D6: =D84 -> 0.45791001 | E6: =E84 -> 0.7 | F6: =F84 -> 0.35066773 | G6: =G84 -> 0.122015 | H6: =H84 -> 0.10134333 | I6: =I84 -> 0.080671665 | J6: =J84 -> 0.06
A7: AI 相關營收（AI 算力、資料中心、HPC） | B7: RMB B | C7: =C81 -> 8.6814 | D7: =D81 -> 17.5154 | E7: =E81 -> 37.2036 | F7: =F81 -> 53.970497 | G7: =G81 -> 61.850359
A8: 非 AI 營收 | B8: RMB B | C8: =C80 -> 10.6106 | D8: =D80 -> 10.6106 | E8: =E80 -> 10.6106 | F8: =F80 -> 10.6106 | G8: =G80 -> 10.6106
A9: 需求面 ÷ 產能上限 | B9: % | D9: =D86 -> 1 | E9: =E86 -> 1.1112198 | F9: =F86 -> 0.98631235 | G9: =G86 -> 0.91358087
A10: 毛利率 | B10: % | C10: =C92 -> 0.3522 | D10: =D92 -> 0.33090415 | E10: =E92 -> 0.3619859 | F10: =F92 -> 0.36373005 | G10: =G92 -> 0.35776293
A11: 營業利益率 | B11: % | C11: =C96 -> 0.26684636 | D11: =D96 -> 0.26591428 | E11: =E96 -> 0.30770024 | F11: =F96 -> 0.31508197 | G11: =G96 -> 0.31123098
A12: 歸屬母公司淨利 | B12: RMB B | C12: =C98 -> 4.312 | D12: =D98 -> 6.5441925 | E12: =E98 -> 12.582286 | F12: =F98 -> 17.46861 | G12: =G98 -> 19.379266 | H12: =H98 -> 21.343226 | I12: =I98 -> 23.065019 | J12: =J98 -> 24.448921
A13: 淨利率 | B13: % | C13: =C103 -> 0.22351234 | D13: =D103 -> 0.23267413 | E13: =E103 -> 0.26314957 | F13: =F103 -> 0.27049107 | G13: =G103 -> 0.26744424 | H13: =H103 -> 0.26744424 | I13: =I103 -> 0.26744424 | J13: =J103 -> 0.26744424
A14: EPS | B14: RMB | C14: =C101 -> 5.01 | D14: =D101 -> 6.9172066 | E14: =E101 -> 12.808484 | F14: =F101 -> 17.782652 | G14: =G101 -> 19.727657 | H14: =H101 -> 21.726923 | I14: =I101 -> 23.47967 | J14: =J101 -> 24.888451
A15: EPS 年增 | B15: % | D15: =D102 -> 0.38067996 | E15: =E102 -> 0.85168448 | F15: =F102 -> 0.38834946 | G15: =G102 -> 0.10937653 | H15: =H102 -> 0.10134333 | I15: =I102 -> 0.080671665 | J15: =J102 -> 0.06
A17: 情境 B
A18: 營收 | B18: RMB B | C18: =C129 -> 19.292 | D18: =D129 -> 28.126 | E18: =E129 -> 47.8142 | F18: =F129 -> 53.786998 | G18: =G129 -> 63.183405 | H18: =H129 -> 71.38447 | I18: =I129 -> 77.444931 | J18: =J129 -> 80.542729
A19: 營收年增 | B19: % | D19: =D130 -> 0.45791001 | E19: =E130 -> 0.7 | F19: =F130 -> 0.12491682 | G19: =G130 -> 0.17469664 | H19: =H130 -> 0.12979776 | I19: =I130 -> 0.08489888 | J19: =J130 -> 0.04
A20: AI 相關營收（AI 算力、資料中心、HPC） | B20: RMB B | C20: =C127 -> 8.6814 | D20: =D127 -> 17.5154 | E20: =E127 -> 37.2036 | F20: =F127 -> 43.176398 | G20: =G127 -> 52.572805
A21: 非 AI 營收 | B21: RMB B | C21: =C126 -> 10.6106 | D21: =D126 -> 10.6106 | E21: =E126 -> 10.6106 | F21: =F126 -> 10.6106 | G21: =G126 -> 10.6106
A22: 需求面 ÷ 產能上限 | B22: % | D22: =D132 -> 1 | E22: =E132 -> 1.1112198 | F22: =F132 -> 0.82145987 | G22: =G132 -> 0.79661036
A23: 毛利率 | B23: % | C23: =C138 -> 0.3522 | D23: =D138 -> 0.33090415 | E23: =E138 -> 0.3619859 | F23: =F138 -> 0.35874944 | G23: =G138 -> 0.35473331
A24: 營業利益率 | B24: % | C24: =C142 -> 0.26684636 | D24: =D142 -> 0.26591428 | E24: =E142 -> 0.30770024 | F24: =F142 -> 0.30687505 | G24: =G142 -> 0.30594475
A25: 歸屬母公司淨利 | B25: RMB B | C25: =C144 -> 4.312 | D25: =D144 -> 6.5441925 | E25: =E144 -> 12.582286 | F25: =F144 -> 14.137205 | G25: =G144 -> 16.586257 | H25: =H144 -> 17.04812 | I25: =I144 -> 16.660925 | J25: =J144 -> 15.419419
A26: 淨利率 | B26: % | C26: =C149 -> 0.22351234 | D26: =D149 -> 0.23267413 | E26: =E149 -> 0.26314957 | F26: =F149 -> 0.26283684 | G26: =G149 -> 0.26250971 | H26: =H149 -> 0.23882113 | I26: =I149 -> 0.21513255 | J26: =J149 -> 0.19144397
A27: EPS | B27: RMB | C27: =C147 -> 5.01 | D27: =D147 -> 6.9172066 | E27: =E147 -> 12.808484 | F27: =F147 -> 14.391356 | G27: =G147 -> 16.884437 | H27: =H147 -> 17.354602 | I27: =I147 -> 16.960447 | J27: =J147 -> 15.696622
A28: EPS 年增 | B28: % | D28: =D148 -> 0.38067996 | E28: =E148 -> 0.85168448 | F28: =F148 -> 0.12357996 | G28: =G148 -> 0.17323458 | H28: =H148 -> 0.027846082 | I28: =I148 -> -0.022711845 | J28: =J148 -> -0.074516024
A30: 情境 C
A31: 營收 | B31: RMB B | C31: =C175 -> 19.292 | D31: =D175 -> 28.126 | E31: =E175 -> 47.8142 | F31: =F175 -> 42.992898 | G31: =G175 -> 47.720816 | H31: =H175 -> 51.537518 | I31: =I175 -> 54.113874 | J31: =J175 -> 55.196151
A32: 營收年增 | B32: % | D32: =D176 -> 0.45791001 | E32: =E176 -> 0.7 | F32: =F176 -> -0.1008341 | G32: =G176 -> 0.10996973 | H32: =H176 -> 0.079979819 | I32: =I176 -> 0.04998991 | J32: =J176 -> 0.02
A33: AI 相關營收（AI 算力、資料中心、HPC） | B33: RMB B | C33: =C173 -> 8.6814 | D33: =D173 -> 17.5154 | E33: =E173 -> 37.2036 | F33: =F173 -> 32.382298 | G33: =G173 -> 37.110216
A34: 非 AI 營收 | B34: RMB B | C34: =C172 -> 10.6106 | D34: =D172 -> 10.6106 | E34: =E172 -> 10.6106 | F34: =F172 -> 10.6106 | G34: =G172 -> 10.6106
A35: 需求面 ÷ 產能上限 | B35: % | D35: =D178 -> 1 | E35: =E178 -> 1.1112198 | F35: =F178 -> 0.6566074 | G35: =G178 -> 0.6016595
A36: 毛利率 | B36: % | C36: =C184 -> 0.3522 | D36: =D184 -> 0.33090415 | E36: =E184 -> 0.3619859 | F36: =F184 -> 0.35126789 | G36: =G184 -> 0.34706616
A37: 營業利益率 | B37: % | C37: =C188 -> 0.26684636 | D37: =D188 -> 0.26591428 | E37: =E188 -> 0.30770024 | F37: =F188 -> 0.29089454 | G37: =G188 -> 0.2890854
A38: 歸屬母公司淨利 | B38: RMB B | C38: =C190 -> 4.312 | D38: =D190 -> 6.5441925 | E38: =E190 -> 12.582286 | F38: =F190 -> 10.669648 | G38: =G190 -> 11.787204 | H38: =H190 -> 10.554627 | I38: =I190 -> 8.7981917 | J38: =J190 -> 6.6444147
A39: 淨利率 | B39: % | C39: =C195 -> 0.22351234 | D39: =D195 -> 0.23267413 | E39: =E195 -> 0.26314957 | F39: =F195 -> 0.24817234 | G39: =G195 -> 0.24700341 | H39: =H195 -> 0.20479501 | I39: =I195 -> 0.16258662 | J39: =J195 -> 0.12037822
A40: EPS | B40: RMB | C40: =C193 -> 5.01 | D40: =D193 -> 6.9172066 | E40: =E193 -> 12.808484 | F40: =F193 -> 10.861462 | G40: =G193 -> 11.999108 | H40: =H193 -> 10.744372 | I40: =I193 -> 8.9563611 | J40: =J193 -> 6.7638645
A41: EPS 年增 | B41: % | D41: =D194 -> 0.38067996 | E41: =E194 -> 0.85168448 | F41: =F194 -> -0.15201037 | G41: =G194 -> 0.10474157 | H41: =H194 -> -0.10456911 | I41: =I194 -> -0.16641374 | J41: =J194 -> -0.2447977
A43: 核對（應為 0）：FY2026 模型 − 錨點
...

Sheet Val
A1: Val — P/E 估值（人民幣）。結論用「現價 ÷ FY2027、FY2028 EPS（模型）」；目標價＝DCF 與 Comparable 加權（第 0 節）；十年 P/E 規則值（第 3 節，年底落後 P/E）只作參考。本版未做先驗，無 Andy 合理 P/E 對照
A2: 循環位置：勝宏不是設備股，不套設備市場見頂年；以本模型營收最高的會計年度為見頂年（比照台光電、Arista、台達電；FY(t)＝CY(t)）。營收到 FY2029 仍在增加時，見頂年未知，判為中段
A4: 0. 目標價
A5: 0.1 DCF（股東權益現金流，FY2027–FY2032 明確期＋FY2032 後永續）
A6: 項目 | B6: A（順利） | C6: B（平平） | D6: C（不如預期） | E6: 說明
A7: 情境 EPS（FY2027–FY2032） | E7: PL 頁各情境；FY2030 起為收斂法
A8: FY2027 | B8: =PL!E14 -> 12.808484 | C8: =PL!E27 -> 12.808484 | D8: =PL!E40 -> 12.808484
A9: FY2028 | B9: =PL!F14 -> 17.782652 | C9: =PL!F27 -> 14.391356 | D9: =PL!F40 -> 10.861462
A10: FY2029 | B10: =PL!G14 -> 19.727657 | C10: =PL!G27 -> 16.884437 | D10: =PL!G40 -> 11.999108
A11: FY2030 | B11: =PL!H14 -> 21.726923 | C11: =PL!H27 -> 17.354602 | D11: =PL!H40 -> 10.744372
A12: FY2031 | B12: =PL!I14 -> 23.47967 | C12: =PL!I27 -> 16.960447 | D12: =PL!I40 -> 8.9563611
A13: FY2032 | B13: =PL!J14 -> 24.888451 | C13: =PL!J27 -> 15.696622 | D13: =PL!J40 -> 6.7638645
A14: 股東現金流＝EPS ×（1 − tp_g ÷ tp_roe）
A15: 再投資率（tp_g ÷ tp_roe，上限 0.8） | B15: =MIN(tp_g/tp_roe,0.8) -> 0.2038736 | E15: ROE 為近三年平均（In 頁 tp_roe）
A16: FY2027 | B16: =B8*(1-$B$15) -> 10.197172 | C16: =C8*(1-$B$15) -> 10.197172 | D16: =D8*(1-$B$15) -> 10.197172
A17: FY2028 | B17: =B9*(1-$B$15) -> 14.157239 | C17: =C9*(1-$B$15) -> 11.457338 | D17: =D9*(1-$B$15) -> 8.6470964
A18: FY2029 | B18: =B10*(1-$B$15) -> 15.705708 | C18: =C10*(1-$B$15) -> 13.442146 | D18: =D10*(1-$B$15) -> 9.5528069
A19: FY2030 | B19: =B11*(1-$B$15) -> 17.297377 | C19: =C11*(1-$B$15) -> 13.816457 | D19: =D11*(1-$B$15) -> 8.5538784
A20: FY2031 | B20: =B12*(1-$B$15) -> 18.692785 | C20: =C12*(1-$B$15) -> 13.50266 | D20: =D12*(1-$B$15) -> 7.1303955
A21: FY2032 | B21: =B13*(1-$B$15) -> 19.814353 | C21: =C13*(1-$B$15) -> 12.496495 | D21: =D13*(1-$B$15) -> 5.3848911
A22: DCF 情境每股價值（折現率 tp_r） | B22: =SUMPRODUCT(B16:B21,1/(1+tp_r)^{1;2;3;4;5;6})+B21*(1+tp_g)/(tp_r-tp_g)/(1+tp_r)^6 -> 261.24394 | C22: =SUMPRODUCT(C16:C21,1/(1+tp_r)^{1;2;3;4;5;6})+C21*(1+tp_g)/(tp_r-tp_g)/(1+tp_r)^6 -> 175.98157 | D22: =SUMPRODUCT(D16:D21,1/(1+tp_r)^{1;2;3;4;5;6})+D21*(1+tp_g)/(tp_r-tp_g)/(1+tp_r)^6 -> 89.590073 | E22: Σ 明確期現金流 ÷ (1＋r)^t ＋ 永續價值 ÷ (1＋r)^6；永續價值＝FY2032 現金流 ×(1＋g)÷(r−g)；基準日 2026 年底
A23: DCF 情境價值推到 12 個月後（×(1＋tp_r)） | B23: =B22*(1+tp_r) -> 287.36834 | C23: =C22*(1+tp_r) -> 193.57972 | D23: =D22*(1+tp_r) -> 98.54908
A24: DCF 目標價（情境加權） | B24: =tp_wA*B23+tp_wB*C23+tp_wC*D23 -> 202.71018 | E24: Σ 權重 × 情境價值 ×(1＋r)；權重見 In 頁
A26: 0.2 Comparable（市場主流同業前瞻 P/E；A 股公司只用 A 股同業）
A27: 同業與前瞻 P/E | B27: 代號 | C27: 前瞻 12 月 P/E | D27: 日期 | E27: 來源 | F27: 標記
A28: 沪电股份（WUS Printed Circuit） | B28: 002463.SZ | C28: 20.66 | D28: 2026-10-22 | E28: stockanalysis.com forward PE（分析師共識；價格日期如左） | F28: Interested-party
A29: 深南电路（Shennan Circuits） | B29: 002916.SZ | C29: 40.68 | D29: 2026-09-14 | E29: stockanalysis.com forward PE（分析師共識；價格日期如左） | F29: Interested-party
A30: 生益电子（Shengyi Electronics） | B30: 688183.SS | C30: 29.59 | D30: 2026-09-28 | E30: stockanalysis.com forward PE（分析師共識；價格日期如左） | F30: Interested-party
A31: 鹏鼎控股（Avary） | B31: 002938.SZ | C31: 31.99 | D31: 2026-09-18 | E31: stockanalysis.com forward PE（分析師共識；價格日期如左） | F31: Interested-party
A32: 並列參考（非 A 股，不進目標價）：金像電 2368.TW 前瞻 P/E 19.6x（10-22）、TTM Technologies TTMI 10.3x（10-23）；stockanalysis，Interested-party
A33: 同業前瞻 P/E 中位數 | B33: =MEDIAN(C28:C31) -> 30.79 | E33: A 股 PCB 同業：沪电、深南、生益电子、鹏鼎（券商常用比較組；摩根大通稱 A 股 PCB 同業 2027 年平均約 30x）；景旺电子前瞻 P/E 未找到
A34: 12 個月後的前瞻 EPS（情境加權） | B34: =tp_wA*(2/12*B8+10/12*B9)+tp_wB*(2/12*C8+10/12*C9)+tp_wC*(2/12*D8+10/12*D9) -> 14.387052 | E34: 約 2027-10 時的未來 12 月 EPS ≈ 2／12 × FY2027＋10／12 × FY2028（會計年度＝日曆年）
A35: Comparable 目標價 | B35: =B33*B34 -> 442.97734 | E35: 同業中位數 × 前瞻 EPS
A37: 0.3 結論
A38: 項目 | B38: 數值 | E38: 說明
A39: 目標價（DCF 與 Comparable 加權） | B39: =tp_w_dcf*B24+(1-tp_w_dcf)*tp_comp_adj -> 303.2377 | E39: tp_w_dcf × DCF＋（1 − tp_w_dcf）× Comparable；tp_w_dcf 見 In 頁
A40: Comparable 目標價（市場主流同業法） | B40: =B35 -> 442.97734
A41: 市場共識目標價 | B41: =cons_tp -> 388.3 | E41: stockanalysis：8 位分析師平均 388.30（2026-10-23 擷取）；多數目標價訂於 9–10 月股價下跌前
A42: 上檔空間：加權目標價 | B42: =B39/px-1 -> 0.65270163 | E42: 現價＝In 頁 px（2026-10-23 收盤）
A43: 上檔空間：Comparable 目標價 | B43: =B40/px-1 -> 1.4143086
...

Sheet Recon
A1: Recon — 本模型 vs 共識、券商估計、研調每架 PCB 金額與台光電模型的每 GW CCL 金額。只作事後對照，不為對上數字而調參數。共識取自同花順（14 家）；券商多為單一來源
A3: 項目 | B3: 對照值 | C3: 模型 A | D3: 差距 A | E3: 模型 B | F3: 差距 B | G3: 模型 C | H3: 差距 C | I3: 對照來源 | J3: 說明
A4: A. 共識與券商估計（校準未使用）
A5: FY2026 營收 vs 共識（同花順） | B5: =cons_rev26 -> 31.604 | C5: =PL!D83 -> 28.126 | D5: =C5/B5-1 -> -0.11004936 | E5: =PL!D129 -> 28.126 | F5: =E5/B5-1 -> -0.11004936 | G5: =PL!D175 -> 28.126 | H5: =G5/B5-1 -> -0.11004936 | I5: 同花順 14 家（2026-10-24） | J5: 共識隱含下半年 200 億、較上半年 +72%；本模型 3Q +20%、4Q +25%
A6: FY2026 EPS vs 共識（同花順） | B6: =cons_eps26 -> 8.61 | C6: =PL!D101 -> 6.9172066 | D6: =C6/B6-1 -> -0.19660783 | E6: =PL!D147 -> 6.9172066 | F6: =E6/B6-1 -> -0.19660783 | G6: =PL!D193 -> 6.9172066 | H6: =G6/B6-1 -> -0.19660783 | I6: 同花順 14 家 | J6: 3Q26 季報（10-29）前；共識最新報告 2026-09-07
A7: FY2026 EPS vs 摩根大通（06-11） | B7: =jpm_eps26 -> 9.2 | C7: =PL!D101 -> 6.9172066 | D7: =C7/B7-1 -> -0.24812972 | E7: =PL!D147 -> 6.9172066 | F7: =E7/B7-1 -> -0.24812972 | G7: =PL!D193 -> 6.9172066 | H7: =G7/B7-1 -> -0.24812972 | I7: 摩根大通 2026-06-11
A8: FY2027 營收 vs 共識（同花順） | B8: =cons_rev27 -> 51.477 | C8: =PL!E83 -> 47.8142 | D8: =C8/B8-1 -> -0.071154108 | E8: =PL!E129 -> 47.8142 | F8: =E8/B8-1 -> -0.071154108 | G8: =PL!E175 -> 47.8142 | H8: =G8/B8-1 -> -0.071154108 | I8: 同花順 14 家
A9: FY2027 營收 vs 摩根大通 | B9: =jpm_rev27 -> 60 | C9: =PL!E83 -> 47.8142 | D9: =C9/B9-1 -> -0.20309667 | E9: =PL!E129 -> 47.8142 | F9: =E9/B9-1 -> -0.20309667 | G9: =PL!E175 -> 47.8142 | H9: =G9/B9-1 -> -0.20309667 | I9: 摩根大通 2026-06-11
A10: FY2027 EPS vs 共識（同花順） | B10: =cons_eps27 -> 14.77 | C10: =PL!E101 -> 12.808484 | D10: =C10/B10-1 -> -0.13280406 | E10: =PL!E147 -> 12.808484 | F10: =E10/B10-1 -> -0.13280406 | G10: =PL!E193 -> 12.808484 | H10: =G10/B10-1 -> -0.13280406 | I10: 同花順 14 家 | J10: 區間 10.42–17.45
A11: FY2027 EPS vs 摩根大通 | B11: =jpm_eps27 -> 17.55 | C11: =PL!E101 -> 12.808484 | D11: =C11/B11-1 -> -0.27017185 | E11: =PL!E147 -> 12.808484 | F11: =E11/B11-1 -> -0.27017185 | G11: =PL!E193 -> 12.808484 | H11: =G11/B11-1 -> -0.27017185 | I11: 摩根大通 2026-06-11
A12: FY2027 EPS vs 高盛隱含（目標價 550 ÷ 26.3 倍） | B12: =gs_eps27 -> 20.912548 | C12: =PL!E101 -> 12.808484 | D12: =C12/B12-1 -> -0.38752158 | E12: =PL!E147 -> 12.808484 | F12: =E12/B12-1 -> -0.38752158 | G12: =PL!E193 -> 12.808484 | H12: =G12/B12-1 -> -0.38752158 | I12: 高盛 2026-09-03（騰訊新聞轉述） | J12: 由目標價推算，非原文數字
A13: FY2028 營收 vs 共識（同花順） | B13: =cons_rev28 -> 74.435 | C13: =PL!F83 -> 64.581097 | D13: =C13/B13-1 -> -0.13238266 | E13: =PL!F129 -> 53.786998 | F13: =E13/B13-1 -> -0.27739642 | G13: =PL!F175 -> 42.992898 | H13: =G13/B13-1 -> -0.42241018 | I13: 同花順 14 家
A14: FY2028 EPS vs 共識（同花順） | B14: =cons_eps28 -> 22.13 | C14: =PL!F101 -> 17.782652 | D14: =C14/B14-1 -> -0.19644591 | E14: =PL!F147 -> 14.391356 | F14: =E14/B14-1 -> -0.34969019 | G14: =PL!F193 -> 10.861462 | H14: =G14/B14-1 -> -0.50919739 | I14: 同花順 14 家 | J14: 區間 14.70–26.17
A15: FY2028 EPS vs 摩根大通 | B15: =jpm_eps28 -> 26.06 | C15: =PL!F101 -> 17.782652 | D15: =C15/B15-1 -> -0.31762655 | E15: =PL!F147 -> 14.391356 | F15: =E15/B15-1 -> -0.44776071 | G15: =PL!F193 -> 10.861462 | H15: =G15/B15-1 -> -0.58321329 | I15: 摩根大通 2026-06-11
A16: B. 每 GW PCB 金額 vs 台光電每 GW CCL 金額（口徑分開；機制檢查）
A17: CY2026 每 GW PCB 金額（本模型）vs 每 GW CCL 金額（台光電模型） | B17: =emc_ccl26 -> 350 | C17: =PL!D69 -> 450 | D17: =C17/B17-1 -> 0.28571429 | E17: =PL!D115 -> 450 | F17: =E17/B17-1 -> 0.28571429 | G17: =PL!D161 -> 450 | H17: =G17/B17-1 -> 0.28571429 | I17: emc/dist Units 頁（唯讀） | J17: 差距＝PCB ÷ CCL − 1。PCB 售價含 CCL 與銅箔、鑽孔、電鍍、HDI 增層等製程；本模型範圍含光模組板與電源板，台光電範圍含非 AI 高速材料，比例只作量級檢查
A18: CY2027 每 GW PCB 金額（本模型）vs 每 GW CCL 金額（台光電模型） | B18: =emc_ccl27 -> 527.5 | C18: =PL!E69 -> 682 | D18: =C18/B18-1 -> 0.292891 | E18: =PL!E115 -> 682 | F18: =E18/B18-1 -> 0.292891 | G18: =PL!E161 -> 682 | H18: =G18/B18-1 -> 0.292891 | I18: emc/dist Units 頁（唯讀） | J18: —
A19: CY2028 每 GW PCB 金額（本模型）vs 每 GW CCL 金額（台光電模型） | B19: =emc_ccl28 -> 609 | C19: =PL!F69 -> 792 | D19: =C19/B19-1 -> 0.30049261 | E19: =PL!F115 -> 792 | F19: =E19/B19-1 -> 0.30049261 | G19: =PL!F161 -> 792 | H19: =G19/B19-1 -> 0.30049261 | I19: emc/dist Units 頁（唯讀） | J19: —
A20: CY2026 每 GW PCB ÷ 每 GW CCL（本模型 ÷ 台光電模型）vs Morgan Stanley 每架 PCB ÷ 每架 CCL（GB300） | B20: =ms_rk_gb/ms_ccl_gb -> 5.2427184 | C20: =PL!D69/emc_ccl26 -> 1.2857143 | D20: =C20/B20-1 -> -0.7547619 | E20: =PL!D115/emc_ccl26 -> 1.2857143 | F20: =E20/B20-1 -> -0.7547619 | G20: =PL!D161/emc_ccl26 -> 1.2857143 | H20: =G20/B20-1 -> -0.7547619 | I20: Morgan Stanley 每架 PCB 35.1K（國金證券轉引）÷ 每架 CCL 6.695K（Deep News 轉述） | J20: 兩模型的比例遠低於每架口徑：台光電每 GW CCL 金額範圍較寬（含非 AI 高速材料）或本模型每 GW PCB 偏低；水準只影響校準份額，不影響營收成長
A21: CY2027 每 GW 金額指數（÷ CY2026）：PCB（本模型）vs CCL（台光電模型） | B21: =emc_ccl27/emc_ccl26 -> 1.5071429 | C21: =PL!E69/PL!D69 -> 1.5155556 | D21: =C21/B21-1 -> 0.0055818852 | E21: =PL!E115/PL!D115 -> 1.5155556 | F21: =E21/B21-1 -> 0.0055818852 | G21: =PL!E161/PL!D161 -> 1.5155556 | H21: =G21/B21-1 -> 0.0055818852 | I21: emc/dist | J21: 兩者世代升級幅度的對照
A22: CY2027 每 GW 勝宏 AI 營收 vs 每 GW 台光電 AI 營收（US$M） | B22: =emc_pg27 -> 180.40841 | C22: =PL!E87 -> 132.93349 | D22: =C22/B22-1 -> -0.26315248 | E22: =PL!E133 -> 132.93349 | F22: =E22/B22-1 -> -0.26315248 | G22: =PL!E179 -> 132.93349 | H22: =G22/B22-1 -> -0.26315248 | I22: emc/dist | J22: 下游 PCB 廠每 GW 營收 ÷ 上游 CCL 廠每 GW 營收
A23: CY2027 每 GW 金額指數（÷ CY2026）vs Morgan Stanley 每架 PCB 換算 | B23: =(ms_rk_vr*racks_vr)/(ms_rk_gb*racks_gb*(1-vr26)+ms_rk_vr*racks_vr*vr26) -> 1.6350017 | C23: =PL!E69/PL!D69 -> 1.5155556 | D23: =C23/B23-1 -> -0.073055689 | E23: =PL!E115/PL!D115 -> 1.5155556 | F23: =E23/B23-1 -> -0.073055689 | G23: =PL!E161/PL!D161 -> 1.5155556 | H23: =G23/B23-1 -> -0.073055689 | I23: Morgan Stanley 每架 GB300 35.1K、VR200 116.7K 美元（國金證券轉引）× 每 GW 架數 | J23: 對照值以 2026 年 Rubin 占比混合
A24: CY2026 每 GW PCB 金額 vs Morgan Stanley 每架金額 × 每 GW 架數（US$M） | B24: =(ms_rk_gb*racks_gb*(1-vr26)+ms_rk_vr*racks_vr*vr26)/1000 -> 289.21584 | C24: =PL!D69 -> 450 | D24: =C24/B24-1 -> 0.55593138 | E24: =PL!D115 -> 450 | F24: =E24/B24-1 -> 0.55593138 | G24: =PL!D161 -> 450 | H24: =G24/B24-1 -> 0.55593138 | I24: 同上 | J24: Morgan Stanley 只含 NVL72 機架內 PCB；本模型另含 scale-out 交換器、光模組、ASIC 伺服器
A25: FY2026 勝宏有效份額 vs 摩根大通 AI／HPC PCB 份額 1H25（Prismark） | B25: =jpm_sh -> 0.138 | C25: =PL!D73 -> 0.24753179 | D25: =C25-B25 -> 0.10953179 | E25: =PL!D119 -> 0.24753179 | F25: =E25-B25 -> 0.10953179 | G25: =PL!D165 -> 0.24753179 | H25: =G25-B25 -> 0.10953179 | I25: 摩根大通 2026-06-11 | J25: 口徑不同：本模型分母只含 AI 部署（含 ASIC）
A26: C. 產能與校準
A27: FY2027 需求面 ÷ 產能上限 | C27: =PL!E86 -> 1.1112198 | E27: =PL!E132 -> 1.1112198 | G27: =PL!E178 -> 1.1112198 | I27: — | J27: 大於 100%＝產能受限
A28: FY2028 需求面 ÷ 產能上限 | C28: =PL!F86 -> 0.98631235 | E28: =PL!F132 -> 0.82145987 | G28: =PL!F178 -> 0.6566074 | I28: —
A29: 其他營收毛利率（Derived） | C29: =PL!D89 -> 0.237492 | E29: =PL!D135 -> 0.237492 | G29: =PL!D181 -> 0.237492 | I29: FY2026 錨點 | J29: AI 相關毛利率＝此值＋d_ai
A30: FY2027 毛利率 vs FY2026（百分點） | B30: =a26_gp/a26_rev -> 0.33090415 | C30: =PL!E92 -> 0.3619859 | D30: =C30-B30 -> 0.03108175 | E30: =PL!E138 -> 0.3619859 | F30: =E30-B30 -> 0.03108175 | G30: =PL!E184 -> 0.3619859 | H30: =G30-B30 -> 0.03108175 | I30: 錨點 | J30: 摩根大通預估 2027 年 41.3%
A31: 4Q26 EPS（模型） | C31: =Q!E15 -> 2.0912649 | E31: =Q!E15 -> 2.0912649 | G31: =Q!E15 -> 2.0912649 | I31: — | J31: 3Q26 季報 2026-10-29 公布
A32: D. 預留
A33: R4 產業部署路徑（markets/deploy_path/，尚未建立）：上線後以部署路徑取代「AI IT 資本支出 ÷ 每 GW IT 資本支出」 | J33: 預留列：本版無數值

Sheet Sens
A1: Sens — 一次動一個輸入（情境 A；有效份額、其他營收毛利率在每個案例內依 FY2026 錨點重算，FY2026 恆等於錨點）：對 FY2027、FY2028 的營收、AI 相關營收、毛利率與 EPS 的影響。每個案例是一個完整推導區塊（本頁下方）
A3: 案例 | B3: 設定 | C3: FY2027 營收 | D3: FY2027 AI 相關 | E3: FY2027 毛利率 | F3: FY2027 EPS | G3: FY2027 EPS 相對基準 | H3: FY2028 營收 | I3: FY2028 AI 相關 | J3: FY2028 毛利率 | K3: FY2028 EPS | L3: FY2028 EPS 相對基準
A4: 基準（情境 A） | B4: PL 區塊 A | C4: =PL!E83 -> 47.8142 | D4: =PL!E81 -> 37.2036 | E4: =PL!E92 -> 0.3619859 | F4: =PL!E101 -> 12.808484 | G4: =F4/F$4-1 -> 0 | H4: =PL!F83 -> 64.581097 | I4: =PL!F81 -> 53.970497 | J4: =PL!F92 -> 0.36373005 | K4: =PL!F101 -> 17.782652 | L4: =K4/K$4-1 -> 0
A5: 每 GW 金額成長 低 | B5: 三項指數皆取低值（運算板 2027 1.25、交換器 1.15、中板 1.40） | C5: =E68 -> 45.400906 | D5: =E66 -> 34.790306 | E5: =E77 -> 0.36009856 | F5: =E86 -> 12.044905 | G5: =F5/F$4-1 -> -0.059615139 | H5: =F68 -> 52.723942 | I5: =F66 -> 42.113342 | J5: =F77 -> 0.35814861 | K5: =F86 -> 14.067892 | L5: =K5/K$4-1 -> -0.20889796
A6: 每 GW 金額成長 高 | B6: 三項指數皆取高值（運算板 2027 1.75、交換器 1.60、中板 2.60） | C6: =E114 -> 47.8142 | D6: =E112 -> 37.2036 | E6: =E123 -> 0.3619859 | F6: =E132 -> 12.808484 | G6: =F6/F$4-1 -> 0 | H6: =F114 -> 65.477328 | I6: =F112 -> 54.866728 | J6: =F123 -> 0.36406976 | K6: =F132 -> 18.06423 | L6: =K6/K$4-1 -> 0.01583444
A7: 中板／背板成長 低 | B7: 只動中板／背板／其他指數（2027 1.40、2028 1.80） | C7: =E160 -> 47.8142 | D7: =E158 -> 37.2036 | E7: =E169 -> 0.3619859 | F7: =E178 -> 12.808484 | G7: =F7/F$4-1 -> 0 | H7: =F160 -> 60.492423 | I7: =F158 -> 49.881823 | J7: =F169 -> 0.36205258 | K7: =F178 -> 16.49807 | L7: =K7/K$4-1 -> -0.072237921
A8: 中板／背板成長 高 | B8: 只動中板／背板／其他指數（2027 2.60、2028 4.00） | C8: =E206 -> 47.8142 | D8: =E204 -> 37.2036 | E8: =E215 -> 0.3619859 | F8: =E224 -> 12.808484 | G8: =F8/F$4-1 -> 0 | H8: =F206 -> 65.477328 | I8: =F204 -> 54.866728 | J8: =F215 -> 0.36406976 | K8: =F224 -> 18.06423 | L8: =K8/K$4-1 -> 0.01583444
A9: 份額流失（低） | B9: 份額相對值 2027 0.70、2028 0.60、2029 0.55（Rubin 份額傳聞情境） | C9: =E252 -> 43.682866 | D9: =E250 -> 33.072266 | E9: =E261 -> 0.35862788 | F9: =E270 -> 11.501307 | G9: =F9/F$4-1 -> -0.10205555 | H9: =F252 -> 51.088473 | I9: =F250 -> 40.477873 | J9: =F261 -> 0.35717544 | K9: =F270 -> 13.561279 | L9: =K9/K$4-1 -> -0.23738717
A10: 份額維持（高） | B10: 份額相對值 2027–28 1.00、2029 0.95 | C10: =E298 -> 47.8142 | D10: =E296 -> 37.2036 | E10: =E307 -> 0.3619859 | F10: =E316 -> 12.808484 | G10: =F10/F$4-1 -> 0 | H10: =F298 -> 65.477328 | I10: =F296 -> 54.866728 | J10: =F307 -> 0.36406976 | K10: =F316 -> 18.06423 | L10: =K10/K$4-1 -> 0.01583444
A11: 價格回落快 | B11: 價格指數 2027 0.95、2028 0.90、2029 0.85 | C11: =E344 -> 45.42349 | D11: =E342 -> 34.81289 | E11: =E353 -> 0.33541028 | F11: =E362 -> 11.061548 | G11: =F11/F$4-1 -> -0.136389 | H11: =F344 -> 60.686319 | I11: =F342 -> 50.075719 | J11: =F353 -> 0.3216114 | K11: =F362 -> 14.395434 | L11: =K11/K$4-1 -> -0.19047879
A12: 價格延續 | B12: 價格指數 2027 1.03、2028 1.02、2029 1.00 | C12: =E390 -> 49.248626 | D12: =E388 -> 38.638026 | E12: =E399 -> 0.37701646 | F12: =E408 -> 13.870715 | G12: =F12/F$4-1 -> 0.0829318 | H12: =F390 -> 67.363081 | I12: =F388 -> 56.752481 | J12: =F399 -> 0.39083292 | K12: =F408 -> 20.203268 | L12: =K12/K$4-1 -> 0.13612234
A13: 擴產延遲 | B13: 產能指數 2027 1.45、2028 1.95、2029 2.40 | C13: =E436 -> 40.7827 | D13: =E434 -> 30.1721 | E13: =E445 -> 0.35586415 | F13: =E454 -> 10.583678 | G13: =F13/F$4-1 -> -0.17369781 | H13: =F436 -> 53.200329 | I13: =F434 -> 42.589729 | J13: =F445 -> 0.35842083 | K13: =F454 -> 14.229557 | L13: =K13/K$4-1 -> -0.19980683
A14: 擴產提前 | B14: 產能指數 2027 1.90、2028 2.80、2029 3.40 | C14: =E482 -> 53.132085 | D14: =E480 -> 42.521485 | E14: =E491 -> 0.36553963 | F14: =E500 -> 14.491093 | G14: =F14/F$4-1 -> 0.13136672 | H14: =F482 -> 64.581097 | I14: =F480 -> 53.970497 | J14: =F491 -> 0.36373005 | K14: =F500 -> 17.761787 | L14: =K14/K$4-1 -> -0.0011733229
A15: AI 毛利率未改善 | B15: 額外改善 2027–29 皆 −1pt | C15: =E528 -> 47.8142 | D15: =E526 -> 37.2036 | E15: =E537 -> 0.34642416 | F15: =E546 -> 12.151776 | G15: =F15/F$4-1 -> -0.05127132 | H15: =F528 -> 64.581097 | I15: =F526 -> 53.970497 | J15: =F537 -> 0.33865902 | K15: =F546 -> 16.353643 | L15: =K15/K$4-1 -> -0.080359719
A16: AI 毛利率改善 快 | B16: 額外改善 2027 +3pt、2028 +4pt、2029 +5pt | C16: =E574 -> 47.8142 | D16: =E572 -> 37.2036 | E16: =E583 -> 0.37754763 | F16: =E592 -> 13.465192 | G16: =F16/F$4-1 -> 0.05127132 | H16: =F574 -> 64.581097 | I16: =F572 -> 53.970497 | J16: =F583 -> 0.38044408 | K16: =F592 -> 18.735325 | L16: =K16/K$4-1 -> 0.053573146
A17: AI 部署 ×0.8 | B17: FY2027 起 AI IT 資本支出 ×0.8 | C17: =E620 -> 44.627788 | D17: =E618 -> 34.017188 | E17: =E629 -> 0.35945077 | F17: =E638 -> 11.800286 | G17: =F17/F$4-1 -> -0.078713324 | H17: =F620 -> 53.786998 | I17: =F618 -> 43.176398 | J17: =F629 -> 0.35874944 | K17: =F638 -> 14.404122 | L17: =K17/K$4-1 -> -0.1899902
A18: AI 部署 ×1.2 | B18: ×1.2 | C18: =E666 -> 47.8142 | D18: =E664 -> 37.2036 | E18: =E675 -> 0.3619859 | F18: =E684 -> 12.808484 | G18: =F18/F$4-1 -> 0 | H18: =F666 -> 65.477328 | I18: =F664 -> 54.866728 | J18: =F675 -> 0.36406976 | K18: =F684 -> 18.06423 | L18: =K18/K$4-1 -> 0.01583444
A19: AI 毛利率差距 10pt | B19: AI 相關毛利率只高 10 個百分點 | C19: =E712 -> 47.8142 | D19: =E710 -> 37.2036 | E19: =E721 -> 0.35421893 | F19: =E730 -> 12.480717 | G19: =F19/F$4-1 -> -0.025589837 | H19: =F712 -> 64.581097 | I19: =F710 -> 53.970497 | J19: =F721 -> 0.35259485 | K19: =F730 -> 17.147963 | L19: =K19/K$4-1 -> -0.035691471
A20: AI 毛利率差距 20pt | B20: 高 20 個百分點 | C20: =E758 -> 47.8142 | D20: =E756 -> 37.2036 | E20: =E767 -> 0.36975286 | F20: =E776 -> 13.136251 | G20: =F20/F$4-1 -> 0.025589837 | H20: =F758 -> 64.581097 | I20: =F756 -> 53.970497 | J20: =F767 -> 0.37486526 | K20: =F776 -> 18.417341 | L20: =K20/K$4-1 -> 0.035691471
A21: 非 AI 成長 低 | B21: 2027–29 −5% | C21: =E804 -> 47.8142 | D21: =E802 -> 37.73413 | E21: =E813 -> 0.3637612 | F21: =E822 -> 12.883402 | G21: =F21/F$4-1 -> 0.0058491056 | H21: =F804 -> 63.546564 | I21: =F802 -> 53.970497 | J21: =F813 -> 0.3657852 | K21: =F822 -> 17.595546 | L21: =K21/K$4-1 -> -0.010521822
A22: 非 AI 成長 高 | B22: 2027–29 +5% | C22: =E850 -> 47.8142 | D22: =E848 -> 36.67307 | E22: =E859 -> 0.36021059 | F22: =E868 -> 12.733566 | G22: =F22/F$4-1 -> -0.0058491056 | H22: =F850 -> 65.477328 | I22: =F848 -> 53.779142 | J22: =F859 -> 0.36156069 | K22: =F868 -> 17.919233 | L22: =K22/K$4-1 -> 0.0076805692
A23: 營業費用彈性 1.0 | B23: 基準 0.6 | C23: =E896 -> 47.8142 | D23: =E894 -> 37.2036 | E23: =E905 -> 0.3619859 | F23: =E914 -> 12.356765 | G23: =F23/F$4-1 -> -0.035267217 | H23: =F896 -> 64.581097 | I23: =F894 -> 53.970497 | J23: =F905 -> 0.36373005 | K23: =F914 -> 16.851196 | L23: =K23/K$4-1 -> -0.05238003
A24: 顆數情境 B | B24: CY2028 ×0.8、CY2029 ×0.85 | C24: =PL!E129 -> 47.8142 | D24: =PL!E127 -> 37.2036 | E24: =PL!E138 -> 0.3619859 | F24: =PL!E147 -> 12.808484 | G24: =F24/F$4-1 -> 0 | H24: =PL!F129 -> 53.786998 | I24: =PL!F127 -> 43.176398 | J24: =PL!F138 -> 0.35874944 | K24: =PL!F147 -> 14.391356 | L24: =K24/K$4-1 -> -0.19070811
A25: 顆數情境 C | B25: CY2028–29 ×0.6 | C25: =PL!E175 -> 47.8142 | D25: =PL!E173 -> 37.2036 | E25: =PL!E184 -> 0.3619859 | F25: =PL!E193 -> 12.808484 | G25: =F25/F$4-1 -> 0 | H25: =PL!F175 -> 42.992898 | I25: =PL!F173 -> 32.382298 | J25: =PL!F184 -> 0.35126789 | K25: =PL!F193 -> 10.861462 | L25: =K25/K$4-1 -> -0.38921024
A27: 讀法：FY2027 三情境相同；顆數情境 B、C 的差異從 FY2028 起。產能受限的年度，需求面輸入（每 GW 金額、份額、AI 部署）對營收的影響被產能上限截斷，只有產能與價格會改變營收；價格指數同時改變產能上限營收與 AI 毛利率（成本不變），所以對 EPS 的影響大於對營收。
A29: 目標價參數（只改 DCF 參數；PL 收斂法的 fade_g 不隨 tp_g 變動）
A30: 案例 | B30: 設定 | C30: DCF 目標價 | D30: Comparable 目標價（相對倍數調整後） | E30: 加權目標價 | F30: 相對基準
A31: 基準 | B31: r 10%、g 4%、DCF 權重 0.5 | C31: =(tp_wA*(Val!B8*(1-MIN(tp_g/tp_roe,0.8))/(1+tp_r)^1+Val!B9*(1-MIN(tp_g/tp_roe,0.8))/(1+tp_r)^2+Val!B10*(1-MIN(tp_g/tp_roe,0.8))/(1+tp_r)^3+Val!B11*(1-MIN(tp_g/tp_roe,0.8))/(1+tp_r)^4+Val!B12*(1-MIN(tp_g/tp_roe,0.8))/(1+tp_r)^5+Val!B13*(1-MIN(tp_g/tp_roe,0.8))/(1+tp_r)^6+Val!B13*(1-MIN(tp_g/tp_roe,0.8))*(1+tp_g)/(tp_r-tp_g)/(1+tp_r)^6)+tp_wB*(Val!C8*(1-MIN(tp_g/tp_roe,0.8))/(1+tp_r)^1+Val!C9*(1-MIN(tp_g/tp_roe,0.8))/(1+tp_r)^2+Val!C10*(1-MIN(tp_g/tp_roe,0.8))/(1+tp_r)^3+Val!C11*(1-MIN(tp_g/tp_roe,0.8))/(1+tp_r)^4+Val!C12*(1-MIN(tp_g/tp_roe,0.8))/(1+tp_r)^5+Val!C13*(1-MIN(tp_g/tp_roe,0.8))/(1+tp_r)^6+Val!C13*(1-MIN(tp_g/tp_roe,0.8))*(1+tp_g)/(tp_r-tp_g)/(1+tp_r)^6)+tp_wC*(Val!D8*(1-MIN(tp_g/tp_roe,0.8))/(1+tp_r)^1+Val!D9*(1-MIN(tp_g/tp_roe,0.8))/(1+tp_r)^2+Val!D10*(1-MIN(tp_g/tp_roe,0.8))/(1+tp_r)^3+Val!D11*(1-MIN(tp_g/tp_roe,0.8))/(1+tp_r)^4+Val!D12*(1-MIN(tp_g/tp_roe,0.8))/(1+tp_r)^5+Val!D13*(1-MIN(tp_g/tp_roe,0.8))/(1+tp_r)^6+Val!D13*(1-MIN(tp_g/tp_roe,0.8))*(1+tp_g)/(tp_r-tp_g)/(1+tp_r)^6))*(1+tp_r) -> 202.71018 | D31: =tp_comp_adj -> 403.76521 | E31: =tp_w_dcf*C31+(1-tp_w_dcf)*D31 -> 303.2377 | F31: =E31/E$31-1 -> 0
A32: 折現率 +1pt | B32: r 11% | C32: =(tp_wA*(Val!B8*(1-MIN(tp_g/tp_roe,0.8))/(1+(tp_r+0.01))^1+Val!B9*(1-MIN(tp_g/tp_roe,0.8))/(1+(tp_r+0.01))^2+Val!B10*(1-MIN(tp_g/tp_roe,0.8))/(1+(tp_r+0.01))^3+Val!B11*(1-MIN(tp_g/tp_roe,0.8))/(1+(tp_r+0.01))^4+Val!B12*(1-MIN(tp_g/tp_roe,0.8))/(1+(tp_r+0.01))^5+Val!B13*(1-MIN(tp_g/tp_roe,0.8))/(1+(tp_r+0.01))^6+Val!B13*(1-MIN(tp_g/tp_roe,0.8))*(1+tp_g)/((tp_r+0.01)-tp_g)/(1+(tp_r+0.01))^6)+tp_wB*(Val!C8*(1-MIN(tp_g/tp_roe,0.8))/(1+(tp_r+0.01))^1+Val!C9*(1-MIN(tp_g/tp_roe,0.8))/(1+(tp_r+0.01))^2+Val!C10*(1-MIN(tp_g/tp_roe,0.8))/(1+(tp_r+0.01))^3+Val!C11*(1-MIN(tp_g/tp_roe,0.8))/(1+(tp_r+0.01))^4+Val!C12*(1-MIN(tp_g/tp_roe,0.8))/(1+(tp_r+0.01))^5+Val!C13*(1-MIN(tp_g/tp_roe,0.8))/(1+(tp_r+0.01))^6+Val!C13*(1-MIN(tp_g/tp_roe,0.8))*(1+tp_g)/((tp_r+0.01)-tp_g)/(1+(tp_r+0.01))^6)+tp_wC*(Val!D8*(1-MIN(tp_g/tp_roe,0.8))/(1+(tp_r+0.01))^1+Val!D9*(1-MIN(tp_g/tp_roe,0.8))/(1+(tp_r+0.01))^2+Val!D10*(1-MIN(tp_g/tp_roe,0.8))/(1+(tp_r+0.01))^3+Val!D11*(1-MIN(tp_g/tp_roe,0.8))/(1+(tp_r+0.01))^4+Val!D12*(1-MIN(tp_g/tp_roe,0.8))/(1+(tp_r+0.01))^5+Val!D13*(1-MIN(tp_g/tp_roe,0.8))/(1+(tp_r+0.01))^6+Val!D13*(1-MIN(tp_g/tp_roe,0.8))*(1+tp_g)/((tp_r+0.01)-tp_g)/(1+(tp_r+0.01))^6))*(1+(tp_r+0.01)) -> 175.62159 | D32: =tp_comp_adj -> 403.76521 | E32: =tp_w_dcf*C32+(1-tp_w_dcf)*D32 -> 289.6934 | F32: =E32/E$31-1 -> -0.0446656
A33: 折現率 −1pt | B33: r 9% | C33: =(tp_wA*(Val!B8*(1-MIN(tp_g/tp_roe,0.8))/(1+(tp_r-0.01))^1+Val!B9*(1-MIN(tp_g/tp_roe,0.8))/(1+(tp_r-0.01))^2+Val!B10*(1-MIN(tp_g/tp_roe,0.8))/(1+(tp_r-0.01))^3+Val!B11*(1-MIN(tp_g/tp_roe,0.8))/(1+(tp_r-0.01))^4+Val!B12*(1-MIN(tp_g/tp_roe,0.8))/(1+(tp_r-0.01))^5+Val!B13*(1-MIN(tp_g/tp_roe,0.8))/(1+(tp_r-0.01))^6+Val!B13*(1-MIN(tp_g/tp_roe,0.8))*(1+tp_g)/((tp_r-0.01)-tp_g)/(1+(tp_r-0.01))^6)+tp_wB*(Val!C8*(1-MIN(tp_g/tp_roe,0.8))/(1+(tp_r-0.01))^1+Val!C9*(1-MIN(tp_g/tp_roe,0.8))/(1+(tp_r-0.01))^2+Val!C10*(1-MIN(tp_g/tp_roe,0.8))/(1+(tp_r-0.01))^3+Val!C11*(1-MIN(tp_g/tp_roe,0.8))/(1+(tp_r-0.01))^4+Val!C12*(1-MIN(tp_g/tp_roe,0.8))/(1+(tp_r-0.01))^5+Val!C13*(1-MIN(tp_g/tp_roe,0.8))/(1+(tp_r-0.01))^6+Val!C13*(1-MIN(tp_g/tp_roe,0.8))*(1+tp_g)/((tp_r-0.01)-tp_g)/(1+(tp_r-0.01))^6)+tp_wC*(Val!D8*(1-MIN(tp_g/tp_roe,0.8))/(1+(tp_r-0.01))^1+Val!D9*(1-MIN(tp_g/tp_roe,0.8))/(1+(tp_r-0.01))^2+Val!D10*(1-MIN(tp_g/tp_roe,0.8))/(1+(tp_r-0.01))^3+Val!D11*(1-MIN(tp_g/tp_roe,0.8))/(1+(tp_r-0.01))^4+Val!D12*(1-MIN(tp_g/tp_roe,0.8))/(1+(tp_r-0.01))^5+Val!D13*(1-MIN(tp_g/tp_roe,0.8))/(1+(tp_r-0.01))^6+Val!D13*(1-MIN(tp_g/tp_roe,0.8))*(1+tp_g)/((tp_r-0.01)-tp_g)/(1+(tp_r-0.01))^6))*(1+(tp_r-0.01)) -> 240.60448 | D33: =tp_comp_adj -> 403.76521 | E33: =tp_w_dcf*C33+(1-tp_w_dcf)*D33 -> 322.18484 | F33: =E33/E$31-1 -> 0.062482828
A34: 長期成長 +1pt | B34: g 5% | C34: =(tp_wA*(Val!B8*(1-MIN((tp_g+0.01)/tp_roe,0.8))/(1+tp_r)^1+Val!B9*(1-MIN((tp_g+0.01)/tp_roe,0.8))/(1+tp_r)^2+Val!B10*(1-MIN((tp_g+0.01)/tp_roe,0.8))/(1+tp_r)^3+Val!B11*(1-MIN((tp_g+0.01)/tp_roe,0.8))/(1+tp_r)^4+Val!B12*(1-MIN((tp_g+0.01)/tp_roe,0.8))/(1+tp_r)^5+Val!B13*(1-MIN((tp_g+0.01)/tp_roe,0.8))/(1+tp_r)^6+Val!B13*(1-MIN((tp_g+0.01)/tp_roe,0.8))*(1+(tp_g+0.01))/(tp_r-(tp_g+0.01))/(1+tp_r)^6)+tp_wB*(Val!C8*(1-MIN((tp_g+0.01)/tp_roe,0.8))/(1+tp_r)^1+Val!C9*(1-MIN((tp_g+0.01)/tp_roe,0.8))/(1+tp_r)^2+Val!C10*(1-MIN((tp_g+0.01)/tp_roe,0.8))/(1+tp_r)^3+Val!C11*(1-MIN((tp_g+0.01)/tp_roe,0.8))/(1+tp_r)^4+Val!C12*(1-MIN((tp_g+0.01)/tp_roe,0.8))/(1+tp_r)^5+Val!C13*(1-MIN((tp_g+0.01)/tp_roe,0.8))/(1+tp_r)^6+Val!C13*(1-MIN((tp_g+0.01)/tp_roe,0.8))*(1+(tp_g+0.01))/(tp_r-(tp_g+0.01))/(1+tp_r)^6)+tp_wC*(Val!D8*(1-MIN((tp_g+0.01)/tp_roe,0.8))/(1+tp_r)^1+Val!D9*(1-MIN((tp_g+0.01)/tp_roe,0.8))/(1+tp_r)^2+Val!D10*(1-MIN((tp_g+0.01)/tp_roe,0.8))/(1+tp_r)^3+Val!D11*(1-MIN((tp_g+0.01)/tp_roe,0.8))/(1+tp_r)^4+Val!D12*(1-MIN((tp_g+0.01)/tp_roe,0.8))/(1+tp_r)^5+Val!D13*(1-MIN((tp_g+0.01)/tp_roe,0.8))/(1+tp_r)^6+Val!D13*(1-MIN((tp_g+0.01)/tp_roe,0.8))*(1+(tp_g+0.01))/(tp_r-(tp_g+0.01))/(1+tp_r)^6))*(1+tp_r) -> 218.00935 | D34: =tp_comp_adj -> 403.76521 | E34: =tp_w_dcf*C34+(1-tp_w_dcf)*D34 -> 310.88728 | F34: =E34/E$31-1 -> 0.025226374
A35: 長期成長 −1pt | B35: g 3% | C35: =(tp_wA*(Val!B8*(1-MIN((tp_g-0.01)/tp_roe,0.8))/(1+tp_r)^1+Val!B9*(1-MIN((tp_g-0.01)/tp_roe,0.8))/(1+tp_r)^2+Val!B10*(1-MIN((tp_g-0.01)/tp_roe,0.8))/(1+tp_r)^3+Val!B11*(1-MIN((tp_g-0.01)/tp_roe,0.8))/(1+tp_r)^4+Val!B12*(1-MIN((tp_g-0.01)/tp_roe,0.8))/(1+tp_r)^5+Val!B13*(1-MIN((tp_g-0.01)/tp_roe,0.8))/(1+tp_r)^6+Val!B13*(1-MIN((tp_g-0.01)/tp_roe,0.8))*(1+(tp_g-0.01))/(tp_r-(tp_g-0.01))/(1+tp_r)^6)+tp_wB*(Val!C8*(1-MIN((tp_g-0.01)/tp_roe,0.8))/(1+tp_r)^1+Val!C9*(1-MIN((tp_g-0.01)/tp_roe,0.8))/(1+tp_r)^2+Val!C10*(1-MIN((tp_g-0.01)/tp_roe,0.8))/(1+tp_r)^3+Val!C11*(1-MIN((tp_g-0.01)/tp_roe,0.8))/(1+tp_r)^4+Val!C12*(1-MIN((tp_g-0.01)/tp_roe,0.8))/(1+tp_r)^5+Val!C13*(1-MIN((tp_g-0.01)/tp_roe,0.8))/(1+tp_r)^6+Val!C13*(1-MIN((tp_g-0.01)/tp_roe,0.8))*(1+(tp_g-0.01))/(tp_r-(tp_g-0.01))/(1+tp_r)^6)+tp_wC*(Val!D8*(1-MIN((tp_g-0.01)/tp_roe,0.8))/(1+tp_r)^1+Val!D9*(1-MIN((tp_g-0.01)/tp_roe,0.8))/(1+tp_r)^2+Val!D10*(1-MIN((tp_g-0.01)/tp_roe,0.8))/(1+tp_r)^3+Val!D11*(1-MIN((tp_g-0.01)/tp_roe,0.8))/(1+tp_r)^4+Val!D12*(1-MIN((tp_g-0.01)/tp_roe,0.8))/(1+tp_r)^5+Val!D13*(1-MIN((tp_g-0.01)/tp_roe,0.8))/(1+tp_r)^6+Val!D13*(1-MIN((tp_g-0.01)/tp_roe,0.8))*(1+(tp_g-0.01))/(tp_r-(tp_g-0.01))/(1+tp_r)^6))*(1+tp_r) -> 192.72706 | D35: =tp_comp_adj -> 403.76521 | E35: =tp_w_dcf*C35+(1-tp_w_dcf)*D35 -> 298.24614 | F35: =E35/E$31-1 -> -0.016460879
A36: DCF 權重 0.4 | C36: =(tp_wA*(Val!B8*(1-MIN(tp_g/tp_roe,0.8))/(1+tp_r)^1+Val!B9*(1-MIN(tp_g/tp_roe,0.8))/(1+tp_r)^2+Val!B10*(1-MIN(tp_g/tp_roe,0.8))/(1+tp_r)^3+Val!B11*(1-MIN(tp_g/tp_roe,0.8))/(1+tp_r)^4+Val!B12*(1-MIN(tp_g/tp_roe,0.8))/(1+tp_r)^5+Val!B13*(1-MIN(tp_g/tp_roe,0.8))/(1+tp_r)^6+Val!B13*(1-MIN(tp_g/tp_roe,0.8))*(1+tp_g)/(tp_r-tp_g)/(1+tp_r)^6)+tp_wB*(Val!C8*(1-MIN(tp_g/tp_roe,0.8))/(1+tp_r)^1+Val!C9*(1-MIN(tp_g/tp_roe,0.8))/(1+tp_r)^2+Val!C10*(1-MIN(tp_g/tp_roe,0.8))/(1+tp_r)^3+Val!C11*(1-MIN(tp_g/tp_roe,0.8))/(1+tp_r)^4+Val!C12*(1-MIN(tp_g/tp_roe,0.8))/(1+tp_r)^5+Val!C13*(1-MIN(tp_g/tp_roe,0.8))/(1+tp_r)^6+Val!C13*(1-MIN(tp_g/tp_roe,0.8))*(1+tp_g)/(tp_r-tp_g)/(1+tp_r)^6)+tp_wC*(Val!D8*(1-MIN(tp_g/tp_roe,0.8))/(1+tp_r)^1+Val!D9*(1-MIN(tp_g/tp_roe,0.8))/(1+tp_r)^2+Val!D10*(1-MIN(tp_g/tp_roe,0.8))/(1+tp_r)^3+Val!D11*(1-MIN(tp_g/tp_roe,0.8))/(1+tp_r)^4+Val!D12*(1-MIN(tp_g/tp_roe,0.8))/(1+tp_r)^5+Val!D13*(1-MIN(tp_g/tp_roe,0.8))/(1+tp_r)^6+Val!D13*(1-MIN(tp_g/tp_roe,0.8))*(1+tp_g)/(tp_r-tp_g)/(1+tp_r)^6))*(1+tp_r) -> 202.71018 | D36: =tp_comp_adj -> 403.76521 | E36: =0.4*C36+(1-0.4)*D36 -> 323.3432 | F36: =E36/E$31-1 -> 0.066302783
A37: DCF 權重 0.8 | C37: =(tp_wA*(Val!B8*(1-MIN(tp_g/tp_roe,0.8))/(1+tp_r)^1+Val!B9*(1-MIN(tp_g/tp_roe,0.8))/(1+tp_r)^2+Val!B10*(1-MIN(tp_g/tp_roe,0.8))/(1+tp_r)^3+Val!B11*(1-MIN(tp_g/tp_roe,0.8))/(1+tp_r)^4+Val!B12*(1-MIN(tp_g/tp_roe,0.8))/(1+tp_r)^5+Val!B13*(1-MIN(tp_g/tp_roe,0.8))/(1+tp_r)^6+Val!B13*(1-MIN(tp_g/tp_roe,0.8))*(1+tp_g)/(tp_r-tp_g)/(1+tp_r)^6)+tp_wB*(Val!C8*(1-MIN(tp_g/tp_roe,0.8))/(1+tp_r)^1+Val!C9*(1-MIN(tp_g/tp_roe,0.8))/(1+tp_r)^2+Val!C10*(1-MIN(tp_g/tp_roe,0.8))/(1+tp_r)^3+Val!C11*(1-MIN(tp_g/tp_roe,0.8))/(1+tp_r)^4+Val!C12*(1-MIN(tp_g/tp_roe,0.8))/(1+tp_r)^5+Val!C13*(1-MIN(tp_g/tp_roe,0.8))/(1+tp_r)^6+Val!C13*(1-MIN(tp_g/tp_roe,0.8))*(1+tp_g)/(tp_r-tp_g)/(1+tp_r)^6)+tp_wC*(Val!D8*(1-MIN(tp_g/tp_roe,0.8))/(1+tp_r)^1+Val!D9*(1-MIN(tp_g/tp_roe,0.8))/(1+tp_r)^2+Val!D10*(1-MIN(tp_g/tp_roe,0.8))/(1+tp_r)^3+Val!D11*(1-MIN(tp_g/tp_roe,0.8))/(1+tp_r)^4+Val!D12*(1-MIN(tp_g/tp_roe,0.8))/(1+tp_r)^5+Val!D13*(1-MIN(tp_g/tp_roe,0.8))/(1+tp_r)^6+Val!D13*(1-MIN(tp_g/tp_roe,0.8))*(1+tp_g)/(tp_r-tp_g)/(1+tp_r)^6))*(1+tp_r) -> 202.71018 | D37: =tp_comp_adj -> 403.76521 | E37: =0.8*C37+(1-0.8)*D37 -> 242.92119 | F37: =E37/E$31-1 -> -0.19890835
A45: 案例區塊：每 GW 金額成長 低（情境 A）
A46: 項目 | B46: 單位 | C46: FY2025A | D46: FY2026（錨點） | E46: FY2027 | F46: FY2028 | G46: FY2029 | H46: FY2030（收斂） | I46: FY2031（收斂） | J46: FY2032（收斂） | K46: 說明
A47: A. AI 部署與每 GW AI 高速 PCB 金額（需求面；D 欄＝FY2026 校準年）
A48: AI IT 資本支出 × 情境顆數係數 | B48: US$B | D48: =itc_26*1 -> 781.87292 | E48: =itc_27*1*1 -> 1565.35 | F48: =itc_28*um28_A*1 -> 1984.2639 | G48: =itc_29*um29_A*1 -> 2260.3903
A49: 每 GW IT 資本支出 | B49: US$B | D49: =itpg_gb*(1-vr26)+itpg_vr*vr26 -> 33.414032 | E49: =itpg_vr -> 37.586352 | F49: =itpg_vr -> 37.586352 | G49: =itpg_vr -> 37.586352
A50: 部署 GW（IT 電力） | B50: GW | D50: =D48/D49 -> 23.399538 | E50: =E48/E49 -> 41.646766 | F50: =F48/F49 -> 52.792138 | G50: =G48/G49 -> 60.138592
...

Sheet Sources
A1: 來源（公司原文＝勝宏科技定期報告與業績交流會，經媒體轉述；券商與研調皆為 Interested-party）
A2: 公司：2026 年半年度報告（深交所 2026-08-28；營收、營業成本、費用、公允價值變動、所得稅、EPS、股數） | B2: https://disc.static.szse.cn/disc/disk03/finalpage/2026-08-28/296a3692-b153-48c1-9201-2bbb41886183.PDF
A3: 二手：華爾街見聞 2026-08-27（1H26 營收、歸母、扣非、EPS、ROE、H 股上市） | B3: https://wallstreetcn.com/articles/3780462
A4: 二手：鳳凰網（1H26 毛利率、公允價值變動、財務費用、交易性金融資產、借款） | B4: https://finance.ifeng.com/c/8wJ1y4oRRjn
A5: 二手：老虎 2026-04-28（1Q26 營收 55.19 億、歸母 12.88 億） | B5: https://www.itiger.com/news/1110866401
A6: 公司：2026 半年度業績交流會（同花順 2026-08-28；固投、排單到 2027、非 AI 持平、毛利率承壓原因） | B6: https://news.10jqka.com.cn/20260828/c679385007.shtml
A7: 二手：證券之星 2026-03-14 FY2025 年報簡析（營收、歸母、毛利率、EPS、4Q25） | B7: https://stock.stockstar.com/RB2026031400003895.shtml
A8: 二手：華爾街見聞 FY2025 年報（加權 ROE 35.56%／13.95%、扣非） | B8: https://wallstreetcn.com/articles/3767370
A9: 二手：界面新聞 2026-03（4Q25 低於預期、2026 投資 200 億、2030 千億產值、季毛利率、AI 占比、產銷量） | B9: https://m.jiemian.com/article/14114673.html
A10: 公司：2024 年度業績快報（巨潮 2025-03-10；FY2023 加權 ROE 9.35%） | B10: https://static.cninfo.com.cn/finalpage/2025-03-10/1222758016.PDF
A11: 券商：摩根大通首次覆蓋（新浪 2026-06-11；2026–28 預估、份額、毛利率、A 股同業倍數） | B11: https://finance.sina.com.cn/stock/hkstock/marketalerts/2026-06-11/doc-iniazihq5543947.shtml
A12: 券商：高盛（騰訊新聞 2026-09-03；目標價 550、26.3 倍 2027 P/E） | B12: https://news.qq.com/rain/a/20260903A09PBG00
A13: 研調：國金證券 2026-05（Morgan Stanley 每架 PCB 金額 GB300 3.51 萬、VR200 11.67 萬美元；層數） | B13: https://pdf.dfcfw.com/pdf/H3_AP202605241822839616_1.pdf
... A21: 匯率：中國經濟網 2026-10-16（人民幣中間價 6.7220） | B21: https://cj.sina.com.cn/articles/view/1663612603/6328b6bb0200248kg
A22: 市場層：markets/network、markets/chip_bridge、tsmc 成品；emc 成品（台光電每 GW CCL，Recon 用）（本 repo，唯讀）
A23: 無法取得：eniu.com 歷史 P/E（權限請求逾時）；pdf.dfcfw.com 2021-04 報告（權限請求逾時） | B23: 未找到
A24: 待補（人工）：3Q26 季報（2026-10-29）；分產品（高多層、HDI）營收與毛利率；2020 年營收與淨利；產能（萬㎡）與產值的公司原文；資本支出與折舊；前瞻 P/E 十年歷史（Bloomberg）；景旺电子前瞻 P/E | B24: 未找到
A25: SemiAnalysis | B25: 未使用
