Workbook

Sheet 導覽
A1: WhiteFiber 收支與評價模型 — Excel 版 v0.1（更新 2026-10-08；與 HTML v0.1 同步；市價截至 2026-10-07 收盤）
A3: 這個活頁簿在回答什麼
A4: 一句話：長約託管能否成為可融資的現金流底座，撐住雲端 GPU 擴張而不反覆稀釋——WhiteFiber 用客戶預付款支應多少擴張資本支出，剩下的缺口要靠多少債務與新股。
A5: 所有分頁用同一組數字，改任何一個輸入，後面全部會跟著動。
A7: 分頁結構（依模組分組，分頁標籤顏色相同者為同一模組）
A8: 摘要 一頁摘要：結論、與市場共識的差異、現價隱含什麼、驗證點（全部活公式）。
A9: 輸入與假設 所有可調參數（A 情境 → B 產能與收入 → C 利潤率 → D 支出 → E 融資 → F 評價 → G 1H 實際 → H 情境區間運算表 → I 市場共識 → J 季度追蹤輸入）。
A10: 各期收支 類現金流量：來源（含客戶預付）、用途、融資前缺口、期前融資瀑布。
A11: 季度追蹤 焦點季的模型／共識／指引／實際與差距（由年度模型拆分，只用於追蹤；實際數填在輸入與假設 J 區）。
A12: 運營_產能與收入 已連網 MW → 在役 MW → 營收（MW × 每 MW 年收入 × 利用率）；RPO 排程只作對照與產能瓶頸旗標。
A13: 資產負債_既有債務／新債與新股／租賃承諾 類資產負債表：季報債務明細、每期現金與總債務與股數、租賃承諾。
A14: 損益 類損益表（FY26＝1H 實際＋下半年模型）。
... A42: DCF 以融資後股數計每股，並加回新股募得現金的現值；EV/EBITDA 用錨定年末淨負債與錨定年末股數。

Sheet 摘要
A1: 一頁摘要 — 結論、與市場的差異、現價隱含什麼、驗證點（全部依輸入連動）
A2: ="模型端＝目前情境：" & CHOOSE(輸入與假設!$C$5,"保守 只有已簽約","基準 加 NC-1 下一批","積極 NC-2／3 與 Krambu") & "（預設＝基準）；共識＝data/consensus_wyfi_20261008.json（2026-10-08）" -> 模型端＝目前情境：基準 加 NC-1 下一批（預設＝基準）；共識＝data/consensus_wyfi_20261008.json（2026-10-08）
A4: 1｜結論
A5: 結論｜評等代碼（1＝買進、0＝中立、−1＝賣出） | C5: =評價_DCF與目標價!C78 -> 0
A6: 結論｜評等 | C6: =CHOOSE(C5+2,"賣出","中立","買進") -> 中立
A7: 結論｜點位（加權目標價） | B7: US$ | C7: =評價_DCF與目標價!C51 -> 16.838649
A8: 結論｜現價 | B8: US$ | C8: =輸入與假設!$C$228 -> 16.83
A9: 結論｜空間 | B9: % | C9: =C7/C8-1 -> 0.00051390791
A10: 結論｜情境區間（下緣／上緣） | B10: US$ | C10: =評價_DCF與目標價!C83 -> 10.044175 | D10: =評價_DCF與目標價!D83 -> 34.655938
A11: 結論｜方法區間（下緣／上緣） | B11: US$ | C11: =評價_DCF與目標價!C85 -> 16.428437 | D11: =評價_DCF與目標價!D85 -> 16.838649
A12: 結論｜賣出門檻價 | B12: US$ | C12: =評價_DCF與目標價!$C$79 -> 14.3055
A13: 結論｜點位 − 賣出門檻 | B13: US$ | C13: =C7-C12 -> 2.5331491
A14: 結論｜結論句 | C14: =C6&"：點位 $"&TEXT(C7,"0.0")&"，較現價 $"&TEXT(C8,"0.00")&" "&IF(C9>=0,"高","低")&" "&TEXT(ABS(C9)*100,"0")&"%；情境區間 $"&TEXT(C10,"0.0")&"–$"&TEXT(D10,"0.0")&"，方法區間 $"&TEXT(C11,"0.0")&"–$"&TEXT(D11,"0.0")&"；點位"&IF(C13<0,"低於","高於")&"賣出門檻 $"&TEXT(C12,"0.0")&" 達 $"&TEXT(ABS(C13),"0.0")&"。" -> 中立：點位 $16.8，較現價 $16.83 高 0%；情境區間 $10.0–$34.7，方法區間 $16.4–$16.8；點位高於賣出門檻 $14.3 達 $2.5。
A15: 結論｜情境判斷句 | C15: =評價_DCF與目標價!C91 -> 情境區間上緣 $34.7 不低於現價 $16.83：賣出並非在三個擴張情境下都成立。
A16: 結論｜融資上限句 | C16: =IF(OR(輸入與假設!$C$199="ebitda",輸入與假設!$C$199="leaseAdj"),"超出可融資上限、需高息債的金額："&IF(SUM(各期收支!C87:G87)>50,"$"&TEXT(SUM(各期收支!C87:G87),"#,##0.0")&"m（五期高息債溢出）","$0")&"；債務上限＝"&IF(輸入與假設!$C$199="leaseAdj","(總債務＋租賃負債) ≤ "&IF(輸入與假設!$C$200=INT(輸入與假設!$C$200),TEXT(輸入與假設!$C$200,"0"),TEXT(輸入與假設!$C$200,"0.0"))&"×(EBITDA＋租金)","總債務 ≤ "&IF(輸入與假設!$C$200=INT(輸入與假設!$C$200),TEXT(輸入與假設!$C$200,"0"),TEXT(輸入與假設!$C$200,"0.0"))&"× 當期 EBITDA")&"，股權每年 ≤ 現市值 "&IF(ROUND(ABS(輸入與假設!$C$207)*100,4)=INT(ROUND(ABS(輸入與假設!$C$207)*100,4)),TEXT(ROUND(ABS(輸入與假設!$C$207)*100,4),"0"),TEXT(ROUND(ABS(輸入與假設!$C$207)*100,4),"0.0"))&"%"&"。","") -> 超出可融資上限、需高息債的金額：$0；債務上限＝總債務 ≤ 5× 當期 EBITDA，股權每年 ≤ 現市值 10%。
A17: 結論｜調整後槓桿句 | C17: =IF(輸入與假設!$C$199="leaseAdj","調整後槓桿（(債務＋租賃負債) ÷ (EBITDA＋租金)）路徑 "&TEXT(資產負債_新債與新股!C38,"0.0")&"／"&TEXT(資產負債_新債與新股!D38,"0.0")&"／"&TEXT(資產負債_新債與新股!E38,"0.0")&"／"&TEXT(資產負債_新債與新股!F38,"0.0")&"／"&TEXT(資產負債_新債與新股!G38,"0.0")&"×；上限 "&IF(輸入與假設!$C$200=INT(輸入與假設!$C$200),TEXT(輸入與假設!$C$200,"0"),TEXT(輸入與假設!$C$200,"0.0"))&"×，"&IF(MAX(資產負債_新債與新股!$C$38:$G$38)>輸入與假設!$C$200+0.000000001,CHOOSE(MATCH(MAX(資產負債_新債與新股!$C$38:$G$38),資產負債_新債與新股!$C$38:$G$38,0),"FY26","FY27","FY28","FY29","FY30")&" 超過 "&TEXT(MAX(資產負債_新債與新股!$C$38:$G$38)-輸入與假設!$C$200,"0.0")&"×：需股權或高息債。","最小空間 "&TEXT(輸入與假設!$C$200-MAX(資產負債_新債與新股!$C$38:$G$38),"0.0")&"×（"&CHOOSE(MATCH(MAX(資產負債_新債與新股!$C$38:$G$38),資產負債_新債與新股!$C$38:$G$38,0),"FY26","FY27","FY28","FY29","FY30")&"）。"),"總債務 ÷ EBITDA（年化）路徑 "&TEXT(資產負債_新債與新股!C40,"0.0")&"／"&TEXT(資產負債_新債與新股!D40,"0.0")&"／"&TEXT(資產負債_新債與新股!E40,"0.0")&"／"&TEXT(資產負債_新債與新股!F40,"0.0")&"／"&TEXT(資產負債_新債與新股!G40,"0.0")&"×；上限 "&IF(輸入與假設!$C$200=INT(輸入與假設!$C$200),TEXT(輸入與假設!$C$200,"0"),TEXT(輸入與假設!$C$200,"0.0"))&"×，"&IF(MAX(資產負債_新債與新股!$C$40:$G$40)>輸入與假設!$C$200+0.000000001,CHOOSE(MATCH(MAX(資產負債_新債與新股!$C$40:$G$40),資產負債_新債與新股!$C$40:$G$40,0),"FY26","FY27","FY28","FY29","FY30")&" 最高超過 "&TEXT(MAX(資產負債_新債與新股!$C$40:$G$40)-輸入與假設!$C$200,"0.0")&"×：超過期間新債只能動用已承諾額度，其餘靠可轉債、股權或高息債。","最小空間 "&TEXT(輸入與假設!$C$200-MAX(資產負債_新債與新股!$C$40:$G$40),"0.0")&"×（"&CHOOSE(MATCH(MAX(資產負債_新債與新股!$C$40:$G$40),資產負債_新債與新股!$C$40:$G$40,0),"FY26","FY27","FY28","FY29","FY30")&"）。")) -> 總債務 ÷ EBITDA（年化）路徑 37.1／29.2／8.6／5.1／3.6×；上限 5×，FY26 最高超過 32.1×：超過期間新債只能動用已承諾額度，其餘靠可轉債、股權或高息債。
A18: 結論｜延誤句 | C18: =IF(運營_產能與收入!$C$62>0,"建設延誤 "&IF(運營_產能與收入!$C$62=INT(運營_產能與收入!$C$62),TEXT(運營_產能與收入!$C$62,"0"),TEXT(運營_產能與收入!$C$62,"0.0"))&" 個月（GPU 資本支出照原時程）：閒置資本（已支出、尚未產生收入）峰值 $"&TEXT(MAX(運營_產能與收入!$C$67:$G$67),"#,##0.0")&"m（"&CHOOSE(MATCH(MAX(運營_產能與收入!$C$67:$G$67),運營_產能與收入!$C$67:$G$67,0),"FY26","FY27","FY28","FY29","FY30")&" 末）。","建設延誤：本情境 0 個月（無閒置資本）。") -> 建設延誤 3 個月（GPU 資本支出照原時程）：閒置資本（已支出、尚未產生收入）峰值 $61.7m（FY26 末）。
A20: 2｜與市場的差異（模型：目前情境 vs 共識；FY26–FY28）
A21: 項目 | B21: 單位 | C21: FY26 | D21: FY27 | E21: FY28
A22: 差異｜營收｜模型 | B22: US$m | C22: =損益!C29 -> 129.87243 | D22: =損益!D29 -> 278.16958 | E22: =損益!E29 -> 417.41242
A23: 差異｜營收｜共識 | B23: US$m | C23: =輸入與假設!$C$344 -> 137 | D23: =輸入與假設!$D$344 -> 296 | E23: =輸入與假設!$E$344 -> 530
A24: 差異｜營收｜差距 | B24: % | C24: =IFERROR(C22/C23-1,"—") -> -0.052026049 | D24: =IFERROR(D22/D23-1,"—") -> -0.060237895 | E24: =IFERROR(E22/E23-1,"—") -> -0.21242939
A25: 差異｜調整後 EBITDA｜模型 | B25: US$m | C25: =輸入與假設!$C$310+損益!C22 -> 14.748729 | D25: =損益!D34 -> 25.404783 | E25: =損益!E34 -> 90.266499
A26: 差異｜調整後 EBITDA｜共識 | B26: US$m | C26: ="—" -> — | D26: ="—" -> — | E26: ="—" -> —
A27: 差異｜調整後 EBITDA｜差距 | B27: % | C27: =IFERROR(C25/C26-1,"—") -> — | D27: =IFERROR(D25/D26-1,"—") -> — | E27: =IFERROR(E25/E26-1,"—") -> — | I27: FY26 模型＝1H 實際調整後 EBITDA（輸入與假設 G 區，報導轉述 [Verified]）＋2H 模型
A28: 差異｜調整後 EBITDA｜差距（金額） | B28: US$m | C28: =IFERROR(C25-C26,"—") -> — | D28: =IFERROR(D25-D26,"—") -> — | E28: =IFERROR(E25-E26,"—") -> — | I28: 與 HTML 一頁摘要、市場共識分頁同一呈現；判斷門檻仍用上一列比例
A29: 差異｜EBITDA 率｜模型 | B29: % | C29: =C25/C22 -> 0.1135632 | D29: =D25/D22 -> 0.091328401 | E29: =E25/E22 -> 0.21625254
A30: 差異｜EBITDA 率｜共識 | B30: % | C30: ="—" -> — | D30: ="—" -> — | E30: ="—" -> —
A31: 差異｜EBITDA 率｜差距（百分點） | B31: pt | C31: =IFERROR(C29-C30,"—") -> — | D31: =IFERROR(D29-D30,"—") -> — | E31: =IFERROR(E29-E30,"—") -> — | I31: EBITDA 率以百分點列差距，不納入判斷
A32: 差異｜CapEx（毛額）｜模型 | B32: US$m | C32: =輸入與假設!$C$293+輸入與假設!C$175 -> 491.69103 | D32: =輸入與假設!D$175 -> 427.14561 | E32: =輸入與假設!E$175 -> 56.385
A33: 差異｜CapEx（毛額）｜共識 | B33: US$m | C33: ="—" -> — | D33: ="—" -> — | E33: ="—" -> —
A34: 差異｜CapEx（毛額）｜差距 | B34: % | C34: =IFERROR(C32/C33-1,"—") -> — | D34: =IFERROR(D32/D33-1,"—") -> — | E34: =IFERROR(E32/E33-1,"—") -> — | I34: 共識 CapEx 口徑未揭露；FY26＝1H 實際毛額＋2H 模型毛額
A35: 差異｜淨負債｜模型 | B35: US$m | C35: =資產負債_新債與新股!C26 -> 324.46042 | D35: =資產負債_新債與新股!D26 -> 712.5112 | E35: =資產負債_新債與新股!E26 -> 749.1855
A36: 差異｜淨負債｜共識 | B36: US$m | C36: ="—" -> — | D36: ="—" -> — | E36: ="—" -> —
A37: 差異｜淨負債｜差距 | B37: % | C37: =IFERROR(C35/C36-1,"—") -> — | D37: =IFERROR(D35/D36-1,"—") -> — | E37: =IFERROR(E35/E36-1,"—") -> — | I37: 共識淨負債不含租賃、口徑未揭露：只列不判斷
A38: 差異｜淨負債｜差距（金額） | B38: US$m | C38: =IFERROR(C35-C36,"—") -> — | D38: =IFERROR(D35-D36,"—") -> — | E38: =IFERROR(E35-E36,"—") -> — | I38: 與 HTML 一頁摘要、市場共識分頁同一呈現；判斷門檻仍用上一列比例
A39: 差異｜分歧項目（超過門檻者） | C39: =MID(IF(ABS(C24)>輸入與假設!$C$367,"、營收 "&IF(C24<0,"−","+")&TEXT(ABS(C24)*100,"0.0")&"%",""),2,999) -> 營收 −5.2% | D39: =MID(IF(ABS(D24)>輸入與假設!$C$367,"、營收 "&IF(D24<0,"−","+")&TEXT(ABS(D24)*100,"0.0")&"%",""),2,999) -> 營收 −6.0% | E39: =MID(IF(ABS(E24)>輸入與假設!$C$367,"、營收 "&IF(E24<0,"−","+")&TEXT(ABS(E24)*100,"0.0")&"%",""),2,999) -> 營收 −21.2% | I39: 營收、EBITDA、CapEx 任一項差距絕對值超過門檻即列出（與 HTML 判斷句同一規則）
A40: 差異｜分歧起始年（1＝FY26…3＝FY28；0＝無） | C40: =IF(C39<>"",1,IF(D39<>"",2,IF(E39<>"",3,0))) -> 1
A41: 差異｜判斷句 | C41: =CHOOSE(C40+1,"FY26–FY28 營收 與共識差距皆在 "&IF(ROUND(ABS(輸入與假設!$C$367)*100,4)=INT(ROUND(ABS(輸入與假設!$C$367)*100,4)),TEXT(ROUND(ABS(輸入與假設!$C$367)*100,4),"0"),TEXT(ROUND(ABS(輸入與假設!$C$367)*100,4),"0.0"))&"%"&" 以內。","分歧始於 FY26（"&C39&"）"&"；FY27 "&IF(D39="","回到 "&IF(ROUND(ABS(輸入與假設!$C$367)*100,4)=INT(ROUND(ABS(輸入與假設!$C$367)*100,4)),TEXT(ROUND(ABS(輸入與假設!$C$367)*100,4),"0"),TEXT(ROUND(ABS(輸入與假設!$C$367)*100,4),"0.0"))&"%"&" 以內",D39)&"；FY28 "&IF(E39="","回到 "&IF(ROUND(ABS(輸入與假設!$C$367)*100,4)=INT(ROUND(ABS(輸入與假設!$C$367)*100,4)),TEXT(ROUND(ABS(輸入與假設!$C$367)*100,4),"0"),TEXT(ROUND(ABS(輸入與假設!$C$367)*100,4),"0.0"))&"%"&" 以內",E39)&"。","FY26 營收 與共識差距在 "&IF(ROUND(ABS(輸入與假設!$C$367)*100,4)=INT(ROUND(ABS(輸入與假設!$C$367)*100,4)),TEXT(ROUND(ABS(輸入與假設!$C$367)*100,4),"0"),TEXT(ROUND(ABS(輸入與假設!$C$367)*100,4),"0.0"))&"%"&" 以內；分歧始於 FY27（"&D39&"）"&"；FY28 "&IF(E39="","回到 "&IF(ROUND(ABS(輸入與假設!$C$367)*100,4)=INT(ROUND(ABS(輸入與假設!$C$367)*100,4)),TEXT(ROUND(ABS(輸入與假設!$C$367)*100,4),"0"),TEXT(ROUND(ABS(輸入與假設!$C$367)*100,4),"0.0"))&"%"&" 以內",E39)&"。","FY26–FY27 營收 與共識差距在 "&IF(ROUND(ABS(輸入與假設!$C$367)*100,4)=INT(ROUND(ABS(輸入與假設!$C$367)*100,4)),TEXT(ROUND(ABS(輸入與假設!$C$367)*100,4),"0"),TEXT(ROUND(ABS(輸入與假設!$C$367)*100,4),"0.0"))&"%"&" 以內；分歧始於 FY28（"&E39&"）。") -> 分歧始於 FY26（營收 −5.2%）；FY27 營收 −6.0%；FY28 營收 −21.2%。
A42: 差異原因｜FY26｜營收 | C42: =IF(ABS(C24)>輸入與假設!$C$367,"觀點","") -> 觀點 | D42: =IF(ABS(C24)>輸入與假設!$C$367,"營收＝雲端（在役 MW × 每 MW 年收入，Tokenomics 正向推導；年底已連網 "&IF((輸入與假設!C$43)<0,"−","")&TEXT(ABS((輸入與假設!C$43)),"#,##0.0")&" MW-IT）＋託管（已簽約合約排程與擴建）；共識未揭露 MW 與單價假設","") -> 營收＝雲端（在役 MW × 每 MW 年收入，Tokenomics 正向推導；年底已連網 14.6 MW-IT）＋託管（已簽約合約排程與擴建）；共識未揭露 MW 與單價假設 | I42: C＝類型、D＝原因（需附原因時顯示；EBITDA 以利潤率差、其餘以比例門檻判斷）
...

Sheet 輸入與假設
A1: 輸入（依類別排序；點左側 ＋／− 展開或收合。藍字可改；黃底為最關鍵假設）
A2: A 情境 → B 產能與收入 → C 利潤率 → D 支出（CapEx／折舊／租賃／JV）→ E 融資 → F 評價 → G 參考：1H26 實際 → H 情境區間運算表 → I 市場共識 → J 季度追蹤輸入。灰底『▸』為明細子區，預設收合
A4: A｜情境與規模（管理層擴張力道）
A5: 情境選擇（1＝保守 只有已簽約、2＝基準 加 NC-1 下一批、3＝積極 NC-2／3 與 Krambu） | C5: 2 | D5: =CHOOSE(C5,"保守 只有已簽約","基準 加 NC-1 下一批","積極 NC-2／3 與 Krambu") -> 基準 加 NC-1 下一批 | I5: 三情境改變擴張力道（已連網 MW 路徑）與每 MW 年收入（Tokenomics 正向推導三情境值）；其餘假設相同（對照表 r1 第 4 節第 1 條）
A6: ▸ 情境路徑明細（已連網 MW、在役比例、表外租金基準）
A7: 已連網 MW 路徑 | B7: 單位 | C7: FY26 | D7: FY27 | E7: FY28 | F7: FY29 | G7: FY30 | I7: FY31 新增 MW
A8: 首期期末已連網 MW（三情境共用） | B8: MW | C8: 14.574 | I8: 首期期末＝評價日已連網＋首期剩餘季度依最新季交付速度；推導與來源見 company.json → scenarios.mwPath.note [Derived]
A9: 保守 只有已簽約｜合約 MW 上限 | B9: MW | C9: 12.074 | D9: 14.048 | E9: 14.048 | F9: 14.048 | G9: 14.048 | I9: company.json → scenarios.mwPath.contracted
A10: 保守 只有已簽約｜併網速度 | B10: MW／年 | C10: 100 | I10: company.json → scenarios.mwPath.pace
A11: 保守 只有已簽約 | B11: MW | C11: =MIN(C9,輸入與假設!$C$8) -> 12.074 | D11: =MIN(D9,C11+輸入與假設!$C$10*D$41) -> 14.048 | E11: =MIN(E9,D11+輸入與假設!$C$10*E$41) -> 14.048 | F11: =MIN(F9,E11+輸入與假設!$C$10*F$41) -> 14.048 | G11: =MIN(G9,F11+輸入與假設!$C$10*G$41) -> 14.048 | I11: 0 | J11: 雲端只計已簽約 GPU 合約（不含尚無客戶的雪梨 2.5 MW）、合約到期以 Tokenomics 每 MW 續作；託管只有 NC-1 40 MW 與 MTL 現有站點；NC-1 專案融資未完成；延誤 6 個月；I 欄＝FY31 新增 MW
A12: 基準 加 NC-1 下一批｜合約 MW 上限 | B12: MW | C12: 14.574 | D12: 16.548 | E12: 19.548 | F12: 22.548 | G12: 25.548 | I12: company.json → scenarios.mwPath.contracted
A13: 基準 加 NC-1 下一批｜併網速度 | B13: MW／年 | C13: 100 | I13: company.json → scenarios.mwPath.pace
A14: 基準 加 NC-1 下一批 | B14: MW | C14: =MIN(C12,輸入與假設!$C$8) -> 14.574 | D14: =MIN(D12,C14+輸入與假設!$C$13*D$41) -> 16.548 | E14: =MIN(E12,D14+輸入與假設!$C$13*E$41) -> 19.548 | F14: =MIN(F12,E14+輸入與假設!$C$13*F$41) -> 22.548 | G14: =MIN(G12,F14+輸入與假設!$C$13*G$41) -> 25.548 | I14: 0 | J14: 雲端加雪梨 2.5 MW 與每年新增 3 MW-IT（2026 年新簽約約 8.6 MW-IT 的四分之一強）；託管加 NC-1 下一批 45 毛 MW（÷1.35 約 33 MW-IT）；NC-1 專案融資完成；延誤 3 個月；I 欄＝FY31 新增 MW
A15: 積極 NC-2／3 與 Krambu｜合約 MW 上限 | B15: MW | C15: 14.574 | D15: 16.548 | E15: 22.548 | F15: 28.548 | G15: 34.548 | I15: company.json → scenarios.mwPath.contracted
A16: 積極 NC-2／3 與 Krambu｜併網速度 | B16: MW／年 | C16: 100 | I16: company.json → scenarios.mwPath.pace
A17: 積極 NC-2／3 與 Krambu | B17: MW | C17: =MIN(C15,輸入與假設!$C$8) -> 14.574 | D17: =MIN(D15,C17+輸入與假設!$C$16*D$41) -> 16.548 | E17: =MIN(E15,D17+輸入與假設!$C$16*E$41) -> 22.548 | F17: =MIN(F15,E17+輸入與假設!$C$16*F$41) -> 28.548 | G17: =MIN(G15,F17+輸入與假設!$C$16*G$41) -> 34.548 | I17: 0 | J17: 雲端每年新增 6 MW-IT；託管再加 NC-2／3（60 毛 MW 起，2027 Q3）、NC-1 擴至長期毛容量、Krambu 100 MW（二手、口徑不明）；NC-1 專案融資完成；延誤 0；I 欄＝FY31 新增 MW
A18: 每 MW 年收入｜保守 只有已簽約 | B18: US$m/MW | C18: 11.62 | D18: 11.62 | E18: 11.62 | F18: 11.62 | G18: 11.62 | I18: Tokenomics 正向推導三情境（data/permw_tokenomics_20261008.json）；不用公司 ACV [Derived]
A19: 每 MW 年收入｜基準 加 NC-1 下一批 | B19: US$m/MW | C19: 17.4 | D19: 17.4 | E19: 17.4 | F19: 17.4 | G19: 17.4 | I19: Tokenomics 正向推導三情境（data/permw_tokenomics_20261008.json）；不用公司 ACV [Derived]
A20: 每 MW 年收入｜積極 NC-2／3 與 Krambu | B20: US$m/MW | C20: 24.2 | D20: 24.2 | E20: 24.2 | F20: 24.2 | G20: 24.2 | I20: Tokenomics 正向推導三情境（data/permw_tokenomics_20261008.json）；不用公司 ACV [Derived]
A21: 在役 MW 收斂比例（期初校準值 → 已連網） | B21: % | C21: 0.7 | D21: 0.85 | E21: 0.9 | F21: 0.9 | G21: 0.9 | I21: 期初可計費 MW＝2026 Q2 經常性雲端營收 11.506（23.806 扣終止費 12.3）× 4＝46.02 ÷ 各情境每 MW 年收入（保守 3.96／基準 2.65／積極 1.9 MW-IT），是對齊已實現實際數的校準，不是以公司目標反推（評價日已連網 5.5 MW 中實際計費當量較低：舊世代 H100 機隊單價低於 Tokenomics）。各期末可計費 MW＝期初校準值＋(已連網 − 期初校準值)× 收斂比例 70%／85%／90%／90%／90%（新合約 2026-07 至 2027 Q2 陸續起算，首期 70% [Assumed]）；小數 2 位（roundDp）。
A22: 期初可計費 MW 校準：Q2 2026 實際營收年化 | B22: US$m | C22: 46.024 | I22: 最新季實際營收 × 4（company.json → scenarios.billableRatio.openAnnualRevenue）[Derived]
A23: 期初可計費 MW｜保守 只有已簽約 | B23: MW | C23: =ROUND(輸入與假設!$C$22/C18,2) -> 3.96 | I23: ＝實際營收年化 ÷ 該情境每 MW 年收入（對齊已實現實際數的校準）
A24: 期初可計費 MW｜基準 加 NC-1 下一批 | B24: MW | C24: =ROUND(輸入與假設!$C$22/C19,2) -> 2.65 | I24: ＝實際營收年化 ÷ 該情境每 MW 年收入（對齊已實現實際數的校準）
A25: 期初可計費 MW｜積極 NC-2／3 與 Krambu | B25: MW | C25: =ROUND(輸入與假設!$C$22/C20,2) -> 1.9 | I25: ＝實際營收年化 ÷ 該情境每 MW 年收入（對齊已實現實際數的校準）
A26: 未起租租賃總額（未折現） | B26: US$m | C26: 20.296 | I26: 季報附註已簽約未起租租賃（company.json → leases.facts.notCommenced）[Interested-party]
A27: 未起租：評價日後第幾季開始起租（0＝首期第一季） | B27: 季 | C27: 1 | I27: company.json → leases.uncommenced.startQ
A28: 未起租：平均分攤起租的季數 | B28: 季 | C28: 1 | I28: 季報：FY27Q2 至 FY2029 起租 → 11 季 [Assumed]
A29: 未起租：每筆租期 | B29: 年 | C29: 4.916667 | I29: 季報 15–19 年取中點；敏感度 15／19 年見報告 [Assumed]
A30: B｜產能與收入（MW、每 MW 年收入、利用率、信用；RPO 只作對照）
A31: 6/30 RPO | B31: US$m | C31: 75.146 | I31: 季報 RPO 75.146（只作對照與債務上限的 backlog）[Interested-party]
A32: 評價日後新增承諾 | B32: US$m | C32: 0 | I32: 評價日後新簽、尚未進 RPO 的承諾；未揭露，取 0 [Assumed]
A33: 五期認列比例（至 2030 末） | B33: % | C33: 1 | I33: 季報 RPO 桶線性分攤後五期合計 100% [Derived]
A34: RPO 桶權重合計 | B34: % | C34: 1 | I34: 下方權重列的合計，用於歸一化
A35: 2025-12-31 主動電力 | B35: MW | C35: 5.5 | I35: 2025 年底雲端已連網 MW-IT：冰島第三方機房 5.5（10-Q；亞特蘭大 2026-02 起承租、加拿大 MW 未揭露）[Interested-party]
A36: 6/30 Billable MW | B36: MW | C36: =CHOOSE(輸入與假設!$C$5,輸入與假設!$C$23,輸入與假設!$C$24,輸入與假設!$C$25) -> 2.65 | I36: ＝依 A 區情境選擇器（以實際營收校準）
A37: 收入用平均在役 MW（1=是） | C37: 1 | I37: 0＝用期末存量全期化；建議 1
A38: 營收驅動（mw＝MW × 每 MW 年收入；rpo＝RPO 排程） | C38: mw | I38: mw：新產能簽約率固定 100%，營收＝容量上限；RPO 只作對照與產能瓶頸旗標（company.json → defaults.revenueDriver）
A39: 每 MW 年收入倍數（整體） | B39: % | C39: 1 | I39: 反向 DCF 與壓力測試用；預設 100%。以『目標搜尋』調整此格即可反解市價隱含單價
A40: 項目 | B40: 單位 | C40: FY26 | D40: FY27 | E40: FY28 | F40: FY29 | G40: FY30 | I40: 來源／標籤
A41: 模型期長度（年） | C41: 0.5 | D41: 1 | E41: 1 | F41: 1 | G41: 1 | I41: 勿改。由 calendar_q.py 推算；只用於容量上限、電力、維護等年率換算 [Derived]
...

Sheet 各期收支
A1: 支出與資金 — 五層支出、四層來源、現金橋
A2: FY26 欄＝1H 實際（季報現金流量表口徑）＋下半年模型；FY27 以後為純模型。瀑布以「融資前現金」決定需求並直接由各支出列加總，因此沒有循環參照
A4: 項目 | B4: 單位 | C4: FY26 | D4: FY27 | E4: FY28 | F4: FY29 | G4: FY30 | I4: 公式／來源說明
A5: 支出（五層）
A6: ① 毛 CapEx（認列，備忘） | B6: US$m | C6: =輸入與假設!$C$293+輸入與假設!C$175 -> 491.69103 | D6: =輸入與假設!D$175 -> 427.14561 | E6: =輸入與假設!E$175 -> 56.385 | F6: =輸入與假設!F$175 -> 56.385 | G6: =輸入與假設!G$175 -> 127.04668 | I6: FY26＝1H 實際認列 344.712＋2H 模型；對照公司全年指引 不適用（公司未給指引）。備忘列：用途合計採現金口徑，不用這一列
A7: 客戶預付率 | B7: % | C7: =輸入與假設!C$152 -> 0.21 | D7: =輸入與假設!D$152 -> 0.21 | E7: =輸入與假設!E$152 -> 0.21 | F7: =輸入與假設!F$152 -> 0.21 | G7: =輸入與假設!G$152 -> 0.21
A8: 客戶預付金額（抵減，2H 起） | B8: US$m | C8: =(輸入與假設!C$165+輸入與假設!C$107)*C7 -> 30.865595 | D8: =(輸入與假設!D$165+輸入與假設!D$107)*D7 -> 89.700579 | E8: =(輸入與假設!E$165+輸入與假設!E$107)*E7 -> 11.84085 | F8: =(輸入與假設!F$165+輸入與假設!F$107)*F7 -> 11.84085 | G8: =(輸入與假設!G$165+輸入與假設!G$107)*G7 -> 7.6965525 | I8: ＝成長型 CapEx × 預付比率（汰換 CapEx 不計）；含託管建置（WhiteFiber v0.1b：defaults.colo.coverPrepay）；1H 的預付已含在實際 CFO 內，不重複計入
A9: 合約負債期初（客戶預付餘額） | B9: US$m | C9: =輸入與假設!$C$149 -> 143.11 | D9: =C12 -> 165.03122 | E9: =D12 -> 234.1029 | F9: =E12 -> 216.68088 | G9: =F12 -> 201.43662 | I9: FY26 期初＝6/30 季報遞延營收
A10: 合約負債利息累積（重大財務組成，非現金） | B10: US$m | C10: =輸入與假設!$C$150*(C9+0.5*C8)*運營_產能與收入!C7 -> 0 | D10: =輸入與假設!$C$150*(D9+0.5*D8)*運營_產能與收入!D7 -> 0 | E10: =輸入與假設!$C$150*(E9+0.5*E8)*運營_產能與收入!E7 -> 0 | F10: =輸入與假設!$C$150*(F9+0.5*F8)*運營_產能與收入!F7 -> 0 | G10: =輸入與假設!$C$150*(G9+0.5*G8)*運營_產能與收入!G7 -> 0 | I10: ＝隱含利率 ×(期初合約負債＋本期預付流入 × ½)× 期間長度；進損益利息、不進現金（v0.1b）
A11: 預付認列（非現金營收） | B11: US$m | C11: =MIN(C9+C10,(C9+C10)/輸入與假設!$C$148*運營_產能與收入!C7) -> 8.944375 | D11: =MIN(D9+D10,(D9+D10)/輸入與假設!$C$148*運營_產能與收入!D7) -> 20.628903 | E11: =MIN(E9+E10,(E9+E10)/輸入與假設!$C$148*運營_產能與收入!E7) -> 29.262862 | F11: =MIN(F9+F10,(F9+F10)/輸入與假設!$C$148*運營_產能與收入!F7) -> 27.085111 | G11: =MIN(G9+G10,(G9+G10)/輸入與假設!$C$148*運營_產能與收入!G7) -> 25.179578 | I11: ＝(期初合約負債＋累積利息) ÷ 認列年數 × 期間長度；這部分營收已在預付時收現，自營運來源扣除
A12: 合約負債期末 | B12: US$m | C12: =C9+C8+C10-C11 -> 165.03122 | D12: =D9+D8+D10-D11 -> 234.1029 | E12: =E9+E8+E10-E11 -> 216.68088 | F12: =F9+F8+F10-F11 -> 201.43662 | G12: =G9+G8+G10-G11 -> 183.9536 | I12: ＝期初＋預付流入＋累積利息−認列
A13: ① CapEx（用途用：1H 現金／2H 毛額） | B13: US$m | C13: =輸入與假設!$C$292+輸入與假設!C$175 -> 491.69103 | D13: =輸入與假設!D$175 -> 427.14561 | E13: =輸入與假設!E$175 -> 56.385 | F13: =輸入與假設!F$175 -> 56.385 | G13: =輸入與假設!G$175 -> 127.04668 | I13: 1H 採現金流量表的現金購置 344.712；2H 起採毛額，客戶預付在來源端抵回（避免重複計入）
A14: ② 在帳現金租金（備忘，1H 已含在 CFO） | B14: US$m | C14: =輸入與假設!C$153 -> 3.268 | D14: =輸入與假設!D$153 -> 4.28 | E14: =輸入與假設!E$153 -> 2.465 | F14: =輸入與假設!F$153 -> 2.304 | G14: =輸入與假設!G$153 -> 2.358 | I14: 見『租賃與承諾』頁；2030 後尚有 5.76。FY26 欄僅 2H：1H 租金 13.044 已含在實際 CFO 內
A15: ② 表外現金租金（未起租） | B15: US$m | C15: =運營_產能與收入!C71 -> 0.51599997 | D15: =運營_產能與收入!D71 -> 4.1279997 | E15: =運營_產能與收入!E71 -> 4.1279997 | F15: =運營_產能與收入!F71 -> 4.1279997 | G15: =運營_產能與收入!G71 -> 4.1279997 | I15: 已簽約未起租租賃 20.296 的現金路徑
A16: ② GPU 租金（租賃設備） | B16: US$m | C16: =輸入與假設!C$172 -> 8.0330849 | D16: =輸入與假設!D$172 -> 37.842479 | E16: =輸入與假設!E$172 -> 50.89496 | F16: =輸入與假設!F$172 -> 65.579644 | G16: =輸入與假設!G$172 -> 77.694508 | I16: 新增 GPU 租賃部分的固定租金（『輸入與假設』D 區；WhiteFiber v0.1b）
A17: 租金合計 | B17: US$m | C17: =C14+C15+C16 -> 11.817085 | D17: =D14+D15+D16 -> 46.250479 | E17: =E14+E15+E16 -> 57.48796 | F17: =F14+F15+F16 -> 72.011644 | G17: =G14+G15+G16 -> 84.180508 | I17: 租金已含在 EBITDA 率內（GAAP 營業租賃費用屬營業費用）：營運來源以 EBITDA 率＋租金÷營收計（租前），此列再扣，淨效果中性
A18: ③ 存量債務利息（備忘，1H 已含在 CFO） | B18: US$m | C18: =輸入與假設!C$225 -> 13.586726 | D18: =輸入與假設!D$225 -> 51.128959 | E18: =輸入與假設!E$225 -> 43.836731 | F18: =輸入與假設!F$225 -> 40.079815 | G18: =輸入與假設!G$225 -> 36.586123 | I18: ="6/30 債務餘額的利息。FY26 全年利息＝1H 實際 8.011＋2H "&TEXT(C18,"0.0")&"＝"&TEXT(8.011+C18,"0.00")&"（見下方備忘）" -> 6/30 債務餘額的利息。FY26 全年利息＝1H 實際 8.011＋2H 13.6＝21.60（見下方備忘）
A19: 期初累積現金 | B19: US$m | C19: =輸入與假設!$C$290 -> 114.441 | D19: =C54 -> 136.21658 | E19: =D54 -> 30 | F19: =E54 -> 30 | G19: =F54 -> 30 | I19: FY26 自 2025-12-31 起算；之後＝前期期末累積現金
A20: 新債利率 | B20: % | C20: =IF(輸入與假設!$C$218=1,輸入與假設!C$224+MAX(0,輸入與假設!$C$217-450)/100*0.004,輸入與假設!C$224) -> 0.095 | D20: =IF(輸入與假設!$C$218=1,輸入與假設!D$224+MAX(0,輸入與假設!$C$217-450)/100*0.004,輸入與假設!D$224) -> 0.095 | E20: =IF(輸入與假設!$C$218=1,輸入與假設!E$224+MAX(0,輸入與假設!$C$217-450)/100*0.004,輸入與假設!E$224) -> 0.095 | F20: =IF(輸入與假設!$C$218=1,輸入與假設!F$224+MAX(0,輸入與假設!$C$217-450)/100*0.004,輸入與假設!F$224) -> 0.095 | G20: =IF(輸入與假設!$C$218=1,輸入與假設!G$224+MAX(0,輸入與假設!$C$217-450)/100*0.004,輸入與假設!G$224) -> 0.095 | I20: CDS 開關：＋MAX(0,CDS−450)×0.4bp/bp
A21: ③ 新債利息（瀑布） | B21: US$m | C21: =C88 -> 0 | D21: =D88 -> 4.1728098 | E21: =E88 -> 8.8531983 | F21: =F88 -> 11.573231 | G21: =G88 -> 14.23471 | I21: ＝新債利率×期間長度×(期初新債＋本期舉借)；見下方「期前融資瀑布」
A22: 利息合計 | B22: US$m | C22: =C18+C21 -> 13.586726 | D22: =D18+D21 -> 55.301769 | E22: =E18+E21 -> 52.68993 | F22: =F18+F21 -> 51.653046 | G22: =G18+G21 -> 50.820832
A23: ④ JV／策略投資出資 | B23: US$m | C23: =輸入與假設!$C$294+輸入與假設!C$158 -> 0 | D23: =輸入與假設!D$158 -> 0 | E23: =輸入與假設!E$158 -> 0 | F23: =輸入與假設!F$158 -> 0 | G23: =輸入與假設!G$158 -> 0 | I23: FY26＝1H 實際 0.0（JV 0.000＋策略投資 0.000）＋2H 模型。WYFI 不發股息
A24: ⑧ 股利（普通股＋特別股） | B24: US$m | C24: =輸入與假設!$C$309+4*輸入與假設!$C$202*運營_產能與收入!C7*(輸入與假設!$C$203+0+SUMPRODUCT(資產負債_既有債務!$D$20:$D$21*資產負債_既有債務!$H$15:$H$16*(資產負債_既有債務!$G$15:$G$16<0)))+輸入與假設!C$222 -> 0 | D24: =4*輸入與假設!$C$202*運營_產能與收入!D7*(輸入與假設!$C$203+C91+SUMPRODUCT(資產負債_既有債務!$D$20:$D$21*資產負債_既有債務!$H$15:$H$16*(資產負債_既有債務!$G$15:$G$16<1)))+輸入與假設!D$222 -> 0 | E24: =4*輸入與假設!$C$202*運營_產能與收入!E7*(輸入與假設!$C$203+D91+SUMPRODUCT(資產負債_既有債務!$D$20:$D$21*資產負債_既有債務!$H$15:$H$16*(資產負債_既有債務!$G$15:$G$16<2)))+輸入與假設!E$222 -> 0 | F24: =4*輸入與假設!$C$202*運營_產能與收入!F7*(輸入與假設!$C$203+E91+SUMPRODUCT(資產負債_既有債務!$D$20:$D$21*資產負債_既有債務!$H$15:$H$16*(資產負債_既有債務!$G$15:$G$16<3)))+輸入與假設!F$222 -> 0 | G24: =4*輸入與假設!$C$202*運營_產能與收入!G7*(輸入與假設!$C$203+F91+SUMPRODUCT(資產負債_既有債務!$D$20:$D$21*資產負債_既有債務!$H$15:$H$16*(資產負債_既有債務!$G$15:$G$16<4)))+輸入與假設!G$222 -> 0 | I24: 普通股＝每股每季 × 4 × 期間長度 ×(基礎股數＋前期累計瀑布新股＋已強制轉換特別股)＋特別股股利；FY26＝1H 實際＋2H 模型（v0.1b）
A25: 電力（overlay） | B25: US$m | C25: =IF(輸入與假設!$C$130=1,運營_產能與收入!C9*8760*輸入與假設!C$132*輸入與假設!C$131/1000000*運營_產能與收入!C7,0) -> 0 | D25: =IF(輸入與假設!$C$130=1,運營_產能與收入!D9*8760*輸入與假設!D$132*輸入與假設!D$131/1000000*運營_產能與收入!D7,0) -> 0 | E25: =IF(輸入與假設!$C$130=1,運營_產能與收入!E9*8760*輸入與假設!E$132*輸入與假設!E$131/1000000*運營_產能與收入!E7,0) -> 0 | F25: =IF(輸入與假設!$C$130=1,運營_產能與收入!F9*8760*輸入與假設!F$132*輸入與假設!F$131/1000000*運營_產能與收入!F7,0) -> 0 | G25: =IF(輸入與假設!$C$130=1,運營_產能與收入!G9*8760*輸入與假設!G$132*輸入與假設!G$131/1000000*運營_產能與收入!G7,0) -> 0 | I25: ＝已連網 MW×8760×PUE×電價÷1e9×期間係數。EBITDA 率已含電費，預設關閉
A26: 維護（overlay） | B26: US$m | C26: =IF(輸入與假設!$C$130=1,運營_產能與收入!C9*輸入與假設!C$133*運營_產能與收入!C7,0) -> 0 | D26: =IF(輸入與假設!$C$130=1,運營_產能與收入!D9*輸入與假設!D$133*運營_產能與收入!D7,0) -> 0 | E26: =IF(輸入與假設!$C$130=1,運營_產能與收入!E9*輸入與假設!E$133*運營_產能與收入!E7,0) -> 0 | F26: =IF(輸入與假設!$C$130=1,運營_產能與收入!F9*輸入與假設!F$133*運營_產能與收入!F7,0) -> 0 | G26: =IF(輸入與假設!$C$130=1,運營_產能與收入!G9*輸入與假設!G$133*運營_產能與收入!G7,0) -> 0
A27: ⑤ 排程還本（季報到期表） | B27: US$m | C27: =輸入與假設!$C$296+IF(輸入與假設!$C$197=1,輸入與假設!C$223,0)+資產負債_既有債務!C32+資產負債_既有債務!C43 -> 17.972 | D27: =IF(輸入與假設!$C$197=1,輸入與假設!D$223,0)+資產負債_既有債務!D32+資產負債_既有債務!D43 -> 90.747 | E27: =IF(輸入與假設!$C$197=1,輸入與假設!E$223,0)+資產負債_既有債務!E32+資產負債_既有債務!E43 -> 36.9595 | F27: =IF(輸入與假設!$C$197=1,輸入與假設!F$223,0)+資產負債_既有債務!F32+資產負債_既有債務!F43 -> 51.6715 | G27: =IF(輸入與假設!$C$197=1,輸入與假設!G$223,0)+資產負債_既有債務!G32+資產負債_既有債務!G43 -> 30.7125 | I27: FY26＝1H 實際還款 12.599＋2H 到期表 5.373
A28: ⑥ capped call 支出（1H 實際） | B28: US$m | C28: =輸入與假設!$C$297 -> 120 | D28: =0 -> 0 | E28: =0 -> 0 | F28: =0 -> 0 | G28: =0 -> 0 | I28: 可轉債配套 capped call 現金支出（未見揭露，0）
A29: ⑦ 現金稅（2H 起） | B29: US$m | C29: =輸入與假設!$C$216*MAX(0,運營_產能與收入!C50*輸入與假設!C$127+輸入與假設!C$51+輸入與假設!C$117-運營_產能與收入!C74-輸入與假設!C$176-輸入與假設!C$225) -> 0 | D29: =輸入與假設!$C$216*MAX(0,運營_產能與收入!D50*輸入與假設!D$127+輸入與假設!D$51+輸入與假設!D$117-運營_產能與收入!D74-輸入與假設!D$176-輸入與假設!D$225) -> 0 | E29: =輸入與假設!$C$216*MAX(0,運營_產能與收入!E50*輸入與假設!E$127+輸入與假設!E$51+輸入與假設!E$117-運營_產能與收入!E74-輸入與假設!E$176-輸入與假設!E$225) -> 0 | F29: =輸入與假設!$C$216*MAX(0,運營_產能與收入!F50*輸入與假設!F$127+輸入與假設!F$51+輸入與假設!F$117-運營_產能與收入!F74-輸入與假設!F$176-輸入與假設!F$225) -> 0 | G29: =輸入與假設!$C$216*MAX(0,運營_產能與收入!G50*輸入與假設!G$127+輸入與假設!G$51+輸入與假設!G$117-運營_產能與收入!G74-輸入與假設!G$176-輸入與假設!G$225) -> 9.5408719 | I29: ＝稅率 × MAX(0, 損益 EBITDA − 車隊 D&A − 存量利息)；1H 的稅已含在 CFO 內（v0.1b）
A30: 用途合計（現金口徑） | B30: US$m | C30: =C13+C17+C22+C23+C25+C26+C27+C28+C29+C24 -> 655.06684 | D30: =D13+D17+D22+D23+D25+D26+D27+D28+D29+D24 -> 619.44486 | E30: =E13+E17+E22+E23+E25+E26+E27+E28+E29+E24 -> 203.52239 | F30: =F13+F17+F22+F23+F25+F26+F27+F28+F29+F24 -> 231.72119 | G30: =G13+G17+G22+G23+G25+G26+G27+G28+G29+G24 -> 302.30139 | I30: FY26 的 1H 部分採季報現金流量表口徑（現金購置、還款、JV、capped call）；1H 的利息與租金已含在 CFO 內，不重複列
A31: 來源（四層）
A32: Ⓐ0 1H26 實際營運現金流（CFO） | B32: US$m | C32: =輸入與假設!$C$291 -> 89.105 | D32: =0 -> 0 | E32: =0 -> 0 | F32: =0 -> 0 | G32: =0 -> 0 | I32: 季報實際值，取代模型推算；已含 1H 的利息、租金與客戶預付
A33: Ⓐ RPO 現金（2H 起） | B33: US$m | C33: =運營_產能與收入!C52 -> -0.91646212 | D33: =運營_產能與收入!D52 -> 3.8687335 | E33: =運營_產能與收入!E52 -> 2.2644478 | F33: =運營_產能與收入!F52 -> 0 | G33: =運營_產能與收入!G52 -> 0
A34: Ⓑ 新簽約現金 | B34: US$m | C34: =運營_產能與收入!C53 -> -0.83010925 | D34: =運營_產能與收入!D53 -> 12.021047 | E34: =運營_產能與收入!E53 -> 56.472883 | F34: =運營_產能與收入!F53 -> 112.69607 | G34: =運營_產能與收入!G53 -> 177.69662
A35: Ⓒ 非算力服務現金 | B35: US$m | C35: =輸入與假設!C$128 -> 0 | D35: =輸入與假設!D$128 -> 0 | E35: =輸入與假設!E$128 -> 0 | F35: =輸入與假設!F$128 -> 0 | G35: =輸入與假設!G$128 -> 0
A36: Ⓒ2 其他事業 EBITDA（2H 起） | B36: US$m | C36: =輸入與假設!C$51 -> 0 | D36: =輸入與假設!D$51 -> 0 | E36: =輸入與假設!E$51 -> 0 | F36: =輸入與假設!F$51 -> 0 | G36: =輸入與假設!G$51 -> 0 | I36: 非核心事業 EBITDA（負值＝燒錢），視為現金（v0.1b）
A37: Ⓒ3 託管 EBITDA（2H 起） | B37: US$m | C37: =輸入與假設!C$117 -> 19.780763 | D37: =輸入與假設!D$117 -> 55.685633 | E37: =輸入與假設!E$117 -> 88.573269 | F37: =輸入與假設!F$117 -> 105.63746 | G37: =輸入與假設!G$117 -> 114.07223 | I37: SaaS、軟體、硬體、服務四線 EBITDA，視為現金（現金稅另列於用途；v0.1b）
A38: Ⓒ4 減：延誤罰則（營業費用） | B38: US$m | C38: =-運營_產能與收入!C74 -> 0 | D38: =-運營_產能與收入!D74 -> 0 | E38: =-運營_產能與收入!E74 -> 0 | F38: =-運營_產能與收入!F74 -> 0 | G38: =-運營_產能與收入!G74 -> 0 | I38: 建設延誤期間應計費而未計費營收 × 罰則比例（預設 0；v0.2）
A39: Ⓓ 客戶預付（2H 起） | B39: US$m | C39: =C8 -> 30.865595 | D39: =D8 -> 89.700579 | E39: =E8 -> 11.84085 | F39: =F8 -> 11.84085 | G39: =G8 -> 7.6965525
A40: Ⓓ2 減：預付認列（非現金營收） | B40: US$m | C40: =-C11 -> -8.944375 | D40: =-D11 -> -20.628903 | E40: =-E11 -> -29.262862 | F40: =-F11 -> -27.085111 | G40: =-G11 -> -25.179578 | I40: 營收中由合約負債轉入的部分已在預付時收現，不重複計入服務現金（v0.1b）
A41: 營運來源合計 | B41: US$m | C41: =C32+C33+C34+C35+C36+C37+C38+C39+C40 -> 129.06041 | D41: =D32+D33+D34+D35+D36+D37+D38+D39+D40 -> 140.64709 | E41: =E32+E33+E34+E35+E36+E37+E38+E39+E40 -> 129.88859 | F41: =F32+F33+F34+F35+F36+F37+F38+F39+F40 -> 203.08927 | G41: =G32+G33+G34+G35+G36+G37+G38+G39+G40 -> 274.28583
...

Sheet 季度追蹤
A1: 季度追蹤 — 焦點季的模型／共識／指引／實際與差距（由年度模型拆分；只用於追蹤，不影響年度數字與目標價）
A2: 設定與實際數在『輸入與假設』J 區，共識在 I 區；缺資料顯示「不適用」，實際數空白＝待公布。差距超過門檻的項目附差異原因（拆法＝所屬期間合計差距在門檻內）。第 2 區為 6 季路徑與拆分明細（預設收合）。
A4: 1｜焦點季（『輸入與假設』J 區選擇）：模型／共識／指引／實際與差距
A5: 指標 | B5: 單位 | C5: 模型 | D5: 共識 | E5: 模型 vs 共識 | F5: 指引（低） | G5: 指引（高） | H5: 模型 vs 指引中點 | I5: 實際 | J5: 實際 vs 模型 | K5: 實際 vs 共識 | L5: 實際 vs 指引中點 | M5: 利潤率 pt：模型 vs 共識 | N5: 模型 vs 指引 | O5: 實際 vs 模型 | P5: 實際 vs 共識 | Q5: 實際 vs 指引
A6: 焦點｜營收 | B6: US$m | C6: =INDEX($C$22:$H$22,輸入與假設!$C$373) -> 31.883144 | D6: =INDEX($C$32:$H$32,輸入與假設!$C$373) -> 不適用 | E6: =INDEX($C$41:$H$41,輸入與假設!$C$373) -> 不適用 | F6: 不適用 | G6: 不適用 | H6: =INDEX($C$42:$H$42,輸入與假設!$C$373) -> 不適用 | I6: =IF(ISNUMBER(INDEX($C$35:$H$35,輸入與假設!$C$373)),INDEX($C$35:$H$35,輸入與假設!$C$373),"待公布") -> 待公布 | J6: =INDEX($C$43:$H$43,輸入與假設!$C$373) | K6: =INDEX($C$44:$H$44,輸入與假設!$C$373) | L6: =INDEX($C$45:$H$45,輸入與假設!$C$373)
A7: 焦點｜調整後 EBITDA | B7: US$m | C7: =INDEX($C$28:$H$28,輸入與假設!$C$373) -> 2.4255511 | D7: =INDEX($C$33:$H$33,輸入與假設!$C$373) -> 不適用 | E7: =INDEX($C$46:$H$46,輸入與假設!$C$373) -> 不適用 | F7: 不適用 | G7: 不適用 | H7: =INDEX($C$47:$H$47,輸入與假設!$C$373) -> 不適用 | I7: =IF(ISNUMBER(INDEX($C$36:$H$36,輸入與假設!$C$373)),INDEX($C$36:$H$36,輸入與假設!$C$373),"待公布") -> 待公布 | J7: =INDEX($C$48:$H$48,輸入與假設!$C$373) | K7: =INDEX($C$49:$H$49,輸入與假設!$C$373) | L7: =INDEX($C$50:$H$50,輸入與假設!$C$373) | M7: =INDEX($C$51:$H$51,輸入與假設!$C$373) -> 不適用 | N7: =INDEX($C$52:$H$52,輸入與假設!$C$373) -> 不適用 | O7: =INDEX($C$53:$H$53,輸入與假設!$C$373) | P7: =INDEX($C$54:$H$54,輸入與假設!$C$373) | Q7: =INDEX($C$55:$H$55,輸入與假設!$C$373)
A8: 焦點｜EBITDA 率 | B8: % | C8: =INDEX($C$27:$H$27,輸入與假設!$C$373) -> 0.076076284 | D8: =INDEX($C$34:$H$34,輸入與假設!$C$373) -> 不適用 | E8: =INDEX($C$56:$H$56,輸入與假設!$C$373) -> 不適用 | F8: 不適用 | G8: 不適用 | H8: =INDEX($C$57:$H$57,輸入與假設!$C$373) -> 不適用 | I8: =IF(ISNUMBER(INDEX($C$37:$H$37,輸入與假設!$C$373)),INDEX($C$37:$H$37,輸入與假設!$C$373),"待公布") -> 待公布 | J8: =INDEX($C$58:$H$58,輸入與假設!$C$373) | K8: =INDEX($C$59:$H$59,輸入與假設!$C$373) | L8: =INDEX($C$60:$H$60,輸入與假設!$C$373)
A9: 焦點｜調整後營業利益 | B9: US$m | C9: =INDEX($C$30:$H$30,輸入與假設!$C$373) -> -10.953068 | D9: 不適用 | E9: =INDEX($C$61:$H$61,輸入與假設!$C$373) -> 不適用 | F9: 不適用 | G9: 不適用 | H9: =INDEX($C$62:$H$62,輸入與假設!$C$373) -> 不適用 | I9: =IF(ISNUMBER(INDEX($C$38:$H$38,輸入與假設!$C$373)),INDEX($C$38:$H$38,輸入與假設!$C$373),"待公布") -> 待公布 | J9: =INDEX($C$63:$H$63,輸入與假設!$C$373) | K9: =INDEX($C$64:$H$64,輸入與假設!$C$373) | L9: =INDEX($C$65:$H$65,輸入與假設!$C$373) | M9: =INDEX($C$66:$H$66,輸入與假設!$C$373) -> 不適用 | N9: =INDEX($C$67:$H$67,輸入與假設!$C$373) -> 不適用 | O9: =INDEX($C$68:$H$68,輸入與假設!$C$373) | P9: =INDEX($C$69:$H$69,輸入與假設!$C$373) | Q9: =INDEX($C$70:$H$70,輸入與假設!$C$373)
A10: 焦點｜CapEx（毛額） | B10: US$m | C10: =INDEX($C$31:$H$31,輸入與假設!$C$373) -> 73.489513 | D10: 不適用 | E10: =INDEX($C$71:$H$71,輸入與假設!$C$373) -> 不適用 | F10: 不適用 | G10: 不適用 | H10: =INDEX($C$72:$H$72,輸入與假設!$C$373) -> 不適用 | I10: =IF(ISNUMBER(INDEX($C$39:$H$39,輸入與假設!$C$373)),INDEX($C$39:$H$39,輸入與假設!$C$373),"待公布") -> 待公布 | J10: =INDEX($C$73:$H$73,輸入與假設!$C$373) | K10: =INDEX($C$74:$H$74,輸入與假設!$C$373) | L10: =INDEX($C$75:$H$75,輸入與假設!$C$373)
A11: 焦點｜季末雲端已連網 MW-IT | B11: MW | C11: =INDEX($C$19:$H$19,輸入與假設!$C$373) -> 10.037 | D11: 不適用 | E11: =INDEX($C$76:$H$76,輸入與假設!$C$373) -> 不適用 | F11: 不適用 | G11: 不適用 | H11: =INDEX($C$77:$H$77,輸入與假設!$C$373) -> 不適用 | I11: =IF(ISNUMBER(INDEX($C$40:$H$40,輸入與假設!$C$373)),INDEX($C$40:$H$40,輸入與假設!$C$373),"待公布") -> 待公布 | J11: =INDEX($C$78:$H$78,輸入與假設!$C$373) | K11: =INDEX($C$79:$H$79,輸入與假設!$C$373) | L11: =INDEX($C$80:$H$80,輸入與假設!$C$373)
A12: 焦點｜季度 | C12: =INDEX($C$16:$H$16,輸入與假設!$C$373) -> Q3 2026
A13: 焦點｜差異原因 | C13: =IF(INDEX($C$117:$H$117,輸入與假設!$C$373)="","無（差距皆在 "&IF(ROUND(ABS(輸入與假設!$C$367)*100,4)=INT(ROUND(ABS(輸入與假設!$C$367)*100,4)),TEXT(ROUND(ABS(輸入與假設!$C$367)*100,4),"0"),TEXT(ROUND(ABS(輸入與假設!$C$367)*100,4),"0.0"))&"%"&" 以內）",INDEX($C$117:$H$117,輸入與假設!$C$373)) -> 無（差距皆在 5% 以內）
A15: 2｜6 季路徑、共識、指引、實際與差距（明細；第 1 區以焦點季引用本區）
A16: 項目 | B16: 單位 | C16: Q3 2026 | D16: Q4 2026 | E16: Q1 2027 | F16: Q2 2027 | G16: Q3 2027 | H16: Q4 2027
A17: 所屬期間 | C17: =輸入與假設!C$372 -> 1 | D17: =輸入與假設!D$372 -> 1 | E17: =輸入與假設!E$372 -> 2 | F17: =輸入與假設!F$372 -> 2 | G17: =輸入與假設!G$372 -> 2 | H17: =輸入與假設!H$372 -> 2 | J17: 1＝2H26、2＝FY27
A18: 季序 | C18: 1 | D18: 2 | E18: 3 | F18: 4 | G18: 5 | H18: 6 | J18: EBITDA 率直線的 x 軸
A19: 季末雲端已連網 MW-IT（模型） | B19: MW | C19: =輸入與假設!$C$375+(輸入與假設!C$43-輸入與假設!$C$375)*1/2 -> 10.037 | D19: =輸入與假設!$C$375+(輸入與假設!C$43-輸入與假設!$C$375)*2/2 -> 14.574 | E19: =輸入與假設!C$43+(輸入與假設!D$43-輸入與假設!C$43)*1/4 -> 15.0675 | F19: =輸入與假設!C$43+(輸入與假設!D$43-輸入與假設!C$43)*2/4 -> 15.561 | G19: =輸入與假設!C$43+(輸入與假設!D$43-輸入與假設!C$43)*3/4 -> 16.0545 | H19: =輸入與假設!C$43+(輸入與假設!D$43-輸入與假設!C$43)*4/4 -> 16.548 | J19: 期初與期末 Accepted 之間線性內插；第 1 期起點見 J 區
A20: 平均在役 MW（Billable，拆分依據） | B20: MW | C20: =輸入與假設!$C$36+(運營_產能與收入!C$11-輸入與假設!$C$36)*1/4 -> 3.69375 | D20: =輸入與假設!$C$36+(運營_產能與收入!C$11-輸入與假設!$C$36)*3/4 -> 5.78125 | E20: =運營_產能與收入!C$11+(運營_產能與收入!D$11-運營_產能與收入!C$11)*1/8 -> 7.67125 | F20: =運營_產能與收入!C$11+(運營_產能與收入!D$11-運營_產能與收入!C$11)*3/8 -> 9.36375 | G20: =運營_產能與收入!C$11+(運營_產能與收入!D$11-運營_產能與收入!C$11)*5/8 -> 11.05625 | H20: =運營_產能與收入!C$11+(運營_產能與收入!D$11-運營_產能與收入!C$11)*7/8 -> 12.74875 | J20: 期初與期末 Billable 之間線性內插的季平均
A21: 季內新增 Accepted MW | B21: MW | C21: =C19-輸入與假設!$C$375 -> 4.537 | D21: =D19-C19 -> 4.537 | E21: =E19-輸入與假設!C$43 -> 0.4935 | F21: =F19-E19 -> 0.4935 | G21: =G19-F19 -> 0.4935 | H21: =H19-G19 -> 0.4935 | J21: CapEx 拆分依據
A22: 營收（模型） | B22: US$m | C22: =輸入與假設!$C$374+1*(損益!C9-2*輸入與假設!$C$374)/3 -> 31.883144 | D22: =輸入與假設!$C$374+2*(損益!C9-2*輸入與假設!$C$374)/3 -> 47.227287 | E22: =損益!D9*E20/(E20+F20+G20+H20) -> 52.250451 | F22: =損益!D9*F20/(E20+F20+G20+H20) -> 63.778414 | G22: =損益!D9*G20/(E20+F20+G20+H20) -> 75.306377 | H22: =損益!D9*H20/(E20+F20+G20+H20) -> 86.834341 | J22: 拆分方法見『輸入與假設』J 區與 HTML「拆分方法」
A23: EBITDA 率直線｜各期營收合計 S | C23: =C22+D22 -> 79.110431 | D23: =E22+F22+G22+H22 -> 278.16958 | J23: 欄＝期間（2H26、FY27）
A24: EBITDA 率直線｜營收 × 季序合計 T | C24: =C22*C18+D22*D18 -> 126.33772 | D24: =E22*E18+F22*F18+G22*G18+H22*H18 -> 1309.4029 | J24: 欄＝期間（2H26、FY27）
A25: EBITDA 率直線｜年度 EBITDA E | C25: =損益!C22 -> 6.212729 | D25: =損益!D22 -> 25.404783 | J25: 欄＝期間（2H26、FY27）
A26: EBITDA 率直線｜截距 a／斜率 b | C26: =(C25*D24-C24*D25)/(C23*D24-C24*D23) -> 0.071962108 | D26: =(C23*D25-D23*C25)/(C23*D24-C24*D23) -> 0.0041141755 | J26: 解兩式：Σ營收×(a＋b×季序)＝各期年度 EBITDA
A27: EBITDA 率（模型） | B27: % | C27: =$C$26+$D$26*C18 -> 0.076076284 | D27: =$C$26+$D$26*D18 -> 0.080190459 | E27: =$C$26+$D$26*E18 -> 0.084304635 | F27: =$C$26+$D$26*F18 -> 0.08841881 | G27: =$C$26+$D$26*G18 -> 0.092532986 | H27: =$C$26+$D$26*H18 -> 0.096647161 | J27: 跨季一條直線，季度 EBITDA 加總＝年度
A28: 調整後 EBITDA（模型） | B28: US$m | C28: =C22*C27 -> 2.4255511 | D28: =D22*D27 -> 3.7871779 | E28: =E22*E27 -> 4.4049552 | F28: =F22*F27 -> 5.6392115 | G28: =G22*G27 -> 6.9683239 | H28: =H22*H27 -> 8.3922925
A29: 車隊折舊（模型） | B29: US$m | C29: =(輸入與假設!C$173+運營_產能與收入!C$66*1/4)/輸入與假設!$C$139*輸入與假設!C$41/2+(輸入與假設!C$110+輸入與假設!C$107*1/4)/輸入與假設!$C$109*輸入與假設!C$41/2 -> 13.378619 | D29: =(輸入與假設!C$173+運營_產能與收入!C$66*3/4)/輸入與假設!$C$139*輸入與假設!C$41/2+(輸入與假設!C$110+輸入與假設!C$107*3/4)/輸入與假設!$C$109*輸入與假設!C$41/2 -> 15.068357 | E29: =(輸入與假設!D$173+運營_產能與收入!D$66*1/8)/輸入與假設!$C$139*輸入與假設!D$41/4+(輸入與假設!D$110+輸入與假設!D$107*1/8)/輸入與假設!$C$109*輸入與假設!D$41/4 -> 17.103233 | F29: =(輸入與假設!D$173+運營_產能與收入!D$66*3/8)/輸入與假設!$C$139*輸入與假設!D$41/4+(輸入與假設!D$110+輸入與假設!D$107*3/8)/輸入與假設!$C$109*輸入與假設!D$41/4 -> 19.483249 | G29: =(輸入與假設!D$173+運營_產能與收入!D$66*5/8)/輸入與假設!$C$139*輸入與假設!D$41/4+(輸入與假設!D$110+輸入與假設!D$107*5/8)/輸入與假設!$C$109*輸入與假設!D$41/4 -> 21.863264 | H29: =(輸入與假設!D$173+運營_產能與收入!D$66*7/8)/輸入與假設!$C$139*輸入與假設!D$41/4+(輸入與假設!D$110+輸入與假設!D$107*7/8)/輸入與假設!$C$109*輸入與假設!D$41/4 -> 24.243279 | J29: 依期內平均 PP&E（與年度車隊折舊公式相同；含託管建物 D&A）
A30: 調整後營業利益（模型） | B30: US$m | C30: =C28-C29 -> -10.953068 | D30: =D28-D29 -> -11.281179 | E30: =E28-E29 -> -12.698278 | F30: =F28-F29 -> -13.844037 | G30: =G28-G29 -> -14.89494 | H30: =H28-H29 -> -15.850987 | J30: ＝調整後 EBITDA − 車隊折舊（未扣 SBC）
A31: CapEx（毛額）（模型） | B31: US$m | C31: =IF((C21+D21)>0,輸入與假設!C$175*C21/(C21+D21),輸入與假設!C$175/2) -> 73.489513 | D31: =IF((C21+D21)>0,輸入與假設!C$175*D21/(C21+D21),輸入與假設!C$175/2) -> 73.489513 | E31: =IF((E21+F21+G21+H21)>0,輸入與假設!D$175*E21/(E21+F21+G21+H21),輸入與假設!D$175/4) -> 106.7864 | F31: =IF((E21+F21+G21+H21)>0,輸入與假設!D$175*F21/(E21+F21+G21+H21),輸入與假設!D$175/4) -> 106.7864 | G31: =IF((E21+F21+G21+H21)>0,輸入與假設!D$175*G21/(E21+F21+G21+H21),輸入與假設!D$175/4) -> 106.7864 | H31: =IF((E21+F21+G21+H21)>0,輸入與假設!D$175*H21/(E21+F21+G21+H21),輸入與假設!D$175/4) -> 106.7864 | J31: 依季內新增 Accepted MW
A32: 共識｜營收 | B32: US$m | C32: 不適用 | D32: 不適用 | E32: 不適用 | F32: 不適用 | G32: 不適用 | H32: 不適用 | J32: I 區季度共識 [Interested-party]
A33: 共識｜調整後 EBITDA | B33: US$m | C33: 不適用 | D33: 不適用 | E33: 不適用 | F33: 不適用 | G33: 不適用 | H33: 不適用 | J33: I 區季度共識 [Interested-party]
A34: 共識｜EBITDA 率 [Derived] | B34: % | C34: 不適用 | D34: 不適用 | E34: 不適用 | F34: 不適用 | G34: 不適用 | H34: 不適用 | J34: ＝共識 EBITDA ÷ 共識營收
A35: 實際｜營收 | B35: US$m | C35: =IF(ISNUMBER(輸入與假設!C$376),輸入與假設!C$376,"") | D35: =IF(ISNUMBER(輸入與假設!D$376),輸入與假設!D$376,"") | E35: =IF(ISNUMBER(輸入與假設!E$376),輸入與假設!E$376,"") | F35: =IF(ISNUMBER(輸入與假設!F$376),輸入與假設!F$376,"") | G35: =IF(ISNUMBER(輸入與假設!G$376),輸入與假設!G$376,"") | H35: =IF(ISNUMBER(輸入與假設!H$376),輸入與假設!H$376,"")
A36: 實際｜調整後 EBITDA | B36: US$m | C36: =IF(ISNUMBER(輸入與假設!C$377),輸入與假設!C$377,"") | D36: =IF(ISNUMBER(輸入與假設!D$377),輸入與假設!D$377,"") | E36: =IF(ISNUMBER(輸入與假設!E$377),輸入與假設!E$377,"") | F36: =IF(ISNUMBER(輸入與假設!F$377),輸入與假設!F$377,"") | G36: =IF(ISNUMBER(輸入與假設!G$377),輸入與假設!G$377,"") | H36: =IF(ISNUMBER(輸入與假設!H$377),輸入與假設!H$377,"")
A37: 實際｜EBITDA 率 | B37: % | C37: =IF(AND(ISNUMBER(輸入與假設!C$377),ISNUMBER(輸入與假設!C$376)),輸入與假設!C$377/輸入與假設!C$376,"") | D37: =IF(AND(ISNUMBER(輸入與假設!D$377),ISNUMBER(輸入與假設!D$376)),輸入與假設!D$377/輸入與假設!D$376,"") | E37: =IF(AND(ISNUMBER(輸入與假設!E$377),ISNUMBER(輸入與假設!E$376)),輸入與假設!E$377/輸入與假設!E$376,"") | F37: =IF(AND(ISNUMBER(輸入與假設!F$377),ISNUMBER(輸入與假設!F$376)),輸入與假設!F$377/輸入與假設!F$376,"") | G37: =IF(AND(ISNUMBER(輸入與假設!G$377),ISNUMBER(輸入與假設!G$376)),輸入與假設!G$377/輸入與假設!G$376,"") | H37: =IF(AND(ISNUMBER(輸入與假設!H$377),ISNUMBER(輸入與假設!H$376)),輸入與假設!H$377/輸入與假設!H$376,"") | J37: ＝實際 EBITDA ÷ 實際營收
A38: 實際｜調整後營業利益 | B38: US$m | C38: =IF(ISNUMBER(輸入與假設!C$378),輸入與假設!C$378,"") | D38: =IF(ISNUMBER(輸入與假設!D$378),輸入與假設!D$378,"") | E38: =IF(ISNUMBER(輸入與假設!E$378),輸入與假設!E$378,"") | F38: =IF(ISNUMBER(輸入與假設!F$378),輸入與假設!F$378,"") | G38: =IF(ISNUMBER(輸入與假設!G$378),輸入與假設!G$378,"") | H38: =IF(ISNUMBER(輸入與假設!H$378),輸入與假設!H$378,"")
A39: 實際｜CapEx（毛額） | B39: US$m | C39: =IF(ISNUMBER(輸入與假設!C$379),輸入與假設!C$379,"") | D39: =IF(ISNUMBER(輸入與假設!D$379),輸入與假設!D$379,"") | E39: =IF(ISNUMBER(輸入與假設!E$379),輸入與假設!E$379,"") | F39: =IF(ISNUMBER(輸入與假設!F$379),輸入與假設!F$379,"") | G39: =IF(ISNUMBER(輸入與假設!G$379),輸入與假設!G$379,"") | H39: =IF(ISNUMBER(輸入與假設!H$379),輸入與假設!H$379,"")
A40: 實際｜季末雲端 MW（口徑不明） | B40: MW | C40: =IF(ISNUMBER(輸入與假設!C$380),輸入與假設!C$380,"") | D40: =IF(ISNUMBER(輸入與假設!D$380),輸入與假設!D$380,"") | E40: =IF(ISNUMBER(輸入與假設!E$380),輸入與假設!E$380,"") | F40: =IF(ISNUMBER(輸入與假設!F$380),輸入與假設!F$380,"") | G40: =IF(ISNUMBER(輸入與假設!G$380),輸入與假設!G$380,"") | H40: =IF(ISNUMBER(輸入與假設!H$380),輸入與假設!H$380,"")
A41: 差距｜營收｜模型 vs 共識 | B41: % | C41: =IF(AND(ISNUMBER(C22),ISNUMBER(C32),C32<>0),C22/(C32)-1,"不適用") -> 不適用 | D41: =IF(AND(ISNUMBER(D22),ISNUMBER(D32),D32<>0),D22/(D32)-1,"不適用") -> 不適用 | E41: =IF(AND(ISNUMBER(E22),ISNUMBER(E32),E32<>0),E22/(E32)-1,"不適用") -> 不適用 | F41: =IF(AND(ISNUMBER(F22),ISNUMBER(F32),F32<>0),F22/(F32)-1,"不適用") -> 不適用 | G41: =IF(AND(ISNUMBER(G22),ISNUMBER(G32),G32<>0),G22/(G32)-1,"不適用") -> 不適用 | H41: =IF(AND(ISNUMBER(H22),ISNUMBER(H32),H32<>0),H22/(H32)-1,"不適用") -> 不適用
A42: 差距｜營收｜模型 vs 指引中點 | B42: % | C42: 不適用 | D42: 不適用 | E42: 不適用 | F42: 不適用 | G42: 不適用 | H42: 不適用
...

Sheet 運營_產能與收入
A1: 產能與收入 — 合約排程 vs 機房產能
A2: 兩條線獨立產生後相減：排程>容量→瓶頸（收不到）；容量>排程→剩餘產能（要靠新簽約賣掉）
A3: FY26 欄口徑：MW 為年底存量；標示「（模型期）」的收入列只含 2026 下半年——RPO 桶自 2026-06-30 起算，1H 收入已實現、不再受產能約束。1H 實際單列，兩者相加即 FY26 全年（見本頁「FY26 全年」列）。
A5: 項目 | B5: 單位 | C5: FY26 | D5: FY27 | E5: FY28 | F5: FY29 | G5: FY30 | I5: 公式／來源說明
A6: 模型期間 | C6: ="2026-07-01~12-31" -> 2026-07-01~12-31 | D6: ="2027 全年" -> 2027 全年 | E6: ="2028 全年" -> 2028 全年 | F6: ="2029 全年" -> 2029 全年 | G6: ="2030 全年" -> 2030 全年 | I6: FY26 的模型期只有下半年；1H 已實現的營收單列於下方
A7: 模型期長度（年） | C7: =輸入與假設!C$41 -> 0.5 | D7: =輸入與假設!D$41 -> 1 | E7: =輸入與假設!E$41 -> 1 | F7: =輸入與假設!F$41 -> 1 | G7: =輸入與假設!G$41 -> 1 | I7: 只用於下方三處：容量上限、電力、維護——把年率換算成該期金額
A8: （A）機房：容量上限
A9: Accepted MW（已驗收，單調不減） | B9: MW | C9: =MAX(0,輸入與假設!C$43) -> 14.574 | D9: =MAX(輸入與假設!D$43,C9) -> 16.548 | E9: =MAX(輸入與假設!E$43,D9) -> 19.548 | F9: =MAX(輸入與假設!F$43,E9) -> 22.548 | G9: =MAX(輸入與假設!G$43,F9) -> 25.548 | I9: 引擎規則：不得低於前期（產能不會消失）
A10: Billable MW（上限為 Accepted） | B10: MW | C10: =MIN(MAX(0,輸入與假設!C$44),C9) -> 11 | D10: =MIN(MAX(0,輸入與假設!D$44),D9) -> 14.46 | E10: =MIN(MAX(0,輸入與假設!E$44),E9) -> 17.86 | F10: =MIN(MAX(0,輸入與假設!F$44),F9) -> 20.56 | G10: =MIN(MAX(0,輸入與假設!G$44),G9) -> 23.26 | I10: 引擎規則：可計費不得超過已驗收
A11: Billable MW（延誤後，計費用） | B11: MW | C11: =IF($C$62<=0,$C$10,輸入與假設!$C$36+($C$10-輸入與假設!$C$36)*MAX(0,MIN(1,($C$63-$C$62/12-0)/$C$7))+($D$10-$C$10)*MAX(0,MIN(1,($C$63-$C$62/12-$C$63)/$D$7))+($E$10-$D$10)*MAX(0,MIN(1,($C$63-$C$62/12-$D$63)/$E$7))+($F$10-$E$10)*MAX(0,MIN(1,($C$63-$C$62/12-$E$63)/$F$7))+($G$10-$F$10)*MAX(0,MIN(1,($C$63-$C$62/12-$F$63)/$G$7))) -> 6.825 | D11: =IF($C$62<=0,$D$10,輸入與假設!$C$36+($C$10-輸入與假設!$C$36)*MAX(0,MIN(1,($D$63-$C$62/12-0)/$C$7))+($D$10-$C$10)*MAX(0,MIN(1,($D$63-$C$62/12-$C$63)/$D$7))+($E$10-$D$10)*MAX(0,MIN(1,($D$63-$C$62/12-$D$63)/$E$7))+($F$10-$E$10)*MAX(0,MIN(1,($D$63-$C$62/12-$E$63)/$F$7))+($G$10-$F$10)*MAX(0,MIN(1,($D$63-$C$62/12-$F$63)/$G$7))) -> 13.595 | E11: =IF($C$62<=0,$E$10,輸入與假設!$C$36+($C$10-輸入與假設!$C$36)*MAX(0,MIN(1,($E$63-$C$62/12-0)/$C$7))+($D$10-$C$10)*MAX(0,MIN(1,($E$63-$C$62/12-$C$63)/$D$7))+($E$10-$D$10)*MAX(0,MIN(1,($E$63-$C$62/12-$D$63)/$E$7))+($F$10-$E$10)*MAX(0,MIN(1,($E$63-$C$62/12-$E$63)/$F$7))+($G$10-$F$10)*MAX(0,MIN(1,($E$63-$C$62/12-$F$63)/$G$7))) -> 17.01 | F11: =IF($C$62<=0,$F$10,輸入與假設!$C$36+($C$10-輸入與假設!$C$36)*MAX(0,MIN(1,($F$63-$C$62/12-0)/$C$7))+($D$10-$C$10)*MAX(0,MIN(1,($F$63-$C$62/12-$C$63)/$D$7))+($E$10-$D$10)*MAX(0,MIN(1,($F$63-$C$62/12-$D$63)/$E$7))+($F$10-$E$10)*MAX(0,MIN(1,($F$63-$C$62/12-$E$63)/$F$7))+($G$10-$F$10)*MAX(0,MIN(1,($F$63-$C$62/12-$F$63)/$G$7))) -> 19.885 | G11: =IF($C$62<=0,$G$10,輸入與假設!$C$36+($C$10-輸入與假設!$C$36)*MAX(0,MIN(1,($G$63-$C$62/12-0)/$C$7))+($D$10-$C$10)*MAX(0,MIN(1,($G$63-$C$62/12-$C$63)/$D$7))+($E$10-$D$10)*MAX(0,MIN(1,($G$63-$C$62/12-$D$63)/$E$7))+($F$10-$E$10)*MAX(0,MIN(1,($G$63-$C$62/12-$E$63)/$F$7))+($G$10-$F$10)*MAX(0,MIN(1,($G$63-$C$62/12-$F$63)/$G$7))) -> 22.585 | I11: ＝上列往後平移建設延誤月數（以期間長度線性內插；評價日之前取期初校準值）；延誤 0 時＝上列；見（E）區（v0.2）
A12: 期初在役 MW | B12: MW | C12: =輸入與假設!$C$36 -> 2.65 | D12: =C11 -> 6.825 | E12: =D11 -> 13.595 | F12: =E11 -> 17.01 | G12: =F11 -> 19.885 | I12: 前期期末＝本期期初（延誤後）
A13: 平均在役 MW（FY26 欄為下半年平均） | B13: MW | C13: =IF(輸入與假設!$C$37=1,(C12+C11)/2,C11) -> 4.7375 | D13: =IF(輸入與假設!$C$37=1,(D12+D11)/2,D11) -> 10.21 | E13: =IF(輸入與假設!$C$37=1,(E12+E11)/2,E11) -> 15.3025 | F13: =IF(輸入與假設!$C$37=1,(F12+F11)/2,F11) -> 18.4475 | G13: =IF(輸入與假設!$C$37=1,(G12+G11)/2,G11) -> 21.235 | I13: 開關在輸入頁：1＝(期初+期末)/2，0＝期末全期化
A14: 利用率 | B14: % | C14: =輸入與假設!C$45 -> 1 | D14: =輸入與假設!D$45 -> 1 | E14: =輸入與假設!E$45 -> 1 | F14: =輸入與假設!F$45 -> 1 | G14: =輸入與假設!G$45 -> 1
A15: 每 MW 年收入 | B15: US$m/MW | C15: =輸入與假設!C$46 -> 17.4 | D15: =輸入與假設!D$46 -> 17.4 | E15: =輸入與假設!E$46 -> 17.4 | F15: =輸入與假設!F$46 -> 17.4 | G15: =輸入與假設!G$46 -> 17.4
A16: 容量上限（模型期最多能交付的收入） | B16: US$m | C16: =C13*輸入與假設!C$46*輸入與假設!$C$39*輸入與假設!C$45*C7 -> 41.21625 | D16: =D13*輸入與假設!D$46*輸入與假設!$C$39*輸入與假設!D$45*D7 -> 177.654 | E16: =E13*輸入與假設!E$46*輸入與假設!$C$39*輸入與假設!E$45*E7 -> 266.2635 | F16: =F13*輸入與假設!F$46*輸入與假設!$C$39*輸入與假設!F$45*F7 -> 320.9865 | G16: =G13*輸入與假設!G$46*輸入與假設!$C$39*輸入與假設!G$45*G7 -> 369.489 | I16: ＝平均在役 MW × 每 MW 年收入 × 利用率 × 期間係數。只看機房，不看合約
A17: （B）合約：排程 RPO
A18: 排程 RPO（模型期，依季報桶分攤） | B18: US$m | C18: =(輸入與假設!$C$31+輸入與假設!$C$32)*(輸入與假設!C$42/輸入與假設!$C$34)*輸入與假設!$C$33 -> 21.627019 | D18: =(輸入與假設!$C$31+輸入與假設!$C$32)*(輸入與假設!D$42/輸入與假設!$C$34)*輸入與假設!$C$33 -> 43.253962 | E18: =(輸入與假設!$C$31+輸入與假設!$C$32)*(輸入與假設!E$42/輸入與假設!$C$34)*輸入與假設!$C$33 -> 10.265019 | F18: =(輸入與假設!$C$31+輸入與假設!$C$32)*(輸入與假設!F$42/輸入與假設!$C$34)*輸入與假設!$C$33 -> 0 | G18: =(輸入與假設!$C$31+輸入與假設!$C$32)*(輸入與假設!G$42/輸入與假設!$C$34)*輸入與假設!$C$33 -> 0 | I18: ＝(6/30 RPO＋評價日後新增)×本期權重÷權重合計×五期認列比例。只看合約，不看機房
A19: （C）兩條線相減
A20: 產能瓶頸（模型期：排程 − 容量） | B20: US$m | C20: =MAX(0,C18-C16) -> 0 | D20: =MAX(0,D18-D16) -> 0 | E20: =MAX(0,E18-E16) -> 0 | F20: =MAX(0,F18-F16) -> 0 | G20: =MAX(0,G18-G16) -> 0 | I20: 合約有、機房沒有 → 本期收不到，且不遞延到下期（保守處理）
A21: 期初 RPO 轉換收入（模型期） | B21: US$m | C21: =C18-C20 -> 21.627019 | D21: =D18-D20 -> 43.253962 | E21: =E18-E20 -> 10.265019 | F21: =F18-F20 -> 0 | G21: =G18-G20 -> 0 | I21: ＝排程 − 瓶頸。當瓶頸>0 時，此值恆等於容量上限
A22: 未被期初 RPO 占用的產能 | B22: US$m | C22: =MAX(0,C16-C18) -> 19.589231 | D22: =MAX(0,D16-D18) -> 134.40004 | E22: =MAX(0,E16-E18) -> 255.99848 | F22: =MAX(0,F16-F18) -> 320.9865 | G22: =MAX(0,G16-G18) -> 369.489 | I22: 容量 − 排程。機房有、期初合約沒占滿 → 要靠新簽約
A23: 新產能簽約率 | B23: % | C23: =IF(輸入與假設!$C$38="mw",1,輸入與假設!C$47) -> 1 | D23: =IF(輸入與假設!$C$38="mw",1,輸入與假設!D$47) -> 1 | E23: =IF(輸入與假設!$C$38="mw",1,輸入與假設!E$47) -> 1 | F23: =IF(輸入與假設!$C$38="mw",1,輸入與假設!F$47) -> 1 | G23: =IF(輸入與假設!$C$38="mw",1,輸入與假設!G$47) -> 1 | I23: MW 驅動時固定 100%
A24: 新簽約收入 | B24: US$m | C24: =C22*C23 -> 19.589231 | D24: =D22*D23 -> 134.40004 | E24: =E22*E23 -> 255.99848 | F24: =F22*F23 -> 320.9865 | G24: =G22*G23 -> 369.489 | I24: 超出期初 RPO 的產能收入（MW 驅動，簽約率 100%）
A25: 未售產能（浪費） | B25: US$m | C25: =MAX(0,C16-C21-C24) -> 0 | D25: =MAX(0,D16-D21-D24) -> 0 | E25: =MAX(0,E16-E21-E24) -> 0 | F25: =MAX(0,F16-F21-F24) -> 0 | G25: =MAX(0,G16-G21-G24) -> 0 | I25: 蓋好但賣不掉（MW 驅動時為 0）
A26: 損益用算力收入（模型期＝RPO 轉換＋新簽約） | B26: US$m | C26: =C21+C24 -> 41.21625 | D26: =D21+D24 -> 177.654 | E26: =E21+E24 -> 266.2635 | F26: =F21+F24 -> 320.9865 | G26: =G21+G24 -> 369.489 | I26: 損益與評價頁的算力收入由此連結，確保現金與損益同一組數字
A27: 核對：算力收入 − 平均在役 MW × 每 MW × 利用率 × 期間 | B27: US$m | C27: =C26-C13*輸入與假設!C$46*輸入與假設!$C$39*輸入與假設!C$45*C7 -> 0 | D27: =D26-D13*輸入與假設!D$46*輸入與假設!$C$39*輸入與假設!D$45*D7 -> 0 | E27: =E26-E13*輸入與假設!E$46*輸入與假設!$C$39*輸入與假設!E$45*E7 -> 0 | F27: =F26-F13*輸入與假設!F$46*輸入與假設!$C$39*輸入與假設!F$45*F7 -> 0 | G27: =G26-G13*輸入與假設!G$46*輸入與假設!$C$39*輸入與假設!G$45*G7 -> 0 | I27: MW 驅動時應為 0：營收可追溯為 MW × 每 MW 年收入 × 利用率（v0.1b）
A28: 對照：評價日起 36 個月營收權重 | B28: % | C28: 1 | D28: 1 | E28: 1 | F28: 0.5 | G28: 0 | I28: RPO 36 個月內轉換的對照用（只作對照，不驅動營收）
A29: 對照：評價日起 36 個月 MW 驅動營收 | B29: US$m | C29: =C26*C28 -> 41.21625 | D29: =D26*D28 -> 177.654 | E29: =E26*E28 -> 266.2635 | F29: =F26*F28 -> 160.49325 | G29: =G26*G28 -> 0 | I29: 合計對照季報 RPO 75.146 × 36 個月內 100%（含託管 RPO）；差額不回推每 MW 單價
A30: 1H26 實際營收（季報，已實現） | B30: US$m | C30: =輸入與假設!$C$301 -> 50.762 | D30: =0 -> 0 | E30: =0 -> 0 | F30: =0 -> 0 | G30: =0 -> 0 | I30: 2026-01-01 至 06-30 已認列營收。已實現，不受下半年產能約束，故不進入上方的瓶頸計算
A31: FY26 全年總營收（1H 實際＋模型期算力＋服務＋託管） | B31: US$m | C31: =C30+C26+輸入與假設!C$50+輸入與假設!C$115 -> 129.87243 | D31: =D30+D26+輸入與假設!D$50+輸入與假設!D$115 -> 278.16958 | E31: =E30+E26+輸入與假設!E$50+輸入與假設!E$115 -> 417.41242 | F31: =F30+F26+輸入與假設!F$50+輸入與假設!F$115 -> 491.92091 | G31: =G30+G26+輸入與假設!G$50+輸入與假設!G$115 -> 544.98474 | I31: FY26 欄對照公司全年指引 不適用（公司未給指引）；FY27 以後即為該年度總營收
A33: ▸ 對照：合約隱含每 MW-IT 年收入 vs Tokenomics（只作對照，不作輸入）
A34: 合約 | B34: 單位 | C34: 合約隱含 | D34: Tokenomics（FY26） | E34: 合約 ÷ Tokenomics | I34: 合約隱含每 MW-IT 年營收 [Derived]：TCV ÷ 年數 ÷（GPU 數 × 每顆 IT kW ÷ 1000），每顆 IT kW 取 Tokenomics v5.26（B300／B200 以 GB300／GB200 近似，HGX 氣冷機實際約低 0–12%，使隱含單價略為低估）；只作對照與敏感度，不作輸入（共同規則第 4 節）
A35: 對照｜合約隱含每 MW｜Baseten（1,392 顆 B300，3 年） | B35: US$m/MW-IT·年 | C35: 19.27 | D35: =輸入與假設!C46*輸入與假設!$C$39 -> 17.4 | E35: =C35/D35 -> 1.1074713 | I35: TCV 165.2 ÷ 3 ÷ 2.858 MW-IT（$4.52／GPU·時）
A36: 對照｜合約隱含每 MW｜Prime Intellect（576 顆 VR200，3 年） | B36: US$m/MW-IT·年 | C36: 18.27 | D36: =輸入與假設!C46*輸入與假設!$C$39 -> 17.4 | E36: =C36/D36 -> 1.05 | I36: TCV 108.2 ÷ 3 ÷ 1.974 MW-IT（$7.15）
A37: 對照｜合約隱含每 MW｜冰島 B300（576 顆，5 年） | B37: US$m/MW-IT·年 | C37: 14.8 | D37: =輸入與假設!C46*輸入與假設!$C$39 -> 17.4 | E37: =C37/D37 -> 0.85057471 | I37: TCV 87.5 ÷ 5 ÷ 1.183 MW-IT（$3.47；另有營收分成）
A38: 對照｜合約隱含每 MW｜128 顆 B300（3 年） | B38: US$m/MW-IT·年 | C38: 20.29 | D38: =輸入與假設!C46*輸入與假設!$C$39 -> 17.4 | E38: =C38/D38 -> 1.166092 | I38: TCV 16.0 ÷ 3 ÷ 0.263 MW-IT（$4.76）
A39: 對照｜合約隱含每 MW｜B200 384 顆（2 年） | B39: US$m/MW-IT·年 | C39: 11.83 | D39: =輸入與假設!C46*輸入與假設!$C$39 -> 17.4 | E39: =C39/D39 -> 0.67988506 | I39: TCV 18.1 ÷ 2 ÷ 0.765 MW-IT
A40: 對照｜合約隱含每 MW｜Prime GB200 216 顆（1 年） | B40: US$m/MW-IT·年 | C40: 15.8 | D40: =輸入與假設!C46*輸入與假設!$C$39 -> 17.4 | E40: =C40/D40 -> 0.90804598 | I40: TCV 6.8 ÷ 0.43 MW-IT
A41: 對照｜合約隱含每 MW｜H100 2,048 顆（2 年；8 卡／台 [Assumed]） | B41: US$m/MW-IT·年 | C41: 8.8 | D41: =輸入與假設!C46*輸入與假設!$C$39 -> 17.4 | E41: =C41/D41 -> 0.50574713 | I41: TCV 50.2 ÷ 2 ÷ 2.852 MW-IT（舊世代）
A42: 對照｜合約隱含每 MW｜新簽 B300／VR200 長約平均（前四筆） | B42: US$m/MW-IT·年 | C42: 18.16 | D42: =輸入與假設!C46*輸入與假設!$C$39 -> 17.4 | E42: =C42/D42 -> 1.0436782 | I42: Baseten、Prime VR200、冰島 B300、128 顆 B300 簡單平均 [Derived]
...

Sheet 運營_站點
A1: 站點租賃 — 公司揭露 vs 季報總額（檢驗租金路徑用）
A2: 季報不揭露逐站租金；下表為具名站點（company.json → defaults.sites），有租約金額者用來檢驗『每 MW 年租金』與模型租金路徑是否一致
A4: 站點 | B4: 營運方 | C4: 契約 MW | D4: 已驗收 MW | E4: 合約總值 $m | F4: 年期 | G4: 年租金 $m | H4: 每 MW 年租金 $m | I4: 時程 | J4: 季報對應 | K4: 說明
A5: 冰島 Blönduós（第三方機房） | B5: 承租容量（雲端） | C5: 5.5 | D5: 5.5 | E5: 未揭露 | F5: 未揭露 | I5: 營運中 | J5: — | K5: 10-Q：已簽 5.5 MW-IT（6 毛 MW）；目前雲端營收主要來自冰島 [Interested-party]
A6: 安大略第三方機房（Baseten） | B6: 第三方機房、WhiteFiber GPU | C6: 2.858 | D6: 0 | E6: 未揭露 | F6: 未揭露 | I6: 2026-11 | J6: — | K6: 1,392 顆 B300 依 Tokenomics 換算 2.858 MW-IT；MW 未揭露 [Derived]
A7: 巴黎第三方機房 | B7: 第三方機房、專案層級融資（未完成） | C7: 1.84 | D7: 0 | E7: 未揭露 | F7: 未揭露 | I7: 2026-09-30 | J7: — | K7: GPU 數與 MW 未揭露；年額 >32 ÷ 17.40 推得 1.84 MW-IT [Derived]
A8: 雪梨第三方機房 | B8: 承租（WhiteFiber, Inc. 保證） | C8: 2.5 | D8: 0 | E8: 未揭露 | F8: 未揭露 | I8: 2026 Q4 | J8: — | K8: 10-Q：2.5 MW-IT、59 個月租約；客戶未揭露 [Interested-party]
A9: 加拿大（Prime Intellect VR200） | B9: 第三方機房 | C9: 1.974 | D9: 0 | E9: 未揭露 | F9: 未揭露 | I9: 2027 Q2 | J9: — | K9: 576 顆 VR200 依 Tokenomics 換算 1.974 MW-IT [Derived]
A10: 具名站點合計 | C10: =SUM(C5:C9) -> 14.672 | D10: =SUM(D5:D9) -> 5.5 | E10: =SUM(E5:E9) -> 0 | G10: =SUM(G5:G9) -> 0 | H10: =IF(I10>0,G10/I10,0) -> 0 | I10: =SUMPRODUCT(ISNUMBER(G5:G9)*C5:C9) -> 0 | K10: 加權每 MW 年租金＝具名站點的市場基準（I 欄＝有租約金額站點的契約 MW；沒有時為 0，不適用）
A12: 對帳：具名站點 vs 季報租賃承諾總額
A13: 季報在帳租賃（未折現，已起租） | E13: 20.435 | K13: company.json → leases.facts.onBal
A14: 季報未起租租賃（未折現） | E14: 20.296 | K14: company.json → leases.facts.notCommenced
A15: 季報單站按造價計租上限 | E15: 0 | K15: company.json → leases.facts.singleCap（無則 0）
A16: 季報已揭露租賃承諾合計 | E16: =SUM(E13:E15) -> 40.731 | K16: 未折現金額
A17: 減：具名站點合約總值 | E17: =-E10 -> 0
A18: ＝ 未具名站點（殘差） | E18: =E16+E17 -> 40.731 | K18: 未具名站點；公司不揭露逐站租金，殘差大是必然
A19: 殘差占季報總額 | E19: =IF(E16<>0,E18/E16,0) -> 1
A21: 檢驗：模型租金路徑 ÷ 在役 MW vs 市場基準
A22: 項目 | B22: 單位 | C22: FY26 | D22: FY27 | E22: FY28 | F22: FY29 | G22: FY30
A23: 模型租金（在帳＋表外） | B23: US$m | C23: =各期收支!C17 -> 11.817085 | D23: =各期收支!D17 -> 46.250479 | E23: =各期收支!E17 -> 57.48796 | F23: =各期收支!F17 -> 72.011644 | G23: =各期收支!G17 -> 84.180508
A24: 平均在役 MW（已連網） | B24: MW | C24: =(輸入與假設!C$160+輸入與假設!C$43)/2 -> 10.037 | D24: =(輸入與假設!D$160+輸入與假設!D$43)/2 -> 15.561 | E24: =(輸入與假設!E$160+輸入與假設!E$43)/2 -> 18.048 | F24: =(輸入與假設!F$160+輸入與假設!F$43)/2 -> 21.048 | G24: =(輸入與假設!G$160+輸入與假設!G$43)/2 -> 24.048
A25: 模型期長度（年） | B25: 年 | C25: =輸入與假設!C$41 -> 0.5 | D25: =輸入與假設!D$41 -> 1 | E25: =輸入與假設!E$41 -> 1 | F25: =輸入與假設!F$41 -> 1 | G25: =輸入與假設!G$41 -> 1
A26: 模型每 MW 年租金 | B26: US$m/MW | C26: =C23/C25/C24 -> 2.3547046 | D26: =D23/D25/D24 -> 2.9722048 | E26: =E23/E25/E24 -> 3.1852815 | F26: =F23/F25/F24 -> 3.4213058 | G26: =G23/G25/G24 -> 3.5005201 | K26: FY26 欄只含下半年租金、MW 取全期平均，略有低估
A27: 第三方租賃占比 | C27: 1 | K27: 其餘為自建，成本走 CapEx（company.json → leases.facts.share）[Assumed]
A28: 基準租金（MW×市場基準×占比） | B28: US$m | C28: =C24*運營_站點!$H$10*$C$27*C25 -> 0 | D28: =D24*運營_站點!$H$10*$C$27*D25 -> 0 | E28: =E24*運營_站點!$H$10*$C$27*E25 -> 0 | F28: =F24*運營_站點!$H$10*$C$27*F25 -> 0 | G28: =G24*運營_站點!$H$10*$C$27*G25 -> 0 | K28: 具名站點有租約金額時才有意義；否則為 0
A29: 差額（基準 − 模型） | B29: US$m | C29: =C28-C23 -> -11.817085 | D29: =D28-D23 -> -46.250479 | E29: =E28-E23 -> -57.48796 | F29: =F28-F23 -> -72.011644 | G29: =G28-G23 -> -84.180508 | K29: 正值＝模型租金可能低估的金額
A30: 五期差額合計 | C30: =SUM(C29:G29) -> -271.74768

Sheet 資產負債_既有債務
A1: 債務明細 — 季報（2026-06-30）逐筆＋存量利息推導
A2: 有效利率為現金票息口徑（可轉債＝票息 ÷ 到期累積倍數，本金以到期累積本金計）。本頁算出的存量利息連回『輸入』頁，再進入支出與資金頁
A4: 工具 | B4: 類別 | C4: 到期 | D4: 有效利率 | E4: 6/30 本金 | F4: 年化利息 | I4: 備註
A5: Bit Digital DDTL（含 B. Riley 持有票據） | B5: 擔保（NC-1 Topco 股權） | C5: 2027-03 | D5: 0.095 | E5: 80 | F5: =D5*E5 -> 7.6 | I5: 已動用 80（6/30 50＋7/27、7/31 共 30）；票面 9.5%（NC-1 完工且 ≥80% 出租後 8.0%）；另有 1.1× MOIC，以 debt.extraCost 加付計入融資成本；到期假設 2027-03（可動用期 9 個月，由 NC-1 專案融資或再融資償還）[Interested-party／Assumed]
A6: Landsbankinn 冰島擔保定期貸款 | B6: 擔保（冰島子公司股權與 GPU） | C6: 2028-06 | D6: 0.0792 | E6: 18 | F6: =D6*E6 -> 1.4256 | I6: SOFR＋4.25%（6/30 票面 7.92%、有效 10.64%）；2 年、季攤還（流動 9.0）[Interested-party]
A7: RBC 聯貸（Enovum，不可循環） | B7: 擔保（MTL-2／MTL-3 不動產） | C7: 2029-07 | D7: 0.055 | E7: 26.2 | F7: =D7*E7 -> 1.441 | I7: 2026-07-15 動用 CAD 36.8（10-Q 換算 USD 26.2；匯率依 10-Q 附註 19）並全額再融資 RBC 17.339；首次動用起 3 年、15 年攤還季付；利率 CORRA＋2.45%＋CSA，以 5.5% 計 [Interested-party／Assumed 區間 5.0–6.5%]
A8: 合計（6/30） | E8: =SUM(E5:E7) -> 124.2 | F8: =SUM(F5:F7) -> 10.4666 | I8: 應等於最新季報本金合計 315.339（company.json → latestQuarter.debtPrincipal）
A9: 加權有效利率 | D9: =F8/E8 -> 0.084272142 | I9: ＝年化利息 ÷ 本金（company.json → debt.instruments 的有效利率）
A11: 評價日後新發可轉債 | D11: 0 | E11: 0 | F11: =D11*E11 -> 0 | I11: company.json → debt.convertible（期後新發；不在五期還本表內，只計利息）
A13: 可轉債逐檔（若轉換法：有效轉換價 < 判斷價 → 視為轉股，不計利息與還本）
A14: 可轉債 | B14: 到期 | C14: 票息 | D14: 原始本金 | E14: 到期累積倍數 | F14: 轉換價 | G14: 到期所屬模型期 | H14: 強制轉換（1＝是） | I14: 備註
A15: 4.50% 2031 可轉債（交換後剩餘） | B15: 2031-02 | C15: 0.045 | D15: 31.85 | E15: 1 | F15: 25.91 | G15: 5 | H15: 0 | I15: 原始 230（2026-01）；2026-08 以現金約 118.5＋約 6.3M 股交換 198.15，剩 31.85；轉換價 25.91（38.5981 股／千元）；2029-02 起可賣回／可贖回 [Interested-party]
A16: 5.00% 2032 可轉債（2026-08） | B16: 2032-09 | C16: 0.05 | D16: 310 | E16: 1 | F16: 33.84 | G16: 5 | H16: 0 | I16: 310（含超額配售 40）；轉換價 33.84（29.5530 股／千元，9.161M 股）；2030-09-06 起可賣回／可贖回；無上限買權（8-K 與新聞稿未提）；淨收入 298.5 [Interested-party 8-K]
I17: 到期所屬模型期：0＝首期 … 4＝末期、5＝模型期後（建置時依期末日推算）
A19: 可轉債（推導） | C19: 到期本金 | D19: 若轉換股數 | E19: 有效轉換價 | F19: 融資分類 | G19: 評價第一輪 | H19: 評價第二輪 | I19: 說明
A20: =A15 -> 4.50% 2031 可轉債（交換後剩餘） | C20: =D15*E15 -> 31.85 | D20: =D15/F15 -> 1.2292551 | E20: =F15*E15 -> 25.91 | F20: =IF(OR(H15=1,E20<輸入與假設!$C$205),1,0) -> 0 | G20: =IF(OR(H15=1,E20<輸入與假設!$C$228),1,0) -> 0 | H20: =IF(OR(H15=1,E20<評價_DCF與目標價!$C$66),1,0) -> 0
A21: =A16 -> 5.00% 2032 可轉債（2026-08） | C21: =D16*E16 -> 310 | D21: =D16/F16 -> 9.1607565 | E21: =F16*E16 -> 33.84 | F21: =IF(OR(H16=1,E21<輸入與假設!$C$205),1,0) -> 0 | G21: =IF(OR(H16=1,E21<輸入與假設!$C$228),1,0) -> 0 | H21: =IF(OR(H16=1,E21<評價_DCF與目標價!$C$66),1,0) -> 0
A22: 合計 | C22: =SUM(C20:C21) -> 341.85 | D22: =SUM(D20:D21) -> 10.390012 | I22: 分類 1＝轉股（若轉換法）、0＝債務。強制轉換者一律為 1。融資分類判斷價＝股權發行價；評價第一輪＝現價；第二輪＝MIN(現價, 第一輪加權目標價)
A24: 存量利息推導（本金依季報到期表遞減）
A25: 項目 | B25: 單位 | C25: FY26 | D25: FY27 | E25: FY28 | F25: FY29 | G25: FY30 | I25: 公式／來源說明
A26: 期初本金 | B26: US$m | C26: =E8 -> 124.2 | D26: =C28 -> 118.827 | E26: =D28 -> 28.08 | F26: =E28 -> 21.833 | G26: =F28 -> 0.874 | I26: FY26 期初為 6/30 本金（模型期起點）
A27: 排程還本 | B27: US$m | C27: =輸入與假設!C$223 -> 5.373 | D27: =輸入與假設!D$223 -> 90.747 | E27: =輸入與假設!E$223 -> 6.247 | F27: =輸入與假設!F$223 -> 20.959 | G27: =輸入與假設!G$223 -> 0 | I27: 季報到期表
A28: 期末本金 | B28: US$m | C28: =C26-C27 -> 118.827 | D28: =D26-D27 -> 28.08 | E28: =E26-E27 -> 21.833 | F28: =F26-F27 -> 0.874 | G28: =G26-G27 -> 0.874
A29: 平均本金 | B29: US$m | C29: =(C26+C28)/2 -> 121.5135 | D29: =(D26+D28)/2 -> 73.4535 | E29: =(E26+E28)/2 -> 24.9565 | F29: =(F26+F28)/2 -> 11.3535 | G29: =(G26+G28)/2 -> 0.874
A30: 存量債務利息 | B30: US$m | C30: =C29*資產負債_既有債務!$D$9*輸入與假設!C$41 -> 5.1201014 | D30: =D29*資產負債_既有債務!$D$9*輸入與假設!D$41 -> 6.1900838 | E30: =E29*資產負債_既有債務!$D$9*輸入與假設!E$41 -> 2.1031377 | F30: =F29*資產負債_既有債務!$D$9*輸入與假設!F$41 -> 0.95678376 | G30: =G29*資產負債_既有債務!$D$9*輸入與假設!G$41 -> 0.073653852 | I30: ＝平均本金×加權有效利率×期間長度。限制：假設利率組合不變；可轉債折價攤銷（非現金）不計
A31: 期後新發可轉債利息 | B31: US$m | C31: =資產負債_既有債務!$F$11*輸入與假設!C$41 -> 0 | D31: =資產負債_既有債務!$F$11*輸入與假設!D$41 -> 0 | E31: =資產負債_既有債務!$F$11*輸入與假設!E$41 -> 0 | F31: =資產負債_既有債務!$F$11*輸入與假設!F$41 -> 0 | G31: =資產負債_既有債務!$F$11*輸入與假設!G$41 -> 0
A32: 可轉債到期還本（債務處理） | B32: US$m | C32: =IF(輸入與假設!$C$197=1,SUMPRODUCT((1-資產負債_既有債務!$F$20:$F$21)*資產負債_既有債務!$C$20:$C$21*(資產負債_既有債務!$G$15:$G$16=0)),0) -> 0 | D32: =IF(輸入與假設!$C$197=1,SUMPRODUCT((1-資產負債_既有債務!$F$20:$F$21)*資產負債_既有債務!$C$20:$C$21*(資產負債_既有債務!$G$15:$G$16=1)),0) -> 0 | E32: =IF(輸入與假設!$C$197=1,SUMPRODUCT((1-資產負債_既有債務!$F$20:$F$21)*資產負債_既有債務!$C$20:$C$21*(資產負債_既有債務!$G$15:$G$16=2)),0) -> 0 | F32: =IF(輸入與假設!$C$197=1,SUMPRODUCT((1-資產負債_既有債務!$F$20:$F$21)*資產負債_既有債務!$C$20:$C$21*(資產負債_既有債務!$G$15:$G$16=3)),0) -> 0 | G32: =IF(輸入與假設!$C$197=1,SUMPRODUCT((1-資產負債_既有債務!$F$20:$F$21)*資產負債_既有債務!$C$20:$C$21*(資產負債_既有債務!$G$15:$G$16=4)),0) -> 0 | I32: 融資分類為債務的可轉債，到期當期以到期累積本金現金還本
A33: 可轉債期末餘額（債務處理） | B33: US$m | C33: =IF(輸入與假設!$C$197=1,SUMPRODUCT((1-資產負債_既有債務!$F$20:$F$21)*資產負債_既有債務!$C$20:$C$21*(資產負債_既有債務!$G$15:$G$16>0)),SUMPRODUCT((1-資產負債_既有債務!$F$20:$F$21)*資產負債_既有債務!$C$20:$C$21)) -> 341.85 | D33: =IF(輸入與假設!$C$197=1,SUMPRODUCT((1-資產負債_既有債務!$F$20:$F$21)*資產負債_既有債務!$C$20:$C$21*(資產負債_既有債務!$G$15:$G$16>1)),SUMPRODUCT((1-資產負債_既有債務!$F$20:$F$21)*資產負債_既有債務!$C$20:$C$21)) -> 341.85 | E33: =IF(輸入與假設!$C$197=1,SUMPRODUCT((1-資產負債_既有債務!$F$20:$F$21)*資產負債_既有債務!$C$20:$C$21*(資產負債_既有債務!$G$15:$G$16>2)),SUMPRODUCT((1-資產負債_既有債務!$F$20:$F$21)*資產負債_既有債務!$C$20:$C$21)) -> 341.85 | F33: =IF(輸入與假設!$C$197=1,SUMPRODUCT((1-資產負債_既有債務!$F$20:$F$21)*資產負債_既有債務!$C$20:$C$21*(資產負債_既有債務!$G$15:$G$16>3)),SUMPRODUCT((1-資產負債_既有債務!$F$20:$F$21)*資產負債_既有債務!$C$20:$C$21)) -> 341.85 | G33: =IF(輸入與假設!$C$197=1,SUMPRODUCT((1-資產負債_既有債務!$F$20:$F$21)*資產負債_既有債務!$C$20:$C$21*(資產負債_既有債務!$G$15:$G$16>4)),SUMPRODUCT((1-資產負債_既有債務!$F$20:$F$21)*資產負債_既有債務!$C$20:$C$21)) -> 341.85 | I33: 到期累積本金；關閉攤還時維持全額
A34: 可轉債票息（債務處理） | B34: US$m | C34: =IF(輸入與假設!$C$197=1,SUMPRODUCT((1-資產負債_既有債務!$F$20:$F$21)*資產負債_既有債務!$D$15:$D$16*資產負債_既有債務!$C$15:$C$16*((資產負債_既有債務!$G$15:$G$16>0)+0.5*(資產負債_既有債務!$G$15:$G$16=0))),SUMPRODUCT((1-資產負債_既有債務!$F$20:$F$21)*資產負債_既有債務!$D$15:$D$16*資產負債_既有債務!$C$15:$C$16))*輸入與假設!C$41 -> 8.466625 | D34: =IF(輸入與假設!$C$197=1,SUMPRODUCT((1-資產負債_既有債務!$F$20:$F$21)*資產負債_既有債務!$D$15:$D$16*資產負債_既有債務!$C$15:$C$16*((資產負債_既有債務!$G$15:$G$16>1)+0.5*(資產負債_既有債務!$G$15:$G$16=1))),SUMPRODUCT((1-資產負債_既有債務!$F$20:$F$21)*資產負債_既有債務!$D$15:$D$16*資產負債_既有債務!$C$15:$C$16))*輸入與假設!D$41 -> 16.93325 | E34: =IF(輸入與假設!$C$197=1,SUMPRODUCT((1-資產負債_既有債務!$F$20:$F$21)*資產負債_既有債務!$D$15:$D$16*資產負債_既有債務!$C$15:$C$16*((資產負債_既有債務!$G$15:$G$16>2)+0.5*(資產負債_既有債務!$G$15:$G$16=2))),SUMPRODUCT((1-資產負債_既有債務!$F$20:$F$21)*資產負債_既有債務!$D$15:$D$16*資產負債_既有債務!$C$15:$C$16))*輸入與假設!E$41 -> 16.93325 | F34: =IF(輸入與假設!$C$197=1,SUMPRODUCT((1-資產負債_既有債務!$F$20:$F$21)*資產負債_既有債務!$D$15:$D$16*資產負債_既有債務!$C$15:$C$16*((資產負債_既有債務!$G$15:$G$16>3)+0.5*(資產負債_既有債務!$G$15:$G$16=3))),SUMPRODUCT((1-資產負債_既有債務!$F$20:$F$21)*資產負債_既有債務!$D$15:$D$16*資產負債_既有債務!$C$15:$C$16))*輸入與假設!F$41 -> 16.93325 | G34: =IF(輸入與假設!$C$197=1,SUMPRODUCT((1-資產負債_既有債務!$F$20:$F$21)*資產負債_既有債務!$D$15:$D$16*資產負債_既有債務!$C$15:$C$16*((資產負債_既有債務!$G$15:$G$16>4)+0.5*(資產負債_既有債務!$G$15:$G$16=4))),SUMPRODUCT((1-資產負債_既有債務!$F$20:$F$21)*資產負債_既有債務!$D$15:$D$16*資產負債_既有債務!$C$15:$C$16))*輸入與假設!G$41 -> 16.93325 | I34: ＝原始本金 × 票息 × 期間長度；到期當期計半期
A35: FY26 新增借款利息校準 | B35: US$m | C35: =0 -> 0 | D35: =0 -> 0 | E35: =0 -> 0 | F35: =0 -> 0 | G35: =0 -> 0 | I35: 讓首期模型利息對上公司季度利息指引的校準值（company.json → defaults.intCal）；無指引時為 0
A36: 額外融資成本｜DDTL 1.1× MOIC 到期加付 | B36: US$m | C36: =0 -> 0 | D36: =1.9 -> 1.9 | E36: =0 -> 0 | F36: =0 -> 0 | G36: =0 -> 0 | I36: MOIC：到期時貸方累計收款至少為本金 1.1 倍＝8.0；評價日後至假設到期 2027-03 的票息約 6.1（50 × 9.5% × 0.75 年＋30 × 9.5% × 約 0.67 年）→ 到期加付約 1.9，列為 FY27 融資成本（非經常利息；審查留言第 2 條）[Derived]；WACC 稅前債務成本仍 9.5%
A37: 存量利息合計（連回輸入頁） | B37: US$m | C37: =C30+C31+C34+C35+C36+C45 -> 13.586726 | D37: =D30+D31+D34+D35+D36+D45 -> 51.128959 | E37: =E30+E31+E34+E35+E36+E45 -> 43.836731 | F37: =F30+F31+F34+F35+F36+F45 -> 40.079815 | G37: =G30+G31+G34+G35+G36+G45 -> 36.586123 | I37: ＝存量債務利息＋期後新發可轉債利息＋可轉債票息＋首期校準＋額外融資成本＋NC-1 專案貸款利息（v0.1c）
A39: NC-1 專案貸款（排程：動用期期初一次動用 × 自有利率 × 次期起直線攤還；WhiteFiber v0.1c）
A40: 項目 | B40: 單位 | C40: FY26 | D40: FY27 | E40: FY28 | F40: FY29 | G40: FY30 | I40: 公式／來源說明
A41: 專案貸款期初餘額 | B41: US$m | C41: =0 -> 0 | D41: =C44 -> 0 | E41: =D44 -> 307.125 | F41: =E44 -> 276.4125 | G41: =F44 -> 245.7
A42: 專案貸款動用 | B42: US$m | C42: =IF(輸入與假設!$C$194=0,輸入與假設!$C$193,0) -> 0 | D42: =IF(輸入與假設!$C$194=1,輸入與假設!$C$193,0) -> 307.125 | E42: =IF(輸入與假設!$C$194=2,輸入與假設!$C$193,0) -> 0 | F42: =IF(輸入與假設!$C$194=3,輸入與假設!$C$193,0) -> 0 | G42: =IF(輸入與假設!$C$194=4,輸入與假設!$C$193,0) -> 0 | I42: ＝NC-1 專案貸款金額（『輸入與假設』E 區），於動用期期初一次到位
A43: 專案貸款攤還 | B43: US$m | C43: =IF(輸入與假設!$C$194<0,MIN(C41,輸入與假設!$C$193/輸入與假設!$C$196*輸入與假設!C$41),0) -> 0 | D43: =IF(輸入與假設!$C$194<1,MIN(D41,輸入與假設!$C$193/輸入與假設!$C$196*輸入與假設!D$41),0) -> 0 | E43: =IF(輸入與假設!$C$194<2,MIN(E41,輸入與假設!$C$193/輸入與假設!$C$196*輸入與假設!E$41),0) -> 30.7125 | F43: =IF(輸入與假設!$C$194<3,MIN(F41,輸入與假設!$C$193/輸入與假設!$C$196*輸入與假設!F$41),0) -> 30.7125 | G43: =IF(輸入與假設!$C$194<4,MIN(G41,輸入與假設!$C$193/輸入與假設!$C$196*輸入與假設!G$41),0) -> 30.7125 | I43: ＝金額 ÷ 攤還年數 × 期間長度（動用次期起；不超過期初餘額）
A44: 專案貸款期末餘額 | B44: US$m | C44: =C41+C42-C43 -> 0 | D44: =D41+D42-D43 -> 307.125 | E44: =E41+E42-E43 -> 276.4125 | F44: =F41+F42-F43 -> 245.7 | G44: =G41+G42-G43 -> 214.9875
A45: 專案貸款利息 | B45: US$m | C45: =輸入與假設!$C$195*(C41+C42+C44)/2*輸入與假設!C$41 -> 0 | D45: =輸入與假設!$C$195*(D41+D42+D44)/2*輸入與假設!D$41 -> 26.105625 | E45: =輸入與假設!$C$195*(E41+E42+E44)/2*輸入與假設!E$41 -> 24.800344 | F45: =輸入與假設!$C$195*(F41+F42+F44)/2*輸入與假設!F$41 -> 22.189781 | G45: =輸入與假設!$C$195*(G41+G42+G44)/2*輸入與假設!G$41 -> 19.579219 | I45: ＝利率 ×(期初＋動用＋期末)÷ 2 × 期間長度（動用當期全期計息）；併入存量利息合計

Sheet 資產負債_新債與新股
A1: 新債與新股（類資產負債表：現金、債務、股本、槓桿）
A2: 全部為連結公式。FY26 欄的現金自 2026-06-30 起算（模型期），與 HTML『資產與負債 → 新債與新股』同口徑
A4: 項目 | B4: 單位 | C4: FY26 | D4: FY27 | E4: FY28 | F4: FY29 | G4: FY30 | I4: 公式／來源說明
A5: 現金
A6: 期初現金 | B6: US$m | C6: =輸入與假設!$C$185 -> 56.056 | D6: =各期收支!C54 -> 136.21658 | E6: =各期收支!D54 -> 30 | F6: =各期收支!E54 -> 30 | G6: =各期收支!F54 -> 30 | I6: FY26＝6/30 現金（模型期起點）
