Workbook

Sheet 導覽
A1: CoreWeave 收支與評價模型 — Excel 版 v4.6（更新 2026-09-25；與 HTML v4.6 同步；市價截至 2026-09-24 收盤）
A3: 這個活頁簿在回答什麼
A4: 一句話：CoreWeave 手上 $103.7bn 的合約（RPO）在 2030 年前能變成多少現金，而同一段時間要付出多少現金——
A5: 差額就是必須向外籌措的金額。所有分頁用同一組數字，改任何一個輸入，後面全部會跟著動。
A7: 分頁結構（依模組分組，分頁標籤顏色相同者為同一模組）
A8: 摘要 一頁摘要：結論、與市場共識的差異、現價隱含什麼、驗證點（v4.3；全部活公式）。
A9: 輸入與假設 所有可調參數（A 情境 → B 產能與收入 → C 利潤率 → D 支出 → E 融資 → F 評價 → G 1H 實際 → H 情境區間運算表 → I 市場共識 → J 季度追蹤輸入）。
A10: 各期收支 類現金流量：來源、用途、融資前缺口、期前融資瀑布。
A11: 季度追蹤 焦點季的模型／共識／指引／實際與差距（v4.4；由年度模型拆分，只用於追蹤；實際數填在輸入與假設 J 區）。
A12: 運營_產能與收入 合約排程 vs 機房產能 → 收入 → 現金；運營_站點：房東揭露與租金檢驗。
A13: 資產負債_既有債務／新債與新股／租賃承諾 類資產負債表：10-Q 債務明細、每期現金與總債務與股數、租賃承諾。
A14: 損益 類損益表（FY26＝1H 實際＋下半年模型）。
... A83: 舊版的透支利息（借款利息）與扣 NTM 缺口（借款本金）並非重複計費；v2.0 的差別是新債設上限、超出部分改以股權支應。瀑布位於「支出與資金」頁下方。

Sheet 摘要
A1: 一頁摘要 — 結論、與市場的差異、現價隱含什麼、驗證點（全部依輸入連動）
A2: ="模型端＝目前情境：" & CHOOSE(輸入與假設!$C$5,"保守 4.2 GW","基準 5.6 GW","積極 8 GW") & "（預設＝基準）；共識＝data/consensus_crwv_20260925.json（2026-09-25）" -> 模型端＝目前情境：基準 5.6 GW（預設＝基準）；共識＝data/consensus_crwv_20260925.json（2026-09-25）
A4: 1｜結論
A5: 結論｜評等代碼（1＝買進、0＝中立、−1＝賣出） | C5: =評價_DCF與目標價!C57 -> -1
A6: 結論｜評等 | C6: =CHOOSE(C5+2,"賣出","中立","買進") -> 賣出
A7: 結論｜點位（加權目標價） | B7: US$ | C7: =評價_DCF與目標價!C48 -> 29.678472
A8: 結論｜現價 | B8: US$ | C8: =輸入與假設!$C$165 -> 90.13
A9: 結論｜空間 | B9: % | C9: =C7/C8-1 -> -0.67071483
A10: 結論｜情境區間（下緣／上緣） | B10: US$ | C10: =評價_DCF與目標價!C62 -> 19.94892 | D10: =評價_DCF與目標價!D62 -> 43.992773
A11: 結論｜方法區間（下緣／上緣） | B11: US$ | C11: =評價_DCF與目標價!C64 -> 15.210032 | D11: =評價_DCF與目標價!D64 -> 29.678472
A12: 結論｜賣出門檻價 | B12: US$ | C12: =評價_DCF與目標價!$C$58 -> 76.6105
A13: 結論｜點位 − 賣出門檻 | B13: US$ | C13: =C7-C12 -> -46.932028
A14: 結論｜結論句 | C14: =C6&"：點位 $"&TEXT(C7,"0.0")&"，較現價 $"&TEXT(C8,"0.00")&" "&IF(C9>=0,"高","低")&" "&TEXT(ABS(C9)*100,"0")&"%；情境區間 $"&TEXT(C10,"0.0")&"–$"&TEXT(D10,"0.0")&"，方法區間 $"&TEXT(C11,"0.0")&"–$"&TEXT(D11,"0.0")&"；點位"&IF(C13<0,"低於","高於")&"賣出門檻 $"&TEXT(C12,"0.0")&" 達 $"&TEXT(ABS(C13),"0.0")&"。" -> 賣出：點位 $29.7，較現價 $90.13 低 67%；情境區間 $19.9–$44.0，方法區間 $15.2–$29.7；點位低於賣出門檻 $76.6 達 $46.9。
A15: 結論｜情境判斷句 | C15: =評價_DCF與目標價!C70 -> 情境區間上緣 $44.0 低於現價 $90.13：賣出在三個擴張情境下都成立。
A16: 結論｜每 MW 經濟性句 | C16: ="每 MW（FY27）：年收入 $"&TEXT(每MW經濟性!D8,"0.0")&"m、現金成本 $"&TEXT(每MW經濟性!D16,"0.0")&"m（含租金 $"&TEXT(每MW經濟性!D15,"0.0")&"m）、EBITDA $"&TEXT(每MW經濟性!D17,"0.0")&"m；計費單價為 Tokenomics 經濟持有成本（含廠房資本回收的打平線）$"&TEXT(每MW經濟性!D83,"0.0")&"m 的 "&TEXT(每MW經濟性!D84,"0.00")&" 倍"&IF(每MW經濟性!D84<1,"，未回收全部持有成本","")&"。" -> 每 MW（FY27）：年收入 $10.6m、現金成本 $4.3m（含租金 $1.6m）、EBITDA $6.2m；計費單價為 Tokenomics 經濟持有成本（含廠房資本回收的打平線）$11.6m 的 0.99 倍，未回收全部持有成本。 | I16: 首個完整財年、目前情境；數字取自『每MW經濟性』彙總表與每 MW 收入對照（持有成本＝Tokenomics IF_HoldEcon 世代加權）
A18: 2｜與市場的差異（模型：目前情境 vs 共識；FY26–FY28）
A19: 項目 | B19: 單位 | C19: FY26 | D19: FY27 | E19: FY28
A20: 差異｜營收｜模型 | B20: US$bn | C20: =損益!C26 -> 13.066 | D20: =損益!D26 -> 26.1275 | E20: =損益!E26 -> 36.669415
A21: 差異｜營收｜共識 | B21: US$bn | C21: =輸入與假設!$C$259 -> 12.882 | D21: =輸入與假設!$D$259 -> 26.376 | E21: =輸入與假設!$E$259 -> 42.55
A22: 差異｜營收｜差距 | B22: % | C22: =C20/C21-1 -> 0.014283496 | D22: =D20/D21-1 -> -0.0094214437 | E22: =E20/E21-1 -> -0.1382041
A23: 差異｜調整後 EBITDA｜模型 | B23: US$bn | C23: =輸入與假設!$C$231+損益!C19 -> 7.5256769 | D23: =損益!D31 -> 15.41514 | E23: =損益!E31 -> 22.104113
A24: 差異｜調整後 EBITDA｜共識 | B24: US$bn | C24: =輸入與假設!$C$260 -> 7.574 | D24: =輸入與假設!$D$260 -> 16.656 | E24: =輸入與假設!$E$260 -> 28.857
A25: 差異｜調整後 EBITDA｜差距 | B25: % | C25: =C23/C24-1 -> -0.0063801233 | D25: =D23/D24-1 -> -0.074499284 | E25: =E23/E24-1 -> -0.23401208 | I25: FY26 模型＝1H 實際調整後 EBITDA（輸入與假設 G 區，報導轉述 [Verified]）＋2H 模型
A26: 差異｜調整後 EBITDA｜差距（金額） | B26: US$bn | C26: =C23-C24 -> -0.048323054 | D26: =D23-D24 -> -1.2408601 | E26: =E23-E24 -> -6.7528866 | I26: 與 HTML 一頁摘要、市場共識分頁同一呈現；判斷門檻仍用上一列比例
A27: 差異｜EBITDA 率｜模型 | B27: % | C27: =C23/C20 -> 0.57597405 | D27: =D23/D20 -> 0.58999674 | E27: =E23/E20 -> 0.60279427
A28: 差異｜EBITDA 率｜共識 | B28: % | C28: =輸入與假設!$C$261 -> 0.588 | D28: =輸入與假設!$D$261 -> 0.632 | E28: =輸入與假設!$E$261 -> 0.678
A29: 差異｜EBITDA 率｜差距（百分點） | B29: pt | C29: =C27-C28 -> -0.012025949 | D29: =D27-D28 -> -0.042003256 | E29: =E27-E28 -> -0.075205733 | I29: EBITDA 率以百分點列差距，不納入判斷
A30: 差異｜CapEx（毛額）｜模型 | B30: US$bn | C30: =輸入與假設!$C$215+輸入與假設!C$137 -> 37.800889 | D30: =輸入與假設!D$137 -> 42.299209 | E30: =輸入與假設!E$137 -> 32.512194
A31: 差異｜CapEx（毛額）｜共識 | B31: US$bn | C31: =輸入與假設!$C$266 -> 35.953 | D31: =輸入與假設!$D$266 -> 46.476 | E31: =輸入與假設!$E$266 -> 50.129
A32: 差異｜CapEx（毛額）｜差距 | B32: % | C32: =C30/C31-1 -> 0.051397347 | D32: =D30/D31-1 -> -0.089869851 | E32: =E30/E31-1 -> -0.35142942 | I32: 共識 CapEx 口徑未揭露；FY26＝1H 實際毛額＋2H 模型毛額
A33: 差異｜淨負債｜模型 | B33: US$bn | C33: =資產負債_新債與新股!C22 -> 46.297792 | D33: =資產負債_新債與新股!D22 -> 77.316635 | E33: =資產負債_新債與新股!E22 -> 94.103031
A34: 差異｜淨負債｜共識 | B34: US$bn | C34: =輸入與假設!$C$268 -> 46.442 | D34: =輸入與假設!$D$268 -> 74.707 | E34: =輸入與假設!$E$268 -> 96.039
A35: 差異｜淨負債｜差距 | B35: % | C35: =C33/C34-1 -> -0.003105125 | D35: =D33/D34-1 -> 0.034931597 | E35: =E33/E34-1 -> -0.020158149 | I35: 共識淨負債不含租賃、口徑未揭露：只列不判斷
A36: 差異｜淨負債｜差距（金額） | B36: US$bn | C36: =C33-C34 -> -0.14420822 | D36: =D33-D34 -> 2.6096348 | E36: =E33-E34 -> -1.9359685 | I36: 與 HTML 一頁摘要、市場共識分頁同一呈現；判斷門檻仍用上一列比例
A37: 差異｜分歧項目（超過門檻者） | C37: =MID(IF(ABS(C22)>輸入與假設!$C$301,"、營收 "&IF(C22<0,"−","+")&TEXT(ABS(C22)*100,"0.0")&"%","")&IF(ABS(C25)>輸入與假設!$C$301,"、EBITDA "&IF(C26<0,"−","+")&"$"&TEXT(ABS(C26),"#,##0.00")&"bn"&"／"&IF(C29<0,"−","+")&TEXT(ABS(C29)*100,"0.0")&"pt","")&IF(ABS(C32)>輸入與假設!$C$301,"、CapEx "&IF(C32<0,"−","+")&TEXT(ABS(C32)*100,"0.0")&"%",""),2,999) -> CapEx +5.1% | D37: =MID(IF(ABS(D22)>輸入與假設!$C$301,"、營收 "&IF(D22<0,"−","+")&TEXT(ABS(D22)*100,"0.0")&"%","")&IF(ABS(D25)>輸入與假設!$C$301,"、EBITDA "&IF(D26<0,"−","+")&"$"&TEXT(ABS(D26),"#,##0.00")&"bn"&"／"&IF(D29<0,"−","+")&TEXT(ABS(D29)*100,"0.0")&"pt","")&IF(ABS(D32)>輸入與假設!$C$301,"、CapEx "&IF(D32<0,"−","+")&TEXT(ABS(D32)*100,"0.0")&"%",""),2,999) -> EBITDA −$1.24bn／−4.2pt、CapEx −9.0% | E37: =MID(IF(ABS(E22)>輸入與假設!$C$301,"、營收 "&IF(E22<0,"−","+")&TEXT(ABS(E22)*100,"0.0")&"%","")&IF(ABS(E25)>輸入與假設!$C$301,"、EBITDA "&IF(E26<0,"−","+")&"$"&TEXT(ABS(E26),"#,##0.00")&"bn"&"／"&IF(E29<0,"−","+")&TEXT(ABS(E29)*100,"0.0")&"pt","")&IF(ABS(E32)>輸入與假設!$C$301,"、CapEx "&IF(E32<0,"−","+")&TEXT(ABS(E32)*100,"0.0")&"%",""),2,999) -> 營收 −13.8%、EBITDA −$6.75bn／−7.5pt、CapEx −35.1% | I37: 營收、EBITDA、CapEx 任一項差距絕對值超過門檻即列出（與 HTML 判斷句同一規則）
A38: 差異｜分歧起始年（1＝FY26…3＝FY28；0＝無） | C38: =IF(C37<>"",1,IF(D37<>"",2,IF(E37<>"",3,0))) -> 1
A39: 差異｜判斷句 | C39: =CHOOSE(C38+1,"FY26–FY28 營收、EBITDA、CapEx 與共識差距皆在 "&IF(ROUND(ABS(輸入與假設!$C$301)*100,4)=INT(ROUND(ABS(輸入與假設!$C$301)*100,4)),TEXT(ROUND(ABS(輸入與假設!$C$301)*100,4),"0"),TEXT(ROUND(ABS(輸入與假設!$C$301)*100,4),"0.0"))&"%"&" 以內。","分歧始於 FY26（"&C37&"）"&"；FY27 "&IF(D37="","回到 "&IF(ROUND(ABS(輸入與假設!$C$301)*100,4)=INT(ROUND(ABS(輸入與假設!$C$301)*100,4)),TEXT(ROUND(ABS(輸入與假設!$C$301)*100,4),"0"),TEXT(ROUND(ABS(輸入與假設!$C$301)*100,4),"0.0"))&"%"&" 以內",D37)&"；FY28 "&IF(E37="","回到 "&IF(ROUND(ABS(輸入與假設!$C$301)*100,4)=INT(ROUND(ABS(輸入與假設!$C$301)*100,4)),TEXT(ROUND(ABS(輸入與假設!$C$301)*100,4),"0"),TEXT(ROUND(ABS(輸入與假設!$C$301)*100,4),"0.0"))&"%"&" 以內",E37)&"。","FY26 營收、EBITDA、CapEx 與共識差距在 "&IF(ROUND(ABS(輸入與假設!$C$301)*100,4)=INT(ROUND(ABS(輸入與假設!$C$301)*100,4)),TEXT(ROUND(ABS(輸入與假設!$C$301)*100,4),"0"),TEXT(ROUND(ABS(輸入與假設!$C$301)*100,4),"0.0"))&"%"&" 以內；分歧始於 FY27（"&D37&"）"&"；FY28 "&IF(E37="","回到 "&IF(ROUND(ABS(輸入與假設!$C$301)*100,4)=INT(ROUND(ABS(輸入與假設!$C$301)*100,4)),TEXT(ROUND(ABS(輸入與假設!$C$301)*100,4),"0"),TEXT(ROUND(ABS(輸入與假設!$C$301)*100,4),"0.0"))&"%"&" 以內",E37)&"。","FY26–FY27 營收、EBITDA、CapEx 與共識差距在 "&IF(ROUND(ABS(輸入與假設!$C$301)*100,4)=INT(ROUND(ABS(輸入與假設!$C$301)*100,4)),TEXT(ROUND(ABS(輸入與假設!$C$301)*100,4),"0"),TEXT(ROUND(ABS(輸入與假設!$C$301)*100,4),"0.0"))&"%"&" 以內；分歧始於 FY28（"&E37&"）。") -> 分歧始於 FY26（CapEx +5.1%）；FY27 EBITDA −$1.24bn／−4.2pt、CapEx −9.0%；FY28 營收 −13.8%、EBITDA −$6.75bn／−7.5pt、CapEx −35.1%。
A40: 差異原因｜FY26｜EBITDA | C40: =IF(ABS(C29)>輸入與假設!$C$302,"觀點","") | D40: =IF(ABS(C29)>輸入與假設!$C$302,"EBITDA 率 "&IF((C27)<0,"−","")&TEXT(ABS((C27))*100,"#,##0.0")&"%"&" 對共識 "&IF((C28)<0,"−","")&TEXT(ABS((C28))*100,"#,##0.0")&"%"&"：模型改為由下而上（Tokenomics 電費與維護 × 平均在役 MW＋管銷率，再扣租金），不含爬坡期閒置產能與未揭露成本；營收差距 "&IF((C22)<0,"−","+")&TEXT(ABS((C22))*100,"#,##0.0")&"%","") | I40: C＝類型、D＝原因（需附原因時顯示；EBITDA 以利潤率差、其餘以比例門檻判斷）
A41: 差異原因｜FY26｜CapEx | C41: =IF(ABS(C32)>輸入與假設!$C$301,"觀點","") -> 觀點 | D41: =IF(ABS(C32)>輸入與假設!$C$301,"CapEx 依新增 MW 計算：新增 "&IF((輸入與假設!C$130)<0,"−","")&TEXT(ABS((輸入與假設!C$130)),"#,##0")&" MW × Tokenomics 每 MW $"&IF((輸入與假設!C$120)<0,"−","")&TEXT(ABS((輸入與假設!C$120)),"#,##0")&"m（IF_CapexIT × 新增世代，含次年預建）；共識口徑未揭露","") -> CapEx 依新增 MW 計算：新增 1,000 MW × Tokenomics 每 MW $35m（IF_CapexIT × 新增世代，含次年預建）；共識口徑未揭露
A42: 差異原因｜FY26｜淨負債 | C42: =IF(ABS(C35)>輸入與假設!$C$301,"觀點","") | D42: =IF(ABS(C35)>輸入與假設!$C$301,"淨負債隨 CapEx 與融資需求而定（模型 CapEx 差距 "&IF((C32)<0,"−","+")&TEXT(ABS((C32))*100,"#,##0.0")&"%"&"）；共識淨負債不含租賃、口徑未揭露","")
...

Sheet 輸入與假設
A1: 輸入（依類別排序；點左側 ＋／− 展開或收合。藍字可改；黃底為最關鍵假設）
A2: A 情境 → B 產能與收入 → C 利潤率 → D 支出（CapEx／折舊／租賃／JV）→ E 融資 → F 評價 → G 參考：1H26 實際 → H 情境區間運算表 → I 市場共識 → J 季度追蹤輸入。灰底『▸』為明細子區，預設收合
A4: A｜情境與規模（管理層擴張力道）
A5: 情境選擇（1＝保守 4.2 GW、2＝基準 5.6 GW、3＝積極 8 GW） | C5: 2 | D5: =CHOOSE(C5,"保守 4.2 GW","基準 5.6 GW","積極 8 GW") -> 基準 5.6 GW | I5: 三情境只改變管理層的擴張力道；其餘假設相同。FY26–FY27 三者相同（年底 1,850／3,100 MW），FY28 起分歧
A6: ▸ 情境路徑明細（Accepted MW、爬坡比例、表外租金基準）
A7: Accepted MW 路徑 | B7: 單位 | C7: FY26 | D7: FY27 | E7: FY28 | F7: FY29 | G7: FY30 | I7: FY31 新增 MW
A8: 保守 4.2 GW | B8: MW | C8: 1850 | D8: 3100 | E8: 3800 | F8: 4200 | G8: 4200 | I8: 0 | J8: 只交付已簽約電力 4.2 GW（8/11 法說），不再新簽
A9: 基準 5.6 GW | B9: MW | C9: 1850 | D9: 3100 | E9: 4000 | F9: 4800 | G9: 5600 | I9: 500 | J9: 2027 年後每年約 +800 MW
A10: 積極 8 GW | B10: MW | C10: 1850 | D10: 3100 | E10: 4600 | F10: 6300 | G10: 8000 | I10: 1000 | J10: 公司目標 2030 ≥8 GW
A11: Billable／Accepted 爬坡比例 | B11: % | C11: 0.91891892 | D11: 0.93548387 | E11: 0.93478261 | F11: 0.93650794 | G11: 0.9375 | I11: 三情境共用
A12: 表外現金租金（積極路徑） | B12: US$bn | C12: 0.3 | D12: 1.6 | E12: 3 | F12: 4 | G12: 4.6 | I12: 其他情境依「新增 MW（相對 6/30 的 1,500 MW）」等比例縮放
A13: 表外租金起算 MW | B13: MW | C13: 1500 | I13: 6/30 主動電力；表外租金依超過此值的新增 MW 等比例縮放（company.json → scenarios.leaseRampFloorMw）
A14: B｜產能與收入（RPO、MW、利用率、單價、簽約、信用）
A15: 6/30 RPO | B15: US$bn | C15: 103.7 | I15: 10-Q 103.7（backlog 104.2 含 0.5 其他）[Verified]
A16: Q3 初新增承諾 | B16: US$bn | C16: 25 | I16: 法說「>25」，尚未入 RPO [Interested-party]
A17: 五期認列比例（至 2030 末） | B17: % | C17: 0.84 | I17: 10-Q 桶 41／39／20 線性分攤後五期合計 84% [Derived]
A18: RPO 桶權重合計 | B18: % | C18: 0.84 | I18: 下方權重列的合計，用於歸一化
A19: 2025-12-31 主動電力 | B19: MW | C19: 850 | I19: Q4 2025 法說：年底 >850 MW、43 座資料中心 [Verified]
A20: 6/30 Billable MW | B20: MW | C20: 1350 | I20: 主動電力 1.5 GW 扣爬坡中 [Assumed]
A21: 收入用平均在役 MW（1=是） | C21: 1 | I21: 0＝用期末存量全期化。CRWV 交付後載（6 月 +300MW），建議 1
A22: 每 MW 年收入倍數（整體） | B22: % | C22: 1 | I22: 反向 DCF 與壓力測試用；預設 100%。以『目標搜尋』調整此格即可反解市價隱含單價
A23: 項目 | B23: 單位 | C23: FY26 | D23: FY27 | E23: FY28 | F23: FY29 | G23: FY30 | I23: 來源／標籤
A24: 模型期長度（年） | C24: 0.5 | D24: 1 | E24: 1 | F24: 1 | G24: 1 | I24: 勿改。FY26 模型期為 2026-07-01～12-31（0.5 年）。只用於容量上限、電力、維護三處年率換算 [Derived]
A25: RPO 桶權重 | B25: % | C25: 0.1025 | D25: 0.205 | E25: 0.2 | F25: 0.195 | G25: 0.1375 | H25: =SUM(C25:G25) -> 0.84 | I25: 10-Q 41%／24m、39%／25-48m、20%／49-78m 桶內線性分攤 [Derived]
A26: Accepted MW（期末主動電力） | B26: MW | C26: =CHOOSE(輸入與假設!$C$5,C8,C9,C10) -> 1850 | D26: =CHOOSE(輸入與假設!$C$5,D8,D9,D10) -> 3100 | E26: =CHOOSE(輸入與假設!$C$5,E8,E9,E10) -> 4000 | F26: =CHOOSE(輸入與假設!$C$5,F8,F9,F10) -> 4800 | G26: =CHOOSE(輸入與假設!$C$5,G8,G9,G10) -> 5600 | I26: ＝依 A 區情境選擇器
A27: Billable MW | B27: MW | C27: =ROUND(C26*C11,0) -> 1700 | D27: =ROUND(D26*D11,0) -> 2900 | E27: =ROUND(E26*E11,0) -> 3739 | F27: =ROUND(F26*F11,0) -> 4495 | G27: =ROUND(G26*G11,0) -> 5250 | I27: ＝Accepted × 爬坡比例（A 區）
A28: 利用率 | B28: % | C28: 0.95 | D28: 0.95 | E28: 0.94 | F28: 0.93 | G28: 0.92 | I28: 法說「近期產能實質售罄」，不擬合 100% [Assumed]
A29: 每 MW 年收入 | B29: US$bn/MW | C29: 0.0112 | D29: 0.0115 | E29: 0.0115 | F29: 0.011 | G29: 0.0105 | I29: 期末 ARR 18.5–19.5÷1.85GW≈10.0–10.5M/MW；7 月漲價 25% 只影響新約 [Derived]
A30: 新產能簽約率 | B30: % | C30: 1 | D30: 1 | E30: 0.9 | F30: 0.85 | G30: 0.8 | I30: 未被期初 RPO 占用的產能能賣掉的比例 [Assumed]
A31: 客戶違約率 | B31: % | C31: 0.005 | D31: 0.01 | E31: 0.015 | F31: 0.02 | G31: 0.025 | I31: 前三大客戶 72% 營收的定價，非預測 [Assumed]
A32: 回收率 | B32: % | C32: 0.5 | D32: 0.5 | E32: 0.5 | F32: 0.5 | G32: 0.5 | I32: [Assumed]
A33: 非算力服務營收 | B33: US$bn | C33: 0.3 | D33: 1 | E33: 1.8 | F33: 2.8 | G33: 3.8 | I33: 軟體／儲存／CPU／managed inference；損益營收與資金現金共用 [Derived]
A35: ▸ 世代組合（W2；公司專屬，世代與 Tokenomics 同名；每 MW 資本支出、成本、收入依此加權）
A36: 每 MW 方法（資本支出／營運成本／收入） | C36: tokenomics／bottomUp／legacy | I36: company.json → methodology.perMw（建置時決定公式）：tokenomics｜legacy、bottomUp｜ebitdaPct、gpuHr｜legacy；全為舊方法時與 v4.5 相同
A37: MW 口徑（1＝IT 關鍵電力、2＝設施） | C37: 1 | I37: company.json → meta.mwBasis。Tokenomics 每 GW＝IT 關鍵電力；設施口徑時 IT MW＝設施 MW ÷ IF_FacilityGW（各 Tokenomics 每 MW 值 × 換算係數）[Assumed，見 W1 第 6a 步]
A38: Tokenomics 成本情境（1＝低成本、2＝基準、3＝高成本） | C38: 2 | I38: 模型主值取基準；低／高只作敏感度（每MW經濟性頁「敏感度」）
A39: 世代組合敏感度（0＝基準、1＝Rubin Ultra 版） | C39: 0 | I39: Rubin Ultra 版（FY29–FY30 新增 100% Rubin Ultra）；只作敏感度
A40: GPU 小時價格情境（1＝低、2＝基準、3＝高） | C40: 2 | I40: 只在 revenue=gpuHr 時影響收入；價格讀 company.json → pricing.gpuHr
A41: 期初在役 MW（2026-06-30，世代組合起點） | B41: MW | C41: 1500 | I41: company.json → fleet.openMix.activeMW（最新已申報季末主動電力）[Verified]
A42: 期初在役占比｜Hopper H100 | B42: % | C42: 0.272667 | I42: [Assumed]；W1 第 6b 步（coreweave/data/permw_inputs_20261007.json → fleetMix.openMix）：依年份分層——2024 年底前 360 MW＝Hopper；2025 年新增 490 MW＝GB200 70%／GB300 20%／H200 10%；2026 上半年新增 650 MW＝GB300 85%／GB200 15%。MW 錨點 [Verified]、各層占比 [Assumed]；W1 回報 27／29／43% 為四捨五入（區間 Hopper 24–31%、GB200 20–42%、GB300 30–53%）
...

Sheet 各期收支
A1: 支出與資金 — 五層支出、四層來源、現金橋
A2: FY26 欄＝1H 實際（10-Q 現金流量表口徑）＋下半年模型；FY27 以後為純模型。瀑布以「融資前現金」決定需求並直接由各支出列加總，因此沒有循環參照
A4: 項目 | B4: 單位 | C4: FY26 | D4: FY27 | E4: FY28 | F4: FY29 | G4: FY30 | I4: 公式／來源說明
A5: 支出（五層）
A6: ① 毛 CapEx（認列，備忘） | B6: US$bn | C6: =輸入與假設!$C$215+輸入與假設!C$137 -> 37.800889 | D6: =輸入與假設!D$137 -> 42.299209 | E6: =輸入與假設!E$137 -> 32.512194 | F6: =輸入與假設!F$137 -> 33.827717 | G6: =輸入與假設!G$137 -> 35.894966 | I6: FY26＝1H 實際認列 16.139＋2H 模型；對照公司全年指引 35–39。備忘列：用途合計採現金口徑，不用這一列
A7: 客戶預付率 | B7: % | C7: =輸入與假設!C$122 -> 0.08 | D7: =輸入與假設!D$122 -> 0.08 | E7: =輸入與假設!E$122 -> 0.08 | F7: =輸入與假設!F$122 -> 0.08 | G7: =輸入與假設!G$122 -> 0.08
A8: 客戶預付金額（抵減，2H 起） | B8: US$bn | C8: =輸入與假設!C$137*C7 -> 1.7329511 | D8: =輸入與假設!D$137*D7 -> 3.3839367 | E8: =輸入與假設!E$137*E7 -> 2.6009756 | F8: =輸入與假設!F$137*F7 -> 2.7062173 | G8: =輸入與假設!G$137*G7 -> 2.8715973 | I8: 1H 的預付已含在實際 CFO 內，不重複計入
A9: ① CapEx（用途用：1H 現金／2H 毛額） | B9: US$bn | C9: =輸入與假設!$C$214+輸入與假設!C$137 -> 35.778889 | D9: =輸入與假設!D$137 -> 42.299209 | E9: =輸入與假設!E$137 -> 32.512194 | F9: =輸入與假設!F$137 -> 33.827717 | G9: =輸入與假設!G$137 -> 35.894966 | I9: 1H 採現金流量表的現金購置 14.117；2H 起採毛額，客戶預付在來源端抵回（避免重複計入）
A10: ② 在帳現金租金（備忘，1H 已含在 CFO） | B10: US$bn | C10: =輸入與假設!C$123 -> 1.04 | D10: =輸入與假設!D$123 -> 2.339 | E10: =輸入與假設!E$123 -> 2.306 | F10: =輸入與假設!F$123 -> 2.373 | G10: =輸入與假設!G$123 -> 2.289 | I10: 見『租賃與承諾』頁；2030 後尚有 19.023。FY26 欄僅 2H：1H 租金 0.748 已含在實際 CFO 內
A11: ② 表外現金租金（未起租） | B11: US$bn | C11: =輸入與假設!C$124 -> 0.3 | D11: =輸入與假設!D$124 -> 1.6 | E11: =輸入與假設!E$124 -> 2.4193548 | F11: =輸入與假設!F$124 -> 2.75 | G11: =輸入與假設!G$124 -> 2.9015385 | I11: 未起租 35.5＋單站上限 14.7＋355MW 造價計租的現金路徑
A12: 租金合計 | B12: US$bn | C12: =C10+C11 -> 1.34 | D12: =D10+D11 -> 3.939 | E12: =E10+E11 -> 4.7253548 | F12: =F10+F11 -> 5.123 | G12: =G10+G11 -> 5.1905385
A13: ③ 存量債務利息（備忘，1H 已含在 CFO） | B13: US$bn | C13: =輸入與假設!C$162 -> 1.8058963 | D13: =輸入與假設!D$162 -> 2.4660068 | E13: =輸入與假設!E$162 -> 2.0200947 | F13: =輸入與假設!F$162 -> 1.7324815 | G13: =輸入與假設!G$162 -> 1.4951385 | I13: ="6/30 債務餘額的利息。FY26 全年利息＝1H 實際 1.176＋2H "&TEXT(C13,"0.0")&"＝"&TEXT(1.176+C13,"0.00")&"（見下方備忘）" -> 6/30 債務餘額的利息。FY26 全年利息＝1H 實際 1.176＋2H 1.8＝2.98（見下方備忘）
A14: 期初累積現金 | B14: US$bn | C14: =輸入與假設!$C$212 -> 3.127 | D14: =C41 -> 2 | E14: =D41 -> 2 | F14: =E41 -> 2 | G14: =F41 -> 2 | I14: FY26 自 2025-12-31 的 3.127 起算；之後＝前期期末累積現金
A15: 新債利率 | B15: % | C15: =IF(輸入與假設!$C$156=1,輸入與假設!C$161+MAX(0,輸入與假設!$C$155-450)/100*0.004,輸入與假設!C$161) -> 0.09 | D15: =IF(輸入與假設!$C$156=1,輸入與假設!D$161+MAX(0,輸入與假設!$C$155-450)/100*0.004,輸入與假設!D$161) -> 0.09 | E15: =IF(輸入與假設!$C$156=1,輸入與假設!E$161+MAX(0,輸入與假設!$C$155-450)/100*0.004,輸入與假設!E$161) -> 0.09 | F15: =IF(輸入與假設!$C$156=1,輸入與假設!F$161+MAX(0,輸入與假設!$C$155-450)/100*0.004,輸入與假設!F$161) -> 0.09 | G15: =IF(輸入與假設!$C$156=1,輸入與假設!G$161+MAX(0,輸入與假設!$C$155-450)/100*0.004,輸入與假設!G$161) -> 0.09 | I15: CDS 開關：＋MAX(0,CDS−450)×0.4bp/bp
A16: ③ 新債利息（瀑布） | B16: US$bn | C16: =C63 -> 0.60569063 | D16: =D63 -> 4.5596371 | E16: =E63 -> 6.4678528 | F16: =F63 -> 7.3610235 | G16: =G63 -> 8.6350905 | I16: ＝新債利率×期間長度×(期初新債＋本期舉借)；見下方「期前融資瀑布」
A17: 利息合計 | B17: US$bn | C17: =C13+C16 -> 2.4115869 | D17: =D13+D16 -> 7.0256439 | E17: =E13+E16 -> 8.4879476 | F17: =F13+F16 -> 9.093505 | G17: =G13+G16 -> 10.130229
A18: ④ JV／策略投資出資 | B18: US$bn | C18: =輸入與假設!$C$216+輸入與假設!C$127 -> 1.938 | D18: =輸入與假設!D$127 -> 0.4 | E18: =輸入與假設!E$127 -> 0.3 | F18: =輸入與假設!F$127 -> 0.2 | G18: =輸入與假設!G$127 -> 0.2 | I18: FY26＝1H 實際 0.688（JV 0.550＋策略投資 0.138）＋2H 模型。10-Q 已承諾 1.7bn。CRWV 不發股息
A19: 電力（overlay） | B19: US$bn | C19: =0 -> 0 | D19: =0 -> 0 | E19: =0 -> 0 | F19: =0 -> 0 | G19: =0 -> 0 | I19: W2 由下而上：電費與維護已含在營運成本，overlay 自動停用（避免重複扣）
A20: 維護（overlay） | B20: US$bn | C20: =0 -> 0 | D20: =0 -> 0 | E20: =0 -> 0 | F20: =0 -> 0 | G20: =0 -> 0
A21: ⑤ 排程還本（10-Q 本金表） | B21: US$bn | C21: =輸入與假設!$C$218+IF(輸入與假設!$C$146=1,輸入與假設!C$160,0) -> 9.632 | D21: =IF(輸入與假設!$C$146=1,輸入與假設!D$160,0) -> 6.184 | E21: =IF(輸入與假設!$C$146=1,輸入與假設!E$160,0) -> 4.416 | F21: =IF(輸入與假設!$C$146=1,輸入與假設!F$160,0) -> 2.421 | G21: =IF(輸入與假設!$C$146=1,輸入與假設!G$160,0) -> 3.221 | I21: FY26＝1H 實際還款 5.219＋2H 到期表 4.413
A22: ⑥ capped call 支出（1H 實際） | B22: US$bn | C22: =輸入與假設!$C$219 -> 0.492 | D22: =0 -> 0 | E22: =0 -> 0 | F22: =0 -> 0 | G22: =0 -> 0 | I22: Q2 4.0bn 可轉債的 capped call 現金支出
A23: 用途合計（現金口徑） | B23: US$bn | C23: =C9+C12+C17+C18+C19+C20+C21+C22 -> 51.592476 | D23: =D9+D12+D17+D18+D19+D20+D21+D22 -> 59.847853 | E23: =E9+E12+E17+E18+E19+E20+E21+E22 -> 50.441497 | F23: =F9+F12+F17+F18+F19+F20+F21+F22 -> 50.665222 | G23: =G9+G12+G17+G18+G19+G20+G21+G22 -> 54.636734 | I23: FY26 的 1H 部分採 10-Q 現金流量表口徑（現金購置、還款、JV、capped call）；1H 的利息與租金已含在 CFO 內，不重複列
A24: 來源（四層）
A25: Ⓐ0 1H26 實際營運現金流（CFO） | B25: US$bn | C25: =輸入與假設!$C$213 -> 3.663 | D25: =0 -> 0 | E25: =0 -> 0 | F25: =0 -> 0 | G25: =0 -> 0 | I25: 10-Q 實際值，取代模型推算；已含 1H 的利息、租金與客戶預付
A26: Ⓐ RPO 現金（2H 起） | B26: US$bn | C26: =運營_產能與收入!C36 -> 5.9626936 | D26: =運營_產能與收入!D36 -> 18.520316 | E26: =運營_產能與收入!E36 -> 18.691628 | F26: =運營_產能與收入!F36 -> 17.726903 | G26: =運營_產能與收入!G36 -> 11.961101
A27: Ⓑ 新簽約現金 | B27: US$bn | C27: =運營_產能與收入!C37 -> 0 | D27: =運營_產能與收入!D37 -> 0 | E27: =運營_產能與收入!E37 -> 6.6295121 | F27: =運營_產能與收入!F37 -> 10.219006 | G27: =運營_產能與收入!G37 -> 15.882354
A28: Ⓒ 非算力服務現金 | B28: US$bn | C28: =輸入與假設!C$88 -> 0.22103923 | D28: =輸入與假設!D$88 -> 0.74075744 | E28: =輸入與假設!E$88 -> 1.3169843 | F28: =輸入與假設!F$88 -> 1.9977565 | G28: =輸入與假設!G$88 -> 2.6009763
A29: Ⓓ 客戶預付（2H 起） | B29: US$bn | C29: =C8 -> 1.7329511 | D29: =D8 -> 3.3839367 | E29: =E8 -> 2.6009756 | F29: =F8 -> 2.7062173 | G29: =G8 -> 2.8715973
A30: 營運來源合計 | B30: US$bn | C30: =C25+C26+C27+C28+C29 -> 11.579684 | D30: =D25+D26+D27+D28+D29 -> 22.64501 | E30: =E25+E26+E27+E28+E29 -> 29.2391 | F30: =F25+F26+F27+F28+F29 -> 32.649884 | G30: =G25+G26+G27+G28+G29 -> 33.316029
A31: Ⓔ 股權／可轉債（融資） | B31: US$bn | C31: =輸入與假設!$C$220+IF(輸入與假設!$C$143=1,輸入與假設!$C$142,0) -> 9.182 | D31: =0 -> 0 | E31: =0 -> 0 | F31: =0 -> 0 | G31: =0 -> 0 | I31: FY26＝1H 私募股權 2.982＋2H 可轉債淨現金 3.2＋ATM 上限 3.0
A32: Ⓕ 1H26 實際借款（融資） | B32: US$bn | C32: =輸入與假設!$C$217 -> 16.747 | D32: =0 -> 0 | E32: =0 -> 0 | F32: =0 -> 0 | G32: =0 -> 0 | I32: 10-Q：H1 借款 16.747。1H 的缺口實際上就是靠舉債填補的
A33: Ⓖ 瀑布：新債（額度＋資產層） | B33: US$bn | C33: =C58 -> 13.459792 | D33: =D58 -> 37.202843 | E33: =E58 -> 21.202397 | F33: =F58 -> 0 | G33: =G58 -> 0.52492452 | I33: 見下方「期前融資瀑布」
A34: Ⓗ 瀑布：股權募資 | B34: US$bn | C34: =C61 -> 0 | D34: =D61 -> 0 | E34: =E61 -> 0 | F34: =F61 -> 10.572249 | G34: =G61 -> 10.572249 | I34: 債務用罄後的殘差；每年不超過股權吸收上限
A35: Ⓘ 瀑布：高息債（股權上限溢出） | B35: US$bn | C35: =C62 -> 0 | D35: =D62 -> 0 | E35: =E62 -> 0 | F35: =F62 -> 7.4430893 | G35: =G62 -> 10.223531 | I35: 股權超過每年上限的部分；不受 backlog 上限約束
A36: 總來源（含融資） | B36: US$bn | C36: =C30+C31+C32+C33+C34+C35 -> 50.968476 | D36: =D30+D31+D32+D33+D34+D35 -> 59.847853 | E36: =E30+E31+E32+E33+E34+E35 -> 50.441497 | F36: =F30+F31+F32+F33+F34+F35 -> 50.665222 | G36: =G30+G31+G32+G33+G34+G35 -> 54.636734
A37: 缺口與現金橋
A38: 1H 其他／受限現金調節 | B38: US$bn | C38: =輸入與假設!$C$141-(輸入與假設!$C$212+輸入與假設!$C$213+輸入與假設!$C$217+輸入與假設!$C$220-輸入與假設!$C$214-輸入與假設!$C$216-輸入與假設!$C$218-輸入與假設!$C$219) -> -0.503 | D38: =0 -> 0 | E38: =0 -> 0 | F38: =0 -> 0 | G38: =0 -> 0 | I38: 使 1H 實際流量接回 6/30 現金餘額；差額來自受限現金重分類與未逐項列出的項目
A39: 營運缺口（不含融資、不含還本） | B39: US$bn | C39: =C30-(C23-C21-C22) -> -29.888792 | D39: =D30-(D23-D21-D22) -> -31.018843 | E39: =E30-(E23-E21-E22) -> -16.786397 | F39: =F30-(F23-F21-F22) -> -15.594338 | G39: =G30-(G23-G21-G22) -> -18.099705 | I39: 本業能不能自給：營運來源 −（用途 − 排程還本 − capped call）
A40: 期間缺口（含融資） | B40: US$bn | C40: =C36-C23+C38 -> -1.127 | D40: =D36-D23+D38 -> 0 | E40: =E36-E23+E38 -> 0 | F40: =F36-F23+F38 -> 0 | G40: =G36-G23+G38 -> 0
A41: 期末累積現金 | B41: US$bn | C41: =C14+C40 -> 2 | D41: =D14+D40 -> 2 | E41: =E14+E40 -> 2 | F41: =F14+F40 -> 2 | G41: =G14+G40 -> 2 | I41: 期前融資：每期末不低於最低現金
...

Sheet 季度追蹤
A1: 季度追蹤 — 焦點季的模型／共識／指引／實際與差距（由年度模型拆分；只用於追蹤，不影響年度數字與目標價）
A2: 設定與實際數在『輸入與假設』J 區，共識在 I 區；缺資料顯示「不適用」，實際數空白＝待公布。差距超過門檻的項目附差異原因（拆法＝所屬期間合計差距在門檻內）。第 2 區為 6 季路徑與拆分明細（預設收合）。
A4: 1｜焦點季（『輸入與假設』J 區選擇）：模型／共識／指引／實際與差距
A5: 指標 | B5: 單位 | C5: 模型 | D5: 共識 | E5: 模型 vs 共識 | F5: 指引（低） | G5: 指引（高） | H5: 模型 vs 指引中點 | I5: 實際 | J5: 實際 vs 模型 | K5: 實際 vs 共識 | L5: 實際 vs 指引中點 | M5: 利潤率 pt：模型 vs 共識 | N5: 模型 vs 指引 | O5: 實際 vs 模型 | P5: 實際 vs 共識 | Q5: 實際 vs 指引
A6: 焦點｜營收 | B6: US$bn | C6: =INDEX($C$22:$H$22,輸入與假設!$C$307) -> 3.6626667 | D6: =INDEX($C$41:$H$41,輸入與假設!$C$307) -> 3.541 | E6: =INDEX($C$51:$H$51,輸入與假設!$C$307) -> 0.034359409 | F6: =IF(ISNUMBER(INDEX($C$31:$H$31,輸入與假設!$C$307)),INDEX($C$31:$H$31,輸入與假設!$C$307),"不適用") -> 3.45 | G6: =INDEX($C$32:$H$32,輸入與假設!$C$307) -> 3.6 | H6: =INDEX($C$52:$H$52,輸入與假設!$C$307) -> 0.039054374 | I6: =IF(ISNUMBER(INDEX($C$45:$H$45,輸入與假設!$C$307)),INDEX($C$45:$H$45,輸入與假設!$C$307),"待公布") -> 待公布 | J6: =INDEX($C$53:$H$53,輸入與假設!$C$307) | K6: =INDEX($C$54:$H$54,輸入與假設!$C$307) | L6: =INDEX($C$55:$H$55,輸入與假設!$C$307)
A7: 焦點｜調整後 EBITDA | B7: US$bn | C7: =INDEX($C$28:$H$28,輸入與假設!$C$307) -> 2.106936 | D7: =INDEX($C$42:$H$42,輸入與假設!$C$307) -> 2.047 | E7: =INDEX($C$56:$H$56,輸入與假設!$C$307) -> 0.059935989 | F7: 不適用 | G7: 不適用 | H7: =INDEX($C$57:$H$57,輸入與假設!$C$307) -> 不適用 | I7: =IF(ISNUMBER(INDEX($C$46:$H$46,輸入與假設!$C$307)),INDEX($C$46:$H$46,輸入與假設!$C$307),"待公布") -> 待公布 | J7: =INDEX($C$58:$H$58,輸入與假設!$C$307) | K7: =INDEX($C$59:$H$59,輸入與假設!$C$307) | L7: =INDEX($C$60:$H$60,輸入與假設!$C$307) | M7: =INDEX($C$61:$H$61,輸入與假設!$C$307) -> -0.0028388388 | N7: =INDEX($C$62:$H$62,輸入與假設!$C$307) -> 不適用 | O7: =INDEX($C$63:$H$63,輸入與假設!$C$307) | P7: =INDEX($C$64:$H$64,輸入與假設!$C$307) | Q7: =INDEX($C$65:$H$65,輸入與假設!$C$307)
A8: 焦點｜EBITDA 率 | B8: % | C8: =INDEX($C$27:$H$27,輸入與假設!$C$307) -> 0.57524645 | D8: =INDEX($C$43:$H$43,輸入與假設!$C$307) -> 0.57808529 | E8: =INDEX($C$66:$H$66,輸入與假設!$C$307) -> -0.0028388388 | F8: 不適用 | G8: 不適用 | H8: =INDEX($C$67:$H$67,輸入與假設!$C$307) -> 不適用 | I8: =IF(ISNUMBER(INDEX($C$47:$H$47,輸入與假設!$C$307)),INDEX($C$47:$H$47,輸入與假設!$C$307),"待公布") -> 待公布 | J8: =INDEX($C$68:$H$68,輸入與假設!$C$307) | K8: =INDEX($C$69:$H$69,輸入與假設!$C$307) | L8: =INDEX($C$70:$H$70,輸入與假設!$C$307)
A9: 焦點｜調整後營業利益 | B9: US$bn | C9: =INDEX($C$30:$H$30,輸入與假設!$C$307) -> -0.066042019 | D9: 不適用 | E9: =INDEX($C$71:$H$71,輸入與假設!$C$307) -> 不適用 | F9: =IF(ISNUMBER(INDEX($C$33:$H$33,輸入與假設!$C$307)),INDEX($C$33:$H$33,輸入與假設!$C$307),IF(INDEX($C$35:$H$35,輸入與假設!$C$307)<>"",INDEX($C$35:$H$35,輸入與假設!$C$307),"不適用")) -> 0.2 | G9: =INDEX($C$34:$H$34,輸入與假設!$C$307) -> 0.26 | H9: =INDEX($C$72:$H$72,輸入與假設!$C$307) -> -0.29604202 | I9: =IF(ISNUMBER(INDEX($C$48:$H$48,輸入與假設!$C$307)),INDEX($C$48:$H$48,輸入與假設!$C$307),"待公布") -> 待公布 | J9: =INDEX($C$73:$H$73,輸入與假設!$C$307) | K9: =INDEX($C$74:$H$74,輸入與假設!$C$307) | L9: =INDEX($C$75:$H$75,輸入與假設!$C$307) | M9: =INDEX($C$76:$H$76,輸入與假設!$C$307) -> 不適用 | N9: =INDEX($C$77:$H$77,輸入與假設!$C$307) -> -0.083279357 | O9: =INDEX($C$78:$H$78,輸入與假設!$C$307) | P9: =INDEX($C$79:$H$79,輸入與假設!$C$307) | Q9: =INDEX($C$80:$H$80,輸入與假設!$C$307)
A10: 焦點｜CapEx（毛額） | B10: US$bn | C10: =INDEX($C$40:$H$40,輸入與假設!$C$307) -> 12.5 | D10: 不適用 | E10: =INDEX($C$81:$H$81,輸入與假設!$C$307) -> 不適用 | F10: =IF(ISNUMBER(INDEX($C$36:$H$36,輸入與假設!$C$307)),INDEX($C$36:$H$36,輸入與假設!$C$307),"不適用") -> 11.5 | G10: =INDEX($C$37:$H$37,輸入與假設!$C$307) -> 13.5 | H10: =INDEX($C$82:$H$82,輸入與假設!$C$307) -> 0 | I10: =IF(ISNUMBER(INDEX($C$49:$H$49,輸入與假設!$C$307)),INDEX($C$49:$H$49,輸入與假設!$C$307),"待公布") -> 待公布 | J10: =INDEX($C$83:$H$83,輸入與假設!$C$307) | K10: =INDEX($C$84:$H$84,輸入與假設!$C$307) | L10: =INDEX($C$85:$H$85,輸入與假設!$C$307)
A11: 焦點｜季末 Accepted MW | B11: MW | C11: =INDEX($C$19:$H$19,輸入與假設!$C$307) -> 1675 | D11: 不適用 | E11: =INDEX($C$86:$H$86,輸入與假設!$C$307) -> 不適用 | F11: 不適用 | G11: 不適用 | H11: =INDEX($C$87:$H$87,輸入與假設!$C$307) -> 不適用 | I11: =IF(ISNUMBER(INDEX($C$50:$H$50,輸入與假設!$C$307)),INDEX($C$50:$H$50,輸入與假設!$C$307),"待公布") -> 待公布 | J11: =INDEX($C$88:$H$88,輸入與假設!$C$307) | K11: =INDEX($C$89:$H$89,輸入與假設!$C$307) | L11: =INDEX($C$90:$H$90,輸入與假設!$C$307)
A12: 焦點｜季度 | C12: =INDEX($C$16:$H$16,輸入與假設!$C$307) -> Q3'26
A13: 焦點｜差異原因 | C13: =IF(INDEX($C$133:$H$133,輸入與假設!$C$307)="","無（差距皆在 "&IF(ROUND(ABS(輸入與假設!$C$301)*100,4)=INT(ROUND(ABS(輸入與假設!$C$301)*100,4)),TEXT(ROUND(ABS(輸入與假設!$C$301)*100,4),"0"),TEXT(ROUND(ABS(輸入與假設!$C$301)*100,4),"0.0"))&"%"&" 以內）",INDEX($C$133:$H$133,輸入與假設!$C$307)) -> 營收 vs 指引中點 +3.9%：觀點（水準 +$0.115bn（2H26 模型 $8.413bn，指引隱含 $8.147bn）；分配 +$0.023bn）；調整後營業利益 vs 指引中點 −$0.30bn／−8.3pt：已知限制（對照指引隱含折舊 1.82（＝共識 EBITDA 2.05 − 指引中點 0.23，Derived），模型折舊 2.17；缺口 −0.30 ≈ 折舊 −0.36 ＋ EBITDA +0.06；待辦 6 修正折舊）
A15: 2｜6 季路徑、共識、指引、實際與差距（明細；第 1 區以焦點季引用本區）
A16: 項目 | B16: 單位 | C16: Q3'26 | D16: Q4'26 | E16: Q1'27 | F16: Q2'27 | G16: Q3'27 | H16: Q4'27
A17: 所屬期間 | C17: =輸入與假設!C$306 -> 1 | D17: =輸入與假設!D$306 -> 1 | E17: =輸入與假設!E$306 -> 2 | F17: =輸入與假設!F$306 -> 2 | G17: =輸入與假設!G$306 -> 2 | H17: =輸入與假設!H$306 -> 2 | J17: 1＝2H26、2＝FY27
A18: 季序 | C18: 1 | D18: 2 | E18: 3 | F18: 4 | G18: 5 | H18: 6 | J18: EBITDA 率直線的 x 軸
A19: 季末 Accepted MW（模型） | B19: MW | C19: =輸入與假設!$C$309+(輸入與假設!C$26-輸入與假設!$C$309)*1/2 -> 1675 | D19: =輸入與假設!$C$309+(輸入與假設!C$26-輸入與假設!$C$309)*2/2 -> 1850 | E19: =輸入與假設!C$26+(輸入與假設!D$26-輸入與假設!C$26)*1/4 -> 2162.5 | F19: =輸入與假設!C$26+(輸入與假設!D$26-輸入與假設!C$26)*2/4 -> 2475 | G19: =輸入與假設!C$26+(輸入與假設!D$26-輸入與假設!C$26)*3/4 -> 2787.5 | H19: =輸入與假設!C$26+(輸入與假設!D$26-輸入與假設!C$26)*4/4 -> 3100 | J19: 期初與期末 Accepted 之間線性內插；第 1 期起點見 J 區
A20: 平均在役 MW（Billable，拆分依據） | B20: MW | C20: =輸入與假設!$C$20+(輸入與假設!C$27-輸入與假設!$C$20)*1/4 -> 1437.5 | D20: =輸入與假設!$C$20+(輸入與假設!C$27-輸入與假設!$C$20)*3/4 -> 1612.5 | E20: =輸入與假設!C$27+(輸入與假設!D$27-輸入與假設!C$27)*1/8 -> 1850 | F20: =輸入與假設!C$27+(輸入與假設!D$27-輸入與假設!C$27)*3/8 -> 2150 | G20: =輸入與假設!C$27+(輸入與假設!D$27-輸入與假設!C$27)*5/8 -> 2450 | H20: =輸入與假設!C$27+(輸入與假設!D$27-輸入與假設!C$27)*7/8 -> 2750 | J20: 期初與期末 Billable 之間線性內插的季平均
A21: 季內新增 Accepted MW | B21: MW | C21: =C19-輸入與假設!$C$309 -> 175 | D21: =D19-C19 -> 175 | E21: =E19-輸入與假設!C$26 -> 312.5 | F21: =F19-E19 -> 312.5 | G21: =G19-F19 -> 312.5 | H21: =H19-G19 -> 312.5 | J21: CapEx 拆分依據
A22: 營收（模型） | B22: US$bn | C22: =輸入與假設!$C$308+1*(損益!C8-2*輸入與假設!$C$308)/3 -> 3.6626667 | D22: =輸入與假設!$C$308+2*(損益!C8-2*輸入與假設!$C$308)/3 -> 4.7503333 | E22: =損益!D8*E20/(E20+F20+G20+H20) -> 5.2538995 | F22: =損益!D8*F20/(E20+F20+G20+H20) -> 6.1058832 | G22: =損益!D8*G20/(E20+F20+G20+H20) -> 6.9578668 | H22: =損益!D8*H20/(E20+F20+G20+H20) -> 7.8098505 | J22: 拆分方法見『輸入與假設』J 區與 HTML「拆分方法」
A23: EBITDA 率直線｜各期營收合計 S | C23: =C22+D22 -> 8.413 | D23: =E22+F22+G22+H22 -> 26.1275 | J23: 欄＝期間（2H26、FY27）
A24: EBITDA 率直線｜營收 × 季序合計 T | C24: =C22*C18+D22*D18 -> 13.163333 | D24: =E22*E18+F22*F18+G22*G18+H22*H18 -> 121.83367 | J24: 欄＝期間（2H26、FY27）
A25: EBITDA 率直線｜年度 EBITDA E | C25: =損益!C19 -> 4.8586769 | D25: =損益!D19 -> 15.41514 | J25: 欄＝期間（2H26、FY27）
A26: EBITDA 率直線｜截距 a／斜率 b | C26: =(C25*D24-C24*D25)/(C23*D24-C24*D23) -> 0.57121966 | D26: =(C23*D25-D23*C25)/(C23*D24-C24*D23) -> 0.004026787 | J26: 解兩式：Σ營收×(a＋b×季序)＝各期年度 EBITDA
A27: EBITDA 率（模型） | B27: % | C27: =$C$26+$D$26*C18 -> 0.57524645 | D27: =$C$26+$D$26*D18 -> 0.57927323 | E27: =$C$26+$D$26*E18 -> 0.58330002 | F27: =$C$26+$D$26*F18 -> 0.58732681 | G27: =$C$26+$D$26*G18 -> 0.5913536 | H27: =$C$26+$D$26*H18 -> 0.59538038 | J27: 跨季一條直線，季度 EBITDA 加總＝年度
A28: 調整後 EBITDA（模型） | B28: US$bn | C28: =C22*C27 -> 2.106936 | D28: =D22*D27 -> 2.751741 | E28: =E22*E27 -> 3.0645997 | F28: =F22*F27 -> 3.5861489 | G28: =G22*G27 -> 4.1145596 | H28: =H22*H27 -> 4.6498318
A29: 車隊折舊（模型） | B29: US$bn | C29: =(輸入與假設!C$135+輸入與假設!C$133*1/4)/輸入與假設!$C$114*輸入與假設!C$24/2 -> 2.172978 | D29: =(輸入與假設!C$135+輸入與假設!C$133*3/4)/輸入與假設!$C$114*輸入與假設!C$24/2 -> 2.6242674 | E29: =(輸入與假設!D$135+輸入與假設!D$133*1/8)/輸入與假設!$C$114*輸入與假設!D$24/4 -> 3.0702204 | F29: =(輸入與假設!D$135+輸入與假設!D$133*3/8)/輸入與假設!$C$114*輸入與假設!D$24/4 -> 3.5108372 | G29: =(輸入與假設!D$135+輸入與假設!D$133*5/8)/輸入與假設!$C$114*輸入與假設!D$24/4 -> 3.9514539 | H29: =(輸入與假設!D$135+輸入與假設!D$133*7/8)/輸入與假設!$C$114*輸入與假設!D$24/4 -> 4.3920707 | J29: 依期內平均 PP&E（與年度車隊折舊公式相同）
A30: 調整後營業利益（模型） | B30: US$bn | C30: =C28-C29 -> -0.066042019 | D30: =D28-D29 -> 0.1274736 | E30: =E28-E29 -> -0.0056207459 | F30: =F28-F29 -> 0.075311695 | G30: =G28-G29 -> 0.16310565 | H30: =H28-H29 -> 0.25776112 | J30: ＝調整後 EBITDA − 車隊折舊（未扣 SBC）
A31: 指引｜營收（低） | B31: US$bn | C31: =IF(ISNUMBER(輸入與假設!C$318),輸入與假設!C$318,"不適用") -> 3.45 | D31: =IF(ISNUMBER(輸入與假設!D$318),輸入與假設!D$318,"不適用") -> 不適用 | E31: =IF(ISNUMBER(輸入與假設!E$318),輸入與假設!E$318,"不適用") -> 不適用 | F31: =IF(ISNUMBER(輸入與假設!F$318),輸入與假設!F$318,"不適用") -> 不適用 | G31: =IF(ISNUMBER(輸入與假設!G$318),輸入與假設!G$318,"不適用") -> 不適用 | H31: =IF(ISNUMBER(輸入與假設!H$318),輸入與假設!H$318,"不適用") -> 不適用
A32: 指引｜營收（高） | B32: US$bn | C32: =IF(ISNUMBER(輸入與假設!C$319),輸入與假設!C$319,"不適用") -> 3.6 | D32: =IF(ISNUMBER(輸入與假設!D$319),輸入與假設!D$319,"不適用") -> 不適用 | E32: =IF(ISNUMBER(輸入與假設!E$319),輸入與假設!E$319,"不適用") -> 不適用 | F32: =IF(ISNUMBER(輸入與假設!F$319),輸入與假設!F$319,"不適用") -> 不適用 | G32: =IF(ISNUMBER(輸入與假設!G$319),輸入與假設!G$319,"不適用") -> 不適用 | H32: =IF(ISNUMBER(輸入與假設!H$319),輸入與假設!H$319,"不適用") -> 不適用
A33: 指引｜調整後營業利益（低） | B33: US$bn | C33: =IF(ISNUMBER(輸入與假設!C$320),輸入與假設!C$320,"不適用") -> 0.2 | D33: =IF(ISNUMBER(輸入與假設!D$320),輸入與假設!D$320,"不適用") -> 不適用 | E33: =IF(ISNUMBER(輸入與假設!E$320),輸入與假設!E$320,"不適用") -> 不適用 | F33: =IF(ISNUMBER(輸入與假設!F$320),輸入與假設!F$320,"不適用") -> 不適用 | G33: =IF(ISNUMBER(輸入與假設!G$320),輸入與假設!G$320,"不適用") -> 不適用 | H33: =IF(ISNUMBER(輸入與假設!H$320),輸入與假設!H$320,"不適用") -> 不適用
A34: 指引｜調整後營業利益（高） | B34: US$bn | C34: =IF(ISNUMBER(輸入與假設!C$321),輸入與假設!C$321,"不適用") -> 0.26 | D34: =IF(ISNUMBER(輸入與假設!D$321),輸入與假設!D$321,"不適用") -> 不適用 | E34: =IF(ISNUMBER(輸入與假設!E$321),輸入與假設!E$321,"不適用") -> 不適用 | F34: =IF(ISNUMBER(輸入與假設!F$321),輸入與假設!F$321,"不適用") -> 不適用 | G34: =IF(ISNUMBER(輸入與假設!G$321),輸入與假設!G$321,"不適用") -> 不適用 | H34: =IF(ISNUMBER(輸入與假設!H$321),輸入與假設!H$321,"不適用") -> 不適用
A35: 指引（文字）｜調整後營業利益 | C35: =IF(ISTEXT(輸入與假設!C$324),輸入與假設!C$324,"") | D35: =IF(ISTEXT(輸入與假設!D$324),輸入與假設!D$324,"") -> 調整後營業利益率 low teens | E35: =IF(ISTEXT(輸入與假設!E$324),輸入與假設!E$324,"") | F35: =IF(ISTEXT(輸入與假設!F$324),輸入與假設!F$324,"") | G35: =IF(ISTEXT(輸入與假設!G$324),輸入與假設!G$324,"") | H35: =IF(ISTEXT(輸入與假設!H$324),輸入與假設!H$324,"") | J35: 文字指引：只列不計差距
A36: 指引｜CapEx（毛額）（低） | B36: US$bn | C36: =IF(ISNUMBER(輸入與假設!C$322),輸入與假設!C$322,"不適用") -> 11.5 | D36: =IF(ISNUMBER(輸入與假設!D$322),輸入與假設!D$322,"不適用") -> 不適用 | E36: =IF(ISNUMBER(輸入與假設!E$322),輸入與假設!E$322,"不適用") -> 不適用 | F36: =IF(ISNUMBER(輸入與假設!F$322),輸入與假設!F$322,"不適用") -> 不適用 | G36: =IF(ISNUMBER(輸入與假設!G$322),輸入與假設!G$322,"不適用") -> 不適用 | H36: =IF(ISNUMBER(輸入與假設!H$322),輸入與假設!H$322,"不適用") -> 不適用
A37: 指引｜CapEx（毛額）（高） | B37: US$bn | C37: =IF(ISNUMBER(輸入與假設!C$323),輸入與假設!C$323,"不適用") -> 13.5 | D37: =IF(ISNUMBER(輸入與假設!D$323),輸入與假設!D$323,"不適用") -> 不適用 | E37: =IF(ISNUMBER(輸入與假設!E$323),輸入與假設!E$323,"不適用") -> 不適用 | F37: =IF(ISNUMBER(輸入與假設!F$323),輸入與假設!F$323,"不適用") -> 不適用 | G37: =IF(ISNUMBER(輸入與假設!G$323),輸入與假設!G$323,"不適用") -> 不適用 | H37: =IF(ISNUMBER(輸入與假設!H$323),輸入與假設!H$323,"不適用") -> 不適用
A38: CapEx 指引錨定值 | B38: US$bn | C38: =IF(AND(ISNUMBER(C36),ISNUMBER(C37)),((C36+C37)/2),"") -> 12.5 | D38: =IF(AND(ISNUMBER(D36),ISNUMBER(D37)),((D36+D37)/2),"") | E38: =IF(AND(ISNUMBER(E36),ISNUMBER(E37)),((E36+E37)/2),"") | F38: =IF(AND(ISNUMBER(F36),ISNUMBER(F37)),((F36+F37)/2),"") | G38: =IF(AND(ISNUMBER(G36),ISNUMBER(G37)),((G36+G37)/2),"") | H38: =IF(AND(ISNUMBER(H36),ISNUMBER(H37)),((H36+H37)/2),"") | J38: 有季度指引的季取指引中點（capexSplit＝guidanceAnchor）
A39: CapEx 未錨定季的新增 MW | B39: MW | C39: =IF(ISNUMBER(C38),0,C21) -> 0 | D39: =IF(ISNUMBER(D38),0,D21) -> 175 | E39: =IF(ISNUMBER(E38),0,E21) -> 312.5 | F39: =IF(ISNUMBER(F38),0,F21) -> 312.5 | G39: =IF(ISNUMBER(G38),0,G21) -> 312.5 | H39: =IF(ISNUMBER(H38),0,H21) -> 312.5 | J39: 期間餘數依此分配
A40: CapEx（毛額）（模型） | B40: US$bn | C40: =IF(ISNUMBER(C38),C38,IF((C39+D39)>0,(輸入與假設!C$137-SUM(C38,D38))*C39/(C39+D39),(輸入與假設!C$137-SUM(C38,D38))/(2-COUNT(C38,D38)))) -> 12.5 | D40: =IF(ISNUMBER(D38),D38,IF((C39+D39)>0,(輸入與假設!C$137-SUM(C38,D38))*D39/(C39+D39),(輸入與假設!C$137-SUM(C38,D38))/(2-COUNT(C38,D38)))) -> 9.1618888 | E40: =IF(ISNUMBER(E38),E38,IF((E39+F39+G39+H39)>0,(輸入與假設!D$137-SUM(E38,F38,G38,H38))*E39/(E39+F39+G39+H39),(輸入與假設!D$137-SUM(E38,F38,G38,H38))/(4-COUNT(E38,F38,G38,H38)))) -> 10.574802 | F40: =IF(ISNUMBER(F38),F38,IF((E39+F39+G39+H39)>0,(輸入與假設!D$137-SUM(E38,F38,G38,H38))*F39/(E39+F39+G39+H39),(輸入與假設!D$137-SUM(E38,F38,G38,H38))/(4-COUNT(E38,F38,G38,H38)))) -> 10.574802 | G40: =IF(ISNUMBER(G38),G38,IF((E39+F39+G39+H39)>0,(輸入與假設!D$137-SUM(E38,F38,G38,H38))*G39/(E39+F39+G39+H39),(輸入與假設!D$137-SUM(E38,F38,G38,H38))/(4-COUNT(E38,F38,G38,H38)))) -> 10.574802 | H40: =IF(ISNUMBER(H38),H38,IF((E39+F39+G39+H39)>0,(輸入與假設!D$137-SUM(E38,F38,G38,H38))*H39/(E39+F39+G39+H39),(輸入與假設!D$137-SUM(E38,F38,G38,H38))/(4-COUNT(E38,F38,G38,H38)))) -> 10.574802 | J40: 有季度指引的季＝指引中點；其餘季＝期間餘數依新增 Accepted MW 分配
A41: 共識｜營收 | B41: US$bn | C41: =IF(ISNUMBER(輸入與假設!$C$277),輸入與假設!$C$277,"不適用") -> 3.541 | D41: =IF(ISNUMBER(輸入與假設!$D$277),輸入與假設!$D$277,"不適用") -> 4.706 | E41: 不適用 | F41: 不適用 | G41: 不適用 | H41: 不適用 | J41: I 區季度共識 [Interested-party]
A42: 共識｜調整後 EBITDA | B42: US$bn | C42: =IF(ISNUMBER(輸入與假設!$C$278),輸入與假設!$C$278,"不適用") -> 2.047 | D42: =IF(ISNUMBER(輸入與假設!$D$278),輸入與假設!$D$278,"不適用") -> 2.897 | E42: 不適用 | F42: 不適用 | G42: 不適用 | H42: 不適用 | J42: I 區季度共識 [Interested-party]
...

Sheet 運營_產能與收入
A1: 產能與收入 — 合約排程 vs 機房產能
A2: 兩條線獨立產生後相減：排程>容量→瓶頸（收不到）；容量>排程→剩餘產能（要靠新簽約賣掉）
A3: FY26 欄口徑：MW 為年底存量；標示「（模型期）」的收入列只含 2026 下半年——RPO 桶自 2026-06-30 起算，1H 收入已實現、不再受產能約束。1H 實際單列，兩者相加即 FY26 全年（見本頁「FY26 全年」列）。
A5: 項目 | B5: 單位 | C5: FY26 | D5: FY27 | E5: FY28 | F5: FY29 | G5: FY30 | I5: 公式／來源說明
A6: 模型期間 | C6: ="2026-07-01~12-31" -> 2026-07-01~12-31 | D6: ="2027 全年" -> 2027 全年 | E6: ="2028 全年" -> 2028 全年 | F6: ="2029 全年" -> 2029 全年 | G6: ="2030 全年" -> 2030 全年 | I6: FY26 的模型期只有下半年；1H 已實現的營收單列於下方
A7: 模型期長度（年） | C7: =輸入與假設!C$24 -> 0.5 | D7: =輸入與假設!D$24 -> 1 | E7: =輸入與假設!E$24 -> 1 | F7: =輸入與假設!F$24 -> 1 | G7: =輸入與假設!G$24 -> 1 | I7: 只用於下方三處：容量上限、電力、維護——把年率換算成該期金額
A8: （A）機房：容量上限
A9: Accepted MW（已驗收，單調不減） | B9: MW | C9: =MAX(0,輸入與假設!C$26) -> 1850 | D9: =MAX(輸入與假設!D$26,C9) -> 3100 | E9: =MAX(輸入與假設!E$26,D9) -> 4000 | F9: =MAX(輸入與假設!F$26,E9) -> 4800 | G9: =MAX(輸入與假設!G$26,F9) -> 5600 | I9: 引擎規則：不得低於前期（產能不會消失）
A10: Billable MW（上限為 Accepted） | B10: MW | C10: =MIN(MAX(0,輸入與假設!C$27),C9) -> 1700 | D10: =MIN(MAX(0,輸入與假設!D$27),D9) -> 2900 | E10: =MIN(MAX(0,輸入與假設!E$27),E9) -> 3739 | F10: =MIN(MAX(0,輸入與假設!F$27),F9) -> 4495 | G10: =MIN(MAX(0,輸入與假設!G$27),G9) -> 5250 | I10: 引擎規則：可計費不得超過已驗收
A11: 期初在役 MW | B11: MW | C11: =輸入與假設!$C$20 -> 1350 | D11: =C10 -> 1700 | E11: =D10 -> 2900 | F11: =E10 -> 3739 | G11: =F10 -> 4495 | I11: 前期期末＝本期期初
A12: 平均在役 MW（FY26 欄為下半年平均） | B12: MW | C12: =IF(輸入與假設!$C$21=1,(C11+C10)/2,C10) -> 1525 | D12: =IF(輸入與假設!$C$21=1,(D11+D10)/2,D10) -> 2300 | E12: =IF(輸入與假設!$C$21=1,(E11+E10)/2,E10) -> 3319.5 | F12: =IF(輸入與假設!$C$21=1,(F11+F10)/2,F10) -> 4117 | G12: =IF(輸入與假設!$C$21=1,(G11+G10)/2,G10) -> 4872.5 | I12: 開關在輸入頁：1＝(期初+期末)/2，0＝期末全期化
A13: 利用率 | B13: % | C13: =輸入與假設!C$28 -> 0.95 | D13: =輸入與假設!D$28 -> 0.95 | E13: =輸入與假設!E$28 -> 0.94 | F13: =輸入與假設!F$28 -> 0.93 | G13: =輸入與假設!G$28 -> 0.92
A14: 每 MW 年收入 | B14: US$bn/MW | C14: =輸入與假設!C$29 -> 0.0112 | D14: =輸入與假設!D$29 -> 0.0115 | E14: =輸入與假設!E$29 -> 0.0115 | F14: =輸入與假設!F$29 -> 0.011 | G14: =輸入與假設!G$29 -> 0.0105
A15: 容量上限（模型期最多能交付的收入） | B15: US$bn | C15: =C12*輸入與假設!C$29*輸入與假設!$C$22*輸入與假設!C$28*C7 -> 8.113 | D15: =D12*輸入與假設!D$29*輸入與假設!$C$22*輸入與假設!D$28*D7 -> 25.1275 | E15: =E12*輸入與假設!E$29*輸入與假設!$C$22*輸入與假設!E$28*E7 -> 35.883795 | F15: =F12*輸入與假設!F$29*輸入與假設!$C$22*輸入與假設!F$28*F7 -> 42.11691 | G15: =G12*輸入與假設!G$29*輸入與假設!$C$22*輸入與假設!G$28*G7 -> 47.06835 | I15: ＝平均在役 MW × 每 MW 年收入 × 利用率 × 期間係數。只看機房，不看合約
A16: （B）合約：排程 RPO
A17: 排程 RPO（模型期，依 10-Q 桶分攤） | B17: US$bn | C17: =(輸入與假設!$C$15+輸入與假設!$C$16)*(輸入與假設!C$25/輸入與假設!$C$18)*輸入與假設!$C$17 -> 13.19175 | D17: =(輸入與假設!$C$15+輸入與假設!$C$16)*(輸入與假設!D$25/輸入與假設!$C$18)*輸入與假設!$C$17 -> 26.3835 | E17: =(輸入與假設!$C$15+輸入與假設!$C$16)*(輸入與假設!E$25/輸入與假設!$C$18)*輸入與假設!$C$17 -> 25.74 | F17: =(輸入與假設!$C$15+輸入與假設!$C$16)*(輸入與假設!F$25/輸入與假設!$C$18)*輸入與假設!$C$17 -> 25.0965 | G17: =(輸入與假設!$C$15+輸入與假設!$C$16)*(輸入與假設!G$25/輸入與假設!$C$18)*輸入與假設!$C$17 -> 17.69625 | I17: ＝(6/30 RPO＋Q3 新增)×本期權重÷權重合計×五期認列比例。只看合約，不看機房
A18: （C）兩條線相減
A19: 產能瓶頸（模型期：排程 − 容量） | B19: US$bn | C19: =MAX(0,C17-C15) -> 5.07875 | D19: =MAX(0,D17-D15) -> 1.256 | E19: =MAX(0,E17-E15) -> 0 | F19: =MAX(0,F17-F15) -> 0 | G19: =MAX(0,G17-G15) -> 0 | I19: 合約有、機房沒有 → 本期收不到，且不遞延到下期（保守處理）
A20: 期初 RPO 轉換收入（模型期） | B20: US$bn | C20: =C17-C19 -> 8.113 | D20: =D17-D19 -> 25.1275 | E20: =E17-E19 -> 25.74 | F20: =F17-F19 -> 25.0965 | G20: =G17-G19 -> 17.69625 | I20: ＝排程 − 瓶頸。當瓶頸>0 時，此值恆等於容量上限
A21: 未被期初 RPO 占用的產能 | B21: US$bn | C21: =MAX(0,C15-C17) -> 0 | D21: =MAX(0,D15-D17) -> 0 | E21: =MAX(0,E15-E17) -> 10.143795 | F21: =MAX(0,F15-F17) -> 17.02041 | G21: =MAX(0,G15-G17) -> 29.3721 | I21: 容量 − 排程。機房有、期初合約沒占滿 → 要靠新簽約
A22: 新產能簽約率 | B22: % | C22: =輸入與假設!C$30 -> 1 | D22: =輸入與假設!D$30 -> 1 | E22: =輸入與假設!E$30 -> 0.9 | F22: =輸入與假設!F$30 -> 0.85 | G22: =輸入與假設!G$30 -> 0.8
A23: 新簽約收入 | B23: US$bn | C23: =C21*輸入與假設!C$30 -> 0 | D23: =D21*輸入與假設!D$30 -> 0 | E23: =E21*輸入與假設!E$30 -> 9.1294155 | F23: =F21*輸入與假設!F$30 -> 14.467348 | G23: =G21*輸入與假設!G$30 -> 23.49768 | I23: 尚未簽署的合約。FY28 起模型收入主要來自此列——8 GW 敘事的風險集中點
A24: 未售產能（浪費） | B24: US$bn | C24: =MAX(0,C15-C20-C23) -> 0 | D24: =MAX(0,D15-D20-D23) -> 0 | E24: =MAX(0,E15-E20-E23) -> 1.0143795 | F24: =MAX(0,F15-F20-F23) -> 2.5530615 | G24: =MAX(0,G15-G20-G23) -> 5.87442 | I24: 蓋好但賣不掉。Bernstein：簽約電力 74% 位於 Tier 3/4 市場
A25: 損益用算力收入（模型期＝RPO 轉換＋新簽約） | B25: US$bn | C25: =C20+C23 -> 8.113 | D25: =D20+D23 -> 25.1275 | E25: =E20+E23 -> 34.869416 | F25: =F20+F23 -> 39.563848 | G25: =G20+G23 -> 41.19393 | I25: 損益與評價頁的算力收入由此連結，確保現金與損益同一組數字
A26: 1H26 實際營收（10-Q，已實現） | B26: US$bn | C26: =輸入與假設!$C$223 -> 4.653 | D26: =0 -> 0 | E26: =0 -> 0 | F26: =0 -> 0 | G26: =0 -> 0 | I26: 2026-01-01 至 06-30 已認列營收。已實現，不受下半年產能約束，故不進入上方的瓶頸計算
A27: FY26 全年總營收（1H 實際＋模型期算力＋服務） | B27: US$bn | C27: =C26+C25+輸入與假設!C$33 -> 13.066 | D27: =D26+D25+輸入與假設!D$33 -> 26.1275 | E27: =E26+E25+輸入與假設!E$33 -> 36.669415 | F27: =F26+F25+輸入與假設!F$33 -> 42.363849 | G27: =G26+G25+輸入與假設!G$33 -> 44.99393 | I27: FY26 欄可直接對照公司全年指引 12.4–13.2；FY27 以後即為該年度總營收
A28: （D）收入 → 現金：三道折扣
A29: 客戶違約率 | B29: % | C29: =輸入與假設!C$31 -> 0.005 | D29: =輸入與假設!D$31 -> 0.01 | E29: =輸入與假設!E$31 -> 0.015 | F29: =輸入與假設!F$31 -> 0.02 | G29: =輸入與假設!G$31 -> 0.025
A30: 回收率 | B30: % | C30: =輸入與假設!C$32 -> 0.5 | D30: =輸入與假設!D$32 -> 0.5 | E30: =輸入與假設!E$32 -> 0.5 | F30: =輸入與假設!F$32 -> 0.5 | G30: =輸入與假設!G$32 -> 0.5
A31: 信用損失（期初 RPO 部分） | B31: US$bn | C31: =C20*輸入與假設!C$31*(1-輸入與假設!C$32) -> 0.0202825 | D31: =D20*輸入與假設!D$31*(1-輸入與假設!D$32) -> 0.1256375 | E31: =E20*輸入與假設!E$31*(1-輸入與假設!E$32) -> 0.19305 | F31: =F20*輸入與假設!F$31*(1-輸入與假設!F$32) -> 0.250965 | G31: =G20*輸入與假設!G$31*(1-輸入與假設!G$32) -> 0.22120313 | I31: ＝收入 × 違約率 × (1−回收率)
A32: 收現（期初 RPO 部分） | B32: US$bn | C32: =C20-C31 -> 8.0927175 | D32: =D20-D31 -> 25.001863 | E32: =E20-E31 -> 25.54695 | F32: =F20-F31 -> 24.845535 | G32: =G20-G31 -> 17.475047
A33: EBITDA 率（損益與資金共用） | B33: % | C33: =輸入與假設!C$87 -> 0.57752014 | D33: =輸入與假設!D$87 -> 0.58999674 | E33: =輸入與假設!E$87 -> 0.60279427 | F33: =輸入與假設!F$87 -> 0.59255589 | G33: =輸入與假設!G$87 -> 0.56910658 | I33: 起始→穩態線性爬升
A34: 模型期總營收（算力＋服務） | B34: US$bn | C34: =C25+輸入與假設!C$33 -> 8.413 | D34: =D25+輸入與假設!D$33 -> 26.1275 | E34: =E25+輸入與假設!E$33 -> 36.669415 | F34: =F25+輸入與假設!F$33 -> 42.363849 | G34: =G25+輸入與假設!G$33 -> 44.99393
A35: EBITDAR 率（EBITDA 率＋租金÷營收） | B35: % | C35: =輸入與假設!C$87+各期收支!C12/MAX(0.01,C34) -> 0.73679745 | D35: =輸入與假設!D$87+各期收支!D12/MAX(0.01,D34) -> 0.74075744 | E35: =輸入與假設!E$87+各期收支!E12/MAX(0.01,E34) -> 0.73165792 | F35: =輸入與假設!F$87+各期收支!F12/MAX(0.01,F34) -> 0.71348447 | G35: =輸入與假設!G$87+各期收支!G12/MAX(0.01,G34) -> 0.68446744 | I35: 租金前的 EBITDA 率。EBITDA 已扣租金，而資金模型把租金列在支出端，所以要加回，避免重複扣除
A36: RPO 現金（可支應資本用途） | B36: US$bn | C36: =C32*C35 -> 5.9626936 | D36: =D32*D35 -> 18.520316 | E36: =E32*E35 -> 18.691628 | F36: =F32*F35 -> 17.726903 | G36: =G32*G35 -> 11.961101 | I36: ×EBITDAR 率。租金與利息在支出頁單獨列示
A37: 新簽約現金 | B37: US$bn | C37: =C23*(1-輸入與假設!C$31*(1-輸入與假設!C$32))*C35 -> 0 | D37: =D23*(1-輸入與假設!D$31*(1-輸入與假設!D$32))*D35 -> 0 | E37: =E23*(1-輸入與假設!E$31*(1-輸入與假設!E$32))*E35 -> 6.6295121 | F37: =F23*(1-輸入與假設!F$31*(1-輸入與假設!F$32))*F35 -> 10.219006 | G37: =G23*(1-輸入與假設!G$31*(1-輸入與假設!G$32))*G35 -> 15.882354 | I37: 同樣扣信用損失、乘 EBITDAR 率
A39: 讀法：FY26（2H）與 FY27 瓶頸>0，合約多於機房；FY28 起反轉，收入愈來愈靠『新簽約收入』這一列。
A40: 把『新產能簽約率』調到 0，就能看到只靠期初 RPO 的資金缺口有多大——這是最重要的一個壓力測試。

Sheet 運營_站點
A1: 站點租賃 — 房東揭露 vs 10-Q 總額（檢驗租金路徑用）
A2: 10-Q 不揭露逐站租金；下表為房東公告的合約值（Interested-party），用來檢驗『每 MW 年租金』與模型租金路徑是否一致
A4: 站點 | B4: 房東 | C4: 契約 MW | D4: 已起租 MW | E4: 合約總值 $bn | F4: 年期 | G4: 年租金 $bn | H4: 每 MW 年租金 $m | I4: 起租時程 | J4: 10-Q 對應 | K4: 來源
A5: Helios（德州 Dickens） | B5: Galaxy (GLXY) | C5: 526 | D5: 133 | E5: 15 | F5: 15 | G5: =E5/F5 -> 1 | H5: =G5/C5*1000 -> 1.9011407 | I5: Ph I 133 MW 2026Q2 起租；Ph II 260 MW 2027H1 起；Ph III 133 MW | J5: 未交付 393 MW＝10-Q「單站上限 14.7／16 年」 | K5: Galaxy 2026-07-06：526 MW、年均租金 >$1bn、15 年＋2×5 年延長 [Interested-party]
A6: Polaris Forge 1（北達科他 Ellendale） | B6: Applied Digital (APLD) | C6: 400 | D6: 250 | E6: 11 | F6: 15 | G6: =E6/F6 -> 0.73333333 | H6: =G6/C6*1000 -> 1.8333333 | I6: 100 MW 2025Q4；150 MW 2026 年中；150 MW 2027 | J6: 大致落在未起租 35.5 內 | K6: APLD 2025-08-29／FQ2 法說：400 MW、約 $11bn、約 15 年 [Interested-party]
A7: Core Scientific 六站（Denton 等） | B7: Core Scientific (CORZ) | C7: 590 | D7: 250 | E7: 10.2 | F7: 12 | G7: =E7/F7 -> 0.85 | H7: =G7/C7*1000 -> 1.440678 | I7: 2026 年約 250 MW；2027 年初全數 590 MW | J7: 部分在帳、部分未起租；「按造價計租」355 MW 可能含部分 | K7: CORZ 2025-02-26：約 590 MW、$10.2bn、12 年；年均約 $850m [Interested-party]
A8: Kenilworth（新澤西 JV） | B8: JV（CRWV 持股 35%） | C8: 未揭露 | D8: 0 | E8: 未揭露 | F8: 15 | I8: 施工中；完工後起租 | J8: 10-Q：租金＝建造成本的一定比例，推定屬「按造價計租」355 MW | K8: 10-Q Note 3：15 年租約、租金依建造成本計；MW 與金額未揭露 [Verified]
A9: 具名站點合計 | C9: =SUM(C5:C8) -> 1516 | D9: =SUM(D5:D8) -> 633 | E9: =SUM(E5:E8) -> 36.2 | G9: =SUM(G5:G8) -> 2.5833333 | H9: =G9/C9*1000 -> 1.7040457 | K9: 加權每 MW 年租金＝具名站點的市場基準
A11: 對帳：具名站點 vs 10-Q 租賃承諾總額
A12: 10-Q 在帳租賃（未折現，已起租） | E12: 29.37 | K12: 營業 29.135＋融資 0.235 [Verified]
A13: 10-Q 未起租租賃（未折現） | E13: 35.5 | K13: 2026–2029 起租、7–16 年 [Verified]
A14: 10-Q 單站按造價計租上限 | E14: 14.7 | K14: 即 Helios 未交付 393 MW [Verified]
A15: 10-Q 已揭露租賃承諾合計 | E15: =SUM(E12:E14) -> 79.57 | K15: 另有 355 MW 按造價計租，金額未定，未含
A16: 減：具名站點合約總值 | E16: =-E9 -> -36.2
A17: ＝ 未具名站點（殘差） | E17: =E15+E16 -> 43.37 | K17: 43 座以上資料中心中未具名者（Equinix、Switch 等託管，以及其他房東）。殘差大是必然——公司不揭露逐站
A18: 殘差占 10-Q 總額 | E18: =E17/E15 -> 0.54505467
A20: 檢驗：模型租金路徑 ÷ 在役 MW vs 市場基準
A21: 項目 | B21: 單位 | C21: FY26 | D21: FY27 | E21: FY28 | F21: FY29 | G21: FY30
A22: 模型租金（在帳＋表外） | B22: US$bn | C22: =各期收支!C12 -> 1.34 | D22: =各期收支!D12 -> 3.939 | E22: =各期收支!E12 -> 4.7253548 | F22: =各期收支!F12 -> 5.123 | G22: =各期收支!G12 -> 5.1905385
A23: 平均在役 MW（Accepted） | B23: MW | C23: =(輸入與假設!C$129+輸入與假設!C$26)/2 -> 1350 | D23: =(輸入與假設!D$129+輸入與假設!D$26)/2 -> 2475 | E23: =(輸入與假設!E$129+輸入與假設!E$26)/2 -> 3550 | F23: =(輸入與假設!F$129+輸入與假設!F$26)/2 -> 4400 | G23: =(輸入與假設!G$129+輸入與假設!G$26)/2 -> 5200
A24: 模型期長度（年） | B24: 年 | C24: =輸入與假設!C$24 -> 0.5 | D24: =輸入與假設!D$24 -> 1 | E24: =輸入與假設!E$24 -> 1 | F24: =輸入與假設!F$24 -> 1 | G24: =輸入與假設!G$24 -> 1
A25: 模型每 MW 年租金 | B25: US$m/MW | C25: =C22/C24/C23*1000 -> 1.9851852 | D25: =D22/D24/D23*1000 -> 1.5915152 | E25: =E22/E24/E23*1000 -> 1.3310859 | F25: =F22/F24/F23*1000 -> 1.1643182 | G25: =G22/G24/G23*1000 -> 0.99818047 | K25: FY26 欄只含下半年租金、MW 取全年平均，略有低估
A26: 第三方租賃占比 | C26: 0.85 | K26: 其餘為自建／JV（Kenilworth、Lancaster），成本走 CapEx 或 JV 出資 [Assumed]
A27: 基準租金（MW×市場基準×占比） | B27: US$bn | C27: =C23*運營_站點!$H$9/1000*$C$26*C24 -> 0.97769624 | D27: =D23*運營_站點!$H$9/1000*$C$26*D24 -> 3.5848862 | E27: =E23*運營_站點!$H$9/1000*$C$26*E24 -> 5.141958 | F27: =F23*運營_站點!$H$9/1000*$C$26*F24 -> 6.373131 | G27: =G23*運營_站點!$H$9/1000*$C$26*G24 -> 7.5318821 | K27: 若 8 GW 多數比照 Helios／APLD／CORZ 的租金水準
A28: 差額（基準 − 模型） | B28: US$bn | C28: =C27-C22 -> -0.36230376 | D28: =D27-D22 -> -0.35411379 | E28: =E27-E22 -> 0.41660316 | F28: =F27-F22 -> 1.250131 | G28: =G27-G22 -> 2.3413437 | K28: 正值＝模型租金可能低估的金額
A29: 五期差額合計 | C29: =SUM(C28:G28) -> 3.2916603

Sheet 每MW經濟性
A1: 每 MW 經濟性（W2：Tokenomics 物理與產業數據 × 公司專屬輸入）
A2: 方法：資本支出 tokenomics／營運成本 bottomUp／收入 legacy（company.json → methodology.perMw）。MW 口徑：IT 關鍵電力。每 MW 值＝期間金額 ÷ 平均在役 MW ÷ 期間長度（年化）。
A4: 項目 | B4: 單位 | C4: FY26 | D4: FY27 | E4: FY28 | F4: FY29 | G4: FY30 | I4: 公式／來源說明
A5: 每 MW 經濟性彙總（每平均在役 MW、年化；US$m／MW／年；目前情境）
A6: 平均在役 MW（IT 關鍵電力） | B6: MW | C6: =IF(輸入與假設!$C$37=2,C50/SUMPRODUCT(C51:C55,輸入與假設!$E$65:$E$69),C50) -> 1675 | D6: =IF(輸入與假設!$C$37=2,D50/SUMPRODUCT(D51:D55,輸入與假設!$E$65:$E$69),D50) -> 2475 | E6: =IF(輸入與假設!$C$37=2,E50/SUMPRODUCT(E51:E55,輸入與假設!$E$65:$E$69),E50) -> 3550 | F6: =IF(輸入與假設!$C$37=2,F50/SUMPRODUCT(F51:F55,輸入與假設!$E$65:$E$69),F50) -> 4400 | G6: =IF(輸入與假設!$C$37=2,G50/SUMPRODUCT(G51:G55,輸入與假設!$E$65:$E$69),G50) -> 5200 | I6: 公司 MW 口徑＝IT 時同上；設施口徑時 ÷ IF_FacilityGW
A7: 平均在役 MW（設施＝IT × IF_FacilityGW） | B7: MW | C7: =IF(輸入與假設!$C$37=2,C50/SUMPRODUCT(C51:C55,輸入與假設!$E$65:$E$69),C50)*SUMPRODUCT(C51:C55,輸入與假設!$E$65:$E$69) -> 2010 | D7: =IF(輸入與假設!$C$37=2,D50/SUMPRODUCT(D51:D55,輸入與假設!$E$65:$E$69),D50)*SUMPRODUCT(D51:D55,輸入與假設!$E$65:$E$69) -> 2970 | E7: =IF(輸入與假設!$C$37=2,E50/SUMPRODUCT(E51:E55,輸入與假設!$E$65:$E$69),E50)*SUMPRODUCT(E51:E55,輸入與假設!$E$65:$E$69) -> 4260 | F7: =IF(輸入與假設!$C$37=2,F50/SUMPRODUCT(F51:F55,輸入與假設!$E$65:$E$69),F50)*SUMPRODUCT(F51:F55,輸入與假設!$E$65:$E$69) -> 5280 | G7: =IF(輸入與假設!$C$37=2,G50/SUMPRODUCT(G51:G55,輸入與假設!$E$65:$E$69),G50)*SUMPRODUCT(G51:G55,輸入與假設!$E$65:$E$69) -> 6240 | I7: IF_FacilityGW 依在役世代加權（基準 1.2）
A8: 每 MW 年收入（算力＋服務） | B8: US$m/MW | C8: =運營_產能與收入!C34/MAX(0.000000001,C50)/輸入與假設!C$24*1000 -> 10.045373 | D8: =運營_產能與收入!D34/MAX(0.000000001,D50)/輸入與假設!D$24*1000 -> 10.556566 | E8: =運營_產能與收入!E34/MAX(0.000000001,E50)/輸入與假設!E$24*1000 -> 10.329413 | F8: =運營_產能與收入!F34/MAX(0.000000001,F50)/輸入與假設!F$24*1000 -> 9.6281474 | G8: =運營_產能與收入!G34/MAX(0.000000001,G50)/輸入與假設!G$24*1000 -> 8.6526788 | I8: 模型期總營收 ÷ 平均在役 MW ÷ 期間長度
A9: 其中：算力收入 | B9: US$m/MW | C9: =運營_產能與收入!C25/MAX(0.000000001,C50)/輸入與假設!C$24*1000 -> 9.6871642 | D9: =運營_產能與收入!D25/MAX(0.000000001,D50)/輸入與假設!D$24*1000 -> 10.152525 | E9: =運營_產能與收入!E25/MAX(0.000000001,E50)/輸入與假設!E$24*1000 -> 9.8223706 | F9: =運營_產能與收入!F25/MAX(0.000000001,F50)/輸入與假設!F$24*1000 -> 8.9917837 | G9: =運營_產能與收入!G25/MAX(0.000000001,G50)/輸入與假設!G$24*1000 -> 7.9219096
A10: 電費 | B10: US$m/MW | C10: =C61/MAX(0.000000001,C50)/輸入與假設!C$24*1000 -> 0.672768 | D10: =D61/MAX(0.000000001,D50)/輸入與假設!D$24*1000 -> 0.672768 | E10: =E61/MAX(0.000000001,E50)/輸入與假設!E$24*1000 -> 0.672768 | F10: =F61/MAX(0.000000001,F50)/輸入與假設!F$24*1000 -> 0.672768 | G10: =G61/MAX(0.000000001,G50)/輸入與假設!G$24*1000 -> 0.672768 | I10: 由下而上明細（下方）
A11: IT 維護 | B11: US$m/MW | C11: =C62/MAX(0.000000001,C50)/輸入與假設!C$24*1000 -> 0.9362069 | D11: =D62/MAX(0.000000001,D50)/輸入與假設!D$24*1000 -> 0.99153829 | E11: =E62/MAX(0.000000001,E50)/輸入與假設!E$24*1000 -> 1.0323653 | F11: =F62/MAX(0.000000001,F50)/輸入與假設!F$24*1000 -> 1.0541961 | G11: =G62/MAX(0.000000001,G50)/輸入與假設!G$24*1000 -> 1.0759512
A12: 人員、軟體、水與耗材 | B12: US$m/MW | C12: =C63/MAX(0.000000001,C50)/輸入與假設!C$24*1000 -> 0.325 | D12: =D63/MAX(0.000000001,D50)/輸入與假設!D$24*1000 -> 0.325 | E12: =E63/MAX(0.000000001,E50)/輸入與假設!E$24*1000 -> 0.325 | F12: =F63/MAX(0.000000001,F50)/輸入與假設!F$24*1000 -> 0.325 | G12: =G63/MAX(0.000000001,G50)/輸入與假設!G$24*1000 -> 0.325
A13: 財產稅與保險 | B13: US$m/MW | C13: =C64/MAX(0.000000001,C50)/輸入與假設!C$24*1000 -> 0.15603448 | D13: =D64/MAX(0.000000001,D50)/輸入與假設!D$24*1000 -> 0.16525638 | E13: =E64/MAX(0.000000001,E50)/輸入與假設!E$24*1000 -> 0.17206088 | F13: =F64/MAX(0.000000001,F50)/輸入與假設!F$24*1000 -> 0.17569935 | G13: =G64/MAX(0.000000001,G50)/輸入與假設!G$24*1000 -> 0.17932521
A14: 公司管銷與其他 | B14: US$m/MW | C14: =C67/MAX(0.000000001,C50)/輸入與假設!C$24*1000 -> 0.55395844 | D14: =D67/MAX(0.000000001,D50)/輸入與假設!D$24*1000 -> 0.58214848 | E14: =E67/MAX(0.000000001,E50)/輸入與假設!E$24*1000 -> 0.56962199 | F14: =F67/MAX(0.000000001,F50)/輸入與假設!F$24*1000 -> 0.53095026 | G14: =G67/MAX(0.000000001,G50)/輸入與假設!G$24*1000 -> 0.47715744
A15: 租金 | B15: US$m/MW | C15: =C70/MAX(0.000000001,C50)/輸入與假設!C$24*1000 -> 1.6 | D15: =D70/MAX(0.000000001,D50)/輸入與假設!D$24*1000 -> 1.5915152 | E15: =E70/MAX(0.000000001,E50)/輸入與假設!E$24*1000 -> 1.3310859 | F15: =F70/MAX(0.000000001,F50)/輸入與假設!F$24*1000 -> 1.1643182 | G15: =G70/MAX(0.000000001,G50)/輸入與假設!G$24*1000 -> 0.99818047
A16: 現金成本合計（含租金） | B16: US$m/MW | C16: =(運營_產能與收入!C34-運營_產能與收入!C34*輸入與假設!C$87)/MAX(0.000000001,C50)/輸入與假設!C$24*1000 -> 4.2439678 | D16: =(運營_產能與收入!D34-運營_產能與收入!D34*輸入與假設!D$87)/MAX(0.000000001,D50)/輸入與假設!D$24*1000 -> 4.3282263 | E16: =(運營_產能與收入!E34-運營_產能與收入!E34*輸入與假設!E$87)/MAX(0.000000001,E50)/輸入與假設!E$24*1000 -> 4.102902 | F16: =(運營_產能與收入!F34-運營_產能與收入!F34*輸入與假設!F$87)/MAX(0.000000001,F50)/輸入與假設!F$24*1000 -> 3.9229319 | G16: =(運營_產能與收入!G34-運營_產能與收入!G34*輸入與假設!G$87)/MAX(0.000000001,G50)/輸入與假設!G$24*1000 -> 3.7283824 | I16: ＝收入 − EBITDA（模型採用的 EBITDA 率；由下而上時＝上列各項合計）
A17: EBITDA | B17: US$m/MW | C17: =運營_產能與收入!C34*輸入與假設!C$87/MAX(0.000000001,C50)/輸入與假設!C$24*1000 -> 5.8014053 | D17: =運營_產能與收入!D34*輸入與假設!D$87/MAX(0.000000001,D50)/輸入與假設!D$24*1000 -> 6.2283394 | E17: =運營_產能與收入!E34*輸入與假設!E$87/MAX(0.000000001,E50)/輸入與假設!E$24*1000 -> 6.2265108 | F17: =運營_產能與收入!F34*輸入與假設!F$87/MAX(0.000000001,F50)/輸入與假設!F$24*1000 -> 5.7052155 | G17: =運營_產能與收入!G34*輸入與假設!G$87/MAX(0.000000001,G50)/輸入與假設!G$24*1000 -> 4.9242965 | I17: ＝營收 × EBITDA 率（損益與資金共用）
A18: D&A（模型車隊折舊） | B18: US$m/MW | C18: =輸入與假設!C$138/MAX(0.000000001,C50)/輸入與假設!C$24*1000 -> 5.7280542 | D18: =輸入與假設!D$138/MAX(0.000000001,D50)/輸入與假設!D$24*1000 -> 6.0301342 | E18: =輸入與假設!E$138/MAX(0.000000001,E50)/輸入與假設!E$24*1000 -> 5.9602439 | F18: =輸入與假設!F$138/MAX(0.000000001,F50)/輸入與假設!F$24*1000 -> 5.9940846 | G18: =輸入與假設!G$138/MAX(0.000000001,G50)/輸入與假設!G$24*1000 -> 5.9724241 | I18: 模型車隊折舊（期初毛 PP&E＋本期成長型×½）÷ 壽命；在役世代加權的建置成本 ÷ 壽命見『資本支出對照』
A19: 利息 | B19: US$m/MW | C19: =各期收支!C17/MAX(0.000000001,C50)/輸入與假設!C$24*1000 -> 2.8795068 | D19: =各期收支!D17/MAX(0.000000001,D50)/輸入與假設!D$24*1000 -> 2.838644 | E19: =各期收支!E17/MAX(0.000000001,E50)/輸入與假設!E$24*1000 -> 2.3909711 | F19: =各期收支!F17/MAX(0.000000001,F50)/輸入與假設!F$24*1000 -> 2.0667057 | G19: =各期收支!G17/MAX(0.000000001,G50)/輸入與假設!G$24*1000 -> 1.948121 | I19: 存量債務＋瀑布新債利息
A20: 稅前 | B20: US$m/MW | C20: =C17-C18-C19 -> -2.8061556 | D20: =D17-D18-D19 -> -2.6404389 | E20: =E17-E18-E19 -> -2.1247042 | F20: =F17-F18-F19 -> -2.3555748 | G20: =G17-G18-G19 -> -2.9962485 | I20: ＝EBITDA − D&A − 利息
A21: 每 MW 資本支出（新增 MW 的建置成本） | B21: US$m/MW | C21: =輸入與假設!C$120*輸入與假設!$C$118 -> 34.759438 | D21: =輸入與假設!D$120*輸入與假設!$C$118 -> 37.515928 | E21: =輸入與假設!E$120*輸入與假設!$C$118 -> 37.586352 | F21: =輸入與假設!F$120*輸入與假設!$C$118 -> 37.586352 | G21: =輸入與假設!G$120*輸入與假設!$C$118 -> 37.586352 | I21: 存量概念（每新增 MW 一次性），與上列年化數字不同
A22: 每設施 MW 年收入 | B22: US$m/MW | C22: =C8*C6/C7 -> 8.3711443 | D22: =D8*D6/D7 -> 8.797138 | E22: =E8*E6/E7 -> 8.607844 | F22: =F8*F6/F7 -> 8.0234562 | G22: =G8*G6/G7 -> 7.2105657
A23: 每設施 MW EBITDA | B23: US$m/MW | C23: =C17*C6/C7 -> 4.8345044 | D23: =D17*D6/D7 -> 5.1902828 | E23: =E17*E6/E7 -> 5.188759 | F23: =F17*F6/F7 -> 4.7543462 | G23: =G17*G6/G7 -> 4.1035804
A24: 讀法：每 MW 收入 − 現金成本（含租金）＝EBITDA；再扣 D&A 與利息＝稅前。W3 前後對照報告直接讀本表。
A25: ▸ 世代結構推導（期初在役 → 汰換 → 新增 → 期末／平均在役；MW，公司口徑）
A26: 期初在役 MW 合計 | B26: MW | C26: =輸入與假設!$C$41 -> 1500 | D26: =C44 -> 1850 | E26: =D44 -> 3100 | F26: =E44 -> 4000 | G26: =F44 -> 4800 | I26: FY26 期初＝2026-06-30 在役（世代組合起點）；之後＝前期期末
A27: 期初在役 MW｜Hopper H100 | B27: MW | C27: =輸入與假設!$C$41*輸入與假設!$C$42 -> 409.0005 | D27: =C39 -> 409.0005 | E27: =D39 -> 409.0005 | F27: =E39 -> 409.0005 | G27: =F39 -> 309.0005
A28: 期初在役 MW｜GB200 NVL72 | B28: MW | C28: =輸入與假設!$C$41*輸入與假設!$C$43 -> 440.5005 | D28: =C40 -> 510.5005 | E28: =D40 -> 510.5005 | F28: =E40 -> 510.5005 | G28: =F40 -> 510.5005
A29: 期初在役 MW｜GB300 NVL72 | B29: MW | C29: =輸入與假設!$C$41*輸入與假設!$C$44 -> 650.499 | D29: =C41 -> 930.499 | E29: =D41 -> 1555.499 | F29: =E41 -> 1555.499 | G29: =F41 -> 1555.499
A30: 期初在役 MW｜VR200 NVL72 | B30: MW | C30: =輸入與假設!$C$41*輸入與假設!$C$45 -> 0 | D30: =C42 -> 0 | E30: =D42 -> 625 | F30: =E42 -> 1525 | G30: =F42 -> 2425
A31: 期初在役 MW｜Rubin Ultra（MGX NVL 單架，72 GPU） | B31: MW | C31: =輸入與假設!$C$41*輸入與假設!$C$46 -> 0 | D31: =C43 -> 0 | E31: =D43 -> 0 | F31: =E43 -> 0 | G31: =F43 -> 0
A32: 汰換 MW（壽命到期批次，最舊世代先出） | B32: MW | C32: =MIN(IF(2026-輸入與假設!$C$114=2023,輸入與假設!$C$115,IF(2026-輸入與假設!$C$114=2024,輸入與假設!$C$116-輸入與假設!$C$115,IF(2026-輸入與假設!$C$114=2025,輸入與假設!$C$19-輸入與假設!$C$116,0))),C26) -> 0 | D32: =MIN(IF(2027-輸入與假設!$C$114=2023,輸入與假設!$C$115,IF(2027-輸入與假設!$C$114=2024,輸入與假設!$C$116-輸入與假設!$C$115,IF(2027-輸入與假設!$C$114=2025,輸入與假設!$C$19-輸入與假設!$C$116,0))),D26) -> 0 | E32: =MIN(IF(2028-輸入與假設!$C$114=2023,輸入與假設!$C$115,IF(2028-輸入與假設!$C$114=2024,輸入與假設!$C$116-輸入與假設!$C$115,IF(2028-輸入與假設!$C$114=2025,輸入與假設!$C$19-輸入與假設!$C$116,0))),E26) -> 0 | F32: =MIN(IF(2029-輸入與假設!$C$114=2023,輸入與假設!$C$115,IF(2029-輸入與假設!$C$114=2024,輸入與假設!$C$116-輸入與假設!$C$115,IF(2029-輸入與假設!$C$114=2025,輸入與假設!$C$19-輸入與假設!$C$116,0))),F26) -> 100 | G32: =MIN(IF(2030-輸入與假設!$C$114=2023,輸入與假設!$C$115,IF(2030-輸入與假設!$C$114=2024,輸入與假設!$C$116-輸入與假設!$C$115,IF(2030-輸入與假設!$C$114=2025,輸入與假設!$C$19-輸入與假設!$C$116,0))),G26) -> 260 | I32: ＝(本年 − GPU 經濟壽命) 那年新增的 MW（與『GPU 汰換 CapEx』同一批次），由世代清單中最舊的世代先出，以當期新增世代補回
A33: 汰換出｜Hopper H100 | B33: MW | C33: =MIN(C27,C32) -> 0 | D33: =MIN(D27,D32) -> 0 | E33: =MIN(E27,E32) -> 0 | F33: =MIN(F27,F32) -> 100 | G33: =MIN(G27,G32) -> 260
A34: 汰換出｜GB200 NVL72 | B34: MW | C34: =MIN(C28,MAX(0,C32-SUM(C27:C27))) -> 0 | D34: =MIN(D28,MAX(0,D32-SUM(D27:D27))) -> 0 | E34: =MIN(E28,MAX(0,E32-SUM(E27:E27))) -> 0 | F34: =MIN(F28,MAX(0,F32-SUM(F27:F27))) -> 0 | G34: =MIN(G28,MAX(0,G32-SUM(G27:G27))) -> 0
A35: 汰換出｜GB300 NVL72 | B35: MW | C35: =MIN(C29,MAX(0,C32-SUM(C27:C28))) -> 0 | D35: =MIN(D29,MAX(0,D32-SUM(D27:D28))) -> 0 | E35: =MIN(E29,MAX(0,E32-SUM(E27:E28))) -> 0 | F35: =MIN(F29,MAX(0,F32-SUM(F27:F28))) -> 0 | G35: =MIN(G29,MAX(0,G32-SUM(G27:G28))) -> 0
A36: 汰換出｜VR200 NVL72 | B36: MW | C36: =MIN(C30,MAX(0,C32-SUM(C27:C29))) -> 0 | D36: =MIN(D30,MAX(0,D32-SUM(D27:D29))) -> 0 | E36: =MIN(E30,MAX(0,E32-SUM(E27:E29))) -> 0 | F36: =MIN(F30,MAX(0,F32-SUM(F27:F29))) -> 0 | G36: =MIN(G30,MAX(0,G32-SUM(G27:G29))) -> 0
A37: 汰換出｜Rubin Ultra（MGX NVL 單架，72 GPU） | B37: MW | C37: =MIN(C31,MAX(0,C32-SUM(C27:C30))) -> 0 | D37: =MIN(D31,MAX(0,D32-SUM(D27:D30))) -> 0 | E37: =MIN(E31,MAX(0,E32-SUM(E27:E30))) -> 0 | F37: =MIN(F31,MAX(0,F32-SUM(F27:F30))) -> 0 | G37: =MIN(G31,MAX(0,G32-SUM(G27:G30))) -> 0
A38: 新增 MW（期末 Accepted − 期初，不為負） | B38: MW | C38: =MAX(0,運營_產能與收入!C9-C26) -> 350 | D38: =MAX(0,運營_產能與收入!D9-D26) -> 1250 | E38: =MAX(0,運營_產能與收入!E9-E26) -> 900 | F38: =MAX(0,運營_產能與收入!F9-F26) -> 800 | G38: =MAX(0,運營_產能與收入!G9-G26) -> 800
A39: 期末在役 MW｜Hopper H100 | B39: MW | C39: =C27-C33+輸入與假設!C58*(C38+C32) -> 409.0005 | D39: =D27-D33+輸入與假設!D58*(D38+D32) -> 409.0005 | E39: =E27-E33+輸入與假設!E58*(E38+E32) -> 409.0005 | F39: =F27-F33+輸入與假設!F58*(F38+F32) -> 309.0005 | G39: =G27-G33+輸入與假設!G58*(G38+G32) -> 49.0005
A40: 期末在役 MW｜GB200 NVL72 | B40: MW | C40: =C28-C34+輸入與假設!C59*(C38+C32) -> 510.5005 | D40: =D28-D34+輸入與假設!D59*(D38+D32) -> 510.5005 | E40: =E28-E34+輸入與假設!E59*(E38+E32) -> 510.5005 | F40: =F28-F34+輸入與假設!F59*(F38+F32) -> 510.5005 | G40: =G28-G34+輸入與假設!G59*(G38+G32) -> 510.5005
A41: 期末在役 MW｜GB300 NVL72 | B41: MW | C41: =C29-C35+輸入與假設!C60*(C38+C32) -> 930.499 | D41: =D29-D35+輸入與假設!D60*(D38+D32) -> 1555.499 | E41: =E29-E35+輸入與假設!E60*(E38+E32) -> 1555.499 | F41: =F29-F35+輸入與假設!F60*(F38+F32) -> 1555.499 | G41: =G29-G35+輸入與假設!G60*(G38+G32) -> 1555.499
...

Sheet 資產負債_既有債務
A1: 債務明細 — 10-Q Note 10（2026-06-30）逐筆＋存量利息推導
A2: 有效利率為 10-Q 揭露值（含折價攤銷，四捨五入至整數 %）。本頁算出的存量利息連回『輸入』頁，再進入支出與資金頁
A4: 工具 | B4: 類別 | C4: 到期 | D4: 有效利率 | E4: 6/30 本金 | F4: 年化利息 | I4: 備註
A5: DDTL 1.0 | B5: 追索 | C5: 2028-03 | D5: 0.15 | E5: 1.3 | F5: =D5*E5 -> 0.195 | I5: 資產層、隨客戶付款攤還 [Verified]
A6: DDTL 2.0 | B6: 追索 | C6: 2030-08 | D6: 0.11 | E6: 3.19 | F6: =D6*E6 -> 0.3509 | I6: [Verified]
A7: DDTL 2.1 | B7: 追索 | C7: 2031-03 | D7: 0.09 | E7: 3 | F7: =D7*E7 -> 0.27 | I7: [Verified]
A8: DDTL 3.0 | B8: 追索 | C8: 2030-08 | D8: 0.09 | E8: 2.215 | F8: =D8*E8 -> 0.19935 | I8: [Verified]
A9: DDTL 5.0 | B9: 追索 | C9: 2031-11 | D9: 0.09 | E9: 1.101 | F9: =D9*E9 -> 0.09909 | I9: SOFR+4.50%；額度 3.1 [Verified]
A10: 2030 Senior Notes | B10: 追索 | C10: 2030-06 | D10: 0.1 | E10: 2 | F10: =D10*E10 -> 0.2 | I10: 到期一次還本 [Verified]
A11: 2031 9.00% Senior Notes | B11: 追索 | C11: 2031-02 | D11: 0.1 | E11: 1.75 | F11: =D11*E11 -> 0.175 | I11: [Verified]
A12: 2031 9.75% Senior Notes | B12: 追索 | C12: 2031-10 | D12: 0.1 | E12: 2.75 | F12: =D12*E12 -> 0.275 | I12: 2026-04 發行 [Verified]
A13: 2032 9.625% Senior Notes | B13: 追索 | C13: 2032-07 | D13: 0.1 | E13: 1.25 | F13: =D13*E13 -> 0.125 | I13: 2026-06 發行 [Verified]
A14: 2032 EUR Senior Notes（€2.0bn） | B14: 追索 | C14: 2032-07 | D14: 0.09 | E14: 2.279 | F14: =D14*E14 -> 0.20511 | I14: 票面 8.50%；已做換匯換利避險 [Verified]
A15: 2031 可轉債 | B15: 追索 | C15: 2031-12 | D15: 0.02 | E15: 2.588 | F15: =D15*E15 -> 0.05176 | I15: [Verified]
A16: 2032 可轉債 | B16: 追索 | C16: 2032-10 | D16: 0.02 | E16: 4 | F16: =D16*E16 -> 0.08 | I16: 票面 1.75%；2026-04 發行 [Verified]
... A20: OEM 融資（非追索） | B20: 非追索 | C20: 2026-08～2028-08 | D20: 0.09 | E20: 0.882 | F20: =D20*E20 -> 0.07938 | I20: [Verified]
A21: 合計（6/30） | E21: =SUM(E5:E20) -> 35.551 | F21: =SUM(F5:F20) -> 2.99106 | I21: 應等於 10-Q 本金合計 35.551
A22: 加權有效利率 | D22: =F21/E21 -> 0.084134342 | I22: 公司 9/17 簡報：Q2 加權 8.3%、含新可轉債 pro forma 7.8%（該口徑用票面，本頁用有效利率）
A24: 9/17 期後：2033 可轉債 | D24: 0.02875 | E24: 3.7 | F24: =D24*E24 -> 0.106375 | I24: 轉換價 $97.85；2033 到期，不在五期還本表內 [Verified]
A26: 存量利息推導（本金依 10-Q 到期表遞減）
A27: 項目 | B27: 單位 | C27: FY26 | D27: FY27 | E27: FY28 | F27: FY29 | G27: FY30 | I27: 公式／來源說明
A28: 期初本金 | B28: US$bn | C28: =E21 -> 35.551 | D28: =C30 -> 31.138 | E28: =D30 -> 24.954 | F28: =E30 -> 20.538 | G28: =F30 -> 18.117 | I28: FY26 期初為 6/30 本金（模型期起點）
A29: 排程還本 | B29: US$bn | C29: =輸入與假設!C$160 -> 4.413 | D29: =輸入與假設!D$160 -> 6.184 | E29: =輸入與假設!E$160 -> 4.416 | F29: =輸入與假設!F$160 -> 2.421 | G29: =輸入與假設!G$160 -> 3.221 | I29: 10-Q 到期表
A30: 期末本金 | B30: US$bn | C30: =C28-C29 -> 31.138 | D30: =D28-D29 -> 24.954 | E30: =E28-E29 -> 20.538 | F30: =F28-F29 -> 18.117 | G30: =G28-G29 -> 14.896
A31: 平均本金 | B31: US$bn | C31: =(C28+C30)/2 -> 33.3445 | D31: =(D28+D30)/2 -> 28.046 | E31: =(E28+E30)/2 -> 22.746 | F31: =(F28+F30)/2 -> 19.3275 | G31: =(G28+G30)/2 -> 16.5065
A32: 存量債務利息 | B32: US$bn | C32: =C31*資產負債_既有債務!$D$22*輸入與假設!C$24 -> 1.4027088 | D32: =D31*資產負債_既有債務!$D$22*輸入與假設!D$24 -> 2.3596318 | E32: =E31*資產負債_既有債務!$D$22*輸入與假設!E$24 -> 1.9137197 | F32: =F31*資產負債_既有債務!$D$22*輸入與假設!F$24 -> 1.6261065 | G32: =G31*資產負債_既有債務!$D$22*輸入與假設!G$24 -> 1.3887635 | I32: ＝平均本金×加權有效利率×期間長度。限制：假設利率組合不變（實際上 15% 的 DDTL 1.0 先到期，後期利率會略降）
