Workbook

Sheet README
A1: 世芯-KY（3661.TW）收支與估值模型 v0.1（AI 半導體 Project：運算層，ASIC 設計服務＋量產） 2026-10-25
A2: 版本：v0.1（初版）。Trainium 顆數讀台積電模型（與 markets/memory 同一份），每顆規格讀 Broadcom 模型 pa_trn（扣 HBM 口徑與 Marvell 模型相同），份額與 Marvell 合計不超過 100%；其他營收（NRE＋非 Trainium 量產）用簡化成長率。本版未做先驗。
A3: 模型命題：世芯的營收由 NRE 轉為 Trainium 量產（turnkey，含晶圓與封裝轉售、毛利率低）。FY2026 3 奈米約 15 億美元、3Q26 單季營收 260 億元；以市場層 Trainium 顆數 × 世芯份額 × 每顆營收往前推，FY2027–28 的營收與 EPS 有多少，2 奈米換代的份額與每顆營收差異有多大？
A4: 核心問題：在市場層 Trainium 顆數（CY2027 2.5 百萬顆）與 Marvell 份額口徑下，世芯 FY2027–28 的 EPS 與賣方差多少；FY2028 的 2 奈米換代靠份額還是每顆營收；現價約 17 倍前瞻 P/E 隱含哪一條路徑。
A6: 會計年度＝日曆年，FY(t)＝CY(t)，不平移。FY2025A 實績、FY2026 錨點、FY2027–FY2029 驅動因子推導、FY2030–FY2032 收斂法。金額：十億新台幣；EPS：新台幣（基本）。口徑：歸屬母公司淨利（TIFRS）。3Q26 財報約 11 月上旬公布，本版只納入 3Q26 營收實績。
A8: 驅動因子 → 推導量（全部唯讀上游，不修改）
A9: Trainium 量產：tsmc 成品的 AWS Trainium 顆數 × 情境係數（CY2028–29；tsmc／markets/memory 同字母）× 世芯份額（Assumed；CY2026 30%，CY2027 A／B／C 55%／50%／40%，CY2028 起 55%／45%／35%）×（每顆核心 6.4K × 2 奈米係數 1.5／1.2／1.0＋代購比例 0 × HBM 金額）× k_x（FY2026 以公司「3 奈米超過 15 億美元」校準）× 匯率 32。
A10: 其他營收：NRE＋非 Trainium 量產（中國 ADAS、Arm CPU、日本客戶等）由 FY2026 錨點依情境成長率推。
A11: 毛利：Trainium 量產毛利率 13%（Assumed；情境 A +1pt、C −2pt）；其他營收毛利率為 FY2026 殘差（Derived）後沿用。營業費用彈性 0.3、年增下限 8%；營業外 1.6、稅率 20%、股數 86.21M（GDR 後）。
A12: 校準：FY2026 ＝ 1H26 實績＋3Q26 營收實績（月營收）＋3Q26 指引（毛利率低至中 20%、費用與 2Q 相近）＋4Q26 假設（營收季增 15%、Trainium 為全年 15 億美元餘額）。不用券商數字（只在 Recon 對帳）。
A13: 估值：Val 第 0 節目標價＝0.5 × DCF 目標價（股東現金流＝EPS ×（1 − g／ROE），FY2027–32 明確期＋永續，r 10%、g 4%，三情境權重 0.3／0.5／0.2，情境價值負值取 0）＋0.5 × Comparable 目標價（創意、智原、聯發科、博通、邁威爾前瞻 P/E 中位數 × 12 個月後前瞻 EPS；不含 A 股）；另列 Comparable 單獨目標價、市場共識目標價與差距拆解。十年 P/E 規則值 × FY2027 EPS 保留為參考（不是目標價）。本版未做先驗，無 Andy 合理 P/E 對照。
A14: 預估期間：FY2027–FY2029 由驅動因子推導；FY2030 起為收斂法，非驅動因子推導（營收年增由 FY2029 線性收斂到 fade_g、淨利率收斂到 fade_m，FY2032 達到；PL 頁灰底）。十年平均淨利率未找到，B、C 依工作單以 FY2029 × 0.8 代替。
... A21: 公司特有：世芯 Trainium 份額 CY2027 55%／50%／40%、CY2028 起 55%／45%／35%；2 奈米每顆營收係數 1.5／1.2／1.0；Trainium 毛利率調整 +1／0／−2pt；其他營收年增 FY2027 +15%／+5%／−10%、FY2028–29 +12%／+5%／−5%。

Sheet In
A1: In — 輸入（藍字；基準欄 E，低 D、高 F）。金額：十億新台幣（NT$B）；每顆價格：千美元（US$K）；顆數：百萬顆；匯率：新台幣／美元。每個輸入附兩個來源（找不到者寫「未找到」）；公司原文算一個
A2: 標記：Verified／Interested-party／Analogy／Assumed／Derived；Analogy、Assumed 給低／高區間，不當點估計（放情境或 Sens）。SemiAnalysis 未使用。公司原文＝世芯新聞稿與法說（alchip.com）；公司說法為 Interested-party；券商、資料商、媒體為 Interested-party
A3: 鍵 | B3: 項目 | C3: 單位 | D3: 低 | E3: 基準 | F3: 高 | G3: 標記 | H3: 來源1 | I3: 來源2／說明
A4: A. AWS Trainium 顆數（tsmc 成品；與 HBM、台積電、Broadcom、Marvell 模型同一份；情境係數讀台積電模型＝markets/memory SCEN_UNITS，不另訂）
A5: u_trn_26 | B5: AWS Trainium 顆數 CY2026 | C5: 百萬顆 | E5: 2 | G5: Assumed | H5: tsmc/dist/20261025_台積電模型_v0.3.xlsx｜In!E29 | I5: markets/memory/market.py UNITS 同值（建置時檢查）
A6: u_trn_27 | B6: AWS Trainium 顆數 CY2027 | C6: 百萬顆 | E6: 2.5 | G6: Assumed | H6: tsmc/dist/20261025_台積電模型_v0.3.xlsx｜In!E30 | I6: 同上
A7: u_trn_28 | B7: AWS Trainium 顆數 CY2028 | C7: 百萬顆 | E7: 3 | G7: Assumed | H7: tsmc/dist/20261025_台積電模型_v0.3.xlsx｜In!E31 | I7: 同上
A8: g29_trn | B8: AWS Trainium CY2029 顆數成長 | C8: % | E8: 0.15 | G8: Assumed | H8: tsmc/dist/20261025_台積電模型_v0.3.xlsx｜In!E32 | I8: markets/memory 無 2029；沿用台積電模型
A9: um28_A | B9: 情境 A：CY2028 顆數 ÷ 基準 | C9: x | E9: 1 | G9: Assumed | H9: tsmc/dist/20261025_台積電模型_v0.3.xlsx｜In!E37 | I9: A＝基準；B＝AI 資本支出消化；C＝明顯下修（與台積電、Broadcom、Marvell 模型相同；markets/memory SCEN_UNITS，建置時檢查）
A10: um29_A | B10: 情境 A：CY2029 顆數 ÷ 基準 | C10: x | E10: 1 | G10: Assumed | H10: tsmc/dist/20261025_台積電模型_v0.3.xlsx｜In!E38 | I10: 同上
A11: um28_B | B11: 情境 B：CY2028 顆數 ÷ 基準 | C11: x | E11: 0.8 | G11: Assumed | H11: tsmc/dist/20261025_台積電模型_v0.3.xlsx｜In!E39 | I11: 同上
A12: um29_B | B12: 情境 B：CY2029 顆數 ÷ 基準 | C12: x | E12: 0.85 | G12: Assumed | H12: tsmc/dist/20261025_台積電模型_v0.3.xlsx｜In!E40 | I12: 同上
A13: um28_C | B13: 情境 C：CY2028 顆數 ÷ 基準 | C13: x | E13: 0.6 | G13: Assumed | H13: tsmc/dist/20261025_台積電模型_v0.3.xlsx｜In!E41 | I13: 同上
A14: um29_C | B14: 情境 C：CY2029 顆數 ÷ 基準 | C14: x | E14: 0.6 | G14: Assumed | H14: tsmc/dist/20261025_台積電模型_v0.3.xlsx｜In!E42 | I14: 同上
A15: gb_trn_26 | B15: AWS Trainium 每顆 HBM CY2026 | C15: GB | E15: 110 | G15: Derived／Assumed | H15: markets/memory/market.py UNITS | I15: CY2029 沿用 CY2028；Marvell 模型同值
A16: gb_trn_27 | B16: AWS Trainium 每顆 HBM CY2027 | C16: GB | E16: 144 | G16: Derived／Assumed | H16: markets/memory/market.py UNITS | I16: 同上
A17: gb_trn_28 | B17: AWS Trainium 每顆 HBM CY2028 | C17: GB | E17: 200 | G17: Derived／Assumed | H17: markets/memory/market.py UNITS | I17: 同上
A18: B. 每顆規格（Broadcom 模型 pa_trn，唯讀；扣 HBM 的口徑與 Marvell 模型相同）與世芯份額（Marvell 份額讀 Marvell 成品，合計 ≤ 100%）
A19: pa_trn | B19: AWS Trainium 每顆（含 HBM，模組層級） | C19: US$K | E19: 8 | G19: Derived | H19: avgo/dist/20261025_Broadcom模型_v0.2.xlsx｜In!E123 | I19: Broadcom 模型讀自 NVIDIA 模型 In 頁
A20: core_trn | B20: Trainium 每顆核心（不含 HBM）＝ 每顆 − CY2026 HBM 金額 | C20: US$K | E20: =pa_trn-gb_trn_26*hbm_A_26/1000 -> 6.394 | G20: Derived | H20: pa_trn − 110 GB × CY2026 HBM 單價（Marvell 模型 core_trn 同式） | I20: mrvl/dist/20261025_邁威爾模型_v0.2.xlsx｜In!E38 同值（建置時檢查）
A21: f_hbm_ref | B21: 對照：Broadcom 模型的 HBM 代購比例 | C21: x | D21: 0.3 | E21: 0.6 | F21: 1 | G21: Assumed | H21: avgo/dist/20261025_Broadcom模型_v0.2.xlsx｜In!E58 | I21: 世芯不沿用（見下列）；只作 Sens 高值
A22: f_al | B22: 世芯代購 HBM 並計入營收的比例 | C22: x | D22: 0 | E22: 0 | F22: 0.6 | G22: Assumed | H22: 美系外資：Trainium 4 生命週期可服務市場「不含 HBM」（旺得富 2026-08-17，Interested-party）；3Q26 毛利率約 18–25% 仍高於代購 HBM 情形 | I22: 公司未揭露 HBM 由誰採購：未找到；高值＝Broadcom 模型 0.6，只放 Sens
A23: m_hbm | B23: 代購 HBM 的毛利率（只在 f_al > 0 時有作用） | C23: x | D23: 0 | E23: 0.1 | F23: 0.2 | G23: Assumed | H23: avgo/dist/20261025_Broadcom模型_v0.2.xlsx｜In!E59 | I23: 沿用 Broadcom 模型
A24: mv_trn_26 | B24: Marvell 占 AWS Trainium 顆數 CY2026（份額加總檢查用） | C24: % | E24: 0.1 | G24: Assumed | H24: mrvl/dist/20261025_邁威爾模型_v0.2.xlsx｜In!E45 | I24: Marvell 模型；Marvell（基準）＋世芯（高）≤ 100%（建置時檢查）
A25: mv_trn_27 | B25: Marvell 占 AWS Trainium 顆數 CY2027（份額加總檢查用） | C25: % | E25: 0.1 | G25: Assumed | H25: mrvl/dist/20261025_邁威爾模型_v0.2.xlsx｜In!E46 | I25: Marvell 模型；Marvell（基準）＋世芯（高）≤ 100%（建置時檢查）
A26: mv_trn_28 | B26: Marvell 占 AWS Trainium 顆數 CY2028（份額加總檢查用） | C26: % | E26: 0.08 | G26: Assumed | H26: mrvl/dist/20261025_邁威爾模型_v0.2.xlsx｜In!E47 | I26: Marvell 模型；Marvell（基準）＋世芯（高）≤ 100%（建置時檢查）
A27: al_trn_26 | B27: 世芯占 AWS Trainium 顆數 CY2026（三情境相同，校準年） | C27: % | D27: 0.2 | E27: 0.3 | F27: 0.4 | G27: Assumed | H27: 公司：3 奈米 AI 加速器 5 月底量產、6 月出貨給北美雲端客戶（2Q26 新聞稿）；Trainium 3 主供應商為世芯（Marvell 模型引 Dolphin Research，二手） | I27: CY2026 份額只用於校準（k_x 吸收）；CY2027 起 A 最有利、C 最不利；高值以 1 − Marvell 基準為上限
A28: al27_A | B28: 世芯占 AWS Trainium 顆數 CY2027（情境 A） | C28: % | D28: 0.4 | E28: 0.55 | F28: 0.75 | G28: Assumed | H28: 同上 | I28: CY2026 份額只用於校準（k_x 吸收）；CY2027 起 A 最有利、C 最不利；高值以 1 − Marvell 基準為上限
A29: al27_B | B29: 世芯占 AWS Trainium 顆數 CY2027（情境 B） | C29: % | D29: 0.4 | E29: 0.5 | F29: 0.75 | G29: Assumed | H29: 同上 | I29: —
A30: al27_C | B30: 世芯占 AWS Trainium 顆數 CY2027（情境 C） | C30: % | D30: 0.3 | E30: 0.4 | F30: 0.75 | G30: Assumed | H30: 同上 | I30: —
A31: al28_A | B31: 世芯占 AWS Trainium 顆數 CY2028（情境 A；CY2029 沿用） | C31: % | D31: 0.35 | E31: 0.55 | F31: 0.85 | G31: Assumed | H31: 同上 | I31: CY2026 份額只用於校準（k_x 吸收）；CY2027 起 A 最有利、C 最不利；高值以 1 − Marvell 基準為上限
A32: al28_B | B32: 世芯占 AWS Trainium 顆數 CY2028（情境 B；CY2029 沿用） | C32: % | D32: 0.3 | E32: 0.45 | F32: 0.85 | G32: Assumed | H32: 同上 | I32: CY2028 為 Trainium 4（2 奈米）換代；世芯負責後段設計（法說），2028 份額未揭露：未找到
A33: al28_C | B33: 世芯占 AWS Trainium 顆數 CY2028（情境 C；CY2029 沿用） | C33: % | D33: 0.2 | E33: 0.35 | F33: 0.85 | G33: Assumed | H33: 同上 | I33: CY2028 為 Trainium 4（2 奈米）換代；世芯負責後段設計（法說），2028 份額未揭露：未找到
A34: pfc_A | B34: CY2028 起每顆營收係數（2 奈米 Trainium 4；情境 A） | C34: x | D34: 0.8 | E34: 1.5 | F34: 2.5 | G34: Assumed | H34: 公司：2 奈米產品價格「遠高於」3 奈米、出貨量高於 3 奈米（2Q26 法說，鉅亨網） | I34: 美系外資：Trainium 4 每顆超過 1 萬美元、2028 年 40 萬顆（時報資訊 2026-08-14，Interested-party）；主要客戶採 COT 模式（法說），每顆營收可能不升反降
A35: pfc_B | B35: CY2028 起每顆營收係數（2 奈米 Trainium 4；情境 B） | C35: x | E35: 1.2 | G35: Assumed | H35: 同上 | I35: A 最有利、C 最不利
A36: pfc_C | B36: CY2028 起每顆營收係數（2 奈米 Trainium 4；情境 C） | C36: x | E36: 1 | G36: Assumed | H36: 同上 | I36: A 最有利、C 最不利
A37: uf | B37: 世芯 Trainium 顆數係數（Sens 用；CY2027 起） | C37: x | D37: 0.8 | E37: 1 | F37: 1.2 | G37: Assumed | H37: 無 | I37: ±20%
A38: m_trn | B38: Trainium 量產（turnkey）毛利率（FY2026 校準與 4Q26 用） | C38: x | D38: 0.1 | E38: 0.13 | F38: 0.16 | G38: Assumed | H38: 公司：3Q、4Q26 綜合毛利率「20 幾」、全年低至中 20%（2Q26 法說，Investing.com 逐字稿） | I38: Q 頁核對：以 13% 推得非 Trainium 毛利率 1Q–3Q26 約 48–50%，與 1Q26 50.2% 一致
A39: gta_A | B39: Trainium 量產毛利率調整（FY2027 起；情境 A） | C39: pt | E39: 0.01 | G39: Assumed | H39: 公司：2 奈米專案毛利率至少與 3 奈米相當、可能更高（2Q26 法說） | I39: A 最有利、C 最不利
A40: gta_B | B40: Trainium 量產毛利率調整（FY2027 起；情境 B） | C40: pt | E40: 0 | G40: Assumed | H40: 同上 | I40: A 最有利、C 最不利
...

Sheet Q
A1: Q — 實績與 FY2026 錨點（十億新台幣；EPS 為新台幣、基本；股數為十億股）。藍字＝輸入（公司新聞稿與媒體轉述財報）；黑字＝公式。Trainium 與其他營收的拆分為 Assumed（公司未揭露）
A2: FY2026 錨點＝1Q、2Q26 實績＋3Q26 營收實績（月營收）與指引（毛利率、費用）＋4Q26 假設；Trainium 全年取公司「3 奈米超過 15 億美元」，4Q26 為全年減 2Q、3Q。3Q26 財報與法說約 11 月上旬（確切日期未找到），屆時以實績取代 E 欄
A3: 項目 | B3: FY2025A | C3: 1Q26（實績） | D3: 2Q26（實績） | E3: 3Q26（營收實績＋指引） | F3: 4Q26（模型） | G3: FY2026 錨點 | H3: 標記 | I3: 來源1 | J3: 來源2／說明
A4: 營收 | B4: 30.926 | C4: 4.187 | D4: 7.64 | E4: =q3_rev -> 26.051 | F4: =E4*(1+q4_g) -> 29.95865 | G4: =SUM(C4:F4) -> 67.83665 | H4: Verified／Assumed（4Q） | I4: FY2025：經濟日報 2026-03-06、stockanalysis；1Q26、2Q26：工商時報 2026-08-14（公司財報） | J4: 3Q26：月營收實績（科技新報）；FY2025 經濟日報 309.3 億
A5: Trainium 量產（3 奈米 AI 加速器，北美雲端客戶） | B5: 0 | C5: 0 | D5: =q2_trn -> 3 | E5: =E4*q3_trnsh -> 20.8408 | F5: =dc26*fx26-D5-E5 -> 23.5592 | G5: =SUM(C5:F5) -> 47.4 | H5: Interested-party／Assumed | I5: 公司：5 月底量產、6 月出貨（2Q26 新聞稿） | J5: FY2025 視為 0（3 奈米 Trainium 量產自 2026-05）；4Q＝全年 15 億美元 × 匯率 − 2Q − 3Q
A6: 其他（NRE＋非 Trainium 量產） | B6: =B4-B5 -> 30.926 | C6: =C4-C5 -> 4.187 | D6: =D4-D5 -> 4.64 | E6: =E4-E5 -> 5.2102 | F6: =F4-F5 -> 6.39945 | G6: =SUM(C6:F6) -> 20.43665 | H6: Derived | I6: — | J6: —
A7: 毛利 | B7: 8.154 | C7: 2.101 | D7: 2.662 | E7: =E4*q3_gm -> 5.47071 | F7: =m_trn*F5+q4_gmo*F6 -> 6.134432 | G7: =SUM(C7:F7) -> 16.368142 | H7: Verified／Interested-party（3Q）／Assumed（4Q） | I7: FY2025：經濟日報 2026-03-06、stockanalysis；1Q26、2Q26：工商時報 2026-08-14（公司財報） | J7: 1Q26＝1H26 47.63 億 − 2Q26 26.62 億；4Q：Trainium × m_trn ＋ 其他 × q4_gmo
A8: 毛利率 | B8: =B7/B4 -> 0.26366164 | C8: =C7/C4 -> 0.50179126 | D8: =D7/D4 -> 0.34842932 | E8: =E7/E4 -> 0.21 | F8: =F7/F4 -> 0.2047633 | G8: =G7/G4 -> 0.24128759 | H8: Derived | I8: — | J8: 公司：FY2025 26.4%、1Q26 50.2%、2Q26 34.8%
A9: 核對：非 Trainium 毛利率（以 m_trn 推得） | C9: =(C7-m_trn*C5)/C6 -> 0.50179126 | D9: =(D7-m_trn*D5)/D6 -> 0.48965517 | E9: =(E7-m_trn*E5)/E6 -> 0.53 | F9: =(F7-m_trn*F5)/F6 -> 0.48 | H9: Derived | I9: — | J9: 1Q–3Q 應接近 4Q 假設 q4_gmo
A10: 營業費用 | B10: =8.154-5.016 -> 3.138 | C10: =2.101-1.367 -> 0.734 | D10: =2.662-1.647 -> 1.015 | E10: =q3_opx -> 1.05 | F10: =q4_opx -> 1.05 | G10: =SUM(C10:F10) -> 3.849 | H10: Derived／Interested-party／Assumed | I10: FY2025：經濟日報 2026-03-06、stockanalysis；1Q26、2Q26：工商時報 2026-08-14（公司財報） | J10: 毛利 − 營業利益
A11: 營業利益 | B11: 5.016 | C11: 1.367 | D11: 1.647 | E11: =E7-E10 -> 4.42071 | F11: =F7-F10 -> 5.084432 | G11: =SUM(C11:F11) -> 12.519142 | H11: Verified／Derived | I11: FY2025：經濟日報 2026-03-06、stockanalysis；1Q26、2Q26：工商時報 2026-08-14（公司財報） | J11: 1Q26＝1H26 30.14 億 − 2Q26 16.47 億
A12: 營業外淨額 | B12: =B13-B11 -> 1.7042198 | C12: =C13-C11 -> 0.417 | D12: =D13-D11 -> 0.388 | E12: =q_nonop -> 0.4 | F12: =q_nonop -> 0.4 | G12: =SUM(C12:F12) -> 1.605 | H12: Derived／Assumed | I12: FY2025：經濟日報 2026-03-06、stockanalysis；1Q26、2Q26：工商時報 2026-08-14（公司財報） | J12: 稅前 − 營業利益
A13: 稅前利益 | B13: =30.926*0.2173 -> 6.7202198 | C13: 1.784 | D13: 2.035 | E13: =E11+E12 -> 4.82071 | F13: =F11+F12 -> 5.484432 | G13: =SUM(C13:F13) -> 14.124142 | H13: Verified／Derived | I13: FY2025：經濟日報 2026-03-06、stockanalysis；1Q26、2Q26：工商時報 2026-08-14（公司財報） | J13: FY2025＝營收 × 稅前淨利率 21.73%（stockanalysis）；1Q26＝1H26 38.19 億 − 2Q26 20.35 億
A14: 所得稅 | B14: =B13-B16 -> 1.1222198 | C14: =C13-C16 -> 0.357 | D14: =D13-D16 -> 0.396 | E14: =E13*q_tax -> 0.964142 | F14: =F13*q_tax -> 1.0968864 | G14: =SUM(C14:F14) -> 2.8140284 | H14: Derived／Assumed | I14: FY2025：經濟日報 2026-03-06、stockanalysis；1Q26、2Q26：工商時報 2026-08-14（公司財報） | J14: 稅前 − 淨利
A15: 有效稅率 | B15: =B14/B13 -> 0.16699153 | C15: =C14/C13 -> 0.20011211 | D15: =D14/D13 -> 0.19459459 | E15: =E14/E13 -> 0.2 | F15: =F14/F13 -> 0.2 | G15: =G14/G13 -> 0.19923535 | H15: Derived | I15: — | J15: —
A16: 歸屬母公司淨利 | B16: 5.598 | C16: 1.427 | D16: 1.639 | E16: =E13-E14 -> 3.856568 | F16: =F13-F14 -> 4.3875456 | G16: =SUM(C16:F16) -> 11.310114 | H16: Verified／Derived | I16: FY2025：經濟日報 2026-03-06、stockanalysis；1Q26、2Q26：工商時報 2026-08-14（公司財報） | J16: 1Q26＝1H26 30.66 億 − 2Q26 16.39 億；無重大非控制權益（假設）
A17: 加權股數（十億股） | B17: =5.598/69.18 -> 0.080919341 | C17: =1.427/17.55 -> 0.081310541 | D17: =1.639/20.02 -> 0.081868132 | E17: =q_sh -> 0.08621 | F17: =q_sh -> 0.08621 | G17: =AVERAGE(C17:F17) -> 0.083899668 | H17: Derived | I17: 淨利 ÷ EPS（公司） | J17: —
A18: EPS（基本） | B18: =B16/B17 -> 69.18 | C18: =C16/C17 -> 17.55 | D18: =D16/D17 -> 20.02 | E18: =E16/E17 -> 44.734578 | F18: =F16/F17 -> 50.893697 | G18: =G16/G17 -> 134.80522 | H18: Derived | I18: 淨利 ÷ 股數 | J18: —
A19: 公司揭露 EPS | B19: 69.18 | C19: 17.55 | D19: 20.02 | H19: Verified | I19: FY2025：經濟日報 2026-03-06、stockanalysis；1Q26、2Q26：工商時報 2026-08-14（公司財報） | J19: HiStock：FY2025 69.18、1Q26 17.55、2Q26 20.01
A21: FY2026 錨點的檢查（參考；校準未使用券商數字）
A22: FY2026 營收年增 | B22: =G4/B4-1 -> 1.1935152
A23: FY2026 Trainium ÷ 營收 | B23: =G5/G4 -> 0.69873733
A24: FY2026 其他營收年增（FY2025 全部視為其他） | B24: =G6/B6-1 -> -0.33917577
A25: 3Q26 營收季增 | B25: =E4/D4-1 -> 2.4098168
A26: 4Q26 Trainium ÷ 4Q26 營收 | B26: =F5/F4 -> 0.78639058
A27: FY2026 營業利益率 | B27: =G11/G4 -> 0.18454835
A28: 檢查：1H26 營收 自算 − 公司 11.827（應約為 0） | B28: =C4+D4-11.827 -> 0
A29: 檢查：1H26 歸屬淨利 自算 − 公司 3.066（應約為 0） | B29: =C16+D16-3.066 -> 0
A30: 檢查：FY2025 營業費用 ÷ 營收 | B30: =B10/B4 -> 0.10146802

Sheet Units
A1: Units — 世芯 Trainium 量產規格（情境 A）。每顆核心＝Broadcom 模型 pa_trn 扣 CY2026 HBM（與 Marvell 模型同口徑，唯讀）；顆數：百萬顆（日曆年；與 HBM、台積電、Broadcom、Marvell 模型同一份）；每顆價：US$K
A3: 項目 | B3: 單位 | C3: CY2026 | D3: CY2027 | E3: CY2028 | F3: CY2029 | G3: 說明
A4: 1. AWS Trainium（情境 A；世芯營收口徑＝晶片與封裝轉售，基準不含 HBM，乘 k_x）
A5: AWS Trainium 市場顆數 | B5: 百萬顆 | C5: =PL!D63 -> 2 | D5: =PL!E63 -> 2.5 | E5: =PL!F63 -> 3 | F5: =PL!G63 -> 3.45 | G5: tsmc 成品 In 頁
A6: 世芯份額：AWS Trainium | B6: % | C6: =PL!D64 -> 0.3 | D6: =PL!E64 -> 0.55 | E6: =PL!F64 -> 0.55 | F6: =PL!G64 -> 0.55 | G6: In 頁 B 節（Assumed）
A7: 世芯顆數：AWS Trainium | B7: 百萬顆 | C7: =PL!D65 -> 0.6 | D7: =PL!E65 -> 1.375 | E7: =PL!F65 -> 1.65 | F7: =PL!G65 -> 1.8975 | G7: 市場層顆數 × 份額
A8: 每顆核心（不含 HBM） | B8: US$K | C8: =PL!D68 -> 6.394 | D8: =PL!E68 -> 6.394 | E8: =PL!F68 -> 9.591 | F8: =PL!G68 -> 9.591 | G8: CY2028 起 × 2 奈米係數（情境 A 1.5）
A9: 每顆世芯營收（校準後） | B9: US$K | C9: =PL!D78 -> 2.5 | D9: =PL!E78 -> 2.5 | E9: =PL!F78 -> 3.75 | F9: =PL!G78 -> 3.75 | G9: （核心＋代購比例 × HBM）× k_x
A10: 世芯 Trainium 量產營收（美元） | B10: US$B | C10: =PL!D73 -> 1.5 | D10: =PL!E73 -> 3.4375 | E10: =PL!F73 -> 6.1875 | F10: =PL!G73 -> 7.115625 | G10: —
A12: 2. 份額加總檢查（Marvell＋世芯 ≤ 100%；Marvell 份額讀 Marvell 成品 In 頁）
A13: Marvell＋世芯：AWS Trainium（情境 A） | B13: % | C13: =mv_trn_26+PL!D64 -> 0.4 | D13: =mv_trn_27+PL!E64 -> 0.65 | E13: =mv_trn_28+PL!F64 -> 0.63 | F13: =mv_trn_28+PL!G64 -> 0.63 | G13: 其餘為 Annapurna 自行設計（COT）或其他夥伴
A14: Marvell＋世芯：AWS Trainium（情境 B） | B14: % | C14: =mv_trn_26+PL!D107 -> 0.4 | D14: =mv_trn_27+PL!E107 -> 0.6 | E14: =mv_trn_28+PL!F107 -> 0.53 | F14: =mv_trn_28+PL!G107 -> 0.53 | G14: 同上
A15: Marvell＋世芯：AWS Trainium（情境 C） | B15: % | C15: =mv_trn_26+PL!D150 -> 0.4 | D15: =mv_trn_27+PL!E150 -> 0.5 | E15: =mv_trn_28+PL!F150 -> 0.43 | F15: =mv_trn_28+PL!G150 -> 0.43 | G15: 同上
A16: 世芯 Trainium 份額上限（1 − Marvell 基準） | B16: % | C16: =1-mv_trn_26 -> 0.9 | D16: =1-mv_trn_27 -> 0.9 | E16: =1-mv_trn_28 -> 0.92 | F16: =1-mv_trn_28 -> 0.92 | G16: In 頁份額高值受此上限限制
A18: 3. 校準值（只用 FY2026 已發生的實績、當季指引與公司全年 3 奈米說法；不用共識、不用 FY2027 起的目標）
A19: 校準係數 k_x | C19: =PL!D72 -> 0.39099155 | G19: 公司 FY2026 3 奈米營收 ÷ 未校準由下而上
A20: 其他營收毛利率（FY2026 殘差） | C20: =PL!D87 -> 0.49940387 | G20: 讓 FY2026 毛利等於錨點
A21: FY2026 3 奈米營收（公司） | C21: =dc26 -> 1.5 | G21: US$B
A23: 讀法：世芯每顆營收只有 Trainium 模組價值的一部分（k_x 約 0.4），顆數與份額決定 FY2027 規模；FY2028 為 2 奈米換代，每顆營收係數與份額是 A、C 情境的主要差異。

Sheet PL
A1: PL — 世芯-KY 損益（十億新台幣；EPS 新台幣、基本；歸屬母公司）。FY2025A 實績、FY2026 錨點（三情境相同），FY2027–FY2029 由驅動因子推導，FY2030–FY2032 為收斂法。FY(t)＝CY(t)。三情境各一個完整推導區塊（本頁下方），頂端為摘要
A2: 灰底＝FY2030–FY2032 收斂法（上游顆數只到 CY2029）：營收年增線性收斂到 fade_g、淨利率線性收斂到 fade_m（In 頁 I 節），非驅動因子推導
A3: 情境／項目 | B3: 單位 | C3: FY2025A | D3: FY2026（錨點） | E3: FY2027 | F3: FY2028 | G3: FY2029 | H3: FY2030（收斂） | I3: FY2031（收斂） | J3: FY2032（收斂） | K3: 說明
A4: 情境 A
A5: 營收 | B5: NT$B | C5: =C81 -> 30.926 | D5: =D81 -> 67.83665 | E5: =E81 -> 133.50215 | F5: =F81 -> 224.32241 | G5: =G81 -> 257.18109 | H5: =H81 -> 287.43926 | I5: =I81 -> 312.97151 | J5: =J81 -> 331.7498
A6: 營收年增 | B6: % | D6: =D82 -> 1.1935152 | E6: =E82 -> 0.9679944 | F6: =F82 -> 0.68029061 | G6: =G82 -> 0.14647974 | H6: =H82 -> 0.11765316 | I6: =I82 -> 0.088826582 | J6: =J82 -> 0.06
A7: Trainium 量產 | B7: NT$B | C7: =C75 -> 0 | D7: =D75 -> 47.4 | E7: =E75 -> 110 | F7: =F75 -> 198 | G7: =G75 -> 227.7
A8: 其他（NRE＋非 Trainium 量產） | B8: NT$B | C8: =C80 -> 30.926 | D8: =D80 -> 20.43665 | E8: =E80 -> 23.502147 | F8: =F80 -> 26.322405 | G8: =G80 -> 29.481094
A9: 毛利率 | B9: % | C9: =C89 -> 0.26366164 | D9: =D89 -> 0.24128759 | E9: =E89 -> 0.20327061 | F9: =F89 -> 0.18217311 | G9: =G89 -> 0.18119906
A10: 營業利益率 | B10: % | C10: =C92 -> 0.16219362 | D10: =D92 -> 0.18454835 | E10: =E92 -> 0.16606714 | F10: =F92 -> 0.15551331 | G10: =G92 -> 0.15608515
A11: 歸屬母公司淨利 | B11: NT$B | C11: =C96 -> 5.598 | D11: =D96 -> 11.310114 | E11: =E96 -> 19.016256 | F11: =F96 -> 29.188095 | G11: =G96 -> 33.393719 | H11: =H96 -> 37.322596 | I11: =I96 -> 40.637835 | J11: =J96 -> 43.076105
A12: 淨利率 | B12: % | C12: =C100 -> 0.18101274 | D12: =D100 -> 0.16672571 | E12: =E100 -> 0.14244157 | F12: =F100 -> 0.13011672 | G12: =G100 -> 0.12984516 | H12: =H100 -> 0.12984516 | I12: =I100 -> 0.12984516 | J12: =J100 -> 0.12984516
A13: EPS | B13: NT$ | C13: =C98 -> 69.18 | D13: =D98 -> 134.80522 | E13: =E98 -> 220.58063 | F13: =F98 -> 338.56972 | G13: =G98 -> 387.3532 | H13: =H98 -> 432.92653 | I13: =I98 -> 471.38191 | J13: =J98 -> 499.66483
A14: EPS 年增 | B14: % | D14: =D99 -> 0.94861556 | E14: =E99 -> 0.63629141 | F14: =F99 -> 0.5349023 | G14: =G99 -> 0.14408696 | H14: =H99 -> 0.11765316 | I14: =I99 -> 0.088826582 | J14: =J99 -> 0.06
A16: 情境 B
A17: 營收 | B17: NT$B | C17: =C124 -> 30.926 | D17: =D124 -> 67.83665 | E17: =E124 -> 121.45848 | F17: =F124 -> 126.21141 | G17: =G124 -> 150.34198 | H17: =H124 -> 171.50929 | I17: =I124 -> 187.01326 | J17: =J124 -> 194.49379
A18: 營收年增 | B18: % | D18: =D125 -> 1.1935152 | E18: =E125 -> 0.7904552 | F18: =F125 -> 0.039132089 | G18: =G125 -> 0.19119168 | H18: =H125 -> 0.14079445 | I18: =I125 -> 0.090397225 | J18: =J125 -> 0.04
A19: Trainium 量產 | B19: NT$B | C19: =C118 -> 0 | D19: =D118 -> 47.4 | E19: =E118 -> 100 | F19: =F118 -> 103.68 | G19: =G118 -> 126.684
A20: 其他（NRE＋非 Trainium 量產） | B20: NT$B | C20: =C123 -> 30.926 | D20: =D123 -> 20.43665 | E20: =E123 -> 21.458482 | F20: =F123 -> 22.531407 | G20: =G123 -> 23.657977
A21: 毛利率 | B21: % | C21: =C132 -> 0.26366164 | D21: =D132 -> 0.24128759 | E21: =E132 -> 0.19526384 | F21: =F132 -> 0.19594641 | G21: =G132 -> 0.18812979
A22: 營業利益率 | B22: % | C22: =C135 -> 0.16219362 | D22: =D135 -> 0.18454835 | E22: =E135 -> 0.15605917 | F22: =F135 -> 0.15519987 | G22: =G135 -> 0.15118674
A23: 歸屬母公司淨利 | B23: NT$B | C23: =C139 -> 5.598 | D23: =D139 -> 11.310114 | E23: =E139 -> 16.443768 | F23: =F139 -> 16.950395 | G23: =G139 -> 19.463771 | H23: =H139 -> 21.464023 | I23: =I139 -> 22.597266 | J23: =J139 -> 22.661829
A24: 淨利率 | B24: % | C24: =C143 -> 0.18101274 | D24: =D143 -> 0.16672571 | E24: =E143 -> 0.13538592 | F24: =F143 -> 0.13430161 | G24: =G143 -> 0.12946331 | H24: =H143 -> 0.12514787 | I24: =I143 -> 0.12083243 | J24: =J143 -> 0.11651698
A25: EPS | B25: NT$ | C25: =C141 -> 69.18 | D25: =D141 -> 134.80522 | E25: =E141 -> 190.74085 | F25: =F141 -> 196.6175 | G25: =G141 -> 225.77161 | H25: =H141 -> 248.9737 | I25: =I141 -> 262.11885 | J25: =J141 -> 262.86776
A26: EPS 年增 | B26: % | D26: =D142 -> 0.94861556 | E26: =E142 -> 0.41493661 | F26: =F142 -> 0.030809647 | G26: =G142 -> 0.14827828 | H26: =H142 -> 0.10276797 | I26: =I142 -> 0.052797321 | J26: =J142 -> 0.0028571429
A28: 情境 C
A29: 營收 | B29: NT$B | C29: =C167 -> 30.926 | D29: =D167 -> 67.83665 | E29: =E167 -> 98.392985 | F29: =F167 -> 67.873336 | G29: =G167 -> 74.559669 | H29: =H167 -> 79.953411 | I29: =I167 -> 83.644912 | J29: =J167 -> 85.31781
A30: 營收年增 | B30: % | D30: =D168 -> 1.1935152 | E30: =E168 -> 0.45043992 | F30: =F168 -> -0.31018115 | G30: =G168 -> 0.098511929 | H30: =H168 -> 0.072341286 | I30: =I168 -> 0.046170643 | J30: =J168 -> 0.02
A31: Trainium 量產 | B31: NT$B | C31: =C161 -> 0 | D31: =D161 -> 47.4 | E31: =E161 -> 80 | F31: =F161 -> 50.4 | G31: =G161 -> 57.96
A32: 其他（NRE＋非 Trainium 量產） | B32: NT$B | C32: =C166 -> 30.926 | D32: =D166 -> 20.43665 | E32: =E166 -> 18.392985 | F32: =F166 -> 17.473336 | G32: =G166 -> 16.599669
A33: 毛利率 | B33: % | C33: =C175 -> 0.26366164 | D33: =D175 -> 0.24128759 | E33: =E175 -> 0.18279279 | F33: =F175 -> 0.21024827 | G33: =G175 -> 0.19669533
A34: 營業利益率 | B34: % | C34: =C178 -> 0.16219362 | D34: =D178 -> 0.18454835 | E34: =E178 -> 0.13838796 | F34: =F178 -> 0.14072682 | G34: =G178 -> 0.12834544
A35: 歸屬母公司淨利 | B35: NT$B | C35: =C182 -> 5.598 | D35: =D182 -> 11.310114 | E35: =E182 -> 12.173124 | F35: =F182 -> 8.9212789 | G35: =G182 -> 8.935515 | H35: =H182 -> 8.9431269 | I35: =I182 -> 8.6877485 | J35: =J182 -> 8.1798493
A36: 淨利率 | B36: % | C36: =C186 -> 0.18101274 | D36: =D186 -> 0.16672571 | E36: =E186 -> 0.12371943 | F36: =F186 -> 0.13144011 | G36: =G186 -> 0.11984381 | H36: =H186 -> 0.11185423 | I36: =I186 -> 0.10386464 | J36: =J186 -> 0.095875051
A37: EPS | B37: NT$ | C37: =C184 -> 69.18 | D37: =D184 -> 134.80522 | E37: =E184 -> 141.20315 | F37: =F184 -> 103.48311 | G37: =G184 -> 103.64824 | H37: =H184 -> 103.73654 | I37: =I184 -> 100.77425 | J37: =J184 -> 94.882837
A38: EPS 年增 | B38: % | D38: =D185 -> 0.94861556 | E38: =E185 -> 0.047460544 | F38: =F185 -> -0.26713315 | G38: =G185 -> 0.0015957537 | H38: =H185 -> 0.00085186675 | I38: =I185 -> -0.028555832 | J38: =J185 -> -0.058461538
A40: 核對（應為 0）：FY2026 模型 − 錨點
A41: 三情境：營收差（NT$B） | D41: =ABS(D81-a26_rev)+ABS(D124-a26_rev)+ABS(D167-a26_rev) -> 0
A42: 三情境：EPS 差（NT$） | D42: =ABS(D98-a26_eps)+ABS(D141-a26_eps)+ABS(D184-a26_eps) -> 0
A43: 情境 A：Trainium 由下而上 − Q 頁 Trainium（NT$B） | D43: =D75-a26_trn -> 0
...

Sheet Val
A1: Val — P/E 估值（新台幣）。結論用「現價 ÷ FY2027、FY2028 EPS（模型）」；目標價＝DCF 與 Comparable 加權（第 0 節）；十年 P/E 規則值（第 3 節，年底落後 P/E）只作參考
A2: 循環位置：世芯不是設備股，不套設備市場見頂年；以本模型營收最高的會計年度為見頂年（比照聯發科、Amkor；FY(t)＝CY(t)）。營收到 FY2029 仍在增加時，見頂年未知，判為中段
A4: 0. 目標價
A5: 0.1 DCF（股東權益現金流，FY2027–FY2032 明確期＋FY2032 後永續）
A6: 項目 | B6: A（順利） | C6: B（平平） | D6: C（不如預期） | E6: 說明
A7: 情境 EPS（FY2027–FY2032） | E7: PL 頁各情境；FY2030 起為收斂法
A8: FY2027 | B8: =PL!E13 -> 220.58063 | C8: =PL!E25 -> 190.74085 | D8: =PL!E37 -> 141.20315
A9: FY2028 | B9: =PL!F13 -> 338.56972 | C9: =PL!F25 -> 196.6175 | D9: =PL!F37 -> 103.48311
A10: FY2029 | B10: =PL!G13 -> 387.3532 | C10: =PL!G25 -> 225.77161 | D10: =PL!G37 -> 103.64824
A11: FY2030 | B11: =PL!H13 -> 432.92653 | C11: =PL!H25 -> 248.9737 | D11: =PL!H37 -> 103.73654
A12: FY2031 | B12: =PL!I13 -> 471.38191 | C12: =PL!I25 -> 262.11885 | D12: =PL!I37 -> 100.77425
A13: FY2032 | B13: =PL!J13 -> 499.66483 | C13: =PL!J25 -> 262.86776 | D13: =PL!J37 -> 94.882837
A14: 股東現金流＝EPS ×（1 − tp_g ÷ tp_roe）
A15: 再投資率（tp_g ÷ tp_roe，上限 0.8） | B15: =MIN(tp_g/tp_roe,0.8) -> 0.20775623 | E15: ROE 為近三年平均（In 頁 tp_roe）
A16: FY2027 | B16: =B8*(1-$B$15) -> 174.75363 | C16: =C8*(1-$B$15) -> 151.11325 | D16: =D8*(1-$B$15) -> 111.86732
A17: FY2028 | B17: =B9*(1-$B$15) -> 268.22975 | C17: =C9*(1-$B$15) -> 155.76899 | D17: =D9*(1-$B$15) -> 81.983849
A18: FY2029 | B18: =B10*(1-$B$15) -> 306.87816 | C18: =C10*(1-$B$15) -> 178.86615 | D18: =D10*(1-$B$15) -> 82.114675
A19: FY2030 | B19: =B11*(1-$B$15) -> 342.98334 | C19: =C11*(1-$B$15) -> 197.24786 | D19: =D11*(1-$B$15) -> 82.184625
A20: FY2031 | B20: =B12*(1-$B$15) -> 373.44938 | C20: =C12*(1-$B$15) -> 207.66202 | D20: =D12*(1-$B$15) -> 79.837775
A21: FY2032 | B21: =B13*(1-$B$15) -> 395.85634 | C21: =C13*(1-$B$15) -> 208.25534 | D21: =D13*(1-$B$15) -> 75.170336
A22: DCF 情境每股價值（折現率 tp_r） | B22: =MAX(0,SUMPRODUCT(B16:B21,1/(1+tp_r)^{1;2;3;4;5;6})+B21*(1+tp_g)/(tp_r-tp_g)/(1+tp_r)^6) -> 5173.8455 | C22: =MAX(0,SUMPRODUCT(C16:C21,1/(1+tp_r)^{1;2;3;4;5;6})+C21*(1+tp_g)/(tp_r-tp_g)/(1+tp_r)^6) -> 2819.3296 | D22: =MAX(0,SUMPRODUCT(D16:D21,1/(1+tp_r)^{1;2;3;4;5;6})+D21*(1+tp_g)/(tp_r-tp_g)/(1+tp_r)^6) -> 1114.7674 | E22: Σ 明確期現金流 ÷ (1＋r)^t ＋ 永續價值 ÷ (1＋r)^6；永續價值＝FY2032 現金流 ×(1＋g)÷(r−g)；基準日 2026 年底；負值取 0
A23: DCF 情境價值推到 12 個月後（×(1＋tp_r)） | B23: =B22*(1+tp_r) -> 5691.2301 | C23: =C22*(1+tp_r) -> 3101.2626 | D23: =D22*(1+tp_r) -> 1226.2441
A24: DCF 目標價（情境加權） | B24: =tp_wA*B23+tp_wB*C23+tp_wC*D23 -> 3503.2491 | E24: Σ 權重 × 情境價值 ×(1＋r)；權重見 In 頁
A26: 0.2 Comparable（市場主流同業前瞻 P/E）
A27: 同業與前瞻 P/E | B27: 代號 | C27: 前瞻 12 月 P/E | D27: 日期 | E27: 來源 | F27: 標記
A28: 創意（GUC） | B28: 3443.TW | C28: 102.85 | D28: 2026-10-08 | E28: stockanalysis.com forward PE（分析師共識；價格日期如左） | F28: Interested-party
A29: 智原（Faraday） | B29: 3035.TW | C29: 37.81 | D29: 2026-09-04 | E29: stockanalysis.com forward PE（分析師共識；價格日期如左） | F29: Interested-party
A30: 聯發科（MediaTek） | B30: 2454.TW | C30: 38.75 | D30: 2026-10-22 | E30: stockanalysis.com forward PE（分析師共識；價格日期如左） | F30: Interested-party
A31: 博通（Broadcom） | B31: AVGO | C31: 18.52 | D31: 2026-10-23 | E31: stockanalysis.com forward PE（分析師共識；價格日期如左） | F31: Interested-party
A32: 邁威爾（Marvell） | B32: MRVL | C32: 40.44 | D32: 2026-10-23 | E32: stockanalysis.com forward PE（分析師共識；價格日期如左） | F32: Interested-party
A33: 同業前瞻 P/E 中位數 | B33: =MEDIAN(C28:C32) -> 38.75 | E33: 台灣 ASIC 設計服務（創意、智原）＋ASIC 對手（聯發科、博通、邁威爾）；不含 A 股（非 A 股公司，Andy 2026-10-25 11:53）
A34: 12 個月後的前瞻 EPS（情境加權） | B34: =tp_wA*(2/12*B8+10/12*B9)+tp_wB*(2/12*C8+10/12*C9)+tp_wC*(2/12*D8+10/12*D9) -> 215.44445 | E34: 約 2027-10 時的未來 12 月 EPS ≈ 2／12 × FY2027＋10／12 × FY2028（會計年度＝日曆年）
A35: Comparable 目標價 | B35: =B33*B34 -> 8348.4724 | E35: 同業中位數 × 前瞻 EPS
A37: 0.3 結論
A38: 項目 | B38: 數值 | E38: 說明
A39: 目標價（DCF 與 Comparable 加權） | B39: =tp_w_dcf*B24+(1-tp_w_dcf)*B35 -> 5925.8607 | E39: tp_w_dcf × DCF＋（1 − tp_w_dcf）× Comparable；tp_w_dcf 見 In 頁
A40: Comparable 目標價（市場主流同業法） | B40: =B35 -> 8348.4724
A41: 市場共識目標價 | B41: =cons_tp -> 5803.25 | E41: stockanalysis：16 位分析師平均 5,803，2026-10-23 擷取
A42: 上檔空間：加權目標價 | B42: =B39/px-1 -> 0.69552525 | E42: 現價＝In 頁 px（2026-10-22 收盤）
A43: 上檔空間：Comparable 目標價 | B43: =B40/px-1 -> 1.3886902
...

Sheet Recon
A1: Recon — 本模型 vs 公司說法、共識、券商。只作事後對照，不為對上數字而調參數。券商 FY2027–28 估計與 UBS 顆數為 Interested-party，不用於校準
A3: 項目 | B3: 對照值 | C3: 模型 A | D3: 差距 A | E3: 模型 B | F3: 差距 B | G3: 模型 C | H3: 差距 C | I3: 對照來源 | J3: 說明
A4: A. FY2026 錨點 vs 公司說法與共識
A5: FY2026 營收 vs 共識 | B5: =cons_rev26 -> 70.7 | C5: =PL!D81 -> 67.83665 | D5: =C5/B5-1 -> -0.0405 | E5: =PL!D124 -> 67.83665 | F5: =E5/B5-1 -> -0.0405 | G5: =PL!D167 -> 67.83665 | H5: =G5/B5-1 -> -0.0405 | I5: stockanalysis（14 位；2026-08-13） | J5: 共識資料日在 3Q26 營收公布前（2026-08-13）；區間 35.4–86.1
A6: FY2026 EPS vs 共識 | B6: =cons_eps26 -> 135.68 | C6: =PL!D98 -> 134.80522 | D6: =C6/B6-1 -> -0.0064473448 | E6: =PL!D141 -> 134.80522 | F6: =E6/B6-1 -> -0.0064473448 | G6: =PL!D184 -> 134.80522 | H6: =G6/B6-1 -> -0.0064473448 | I6: stockanalysis（2026-08-13） | J6: 共識區間 103.06–163.01；美系外資甲 132.94
A7: FY2026 毛利率 vs 公司低至中 20%（百分點） | B7: =co_gm26 -> 0.23 | C7: =PL!D89 -> 0.24128759 | D7: =C7-B7 -> 0.011287593 | E7: =PL!D132 -> 0.24128759 | F7: =E7-B7 -> 0.011287593 | G7: =PL!D175 -> 0.24128759 | H7: =G7-B7 -> 0.011287593 | I7: 2Q26 法說
A8: FY2026 Trainium（美元）vs 美系外資甲 13 億美元 | B8: =b1_trn26 -> 1.3 | C8: =PL!D73 -> 1.5 | D8: =C8/B8-1 -> 0.15384615 | E8: =PL!D116 -> 1.5 | F8: =E8/B8-1 -> 0.15384615 | G8: =PL!D159 -> 1.5 | H8: =G8/B8-1 -> 0.15384615 | I8: 旺得富 2026-08-17 | J8: 模型取公司「超過 15 億美元」
A9: B. Trainium vs 賣方（市場層顆數 × 份額口徑）
A10: FY2027 Trainium（美元）vs 美系外資甲 22 億美元 | B10: =b1_trn27 -> 2.2 | C10: =PL!E73 -> 3.4375 | D10: =C10/B10-1 -> 0.5625 | E10: =PL!E116 -> 3.125 | F10: =E10/B10-1 -> 0.42045455 | G10: =PL!E159 -> 2.5 | H10: =G10/B10-1 -> 0.13636364 | I10: 旺得富 2026-08-17
A11: FY2027 Trainium（美元）vs 美系外資乙 AI ASIC 38 億美元 | B11: =b2_ai27 -> 3.8 | C11: =PL!E73 -> 3.4375 | D11: =C11/B11-1 -> -0.095394737 | E11: =PL!E116 -> 3.125 | F11: =E11/B11-1 -> -0.17763158 | G11: =PL!E159 -> 2.5 | H11: =G11/B11-1 -> -0.34210526 | I11: 旺得富 2026-08-17 | J11: 美系外資乙口徑含其他 AI ASIC
A12: FY2028 Trainium（美元）vs 美系外資 Trainium 4 40 億美元 | B12: =b1_trn4 -> 4 | C12: =PL!F73 -> 6.1875 | D12: =C12/B12-1 -> 0.546875 | E12: =PL!F116 -> 3.24 | F12: =E12/B12-1 -> -0.19 | G12: =PL!F159 -> 1.575 | H12: =G12/B12-1 -> -0.60625 | I12: 旺得富、時報資訊 | J12: 對照值不含 3 奈米尾量；美系外資丙情境 90–120 億美元
A13: CY2027 市場層 Trainium 顆數 vs UBS Trainium 3 出貨 | B13: =ubs_trn27 -> 2.8 | C13: =PL!E63 -> 2.5 | D13: =C13/B13-1 -> -0.10714286 | E13: =PL!E106 -> 2.5 | F13: =E13/B13-1 -> -0.10714286 | G13: =PL!E149 -> 2.5 | H13: =G13/B13-1 -> -0.10714286 | I13: 理財周刊轉述 UBS | J13: 市場層含全部 Trainium 世代仍低於 UBS 的 Trainium 3；修訂應由市場層提出
A14: CY2027 世芯顆數 ÷ UBS Trainium 3 出貨 | C14: =PL!E65/ubs_trn27 -> 0.49107143 | E14: =PL!E108/ubs_trn27 -> 0.44642857 | G14: =PL!E151/ubs_trn27 -> 0.35714286 | I14: 推導 | J14: 世芯為 Trainium 3 主供應商時，此值應接近 100%
A15: FY2027 每顆世芯營收（校準後） | C15: =PL!E78 -> 2.5 | E15: =PL!E121 -> 2.5 | G15: =PL!E164 -> 2.5 | I15: 推導 | J15: US$K；k_x × 核心
A16: C. EPS 與營收 vs 券商（校準未使用）
A17: FY2027 EPS vs 美系外資甲 | B17: =b1_eps27 -> 204.17 | C17: =PL!E98 -> 220.58063 | D17: =C17/B17-1 -> 0.080377285 | E17: =PL!E141 -> 190.74085 | F17: =E17/B17-1 -> -0.065774371 | G17: =PL!E184 -> 141.20315 | H17: =G17/B17-1 -> -0.30840401 | I17: 旺得富 2026-08-17
A18: FY2027 EPS vs 理財周刊作者 | B18: =aut_eps27 -> 195 | C18: =PL!E98 -> 220.58063 | D18: =C18/B18-1 -> 0.13118272 | E18: =PL!E141 -> 190.74085 | F18: =E18/B18-1 -> -0.021841812 | G18: =PL!E184 -> 141.20315 | H18: =G18/B18-1 -> -0.27588126 | I18: 理財周刊 2026-09-06
A19: FY2027 營收 vs 理財周刊作者 | B19: =aut_rev27 -> 110.4 | C19: =PL!E81 -> 133.50215 | D19: =C19/B19-1 -> 0.20925858 | E19: =PL!E124 -> 121.45848 | F19: =E19/B19-1 -> 0.10016741 | G19: =PL!E167 -> 98.392985 | H19: =G19/B19-1 -> -0.10875919 | I19: 理財周刊 2026-09-06
A20: 共識前瞻 12 月 EPS vs 模型（情境加權 2／12 × FY2027＋10／12 × FY2028） | B20: =cons_feps -> 203.79009 | C20: =Val!B34 -> 215.44445 | D20: =C20/B20-1 -> 0.057188066 | E20: =Val!B34 -> 215.44445 | F20: =E20/B20-1 -> 0.057188066 | G20: =Val!B34 -> 215.44445 | H20: =G20/B20-1 -> 0.057188066 | I20: stockanalysis 前瞻 P/E 推得 | J20: 三欄同值（情境加權）
A21: D. 校準與份額
A22: k_x（校準係數） | C22: =PL!D72 -> 0.39099155 | E22: =PL!D115 -> 0.39099155 | G22: =PL!D158 -> 0.39099155 | I22: 公司 FY2026 3 奈米營收 ÷ 未校準 | J22: < 1：世芯營收為晶片與封裝轉售，不含模組其他價值；CY2026 只有約 7 個月量產
A23: 其他營收毛利率（FY2026 殘差） | C23: =PL!D87 -> 0.49940387 | E23: =PL!D130 -> 0.49940387 | G23: =PL!D173 -> 0.49940387 | I23: FY2026 毛利殘差 | J23: 1Q26 綜合毛利率 50.2%（NRE 比重高）
A24: CY2028 Marvell＋世芯 Trainium 份額 | B24: 1 | C24: =Units!E13 -> 0.63 | D24: =C24-B24 -> -0.37 | E24: =Units!E14 -> 0.53 | F24: =E24-B24 -> -0.47 | G24: =Units!E15 -> 0.43 | H24: =G24-B24 -> -0.57 | I24: mrvl 成品 | J24: 應 ≤ 100%
A25: FY2027 其他營收 ÷ 營收 vs 公司 NRE 10–20%（百分點） | B25: =co_nre -> 0.15 | C25: =PL!E84 -> 0.17604322 | D25: =C25-B25 -> 0.026043217 | E25: =PL!E127 -> 0.1766734 | F25: =E25-B25 -> 0.026673395 | G25: =PL!E170 -> 0.18693391 | H25: =G25-B25 -> 0.036933906 | I25: 2Q26 法說 | J25: 其他營收含非 Trainium 量產，應高於 NRE 比重
A26: E. 預留
A27: R4 產業部署路徑（markets/deploy_path/，尚未建立）：上線後以世芯 Trainium 營收 ÷ 部署 GW 對照 Tokenomics 非 NVIDIA 加速器比例 | J27: 預留列：本版無數值

Sheet Sens
A1: Sens — 一次動一個輸入（情境 A；FY2026 恆等於錨點，k_x 與其他營收毛利率在每個案例內重算）：對 FY2027、FY2028 營收、毛利率與 EPS 的影響。每個案例是一個完整推導區塊（本頁下方）
A3: 案例 | B3: 設定 | C3: FY2027 營收 | D3: FY2027 毛利率 | E3: FY2027 EPS | F3: FY2027 EPS 相對基準 | G3: FY2028 營收 | H3: FY2028 毛利率 | I3: FY2028 EPS | J3: FY2028 EPS 相對基準
A4: 基準（情境 A） | B4: PL 區塊 A | C4: =PL!E81 -> 133.50215 | D4: =PL!E89 -> 0.20327061 | E4: =PL!E98 -> 220.58063 | F4: =E4/E$4-1 -> 0 | G4: =PL!F81 -> 224.32241 | H4: =PL!F89 -> 0.18217311 | I4: =PL!F98 -> 338.56972 | J4: =I4/I$4-1 -> 0
A5: Trainium 份額 −10pt | B5: CY2027 起世芯占 Trainium −10 個百分點 | C5: =E61 -> 113.50215 | D5: =E69 -> 0.21441941 | E5: =E78 -> 197.75669 | F5: =E5/E$4-1 -> -0.10347208 | G5: =F61 -> 188.32241 | H5: =F69 -> 0.19023499 | I5: =F78 -> 295.87574 | J5: =I5/I$4-1 -> -0.126101
A6: Trainium 份額取高值 | B6: CY2027 75%、CY2028 起 85%（上限 1 − Marvell） | C6: =E104 -> 173.50215 | D6: =E112 -> 0.18868391 | E6: =E121 -> 266.22851 | F6: =E6/E$4-1 -> 0.20694417 | G6: =F104 -> 332.32241 | H6: =F112 -> 0.16846746 | I6: =F121 -> 467.57438 | J6: =I6/I$4-1 -> 0.38102836
A7: 顆數 ×0.8 | B7: CY2027 起世芯顆數 ×0.8 | C7: =E147 -> 111.50215 | D7: =E155 -> 0.21575426 | E7: =E164 -> 195.4743 | F7: =E7/E$4-1 -> -0.11381929 | G7: =F147 -> 184.72241 | H7: =F155 -> 0.191214 | I7: =F164 -> 291.60946 | J7: =I7/I$4-1 -> -0.13870188
A8: 顆數 ×1.2 | B8: ×1.2（市場層 Trainium 顆數低於 UBS 估計） | C8: =E190 -> 155.50215 | D8: =E198 -> 0.19431927 | E8: =E207 -> 245.68696 | F8: =E8/E$4-1 -> 0.11381929 | G8: =F190 -> 263.92241 | H8: =F198 -> 0.17584529 | I8: =F207 -> 385.5801 | J8: =I8/I$4-1 -> 0.13884994
A9: 2 奈米每顆營收 ×2.5 | B9: CY2028 起（美系外資：Trainium 4 每顆超過 1 萬美元） | C9: =E233 -> 133.50215 | D9: =E241 -> 0.20327061 | E9: =E250 -> 220.58063 | F9: =E9/E$4-1 -> 0 | G9: =F233 -> 356.32241 | H9: =F241 -> 0.16655004 | I9: =F250 -> 496.38661 | J9: =I9/I$4-1 -> 0.46612819
A10: 2 奈米每顆營收 ×0.8 | B10: CY2028 起（COT 模式、客戶自購晶圓） | C10: =E276 -> 133.50215 | D10: =E284 -> 0.20327061 | E10: =E293 -> 220.58063 | F10: =E10/E$4-1 -> 0 | G10: =F276 -> 131.92241 | H10: =F284 -> 0.21171166 | I10: =F293 -> 224.2471 | J10: =I10/I$4-1 -> -0.33766344
A11: 代購 HBM 0.6 | B11: 比照 Broadcom 模型（k_x 重算） | C11: =E319 -> 153.04237 | D11: =E327 -> 0.18771927 | E11: =E336 -> 232.26679 | F11: =E11/E$4-1 -> 0.052979067 | G11: =F319 -> 260.62635 | H11: =F327 -> 0.16766731 | I11: =F336 -> 360.80811 | J11: =I11/I$4-1 -> 0.065683355
A12: Trainium 毛利率 10% | B12: 基準 13%（＋情境 A 調整 1pt） | C12: =E362 -> 133.50215 | D12: =E370 -> 0.19080115 | E12: =E379 -> 205.13277 | F12: =E12/E$4-1 -> -0.070032713 | G12: =F362 -> 224.32241 | H12: =F370 -> 0.16385812 | I12: =F379 -> 300.44454 | J12: =I12/I$4-1 -> -0.11260657
A13: Trainium 毛利率 16% | C13: =E405 -> 133.50215 | D13: =E413 -> 0.21574007 | E13: =E422 -> 236.02849 | F13: =E13/E$4-1 -> 0.070032713 | G13: =F405 -> 224.32241 | H13: =F413 -> 0.20048811 | I13: =F422 -> 376.69489 | J13: =I13/I$4-1 -> 0.11260657
A14: 其他營收 情境 C 路徑 | B14: FY2027 −10%、之後 −5% | C14: =E448 -> 128.39299 | D14: =E456 -> 0.19148653 | E14: =E465 -> 197.71026 | F14: =E14/E$4-1 -> -0.1036826 | G14: =F448 -> 215.47334 | H14: =F456 -> 0.16914507 | I14: =F465 -> 298.56015 | J14: =I14/I$4-1 -> -0.11817232
A15: 其他營收毛利率 −3pt | B15: FY2027 起 | C15: =E491 -> 133.50215 | D15: =E499 -> 0.19798932 | E15: =E508 -> 214.03787 | F15: =E15/E$4-1 -> -0.029661545 | G15: =F491 -> 224.32241 | H15: =F499 -> 0.17865286 | I15: =F508 -> 331.24182 | J15: =I15/I$4-1 -> -0.021643678
A16: 營業費用彈性 0.6 | B16: 基準 0.3 | C16: =E534 -> 133.50215 | D16: =E542 -> 0.20327061 | E16: =E551 -> 210.20835 | F16: =E16/E$4-1 -> -0.047022637 | G16: =F534 -> 224.32241 | H16: =F542 -> 0.18217311 | I16: =F551 -> 314.55741 | J16: =I16/I$4-1 -> -0.070922774
A17: 營業費用率 +2pt | B17: 營業費用額外 +2% × 營收 | C17: =E577 -> 133.50215 | D17: =E585 -> 0.20327061 | E17: =E594 -> 195.80352 | F17: =E17/E$4-1 -> -0.11232676 | G17: =F577 -> 224.32241 | H17: =F585 -> 0.18217311 | I17: =F594 -> 267.10318 | J17: =I17/I$4-1 -> -0.21108366
A18: 匯率 30 | B18: 基準 32（Trainium 美元營收換算） | C18: =E620 -> 126.62715 | D18: =E628 -> 0.20670578 | E18: =E637 -> 212.7349 | F18: =E18/E$4-1 -> -0.035568529 | G18: =F620 -> 211.94741 | H18: =F628 -> 0.18463548 | I18: =F637 -> 323.88802 | J18: =I18/I$4-1 -> -0.043363871
A19: 稅率 25% | B19: 基準 20% | C19: =E663 -> 133.50215 | D19: =E671 -> 0.20327061 | E19: =E680 -> 206.79434 | F19: =E19/E$4-1 -> -0.0625 | G19: =F663 -> 224.32241 | H19: =F671 -> 0.18217311 | I19: =F680 -> 317.40911 | J19: =I19/I$4-1 -> -0.0625
A20: 營業外 1.0 | B20: 基準 1.6 | C20: =E706 -> 133.50215 | D20: =E714 -> 0.20327061 | E20: =E723 -> 215.01283 | F20: =E20/E$4-1 -> -0.025241562 | G20: =F706 -> 224.32241 | H20: =F714 -> 0.18217311 | I20: =F723 -> 333.00192 | J20: =I20/I$4-1 -> -0.016445061
A21: 情境 B | B21: 顆數 B；份額 50%／45%；2 奈米 ×1.2；其他營收 +5% | C21: =PL!E124 -> 121.45848 | D21: =PL!E132 -> 0.19526384 | E21: =PL!E141 -> 190.74085 | F21: =E21/E$4-1 -> -0.13527835 | G21: =PL!F124 -> 126.21141 | H21: =PL!F132 -> 0.19594641 | I21: =PL!F141 -> 196.6175 | J21: =I21/I$4-1 -> -0.41927026
A22: 情境 C | B22: 顆數 C；份額 40%／35%；Trainium 毛利率 −2pt；其他營收 −10% | C22: =PL!E167 -> 98.392985 | D22: =PL!E175 -> 0.18279279 | E22: =PL!E184 -> 141.20315 | F22: =E22/E$4-1 -> -0.35985697 | G22: =PL!F167 -> 67.873336 | H22: =PL!F175 -> 0.21024827 | I22: =PL!F184 -> 103.48311 | J22: =I22/I$4-1 -> -0.69435214
A24: 讀法：FY2027 三情境差在世芯份額、Trainium 毛利率與其他營收；顆數情境 B、C 的差異從 FY2028 起。FY2028 最大的單一變數是 2 奈米每顆營收係數（價格遠高於 3 奈米 vs COT 模式），其次是份額與顆數。
A26: 目標價參數（只改 DCF 參數；PL 收斂法的 fade_g 不隨 tp_g 變動）
A27: 案例 | B27: 設定 | C27: DCF 目標價 | D27: Comparable 目標價 | E27: 加權目標價 | F27: 相對基準
A28: 基準 | B28: r 10%、g 4%、DCF 權重 0.5 | C28: =(tp_wA*MAX(0,Val!B8*(1-MIN(tp_g/tp_roe,0.8))/(1+tp_r)^1+Val!B9*(1-MIN(tp_g/tp_roe,0.8))/(1+tp_r)^2+Val!B10*(1-MIN(tp_g/tp_roe,0.8))/(1+tp_r)^3+Val!B11*(1-MIN(tp_g/tp_roe,0.8))/(1+tp_r)^4+Val!B12*(1-MIN(tp_g/tp_roe,0.8))/(1+tp_r)^5+Val!B13*(1-MIN(tp_g/tp_roe,0.8))/(1+tp_r)^6+Val!B13*(1-MIN(tp_g/tp_roe,0.8))*(1+tp_g)/(tp_r-tp_g)/(1+tp_r)^6)+tp_wB*MAX(0,Val!C8*(1-MIN(tp_g/tp_roe,0.8))/(1+tp_r)^1+Val!C9*(1-MIN(tp_g/tp_roe,0.8))/(1+tp_r)^2+Val!C10*(1-MIN(tp_g/tp_roe,0.8))/(1+tp_r)^3+Val!C11*(1-MIN(tp_g/tp_roe,0.8))/(1+tp_r)^4+Val!C12*(1-MIN(tp_g/tp_roe,0.8))/(1+tp_r)^5+Val!C13*(1-MIN(tp_g/tp_roe,0.8))/(1+tp_r)^6+Val!C13*(1-MIN(tp_g/tp_roe,0.8))*(1+tp_g)/(tp_r-tp_g)/(1+tp_r)^6)+tp_wC*MAX(0,Val!D8*(1-MIN(tp_g/tp_roe,0.8))/(1+tp_r)^1+Val!D9*(1-MIN(tp_g/tp_roe,0.8))/(1+tp_r)^2+Val!D10*(1-MIN(tp_g/tp_roe,0.8))/(1+tp_r)^3+Val!D11*(1-MIN(tp_g/tp_roe,0.8))/(1+tp_r)^4+Val!D12*(1-MIN(tp_g/tp_roe,0.8))/(1+tp_r)^5+Val!D13*(1-MIN(tp_g/tp_roe,0.8))/(1+tp_r)^6+Val!D13*(1-MIN(tp_g/tp_roe,0.8))*(1+tp_g)/(tp_r-tp_g)/(1+tp_r)^6))*(1+tp_r) -> 3503.2491 | D28: =Val!B35 -> 8348.4724 | E28: =tp_w_dcf*C28+(1-tp_w_dcf)*D28 -> 5925.8607 | F28: =E28/E$28-1 -> 0
A29: 折現率 +1pt | B29: r 11% | C29: =(tp_wA*MAX(0,Val!B8*(1-MIN(tp_g/tp_roe,0.8))/(1+(tp_r+0.01))^1+Val!B9*(1-MIN(tp_g/tp_roe,0.8))/(1+(tp_r+0.01))^2+Val!B10*(1-MIN(tp_g/tp_roe,0.8))/(1+(tp_r+0.01))^3+Val!B11*(1-MIN(tp_g/tp_roe,0.8))/(1+(tp_r+0.01))^4+Val!B12*(1-MIN(tp_g/tp_roe,0.8))/(1+(tp_r+0.01))^5+Val!B13*(1-MIN(tp_g/tp_roe,0.8))/(1+(tp_r+0.01))^6+Val!B13*(1-MIN(tp_g/tp_roe,0.8))*(1+tp_g)/((tp_r+0.01)-tp_g)/(1+(tp_r+0.01))^6)+tp_wB*MAX(0,Val!C8*(1-MIN(tp_g/tp_roe,0.8))/(1+(tp_r+0.01))^1+Val!C9*(1-MIN(tp_g/tp_roe,0.8))/(1+(tp_r+0.01))^2+Val!C10*(1-MIN(tp_g/tp_roe,0.8))/(1+(tp_r+0.01))^3+Val!C11*(1-MIN(tp_g/tp_roe,0.8))/(1+(tp_r+0.01))^4+Val!C12*(1-MIN(tp_g/tp_roe,0.8))/(1+(tp_r+0.01))^5+Val!C13*(1-MIN(tp_g/tp_roe,0.8))/(1+(tp_r+0.01))^6+Val!C13*(1-MIN(tp_g/tp_roe,0.8))*(1+tp_g)/((tp_r+0.01)-tp_g)/(1+(tp_r+0.01))^6)+tp_wC*MAX(0,Val!D8*(1-MIN(tp_g/tp_roe,0.8))/(1+(tp_r+0.01))^1+Val!D9*(1-MIN(tp_g/tp_roe,0.8))/(1+(tp_r+0.01))^2+Val!D10*(1-MIN(tp_g/tp_roe,0.8))/(1+(tp_r+0.01))^3+Val!D11*(1-MIN(tp_g/tp_roe,0.8))/(1+(tp_r+0.01))^4+Val!D12*(1-MIN(tp_g/tp_roe,0.8))/(1+(tp_r+0.01))^5+Val!D13*(1-MIN(tp_g/tp_roe,0.8))/(1+(tp_r+0.01))^6+Val!D13*(1-MIN(tp_g/tp_roe,0.8))*(1+tp_g)/((tp_r+0.01)-tp_g)/(1+(tp_r+0.01))^6))*(1+(tp_r+0.01)) -> 3019.4276 | D29: =Val!B35 -> 8348.4724 | E29: =tp_w_dcf*C29+(1-tp_w_dcf)*D29 -> 5683.95 | F29: =E29/E$28-1 -> -0.040822888
A30: 折現率 −1pt | B30: r 9% | C30: =(tp_wA*MAX(0,Val!B8*(1-MIN(tp_g/tp_roe,0.8))/(1+(tp_r-0.01))^1+Val!B9*(1-MIN(tp_g/tp_roe,0.8))/(1+(tp_r-0.01))^2+Val!B10*(1-MIN(tp_g/tp_roe,0.8))/(1+(tp_r-0.01))^3+Val!B11*(1-MIN(tp_g/tp_roe,0.8))/(1+(tp_r-0.01))^4+Val!B12*(1-MIN(tp_g/tp_roe,0.8))/(1+(tp_r-0.01))^5+Val!B13*(1-MIN(tp_g/tp_roe,0.8))/(1+(tp_r-0.01))^6+Val!B13*(1-MIN(tp_g/tp_roe,0.8))*(1+tp_g)/((tp_r-0.01)-tp_g)/(1+(tp_r-0.01))^6)+tp_wB*MAX(0,Val!C8*(1-MIN(tp_g/tp_roe,0.8))/(1+(tp_r-0.01))^1+Val!C9*(1-MIN(tp_g/tp_roe,0.8))/(1+(tp_r-0.01))^2+Val!C10*(1-MIN(tp_g/tp_roe,0.8))/(1+(tp_r-0.01))^3+Val!C11*(1-MIN(tp_g/tp_roe,0.8))/(1+(tp_r-0.01))^4+Val!C12*(1-MIN(tp_g/tp_roe,0.8))/(1+(tp_r-0.01))^5+Val!C13*(1-MIN(tp_g/tp_roe,0.8))/(1+(tp_r-0.01))^6+Val!C13*(1-MIN(tp_g/tp_roe,0.8))*(1+tp_g)/((tp_r-0.01)-tp_g)/(1+(tp_r-0.01))^6)+tp_wC*MAX(0,Val!D8*(1-MIN(tp_g/tp_roe,0.8))/(1+(tp_r-0.01))^1+Val!D9*(1-MIN(tp_g/tp_roe,0.8))/(1+(tp_r-0.01))^2+Val!D10*(1-MIN(tp_g/tp_roe,0.8))/(1+(tp_r-0.01))^3+Val!D11*(1-MIN(tp_g/tp_roe,0.8))/(1+(tp_r-0.01))^4+Val!D12*(1-MIN(tp_g/tp_roe,0.8))/(1+(tp_r-0.01))^5+Val!D13*(1-MIN(tp_g/tp_roe,0.8))/(1+(tp_r-0.01))^6+Val!D13*(1-MIN(tp_g/tp_roe,0.8))*(1+tp_g)/((tp_r-0.01)-tp_g)/(1+(tp_r-0.01))^6))*(1+(tp_r-0.01)) -> 4180.7521 | D30: =Val!B35 -> 8348.4724 | E30: =tp_w_dcf*C30+(1-tp_w_dcf)*D30 -> 6264.6122 | F30: =E30/E$28-1 -> 0.057164942
A31: 長期成長 +1pt | B31: g 5% | C31: =(tp_wA*MAX(0,Val!B8*(1-MIN((tp_g+0.01)/tp_roe,0.8))/(1+tp_r)^1+Val!B9*(1-MIN((tp_g+0.01)/tp_roe,0.8))/(1+tp_r)^2+Val!B10*(1-MIN((tp_g+0.01)/tp_roe,0.8))/(1+tp_r)^3+Val!B11*(1-MIN((tp_g+0.01)/tp_roe,0.8))/(1+tp_r)^4+Val!B12*(1-MIN((tp_g+0.01)/tp_roe,0.8))/(1+tp_r)^5+Val!B13*(1-MIN((tp_g+0.01)/tp_roe,0.8))/(1+tp_r)^6+Val!B13*(1-MIN((tp_g+0.01)/tp_roe,0.8))*(1+(tp_g+0.01))/(tp_r-(tp_g+0.01))/(1+tp_r)^6)+tp_wB*MAX(0,Val!C8*(1-MIN((tp_g+0.01)/tp_roe,0.8))/(1+tp_r)^1+Val!C9*(1-MIN((tp_g+0.01)/tp_roe,0.8))/(1+tp_r)^2+Val!C10*(1-MIN((tp_g+0.01)/tp_roe,0.8))/(1+tp_r)^3+Val!C11*(1-MIN((tp_g+0.01)/tp_roe,0.8))/(1+tp_r)^4+Val!C12*(1-MIN((tp_g+0.01)/tp_roe,0.8))/(1+tp_r)^5+Val!C13*(1-MIN((tp_g+0.01)/tp_roe,0.8))/(1+tp_r)^6+Val!C13*(1-MIN((tp_g+0.01)/tp_roe,0.8))*(1+(tp_g+0.01))/(tp_r-(tp_g+0.01))/(1+tp_r)^6)+tp_wC*MAX(0,Val!D8*(1-MIN((tp_g+0.01)/tp_roe,0.8))/(1+tp_r)^1+Val!D9*(1-MIN((tp_g+0.01)/tp_roe,0.8))/(1+tp_r)^2+Val!D10*(1-MIN((tp_g+0.01)/tp_roe,0.8))/(1+tp_r)^3+Val!D11*(1-MIN((tp_g+0.01)/tp_roe,0.8))/(1+tp_r)^4+Val!D12*(1-MIN((tp_g+0.01)/tp_roe,0.8))/(1+tp_r)^5+Val!D13*(1-MIN((tp_g+0.01)/tp_roe,0.8))/(1+tp_r)^6+Val!D13*(1-MIN((tp_g+0.01)/tp_roe,0.8))*(1+(tp_g+0.01))/(tp_r-(tp_g+0.01))/(1+tp_r)^6))*(1+tp_r) -> 3779.7385 | D31: =Val!B35 -> 8348.4724 | E31: =tp_w_dcf*C31+(1-tp_w_dcf)*D31 -> 6064.1054 | F31: =E31/E$28-1 -> 0.023329044
A32: 長期成長 −1pt | B32: g 3% | C32: =(tp_wA*MAX(0,Val!B8*(1-MIN((tp_g-0.01)/tp_roe,0.8))/(1+tp_r)^1+Val!B9*(1-MIN((tp_g-0.01)/tp_roe,0.8))/(1+tp_r)^2+Val!B10*(1-MIN((tp_g-0.01)/tp_roe,0.8))/(1+tp_r)^3+Val!B11*(1-MIN((tp_g-0.01)/tp_roe,0.8))/(1+tp_r)^4+Val!B12*(1-MIN((tp_g-0.01)/tp_roe,0.8))/(1+tp_r)^5+Val!B13*(1-MIN((tp_g-0.01)/tp_roe,0.8))/(1+tp_r)^6+Val!B13*(1-MIN((tp_g-0.01)/tp_roe,0.8))*(1+(tp_g-0.01))/(tp_r-(tp_g-0.01))/(1+tp_r)^6)+tp_wB*MAX(0,Val!C8*(1-MIN((tp_g-0.01)/tp_roe,0.8))/(1+tp_r)^1+Val!C9*(1-MIN((tp_g-0.01)/tp_roe,0.8))/(1+tp_r)^2+Val!C10*(1-MIN((tp_g-0.01)/tp_roe,0.8))/(1+tp_r)^3+Val!C11*(1-MIN((tp_g-0.01)/tp_roe,0.8))/(1+tp_r)^4+Val!C12*(1-MIN((tp_g-0.01)/tp_roe,0.8))/(1+tp_r)^5+Val!C13*(1-MIN((tp_g-0.01)/tp_roe,0.8))/(1+tp_r)^6+Val!C13*(1-MIN((tp_g-0.01)/tp_roe,0.8))*(1+(tp_g-0.01))/(tp_r-(tp_g-0.01))/(1+tp_r)^6)+tp_wC*MAX(0,Val!D8*(1-MIN((tp_g-0.01)/tp_roe,0.8))/(1+tp_r)^1+Val!D9*(1-MIN((tp_g-0.01)/tp_roe,0.8))/(1+tp_r)^2+Val!D10*(1-MIN((tp_g-0.01)/tp_roe,0.8))/(1+tp_r)^3+Val!D11*(1-MIN((tp_g-0.01)/tp_roe,0.8))/(1+tp_r)^4+Val!D12*(1-MIN((tp_g-0.01)/tp_roe,0.8))/(1+tp_r)^5+Val!D13*(1-MIN((tp_g-0.01)/tp_roe,0.8))/(1+tp_r)^6+Val!D13*(1-MIN((tp_g-0.01)/tp_roe,0.8))*(1+(tp_g-0.01))/(tp_r-(tp_g-0.01))/(1+tp_r)^6))*(1+tp_r) -> 3320.646 | D32: =Val!B35 -> 8348.4724 | E32: =tp_w_dcf*C32+(1-tp_w_dcf)*D32 -> 5834.5592 | F32: =E32/E$28-1 -> -0.015407307
A33: DCF 權重 0.3 | C33: =(tp_wA*MAX(0,Val!B8*(1-MIN(tp_g/tp_roe,0.8))/(1+tp_r)^1+Val!B9*(1-MIN(tp_g/tp_roe,0.8))/(1+tp_r)^2+Val!B10*(1-MIN(tp_g/tp_roe,0.8))/(1+tp_r)^3+Val!B11*(1-MIN(tp_g/tp_roe,0.8))/(1+tp_r)^4+Val!B12*(1-MIN(tp_g/tp_roe,0.8))/(1+tp_r)^5+Val!B13*(1-MIN(tp_g/tp_roe,0.8))/(1+tp_r)^6+Val!B13*(1-MIN(tp_g/tp_roe,0.8))*(1+tp_g)/(tp_r-tp_g)/(1+tp_r)^6)+tp_wB*MAX(0,Val!C8*(1-MIN(tp_g/tp_roe,0.8))/(1+tp_r)^1+Val!C9*(1-MIN(tp_g/tp_roe,0.8))/(1+tp_r)^2+Val!C10*(1-MIN(tp_g/tp_roe,0.8))/(1+tp_r)^3+Val!C11*(1-MIN(tp_g/tp_roe,0.8))/(1+tp_r)^4+Val!C12*(1-MIN(tp_g/tp_roe,0.8))/(1+tp_r)^5+Val!C13*(1-MIN(tp_g/tp_roe,0.8))/(1+tp_r)^6+Val!C13*(1-MIN(tp_g/tp_roe,0.8))*(1+tp_g)/(tp_r-tp_g)/(1+tp_r)^6)+tp_wC*MAX(0,Val!D8*(1-MIN(tp_g/tp_roe,0.8))/(1+tp_r)^1+Val!D9*(1-MIN(tp_g/tp_roe,0.8))/(1+tp_r)^2+Val!D10*(1-MIN(tp_g/tp_roe,0.8))/(1+tp_r)^3+Val!D11*(1-MIN(tp_g/tp_roe,0.8))/(1+tp_r)^4+Val!D12*(1-MIN(tp_g/tp_roe,0.8))/(1+tp_r)^5+Val!D13*(1-MIN(tp_g/tp_roe,0.8))/(1+tp_r)^6+Val!D13*(1-MIN(tp_g/tp_roe,0.8))*(1+tp_g)/(tp_r-tp_g)/(1+tp_r)^6))*(1+tp_r) -> 3503.2491 | D33: =Val!B35 -> 8348.4724 | E33: =0.3*C33+(1-0.3)*D33 -> 6894.9054 | F33: =E33/E$28-1 -> 0.16352808
A34: DCF 權重 0.7 | C34: =(tp_wA*MAX(0,Val!B8*(1-MIN(tp_g/tp_roe,0.8))/(1+tp_r)^1+Val!B9*(1-MIN(tp_g/tp_roe,0.8))/(1+tp_r)^2+Val!B10*(1-MIN(tp_g/tp_roe,0.8))/(1+tp_r)^3+Val!B11*(1-MIN(tp_g/tp_roe,0.8))/(1+tp_r)^4+Val!B12*(1-MIN(tp_g/tp_roe,0.8))/(1+tp_r)^5+Val!B13*(1-MIN(tp_g/tp_roe,0.8))/(1+tp_r)^6+Val!B13*(1-MIN(tp_g/tp_roe,0.8))*(1+tp_g)/(tp_r-tp_g)/(1+tp_r)^6)+tp_wB*MAX(0,Val!C8*(1-MIN(tp_g/tp_roe,0.8))/(1+tp_r)^1+Val!C9*(1-MIN(tp_g/tp_roe,0.8))/(1+tp_r)^2+Val!C10*(1-MIN(tp_g/tp_roe,0.8))/(1+tp_r)^3+Val!C11*(1-MIN(tp_g/tp_roe,0.8))/(1+tp_r)^4+Val!C12*(1-MIN(tp_g/tp_roe,0.8))/(1+tp_r)^5+Val!C13*(1-MIN(tp_g/tp_roe,0.8))/(1+tp_r)^6+Val!C13*(1-MIN(tp_g/tp_roe,0.8))*(1+tp_g)/(tp_r-tp_g)/(1+tp_r)^6)+tp_wC*MAX(0,Val!D8*(1-MIN(tp_g/tp_roe,0.8))/(1+tp_r)^1+Val!D9*(1-MIN(tp_g/tp_roe,0.8))/(1+tp_r)^2+Val!D10*(1-MIN(tp_g/tp_roe,0.8))/(1+tp_r)^3+Val!D11*(1-MIN(tp_g/tp_roe,0.8))/(1+tp_r)^4+Val!D12*(1-MIN(tp_g/tp_roe,0.8))/(1+tp_r)^5+Val!D13*(1-MIN(tp_g/tp_roe,0.8))/(1+tp_r)^6+Val!D13*(1-MIN(tp_g/tp_roe,0.8))*(1+tp_g)/(tp_r-tp_g)/(1+tp_r)^6))*(1+tp_r) -> 3503.2491 | D34: =Val!B35 -> 8348.4724 | E34: =0.7*C34+(1-0.7)*D34 -> 4956.8161 | F34: =E34/E$28-1 -> -0.16352808
A40: 案例區塊：Trainium 份額 −10pt（情境 A）
A41: 項目 | B41: 單位 | C41: FY2025A | D41: FY2026（錨點） | E41: FY2027 | F41: FY2028 | G41: FY2029 | H41: FY2030（收斂） | I41: FY2031（收斂） | J41: FY2032（收斂） | K41: 說明
A42: A. Trainium 量產（由下而上；D 欄＝FY2026 校準年；FY(t)＝CY(t)）
A43: AWS Trainium 市場顆數（含情境係數） | B43: 百萬顆 | D43: =u_trn_26 -> 2 | E43: =u_trn_27 -> 2.5 | F43: =u_trn_28*um28_A -> 3 | G43: =u_trn_28*(1+g29_trn)*um29_A -> 3.45
A44: 世芯份額：AWS Trainium | B44: % | D44: =al_trn_26 -> 0.3 | E44: =MIN(1,MAX(0,al27_A+(-0.1))) -> 0.45 | F44: =MIN(1,MAX(0,al28_A+(-0.1))) -> 0.45 | G44: =MIN(1,MAX(0,al28_A+(-0.1))) -> 0.45
A45: 世芯顆數：AWS Trainium | B45: 百萬顆 | D45: =D43*D44 -> 0.6 | E45: =E43*E44*1 -> 1.125 | F45: =F43*F44*1 -> 1.35 | G45: =G43*G44*1 -> 1.5525
A46: 每顆 HBM | B46: GB | D46: =gb_trn_26 -> 110 | E46: =gb_trn_27 -> 144 | F46: =gb_trn_28 -> 200 | G46: =gb_trn_28 -> 200
A47: HBM 單價 | B47: US$/GB | D47: =hbm_A_26 -> 14.6 | E47: =hbm_A_27 -> 26.28 | F47: =hbm_A_28 -> 28.908 | G47: =hbm_A_29 -> 27.4626
A48: 每顆核心（不含 HBM；CY2028 起 × 2 奈米係數） | B48: US$K | D48: =core_trn -> 6.394 | E48: =core_trn -> 6.394 | F48: =core_trn*pfc_A -> 9.591 | G48: =core_trn*pfc_A -> 9.591
...

Sheet Sources
A1: 來源（公司原文＝世芯新聞稿；法說內容多為媒體與逐字稿轉述；券商、資料商、媒體皆為 Interested-party）
A2: 公司：2Q26 財報新聞稿（美元營收、毛利、稅前、淨利；製程、應用、地區占比） | B2: https://www.alchip.com/en/Newsroom/Alchip_2026_Q2_financial_results
A3: 媒體：工商時報 2026-08-14（2Q26、1H26 新台幣損益：營收、毛利、營業利益、稅前、淨利、EPS） | B3: https://www.ctee.com.tw/news/20260814701424-430201
A4: 逐字稿：Investing.com 2Q26 法說（毛利率指引、NRE 10–20%、營業費用、2 奈米） | B4: https://ca.investing.com/news/transcripts/earnings-call-transcript-alchip-q2-2026-tops-eps-view-as-ai-ramp-drives-growth-93CH-4800784
A5: 媒體：鉅亨網 2026-08-14（2Q26 法說：2 奈米價量、COT 模式、2027 年 3 奈米上修空間） | B5: https://news.cnyes.com/news/id/6577160
A6: 二手：方格子 1Q26 法說摘要（1Q26 營收、應用、製程、地區） | B6: https://vocus.cc/article/6a01c1ccfd89780001c384b6
A7: 二手：方格子 2Q26 財報摘要（毛利率 50.2% → 34.8%、製程占比） | B7: https://vocus.cc/article/6a805de6fd8978000134e926
A8: 媒體：經濟日報 2026-03-06（FY2025 營收、毛利率、營業利益率、淨利、EPS；4Q25） | B8: https://money.udn.com/money/amp/story/5607/9363922
A9: 媒體：科技新報（2026 年 9 月營收、前 9 月累計） | B9: https://finance.technews.tw/2026/10/12/alchip-3661-202609-financial-report/
A10: 媒體：科技新報（2025 年 9 月營收） | B10: https://finance.technews.tw/2025/10/13/alchip-3661-202509-financial-report/
A11: 媒體：經濟日報 2026-07-07（GDR 掛牌） | B11: https://money.udn.com/money/story/5607/9613262
A12: 券商轉述：時報資訊 2026-08-14（美系外資 5,088；3Q26 毛利率約 18%；Trainium 4 2028 年 40 萬顆、每顆超過 1 萬美元） | B12: https://www.chinatimes.com/realtimenews/20260814001557-260410
A13: 券商轉述：旺得富 2026-08-17（三家美系外資：EPS、Trainium 3／4 營收、目標價） | B13: https://wantrich.chinatimes.com/news/20260817900143-420101
... A25: SemiAnalysis | B25: 未使用
