Workbook

Sheet 導覽
A1: Microsoft 收支與評價模型 — Excel 版 v0.2.1（更新 2026-10-11；與 HTML v0.2.1 同步；市價截至 2026-10-07 收盤）
A3: 這個活頁簿在回答什麼
A4: 一句話：AI 資本支出有沒有賺到資金成本：每 MW 收入能否覆蓋每 MW 全成本——Microsoft 用客戶預付款支應多少擴張資本支出，剩下的缺口要靠多少債務與新股。
A5: 所有分頁用同一組數字，改任何一個輸入，後面全部會跟著動。
A7: 分頁結構（依模組分組，分頁標籤顏色相同者為同一模組）
A8: 摘要 一頁摘要：結論、與市場共識的差異、現價隱含什麼、驗證點（全部活公式）。
A9: 輸入與假設 所有可調參數（A 情境 → B 產能與收入 → C 利潤率 → D 支出 → E 融資 → F 評價 → G 年初至今 實際 → H 情境區間運算表 → I 市場共識 → J 季度追蹤輸入）。
A10: 各期收支 類現金流量：來源（含客戶預付）、用途、融資前缺口、期前融資瀑布。
A11: 季度追蹤 焦點季的模型／共識／指引／實際與差距（由年度模型拆分，只用於追蹤；實際數填在輸入與假設 J 區）。
A12: 運營_產能與收入 已連網 MW → 在役 MW → 營收（MW × 每 MW 年收入 × 利用率）；RPO 排程只作對照與產能瓶頸旗標。
A13: 資產負債_既有債務／新債與新股／租賃承諾 類資產負債表：季報債務明細、每期現金與總債務與股數、租賃承諾。
A14: 損益 類損益表（FY27＝全年模型）。
... A42: DCF 以融資後股數計每股，並加回新股募得現金的現值；EV/EBITDA 用錨定年末淨負債與錨定年末股數。

Sheet 摘要
A1: 一頁摘要 — 結論、與市場的差異、現價隱含什麼、驗證點（全部依輸入連動）
A2: ="模型端＝目前情境：" & CHOOSE(輸入與假設!$C$5,"保守 第三方可辨識站點","基準 依資本支出指引","積極 依公司容量目標") & "（預設＝基準）；共識＝data/consensus_msft_20261008.json（2026-10-08）" -> 模型端＝目前情境：基準 依資本支出指引（預設＝基準）；共識＝data/consensus_msft_20261008.json（2026-10-08）
A4: 1｜結論
A5: 結論｜評等代碼（1＝買進、0＝中立、−1＝賣出） | C5: =評價_DCF與目標價!C99 -> -1
A6: 結論｜評等 | C6: =CHOOSE(C5+2,"賣出","中立","買進") -> 賣出
A7: 結論｜點位（加權目標價） | B7: US$ | C7: =評價_DCF與目標價!C51 -> 359.05884
A8: 結論｜現價 | B8: US$ | C8: =輸入與假設!$C$345 -> 529.76
A9: 結論｜空間 | B9: % | C9: =C7/C8-1 -> -0.32222358
A10: 結論｜情境區間（下緣／上緣） | B10: US$ | C10: =評價_DCF與目標價!C104 -> 360.15761 | D10: =評價_DCF與目標價!D104 -> 380.56412
A11: 結論｜方法區間（下緣／上緣） | B11: US$ | C11: =評價_DCF與目標價!C106 -> 353.54635 | D11: =評價_DCF與目標價!D106 -> 359.05884
A12: 結論｜賣出門檻價 | B12: US$ | C12: =評價_DCF與目標價!$C$100 -> 450.296
A13: 結論｜點位 − 賣出門檻 | B13: US$ | C13: =C7-C12 -> -91.237161
A14: 結論｜結論句 | C14: =C6&"：點位 $"&TEXT(C7,"0.0")&"，較現價 $"&TEXT(C8,"0.00")&" "&IF(C9>=0,"高","低")&" "&TEXT(ABS(C9)*100,"0")&"%；情境區間 $"&TEXT(C10,"0.0")&"–$"&TEXT(D10,"0.0")&"，方法區間 $"&TEXT(C11,"0.0")&"–$"&TEXT(D11,"0.0")&"；點位"&IF(C13<0,"低於","高於")&"賣出門檻 $"&TEXT(C12,"0.0")&" 達 $"&TEXT(ABS(C13),"0.0")&"。" -> 賣出：點位 $359.1，較現價 $529.76 低 32%；情境區間 $360.2–$380.6，方法區間 $353.5–$359.1；點位低於賣出門檻 $450.3 達 $91.2。
A15: 結論｜情境判斷句 | C15: =評價_DCF與目標價!C129 -> 情境區間上緣 $380.6 低於現價 $529.76：賣出在三個擴張情境下都成立。
A16: 結論｜投資級句 | C16: =IF(OR(輸入與假設!$C$313="ebitda",輸入與假設!$C$313="leaseAdj"),"需失去投資級才能融資的金額："&IF(SUM(各期收支!C93:G93)>0.05,"$"&TEXT(SUM(各期收支!C93:G93),"0.0")&"bn（五期高息債溢出）","$0")&"；投資級上限＝"&IF(輸入與假設!$C$313="leaseAdj","(總債務＋租賃負債) ≤ "&IF(輸入與假設!$C$314=INT(輸入與假設!$C$314),TEXT(輸入與假設!$C$314,"0"),TEXT(輸入與假設!$C$314,"0.0"))&"×(EBITDA＋租金)","總債務 ≤ "&IF(輸入與假設!$C$314=INT(輸入與假設!$C$314),TEXT(輸入與假設!$C$314,"0"),TEXT(輸入與假設!$C$314,"0.0"))&"× 當期 EBITDA")&"，股權每年 ≤ 現市值 "&IF(ROUND(ABS(輸入與假設!$C$324)*100,4)=INT(ROUND(ABS(輸入與假設!$C$324)*100,4)),TEXT(ROUND(ABS(輸入與假設!$C$324)*100,4),"0"),TEXT(ROUND(ABS(輸入與假設!$C$324)*100,4),"0.0"))&"%"&"。","") -> 需失去投資級才能融資的金額：$0；投資級上限＝(總債務＋租賃負債) ≤ 3×(EBITDA＋租金)，股權每年 ≤ 現市值 5%。
A17: 結論｜調整後槓桿句 | C17: ="調整後槓桿（(債務＋租賃負債) ÷ (EBITDA＋租金)）路徑 "&TEXT(資產負債_新債與新股!C37,"0.0")&"／"&TEXT(資產負債_新債與新股!D37,"0.0")&"／"&TEXT(資產負債_新債與新股!E37,"0.0")&"／"&TEXT(資產負債_新債與新股!F37,"0.0")&"／"&TEXT(資產負債_新債與新股!G37,"0.0")&"×；上限 "&IF(輸入與假設!$C$314=INT(輸入與假設!$C$314),TEXT(輸入與假設!$C$314,"0"),TEXT(輸入與假設!$C$314,"0.0"))&"×，"&IF(MAX(資產負債_新債與新股!$C$37:$G$37)>輸入與假設!$C$314+0.000000001,CHOOSE(MATCH(MAX(資產負債_新債與新股!$C$37:$G$37),資產負債_新債與新股!$C$37:$G$37,0),"FY27","FY28","FY29","FY30","FY31")&" 超過 "&TEXT(MAX(資產負債_新債與新股!$C$37:$G$37)-輸入與假設!$C$314,"0.0")&"×：需股權或失去投資級。","最小空間 "&TEXT(輸入與假設!$C$314-MAX(資產負債_新債與新股!$C$37:$G$37),"0.0")&"×（"&CHOOSE(MATCH(MAX(資產負債_新債與新股!$C$37:$G$37),資產負債_新債與新股!$C$37:$G$37,0),"FY27","FY28","FY29","FY30","FY31")&"）。") -> 調整後槓桿（(債務＋租賃負債) ÷ (EBITDA＋租金)）路徑 0.8／0.8／0.8／0.8／0.7×；上限 3×，最小空間 2.2×（FY28）。
A18: 結論｜評價口徑敏感度句 | C18: ="評價口徑敏感度："&"WACC 9% $"&TEXT(評價_DCF與目標價!C114,"0.00")&"（"&CHOOSE(評價_DCF與目標價!D114+2,"賣出","中立","買進")&"）"&"、"&"WACC 10% $"&TEXT(評價_DCF與目標價!C115,"0.00")&"（"&CHOOSE(評價_DCF與目標價!D115+2,"賣出","中立","買進")&"）"&"、"&"WACC 11% $"&TEXT(評價_DCF與目標價!C116,"0.00")&"（"&CHOOSE(評價_DCF與目標價!D116+2,"賣出","中立","買進")&"）"&"；"&"非 AI 分部改用公司自身 NTM EV/EBITDA 15.67× $"&TEXT(評價_DCF與目標價!C119,"0.00")&"（"&CHOOSE(評價_DCF與目標價!D119+2,"賣出","中立","買進")&"）"&"、"&"AI 雲端 15× $"&TEXT(評價_DCF與目標價!C120,"0.00")&"（"&CHOOSE(評價_DCF與目標價!D120+2,"賣出","中立","買進")&"）"&"、"&"組合：WACC 9%＋非 AI 自身倍數＋AI 15× $"&TEXT(評價_DCF與目標價!C121,"0.00")&"（"&CHOOSE(評價_DCF與目標價!D121+2,"賣出","中立","買進")&"）"&"；評等翻轉點："&"WACC 約 "&TEXT(評價_DCF與目標價!C122*100,"0.0")&"%（ERP "&TEXT(評價_DCF與目標價!D122*100,"0.00")&"%）以下由「賣出」轉為「中立」"&"。" -> 評價口徑敏感度：WACC 9% $419.06（賣出）、WACC 10% $383.70（賣出）、WACC 11% $356.52（賣出）；非 AI 分部改用公司自身 NTM EV/EBITDA 15.67× $420.00（賣出）、AI 雲端 15× $408.67（賣出）、組合：WACC 9%＋非 AI 自身倍數＋AI 15× $533.49（中立）；評等翻轉點：WACC 約 8.3%（ERP 2.70%）以下由「賣出」轉為「中立」。
A19: 結論｜終值占比規則句 | C19: ="評等規則：買進須空間 ≥ +"&IF(ROUND(ABS(輸入與假設!$C$434)*100,4)=INT(ROUND(ABS(輸入與假設!$C$434)*100,4)),TEXT(ROUND(ABS(輸入與假設!$C$434)*100,4),"0"),TEXT(ROUND(ABS(輸入與假設!$C$434)*100,4),"0.0"))&"%"&" 且終值占 EV < "&IF(ROUND(ABS(輸入與假設!$C$435)*100,4)=INT(ROUND(ABS(輸入與假設!$C$435)*100,4)),TEXT(ROUND(ABS(輸入與假設!$C$435)*100,4),"0"),TEXT(ROUND(ABS(輸入與假設!$C$435)*100,4),"0.0"))&"%"&"；目前終值占 EV "&TEXT(評價_DCF與目標價!C97*100,"0")&"%"&IF(評價_DCF與目標價!C97>=輸入與假設!$C$435,"，此規則下只可能「賣出」或「中立」","")&"（規則是否修改待 Andy 決定）。" -> 評等規則：買進須空間 ≥ +25% 且終值占 EV < 90%；目前終值占 EV 95%，此規則下只可能「賣出」或「中立」（規則是否修改待 Andy 決定）。
A20: 結論｜兩種讀法句 | C20: ="兩種讀法（自用 AI）：讀法 1（影子收入不進評價）$"&TEXT(評價_DCF與目標價!C51,"0.00")&"；讀法 2（自用 AI 價值中性：自用 MW 以 k＝1 計影子收入並進評價）$"&TEXT(評價_DCF與目標價!C73,"0.00")&"；差額 "&IF(評價_DCF與目標價!C73-評價_DCF與目標價!C51<0,"−","+")&"$"&TEXT(ABS(評價_DCF與目標價!C73-評價_DCF與目標價!C51),"0.00")&"。主值取哪一個是 Andy 的判斷（待決）。" -> 兩種讀法（自用 AI）：讀法 1（影子收入不進評價）$359.06；讀法 2（自用 AI 價值中性：自用 MW 以 k＝1 計影子收入並進評價）$429.43；差額 +$70.37。主值取哪一個是 Andy 的判斷（待決）。
A21: 結論｜對外比例句 | C21: ="對外比例無揭露（目前 "&TEXT(輸入與假設!$C$242*100,"0")&"%，[Assumed]），是最大不確定："&TEXT(評價_DCF與目標價!C112*100,"0")&"% → $"&TEXT(評價_DCF與目標價!D112,"0.00")&"、"&TEXT(評價_DCF與目標價!C113*100,"0")&"% → $"&TEXT(評價_DCF與目標價!D113,"0.00")&"（基準 $"&TEXT(評價_DCF與目標價!C51,"0.00")&"）。" -> 對外比例無揭露（目前 60%，[Assumed]），是最大不確定：40% → $285.64、80% → $391.20（基準 $359.06）。
A22: 結論｜主命題句 | C22: ="主命題（AI 資本支出有沒有賺到資金成本）：FY29 對外 AI ROIC "&TEXT(AI增量報酬!E23*100,"0.0")&"% vs WACC "&TEXT(輸入與假設!$C$364*100,"0.0")&"%（"&IF(AI增量報酬!E25<0,"−","+")&TEXT(ABS(AI增量報酬!E25)*100,"0.0")&"pt）；打平 k "&TEXT(AI增量報酬!C29,"0.00")&"（目前 "&TEXT(輸入與假設!$C$71,"0.00")&"）；全 AI（含影子收入）"&TEXT(AI增量報酬!E27*100,"0.0")&"%。" -> 主命題（AI 資本支出有沒有賺到資金成本）：FY29 對外 AI ROIC 13.5% vs WACC 10.9%（+2.6pt）；打平 k 1.09（目前 1.17）；全 AI（含影子收入）13.1%。
A23: 結論｜股東回饋與 FCF 句 | C23: ="股東回饋與 FCF：FCF "&IF(各期收支!C44<0,"首次為負 FY27（−$"&TEXT(-各期收支!C44,"0.0")&"bn）",IF(各期收支!D44<0,"首次為負 FY28（−$"&TEXT(-各期收支!D44,"0.0")&"bn）",IF(各期收支!E44<0,"首次為負 FY29（−$"&TEXT(-各期收支!E44,"0.0")&"bn）",IF(各期收支!F44<0,"首次為負 FY30（−$"&TEXT(-各期收支!F44,"0.0")&"bn）",IF(各期收支!G44<0,"首次為負 FY31（−$"&TEXT(-各期收支!G44,"0.0")&"bn）","五期皆為正")))))&"；"&IF(SUM(各期收支!C75:G75)<=0.05,"無回購計畫（減少回購步驟不適用）",IF(SUM(各期收支!C77:G77)>0,"回購被迫減少："&MID(IF(各期收支!C77>0.05,"、FY27 $"&TEXT(各期收支!C77,"0.0"),"")&IF(各期收支!D77>0.05,"、FY28 $"&TEXT(各期收支!D77,"0.0"),"")&IF(各期收支!E77>0.05,"、FY29 $"&TEXT(各期收支!E77,"0.0"),"")&IF(各期收支!F77>0.05,"、FY30 $"&TEXT(各期收支!F77,"0.0"),"")&IF(各期收支!G77>0.05,"、FY31 $"&TEXT(各期收支!G77,"0.0"),""),2,999)&"bn","回購未被迫減少"))&"；五期新債 $"&TEXT(SUM(各期收支!C86:G86)+SUM(各期收支!C93:G93),"0.0")&"bn、股權 $"&TEXT(SUM(各期收支!C92:G92),"0.0")&"bn。" -> 股東回饋與 FCF：FCF 五期皆為正；回購被迫減少：FY27 $22.3、FY28 $22.3、FY31 $20.7bn；五期新債 $23.1bn、股權 $0.0bn。
A24: 結論｜延誤句 | C24: =IF(運營_產能與收入!$C$50>0,"建設延誤 "&IF(運營_產能與收入!$C$50=INT(運營_產能與收入!$C$50),TEXT(運營_產能與收入!$C$50,"0"),TEXT(運營_產能與收入!$C$50,"0.0"))&" 個月（GPU 資本支出照原時程）：閒置資本（已支出、尚未產生收入）峰值 $"&TEXT(MAX(運營_產能與收入!$C$55:$G$55),"0.0")&"bn（"&CHOOSE(MATCH(MAX(運營_產能與收入!$C$55:$G$55),運營_產能與收入!$C$55:$G$55,0),"FY27","FY28","FY29","FY30","FY31")&" 末）。","建設延誤：本情境 0 個月（無閒置資本）。") -> 建設延誤：本情境 0 個月（無閒置資本）。
A26: 2｜與市場的差異（模型：目前情境 vs 共識；FY27–FY29）
A27: 項目 | B27: 單位 | C27: FY27 | D27: FY28 | E27: FY29
A28: 差異｜營收｜模型 | B28: US$bn | C28: =損益!C29 -> 397.44559 | D28: =損益!D29 -> 474.55515 | E28: =損益!E29 -> 552.58861
A29: 差異｜營收｜共識 | B29: US$bn | C29: =輸入與假設!$C$493 -> 391.271 | D29: =輸入與假設!$D$493 -> 467.955 | E29: =輸入與假設!$E$493 -> 569.502
A30: 差異｜營收｜差距 | B30: % | C30: =C28/C29-1 -> 0.015780847 | D30: =D28/D29-1 -> 0.014104236 | E30: =E28/E29-1 -> -0.029698567
A31: 差異｜調整後 EBITDA｜模型 | B31: US$bn | C31: =輸入與假設!$C$463+損益!C22 -> 233.75228 | D31: =損益!D34 -> 287.0195 | E31: =損益!E34 -> 342.13867
A32: 差異｜調整後 EBITDA｜共識 | B32: US$bn | C32: =輸入與假設!$C$494 -> 239.452 | D32: =輸入與假設!$D$494 -> 295.606 | E32: =輸入與假設!$E$494 -> 372.456
A33: 差異｜調整後 EBITDA｜差距 | B33: % | C33: =C31/C32-1 -> -0.023803167 | D33: =D31/D32-1 -> -0.029047117 | E33: =E31/E32-1 -> -0.08139841 | I33: FY27 模型＝年初至今 實際調整後 EBITDA（輸入與假設 G 區，報導轉述 [Verified]）＋全年 模型
A34: 差異｜調整後 EBITDA｜差距（金額） | B34: US$bn | C34: =C31-C32 -> -5.6997159 | D34: =D31-D32 -> -8.5865022 | E34: =E31-E32 -> -30.317326 | I34: 與 HTML 一頁摘要、市場共識分頁同一呈現；判斷門檻仍用上一列比例
A35: 差異｜EBITDA 率｜模型 | B35: % | C35: =C31/C28 -> 0.58813657 | D35: =D31/D28 -> 0.60481801 | E35: =E31/E28 -> 0.61915622
A36: 差異｜EBITDA 率｜共識 | B36: % | C36: =輸入與假設!$C$495 -> 0.61198504 | D36: =輸入與假設!$D$495 -> 0.63169749 | E36: =輸入與假設!$E$495 -> 0.65400297
A37: 差異｜EBITDA 率｜差距（百分點） | B37: pt | C37: =C35-C36 -> -0.023848475 | D37: =D35-D36 -> -0.026879487 | E37: =E35-E36 -> -0.034846749 | I37: EBITDA 率以百分點列差距，不納入判斷
A38: 差異｜CapEx（毛額）｜模型 | B38: US$bn | C38: =輸入與假設!$C$446+輸入與假設!C$302 -> 204.2 | D38: =輸入與假設!D$302 -> 224.45558 | E38: =輸入與假設!E$302 -> 234.55806
A39: 差異｜CapEx（毛額）｜共識 | B39: US$bn | C39: =輸入與假設!$C$499 -> 192.827 | D39: =輸入與假設!$D$499 -> 216.787 | E39: =輸入與假設!$E$499 -> 251.173
A40: 差異｜CapEx（毛額）｜差距 | B40: % | C40: =C38/C39-1 -> 0.05898033 | D40: =D38/D39-1 -> 0.035373816 | E40: =E38/E39-1 -> -0.066149396 | I40: 共識 CapEx 口徑未揭露；FY27＝年初至今 實際毛額＋全年 模型毛額
A41: 差異｜淨負債｜模型 | B41: US$bn | C41: =資產負債_新債與新股!C25 -> 6.2385787 | D41: =資產負債_新債與新股!D25 -> 9.9911026 | E41: =資產負債_新債與新股!E25 -> -3.9809265
A42: 差異｜淨負債｜共識 | B42: US$bn | C42: =輸入與假設!$C$501 -> -51.842 | D42: =輸入與假設!$D$501 -> -38.829 | E42: =輸入與假設!$E$501 -> 99.57
...

Sheet 輸入與假設
A1: 輸入（依類別排序；點左側 ＋／− 展開或收合。藍字可改；黃底為最關鍵假設）
A2: A 情境 → B 產能與收入 → C 利潤率 → D 支出（CapEx／折舊／租賃／JV）→ E 融資 → F 評價 → G 參考：年初至今 實際 → H 情境區間運算表 → I 市場共識 → J 季度追蹤輸入。灰底『▸』為明細子區，預設收合
A4: A｜情境與規模（管理層擴張力道）
A5: 情境選擇（1＝保守 第三方可辨識站點、2＝基準 依資本支出指引、3＝積極 依公司容量目標） | C5: 2 | D5: =CHOOSE(C5,"保守 第三方可辨識站點","基準 依資本支出指引","積極 依公司容量目標") -> 基準 依資本支出指引 | I5: 三情境只改容量軸（對外 AI MW 路徑；世代組合隨新增 MW 改變每 MW 年收入）；價格軸另見 B0（對照表 r1 第 5 節第 1 條）
A6: ▸ 情境路徑明細（已連網 MW、在役比例、表外租金基準）
A7: 已連網 MW 路徑 | B7: 單位 | C7: FY27 | D7: FY28 | E7: FY29 | F7: FY30 | G7: FY31 | I7: FY32 新增 MW
A8: 評價日在役 MW（期初計費，三情境共用） | B8: MW | C8: 3250 | I8: company.json → defaults.billableOpen；來源見 scenarios.mwPath.note（第三方估計，不以營收校準）[Derived／Assumed]
A9: 保守 第三方可辨識站點｜合約 MW 上限 | B9: MW | C9: 4386 | D9: 4386 | E9: 4386 | F9: 4386 | G9: 4386 | I9: company.json → scenarios.mwPath.contracted
A10: 保守 第三方可辨識站點｜併網速度 | B10: MW／年 | C10: 650 | I10: company.json → scenarios.mwPath.pace
A11: 保守 第三方可辨識站點 | B11: MW | C11: =MIN(C9,輸入與假設!$C$8+輸入與假設!$C$10*C$34) -> 3900 | D11: =MIN(D9,C11+輸入與假設!$C$10*D$34) -> 4386 | E11: =MIN(E9,D11+輸入與假設!$C$10*E$34) -> 4386 | F11: =MIN(F9,E11+輸入與假設!$C$10*F$34) -> 4386 | G11: =MIN(G9,F11+輸入與假設!$C$10*G$34) -> 4386 | I11: 0 | J11: 對外 AI MW-IT 只計 Epoch AI 可辨識站點的已交付＋在建：Fairwater Wisconsin 369 → 2028Q2 預測 2,263（+1,894，約 1.75 年）× 對外 60% → 每年 +650、上限 4,386（Atlanta 636 已全數運轉）[Derived]；I 欄＝FY32 新增 MW
A12: 基準 依資本支出指引｜合約 MW 上限 | B12: MW | C12: 99999 | D12: 99999 | E12: 99999 | F12: 99999 | G12: 99999 | I12: company.json → scenarios.mwPath.contracted
A13: 基準 依資本支出指引｜併網速度 | B13: MW／年 | C13: 2527.2 | I13: company.json → scenarios.mwPath.pace
A14: 基準 依資本支出指引 | B14: MW | C14: =MIN(C12,輸入與假設!$C$8+輸入與假設!$C$13*C$34) -> 5777.2 | D14: =MIN(D12,C14+輸入與假設!$C$13*D$34) -> 8304.4 | E14: =MIN(E12,D14+輸入與假設!$C$13*E$34) -> 10831.6 | F14: =MIN(F12,E14+輸入與假設!$C$13*F$34) -> 13358.8 | G14: =MIN(G12,F14+輸入與假設!$C$13*G$34) -> 15886 | I14: 2527.2 | J14: 對外 AI MW 新增速度＝近端資本支出隱含的建置量：FY27 資本支出（公司口徑含融資租賃）204.2 −（非 AI 公式值＋GPU 汰換）÷ 每 MW 全成本（Tokenomics IT＋自建比例 × 機房）× 對外 60%，依 λ 遞延上線（scripts/calib_pace.js 解，對帳落差＝0）；之後各年資本支出＝MW 路徑 × 每 MW 成本（同一套數字）[Derived]。FY27 資本支出＝2 ×（曆年 2026 約 175 − FY26 下半年實際 72.9）＝204.2（下半年＝上半年；FY27Q1 指引 >50 吻合）；I 欄＝FY32 新增 MW
A15: 積極 依公司容量目標｜合約 MW 上限 | B15: MW | C15: 99999 | D15: 99999 | E15: 99999 | F15: 99999 | G15: 99999 | I15: company.json → scenarios.mwPath.contracted
A16: 積極 依公司容量目標｜併網速度 | B16: MW／年 | C16: 2400 | I16: company.json → scenarios.mwPath.pace
A17: 積極 依公司容量目標 | B17: MW | C17: =MIN(C15,輸入與假設!$C$8+輸入與假設!$C$16*C$34) -> 5650 | D17: =MIN(D15,C17+輸入與假設!$C$16*D$34) -> 8050 | E17: =MIN(E15,D17+輸入與假設!$C$16*E$34) -> 10450 | F17: =MIN(F15,E17+輸入與假設!$C$16*F$34) -> 12850 | G17: =MIN(G15,F17+輸入與假設!$C$16*G$34) -> 15250 | I17: 2400 | J17: 公司目標：總產能約兩年翻倍（FY26 起多次重申）。以 Bloomberg 總容量約 12 GW（2026-09，口徑不明）為基數 → 每年 +6 GW（設施）× AI 占新增 80%（70%–90% 中點）÷ PUE 1.2 × 對外 60%＝每年 +2,400 MW-IT [Derived；總容量為第三方報導，非公司揭露]；I 欄＝FY32 新增 MW
A18: 在役／已連網比例 | B18: % | C18: 1 | D18: 1 | E18: 1 | F18: 1 | G18: 1 | I18: 對外 AI MW 依 MW-year 計價：已連網即計費（在役比例 100%）；期初計費 MW＝三法交叉估計 3,250，不以 Azure 營收校準 [Assumed]
A19: 未起租租賃總額（未折現） | B19: US$bn | C19: 329.1 | I19: 季報附註已簽約未起租租賃（company.json → leases.facts.notCommenced）[Interested-party]
A20: 未起租：評價日後第幾季開始起租（0＝首期第一季） | B20: 季 | C20: 0 | I20: company.json → leases.uncommenced.startQ
A21: 未起租：平均分攤起租的季數 | B21: 季 | C21: 16 | I21: company.json → leases.uncommenced.quarters（起租時程見該欄說明）[Assumed]
A22: 未起租：每筆租期 | B22: 年 | C22: 15 | I22: 季報 15–19 年取中點；敏感度 15／19 年見報告 [Assumed]
A23: B｜產能與收入（MW、每 MW 年收入、利用率、信用；RPO 只作對照）
A24: 6/30 RPO | B24: US$bn | C24: 0 | I24: 季報 RPO 684.0（只作對照與債務上限的 backlog）[Interested-party]
A25: 評價日後新增承諾 | B25: US$bn | C25: 0 | I25: 評價日後新簽、尚未進 RPO 的承諾；未揭露，取 0 [Assumed]
A26: 五期認列比例（至 2030 末） | B26: % | C26: 0 | I26: 季報 RPO 桶線性分攤後五期合計 0% [Derived]
A27: RPO 桶權重合計 | B27: % | C27: 0.9 | I27: 下方權重列的合計，用於歸一化
A28: 2026-06-30 主動電力 | B28: MW | C28: 3250 | I28: FY26 末（評價日）對外 AI MW-IT 3,250（自有 4,500 × 60%＋租用 1,100 × 50%；三法交叉，事實總帳 split.extMW）[Derived／Assumed]
A29: 6/30 Billable MW | B29: MW | C29: =輸入與假設!$C$8 -> 3250 | I29: 季末在役 MW 未揭露 [Derived]
A30: 收入用平均在役 MW（1=是） | C30: 1 | I30: 0＝用期末存量全期化；建議 1
A31: 營收驅動（mw＝MW × 每 MW 年收入；rpo＝RPO 排程） | C31: mw | I31: mw：新產能簽約率固定 100%，營收＝容量上限；RPO 只作對照與產能瓶頸旗標（company.json → defaults.revenueDriver）
A32: 每 MW 年收入倍數（整體） | B32: % | C32: 1 | I32: 反向 DCF 與壓力測試用；預設 100%。以『目標搜尋』調整此格即可反解市價隱含單價
A33: 項目 | B33: 單位 | C33: FY27 | D33: FY28 | E33: FY29 | F33: FY30 | G33: FY31 | I33: 來源／標籤
A34: 模型期長度（年） | C34: 1 | D34: 1 | E34: 1 | F34: 1 | G34: 1 | I34: 勿改。由 calendar_q.py 推算；只用於容量上限、電力、維護等年率換算 [Derived]
A35: RPO 桶權重 | B35: % | C35: 0.3 | D35: 0.25 | E35: 0.2 | F35: 0.1 | G35: 0.05 | H35: =SUM(C35:G35) -> 0.9 | I35: 季報 RPO 桶（商用 RPO 678B（約 30% 於 12 個月內、加權平均 2.3 年；約 45% 來自 OpenAI，FY26Q2）含 M365 與非 AI 雲端，只作對照（模型排程歸 0：AI 雲端收入＝MW × 每 MW））桶內線性分攤 [Derived]
A36: Accepted MW（期末主動電力） | B36: MW | C36: =CHOOSE(輸入與假設!$C$5,C11,C14,C17) -> 5777.2 | D36: =CHOOSE(輸入與假設!$C$5,D11,D14,D17) -> 8304.4 | E36: =CHOOSE(輸入與假設!$C$5,E11,E14,E17) -> 10831.6 | F36: =CHOOSE(輸入與假設!$C$5,F11,F14,F17) -> 13358.8 | G36: =CHOOSE(輸入與假設!$C$5,G11,G14,G17) -> 15886 | I36: ＝依 A 區情境選擇器（已連網 MW-IT）
A37: Billable MW | B37: MW | C37: =ROUND(C36*C18,0) -> 5777 | D37: =ROUND(D36*D18,0) -> 8304 | E37: =ROUND(E36*E18,0) -> 10832 | F37: =ROUND(F36*F18,0) -> 13359 | G37: =ROUND(G36*G18,0) -> 15886 | I37: ＝已連網 × 在役比例（A 區）
A38: 利用率 | B38: % | C38: 1 | D38: 1 | E38: 1 | F38: 1 | G38: 1 | I38: 100%：按 MW-year 計價，收入端不乘 IF_Util（Tokenomics 下游契約第 3 條）
A39: 每 MW 年收入 | B39: US$bn/MW | C39: =C112*輸入與假設!$C$71/1000 -> 0.012199576 | D39: =D112*輸入與假設!$C$71/1000 -> 0.012704599 | E39: =E112*輸入與假設!$C$71/1000 -> 0.013047202 | F39: =F112*輸入與假設!$C$71/1000 -> 0.013260179 | G39: =G112*輸入與假設!$C$71/1000 -> 0.013405393 | I39: ＝加權每 MW 年持有成本 × 採用 k ÷ 1000（B0；Tokenomics × k，不以公司營收反推）
A40: 新產能簽約率 | B40: % | C40: 1 | D40: 1 | E40: 1 | F40: 1 | G40: 1 | I40: MW 驅動：100%（RPO 只作對照）
A41: 客戶違約率 | B41: % | C41: 0 | D41: 0 | E41: 0 | F41: 0 | G41: 0 | I41: 前三大客戶約 59% 營收的定價，非預測 [Assumed]
...

Sheet 各期收支
A1: 支出與資金 — 五層支出、四層來源、現金橋
A2: FY27 欄＝年初至今 實際（季報現金流量表口徑）＋全年模型；FY28 以後為純模型。瀑布以「融資前現金」決定需求並直接由各支出列加總，因此沒有循環參照
A4: 項目 | B4: 單位 | C4: FY27 | D4: FY28 | E4: FY29 | F4: FY30 | G4: FY31 | I4: 公式／來源說明
A5: 支出（五層）
A6: ① 毛 CapEx（認列，備忘） | B6: US$bn | C6: =輸入與假設!$C$446+輸入與假設!C$302 -> 204.2 | D6: =輸入與假設!D$302 -> 224.45558 | E6: =輸入與假設!E$302 -> 234.55806 | F6: =輸入與假設!F$302 -> 279.22234 | G6: =輸入與假設!G$302 -> 394.5143 | I6: FY27＝年初至今 實際認列 0.0＋全年 模型；對照公司全年指引 204.2–204.2。備忘列：用途合計採現金口徑，不用這一列
A7: 客戶預付率 | B7: % | C7: =輸入與假設!C$258 -> 0 | D7: =輸入與假設!D$258 -> 0 | E7: =輸入與假設!E$258 -> 0 | F7: =輸入與假設!F$258 -> 0 | G7: =輸入與假設!G$258 -> 0
A8: 客戶預付金額（抵減，全年 起） | B8: US$bn | C8: =輸入與假設!C$278*C7 -> 0 | D8: =輸入與假設!D$278*D7 -> 0 | E8: =輸入與假設!E$278*E7 -> 0 | F8: =輸入與假設!F$278*F7 -> 0 | G8: =輸入與假設!G$278*G7 -> 0 | I8: ＝成長型 CapEx × 預付比率（汰換 CapEx 不計）；年初至今 的預付已含在實際 CFO 內，不重複計入
A9: 合約負債期初（客戶預付餘額） | B9: US$bn | C9: =輸入與假設!$C$255 -> 0 | D9: =C12 -> 0 | E9: =D12 -> 0 | F9: =E12 -> 0 | G9: =F12 -> 0 | I9: FY27 期初＝6/30 季報遞延營收
A10: 合約負債利息累積（重大財務組成，非現金） | B10: US$bn | C10: =輸入與假設!$C$256*(C9+0.5*C8)*運營_產能與收入!C7 -> 0 | D10: =輸入與假設!$C$256*(D9+0.5*D8)*運營_產能與收入!D7 -> 0 | E10: =輸入與假設!$C$256*(E9+0.5*E8)*運營_產能與收入!E7 -> 0 | F10: =輸入與假設!$C$256*(F9+0.5*F8)*運營_產能與收入!F7 -> 0 | G10: =輸入與假設!$C$256*(G9+0.5*G8)*運營_產能與收入!G7 -> 0 | I10: ＝隱含利率 ×(期初合約負債＋本期預付流入 × ½)× 期間長度；進損益利息、不進現金（v0.1b）
A11: 預付認列（非現金營收） | B11: US$bn | C11: =MIN(C9+C10,(C9+C10)/輸入與假設!$C$254*運營_產能與收入!C7) -> 0 | D11: =MIN(D9+D10,(D9+D10)/輸入與假設!$C$254*運營_產能與收入!D7) -> 0 | E11: =MIN(E9+E10,(E9+E10)/輸入與假設!$C$254*運營_產能與收入!E7) -> 0 | F11: =MIN(F9+F10,(F9+F10)/輸入與假設!$C$254*運營_產能與收入!F7) -> 0 | G11: =MIN(G9+G10,(G9+G10)/輸入與假設!$C$254*運營_產能與收入!G7) -> 0 | I11: ＝(期初合約負債＋累積利息) ÷ 認列年數 × 期間長度；這部分營收已在預付時收現，自營運來源扣除
A12: 合約負債期末 | B12: US$bn | C12: =C9+C8+C10-C11 -> 0 | D12: =D9+D8+D10-D11 -> 0 | E12: =E9+E8+E10-E11 -> 0 | F12: =F9+F8+F10-F11 -> 0 | G12: =G9+G8+G10-G11 -> 0 | I12: ＝期初＋預付流入＋累積利息−認列
A13: ① CapEx（用途用：年初至今 現金／全年 毛額） | B13: US$bn | C13: =輸入與假設!$C$445+輸入與假設!C$302 -> 204.2 | D13: =輸入與假設!D$302 -> 224.45558 | E13: =輸入與假設!E$302 -> 234.55806 | F13: =輸入與假設!F$302 -> 279.22234 | G13: =輸入與假設!G$302 -> 394.5143 | I13: 年初至今 採現金流量表的現金購置 0.0；全年 起採毛額，客戶預付在來源端抵回（避免重複計入）
A14: ② 在帳現金租金（備忘，年初至今 已含在 CFO） | B14: US$bn | C14: =輸入與假設!C$259 -> 13.203 | D14: =輸入與假設!D$259 -> 11.628 | E14: =輸入與假設!E$259 -> 9.814 | F14: =輸入與假設!F$259 -> 9.182 | G14: =輸入與假設!G$259 -> 8.859 | I14: 見『租賃與承諾』頁；2031 後尚有 61.706。FY27 欄僅 全年：年初至今 租金 0.0 已含在實際 CFO 內
A15: ② 表外現金租金（未起租） | B15: US$bn | C15: =運營_產能與收入!C59 -> 3.428125 | D15: =運營_產能與收入!D59 -> 8.913125 | E15: =運營_產能與收入!E59 -> 14.398125 | F15: =運營_產能與收入!F59 -> 19.883125 | G15: =運營_產能與收入!G59 -> 21.94 | I15: 已簽約未起租租賃 329.1 的現金路徑
A16: 租金合計 | B16: US$bn | C16: =輸入與假設!C$262+C15*輸入與假設!$C$263 -> 7.9780312 | D16: =輸入與假設!D$262+D15*輸入與假設!$C$263 -> 9.5222813 | E16: =輸入與假設!E$262+E15*輸入與假設!$C$263 -> 10.267531 | F16: =輸入與假設!F$262+F15*輸入與假設!$C$263 -> 11.540781 | G16: =輸入與假設!G$262+G15*輸入與假設!$C$263 -> 12.028 | I16: ＝在帳融資租賃現金＋未起租 × 融資部分比例（MAG v0.1b：營業租賃已含在分部 EBITDA，不重複扣除；AI 雲端 EBITDA 由 Tokenomics 推得、未扣租金）
A17: ③ 存量債務利息（備忘，年初至今 已含在 CFO） | B17: US$bn | C17: =輸入與假設!C$342 -> 1.3005073 | D17: =輸入與假設!D$342 -> 1.1556097 | E17: =輸入與假設!E$342 -> 1.1242648 | F17: =輸入與假設!F$342 -> 1.0929199 | G17: =輸入與假設!G$342 -> 1.0850876 | I17: ="6/30 債務餘額的利息。FY27 全年利息＝年初至今 實際 0.0＋全年 "&TEXT(C17,"0.0")&"＝"&TEXT(0+C17,"0.00")&"（見下方備忘）" -> 6/30 債務餘額的利息。FY27 全年利息＝年初至今 實際 0.0＋全年 1.3＝1.30（見下方備忘）
A18: 期初累積現金 | B18: US$bn | C18: =輸入與假設!$C$443 -> 76.843 | D18: =C56 -> 50 | E18: =D56 -> 50 | F18: =E56 -> 61.971029 | G18: =F56 -> 79.976487 | I18: FY27 自 2026-06-30 起算；之後＝前期期末累積現金
A19: 新債利率 | B19: % | C19: =IF(輸入與假設!$C$335=1,輸入與假設!C$341+MAX(0,輸入與假設!$C$334-450)/100*0.004,輸入與假設!C$341) -> 0.05 | D19: =IF(輸入與假設!$C$335=1,輸入與假設!D$341+MAX(0,輸入與假設!$C$334-450)/100*0.004,輸入與假設!D$341) -> 0.05 | E19: =IF(輸入與假設!$C$335=1,輸入與假設!E$341+MAX(0,輸入與假設!$C$334-450)/100*0.004,輸入與假設!E$341) -> 0.05 | F19: =IF(輸入與假設!$C$335=1,輸入與假設!F$341+MAX(0,輸入與假設!$C$334-450)/100*0.004,輸入與假設!F$341) -> 0.05 | G19: =IF(輸入與假設!$C$335=1,輸入與假設!G$341+MAX(0,輸入與假設!$C$334-450)/100*0.004,輸入與假設!G$341) -> 0.05 | I19: CDS 開關：＋MAX(0,CDS−450)×0.4bp/bp
A20: ③ 新債利息（瀑布） | B20: US$bn | C20: =C94 -> 0.96762893 | D20: =D94 -> 1.1552551 | E20: =E94 -> 1.1552551 | F20: =F94 -> 1.1552551 | G20: =G94 -> 1.1552551 | I20: ＝新債利率×期間長度×(期初新債＋本期舉借)；見下方「期前融資瀑布」
A21: 利息合計 | B21: US$bn | C21: =C17+C20 -> 2.2681363 | D21: =D17+D20 -> 2.3108648 | E21: =E17+E20 -> 2.2795199 | F21: =F17+F20 -> 2.2481751 | G21: =G17+G20 -> 2.2403427
A22: ④ JV／策略投資出資 | B22: US$bn | C22: =輸入與假設!$C$447+輸入與假設!C$266 -> 1.1 | D22: =輸入與假設!D$266 -> 0 | E22: =輸入與假設!E$266 -> 0 | F22: =輸入與假設!F$266 -> 0 | G22: =輸入與假設!G$266 -> 0 | I22: FY27＝年初至今 實際 0.0（JV 0.000＋策略投資 0.000）＋全年 模型。MSFT 不發股息
A23: ⑧ 股利（普通股＋特別股） | B23: US$bn | C23: =輸入與假設!$C$462+4*輸入與假設!$C$316*(1+輸入與假設!$C$317)^0*運營_產能與收入!C7*(輸入與假設!$C$318+0+SUMPRODUCT(資產負債_既有債務!$D$29:$D$29*資產負債_既有債務!$H$25:$H$25*(資產負債_既有債務!$G$25:$G$25<0)))+輸入與假設!C$339 -> 29.11384 | D23: =4*輸入與假設!$C$316*(1+輸入與假設!$C$317)^1*運營_產能與收入!D7*(輸入與假設!$C$318+C97+SUMPRODUCT(資產負債_既有債務!$D$29:$D$29*資產負債_既有債務!$H$25:$H$25*(資產負債_既有債務!$G$25:$G$25<1)))+輸入與假設!D$339 -> 31.442947 | E23: =4*輸入與假設!$C$316*(1+輸入與假設!$C$317)^2*運營_產能與收入!E7*(輸入與假設!$C$318+D97+SUMPRODUCT(資產負債_既有債務!$D$29:$D$29*資產負債_既有債務!$H$25:$H$25*(資產負債_既有債務!$G$25:$G$25<2)))+輸入與假設!E$339 -> 33.958383 | F23: =4*輸入與假設!$C$316*(1+輸入與假設!$C$317)^3*運營_產能與收入!F7*(輸入與假設!$C$318+E97+SUMPRODUCT(資產負債_既有債務!$D$29:$D$29*資產負債_既有債務!$H$25:$H$25*(資產負債_既有債務!$G$25:$G$25<3)))+輸入與假設!F$339 -> 36.467458 | G23: =4*輸入與假設!$C$316*(1+輸入與假設!$C$317)^4*運營_產能與收入!G7*(輸入與假設!$C$318+F97+SUMPRODUCT(資產負債_既有債務!$D$29:$D$29*資產負債_既有債務!$H$25:$H$25*(資產負債_既有債務!$G$25:$G$25<4)))+輸入與假設!G$339 -> 39.160652 | I23: 普通股＝每股每季 × 4 × 期間長度 ×(基礎股數＋前期累計瀑布新股＋已強制轉換特別股)＋特別股股利；FY27＝年初至今 實際＋全年 模型（v0.1b）
A24: ⑨ 回購（瀑布：現金不足時先減） | B24: US$bn | C24: =輸入與假設!$C$464+C76 -> 0 | D24: =D76 -> 0 | E24: =E76 -> 22.271 | F24: =F76 -> 22.271 | G24: =G76 -> 1.5519493 | I24: FY27＝年初至今 實際＋全年 瀑布後實際回購；計畫與被迫減少見下方「期前融資瀑布」（MAG v0.1b）
A25: 電力（overlay） | B25: US$bn | C25: =IF(輸入與假設!$C$232=1,運營_產能與收入!C9*8760*輸入與假設!C$234*輸入與假設!C$233/1000000000*運營_產能與收入!C7,0) -> 0 | D25: =IF(輸入與假設!$C$232=1,運營_產能與收入!D9*8760*輸入與假設!D$234*輸入與假設!D$233/1000000000*運營_產能與收入!D7,0) -> 0 | E25: =IF(輸入與假設!$C$232=1,運營_產能與收入!E9*8760*輸入與假設!E$234*輸入與假設!E$233/1000000000*運營_產能與收入!E7,0) -> 0 | F25: =IF(輸入與假設!$C$232=1,運營_產能與收入!F9*8760*輸入與假設!F$234*輸入與假設!F$233/1000000000*運營_產能與收入!F7,0) -> 0 | G25: =IF(輸入與假設!$C$232=1,運營_產能與收入!G9*8760*輸入與假設!G$234*輸入與假設!G$233/1000000000*運營_產能與收入!G7,0) -> 0 | I25: ＝已連網 MW×8760×PUE×電價÷1e9×期間係數。EBITDA 率已含電費，預設關閉
A26: 維護（overlay） | B26: US$bn | C26: =IF(輸入與假設!$C$232=1,運營_產能與收入!C9*輸入與假設!C$235/1000*運營_產能與收入!C7,0) -> 0 | D26: =IF(輸入與假設!$C$232=1,運營_產能與收入!D9*輸入與假設!D$235/1000*運營_產能與收入!D7,0) -> 0 | E26: =IF(輸入與假設!$C$232=1,運營_產能與收入!E9*輸入與假設!E$235/1000*運營_產能與收入!E7,0) -> 0 | F26: =IF(輸入與假設!$C$232=1,運營_產能與收入!F9*輸入與假設!F$235/1000*運營_產能與收入!F7,0) -> 0 | G26: =IF(輸入與假設!$C$232=1,運營_產能與收入!G9*輸入與假設!G$235/1000*運營_產能與收入!G7,0) -> 0
A27: ⑤ 排程還本（季報到期表） | B27: US$bn | C27: =輸入與假設!$C$449+IF(輸入與假設!$C$311=1,輸入與假設!C$340,0)+資產負債_既有債務!C40 -> 9.25 | D27: =IF(輸入與假設!$C$311=1,輸入與假設!D$340,0)+資產負債_既有債務!D40 -> 0 | E27: =IF(輸入與假設!$C$311=1,輸入與假設!E$340,0)+資產負債_既有債務!E40 -> 2.001 | F27: =IF(輸入與假設!$C$311=1,輸入與假設!F$340,0)+資產負債_既有債務!F40 -> 0 | G27: =IF(輸入與假設!$C$311=1,輸入與假設!G$340,0)+資產負債_既有債務!G40 -> 0.5 | I27: FY27＝年初至今 實際還款 0.0＋全年 到期表 9.25
A28: ⑥ capped call 支出（年初至今 實際） | B28: US$bn | C28: =輸入與假設!$C$450 -> 0 | D28: =0 -> 0 | E28: =0 -> 0 | F28: =0 -> 0 | G28: =0 -> 0 | I28: 可轉債配套 capped call 現金支出（未見揭露，0）
A29: ⑦ 現金稅（全年 起） | B29: US$bn | C29: =輸入與假設!$C$333*MAX(0,運營_產能與收入!C38*輸入與假設!C$229+輸入與假設!C$56+輸入與假設!C$220-輸入與假設!C$221-運營_產能與收入!C62-輸入與假設!C$303-輸入與假設!C$342) -> 36.000564 | D29: =輸入與假設!$C$333*MAX(0,運營_產能與收入!D38*輸入與假設!D$229+輸入與假設!D$56+輸入與假設!D$220-輸入與假設!D$221-運營_產能與收入!D62-輸入與假設!D$303-輸入與假設!D$342) -> 40.78064 | E29: =輸入與假設!$C$333*MAX(0,運營_產能與收入!E38*輸入與假設!E$229+輸入與假設!E$56+輸入與假設!E$220-輸入與假設!E$221-運營_產能與收入!E62-輸入與假設!E$303-輸入與假設!E$342) -> 45.489573 | F29: =輸入與假設!$C$333*MAX(0,運營_產能與收入!F38*輸入與假設!F$229+輸入與假設!F$56+輸入與假設!F$220-輸入與假設!F$221-運營_產能與收入!F62-輸入與假設!F$303-輸入與假設!F$342) -> 49.77149 | G29: =輸入與假設!$C$333*MAX(0,運營_產能與收入!G38*輸入與假設!G$229+輸入與假設!G$56+輸入與假設!G$220-輸入與假設!G$221-運營_產能與收入!G62-輸入與假設!G$303-輸入與假設!G$342) -> 53.427004 | I29: ＝稅率 × MAX(0, 損益 EBITDA − 車隊 D&A − 存量利息)；年初至今 的稅已含在 CFO 內（v0.1b）
A30: 用途合計（現金口徑） | B30: US$bn | C30: =C13+C16+C21+C22+C25+C26+C27+C28+C29+C23+C24 -> 289.91057 | D30: =D13+D16+D21+D22+D25+D26+D27+D28+D29+D23+D24 -> 308.51232 | E30: =E13+E16+E21+E22+E25+E26+E27+E28+E29+E23+E24 -> 350.82506 | F30: =F13+F16+F21+F22+F25+F26+F27+F28+F29+F23+F24 -> 401.52124 | G30: =G13+G16+G21+G22+G25+G26+G27+G28+G29+G23+G24 -> 503.42225 | I30: FY27 的 年初至今 部分採季報現金流量表口徑（現金購置、還款、JV、capped call）；年初至今 的利息與租金已含在 CFO 內，不重複列
A31: 來源（四層）
A32: Ⓐ0 年初至今 實際營運現金流（CFO） | B32: US$bn | C32: =輸入與假設!$C$444 -> 0 | D32: =0 -> 0 | E32: =0 -> 0 | F32: =0 -> 0 | G32: =0 -> 0 | I32: 季報實際值，取代模型推算；已含 年初至今 的利息、租金與客戶預付
A33: Ⓐ RPO 現金（全年 起） | B33: US$bn | C33: =運營_產能與收入!C40 -> 0 | D33: =運營_產能與收入!D40 -> 0 | E33: =運營_產能與收入!E40 -> 0 | F33: =運營_產能與收入!F40 -> 0 | G33: =運營_產能與收入!G40 -> 0
A34: Ⓑ 新簽約現金 | B34: US$bn | C34: =運營_產能與收入!C41 -> 46.292949 | D34: =運營_產能與收入!D41 -> 75.515734 | E34: =運營_產能與收入!E41 -> 105.66974 | F34: =運營_產能與收入!F41 -> 135.97718 | G34: =運營_產能與收入!G41 -> 166.36199
A35: Ⓒ 非算力服務現金 | B35: US$bn | C35: =輸入與假設!C$230 -> 0 | D35: =輸入與假設!D$230 -> 0 | E35: =輸入與假設!E$230 -> 0 | F35: =輸入與假設!F$230 -> 0 | G35: =輸入與假設!G$230 -> 0
A36: Ⓒ2 其他事業 EBITDA（全年 起） | B36: US$bn | C36: =輸入與假設!C$56 -> -11.449 | D36: =輸入與假設!D$56 -> -12.477 | E36: =輸入與假設!E$56 -> -12.477 | F36: =輸入與假設!F$56 -> -12.477 | G36: =輸入與假設!G$56 -> -12.477 | I36: 非核心事業 EBITDA（負值＝燒錢），視為現金（v0.1b）
A37: Ⓒ3 非 AI 事業 EBITDA（全年 起） | B37: US$bn | C37: =輸入與假設!C$220-輸入與假設!C$221 -> 198.90833 | D37: =輸入與假設!D$220-輸入與假設!D$221 -> 223.98076 | E37: =輸入與假設!E$220-輸入與假設!E$221 -> 248.94593 | F37: =輸入與假設!F$220-輸入與假設!F$221 -> 272.53506 | G37: =輸入與假設!G$220-輸入與假設!G$221 -> 293.41139 | I37: 各線 EBITDA − 其他攤銷（視為等額現金支出），視為現金（現金稅另列於用途；MAG v0.1b）
A38: Ⓒ4 減：延誤罰則（營業費用） | B38: US$bn | C38: =-運營_產能與收入!C62 -> 0 | D38: =-運營_產能與收入!D62 -> 0 | E38: =-運營_產能與收入!E62 -> 0 | F38: =-運營_產能與收入!F62 -> 0 | G38: =-運營_產能與收入!G62 -> 0 | I38: 建設延誤期間應計費而未計費營收 × 罰則比例（預設 0；v0.2）
A39: Ⓒ5 加回：股權報酬（非現金） | B39: US$bn | C39: =輸入與假設!$C$57*(運營_產能與收入!C38+輸入與假設!C$219) -> 14.857708 | D39: =輸入與假設!$C$57*(運營_產能與收入!D38+輸入與假設!D$219) -> 17.740295 | E39: =輸入與假設!$C$57*(運營_產能與收入!E38+輸入與假設!E$219) -> 20.65742 | F39: =輸入與假設!$C$57*(運營_產能與收入!F38+輸入與假設!F$219) -> 23.49146 | G39: =輸入與假設!$C$57*(運營_產能與收入!G38+輸入與假設!G$219) -> 26.149384 | I39: ＝SBC 占營收 × 模型期總營收（分部營業利益已扣 SBC；年初至今 已含在實際 CFO；MAG v0.1b）
A40: Ⓒ6 首期營運資金變動（上年同期實際） | B40: US$bn | C40: =IF(ISBLANK(輸入與假設!$C$58),0,輸入與假設!$C$58) -> -4.895 | D40: =0 -> 0 | E40: =0 -> 0 | F40: =0 -> 0 | G40: =0 -> 0 | I40: FY27 剩餘季度＝上一年度同期實際（流入為正；10-Q／10-K 現金流量表 [Derived]）；之後年度資金模型不計營運資金（MAG v0.1b r2 C14）
A41: Ⓓ 客戶預付（全年 起） | B41: US$bn | C41: =C8 -> 0 | D41: =D8 -> 0 | E41: =E8 -> 0 | F41: =F8 -> 0 | G41: =G8 -> 0
...

Sheet 季度追蹤
A1: 季度追蹤 — 焦點季的模型／共識／指引／實際與差距（由年度模型拆分；只用於追蹤，不影響年度數字與目標價）
A2: 設定與實際數在『輸入與假設』J 區，共識在 I 區；缺資料顯示「不適用」，實際數空白＝待公布。差距超過門檻的項目附差異原因（拆法＝所屬期間合計差距在門檻內）。第 2 區為 6 季路徑與拆分明細（預設收合）。
A4: 1｜焦點季（『輸入與假設』J 區選擇）：模型／共識／指引／實際與差距
A5: 指標 | B5: 單位 | C5: 模型 | D5: 共識 | E5: 模型 vs 共識 | F5: 指引（低） | G5: 指引（高） | H5: 模型 vs 指引中點 | I5: 實際 | J5: 實際 vs 模型 | K5: 實際 vs 共識 | L5: 實際 vs 指引中點 | M5: 利潤率 pt：模型 vs 共識 | N5: 模型 vs 指引 | O5: 實際 vs 模型 | P5: 實際 vs 共識 | Q5: 實際 vs 指引
A6: 焦點｜營收 | B6: US$bn | C6: =INDEX($C$22:$H$22,輸入與假設!$C$530) -> 93.748759 | D6: =INDEX($C$37:$H$37,輸入與假設!$C$530) -> 90.685 | E6: =INDEX($C$47:$H$47,輸入與假設!$C$530) -> 0.033784626 | F6: =IF(ISNUMBER(INDEX($C$32:$H$32,輸入與假設!$C$530)),INDEX($C$32:$H$32,輸入與假設!$C$530),"不適用") -> 89.85 | G6: =INDEX($C$33:$H$33,輸入與假設!$C$530) -> 90.95 | H6: =INDEX($C$48:$H$48,輸入與假設!$C$530) -> 0.037043792 | I6: =IF(ISNUMBER(INDEX($C$41:$H$41,輸入與假設!$C$530)),INDEX($C$41:$H$41,輸入與假設!$C$530),"待公布") -> 待公布 | J6: =INDEX($C$49:$H$49,輸入與假設!$C$530) | K6: =INDEX($C$50:$H$50,輸入與假設!$C$530) | L6: =INDEX($C$51:$H$51,輸入與假設!$C$530)
A7: 焦點｜調整後 EBITDA | B7: US$bn | C7: =INDEX($C$28:$H$28,輸入與假設!$C$530) -> 54.330009 | D7: =INDEX($C$38:$H$38,輸入與假設!$C$530) -> 56.56 | E7: =INDEX($C$52:$H$52,輸入與假設!$C$530) -> -2.2299909 | F7: 不適用 | G7: 不適用 | H7: =INDEX($C$53:$H$53,輸入與假設!$C$530) -> 不適用 | I7: =IF(ISNUMBER(INDEX($C$42:$H$42,輸入與假設!$C$530)),INDEX($C$42:$H$42,輸入與假設!$C$530),"待公布") -> 待公布 | J7: =INDEX($C$54:$H$54,輸入與假設!$C$530) | K7: =INDEX($C$55:$H$55,輸入與假設!$C$530) | L7: =INDEX($C$56:$H$56,輸入與假設!$C$530) | M7: =INDEX($C$57:$H$57,輸入與假設!$C$530) -> -0.044169644 | N7: =INDEX($C$58:$H$58,輸入與假設!$C$530) -> 不適用 | O7: =INDEX($C$59:$H$59,輸入與假設!$C$530) | P7: =INDEX($C$60:$H$60,輸入與假設!$C$530) | Q7: =INDEX($C$61:$H$61,輸入與假設!$C$530)
A8: 焦點｜EBITDA 率 | B8: % | C8: =INDEX($C$27:$H$27,輸入與假設!$C$530) -> 0.57952777 | D8: =INDEX($C$39:$H$39,輸入與假設!$C$530) -> 0.62369741 | E8: =INDEX($C$62:$H$62,輸入與假設!$C$530) -> -0.044169644 | F8: 不適用 | G8: 不適用 | H8: =INDEX($C$63:$H$63,輸入與假設!$C$530) -> 不適用 | I8: =IF(ISNUMBER(INDEX($C$43:$H$43,輸入與假設!$C$530)),INDEX($C$43:$H$43,輸入與假設!$C$530),"待公布") -> 待公布 | J8: =INDEX($C$64:$H$64,輸入與假設!$C$530) | K8: =INDEX($C$65:$H$65,輸入與假設!$C$530) | L8: =INDEX($C$66:$H$66,輸入與假設!$C$530)
A9: 焦點｜調整後營業利益 | B9: US$bn | C9: =INDEX($C$31:$H$31,輸入與假設!$C$530) -> 41.217769 | D9: 不適用 | E9: =INDEX($C$67:$H$67,輸入與假設!$C$530) -> 不適用 | F9: =IF(ISNUMBER(INDEX($C$34:$H$34,輸入與假設!$C$530)),INDEX($C$34:$H$34,輸入與假設!$C$530),"不適用") -> 43.15 | G9: =INDEX($C$35:$H$35,輸入與假設!$C$530) -> 44.55 | H9: =INDEX($C$68:$H$68,輸入與假設!$C$530) -> -2.6322306 | I9: =IF(ISNUMBER(INDEX($C$44:$H$44,輸入與假設!$C$530)),INDEX($C$44:$H$44,輸入與假設!$C$530),"待公布") -> 待公布 | J9: =INDEX($C$69:$H$69,輸入與假設!$C$530) | K9: =INDEX($C$70:$H$70,輸入與假設!$C$530) | L9: =INDEX($C$71:$H$71,輸入與假設!$C$530) | M9: =INDEX($C$72:$H$72,輸入與假設!$C$530) -> 不適用 | N9: =INDEX($C$73:$H$73,輸入與假設!$C$530) -> -0.045404343 | O9: =INDEX($C$74:$H$74,輸入與假設!$C$530) | P9: =INDEX($C$75:$H$75,輸入與假設!$C$530) | Q9: =INDEX($C$76:$H$76,輸入與假設!$C$530)
A10: 焦點｜CapEx（毛額） | B10: US$bn | C10: =INDEX($C$36:$H$36,輸入與假設!$C$530) -> 51.05 | D10: 不適用 | E10: =INDEX($C$77:$H$77,輸入與假設!$C$530) -> 不適用 | F10: 不適用 | G10: 不適用 | H10: =INDEX($C$78:$H$78,輸入與假設!$C$530) -> 不適用 | I10: =IF(ISNUMBER(INDEX($C$45:$H$45,輸入與假設!$C$530)),INDEX($C$45:$H$45,輸入與假設!$C$530),"待公布") -> 待公布 | J10: =INDEX($C$79:$H$79,輸入與假設!$C$530) | K10: =INDEX($C$80:$H$80,輸入與假設!$C$530) | L10: =INDEX($C$81:$H$81,輸入與假設!$C$530)
A11: 焦點｜季末已連網 MW-IT | B11: MW | C11: =INDEX($C$19:$H$19,輸入與假設!$C$530) -> 3881.8 | D11: 不適用 | E11: =INDEX($C$82:$H$82,輸入與假設!$C$530) -> 不適用 | F11: 不適用 | G11: 不適用 | H11: =INDEX($C$83:$H$83,輸入與假設!$C$530) -> 不適用 | I11: =IF(ISNUMBER(INDEX($C$46:$H$46,輸入與假設!$C$530)),INDEX($C$46:$H$46,輸入與假設!$C$530),"待公布") -> 待公布 | J11: =INDEX($C$84:$H$84,輸入與假設!$C$530) | K11: =INDEX($C$85:$H$85,輸入與假設!$C$530) | L11: =INDEX($C$86:$H$86,輸入與假設!$C$530)
A12: 焦點｜季度 | C12: =INDEX($C$16:$H$16,輸入與假設!$C$530) -> Q1 FY27
A13: 焦點｜差異原因 | C13: =IF(INDEX($C$123:$H$123,輸入與假設!$C$530)="","無（差距皆在 "&IF(ROUND(ABS(輸入與假設!$C$524)*100,4)=INT(ROUND(ABS(輸入與假設!$C$524)*100,4)),TEXT(ROUND(ABS(輸入與假設!$C$524)*100,4),"0"),TEXT(ROUND(ABS(輸入與假設!$C$524)*100,4),"0.0"))&"%"&" 以內）",INDEX($C$123:$H$123,輸入與假設!$C$530)) -> 營收 vs 指引中點 +3.7%：觀點（營收＝對外 AI 雲端（在役 MW × 每 MW 年收入，Tokenomics × k）＋各分部依近四季年增率收斂；年度總額線性分到各季，未建模季節性）；調整後 EBITDA vs 共識 −$2.23bn／−4.4pt：觀點（模型 EBITDA 率 58.0%；EBITDA＝分部營業利益＋分攤 D&A 與 AI 雲端 Tokenomics 由下而上營運成本）；調整後營業利益 vs 指引中點 −$2.63bn／−4.5pt：觀點（模型折舊 13.11 依期初 PP&E 與資本支出推算；營業利益＝EBITDA − 折舊，年度總額線性分到各季）
A15: 2｜6 季路徑、共識、指引、實際與差距（明細；第 1 區以焦點季引用本區）
A16: 項目 | B16: 單位 | C16: Q1 FY27 | D16: Q2 FY27 | E16: Q3 FY27 | F16: Q4 FY27 | G16: Q1 FY28 | H16: Q2 FY28
A17: 所屬期間 | C17: =輸入與假設!C$529 -> 1 | D17: =輸入與假設!D$529 -> 1 | E17: =輸入與假設!E$529 -> 1 | F17: =輸入與假設!F$529 -> 1 | G17: =輸入與假設!G$529 -> 2 | H17: =輸入與假設!H$529 -> 2 | J17: 1＝FY27、2＝FY28
A18: 季序 | C18: 1 | D18: 2 | E18: 3 | F18: 4 | G18: 5 | H18: 6 | J18: EBITDA 率直線的 x 軸
A19: 季末已連網 MW-IT（模型） | B19: MW | C19: =輸入與假設!$C$532+(輸入與假設!C$36-輸入與假設!$C$532)*1/4 -> 3881.8 | D19: =輸入與假設!$C$532+(輸入與假設!C$36-輸入與假設!$C$532)*2/4 -> 4513.6 | E19: =輸入與假設!$C$532+(輸入與假設!C$36-輸入與假設!$C$532)*3/4 -> 5145.4 | F19: =輸入與假設!$C$532+(輸入與假設!C$36-輸入與假設!$C$532)*4/4 -> 5777.2 | G19: =輸入與假設!C$36+(輸入與假設!D$36-輸入與假設!C$36)*1/2 -> 7040.8 | H19: =輸入與假設!C$36+(輸入與假設!D$36-輸入與假設!C$36)*2/2 -> 8304.4 | J19: 期初與期末 Accepted 之間線性內插；第 1 期起點見 J 區
A20: 平均在役 MW（Billable，拆分依據） | B20: MW | C20: =輸入與假設!$C$29+(運營_產能與收入!C$11-輸入與假設!$C$29)*1/8 -> 3565.875 | D20: =輸入與假設!$C$29+(運營_產能與收入!C$11-輸入與假設!$C$29)*3/8 -> 4197.625 | E20: =輸入與假設!$C$29+(運營_產能與收入!C$11-輸入與假設!$C$29)*5/8 -> 4829.375 | F20: =輸入與假設!$C$29+(運營_產能與收入!C$11-輸入與假設!$C$29)*7/8 -> 5461.125 | G20: =運營_產能與收入!C$11+(運營_產能與收入!D$11-運營_產能與收入!C$11)*1/4 -> 6408.75 | H20: =運營_產能與收入!C$11+(運營_產能與收入!D$11-運營_產能與收入!C$11)*3/4 -> 7672.25 | J20: 期初與期末 Billable 之間線性內插的季平均
A21: 季內新增 Accepted MW | B21: MW | C21: =C19-輸入與假設!$C$532 -> 631.8 | D21: =D19-C19 -> 631.8 | E21: =E19-D19 -> 631.8 | F21: =F19-E19 -> 631.8 | G21: =G19-輸入與假設!C$36 -> 1263.6 | H21: =H19-G19 -> 1263.6 | J21: CapEx 拆分依據
A22: 營收（模型） | B22: US$bn | C22: =輸入與假設!$C$531+1*(損益!C9-4*輸入與假設!$C$531)/10 -> 93.748759 | D22: =輸入與假設!$C$531+2*(損益!C9-4*輸入與假設!$C$531)/10 -> 97.490518 | E22: =輸入與假設!$C$531+3*(損益!C9-4*輸入與假設!$C$531)/10 -> 101.23228 | F22: =輸入與假設!$C$531+4*(損益!C9-4*輸入與假設!$C$531)/10 -> 104.97404 | G22: =損益!D9*G20/(G20+H20) -> 215.98646 | H22: =損益!D9*H20/(G20+H20) -> 258.56869 | J22: 拆分方法見『輸入與假設』J 區與 HTML「拆分方法」
A23: EBITDA 率直線｜各期營收合計 S | C23: =C22+D22+E22+F22 -> 397.44559 | D23: =G22+H22 -> 474.55515 | J23: 欄＝期間（FY27、FY28）
A24: EBITDA 率直線｜營收 × 季序合計 T | C24: =C22*C18+D22*D18+E22*E18+F22*F18 -> 1012.3228 | D24: =G22*G18+H22*H18 -> 2631.3444 | J24: 欄＝期間（FY27、FY28）
A25: EBITDA 率直線｜年度 EBITDA E | C25: =損益!C22 -> 233.75228 | D25: =損益!D22 -> 287.0195 | J25: 欄＝期間（FY27、FY28）
A26: EBITDA 率直線｜截距 a／斜率 b | C26: =(C25*D24-C24*D25)/(C23*D24-C24*D23) -> 0.5739632 | D26: =(C23*D25-D23*C25)/(C23*D24-C24*D23) -> 0.0055645731 | J26: 解兩式：Σ營收×(a＋b×季序)＝各期年度 EBITDA
A27: EBITDA 率（模型） | B27: % | C27: =$C$26+$D$26*C18 -> 0.57952777 | D27: =$C$26+$D$26*D18 -> 0.58509234 | E27: =$C$26+$D$26*E18 -> 0.59065692 | F27: =$C$26+$D$26*F18 -> 0.59622149 | G27: =$C$26+$D$26*G18 -> 0.60178606 | H27: =$C$26+$D$26*H18 -> 0.60735064 | J27: 跨季一條直線，季度 EBITDA 加總＝年度
A28: 調整後 EBITDA（模型） | B28: US$bn | C28: =C22*C27 -> 54.330009 | D28: =D22*D27 -> 57.040955 | E28: =E22*E27 -> 59.793544 | F28: =F22*F27 -> 62.587776 | G28: =G22*G27 -> 129.97764 | H28: =H22*H27 -> 157.04186
A29: 車隊折舊（模型） | B29: US$bn | C29: =輸入與假設!C$303/4 -> 13.11224 | D29: =輸入與假設!C$303/4 -> 13.11224 | E29: =輸入與假設!C$303/4 -> 13.11224 | F29: =輸入與假設!C$303/4 -> 13.11224 | G29: =輸入與假設!D$303/2 -> 40.980344 | H29: =輸入與假設!D$303/2 -> 40.980344 | J29: ＝期間 D&A（AI＋非 AI 分池）÷ 期內季數
A30: 其他攤銷（模型） | B30: US$bn | C30: =輸入與假設!C$221*C22/MAX(0.000000001,C23) -> 0 | D30: =輸入與假設!C$221*D22/MAX(0.000000001,C23) -> 0 | E30: =輸入與假設!C$221*E22/MAX(0.000000001,C23) -> 0 | F30: =輸入與假設!C$221*F22/MAX(0.000000001,C23) -> 0 | G30: =輸入與假設!D$221*G22/MAX(0.000000001,D23) -> 0 | H30: =輸入與假設!D$221*H22/MAX(0.000000001,D23) -> 0 | J30: ＝期間非 AI 事業其他攤銷 × 季營收占比（MAG v0.1b）
A31: 調整後營業利益（模型） | B31: US$bn | C31: =C28-C29-C30 -> 41.217769 | D31: =D28-D29-D30 -> 43.928716 | E31: =E28-E29-E30 -> 46.681304 | F31: =F28-F29-F30 -> 49.475536 | G31: =G28-G29-G30 -> 88.997296 | H31: =H28-H29-H30 -> 116.06151 | J31: ＝調整後 EBITDA − 車隊折舊 − 其他攤銷（未扣 SBC）
A32: 指引｜營收（低） | B32: US$bn | C32: =IF(ISNUMBER(輸入與假設!C$541),輸入與假設!C$541,"不適用") -> 89.85 | D32: =IF(ISNUMBER(輸入與假設!D$541),輸入與假設!D$541,"不適用") -> 不適用 | E32: =IF(ISNUMBER(輸入與假設!E$541),輸入與假設!E$541,"不適用") -> 不適用 | F32: =IF(ISNUMBER(輸入與假設!F$541),輸入與假設!F$541,"不適用") -> 不適用 | G32: =IF(ISNUMBER(輸入與假設!G$541),輸入與假設!G$541,"不適用") -> 不適用 | H32: =IF(ISNUMBER(輸入與假設!H$541),輸入與假設!H$541,"不適用") -> 不適用
A33: 指引｜營收（高） | B33: US$bn | C33: =IF(ISNUMBER(輸入與假設!C$542),輸入與假設!C$542,"不適用") -> 90.95 | D33: =IF(ISNUMBER(輸入與假設!D$542),輸入與假設!D$542,"不適用") -> 不適用 | E33: =IF(ISNUMBER(輸入與假設!E$542),輸入與假設!E$542,"不適用") -> 不適用 | F33: =IF(ISNUMBER(輸入與假設!F$542),輸入與假設!F$542,"不適用") -> 不適用 | G33: =IF(ISNUMBER(輸入與假設!G$542),輸入與假設!G$542,"不適用") -> 不適用 | H33: =IF(ISNUMBER(輸入與假設!H$542),輸入與假設!H$542,"不適用") -> 不適用
A34: 指引｜調整後營業利益（低） | B34: US$bn | C34: =IF(ISNUMBER(輸入與假設!C$543),輸入與假設!C$543,"不適用") -> 43.15 | D34: =IF(ISNUMBER(輸入與假設!D$543),輸入與假設!D$543,"不適用") -> 不適用 | E34: =IF(ISNUMBER(輸入與假設!E$543),輸入與假設!E$543,"不適用") -> 不適用 | F34: =IF(ISNUMBER(輸入與假設!F$543),輸入與假設!F$543,"不適用") -> 不適用 | G34: =IF(ISNUMBER(輸入與假設!G$543),輸入與假設!G$543,"不適用") -> 不適用 | H34: =IF(ISNUMBER(輸入與假設!H$543),輸入與假設!H$543,"不適用") -> 不適用
A35: 指引｜調整後營業利益（高） | B35: US$bn | C35: =IF(ISNUMBER(輸入與假設!C$544),輸入與假設!C$544,"不適用") -> 44.55 | D35: =IF(ISNUMBER(輸入與假設!D$544),輸入與假設!D$544,"不適用") -> 不適用 | E35: =IF(ISNUMBER(輸入與假設!E$544),輸入與假設!E$544,"不適用") -> 不適用 | F35: =IF(ISNUMBER(輸入與假設!F$544),輸入與假設!F$544,"不適用") -> 不適用 | G35: =IF(ISNUMBER(輸入與假設!G$544),輸入與假設!G$544,"不適用") -> 不適用 | H35: =IF(ISNUMBER(輸入與假設!H$544),輸入與假設!H$544,"不適用") -> 不適用
A36: CapEx（毛額）（模型） | B36: US$bn | C36: =IF((C21+D21+E21+F21)>0,輸入與假設!C$302*C21/(C21+D21+E21+F21),輸入與假設!C$302/4) -> 51.05 | D36: =IF((C21+D21+E21+F21)>0,輸入與假設!C$302*D21/(C21+D21+E21+F21),輸入與假設!C$302/4) -> 51.05 | E36: =IF((C21+D21+E21+F21)>0,輸入與假設!C$302*E21/(C21+D21+E21+F21),輸入與假設!C$302/4) -> 51.05 | F36: =IF((C21+D21+E21+F21)>0,輸入與假設!C$302*F21/(C21+D21+E21+F21),輸入與假設!C$302/4) -> 51.05 | G36: =IF((G21+H21)>0,輸入與假設!D$302*G21/(G21+H21),輸入與假設!D$302/2) -> 112.22779 | H36: =IF((G21+H21)>0,輸入與假設!D$302*H21/(G21+H21),輸入與假設!D$302/2) -> 112.22779 | J36: 依季內新增 Accepted MW
A37: 共識｜營收 | B37: US$bn | C37: =IF(ISNUMBER(輸入與假設!$C$510),輸入與假設!$C$510,"不適用") -> 90.685 | D37: 不適用 | E37: 不適用 | F37: 不適用 | G37: 不適用 | H37: 不適用 | J37: I 區季度共識 [Interested-party]
A38: 共識｜調整後 EBITDA | B38: US$bn | C38: =IF(ISNUMBER(輸入與假設!$C$511),輸入與假設!$C$511,"不適用") -> 56.56 | D38: 不適用 | E38: 不適用 | F38: 不適用 | G38: 不適用 | H38: 不適用 | J38: I 區季度共識 [Interested-party]
A39: 共識｜EBITDA 率 [Derived] | B39: % | C39: =IF(AND(ISNUMBER(輸入與假設!$C$511),ISNUMBER(輸入與假設!$C$510)),輸入與假設!$C$511/輸入與假設!$C$510,"不適用") -> 0.62369741 | D39: 不適用 | E39: 不適用 | F39: 不適用 | G39: 不適用 | H39: 不適用 | J39: ＝共識 EBITDA ÷ 共識營收
A40: 共識 EBIT（供應商口徑） | B40: US$bn | C40: =IF(ISNUMBER(輸入與假設!$C$512),輸入與假設!$C$512,"不適用") -> 43.994 | D40: 不適用 | E40: 不適用 | F40: 不適用 | G40: 不適用 | H40: 不適用 | J40: 口徑未揭露：只列不比較
A41: 實際｜營收 | B41: US$bn | C41: =IF(ISNUMBER(輸入與假設!C$533),輸入與假設!C$533,"") | D41: =IF(ISNUMBER(輸入與假設!D$533),輸入與假設!D$533,"") | E41: =IF(ISNUMBER(輸入與假設!E$533),輸入與假設!E$533,"") | F41: =IF(ISNUMBER(輸入與假設!F$533),輸入與假設!F$533,"") | G41: =IF(ISNUMBER(輸入與假設!G$533),輸入與假設!G$533,"") | H41: =IF(ISNUMBER(輸入與假設!H$533),輸入與假設!H$533,"")
A42: 實際｜調整後 EBITDA | B42: US$bn | C42: =IF(ISNUMBER(輸入與假設!C$534),輸入與假設!C$534,"") | D42: =IF(ISNUMBER(輸入與假設!D$534),輸入與假設!D$534,"") | E42: =IF(ISNUMBER(輸入與假設!E$534),輸入與假設!E$534,"") | F42: =IF(ISNUMBER(輸入與假設!F$534),輸入與假設!F$534,"") | G42: =IF(ISNUMBER(輸入與假設!G$534),輸入與假設!G$534,"") | H42: =IF(ISNUMBER(輸入與假設!H$534),輸入與假設!H$534,"")
...

Sheet 運營_產能與收入
A1: 產能與收入 — 合約排程 vs 機房產能
A2: 兩條線獨立產生後相減：排程>容量→瓶頸（收不到）；容量>排程→剩餘產能（要靠新簽約賣掉）
A3: FY27 欄口徑：MW 為年底存量；標示「（模型期）」的收入列只含 2027 全年——RPO 桶自 2026-06-30 起算，年初至今 收入已實現、不再受產能約束。年初至今 實際單列，兩者相加即 FY27 全年（見本頁「FY26 全年」列）。
A5: 項目 | B5: 單位 | C5: FY27 | D5: FY28 | E5: FY29 | F5: FY30 | G5: FY31 | I5: 公式／來源說明
A6: 模型期間 | C6: ="2026-07-01~06-30" -> 2026-07-01~06-30 | D6: ="2028 全年" -> 2028 全年 | E6: ="2029 全年" -> 2029 全年 | F6: ="2030 全年" -> 2030 全年 | G6: ="2031 全年" -> 2031 全年 | I6: FY27 的模型期只有全年；年初至今 已實現的營收單列於下方
A7: 模型期長度（年） | C7: =輸入與假設!C$34 -> 1 | D7: =輸入與假設!D$34 -> 1 | E7: =輸入與假設!E$34 -> 1 | F7: =輸入與假設!F$34 -> 1 | G7: =輸入與假設!G$34 -> 1 | I7: 只用於下方三處：容量上限、電力、維護——把年率換算成該期金額
A8: （A）機房：容量上限
A9: Accepted MW（已驗收，單調不減） | B9: MW | C9: =MAX(0,輸入與假設!C$36) -> 5777.2 | D9: =MAX(輸入與假設!D$36,C9) -> 8304.4 | E9: =MAX(輸入與假設!E$36,D9) -> 10831.6 | F9: =MAX(輸入與假設!F$36,E9) -> 13358.8 | G9: =MAX(輸入與假設!G$36,F9) -> 15886 | I9: 引擎規則：不得低於前期（產能不會消失）
A10: Billable MW（上限為 Accepted） | B10: MW | C10: =MIN(MAX(0,輸入與假設!C$37),C9) -> 5777 | D10: =MIN(MAX(0,輸入與假設!D$37),D9) -> 8304 | E10: =MIN(MAX(0,輸入與假設!E$37),E9) -> 10831.6 | F10: =MIN(MAX(0,輸入與假設!F$37),F9) -> 13358.8 | G10: =MIN(MAX(0,輸入與假設!G$37),G9) -> 15886 | I10: 引擎規則：可計費不得超過已驗收
A11: Billable MW（延誤後，計費用） | B11: MW | C11: =IF($C$50<=0,$C$10,輸入與假設!$C$29+($C$10-輸入與假設!$C$29)*MAX(0,MIN(1,($C$51-$C$50/12-0)/$C$7))+($D$10-$C$10)*MAX(0,MIN(1,($C$51-$C$50/12-$C$51)/$D$7))+($E$10-$D$10)*MAX(0,MIN(1,($C$51-$C$50/12-$D$51)/$E$7))+($F$10-$E$10)*MAX(0,MIN(1,($C$51-$C$50/12-$E$51)/$F$7))+($G$10-$F$10)*MAX(0,MIN(1,($C$51-$C$50/12-$F$51)/$G$7))) -> 5777 | D11: =IF($C$50<=0,$D$10,輸入與假設!$C$29+($C$10-輸入與假設!$C$29)*MAX(0,MIN(1,($D$51-$C$50/12-0)/$C$7))+($D$10-$C$10)*MAX(0,MIN(1,($D$51-$C$50/12-$C$51)/$D$7))+($E$10-$D$10)*MAX(0,MIN(1,($D$51-$C$50/12-$D$51)/$E$7))+($F$10-$E$10)*MAX(0,MIN(1,($D$51-$C$50/12-$E$51)/$F$7))+($G$10-$F$10)*MAX(0,MIN(1,($D$51-$C$50/12-$F$51)/$G$7))) -> 8304 | E11: =IF($C$50<=0,$E$10,輸入與假設!$C$29+($C$10-輸入與假設!$C$29)*MAX(0,MIN(1,($E$51-$C$50/12-0)/$C$7))+($D$10-$C$10)*MAX(0,MIN(1,($E$51-$C$50/12-$C$51)/$D$7))+($E$10-$D$10)*MAX(0,MIN(1,($E$51-$C$50/12-$D$51)/$E$7))+($F$10-$E$10)*MAX(0,MIN(1,($E$51-$C$50/12-$E$51)/$F$7))+($G$10-$F$10)*MAX(0,MIN(1,($E$51-$C$50/12-$F$51)/$G$7))) -> 10831.6 | F11: =IF($C$50<=0,$F$10,輸入與假設!$C$29+($C$10-輸入與假設!$C$29)*MAX(0,MIN(1,($F$51-$C$50/12-0)/$C$7))+($D$10-$C$10)*MAX(0,MIN(1,($F$51-$C$50/12-$C$51)/$D$7))+($E$10-$D$10)*MAX(0,MIN(1,($F$51-$C$50/12-$D$51)/$E$7))+($F$10-$E$10)*MAX(0,MIN(1,($F$51-$C$50/12-$E$51)/$F$7))+($G$10-$F$10)*MAX(0,MIN(1,($F$51-$C$50/12-$F$51)/$G$7))) -> 13358.8 | G11: =IF($C$50<=0,$G$10,輸入與假設!$C$29+($C$10-輸入與假設!$C$29)*MAX(0,MIN(1,($G$51-$C$50/12-0)/$C$7))+($D$10-$C$10)*MAX(0,MIN(1,($G$51-$C$50/12-$C$51)/$D$7))+($E$10-$D$10)*MAX(0,MIN(1,($G$51-$C$50/12-$D$51)/$E$7))+($F$10-$E$10)*MAX(0,MIN(1,($G$51-$C$50/12-$E$51)/$F$7))+($G$10-$F$10)*MAX(0,MIN(1,($G$51-$C$50/12-$F$51)/$G$7))) -> 15886 | I11: ＝上列往後平移建設延誤月數（以期間長度線性內插；評價日之前取期初校準值）；延誤 0 時＝上列；見（E）區（v0.2）
A12: 期初在役 MW | B12: MW | C12: =輸入與假設!$C$29 -> 3250 | D12: =C11 -> 5777 | E12: =D11 -> 8304 | F12: =E11 -> 10831.6 | G12: =F11 -> 13358.8 | I12: 前期期末＝本期期初（延誤後）
A13: 平均在役 MW（FY27 欄為全年平均） | B13: MW | C13: =IF(輸入與假設!$C$30=1,(C12+C11)/2,C11) -> 4513.5 | D13: =IF(輸入與假設!$C$30=1,(D12+D11)/2,D11) -> 7040.5 | E13: =IF(輸入與假設!$C$30=1,(E12+E11)/2,E11) -> 9567.8 | F13: =IF(輸入與假設!$C$30=1,(F12+F11)/2,F11) -> 12095.2 | G13: =IF(輸入與假設!$C$30=1,(G12+G11)/2,G11) -> 14622.4 | I13: 開關在輸入頁：1＝(期初+期末)/2，0＝期末全期化
A14: 利用率 | B14: % | C14: =輸入與假設!C$38 -> 1 | D14: =輸入與假設!D$38 -> 1 | E14: =輸入與假設!E$38 -> 1 | F14: =輸入與假設!F$38 -> 1 | G14: =輸入與假設!G$38 -> 1
A15: 每 MW 年收入 | B15: US$bn/MW | C15: =輸入與假設!C$39 -> 0.012199576 | D15: =輸入與假設!D$39 -> 0.012704599 | E15: =輸入與假設!E$39 -> 0.013047202 | F15: =輸入與假設!F$39 -> 0.013260179 | G15: =輸入與假設!G$39 -> 0.013405393
A16: 容量上限（模型期最多能交付的收入） | B16: US$bn | C16: =C13*輸入與假設!C$39*輸入與假設!$C$32*輸入與假設!C$38*C7 -> 55.062787 | D16: =D13*輸入與假設!D$39*輸入與假設!$C$32*輸入與假設!D$38*D7 -> 89.44673 | E16: =E13*輸入與假設!E$39*輸入與假設!$C$32*輸入與假設!E$38*E7 -> 124.83302 | F16: =F13*輸入與假設!F$39*輸入與假設!$C$32*輸入與假設!F$38*F7 -> 160.38452 | G16: =G13*輸入與假設!G$39*輸入與假設!$C$32*輸入與假設!G$38*G7 -> 196.01903 | I16: ＝平均在役 MW × 每 MW 年收入 × 利用率 × 期間係數。只看機房，不看合約
A17: （B）合約：排程 RPO
A18: 排程 RPO（模型期，依季報桶分攤） | B18: US$bn | C18: =(輸入與假設!$C$24+輸入與假設!$C$25)*(輸入與假設!C$35/輸入與假設!$C$27)*輸入與假設!$C$26 -> 0 | D18: =(輸入與假設!$C$24+輸入與假設!$C$25)*(輸入與假設!D$35/輸入與假設!$C$27)*輸入與假設!$C$26 -> 0 | E18: =(輸入與假設!$C$24+輸入與假設!$C$25)*(輸入與假設!E$35/輸入與假設!$C$27)*輸入與假設!$C$26 -> 0 | F18: =(輸入與假設!$C$24+輸入與假設!$C$25)*(輸入與假設!F$35/輸入與假設!$C$27)*輸入與假設!$C$26 -> 0 | G18: =(輸入與假設!$C$24+輸入與假設!$C$25)*(輸入與假設!G$35/輸入與假設!$C$27)*輸入與假設!$C$26 -> 0 | I18: ＝(6/30 RPO＋評價日後新增)×本期權重÷權重合計×五期認列比例。只看合約，不看機房
A19: （C）兩條線相減
A20: 產能瓶頸（模型期：排程 − 容量） | B20: US$bn | C20: =MAX(0,C18-C16) -> 0 | D20: =MAX(0,D18-D16) -> 0 | E20: =MAX(0,E18-E16) -> 0 | F20: =MAX(0,F18-F16) -> 0 | G20: =MAX(0,G18-G16) -> 0 | I20: 合約有、機房沒有 → 本期收不到，且不遞延到下期（保守處理）
A21: 期初 RPO 轉換收入（模型期） | B21: US$bn | C21: =C18-C20 -> 0 | D21: =D18-D20 -> 0 | E21: =E18-E20 -> 0 | F21: =F18-F20 -> 0 | G21: =G18-G20 -> 0 | I21: ＝排程 − 瓶頸。當瓶頸>0 時，此值恆等於容量上限
A22: 未被期初 RPO 占用的產能 | B22: US$bn | C22: =MAX(0,C16-C18) -> 55.062787 | D22: =MAX(0,D16-D18) -> 89.44673 | E22: =MAX(0,E16-E18) -> 124.83302 | F22: =MAX(0,F16-F18) -> 160.38452 | G22: =MAX(0,G16-G18) -> 196.01903 | I22: 容量 − 排程。機房有、期初合約沒占滿 → 要靠新簽約
A23: 新產能簽約率 | B23: % | C23: =IF(輸入與假設!$C$31="mw",1,輸入與假設!C$40) -> 1 | D23: =IF(輸入與假設!$C$31="mw",1,輸入與假設!D$40) -> 1 | E23: =IF(輸入與假設!$C$31="mw",1,輸入與假設!E$40) -> 1 | F23: =IF(輸入與假設!$C$31="mw",1,輸入與假設!F$40) -> 1 | G23: =IF(輸入與假設!$C$31="mw",1,輸入與假設!G$40) -> 1 | I23: MW 驅動時固定 100%
A24: 新簽約收入 | B24: US$bn | C24: =C22*C23 -> 55.062787 | D24: =D22*D23 -> 89.44673 | E24: =E22*E23 -> 124.83302 | F24: =F22*F23 -> 160.38452 | G24: =G22*G23 -> 196.01903 | I24: 超出期初 RPO 的產能收入（MW 驅動，簽約率 100%）
A25: 未售產能（浪費） | B25: US$bn | C25: =MAX(0,C16-C21-C24) -> 0 | D25: =MAX(0,D16-D21-D24) -> 0 | E25: =MAX(0,E16-E21-E24) -> 0 | F25: =MAX(0,F16-F21-F24) -> 0 | G25: =MAX(0,G16-G21-G24) -> 0 | I25: 蓋好但賣不掉（MW 驅動時為 0）
A26: 損益用算力收入（模型期＝RPO 轉換＋新簽約） | B26: US$bn | C26: =C21+C24 -> 55.062787 | D26: =D21+D24 -> 89.44673 | E26: =E21+E24 -> 124.83302 | F26: =F21+F24 -> 160.38452 | G26: =G21+G24 -> 196.01903 | I26: 損益與評價頁的算力收入由此連結，確保現金與損益同一組數字
A27: 核對：算力收入 − 平均在役 MW × 每 MW × 利用率 × 期間 | B27: US$bn | C27: =C26-C13*輸入與假設!C$39*輸入與假設!$C$32*輸入與假設!C$38*C7 -> 0 | D27: =D26-D13*輸入與假設!D$39*輸入與假設!$C$32*輸入與假設!D$38*D7 -> 0 | E27: =E26-E13*輸入與假設!E$39*輸入與假設!$C$32*輸入與假設!E$38*E7 -> 0 | F27: =F26-F13*輸入與假設!F$39*輸入與假設!$C$32*輸入與假設!F$38*F7 -> 0 | G27: =G26-G13*輸入與假設!G$39*輸入與假設!$C$32*輸入與假設!G$38*G7 -> 0 | I27: MW 驅動時應為 0：營收可追溯為 MW × 每 MW 年收入 × 利用率（v0.1b）
A28: 對照：評價日起 36 個月營收權重 | B28: % | C28: 1 | D28: 1 | E28: 1 | F28: 0 | G28: 0 | I28: RPO 36 個月內轉換的對照用（只作對照，不驅動營收）
A29: 對照：評價日起 36 個月 MW 驅動營收 | B29: US$bn | C29: =C26*C28 -> 55.062787 | D29: =D26*D28 -> 89.44673 | E29: =E26*E28 -> 124.83302 | F29: =F26*F28 -> 0 | G29: =G26*G28 -> 0 | I29: 合計對照季報 RPO 684 × 36 個月內 75%（含非 AI 事業 RPO）；差額不回推每 MW 單價
A30: 年初至今 實際營收（季報，已實現） | B30: US$bn | C30: =輸入與假設!$C$454 -> 0 | D30: =0 -> 0 | E30: =0 -> 0 | F30: =0 -> 0 | G30: =0 -> 0 | I30: 2026-07-01 至 06-30 已認列營收。已實現，不受全年產能約束，故不進入上方的瓶頸計算
A31: FY27 全年總營收（年初至今 實際＋模型期算力＋服務＋非 AI 事業） | B31: US$bn | C31: =C30+C26+輸入與假設!C$43+輸入與假設!C$219 -> 397.44559 | D31: =D30+D26+輸入與假設!D$43+輸入與假設!D$219 -> 474.55515 | E31: =E30+E26+輸入與假設!E$43+輸入與假設!E$219 -> 552.58861 | F31: =F30+F26+輸入與假設!F$43+輸入與假設!F$219 -> 628.39954 | G31: =G30+G26+輸入與假設!G$43+輸入與假設!G$219 -> 699.49935 | I31: FY27 欄對照公司全年指引 未給全年營收指引；FY28 以後即為該年度總營收
A32: （D）收入 → 現金：三道折扣
A33: 客戶違約率 | B33: % | C33: =輸入與假設!C$41 -> 0 | D33: =輸入與假設!D$41 -> 0 | E33: =輸入與假設!E$41 -> 0 | F33: =輸入與假設!F$41 -> 0 | G33: =輸入與假設!G$41 -> 0
A34: 回收率 | B34: % | C34: =輸入與假設!C$42 -> 0.5 | D34: =輸入與假設!D$42 -> 0.5 | E34: =輸入與假設!E$42 -> 0.5 | F34: =輸入與假設!F$42 -> 0.5 | G34: =輸入與假設!G$42 -> 0.5
A35: 信用損失（期初 RPO 部分） | B35: US$bn | C35: =C21*輸入與假設!C$41*(1-輸入與假設!C$42) -> 0 | D35: =D21*輸入與假設!D$41*(1-輸入與假設!D$42) -> 0 | E35: =E21*輸入與假設!E$41*(1-輸入與假設!E$42) -> 0 | F35: =F21*輸入與假設!F$41*(1-輸入與假設!F$42) -> 0 | G35: =G21*輸入與假設!G$41*(1-輸入與假設!G$42) -> 0 | I35: ＝收入 × 違約率 × (1−回收率)
A36: 收現（期初 RPO 部分） | B36: US$bn | C36: =C21-C35 -> 0 | D36: =D21-D35 -> 0 | E36: =E21-E35 -> 0 | F36: =F21-F35 -> 0 | G36: =G21-G35 -> 0
A37: EBITDA 率（損益與資金共用） | B37: % | C37: =輸入與假設!C$229 -> 0.84073023 | D37: =輸入與假設!D$229 -> 0.84425371 | E37: =輸入與假設!E$229 -> 0.84648872 | F37: =輸入與假設!F$229 -> 0.84781988 | G37: =輸入與假設!G$229 -> 0.84870326 | I37: 起始→穩態線性爬升
A38: 模型期總營收（算力＋服務） | B38: US$bn | C38: =C26+輸入與假設!C$43 -> 55.062787 | D38: =D26+輸入與假設!D$43 -> 89.44673 | E38: =E26+輸入與假設!E$43 -> 124.83302 | F38: =F26+輸入與假設!F$43 -> 160.38452 | G38: =G26+輸入與假設!G$43 -> 196.01903
A39: EBITDAR 率（EBITDA 率＋租金÷營收） | B39: % | C39: =輸入與假設!C$229 -> 0.84073023 | D39: =輸入與假設!D$229 -> 0.84425371 | E39: =輸入與假設!E$229 -> 0.84648872 | F39: =輸入與假設!F$229 -> 0.84781988 | G39: =輸入與假設!G$229 -> 0.84870326 | I39: 租金前的 EBITDA 率。EBITDA 已扣租金，而資金模型把租金列在支出端，所以要加回，避免重複扣除
A40: RPO 現金（可支應資本用途） | B40: US$bn | C40: =C36*C39 -> 0 | D40: =D36*D39 -> 0 | E40: =E36*E39 -> 0 | F40: =F36*F39 -> 0 | G40: =G36*G39 -> 0 | I40: ×EBITDAR 率。租金與利息在支出頁單獨列示
A41: 新簽約現金 | B41: US$bn | C41: =C24*(1-輸入與假設!C$41*(1-輸入與假設!C$42))*C39 -> 46.292949 | D41: =D24*(1-輸入與假設!D$41*(1-輸入與假設!D$42))*D39 -> 75.515734 | E41: =E24*(1-輸入與假設!E$41*(1-輸入與假設!E$42))*E39 -> 105.66974 | F41: =F24*(1-輸入與假設!F$41*(1-輸入與假設!F$42))*F39 -> 135.97718 | G41: =G24*(1-輸入與假設!G$41*(1-輸入與假設!G$42))*G39 -> 166.36199 | I41: 同樣扣信用損失、乘 EBITDAR 率
...

Sheet 運營_站點
A1: 站點租賃 — 公司揭露 vs 季報總額（檢驗租金路徑用）
A2: 季報不揭露逐站租金；下表為具名站點（company.json → defaults.sites），有租約金額者用來檢驗『每 MW 年租金』與模型租金路徑是否一致
A4: 站點 | B4: 營運方 | C4: 契約 MW | D4: 已驗收 MW | E4: 合約總值 $bn | F4: 年期 | G4: 年租金 $bn | H4: 每 MW 年租金 $m | I4: 時程 | J4: 季報對應 | K4: 說明
A5: Fairwater Wisconsin（Mount Pleasant） | B5: Microsoft 自建（OpenAI 與 Microsoft，B200） | C5: 2263 | D5: 369 | E5: 未揭露 | F5: 未揭露 | I5: 2026 | J5: — | K5: Epoch AI：目前 IT 電力 369 MW（2026-10-05 更新；2028Q2 預測 2,263；事實總帳 mw.epoch.fairwaterWI）[Analogy／第三方]
A6: Fairwater Atlanta | B6: Microsoft 自建（OpenAI 與 Microsoft，GB200） | C6: 636 | D6: 636 | E6: 未揭露 | F6: 未揭露 | I6: 2026 | J6: — | K6: Epoch AI：Buildings 1–4 已運轉，636 MW-IT（2026-06-14）
A7: 具名站點合計 | C7: =SUM(C5:C6) -> 2899 | D7: =SUM(D5:D6) -> 1005 | E7: =SUM(E5:E6) -> 0 | G7: =SUM(G5:G6) -> 0 | H7: =IF(I7>0,G7/I7*1000,0) -> 0 | I7: =SUMPRODUCT(ISNUMBER(G5:G6)*C5:C6) -> 0 | K7: 加權每 MW 年租金＝具名站點的市場基準（I 欄＝有租約金額站點的契約 MW；沒有時為 0，不適用）
A9: 對帳：具名站點 vs 季報租賃承諾總額
A10: 季報在帳租賃（未折現，已起租） | E10: 114.392 | K10: company.json → leases.facts.onBal
A11: 季報未起租租賃（未折現） | E11: 329.1 | K11: company.json → leases.facts.notCommenced
A12: 季報單站按造價計租上限 | E12: 0 | K12: company.json → leases.facts.singleCap（無則 0）
A13: 季報已揭露租賃承諾合計 | E13: =SUM(E10:E12) -> 443.492 | K13: 未折現金額
A14: 減：具名站點合約總值 | E14: =-E7 -> 0
A15: ＝ 未具名站點（殘差） | E15: =E13+E14 -> 443.492 | K15: 未具名站點；公司不揭露逐站租金，殘差大是必然
A16: 殘差占季報總額 | E16: =IF(E13<>0,E15/E13,0) -> 1
A18: 檢驗：模型租金路徑 ÷ 在役 MW vs 市場基準
A19: 項目 | B19: 單位 | C19: FY27 | D19: FY28 | E19: FY29 | F19: FY30 | G19: FY31
A20: 模型租金（在帳＋表外） | B20: US$bn | C20: =各期收支!C16 -> 7.9780312 | D20: =各期收支!D16 -> 9.5222813 | E20: =各期收支!E16 -> 10.267531 | F20: =各期收支!F16 -> 11.540781 | G20: =各期收支!G16 -> 12.028
A21: 平均在役 MW（已連網） | B21: MW | C21: =(輸入與假設!C$268+輸入與假設!C$36)/2 -> 4513.6 | D21: =(輸入與假設!D$268+輸入與假設!D$36)/2 -> 7040.8 | E21: =(輸入與假設!E$268+輸入與假設!E$36)/2 -> 9568 | F21: =(輸入與假設!F$268+輸入與假設!F$36)/2 -> 12095.2 | G21: =(輸入與假設!G$268+輸入與假設!G$36)/2 -> 14622.4
A22: 模型期長度（年） | B22: 年 | C22: =輸入與假設!C$34 -> 1 | D22: =輸入與假設!D$34 -> 1 | E22: =輸入與假設!E$34 -> 1 | F22: =輸入與假設!F$34 -> 1 | G22: =輸入與假設!G$34 -> 1
A23: 模型每 MW 年租金 | B23: US$m/MW | C23: =C20/C22/C21*1000 -> 1.7675539 | D23: =D20/D22/D21*1000 -> 1.3524431 | E23: =E20/E22/E21*1000 -> 1.0731115 | F23: =F20/F22/F21*1000 -> 0.95416208 | G23: =G20/G22/G21*1000 -> 0.82257359 | K23: FY27 欄只含全年租金、MW 取全期平均，略有低估
A24: 第三方租賃占比 | C24: 1 | K24: 其餘為自建，成本走 CapEx（company.json → leases.facts.share）[Assumed]
A25: 基準租金（MW×市場基準×占比） | B25: US$bn | C25: =C21*運營_站點!$H$7/1000*$C$24*C22 -> 0 | D25: =D21*運營_站點!$H$7/1000*$C$24*D22 -> 0 | E25: =E21*運營_站點!$H$7/1000*$C$24*E22 -> 0 | F25: =F21*運營_站點!$H$7/1000*$C$24*F22 -> 0 | G25: =G21*運營_站點!$H$7/1000*$C$24*G22 -> 0 | K25: 具名站點有租約金額時才有意義；否則為 0
A26: 差額（基準 − 模型） | B26: US$bn | C26: =C25-C20 -> -7.9780312 | D26: =D25-D20 -> -9.5222813 | E26: =E25-E20 -> -10.267531 | F26: =F25-F20 -> -11.540781 | G26: =G25-G20 -> -12.028 | K26: 正值＝模型租金可能低估的金額
A27: 五期差額合計 | C27: =SUM(C26:G26) -> -51.336625

Sheet 資產負債_既有債務
A1: 債務明細 — 季報（2026-06-30）逐筆＋存量利息推導
A2: 有效利率為現金票息口徑（可轉債＝票息 ÷ 到期累積倍數，本金以到期累積本金計）。本頁算出的存量利息連回『輸入』頁，再進入支出與資金頁
A4: 工具 | B4: 類別 | C4: 到期 | D4: 有效利率 | E4: 6/30 本金 | F4: 年化利息 | I4: 備註
A5: 2009 票據 | B5: 無擔保 | C5: 2039-06 | D5: 0.052 | E5: 0.52 | F5: =D5*E5 -> 0.02704 | I5: 10-K FY26 附註 10：面額 520、票面 5.20%–5.20%（取中點）、到期 2039–2039；到期日取區間中點 [Derived]
A6: 2010 票據 | B6: 無擔保 | C6: 2040-06 | D6: 0.045 | E6: 0.486 | F6: =D6*E6 -> 0.02187 | I6: 10-K FY26 附註 10：面額 486、票面 4.50%–4.50%（取中點）、到期 2040–2040；到期日取區間中點 [Derived]
A7: 2011 票據 | B7: 無擔保 | C7: 2041-06 | D7: 0.053 | E7: 0.718 | F7: =D7*E7 -> 0.038054 | I7: 10-K FY26 附註 10：面額 718、票面 5.30%–5.30%（取中點）、到期 2041–2041；到期日取區間中點 [Derived]
A8: 2012 票據 | B8: 無擔保 | C8: 2042-06 | D8: 0.035 | E8: 0.454 | F8: =D8*E8 -> 0.01589 | I8: 10-K FY26 附註 10：面額 454、票面 3.50%–3.50%（取中點）、到期 2042–2042；到期日取區間中點 [Derived]
A9: 2013 美元票據 | B9: 無擔保 | C9: 2043-06 | D9: 0.04315 | E9: 0.314 | F9: =D9*E9 -> 0.0135491 | I9: 10-K FY26 附註 10：面額 314、票面 3.75%–4.88%（取中點）、到期 2043–2043；到期日取區間中點 [Derived]
A10: 2013 歐元票據 | B10: 無擔保 | C10: 2030-06 | D10: 0.0288 | E10: 2.63 | F10: =D10*E10 -> 0.075744 | I10: 10-K FY26 附註 10：面額 2,630、票面 2.63%–3.13%（取中點）、到期 2028–2033；到期日取區間中點 [Derived]
A11: 2015 票據 | B11: 無擔保 | C11: 2045-06 | D11: 0.04125 | E11: 4.555 | F11: =D11*E11 -> 0.18789375 | I11: 10-K FY26 附註 10：面額 4,555、票面 3.50%–4.75%（取中點）、到期 2035–2055；到期日取區間中點 [Derived]
A12: 2016 票據 | B12: 無擔保 | C12: 2041-06 | D12: 0.03175 | E12: 7.93 | F12: =D12*E12 -> 0.2517775 | I12: 10-K FY26 附註 10：面額 7,930、票面 2.40%–3.95%（取中點）、到期 2026–2056；到期日取區間中點 [Derived]
A13: 2017 票據 | B13: 無擔保 | C13: 2041-06 | D13: 0.039 | E13: 6.833 | F13: =D13*E13 -> 0.266487 | I13: 10-K FY26 附註 10：面額 6,833、票面 3.30%–4.50%（取中點）、到期 2026–2057；到期日取區間中點 [Derived]
A14: 2020 票據（交換） | B14: 無擔保 | C14: 2045-06 | D14: 0.02015 | E14: 10.111 | F14: =D14*E14 -> 0.20373665 | I14: 10-K FY26 附註 10：面額 10,111、票面 1.35%–2.68%（取中點）、到期 2030–2060；到期日取區間中點 [Derived]
A15: 2021 票據（交換） | B15: 無擔保 | C15: 2057-06 | D15: 0.0298 | E15: 8.185 | F15: =D15*E15 -> 0.243913 | I15: 10-K FY26 附註 10：面額 8,185、票面 2.92%–3.04%（取中點）、到期 2052–2062；到期日取區間中點 [Derived]
A16: 2023 票據（Activision 交換） | B16: 無擔保 | C16: 2038-06 | D16: 0.02925 | E16: 0.056 | F16: =D16*E16 -> 0.001638 | I16: 10-K FY26 附註 10：面額 56、票面 1.35%–4.50%（取中點）、到期 2026–2050；到期日取區間中點 [Derived]
A17: 2024 票據（Activision 交換） | B17: 無擔保 | C17: 2038-06 | D17: 0.02925 | E17: 3.344 | F17: =D17*E17 -> 0.097812 | I17: 10-K FY26 附註 10：面額 3,344、票面 1.35%–4.50%（取中點）、到期 2026–2050；到期日取區間中點 [Derived]
A18: 合計（6/30） | E18: =SUM(E5:E17) -> 46.136 | F18: =SUM(F5:F17) -> 1.445405 | I18: 應等於最新季報本金合計 46.136（company.json → latestQuarter.debtPrincipal）
A19: 加權有效利率 | D19: =F18/E18 -> 0.031329222 | I19: ＝年化利息 ÷ 本金（company.json → debt.instruments 的有效利率）
A21: 評價日後新發可轉債 | D21: 0 | E21: 0 | F21: =D21*E21 -> 0 | I21: company.json → debt.convertible（期後新發；不在五期還本表內，只計利息）
A23: 可轉債逐檔（若轉換法：有效轉換價 < 判斷價 → 視為轉股，不計利息與還本）
A24: 可轉債 | B24: 到期 | C24: 票息 | D24: 原始本金 | E24: 到期累積倍數 | F24: 轉換價 | G24: 到期所屬模型期 | H24: 強制轉換（1＝是） | I24: 備註
A25: （無可轉債，不適用） | B25: 2099-12 | C25: 0 | D25: 0 | E25: 1 | F25: 1 | G25: 5 | H25: 0 | I25: company.json → debt.convertibles 為空清單
I26: 到期所屬模型期：0＝首期 … 4＝末期、5＝模型期後（建置時依期末日推算）
A28: 可轉債（推導） | C28: 到期本金 | D28: 若轉換股數 | E28: 有效轉換價 | F28: 融資分類 | G28: 評價第一輪 | H28: 評價第二輪 | I28: 說明
A29: =A25 -> （無可轉債，不適用） | C29: =D25*E25 -> 0 | D29: =D25/F25 -> 0 | E29: =F25*E25 -> 1 | F29: =IF(OR(H25=1,E29<輸入與假設!$C$322),1,0) -> 1 | G29: =IF(OR(H25=1,E29<輸入與假設!$C$345),1,0) -> 1 | H29: =IF(OR(H25=1,E29<評價_DCF與目標價!$C$87),1,0) -> 1
A30: 合計 | C30: =SUM(C29:C29) -> 0 | D30: =SUM(D29:D29) -> 0 | I30: 分類 1＝轉股（若轉換法）、0＝債務。強制轉換者一律為 1。融資分類判斷價＝股權發行價；評價第一輪＝現價；第二輪＝MIN(現價, 第一輪加權目標價)
A32: 存量利息推導（本金依季報到期表遞減）
A33: 項目 | B33: 單位 | C33: FY27 | D33: FY28 | E33: FY29 | F33: FY30 | G33: FY31 | I33: 公式／來源說明
A34: 期初本金 | B34: US$bn | C34: =E18 -> 46.136 | D34: =C36 -> 36.886 | E34: =D36 -> 36.886 | F34: =E36 -> 34.885 | G34: =F36 -> 34.885 | I34: FY27 期初為 6/30 本金（模型期起點）
A35: 排程還本 | B35: US$bn | C35: =輸入與假設!C$340 -> 9.25 | D35: =輸入與假設!D$340 -> 0 | E35: =輸入與假設!E$340 -> 2.001 | F35: =輸入與假設!F$340 -> 0 | G35: =輸入與假設!G$340 -> 0.5 | I35: 季報到期表
A36: 期末本金 | B36: US$bn | C36: =C34-C35 -> 36.886 | D36: =D34-D35 -> 36.886 | E36: =E34-E35 -> 34.885 | F36: =F34-F35 -> 34.885 | G36: =G34-G35 -> 34.385
A37: 平均本金 | B37: US$bn | C37: =(C34+C36)/2 -> 41.511 | D37: =(D34+D36)/2 -> 36.886 | E37: =(E34+E36)/2 -> 35.8855 | F37: =(F34+F36)/2 -> 34.885 | G37: =(G34+G36)/2 -> 34.635
A38: 存量債務利息 | B38: US$bn | C38: =C37*資產負債_既有債務!$D$19*輸入與假設!C$34 -> 1.3005073 | D38: =D37*資產負債_既有債務!$D$19*輸入與假設!D$34 -> 1.1556097 | E38: =E37*資產負債_既有債務!$D$19*輸入與假設!E$34 -> 1.1242648 | F38: =F37*資產負債_既有債務!$D$19*輸入與假設!F$34 -> 1.0929199 | G38: =G37*資產負債_既有債務!$D$19*輸入與假設!G$34 -> 1.0850876 | I38: ＝平均本金×加權有效利率×期間長度。限制：假設利率組合不變；可轉債折價攤銷（非現金）不計
A39: 期後新發可轉債利息 | B39: US$bn | C39: =資產負債_既有債務!$F$21*輸入與假設!C$34 -> 0 | D39: =資產負債_既有債務!$F$21*輸入與假設!D$34 -> 0 | E39: =資產負債_既有債務!$F$21*輸入與假設!E$34 -> 0 | F39: =資產負債_既有債務!$F$21*輸入與假設!F$34 -> 0 | G39: =資產負債_既有債務!$F$21*輸入與假設!G$34 -> 0
A40: 可轉債到期還本（債務處理） | B40: US$bn | C40: =IF(輸入與假設!$C$311=1,SUMPRODUCT((1-資產負債_既有債務!$F$29:$F$29)*資產負債_既有債務!$C$29:$C$29*(資產負債_既有債務!$G$25:$G$25=0)),0) -> 0 | D40: =IF(輸入與假設!$C$311=1,SUMPRODUCT((1-資產負債_既有債務!$F$29:$F$29)*資產負債_既有債務!$C$29:$C$29*(資產負債_既有債務!$G$25:$G$25=1)),0) -> 0 | E40: =IF(輸入與假設!$C$311=1,SUMPRODUCT((1-資產負債_既有債務!$F$29:$F$29)*資產負債_既有債務!$C$29:$C$29*(資產負債_既有債務!$G$25:$G$25=2)),0) -> 0 | F40: =IF(輸入與假設!$C$311=1,SUMPRODUCT((1-資產負債_既有債務!$F$29:$F$29)*資產負債_既有債務!$C$29:$C$29*(資產負債_既有債務!$G$25:$G$25=3)),0) -> 0 | G40: =IF(輸入與假設!$C$311=1,SUMPRODUCT((1-資產負債_既有債務!$F$29:$F$29)*資產負債_既有債務!$C$29:$C$29*(資產負債_既有債務!$G$25:$G$25=4)),0) -> 0 | I40: 融資分類為債務的可轉債，到期當期以到期累積本金現金還本
A41: 可轉債期末餘額（債務處理） | B41: US$bn | C41: =IF(輸入與假設!$C$311=1,SUMPRODUCT((1-資產負債_既有債務!$F$29:$F$29)*資產負債_既有債務!$C$29:$C$29*(資產負債_既有債務!$G$25:$G$25>0)),SUMPRODUCT((1-資產負債_既有債務!$F$29:$F$29)*資產負債_既有債務!$C$29:$C$29)) -> 0 | D41: =IF(輸入與假設!$C$311=1,SUMPRODUCT((1-資產負債_既有債務!$F$29:$F$29)*資產負債_既有債務!$C$29:$C$29*(資產負債_既有債務!$G$25:$G$25>1)),SUMPRODUCT((1-資產負債_既有債務!$F$29:$F$29)*資產負債_既有債務!$C$29:$C$29)) -> 0 | E41: =IF(輸入與假設!$C$311=1,SUMPRODUCT((1-資產負債_既有債務!$F$29:$F$29)*資產負債_既有債務!$C$29:$C$29*(資產負債_既有債務!$G$25:$G$25>2)),SUMPRODUCT((1-資產負債_既有債務!$F$29:$F$29)*資產負債_既有債務!$C$29:$C$29)) -> 0 | F41: =IF(輸入與假設!$C$311=1,SUMPRODUCT((1-資產負債_既有債務!$F$29:$F$29)*資產負債_既有債務!$C$29:$C$29*(資產負債_既有債務!$G$25:$G$25>3)),SUMPRODUCT((1-資產負債_既有債務!$F$29:$F$29)*資產負債_既有債務!$C$29:$C$29)) -> 0 | G41: =IF(輸入與假設!$C$311=1,SUMPRODUCT((1-資產負債_既有債務!$F$29:$F$29)*資產負債_既有債務!$C$29:$C$29*(資產負債_既有債務!$G$25:$G$25>4)),SUMPRODUCT((1-資產負債_既有債務!$F$29:$F$29)*資產負債_既有債務!$C$29:$C$29)) -> 0 | I41: 到期累積本金；關閉攤還時維持全額
A42: 可轉債票息（債務處理） | B42: US$bn | C42: =IF(輸入與假設!$C$311=1,SUMPRODUCT((1-資產負債_既有債務!$F$29:$F$29)*資產負債_既有債務!$D$25:$D$25*資產負債_既有債務!$C$25:$C$25*((資產負債_既有債務!$G$25:$G$25>0)+0.5*(資產負債_既有債務!$G$25:$G$25=0))),SUMPRODUCT((1-資產負債_既有債務!$F$29:$F$29)*資產負債_既有債務!$D$25:$D$25*資產負債_既有債務!$C$25:$C$25))*輸入與假設!C$34 -> 0 | D42: =IF(輸入與假設!$C$311=1,SUMPRODUCT((1-資產負債_既有債務!$F$29:$F$29)*資產負債_既有債務!$D$25:$D$25*資產負債_既有債務!$C$25:$C$25*((資產負債_既有債務!$G$25:$G$25>1)+0.5*(資產負債_既有債務!$G$25:$G$25=1))),SUMPRODUCT((1-資產負債_既有債務!$F$29:$F$29)*資產負債_既有債務!$D$25:$D$25*資產負債_既有債務!$C$25:$C$25))*輸入與假設!D$34 -> 0 | E42: =IF(輸入與假設!$C$311=1,SUMPRODUCT((1-資產負債_既有債務!$F$29:$F$29)*資產負債_既有債務!$D$25:$D$25*資產負債_既有債務!$C$25:$C$25*((資產負債_既有債務!$G$25:$G$25>2)+0.5*(資產負債_既有債務!$G$25:$G$25=2))),SUMPRODUCT((1-資產負債_既有債務!$F$29:$F$29)*資產負債_既有債務!$D$25:$D$25*資產負債_既有債務!$C$25:$C$25))*輸入與假設!E$34 -> 0 | F42: =IF(輸入與假設!$C$311=1,SUMPRODUCT((1-資產負債_既有債務!$F$29:$F$29)*資產負債_既有債務!$D$25:$D$25*資產負債_既有債務!$C$25:$C$25*((資產負債_既有債務!$G$25:$G$25>3)+0.5*(資產負債_既有債務!$G$25:$G$25=3))),SUMPRODUCT((1-資產負債_既有債務!$F$29:$F$29)*資產負債_既有債務!$D$25:$D$25*資產負債_既有債務!$C$25:$C$25))*輸入與假設!F$34 -> 0 | G42: =IF(輸入與假設!$C$311=1,SUMPRODUCT((1-資產負債_既有債務!$F$29:$F$29)*資產負債_既有債務!$D$25:$D$25*資產負債_既有債務!$C$25:$C$25*((資產負債_既有債務!$G$25:$G$25>4)+0.5*(資產負債_既有債務!$G$25:$G$25=4))),SUMPRODUCT((1-資產負債_既有債務!$F$29:$F$29)*資產負債_既有債務!$D$25:$D$25*資產負債_既有債務!$C$25:$C$25))*輸入與假設!G$34 -> 0 | I42: ＝原始本金 × 票息 × 期間長度；到期當期計半期
A43: 首期新增借款利息校準 | B43: US$bn | C43: =0 -> 0 | D43: =0 -> 0 | E43: =0 -> 0 | F43: =0 -> 0 | G43: =0 -> 0 | I43: 讓首期模型利息對上公司季度利息指引的校準值（company.json → defaults.intCal）；無指引時為 0
A44: 存量利息合計（連回輸入頁） | B44: US$bn | C44: =C38+C39+C42+C43 -> 1.3005073 | D44: =D38+D39+D42+D43 -> 1.1556097 | E44: =E38+E39+E42+E43 -> 1.1242648 | F44: =F38+F39+F42+F43 -> 1.0929199 | G44: =G38+G39+G42+G43 -> 1.0850876 | I44: ＝存量債務利息＋期後新發可轉債利息＋可轉債票息＋首期校準

Sheet 資產負債_新債與新股
A1: 新債與新股（類資產負債表：現金、債務、股本、槓桿）
A2: 全部為連結公式。FY27 欄的現金自 2026-06-30 起算（模型期），與 HTML『資產與負債 → 新債與新股』同口徑
A4: 項目 | B4: 單位 | C4: FY27 | D4: FY28 | E4: FY29 | F4: FY30 | G4: FY31 | I4: 公式／來源說明
A5: 現金
A6: 期初現金 | B6: US$bn | C6: =輸入與假設!$C$306 -> 76.843 | D6: =各期收支!C56 -> 50 | E6: =各期收支!D56 -> 50 | F6: =各期收支!E56 -> 61.971029 | G6: =各期收支!F56 -> 79.976487 | I6: FY27＝6/30 現金（模型期起點）
A7: 營運收支淨額（含期後股權／可轉債，不含瀑布） | B7: US$bn | C7: =各期收支!C103-輸入與假設!$C$306 -> -45.22795 | D7: =各期收支!D103-各期收支!C103 -> -2.5972688 | E7: =各期收支!E103-各期收支!D103 -> 35.397284 | F7: =各期收支!F103-各期收支!E103 -> 41.431713 | G7: =各期收支!G103-各期收支!F103 -> -27.269282 | I7: ＝融資前累積現金的當期變動；負值即當期外部資金需求
