Workbook

Sheet README
A1: Microsoft（MSFT）個股模型 v0.3 — 命題＋官方營收分部 → 損益表（2026-10-27；資料截至 FY26Q4；FY27Q1 財報 2026-10-28 未納入）
A2: 工作表：README → In → Q → Thesis → Seg → PL → CF → Val → Recon → Sens → Sources。金額十億美元；財年 6 月結束（FY2027＝2026-07～2027-06）
A3: 命題：AI 能否同時在 Azure（算力）與 Microsoft 365（Copilot 應用）變現，撐住翻倍的資本支出。
A4: 核心問題：FY2029 的 AI 增量營業利益能否覆蓋 AI 資本支出的資金成本（AI 增量 ROIC 對 WACC），且自由現金流不需停止回購。
A5: ="① 命題答案（FY2029，基準情境 B）：讀法 2（主值；自用 AI 價值中性）AI 增量 ROIC "&TEXT(Thesis!H96,"0.0%")&"，讀法 1（自用 AI 只計成本）"&TEXT(Thesis!H97,"0.0%")&"，WACC "&TEXT(wacc,"0.0%")&"；對外 Azure AI 本身 "&TEXT(Thesis!H99,"0.0%")&"。讀法 1 下 AI 容量越大、目標價越低（自用算力只有成本）；讀法 2 下容量增加對目標價中性偏正（敏感度：MW 速度改 Epoch 可辨識站點 "&TEXT(Sens!D9,"+0.0;-0.0")&"、+20% "&TEXT(Sens!D10,"+0.0;-0.0")&"）。AI 折舊 FY2026 "&TEXT(Thesis!E89,"0.0")&" → FY2029 "&TEXT(Thesis!H89,"0.0")&" 十億美元，財報口徑營業利益率 FY2029 "&TEXT(PL!H76,"0.0%")&"（FY2026 "&TEXT(PL!E76,"0.0%")&"）。" -> ① 命題答案（FY2029，基準情境 B）：讀法 2（主值；自用 AI 價值中性）AI 增量 ROIC 10.6%，讀法 1（自用 AI 只計成本）1.1%，WACC 10.3%；對外 Azure AI 本身 13.1%。讀法 1 下 AI 容量越大、目標價越低（自用算力只有成本）；讀法 2 下容量增加對目標價中性偏正（敏感度：MW 速度改 Epoch 可辨識站點 -48.0、+20% +4.5）。AI 折舊 FY2026 16.3 → FY2029 87.7 十億美元，財報口徑營業利益率 FY2029 39.3%（FY2026 46.8%）。
A6: ="② 收支關卡：基準情境首年起五年（FY2027–FY2031）自由現金流扣股利合計 "&TEXT(CF!C5,"#,##0.0")&" 十億美元（樂觀 "&TEXT(CF!B5,"#,##0.0")&"、保守 "&TEXT(CF!D5,"#,##0.0")&"）；"&CF!C6&"。" -> ② 收支關卡：基準情境首年起五年（FY2027–FY2031）自由現金流扣股利合計 274.0 十億美元（樂觀 378.6、保守 151.4）；需要舉債 9.8 十億美元；回購較每年 22.3 的目標少 43.9 十億美元（2 年減少）。
A7: ="③ 評價：加權目標價 "&TEXT(Val!$B$36,"#,##0")&" 美元（讀法 2），較現價 "&TEXT(px,"#,##0.00")&" "&TEXT(Val!$B$40,"+0.0%;-0.0%")&"；DCF "&TEXT(Val!$B$14,"#,##0")&"、分部加總 "&TEXT(Val!$B$31,"#,##0")&"；讀法 1 目標價 "&TEXT(Val!$B$47,"#,##0")&"（"&Val!$B$49&"）；市場共識 "&TEXT(cons_tp,"#,##0")&"。WACC "&TEXT(wacc,"0.0%")&"（−1pt 時目標價 "&TEXT(Sens!C25,"#,##0")&"）；非 AI 各線改用 Microsoft 自身 NTM EV/EBITDA "&TEXT(m_own,"0.0")&"× 時目標價 "&TEXT(Sens!C38,"#,##0")&"。" -> ③ 評價：加權目標價 389 美元（讀法 2），較現價 532.60 -27.0%；DCF 342、分部加總 436；讀法 1 目標價 304（放空）；市場共識 603。WACC 10.3%（−1pt 時目標價 413）；非 AI 各線改用 Microsoft 自身 NTM EV/EBITDA 15.7× 時目標價 455。
A8: ="投資建議："&Val!$B$43&"（讀法 2 主值；上檔空間 "&TEXT(Val!$B$40,"+0.0%;-0.0%")&"；讀法 1："&Val!$B$49&"；五級固定規則：≥ +50% 強力買進、+25%～+50% 買進、−25%～+25% 中立、−50%～−25% 放空、≤ −50% 強力放空）" -> 投資建議：放空（讀法 2 主值；上檔空間 -27.0%；讀法 1：放空；五級固定規則：≥ +50% 強力買進、+25%～+50% 買進、−25%～+25% 中立、−50%～−25% 放空、≤ −50% 強力放空）
A9: ="收支關卡（地圖）：CF 頁「收支關卡：自由現金流扣股利（五年合計）」基準 "&TEXT(CF!C5,"#,##0.0")&" 十億美元（財報現金，不含影子效益）" -> 收支關卡（地圖）：CF 頁「收支關卡：自由現金流扣股利（五年合計）」基準 274.0 十億美元（財報現金，不含影子效益）
A11: 驅動 → 推導對照表（每頁輸入、推導量、因果方向）
A12: 頁 | B12: 輸入（In 頁鍵） | C12: 推導量 | D12: 因果方向 | E12: 基準值（FY2029，情境 B）
A13: Thesis | B13: pace、mw_ext_26、ext_sh、rent_ext_f | C13: 在役對外 AI MW、自有 AI MW（含自用） | D13: MW 越多 → Azure AI 營收↑、AI 資本支出與折舊↑ | E13: =Thesis!H57 -> 10831.6
A14: Thesis | B14: tk_hold_*、p_long、p_spot、ls_*（k） | C14: 每 MW 年收入（US$M/MW-年） | D14: k 越高 → Azure AI 營收與 EBITDA↑（三情境主要差異） | E14: =Thesis!H71 -> 13.047202
A15: Thesis | B15: tk_cxit_*、tk_cxfac、self_build、capex_floor27、life_it | C15: AI 資本支出、AI 折舊 | D15: 資本支出 → 折舊 → Agents and Infra 營業利益↓；→ 自由現金流↓ | E15: =Thesis!H89 -> 87.742316
A16: Seg | B16: cop_s26、cop_add_*、cop_px | C16: Copilot 營收（M365 cloud 子列） | D16: 座席 × 月費 → M365 cloud↑ | E16: =Seg!H38 -> 24
A17: Seg | B17: glt_*、n_conv | C17: 非命題產品線營收 | D17: 近一年年增收斂到長期值 | E17: =Seg!H56 -> 552.7731
A18: PL | B18: （FY2026 校準）、dm_seg | C18: Agents and Infra 核心利益率、分部營業利益 | D18: 核心利益率 ×（分部 − Azure AI）＋ Azure AI − AI 成本 − AI 折舊 | E18: =PL!H71 -> 196.82255
A19: PL | B19: internal_ai_reading、tax_f、oie_f | C19: 自用 AI 影子效益、淨利、EPS（評價口徑） | D19: 讀法 2：自用 MW × 持有成本（扣 Copilot）進評價口徑營業利益 | E19: =PL!H88 -> 28.491897
A20: CF | B20: sbc_r、wc27、cx_*、fl_pay_*、bb_target、dps_* | C20: 自由現金流、回購、舉債、股數 | D20: 自由現金流扣股利 → 回購（不足先減）→ 舉債 | E20: =CF!H56 -> 70.552903
A21: Val | B21: rf、beta、erp、kd、g_tv、m_*、al_*、w_* | C21: DCF、SOTP（AI 模組 DCF）、加權目標價 | D21: WACC↑ → DCF↓；倍數↑ → SOTP↑ | E21: =Val!$B$36 -> 388.94796
A23: 結果摘要（三情境）
A24: 項目 | B24: 情境 A（樂觀） | C24: 情境 B（基準） | D24: 情境 C（保守） | E24: 說明
A25: 營收 FY2029（US$B） | B25: =Seg!H29 -> 585.22308 | C25: =Seg!H56 -> 552.7731 | D25: =Seg!H83 -> 515.33313
A26: Azure AI 營收 FY2029 | B26: =Thesis!H23 -> 149.78561 | C26: =Thesis!H72 -> 124.83563 | D26: =Thesis!H121 -> 94.895656
A27: Copilot 營收 FY2029 | B27: =Seg!H11 -> 31.5 | C27: =Seg!H38 -> 24 | D27: =Seg!H65 -> 16.5
A28: 營業利益率 FY2029（財報口徑） | B28: =PL!H37 -> 0.42152971 | C28: =PL!H76 -> 0.39334721 | D28: =PL!H115 -> 0.35546832
A29: EPS FY2029（財報口徑，US$） | B29: =PL!H47 -> 26.182083 | C29: =PL!H86 -> 23.011461 | D29: =PL!H125 -> 19.346501
A30: EPS FY2029（評價口徑，US$） | B30: =PL!H49 -> 31.221682 | C30: =PL!H88 -> 28.491897 | D30: =PL!H127 -> 25.270618
A31: 自由現金流 FY2029（財報現金） | B31: =CF!H27 -> 94.524344 | C31: =CF!H56 -> 70.552903 | D31: =CF!H85 -> 42.402925
A32: AI 增量 ROIC FY2029（讀法 2） | B32: =Thesis!H47 -> 0.15232209 | C32: =Thesis!H96 -> 0.10623047 | D32: =Thesis!H145 -> 0.050960142
A33: AI 增量 ROIC FY2029（讀法 1） | B33: =Thesis!H48 -> 0.064879597 | C33: =Thesis!H97 -> 0.010911343 | D33: =Thesis!H146 -> -0.052231994
A35: 情境目標價（US$；讀法 2） | B35: =Val!B44 -> 428.63908 | C35: =Val!C44 -> 390.89987 | D35: =Val!D44 -> 345.353
A37: 與 v0.2.2 的差異：v0.2.2 沿用 CoreWeave 架構（對外 AI MW × 每 MW 收入＋其餘業務成長率線、融資瀑布）；v0.3 改為官方兩分部、八條產品線，命題只驅動 Azure AI 與 Copilot 兩條子列，AI 資本支出經折舊進分部營業利益；評價改 DCF 50%＋SOTP 50%、情境 25／50／25。拆解見 Recon 第 5 節。
A38: 已知限制：AI 在役 MW、對外比例、Copilot 營收與座席歷史、產品線利潤公司皆未揭露（Assumed，給區間）；FY27Q1 財報（2026-10-28）未納入，將以 v0.3.1 滾入；Tokenomics 維持 v21.4。
A39: 建置：python3 microsoft/build_microsoft.py raw.xlsx → soffice --headless --calc --convert-to xlsx → microsoft/dist/；HTML：python3 tools/company_html/build_company_html.py microsoft
A40: 修正一（2026-10-27，獨立核對後）：收支關卡範圍公式誤加 FY2032（改為首年起五年並加核對列）；自用 AI 讀法 2 為主值；DCF 扣股票薪酬、減融資租賃負債、扣期間股利；SOTP 的 AI 腿改用模組 DCF；WACC 改 Blume β、10 年期 kd、負債含融資租賃；FY2029 後 MW 新增速度收斂；汰換時更新在役世代。前後對照見報告「修正一」節。

Sheet In
A1: In — 輸入（藍字＝輸入、黑字＝由其他輸入推得）。基準欄 E，低 D、高 F；金額十億美元（US$B），MW＝IT 關鍵電力。標記：Verified／Interested-party／Analogy／Assumed／Derived；Analogy、Assumed 一律給區間
A2: 「沿用 v0.2.2」＝MAG v0.2.2（2026-10-25，PR #105）已核准的參數與證據，原出處見來源欄；SEC 一手數字取自 microsoft/data/microsoft_facts_20261008.json（v0.1a 起的事實總帳）
A3: 鍵 | B3: 項目 | C3: 單位 | D3: 低 | E3: 基準 | F3: 高 | G3: 標記 | H3: 來源1 | I3: 來源2／說明
A4: A. 股價、股數與資本結構（評價日 2026-06-30＝FY2026 年底；目標價時點＝今日 2026-10-27 後 12 個月）
A5: px | B5: 現價（2026-10-26 收盤） | C5: US$ | E5: 532.6 | G5: Verified | H5: https://stockanalysis.com/stocks/msft/statistics/（2026-10-26 收盤 532.60，+8.09／+1.54%；擷取 2026-10-27） | I5: markets/invest_map/data/prices.csv：2026-10-23 收盤 524.51（stockscan；bullfincher）＋ 10-26 漲 8.09＝532.60，兩來源一致
A6: sh_dil26 | B6: FY2026 稀釋加權股數 | C6: 十億股 | E6: 7.453 | G6: Verified | H6: 事實總帳 microsoft/data/microsoft_facts_20261008.json｜is.sharesDilW.fy2026（10-K FY2026） | I6: DCF 每股（評價日 2026-06-30）的分母
A7: sh_basic26 | B7: FY2026 基本加權股數 | C7: 十億股 | E7: 7.429 | G7: Verified | H7: 事實總帳 microsoft/data/microsoft_facts_20261008.json｜is.sharesBasicW.fy2026 | I7: —
A8: dil_gap | B8: 稀釋與基本股數差 | C8: 十億股 | E8: =sh_dil26-sh_basic26 -> 0.024 | G8: Derived | H8: FY2026 稀釋 − 基本 | I8: 預測期稀釋股數＝期間平均流通股數＋此差額
A9: sh_out26 | B9: 流通股數（2026-06-30） | C9: 十億股 | E9: 7.427 | G9: Verified | H9: 事實總帳 microsoft/data/microsoft_facts_20261008.json｜sh.out.fy2026（10-K 附註 15） | I9: —
A10: cash_open | B10: 現金與短期投資（2026-06-30） | C10: US$B | E10: 76.843 | G10: Verified | H10: 事實總帳 microsoft/data/microsoft_facts_20261008.json｜bs.cashSti.fy2026 | I10: —
A11: debt_face | B11: 債務面額（2026-06-30） | C11: US$B | E11: 46.136 | G11: Verified | H11: 事實總帳 microsoft/data/microsoft_facts_20261008.json｜debt.face.fy2026（附註 10） | I11: 帳面值 40.294；WACC 與淨現金用面額
A12: debt_mat_27 | B12: 債務到期 FY2027 | C12: US$B | E12: 9.25 | G12: Verified | H12: 事實總帳 microsoft/data/microsoft_facts_20261008.json｜debt.maturity.fy2027（附註 10 到期表） | I12: —
A13: debt_mat_28 | B13: 債務到期 FY2028 | C13: US$B | E13: 0 | G13: Verified | H13: 事實總帳 microsoft/data/microsoft_facts_20261008.json｜debt.maturity.fy2028（附註 10 到期表） | I13: —
A14: debt_mat_29 | B14: 債務到期 FY2029 | C14: US$B | E14: 2.001 | G14: Verified | H14: 事實總帳 microsoft/data/microsoft_facts_20261008.json｜debt.maturity.fy2029（附註 10 到期表） | I14: —
A15: debt_mat_30 | B15: 債務到期 FY2030 | C15: US$B | E15: 0 | G15: Verified | H15: 事實總帳 microsoft/data/microsoft_facts_20261008.json｜debt.maturity.fy2030（附註 10 到期表） | I15: —
A16: debt_mat_31 | B16: 債務到期 FY2031 | C16: US$B | E16: 0.5 | G16: Verified | H16: 事實總帳 microsoft/data/microsoft_facts_20261008.json｜debt.maturity.fy2031（附註 10 到期表） | I16: —
A17: debt_mat_32 | B17: 債務到期 FY2032 | C17: US$B | E17: 0 | G17: Assumed | H17: 事實總帳 microsoft/data/microsoft_facts_20261008.json｜到期表只列 FY2031 以後合計 34.385；FY2032 取 0 | I17: —
A18: fl_liab | B18: 融資租賃負債（2026-06-30，在帳） | C18: US$B | E18: 66.594 | G18: Verified | H18: 事實總帳 microsoft/data/microsoft_facts_20261008.json｜lease.finLiab.fy2026（附註 13） | I18: 在帳融資租賃的資產已在過去的資本支出（公司口徑）內，其本金在預測期照付（CF 頁）
A19: fl_rate | B19: 融資租賃加權利率 | C19: % | E19: 0.045 | G19: Verified | H19: 事實總帳 microsoft/data/microsoft_facts_20261008.json｜lease.wtdRate.fin | I19: —
A20: fl_pay_27 | B20: 在帳融資租賃付款 FY2027（未折現，含息） | C20: US$B | E20: 7.121 | G20: Verified | H20: 事實總帳 microsoft/data/microsoft_facts_20261008.json｜lease.maturity.fin.fy2027 | I20: —
... A24: fl_pay_31 | B24: 在帳融資租賃付款 FY2031（未折現，含息） | C24: US$B | E24: 6.543 | G24: Verified | H24: 事實總帳 microsoft/data/microsoft_facts_20261008.json｜lease.maturity.fin.fy2031 | I24: —
A25: fl_pay_32 | B25: 在帳融資租賃付款 FY2032（未折現，含息） | C25: US$B | E25: =fl_pay_31 -> 6.543 | G25: Assumed | H25: 事實總帳 microsoft/data/microsoft_facts_20261008.json｜FY2032 比照 FY2031（之後合計 55.490 分多年） | I25: —
A26: min_cash | B26: 最低現金 | C26: US$B | D26: 30 | E26: 50 | F26: 70 | G26: Assumed | H26: 沿用 v0.2.2（microsoft/legacy_v0.2/company.json；交接檔 docs/handoff/20261025_Microsoft收支模型_交接檔_v0_2_2.md）（defaults.minCash 50） | I26: 低於此水準先停回購、再舉債
A27: bb_target | B27: 回購目標（每年） | C27: US$B | E27: 22.271 | G27: Verified | H27: 事實總帳 microsoft/data/microsoft_facts_20261008.json｜cf.buyback.fy2026（含員工扣稅買回 5.6） | I27: 現金不足時先減回購
A28: bb_g | B28: 回購價格年增（以現價起算） | C28: % | D28: 0 | E28: 0.08 | F28: 0.12 | G28: Assumed | H28: 無：約等於股東權益成本扣股利率 | I28: 只影響股數
A29: sh_iss | B29: 員工股票發行（每年） | C29: 十億股 | D29: 0.035 | E29: 0.045 | F29: 0.055 | G29: Derived | H29: 事實總帳 microsoft/data/microsoft_facts_20261008.json｜FY2026 回購約 0.048 十億股（計畫 0.036＋扣稅買回 5.6 ÷ 約 470 美元），基本加權股數 7.433 → 7.429 幾乎不變 → 發行約 0.045 | I29: 低／高 Assumed
A30: dps_q0 | B30: 每季股利（FY2027 第一季付，舊額） | C30: US$ | E30: 0.91 | G30: Verified | H30: 事實總帳 microsoft/data/microsoft_facts_20261008.json｜sh.dps.fy2026（每季 0.91） | I30: —
A31: dps_q1 | B31: 每季股利（2026-09-15 宣告，新額） | C31: US$ | E31: 0.98 | G31: Interested-party | H31: 事實總帳 microsoft/data/microsoft_facts_20261008.json｜sh.dpsQ.fy27q1 | I31: —
A32: dps_27 | B32: FY2027 每股股利（付現） | C32: US$ | E32: =dps_q0+3*dps_q1 -> 3.85 | G32: Derived | H32: 第一季付舊額、其後三季付新額 | I32: —
A33: dps_g | B33: 每股股利年增（FY2028 起） | C33: % | D33: 0.05 | E33: 0.08 | F33: 0.1 | G33: Interested-party | H33: 沿用 v0.2.2（microsoft/legacy_v0.2/company.json；交接檔 docs/handoff/20261025_Microsoft收支模型_交接檔_v0_2_2.md）（defaults.dividend.growth；2026-09 宣告 +8%） | I33: —
A34: B. 折現率與評價參數（WACC 沿用 v0.2.2 的 CAPM 輸入；權重為 [判斷] 預設，Andy 可改）
A35: rf | B35: 無風險利率（10 年美債，2026-10-26） | C35: % | E35: 0.05 | G35: Verified | H35: U.S. Treasury 10 年期殖利率 2026-10-26：5.00%（修正一：chat 端統一 MAG＋Oracle 個股模型的同一輸入，與 Amazon v0.3 相同） | I35: 事實總帳 microsoft/data/microsoft_facts_20261008.json｜val.ust10：2026-10-07 為 5.28%（v0.2.2 與 v0.3 初版）
A36: beta_sa | B36: 原始 β：StockAnalysis（5 年月資料；Yahoo 同值，推測同源，算 1 個） | C36: x | E36: 1.1 | G36: Verified | H36: 事實總帳 microsoft/data/microsoft_facts_20261008.json｜val.beta.sa（2026-10-08） | I36: C13：獨立來源
A37: beta_gf | B37: 原始 β：GuruFocus（3 年） | C37: x | E37: 1.1741 | G37: Verified | H37: 事實總帳 microsoft/data/microsoft_facts_20261008.json｜val.beta.gurufocus（2026-10-08） | I37: C13：獨立來源
A38: blume_w | B38: Blume 調整：原始 β 權重（其餘向 1 收斂） | C38: x | E38: 0.67 | G38: Assumed | H38: 共同修正工作單 F4（2026-10-27）：0.67 × 原始 β＋0.33 | I38: —
A39: beta | B39: β（兩個獨立來源 Blume 調整後的中位數） | C39: x | D39: 0.95 | E39: =MEDIAN(blume_w*beta_sa+(1-blume_w),blume_w*beta_gf+(1-blume_w)) -> 1.0918235 | F39: 1.174 | G39: Derived | H39: Blume：1.10 → 1.067、1.1741 → 1.117；中位數 1.092（修正一；v0.3 初版用原始平均 1.137） | I39: 低 0.95＝獨立核對建議區間下緣；高＝原始 GuruFocus
A40: erp | B40: 股權風險溢酬 | C40: % | D40: 0.04 | E40: 0.05 | F40: 0.06 | G40: Assumed | H40: MAG 對照表 r1 5.10（判斷，列敏感度） | I40: 沿用 v0.2.2（microsoft/legacy_v0.2/company.json；交接檔 docs/handoff/20261025_Microsoft收支模型_交接檔_v0_2_2.md）
A41: kd_aaa | B41: 對照：Moody's Aaa 公司債殖利率（長天期） | C41: % | E41: 0.0626 | G41: Analogy | H41: 事實總帳 microsoft/data/microsoft_facts_20261008.json｜val.kd.aaa（FRED DAAA 2026-10-06） | I41: v0.3 初版 kd；Aaa 指數為 20 年以上長債，修正一改用約 10 年期
A42: kd_spread | B42: 約 10 年期 AAA 公司債對美債利差 | C42: pt | D42: 0.003 | E42: 0.006 | F42: 0.009 | G42: Assumed | H42: 無：MSFT 個別債券殖利率找不到；AAA 10 年期利差歷史約 0.3–0.9 個百分點 | I42: kd＝rf＋利差（修正一 F4）
A43: kd | B43: 稅前債務成本（約 10 年期公司債） | C43: % | E43: =rf+kd_spread -> 0.056 | G43: Derived | H43: rf（10 年美債）＋利差 | I43: —
...

Sheet Q
A1: Q — 實績（十億美元）。分部與產品線為 FY2027 起的報導口徑（8-K 2026-09-02「Segment History／Products and Service Offerings — As Restated」，未經查核）；合併損益、現金流量取自 10-K／財報新聞稿（事實總帳）
A2: J、K 欄＝四季合計（公式）；L、M 欄＝公司揭露的年度值（輸入）；核對列實績必須為 0。舊三分部（PBP／IC／MPC）列在下方對照（FY2026 以前口徑）
A3: 項目 | B3: FY25Q1（～2024-09） | C3: FY25Q2（～12） | D3: FY25Q3（～2025-03） | E3: FY25Q4（～06） | F3: FY26Q1（～2025-09） | G3: FY26Q2（～12） | H3: FY26Q3（～2026-03） | I3: FY26Q4（～06） | J3: FY2025（四季合計） | K3: FY2026（四季合計） | L3: FY2025（公司年度值） | M3: FY2026（公司年度值） | N3: 標記 | O3: 來源（事實總帳 id）
A4: 1. 官方分部與產品線營收（FY2027 起報導口徑）
A5: Agents and Infra | B5: 50.476 | C5: 52.766 | D5: 54.763 | E5: 60.778 | F5: 61.672 | G5: 64.441 | H5: 67.438 | I5: 74.576 | J5: =SUM(B5:E5) -> 218.783 | K5: =SUM(F5:I5) -> 268.127 | L5: 218.783 | M5: 268.127 | N5: Verified | O5: 8-K 2026-09-02 附件 99.1（As Restated）｜q.seg27.ai.rev.*、seg27.ai.rev.*
A6: Azure | B6: 16.021 | C6: 17.337 | D6: 18.54 | E6: 20.712 | F6: 22.384 | G6: 24.129 | H6: 26.008 | I6: 29.417 | J6: =SUM(B6:E6) -> 72.61 | K6: =SUM(F6:I6) -> 101.938 | L6: 72.61 | M6: 101.938 | N6: Verified | O6: 8-K 2026-09-02 附件 99.1（As Restated）｜q.prod27.azure.*
A7: Microsoft 365 cloud | B7: 20.017 | C7: 20.686 | D7: 20.967 | E7: 22.935 | F7: 23.694 | G7: 24.466 | H7: 25.418 | I7: 26.721 | J7: =SUM(B7:E7) -> 84.605 | K7: =SUM(F7:I7) -> 100.299 | L7: 84.605 | M7: 100.299 | N7: Verified | O7: 8-K 2026-09-02 附件 99.1（As Restated）｜q.prod27.m365cloud.*
A8: Productivity and server licensing | B8: 8.051 | C8: 8.307 | D8: 8.731 | E8: 10.302 | F8: 8.678 | G8: 8.814 | H8: 8.76 | I8: 11.033 | J8: =SUM(B8:E8) -> 35.391 | K8: =SUM(F8:I8) -> 37.285 | L8: 35.391 | M8: 37.285 | N8: Verified | O8: 8-K 2026-09-02 附件 99.1（As Restated）｜q.prod27.licensing.*
A9: Industry solutions | B9: 4.459 | C9: 4.544 | D9: 4.579 | E9: 4.835 | F9: 4.894 | G9: 4.994 | H9: 5.165 | I9: 5.292 | J9: =SUM(B9:E9) -> 18.417 | K9: =SUM(F9:I9) -> 20.345 | L9: 18.417 | M9: 20.345 | N9: Verified | O9: 8-K 2026-09-02 附件 99.1（As Restated）｜q.prod27.industry.*
A10: Frontier and support services | B10: 1.928 | C10: 1.892 | D10: 1.946 | E10: 1.994 | F10: 2.022 | G10: 2.038 | H10: 2.087 | I10: 2.113 | J10: =SUM(B10:E10) -> 7.76 | K10: =SUM(F10:I10) -> 8.26 | L10: 7.76 | M10: 8.26 | N10: Verified | O10: 8-K 2026-09-02 附件 99.1（As Restated）｜q.prod27.frontier.*
A11: 檢查：Agents and Infra 產品線合計 − 分部 | B11: =SUM(B6:B10)-B5 -> 0 | C11: =SUM(C6:C10)-C5 -> 0 | D11: =SUM(D6:D10)-D5 -> 0 | E11: =SUM(E6:E10)-E5 -> 0 | F11: =SUM(F6:F10)-F5 -> 0 | G11: =SUM(G6:G10)-G5 -> 0 | H11: =SUM(H6:H10)-H5 -> 0 | I11: =SUM(I6:I10)-I5 -> 0 | ... M11: =SUM(M6:M10)-M5 -> 0 | N11: 核對
A12: Devices and Consumer | B12: 15.109 | C12: 16.866 | D12: 15.303 | E12: 15.663 | F12: 16.001 | G12: 16.832 | H12: 15.448 | I12: 15.431 | J12: =SUM(B12:E12) -> 62.941 | K12: =SUM(F12:I12) -> 63.712 | L12: 62.941 | M12: 63.712 | N12: Verified | O12: 8-K 2026-09-02 附件 99.1（As Restated）｜q.seg27.dc.rev.*
A13: Search and advertising | B13: 5.159 | C13: 5.773 | D13: 5.437 | E13: 5.802 | F13: 5.942 | G13: 6.393 | H13: 6.065 | I13: 6.435 | J13: =SUM(B13:E13) -> 22.171 | K13: =SUM(F13:I13) -> 24.835 | L13: 22.171 | M13: 24.835 | N13: Verified | O13: 8-K 2026-09-02 附件 99.1（As Restated）｜q.prod27.searchads.*
A14: XBOX | B14: 5.621 | C14: 6.581 | D14: 5.721 | E14: 5.532 | F14: 5.508 | G14: 5.958 | H14: 5.341 | I14: 4.983 | J14: =SUM(B14:E14) -> 23.455 | K14: =SUM(F14:I14) -> 21.79 | L14: 23.455 | M14: 21.79 | N14: Verified | O14: 8-K 2026-09-02 附件 99.1（As Restated）｜q.prod27.xbox.*
A15: Windows OEM and devices | B15: 4.329 | C15: 4.512 | D15: 4.145 | E15: 4.329 | F15: 4.551 | G15: 4.481 | H15: 4.042 | I15: 4.013 | J15: =SUM(B15:E15) -> 17.315 | K15: =SUM(F15:I15) -> 17.087 | L15: 17.315 | M15: 17.087 | N15: Verified | O15: 8-K 2026-09-02 附件 99.1（As Restated）｜q.prod27.windows.*
A16: 檢查：Devices and Consumer 產品線合計 − 分部 | B16: =SUM(B13:B15)-B12 -> 0 | C16: =SUM(C13:C15)-C12 -> 0 | D16: =SUM(D13:D15)-D12 -> 0 | E16: =SUM(E13:E15)-E12 -> 0 | F16: =SUM(F13:F15)-F12 -> 0 | G16: =SUM(G13:G15)-G12 -> 0 | H16: =SUM(H13:H15)-H12 -> 0 | I16: =SUM(I13:I15)-I12 -> 0 | ... M16: =SUM(M13:M15)-M12 -> 0 | N16: 核對
A17: 分部合計（營收） | B17: =B5+B12 -> 65.585 | C17: =C5+C12 -> 69.632 | D17: =D5+D12 -> 70.066 | E17: =E5+E12 -> 76.441 | F17: =F5+F12 -> 77.673 | G17: =G5+G12 -> 81.273 | H17: =H5+H12 -> 82.886 | I17: =I5+I12 -> 90.007 | J17: =SUM(B17:E17) -> 281.724 | K17: =SUM(F17:I17) -> 331.839 | L17: =L5+L12 -> 281.724 | M17: =M5+M12 -> 331.839 | N17: Derived
A18: 合併營收（公司損益表） | B18: 65.585 | C18: 69.632 | D18: 70.066 | E18: 76.441 | F18: 77.673 | G18: 81.273 | H18: 82.886 | I18: 90.007 | J18: =SUM(B18:E18) -> 281.724 | K18: =SUM(F18:I18) -> 331.839 | L18: 281.724 | M18: 331.839 | N18: Verified | O18: 財報新聞稿／10-K｜q.rev.*、is.rev.*
A19: 檢查：分部合計 − 合併營收 | B19: =B17-B18 -> 0 | C19: =C17-C18 -> 0 | D19: =D17-D18 -> 0 | E19: =E17-E18 -> 0 | F19: =F17-F18 -> 0 | G19: =G17-G18 -> 0 | H19: =H17-H18 -> 0 | I19: =I17-I18 -> 0 | ... M19: =M17-M18 -> 0 | N19: 核對
A20: 2. 分部營業利益（Microsoft 無未分攤項：分部合計＝合併營業利益）
A21: Agents and Infra 營業利益 | B21: 26.171 | C21: 26.718 | D21: 27.704 | E21: 30.221 | F21: 32.718 | G21: 33.167 | H21: 33.748 | I21: 36.732 | J21: =SUM(B21:E21) -> 110.814 | K21: =SUM(F21:I21) -> 136.365 | L21: 110.814 | M21: 136.365 | N21: Verified | O21: 8-K 2026-09-02 附件 99.1（As Restated）｜q.seg27.ai.oi.*
A22: Devices and Consumer 營業利益 | B22: 4.381 | C22: 4.935 | D22: 4.296 | E22: 4.102 | F22: 5.243 | G22: 5.108 | H22: 4.65 | I22: 3.871 | J22: =SUM(B22:E22) -> 17.714 | K22: =SUM(F22:I22) -> 18.872 | L22: 17.714 | M22: 18.872 | N22: Verified | O22: 8-K 2026-09-02 附件 99.1（As Restated）｜q.seg27.dc.oi.*
A23: 合併營業利益（公司損益表） | B23: 30.552 | C23: 31.653 | D23: 32 | E23: 34.323 | F23: 37.961 | G23: 38.275 | H23: 38.398 | I23: 40.603 | J23: =SUM(B23:E23) -> 128.528 | K23: =SUM(F23:I23) -> 155.237 | L23: 128.528 | M23: 155.237 | N23: Verified | O23: 財報新聞稿／10-K｜q.oi.*、is.oi.*
A24: 檢查：分部營業利益合計 − 合併營業利益（未分攤＝0） | B24: =B21+B22-B23 -> 0 | C24: =C21+C22-C23 -> 0 | D24: =D21+D22-D23 -> 0 | E24: =E21+E22-E23 -> 0 | F24: =F21+F22-F23 -> 0 | G24: =G21+G22-G23 -> 0 | H24: =H21+H22-H23 -> 0 | I24: =I21+I22-I23 -> 0 | ... M24: =M21+M22-M23 -> 0 | N24: 核對
A25: 3. 合併損益主要列（年度值；淨利另列各季）
A26: 淨利（GAAP，含 OpenAI 等持股損益） | B26: 24.667 | C26: 24.108 | D26: 25.824 | E26: 27.233 | F26: 27.747 | G26: 38.458 | H26: 31.778 | I26: 35.766 | J26: =SUM(B26:E26) -> 101.832 | K26: =SUM(F26:I26) -> 133.749 | L26: 101.832 | M26: 133.749 | N26: Verified | O26: 財報新聞稿／10-K｜q.ni.*、is.ni.*
A27: 業外收支（other income (expense), net） | L27: -4.901 | M27: 10.697 | N27: Verified | O27: 10-K｜is.oie.*
A28: 稅前淨利 | L28: 123.627 | M28: 165.934 | N28: Verified | O28: 10-K｜is.pretax.*
A29: 所得稅 | L29: 21.795 | M29: 32.185 | N29: Verified | O29: 10-K｜is.tax.*
A30: 其中：OpenAI 等持股損益（公司非 GAAP 調節） | L30: -4.763 | M30: 6.53 | N30: Verified | O30: 10-K｜is.openaiGain.*
A31: 稀釋加權股數（十億股） | L31: 7.465 | M31: 7.453 | N31: Verified | O31: 10-K｜is.sharesDilW.*
A32: 稀釋 EPS（US$） | L32: 13.64 | M32: 17.95 | N32: Verified | O32: 10-K｜is.epsDil.*
A33: 檢查：營業利益＋業外 − 稅前；稅前 − 稅 − 淨利（年度，應為 0） | L33: =(L23+L27-L28)+(L28-L29-L26) -> 0 | M33: =(M23+M27-M28)+(M28-M29-M26) -> 0 | N33: 核對
A34: 4. 現金流量（各季為新聞稿單季值；資本支出為現金 PP&E）
A35: 營業現金流 | B35: 34.18 | C35: 22.291 | D35: 37.044 | E35: 42.647 | F35: 45.057 | G35: 35.758 | H35: 46.679 | I35: 55.441 | J35: =SUM(B35:E35) -> 136.162 | K35: =SUM(F35:I35) -> 182.935 | L35: 136.162 | M35: 182.935 | N35: Verified | O35: 新聞稿現金流量表｜q.cf.ocf.*
A36: 資本支出（現金 PP&E，正值） | B36: 14.923 | C36: 15.804 | D36: 16.745 | E36: 17.079 | F36: 19.394 | G36: 29.876 | H36: 30.876 | I36: 35.802 | J36: =SUM(B36:E36) -> 64.551 | K36: =SUM(F36:I36) -> 115.948 | L36: 64.551 | M36: 115.948 | N36: Verified | O36: 新聞稿現金流量表｜q.cf.capex.*
A37: 自由現金流（營業現金流 − 現金資本支出） | B37: =B35-B36 -> 19.257 | C37: =C35-C36 -> 6.487 | D37: =D35-D36 -> 20.299 | E37: =E35-E36 -> 25.568 | F37: =F35-F36 -> 25.663 | G37: =G35-G36 -> 5.882 | H37: =H35-H36 -> 15.803 | I37: =I35-I36 -> 19.639 | J37: =SUM(B37:E37) -> 71.611 | K37: =SUM(F37:I37) -> 66.987 | L37: =L35-L36 -> 71.611 | M37: =M35-M36 -> 66.987 | N37: Derived
A38: 折舊、攤銷及其他（現金流量表） | B38: 6.716 | C38: 5.667 | D38: 7.734 | E38: 9.317 | F38: 8.147 | G38: 9.198 | H38: 10.167 | I38: 11.022 | J38: =SUM(B38:E38) -> 29.434 | K38: =SUM(F38:I38) -> 38.534 | L38: 29.433 | M38: 38.534 | N38: Verified | O38: 新聞稿現金流量表｜q.cf.da.*（Q1 由年初至今推得）
A39: 股票薪酬 | B39: 2.832 | C39: 3.089 | D39: 2.98 | E39: 3.073 | F39: 2.983 | G39: 3.219 | H39: 3.081 | I39: 3.122 | J39: =SUM(B39:E39) -> 11.974 | K39: =SUM(F39:I39) -> 12.405 | L39: 11.974 | M39: 12.405 | N39: Verified | O39: 新聞稿現金流量表｜q.cf.sbc.*
A40: 回購（正值） | B40: 4.107 | C40: 4.986 | D40: 4.781 | E40: 4.546 | F40: 5.65 | G40: 7.415 | H40: 4.627 | I40: 4.579 | J40: =SUM(B40:E40) -> 18.42 | K40: =SUM(F40:I40) -> 22.271 | L40: 18.42 | M40: 22.271 | N40: Verified | O40: 新聞稿現金流量表｜q.cf.buyback.*
...

Sheet Thesis
A1: Thesis — 命題模組：AI 在役 MW → Azure AI 營收（MW × Tokenomics 每 MW 持有成本 × k）；AI 資本支出（MW × Tokenomics 每 MW 成本）→ AI 折舊與營運成本 → Agents and Infra 營業利益；AI 增量 ROIC 對 WACC
A2: 三情境的 MW 路徑相同（資本支出依公司指引），差在變現：k（長約／現貨組合）與 Copilot 座席。命題模組只驅動 Azure 的「Azure AI」子列與 M365 cloud 的「Copilot」子列，不取代官方分部
A3: 核心問題的答案列：「AI 增量 ROIC − WACC」（FY2029 欄）
A4: 情境 A（樂觀）｜命題模組（Thesis）
A5: 項目 | B5: 單位 | C5: FY2024A | D5: FY2025A | E5: FY2026A | F5: FY2027 | G5: FY2028 | H5: FY2029 | I5: FY2030 | J5: FY2031 | K5: FY2032 | L5: 說明
A6: 會計年度（數值；公式以「年度 − base_fy」計年數） | B6: 年 | C6: 2024 | D6: 2025 | E6: 2026 | F6: 2027 | G6: 2028 | H6: 2029 | I6: 2030 | J6: 2031 | K6: 2032
A7: 在役對外 AI MW 每年新增 | B7: MW | F7: =pace -> 2527.2 | G7: =pace -> 2527.2 | H7: =pace -> 2527.2 | I7: =pace+(g_tv*Thesis!H8-pace)*MIN(1,(Thesis!I6-pace_y0)/(pace_y1-pace_y0)) -> 1793.116 | J7: =pace+(g_tv*Thesis!H8-pace)*MIN(1,(Thesis!J6-pace_y0)/(pace_y1-pace_y0)) -> 1059.032 | K7: =pace+(g_tv*Thesis!H8-pace)*MIN(1,(Thesis!K6-pace_y0)/(pace_y1-pace_y0)) -> 324.948 | L7: FY2029 以前＝依資本支出指引的速度；之後逐年線性收斂，FY2032 只剩 g_tv × FY2029 在役 MW（修正一 F5：終值不落在建置高峰）
A8: 在役對外 AI MW（年底，含租用） | B8: MW | C8: =mw_ext_24 -> 640 | D8: =mw_ext_25 -> 1630 | E8: =mw_ext_26 -> 3250 | F8: =Thesis!E8+Thesis!F7 -> 5777.2 | G8: =Thesis!F8+Thesis!G7 -> 8304.4 | H8: =Thesis!G8+Thesis!H7 -> 10831.6 | I8: =Thesis!H8+Thesis!I7 -> 12624.716 | J8: =Thesis!I8+Thesis!J7 -> 13683.748 | K8: =Thesis!J8+Thesis!K7 -> 14008.696 | L8: 三情境速度相同（變現驅動不同）
A9: 其中租用 neocloud 的對外 MW | B9: MW | C9: =rent_ext_24 -> 150 | D9: =rent_ext_25 -> 400 | E9: =rent_ext_26 -> 550 | F9: =rent_ext_f -> 756 | G9: =rent_ext_f -> 756 | H9: =rent_ext_f -> 756 | I9: =rent_ext_f -> 756 | J9: =rent_ext_f -> 756 | K9: =rent_ext_f -> 756 | L9: 收入照算，不計資本支出與折舊（C20）
A10: 自有對外 MW | B10: MW | C10: =Thesis!C8-Thesis!C9 -> 490 | D10: =Thesis!D8-Thesis!D9 -> 1230 | E10: =Thesis!E8-Thesis!E9 -> 2700 | F10: =Thesis!F8-Thesis!F9 -> 5021.2 | G10: =Thesis!G8-Thesis!G9 -> 7548.4 | H10: =Thesis!H8-Thesis!H9 -> 10075.6 | I10: =Thesis!I8-Thesis!I9 -> 11868.716 | J10: =Thesis!J8-Thesis!J9 -> 12927.748 | K10: =Thesis!K8-Thesis!K9 -> 13252.696
A11: 自有 AI MW（對外 ÷ 對外比例） | B11: MW | C11: =Thesis!C10/ext_sh -> 816.66667 | D11: =Thesis!D10/ext_sh -> 2050 | E11: =Thesis!E10/ext_sh -> 4500 | F11: =Thesis!F10/ext_sh -> 8368.6667 | G11: =Thesis!G10/ext_sh -> 12580.667 | H11: =Thesis!H10/ext_sh -> 16792.667 | I11: =Thesis!I10/ext_sh -> 19781.193 | J11: =Thesis!J10/ext_sh -> 21546.247 | K11: =Thesis!K10/ext_sh -> 22087.827 | L11: 含自用（M365／GitHub Copilot、MAI 研發）
A12: 其中自用 AI MW | B12: MW | C12: =Thesis!C11-Thesis!C10 -> 326.66667 | D12: =Thesis!D11-Thesis!D10 -> 820 | E12: =Thesis!E11-Thesis!E10 -> 1800 | F12: =Thesis!F11-Thesis!F10 -> 3347.4667 | G12: =Thesis!G11-Thesis!G10 -> 5032.2667 | H12: =Thesis!H11-Thesis!H10 -> 6717.0667 | I12: =Thesis!I11-Thesis!I10 -> 7912.4773 | J12: =Thesis!J11-Thesis!J10 -> 8618.4987 | K12: =Thesis!K11-Thesis!K10 -> 8835.1307
A13: 自有 AI MW 新增（FY2024 欄含以前全部） | B13: MW | C13: =Thesis!C11 -> 816.66667 | D13: =Thesis!D11-Thesis!C11 -> 1233.3333 | E13: =Thesis!E11-Thesis!D11 -> 2450 | F13: =Thesis!F11-Thesis!E11 -> 3868.6667 | G13: =Thesis!G11-Thesis!F11 -> 4212 | H13: =Thesis!H11-Thesis!G11 -> 4212 | I13: =Thesis!I11-Thesis!H11 -> 2988.5267 | J13: =Thesis!J11-Thesis!I11 -> 1765.0533 | K13: =Thesis!K11-Thesis!J11 -> 541.58
A14: 在役對外 MW 新增 | B14: MW | D14: =Thesis!D8-Thesis!C8 -> 990 | E14: =Thesis!E8-Thesis!D8 -> 1620 | F14: =Thesis!F8-Thesis!E8 -> 2527.2 | G14: =Thesis!G8-Thesis!F8 -> 2527.2 | H14: =Thesis!H8-Thesis!G8 -> 2527.2 | I14: =Thesis!I8-Thesis!H8 -> 1793.116 | J14: =Thesis!J8-Thesis!I8 -> 1059.032 | K14: =Thesis!K8-Thesis!J8 -> 324.948
A15: 其中汰換為新世代的對外 MW（汰換 MW × 對外比例） | B15: MW | F15: =Thesis!F32*ext_sh -> 0 | G15: =Thesis!G32*ext_sh -> 0 | H15: =Thesis!H32*ext_sh -> 0 | I15: =Thesis!I32*ext_sh -> 490 | J15: =Thesis!J32*ext_sh -> 740 | K15: =Thesis!K32*ext_sh -> 1470 | L15: 修正一：汰換時在役世代占比同步更新（舊世代依期初占比移出、新世代依當年新增占比移入）
A16: 在役對外 MW：Hopper | B16: MW | C16: =mix_h*Thesis!C8 -> 128 | D16: =mix_h*Thesis!D8 -> 326 | E16: =mix_h*Thesis!E8 -> 650 | F16: =Thesis!E16-Thesis!F15*mix_h -> 650 | G16: =Thesis!F16-Thesis!G15*mix_h -> 650 | H16: =Thesis!G16-Thesis!H15*mix_h -> 650 | I16: =Thesis!H16-Thesis!I15*mix_h -> 552 | J16: =Thesis!I16-Thesis!J15*mix_h -> 404 | K16: =Thesis!J16-Thesis!K15*mix_h -> 110
A17: 在役對外 MW：GB200 | B17: MW | C17: =mix_g2*Thesis!C8 -> 288 | D17: =mix_g2*Thesis!D8 -> 733.5 | E17: =mix_g2*Thesis!E8 -> 1462.5 | F17: =Thesis!E17-Thesis!F15*mix_g2 -> 1462.5 | G17: =Thesis!F17-Thesis!G15*mix_g2 -> 1462.5 | H17: =Thesis!G17-Thesis!H15*mix_g2 -> 1462.5 | I17: =Thesis!H17-Thesis!I15*mix_g2 -> 1242 | J17: =Thesis!I17-Thesis!J15*mix_g2 -> 909 | K17: =Thesis!J17-Thesis!K15*mix_g2 -> 247.5
A18: 在役對外 MW：GB300（含 Maia 200） | B18: MW | C18: =mix_g3*Thesis!C8 -> 224 | D18: =mix_g3*Thesis!D8 -> 570.5 | E18: =mix_g3*Thesis!E8 -> 1137.5 | F18: =Thesis!E18+(Thesis!F14+Thesis!F15)*a_g3_27-Thesis!F15*mix_g3 -> 2906.54 | G18: =Thesis!F18+(Thesis!G14+Thesis!G15)*a_g3_28-Thesis!G15*mix_g3 -> 3664.7 | H18: =Thesis!G18+(Thesis!H14+Thesis!H15)*a_g3_29-Thesis!H15*mix_g3 -> 3917.42 | I18: =Thesis!H18+(Thesis!I14+Thesis!I15)*a_g3_29-Thesis!I15*mix_g3 -> 3974.2316 | J18: =Thesis!I18+(Thesis!J14+Thesis!J15)*a_g3_29-Thesis!J15*mix_g3 -> 3895.1348 | K18: =Thesis!J18+(Thesis!K14+Thesis!K15)*a_g3_29-Thesis!K15*mix_g3 -> 3560.1296
A19: 在役對外 MW：VR200 | B19: MW | C19: 0 | D19: 0 | E19: 0 | F19: =Thesis!E19+(Thesis!F14+Thesis!F15)*(1-a_g3_27) -> 758.16 | G19: =Thesis!F19+(Thesis!G14+Thesis!G15)*(1-a_g3_28) -> 2527.2 | H19: =Thesis!G19+(Thesis!H14+Thesis!H15)*(1-a_g3_29) -> 4801.68 | I19: =Thesis!H19+(Thesis!I14+Thesis!I15)*(1-a_g3_29) -> 6856.4844 | J19: =Thesis!I19+(Thesis!J14+Thesis!J15)*(1-a_g3_29) -> 8475.6132 | K19: =Thesis!J19+(Thesis!K14+Thesis!K15)*(1-a_g3_29) -> 10091.066
A20: 在役世代加權 IF_HoldEcon | B20: US$M/MW-年 | C20: =(Thesis!C16*tk_hold_h100+Thesis!C17*tk_hold_gb200+Thesis!C18*tk_hold_gb300+Thesis!C19*tk_hold_vr200)/Thesis!C8 -> 9.7235358 | D20: =(Thesis!D16*tk_hold_h100+Thesis!D17*tk_hold_gb200+Thesis!D18*tk_hold_gb300+Thesis!D19*tk_hold_vr200)/Thesis!D8 -> 9.7235358 | E20: =(Thesis!E16*tk_hold_h100+Thesis!E17*tk_hold_gb200+Thesis!E18*tk_hold_gb300+Thesis!E19*tk_hold_vr200)/Thesis!E8 -> 9.7235358 | F20: =(Thesis!F16*tk_hold_h100+Thesis!F17*tk_hold_gb200+Thesis!F18*tk_hold_gb300+Thesis!F19*tk_hold_vr200)/Thesis!F8 -> 10.407957 | G20: =(Thesis!G16*tk_hold_h100+Thesis!G17*tk_hold_gb200+Thesis!G18*tk_hold_gb300+Thesis!G19*tk_hold_vr200)/Thesis!G8 -> 10.838813 | H20: =(Thesis!H16*tk_hold_h100+Thesis!H17*tk_hold_gb200+Thesis!H18*tk_hold_gb300+Thesis!H19*tk_hold_vr200)/Thesis!H8 -> 11.131102 | I20: =(Thesis!I16*tk_hold_h100+Thesis!I17*tk_hold_gb200+Thesis!I18*tk_hold_gb300+Thesis!I19*tk_hold_vr200)/Thesis!I8 -> 11.359428 | J20: =(Thesis!J16*tk_hold_h100+Thesis!J17*tk_hold_gb200+Thesis!J18*tk_hold_gb300+Thesis!J19*tk_hold_vr200)/Thesis!J8 -> 11.544151 | K20: =(Thesis!K16*tk_hold_h100+Thesis!K17*tk_hold_gb200+Thesis!K18*tk_hold_gb300+Thesis!K19*tk_hold_vr200)/Thesis!K8 -> 11.805338
A21: k（長約占比 × k_長約＋其餘 × k_現貨） | B21: x | C21: =k_B -> 1.1721393 | D21: =k_B -> 1.1721393 | E21: =k_B -> 1.1721393 | F21: =(k_B+((ls_A*k_long+(1-ls_A)*k_spot)-k_B)*MIN(1,(Thesis!F6-base_fy)/k_ramp)) -> 1.2502283 | G21: =(k_B+((ls_A*k_long+(1-ls_A)*k_spot)-k_B)*MIN(1,(Thesis!G6-base_fy)/k_ramp)) -> 1.3283172 | H21: =(k_B+((ls_A*k_long+(1-ls_A)*k_spot)-k_B)*MIN(1,(Thesis!H6-base_fy)/k_ramp)) -> 1.4064062 | I21: =(k_B+((ls_A*k_long+(1-ls_A)*k_spot)-k_B)*MIN(1,(Thesis!I6-base_fy)/k_ramp)) -> 1.4064062 | J21: =(k_B+((ls_A*k_long+(1-ls_A)*k_spot)-k_B)*MIN(1,(Thesis!J6-base_fy)/k_ramp)) -> 1.4064062 | K21: =(k_B+((ls_A*k_long+(1-ls_A)*k_spot)-k_B)*MIN(1,(Thesis!K6-base_fy)/k_ramp)) -> 1.4064062 | L21: 實績期三情境同用基準 k（拆分是估計，不是情境）；FY2027 起 k_ramp 年線性移到情境 k
A22: 每 MW 年收入（對外） | B22: US$M/MW-年 | C22: =Thesis!C20*Thesis!C21*chip_f -> 11.397339 | D22: =Thesis!D20*Thesis!D21*chip_f -> 11.397339 | E22: =Thesis!E20*Thesis!E21*chip_f -> 11.397339 | F22: =Thesis!F20*Thesis!F21*chip_f -> 13.012323 | G22: =Thesis!G20*Thesis!G21*chip_f -> 14.397382 | H22: =Thesis!H20*Thesis!H21*chip_f -> 15.654851 | I22: =Thesis!I20*Thesis!I21*chip_f -> 15.97597 | J22: =Thesis!J20*Thesis!J21*chip_f -> 16.235765 | K22: =Thesis!K20*Thesis!K21*chip_f -> 16.6031 | L22: 按 MW-year 計價，不乘利用率（v0.2.2 口徑）
A23: Azure AI 營收（期間平均在役對外 MW × 每 MW 年收入） | B23: US$B | D23: =(Thesis!C8+Thesis!D8)/2*Thesis!D22/1000 -> 12.935979 | E23: =(Thesis!D8+Thesis!E8)/2*Thesis!E22/1000 -> 27.809506 | F23: =(Thesis!E8+Thesis!F8)/2*Thesis!F22/1000 -> 58.732419 | G23: =(Thesis!F8+Thesis!G8)/2*Thesis!G22/1000 -> 101.36909 | H23: =(Thesis!G8+Thesis!H8)/2*Thesis!H22/1000 -> 149.78561 | I23: =(Thesis!H8+Thesis!I8)/2*Thesis!I22/1000 -> 187.3687 | J23: =(Thesis!I8+Thesis!J8)/2*Thesis!J22/1000 -> 213.56902 | K23: =(Thesis!J8+Thesis!K8)/2*Thesis!K22/1000 -> 229.89021 | L23: FY2025、FY2026 為模型估計（用於拆出 Azure 其他）
A24: 在役世代加權 IF_OpexGW | B24: US$M/MW-年 | C24: =(Thesis!C16*tk_opex_h100+Thesis!C17*tk_opex_gb200+Thesis!C18*tk_opex_gb300+Thesis!C19*tk_opex_vr200)/Thesis!C8 -> 1.8863604 | D24: =(Thesis!D16*tk_opex_h100+Thesis!D17*tk_opex_gb200+Thesis!D18*tk_opex_gb300+Thesis!D19*tk_opex_vr200)/Thesis!D8 -> 1.8863604 | E24: =(Thesis!E16*tk_opex_h100+Thesis!E17*tk_opex_gb200+Thesis!E18*tk_opex_gb300+Thesis!E19*tk_opex_vr200)/Thesis!E8 -> 1.8863604 | F24: =(Thesis!F16*tk_opex_h100+Thesis!F17*tk_opex_gb200+Thesis!F18*tk_opex_gb300+Thesis!F19*tk_opex_vr200)/Thesis!F8 -> 1.9430236 | G24: =(Thesis!G16*tk_opex_h100+Thesis!G17*tk_opex_gb200+Thesis!G18*tk_opex_gb300+Thesis!G19*tk_opex_vr200)/Thesis!G8 -> 1.9786942 | H24: =(Thesis!H16*tk_opex_h100+Thesis!H17*tk_opex_gb200+Thesis!H18*tk_opex_gb300+Thesis!H19*tk_opex_vr200)/Thesis!H8 -> 2.0028928 | I24: =(Thesis!I16*tk_opex_h100+Thesis!I17*tk_opex_gb200+Thesis!I18*tk_opex_gb300+Thesis!I19*tk_opex_vr200)/Thesis!I8 -> 2.0217959 | J24: =(Thesis!J16*tk_opex_h100+Thesis!J17*tk_opex_gb200+Thesis!J18*tk_opex_gb300+Thesis!J19*tk_opex_vr200)/Thesis!J8 -> 2.0370891 | K24: =(Thesis!K16*tk_opex_h100+Thesis!K17*tk_opex_gb200+Thesis!K18*tk_opex_gb300+Thesis!K19*tk_opex_vr200)/Thesis!K8 -> 2.0587127
A25: AI 營運成本：自有 AI MW（平均 × IF_OpexGW） | B25: US$B | D25: =(Thesis!C11+Thesis!D11)/2*Thesis!D24/1000 -> 2.7037833 | E25: =(Thesis!D11+Thesis!E11)/2*Thesis!E24/1000 -> 6.1778304 | F25: =(Thesis!E11+Thesis!F11)/2*Thesis!F24/1000 -> 12.502062 | G25: =(Thesis!F11+Thesis!G11)/2*Thesis!G24/1000 -> 20.726162 | H25: =(Thesis!G11+Thesis!H11)/2*Thesis!H24/1000 -> 29.415818 | I25: =(Thesis!H11+Thesis!I11)/2*Thesis!I24/1000 -> 36.97244 | J25: =(Thesis!I11+Thesis!J11)/2*Thesis!J24/1000 -> 42.093838 | K25: =(Thesis!J11+Thesis!K11)/2*Thesis!K24/1000 -> 44.915011
A26: AI 營運成本：租用 neocloud 租金 | B26: US$B | D26: =(Thesis!C9+Thesis!D9)/2*rent_mw/1000 -> 2.44475 | E26: =(Thesis!D9+Thesis!E9)/2*rent_mw/1000 -> 4.22275 | F26: =(Thesis!E9+Thesis!F9)/2*rent_mw/1000 -> 5.80517 | G26: =(Thesis!F9+Thesis!G9)/2*rent_mw/1000 -> 6.72084 | H26: =(Thesis!G9+Thesis!H9)/2*rent_mw/1000 -> 6.72084 | I26: =(Thesis!H9+Thesis!I9)/2*rent_mw/1000 -> 6.72084 | J26: =(Thesis!I9+Thesis!J9)/2*rent_mw/1000 -> 6.72084 | K26: =(Thesis!J9+Thesis!K9)/2*rent_mw/1000 -> 6.72084
A27: AI 營運成本：租用機房租金（1 − 自建比例） | B27: US$B | D27: =(Thesis!C11+Thesis!D11)/2*(1-self_build)*fac_rent/1000 -> 0.85324238 | E27: =(Thesis!D11+Thesis!E11)/2*(1-self_build)*fac_rent/1000 -> 1.9495596 | F27: =(Thesis!E11+Thesis!F11)/2*(1-self_build)*fac_rent/1000 -> 3.8302646 | G27: =(Thesis!F11+Thesis!G11)/2*(1-self_build)*fac_rent/1000 -> 6.2354159 | H27: =(Thesis!G11+Thesis!H11)/2*(1-self_build)*fac_rent/1000 -> 8.7427579 | I27: =(Thesis!H11+Thesis!I11)/2*(1-self_build)*fac_rent/1000 -> 10.885942 | J27: =(Thesis!I11+Thesis!J11)/2*(1-self_build)*fac_rent/1000 -> 12.30081 | K27: =(Thesis!J11+Thesis!K11)/2*(1-self_build)*fac_rent/1000 -> 12.987363 | L27: C22
A28: 自有 AI 中對外的比重（期間平均） | B28: % | D28: =(Thesis!C10+Thesis!D10)/(Thesis!C11+Thesis!D11) -> 0.6 | E28: =(Thesis!D10+Thesis!E10)/(Thesis!D11+Thesis!E11) -> 0.6 | F28: =(Thesis!E10+Thesis!F10)/(Thesis!E11+Thesis!F11) -> 0.6 | G28: =(Thesis!F10+Thesis!G10)/(Thesis!F11+Thesis!G11) -> 0.6 | H28: =(Thesis!G10+Thesis!H10)/(Thesis!G11+Thesis!H11) -> 0.6 | I28: =(Thesis!H10+Thesis!I10)/(Thesis!H11+Thesis!I11) -> 0.6 | J28: =(Thesis!I10+Thesis!J10)/(Thesis!I11+Thesis!J11) -> 0.6 | K28: =(Thesis!J10+Thesis!K10)/(Thesis!J11+Thesis!K11) -> 0.6
A29: Azure AI EBITDA（營收 − 對外營運成本 − 租金） | B29: US$B | D29: =Thesis!D23-Thesis!D28*(Thesis!D25+Thesis!D27)-Thesis!D26 -> 8.3570141 | E29: =Thesis!E23-Thesis!E28*(Thesis!E25+Thesis!E27)-Thesis!E26 -> 18.710322 | F29: =Thesis!F23-Thesis!F28*(Thesis!F25+Thesis!F27)-Thesis!F26 -> 43.127853 | G29: =Thesis!G23-Thesis!G28*(Thesis!G25+Thesis!G27)-Thesis!G26 -> 78.471302 | H29: =Thesis!H23-Thesis!H28*(Thesis!H25+Thesis!H27)-Thesis!H26 -> 120.16962 | I29: =Thesis!I23-Thesis!I28*(Thesis!I25+Thesis!I27)-Thesis!I26 -> 151.93283 | J29: =Thesis!J23-Thesis!J28*(Thesis!J25+Thesis!J27)-Thesis!J26 -> 174.21139 | K29: =Thesis!K23-Thesis!K28*(Thesis!K25+Thesis!K27)-Thesis!K26 -> 188.42794
A30: 自用 AI 營運成本（服務 Copilot 等自有產品） | B30: US$B | D30: =(1-Thesis!D28)*(Thesis!D25+Thesis!D27) -> 1.4228103 | E30: =(1-Thesis!E28)*(Thesis!E25+Thesis!E27) -> 3.250956 | F30: =(1-Thesis!F28)*(Thesis!F25+Thesis!F27) -> 6.5329306 | G30: =(1-Thesis!G28)*(Thesis!G25+Thesis!G27) -> 10.784631 | H30: =(1-Thesis!H28)*(Thesis!H25+Thesis!H27) -> 15.263431 | I30: =(1-Thesis!I28)*(Thesis!I25+Thesis!I27) -> 19.143353 | J30: =(1-Thesis!J28)*(Thesis!J25+Thesis!J27) -> 21.757859 | K30: =(1-Thesis!K28)*(Thesis!K25+Thesis!K27) -> 23.160949
A31: 新增與汰換 MW 的 IT 資本支出（世代加權） | B31: US$M/MW | C31: =cxit_open -> 27.5919 | D31: =cxit_open -> 27.5919 | E31: =cxit_open -> 27.5919 | F31: =(a_g3_27*tk_cxit_gb300+(1-a_g3_27)*tk_cxit_vr200) -> 33.841962 | G31: =(a_g3_28*tk_cxit_gb300+(1-a_g3_28)*tk_cxit_vr200) -> 35.981614 | H31: =(a_g3_29*tk_cxit_gb300+(1-a_g3_29)*tk_cxit_vr200) -> 37.051439 | I31: =(a_g3_29*tk_cxit_gb300+(1-a_g3_29)*tk_cxit_vr200) -> 37.051439 | J31: =(a_g3_29*tk_cxit_gb300+(1-a_g3_29)*tk_cxit_vr200) -> 37.051439 | K31: =(a_g3_29*tk_cxit_gb300+(1-a_g3_29)*tk_cxit_vr200) -> 37.051439 | L31: FY2026 以前用期初世代加權（估計）
A32: GPU 汰換 MW（自有 AI MW 滿 IT 年限者） | B32: MW | F32: =Thesis!C13*IF(Thesis!F6-Thesis!C6=life_it,1,0)+Thesis!D13*IF(Thesis!F6-Thesis!D6=life_it,1,0)+Thesis!E13*IF(Thesis!F6-Thesis!E6=life_it,1,0) -> 0 | G32: =Thesis!C13*IF(Thesis!G6-Thesis!C6=life_it,1,0)+Thesis!D13*IF(Thesis!G6-Thesis!D6=life_it,1,0)+Thesis!E13*IF(Thesis!G6-Thesis!E6=life_it,1,0)+Thesis!F13*IF(Thesis!G6-Thesis!F6=life_it,1,0) -> 0 | H32: =Thesis!C13*IF(Thesis!H6-Thesis!C6=life_it,1,0)+Thesis!D13*IF(Thesis!H6-Thesis!D6=life_it,1,0)+Thesis!E13*IF(Thesis!H6-Thesis!E6=life_it,1,0)+Thesis!F13*IF(Thesis!H6-Thesis!F6=life_it,1,0)+Thesis!G13*IF(Thesis!H6-Thesis!G6=life_it,1,0) -> 0 | I32: =Thesis!C13*IF(Thesis!I6-Thesis!C6=life_it,1,0)+Thesis!D13*IF(Thesis!I6-Thesis!D6=life_it,1,0)+Thesis!E13*IF(Thesis!I6-Thesis!E6=life_it,1,0)+Thesis!F13*IF(Thesis!I6-Thesis!F6=life_it,1,0)+Thesis!G13*IF(Thesis!I6-Thesis!G6=life_it,1,0)+Thesis!H13*IF(Thesis!I6-Thesis!H6=life_it,1,0) -> 816.66667 | J32: =Thesis!C13*IF(Thesis!J6-Thesis!C6=life_it,1,0)+Thesis!D13*IF(Thesis!J6-Thesis!D6=life_it,1,0)+Thesis!E13*IF(Thesis!J6-Thesis!E6=life_it,1,0)+Thesis!F13*IF(Thesis!J6-Thesis!F6=life_it,1,0)+Thesis!G13*IF(Thesis!J6-Thesis!G6=life_it,1,0)+Thesis!H13*IF(Thesis!J6-Thesis!H6=life_it,1,0)+Thesis!I13*IF(Thesis!J6-Thesis!I6=life_it,1,0) -> 1233.3333 | K32: =Thesis!C13*IF(Thesis!K6-Thesis!C6=life_it,1,0)+Thesis!D13*IF(Thesis!K6-Thesis!D6=life_it,1,0)+Thesis!E13*IF(Thesis!K6-Thesis!E6=life_it,1,0)+Thesis!F13*IF(Thesis!K6-Thesis!F6=life_it,1,0)+Thesis!G13*IF(Thesis!K6-Thesis!G6=life_it,1,0)+Thesis!H13*IF(Thesis!K6-Thesis!H6=life_it,1,0)+Thesis!I13*IF(Thesis!K6-Thesis!I6=life_it,1,0)+Thesis!J13*IF(Thesis!K6-Thesis!J6=life_it,1,0) -> 2450 | L32: 只換 IT、機房不換；FY2024 欄含 FY2024 以前全部（視同 FY2024 投入）；舊機隊在年限到期後停止折舊，汰換後的新 IT 另計折舊（不重複）
A33: AI IT 資本支出（公式） | B33: US$B | C33: =Thesis!C13*Thesis!C31/1000 -> 22.533385 | D33: =Thesis!D13*Thesis!D31/1000 -> 34.030009 | E33: =Thesis!E13*Thesis!E31/1000 -> 67.600154 | F33: =(Thesis!F13+Thesis!F32)*Thesis!F31/1000 -> 130.92327 | G33: =(Thesis!G13+Thesis!G32)*Thesis!G31/1000 -> 151.55456 | H33: =(Thesis!H13+Thesis!H32)*Thesis!H31/1000 -> 156.06066 | I33: =(Thesis!I13+Thesis!I32)*Thesis!I31/1000 -> 140.98789 | J33: =(Thesis!J13+Thesis!J32)*Thesis!J31/1000 -> 111.09454 | K33: =(Thesis!K13+Thesis!K32)*Thesis!K31/1000 -> 110.84234
A34: AI 機房資本支出（自建比例 × IF_CapexFacility） | B34: US$B | C34: =Thesis!C13*self_build*tk_cxfac/1000 -> 6.2083 | D34: =Thesis!D13*self_build*tk_cxfac/1000 -> 9.3758 | E34: =Thesis!E13*self_build*tk_cxfac/1000 -> 18.6249 | F34: =Thesis!F13*self_build*tk_cxfac/1000 -> 29.409604 | G34: =Thesis!G13*self_build*tk_cxfac/1000 -> 32.019624 | H34: =Thesis!H13*self_build*tk_cxfac/1000 -> 32.019624 | I34: =Thesis!I13*self_build*tk_cxfac/1000 -> 22.71878 | J34: =Thesis!J13*self_build*tk_cxfac/1000 -> 13.417935 | K34: =Thesis!K13*self_build*tk_cxfac/1000 -> 4.1170912
A35: FY2027 補足到公司資本支出下限的差額（計入 IT） | B35: US$B | F35: =MAX(0,capex_floor27-Thesis!F33-Thesis!F34-CF!F23) -> 8.1377769 | L35: 近期以公司指引為下限（C10 方法沿用）；IT 占約三分之二（法說短期資產）
A36: AI IT 資本支出（含補足差額） | B36: US$B | C36: =Thesis!C33 -> 22.533385 | D36: =Thesis!D33 -> 34.030009 | E36: =Thesis!E33 -> 67.600154 | F36: =Thesis!F33+Thesis!F35 -> 139.06105 | G36: =Thesis!G33 -> 151.55456 | H36: =Thesis!H33 -> 156.06066 | I36: =Thesis!I33 -> 140.98789 | J36: =Thesis!J33 -> 111.09454 | K36: =Thesis!K33 -> 110.84234
A37: AI 資本支出合計 | B37: US$B | C37: =Thesis!C36+Thesis!C34 -> 28.741685 | D37: =Thesis!D36+Thesis!D34 -> 43.405809 | E37: =Thesis!E36+Thesis!E34 -> 86.225054 | F37: =Thesis!F36+Thesis!F34 -> 168.47065 | G37: =Thesis!G36+Thesis!G34 -> 183.57418 | H37: =Thesis!H36+Thesis!H34 -> 188.08029 | I37: =Thesis!I36+Thesis!I34 -> 163.70667 | J37: =Thesis!J36+Thesis!J34 -> 124.51248 | K37: =Thesis!K36+Thesis!K34 -> 114.95944 | L37: FY2026 以前為依 MW 估計的值（非公司揭露）
A38: AI IT 折舊（半年慣例、年限 life_it） | B38: US$B | E38: =(Thesis!C36*IF(2<life_it,1,IF(2=life_it,0.5,0))+Thesis!D36*IF(1<life_it,1,IF(1=life_it,0.5,0))+Thesis!E36*0.5)/life_it -> 15.060578 | F38: =(Thesis!C36*IF(3<life_it,1,IF(3=life_it,0.5,0))+Thesis!D36*IF(2<life_it,1,IF(2=life_it,0.5,0))+Thesis!E36*IF(1<life_it,1,IF(1=life_it,0.5,0))+Thesis!F36*0.5)/life_it -> 32.282345 | G38: =(Thesis!C36*IF(4<life_it,1,IF(4=life_it,0.5,0))+Thesis!D36*IF(3<life_it,1,IF(3=life_it,0.5,0))+Thesis!E36*IF(2<life_it,1,IF(2=life_it,0.5,0))+Thesis!F36*IF(1<life_it,1,IF(1=life_it,0.5,0))+Thesis!G36*0.5)/life_it -> 56.500312 | H38: =(Thesis!C36*IF(5<life_it,1,IF(5=life_it,0.5,0))+Thesis!D36*IF(4<life_it,1,IF(4=life_it,0.5,0))+Thesis!E36*IF(3<life_it,1,IF(3=life_it,0.5,0))+Thesis!F36*IF(2<life_it,1,IF(2=life_it,0.5,0))+Thesis!G36*IF(1<life_it,1,IF(1=life_it,0.5,0))+Thesis!H36*0.5)/life_it -> 82.134914 | I38: =(Thesis!C36*IF(6<life_it,1,IF(6=life_it,0.5,0))+Thesis!D36*IF(5<life_it,1,IF(5=life_it,0.5,0))+Thesis!E36*IF(4<life_it,1,IF(4=life_it,0.5,0))+Thesis!F36*IF(3<life_it,1,IF(3=life_it,0.5,0))+Thesis!G36*IF(2<life_it,1,IF(2=life_it,0.5,0))+Thesis!H36*IF(1<life_it,1,IF(1=life_it,0.5,0))+Thesis!I36*0.5)/life_it -> 105.01118 | J38: =(Thesis!C36*IF(7<life_it,1,IF(7=life_it,0.5,0))+Thesis!D36*IF(6<life_it,1,IF(6=life_it,0.5,0))+Thesis!E36*IF(5<life_it,1,IF(5=life_it,0.5,0))+Thesis!F36*IF(4<life_it,1,IF(4=life_it,0.5,0))+Thesis!G36*IF(3<life_it,1,IF(3=life_it,0.5,0))+Thesis!H36*IF(2<life_it,1,IF(2=life_it,0.5,0))+Thesis!I36*IF(1<life_it,1,IF(1=life_it,0.5,0))+Thesis!J36*0.5)/life_it -> 121.30443 | K38: =(Thesis!C36*IF(8<life_it,1,IF(8=life_it,0.5,0))+Thesis!D36*IF(7<life_it,1,IF(7=life_it,0.5,0))+Thesis!E36*IF(6<life_it,1,IF(6=life_it,0.5,0))+Thesis!F36*IF(5<life_it,1,IF(5=life_it,0.5,0))+Thesis!G36*IF(4<life_it,1,IF(4=life_it,0.5,0))+Thesis!H36*IF(3<life_it,1,IF(3=life_it,0.5,0))+Thesis!I36*IF(2<life_it,1,IF(2=life_it,0.5,0))+Thesis!J36*IF(1<life_it,1,IF(1=life_it,0.5,0))+Thesis!K36*0.5)/life_it -> 131.32999
A39: AI 機房折舊（年限 life_fac） | B39: US$B | E39: =(Thesis!C34*IF(2<life_fac,1,IF(2=life_fac,0.5,0))+Thesis!D34*IF(1<life_fac,1,IF(1=life_fac,0.5,0))+Thesis!E34*0.5)/life_fac -> 1.2448275 | F39: =(Thesis!C34*IF(3<life_fac,1,IF(3=life_fac,0.5,0))+Thesis!D34*IF(2<life_fac,1,IF(2=life_fac,0.5,0))+Thesis!E34*IF(1<life_fac,1,IF(1=life_fac,0.5,0))+Thesis!F34*0.5)/life_fac -> 2.4456901 | G39: =(Thesis!C34*IF(4<life_fac,1,IF(4=life_fac,0.5,0))+Thesis!D34*IF(3<life_fac,1,IF(3=life_fac,0.5,0))+Thesis!E34*IF(2<life_fac,1,IF(2=life_fac,0.5,0))+Thesis!F34*IF(1<life_fac,1,IF(1=life_fac,0.5,0))+Thesis!G34*0.5)/life_fac -> 3.9814208 | H39: =(Thesis!C34*IF(5<life_fac,1,IF(5=life_fac,0.5,0))+Thesis!D34*IF(4<life_fac,1,IF(4=life_fac,0.5,0))+Thesis!E34*IF(3<life_fac,1,IF(3=life_fac,0.5,0))+Thesis!F34*IF(2<life_fac,1,IF(2=life_fac,0.5,0))+Thesis!G34*IF(1<life_fac,1,IF(1=life_fac,0.5,0))+Thesis!H34*0.5)/life_fac -> 5.582402 | I39: =(Thesis!C34*IF(6<life_fac,1,IF(6=life_fac,0.5,0))+Thesis!D34*IF(5<life_fac,1,IF(5=life_fac,0.5,0))+Thesis!E34*IF(4<life_fac,1,IF(4=life_fac,0.5,0))+Thesis!F34*IF(3<life_fac,1,IF(3=life_fac,0.5,0))+Thesis!G34*IF(2<life_fac,1,IF(2=life_fac,0.5,0))+Thesis!H34*IF(1<life_fac,1,IF(1=life_fac,0.5,0))+Thesis!I34*0.5)/life_fac -> 6.9508621 | J39: =(Thesis!C34*IF(7<life_fac,1,IF(7=life_fac,0.5,0))+Thesis!D34*IF(6<life_fac,1,IF(6=life_fac,0.5,0))+Thesis!E34*IF(5<life_fac,1,IF(5=life_fac,0.5,0))+Thesis!F34*IF(4<life_fac,1,IF(4=life_fac,0.5,0))+Thesis!G34*IF(3<life_fac,1,IF(3=life_fac,0.5,0))+Thesis!H34*IF(2<life_fac,1,IF(2=life_fac,0.5,0))+Thesis!I34*IF(1<life_fac,1,IF(1=life_fac,0.5,0))+Thesis!J34*0.5)/life_fac -> 7.85428 | K39: =(Thesis!C34*IF(8<life_fac,1,IF(8=life_fac,0.5,0))+Thesis!D34*IF(7<life_fac,1,IF(7=life_fac,0.5,0))+Thesis!E34*IF(6<life_fac,1,IF(6=life_fac,0.5,0))+Thesis!F34*IF(5<life_fac,1,IF(5=life_fac,0.5,0))+Thesis!G34*IF(4<life_fac,1,IF(4=life_fac,0.5,0))+Thesis!H34*IF(3<life_fac,1,IF(3=life_fac,0.5,0))+Thesis!I34*IF(2<life_fac,1,IF(2=life_fac,0.5,0))+Thesis!J34*IF(1<life_fac,1,IF(1=life_fac,0.5,0))+Thesis!K34*0.5)/life_fac -> 8.2926556
A40: AI 折舊合計（進 Agents and Infra 營業利益） | B40: US$B | E40: =Thesis!E38+Thesis!E39 -> 16.305406 | F40: =Thesis!F38+Thesis!F39 -> 34.728035 | G40: =Thesis!G38+Thesis!G39 -> 60.481733 | H40: =Thesis!H38+Thesis!H39 -> 87.717316 | I40: =Thesis!I38+Thesis!I39 -> 111.96204 | J40: =Thesis!J38+Thesis!J39 -> 129.15871 | K40: =Thesis!K38+Thesis!K39 -> 139.62265
...

Sheet Seg
A1: Seg — 營收分部層：官方分部 Agents and Infra、Devices and Consumer（8-K 2026-09-02 重編）→ 八條產品線；Azure ＝ Azure AI（命題）＋ Azure 其他；Microsoft 365 cloud ＝ 基礎 ＋ Copilot（命題）
A2: 非命題產品線：FY2026 對 FY2025 年增線性收斂到長期值（FY2032 到達；In 頁 F 節）；三情境相同。FY2025、FY2026 欄為實績（Azure、M365 cloud 的子列為模型拆分）
A4: 情境 A（樂觀）｜營收分部層（Seg）
A5: 項目 | B5: 單位 | C5: FY2024A | D5: FY2025A | E5: FY2026A | F5: FY2027 | G5: FY2028 | H5: FY2029 | I5: FY2030 | J5: FY2031 | K5: FY2032 | L5: 說明
A6: Azure AI（命題子列） | B6: US$B | D6: =Thesis!D23 -> 12.935979 | E6: =Thesis!E23 -> 27.809506 | F6: =Thesis!F23 -> 58.732419 | G6: =Thesis!G23 -> 101.36909 | H6: =Thesis!H23 -> 149.78561 | I6: =Thesis!I23 -> 187.3687 | J6: =Thesis!J23 -> 213.56902 | K6: =Thesis!K23 -> 229.89021
A7: Azure 其他（非 AI 雲端；FY2025–26＝Azure 實績 − Azure AI 估計） | B7: US$B | D7: =Q!L6-Seg!D6 -> 59.674021 | E7: =Q!M6-Seg!E6 -> 74.128494 | F7: =Seg!E7*(1+Seg!F8) -> 90.07995 | G7: =Seg!F7*(1+Seg!G8) -> 107.02843 | H7: =Seg!G7*(1+Seg!H8) -> 124.27198 | I7: =Seg!H7*(1+Seg!I8) -> 140.9337 | J7: =Seg!I7*(1+Seg!J8) -> 156.01887 | K7: =Seg!J7*(1+Seg!K8) -> 168.50038
A8: 年增（近一年 → 長期值） | B8: % | E8: =Seg!E7/Seg!D7-1 -> 0.24222388 | F8: =Seg!$E$8+(glt_azo-Seg!$E$8)*MIN(1,(Thesis!F6-base_fy)/n_conv) -> 0.21518657 | G8: =Seg!$E$8+(glt_azo-Seg!$E$8)*MIN(1,(Thesis!G6-base_fy)/n_conv) -> 0.18814926 | H8: =Seg!$E$8+(glt_azo-Seg!$E$8)*MIN(1,(Thesis!H6-base_fy)/n_conv) -> 0.16111194 | I8: =Seg!$E$8+(glt_azo-Seg!$E$8)*MIN(1,(Thesis!I6-base_fy)/n_conv) -> 0.13407463 | J8: =Seg!$E$8+(glt_azo-Seg!$E$8)*MIN(1,(Thesis!J6-base_fy)/n_conv) -> 0.10703731 | K8: =Seg!$E$8+(glt_azo-Seg!$E$8)*MIN(1,(Thesis!K6-base_fy)/n_conv) -> 0.08
A9: Azure | B9: US$B | D9: =Seg!D6+Seg!D7 -> 72.61 | E9: =Seg!E6+Seg!E7 -> 101.938 | F9: =Seg!F6+Seg!F7 -> 148.81237 | G9: =Seg!G6+Seg!G7 -> 208.39751 | H9: =Seg!H6+Seg!H7 -> 274.05759 | I9: =Seg!I6+Seg!I7 -> 328.30241 | J9: =Seg!J6+Seg!J7 -> 369.58789 | K9: =Seg!K6+Seg!K7 -> 398.39058
A10: Copilot 付費座席（年底） | B10: 百萬席 | C10: =cop_s24 -> 1 | D10: =cop_s25 -> 5 | E10: =cop_s26 -> 30 | F10: =Seg!E10+cop_add_A -> 60 | G10: =Seg!F10+cop_add_A -> 90 | H10: =Seg!G10+cop_add_A -> 120 | I10: =Seg!H10+cop_add_A*cop_tail -> 135 | J10: =Seg!I10+cop_add_A*cop_tail -> 150 | K10: =Seg!J10+cop_add_A*cop_tail -> 165 | L10: FY2027–FY2029 每年淨增 cop_add；FY2030 起 × cop_tail
A11: Copilot（命題子列：平均座席 × 月費 × 12） | B11: US$B | D11: =(Seg!C10+Seg!D10)/2*cop_px*12/1000 -> 0.9 | E11: =(Seg!D10+Seg!E10)/2*cop_px*12/1000 -> 5.25 | F11: =(Seg!E10+Seg!F10)/2*cop_px*12/1000 -> 13.5 | G11: =(Seg!F10+Seg!G10)/2*cop_px*12/1000 -> 22.5 | H11: =(Seg!G10+Seg!H10)/2*cop_px*12/1000 -> 31.5 | I11: =(Seg!H10+Seg!I10)/2*cop_px*12/1000 -> 38.25 | J11: =(Seg!I10+Seg!J10)/2*cop_px*12/1000 -> 42.75 | K11: =(Seg!J10+Seg!K10)/2*cop_px*12/1000 -> 47.25 | L11: 實績期用基準月費（拆分是估計）；敏感度只改預測期
A12: M365 基礎（不含 Copilot；FY2025–26＝實績 − Copilot 估計） | B12: US$B | D12: =Q!L7-Seg!D11 -> 83.705 | E12: =Q!M7-Seg!E11 -> 95.049 | F12: =Seg!E12*(1+Seg!F13) -> 106.89239 | G12: =Seg!F12*(1+Seg!G13) -> 119.04417 | H12: =Seg!G12*(1+Seg!H13) -> 131.27736 | I12: =Seg!H12*(1+Seg!I13) -> 143.33403 | J12: =Seg!I12*(1+Seg!J13) -> 154.9327 | K12: =Seg!J12*(1+Seg!K13) -> 165.77799
A13: 年增（近一年 → 長期值） | B13: % | E13: =Seg!E12/Seg!D12-1 -> 0.13552356 | F13: =Seg!$E$13+(glt_m365b-Seg!$E$13)*MIN(1,(Thesis!F6-base_fy)/n_conv) -> 0.12460297 | G13: =Seg!$E$13+(glt_m365b-Seg!$E$13)*MIN(1,(Thesis!G6-base_fy)/n_conv) -> 0.11368238 | H13: =Seg!$E$13+(glt_m365b-Seg!$E$13)*MIN(1,(Thesis!H6-base_fy)/n_conv) -> 0.10276178 | I13: =Seg!$E$13+(glt_m365b-Seg!$E$13)*MIN(1,(Thesis!I6-base_fy)/n_conv) -> 0.091841188 | J13: =Seg!$E$13+(glt_m365b-Seg!$E$13)*MIN(1,(Thesis!J6-base_fy)/n_conv) -> 0.080920594 | K13: =Seg!$E$13+(glt_m365b-Seg!$E$13)*MIN(1,(Thesis!K6-base_fy)/n_conv) -> 0.07
A14: Microsoft 365 cloud | B14: US$B | D14: =Seg!D12+Seg!D11 -> 84.605 | E14: =Seg!E12+Seg!E11 -> 100.299 | F14: =Seg!F12+Seg!F11 -> 120.39239 | G14: =Seg!G12+Seg!G11 -> 141.54417 | H14: =Seg!H12+Seg!H11 -> 162.77736 | I14: =Seg!I12+Seg!I11 -> 181.58403 | J14: =Seg!J12+Seg!J11 -> 197.6827 | K14: =Seg!K12+Seg!K11 -> 213.02799
A15: Productivity and server licensing | B15: US$B | D15: =Q!L8 -> 35.391 | E15: =Q!M8 -> 37.285 | F15: =Seg!E15*(1+Seg!F16) -> 39.072083 | G15: =Seg!F15*(1+Seg!G16) -> 40.726563 | H15: =Seg!G15*(1+Seg!H16) -> 42.223599 | I15: =Seg!H15*(1+Seg!I16) -> 43.539799 | J15: =Seg!I15*(1+Seg!J16) -> 44.653811 | K15: =Seg!J15*(1+Seg!K16) -> 45.546887
A16: 年增（近一年 → 長期值） | B16: % | E16: =Seg!E15/Seg!D15-1 -> 0.053516431 | F16: =Seg!$E$16+(glt_lic-Seg!$E$16)*MIN(1,(Thesis!F6-base_fy)/n_conv) -> 0.047930359 | G16: =Seg!$E$16+(glt_lic-Seg!$E$16)*MIN(1,(Thesis!G6-base_fy)/n_conv) -> 0.042344287 | H16: =Seg!$E$16+(glt_lic-Seg!$E$16)*MIN(1,(Thesis!H6-base_fy)/n_conv) -> 0.036758215 | I16: =Seg!$E$16+(glt_lic-Seg!$E$16)*MIN(1,(Thesis!I6-base_fy)/n_conv) -> 0.031172144 | J16: =Seg!$E$16+(glt_lic-Seg!$E$16)*MIN(1,(Thesis!J6-base_fy)/n_conv) -> 0.025586072 | K16: =Seg!$E$16+(glt_lic-Seg!$E$16)*MIN(1,(Thesis!K6-base_fy)/n_conv) -> 0.02
A17: Industry solutions | B17: US$B | D17: =Q!L9 -> 18.417 | E17: =Q!M9 -> 20.345 | F17: =Seg!E17*(1+Seg!F18) -> 22.35722 | G17: =Seg!F17*(1+Seg!G18) -> 24.439212 | H17: =Seg!G17*(1+Seg!H18) -> 26.573805 | I17: =Seg!H17*(1+Seg!I18) -> 28.741217 | J17: =Seg!I17*(1+Seg!J18) -> 30.919255 | K17: =Seg!J17*(1+Seg!K18) -> 33.083602
A18: 年增（近一年 → 長期值） | B18: % | E18: =Seg!E17/Seg!D17-1 -> 0.10468589 | F18: =Seg!$E$18+(glt_ind-Seg!$E$18)*MIN(1,(Thesis!F6-base_fy)/n_conv) -> 0.098904907 | G18: =Seg!$E$18+(glt_ind-Seg!$E$18)*MIN(1,(Thesis!G6-base_fy)/n_conv) -> 0.093123925 | H18: =Seg!$E$18+(glt_ind-Seg!$E$18)*MIN(1,(Thesis!H6-base_fy)/n_conv) -> 0.087342944 | I18: =Seg!$E$18+(glt_ind-Seg!$E$18)*MIN(1,(Thesis!I6-base_fy)/n_conv) -> 0.081561963 | J18: =Seg!$E$18+(glt_ind-Seg!$E$18)*MIN(1,(Thesis!J6-base_fy)/n_conv) -> 0.075780981 | K18: =Seg!$E$18+(glt_ind-Seg!$E$18)*MIN(1,(Thesis!K6-base_fy)/n_conv) -> 0.07
A19: Frontier and support services | B19: US$B | D19: =Q!L10 -> 7.76 | E19: =Q!M10 -> 8.26 | F19: =Seg!E19*(1+Seg!F20) -> 8.7998804 | G19: =Seg!F19*(1+Seg!G20) -> 9.3832127 | H19: =Seg!G19*(1+Seg!H20) -> 10.013919 | I19: =Seg!H19*(1+Seg!I20) -> 10.696311 | J19: =Seg!I19*(1+Seg!J20) -> 11.435129 | K19: =Seg!J19*(1+Seg!K20) -> 12.235588
A20: 年增（近一年 → 長期值） | B20: % | E20: =Seg!E19/Seg!D19-1 -> 0.06443299 | F20: =Seg!$E$20+(glt_fro-Seg!$E$20)*MIN(1,(Thesis!F6-base_fy)/n_conv) -> 0.065360825 | G20: =Seg!$E$20+(glt_fro-Seg!$E$20)*MIN(1,(Thesis!G6-base_fy)/n_conv) -> 0.06628866 | H20: =Seg!$E$20+(glt_fro-Seg!$E$20)*MIN(1,(Thesis!H6-base_fy)/n_conv) -> 0.067216495 | I20: =Seg!$E$20+(glt_fro-Seg!$E$20)*MIN(1,(Thesis!I6-base_fy)/n_conv) -> 0.06814433 | J20: =Seg!$E$20+(glt_fro-Seg!$E$20)*MIN(1,(Thesis!J6-base_fy)/n_conv) -> 0.069072165 | K20: =Seg!$E$20+(glt_fro-Seg!$E$20)*MIN(1,(Thesis!K6-base_fy)/n_conv) -> 0.07
A21: Agents and Infra | B21: US$B | D21: =Seg!D9+Seg!D14+Seg!D15+Seg!D17+Seg!D19 -> 218.783 | E21: =Seg!E9+Seg!E14+Seg!E15+Seg!E17+Seg!E19 -> 268.127 | F21: =Seg!F9+Seg!F14+Seg!F15+Seg!F17+Seg!F19 -> 339.43394 | G21: =Seg!G9+Seg!G14+Seg!G15+Seg!G17+Seg!G19 -> 424.49067 | H21: =Seg!H9+Seg!H14+Seg!H15+Seg!H17+Seg!H19 -> 515.64628 | I21: =Seg!I9+Seg!I14+Seg!I15+Seg!I17+Seg!I19 -> 592.86376 | J21: =Seg!J9+Seg!J14+Seg!J15+Seg!J17+Seg!J19 -> 654.27879 | K21: =Seg!K9+Seg!K14+Seg!K15+Seg!K17+Seg!K19 -> 702.28465
A22: Search and advertising | B22: US$B | D22: =Q!L13 -> 22.171 | E22: =Q!M13 -> 24.835 | F22: =Seg!E22*(1+Seg!F23) -> 27.61149 | G22: =Seg!F22*(1+Seg!G23) -> 30.467567 | H22: =Seg!G22*(1+Seg!H23) -> 33.364377 | I22: =Seg!H22*(1+Seg!I23) -> 36.257702 | J22: =Seg!I22*(1+Seg!J23) -> 39.098837 | K22: =Seg!J22*(1+Seg!K23) -> 41.835755
A23: 年增（近一年 → 長期值） | B23: % | E23: =Seg!E22/Seg!D22-1 -> 0.12015696 | F23: =Seg!$E$23+(glt_srch-Seg!$E$23)*MIN(1,(Thesis!F6-base_fy)/n_conv) -> 0.11179747 | G23: =Seg!$E$23+(glt_srch-Seg!$E$23)*MIN(1,(Thesis!G6-base_fy)/n_conv) -> 0.10343797 | H23: =Seg!$E$23+(glt_srch-Seg!$E$23)*MIN(1,(Thesis!H6-base_fy)/n_conv) -> 0.095078481 | I23: =Seg!$E$23+(glt_srch-Seg!$E$23)*MIN(1,(Thesis!I6-base_fy)/n_conv) -> 0.086718987 | J23: =Seg!$E$23+(glt_srch-Seg!$E$23)*MIN(1,(Thesis!J6-base_fy)/n_conv) -> 0.078359494 | K23: =Seg!$E$23+(glt_srch-Seg!$E$23)*MIN(1,(Thesis!K6-base_fy)/n_conv) -> 0.07
A24: XBOX | B24: US$B | D24: =Q!L14 -> 23.455 | E24: =Q!M14 -> 21.79 | F24: =Seg!E24*(1+Seg!F25) -> 20.573628 | G24: =Seg!F24*(1+Seg!G25) -> 19.737145 | H24: =Seg!G24*(1+Seg!H25) -> 19.233976 | I24: =Seg!H24*(1+Seg!I25) -> 19.035309 | J24: =Seg!I24*(1+Seg!J25) -> 19.127354 | K24: =Seg!J24*(1+Seg!K25) -> 19.509901
A25: 年增（近一年 → 長期值） | B25: % | E25: =Seg!E24/Seg!D24-1 -> -0.070986996 | F25: =Seg!$E$25+(glt_xbox-Seg!$E$25)*MIN(1,(Thesis!F6-base_fy)/n_conv) -> -0.055822497 | G25: =Seg!$E$25+(glt_xbox-Seg!$E$25)*MIN(1,(Thesis!G6-base_fy)/n_conv) -> -0.040657998 | H25: =Seg!$E$25+(glt_xbox-Seg!$E$25)*MIN(1,(Thesis!H6-base_fy)/n_conv) -> -0.025493498 | I25: =Seg!$E$25+(glt_xbox-Seg!$E$25)*MIN(1,(Thesis!I6-base_fy)/n_conv) -> -0.010328999 | J25: =Seg!$E$25+(glt_xbox-Seg!$E$25)*MIN(1,(Thesis!J6-base_fy)/n_conv) -> 0.0048355006 | K25: =Seg!$E$25+(glt_xbox-Seg!$E$25)*MIN(1,(Thesis!K6-base_fy)/n_conv) -> 0.02
A26: Windows OEM and devices | B26: US$B | D26: =Q!L15 -> 17.315 | E26: =Q!M15 -> 17.087 | F26: =Seg!E26*(1+Seg!F27) -> 16.956459 | G26: =Seg!F26*(1+Seg!G27) -> 16.920649 | H26: =Seg!G26*(1+Seg!H27) -> 16.978452 | I26: =Seg!H26*(1+Seg!I27) -> 17.130308 | J26: =Seg!I26*(1+Seg!J27) -> 17.378219 | K26: =Seg!J26*(1+Seg!K27) -> 17.725783
A27: 年增（近一年 → 長期值） | B27: % | E27: =Seg!E26/Seg!D26-1 -> -0.013167774 | F27: =Seg!$E$27+(glt_win-Seg!$E$27)*MIN(1,(Thesis!F6-base_fy)/n_conv) -> -0.0076398113 | G27: =Seg!$E$27+(glt_win-Seg!$E$27)*MIN(1,(Thesis!G6-base_fy)/n_conv) -> -0.0021118491 | H27: =Seg!$E$27+(glt_win-Seg!$E$27)*MIN(1,(Thesis!H6-base_fy)/n_conv) -> 0.0034161132 | I27: =Seg!$E$27+(glt_win-Seg!$E$27)*MIN(1,(Thesis!I6-base_fy)/n_conv) -> 0.0089440755 | J27: =Seg!$E$27+(glt_win-Seg!$E$27)*MIN(1,(Thesis!J6-base_fy)/n_conv) -> 0.014472038 | K27: =Seg!$E$27+(glt_win-Seg!$E$27)*MIN(1,(Thesis!K6-base_fy)/n_conv) -> 0.02
A28: Devices and Consumer | B28: US$B | D28: =Seg!D22+Seg!D24+Seg!D26 -> 62.941 | E28: =Seg!E22+Seg!E24+Seg!E26 -> 63.712 | F28: =Seg!F22+Seg!F24+Seg!F26 -> 65.141576 | G28: =Seg!G22+Seg!G24+Seg!G26 -> 67.125361 | H28: =Seg!H22+Seg!H24+Seg!H26 -> 69.576805 | I28: =Seg!I22+Seg!I24+Seg!I26 -> 72.423319 | J28: =Seg!J22+Seg!J24+Seg!J26 -> 75.60441 | K28: =Seg!K22+Seg!K24+Seg!K26 -> 79.07144
A29: 合併營收（分部合計） | B29: US$B | D29: =Seg!D21+Seg!D28 -> 281.724 | E29: =Seg!E21+Seg!E28 -> 331.839 | F29: =Seg!F21+Seg!F28 -> 404.57552 | G29: =Seg!G21+Seg!G28 -> 491.61603 | H29: =Seg!H21+Seg!H28 -> 585.22308 | I29: =Seg!I21+Seg!I28 -> 665.28708 | J29: =Seg!J21+Seg!J28 -> 729.8832 | K29: =Seg!K21+Seg!K28 -> 781.35609
A30: 檢查：產品線合計 − 分部；實績期另比對公司分部值 | B30: US$B | D30: =(Seg!D9+Seg!D14+Seg!D15+Seg!D17+Seg!D19-Seg!D21)+(Seg!D22+Seg!D24+Seg!D26-Seg!D28)+(Seg!D21-Q!L5)+(Seg!D28-Q!L12)+(Seg!D9-Q!L6)+(Seg!D14-Q!L7) -> 0 | E30: =(Seg!E9+Seg!E14+Seg!E15+Seg!E17+Seg!E19-Seg!E21)+(Seg!E22+Seg!E24+Seg!E26-Seg!E28)+(Seg!E21-Q!M5)+(Seg!E28-Q!M12)+(Seg!E9-Q!M6)+(Seg!E14-Q!M7) -> 0 | F30: =(Seg!F9+Seg!F14+Seg!F15+Seg!F17+Seg!F19-Seg!F21)+(Seg!F22+Seg!F24+Seg!F26-Seg!F28) -> 0 | G30: =(Seg!G9+Seg!G14+Seg!G15+Seg!G17+Seg!G19-Seg!G21)+(Seg!G22+Seg!G24+Seg!G26-Seg!G28) -> 0 | H30: =(Seg!H9+Seg!H14+Seg!H15+Seg!H17+Seg!H19-Seg!H21)+(Seg!H22+Seg!H24+Seg!H26-Seg!H28) -> 0 | I30: =(Seg!I9+Seg!I14+Seg!I15+Seg!I17+Seg!I19-Seg!I21)+(Seg!I22+Seg!I24+Seg!I26-Seg!I28) -> 0 | J30: =(Seg!J9+Seg!J14+Seg!J15+Seg!J17+Seg!J19-Seg!J21)+(Seg!J22+Seg!J24+Seg!J26-Seg!J28) -> 0 | K30: =(Seg!K9+Seg!K14+Seg!K15+Seg!K17+Seg!K19-Seg!K21)+(Seg!K22+Seg!K24+Seg!K26-Seg!K28) -> 0
A31: 情境 B（基準）｜營收分部層（Seg）
A32: 項目 | B32: 單位 | C32: FY2024A | D32: FY2025A | E32: FY2026A | F32: FY2027 | G32: FY2028 | H32: FY2029 | I32: FY2030 | J32: FY2031 | K32: FY2032 | L32: 說明
A33: Azure AI（命題子列） | B33: US$B | D33: =Thesis!D72 -> 12.935979 | E33: =Thesis!E72 -> 27.809506 | F33: =Thesis!F72 -> 55.064007 | G33: =Thesis!G72 -> 89.450541 | H33: =Thesis!H72 -> 124.83563 | I33: =Thesis!I72 -> 156.15846 | J33: =Thesis!J72 -> 177.99456 | K33: =Thesis!K72 -> 191.5971
A34: Azure 其他（非 AI 雲端；FY2025–26＝Azure 實績 − Azure AI 估計） | B34: US$B | D34: =Q!L6-Seg!D33 -> 59.674021 | E34: =Q!M6-Seg!E33 -> 74.128494 | F34: =Seg!E34*(1+Seg!F35) -> 90.07995 | G34: =Seg!F34*(1+Seg!G35) -> 107.02843 | H34: =Seg!G34*(1+Seg!H35) -> 124.27198 | I34: =Seg!H34*(1+Seg!I35) -> 140.9337 | J34: =Seg!I34*(1+Seg!J35) -> 156.01887 | K34: =Seg!J34*(1+Seg!K35) -> 168.50038
A35: 年增（近一年 → 長期值） | B35: % | E35: =Seg!E34/Seg!D34-1 -> 0.24222388 | F35: =Seg!$E$35+(glt_azo-Seg!$E$35)*MIN(1,(Thesis!F55-base_fy)/n_conv) -> 0.21518657 | G35: =Seg!$E$35+(glt_azo-Seg!$E$35)*MIN(1,(Thesis!G55-base_fy)/n_conv) -> 0.18814926 | H35: =Seg!$E$35+(glt_azo-Seg!$E$35)*MIN(1,(Thesis!H55-base_fy)/n_conv) -> 0.16111194 | I35: =Seg!$E$35+(glt_azo-Seg!$E$35)*MIN(1,(Thesis!I55-base_fy)/n_conv) -> 0.13407463 | J35: =Seg!$E$35+(glt_azo-Seg!$E$35)*MIN(1,(Thesis!J55-base_fy)/n_conv) -> 0.10703731 | K35: =Seg!$E$35+(glt_azo-Seg!$E$35)*MIN(1,(Thesis!K55-base_fy)/n_conv) -> 0.08
A36: Azure | B36: US$B | D36: =Seg!D33+Seg!D34 -> 72.61 | E36: =Seg!E33+Seg!E34 -> 101.938 | F36: =Seg!F33+Seg!F34 -> 145.14396 | G36: =Seg!G33+Seg!G34 -> 196.47897 | H36: =Seg!H33+Seg!H34 -> 249.10761 | I36: =Seg!I33+Seg!I34 -> 297.09216 | J36: =Seg!J33+Seg!J34 -> 334.01343 | K36: =Seg!K33+Seg!K34 -> 360.09748
A37: Copilot 付費座席（年底） | B37: 百萬席 | C37: =cop_s24 -> 1 | D37: =cop_s25 -> 5 | E37: =cop_s26 -> 30 | F37: =Seg!E37+cop_add_B -> 50 | G37: =Seg!F37+cop_add_B -> 70 | H37: =Seg!G37+cop_add_B -> 90 | I37: =Seg!H37+cop_add_B*cop_tail -> 100 | J37: =Seg!I37+cop_add_B*cop_tail -> 110 | K37: =Seg!J37+cop_add_B*cop_tail -> 120 | L37: FY2027–FY2029 每年淨增 cop_add；FY2030 起 × cop_tail
A38: Copilot（命題子列：平均座席 × 月費 × 12） | B38: US$B | D38: =(Seg!C37+Seg!D37)/2*cop_px*12/1000 -> 0.9 | E38: =(Seg!D37+Seg!E37)/2*cop_px*12/1000 -> 5.25 | F38: =(Seg!E37+Seg!F37)/2*cop_px*12/1000 -> 12 | G38: =(Seg!F37+Seg!G37)/2*cop_px*12/1000 -> 18 | H38: =(Seg!G37+Seg!H37)/2*cop_px*12/1000 -> 24 | I38: =(Seg!H37+Seg!I37)/2*cop_px*12/1000 -> 28.5 | J38: =(Seg!I37+Seg!J37)/2*cop_px*12/1000 -> 31.5 | K38: =(Seg!J37+Seg!K37)/2*cop_px*12/1000 -> 34.5 | L38: 實績期用基準月費（拆分是估計）；敏感度只改預測期
A39: M365 基礎（不含 Copilot；FY2025–26＝實績 − Copilot 估計） | B39: US$B | D39: =Q!L7-Seg!D38 -> 83.705 | E39: =Q!M7-Seg!E38 -> 95.049 | F39: =Seg!E39*(1+Seg!F40) -> 106.89239 | G39: =Seg!F39*(1+Seg!G40) -> 119.04417 | H39: =Seg!G39*(1+Seg!H40) -> 131.27736 | I39: =Seg!H39*(1+Seg!I40) -> 143.33403 | J39: =Seg!I39*(1+Seg!J40) -> 154.9327 | K39: =Seg!J39*(1+Seg!K40) -> 165.77799
A40: 年增（近一年 → 長期值） | B40: % | E40: =Seg!E39/Seg!D39-1 -> 0.13552356 | F40: =Seg!$E$40+(glt_m365b-Seg!$E$40)*MIN(1,(Thesis!F55-base_fy)/n_conv) -> 0.12460297 | G40: =Seg!$E$40+(glt_m365b-Seg!$E$40)*MIN(1,(Thesis!G55-base_fy)/n_conv) -> 0.11368238 | H40: =Seg!$E$40+(glt_m365b-Seg!$E$40)*MIN(1,(Thesis!H55-base_fy)/n_conv) -> 0.10276178 | I40: =Seg!$E$40+(glt_m365b-Seg!$E$40)*MIN(1,(Thesis!I55-base_fy)/n_conv) -> 0.091841188 | J40: =Seg!$E$40+(glt_m365b-Seg!$E$40)*MIN(1,(Thesis!J55-base_fy)/n_conv) -> 0.080920594 | K40: =Seg!$E$40+(glt_m365b-Seg!$E$40)*MIN(1,(Thesis!K55-base_fy)/n_conv) -> 0.07
A41: Microsoft 365 cloud | B41: US$B | D41: =Seg!D39+Seg!D38 -> 84.605 | E41: =Seg!E39+Seg!E38 -> 100.299 | F41: =Seg!F39+Seg!F38 -> 118.89239 | G41: =Seg!G39+Seg!G38 -> 137.04417 | H41: =Seg!H39+Seg!H38 -> 155.27736 | I41: =Seg!I39+Seg!I38 -> 171.83403 | J41: =Seg!J39+Seg!J38 -> 186.4327 | K41: =Seg!K39+Seg!K38 -> 200.27799
...

Sheet PL
A1: PL — 分部營收 → 分部營業利益（Agents and Infra 由核心利益率扣 AI 營運成本與 AI 折舊；Devices and Consumer 依實績利益率）→ 合併營業利益 → 業外 → 稅 → 淨利 → EPS
A2: 核對列（三情境、全部年度合計，應為 0；segments.json 與 tools/segment_check 讀這三列）
