Workbook

Sheet README
A1: NAND 市場層 v0.1（AI 半導體 Project；樣板 markets/memory） 2026-10-25
A2: 命題：NAND 營收由 AI 推論帶動的企業級 SSD 位元需求與合約價循環決定；2026–27 供給受限、價格在高檔，2028 起各情境依加速器顆數係數與價格路徑分歧。
A4: 驅動因子 → 推導量
A5: Mkt A 區｜加速器顆數（markets/memory UNITS × 同字母 SCEN_UNITS）× 每顆企業級 SSD 容量 → AI 企業級 SSD 需求；非 AI 企業級 SSD、手機、PC、消費性以 2025 基期 × 年增 → 位元需求合計
A6: Mkt A 區｜全產業位元供給（2025 基期 ×（1＋美光指引年增），三情境相同）；出貨＝MIN(需求, 供給)
A7: Mkt B 區｜季價指數（markets/memory NAND 路徑，同字母；2030 收斂法）× 季度位元 → 以 2Q26 實績為錨的季度市場營收；份額（2026Q3 由 Kioxia、SanDisk 公司指引推得）→ 各廠營收與位元
A8: Ann｜年度摘要：需求、供給、出貨、平均售價、營收、各廠份額；Kioxia＋SanDisk 合資群份額＝兩家相加（下游公司模型讀同一組列）
A10: 情境：A＝順利、B＝平平、C＝不如預期；價格讀 markets/memory NAND_S 同字母，顆數讀 SCEN_UNITS 同字母（2028–29；CY2030 沿用 2029），不自訂行業路徑。CY2030 價格為收斂法（十年平均年變動 p10，三情境相同）。
A11: 單位：$B、EB、$/GB、百萬顆。2026Q2 以前為 TrendForce 實績；季度位元為年度依年增平滑（近似）。
A12: 已知限制：全產業 EB 基期與各應用占比為 Assumed（只影響 AI 與非 AI 需求的相對大小與 EB 絕對值）；各廠晶圓產能未找到（Sup 頁）；各廠平均售價假設等於市場平均。
A14: v0.3（2026-10-31）：季價指數的口徑改為「實現平均售價」。Siliconomics v0.10：2026Q3 +25%（Kioxia、SK 海力士實績 mid-20%；原合約價 +15%）、2026Q4 +8.1%（兩季累計 1.15 × 1.175 不變；原 +17.5%）；2027 起價格水準不變。SanDisk、Kioxia 的 2026Q3 份額因此由 11.6%／15.8% 降為 10.7%／14.5%。另：兩家 2026Q4 起的份額改為「2026Q3 實績份額與 2026Q4 公司指引份額的平均」（新增輸入 sd_g4、kx_g4、kx_fxg4；三星、SK 海力士、美光本來就用 1H26 兩季平均），以平滑 Kioxia 公司揭露的出貨季別移動：Kioxia 13.9%、SanDisk 10.65%；其他廠（餘額）13.4%。2026Q4 對公司指引：SanDisk +0.4%（原 +9.6%）、Kioxia（美元、TrendForce 口徑）+4.8%（原 +19.2%；日圓口徑另含匯率假設 160 對 157 的 +1.9%；見 Recon）。

Sheet In
A1: In — NAND 市場層輸入（藍字；基準 E 欄，低 D、高 F）。金額：十億美元（$B）；位元：EB（10^18 位元組）；顆數：百萬顆。每個輸入附標記與來源；找不到者寫「未找到」
A2: 標記：Verified／Interested-party（寫明是誰）／Analogy／Assumed（給低／高區間）／Derived（寫明換算）。價格路徑、加速器顆數、情境顆數係數取自 markets/memory/market.py（單一來源，本頁只抄錄並標示來源；改 markets/memory 後重建本檔）。SemiAnalysis 未使用
A3: 鍵 | B3: 項目 | C3: 單位 | D3: 低 | E3: 基準 | F3: 高 | G3: 標記 | H3: 來源1 | I3: 來源2／說明
A4: N1. NAND 合約價季增（共用市場層 markets/memory；情境 A／B／C 同字母）
A5: nq_1 | B5: NAND 合約價季增 2025Q2 | C5: % | E5: 0 | G5: Interested-party | H5: markets/memory/market.py NAND_COMMON[0] | I5: TrendForce：1Q26 +85~90%、2Q26 +70~75%、3Q26 +10~15%（MS 實際約 +20%）、4Q26 +15~20%；2025Q2–Q4 為 Assumed
A6: nq_2 | B6: NAND 合約價季增 2025Q3 | C6: % | E6: 0.05 | G6: Interested-party | H6: markets/memory/market.py NAND_COMMON[1] | I6: 同上
A7: nq_3 | B7: NAND 合約價季增 2025Q4 | C7: % | E7: 0.3 | G7: Interested-party | H7: markets/memory/market.py NAND_COMMON[2] | I7: 同上
A8: nq_4 | B8: NAND 合約價季增 2026Q1 | C8: % | E8: 0.875 | G8: Interested-party | H8: markets/memory/market.py NAND_COMMON[3] | I8: 同上
A9: nq_5 | B9: NAND 合約價季增 2026Q2 | C9: % | E9: 0.725 | G9: Interested-party | H9: markets/memory/market.py NAND_COMMON[4] | I9: 同上
A10: nq_6 | B10: NAND 合約價季增 2026Q3 | C10: % | E10: 0.25 | G10: Interested-party | H10: markets/memory/market.py NAND_COMMON[5] | I10: 同上
A11: nq_7 | B11: NAND 合約價季增 2026Q4 | C11: % | E11: 0.081 | G11: Interested-party | H11: markets/memory/market.py NAND_COMMON[6] | I11: 同上
A12: nqA_8 | B12: NAND 合約價季增 2027Q1（A） | C12: % | E12: 0.03 | G12: Interested-party | H12: markets/memory/market.py NAND_S['A'][0] | I12: 本庫情境路徑，依據：TrendForce：2027 下半年供需平衡、價格面臨下修壓力（2026-10-28 來源複核：來源無逐季數字，逐季值為本庫拆分）
A13: nqA_9 | B13: NAND 合約價季增 2027Q2（A） | C13: % | E13: 0 | G13: Interested-party | H13: markets/memory/market.py NAND_S['A'][1] | I13: 同上
A14: nqA_10 | B14: NAND 合約價季增 2027Q3（A） | C14: % | E14: -0.05 | G14: Interested-party | H14: markets/memory/market.py NAND_S['A'][2] | I14: 同上
A15: nqA_11 | B15: NAND 合約價季增 2027Q4（A） | C15: % | E15: -0.07 | G15: Interested-party | H15: markets/memory/market.py NAND_S['A'][3] | I15: 同上
A16: nqA_12 | B16: NAND 合約價季增 2028Q1（A） | C16: % | E16: -0.05 | G16: Interested-party | H16: markets/memory/market.py NAND_S['A'][4] | I16: 同上
... A47: nqC_19 | B47: NAND 合約價季增 2029Q4（C） | C47: % | E47: 0.1 | G47: Assumed | H47: markets/memory/market.py NAND_S['C'][11] | I47: 同上
A48: p10 | B48: CY2030 NAND 平均售價年變動（收斂法：十年平均；三情境相同） | C48: % | D48: -0.2 | E48: -0.12 | F48: -0.05 | G48: Analogy | H48: 上游 markets/memory 季價只到 2029Q4。收斂法：CY2030 起價格回到長期趨勢＝過去十年 NAND 每 GB 售價的年均變動；可驗證的 2016–2025 年 $/GB 序列未找到，取每位元成本年降 15–20% 減去循環中段的溢價（Analogy：製程每代密度提升、價格長期跟隨成本） | I48: 2030 各季季增＝(1＋p10)^(1/4)−1，自 2029Q4 起算；低 −20%、高 −5%（Sens 列）
A49: N2. 加速器顆數（markets/memory UNITS 合計；2028–29 情境係數 SCEN_UNITS，同字母）
A50: u_26 | B50: 加速器顆數合計 2026（情境 A 基準） | C50: 百萬顆 | E50: 15.2 | G50: Derived | H50: markets/memory/market.py UNITS 各列 2026 合計（NVIDIA、AMD、TPU、Trainium、其他 ASIC） | I50: 與 HBM 需求、台積電 CoWoS、Advantest 同一套顆數
A51: u_27 | B51: 加速器顆數合計 2027（情境 A 基準） | C51: 百萬顆 | E51: 23.7 | G51: Derived | H51: markets/memory/market.py UNITS 各列 2027 合計（NVIDIA、AMD、TPU、Trainium、其他 ASIC） | I51: 同上
A52: u_28 | B52: 加速器顆數合計 2028（情境 A 基準） | C52: 百萬顆 | E52: 26.5 | G52: Derived | H52: markets/memory/market.py UNITS 各列 2028 合計（NVIDIA、AMD、TPU、Trainium、其他 ASIC） | I52: 同上
A53: um28_A | B53: 情境 A：2028 顆數 ÷ 基準 | C53: x | E53: 1 | G53: Derived | H53: markets/memory/market.py SCEN_UNITS['A'][0] | I53: A＝1.0；B、C 為 Assumed（markets/memory）；CY2030 沿用 2029 係數
A54: um29_A | B54: 情境 A：2029 顆數 ÷ 基準 | C54: x | E54: 1 | G54: Derived | H54: markets/memory/market.py SCEN_UNITS['A'][1] | I54: 同上
A55: um28_B | B55: 情境 B：2028 顆數 ÷ 基準 | C55: x | E55: 0.8 | G55: Derived | H55: markets/memory/market.py SCEN_UNITS['B'][0] | I55: 同上
A56: um29_B | B56: 情境 B：2029 顆數 ÷ 基準 | C56: x | E56: 0.85 | G56: Derived | H56: markets/memory/market.py SCEN_UNITS['B'][1] | I56: 同上
A57: um28_C | B57: 情境 C：2028 顆數 ÷ 基準 | C57: x | E57: 0.6 | G57: Derived | H57: markets/memory/market.py SCEN_UNITS['C'][0] | I57: 同上
A58: um29_C | B58: 情境 C：2029 顆數 ÷ 基準 | C58: x | E58: 0.6 | G58: Derived | H58: markets/memory/market.py SCEN_UNITS['C'][1] | I58: 同上
A59: g_u29 | B59: 2029 加速器顆數年增（情境 A 基準；B、C 再乘 um29） | C59: % | D59: 0 | E59: 0.13773585 | F59: 0.25 | G59: Derived | H59: Siliconomics SIF_UnitsGrowth29：平台別 2029 成長率（M5 節）加權，與台積電、網通模型同一路徑（v0.2 起；原 Assumed 10%）；低／高沿用原區間供敏感度 | I59: 三情境同一基準，情境差異只來自 um29（不自訂行業路徑）
A60: g_u30 | B60: 2030 加速器顆數年增（情境 A 基準；B、C 再乘 um29） | C60: % | D60: -0.05 | E60: 0.05 | F60: 0.15 | G60: Assumed | H60: 上游只到 2029；收斂到低個位數成長 | I60: 同上
A61: tb_26 | B61: 每顆加速器帶動的企業級 SSD 容量 2026 | C61: TB／顆 | D61: 24 | E61: 30 | F61: 36 | G61: Assumed | H61: AI 推論的 KV 快取卸載、RAG 向量庫、檢查點與資料湖（伺服器內建＋外接儲存）。2026 值使 2026 企業級 SSD 約占位元需求四成（TrendForce 2026-07：伺服器約 40%；Counterpoint 2Q26：企業級 SSD 占出貨位元 48%） | I61: 低／高 ±20%（Sens 列）；三情境相同（情境差異來自顆數）
A62: tb_27 | B62: 每顆加速器帶動的企業級 SSD 容量 2027 | C62: TB／顆 | D62: 27 | E62: 34 | F62: 41 | G62: Assumed | H62: 每年約 +13–18%：單顆加速器記憶體與脈絡長度增加（Assumed） | I62: 低／高 ±20%（Sens 列）；三情境相同（情境差異來自顆數）
A63: tb_28 | B63: 每顆加速器帶動的企業級 SSD 容量 2028 | C63: TB／顆 | D63: 32 | E63: 40 | F63: 48 | G63: Assumed | H63: 每年約 +13–18%：單顆加速器記憶體與脈絡長度增加（Assumed） | I63: 低／高 ±20%（Sens 列）；三情境相同（情境差異來自顆數）
A64: tb_29 | B64: 每顆加速器帶動的企業級 SSD 容量 2029 | C64: TB／顆 | D64: 37 | E64: 46 | F64: 55 | G64: Assumed | H64: 每年約 +13–18%：單顆加速器記憶體與脈絡長度增加（Assumed） | I64: 低／高 ±20%（Sens 列）；三情境相同（情境差異來自顆數）
A65: tb_30 | B65: 每顆加速器帶動的企業級 SSD 容量 2030 | C65: TB／顆 | D65: 42 | E65: 52 | F65: 62 | G65: Assumed | H65: 每年約 +13–18%：單顆加速器記憶體與脈絡長度增加（Assumed） | I65: 低／高 ±20%（Sens 列）；三情境相同（情境差異來自顆數）
A66: N3. 位元需求（2025 基期與各應用年增；非 AI 應用三情境相同）
A67: bits25 | B67: 2025 NAND 位元出貨（全產業） | C67: EB | D67: 850 | E67: 1000 | F67: 1150 | G67: Assumed | H67: 全產業 EB 的公開數字未找到（TrendForce、Yole 付費）；以 2025 營收約 $72B ÷ 合約均價約 $0.07／GB 粗估約 1 ZB | I67: 只影響 EB 與 $/GB 的絕對值，以及 AI 需求（顆數 × 容量，絕對量）與其他應用（比例 × 基期）的相對大小；營收以 2Q26 實績為錨，不受基期水準影響
A68: g25 | B68: 2025 位元出貨年增（推 2024 位元） | C68: % | D68: 0.08 | E68: 0.12 | F68: 0.16 | G68: Assumed | H68: 2025 上半庫存去化、下半價漲；全年位元成長公開數字未找到 | I68: 只用於 CY2024 欄
A69: sh_essd25 | B69: 2025 企業級 SSD 占位元需求 | C69: % | D69: 0.26 | E69: 0.3 | F69: 0.34 | G69: Interested-party | H69: Counterpoint 2Q25 企業級 SSD 占 NAND 出貨位元 26%、2Q26 48%（capitalandcompute 2026-08 轉載 Counterpoint Q2 2026 Memory & Storage Tracker） | I69: 全年平均取 30%（下半年 AI 伺服器拉貨，Derived／Assumed）
A70: ai25 | B70: 2025 企業級 SSD 中 AI 伺服器的比例 | C70: % | D70: 0.45 | E70: 0.55 | F70: 0.65 | G70: Assumed | H70: 未找到；AI 伺服器（加速器）帶動的企業級 SSD 約過半 | I70: 2026 起 AI 部分改由顆數 × 每顆容量推導
...

Sheet Ann
A1: Ann — NAND 市場年度摘要（三情境；引用 Mkt 頁）。CY2024–2025 為實績（位元為 Assumed 基期）；CY2026 含 1H26 實績；CY2030 價格為收斂法（灰底）
A3: 情境／項目 | B3: 單位 | C3: CY2024 | D3: CY2025 | E3: CY2026 | F3: CY2027 | G3: CY2028 | H3: CY2029 | I3: CY2030 | J3: 說明
A4: 情境 A（順利）
A5: 加速器顆數 | B5: 百萬顆 | E5: =Mkt!E6 -> 15.2 | F5: =Mkt!F6 -> 23.7 | G5: =Mkt!G6 -> 26.5 | H5: =Mkt!H6 -> 30.15 | I5: =Mkt!I6 -> 31.6575
A6: 需求：AI 企業級 SSD | B6: EB | D6: =Mkt!D8 -> 165 | E6: =Mkt!E8 -> 456 | F6: =Mkt!F8 -> 805.8 | G6: =Mkt!G8 -> 1060 | H6: =Mkt!H8 -> 1386.9 | I6: =Mkt!I8 -> 1646.19
A7: 需求：非 AI 企業級 SSD | B7: EB | D7: =Mkt!D9 -> 135 | E7: =Mkt!E9 -> 148.5 | F7: =Mkt!F9 -> 163.35 | G7: =Mkt!G9 -> 179.685 | H7: =Mkt!H9 -> 197.6535 | I7: =Mkt!I9 -> 217.41885
A8: 需求：手機 | B8: EB | D8: =Mkt!D10 -> 320 | E8: =Mkt!E10 -> 304 | F8: =Mkt!F10 -> 313.12 | G8: =Mkt!G10 -> 338.1696 | H8: =Mkt!H10 -> 365.22317 | I8: =Mkt!I10 -> 394.44102
A9: 需求：PC | B9: EB | D9: =Mkt!D11 -> 230 | E9: =Mkt!E11 -> 218.5 | F9: =Mkt!F11 -> 218.5 | G9: =Mkt!G11 -> 231.61 | H9: =Mkt!H11 -> 245.5066 | I9: =Mkt!I11 -> 260.237
A10: 需求：消費性與其他 | B10: EB | D10: =Mkt!D12 -> 150 | E10: =Mkt!E12 -> 135 | F10: =Mkt!F12 -> 135 | G10: =Mkt!G12 -> 141.75 | H10: =Mkt!H12 -> 148.8375 | I10: =Mkt!I12 -> 156.27937
A11: 位元需求合計 | B11: EB | D11: =Mkt!D13 -> 1000 | E11: =Mkt!E13 -> 1262 | F11: =Mkt!F13 -> 1635.77 | G11: =Mkt!G13 -> 1951.2146 | H11: =Mkt!H13 -> 2344.1208 | I11: =Mkt!I13 -> 2674.5662
A12: 企業級 SSD 占需求 | B12: % | D12: =Mkt!D14 -> 0.3 | E12: =Mkt!E14 -> 0.47900158 | F12: =Mkt!F14 -> 0.59247327 | G12: =Mkt!G14 -> 0.63534016 | H12: =Mkt!H14 -> 0.67596923 | I12: =Mkt!I14 -> 0.69678919
A13: 位元供給 | B13: EB | D13: =Mkt!D15 -> 1000 | E13: =Mkt!E15 -> 1210 | F13: =Mkt!F15 -> 1512.5 | G13: =Mkt!G15 -> 1890.625 | H13: =Mkt!H15 -> 2306.5625 | I13: =Mkt!I15 -> 2767.875
A14: 需求 ÷ 供給 − 1 | B14: % | E14: =Mkt!E16 -> 0.042975207 | F14: =Mkt!F16 -> 0.081500826 | G14: =Mkt!G16 -> 0.032047392 | H14: =Mkt!H16 -> 0.016283221 | I14: =Mkt!I16 -> -0.033711334
A15: 位元出貨 | B15: EB | C15: =Mkt!C17 -> 892.85714 | D15: =Mkt!D17 -> 1000 | E15: =Mkt!E17 -> 1210 | F15: =Mkt!F17 -> 1512.5 | G15: =Mkt!G17 -> 1890.625 | H15: =Mkt!H17 -> 2306.5625 | I15: =Mkt!I17 -> 2674.5662
A16: 位元出貨年增 | B16: % | D16: =Mkt!D18 -> 0.12 | E16: =Mkt!E18 -> 0.21 | F16: =Mkt!F18 -> 0.25 | G16: =Mkt!G18 -> 0.25 | H16: =Mkt!H18 -> 0.22 | I16: =Mkt!I18 -> 0.1595464
A17: 平均售價 | B17: $/GB | C17: =Mkt!C21 -> 0.075488 | D17: =Mkt!D21 -> 0.071103592 | E17: =Mkt!E21 -> 0.28332293 | F17: =Mkt!F21 -> 0.3548659 | G17: =Mkt!G21 -> 0.28805826 | H17: =Mkt!H21 -> 0.2473227 | I17: =Mkt!I21 -> 0.21823704
A18: 平均售價年變動 | B18: % | D18: =Mkt!D22 -> -0.058080856 | E18: =Mkt!E22 -> 2.9846501 | F18: =Mkt!F22 -> 0.25251387 | G18: =Mkt!G22 -> -0.18826165 | H18: =Mkt!H22 -> -0.1414143 | I18: =Mkt!I22 -> -0.11760206
A19: NAND 市場營收 | B19: $B | C19: =Mkt!C19 -> 67.4 | D19: =Mkt!D19 -> 71.103592 | E19: =Mkt!E19 -> 342.82075 | F19: =Mkt!F19 -> 536.73468 | G19: =Mkt!G19 -> 544.61015 | H19: =Mkt!H19 -> 570.46528 | I19: =Mkt!I19 -> 583.68943 | J19: CY2026–28 三情境營收與位元成長見 README
A20: 市場營收年增 | B20: % | D20: =Mkt!D20 -> 0.054949442 | E20: =Mkt!E20 -> 3.8214266 | F20: =Mkt!F20 -> 0.56564233 | G20: =Mkt!G20 -> 0.014672931 | H20: =Mkt!H20 -> 0.04747456 | I20: =Mkt!I20 -> 0.023181352
A21: 份額：三星 | B21: % | D21: =Mkt!D23 -> 0.30940771 | E21: =Mkt!E23 -> 0.29814637 | F21: =Mkt!F23 -> 0.29314637 | G21: =Mkt!G23 -> 0.28814637 | H21: =Mkt!H23 -> 0.28314637 | I21: =Mkt!I23 -> 0.27814637
A22: 份額：SK 海力士＋Solidigm | B22: % | D22: =Mkt!D24 -> 0.20069309 | E22: =Mkt!E24 -> 0.17773013 | F22: =Mkt!F24 -> 0.17773013 | G22: =Mkt!G24 -> 0.17773013 | H22: =Mkt!H24 -> 0.17773013 | I22: =Mkt!I24 -> 0.17773013
A23: 份額：美光 | B23: % | D23: =Mkt!D25 -> 0.134733 | E23: =Mkt!E25 -> 0.1451191 | F23: =Mkt!F25 -> 0.1471191 | G23: =Mkt!G25 -> 0.1491191 | H23: =Mkt!H25 -> 0.1511191 | I23: =Mkt!I25 -> 0.1531191
A24: 份額：Kioxia | B24: % | D24: =Mkt!D26 -> 0.14359331 | E24: =Mkt!E26 -> 0.13953322 | F24: =Mkt!F26 -> 0.13851299 | G24: =Mkt!G26 -> 0.13851299 | H24: =Mkt!H26 -> 0.13851299 | I24: =Mkt!I26 -> 0.13851299
A25: 份額：SanDisk | B25: % | D25: =Mkt!D27 -> 0.1255914 | E25: =Mkt!E27 -> 0.11206254 | F25: =Mkt!F27 -> 0.10651367 | G25: =Mkt!G27 -> 0.10651367 | H25: =Mkt!H27 -> 0.10651367 | I25: =Mkt!I27 -> 0.10651367
A26: 份額：其他（長江存儲等） | B26: % | D26: =Mkt!D28 -> 0.085981484 | E26: =Mkt!E28 -> 0.12740864 | F26: =Mkt!F28 -> 0.13697774 | G26: =Mkt!G28 -> 0.13997774 | H26: =Mkt!H28 -> 0.14297774 | I26: =Mkt!I28 -> 0.14597774
A27: Kioxia＋SanDisk（合資群）份額 | B27: % | D27: =D24+D25 -> 0.26918471 | E27: =E24+E25 -> 0.25159576 | F27: =F24+F25 -> 0.24502666 | G27: =G24+g25 -> 0.25851299 | H27: =H24+H25 -> 0.24502666 | I27: =I24+I25 -> 0.24502666
A28: Kioxia 營收（年） | B28: $B | D28: =SUM(Mkt!C43:F43) -> 10.21 | E28: =SUM(Mkt!G43:J43) -> 47.834882 | F28: =SUM(Mkt!K43:N43) -> 74.344724 | G28: =SUM(Mkt!O43:R43) -> 75.435579 | H28: =SUM(Mkt!S43:V43) -> 79.01685 | I28: =SUM(Mkt!W43:Z43) -> 80.848567
A29: SanDisk 營收（年） | B29: $B | D29: =SUM(Mkt!C44:F44) -> 8.93 | E29: =SUM(Mkt!G44:J44) -> 38.417364 | F29: =SUM(Mkt!K44:N44) -> 57.169581 | G29: =SUM(Mkt!O44:R44) -> 58.008426 | H29: =SUM(Mkt!S44:V44) -> 60.76235 | I29: =SUM(Mkt!W44:Z44) -> 62.170904
A31: 情境 B（平平）
A32: 加速器顆數 | B32: 百萬顆 | E32: =Mkt!E54 -> 15.2 | F32: =Mkt!F54 -> 23.7 | G32: =Mkt!G54 -> 21.2 | H32: =Mkt!H54 -> 25.6275 | I32: =Mkt!I54 -> 26.908875
A33: 需求：AI 企業級 SSD | B33: EB | D33: =Mkt!D56 -> 165 | E33: =Mkt!E56 -> 456 | F33: =Mkt!F56 -> 805.8 | G33: =Mkt!G56 -> 848 | H33: =Mkt!H56 -> 1178.865 | I33: =Mkt!I56 -> 1399.2615
A34: 需求：非 AI 企業級 SSD | B34: EB | D34: =Mkt!D57 -> 135 | E34: =Mkt!E57 -> 148.5 | F34: =Mkt!F57 -> 163.35 | G34: =Mkt!G57 -> 179.685 | H34: =Mkt!H57 -> 197.6535 | I34: =Mkt!I57 -> 217.41885
A35: 需求：手機 | B35: EB | D35: =Mkt!D58 -> 320 | E35: =Mkt!E58 -> 304 | F35: =Mkt!F58 -> 313.12 | G35: =Mkt!G58 -> 338.1696 | H35: =Mkt!H58 -> 365.22317 | I35: =Mkt!I58 -> 394.44102
A36: 需求：PC | B36: EB | D36: =Mkt!D59 -> 230 | E36: =Mkt!E59 -> 218.5 | F36: =Mkt!F59 -> 218.5 | G36: =Mkt!G59 -> 231.61 | H36: =Mkt!H59 -> 245.5066 | I36: =Mkt!I59 -> 260.237
A37: 需求：消費性與其他 | B37: EB | D37: =Mkt!D60 -> 150 | E37: =Mkt!E60 -> 135 | F37: =Mkt!F60 -> 135 | G37: =Mkt!G60 -> 141.75 | H37: =Mkt!H60 -> 148.8375 | I37: =Mkt!I60 -> 156.27937
A38: 位元需求合計 | B38: EB | D38: =Mkt!D61 -> 1000 | E38: =Mkt!E61 -> 1262 | F38: =Mkt!F61 -> 1635.77 | G38: =Mkt!G61 -> 1739.2146 | H38: =Mkt!H61 -> 2136.0858 | I38: =Mkt!I61 -> 2427.6377
A39: 企業級 SSD 占需求 | B39: % | D39: =Mkt!D62 -> 0.3 | E39: =Mkt!E62 -> 0.47900158 | F39: =Mkt!F62 -> 0.59247327 | G39: =Mkt!G62 -> 0.59089028 | H39: =Mkt!H62 -> 0.64441162 | I39: =Mkt!I62 -> 0.66594794
A40: 位元供給 | B40: EB | D40: =Mkt!D63 -> 1000 | E40: =Mkt!E63 -> 1210 | F40: =Mkt!F63 -> 1512.5 | G40: =Mkt!G63 -> 1890.625 | H40: =Mkt!H63 -> 2306.5625 | I40: =Mkt!I63 -> 2767.875
A41: 需求 ÷ 供給 − 1 | B41: % | E41: =Mkt!E64 -> 0.042975207 | F41: =Mkt!F64 -> 0.081500826 | G41: =Mkt!G64 -> -0.08008484 | H41: =Mkt!H64 -> -0.073909435 | I41: =Mkt!I64 -> -0.12292364
A42: 位元出貨 | B42: EB | C42: =Mkt!C65 -> 892.85714 | D42: =Mkt!D65 -> 1000 | E42: =Mkt!E65 -> 1210 | F42: =Mkt!F65 -> 1512.5 | G42: =Mkt!G65 -> 1739.2146 | H42: =Mkt!H65 -> 2136.0858 | I42: =Mkt!I65 -> 2427.6377
...

Sheet Path
A1: Path — NAND 合約價指數（2025Q1＝1）。2025Q2–2029Q4 季增取自 markets/memory（In 頁 N1）；2030 各季＝(1＋p10)^(1/4)（收斂法，灰底）
A3: 情境 | B3: 說明 | C3: 2025Q1 | D3: 2025Q2 | E3: 2025Q3 | F3: 2025Q4 | G3: 2026Q1 | H3: 2026Q2 | I3: 2026Q3 | J3: 2026Q4 | K3: 2027Q1 | L3: 2027Q2 | M3: 2027Q3 | N3: 2027Q4 | O3: 2028Q1 | P3: 2028Q2 | Q3: 2028Q3 | R3: 2028Q4 | S3: 2029Q1 | T3: 2029Q2 | U3: 2029Q3 | V3: 2029Q4 | W3: 2030Q1 | X3: 2030Q2 | Y3: 2030Q3 | Z3: 2030Q4
A4: A | B4: 情境 A（順利） | C4: 1 | D4: =C4*(1+nq_1) -> 1 | E4: =D4*(1+nq_2) -> 1.05 | F4: =E4*(1+nq_3) -> 1.365 | G4: =F4*(1+nq_4) -> 2.559375 | H4: =G4*(1+nq_5) -> 4.4149219 | I4: =H4*(1+nq_6) -> 5.5186523 | J4: =I4*(1+nq_7) -> 5.9656632 | K4: =J4*(1+nqA_8) -> 6.1446331 | L4: =K4*(1+nqA_9) -> 6.1446331 | M4: =L4*(1+nqA_10) -> 5.8374014 | N4: =M4*(1+nqA_11) -> 5.4287833 | O4: =N4*(1+nqA_12) -> 5.1573442 | P4: =O4*(1+nqA_13) -> 4.899477 | Q4: =P4*(1+nqA_14) -> 4.6545031 | R4: =Q4*(1+nqA_15) -> 4.4217779 | S4: =R4*(1+nqA_16) -> 4.2891246 | T4: =S4*(1+nqA_17) -> 4.1604509 | U4: =T4*(1+nqA_18) -> 4.0356373 | V4: =U4*(1+nqA_19) -> 3.9145682 | W4: =V4*(1+((1+p10)^(1/4)-1)) -> 3.791443 | X4: =W4*(1+((1+p10)^(1/4)-1)) -> 3.6721905 | Y4: =X4*(1+((1+p10)^(1/4)-1)) -> 3.5566888 | Z4: =Y4*(1+((1+p10)^(1/4)-1)) -> 3.44482
A5: B | B5: 情境 B（平平） | C5: 1 | D5: =C5*(1+nq_1) -> 1 | E5: =D5*(1+nq_2) -> 1.05 | F5: =E5*(1+nq_3) -> 1.365 | G5: =F5*(1+nq_4) -> 2.559375 | H5: =G5*(1+nq_5) -> 4.4149219 | I5: =H5*(1+nq_6) -> 5.5186523 | J5: =I5*(1+nq_7) -> 5.9656632 | K5: =J5*(1+nqB_8) -> 6.2639463 | L5: =K5*(1+nqB_9) -> 6.3892253 | M5: =L5*(1+nqB_10) -> 5.7503027 | N5: =M5*(1+nqB_11) -> 4.6002422 | O5: =N5*(1+nqB_12) -> 3.2201695 | P5: =O5*(1+nqB_13) -> 2.4151272 | Q5: =P5*(1+nqB_14) -> 1.9321017 | R5: =Q5*(1+nqB_15) -> 1.7388915 | S5: =R5*(1+nqB_16) -> 1.8258361 | T5: =S5*(1+nqB_17) -> 1.9171279 | U5: =T5*(1+nqB_18) -> 1.9746418 | V5: =U5*(1+nqB_19) -> 2.033881 | W5: =V5*(1+((1+p10)^(1/4)-1)) -> 1.9699092 | X5: =W5*(1+((1+p10)^(1/4)-1)) -> 1.9079495 | Y5: =X5*(1+((1+p10)^(1/4)-1)) -> 1.8479386 | Z5: =Y5*(1+((1+p10)^(1/4)-1)) -> 1.7898153
A6: C | B6: 情境 C（不如預期） | C6: 1 | D6: =C6*(1+nq_1) -> 1 | E6: =D6*(1+nq_2) -> 1.05 | F6: =E6*(1+nq_3) -> 1.365 | G6: =F6*(1+nq_4) -> 2.559375 | H6: =G6*(1+nq_5) -> 4.4149219 | I6: =H6*(1+nq_6) -> 5.5186523 | J6: =I6*(1+nq_7) -> 5.9656632 | K6: =J6*(1+nqC_8) -> 6.2639463 | L6: =K6*(1+nqC_9) -> 6.3892253 | M6: =L6*(1+nqC_10) -> 5.7503027 | N6: =M6*(1+nqC_11) -> 4.6002422 | O6: =N6*(1+nqC_12) -> 2.9901574 | P6: =O6*(1+nqC_13) -> 1.9436023 | Q6: =P6*(1+nqC_14) -> 1.4577017 | R6: =Q6*(1+nqC_15) -> 1.1661614 | S6: =R6*(1+nqC_16) -> 1.1661614 | T6: =S6*(1+nqC_17) -> 1.2244695 | U6: =T6*(1+nqC_18) -> 1.322427 | V6: =U6*(1+nqC_19) -> 1.4546697 | W6: =V6*(1+((1+p10)^(1/4)-1)) -> 1.4089159 | X6: =W6*(1+((1+p10)^(1/4)-1)) -> 1.3646012 | Y6: =X6*(1+((1+p10)^(1/4)-1)) -> 1.3216803 | Z6: =Y6*(1+((1+p10)^(1/4)-1)) -> 1.2801094
A8: 年均指數
A9: 情境 | B9: 說明 | C9: CY2025 | D9: CY2026 | E9: CY2027 | F9: CY2028 | G9: CY2029 | H9: CY2030 | I9: CY2026÷CY2025 | J9: CY2027÷CY2026 | K9: CY2028÷CY2027 | L9: CY2029÷CY2028 | M9: CY2030÷CY2029
A10: A | B10: 四季平均 | C10: =AVERAGE(C4:F4) -> 1.10375 | D10: =AVERAGE(G4:J4) -> 4.6146531 | E10: =AVERAGE(K4:N4) -> 5.8888627 | F10: =AVERAGE(O4:R4) -> 4.7832755 | G10: =AVERAGE(S4:V4) -> 4.0999453 | H10: =AVERAGE(W4:Z4) -> 3.6162856 | I10: =D10/C10-1 -> 3.1808862 | J10: =E10/D10-1 -> 0.27612252 | K10: =F10/E10-1 -> -0.18774205 | L10: =G10/F10-1 -> -0.14285823 | M10: =H10/G10-1 -> -0.11796735
A11: B | B11: 四季平均 | C11: =AVERAGE(C5:F5) -> 1.10375 | D11: =AVERAGE(G5:J5) -> 4.6146531 | E11: =AVERAGE(K5:N5) -> 5.7509291 | F11: =AVERAGE(O5:R5) -> 2.3265725 | G11: =AVERAGE(S5:V5) -> 1.9378717 | H11: =AVERAGE(W5:Z5) -> 1.8789032 | I11: =D11/C11-1 -> 3.1808862 | J11: =E11/D11-1 -> 0.24623217 | K11: =F11/E11-1 -> -0.59544407 | L11: =G11/F11-1 -> -0.16707013 | M11: =H11/G11-1 -> -0.030429538
A12: C | B12: 四季平均 | C12: =AVERAGE(C6:F6) -> 1.10375 | D12: =AVERAGE(G6:J6) -> 4.6146531 | E12: =AVERAGE(K6:N6) -> 5.7509291 | F12: =AVERAGE(O6:R6) -> 1.8894057 | G12: =AVERAGE(S6:V6) -> 1.2919319 | H12: =AVERAGE(W6:Z6) -> 1.3438267 | I12: =D12/C12-1 -> 3.1808862 | J12: =E12/D12-1 -> 0.24623217 | K12: =F12/E12-1 -> -0.67146079 | L12: =G12/F12-1 -> -0.31622315 | M12: =H12/G12-1 -> 0.040168345

Sheet Mkt
A1: Mkt — NAND 市場（三情境各一個完整推導區塊；A 區年度、B 區季度）。需求＝AI 企業級 SSD（加速器顆數 × 每顆容量）＋非 AI；出貨＝MIN(需求, 供給)；營收＝2Q26 實績 × 價格指數比 × 位元比；份額 × 市場＝各廠營收
A2: 下游讀數列：「Kioxia 營收（情境 s）」「SanDisk 營收（情境 s）」「Kioxia 位元（…）」「SanDisk 位元（…）」（C..Z＝2025Q1..2030Q4）。灰底＝2030 收斂法
A4: 情境 A（順利）：價格路徑 A（2027–28 高檔持平、2029 緩降（BofA、TrendForce 型））；2028–29 顆數 × 1.0／1.0；合資群份額年變動 dr_jv_A
A5: A. 年度（日曆年） | B5: 單位 | C5: CY2024 | D5: CY2025 | E5: CY2026 | F5: CY2027 | G5: CY2028 | H5: CY2029 | I5: CY2030 | AB5: 說明
A6: 加速器顆數（同字母情境係數） | B6: 百萬顆 | E6: =(u_26)*1 -> 15.2 | F6: =(u_27)*1 -> 23.7 | G6: =(u_28)*um28_A -> 26.5 | H6: =(u_28*(1+g_u29))*um29_A -> 30.15 | I6: =(u_28*(1+g_u29)*(1+g_u30))*um29_A -> 31.6575 | AB6: markets/memory UNITS × SCEN_UNITS；2029–30 基準以 g_u29、g_u30 外推，CY2030 沿用 um29
A7: 每顆企業級 SSD 容量 | B7: TB | E7: =tb_26 -> 30 | F7: =tb_27 -> 34 | G7: =tb_28 -> 40 | H7: =tb_29 -> 46 | I7: =tb_30 -> 52
A8: 需求：AI 企業級 SSD | B8: EB | D8: =bits25*sh_essd25*ai25 -> 165 | E8: =E6*E7 -> 456 | F8: =F6*F7 -> 805.8 | G8: =G6*G7 -> 1060 | H8: =H6*H7 -> 1386.9 | I8: =I6*I7 -> 1646.19 | AB8: 顆數 × 每顆容量（百萬顆 × TB＝EB）；2025＝基期 × 占比
A9: 需求：非 AI 企業級 SSD | B9: EB | D9: =bits25*sh_essd25*(1-ai25) -> 135 | E9: =D9*(1+g_nai) -> 148.5 | F9: =E9*(1+g_nai) -> 163.35 | G9: =F9*(1+g_nai) -> 179.685 | H9: =G9*(1+g_nai) -> 197.6535 | I9: =H9*(1+g_nai) -> 217.41885
A10: 需求：手機 | B10: EB | D10: =bits25*sh_mob25 -> 320 | E10: =D10*(1+g_mob_26) -> 304 | F10: =E10*(1+g_mob_27) -> 313.12 | G10: =F10*(1+g_mob_28) -> 338.1696 | H10: =G10*(1+g_mob_28) -> 365.22317 | I10: =H10*(1+g_mob_28) -> 394.44102
A11: 需求：PC（client SSD） | B11: EB | D11: =bits25*sh_pc25 -> 230 | E11: =D11*(1+g_pc_26) -> 218.5 | F11: =E11*(1+g_pc_27) -> 218.5 | G11: =F11*(1+g_pc_28) -> 231.61 | H11: =G11*(1+g_pc_28) -> 245.5066 | I11: =H11*(1+g_pc_28) -> 260.237
A12: 需求：消費性與其他 | B12: EB | D12: =bits25*(1-sh_essd25-sh_mob25-sh_pc25) -> 150 | E12: =D12*(1+g_con_26) -> 135 | F12: =E12*(1+g_con_27) -> 135 | G12: =F12*(1+g_con_28) -> 141.75 | H12: =G12*(1+g_con_28) -> 148.8375 | I12: =H12*(1+g_con_28) -> 156.27937
A13: 位元需求合計 | B13: EB | D13: =SUM(D8:D12) -> 1000 | E13: =SUM(E8:E12) -> 1262 | F13: =SUM(F8:F12) -> 1635.77 | G13: =SUM(G8:G12) -> 1951.2146 | H13: =SUM(H8:H12) -> 2344.1208 | I13: =SUM(I8:I12) -> 2674.5662
A14: 企業級 SSD 占位元需求 | B14: % | D14: =(D8+D9)/D13 -> 0.3 | E14: =(E8+E9)/E13 -> 0.47900158 | F14: =(F8+F9)/F13 -> 0.59247327 | G14: =(G8+G9)/G13 -> 0.63534016 | H14: =(H8+H9)/H13 -> 0.67596923 | I14: =(I8+I9)/I13 -> 0.69678919
A15: 位元供給（三情境相同） | B15: EB | D15: =bits25 -> 1000 | E15: =D15*(1+gs_26) -> 1210 | F15: =E15*(1+gs_27) -> 1512.5 | G15: =F15*(1+gs_28) -> 1890.625 | H15: =G15*(1+gs_29) -> 2306.5625 | I15: =H15*(1+gs_30) -> 2767.875 | AB15: 2025＝出貨實績（基期）；供給不隨需求情境變（產能 2027 前已訂定），需求不足的結果是閒置產能與降價
A16: 需求 ÷ 供給 − 1（>0＝短缺） | B16: % | E16: =E13/E15-1 -> 0.042975207 | F16: =F13/F15-1 -> 0.081500826 | G16: =G13/G15-1 -> 0.032047392 | H16: =H13/H15-1 -> 0.016283221 | I16: =I13/I15-1 -> -0.033711334
A17: 位元出貨＝MIN(需求, 供給) | B17: EB | C17: =bits25/(1+g25) -> 892.85714 | D17: =bits25 -> 1000 | E17: =MIN(E13,E15) -> 1210 | F17: =MIN(F13,F15) -> 1512.5 | G17: =MIN(G13,G15) -> 1890.625 | H17: =MIN(H13,H15) -> 2306.5625 | I17: =MIN(I13,I15) -> 2674.5662
A18: 位元出貨年增 | B18: % | D18: =D17/C17-1 -> 0.12 | E18: =E17/D17-1 -> 0.21 | F18: =F17/E17-1 -> 0.25 | G18: =G17/F17-1 -> 0.25 | H18: =H17/G17-1 -> 0.22 | I18: =I17/H17-1 -> 0.1595464
A19: NAND 市場營收（四季合計） | B19: $B | C19: =rev24 -> 67.4 | D19: =SUM(C33:F33) -> 71.103592 | E19: =SUM(G33:J33) -> 342.82075 | F19: =SUM(K33:N33) -> 536.73468 | G19: =SUM(O33:R33) -> 544.61015 | H19: =SUM(S33:V33) -> 570.46528 | I19: =SUM(W33:Z33) -> 583.68943 | AB19: CY2024 為 TrendForce 年度值
A20: 市場營收年增 | B20: % | D20: =D19/C19-1 -> 0.054949442 | E20: =E19/D19-1 -> 3.8214266 | F20: =F19/E19-1 -> 0.56564233 | G20: =G19/F19-1 -> 0.014672931 | H20: =H19/G19-1 -> 0.04747456 | I20: =I19/H19-1 -> 0.023181352
A21: 平均售價（營收 ÷ 位元出貨） | B21: $/GB | C21: =C19/C17 -> 0.075488 | D21: =D19/D17 -> 0.071103592 | E21: =E19/E17 -> 0.28332293 | F21: =F19/F17 -> 0.3548659 | G21: =G19/G17 -> 0.28805826 | H21: =H19/H17 -> 0.2473227 | I21: =I19/I17 -> 0.21823704
A22: 平均售價年變動 | B22: % | D22: =D21/C21-1 -> -0.058080856 | E22: =E21/D21-1 -> 2.9846501 | F22: =F21/E21-1 -> 0.25251387 | G22: =G21/F21-1 -> -0.18826165 | H22: =H21/G21-1 -> -0.1414143 | I22: =I21/H21-1 -> -0.11760206 | AB22: CY2030 為收斂法（p10）＋位元平滑效果
A23: 年度份額：三星 | B23: % | D23: =SUM(C40:F40)/D19 -> 0.30940771 | E23: =SUM(G40:J40)/E19 -> 0.29814637 | F23: =SUM(K40:N40)/F19 -> 0.29314637 | G23: =SUM(O40:R40)/G19 -> 0.28814637 | H23: =SUM(S40:V40)/H19 -> 0.28314637 | I23: =SUM(W40:Z40)/I19 -> 0.27814637
A24: 年度份額：SK 海力士＋Solidigm | B24: % | D24: =SUM(C41:F41)/D19 -> 0.20069309 | E24: =SUM(G41:J41)/E19 -> 0.17773013 | F24: =SUM(K41:N41)/F19 -> 0.17773013 | G24: =SUM(O41:R41)/G19 -> 0.17773013 | H24: =SUM(S41:V41)/H19 -> 0.17773013 | I24: =SUM(W41:Z41)/I19 -> 0.17773013
A25: 年度份額：美光 | B25: % | D25: =SUM(C42:F42)/D19 -> 0.134733 | E25: =SUM(G42:J42)/E19 -> 0.1451191 | F25: =SUM(K42:N42)/F19 -> 0.1471191 | G25: =SUM(O42:R42)/G19 -> 0.1491191 | H25: =SUM(S42:V42)/H19 -> 0.1511191 | I25: =SUM(W42:Z42)/I19 -> 0.1531191
A26: 年度份額：Kioxia | B26: % | D26: =SUM(C43:F43)/D19 -> 0.14359331 | E26: =SUM(G43:J43)/E19 -> 0.13953322 | F26: =SUM(K43:N43)/F19 -> 0.13851299 | G26: =SUM(O43:R43)/G19 -> 0.13851299 | H26: =SUM(S43:V43)/H19 -> 0.13851299 | I26: =SUM(W43:Z43)/I19 -> 0.13851299
A27: 年度份額：SanDisk | B27: % | D27: =SUM(C44:F44)/D19 -> 0.1255914 | E27: =SUM(G44:J44)/E19 -> 0.11206254 | F27: =SUM(K44:N44)/F19 -> 0.10651367 | G27: =SUM(O44:R44)/G19 -> 0.10651367 | H27: =SUM(S44:V44)/H19 -> 0.10651367 | I27: =SUM(W44:Z44)/I19 -> 0.10651367
A28: 年度份額：其他（長江存儲等） | B28: % | D28: =SUM(C45:F45)/D19 -> 0.085981484 | E28: =SUM(G45:J45)/E19 -> 0.12740864 | F28: =SUM(K45:N45)/F19 -> 0.13697774 | G28: =SUM(O45:R45)/G19 -> 0.13997774 | H28: =SUM(S45:V45)/H19 -> 0.14297774 | I28: =SUM(W45:Z45)/I19 -> 0.14597774
A30: B. 季度 | B30: 單位 | C30: 2025Q1 | D30: 2025Q2 | E30: 2025Q3 | F30: 2025Q4 | G30: 2026Q1 | H30: 2026Q2 | I30: 2026Q3 | J30: 2026Q4 | K30: 2027Q1 | L30: 2027Q2 | M30: 2027Q3 | N30: 2027Q4 | O30: 2028Q1 | P30: 2028Q2 | Q30: 2028Q3 | R30: 2028Q4 | S30: 2029Q1 | T30: 2029Q2 | U30: 2029Q3 | V30: 2029Q4 | W30: 2030Q1 | X30: 2030Q2 | Y30: 2030Q3 | Z30: 2030Q4 | AB30: 說明
A31: 合約價指數（同字母路徑） | B31: 2025Q1＝1 | C31: =Path!C4 -> 1 | D31: =Path!D4 -> 1 | E31: =Path!E4 -> 1.05 | F31: =Path!F4 -> 1.365 | G31: =Path!G4 -> 2.559375 | H31: =Path!H4 -> 4.4149219 | I31: =Path!I4 -> 5.5186523 | J31: =Path!J4 -> 5.9656632 | K31: =Path!K4*1 -> 6.1446331 | L31: =Path!L4*1 -> 6.1446331 | M31: =Path!M4*1 -> 5.8374014 | N31: =Path!N4*1 -> 5.4287833 | O31: =Path!O4*1 -> 5.1573442 | P31: =Path!P4*1 -> 4.899477 | Q31: =Path!Q4*1 -> 4.6545031 | R31: =Path!R4*1 -> 4.4217779 | ... V31: =Path!V4*1 -> 3.9145682 | W31: =Path!V4*(1+p10)^(1/4)*1 -> 3.791443 | X31: =Path!V4*(1+p10)^(2/4)*1 -> 3.6721905 | Y31: =Path!V4*(1+p10)^(3/4)*1 -> 3.5566888 | Z31: =Path!V4*(1+p10)^(4/4)*1 -> 3.44482 | AB31: Path 頁；Sens 可對 2027 起的季價乘價格係數
A32: 季度位元出貨（年內依年增平滑；四季合計＝年度） | B32: EB | C32: =D17/4*(D17/C17)^((1-2.5)/4)/(((D17/C17)^(-0.375)+(D17/C17)^(-0.125)+(D17/C17)^(0.125)+(D17/C17)^(0.375))/4) -> 239.47787 | D32: =D17/4*(D17/C17)^((2-2.5)/4)/(((D17/C17)^(-0.375)+(D17/C17)^(-0.125)+(D17/C17)^(0.125)+(D17/C17)^(0.375))/4) -> 246.35983 | E32: =D17/4*(D17/C17)^((3-2.5)/4)/(((D17/C17)^(-0.375)+(D17/C17)^(-0.125)+(D17/C17)^(0.125)+(D17/C17)^(0.375))/4) -> 253.43956 | F32: =D17/4*(D17/C17)^((4-2.5)/4)/(((D17/C17)^(-0.375)+(D17/C17)^(-0.125)+(D17/C17)^(0.125)+(D17/C17)^(0.375))/4) -> 260.72274 | G32: =E17/4*(E17/D17)^((1-2.5)/4)/(((E17/D17)^(-0.375)+(E17/D17)^(-0.125)+(E17/D17)^(0.125)+(E17/D17)^(0.375))/4) -> 281.23193 | H32: =E17/4*(E17/D17)^((2-2.5)/4)/(((E17/D17)^(-0.375)+(E17/D17)^(-0.125)+(E17/D17)^(0.125)+(E17/D17)^(0.375))/4) -> 294.95854 | I32: =E17/4*(E17/D17)^((3-2.5)/4)/(((E17/D17)^(-0.375)+(E17/D17)^(-0.125)+(E17/D17)^(0.125)+(E17/D17)^(0.375))/4) -> 309.35513 | J32: =E17/4*(E17/D17)^((4-2.5)/4)/(((E17/D17)^(-0.375)+(E17/D17)^(-0.125)+(E17/D17)^(0.125)+(E17/D17)^(0.375))/4) -> 324.4544 | K32: =F17/4*(F17/E17)^((1-2.5)/4)/(((F17/E17)^(-0.375)+(F17/E17)^(-0.125)+(F17/E17)^(0.125)+(F17/E17)^(0.375))/4) -> 347.09614 | L32: =F17/4*(F17/E17)^((2-2.5)/4)/(((F17/E17)^(-0.375)+(F17/E17)^(-0.125)+(F17/E17)^(0.125)+(F17/E17)^(0.375))/4) -> 367.00949 | M32: =F17/4*(F17/E17)^((3-2.5)/4)/(((F17/E17)^(-0.375)+(F17/E17)^(-0.125)+(F17/E17)^(0.125)+(F17/E17)^(0.375))/4) -> 388.06529 | N32: =F17/4*(F17/E17)^((4-2.5)/4)/(((F17/E17)^(-0.375)+(F17/E17)^(-0.125)+(F17/E17)^(0.125)+(F17/E17)^(0.375))/4) -> 410.32908 | O32: =G17/4*(G17/F17)^((1-2.5)/4)/(((G17/F17)^(-0.375)+(G17/F17)^(-0.125)+(G17/F17)^(0.125)+(G17/F17)^(0.375))/4) -> 433.87018 | P32: =G17/4*(G17/F17)^((2-2.5)/4)/(((G17/F17)^(-0.375)+(G17/F17)^(-0.125)+(G17/F17)^(0.125)+(G17/F17)^(0.375))/4) -> 458.76186 | Q32: =G17/4*(G17/F17)^((3-2.5)/4)/(((G17/F17)^(-0.375)+(G17/F17)^(-0.125)+(G17/F17)^(0.125)+(G17/F17)^(0.375))/4) -> 485.08161 | R32: =G17/4*(G17/F17)^((4-2.5)/4)/(((G17/F17)^(-0.375)+(G17/F17)^(-0.125)+(G17/F17)^(0.125)+(G17/F17)^(0.375))/4) -> 512.91135 | S32: =H17/4*(H17/G17)^((1-2.5)/4)/(((H17/G17)^(-0.375)+(H17/G17)^(-0.125)+(H17/G17)^(0.125)+(H17/G17)^(0.375))/4) -> 534.37942 | T32: =H17/4*(H17/G17)^((2-2.5)/4)/(((H17/G17)^(-0.375)+(H17/G17)^(-0.125)+(H17/G17)^(0.125)+(H17/G17)^(0.375))/4) -> 561.61627 | U32: =H17/4*(H17/G17)^((3-2.5)/4)/(((H17/G17)^(-0.375)+(H17/G17)^(-0.125)+(H17/G17)^(0.125)+(H17/G17)^(0.375))/4) -> 590.24136 | V32: =H17/4*(H17/G17)^((4-2.5)/4)/(((H17/G17)^(-0.375)+(H17/G17)^(-0.125)+(H17/G17)^(0.125)+(H17/G17)^(0.375))/4) -> 620.32545 | W32: =I17/4*(I17/H17)^((1-2.5)/4)/(((I17/H17)^(-0.375)+(I17/H17)^(-0.125)+(I17/H17)^(0.125)+(I17/H17)^(0.375))/4) -> 631.99501 | X32: =I17/4*(I17/H17)^((2-2.5)/4)/(((I17/H17)^(-0.375)+(I17/H17)^(-0.125)+(I17/H17)^(0.125)+(I17/H17)^(0.375))/4) -> 655.82155 | Y32: =I17/4*(I17/H17)^((3-2.5)/4)/(((I17/H17)^(-0.375)+(I17/H17)^(-0.125)+(I17/H17)^(0.125)+(I17/H17)^(0.375))/4) -> 680.54636 | Z32: =I17/4*(I17/H17)^((4-2.5)/4)/(((I17/H17)^(-0.375)+(I17/H17)^(-0.125)+(I17/H17)^(0.125)+(I17/H17)^(0.375))/4) -> 706.20331 | AB32: 季度＝年度 ÷ 4 ×（1＋年增）^((季−2.5)/4)，再正規化使四季合計等於年度
A33: NAND 市場營收（2026Q2 前實績；之後＝2Q26 實績 × 價格指數比 × 位元比） | B33: $B | C33: =(rv_ss_0+rv_sk_0+rv_mu_0+rv_kx_0+rv_sd_0)/t5_0 -> 12.935484 | D33: =(rv_ss_1+rv_sk_1+rv_mu_1+rv_kx_1+rv_sd_1)/t5_1 -> 15.805471 | E33: =(rv_ss_2+rv_sk_2+rv_mu_2+rv_kx_2+rv_sd_2)/t5_2 -> 18.791209 | F33: =(rv_ss_3+rv_sk_3+rv_mu_3+rv_kx_3+rv_sd_3)/t5_3 -> 23.571429 | G33: =(rv_ss_4+rv_sk_4+rv_mu_4+rv_kx_4+rv_sd_4)/t5_4 -> 43.954802 | H33: =(rv_ss_5+rv_sk_5+rv_mu_5+rv_kx_5+rv_sd_5)/t5_5 -> 78.703072 | I33: =$H33*I31/$H31*I32/$H32 -> 103.1806 | J33: =$H33*J31/$H31*J32/$H32 -> 116.98228 | K33: =$H33*K31/$H31*K32/$H32 -> 128.90015 | L33: =$H33*L31/$H31*L32/$H32 -> 136.29532 | M33: =$H33*M31/$H31*M32/$H32 -> 136.90901 | N33: =$H33*N31/$H31*N32/$H32 -> 134.6302 | O33: =$H33*O31/$H31*O32/$H32 -> 135.2364 | P33: =$H33*P31/$H31*P32/$H32 -> 135.84533 | ... Z33: =$H33*Z31/$H31*Z32/$H32 -> 147.02933 | AB33: 實績＝TrendForce 前五大 ÷ 前五大占比；以 2Q26 為錨
A34: 份額：三星 | B34: % | C34: =rv_ss_0/C33 -> 0.32468828 | D34: =rv_ss_1/D33 -> 0.329 | E34: =rv_ss_2/E33 -> 0.31929825 | F34: =rv_ss_3/F33 -> 0.28 | G34: =rv_ss_4/G33 -> 0.30736118 | H34: =rv_ss_5/H33 -> 0.293 | I34: =(rv_ss_4+rv_ss_5)/($G33+$H33) -> 0.29814637 | J34: =(rv_ss_4+rv_ss_5)/($G33+$H33) -> 0.29814637 | K34: =(rv_ss_4+rv_ss_5)/($G33+$H33)+dr_ss/100*1 -> 0.29314637 | L34: =(rv_ss_4+rv_ss_5)/($G33+$H33)+dr_ss/100*1 -> 0.29314637 | M34: =(rv_ss_4+rv_ss_5)/($G33+$H33)+dr_ss/100*1 -> 0.29314637 | N34: =(rv_ss_4+rv_ss_5)/($G33+$H33)+dr_ss/100*1 -> 0.29314637 | O34: =(rv_ss_4+rv_ss_5)/($G33+$H33)+dr_ss/100*2 -> 0.28814637 | P34: =(rv_ss_4+rv_ss_5)/($G33+$H33)+dr_ss/100*2 -> 0.28814637 | Q34: =(rv_ss_4+rv_ss_5)/($G33+$H33)+dr_ss/100*2 -> 0.28814637 | R34: =(rv_ss_4+rv_ss_5)/($G33+$H33)+dr_ss/100*2 -> 0.28814637 | S34: =(rv_ss_4+rv_ss_5)/($G33+$H33)+dr_ss/100*3 -> 0.28314637 | T34: =(rv_ss_4+rv_ss_5)/($G33+$H33)+dr_ss/100*3 -> 0.28314637 | U34: =(rv_ss_4+rv_ss_5)/($G33+$H33)+dr_ss/100*3 -> 0.28314637 | V34: =(rv_ss_4+rv_ss_5)/($G33+$H33)+dr_ss/100*3 -> 0.28314637 | W34: =(rv_ss_4+rv_ss_5)/($G33+$H33)+dr_ss/100*4 -> 0.27814637 | X34: =(rv_ss_4+rv_ss_5)/($G33+$H33)+dr_ss/100*4 -> 0.27814637 | Y34: =(rv_ss_4+rv_ss_5)/($G33+$H33)+dr_ss/100*4 -> 0.27814637 | Z34: =(rv_ss_4+rv_ss_5)/($G33+$H33)+dr_ss/100*4 -> 0.27814637 | AB34: 2026Q3–Q4＝1H26 實績份額；2027 起每年＋年變動
A35: 份額：SK 海力士＋Solidigm | B35: % | C35: =rv_sk_0/C33 -> 0.16930175 | D35: =rv_sk_1/D33 -> 0.21131923 | E35: =rv_sk_2/E33 -> 0.1878538 | F35: =rv_sk_3/F33 -> 0.2210303 | G35: =rv_sk_4/G33 -> 0.17131234 | H35: =rv_sk_5/H33 -> 0.1813144 | I35: =(rv_sk_4+rv_sk_5)/($G33+$H33) -> 0.17773013 | J35: =(rv_sk_4+rv_sk_5)/($G33+$H33) -> 0.17773013 | K35: =(rv_sk_4+rv_sk_5)/($G33+$H33)+dr_sk/100*1 -> 0.17773013 | L35: =(rv_sk_4+rv_sk_5)/($G33+$H33)+dr_sk/100*1 -> 0.17773013 | M35: =(rv_sk_4+rv_sk_5)/($G33+$H33)+dr_sk/100*1 -> 0.17773013 | N35: =(rv_sk_4+rv_sk_5)/($G33+$H33)+dr_sk/100*1 -> 0.17773013 | O35: =(rv_sk_4+rv_sk_5)/($G33+$H33)+dr_sk/100*2 -> 0.17773013 | P35: =(rv_sk_4+rv_sk_5)/($G33+$H33)+dr_sk/100*2 -> 0.17773013 | Q35: =(rv_sk_4+rv_sk_5)/($G33+$H33)+dr_sk/100*2 -> 0.17773013 | R35: =(rv_sk_4+rv_sk_5)/($G33+$H33)+dr_sk/100*2 -> 0.17773013 | S35: =(rv_sk_4+rv_sk_5)/($G33+$H33)+dr_sk/100*3 -> 0.17773013 | T35: =(rv_sk_4+rv_sk_5)/($G33+$H33)+dr_sk/100*3 -> 0.17773013 | U35: =(rv_sk_4+rv_sk_5)/($G33+$H33)+dr_sk/100*3 -> 0.17773013 | V35: =(rv_sk_4+rv_sk_5)/($G33+$H33)+dr_sk/100*3 -> 0.17773013 | W35: =(rv_sk_4+rv_sk_5)/($G33+$H33)+dr_sk/100*4 -> 0.17773013 | X35: =(rv_sk_4+rv_sk_5)/($G33+$H33)+dr_sk/100*4 -> 0.17773013 | Y35: =(rv_sk_4+rv_sk_5)/($G33+$H33)+dr_sk/100*4 -> 0.17773013 | Z35: =(rv_sk_4+rv_sk_5)/($G33+$H33)+dr_sk/100*4 -> 0.17773013 | AB35: 2026Q3–Q4＝1H26 實績份額；2027 起每年＋年變動
A36: 份額：美光 | B36: % | C36: =rv_mu_0/C33 -> 0.15693267 | D36: =rv_mu_1/D33 -> 0.13286538 | E36: =rv_mu_2/E33 -> 0.12878363 | F36: =rv_mu_3/F33 -> 0.12854545 | G36: =rv_mu_4/G33 -> 0.13536632 | H36: =rv_mu_5/H33 -> 0.15056592 | I36: =(rv_mu_4+rv_mu_5)/($G33+$H33) -> 0.1451191 | J36: =(rv_mu_4+rv_mu_5)/($G33+$H33) -> 0.1451191 | K36: =(rv_mu_4+rv_mu_5)/($G33+$H33)+dr_mu/100*1 -> 0.1471191 | L36: =(rv_mu_4+rv_mu_5)/($G33+$H33)+dr_mu/100*1 -> 0.1471191 | M36: =(rv_mu_4+rv_mu_5)/($G33+$H33)+dr_mu/100*1 -> 0.1471191 | N36: =(rv_mu_4+rv_mu_5)/($G33+$H33)+dr_mu/100*1 -> 0.1471191 | O36: =(rv_mu_4+rv_mu_5)/($G33+$H33)+dr_mu/100*2 -> 0.1491191 | P36: =(rv_mu_4+rv_mu_5)/($G33+$H33)+dr_mu/100*2 -> 0.1491191 | Q36: =(rv_mu_4+rv_mu_5)/($G33+$H33)+dr_mu/100*2 -> 0.1491191 | R36: =(rv_mu_4+rv_mu_5)/($G33+$H33)+dr_mu/100*2 -> 0.1491191 | S36: =(rv_mu_4+rv_mu_5)/($G33+$H33)+dr_mu/100*3 -> 0.1511191 | T36: =(rv_mu_4+rv_mu_5)/($G33+$H33)+dr_mu/100*3 -> 0.1511191 | U36: =(rv_mu_4+rv_mu_5)/($G33+$H33)+dr_mu/100*3 -> 0.1511191 | V36: =(rv_mu_4+rv_mu_5)/($G33+$H33)+dr_mu/100*3 -> 0.1511191 | W36: =(rv_mu_4+rv_mu_5)/($G33+$H33)+dr_mu/100*4 -> 0.1531191 | X36: =(rv_mu_4+rv_mu_5)/($G33+$H33)+dr_mu/100*4 -> 0.1531191 | Y36: =(rv_mu_4+rv_mu_5)/($G33+$H33)+dr_mu/100*4 -> 0.1531191 | Z36: =(rv_mu_4+rv_mu_5)/($G33+$H33)+dr_mu/100*4 -> 0.1531191 | AB36: 2026Q3–Q4＝1H26 實績份額；2027 起每年＋年變動
A37: 份額：Kioxia | B37: % | C37: =rv_kx_0/C33 -> 0.14842893 | D37: =rv_kx_1/D33 -> 0.13539615 | E37: =rv_kx_2/E33 -> 0.1511345 | F37: =rv_kx_3/F33 -> 0.14042424 | G37: =rv_kx_4/G33 -> 0.13559383 | H37: =rv_kx_5/H33 -> 0.13620815 | I37: =kx_g/kx_fxg/kx_k/$I33 -> 0.14490434 | J37: =(kx_g/kx_fxg/kx_k/$I33+kx_g4/kx_fxg4/kx_k/$J33)/2 -> 0.13851299 | K37: =(kx_g/kx_fxg/kx_k/$I33+kx_g4/kx_fxg4/kx_k/$J33)/2+dr_jv_A/100*1*(kx_g/kx_fxg/kx_k)/(kx_g/kx_fxg/kx_k+sd_g/sd_k) -> 0.13851299 | L37: =(kx_g/kx_fxg/kx_k/$I33+kx_g4/kx_fxg4/kx_k/$J33)/2+dr_jv_A/100*1*(kx_g/kx_fxg/kx_k)/(kx_g/kx_fxg/kx_k+sd_g/sd_k) -> 0.13851299 | M37: =(kx_g/kx_fxg/kx_k/$I33+kx_g4/kx_fxg4/kx_k/$J33)/2+dr_jv_A/100*1*(kx_g/kx_fxg/kx_k)/(kx_g/kx_fxg/kx_k+sd_g/sd_k) -> 0.13851299 | N37: =(kx_g/kx_fxg/kx_k/$I33+kx_g4/kx_fxg4/kx_k/$J33)/2+dr_jv_A/100*1*(kx_g/kx_fxg/kx_k)/(kx_g/kx_fxg/kx_k+sd_g/sd_k) -> 0.13851299 | O37: =(kx_g/kx_fxg/kx_k/$I33+kx_g4/kx_fxg4/kx_k/$J33)/2+dr_jv_A/100*2*(kx_g/kx_fxg/kx_k)/(kx_g/kx_fxg/kx_k+sd_g/sd_k) -> 0.13851299 | P37: =(kx_g/kx_fxg/kx_k/$I33+kx_g4/kx_fxg4/kx_k/$J33)/2+dr_jv_A/100*2*(kx_g/kx_fxg/kx_k)/(kx_g/kx_fxg/kx_k+sd_g/sd_k) -> 0.13851299 | Q37: =(kx_g/kx_fxg/kx_k/$I33+kx_g4/kx_fxg4/kx_k/$J33)/2+dr_jv_A/100*2*(kx_g/kx_fxg/kx_k)/(kx_g/kx_fxg/kx_k+sd_g/sd_k) -> 0.13851299 | R37: =(kx_g/kx_fxg/kx_k/$I33+kx_g4/kx_fxg4/kx_k/$J33)/2+dr_jv_A/100*2*(kx_g/kx_fxg/kx_k)/(kx_g/kx_fxg/kx_k+sd_g/sd_k) -> 0.13851299 | S37: =(kx_g/kx_fxg/kx_k/$I33+kx_g4/kx_fxg4/kx_k/$J33)/2+dr_jv_A/100*3*(kx_g/kx_fxg/kx_k)/(kx_g/kx_fxg/kx_k+sd_g/sd_k) -> 0.13851299 | T37: =(kx_g/kx_fxg/kx_k/$I33+kx_g4/kx_fxg4/kx_k/$J33)/2+dr_jv_A/100*3*(kx_g/kx_fxg/kx_k)/(kx_g/kx_fxg/kx_k+sd_g/sd_k) -> 0.13851299 | U37: =(kx_g/kx_fxg/kx_k/$I33+kx_g4/kx_fxg4/kx_k/$J33)/2+dr_jv_A/100*3*(kx_g/kx_fxg/kx_k)/(kx_g/kx_fxg/kx_k+sd_g/sd_k) -> 0.13851299 | V37: =(kx_g/kx_fxg/kx_k/$I33+kx_g4/kx_fxg4/kx_k/$J33)/2+dr_jv_A/100*3*(kx_g/kx_fxg/kx_k)/(kx_g/kx_fxg/kx_k+sd_g/sd_k) -> 0.13851299 | W37: =(kx_g/kx_fxg/kx_k/$I33+kx_g4/kx_fxg4/kx_k/$J33)/2+dr_jv_A/100*4*(kx_g/kx_fxg/kx_k)/(kx_g/kx_fxg/kx_k+sd_g/sd_k) -> 0.13851299 | X37: =(kx_g/kx_fxg/kx_k/$I33+kx_g4/kx_fxg4/kx_k/$J33)/2+dr_jv_A/100*4*(kx_g/kx_fxg/kx_k)/(kx_g/kx_fxg/kx_k+sd_g/sd_k) -> 0.13851299 | Y37: =(kx_g/kx_fxg/kx_k/$I33+kx_g4/kx_fxg4/kx_k/$J33)/2+dr_jv_A/100*4*(kx_g/kx_fxg/kx_k)/(kx_g/kx_fxg/kx_k+sd_g/sd_k) -> 0.13851299 | Z37: =(kx_g/kx_fxg/kx_k/$I33+kx_g4/kx_fxg4/kx_k/$J33)/2+dr_jv_A/100*4*(kx_g/kx_fxg/kx_k)/(kx_g/kx_fxg/kx_k+sd_g/sd_k) -> 0.13851299 | AB37: 2026Q3＝公司第二季實績 ÷ 匯率 ÷ 公司口徑係數 ÷ 市場；2026Q4 起＝2026Q3 實績份額與 2026Q4 指引份額的平均（平滑出貨季別移動）；2027 起＋合資群年變動 × Kioxia 比重
A38: 份額：SanDisk | B38: % | C38: =rv_sd_0/C33 -> 0.13064838 | D38: =rv_sd_1/D33 -> 0.12021154 | E38: =rv_sd_2/E33 -> 0.12292982 | F38: =rv_sd_3/F33 -> 0.12854545 | G38: =rv_sd_4/G33 -> 0.13536632 | H38: =rv_sd_5/H33 -> 0.11397268 | I38: =sd_g/sd_k/$I33 -> 0.10696926 | J38: =(sd_g/sd_k/$I33+sd_g4/sd_k/$J33)/2 -> 0.10651367 | K38: =(sd_g/sd_k/$I33+sd_g4/sd_k/$J33)/2+dr_jv_A/100*1*(sd_g/sd_k)/(kx_g/kx_fxg/kx_k+sd_g/sd_k) -> 0.10651367 | L38: =(sd_g/sd_k/$I33+sd_g4/sd_k/$J33)/2+dr_jv_A/100*1*(sd_g/sd_k)/(kx_g/kx_fxg/kx_k+sd_g/sd_k) -> 0.10651367 | M38: =(sd_g/sd_k/$I33+sd_g4/sd_k/$J33)/2+dr_jv_A/100*1*(sd_g/sd_k)/(kx_g/kx_fxg/kx_k+sd_g/sd_k) -> 0.10651367 | N38: =(sd_g/sd_k/$I33+sd_g4/sd_k/$J33)/2+dr_jv_A/100*1*(sd_g/sd_k)/(kx_g/kx_fxg/kx_k+sd_g/sd_k) -> 0.10651367 | O38: =(sd_g/sd_k/$I33+sd_g4/sd_k/$J33)/2+dr_jv_A/100*2*(sd_g/sd_k)/(kx_g/kx_fxg/kx_k+sd_g/sd_k) -> 0.10651367 | P38: =(sd_g/sd_k/$I33+sd_g4/sd_k/$J33)/2+dr_jv_A/100*2*(sd_g/sd_k)/(kx_g/kx_fxg/kx_k+sd_g/sd_k) -> 0.10651367 | Q38: =(sd_g/sd_k/$I33+sd_g4/sd_k/$J33)/2+dr_jv_A/100*2*(sd_g/sd_k)/(kx_g/kx_fxg/kx_k+sd_g/sd_k) -> 0.10651367 | R38: =(sd_g/sd_k/$I33+sd_g4/sd_k/$J33)/2+dr_jv_A/100*2*(sd_g/sd_k)/(kx_g/kx_fxg/kx_k+sd_g/sd_k) -> 0.10651367 | S38: =(sd_g/sd_k/$I33+sd_g4/sd_k/$J33)/2+dr_jv_A/100*3*(sd_g/sd_k)/(kx_g/kx_fxg/kx_k+sd_g/sd_k) -> 0.10651367 | T38: =(sd_g/sd_k/$I33+sd_g4/sd_k/$J33)/2+dr_jv_A/100*3*(sd_g/sd_k)/(kx_g/kx_fxg/kx_k+sd_g/sd_k) -> 0.10651367 | U38: =(sd_g/sd_k/$I33+sd_g4/sd_k/$J33)/2+dr_jv_A/100*3*(sd_g/sd_k)/(kx_g/kx_fxg/kx_k+sd_g/sd_k) -> 0.10651367 | V38: =(sd_g/sd_k/$I33+sd_g4/sd_k/$J33)/2+dr_jv_A/100*3*(sd_g/sd_k)/(kx_g/kx_fxg/kx_k+sd_g/sd_k) -> 0.10651367 | W38: =(sd_g/sd_k/$I33+sd_g4/sd_k/$J33)/2+dr_jv_A/100*4*(sd_g/sd_k)/(kx_g/kx_fxg/kx_k+sd_g/sd_k) -> 0.10651367 | X38: =(sd_g/sd_k/$I33+sd_g4/sd_k/$J33)/2+dr_jv_A/100*4*(sd_g/sd_k)/(kx_g/kx_fxg/kx_k+sd_g/sd_k) -> 0.10651367 | Y38: =(sd_g/sd_k/$I33+sd_g4/sd_k/$J33)/2+dr_jv_A/100*4*(sd_g/sd_k)/(kx_g/kx_fxg/kx_k+sd_g/sd_k) -> 0.10651367 | Z38: =(sd_g/sd_k/$I33+sd_g4/sd_k/$J33)/2+dr_jv_A/100*4*(sd_g/sd_k)/(kx_g/kx_fxg/kx_k+sd_g/sd_k) -> 0.10651367 | AB38: 2026Q3＝公司 FQ1 FY27 實績 ÷ 口徑係數 ÷ 市場；2026Q4 起＝2026Q3 實績份額與 FQ2 FY27 指引份額的平均；2027 起＋合資群年變動 × SanDisk 比重
A39: 份額：其他（長江存儲等） | B39: % | C39: =1-t5_0 -> 0.07 | D39: =1-t5_1 -> 0.071207692 | E39: =1-t5_2 -> 0.09 | F39: =1-t5_3 -> 0.10145455 | G39: =1-t5_4 -> 0.115 | H39: =1-t5_5 -> 0.12493886 | I39: =1-I34-I35-I36-I37-I38 -> 0.12713079 | J39: =1-J34-J35-J36-J37-J38 -> 0.13397774 | K39: =1-K34-K35-K36-K37-K38 -> 0.13697774 | L39: =1-L34-L35-L36-L37-L38 -> 0.13697774 | M39: =1-M34-M35-M36-M37-M38 -> 0.13697774 | N39: =1-N34-N35-N36-N37-N38 -> 0.13697774 | O39: =1-O34-O35-O36-O37-O38 -> 0.13997774 | P39: =1-P34-P35-P36-P37-P38 -> 0.13997774 | ... Z39: =1-Z34-Z35-Z36-Z37-Z38 -> 0.14597774 | AB39: 餘額（長江存儲等）
A40: 三星 營收（情境 A） | B40: $B | C40: =C33*C34 -> 4.2 | D40: =D33*D34 -> 5.2 | E40: =E33*E34 -> 6 | F40: =F33*F34 -> 6.6 | G40: =G33*G34 -> 13.51 | H40: =H33*H34 -> 23.06 | I40: =I33*I34 -> 30.762921 | J40: =J33*J34 -> 34.877842 | ... Z40: =Z33*Z34 -> 40.895674
A41: SK 海力士＋Solidigm 營收（情境 A） | B41: $B | C41: =C33*C35 -> 2.19 | D41: =D33*D35 -> 3.34 | E41: =E33*E35 -> 3.53 | F41: =F33*F35 -> 5.21 | G41: =G33*G35 -> 7.53 | H41: =H33*H35 -> 14.27 | I41: =I33*I35 -> 18.338301 | J41: =J33*J35 -> 20.791276 | ... Z41: =Z33*Z35 -> 26.131542
A42: 美光 營收（情境 A） | B42: $B | C42: =C33*C36 -> 2.03 | D42: =D33*D36 -> 2.1 | E42: =E33*E36 -> 2.42 | F42: =F33*F36 -> 3.03 | G42: =G33*G36 -> 5.95 | H42: =H33*H36 -> 11.85 | I42: =I33*I36 -> 14.973475 | J42: =J33*J36 -> 16.976363 | ... Z42: =Z33*Z36 -> 22.512998
...

Sheet Sup
A1: Sup — 主要廠位元供給說明（層數、產能動向；本頁為文字輸入，不進計算：位元供給以全產業年增 gs_ 計，見 In 頁 N4）
A3: 廠商 | B3: 主力世代（2026） | C3: 下一代 | D3: 2026 產能動向 | E3: 2Q26 位元市占 | F3: 標記 | G3: 來源
A4: 三星 | B4: V9（286 層） | C4: V10（430 層以上；大規模投資不早於 1H26） | D4: 晶圓投片約 −4.5%（投資轉向 HBM） | E4: 25% | F4: Interested-party | G4: borecraft 2026-05-26（轉載 DigiTimes 2026-05-25、Blocks & Files 2026-01-20）；Counterpoint 2Q26 位元市占
A5: SK 海力士＋Solidigm | B5: 321 層（V9 世代） | C5: 300 層級新品 2027 年初全面量產 | D5: 晶圓投片約 −10%；Solidigm QLC 企業級 SSD 出貨季增約 40% | E5: 22% | F5: Interested-party | G5: 同上；TrendForce 2026-08-18
A6: Kioxia（合資群） | B6: BiCS8（218 層） | C6: BiCS10（332 層，北上 K2，FY2026 量產；密度高約 59%） | D6: Kioxia＋SanDisk 2026 資本支出 $4.5B（+41%）；Kioxia FY26–28 年均 ¥470B | E6: 未找到 | F6: Interested-party | G6: TrendForce 2025-11-13、2026-06-03；borecraft 2026-05-26
A7: SanDisk（合資群） | B7: BiCS8（218 層；與 Kioxia 共用晶圓廠） | C7: BiCS10 | D7: 位元成長相對保守（TrendForce 2Q26）；Flash Ventures 持股 49.9% | E7: 未找到 | F7: Interested-party | G7: TrendForce 2026-08-18；SanDisk FQ4 FY26 簡報
A8: 美光 | B8: G9（276 層） | C8: 未找到 | D8: 位元成長低於產業（美光 FQ4 FY26） | E8: 未找到 | F8: Interested-party | G8: 美光 FQ4 FY26 法說（Guru3D 2026-10-01）
A9: 長江存儲 | B9: Xtacking 4.0（267 層） | C9: 未找到 | D9: 2Q26 位元市占 14%（第三），年增約 22%；三廠 2026 年底投產 | E9: 14% | F9: Interested-party | G9: Counterpoint 2Q26（hwbusters 轉載）；markets/equipment In 頁
A11: 各廠晶圓月產能（千片）：未找到可驗證的公開數字（TrendForce、Yole 付費）。本版不以各廠產能加總推供給，改用全產業位元年增（美光指引），各廠以營收份額分配。

Sheet Recon
A1: Recon — 本模型 vs 公司指引、公開預測（只作事後對照，不回推參數）。差距＝模型 ÷ 對照 − 1（百分點列為相減）
A3: 項目 | B3: 對照值 | C3: 模型 A | D3: 模型 B | E3: 模型 C | F3: 差距 A | G3: 對照來源 | H3: 說明
A4: 2Q26 SanDisk 營收（實績重現） | B4: =rv_sd_5 -> 8.97 | C4: =Mkt!H44 -> 8.97 | D4: =Mkt!H92 -> 8.97 | E4: =Mkt!H140 -> 8.97 | F4: =C4/B4-1 -> 0 | G4: TrendForce 2026-08-18（2Q26 NAND 前五大營收排名）https://www.trendforce.com/presscenter/news/20260818-13186.html | H4: 恆等式
A5: 2026Q3 SanDisk 營收 vs 公司指引（TrendForce 口徑） | B5: =sd_g/sd_k -> 11.037152 | C5: =Mkt!I44 -> 11.037152 | D5: =Mkt!I92 -> 11.037152 | E5: =Mkt!I140 -> 11.037152 | F5: =C5/B5-1 -> 0 | G5: SanDisk 指引 $10.3–10.8B | H5: 恆等式（份額由指引推得）
A6: 2026Q3 市場營收 vs 2Q26 ×（1＋季價 25%） | B6: =Mkt!H33*1.25 -> 98.37884 | C6: =Mkt!I33 -> 103.1806 | D6: =Mkt!I81 -> 103.1806 | E6: =Mkt!I129 -> 103.1806 | F6: =C6/B6-1 -> 0.048808848 | G6: Siliconomics v0.10 nq_6：2026Q3 實現平均售價 +25%（Kioxia、SK 海力士 mid-20%；TrendForce 合約價 +10~15% 只作對照） | H6: 差額＝位元季增
A7: CY2026 位元出貨年增 vs 美光「低 20% 段」（百分點） | B7: 0.21 | C7: =Mkt!E18 -> 0.21 | D7: =Mkt!E66 -> 0.21 | E7: =Mkt!E114 -> 0.21 | F7: =C7-B7 -> 0 | G7: 美光 FQ4 FY26（Guru3D 2026-10-01） | H7: 供給受限時＝gs_26
A8: CY2027 位元出貨年增 vs 美光「約中 20% 段」（百分點） | B8: 0.25 | C8: =Mkt!F18 -> 0.25 | D8: =Mkt!F66 -> 0.25 | E8: =Mkt!F114 -> 0.25 | F8: =C8-B8 -> 0 | G8: 同上
A9: CY2028 位元出貨年增 vs 美光「約中 20% 段」（百分點） | B9: 0.25 | C9: =Mkt!G18 -> 0.25 | D9: =Mkt!G66 -> 0.14989395 | E9: =Mkt!G114 -> 0.0097286612 | F9: =C9-B9 -> 0 | G9: 同上 | H9: B、C 需求低於供給，出貨＝需求
A10: CY2026 需求 ÷ 供給 − 1 vs TrendForce 供給缺口 4–6%（百分點） | B10: 0.05 | C10: =Mkt!E16 -> 0.042975207 | D10: =Mkt!E64 -> 0.042975207 | E10: =Mkt!E112 -> 0.042975207 | F10: =C10-B10 -> -0.0070247934 | G10: TrendForce 2026-07-21（Guru3D 轉載）：2026 供給低於需求 4–6%；2H27 回到平衡
A11: CY2026 企業級 SSD 占需求 vs Counterpoint 2Q26 48%（百分點） | B11: 0.48 | C11: =Mkt!E14 -> 0.47900158 | D11: =Mkt!E62 -> 0.47900158 | E11: =Mkt!E110 -> 0.47900158 | F11: =C11-B11 -> -0.00099841521 | G11: Counterpoint 2Q26（季度值；全年平均應較低） | H11: TrendForce：2026 伺服器約 40%
A12: CY2025 市場營收（實績）vs 前五大合計 ÷ 0.9 | B12: =(rv_ss_0+rv_ss_1+rv_ss_2+rv_ss_3+rv_sk_0+rv_sk_1+rv_sk_2+rv_sk_3+rv_mu_0+rv_mu_1+rv_mu_2+rv_mu_3+rv_kx_0+rv_kx_1+rv_kx_2+rv_kx_3+rv_sd_0+rv_sd_1+rv_sd_2+rv_sd_3)/0.9 -> 72.211111 | C12: =Mkt!D19 -> 71.103592 | D12: =Mkt!D67 -> 71.103592 | E12: =Mkt!D115 -> 71.103592 | F12: =C12/B12-1 -> -0.015337235 | G12: TrendForce 季度合計
A13: CY2027 Kioxia＋SanDisk 營收 vs 共識（會計年度依月份拼成日曆年：Kioxia ¼ FY2026＋¾ FY2027；SanDisk ½ FY2027＋½ FY2028） | B13: =10071/160/kx_k*0.25+13477/160/kx_k*0.75+49.1/sd_k*0.5+58.4/sd_k*0.5 -> 130.37177 | C13: =Ann!F28+Ann!F29 -> 131.5143 | D13: =Ann!F55+Ann!F56 -> 126.35556 | E13: =Ann!F82+Ann!F83 -> 124.78934 | F13: =C13/B13-1 -> 0.008763647 | G13: MarketScreener 2026-10-23 擷取：Kioxia FY2027（2027-03）營收 ¥10.07 兆、FY2028 ¥13.48 兆；SanDisk FY2027 $49.1B、FY2028 $58.4B | H13: 會計年度依月份拼成日曆年（Derived）；共識只作對照
A14: 2026Q4 SanDisk 營收 vs FQ2 FY27 指引中點 12.4（TrendForce 口徑） | B14: =12.4/sd_k -> 12.406916 | C14: =Mkt!J44 -> 12.460212 | D14: =Mkt!J92 -> 12.460212 | E14: =Mkt!J140 -> 12.460212 | F14: =C14/B14-1 -> 0.0042956712 | G14: SanDisk FQ1 FY27 法說（2026-10-29）：FQ2 FY27 營收指引 12.2–12.6 | H14: v0.3：2026Q4 季價 +8.1%＋份額取兩季平均（v0.2 差距 +9.6%）；公司稱價量皆貢獻、同品項價格溫和上升
A15: 2026Q4 Kioxia 營收 vs 第三季指引 ¥2,500B ÷ 157 日圓（TrendForce 口徑） | B15: =2500/157/kx_k -> 15.455889 | C15: =Mkt!J43 -> 16.203565 | D15: =Mkt!J91 -> 16.203565 | E15: =Mkt!J139 -> 16.203565 | F15: =C15/B15-1 -> 0.0483748 | G15: Kioxia 第二季財報（2026-10-30）：第三季營收指引 ¥2,500B（157 日圓）；位元持平、平均售價季增低個位數 | H15: v0.3：季價 +8.1%＋份額取兩季平均（v0.2 差距 +19.2%）。餘差＝份額平均只平滑一半的出貨季別移動（7–9 月提前、部分遞延到 1–3 月，同一會計年度內）與產品組合

Sheet Sens
A1: Sens — 一次動一個輸入（情境 A）：對 CY2027、CY2028 市場營收與 Kioxia＋SanDisk 營收的影響。每個案例為一個完整推導區塊（本頁下方，與 Mkt 同一引擎）
A3: 案例 | B3: 設定 | C3: CY2027 市場 $B | D3: 相對基準 | E3: CY2028 市場 $B | F3: 相對基準 | G3: CY2028 位元出貨 EB | H3: CY2028 合資群營收 $B | I3: 相對基準 | J3: CY2030 市場 $B | K3: 相對基準
A4: 基準（情境 A） | B4: Mkt 區塊 A | C4: =Mkt!F19 -> 536.73468 | D4: =C4/C$4-1 -> 0 | E4: =Mkt!G19 -> 544.61015 | F4: =E4/E$4-1 -> 0 | G4: =Mkt!G17 -> 1890.625 | H4: =SUM(Mkt!O43:R43)+SUM(Mkt!O44:R44) -> 133.444 | I4: =H4/H$4-1 -> 0 | J4: =Mkt!I19 -> 583.68943 | K4: =J4/J$4-1 -> 0
A5: 每顆容量 −20% | B5: tb 低欄 | C5: =F55 -> 536.58496 | D5: =C5/C$4-1 -> -0.00027894775 | E5: =G55 -> 515.86451 | F5: =E5/E$4-1 -> -0.052782043 | G5: =G53 -> 1739.2146 | H5: =SUM(O79:R79)+SUM(O80:R80) -> 127.95763 | I5: =H5/H$4-1 -> -0.041113648 | J5: =I55 -> 529.50958 | K5: =J5/J$4-1 -> -0.092823077
A6: 每顆容量 +20% | B6: tb 高欄 | C6: =F125 -> 536.73468 | D6: =C6/C$4-1 -> 0 | E6: =G125 -> 544.61015 | F6: =E6/E$4-1 -> 0 | G6: =G123 -> 1890.625 | H6: =SUM(O149:R149)+SUM(O150:R150) -> 133.444 | I6: =H6/H$4-1 -> 0 | J6: =I125 -> 603.84615 | K6: =J6/J$4-1 -> 0.034533288
A7: 位元供給成長 低 | B7: gs 低欄 | C7: =F195 -> 513.74938 | D7: =C7/C$4-1 -> -0.042824321 | E7: =G195 -> 500.49259 | F7: =E7/E$4-1 -> -0.0810076 | G7: =G193 -> 1699.2 | H7: =SUM(O219:R219)+SUM(O220:R220) -> 123.7838 | I7: =H7/H$4-1 -> -0.072391471 | J7: =I195 -> 488.23413 | K7: =J7/J$4-1 -> -0.16353782
A8: 位元供給成長 高 | B8: gs 高欄 | C8: =F265 -> 551.34164 | D8: =C8/C$4-1 -> 0.027214494 | E8: =G265 -> 550.50712 | F8: =E8/E$4-1 -> 0.010827884 | G8: =G263 -> 1951.2146 | H8: =SUM(O289:R289)+SUM(O290:R290) -> 133.66781 | I8: =H8/H$4-1 -> 0.001677183 | J8: =I265 -> 571.62806 | K8: =J8/J$4-1 -> -0.020664033
A9: 2025 位元基期 850 EB | B9: bits25 低 | C9: =F335 -> 536.73468 | D9: =C9/C$4-1 -> 0 | E9: =G335 -> 544.61015 | F9: =E9/E$4-1 -> 0 | G9: =G333 -> 1607.0312 | H9: =SUM(O359:R359)+SUM(O360:R360) -> 133.444 | I9: =H9/H$4-1 -> 0 | J9: =I335 -> 603.84615 | K9: =J9/J$4-1 -> 0.034533288
A10: 2025 位元基期 1,150 EB | B10: bits25 高 | C10: =F405 -> 539.56078 | D10: =C10/C$4-1 -> 0.0052653652 | E10: =G405 -> 525.38218 | F10: =E10/E$4-1 -> -0.035305942 | G10: =G403 -> 2084.8968 | H10: =SUM(O429:R429)+SUM(O430:R430) -> 129.02951 | I10: =H10/H$4-1 -> -0.033081227 | J10: =I405 -> 539.80573 | K10: =J10/J$4-1 -> -0.075183317
A11: 企業級 SSD 2025 占比 26% | B11: sh_essd25 低 | C11: =F475 -> 536.73468 | D11: =C11/C$4-1 -> 0 | E11: =G475 -> 544.61015 | F11: =E11/E$4-1 -> 0 | G11: =G473 -> 1890.625 | H11: =SUM(O499:R499)+SUM(O500:R500) -> 133.444 | I11: =H11/H$4-1 -> 0 | J11: =I475 -> 586.43014 | K11: =J11/J$4-1 -> 0.0046954883
A12: 非 AI 企業級 SSD 年增 5% | B12: g_nai 低 | C12: =F545 -> 536.73468 | D12: =C12/C$4-1 -> 0 | E12: =G545 -> 544.61015 | F12: =E12/E$4-1 -> 0 | G12: =G543 -> 1890.625 | H12: =SUM(O569:R569)+SUM(O570:R570) -> 133.444 | I12: =H12/H$4-1 -> 0 | J12: =I545 -> 573.93987 | K12: =J12/J$4-1 -> -0.016703333
A13: 2029 顆數年增 0% | B13: g_u29 低 | C13: =F615 -> 536.73468 | D13: =C13/C$4-1 -> 0 | E13: =G615 -> 544.61015 | F13: =E13/E$4-1 -> 0 | G13: =G613 -> 1890.625 | H13: =SUM(O639:R639)+SUM(O640:R640) -> 133.444 | I13: =H13/H$4-1 -> 0 | J13: =I615 -> 540.30089 | K13: =J13/J$4-1 -> -0.074334987
A14: CY2030 售價年變動 −20% | B14: p10 低 | C14: =F685 -> 536.73468 | D14: =C14/C$4-1 -> 0 | E14: =G685 -> 544.61015 | F14: =E14/E$4-1 -> 0 | G14: =G683 -> 1890.625 | H14: =SUM(O709:R709)+SUM(O710:R710) -> 133.444 | I14: =H14/H$4-1 -> 0 | J14: =I685 -> 550.0475 | K14: =J14/J$4-1 -> -0.057636697
A15: 2027 起季價水準 ×0.8 | B15: 價格係數 0.8 | C15: =F755 -> 429.38774 | D15: =C15/C$4-1 -> -0.2 | E15: =G755 -> 435.68812 | F15: =E15/E$4-1 -> -0.2 | G15: =G753 -> 1890.625 | H15: =SUM(O779:R779)+SUM(O780:R780) -> 106.7552 | I15: =H15/H$4-1 -> -0.2 | J15: =I755 -> 466.95155 | K15: =J15/J$4-1 -> -0.2
A16: 合資群份額年變動取 C（−0.6pt） | B16: dr_jv_C | C16: =F825 -> 536.73468 | D16: =C16/C$4-1 -> 0 | E16: =G825 -> 544.61015 | F16: =E16/E$4-1 -> 0 | G16: =G823 -> 1890.625 | H16: =SUM(O849:R849)+SUM(O850:R850) -> 126.90868 | I16: =H16/H$4-1 -> -0.048974263 | J16: =I825 -> 583.68943 | K16: =J16/J$4-1 -> 0
A17: 情境 B | B17: Mkt 區塊 B | C17: =Mkt!F67 -> 522.07288 | D17: =C17/C$4-1 -> -0.027316653 | E17: =Mkt!G67 -> 242.30569 | F17: =E17/E$4-1 -> -0.55508414 | G17: =Mkt!G65 -> 1739.2146 | H17: =SUM(Mkt!O91:R91)+SUM(Mkt!O92:R92) -> 57.917519 | I17: =H17/H$4-1 -> -0.56597886 | J17: =Mkt!I67 -> 275.32213 | K17: =J17/J$4-1 -> -0.52830716
A18: 情境 C | B18: Mkt 區塊 C | C18: =Mkt!F115 -> 522.07288 | D18: =C18/C$4-1 -> -0.027316653 | E18: =Mkt!G115 -> 174.22825 | F18: =E18/E$4-1 -> -0.6800863 | G18: =Mkt!G113 -> 1527.2146 | H18: =SUM(Mkt!O139:R139)+SUM(Mkt!O140:R140) -> 40.599827 | I18: =H18/H$4-1 -> -0.69575384 | J18: =Mkt!I115 -> 163.54736 | K18: =J18/J$4-1 -> -0.71980415
A20: 讀法：營收以 2Q26 實績為錨，2026Q3 起的變動＝價格指數比 × 位元比；Kioxia、SanDisk 的 2026Q3 份額由公司指引推得，因此改變市場路徑時兩家 2026Q3 營收不變（份額反向調整）。
A40: 案例區塊：每顆容量 −20%（情境 A）
A41: A. 年度（日曆年） | B41: 單位 | C41: CY2024 | D41: CY2025 | E41: CY2026 | F41: CY2027 | G41: CY2028 | H41: CY2029 | I41: CY2030 | AB41: 說明
A42: 加速器顆數（同字母情境係數） | B42: 百萬顆 | E42: =(u_26)*1 -> 15.2 | F42: =(u_27)*1 -> 23.7 | G42: =(u_28)*um28_A -> 26.5 | H42: =(u_28*(1+g_u29))*um29_A -> 30.15 | I42: =(u_28*(1+g_u29)*(1+g_u30))*um29_A -> 31.6575 | AB42: markets/memory UNITS × SCEN_UNITS；2029–30 基準以 g_u29、g_u30 外推，CY2030 沿用 um29
A43: 每顆企業級 SSD 容量 | B43: TB | E43: =tb_26_lo -> 24 | F43: =tb_27_lo -> 27 | G43: =tb_28_lo -> 32 | H43: =tb_29_lo -> 37 | I43: =tb_30_lo -> 42
A44: 需求：AI 企業級 SSD | B44: EB | D44: =bits25*sh_essd25*ai25 -> 165 | E44: =E42*E43 -> 364.8 | F44: =F42*F43 -> 639.9 | G44: =G42*G43 -> 848 | H44: =H42*H43 -> 1115.55 | I44: =I42*I43 -> 1329.615 | AB44: 顆數 × 每顆容量（百萬顆 × TB＝EB）；2025＝基期 × 占比
A45: 需求：非 AI 企業級 SSD | B45: EB | D45: =bits25*sh_essd25*(1-ai25) -> 135 | E45: =D45*(1+g_nai) -> 148.5 | F45: =E45*(1+g_nai) -> 163.35 | G45: =F45*(1+g_nai) -> 179.685 | H45: =G45*(1+g_nai) -> 197.6535 | I45: =H45*(1+g_nai) -> 217.41885
A46: 需求：手機 | B46: EB | D46: =bits25*sh_mob25 -> 320 | E46: =D46*(1+g_mob_26) -> 304 | F46: =E46*(1+g_mob_27) -> 313.12 | G46: =F46*(1+g_mob_28) -> 338.1696 | H46: =G46*(1+g_mob_28) -> 365.22317 | I46: =H46*(1+g_mob_28) -> 394.44102
A47: 需求：PC（client SSD） | B47: EB | D47: =bits25*sh_pc25 -> 230 | E47: =D47*(1+g_pc_26) -> 218.5 | F47: =E47*(1+g_pc_27) -> 218.5 | G47: =F47*(1+g_pc_28) -> 231.61 | H47: =G47*(1+g_pc_28) -> 245.5066 | I47: =H47*(1+g_pc_28) -> 260.237
A48: 需求：消費性與其他 | B48: EB | D48: =bits25*(1-sh_essd25-sh_mob25-sh_pc25) -> 150 | E48: =D48*(1+g_con_26) -> 135 | F48: =E48*(1+g_con_27) -> 135 | G48: =F48*(1+g_con_28) -> 141.75 | H48: =G48*(1+g_con_28) -> 148.8375 | I48: =H48*(1+g_con_28) -> 156.27937
A49: 位元需求合計 | B49: EB | D49: =SUM(D44:D48) -> 1000 | E49: =SUM(E44:E48) -> 1170.8 | F49: =SUM(F44:F48) -> 1469.87 | G49: =SUM(G44:G48) -> 1739.2146 | H49: =SUM(H44:H48) -> 2072.7708 | I49: =SUM(I44:I48) -> 2357.9912
A50: 企業級 SSD 占位元需求 | B50: % | D50: =(D44+D45)/D49 -> 0.3 | E50: =(E44+E45)/E49 -> 0.43841818 | F50: =(F44+F45)/F49 -> 0.5464769 | G50: =(G44+G45)/G49 -> 0.59089028 | H50: =(H44+H45)/H49 -> 0.6335498 | I50: =(I44+I45)/I49 -> 0.65608125
A51: 位元供給（三情境相同） | B51: EB | D51: =bits25 -> 1000 | E51: =D51*(1+gs_26) -> 1210 | F51: =E51*(1+gs_27) -> 1512.5 | G51: =F51*(1+gs_28) -> 1890.625 | H51: =G51*(1+gs_29) -> 2306.5625 | I51: =H51*(1+gs_30) -> 2767.875 | AB51: 2025＝出貨實績（基期）；供給不隨需求情境變（產能 2027 前已訂定），需求不足的結果是閒置產能與降價
A52: 需求 ÷ 供給 − 1（>0＝短缺） | B52: % | E52: =E49/E51-1 -> -0.032396694 | F52: =F49/F51-1 -> -0.028185124 | G52: =G49/G51-1 -> -0.08008484 | H52: =H49/H51-1 -> -0.10135937 | I52: =I49/I51-1 -> -0.14808608
A53: 位元出貨＝MIN(需求, 供給) | B53: EB | C53: =bits25/(1+g25) -> 892.85714 | D53: =bits25 -> 1000 | E53: =MIN(E49,E51) -> 1170.8 | F53: =MIN(F49,F51) -> 1469.87 | G53: =MIN(G49,G51) -> 1739.2146 | H53: =MIN(H49,H51) -> 2072.7708 | I53: =MIN(I49,I51) -> 2357.9912
A54: 位元出貨年增 | B54: % | D54: =D53/C53-1 -> 0.12 | E54: =E53/D53-1 -> 0.1708 | F54: =F53/E53-1 -> 0.25544072 | G54: =G53/F53-1 -> 0.18324382 | H54: =H53/G53-1 -> 0.19178552 | I54: =I53/H53-1 -> 0.13760348
A55: NAND 市場營收（四季合計） | B55: $B | C55: =rev24 -> 67.4 | D55: =SUM(C69:F69) -> 71.103592 | E55: =SUM(G69:J69) -> 340.0642 | F55: =SUM(K69:N69) -> 536.58496 | G55: =SUM(O69:R69) -> 515.86451 | H55: =SUM(S69:V69) -> 527.51186 | I55: =SUM(W69:Z69) -> 529.50958 | AB55: CY2024 為 TrendForce 年度值
A56: 市場營收年增 | B56: % | D56: =D55/C55-1 -> 0.054949442 | E56: =E55/D55-1 -> 3.7826585 | F56: =F55/E55-1 -> 0.5778931 | G56: =G55/F55-1 -> -0.038615403 | H56: =H55/G55-1 -> 0.022578311 | I56: =I55/H55-1 -> 0.0037870646
A57: 平均售價（營收 ÷ 位元出貨） | B57: $/GB | C57: =C55/C53 -> 0.075488 | D57: =D55/D53 -> 0.071103592 | E57: =E55/E53 -> 0.29045456 | F57: =F55/F53 -> 0.36505606 | G57: =G55/G53 -> 0.29660774 | H57: =H55/H53 -> 0.254496 | I57: =I55/I53 -> 0.22455961
A58: 平均售價年變動 | B58: % | D58: =D57/C57-1 -> -0.058080856 | E58: =E57/D57-1 -> 3.0849492 | F58: =F57/E57-1 -> 0.25684396 | G58: =G57/F57-1 -> -0.18750085 | H58: =H57/G57-1 -> -0.1419779 | I58: =I57/H57-1 -> -0.11763011 | AB58: CY2030 為收斂法（p10）＋位元平滑效果
A59: 年度份額：三星 | B59: % | D59: =SUM(C76:F76)/D55 -> 0.30940771 | E59: =SUM(G76:J76)/E55 -> 0.29814637 | F59: =SUM(K76:N76)/F55 -> 0.29314637 | G59: =SUM(O76:R76)/G55 -> 0.28814637 | H59: =SUM(S76:V76)/H55 -> 0.28314637 | I59: =SUM(W76:Z76)/I55 -> 0.27814637
A60: 年度份額：SK 海力士＋Solidigm | B60: % | D60: =SUM(C77:F77)/D55 -> 0.20069309 | E60: =SUM(G77:J77)/E55 -> 0.17773013 | F60: =SUM(K77:N77)/F55 -> 0.17773013 | G60: =SUM(O77:R77)/G55 -> 0.17773013 | H60: =SUM(S77:V77)/H55 -> 0.17773013 | I60: =SUM(W77:Z77)/I55 -> 0.17773013
A61: 年度份額：美光 | B61: % | D61: =SUM(C78:F78)/D55 -> 0.134733 | E61: =SUM(G78:J78)/E55 -> 0.1451191 | F61: =SUM(K78:N78)/F55 -> 0.1471191 | G61: =SUM(O78:R78)/G55 -> 0.1491191 | H61: =SUM(S78:V78)/H55 -> 0.1511191 | I61: =SUM(W78:Z78)/I55 -> 0.1531191
...

Sheet Sources
A1: 來源
A2: markets/memory/market.py：NAND 季價路徑（NAND_COMMON、NAND_S）、加速器顆數 UNITS、情境顆數係數 SCEN_UNITS | B2: 本 repo（單一來源）
A3: TrendForce：2Q26 NAND 前五大營收（2026-08-18） | B3: https://www.trendforce.com/presscenter/news/20260818-13186.html
A4: TrendForce：2Q25 NAND 營收（2025-08-28） | B4: https://www.trendforce.com/presscenter/news/20250828-12688.html
A5: TrendForce：3Q25 NAND 營收（2025-12-03） | B5: https://www.trendforce.com/presscenter/news/20251203-12813.html
A6: TrendForce：4Q25 NAND 營收（I-Connect007 轉載） | B6: https://iconnect007.com/article/149024/ai-server-storage-demand-surges-top-five-nand-flash-suppliers-post-238-qoq-revenue-growth-in-4q25/149021/pcb
A7: TrendForce：2024 NAND 營收 $67.4B（TelecomLead 轉載） | B7: https://telecomlead.com/semiconductor/memory-industry-to-see-significant-revenue-growth-trendforce-117301
A8: TrendForce：2026 供給缺口 4–6%、2H27 平衡、伺服器約 40%（Guru3D 2026-07-21 轉載） | B8: https://www.guru3d.com/story/nand-flash-supply-expected-to-return-to-market-balance-in-2027/
A9: 美光：產業 NAND 位元出貨 CY2026–28（Guru3D 2026-10-01 轉載 FQ4 FY26） | B9: https://www.guru3d.com/story/micron-expects-dram-and-nand-supply-to-tighten-further-through-2028/
A10: Counterpoint：2Q26 企業級 SSD 占位元 48%、位元市占（capitalandcompute、hwbusters 轉載） | B10: https://capitalandcompute.net/blog/why-are-ssds-so-expensive/
A11: SanDisk FQ4 FY26 新聞稿（8-K，2026-08-05） | B11: https://www.sec.gov/Archives/edgar/data/0002023554/000162828026053346/sndkq4-26ex991xpressrelease.htm
A12: Kioxia FY2026 第一季財報（SGX 轉載，2026-07-31） | B12: https://links.sgx.com/1.0.0/corporate-announcements/DOATO9EIE4EEQ2Y8/898078_Earnings-Release-FY2026-1Q-EN.pdf
A13: borecraft：Kioxia 332 層、三星／SK 投片（2026-05-26，轉載 DigiTimes 等；AI 輔助撰寫，弱） | B13: https://borecraft.com/?p=15672
... A16: SemiAnalysis | B16: 未使用
