Workbook

Sheet README
A1: GW 帳 v0.1 — 全市場 AI 資料中心 GW 唯一基準事實（20261028）
A2: 命題：市場總 GW 要與主要玩家 GW 對得上，再與資本支出、GPU／ASIC 顆數、記憶體、電廠與發電機組、電源散熱、AI 投資地圖個股逐環對得上；並加入與需求情景正交的基建延遲情景。
A3: 驅動 → 推導：In（Epoch 晶片功耗、玩家年底 MW、觀測、園區管線、延遲 D0–D2、世代組合、使用者分配）＋ TK_In（每 GW 係數、IF_FacilityGW）＋ SIL_In（顆數、情景係數）→ Players（玩家 × 年 IT GW）→ Matrix（營運者 × 使用者）→ Pipeline（上線事件 × 延遲）→ Deploy（需求 × 延遲 3×3）→ C0／C1／Compare（對帳）→ Interface（GIF_）→ Checks（GGOV_Errors＝0）。
A4: 單位（規劃書 r1）：主口徑 IT GW＝TK GW（IT 關鍵電力）；設施電力＝IT × TK IF_FacilityGW（1.2）。公司標設施者 ÷ IF_FacilityGW；口徑未說明者基準取 IT 讀法，Players 另列設施讀法；Epoch 晶片功耗 × k_chip2it。
A5: 頁面：README｜In 輸入｜TK_In、SIL_In 鏡像（綠字）｜Players 玩家 × 年｜Matrix 營運者 × 使用者｜Pipeline 園區管線 × 延遲｜Deploy 市場總 GW 需求 × 延遲｜C0 由下而上 vs 第三方｜C1 資本支出對帳｜Compare 與 Siliconomics 成本等值 GW｜Interface GIF_｜Checks｜Decisions｜DB_Evidence｜Sources｜Requests。
A6: v0.1 範圍：C0、C1、延遲管線（D0–D2）、GIF_ 輸出；C2–C7 自 v0.2 起。第 2 階段：填入 evidence_raw 證據（只用 C 段判屬實或已更正的列；DB_Evidence 頁列全部證據與判定），延遲參數依 B_delay 校準。
A7: 第 3 階段：新增 CapexGW 頁（甲2：資本支出推得 GW；MSFT、GOOGL、AMZN、META、ORCL、CRWV、NBIS 2027 起進主路徑）；Interface 另出 _SiteOnly（只有 甲）；GIF_Coverage_<yyyy>。下游取用 2027 年後數值前看覆蓋率。
A8: 顏色：藍字＝輸入；黑字＝公式；綠字＝跨頁或外部鏡像；淡黃底＝關鍵輸出；亮黃底＝待證據或預設待決。
A9: Excel 優先：要改輸入，直接改 In 頁藍字；builder 重建時讀回（--base）。公式頁不要手改。下游只讀 Interface 的 GIF_ 名稱（經快照）。
A10: 版本命名：YYYYMMDD_GWLedger_vX.Y.xlsx；model/CURRENT 記錄現行檔名；data/CURRENT_SNAPSHOT 指向現行快照。

Sheet In
A1: In — GW 帳輸入（藍字＝輸入，由本活頁簿擁有；要改值直接改本頁，builder 重建時以 --base 讀回）。純量列：H／I／J＝低／基準／高，具名範圍＝鍵（I 欄）；年度列：H–Q＝2023–2032；T1 分配表、T2 園區表見節標題
A2: 標記：Verified／Interested-party（寫明是誰）／Analogy／Assumed（給低／高）／Derived（寫明換算）／待證據（值留空）。來源 ID 見 Sources 頁；說明欄的 A#n／B#n／D#n＝evidence_raw 列號（DB_Evidence 頁，含 C 段判定）。口徑：IT／設施／未說明／晶片（主口徑 IT GW；設施 ÷ IF_FacilityGW；未說明者基準取 IT 讀法）。S 欄＝輸入列類型（治理檢查用）
A4: 鍵 | B4: 項目 | C4: 口徑 | D4: 單位 | E4: 標記 | F4: 來源 ID | G4: 說明 | H4: 2023 | I4: 2024 | J4: 2025 | K4: 2026 | L4: 2027 | M4: 2028 | N4: 2029 | O4: 2030 | P4: 2031 | Q4: 2032 | S4: 類型
A5: S1. 單位換算與共用參數（主口徑 IT GW＝TK GW；設施電力＝IT × TK IF_FacilityGW）
A6: g_ITtoFac | B6: 公司 IT 值 → GW 帳主口徑（IT→IT）換算係數 | C6: — | D6: x | E6: Derived | F6: SRC_GL_003 | G6: Requests R1 裁定（2026-10-28）：TK Interface 每 GW＝IT 關鍵電力，主口徑＝IT GW，係數＝1；設施電力另列＝IT × TK_FacilityGW（TK_In） | I6: 1 | S6: 1
A7: k_chip2it | B7: Epoch 晶片功耗 → IT 電力換算係數 | C7: — | D7: x | E7: Analogy | F7: SRC_GL_203 | G7: 低 1.65＝repo mw.conv.itPerTdp；高 2.08＝Epoch 設施係數 2.5 ÷ 1.2；C 段 6.4：A 段 × 1.98 與 Epoch × 2.5 不一致 | H7: 1.65 | I7: 1.85 | J7: 2.08 | S7: 1
A8: asof | B8: 評價時點（小數年；2026-10-28） | C8: — | D8: 年 | E8: Derived | F8: SRC_GL_004 | G8: 2026 ＋（9 ＋ 28/31）÷ 12；延遲只作用於此時點之後的上線量 | I8: 2026.825 | S8: 1
A9: tolband | B9: 對帳容許帶（±） | C9: — | D9: % | E9: Assumed | F9: SRC_GL_003 | G9: 規劃書 G6 預設 ±15% | H9: 0.1 | I9: 0.15 | J9: 0.2 | S9: 1
A10: lag_bldg | B10: 建物資本支出提前入帳月數 | C10: — | D10: 月 | E10: Assumed | F10: SRC_GL_004 | G10: 工作單 C1：12–24 月；D#14 建物工期 12–24 月（屬實） | H10: 12 | I10: 18 | J10: 24 | S10: 1
A11: g_lt | B11: 長期年新增 GW 成長率（2030–2032 收斂目標） | C11: — | D11: % | E11: Assumed | F11: SRC_GL_004 | G11: 工作單 Deploy：2029 年增率線性收斂到長期成長率（chat 端第 2 階段指示） | H11: 0.05 | I11: 0.1 | J11: 0.15 | S11: 1
A12: S1b. 甲2 資本支出推得 GW（MSFT、GOOGL、AMZN、META、ORCL、CRWV、NBIS；2027 起主路徑）
A13: ai_sh | B13: 資本支出 AI 占比（全公司資本支出中用於 AI 資料中心的比例；各家未覆寫者） | C13: — | D13: % | E13: Assumed | F13: SRC_GL_004 | G13: chat 端第 3 階段指示 1；依證據逐家覆寫見 ai_<玩家> | H13: 0.75 | I13: 0.85 | J13: 0.95 | S13: 1
A14: ai_amzn | B14: Amazon 資本支出 AI 占比覆寫（AWS 占淨增加比） | C14: — | D14: % | E14: Derived | F14: SRC_GL_030 | G14: amazon/company.json mag.capex.netAddBySegFY FY2025：AWS 96.5 ÷ 全公司 142.4＝0.68（零售物流非 AI）；AWS 內 AI 占比未知，以 AWS 占比代（偏高） | H14: 0.6 | I14: 0.68 | J14: 0.75 | S14: 1
A15: cap_g_ext | B15: 個股模型最後一年之後的資本支出年增（甲2 外推） | C15: — | D15: % | E15: Assumed | F15: SRC_GL_004 | G15: 共識只到 FY28–FY29（Meta 只有 2026 指引）；之後以本值外推，基準＝g_lt；最早一年之前取最早值 | H15: 0 | I15: 0.1 | J15: 0.15 | S15: 1
A16: S1c. 中國 2027 年後路徑（Rystad：容量 × AI 占比，幾何／線性內插；2031–32 用 g_lt）
A17: cn_tot26 | B17: 中國資料中心總容量 2026 年底 | C17: 未說明 | D17: GW | E17: Analogy | F17: SRC_GL_201 | G17: B#51（屬實；Rystad）；單一來源（Rystad），區間 ±10% [Assumed]；Players 用基準 | H17: 36 | I17: 40 | J17: 44 | S17: 1
A18: cn_tot30 | B18: 中國資料中心總容量 2030 | C18: 未說明 | D18: GW | E18: Analogy | F18: SRC_GL_201 | G18: B#51（屬實；Rystad >60 GW 取下限）；單一來源（Rystad），區間 60–70（Rystad「>60」） [Assumed]；Players 用基準 | H18: 60 | I18: 60 | J18: 70 | S18: 1
A19: cn_sh26 | B19: 中國 AI／HPC 占比 2026 | C19: — | D19: % | E19: Analogy | F19: SRC_GL_201 | G19: B#51（屬實；Rystad）；單一來源（Rystad），區間 ±10% [Assumed]；Players 用基準 | H19: 0.351 | I19: 0.39 | J19: 0.429 | S19: 1
A20: cn_sh30 | B20: 中國 AI／HPC 占比 2030 | C20: — | D20: % | E20: Analogy | F20: SRC_GL_201 | G20: B#51（屬實；Rystad）。中國 2027–30＝2026 年底 × (容量 × 占比) 比值，容量幾何內插、占比線性內插 [Assumed]；單一來源（Rystad），區間 ±10% [Assumed]；Players 用基準 | H20: 0.432 | I20: 0.48 | J20: 0.528 | S20: 1
A21: S2. 基建延遲參數（D0 準時；D1 基準延遲；D2 嚴重延遲）
A22: dly_d1_s | B22: D1：每年排定新 GW 延後的比例 | C22: — | D22: % | E22: Derived | F22: SRC_GL_202 | G22: D#15（Sightline，屬實）：2025 26%（容量）延遲；2026 預測 30–50%；取中下。另 10%（專案數）延後商轉，單位不同不可相加（C 段第 2 節） | H22: 0.25 | I22: 0.35 | J22: 0.45 | S22: 1
A23: dly_d1_m | B23: D1：延後量的延遲月數 | C23: — | D23: 月 | E23: Derived | F23: SRC_GL_202 | G23: D#16、D#18、D#19（已排定案例 3–12 月：Oracle 部分站 12、Denton 約 6〔無法核對〕、Nebius NJ 6–7） | H23: 3 | I23: 6 | J23: 12 | S23: 1
A24: dly_d2_bind | B24: D2：2027–28 未確保電力的新 GW 再延比例 | C24: — | D24: % | E24: Derived | F24: SRC_GL_202 | G24: D#2、D#3、D#5（併網 48–60 月）、D#7、D#8（渦輪 ≥36 月）、D#11（升壓變壓器 37 月）長於建物工期 D#14；反證 D#25（表後發電）、D#7（許多案子渦輪不卡關）→ 不高於 50% | H24: 0.3 | I24: 0.4 | J24: 0.5 | S24: 1
A25: dly_d2_m | B25: D2：綁定部分再延月數 | C25: — | D25: 月 | E25: Derived | F25: SRC_GL_202 | G25: B_summary 5.3：再延 12 個月 | H25: 12 | I25: 12 | J25: 12 | S25: 1
A26: dly_d2_y0 | B26: D2 適用起年（原排定上線年） | C26: — | D26: 年 | E26: Derived | F26: SRC_GL_202 | G26: B_summary 5.3：2027–2028 新增 GW | I26: 2027 | S26: 1
A27: dly_d2_y1 | B27: D2 適用迄年（原排定上線年） | C27: — | D27: 年 | E27: Derived | F27: SRC_GL_202 | G27: 同上 | I27: 2028 | S27: 1
A28: S3. 玩家最新觀測（觀測年：年底值＝觀測值＋觀測後至年底的園區上線量）
A29: obs_msft | B29: Microsoft 自有 AI 在役 MW-IT（FY26 末） | C29: IT | D29: MW | E29: Derived／Assumed | F29: SRC_GL_010 | G29: microsoft/company.json mag.mw.aiOpenIT（三法交叉，未用營收）；A#13 同值 | H29: 3500 | I29: 4500 | J29: 5500 | S29: 1
A30: obsd_msft | B30: Microsoft 觀測時點 | C30: — | D30: 年 | E30: Verified | F30: SRC_GL_010 | G30: 2026-06-30 | I30: 2026.5 | S30: 1
A31: obschip_googl | B31: Alphabet 晶片功耗（2026Q2；× Google 倍數＝IT） | C31: 晶片 | D31: MW | E31: Derived | F31: SRC_GL_020 | G31: alphabet/company.json scenarios.mwPath.note（repo 由 Epoch AI Chip Owners 晶片功耗整理 3,841 MW）；IT＝本值 × Google 倍數（ovr25_googl ÷ 2025 晶片功耗），原 × 1.65＝6,338 | I31: 3841 | S31: 1
A32: obsd_googl | B32: Alphabet 觀測時點 | C32: — | D32: 年 | E32: Verified | F32: SRC_GL_020 | G32: 2026-06-30 | I32: 2026.5 | S32: 1
A33: obs_amzn | B33: Amazon AI 在役 MW-IT（2026Q2） | C33: IT | D33: MW | E33: Derived／Assumed | F33: SRC_GL_030 | G33: amazon/company.json mag.mw.aiInServiceIT（第三方估計）；A#40 同值 | H33: 2000 | I33: 2600 | J33: 3300 | S33: 1
A34: obsd_amzn | B34: Amazon 觀測時點 | C34: — | D34: 年 | E34: Verified | F34: SRC_GL_030 | G34: 2026-06-30 | I34: 2026.5 | S34: 1
A35: obs_orcl | B35: Oracle 已連網 MW-IT（FY27Q1 末） | C35: IT | D35: MW | E35: Derived | F35: SRC_GL_040 | G35: oracle/company.json fleet.openMw（FY26 末 1,835＋Q1 交付 850 ÷ 1.2）；A#64、A#65（屬實） | I35: 2543 | S35: 1
A36: obsd_orcl | B36: Oracle 觀測時點 | C36: — | D36: 年 | E36: Verified | F36: SRC_GL_040 | G36: 2026-08-31 | I36: 2026.667 | S36: 1
A37: obs_crwv | B37: CoreWeave active power MW（2026Q2） | C37: IT | D37: MW | E37: Interested-party | F37: SRC_GL_050 | G37: A#81（屬實）；2026 年底已有指引值，本觀測不進計算 | I37: 1500 | S37: 1
A38: obsd_crwv | B38: CoreWeave 觀測時點 | C38: — | D38: 年 | E38: Verified | F38: SRC_GL_050 | G38: 2026-06-30 | I38: 2026.5 | S38: 1
A39: obs_xai | B39: SpaceX／xAI nameplate compute（2026Q2） | C39: 未說明 | D39: MW | E39: Interested-party | F39: SRC_GL_201 | G39: B#46（屬實；SpaceX 季報，剛上市）；2026 年底已有目標值，本觀測不進計算 | I39: 1400 | S39: 1
A40: obsd_xai | B40: SpaceX／xAI 觀測時點 | C40: — | D40: 年 | E40: Verified | F40: SRC_GL_201 | G40: 2026-06-30 | I40: 2026.5 | S40: 1
A41: S3b. 2025 年底 IT 覆寫與區間（C 段更正；Epoch 推得者另依 k_chip2it 區間）
...

Sheet TK_In
A1: TK_In — Tokenomics 取數（只讀鏡像；權威在 Tokenomics）：20261025_Tokenomics_v21.7.xlsx（v21.7，commit 91d541f，擷取 2026-10-27）。同一份快照與 Siliconomics 相同（siliconomics/data/tokenomics_snapshot_v21.7.json），不另抽；綠字不得修改
A2: 快照註記：主值取「基準」成本情境；低成本／高成本只作敏感度。每 GW＝IT 關鍵電力（Tokenomics Interface 第 1 列）。
A4: 名稱（TK） | B4: 世代／項目 | C4: 本庫名稱 | D4: 低 | E4: 基準 | F4: 高 | G4: 單位 | H4: TK 位置
A5: IF_RacksPerGW | B5: Hopper H100 | C5: TK_RacksPerGW_H100 | D5: 22439 | E5: 22439 | F5: 22439 | G5: 架 | H5: Interface!C6:Q6
A6: IF_RacksPerGW | B6: GB200 NVL72 | C6: TK_RacksPerGW_GB200 | D6: 6969 | E6: 6969 | F6: 6969 | G6: 架 | H6: Interface!C6:Q6
A7: IF_RacksPerGW | B7: GB300 NVL72 | C7: TK_RacksPerGW_GB300 | D7: 6764 | E7: 6764 | F7: 6764 | G7: 架 | H7: Interface!C6:Q6
A8: IF_RacksPerGW | B8: VR200 NVL72 | C8: TK_RacksPerGW_VR200 | D8: 4052 | E8: 4052 | F8: 4052 | G8: 架 | H8: Interface!C6:Q6
A9: IF_RacksPerGW | B9: Rubin Ultra（MGX NVL 單架，72 GPU） | C9: TK_RacksPerGW_RU | D9: 2705 | E9: 2705 | F9: 2705 | G9: 架 | H9: Interface!C6:Q6
A10: IF_GPUsPerGW | B10: Hopper H100 | C10: TK_GPUsPerGW_H100 | D10: 718048 | E10: 718048 | F10: 718048 | G10: 顆 | H10: Interface!C7:Q7
A11: IF_GPUsPerGW | B11: GB200 NVL72 | C11: TK_GPUsPerGW_GB200 | D11: 501768 | E11: 501768 | F11: 501768 | G11: 顆 | H11: Interface!C7:Q7
A12: IF_GPUsPerGW | B12: GB300 NVL72 | C12: TK_GPUsPerGW_GB300 | D12: 487008 | E12: 487008 | F12: 487008 | G12: 顆 | H12: Interface!C7:Q7
A13: IF_GPUsPerGW | B13: VR200 NVL72 | C13: TK_GPUsPerGW_VR200 | D13: 291744 | E13: 291744 | F13: 291744 | G13: 顆 | H13: Interface!C7:Q7
A14: IF_GPUsPerGW | B14: Rubin Ultra（MGX NVL 單架，72 GPU） | C14: TK_GPUsPerGW_RU | D14: 194760 | E14: 194760 | F14: 194760 | G14: 顆 | H14: Interface!C7:Q7
A15: IF_CapexIT | B15: Hopper H100 | C15: TK_CapexIT_H100 | D15: 21.420269 | E15: 27.510214 | F15: 34.120743 | G15: $B | H15: Interface!C9:Q9
A16: IF_CapexIT | B16: GB200 NVL72 | C16: TK_CapexIT_GB200 | D16: 20.63939 | E16: 24.015174 | F16: 27.650204 | G16: $B | H16: Interface!C9:Q9
... A63: IF_FacilityGW | B63: Rubin Ultra（MGX NVL 單架，72 GPU） | C63: TK_FacilityGW_RU | D63: 1.1 | E63: 1.2 | F63: 1.3 | G63: GW | H63: model/20261025_Tokenomics_v21.7.xlsx Interface!C8:Q8（快照未含；直接讀活頁簿，commit 730b6a5，SRC_GL_006）

Sheet SIL_In
A1: SIL_In — Siliconomics 取數（只讀鏡像；權威在 AI半導體）：20261028_Siliconomics_v0.7.1.xlsx（v0.7.1，sha256 54b59045b9ac）。由 siliconomics/data/CURRENT_SNAPSHOT 指向；綠字不得修改
A3: 名稱（SIF_） | B3: 本庫名稱 | C3: 單位 | D3: 值（純量）／2023 | E3: 2024 | F3: 2025 | G3: 2026 | H3: 2027 | I3: 2028 | J3: 2029 | K3: 2030 | L3: 2031 | M3: 2032
A4: A. 純量
A5: SIF_vr26 | B5: SIL_vr26 | C5: x | D5: 0.22
A6: SIF_vr26_lo | B6: SIL_vr26_lo | C6: x | D6: 0.15
A7: SIF_vr26_hi | B7: SIL_vr26_hi | C7: x | D7: 0.3
A8: SIF_it_GB | B8: SIL_it_GB | C8: US$K／顆 | D8: 66.194444
A9: SIF_it_VR | B9: SIL_it_VR | C9: US$K／顆 | D9: 128.83333
A10: SIF_it_RU | B10: SIL_it_RU | C10: US$K／顆 | D10: 257.16667
A11: SIF_it_HP | B11: SIL_it_HP | C11: US$K／顆 | D11: 38.3125
A12: SIF_it_AMD8 | B12: SIL_it_AMD8 | C12: US$K／顆 | D12: 40
A13: SIF_it_AMDR | B13: SIL_it_AMDR | C13: US$K／顆 | D13: 100
A14: SIF_it_TPU | B14: SIL_it_TPU | C14: US$K／顆 | D14: 25
A15: SIF_it_TRN | B15: SIL_it_TRN | C15: US$K／顆 | D15: 20
A16: SIF_it_ASIC | B16: SIL_it_ASIC | C16: US$K／顆 | D16: 20
A18: B. 年度（欄 D–M＝2023–2032；Siliconomics 只到 2029）
A19: SIF_UnitsPlat_bw | C19: 百萬顆 | G19: 5.4 | H19: 2.4 | I19: 0.5 | J19: 0.25
A20: SIF_UnitsPlat_rb | C20: 百萬顆 | G20: 1.7 | H20: 7 | I20: 7 | J20: 8.05
A21: SIF_UnitsPlat_ru | C21: 百萬顆 | G21: 0 | H21: 0.3 | I21: 2 | J21: 2.3
A22: SIF_UnitsPlat_hp | C22: 百萬顆 | G22: 0.5 | H22: 0 | I22: 0 | J22: 0
A23: SIF_UnitsPlat_amd | C23: 百萬顆 | G23: 0.75 | H23: 1.5 | I23: 2 | J23: 2.3
A24: SIF_UnitsPlat_tpu | C24: 百萬顆 | G24: 3.85 | H24: 5.5 | I24: 7 | J24: 8.05
A25: SIF_UnitsPlat_trn | C25: 百萬顆 | G25: 2 | H25: 2.5 | I25: 3 | J25: 3.45
A26: SIF_UnitsPlat_oth | C26: 百萬顆 | G26: 1 | H26: 4.5 | I26: 5 | J26: 5.75
A27: SIF_UnitsCoef_A | C27: x | G27: 1 | H27: 1 | I27: 1 | J27: 1
A28: SIF_UnitsCoef_B | C28: x | G28: 1 | H28: 1 | I28: 0.8 | J28: 0.85
A29: SIF_UnitsCoef_C | C29: x | G29: 1 | H29: 1 | I29: 0.6 | J29: 0.6
A30: SIF_DeployGW_A | C30: GW（成本等值） | G30: 23.399538 | H30: 41.646766 | I30: 52.792138 | J30: 60.138592
... A36: SIF_ITCapexPerGW | C36: US$B/GW | G36: 33.414032 | H36: 37.586352 | I36: 37.586352 | J36: 37.586352

Sheet Players
A1: Players — 玩家 × 年（2023–2032）年底上線 IT GW（＝TK GW；甲：公告路徑；營運者口徑）。已知值優先序：In Y1 輸入（設施 ÷ IF_FacilityGW）→ Y0 晶片功耗 × 倍數 → S3 觀測＋觀測後至年底的 T2 園區上線量；兩已知值間線性內插；最後已知值後＝前年＋當年 T2 園區（D0）；第一個已知值前留空（GL01-03）
A2: 旗標：1 輸入／5 晶片換算／2 觀測／3 內插／4 園區延伸／0 未知。年新增＝年底差（第一個已知年為『新納入存量』，不計新增）。低／高列：晶片換算用 k_chip2it 區間或 C 段區間，其餘＝基準
A3: 項目 | B3: 鍵 | C3: 單位 | D3: 2023 | E3: 2024 | F3: 2025 | G3: 2026 | H3: 2027 | I3: 2028 | J3: 2029 | K3: 2030 | L3: 2031 | M3: 2032 | N3: 說明
A4: 世代組合（新增 GW；NVIDIA 內部占比）與換算係數
A5: 世代占比：Hopper H100 | B5: mix_H100 | C5: % | D5: =IF(In!$H$142<>"",In!$H$142,0) -> 1 | E5: =IF(In!$I$142<>"",In!$I$142,0) -> 1 | F5: =IF(In!$J$142<>"",In!$J$142,0) -> 0.1 | G5: =IF(In!$K$142<>"",In!$K$142,0) -> 0 | H5: =IF(In!$L$142<>"",In!$L$142,0) -> 0 | I5: =IF(In!$M$142<>"",In!$M$142,0) -> 0 | J5: =IF(In!$N$142<>"",In!$N$142,0) -> 0 | K5: =IF(In!$O$142<>"",In!$O$142,J5) -> 0 | L5: =IF(In!$P$142<>"",In!$P$142,J5) -> 0 | M5: =IF(In!$Q$142<>"",In!$Q$142,J5) -> 0
A6: 世代占比：GB200 NVL72 | B6: mix_GB200 | C6: % | D6: =IF(In!$H$143<>"",In!$H$143,0) -> 0 | E6: =IF(In!$I$143<>"",In!$I$143,0) -> 0 | F6: =IF(In!$J$143<>"",In!$J$143,0) -> 0.7 | G6: =IF(In!$K$143<>"",In!$K$143,0) -> 0 | H6: =IF(In!$L$143<>"",In!$L$143,0) -> 0 | I6: =IF(In!$M$143<>"",In!$M$143,0) -> 0 | J6: =IF(In!$N$143<>"",In!$N$143,0) -> 0 | K6: =IF(In!$O$143<>"",In!$O$143,J6) -> 0 | L6: =IF(In!$P$143<>"",In!$P$143,J6) -> 0 | M6: =IF(In!$Q$143<>"",In!$Q$143,J6) -> 0
A7: 世代占比：GB300 NVL72 | B7: mix_GB300 | C7: % | D7: =IF(In!$H$144<>"",In!$H$144,0) -> 0 | E7: =IF(In!$I$144<>"",In!$I$144,0) -> 0 | F7: =IF(In!$J$144<>"",In!$J$144,0) -> 0.2 | G7: =IF(In!$K$144<>"",In!$K$144,(1-SIL_vr26)) -> 0.78 | H7: =IF(In!$L$144<>"",In!$L$144,0) -> 0 | I7: =IF(In!$M$144<>"",In!$M$144,0) -> 0 | J7: =IF(In!$N$144<>"",In!$N$144,0) -> 0 | K7: =IF(In!$O$144<>"",In!$O$144,J7) -> 0 | L7: =IF(In!$P$144<>"",In!$P$144,J7) -> 0 | M7: =IF(In!$Q$144<>"",In!$Q$144,J7) -> 0
A8: 世代占比：VR200 NVL72 | B8: mix_VR200 | C8: % | D8: =IF(In!$H$145<>"",In!$H$145,0) -> 0 | E8: =IF(In!$I$145<>"",In!$I$145,0) -> 0 | F8: =IF(In!$J$145<>"",In!$J$145,0) -> 0 | G8: =IF(In!$K$145<>"",In!$K$145,SIL_vr26) -> 0.22 | H8: =IF(In!$L$145<>"",In!$L$145,(1-H$11)) -> 0.93967425 | I8: =IF(In!$M$145<>"",In!$M$145,(1-I$11)) -> 0.70028477 | J8: =IF(In!$N$145<>"",In!$N$145,(1-J$11)) -> 0.70028477 | K8: =IF(In!$O$145<>"",In!$O$145,J8) -> 0.70028477 | L8: =IF(In!$P$145<>"",In!$P$145,J8) -> 0.70028477 | M8: =IF(In!$Q$145<>"",In!$Q$145,J8) -> 0.70028477
A9: 世代占比：Rubin Ultra | B9: mix_RU | C9: % | D9: =IF(In!$H$146<>"",In!$H$146,0) -> 0 | E9: =IF(In!$I$146<>"",In!$I$146,0) -> 0 | F9: =IF(In!$J$146<>"",In!$J$146,0) -> 0 | G9: =IF(In!$K$146<>"",In!$K$146,0) -> 0 | H9: =IF(In!$L$146<>"",In!$L$146,H$11) -> 0.060325747 | I9: =IF(In!$M$146<>"",In!$M$146,I$11) -> 0.29971523 | J9: =IF(In!$N$146<>"",In!$N$146,J$11) -> 0.29971523 | K9: =IF(In!$O$146<>"",In!$O$146,J9) -> 0.29971523 | L9: =IF(In!$P$146<>"",In!$P$146,J9) -> 0.29971523 | M9: =IF(In!$Q$146<>"",In!$Q$146,J9) -> 0.29971523
A10: 世代占比合計（須＝1） | C10: % | D10: =SUM(D5:D9) -> 1 | E10: =SUM(E5:E9) -> 1 | F10: =SUM(F5:F9) -> 1 | G10: =SUM(G5:G9) -> 1 | H10: =SUM(H5:H9) -> 1 | I10: =SUM(I5:I9) -> 1 | J10: =SUM(J5:J9) -> 1 | K10: =SUM(K5:K9) -> 1 | ... M10: =SUM(M5:M9) -> 1
A11: Rubin Ultra 占 Rubin 平台 GW 比（Derived：Units ÷ TK 每 GW GPU 數） | C11: % | H11: =(SIL_In!$H$21/TK_GPUsPerGW_RU)/(SIL_In!$H$20/TK_GPUsPerGW_VR200+SIL_In!$H$21/TK_GPUsPerGW_RU) -> 0.060325747 | I11: =(SIL_In!$I$21/TK_GPUsPerGW_RU)/(SIL_In!$I$20/TK_GPUsPerGW_VR200+SIL_In!$I$21/TK_GPUsPerGW_RU) -> 0.29971523 | J11: =(SIL_In!$J$21/TK_GPUsPerGW_RU)/(SIL_In!$J$20/TK_GPUsPerGW_VR200+SIL_In!$J$21/TK_GPUsPerGW_RU) -> 0.29971523 | N11: 工作單：Rubin Ultra 比例讀 Siliconomics Units；以每 GW GPU 數換成 GW 占比（GL01-11）；2027 Blackwell 2.4M 顆不計（工作單：2027 起 VR200）
A12: 市場新增 GW 非 NVIDIA 占比 | B12: nnv_mkt | C12: % | D12: =IF(In!$H$147<>"",In!$H$147,G12) -> 0.23821007 | E12: =IF(In!$I$147<>"",In!$I$147,G12) -> 0.23821007 | F12: =IF(In!$J$147<>"",In!$J$147,G12) -> 0.23821007 | G12: =IF(In!$K$147<>"",In!$K$147,(SIL_In!$G$23*SIL_it_AMD8+SIL_In!$G$24*SIL_it_TPU+SIL_In!$G$25*SIL_it_TRN+SIL_In!$G$26*SIL_it_ASIC)/((SIL_In!$G$23*SIL_it_AMD8+SIL_In!$G$24*SIL_it_TPU+SIL_In!$G$25*SIL_it_TRN+SIL_In!$G$26*SIL_it_ASIC)+(SIL_In!$G$19*SIL_it_GB+SIL_In!$G$20*SIL_it_VR+SIL_In!$G$21*SIL_it_RU+SIL_In!$G$22*SIL_it_HP))) -> 0.23821007 | H12: =IF(In!$L$147<>"",In!$L$147,(SIL_In!$H$23*SIL_it_AMDR+SIL_In!$H$24*SIL_it_TPU+SIL_In!$H$25*SIL_it_TRN+SIL_In!$H$26*SIL_it_ASIC)/((SIL_In!$H$23*SIL_it_AMDR+SIL_In!$H$24*SIL_it_TPU+SIL_In!$H$25*SIL_it_TRN+SIL_In!$H$26*SIL_it_ASIC)+(SIL_In!$H$19*SIL_it_GB+SIL_In!$H$20*SIL_it_VR+SIL_In!$H$21*SIL_it_RU+SIL_In!$H$22*SIL_it_HP))) -> 0.27310186 | I12: =IF(In!$M$147<>"",In!$M$147,(SIL_In!$I$23*SIL_it_AMDR+SIL_In!$I$24*SIL_it_TPU+SIL_In!$I$25*SIL_it_TRN+SIL_In!$I$26*SIL_it_ASIC)/((SIL_In!$I$23*SIL_it_AMDR+SIL_In!$I$24*SIL_it_TPU+SIL_In!$I$25*SIL_it_TRN+SIL_In!$I$26*SIL_it_ASIC)+(SIL_In!$I$19*SIL_it_GB+SIL_In!$I$20*SIL_it_VR+SIL_In!$I$21*SIL_it_RU+SIL_In!$I$22*SIL_it_HP))) -> 0.2696214 | J12: =IF(In!$N$147<>"",In!$N$147,(SIL_In!$J$23*SIL_it_AMDR+SIL_In!$J$24*SIL_it_TPU+SIL_In!$J$25*SIL_it_TRN+SIL_In!$J$26*SIL_it_ASIC)/((SIL_In!$J$23*SIL_it_AMDR+SIL_In!$J$24*SIL_it_TPU+SIL_In!$J$25*SIL_it_TRN+SIL_In!$J$26*SIL_it_ASIC)+(SIL_In!$J$19*SIL_it_GB+SIL_In!$J$20*SIL_it_VR+SIL_In!$J$21*SIL_it_RU+SIL_In!$J$22*SIL_it_HP))) -> 0.27218751 | K12: =IF(In!$O$147<>"",In!$O$147,J12) -> 0.27218751 | L12: =IF(In!$P$147<>"",In!$P$147,J12) -> 0.27218751 | M12: =IF(In!$Q$147<>"",In!$Q$147,J12) -> 0.27218751 | N12: Derived：Siliconomics Units 非 NVIDIA 平台 IT capex 占比（工作單第 2 節）；2023–25 沿用 2026（待決）、2030–32 沿用 2029
A13: 每 IT GW 對應設施電力（TK IF_FacilityGW，世代加權） | C13: x | D13: =D5*TK_FacilityGW_H100+D6*TK_FacilityGW_GB200+D7*TK_FacilityGW_GB300+D8*TK_FacilityGW_VR200+D9*TK_FacilityGW_RU -> 1.2 | E13: =E5*TK_FacilityGW_H100+E6*TK_FacilityGW_GB200+E7*TK_FacilityGW_GB300+E8*TK_FacilityGW_VR200+E9*TK_FacilityGW_RU -> 1.2 | F13: =F5*TK_FacilityGW_H100+F6*TK_FacilityGW_GB200+F7*TK_FacilityGW_GB300+F8*TK_FacilityGW_VR200+F9*TK_FacilityGW_RU -> 1.2 | G13: =G5*TK_FacilityGW_H100+G6*TK_FacilityGW_GB200+G7*TK_FacilityGW_GB300+G8*TK_FacilityGW_VR200+G9*TK_FacilityGW_RU -> 1.2 | H13: =H5*TK_FacilityGW_H100+H6*TK_FacilityGW_GB200+H7*TK_FacilityGW_GB300+H8*TK_FacilityGW_VR200+H9*TK_FacilityGW_RU -> 1.2 | I13: =I5*TK_FacilityGW_H100+I6*TK_FacilityGW_GB200+I7*TK_FacilityGW_GB300+I8*TK_FacilityGW_VR200+I9*TK_FacilityGW_RU -> 1.2 | J13: =J5*TK_FacilityGW_H100+J6*TK_FacilityGW_GB200+J7*TK_FacilityGW_GB300+J8*TK_FacilityGW_VR200+J9*TK_FacilityGW_RU -> 1.2 | K13: =K5*TK_FacilityGW_H100+K6*TK_FacilityGW_GB200+K7*TK_FacilityGW_GB300+K8*TK_FacilityGW_VR200+K9*TK_FacilityGW_RU -> 1.2 | ... M13: =M5*TK_FacilityGW_H100+M6*TK_FacilityGW_GB200+M7*TK_FacilityGW_GB300+M8*TK_FacilityGW_VR200+M9*TK_FacilityGW_RU -> 1.2 | N13: TK_In（Tokenomics v21.7 Interface 第 8 列；快照未含，直接讀活頁簿，SRC_GL_006）；非 NVIDIA 以 NVIDIA 世代加權近似
A14: 晶片 → IT 倍數：Microsoft（自有＋融資租賃 AI 在役） | B14: mult_msft | C14: x | D14: =k_chip2it -> 1.85 | E14: =k_chip2it_lo -> 1.65 | F14: =k_chip2it_hi -> 2.08 | N14: k_chip2it（D＝基準、E＝低、F＝高）
A15: 晶片 → IT 倍數：Alphabet（Google；TPU＋NVIDIA） | B15: mult_googl | C15: x | D15: =ovr25_googl/In!$J$82 -> 1.4560477 | E15: =ovr25_googl_lo/In!$J$82 -> 1.3206014 | F15: =ovr25_googl_hi/In!$J$82 -> 1.6592171 | N15: C 段 2025 更正值 ovr25_googl ÷ 2025 晶片功耗（D＝基準、E＝低、F＝高）
A16: 晶片 → IT 倍數：Amazon（AWS；Trainium＋NVIDIA） | B16: mult_amzn | C16: x | D16: =ovr25_amzn/In!$J$83 -> 1.3153961 | E16: =ovr25_amzn_lo/In!$J$83 -> 1.1360239 | F16: =ovr25_amzn_hi/In!$J$83 -> 1.554559 | N16: C 段 2025 更正值 ovr25_amzn ÷ 2025 晶片功耗（D＝基準、E＝低、F＝高）
A17: 晶片 → IT 倍數：Meta | B17: mult_meta | C17: x | D17: =k_chip2it -> 1.85 | E17: =k_chip2it_lo -> 1.65 | F17: =k_chip2it_hi -> 2.08 | N17: k_chip2it（D＝基準、E＝低、F＝高）
A18: 晶片 → IT 倍數：Oracle（OCI；含承租 Stargate 站點） | B18: mult_orcl | C18: x | D18: =k_chip2it -> 1.85 | E18: =k_chip2it_lo -> 1.65 | F18: =k_chip2it_hi -> 2.08 | N18: k_chip2it（D＝基準、E＝低、F＝高）
A19: 晶片 → IT 倍數：SpaceX／xAI（Colossus；兼出租） | B19: mult_xai | C19: x | D19: =k_chip2it -> 1.85 | E19: =k_chip2it_lo -> 1.65 | F19: =k_chip2it_hi -> 2.08 | N19: k_chip2it（D＝基準、E＝低、F＝高）
A21: Microsoft（自有＋融資租賃 AI 在役） | B21: msft | N21: In 第 88 列；口徑＝In!C88
A22: 輸入（IT GW；設施 ÷ IF_FacilityGW） | B22: msft_in | C22: GW | D22: =IF(In!$H$88="","",IF(In!$C$88="設施",In!$H$88/1000/D$13,In!$H$88/1000)) | E22: =IF(In!$I$88="","",IF(In!$C$88="設施",In!$I$88/1000/E$13,In!$I$88/1000)) | F22: =IF(In!$J$88="","",IF(In!$C$88="設施",In!$J$88/1000/F$13,In!$J$88/1000)) | G22: =IF(In!$K$88="","",IF(In!$C$88="設施",In!$K$88/1000/G$13,In!$K$88/1000)) | H22: =IF(In!$L$88="","",IF(In!$C$88="設施",In!$L$88/1000/H$13,In!$L$88/1000)) | I22: =IF(In!$M$88="","",IF(In!$C$88="設施",In!$M$88/1000/I$13,In!$M$88/1000)) | J22: =IF(In!$N$88="","",IF(In!$C$88="設施",In!$N$88/1000/J$13,In!$N$88/1000)) | K22: =IF(In!$O$88="","",IF(In!$C$88="設施",In!$O$88/1000/K$13,In!$O$88/1000)) | L22: =IF(In!$P$88="","",IF(In!$C$88="設施",In!$P$88/1000/L$13,In!$P$88/1000)) | M22: =IF(In!$Q$88="","",IF(In!$C$88="設施",In!$Q$88/1000/M$13,In!$Q$88/1000))
A23: 晶片換算 IT GW | B23: msft_chip | C23: GW | D23: =IF(In!$H$81="","",In!$H$81*Players!$D$14/1000) | E23: =IF(In!$I$81="","",In!$I$81*Players!$D$14/1000) -> 1.593775 | F23: =IF(In!$J$81="","",In!$J$81*Players!$D$14/1000) -> 3.729045 | G23: =IF(In!$K$81="","",In!$K$81*Players!$D$14/1000) | H23: =IF(In!$L$81="","",In!$L$81*Players!$D$14/1000) | I23: =IF(In!$M$81="","",In!$M$81*Players!$D$14/1000) | J23: =IF(In!$N$81="","",In!$N$81*Players!$D$14/1000) | K23: =IF(In!$O$81="","",In!$O$81*Players!$D$14/1000) | L23: =IF(In!$P$81="","",In!$P$81*Players!$D$14/1000) | M23: =IF(In!$Q$81="","",In!$Q$81*Players!$D$14/1000)
A24: 已知值 | B24: msft_k | C24: GW | D24: =IF(D22<>"",D22,IF(D23<>"",D23,IF(INT(obsd_msft)=2023,obs_msft/1000+SUMIFS(Pipeline!$L$5:$L$47,Pipeline!$C$5:$C$47,"msft",Pipeline!$Q$5:$Q$47,1,Pipeline!$K$5:$K$47,">"&obsd_msft,Pipeline!$K$5:$K$47,"<="&2024),""))) | E24: =IF(E22<>"",E22,IF(E23<>"",E23,IF(INT(obsd_msft)=2024,obs_msft/1000+SUMIFS(Pipeline!$L$5:$L$47,Pipeline!$C$5:$C$47,"msft",Pipeline!$Q$5:$Q$47,1,Pipeline!$K$5:$K$47,">"&obsd_msft,Pipeline!$K$5:$K$47,"<="&2025),""))) -> 1.593775 | F24: =IF(F22<>"",F22,IF(F23<>"",F23,IF(INT(obsd_msft)=2025,obs_msft/1000+SUMIFS(Pipeline!$L$5:$L$47,Pipeline!$C$5:$C$47,"msft",Pipeline!$Q$5:$Q$47,1,Pipeline!$K$5:$K$47,">"&obsd_msft,Pipeline!$K$5:$K$47,"<="&2026),""))) -> 3.729045 | G24: =IF(G22<>"",G22,IF(G23<>"",G23,IF(INT(obsd_msft)=2026,obs_msft/1000+SUMIFS(Pipeline!$L$5:$L$47,Pipeline!$C$5:$C$47,"msft",Pipeline!$Q$5:$Q$47,1,Pipeline!$K$5:$K$47,">"&obsd_msft,Pipeline!$K$5:$K$47,"<="&2027),""))) -> 4.5 | H24: =IF(H22<>"",H22,IF(H23<>"",H23,IF(INT(obsd_msft)=2027,obs_msft/1000+SUMIFS(Pipeline!$L$5:$L$47,Pipeline!$C$5:$C$47,"msft",Pipeline!$Q$5:$Q$47,1,Pipeline!$K$5:$K$47,">"&obsd_msft,Pipeline!$K$5:$K$47,"<="&2028),""))) | I24: =IF(I22<>"",I22,IF(I23<>"",I23,IF(INT(obsd_msft)=2028,obs_msft/1000+SUMIFS(Pipeline!$L$5:$L$47,Pipeline!$C$5:$C$47,"msft",Pipeline!$Q$5:$Q$47,1,Pipeline!$K$5:$K$47,">"&obsd_msft,Pipeline!$K$5:$K$47,"<="&2029),""))) | J24: =IF(J22<>"",J22,IF(J23<>"",J23,IF(INT(obsd_msft)=2029,obs_msft/1000+SUMIFS(Pipeline!$L$5:$L$47,Pipeline!$C$5:$C$47,"msft",Pipeline!$Q$5:$Q$47,1,Pipeline!$K$5:$K$47,">"&obsd_msft,Pipeline!$K$5:$K$47,"<="&2030),""))) | K24: =IF(K22<>"",K22,IF(K23<>"",K23,IF(INT(obsd_msft)=2030,obs_msft/1000+SUMIFS(Pipeline!$L$5:$L$47,Pipeline!$C$5:$C$47,"msft",Pipeline!$Q$5:$Q$47,1,Pipeline!$K$5:$K$47,">"&obsd_msft,Pipeline!$K$5:$K$47,"<="&2031),""))) | L24: =IF(L22<>"",L22,IF(L23<>"",L23,IF(INT(obsd_msft)=2031,obs_msft/1000+SUMIFS(Pipeline!$L$5:$L$47,Pipeline!$C$5:$C$47,"msft",Pipeline!$Q$5:$Q$47,1,Pipeline!$K$5:$K$47,">"&obsd_msft,Pipeline!$K$5:$K$47,"<="&2032),""))) | M24: =IF(M22<>"",M22,IF(M23<>"",M23,IF(INT(obsd_msft)=2032,obs_msft/1000+SUMIFS(Pipeline!$L$5:$L$47,Pipeline!$C$5:$C$47,"msft",Pipeline!$Q$5:$Q$47,1,Pipeline!$K$5:$K$47,">"&obsd_msft,Pipeline!$K$5:$K$47,"<="&2033),"")))
A25: 前一已知值 | B25: msft_L | C25: GW | D25: =IF(D24<>"",D24,"") | E25: =IF(E24<>"",E24,D25) -> 1.593775 | F25: =IF(F24<>"",F24,E25) -> 3.729045 | G25: =IF(G24<>"",G24,F25) -> 4.5 | H25: =IF(H24<>"",H24,G25) -> 4.5 | I25: =IF(I24<>"",I24,H25) -> 4.5 | J25: =IF(J24<>"",J24,I25) -> 4.5 | K25: =IF(K24<>"",K24,J25) -> 4.5 | L25: =IF(L24<>"",L24,K25) -> 4.5 | M25: =IF(M24<>"",M24,L25) -> 4.5
A26: 前一已知年 | B26: msft_LY | C26: 年 | D26: =IF(D24<>"",2023,"") | E26: =IF(E24<>"",2024,D26) -> 2024 | F26: =IF(F24<>"",2025,E26) -> 2025 | G26: =IF(G24<>"",2026,F26) -> 2026 | H26: =IF(H24<>"",2027,G26) -> 2026 | I26: =IF(I24<>"",2028,H26) -> 2026 | J26: =IF(J24<>"",2029,I26) -> 2026 | K26: =IF(K24<>"",2030,J26) -> 2026 | L26: =IF(L24<>"",2031,K26) -> 2026 | M26: =IF(M24<>"",2032,L26) -> 2026
A27: 下一已知值 | B27: msft_N | C27: GW | D27: =IF(D24<>"",D24,E27) -> 1.593775 | E27: =IF(E24<>"",E24,F27) -> 1.593775 | F27: =IF(F24<>"",F24,G27) -> 3.729045 | G27: =IF(G24<>"",G24,H27) -> 4.5 | H27: =IF(H24<>"",H24,I27) | I27: =IF(I24<>"",I24,J27) | J27: =IF(J24<>"",J24,K27) | K27: =IF(K24<>"",K24,L27) | L27: =IF(L24<>"",L24,M27) | M27: =IF(M24<>"",M24,"")
A28: 下一已知年 | B28: msft_NY | C28: 年 | D28: =IF(D24<>"",2023,E28) -> 2024 | E28: =IF(E24<>"",2024,F28) -> 2024 | F28: =IF(F24<>"",2025,G28) -> 2025 | G28: =IF(G24<>"",2026,H28) -> 2026 | H28: =IF(H24<>"",2027,I28) | I28: =IF(I24<>"",2028,J28) | J28: =IF(J24<>"",2029,K28) | K28: =IF(K24<>"",2030,L28) | L28: =IF(L24<>"",2031,M28) | M28: =IF(M24<>"",2032,"")
A29: 當年 T2 園區上線（D0，IT GW） | B29: msft_cp | C29: GW | D29: =SUMIFS(Pipeline!$L$5:$L$47,Pipeline!$C$5:$C$47,"msft",Pipeline!$Q$5:$Q$47,1,Pipeline!$P$5:$P$47,2023) -> 0 | E29: =SUMIFS(Pipeline!$L$5:$L$47,Pipeline!$C$5:$C$47,"msft",Pipeline!$Q$5:$Q$47,1,Pipeline!$P$5:$P$47,2024) -> 0 | F29: =SUMIFS(Pipeline!$L$5:$L$47,Pipeline!$C$5:$C$47,"msft",Pipeline!$Q$5:$Q$47,1,Pipeline!$P$5:$P$47,2025) -> 0.636 | G29: =SUMIFS(Pipeline!$L$5:$L$47,Pipeline!$C$5:$C$47,"msft",Pipeline!$Q$5:$Q$47,1,Pipeline!$P$5:$P$47,2026) -> 0.369 | H29: =SUMIFS(Pipeline!$L$5:$L$47,Pipeline!$C$5:$C$47,"msft",Pipeline!$Q$5:$Q$47,1,Pipeline!$P$5:$P$47,2027) -> 0.9 | I29: =SUMIFS(Pipeline!$L$5:$L$47,Pipeline!$C$5:$C$47,"msft",Pipeline!$Q$5:$Q$47,1,Pipeline!$P$5:$P$47,2028) -> 1.894 | J29: =SUMIFS(Pipeline!$L$5:$L$47,Pipeline!$C$5:$C$47,"msft",Pipeline!$Q$5:$Q$47,1,Pipeline!$P$5:$P$47,2029) -> 0 | K29: =SUMIFS(Pipeline!$L$5:$L$47,Pipeline!$C$5:$C$47,"msft",Pipeline!$Q$5:$Q$47,1,Pipeline!$P$5:$P$47,2030) -> 0 | L29: =SUMIFS(Pipeline!$L$5:$L$47,Pipeline!$C$5:$C$47,"msft",Pipeline!$Q$5:$Q$47,1,Pipeline!$P$5:$P$47,2031) -> 0 | M29: =SUMIFS(Pipeline!$L$5:$L$47,Pipeline!$C$5:$C$47,"msft",Pipeline!$Q$5:$Q$47,1,Pipeline!$P$5:$P$47,2032) -> 0
A30: 年底上線 IT GW | B30: msft_tk | C30: GW | D30: =IF(D24<>"",D24,IF(AND(D25<>"",D27<>""),D25+(D27-D25)*(2023-D26)/(D28-D26),"")) | E30: =IF(E24<>"",E24,IF(AND(E25<>"",E27<>""),E25+(E27-E25)*(2024-E26)/(E28-E26),IF(D30<>"",D30+E29,""))) -> 1.593775 | F30: =IF(F24<>"",F24,IF(AND(F25<>"",F27<>""),F25+(F27-F25)*(2025-F26)/(F28-F26),IF(E30<>"",E30+F29,""))) -> 3.729045 | G30: =IF(G24<>"",G24,IF(AND(G25<>"",G27<>""),G25+(G27-G25)*(2026-G26)/(G28-G26),IF(F30<>"",F30+G29,""))) -> 4.5 | H30: =IF(H24<>"",H24,IF(AND(H25<>"",H27<>""),H25+(H27-H25)*(2027-H26)/(H28-H26),IF(G30<>"",G30+H29,""))) -> 5.4 | I30: =IF(I24<>"",I24,IF(AND(I25<>"",I27<>""),I25+(I27-I25)*(2028-I26)/(I28-I26),IF(H30<>"",H30+I29,""))) -> 7.294 | J30: =IF(J24<>"",J24,IF(AND(J25<>"",J27<>""),J25+(J27-J25)*(2029-J26)/(J28-J26),IF(I30<>"",I30+J29,""))) -> 7.294 | K30: =IF(K24<>"",K24,IF(AND(K25<>"",K27<>""),K25+(K27-K25)*(2030-K26)/(K28-K26),IF(J30<>"",J30+K29,""))) -> 7.294 | L30: =IF(L24<>"",L24,IF(AND(L25<>"",L27<>""),L25+(L27-L25)*(2031-L26)/(L28-L26),IF(K30<>"",K30+L29,""))) -> 7.294 | M30: =IF(M24<>"",M24,IF(AND(M25<>"",M27<>""),M25+(M27-M25)*(2032-M26)/(M28-M26),IF(L30<>"",L30+M29,""))) -> 7.294
A31: 旗標 | B31: msft_f | C31: — | D31: =IF(D22<>"",1,IF(D23<>"",5,IF(D24<>"",2,IF(AND(D25<>"",D27<>""),3,IF(D30<>"",4,0))))) -> 0 | E31: =IF(E22<>"",1,IF(E23<>"",5,IF(E24<>"",2,IF(AND(E25<>"",E27<>""),3,IF(E30<>"",4,0))))) -> 5 | F31: =IF(F22<>"",1,IF(F23<>"",5,IF(F24<>"",2,IF(AND(F25<>"",F27<>""),3,IF(F30<>"",4,0))))) -> 5 | G31: =IF(G22<>"",1,IF(G23<>"",5,IF(G24<>"",2,IF(AND(G25<>"",G27<>""),3,IF(G30<>"",4,0))))) -> 2 | H31: =IF(H22<>"",1,IF(H23<>"",5,IF(H24<>"",2,IF(AND(H25<>"",H27<>""),3,IF(H30<>"",4,0))))) -> 4 | I31: =IF(I22<>"",1,IF(I23<>"",5,IF(I24<>"",2,IF(AND(I25<>"",I27<>""),3,IF(I30<>"",4,0))))) -> 4 | J31: =IF(J22<>"",1,IF(J23<>"",5,IF(J24<>"",2,IF(AND(J25<>"",J27<>""),3,IF(J30<>"",4,0))))) -> 4 | K31: =IF(K22<>"",1,IF(K23<>"",5,IF(K24<>"",2,IF(AND(K25<>"",K27<>""),3,IF(K30<>"",4,0))))) -> 4 | ... M31: =IF(M22<>"",1,IF(M23<>"",5,IF(M24<>"",2,IF(AND(M25<>"",M27<>""),3,IF(M30<>"",4,0))))) -> 4
A32: 年底上線 IT GW：低 | B32: msft_lo | C32: GW | D32: =IF(D30="","",IF(D31=2,D30-(obs_msft-obs_msft_lo)/1000,IF(AND(D31=5,In!$H$81<>""),In!$H$81*Players!$E$14/1000,D30))) | E32: =IF(E30="","",IF(E31=2,E30-(obs_msft-obs_msft_lo)/1000,IF(AND(E31=5,In!$I$81<>""),In!$I$81*Players!$E$14/1000,E30))) -> 1.421475 | F32: =IF(F30="","",IF(F31=2,F30-(obs_msft-obs_msft_lo)/1000,MIN(IF(AND(F31=5,In!$J$81<>""),In!$J$81*Players!$E$14/1000,F30),msft_guardian_lo/1000))) -> 1 | G32: =IF(G30="","",IF(G31=2,G30-(obs_msft-obs_msft_lo)/1000,IF(AND(G31=5,In!$K$81<>""),In!$K$81*Players!$E$14/1000,G30))) -> 3.5 | H32: =IF(H30="","",IF(H31=2,H30-(obs_msft-obs_msft_lo)/1000,IF(AND(H31=5,In!$L$81<>""),In!$L$81*Players!$E$14/1000,H30))) -> 5.4 | I32: =IF(I30="","",IF(I31=2,I30-(obs_msft-obs_msft_lo)/1000,IF(AND(I31=5,In!$M$81<>""),In!$M$81*Players!$E$14/1000,I30))) -> 7.294 | J32: =IF(J30="","",IF(J31=2,J30-(obs_msft-obs_msft_lo)/1000,IF(AND(J31=5,In!$N$81<>""),In!$N$81*Players!$E$14/1000,J30))) -> 7.294 | K32: =IF(K30="","",IF(K31=2,K30-(obs_msft-obs_msft_lo)/1000,IF(AND(K31=5,In!$O$81<>""),In!$O$81*Players!$E$14/1000,K30))) -> 7.294 | L32: =IF(L30="","",IF(L31=2,L30-(obs_msft-obs_msft_lo)/1000,IF(AND(L31=5,In!$P$81<>""),In!$P$81*Players!$E$14/1000,L30))) -> 7.294 | M32: =IF(M30="","",IF(M31=2,M30-(obs_msft-obs_msft_lo)/1000,IF(AND(M31=5,In!$Q$81<>""),In!$Q$81*Players!$E$14/1000,M30))) -> 7.294
A33: 年底上線 IT GW：高 | B33: msft_hi | C33: GW | D33: =IF(D30="","",IF(D31=2,D30+(obs_msft_hi-obs_msft)/1000,IF(AND(D31=5,In!$H$81<>""),In!$H$81*Players!$F$14/1000,D30))) | E33: =IF(E30="","",IF(E31=2,E30+(obs_msft_hi-obs_msft)/1000,IF(AND(E31=5,In!$I$81<>""),In!$I$81*Players!$F$14/1000,E30))) -> 1.79192 | F33: =IF(F30="","",IF(F31=2,F30+(obs_msft_hi-obs_msft)/1000,IF(AND(F31=5,In!$J$81<>""),In!$J$81*Players!$F$14/1000,F30))) -> 4.192656 | G33: =IF(G30="","",IF(G31=2,G30+(obs_msft_hi-obs_msft)/1000,IF(AND(G31=5,In!$K$81<>""),In!$K$81*Players!$F$14/1000,G30))) -> 5.5 | H33: =IF(H30="","",IF(H31=2,H30+(obs_msft_hi-obs_msft)/1000,IF(AND(H31=5,In!$L$81<>""),In!$L$81*Players!$F$14/1000,H30))) -> 5.4 | I33: =IF(I30="","",IF(I31=2,I30+(obs_msft_hi-obs_msft)/1000,IF(AND(I31=5,In!$M$81<>""),In!$M$81*Players!$F$14/1000,I30))) -> 7.294 | J33: =IF(J30="","",IF(J31=2,J30+(obs_msft_hi-obs_msft)/1000,IF(AND(J31=5,In!$N$81<>""),In!$N$81*Players!$F$14/1000,J30))) -> 7.294 | K33: =IF(K30="","",IF(K31=2,K30+(obs_msft_hi-obs_msft)/1000,IF(AND(K31=5,In!$O$81<>""),In!$O$81*Players!$F$14/1000,K30))) -> 7.294 | L33: =IF(L30="","",IF(L31=2,L30+(obs_msft_hi-obs_msft)/1000,IF(AND(L31=5,In!$P$81<>""),In!$P$81*Players!$F$14/1000,L30))) -> 7.294 | M33: =IF(M30="","",IF(M31=2,M30+(obs_msft_hi-obs_msft)/1000,IF(AND(M31=5,In!$Q$81<>""),In!$Q$81*Players!$F$14/1000,M30))) -> 7.294
A34: 另讀（口徑未說明者讀為設施 ÷ IF_FacilityGW） | B34: msft_alt | C34: GW | D34: =IF(D30="","",IF(In!$C$88="未說明",D30/D$13,D30)) | E34: =IF(E30="","",IF(In!$C$88="未說明",E30/E$13,E30)) -> 1.593775 | F34: =IF(F30="","",IF(In!$C$88="未說明",F30/F$13,F30)) -> 3.729045 | G34: =IF(G30="","",IF(In!$C$88="未說明",G30/G$13,G30)) -> 4.5 | H34: =IF(H30="","",IF(In!$C$88="未說明",H30/H$13,H30)) -> 5.4 | I34: =IF(I30="","",IF(In!$C$88="未說明",I30/I$13,I30)) -> 7.294 | J34: =IF(J30="","",IF(In!$C$88="未說明",J30/J$13,J30)) -> 7.294 | K34: =IF(K30="","",IF(In!$C$88="未說明",K30/K$13,K30)) -> 7.294 | ... M34: =IF(M30="","",IF(In!$C$88="未說明",M30/M$13,M30)) -> 7.294
A35: 年平均 IT GW | B35: msft_avg | C35: GW | D35: ="" | E35: =IF(AND(D30<>"",E30<>""),(D30+E30)/2,"") | F35: =IF(AND(E30<>"",F30<>""),(E30+F30)/2,"") -> 2.66141 | G35: =IF(AND(F30<>"",G30<>""),(F30+G30)/2,"") -> 4.1145225 | H35: =IF(AND(G30<>"",H30<>""),(G30+H30)/2,"") -> 4.95 | I35: =IF(AND(H30<>"",I30<>""),(H30+I30)/2,"") -> 6.347 | J35: =IF(AND(I30<>"",J30<>""),(I30+J30)/2,"") -> 7.294 | K35: =IF(AND(J30<>"",K30<>""),(J30+K30)/2,"") -> 7.294 | L35: =IF(AND(K30<>"",L30<>""),(K30+L30)/2,"") -> 7.294 | M35: =IF(AND(L30<>"",M30<>""),(L30+M30)/2,"") -> 7.294
A36: 年新增 IT GW | B36: msft_add | C36: GW | D36: 0 | E36: =IF(AND(D30<>"",E30<>""),E30-D30,0) -> 0 | F36: =IF(AND(E30<>"",F30<>""),F30-E30,0) -> 2.13527 | G36: =IF(AND(F30<>"",G30<>""),G30-F30,0) -> 0.770955 | H36: =IF(AND(G30<>"",H30<>""),H30-G30,0) -> 0.9 | I36: =IF(AND(H30<>"",I30<>""),I30-H30,0) -> 1.894 | J36: =IF(AND(I30<>"",J30<>""),J30-I30,0) -> 0 | K36: =IF(AND(J30<>"",K30<>""),K30-J30,0) -> 0 | L36: =IF(AND(K30<>"",L30<>""),L30-K30,0) -> 0 | M36: =IF(AND(L30<>"",M30<>""),M30-L30,0) -> 0
A37: 新納入存量 IT GW | B37: msft_stk | C37: GW | D37: =IF(D30<>"",D30,0) -> 0 | E37: =IF(AND(D30="",E30<>""),E30,0) -> 1.593775 | F37: =IF(AND(E30="",F30<>""),F30,0) -> 0 | G37: =IF(AND(F30="",G30<>""),G30,0) -> 0 | H37: =IF(AND(G30="",H30<>""),H30,0) -> 0 | I37: =IF(AND(H30="",I30<>""),I30,0) -> 0 | J37: =IF(AND(I30="",J30<>""),J30,0) -> 0 | K37: =IF(AND(J30="",K30<>""),K30,0) -> 0 | L37: =IF(AND(K30="",L30<>""),L30,0) -> 0 | M37: =IF(AND(L30="",M30<>""),M30,0) -> 0
A38: 新增 GW 非 NVIDIA 占比 | B38: msft_nnv | C38: % | D38: =D$12 -> 0.23821007 | E38: =E$12 -> 0.23821007 | F38: =F$12 -> 0.23821007 | G38: =G$12 -> 0.23821007 | H38: =H$12 -> 0.27310186 | I38: =I$12 -> 0.2696214 | J38: =J$12 -> 0.27218751 | K38: =K$12 -> 0.27218751 | ... M38: =M$12 -> 0.27218751
A40: Alphabet（Google；TPU＋NVIDIA） | B40: googl | N40: In 第 89 列；口徑＝In!C89
A41: 輸入（IT GW；設施 ÷ IF_FacilityGW） | B41: googl_in | C41: GW | D41: =IF(In!$H$89="","",IF(In!$C$89="設施",In!$H$89/1000/D$13,In!$H$89/1000)) | E41: =IF(In!$I$89="","",IF(In!$C$89="設施",In!$I$89/1000/E$13,In!$I$89/1000)) | F41: =IF(In!$J$89="","",IF(In!$C$89="設施",In!$J$89/1000/F$13,In!$J$89/1000)) | G41: =IF(In!$K$89="","",IF(In!$C$89="設施",In!$K$89/1000/G$13,In!$K$89/1000)) | H41: =IF(In!$L$89="","",IF(In!$C$89="設施",In!$L$89/1000/H$13,In!$L$89/1000)) | I41: =IF(In!$M$89="","",IF(In!$C$89="設施",In!$M$89/1000/I$13,In!$M$89/1000)) | J41: =IF(In!$N$89="","",IF(In!$C$89="設施",In!$N$89/1000/J$13,In!$N$89/1000)) | K41: =IF(In!$O$89="","",IF(In!$C$89="設施",In!$O$89/1000/K$13,In!$O$89/1000)) | L41: =IF(In!$P$89="","",IF(In!$C$89="設施",In!$P$89/1000/L$13,In!$P$89/1000)) | M41: =IF(In!$Q$89="","",IF(In!$C$89="設施",In!$Q$89/1000/M$13,In!$Q$89/1000))
A42: 晶片換算 IT GW | B42: googl_chip | C42: GW | D42: =IF(In!$H$82="","",In!$H$82*Players!$D$15/1000) -> 0.56057836 | E42: =IF(In!$I$82="","",In!$I$82*Players!$D$15/1000) -> 1.8903867 | F42: =IF(In!$J$82="","",In!$J$82*Players!$D$15/1000) -> 4.3 | G42: =IF(In!$K$82="","",In!$K$82*Players!$D$15/1000) | H42: =IF(In!$L$82="","",In!$L$82*Players!$D$15/1000) | I42: =IF(In!$M$82="","",In!$M$82*Players!$D$15/1000) | J42: =IF(In!$N$82="","",In!$N$82*Players!$D$15/1000) | K42: =IF(In!$O$82="","",In!$O$82*Players!$D$15/1000) | L42: =IF(In!$P$82="","",In!$P$82*Players!$D$15/1000) | M42: =IF(In!$Q$82="","",In!$Q$82*Players!$D$15/1000)
...

Sheet Matrix
A1: Matrix — 營運者 × 使用者（年底 IT GW）。列＝營運者（Players 年底值），欄＝使用者：In T1 每筆分配（比＝× 營運者年底 GW；GW＝絕對值）加總；『未分配』＝列和缺口（無揭露者；Decisions GL01-15）。列和＝Players；欄和合計＝總量（市場總量只按營運者加總一次）
A3: 2025 年底
A4: 營運者 | B4: 鍵 | C4: 自用 | D4: OpenAI | E4: Anthropic | F4: xAI | G4: Meta | H4: Google（租用） | I4: Microsoft（租用） | J4: 其他 | K4: 未分配 | L4: 列和 | M4: Players | N4: 差
A5: Microsoft（自有＋融資租賃 AI 在役） | B5: msft | C5: =SUMPRODUCT((In!$H$150:$H$162="msft")*(In!$I$150:$I$162="self")*((In!$J$150:$J$162="比")*$M5+(In!$J$150:$J$162<>"比"))*In!K$150:K$162) -> 1.491618 | D5: =SUMPRODUCT((In!$H$150:$H$162="msft")*(In!$I$150:$I$162="oai")*((In!$J$150:$J$162="比")*$M5+(In!$J$150:$J$162<>"比"))*In!K$150:K$162) -> 0 | E5: =SUMPRODUCT((In!$H$150:$H$162="msft")*(In!$I$150:$I$162="ant")*((In!$J$150:$J$162="比")*$M5+(In!$J$150:$J$162<>"比"))*In!K$150:K$162) -> 0 | F5: =SUMPRODUCT((In!$H$150:$H$162="msft")*(In!$I$150:$I$162="xai")*((In!$J$150:$J$162="比")*$M5+(In!$J$150:$J$162<>"比"))*In!K$150:K$162) -> 0 | G5: =SUMPRODUCT((In!$H$150:$H$162="msft")*(In!$I$150:$I$162="meta")*((In!$J$150:$J$162="比")*$M5+(In!$J$150:$J$162<>"比"))*In!K$150:K$162) -> 0 | H5: =SUMPRODUCT((In!$H$150:$H$162="msft")*(In!$I$150:$I$162="googl")*((In!$J$150:$J$162="比")*$M5+(In!$J$150:$J$162<>"比"))*In!K$150:K$162) -> 0 | I5: =SUMPRODUCT((In!$H$150:$H$162="msft")*(In!$I$150:$I$162="msft")*((In!$J$150:$J$162="比")*$M5+(In!$J$150:$J$162<>"比"))*In!K$150:K$162) -> 0 | J5: =SUMPRODUCT((In!$H$150:$H$162="msft")*(In!$I$150:$I$162="oth")*((In!$J$150:$J$162="比")*$M5+(In!$J$150:$J$162<>"比"))*In!K$150:K$162) -> 0 | K5: =$M5-SUM(C5:J5) -> 2.237427 | L5: =SUM(C5:K5) -> 3.729045 | M5: =N(Players!F30) -> 3.729045 | N5: =L5-M5 -> 0
A6: Alphabet（Google；TPU＋NVIDIA） | B6: googl | C6: =SUMPRODUCT((In!$H$150:$H$162="googl")*(In!$I$150:$I$162="self")*((In!$J$150:$J$162="比")*$M6+(In!$J$150:$J$162<>"比"))*In!K$150:K$162) -> 3.01 | D6: =SUMPRODUCT((In!$H$150:$H$162="googl")*(In!$I$150:$I$162="oai")*((In!$J$150:$J$162="比")*$M6+(In!$J$150:$J$162<>"比"))*In!K$150:K$162) -> 0 | E6: =SUMPRODUCT((In!$H$150:$H$162="googl")*(In!$I$150:$I$162="ant")*((In!$J$150:$J$162="比")*$M6+(In!$J$150:$J$162<>"比"))*In!K$150:K$162) -> 0 | F6: =SUMPRODUCT((In!$H$150:$H$162="googl")*(In!$I$150:$I$162="xai")*((In!$J$150:$J$162="比")*$M6+(In!$J$150:$J$162<>"比"))*In!K$150:K$162) -> 0 | G6: =SUMPRODUCT((In!$H$150:$H$162="googl")*(In!$I$150:$I$162="meta")*((In!$J$150:$J$162="比")*$M6+(In!$J$150:$J$162<>"比"))*In!K$150:K$162) -> 0 | H6: =SUMPRODUCT((In!$H$150:$H$162="googl")*(In!$I$150:$I$162="googl")*((In!$J$150:$J$162="比")*$M6+(In!$J$150:$J$162<>"比"))*In!K$150:K$162) -> 0 | I6: =SUMPRODUCT((In!$H$150:$H$162="googl")*(In!$I$150:$I$162="msft")*((In!$J$150:$J$162="比")*$M6+(In!$J$150:$J$162<>"比"))*In!K$150:K$162) -> 0 | J6: =SUMPRODUCT((In!$H$150:$H$162="googl")*(In!$I$150:$I$162="oth")*((In!$J$150:$J$162="比")*$M6+(In!$J$150:$J$162<>"比"))*In!K$150:K$162) -> 0 | K6: =$M6-SUM(C6:J6) -> 1.29 | L6: =SUM(C6:K6) -> 4.3 | M6: =N(Players!F49) -> 4.3 | N6: =L6-M6 -> 0
A7: Amazon（AWS；Trainium＋NVIDIA） | B7: amzn | C7: =SUMPRODUCT((In!$H$150:$H$162="amzn")*(In!$I$150:$I$162="self")*((In!$J$150:$J$162="比")*$M7+(In!$J$150:$J$162<>"比"))*In!K$150:K$162) -> 0.44 | D7: =SUMPRODUCT((In!$H$150:$H$162="amzn")*(In!$I$150:$I$162="oai")*((In!$J$150:$J$162="比")*$M7+(In!$J$150:$J$162<>"比"))*In!K$150:K$162) -> 0 | E7: =SUMPRODUCT((In!$H$150:$H$162="amzn")*(In!$I$150:$I$162="ant")*((In!$J$150:$J$162="比")*$M7+(In!$J$150:$J$162<>"比"))*In!K$150:K$162) -> 0.626 | F7: =SUMPRODUCT((In!$H$150:$H$162="amzn")*(In!$I$150:$I$162="xai")*((In!$J$150:$J$162="比")*$M7+(In!$J$150:$J$162<>"比"))*In!K$150:K$162) -> 0 | G7: =SUMPRODUCT((In!$H$150:$H$162="amzn")*(In!$I$150:$I$162="meta")*((In!$J$150:$J$162="比")*$M7+(In!$J$150:$J$162<>"比"))*In!K$150:K$162) -> 0 | H7: =SUMPRODUCT((In!$H$150:$H$162="amzn")*(In!$I$150:$I$162="googl")*((In!$J$150:$J$162="比")*$M7+(In!$J$150:$J$162<>"比"))*In!K$150:K$162) -> 0 | I7: =SUMPRODUCT((In!$H$150:$H$162="amzn")*(In!$I$150:$I$162="msft")*((In!$J$150:$J$162="比")*$M7+(In!$J$150:$J$162<>"比"))*In!K$150:K$162) -> 0 | J7: =SUMPRODUCT((In!$H$150:$H$162="amzn")*(In!$I$150:$I$162="oth")*((In!$J$150:$J$162="比")*$M7+(In!$J$150:$J$162<>"比"))*In!K$150:K$162) -> 0 | K7: =$M7-SUM(C7:J7) -> 1.134 | L7: =SUM(C7:K7) -> 2.2 | M7: =N(Players!F68) -> 2.2 | N7: =L7-M7 -> 0
A8: Meta | B8: meta | C8: =SUMPRODUCT((In!$H$150:$H$162="meta")*(In!$I$150:$I$162="self")*((In!$J$150:$J$162="比")*$M8+(In!$J$150:$J$162<>"比"))*In!K$150:K$162) -> 0 | D8: =SUMPRODUCT((In!$H$150:$H$162="meta")*(In!$I$150:$I$162="oai")*((In!$J$150:$J$162="比")*$M8+(In!$J$150:$J$162<>"比"))*In!K$150:K$162) -> 0 | E8: =SUMPRODUCT((In!$H$150:$H$162="meta")*(In!$I$150:$I$162="ant")*((In!$J$150:$J$162="比")*$M8+(In!$J$150:$J$162<>"比"))*In!K$150:K$162) -> 0 | F8: =SUMPRODUCT((In!$H$150:$H$162="meta")*(In!$I$150:$I$162="xai")*((In!$J$150:$J$162="比")*$M8+(In!$J$150:$J$162<>"比"))*In!K$150:K$162) -> 0 | G8: =SUMPRODUCT((In!$H$150:$H$162="meta")*(In!$I$150:$I$162="meta")*((In!$J$150:$J$162="比")*$M8+(In!$J$150:$J$162<>"比"))*In!K$150:K$162) -> 2.476595 | H8: =SUMPRODUCT((In!$H$150:$H$162="meta")*(In!$I$150:$I$162="googl")*((In!$J$150:$J$162="比")*$M8+(In!$J$150:$J$162<>"比"))*In!K$150:K$162) -> 0 | I8: =SUMPRODUCT((In!$H$150:$H$162="meta")*(In!$I$150:$I$162="msft")*((In!$J$150:$J$162="比")*$M8+(In!$J$150:$J$162<>"比"))*In!K$150:K$162) -> 0 | J8: =SUMPRODUCT((In!$H$150:$H$162="meta")*(In!$I$150:$I$162="oth")*((In!$J$150:$J$162="比")*$M8+(In!$J$150:$J$162<>"比"))*In!K$150:K$162) -> 0 | K8: =$M8-SUM(C8:J8) -> 0 | L8: =SUM(C8:K8) -> 2.476595 | M8: =N(Players!F87) -> 2.476595 | N8: =L8-M8 -> 0
A9: Oracle（OCI；含承租 Stargate 站點） | B9: orcl | C9: =SUMPRODUCT((In!$H$150:$H$162="orcl")*(In!$I$150:$I$162="self")*((In!$J$150:$J$162="比")*$M9+(In!$J$150:$J$162<>"比"))*In!K$150:K$162) -> 0 | D9: =SUMPRODUCT((In!$H$150:$H$162="orcl")*(In!$I$150:$I$162="oai")*((In!$J$150:$J$162="比")*$M9+(In!$J$150:$J$162<>"比"))*In!K$150:K$162) -> 0 | E9: =SUMPRODUCT((In!$H$150:$H$162="orcl")*(In!$I$150:$I$162="ant")*((In!$J$150:$J$162="比")*$M9+(In!$J$150:$J$162<>"比"))*In!K$150:K$162) -> 0 | F9: =SUMPRODUCT((In!$H$150:$H$162="orcl")*(In!$I$150:$I$162="xai")*((In!$J$150:$J$162="比")*$M9+(In!$J$150:$J$162<>"比"))*In!K$150:K$162) -> 0 | G9: =SUMPRODUCT((In!$H$150:$H$162="orcl")*(In!$I$150:$I$162="meta")*((In!$J$150:$J$162="比")*$M9+(In!$J$150:$J$162<>"比"))*In!K$150:K$162) -> 0 | H9: =SUMPRODUCT((In!$H$150:$H$162="orcl")*(In!$I$150:$I$162="googl")*((In!$J$150:$J$162="比")*$M9+(In!$J$150:$J$162<>"比"))*In!K$150:K$162) -> 0 | I9: =SUMPRODUCT((In!$H$150:$H$162="orcl")*(In!$I$150:$I$162="msft")*((In!$J$150:$J$162="比")*$M9+(In!$J$150:$J$162<>"比"))*In!K$150:K$162) -> 0 | J9: =SUMPRODUCT((In!$H$150:$H$162="orcl")*(In!$I$150:$I$162="oth")*((In!$J$150:$J$162="比")*$M9+(In!$J$150:$J$162<>"比"))*In!K$150:K$162) -> 0 | K9: =$M9-SUM(C9:J9) -> 1.20287 | L9: =SUM(C9:K9) -> 1.20287 | M9: =N(Players!F106) -> 1.20287 | N9: =L9-M9 -> 0
A10: CoreWeave | B10: crwv | C10: =SUMPRODUCT((In!$H$150:$H$162="crwv")*(In!$I$150:$I$162="self")*((In!$J$150:$J$162="比")*$M10+(In!$J$150:$J$162<>"比"))*In!K$150:K$162) -> 0 | D10: =SUMPRODUCT((In!$H$150:$H$162="crwv")*(In!$I$150:$I$162="oai")*((In!$J$150:$J$162="比")*$M10+(In!$J$150:$J$162<>"比"))*In!K$150:K$162) -> 0 | E10: =SUMPRODUCT((In!$H$150:$H$162="crwv")*(In!$I$150:$I$162="ant")*((In!$J$150:$J$162="比")*$M10+(In!$J$150:$J$162<>"比"))*In!K$150:K$162) -> 0 | F10: =SUMPRODUCT((In!$H$150:$H$162="crwv")*(In!$I$150:$I$162="xai")*((In!$J$150:$J$162="比")*$M10+(In!$J$150:$J$162<>"比"))*In!K$150:K$162) -> 0 | G10: =SUMPRODUCT((In!$H$150:$H$162="crwv")*(In!$I$150:$I$162="meta")*((In!$J$150:$J$162="比")*$M10+(In!$J$150:$J$162<>"比"))*In!K$150:K$162) -> 0 | H10: =SUMPRODUCT((In!$H$150:$H$162="crwv")*(In!$I$150:$I$162="googl")*((In!$J$150:$J$162="比")*$M10+(In!$J$150:$J$162<>"比"))*In!K$150:K$162) -> 0 | I10: =SUMPRODUCT((In!$H$150:$H$162="crwv")*(In!$I$150:$I$162="msft")*((In!$J$150:$J$162="比")*$M10+(In!$J$150:$J$162<>"比"))*In!K$150:K$162) -> 0 | J10: =SUMPRODUCT((In!$H$150:$H$162="crwv")*(In!$I$150:$I$162="oth")*((In!$J$150:$J$162="比")*$M10+(In!$J$150:$J$162<>"比"))*In!K$150:K$162) -> 0 | K10: =$M10-SUM(C10:J10) -> 0.85 | L10: =SUM(C10:K10) -> 0.85 | M10: =N(Players!F125) -> 0.85 | N10: =L10-M10 -> 0
A11: Nebius | B11: nbis | C11: =SUMPRODUCT((In!$H$150:$H$162="nbis")*(In!$I$150:$I$162="self")*((In!$J$150:$J$162="比")*$M11+(In!$J$150:$J$162<>"比"))*In!K$150:K$162) -> 0 | D11: =SUMPRODUCT((In!$H$150:$H$162="nbis")*(In!$I$150:$I$162="oai")*((In!$J$150:$J$162="比")*$M11+(In!$J$150:$J$162<>"比"))*In!K$150:K$162) -> 0 | E11: =SUMPRODUCT((In!$H$150:$H$162="nbis")*(In!$I$150:$I$162="ant")*((In!$J$150:$J$162="比")*$M11+(In!$J$150:$J$162<>"比"))*In!K$150:K$162) -> 0 | F11: =SUMPRODUCT((In!$H$150:$H$162="nbis")*(In!$I$150:$I$162="xai")*((In!$J$150:$J$162="比")*$M11+(In!$J$150:$J$162<>"比"))*In!K$150:K$162) -> 0 | G11: =SUMPRODUCT((In!$H$150:$H$162="nbis")*(In!$I$150:$I$162="meta")*((In!$J$150:$J$162="比")*$M11+(In!$J$150:$J$162<>"比"))*In!K$150:K$162) -> 0 | H11: =SUMPRODUCT((In!$H$150:$H$162="nbis")*(In!$I$150:$I$162="googl")*((In!$J$150:$J$162="比")*$M11+(In!$J$150:$J$162<>"比"))*In!K$150:K$162) -> 0 | I11: =SUMPRODUCT((In!$H$150:$H$162="nbis")*(In!$I$150:$I$162="msft")*((In!$J$150:$J$162="比")*$M11+(In!$J$150:$J$162<>"比"))*In!K$150:K$162) -> 0 | J11: =SUMPRODUCT((In!$H$150:$H$162="nbis")*(In!$I$150:$I$162="oth")*((In!$J$150:$J$162="比")*$M11+(In!$J$150:$J$162<>"比"))*In!K$150:K$162) -> 0 | K11: =$M11-SUM(C11:J11) -> 0.17 | L11: =SUM(C11:K11) -> 0.17 | M11: =N(Players!F144) -> 0.17 | N11: =L11-M11 -> 0
A12: WhiteFiber（雲端） | B12: wyfi | C12: =SUMPRODUCT((In!$H$150:$H$162="wyfi")*(In!$I$150:$I$162="self")*((In!$J$150:$J$162="比")*$M12+(In!$J$150:$J$162<>"比"))*In!K$150:K$162) -> 0 | D12: =SUMPRODUCT((In!$H$150:$H$162="wyfi")*(In!$I$150:$I$162="oai")*((In!$J$150:$J$162="比")*$M12+(In!$J$150:$J$162<>"比"))*In!K$150:K$162) -> 0 | E12: =SUMPRODUCT((In!$H$150:$H$162="wyfi")*(In!$I$150:$I$162="ant")*((In!$J$150:$J$162="比")*$M12+(In!$J$150:$J$162<>"比"))*In!K$150:K$162) -> 0 | F12: =SUMPRODUCT((In!$H$150:$H$162="wyfi")*(In!$I$150:$I$162="xai")*((In!$J$150:$J$162="比")*$M12+(In!$J$150:$J$162<>"比"))*In!K$150:K$162) -> 0 | G12: =SUMPRODUCT((In!$H$150:$H$162="wyfi")*(In!$I$150:$I$162="meta")*((In!$J$150:$J$162="比")*$M12+(In!$J$150:$J$162<>"比"))*In!K$150:K$162) -> 0 | H12: =SUMPRODUCT((In!$H$150:$H$162="wyfi")*(In!$I$150:$I$162="googl")*((In!$J$150:$J$162="比")*$M12+(In!$J$150:$J$162<>"比"))*In!K$150:K$162) -> 0 | I12: =SUMPRODUCT((In!$H$150:$H$162="wyfi")*(In!$I$150:$I$162="msft")*((In!$J$150:$J$162="比")*$M12+(In!$J$150:$J$162<>"比"))*In!K$150:K$162) -> 0 | J12: =SUMPRODUCT((In!$H$150:$H$162="wyfi")*(In!$I$150:$I$162="oth")*((In!$J$150:$J$162="比")*$M12+(In!$J$150:$J$162<>"比"))*In!K$150:K$162) -> 0 | K12: =$M12-SUM(C12:J12) -> 0.0055 | L12: =SUM(C12:K12) -> 0.0055 | M12: =N(Players!F163) -> 0.0055 | N12: =L12-M12 -> 0
A13: SpaceX／xAI（Colossus；兼出租） | B13: xai | C13: =SUMPRODUCT((In!$H$150:$H$162="xai")*(In!$I$150:$I$162="self")*((In!$J$150:$J$162="比")*$M13+(In!$J$150:$J$162<>"比"))*In!K$150:K$162) -> 0 | D13: =SUMPRODUCT((In!$H$150:$H$162="xai")*(In!$I$150:$I$162="oai")*((In!$J$150:$J$162="比")*$M13+(In!$J$150:$J$162<>"比"))*In!K$150:K$162) -> 0 | E13: =SUMPRODUCT((In!$H$150:$H$162="xai")*(In!$I$150:$I$162="ant")*((In!$J$150:$J$162="比")*$M13+(In!$J$150:$J$162<>"比"))*In!K$150:K$162) -> 0 | F13: =SUMPRODUCT((In!$H$150:$H$162="xai")*(In!$I$150:$I$162="xai")*((In!$J$150:$J$162="比")*$M13+(In!$J$150:$J$162<>"比"))*In!K$150:K$162) -> 0 | G13: =SUMPRODUCT((In!$H$150:$H$162="xai")*(In!$I$150:$I$162="meta")*((In!$J$150:$J$162="比")*$M13+(In!$J$150:$J$162<>"比"))*In!K$150:K$162) -> 0 | H13: =SUMPRODUCT((In!$H$150:$H$162="xai")*(In!$I$150:$I$162="googl")*((In!$J$150:$J$162="比")*$M13+(In!$J$150:$J$162<>"比"))*In!K$150:K$162) -> 0 | I13: =SUMPRODUCT((In!$H$150:$H$162="xai")*(In!$I$150:$I$162="msft")*((In!$J$150:$J$162="比")*$M13+(In!$J$150:$J$162<>"比"))*In!K$150:K$162) -> 0 | J13: =SUMPRODUCT((In!$H$150:$H$162="xai")*(In!$I$150:$I$162="oth")*((In!$J$150:$J$162="比")*$M13+(In!$J$150:$J$162<>"比"))*In!K$150:K$162) -> 0 | K13: =$M13-SUM(C13:J13) -> 0.5698 | L13: =SUM(C13:K13) -> 0.5698 | M13: =N(Players!F182) -> 0.5698 | N13: =L13-M13 -> 0
A14: OpenAI／Stargate 自建（SoftBank、SB Energy 營運） | B14: oai | C14: =SUMPRODUCT((In!$H$150:$H$162="oai")*(In!$I$150:$I$162="self")*((In!$J$150:$J$162="比")*$M14+(In!$J$150:$J$162<>"比"))*In!K$150:K$162) -> 0 | D14: =SUMPRODUCT((In!$H$150:$H$162="oai")*(In!$I$150:$I$162="oai")*((In!$J$150:$J$162="比")*$M14+(In!$J$150:$J$162<>"比"))*In!K$150:K$162) -> 0 | E14: =SUMPRODUCT((In!$H$150:$H$162="oai")*(In!$I$150:$I$162="ant")*((In!$J$150:$J$162="比")*$M14+(In!$J$150:$J$162<>"比"))*In!K$150:K$162) -> 0 | F14: =SUMPRODUCT((In!$H$150:$H$162="oai")*(In!$I$150:$I$162="xai")*((In!$J$150:$J$162="比")*$M14+(In!$J$150:$J$162<>"比"))*In!K$150:K$162) -> 0 | G14: =SUMPRODUCT((In!$H$150:$H$162="oai")*(In!$I$150:$I$162="meta")*((In!$J$150:$J$162="比")*$M14+(In!$J$150:$J$162<>"比"))*In!K$150:K$162) -> 0 | H14: =SUMPRODUCT((In!$H$150:$H$162="oai")*(In!$I$150:$I$162="googl")*((In!$J$150:$J$162="比")*$M14+(In!$J$150:$J$162<>"比"))*In!K$150:K$162) -> 0 | I14: =SUMPRODUCT((In!$H$150:$H$162="oai")*(In!$I$150:$I$162="msft")*((In!$J$150:$J$162="比")*$M14+(In!$J$150:$J$162<>"比"))*In!K$150:K$162) -> 0 | J14: =SUMPRODUCT((In!$H$150:$H$162="oai")*(In!$I$150:$I$162="oth")*((In!$J$150:$J$162="比")*$M14+(In!$J$150:$J$162<>"比"))*In!K$150:K$162) -> 0 | K14: =$M14-SUM(C14:J14) -> 0 | L14: =SUM(C14:K14) -> 0 | M14: =N(Players!F201) -> 0 | N14: =L14-M14 -> 0
A15: Anthropic 自建 | B15: ant | C15: =SUMPRODUCT((In!$H$150:$H$162="ant")*(In!$I$150:$I$162="self")*((In!$J$150:$J$162="比")*$M15+(In!$J$150:$J$162<>"比"))*In!K$150:K$162) -> 0 | D15: =SUMPRODUCT((In!$H$150:$H$162="ant")*(In!$I$150:$I$162="oai")*((In!$J$150:$J$162="比")*$M15+(In!$J$150:$J$162<>"比"))*In!K$150:K$162) -> 0 | E15: =SUMPRODUCT((In!$H$150:$H$162="ant")*(In!$I$150:$I$162="ant")*((In!$J$150:$J$162="比")*$M15+(In!$J$150:$J$162<>"比"))*In!K$150:K$162) -> 0 | F15: =SUMPRODUCT((In!$H$150:$H$162="ant")*(In!$I$150:$I$162="xai")*((In!$J$150:$J$162="比")*$M15+(In!$J$150:$J$162<>"比"))*In!K$150:K$162) -> 0 | G15: =SUMPRODUCT((In!$H$150:$H$162="ant")*(In!$I$150:$I$162="meta")*((In!$J$150:$J$162="比")*$M15+(In!$J$150:$J$162<>"比"))*In!K$150:K$162) -> 0 | H15: =SUMPRODUCT((In!$H$150:$H$162="ant")*(In!$I$150:$I$162="googl")*((In!$J$150:$J$162="比")*$M15+(In!$J$150:$J$162<>"比"))*In!K$150:K$162) -> 0 | I15: =SUMPRODUCT((In!$H$150:$H$162="ant")*(In!$I$150:$I$162="msft")*((In!$J$150:$J$162="比")*$M15+(In!$J$150:$J$162<>"比"))*In!K$150:K$162) -> 0 | J15: =SUMPRODUCT((In!$H$150:$H$162="ant")*(In!$I$150:$I$162="oth")*((In!$J$150:$J$162="比")*$M15+(In!$J$150:$J$162<>"比"))*In!K$150:K$162) -> 0 | K15: =$M15-SUM(C15:J15) -> 0 | L15: =SUM(C15:K15) -> 0 | M15: =N(Players!F220) -> 0 | N15: =L15-M15 -> 0
A16: 其他新雲合計（IREN、TeraWulf、Lambda、Nscale、Crusoe 雲等） | B16: neo | C16: =SUMPRODUCT((In!$H$150:$H$162="neo")*(In!$I$150:$I$162="self")*((In!$J$150:$J$162="比")*$M16+(In!$J$150:$J$162<>"比"))*In!K$150:K$162) -> 0 | D16: =SUMPRODUCT((In!$H$150:$H$162="neo")*(In!$I$150:$I$162="oai")*((In!$J$150:$J$162="比")*$M16+(In!$J$150:$J$162<>"比"))*In!K$150:K$162) -> 0 | E16: =SUMPRODUCT((In!$H$150:$H$162="neo")*(In!$I$150:$I$162="ant")*((In!$J$150:$J$162="比")*$M16+(In!$J$150:$J$162<>"比"))*In!K$150:K$162) -> 0 | F16: =SUMPRODUCT((In!$H$150:$H$162="neo")*(In!$I$150:$I$162="xai")*((In!$J$150:$J$162="比")*$M16+(In!$J$150:$J$162<>"比"))*In!K$150:K$162) -> 0 | G16: =SUMPRODUCT((In!$H$150:$H$162="neo")*(In!$I$150:$I$162="meta")*((In!$J$150:$J$162="比")*$M16+(In!$J$150:$J$162<>"比"))*In!K$150:K$162) -> 0 | H16: =SUMPRODUCT((In!$H$150:$H$162="neo")*(In!$I$150:$I$162="googl")*((In!$J$150:$J$162="比")*$M16+(In!$J$150:$J$162<>"比"))*In!K$150:K$162) -> 0 | I16: =SUMPRODUCT((In!$H$150:$H$162="neo")*(In!$I$150:$I$162="msft")*((In!$J$150:$J$162="比")*$M16+(In!$J$150:$J$162<>"比"))*In!K$150:K$162) -> 0 | J16: =SUMPRODUCT((In!$H$150:$H$162="neo")*(In!$I$150:$I$162="oth")*((In!$J$150:$J$162="比")*$M16+(In!$J$150:$J$162<>"比"))*In!K$150:K$162) -> 0 | K16: =$M16-SUM(C16:J16) -> 0.5 | L16: =SUM(C16:K16) -> 0.5 | M16: =N(Players!F239) -> 0.5 | N16: =L16-M16 -> 0
A17: 主權 AI（中國以外；v0.1 只含 Humain） | B17: sov | C17: =SUMPRODUCT((In!$H$150:$H$162="sov")*(In!$I$150:$I$162="self")*((In!$J$150:$J$162="比")*$M17+(In!$J$150:$J$162<>"比"))*In!K$150:K$162) -> 0 | D17: =SUMPRODUCT((In!$H$150:$H$162="sov")*(In!$I$150:$I$162="oai")*((In!$J$150:$J$162="比")*$M17+(In!$J$150:$J$162<>"比"))*In!K$150:K$162) -> 0 | E17: =SUMPRODUCT((In!$H$150:$H$162="sov")*(In!$I$150:$I$162="ant")*((In!$J$150:$J$162="比")*$M17+(In!$J$150:$J$162<>"比"))*In!K$150:K$162) -> 0 | F17: =SUMPRODUCT((In!$H$150:$H$162="sov")*(In!$I$150:$I$162="xai")*((In!$J$150:$J$162="比")*$M17+(In!$J$150:$J$162<>"比"))*In!K$150:K$162) -> 0 | G17: =SUMPRODUCT((In!$H$150:$H$162="sov")*(In!$I$150:$I$162="meta")*((In!$J$150:$J$162="比")*$M17+(In!$J$150:$J$162<>"比"))*In!K$150:K$162) -> 0 | H17: =SUMPRODUCT((In!$H$150:$H$162="sov")*(In!$I$150:$I$162="googl")*((In!$J$150:$J$162="比")*$M17+(In!$J$150:$J$162<>"比"))*In!K$150:K$162) -> 0 | I17: =SUMPRODUCT((In!$H$150:$H$162="sov")*(In!$I$150:$I$162="msft")*((In!$J$150:$J$162="比")*$M17+(In!$J$150:$J$162<>"比"))*In!K$150:K$162) -> 0 | J17: =SUMPRODUCT((In!$H$150:$H$162="sov")*(In!$I$150:$I$162="oth")*((In!$J$150:$J$162="比")*$M17+(In!$J$150:$J$162<>"比"))*In!K$150:K$162) -> 0 | K17: =$M17-SUM(C17:J17) -> 0 | L17: =SUM(C17:K17) -> 0 | M17: =N(Players!F258) -> 0 | N17: =L17-M17 -> 0
A18: 中國合計（AI；Rystad 容量 × AI 占比） | B18: cn | C18: =SUMPRODUCT((In!$H$150:$H$162="cn")*(In!$I$150:$I$162="self")*((In!$J$150:$J$162="比")*$M18+(In!$J$150:$J$162<>"比"))*In!K$150:K$162) -> 8.3333333 | D18: =SUMPRODUCT((In!$H$150:$H$162="cn")*(In!$I$150:$I$162="oai")*((In!$J$150:$J$162="比")*$M18+(In!$J$150:$J$162<>"比"))*In!K$150:K$162) -> 0 | E18: =SUMPRODUCT((In!$H$150:$H$162="cn")*(In!$I$150:$I$162="ant")*((In!$J$150:$J$162="比")*$M18+(In!$J$150:$J$162<>"比"))*In!K$150:K$162) -> 0 | F18: =SUMPRODUCT((In!$H$150:$H$162="cn")*(In!$I$150:$I$162="xai")*((In!$J$150:$J$162="比")*$M18+(In!$J$150:$J$162<>"比"))*In!K$150:K$162) -> 0 | G18: =SUMPRODUCT((In!$H$150:$H$162="cn")*(In!$I$150:$I$162="meta")*((In!$J$150:$J$162="比")*$M18+(In!$J$150:$J$162<>"比"))*In!K$150:K$162) -> 0 | H18: =SUMPRODUCT((In!$H$150:$H$162="cn")*(In!$I$150:$I$162="googl")*((In!$J$150:$J$162="比")*$M18+(In!$J$150:$J$162<>"比"))*In!K$150:K$162) -> 0 | I18: =SUMPRODUCT((In!$H$150:$H$162="cn")*(In!$I$150:$I$162="msft")*((In!$J$150:$J$162="比")*$M18+(In!$J$150:$J$162<>"比"))*In!K$150:K$162) -> 0 | J18: =SUMPRODUCT((In!$H$150:$H$162="cn")*(In!$I$150:$I$162="oth")*((In!$J$150:$J$162="比")*$M18+(In!$J$150:$J$162<>"比"))*In!K$150:K$162) -> 0 | K18: =$M18-SUM(C18:J18) -> 0 | L18: =SUM(C18:K18) -> 8.3333333 | M18: =N(Players!F277) -> 8.3333333 | N18: =L18-M18 -> 0
A19: 其他（主權、企業、學研；Epoch Other 扣新雲） | B19: oth | C19: =SUMPRODUCT((In!$H$150:$H$162="oth")*(In!$I$150:$I$162="self")*((In!$J$150:$J$162="比")*$M19+(In!$J$150:$J$162<>"比"))*In!K$150:K$162) -> 0 | D19: =SUMPRODUCT((In!$H$150:$H$162="oth")*(In!$I$150:$I$162="oai")*((In!$J$150:$J$162="比")*$M19+(In!$J$150:$J$162<>"比"))*In!K$150:K$162) -> 0 | E19: =SUMPRODUCT((In!$H$150:$H$162="oth")*(In!$I$150:$I$162="ant")*((In!$J$150:$J$162="比")*$M19+(In!$J$150:$J$162<>"比"))*In!K$150:K$162) -> 0 | F19: =SUMPRODUCT((In!$H$150:$H$162="oth")*(In!$I$150:$I$162="xai")*((In!$J$150:$J$162="比")*$M19+(In!$J$150:$J$162<>"比"))*In!K$150:K$162) -> 0 | G19: =SUMPRODUCT((In!$H$150:$H$162="oth")*(In!$I$150:$I$162="meta")*((In!$J$150:$J$162="比")*$M19+(In!$J$150:$J$162<>"比"))*In!K$150:K$162) -> 0 | H19: =SUMPRODUCT((In!$H$150:$H$162="oth")*(In!$I$150:$I$162="googl")*((In!$J$150:$J$162="比")*$M19+(In!$J$150:$J$162<>"比"))*In!K$150:K$162) -> 0 | I19: =SUMPRODUCT((In!$H$150:$H$162="oth")*(In!$I$150:$I$162="msft")*((In!$J$150:$J$162="比")*$M19+(In!$J$150:$J$162<>"比"))*In!K$150:K$162) -> 0 | J19: =SUMPRODUCT((In!$H$150:$H$162="oth")*(In!$I$150:$I$162="oth")*((In!$J$150:$J$162="比")*$M19+(In!$J$150:$J$162<>"比"))*In!K$150:K$162) -> 0 | K19: =$M19-SUM(C19:J19) -> 1 | L19: =SUM(C19:K19) -> 1 | M19: =N(Players!F296) -> 1 | N19: =L19-M19 -> 0
A20: 欄和（使用者合計） | C20: =SUM(C5:C19) -> 13.274951 | D20: =SUM(D5:D19) -> 0 | E20: =SUM(E5:E19) -> 0.626 | F20: =SUM(F5:F19) -> 0 | G20: =SUM(G5:G19) -> 2.476595 | H20: =SUM(H5:H19) -> 0 | I20: =SUM(I5:I19) -> 0 | J20: =SUM(J5:J19) -> 0 | ... N20: =SUM(N5:N19) -> 0
A21: 對照：usr_oai 報導值（口徑 In!C136；未說明讀為 IT） | D21: =IF(In!J136="","",IF(In!$C$136="設施",In!J136/Players!F$13,In!J136)) -> 1.9 | L21: =IF(OR(D21="",N(D21)=0),"",D20/D21) -> 0 | M21: ← 矩陣欄和 ÷ 報導（< 1＝揭露不足，差額在『未分配』）
A22: 對照：usr_ant 報導值（口徑 In!C137；未說明讀為 IT） | E22: =IF(In!J137="","",IF(In!$C$137="設施",In!J137/Players!F$13,In!J137)) -> 1.4 | L22: =IF(OR(E22="",N(E22)=0),"",E20/E22) -> 0.44714286 | M22: ← 矩陣欄和 ÷ 報導（< 1＝揭露不足，差額在『未分配』）
A24: 2026 年底
A25: 營運者 | B25: 鍵 | C25: 自用 | D25: OpenAI | E25: Anthropic | F25: xAI | G25: Meta | H25: Google（租用） | I25: Microsoft（租用） | J25: 其他 | K25: 未分配 | L25: 列和 | M25: Players | N25: 差
A26: Microsoft（自有＋融資租賃 AI 在役） | B26: msft | C26: =SUMPRODUCT((In!$H$150:$H$162="msft")*(In!$I$150:$I$162="self")*((In!$J$150:$J$162="比")*$M26+(In!$J$150:$J$162<>"比"))*In!L$150:L$162) -> 1.8 | D26: =SUMPRODUCT((In!$H$150:$H$162="msft")*(In!$I$150:$I$162="oai")*((In!$J$150:$J$162="比")*$M26+(In!$J$150:$J$162<>"比"))*In!L$150:L$162) -> 0 | E26: =SUMPRODUCT((In!$H$150:$H$162="msft")*(In!$I$150:$I$162="ant")*((In!$J$150:$J$162="比")*$M26+(In!$J$150:$J$162<>"比"))*In!L$150:L$162) -> 0 | F26: =SUMPRODUCT((In!$H$150:$H$162="msft")*(In!$I$150:$I$162="xai")*((In!$J$150:$J$162="比")*$M26+(In!$J$150:$J$162<>"比"))*In!L$150:L$162) -> 0 | G26: =SUMPRODUCT((In!$H$150:$H$162="msft")*(In!$I$150:$I$162="meta")*((In!$J$150:$J$162="比")*$M26+(In!$J$150:$J$162<>"比"))*In!L$150:L$162) -> 0 | H26: =SUMPRODUCT((In!$H$150:$H$162="msft")*(In!$I$150:$I$162="googl")*((In!$J$150:$J$162="比")*$M26+(In!$J$150:$J$162<>"比"))*In!L$150:L$162) -> 0 | I26: =SUMPRODUCT((In!$H$150:$H$162="msft")*(In!$I$150:$I$162="msft")*((In!$J$150:$J$162="比")*$M26+(In!$J$150:$J$162<>"比"))*In!L$150:L$162) -> 0 | J26: =SUMPRODUCT((In!$H$150:$H$162="msft")*(In!$I$150:$I$162="oth")*((In!$J$150:$J$162="比")*$M26+(In!$J$150:$J$162<>"比"))*In!L$150:L$162) -> 0 | K26: =$M26-SUM(C26:J26) -> 2.7 | L26: =SUM(C26:K26) -> 4.5 | M26: =N(Players!G30) -> 4.5 | N26: =L26-M26 -> 0
A27: Alphabet（Google；TPU＋NVIDIA） | B27: googl | C27: =SUMPRODUCT((In!$H$150:$H$162="googl")*(In!$I$150:$I$162="self")*((In!$J$150:$J$162="比")*$M27+(In!$J$150:$J$162<>"比"))*In!L$150:L$162) -> 3.9148754 | D27: =SUMPRODUCT((In!$H$150:$H$162="googl")*(In!$I$150:$I$162="oai")*((In!$J$150:$J$162="比")*$M27+(In!$J$150:$J$162<>"比"))*In!L$150:L$162) -> 0 | E27: =SUMPRODUCT((In!$H$150:$H$162="googl")*(In!$I$150:$I$162="ant")*((In!$J$150:$J$162="比")*$M27+(In!$J$150:$J$162<>"比"))*In!L$150:L$162) -> 1 | F27: =SUMPRODUCT((In!$H$150:$H$162="googl")*(In!$I$150:$I$162="xai")*((In!$J$150:$J$162="比")*$M27+(In!$J$150:$J$162<>"比"))*In!L$150:L$162) -> 0 | G27: =SUMPRODUCT((In!$H$150:$H$162="googl")*(In!$I$150:$I$162="meta")*((In!$J$150:$J$162="比")*$M27+(In!$J$150:$J$162<>"比"))*In!L$150:L$162) -> 0 | H27: =SUMPRODUCT((In!$H$150:$H$162="googl")*(In!$I$150:$I$162="googl")*((In!$J$150:$J$162="比")*$M27+(In!$J$150:$J$162<>"比"))*In!L$150:L$162) -> 0 | I27: =SUMPRODUCT((In!$H$150:$H$162="googl")*(In!$I$150:$I$162="msft")*((In!$J$150:$J$162="比")*$M27+(In!$J$150:$J$162<>"比"))*In!L$150:L$162) -> 0 | J27: =SUMPRODUCT((In!$H$150:$H$162="googl")*(In!$I$150:$I$162="oth")*((In!$J$150:$J$162="比")*$M27+(In!$J$150:$J$162<>"比"))*In!L$150:L$162) -> 0 | K27: =$M27-SUM(C27:J27) -> 0.67780374 | L27: =SUM(C27:K27) -> 5.5926791 | M27: =N(Players!G49) -> 5.5926791 | N27: =L27-M27 -> 0
