Workbook

Sheet README
A1: 智譜（智譜華章，02513.HK）收支模型 v0.1-Z2（2026-10-08）
A2: 命題（規格 D1，與 OpenAI v0.6 同一句）：智譜每 VR 等值 GW 的年營收能否覆蓋每 GW 年全成本；若不能，缺口要多少外部資金、由誰以什麼條件提供。FY2025–FY2030，曆年制。
A4: 本版範圍 | B4: v0.1-Z2：SRC_ZP（公司財務原始數據）、TK_Link（Tokenomics 快照）、OAI_Link（OpenAI v0.6 命題輸出快照）、Inputs（假設）、Demand（需求與 token）、Revenue（營收）、Checks。Compute、Cost（Z3）與 Funding、Reverse（Z4）尚未建立；容量上限係數暫以 1 佔位（只回乘雲端營收）。
A5: 幣別與單位 | B5: 公司金額一律人民幣億元（RMB 億），與財報一致。港幣、美元數據以 Inputs 匯率（USD/CNY、HKD/CNY，2026-09-28 中間價；定義常數，區間 ±5%）換算後才進計算頁。API 牌價：人民幣元／百萬 token；token：兆（T）；Coding Plan 訂閱者：萬人；智譜清言用戶：百萬人。OAI_Link 為美元（$B），不換算、不參與計算。
A6: Excel 為唯一計算引擎 | B6: 藍字＝輸入（Excel 擁有）；黑字＝公式；綠字＝跨頁連結。builder 只產生結構，重建時保留 Excel 內已改過的藍字（隱藏頁 _Defaults）。公式不含常數（E6）：單位換算、天數、月數為 Inputs 的定義常數。
A7: SRC_ZP | B7: 604 列（SRC_ZP_001–604，Z1 發出、穩定不改號）；有數值者具名 SRC_ZP_nnn，有低／高者另具名 _Lo／_Hi。來源四欄為 CC 初評（builder/source_rules.py）。
A8: TK_Link | B8: Tokenomics v5.26（20261007_Tokenomics_v5.26.xlsx），master 提交 3dd1216，讀取日 2026-10-08；63 個具名範圍（同 OpenAI v0.6 的 63 名）＋7 列以列標籤讀表（狀態『讀表（非具名）』，只供對照）。
A9: OAI_Link | B9: OpenAI v0.6 Excel（20261008_OpenAI_v0.6.xlsx，claude/openai-s6-release@e91df57；SHA-256 34fc34a7ea2c18e8…）的命題輸出逐年值（美元）；只被 Checks 與 HTML 引用（規格 D26）。
A10: Inputs | B10: 73 列（INP_001 起，依 data/zhipu_inputs.yaml 的鍵發號）；每列附標記、依據、區間理由；Analogy／Assumed 一律給區間。
A11: Demand | B11: 需求：①API 按量計費 token（2025、1H26＝營收 ÷ 有效單價倒推；2H26 起任務數 × 每任務 token × 價格反應）②GLM Coding Plan 訂閱者（方案別）× 每訂閱者 token ③智譜清言（免費）用戶 × 任務 × 每任務 token；輸出 DEM_Tok_*（層級 Sol／Luna × 付費／免費）。本地化部署不耗智譜算力，不進 Demand（D4）。
A12: Revenue | B12: 營收：①開放平台及 API（按量計費：層級 × 輸入／快取／輸出 × 有效價；Coding Plan 子列：方案別訂閱）②企業級智能體 ③企業級通用大模型 ④技術服務及其他（②③④＝本地化部署分部，規格 D2r）；廣告＝0（D3）；總額＝淨額（D5）；雲端 vs 本地化、企業 vs 個人彙總；2025 與 1H26 對財報校準差距＝0；公司說法（ARR、平均售價 +101%、呼叫量 40 倍）只列對照。
A13: Checks | B13: C01 起；CHK_Errors 必須為 0。WARN（ARR 對照）與 INFO 不計入。
A14: 標記 | B14: Verified／Interested-party／Analogy／Assumed／Derived／Decision（Analogy、Assumed 一律附區間）。
A15: 分層 | B15: 公司財務原始數據→SRC_ZP；AI 技術與算力→TK_Link（取自 Tokenomics）；假設→Inputs；OpenAI 對照→OAI_Link（不進計算）。

Sheet SRC_ZP
A1: SRC_ZP — 第 0 層 Source：智譜公司財務原始數據（財報、分部、牌價、用戶、算力採購、融資、股本與市值）
A2: 只存已取得的原始訊息（非計算、非假設）。藍字＝原始值，由本活頁簿擁有；來源 data/zhipu_src.yaml（Z1）。AI 技術與算力的物理數據不在此登錄（取自 TK_Link）。
A3: 來源等級（1 一手已讀原文／2 二手或轉載／3 待查核）、立場、立場說明、一手／二手：builder/source_rules.py 機械初評（欄 X 標『CC 初評』）。無數值列＝日期、事件或找不到數值的說明列（另見 Checks）。
A4: SRC_ID | B4: 鍵（key） | C4: 項目 | D4: 值 | E4: 低 | F4: 高 | G4: 單位 | H4: 期間 | I4: 來源 | J4: 網址 | K4: 文件日期 | L4: 擷取日 | M4: 標記 | N4: 利害方與誘因 | O4: 口徑（basis） | P4: 來源等級 | Q4: 立場 | R4: 立場說明 | S4: 一手／二手 | T4: 備註 | U4: 無數值（公式） | V4: 缺出處（公式） | W4: 區間順序異常（公式） | X4: 四欄標註
A5: SRC_ZP_001 | B5: rev_total_fy22 | C5: 營收總額 | D5: 0.5741 | G5: RMB 億 | H5: FY2022 | I5: 智譜招股章程（概要節） | J5: https://www1.hkexnews.hk/listedco/listconews/sehk/2025/1230/2025123000018_c.pdf | K5: 2025-12-30 | L5: 2026-10-08 | M5: Verified | O5: 經審計（會計師報告，招股章程概要轉載） | P5: 1 | Q5: 利害關係方 | R5: 經審計或經審閱的公司公告（誘因：上市後股價、配售；數字可由公告原文核對） | S5: 一手 | T5: 原文「收入 57,409 100.0」；千元值 57,409；RMB 千元÷100,000 換算成億 | U5: =IF(AND($D5="",$E5="",$F5=""),1,0) -> 0 | V5: =IF(OR($I5="",$I5="—"),1,0) -> 0 | W5: =IF(AND(ISNUMBER($D5),ISNUMBER($E5)),IF($E5>$D5,1,0),0)+IF(AND(ISNUMBER($D5),ISNUMBER($F5)),IF($D5>$F5,1,0),0)+IF(AND(ISNUMBER($E5),ISNUMBER($F5)),IF($E5>$F5,1,0),0) -> 0 | X5: CC 初評
A6: SRC_ZP_002 | B6: rev_total_fy23 | C6: 營收總額 | D6: 1.2454 | G6: RMB 億 | H6: FY2023 | I6: 智譜招股章程（概要節） | J6: https://www1.hkexnews.hk/listedco/listconews/sehk/2025/1230/2025123000018_c.pdf | K6: 2025-12-30 | L6: 2026-10-08 | M6: Verified | O6: 經審計（會計師報告，招股章程概要轉載） | P6: 1 | Q6: 利害關係方 | R6: 經審計或經審閱的公司公告（誘因：上市後股價、配售；數字可由公告原文核對） | S6: 一手 | T6: 原文「收入 57,409 100.0」；千元值 124,538；RMB 千元÷100,000 換算成億 | U6: =IF(AND($D6="",$E6="",$F6=""),1,0) -> 0 | V6: =IF(OR($I6="",$I6="—"),1,0) -> 0 | W6: =IF(AND(ISNUMBER($D6),ISNUMBER($E6)),IF($E6>$D6,1,0),0)+IF(AND(ISNUMBER($D6),ISNUMBER($F6)),IF($D6>$F6,1,0),0)+IF(AND(ISNUMBER($E6),ISNUMBER($F6)),IF($E6>$F6,1,0),0) -> 0 | X6: CC 初評
A7: SRC_ZP_003 | B7: rev_total_fy24 | C7: 營收總額 | D7: 3.1241 | G7: RMB 億 | H7: FY2024 | I7: 智譜招股章程（概要節） | J7: https://www1.hkexnews.hk/listedco/listconews/sehk/2025/1230/2025123000018_c.pdf | K7: 2025-12-30 | L7: 2026-10-08 | M7: Verified | O7: 經審計（會計師報告，招股章程概要轉載） | P7: 1 | Q7: 利害關係方 | R7: 經審計或經審閱的公司公告（誘因：上市後股價、配售；數字可由公告原文核對） | S7: 一手 | T7: 原文「收入 57,409 100.0」；千元值 312,414；RMB 千元÷100,000 換算成億 | U7: =IF(AND($D7="",$E7="",$F7=""),1,0) -> 0 | V7: =IF(OR($I7="",$I7="—"),1,0) -> 0 | W7: =IF(AND(ISNUMBER($D7),ISNUMBER($E7)),IF($E7>$D7,1,0),0)+IF(AND(ISNUMBER($D7),ISNUMBER($F7)),IF($D7>$F7,1,0),0)+IF(AND(ISNUMBER($E7),ISNUMBER($F7)),IF($E7>$F7,1,0),0) -> 0 | X7: CC 初評
A8: SRC_ZP_004 | B8: rev_total_1h24 | C8: 營收總額 | D8: 0.4491 | G8: RMB 億 | H8: 1H2024 | I8: 智譜招股章程（概要節） | J8: https://www1.hkexnews.hk/listedco/listconews/sehk/2025/1230/2025123000018_c.pdf | K8: 2025-12-30 | L8: 2026-10-08 | M8: Verified | O8: 會計師報告（1H2024 比較期通常為未經審計已審閱；招股章程概要轉載） | P8: 1 | Q8: 利害關係方 | R8: 經審計或經審閱的公司公告（誘因：上市後股價、配售；數字可由公告原文核對） | S8: 一手 | T8: 原文「收入 57,409 100.0」；千元值 44,909；RMB 千元÷100,000 換算成億 | U8: =IF(AND($D8="",$E8="",$F8=""),1,0) -> 0 | V8: =IF(OR($I8="",$I8="—"),1,0) -> 0 | W8: =IF(AND(ISNUMBER($D8),ISNUMBER($E8)),IF($E8>$D8,1,0),0)+IF(AND(ISNUMBER($D8),ISNUMBER($F8)),IF($D8>$F8,1,0),0)+IF(AND(ISNUMBER($E8),ISNUMBER($F8)),IF($E8>$F8,1,0),0) -> 0 | X8: CC 初評
A9: SRC_ZP_005 | B9: rev_total_1h25 | C9: 營收總額 | D9: 1.9088 | G9: RMB 億 | H9: 1H2025 | I9: 智譜招股章程（概要節） | J9: https://www1.hkexnews.hk/listedco/listconews/sehk/2025/1230/2025123000018_c.pdf | K9: 2025-12-30 | L9: 2026-10-08 | M9: Verified | O9: 經審計（會計師報告，招股章程概要轉載） | P9: 1 | Q9: 利害關係方 | R9: 經審計或經審閱的公司公告（誘因：上市後股價、配售；數字可由公告原文核對） | S9: 一手 | T9: 原文「收入 57,409 100.0」；千元值 190,877；RMB 千元÷100,000 換算成億 | U9: =IF(AND($D9="",$E9="",$F9=""),1,0) -> 0 | V9: =IF(OR($I9="",$I9="—"),1,0) -> 0 | W9: =IF(AND(ISNUMBER($D9),ISNUMBER($E9)),IF($E9>$D9,1,0),0)+IF(AND(ISNUMBER($D9),ISNUMBER($F9)),IF($D9>$F9,1,0),0)+IF(AND(ISNUMBER($E9),ISNUMBER($F9)),IF($E9>$F9,1,0),0) -> 0 | X9: CC 初評
A10: SRC_ZP_006 | B10: rev_onprem_fy22 | C10: 本地化部署收入（舊分部） | D10: 0.5482 | G10: RMB 億 | H10: FY2022 | I10: 智譜招股章程（概要節） | J10: https://www1.hkexnews.hk/listedco/listconews/sehk/2025/1230/2025123000018_c.pdf | K10: 2025-12-30 | L10: 2026-10-08 | M10: Verified | O10: 經審計（會計師報告，招股章程概要轉載） | P10: 1 | Q10: 利害關係方 | R10: 經審計或經審閱的公司公告（誘因：上市後股價、配售；數字可由公告原文核對） | S10: 一手 | T10: 原文「本地化部署 54,815 95.5%」；千元值 54,815；RMB 千元÷100,000 換算成億；占比 95.5/90.4/84.5/59.7/84.8% | U10: =IF(AND($D10="",$E10="",$F10=""),1,0) -> 0 | V10: =IF(OR($I10="",$I10="—"),1,0) -> 0 | W10: =IF(AND(ISNUMBER($D10),ISNUMBER($E10)),IF($E10>$D10,1,0),0)+IF(AND(ISNUMBER($D10),ISNUMBER($F10)),IF($D10>$F10,1,0),0)+IF(AND(ISNUMBER($E10),ISNUMBER($F10)),IF($E10>$F10,1,0),0) -> 0 | X10: CC 初評
A11: SRC_ZP_007 | B11: rev_onprem_fy23 | C11: 本地化部署收入（舊分部） | D11: 1.1261 | G11: RMB 億 | H11: FY2023 | I11: 智譜招股章程（概要節） | J11: https://www1.hkexnews.hk/listedco/listconews/sehk/2025/1230/2025123000018_c.pdf | K11: 2025-12-30 | L11: 2026-10-08 | M11: Verified | O11: 經審計（會計師報告，招股章程概要轉載） | P11: 1 | Q11: 利害關係方 | R11: 經審計或經審閱的公司公告（誘因：上市後股價、配售；數字可由公告原文核對） | S11: 一手 | T11: 原文「本地化部署 54,815 95.5%」；千元值 112,614；RMB 千元÷100,000 換算成億；占比 95.5/90.4/84.5/59.7/84.8% | U11: =IF(AND($D11="",$E11="",$F11=""),1,0) -> 0 | V11: =IF(OR($I11="",$I11="—"),1,0) -> 0 | W11: =IF(AND(ISNUMBER($D11),ISNUMBER($E11)),IF($E11>$D11,1,0),0)+IF(AND(ISNUMBER($D11),ISNUMBER($F11)),IF($D11>$F11,1,0),0)+IF(AND(ISNUMBER($E11),ISNUMBER($F11)),IF($E11>$F11,1,0),0) -> 0 | X11: CC 初評
A12: SRC_ZP_008 | B12: rev_onprem_fy24 | C12: 本地化部署收入（舊分部） | D12: 2.6393 | G12: RMB 億 | H12: FY2024 | I12: 智譜招股章程（概要節） | J12: https://www1.hkexnews.hk/listedco/listconews/sehk/2025/1230/2025123000018_c.pdf | K12: 2025-12-30 | L12: 2026-10-08 | M12: Verified | O12: 經審計（會計師報告，招股章程概要轉載） | P12: 1 | Q12: 利害關係方 | R12: 經審計或經審閱的公司公告（誘因：上市後股價、配售；數字可由公告原文核對） | S12: 一手 | T12: 原文「本地化部署 54,815 95.5%」；千元值 263,930；RMB 千元÷100,000 換算成億；占比 95.5/90.4/84.5/59.7/84.8% | U12: =IF(AND($D12="",$E12="",$F12=""),1,0) -> 0 | V12: =IF(OR($I12="",$I12="—"),1,0) -> 0 | W12: =IF(AND(ISNUMBER($D12),ISNUMBER($E12)),IF($E12>$D12,1,0),0)+IF(AND(ISNUMBER($D12),ISNUMBER($F12)),IF($D12>$F12,1,0),0)+IF(AND(ISNUMBER($E12),ISNUMBER($F12)),IF($E12>$F12,1,0),0) -> 0 | X12: CC 初評
A13: SRC_ZP_009 | B13: rev_onprem_1h24 | C13: 本地化部署收入（舊分部） | D13: 0.2681 | G13: RMB 億 | H13: 1H2024 | I13: 智譜招股章程（概要節） | J13: https://www1.hkexnews.hk/listedco/listconews/sehk/2025/1230/2025123000018_c.pdf | K13: 2025-12-30 | L13: 2026-10-08 | M13: Verified | O13: 會計師報告（1H2024 比較期通常為未經審計已審閱；招股章程概要轉載） | P13: 1 | Q13: 利害關係方 | R13: 經審計或經審閱的公司公告（誘因：上市後股價、配售；數字可由公告原文核對） | S13: 一手 | T13: 原文「本地化部署 54,815 95.5%」；千元值 26,806；RMB 千元÷100,000 換算成億；占比 95.5/90.4/84.5/59.7/84.8% | U13: =IF(AND($D13="",$E13="",$F13=""),1,0) -> 0 | V13: =IF(OR($I13="",$I13="—"),1,0) -> 0 | W13: =IF(AND(ISNUMBER($D13),ISNUMBER($E13)),IF($E13>$D13,1,0),0)+IF(AND(ISNUMBER($D13),ISNUMBER($F13)),IF($D13>$F13,1,0),0)+IF(AND(ISNUMBER($E13),ISNUMBER($F13)),IF($E13>$F13,1,0),0) -> 0 | X13: CC 初評
A14: SRC_ZP_010 | B14: rev_onprem_1h25 | C14: 本地化部署收入（舊分部） | D14: 1.6178 | G14: RMB 億 | H14: 1H2025 | I14: 智譜招股章程（概要節） | J14: https://www1.hkexnews.hk/listedco/listconews/sehk/2025/1230/2025123000018_c.pdf | K14: 2025-12-30 | L14: 2026-10-08 | M14: Verified | O14: 經審計（會計師報告，招股章程概要轉載） | P14: 1 | Q14: 利害關係方 | R14: 經審計或經審閱的公司公告（誘因：上市後股價、配售；數字可由公告原文核對） | S14: 一手 | T14: 原文「本地化部署 54,815 95.5%」；千元值 161,777；RMB 千元÷100,000 換算成億；占比 95.5/90.4/84.5/59.7/84.8% | U14: =IF(AND($D14="",$E14="",$F14=""),1,0) -> 0 | V14: =IF(OR($I14="",$I14="—"),1,0) -> 0 | W14: =IF(AND(ISNUMBER($D14),ISNUMBER($E14)),IF($E14>$D14,1,0),0)+IF(AND(ISNUMBER($D14),ISNUMBER($F14)),IF($D14>$F14,1,0),0)+IF(AND(ISNUMBER($E14),ISNUMBER($F14)),IF($E14>$F14,1,0),0) -> 0 | X14: CC 初評
A15: SRC_ZP_011 | B15: rev_cloud_fy22 | C15: 雲端部署收入（舊分部；＝開放平台及API） | D15: 0.0259 | G15: RMB 億 | H15: FY2022 | I15: 智譜招股章程（概要節） | J15: https://www1.hkexnews.hk/listedco/listconews/sehk/2025/1230/2025123000018_c.pdf | K15: 2025-12-30 | L15: 2026-10-08 | M15: Verified | O15: 經審計（會計師報告，招股章程概要轉載） | P15: 1 | Q15: 利害關係方 | R15: 經審計或經審閱的公司公告（誘因：上市後股價、配售；數字可由公告原文核對） | S15: 一手 | T15: 原文「雲端部署 2,594 4.5%」；千元值 2,594；RMB 千元÷100,000 換算成億；占比 4.5/9.6/15.5/40.3/15.2%；2025 起新分類下雲端部署＝開放平台及 API | U15: =IF(AND($D15="",$E15="",$F15=""),1,0) -> 0 | V15: =IF(OR($I15="",$I15="—"),1,0) -> 0 | W15: =IF(AND(ISNUMBER($D15),ISNUMBER($E15)),IF($E15>$D15,1,0),0)+IF(AND(ISNUMBER($D15),ISNUMBER($F15)),IF($D15>$F15,1,0),0)+IF(AND(ISNUMBER($E15),ISNUMBER($F15)),IF($E15>$F15,1,0),0) -> 0 | X15: CC 初評
A16: SRC_ZP_012 | B16: rev_cloud_fy23 | C16: 雲端部署收入（舊分部；＝開放平台及API） | D16: 0.1192 | G16: RMB 億 | H16: FY2023 | I16: 智譜招股章程（概要節） | J16: https://www1.hkexnews.hk/listedco/listconews/sehk/2025/1230/2025123000018_c.pdf | K16: 2025-12-30 | L16: 2026-10-08 | M16: Verified | O16: 經審計（會計師報告，招股章程概要轉載） | P16: 1 | Q16: 利害關係方 | R16: 經審計或經審閱的公司公告（誘因：上市後股價、配售；數字可由公告原文核對） | S16: 一手 | T16: 原文「雲端部署 2,594 4.5%」；千元值 11,924；RMB 千元÷100,000 換算成億；占比 4.5/9.6/15.5/40.3/15.2%；2025 起新分類下雲端部署＝開放平台及 API | U16: =IF(AND($D16="",$E16="",$F16=""),1,0) -> 0 | V16: =IF(OR($I16="",$I16="—"),1,0) -> 0 | W16: =IF(AND(ISNUMBER($D16),ISNUMBER($E16)),IF($E16>$D16,1,0),0)+IF(AND(ISNUMBER($D16),ISNUMBER($F16)),IF($D16>$F16,1,0),0)+IF(AND(ISNUMBER($E16),ISNUMBER($F16)),IF($E16>$F16,1,0),0) -> 0 | X16: CC 初評
... A109: SRC_ZP_105 | B109: gm_total_1h25 | C109: 整體毛利率 | D109: 50 | G109: % | H109: 1H2025 | I109: 智譜招股章程（概要節） | J109: https://www1.hkexnews.hk/listedco/listconews/sehk/2025/1230/2025123000018_c.pdf | K109: 2025-12-30 | L109: 2026-10-08 | M109: Verified | O109: 經審計（會計師報告，招股章程概要轉載） | P109: 1 | Q109: 利害關係方 | R109: 經審計或經審閱的公司公告（誘因：上市後股價、配售；數字可由公告原文核對） | S109: 一手 | T109: 原文「毛利 31,360 54.6」表內毛利率欄 | U109: =IF(AND($D109="",$E109="",$F109=""),1,0) -> 0 | V109: =IF(OR($I109="",$I109="—"),1,0) -> 0 | W109: =IF(AND(ISNUMBER($D109),ISNUMBER($E109)),IF($E109>$D109,1,0),0)+IF(AND(ISNUMBER($D109),ISNUMBER($F109)),IF($D109>$F109,1,0),0)+IF(AND(ISNUMBER($E109),ISNUMBER($F109)),IF($E109>$F109,1,0),0) -> 0 | X109: CC 初評
A110: SRC_ZP_106 | B110: cash_burn_m_fy22 | C110: 平均每月現金消耗率 | D110: 0.03 | G110: RMB 億／月 | H110: FY2022 | I110: 智譜招股章程（概要節） | J110: https://www1.hkexnews.hk/listedco/listconews/sehk/2025/1230/2025123000017.pdf | K110: 2025-12-30 | L110: 2026-10-08 | M110: Interested-party | N110: 智譜：IPO 招股，誘因為發行定價 | O110: 管理層口徑（招股章程） | P110: 1 | Q110: 利害關係方 | R110: 智譜：IPO 招股，誘因為發行定價 | S110: 一手 | T110: 原文 average monthly cash burn RMB3.0 million；含經營現金流、購置設備、理財淨額、租賃付款；百萬÷100 換算成億 | U110: =IF(AND($D110="",$E110="",$F110=""),1,0) -> 0 | V110: =IF(OR($I110="",$I110="—"),1,0) -> 0 | W110: =IF(AND(ISNUMBER($D110),ISNUMBER($E110)),IF($E110>$D110,1,0),0)+IF(AND(ISNUMBER($D110),ISNUMBER($F110)),IF($D110>$F110,1,0),0)+IF(AND(ISNUMBER($E110),ISNUMBER($F110)),IF($E110>$F110,1,0),0) -> 0 | X110: CC 初評
A111: SRC_ZP_107 | B111: cash_burn_m_fy23 | C111: 平均每月現金消耗率 | D111: 1.059 | G111: RMB 億／月 | H111: FY2023 | I111: 智譜招股章程（概要節） | J111: https://www1.hkexnews.hk/listedco/listconews/sehk/2025/1230/2025123000017.pdf | K111: 2025-12-30 | L111: 2026-10-08 | M111: Interested-party | N111: 智譜：IPO 招股，誘因為發行定價 | O111: 管理層口徑（招股章程） | P111: 1 | Q111: 利害關係方 | R111: 智譜：IPO 招股，誘因為發行定價 | S111: 一手 | T111: 原文 average monthly cash burn RMB105.9 million；含經營現金流、購置設備、理財淨額、租賃付款；百萬÷100 換算成億 | U111: =IF(AND($D111="",$E111="",$F111=""),1,0) -> 0 | V111: =IF(OR($I111="",$I111="—"),1,0) -> 0 | W111: =IF(AND(ISNUMBER($D111),ISNUMBER($E111)),IF($E111>$D111,1,0),0)+IF(AND(ISNUMBER($D111),ISNUMBER($F111)),IF($D111>$F111,1,0),0)+IF(AND(ISNUMBER($E111),ISNUMBER($F111)),IF($E111>$F111,1,0),0) -> 0 | X111: CC 初評
A112: SRC_ZP_108 | B112: cash_burn_m_fy24 | C112: 平均每月現金消耗率 | D112: 1.945 | G112: RMB 億／月 | H112: FY2024 | I112: 智譜招股章程（概要節） | J112: https://www1.hkexnews.hk/listedco/listconews/sehk/2025/1230/2025123000017.pdf | K112: 2025-12-30 | L112: 2026-10-08 | M112: Interested-party | N112: 智譜：IPO 招股，誘因為發行定價 | O112: 管理層口徑（招股章程） | P112: 1 | Q112: 利害關係方 | R112: 智譜：IPO 招股，誘因為發行定價 | S112: 一手 | T112: 原文 average monthly cash burn RMB194.5 million；含經營現金流、購置設備、理財淨額、租賃付款；百萬÷100 換算成億 | U112: =IF(AND($D112="",$E112="",$F112=""),1,0) -> 0 | V112: =IF(OR($I112="",$I112="—"),1,0) -> 0 | W112: =IF(AND(ISNUMBER($D112),ISNUMBER($E112)),IF($E112>$D112,1,0),0)+IF(AND(ISNUMBER($D112),ISNUMBER($F112)),IF($D112>$F112,1,0),0)+IF(AND(ISNUMBER($E112),ISNUMBER($F112)),IF($E112>$F112,1,0),0) -> 0 | X112: CC 初評
A113: SRC_ZP_109 | B113: cash_burn_m_1h25 | C113: 平均每月現金消耗率 | D113: 3.273 | G113: RMB 億／月 | H113: 1H2025 | I113: 智譜招股章程（概要節） | J113: https://www1.hkexnews.hk/listedco/listconews/sehk/2025/1230/2025123000017.pdf | K113: 2025-12-30 | L113: 2026-10-08 | M113: Interested-party | N113: 智譜：IPO 招股，誘因為發行定價 | O113: 管理層口徑（招股章程） | P113: 1 | Q113: 利害關係方 | R113: 智譜：IPO 招股，誘因為發行定價 | S113: 一手 | T113: 原文 average monthly cash burn RMB327.3 million；含經營現金流、購置設備、理財淨額、租賃付款；百萬÷100 換算成億 | U113: =IF(AND($D113="",$E113="",$F113=""),1,0) -> 0 | V113: =IF(OR($I113="",$I113="—"),1,0) -> 0 | W113: =IF(AND(ISNUMBER($D113),ISNUMBER($E113)),IF($E113>$D113,1,0),0)+IF(AND(ISNUMBER($D113),ISNUMBER($F113)),IF($D113>$F113,1,0),0)+IF(AND(ISNUMBER($E113),ISNUMBER($F113)),IF($E113>$F113,1,0),0) -> 0 | X113: CC 初評
A114: SRC_ZP_110 | B114: liquidity_2510 | C114: 現金＋FVPL 短期投資＋可用承諾銀行授信合計 | D114: 89.431 | G114: RMB 億 | H114: 2025-10-31 | I114: 智譜招股章程（概要節） | J114: https://www1.hkexnews.hk/listedco/listconews/sehk/2025/1230/2025123000017.pdf | K114: 2025-12-30 | L114: 2026-10-08 | M114: Interested-party | N114: 智譜：IPO 招股，營運資金說明 | O114: 管理層口徑（招股章程營運資金充足性） | P114: 1 | Q114: 利害關係方 | R114: 智譜：IPO 招股，營運資金說明 | S114: 一手 | T114: 原文「available committed bank facilities of RMB8,943.1 million in aggregate」；三項合計，未拆授信額 | U114: =IF(AND($D114="",$E114="",$F114=""),1,0) -> 0 | V114: =IF(OR($I114="",$I114="—"),1,0) -> 0 | W114: =IF(AND(ISNUMBER($D114),ISNUMBER($E114)),IF($E114>$D114,1,0),0)+IF(AND(ISNUMBER($D114),ISNUMBER($F114)),IF($D114>$F114,1,0),0)+IF(AND(ISNUMBER($E114),ISNUMBER($F114)),IF($E114>$F114,1,0),0) -> 0 | X114: CC 初評
A115: SRC_ZP_111 | B115: rd_staff_1h25 | C115: 研發團隊人數 | D115: 657 | G115: 人 | H115: 2025-06-30 | I115: 智譜招股章程（概要節） | J115: https://www1.hkexnews.hk/listedco/listconews/sehk/2025/1230/2025123000018_c.pdf | K115: 2025-12-30 | L115: 2026-10-08 | M115: Verified | O115: 管理層口徑 | P115: 1 | Q115: 利害關係方 | R115: 經審計或經審閱的公司公告（誘因：上市後股價、配售；數字可由公告原文核對） | S115: 一手 | T115: 原文「一支由657名成員組成的研發團隊」 | U115: =IF(AND($D115="",$E115="",$F115=""),1,0) -> 0 | V115: =IF(OR($I115="",$I115="—"),1,0) -> 0 | W115: =IF(AND(ISNUMBER($D115),ISNUMBER($E115)),IF($E115>$D115,1,0),0)+IF(AND(ISNUMBER($D115),ISNUMBER($F115)),IF($D115>$F115,1,0),0)+IF(AND(ISNUMBER($E115),ISNUMBER($F115)),IF($E115>$F115,1,0),0) -> 0 | X115: CC 初評
A116: SRC_ZP_112 | B116: rev_api_fy25 | C116: 開放平台及 API 收入（新分類） | D116: 1.9038 | G116: RMB 億 | H116: FY2025 | I116: 智譜 2025 年度業績公告 | J116: https://www1.hkexnews.hk/listedco/listconews/sehk/2026/0331/2026033101549.pdf | K116: 2026-03-31 | L116: 2026-10-08 | M116: Verified | O116: 經審計（KPMG；年度業績公告） | P116: 1 | Q116: 利害關係方 | R116: 經審計或經審閱的公司公告（誘因：上市後股價、配售；數字可由公告原文核對） | S116: 一手 | T116: 原文「Open Platform and API」；千元值 190,379；RMB 千元÷100,000 換算成億；2025 占營收 26.3%；新分類下＝雲端部署 | U116: =IF(AND($D116="",$E116="",$F116=""),1,0) -> 0 | V116: =IF(OR($I116="",$I116="—"),1,0) -> 0 | W116: =IF(AND(ISNUMBER($D116),ISNUMBER($E116)),IF($E116>$D116,1,0),0)+IF(AND(ISNUMBER($D116),ISNUMBER($F116)),IF($D116>$F116,1,0),0)+IF(AND(ISNUMBER($E116),ISNUMBER($F116)),IF($E116>$F116,1,0),0) -> 0 | X116: CC 初評
A117: SRC_ZP_113 | B117: rev_api_fy24 | C117: 開放平台及 API 收入（新分類） | D117: 0.4848 | G117: RMB 億 | H117: FY2024 | I117: 智譜 2025 年度業績公告 | J117: https://www1.hkexnews.hk/listedco/listconews/sehk/2026/0331/2026033101549.pdf | K117: 2026-03-31 | L117: 2026-10-08 | M117: Verified | O117: 經審計（KPMG；年度業績公告） | P117: 1 | Q117: 利害關係方 | R117: 經審計或經審閱的公司公告（誘因：上市後股價、配售；數字可由公告原文核對） | S117: 一手 | T117: 原文「Open Platform and API」；千元值 48,484；RMB 千元÷100,000 換算成億；2025 占營收 26.3%；新分類下＝雲端部署 | U117: =IF(AND($D117="",$E117="",$F117=""),1,0) -> 0 | V117: =IF(OR($I117="",$I117="—"),1,0) -> 0 | W117: =IF(AND(ISNUMBER($D117),ISNUMBER($E117)),IF($E117>$D117,1,0),0)+IF(AND(ISNUMBER($D117),ISNUMBER($F117)),IF($D117>$F117,1,0),0)+IF(AND(ISNUMBER($E117),ISNUMBER($F117)),IF($E117>$F117,1,0),0) -> 0 | X117: CC 初評
A118: SRC_ZP_114 | B118: rev_agent_fy25 | C118: 企業級智能體收入（新分類） | D118: 1.6569 | G118: RMB 億 | H118: FY2025 | I118: 智譜 2025 年度業績公告 | J118: https://www1.hkexnews.hk/listedco/listconews/sehk/2026/0331/2026033101549.pdf | K118: 2026-03-31 | L118: 2026-10-08 | M118: Verified | O118: 經審計（KPMG；年度業績公告） | P118: 1 | Q118: 利害關係方 | R118: 經審計或經審閱的公司公告（誘因：上市後股價、配售；數字可由公告原文核對） | S118: 一手 | T118: 原文「Enterprise-level Agents」；千元值 165,687；RMB 千元÷100,000 換算成億；屬本地化部署分部 | U118: =IF(AND($D118="",$E118="",$F118=""),1,0) -> 0 | V118: =IF(OR($I118="",$I118="—"),1,0) -> 0 | W118: =IF(AND(ISNUMBER($D118),ISNUMBER($E118)),IF($E118>$D118,1,0),0)+IF(AND(ISNUMBER($D118),ISNUMBER($F118)),IF($D118>$F118,1,0),0)+IF(AND(ISNUMBER($E118),ISNUMBER($F118)),IF($E118>$F118,1,0),0) -> 0 | X118: CC 初評
A119: SRC_ZP_115 | B119: rev_agent_fy24 | C119: 企業級智能體收入（新分類） | D119: 0.4749 | G119: RMB 億 | H119: FY2024 | I119: 智譜 2025 年度業績公告 | J119: https://www1.hkexnews.hk/listedco/listconews/sehk/2026/0331/2026033101549.pdf | K119: 2026-03-31 | L119: 2026-10-08 | M119: Verified | O119: 經審計（KPMG；年度業績公告） | P119: 1 | Q119: 利害關係方 | R119: 經審計或經審閱的公司公告（誘因：上市後股價、配售；數字可由公告原文核對） | S119: 一手 | T119: 原文「Enterprise-level Agents」；千元值 47,492；RMB 千元÷100,000 換算成億；屬本地化部署分部 | U119: =IF(AND($D119="",$E119="",$F119=""),1,0) -> 0 | V119: =IF(OR($I119="",$I119="—"),1,0) -> 0 | W119: =IF(AND(ISNUMBER($D119),ISNUMBER($E119)),IF($E119>$D119,1,0),0)+IF(AND(ISNUMBER($D119),ISNUMBER($F119)),IF($D119>$F119,1,0),0)+IF(AND(ISNUMBER($E119),ISNUMBER($F119)),IF($E119>$F119,1,0),0) -> 0 | X119: CC 初評
A120: SRC_ZP_116 | B120: rev_gpllm_fy25 | C120: 企業級通用大模型收入（新分類） | D120: 3.6572 | G120: RMB 億 | H120: FY2025 | I120: 智譜 2025 年度業績公告 | J120: https://www1.hkexnews.hk/listedco/listconews/sehk/2026/0331/2026033101549.pdf | K120: 2026-03-31 | L120: 2026-10-08 | M120: Verified | O120: 經審計（KPMG；年度業績公告） | P120: 1 | Q120: 利害關係方 | R120: 經審計或經審閱的公司公告（誘因：上市後股價、配售；數字可由公告原文核對） | S120: 一手 | T120: 原文「Enterprise-level General-purpose Large Models」；千元值 365,724；RMB 千元÷100,000 換算成億；屬本地化部署分部 | U120: =IF(AND($D120="",$E120="",$F120=""),1,0) -> 0 | V120: =IF(OR($I120="",$I120="—"),1,0) -> 0 | W120: =IF(AND(ISNUMBER($D120),ISNUMBER($E120)),IF($E120>$D120,1,0),0)+IF(AND(ISNUMBER($D120),ISNUMBER($F120)),IF($D120>$F120,1,0),0)+IF(AND(ISNUMBER($E120),ISNUMBER($F120)),IF($E120>$F120,1,0),0) -> 0 | X120: CC 初評
A121: SRC_ZP_117 | B121: rev_gpllm_fy24 | C121: 企業級通用大模型收入（新分類） | D121: 2.145 | G121: RMB 億 | H121: FY2024 | I121: 智譜 2025 年度業績公告 | J121: https://www1.hkexnews.hk/listedco/listconews/sehk/2026/0331/2026033101549.pdf | K121: 2026-03-31 | L121: 2026-10-08 | M121: Verified | O121: 經審計（KPMG；年度業績公告） | P121: 1 | Q121: 利害關係方 | R121: 經審計或經審閱的公司公告（誘因：上市後股價、配售；數字可由公告原文核對） | S121: 一手 | T121: 原文「Enterprise-level General-purpose Large Models」；千元值 214,502；RMB 千元÷100,000 換算成億；屬本地化部署分部 | U121: =IF(AND($D121="",$E121="",$F121=""),1,0) -> 0 | V121: =IF(OR($I121="",$I121="—"),1,0) -> 0 | W121: =IF(AND(ISNUMBER($D121),ISNUMBER($E121)),IF($E121>$D121,1,0),0)+IF(AND(ISNUMBER($D121),ISNUMBER($F121)),IF($D121>$F121,1,0),0)+IF(AND(ISNUMBER($E121),ISNUMBER($F121)),IF($E121>$F121,1,0),0) -> 0 | X121: CC 初評
A122: SRC_ZP_118 | B122: rev_techsvc_fy25 | C122: 技術服務及其他收入（新分類） | D122: 0.0254 | G122: RMB 億 | H122: FY2025 | I122: 智譜 2025 年度業績公告 | J122: https://www1.hkexnews.hk/listedco/listconews/sehk/2026/0331/2026033101549.pdf | K122: 2026-03-31 | L122: 2026-10-08 | M122: Verified | O122: 經審計（KPMG；年度業績公告） | P122: 1 | Q122: 利害關係方 | R122: 經審計或經審閱的公司公告（誘因：上市後股價、配售；數字可由公告原文核對） | S122: 一手 | T122: 原文「Technical Services and Others」；千元值 2,544；RMB 千元÷100,000 換算成億 | U122: =IF(AND($D122="",$E122="",$F122=""),1,0) -> 0 | V122: =IF(OR($I122="",$I122="—"),1,0) -> 0 | W122: =IF(AND(ISNUMBER($D122),ISNUMBER($E122)),IF($E122>$D122,1,0),0)+IF(AND(ISNUMBER($D122),ISNUMBER($F122)),IF($D122>$F122,1,0),0)+IF(AND(ISNUMBER($E122),ISNUMBER($F122)),IF($E122>$F122,1,0),0) -> 0 | X122: CC 初評
A123: SRC_ZP_119 | B123: rev_techsvc_fy24 | C123: 技術服務及其他收入（新分類） | D123: 0.0194 | G123: RMB 億 | H123: FY2024 | I123: 智譜 2025 年度業績公告 | J123: https://www1.hkexnews.hk/listedco/listconews/sehk/2026/0331/2026033101549.pdf | K123: 2026-03-31 | L123: 2026-10-08 | M123: Verified | O123: 經審計（KPMG；年度業績公告） | P123: 1 | Q123: 利害關係方 | R123: 經審計或經審閱的公司公告（誘因：上市後股價、配售；數字可由公告原文核對） | S123: 一手 | T123: 原文「Technical Services and Others」；千元值 1,936；RMB 千元÷100,000 換算成億 | U123: =IF(AND($D123="",$E123="",$F123=""),1,0) -> 0 | V123: =IF(OR($I123="",$I123="—"),1,0) -> 0 | W123: =IF(AND(ISNUMBER($D123),ISNUMBER($E123)),IF($E123>$D123,1,0),0)+IF(AND(ISNUMBER($D123),ISNUMBER($F123)),IF($D123>$F123,1,0),0)+IF(AND(ISNUMBER($E123),ISNUMBER($F123)),IF($E123>$F123,1,0),0) -> 0 | X123: CC 初評
A124: SRC_ZP_120 | B124: rev_total_fy25 | C124: 營收總額 | D124: 7.2433 | G124: RMB 億 | H124: FY2025 | I124: 智譜 2025 年度業績公告 | J124: https://www1.hkexnews.hk/listedco/listconews/sehk/2026/0331/2026033101549.pdf | K124: 2026-03-31 | L124: 2026-10-08 | M124: Verified | O124: 經審計（KPMG；年度業績公告） | P124: 1 | Q124: 利害關係方 | R124: 經審計或經審閱的公司公告（誘因：上市後股價、配售；數字可由公告原文核對） | S124: 一手 | T124: 原文「total revenue reached RMB724.3 million」，同比 +131.9%；千元 724,334；RMB 千元÷100,000 換算成億 | U124: =IF(AND($D124="",$E124="",$F124=""),1,0) -> 0 | V124: =IF(OR($I124="",$I124="—"),1,0) -> 0 | W124: =IF(AND(ISNUMBER($D124),ISNUMBER($E124)),IF($E124>$D124,1,0),0)+IF(AND(ISNUMBER($D124),ISNUMBER($F124)),IF($D124>$F124,1,0),0)+IF(AND(ISNUMBER($E124),ISNUMBER($F124)),IF($E124>$F124,1,0),0) -> 0 | X124: CC 初評
A125: SRC_ZP_121 | B125: rev_onprem_fy25 | C125: 本地化部署收入（分部） | D125: 5.3396 | G125: RMB 億 | H125: FY2025 | I125: 智譜 2025 年度業績公告 | J125: https://www1.hkexnews.hk/listedco/listconews/sehk/2026/0331/2026033101549.pdf | K125: 2026-03-31 | L125: 2026-10-08 | M125: Verified | O125: 經審計（KPMG；年度業績公告） | P125: 1 | Q125: 利害關係方 | R125: 經審計或經審閱的公司公告（誘因：上市後股價、配售；數字可由公告原文核對） | S125: 一手 | T125: 分部附註 on-premise deployment 533,955 千元（＝智能體＋通用大模型＋技術服務）；RMB 千元÷100,000 換算成億 | U125: =IF(AND($D125="",$E125="",$F125=""),1,0) -> 0 | V125: =IF(OR($I125="",$I125="—"),1,0) -> 0 | W125: =IF(AND(ISNUMBER($D125),ISNUMBER($E125)),IF($E125>$D125,1,0),0)+IF(AND(ISNUMBER($D125),ISNUMBER($F125)),IF($D125>$F125,1,0),0)+IF(AND(ISNUMBER($E125),ISNUMBER($F125)),IF($E125>$F125,1,0),0) -> 0 | X125: CC 初評
A126: SRC_ZP_122 | B126: rev_cloud_fy25 | C126: 雲端部署收入（分部） | D126: 1.9038 | G126: RMB 億 | H126: FY2025 | I126: 智譜 2025 年度業績公告 | J126: https://www1.hkexnews.hk/listedco/listconews/sehk/2026/0331/2026033101549.pdf | K126: 2026-03-31 | L126: 2026-10-08 | M126: Verified | O126: 經審計（KPMG；年度業績公告） | P126: 1 | Q126: 利害關係方 | R126: 經審計或經審閱的公司公告（誘因：上市後股價、配售；數字可由公告原文核對） | S126: 一手 | T126: 分部附註 cloud-based deployment 190,379 千元＝開放平台及 API；RMB 千元÷100,000 換算成億 | U126: =IF(AND($D126="",$E126="",$F126=""),1,0) -> 0 | V126: =IF(OR($I126="",$I126="—"),1,0) -> 0 | W126: =IF(AND(ISNUMBER($D126),ISNUMBER($E126)),IF($E126>$D126,1,0),0)+IF(AND(ISNUMBER($D126),ISNUMBER($F126)),IF($D126>$F126,1,0),0)+IF(AND(ISNUMBER($E126),ISNUMBER($F126)),IF($E126>$F126,1,0),0) -> 0 | X126: CC 初評
... A168: SRC_ZP_164 | B168: comp_per_head_fy25 | C168: 人均薪酬（含股權報酬） | D168: 0.01246 | G168: RMB 億／人 | H168: FY2025 | I168: 智譜 2025 年度業績公告 | J168: https://www1.hkexnews.hk/listedco/listconews/sehk/2026/0331/2026033101549.pdf | K168: 2026-03-31 | L168: 2026-10-08 | M168: Derived | O168: Derived | P168: 2 | Q168: 推算 | R168: 由其他 SRC 列推算（見備註）；立場同其來源 | S168: 一手 | T168: 1,363.4 百萬÷期末人數 1,094＝約 RMB 124.6 萬／人；以期末人數計（無平均人數） | U168: =IF(AND($D168="",$E168="",$F168=""),1,0) -> 0 | V168: =IF(OR($I168="",$I168="—"),1,0) -> 0 | W168: =IF(AND(ISNUMBER($D168),ISNUMBER($E168)),IF($E168>$D168,1,0),0)+IF(AND(ISNUMBER($D168),ISNUMBER($F168)),IF($D168>$F168,1,0),0)+IF(AND(ISNUMBER($E168),ISNUMBER($F168)),IF($E168>$F168,1,0),0) -> 0 | X168: CC 初評
A169: SRC_ZP_165 | B169: esop_fy25 | C169: 員工激勵計畫 | H169: FY2025 | I169: 智譜 2025 年度業績公告 | J169: https://www1.hkexnews.hk/listedco/listconews/sehk/2026/0331/2026033101549.pdf | K169: 2026-03-31 | L169: 2026-10-08 | M169: Verified | O169: 經審計（KPMG；年度業績公告） | P169: 1 | Q169: 利害關係方 | R169: 經審計或經審閱的公司公告（誘因：上市後股價、配售；數字可由公告原文核對） | S169: 一手 | T169: 原文「adopted the employee incentive scheme and established an employee shareholding platform」；條款未揭露 | U169: =IF(AND($D169="",$E169="",$F169=""),1,0) -> 1 | V169: =IF(OR($I169="",$I169="—"),1,0) -> 0 | W169: =IF(AND(ISNUMBER($D169),ISNUMBER($E169)),IF($E169>$D169,1,0),0)+IF(AND(ISNUMBER($D169),ISNUMBER($F169)),IF($D169>$F169,1,0),0)+IF(AND(ISNUMBER($E169),ISNUMBER($F169)),IF($E169>$F169,1,0),0) -> 0 | X169: CC 初評
A170: SRC_ZP_166 | B170: api_price_fy25 | C170: API 呼叫價格較上年底上升 | D170: 83 | G170: % | H170: 2026Q1（公告時點） | I170: 智譜 2025 年度業績公告 | J170: https://www1.hkexnews.hk/listedco/listconews/sehk/2026/0331/2026033101549.pdf | K170: 2026-03-31 | L170: 2026-10-08 | M170: Interested-party | N170: 智譜：上市後股價、配售誘因 | O170: 管理層口徑 | P170: 1 | Q170: 利害關係方 | R170: 智譜：上市後股價、配售誘因 | S170: 一手 | T170: 原文「an 83% increase in API call pricing compared to the end of last year」 | U170: =IF(AND($D170="",$E170="",$F170=""),1,0) -> 0 | V170: =IF(OR($I170="",$I170="—"),1,0) -> 0 | W170: =IF(AND(ISNUMBER($D170),ISNUMBER($E170)),IF($E170>$D170,1,0),0)+IF(AND(ISNUMBER($D170),ISNUMBER($F170)),IF($D170>$F170,1,0),0)+IF(AND(ISNUMBER($E170),ISNUMBER($F170)),IF($E170>$F170,1,0),0) -> 0 | X170: CC 初評
A171: SRC_ZP_167 | B171: codingplan_class_fy25 | C171: GLM Coding Plan 收入歸屬 | H171: FY2025 | I171: 智譜 2025 年度業績公告 | J171: https://www1.hkexnews.hk/listedco/listconews/sehk/2026/0331/2026033101549.pdf | K171: 2026-03-31 | L171: 2026-10-08 | M171: Derived | O171: Derived | P171: 2 | Q171: 推算 | R171: 由其他 SRC 列推算（見備註）；立場同其來源 | S171: 一手 | T171: 公告於開放平台及 API 毛利段提及「programming subscription packages」；未單列收入。判定歸入開放平台及 API（雲端） | U171: =IF(AND($D171="",$E171="",$F171=""),1,0) -> 1 | V171: =IF(OR($I171="",$I171="—"),1,0) -> 0 | W171: =IF(AND(ISNUMBER($D171),ISNUMBER($E171)),IF($E171>$D171,1,0),0)+IF(AND(ISNUMBER($D171),ISNUMBER($F171)),IF($D171>$F171,1,0),0)+IF(AND(ISNUMBER($E171),ISNUMBER($F171)),IF($E171>$F171,1,0),0) -> 0 | X171: CC 初評
A172: SRC_ZP_168 | B172: codingplan_paying_fy25 | C172: Coding Plan 付費開發者 | D172: 242000 | E172: 242000 | G172: 人 | H172: FY2025 | I172: 智譜 2025 年度業績公告 | J172: https://www1.hkexnews.hk/listedco/listconews/sehk/2026/0331/2026033101549.pdf | K172: 2026-03-31 | L172: 2026-10-08 | M172: Interested-party | N172: 智譜：上市後股價、配售誘因 | O172: 管理層口徑 | P172: 1 | Q172: 利害關係方 | R172: 智譜：上市後股價、配售誘因 | S172: 一手 | T172: 原文 over 242,000 paying Coding Plan developers（下限值） | U172: =IF(AND($D172="",$E172="",$F172=""),1,0) -> 0 | V172: =IF(OR($I172="",$I172="—"),1,0) -> 0 | W172: =IF(AND(ISNUMBER($D172),ISNUMBER($E172)),IF($E172>$D172,1,0),0)+IF(AND(ISNUMBER($D172),ISNUMBER($F172)),IF($D172>$F172,1,0),0)+IF(AND(ISNUMBER($E172),ISNUMBER($F172)),IF($E172>$F172,1,0),0) -> 0 | X172: CC 初評
A173: SRC_ZP_169 | B173: rev_api_1h26 | C173: 開放平台及 API 收入 | D173: 8.2518 | G173: RMB 億 | H173: 1H2026 | I173: 智譜（Z.AI）2026 中期業績公告 | J173: https://www1.hkexnews.hk/listedco/listconews/sehk/2026/0831/2026083101539.pdf | K173: 2026-08-31 | L173: 2026-10-08 | M173: Verified | O173: 未經審計（中期業績公告；是否經核數師審閱公告未見明載） | P173: 1 | Q173: 利害關係方 | R173: 經審計或經審閱的公司公告（誘因：上市後股價、配售；數字可由公告原文核對） | S173: 一手 | T173: 原文「Open Platform and API」；千元值 825,176；RMB 千元÷100,000 換算成億；1H26 占 86.5%（1H25 15.2%）；＝雲端部署分部 | U173: =IF(AND($D173="",$E173="",$F173=""),1,0) -> 0 | V173: =IF(OR($I173="",$I173="—"),1,0) -> 0 | W173: =IF(AND(ISNUMBER($D173),ISNUMBER($E173)),IF($E173>$D173,1,0),0)+IF(AND(ISNUMBER($D173),ISNUMBER($F173)),IF($D173>$F173,1,0),0)+IF(AND(ISNUMBER($E173),ISNUMBER($F173)),IF($E173>$F173,1,0),0) -> 0 | X173: CC 初評
...

Sheet TK_Link
A1: TK_Link — Tokenomics 快照（第 0 層連結；不用 Excel 外部連結）
A2: 具名區（同 OpenAI v0.6 的 63 名：IF_／SRC_DEM_／L1_）：值（藍字）由 builder 從 Tokenomics master 的 model/CURRENT 讀出寫入。本模型公式只引用 TK_ 名稱或本頁儲存格。
A3: Tokenomics 檔案 | B3: 20261007_Tokenomics_v5.26.xlsx
A4: Tokenomics 版本 | B4: v5.26
A5: Tokenomics 提交 SHA（master） | B5: 3dd1216688e3872fcb80b28c279d8976a07df29b
A6: 讀取日期 | B6: 2026-10-08
I7: 世代 | J7: Hopper H100 | K7: Hopper H100 | L7: Hopper H100 | M7: GB200 NVL72 | N7: GB200 NVL72 | O7: GB200 NVL72 | P7: GB300 NVL72 | Q7: GB300 NVL72 | R7: GB300 NVL72 | S7: VR200 NVL72 | T7: VR200 NVL72 | U7: VR200 NVL72 | V7: Rubin Ultra（MGX NVL 單架，72 GPU） | W7: Rubin Ultra（MGX NVL 單架，72 GPU） | X7: Rubin Ultra（MGX NVL 單架，72 GPU）
I8: 成本情境 | J8: 低成本 | K8: 基準 | L8: 高成本 | M8: 低成本 | N8: 基準 | O8: 高成本 | P8: 低成本 | Q8: 基準 | R8: 高成本 | S8: 低成本 | T8: 基準 | U8: 高成本 | V8: 低成本 | W8: 基準 | X8: 高成本
A9: Tokenomics 名稱 | B9: 本模型名稱 | C9: 說明 | D9: 單位 | E9: 欄數 | F9: 狀態 | G9: Tokenomics 版本 | H9: 提交 SHA | I9: 讀取日期 | J9: 值1 | K9: 值2 | L9: 值3 | M9: 值4 | N9: 值5 | O9: 值6 | P9: 值7 | Q9: 值8 | R9: 值9 | S9: 值10 | T9: 值11 | U9: 值12 | V9: 值13 | W9: 值14 | X9: 值15
A10: IF_TokGW_Astra | B10: TK_IF_TokGW_Astra | C10: 每 GW 總產出（100%） | D10: M tok/年 | E10: 15 | F10: OK | G10: v5.26 | H10: 3dd1216 | I10: 2026-10-08 | J10: 3.8765183e+09 | K10: 3.8765183e+09 | L10: 3.8765183e+09 | M10: 2.0041839e+10 | N10: 2.0041839e+10 | O10: 2.0041839e+10 | P10: 2.4234238e+10 | Q10: 2.4234238e+10 | R10: 2.4234238e+10 | S10: 5.1167891e+10 | T10: 5.1167891e+10 | U10: 5.1167891e+10 | V10: 7.4400956e+10 | W10: 7.4400956e+10 | X10: 7.4400956e+10
A11: IF_TokGW_Luna | B11: TK_IF_TokGW_Luna | C11: 每 GW 總產出（100%） | D11: M tok/年 | E11: 15 | F11: OK | G11: v5.26 | H11: 3dd1216 | I11: 2026-10-08 | J11: 7.4067251e+10 | K11: 7.4067251e+10 | L11: 7.4067251e+10 | M11: 3.6230689e+11 | N11: 3.6230689e+11 | O11: 3.6230689e+11 | P11: 5.2747392e+11 | Q11: 5.2747392e+11 | R11: 5.2747392e+11 | S11: 7.727784e+11 | T11: 7.727784e+11 | U11: 7.727784e+11 | V11: 1.0443737e+12 | W11: 1.0443737e+12 | X11: 1.0443737e+12
A12: IF_TokGW_Sol | B12: TK_IF_TokGW_Sol | C12: 每 GW 總產出（100%） | D12: M tok/年 | E12: 15 | F12: OK | G12: v5.26 | H12: 3dd1216 | I12: 2026-10-08 | J12: 2.149043e+10 | K12: 2.149043e+10 | L12: 2.149043e+10 | M12: 1.041254e+11 | N12: 1.041254e+11 | O12: 1.041254e+11 | P12: 1.5159367e+11 | Q12: 1.5159367e+11 | R12: 1.5159367e+11 | S12: 2.3728734e+11 | T12: 2.3728734e+11 | U12: 2.3728734e+11 | V12: 3.2618567e+11 | W12: 3.2618567e+11 | X12: 3.2618567e+11
A13: IF_Util | B13: TK_IF_Util | C13: 基準利用率（第 0 層；下游可覆寫） | D13: % | E13: 1 | F13: OK | G13: v5.26 | H13: 3dd1216 | I13: 2026-10-08 | J13: 0.6
A14: IF_HoldEcon | B14: TK_IF_HoldEcon | C14: 每 GW 年持有成本 — 經濟口徑 | D14: $B/年 | E14: 15 | F14: OK | G14: v5.26 | H14: 3dd1216 | I14: 2026-10-08 | J14: 7.0000433 | K14: 10.095795 | L14: 17.405972 | M14: 6.813167 | N14: 9.1709819 | O14: 14.920029 | P14: 8.7074708 | Q14: 12.724746 | R14: 23.871869 | S14: 9.8366806 | T14: 12.762016 | U14: 20.678089 | V14: 10.452242 | W14: 16.069457 | X14: 29.454615
A15: IF_FullCost_Astra | B15: TK_IF_FullCost_Astra | C15: 全成本 $/M（服務＋快取儲存＋自下而上攤提；基準利用率） | D15: $/M | E15: 15 | F15: OK | G15: v5.26 | H15: 3dd1216 | I15: 2026-10-08 | J15: 6.9823234 | K15: 10.07014 | L15: 17.361579 | M15: 0.92982466 | N15: 1.2515294 | O15: 2.0359402 | P15: 0.93305227 | Q15: 1.3634219 | R15: 2.5576103 | S15: 0.42538461 | T15: 0.55182355 | U15: 0.89397238 | V15: 0.27809403 | W15: 0.42742659 | X15: 0.78326839
A16: IF_FullCost_Luna | B16: TK_IF_FullCost_Luna | C16: 全成本 $/M（服務＋快取儲存＋自下而上攤提；基準利用率） | D16: $/M | E16: 15 | F16: OK | G16: v5.26 | H16: 3dd1216 | I16: 2026-10-08 | J16: 0.13332981 | K16: 0.19228981 | L16: 0.33151542 | M16: 0.02765365 | N16: 0.037219928 | O16: 0.060545328 | P16: 0.024207999 | Q16: 0.035371595 | R16: 0.066348304 | S16: 0.018368232 | T16: 0.023827547 | U16: 0.038600674 | V16: 0.014351218 | W16: 0.022057988 | X16: 0.04042231
A17: IF_FullCost_Sol | B17: TK_IF_FullCost_Sol | C17: 全成本 $/M（服務＋快取儲存＋自下而上攤提；基準利用率） | D17: $/M | E17: 15 | F17: OK | G17: v5.26 | H17: 3dd1216 | I17: 2026-10-08 | J17: 0.53191053 | K17: 0.76713986 | L17: 1.3226004 | M17: 0.10319199 | N17: 0.13889806 | O17: 0.22595995 | P17: 0.090371238 | Q17: 0.13205779 | R17: 0.2477295 | S17: 0.061571891 | T17: 0.079878216 | U17: 0.12941586 | V17: 0.046474526 | W17: 0.07144248 | X17: 0.13093816
A18: IF_PriceCached_Astra | B18: TK_IF_PriceCached_Astra | C18: 快取輸入 $/M — OpenAI 有效 | D18: $/M | E18: 1 | F18: OK | G18: v5.26 | H18: 3dd1216 | I18: 2026-10-08 | J18: 0.8
A19: IF_PriceCached_Luna | B19: TK_IF_PriceCached_Luna | C19: 快取輸入 $/M — OpenAI 有效 | D19: $/M | E19: 1 | F19: OK | G19: v5.26 | H19: 3dd1216 | I19: 2026-10-08 | J19: 0.008
A20: IF_PriceCached_Sol | B20: TK_IF_PriceCached_Sol | C20: 快取輸入 $/M — OpenAI 有效 | D20: $/M | E20: 1 | F20: OK | G20: v5.26 | H20: 3dd1216 | I20: 2026-10-08 | J20: 0.16
A21: IF_PriceFresh_Astra | B21: TK_IF_PriceFresh_Astra | C21: 新鮮輸入 $/M — OpenAI 有效 | D21: $/M | E21: 1 | F21: OK | G21: v5.26 | H21: 3dd1216 | I21: 2026-10-08 | J21: 8
A22: IF_PriceFresh_Luna | B22: TK_IF_PriceFresh_Luna | C22: 新鮮輸入 $/M — OpenAI 有效 | D22: $/M | E22: 1 | F22: OK | G22: v5.26 | H22: 3dd1216 | I22: 2026-10-08 | J22: 0.08
A23: IF_PriceFresh_Sol | B23: TK_IF_PriceFresh_Sol | C23: 新鮮輸入 $/M — OpenAI 有效 | D23: $/M | E23: 1 | F23: OK | G23: v5.26 | H23: 3dd1216 | I23: 2026-10-08 | J23: 1.6
A24: IF_PriceOut_Astra | B24: TK_IF_PriceOut_Astra | C24: 可見輸出 $/M — OpenAI 有效 | D24: $/M | E24: 1 | F24: OK | G24: v5.26 | H24: 3dd1216 | I24: 2026-10-08 | J24: 40
A25: IF_PriceOut_Luna | B25: TK_IF_PriceOut_Luna | C25: 可見輸出 $/M — OpenAI 有效 | D25: $/M | E25: 1 | F25: OK | G25: v5.26 | H25: 3dd1216 | I25: 2026-10-08 | J25: 0.4
A26: IF_PriceOut_Sol | B26: TK_IF_PriceOut_Sol | C26: 可見輸出 $/M — OpenAI 有效 | D26: $/M | E26: 1 | F26: OK | G26: v5.26 | H26: 3dd1216 | I26: 2026-10-08 | J26: 8
A27: IF_PriceRef_Astra | B27: TK_IF_PriceRef_Astra | C27: 參考請求混合 $/M — OpenAI 有效 | D27: $/M | E27: 1 | F27: OK | G27: v5.26 | H27: 3dd1216 | I27: 2026-10-08 | J27: 8.0355556
A28: IF_PriceRef_Luna | B28: TK_IF_PriceRef_Luna | C28: 參考請求混合 $/M — OpenAI 有效 | D28: $/M | E28: 1 | F28: OK | G28: v5.26 | H28: 3dd1216 | I28: 2026-10-08 | J28: 0.080355556
A29: IF_PriceRef_Sol | B29: TK_IF_PriceRef_Sol | C29: 參考請求混合 $/M — OpenAI 有效 | D29: $/M | E29: 1 | F29: OK | G29: v5.26 | H29: 3dd1216 | I29: 2026-10-08 | J29: 1.6071111
... A35: IF_FrontRef_Sol | B35: TK_IF_FrontRef_Sol | C35: 參考請求混合 $/M — 前緣有效 | D35: $/M | E35: 1 | F35: OK | G35: v5.26 | H35: 3dd1216 | I35: 2026-10-08 | J35: 1.6071111
A36: IF_ProgGWyr_Astra | B36: TK_IF_ProgGWyr_Astra | C36: 研發計畫占 1 GW 一年 | D36: % | E36: 15 | F36: OK | G36: v5.26 | H36: 3dd1216 | I36: 2026-10-08 | J36: 0.14267939 | K36: 0.14267939 | L36: 0.14267939 | M36: 0.07039759 | N36: 0.07039759 | O36: 0.07039759 | P36: 0.065586407 | Q36: 0.065586407 | R36: 0.065586407 | S36: 0.040017843 | T36: 0.040017843 | U36: 0.040017843 | V36: 0.027250415 | W36: 0.027250415 | X36: 0.027250415
A37: IF_ProgGWyr_Luna | B37: TK_IF_ProgGWyr_Luna | C37: 研發計畫占 1 GW 一年 | D37: % | E37: 15 | F37: OK | G37: v5.26 | H37: 3dd1216 | I37: 2026-10-08 | J37: 0.0081323583 | K37: 0.0081323583 | L37: 0.0081323583 | M37: 0.0037853004 | N37: 0.0037853004 | O37: 0.0037853004 | P37: 0.0033289655 | Q37: 0.0033289655 | R37: 0.0033289655 | S37: 0.0022043397 | T37: 0.0022043397 | U37: 0.0022043397 | V37: 0.0014304485 | W37: 0.0014304485 | X37: 0.0014304485
A38: IF_ProgGWyr_Sol | B38: TK_IF_ProgGWyr_Sol | C38: 研發計畫占 1 GW 一年 | D38: % | E38: 15 | F38: OK | G38: v5.26 | H38: 3dd1216 | I38: 2026-10-08 | J38: 0.023146292 | K38: 0.023146292 | L38: 0.023146292 | M38: 0.011197547 | N38: 0.011197547 | O38: 0.011197547 | P38: 0.010227304 | Q38: 0.010227304 | R38: 0.010227304 | S38: 0.006421121 | T38: 0.006421121 | U38: 0.006421121 | V38: 0.0043094856 | W38: 0.0043094856 | X38: 0.0043094856
A39: IF_RDMult | B39: TK_IF_RDMult | C39: 研發倍數（第 0 層基準；下游可覆寫） | D39: x | E39: 1 | F39: OK | G39: v5.26 | H39: 3dd1216 | I39: 2026-10-08 | J39: 8
A40: IF_TrainGenDefault | B40: TK_IF_TrainGenDefault | C40: 下游預設訓練世代（索引；J13） | D40: 索引 | E40: 1 | F40: OK | G40: v5.26 | H40: 3dd1216 | I40: 2026-10-08 | J40: 4
A41: SRC_DEM_004 | B41: TK_SRC_DEM_004 | C41: OpenAI 2025 推論支出（年度） | D41: $B | E41: 1 | F41: OK | G41: v5.26 | H41: 3dd1216 | I41: 2026-10-08 | J41: 8.4
A42: SRC_DEM_005 | B42: TK_SRC_DEM_005 | C42: OpenAI 2025 非付費用戶推論支出（年度） | D42: $B | E42: 1 | F42: OK | G42: v5.26 | H42: 3dd1216 | I42: 2026-10-08 | J42: 3.9
A43: SRC_DEM_006 | B43: TK_SRC_DEM_006 | C43: OpenAI 2025 訓練支出（年度；約值） | D43: $B | E43: 1 | F43: OK | G43: v5.26 | H43: 3dd1216 | I43: 2026-10-08 | J43: 12
A44: SRC_DEM_007 | B44: TK_SRC_DEM_007 | C44: OpenAI 2025 營收（年度） | D44: $B | E44: 1 | F44: OK | G44: v5.26 | H44: 3dd1216 | I44: 2026-10-08 | J44: 13.07
A45: SRC_DEM_008 | B45: TK_SRC_DEM_008 | C45: OpenAI 算力規模 2024 年底（GW 口徑未明（D1）） | D45: GW | E45: 1 | F45: OK | G45: v5.26 | H45: 3dd1216 | I45: 2026-10-08 | J45: 0.6
...

Sheet OAI_Link
A1: OAI_Link — OpenAI v0.6 命題輸出快照（美元；只被 Checks 與 HTML 引用，規格 D26）
A2: 值（藍字）由 builder 從 OpenAI v0.6 Excel 的具名範圍讀出（LibreOffice 重算後快取值）。本頁不參與任何計算；test_builder 掃描其他頁公式不得含 OAI_。
A3: OpenAI Excel 檔案 | B3: 20261008_OpenAI_v0.6.xlsx
A4: SHA-256 | B4: 34fc34a7ea2c18e8f608356ca462d8bd208496ca61780589b559fd2efc6597fe
A5: 來源分支與提交 | B5: claude/openai-s6-release@e91df57
A6: 讀取日期 | B6: 2026-10-08
A9: OpenAI 名稱 | B9: 本模型名稱 | C9: 說明 | D9: 單位 | E9: 狀態 | F9: 2025 | G9: 2026 | H9: 2027 | I9: 2028 | J9: 2029 | K9: 2030
A10: REV_Gross | B10: OAI_REV_Gross | C10: 營收總額（未截頂） | D10: $B | E10: OK | F10: 13.07 | G10: 34.203781 | H10: 54.795653 | I10: 78.424089 | J10: 102.12737 | K10: 126.38309
A11: REV_NetCapped | B11: OAI_REV_NetCapped | C11: 營收淨額（容量截頂後） | D11: $B | E11: OK | F11: 10.456 | G11: 27.363025 | H11: 43.836523 | I11: 62.739271 | J11: 97.612079 | K11: 126.38309
A12: DEM_Tok_Total | B12: OAI_DEM_Tok_Total | C12: token 合計（付費＋免費） | D12: T | E12: OK | F12: 3538.0601 | G12: 10018.624 | H12: 22447.299 | I12: 47137.552 | J12: 92412.32 | K12: 173673.87
A13: CMP_InfGW_Eff | B13: OAI_CMP_InfGW_Eff | C13: 有效推論 GW | D13: GW | E13: OK | F13: 0.7 | G13: 0.69567332 | H13: 1.0429667 | I13: 1.7703734 | J13: 3.1650072 | K13: 5.5973071
A14: CMP_Supply_VReq | B14: OAI_CMP_Supply_VReq | C14: 供給 VR 等值 GW | D14: GW | E14: OK | F14: 0.28264462 | G14: 1.1565252 | H14: 5.7520321 | I14: 8.9411774 | J14: 12.146409 | K14: 14.944726
A15: COST_Compute | B15: OAI_COST_Compute | C15: 算力成本（現金） | D15: $B | E15: OK | F15: 14.755238 | G15: 53.240635 | H15: 141.72603 | I15: 175.21143 | J15: 208.69683 | K15: 228.22222
A16: COST_FullCash | B16: OAI_COST_FullCash | C16: 全成本（現金，含股權報酬） | D16: $B | E16: OK | F16: 29.235238 | G16: 76.078955 | H16: 171.94384 | I16: 212.1254 | J16: 251.9209 | K16: 276.64452
A17: COST_PropRev_VR | B17: OAI_COST_PropRev_VR | C17: 每 VR 等值 GW 營收淨額 | D17: $B/GW | E17: OK | F17: 36.993451 | G17: 23.659688 | H17: 7.6210498 | I17: 7.0168914 | J17: 8.0362912 | K17: 8.456702
A18: COST_PropFull_VR | B18: OAI_COST_PropFull_VR | C18: 每 VR 等值 GW 全成本 | D18: $B/GW | E18: OK | F18: 103.43462 | G18: 65.782359 | H18: 29.892713 | I18: 23.724549 | J18: 20.740361 | K18: 18.511181
A19: COST_PropGap_VR | B19: OAI_COST_PropGap_VR | C19: 每 VR 等值 GW 差額（命題 1） | D19: $B/GW | E19: OK | F19: -66.441166 | G19: -42.122671 | H19: -22.271663 | I19: -16.707658 | J19: -12.704069 | K19: -10.054479
A20: COST_Coverage | B20: OAI_COST_Coverage | C20: 覆蓋率（營收 ÷ 全成本） | D20: 比例 | E20: OK | F20: 0.35765058 | G20: 0.35966615 | H20: 0.25494674 | I20: 0.29576501 | J20: 0.38747114 | K20: 0.45684293
A21: FND_FCF | B21: OAI_FND_FCF | C21: 自由現金流 | D21: $B | E21: OK | F21: -12.779238 | G21: -39.41593 | H21: -116.01732 | I21: -134.87813 | J21: -137.62462 | K21: -131.90881
A22: FND_ExtNeed | B22: OAI_FND_ExtNeed | C22: 外部資金需求（單年） | D22: $B | E22: OK | G22: 0 | H22: 38.433249 | I22: 134.87813 | J22: 137.62462 | K22: 131.90881
A23: FND_ExtNeedCum | B23: OAI_FND_ExtNeedCum | C23: 累計外部資金需求（命題 2） | D23: $B | E23: OK | G23: 0 | H23: 38.433249 | I23: 173.31138 | J23: 310.936 | K23: 442.84481

Sheet Inputs
A1: Inputs — 假設輸入（藍字）：值、低、高、標記、依據、區間理由；匯率與單位換算定義常數（D23、E6）
A2: 長表格式：一列一個參數（× 索引）。來源 data/zhipu_inputs.yaml；INP_nnn 由 builder/id_registry.json 依鍵發出，穩定不重用。
A3: Analogy 寫明參照（如『OpenAI v0.6 INP_nnn』）與差異；Assumed 寫明依據；兩者一律給區間。Decision＝定義常數或規格決策（低＝值＝高）。
A4: INP_ID | B4: 鍵（key） | C4: 參數 | D4: 索引 | E4: 單位 | F4: 值 | G4: 低 | H4: 高 | I4: 標記 | J4: 依據 | K4: 區間理由 | L4: 區間順序異常（公式） | M4: Analogy／Assumed 缺區間（公式）
A5: INP_001 | B5: year_2025 | C5: 模型年度 | D5: 第 1 年 | E5: 年 | F5: 2025 | G5: 2025 | H5: 2025 | I5: Decision | J5: 曆年制，2025 為實際校準年（規格 D1、D14） | K5: 定義 | L5: =IF(AND(ISNUMBER($F5),ISNUMBER($G5),ISNUMBER($H5)),IF(AND($G5<=$F5,$F5<=$H5),0,1),0) -> 0 | M5: =IF(AND(OR($I5="Analogy",$I5="Assumed"),OR($G5="",$H5="")),1,0) -> 0
A6: INP_002 | B6: year_2026 | C6: 模型年度 | D6: 第 2 年 | E6: 年 | F6: 2026 | G6: 2026 | H6: 2026 | I6: Decision | J6: 2026＝1H26 實際＋2H26 驅動（D14） | K6: 定義 | L6: =IF(AND(ISNUMBER($F6),ISNUMBER($G6),ISNUMBER($H6)),IF(AND($G6<=$F6,$F6<=$H6),0,1),0) -> 0 | M6: =IF(AND(OR($I6="Analogy",$I6="Assumed"),OR($G6="",$H6="")),1,0) -> 0
A7: INP_003 | B7: year_2027 | C7: 模型年度 | D7: 第 3 年 | E7: 年 | F7: 2027 | G7: 2027 | H7: 2027 | I7: Decision | J7: 定義 | K7: 定義 | L7: =IF(AND(ISNUMBER($F7),ISNUMBER($G7),ISNUMBER($H7)),IF(AND($G7<=$F7,$F7<=$H7),0,1),0) -> 0 | M7: =IF(AND(OR($I7="Analogy",$I7="Assumed"),OR($G7="",$H7="")),1,0) -> 0
A8: INP_004 | B8: year_2028 | C8: 模型年度 | D8: 第 4 年 | E8: 年 | F8: 2028 | G8: 2028 | H8: 2028 | I8: Decision | J8: 定義 | K8: 定義 | L8: =IF(AND(ISNUMBER($F8),ISNUMBER($G8),ISNUMBER($H8)),IF(AND($G8<=$F8,$F8<=$H8),0,1),0) -> 0 | M8: =IF(AND(OR($I8="Analogy",$I8="Assumed"),OR($G8="",$H8="")),1,0) -> 0
A9: INP_005 | B9: year_2029 | C9: 模型年度 | D9: 第 5 年 | E9: 年 | F9: 2029 | G9: 2029 | H9: 2029 | I9: Decision | J9: 定義 | K9: 定義 | L9: =IF(AND(ISNUMBER($F9),ISNUMBER($G9),ISNUMBER($H9)),IF(AND($G9<=$F9,$F9<=$H9),0,1),0) -> 0 | M9: =IF(AND(OR($I9="Analogy",$I9="Assumed"),OR($G9="",$H9="")),1,0) -> 0
A10: INP_006 | B10: year_2030 | C10: 模型年度 | D10: 第 6 年 | E10: 年 | F10: 2030 | G10: 2030 | H10: 2030 | I10: Decision | J10: 定義 | K10: 定義 | L10: =IF(AND(ISNUMBER($F10),ISNUMBER($G10),ISNUMBER($H10)),IF(AND($G10<=$F10,$F10<=$H10),0,1),0) -> 0 | M10: =IF(AND(OR($I10="Analogy",$I10="Assumed"),OR($G10="",$H10="")),1,0) -> 0
A11: INP_007 | B11: days_year | C11: 每年天數（定義常數） | D11: — | E11: 天 | F11: 365 | G11: 365 | H11: 365 | I11: Decision | J11: 同 OpenAI v0.6 INP_251 | K11: 定義 | L11: =IF(AND(ISNUMBER($F11),ISNUMBER($G11),ISNUMBER($H11)),IF(AND($G11<=$F11,$F11<=$H11),0,1),0) -> 0 | M11: =IF(AND(OR($I11="Analogy",$I11="Assumed"),OR($G11="",$H11="")),1,0) -> 0
A12: INP_008 | B12: days_1h26 | C12: 2026 上半年天數（定義常數） | D12: 1H2026 | E12: 天 | F12: 181 | G12: 181 | H12: 181 | I12: Decision | J12: 2026-01-01～06-30 | K12: 定義 | L12: =IF(AND(ISNUMBER($F12),ISNUMBER($G12),ISNUMBER($H12)),IF(AND($G12<=$F12,$F12<=$H12),0,1),0) -> 0 | M12: =IF(AND(OR($I12="Analogy",$I12="Assumed"),OR($G12="",$H12="")),1,0) -> 0
A13: INP_009 | B13: days_2h26 | C13: 2026 下半年天數（定義常數） | D13: 2H2026 | E13: 天 | F13: 184 | G13: 184 | H13: 184 | I13: Decision | J13: 2026-07-01～12-31 | K13: 定義 | L13: =IF(AND(ISNUMBER($F13),ISNUMBER($G13),ISNUMBER($H13)),IF(AND($G13<=$F13,$F13<=$H13),0,1),0) -> 0 | M13: =IF(AND(OR($I13="Analogy",$I13="Assumed"),OR($G13="",$H13="")),1,0) -> 0
A14: INP_010 | B14: months_year | C14: 每年月數（定義常數） | D14: — | E14: 月 | F14: 12 | G14: 12 | H14: 12 | I14: Decision | J14: 同 OpenAI v0.6 INP_252 | K14: 定義 | L14: =IF(AND(ISNUMBER($F14),ISNUMBER($G14),ISNUMBER($H14)),IF(AND($G14<=$F14,$F14<=$H14),0,1),0) -> 0 | M14: =IF(AND(OR($I14="Analogy",$I14="Assumed"),OR($G14="",$H14="")),1,0) -> 0
A15: INP_011 | B15: months_half | C15: 每半年月數（定義常數） | D15: — | E15: 月 | F15: 6 | G15: 6 | H15: 6 | I15: Decision | J15: 定義 | K15: 定義 | L15: =IF(AND(ISNUMBER($F15),ISNUMBER($G15),ISNUMBER($H15)),IF(AND($G15<=$F15,$F15<=$H15),0,1),0) -> 0 | M15: =IF(AND(OR($I15="Analogy",$I15="Assumed"),OR($G15="",$H15="")),1,0) -> 0
A16: INP_012 | B16: months_qtr | C16: 每季月數（定義常數） | D16: — | E16: 月 | F16: 3 | G16: 3 | H16: 3 | I16: Decision | J16: 國際站 Coding Plan 季付價換算每月 | K16: 定義 | L16: =IF(AND(ISNUMBER($F16),ISNUMBER($G16),ISNUMBER($H16)),IF(AND($G16<=$F16,$F16<=$H16),0,1),0) -> 0 | M16: =IF(AND(OR($I16="Analogy",$I16="Assumed"),OR($G16="",$H16="")),1,0) -> 0
... A77: INP_073 | B77: arr_warn | C77: ARR 對照 WARN 門檻（模型年化 ÷ 公司 ARR − 1 的絕對值） | D77: — | E77: 比例 | F77: 0.25 | G77: 0.25 | H77: 0.25 | I77: Decision | J77: 規格 D14r（WARN >25%） | K77: 規格 | L77: =IF(AND(ISNUMBER($F77),ISNUMBER($G77),ISNUMBER($H77)),IF(AND($G77<=$F77,$F77<=$H77),0,1),0) -> 0 | M77: =IF(AND(OR($I77="Analogy",$I77="Assumed"),OR($G77="",$H77="")),1,0) -> 0

Sheet Demand
A1: Demand — 需求：API 按量計費 token、GLM Coding Plan 訂閱者與 token、智譜清言（免費）token；輸出 DEM_Tok_*（層級 Sol／Luna × 付費／免費）
A2: 2025 與 1H26 為校準期：API 按量計費 token＝（開放平台及 API 實際營收 − Coding Plan 估計營收）÷ 組合有效單價（規格 D14；單價為驅動、token 為倒推）。2H26 起：任務數 ×（1＋成長）× 每任務 token ×（1＋成長）× 價格反應 (p/p前)^ε（D15）。本地化部署不耗智譜算力，不進本頁（D4）。
A3: token 單位 T＝10^12；Coding Plan 訂閱者單位萬人；清言用戶百萬人；任務數十億。容量上限於 Z3 接 Compute；本頁不截頂。
A5: 編號 | B5: 項目 | C5: 單位 | D5: 2025 | E5: 2026 | F5: 2027 | G5: 2028 | H5: 2029 | I5: 2030 | K5: 1H2026 | L5: 2H2026 | M5: 說明
B6: 年度 | D6: =INP_001 -> 2025 | E6: =INP_002 -> 2026 | F6: =INP_003 -> 2027 | G6: =INP_004 -> 2028 | H6: =INP_005 -> 2029 | I6: =INP_006 -> 2030 | K6: 1H2026（實際） | L6: 2H2026（驅動）
A7: 一、API 按量計費（開放平台及 API 扣除 Coding Plan）
A8: D01 | B8: 價格反應底數 p/p前（組合有效單價） | C8: 倍 | F8: =Revenue!F24/Revenue!L24 -> 0.8 | G8: =Revenue!G24/Revenue!F24 -> 0.8 | H8: =Revenue!H24/Revenue!G24 -> 0.8 | I8: =Revenue!I24/Revenue!H24 -> 0.8 | L8: =Revenue!L24/Revenue!K24 -> 1.2696313 | M8: 2H26＝2H26 ÷ 1H26；2027＝2027 ÷ 2H26（最新價格水準）；之後逐年
A9: D02 | B9: API 每任務 token | C9: K tok／任務 | D9: =INP_037 -> 20 | E9: =E11/E10 -> 20.316741 | F9: =E9*(1+INP_044)*F8^INP_046 -> 24.981867 | G9: =F9*(1+INP_044)*G8^INP_046 -> 30.718198 | H9: =G9*(1+INP_044)*H8^INP_046 -> 37.771704 | I9: =H9*(1+INP_044)*I8^INP_046 -> 46.444835 | K9: =INP_037 -> 20 | L9: =K9*(1+INP_039)*L8^INP_046 -> 20.479502 | M9: 校準期＝Inputs 基準（只影響任務數與每任務 token 的水準拆分，不影響營收）；2H26 起 ×（1＋成長）× 價格反應^ε（每任務 token）；2026 欄＝全年 token ÷ 全年任務
A10: D03 | B10: API 任務數 | C10: 十億 | D10: =D11/D9 -> 3.3230757 | E10: =K10+L10 -> 26.880458 | F10: =E10*(1+INP_040)*F8^INP_045 -> 56.56479 | G10: =F10*(1+INP_041)*G8^INP_045 -> 99.191498 | H10: =G10*(1+INP_042)*H8^INP_045 -> 156.54717 | I10: =H10*(1+INP_043)*I8^INP_045 -> 228.76641 | K10: =K11/K9 -> 9.1242437 | L10: =K10*(1+INP_038)*L8^INP_045 -> 17.756214 | M10: 校準期＝token ÷ 每任務 token；2H26＝1H26 ×（1＋半年成長）× 價格反應^ε；2027 起以 2026 全年為基期
A11: D04 | B11: API 按量計費 token | C11: T | D11: =Revenue!D44*INP_015/Revenue!D24 -> 66.461514 | E11: =K11+L11 -> 546.12331 | F11: =F10*F9 -> 1413.0941 | G11: =G10*G9 -> 3046.9841 | H11: =H10*H9 -> 5913.0535 | I11: =I10*I9 -> 10625.018 | K11: =Revenue!K44*INP_015/Revenue!K24 -> 182.48487 | L11: =L10*L9 -> 363.63844 | M11: 2025、1H26：按量計費營收（API 實際 − Coding Plan 估計）× 100 ÷ 組合有效單價（元／百萬 token；×100 為 Inputs 定義常數）；之後＝任務數 × 每任務 token
A12: D05 | B12: API 按量計費 token：Sol（GLM 旗艦） | C12: T | D12: =D11*Revenue!D22 -> 39.876908 | E12: =K12+L12 -> 382.28632 | F12: =F11*Revenue!F22 -> 989.16584 | G12: =G11*Revenue!G22 -> 2132.8888 | H12: =H11*Revenue!H22 -> 4139.1374 | I12: =I11*Revenue!I22 -> 7437.5125 | K12: =K11*Revenue!K22 -> 127.73941 | L12: =L11*Revenue!L22 -> 254.5469 | M12: token × 層級組合（Revenue）
A13: D06 | B13: API 按量計費 token：Luna（Air／Flash） | C13: T | D13: =D11*Revenue!D23 -> 26.584606 | E13: =K13+L13 -> 163.83699 | F13: =F11*Revenue!F23 -> 423.92822 | G13: =G11*Revenue!G23 -> 914.09522 | H13: =H11*Revenue!H23 -> 1773.916 | I13: =I11*Revenue!I23 -> 3187.5054 | K13: =K11*Revenue!K23 -> 54.745462 | L13: =L11*Revenue!L23 -> 109.09153 | M13: token × 層級組合（Revenue）
A14: D07 | B14: 免費 API 型號 token（Luna；耗算力無營收） | C14: T | D14: =D11*INP_047 -> 19.938454 | E14: =K14+L14 -> 163.83699 | F14: =F11*INP_047 -> 423.92822 | G14: =G11*INP_047 -> 914.09522 | H14: =H11*INP_047 -> 1773.916 | I14: =I11*INP_047 -> 3187.5054 | K14: =K11*INP_047 -> 54.745462 | L14: =L11*INP_047 -> 109.09153 | M14: GLM-4.7-Flash 等免費型號（SRC_ZP_333）＝付費 API token × Inputs 比例（D24r：免費型號單列）
A15: 二、GLM Coding Plan（訂閱者 × 每訂閱者 token；收入在開放平台及 API 內，D2r）
A16: D08 | B16: Coding Plan 付費訂閱者（期間平均） | C16: 萬人 | D16: =SRC_ZP_402*INP_049 -> 3.63 | E16: =(K16+L16)/INP_013 -> 30.25 | F16: =E16*(1+INP_051) -> 45.375 | G16: =F16*(1+INP_052) -> 58.9875 | H16: =G16*(1+INP_053) -> 70.785 | I16: =H16*(1+INP_054) -> 81.40275 | K16: =SRC_ZP_402*INP_048 -> 24.2 | L16: =K16*(1+INP_050) -> 36.3 | M16: 2025、1H26＝2026-03 付費開發者 24.2 萬（SRC_ZP_402）× Inputs 倍數（營收未單列，無法倒推；工作單：給區間）；2H26＝1H26 ×（1＋半年成長）；2026 欄＝兩個半年平均；2027 起 ×（1＋年增率）
A17: D09 | B17: Coding Plan 訂閱者：Lite | C17: 萬人 | D17: =D16*Revenue!D35 -> 2.178 | E17: =E16*Revenue!E35 -> 18.15 | F17: =F16*Revenue!F35 -> 27.225 | G17: =G16*Revenue!G35 -> 35.3925 | H17: =H16*Revenue!H35 -> 42.471 | I17: =I16*Revenue!I35 -> 48.84165 | K17: =K16*Revenue!K35 -> 14.52 | L17: =L16*Revenue!L35 -> 21.78 | M17: 訂閱者 × 方案組合（Revenue）
A18: D10 | B18: Coding Plan 訂閱者：Pro | C18: 萬人 | D18: =D16*Revenue!D36 -> 1.089 | E18: =E16*Revenue!E36 -> 9.075 | F18: =F16*Revenue!F36 -> 13.6125 | G18: =G16*Revenue!G36 -> 17.69625 | H18: =H16*Revenue!H36 -> 21.2355 | I18: =I16*Revenue!I36 -> 24.420825 | K18: =K16*Revenue!K36 -> 7.26 | L18: =L16*Revenue!L36 -> 10.89 | M18: 訂閱者 × 方案組合（Revenue）
A19: D11 | B19: Coding Plan 訂閱者：Max | C19: 萬人 | D19: =D16*Revenue!D37 -> 0.363 | E19: =E16*Revenue!E37 -> 3.025 | F19: =F16*Revenue!F37 -> 4.5375 | G19: =G16*Revenue!G37 -> 5.89875 | H19: =H16*Revenue!H37 -> 7.0785 | I19: =I16*Revenue!I37 -> 8.140275 | K19: =K16*Revenue!K37 -> 2.42 | L19: =L16*Revenue!L37 -> 3.63 | M19: 訂閱者 × 方案組合（Revenue）
A20: D12 | B20: 每訂閱者每日 token：Lite | C20: M tok／日 | D20: =SRC_ZP_376*INP_022*INP_060*INP_061*INP_062/INP_019 -> 20.16 | E20: =SRC_ZP_376*INP_022*INP_060*INP_061*INP_062/INP_019 -> 20.16 | F20: =SRC_ZP_376*INP_022*INP_060*INP_061*INP_062/INP_019 -> 20.16 | G20: =SRC_ZP_376*INP_022*INP_060*INP_061*INP_062/INP_019 -> 20.16 | H20: =SRC_ZP_376*INP_022*INP_060*INP_061*INP_062/INP_019 -> 20.16 | I20: =SRC_ZP_376*INP_022*INP_060*INP_061*INP_062/INP_019 -> 20.16 | K20: =SRC_ZP_376*INP_022*INP_060*INP_061*INP_062/INP_019 -> 20.16 | L20: =SRC_ZP_376*INP_022*INP_060*INP_061*INP_062/INP_019 -> 20.16 | M20: 每 5 小時額度（SRC_ZP_376–378）× 每日窗口數 × 額度使用率 × 每 prompt 呼叫次數 × 每次呼叫 token（K）÷ 1000
A21: D13 | B21: 每訂閱者每日 token：Pro | C21: M tok／日 | D21: =SRC_ZP_377*INP_022*INP_060*INP_061*INP_062/INP_019 -> 100.8 | E21: =SRC_ZP_377*INP_022*INP_060*INP_061*INP_062/INP_019 -> 100.8 | F21: =SRC_ZP_377*INP_022*INP_060*INP_061*INP_062/INP_019 -> 100.8 | G21: =SRC_ZP_377*INP_022*INP_060*INP_061*INP_062/INP_019 -> 100.8 | H21: =SRC_ZP_377*INP_022*INP_060*INP_061*INP_062/INP_019 -> 100.8 | I21: =SRC_ZP_377*INP_022*INP_060*INP_061*INP_062/INP_019 -> 100.8 | K21: =SRC_ZP_377*INP_022*INP_060*INP_061*INP_062/INP_019 -> 100.8 | L21: =SRC_ZP_377*INP_022*INP_060*INP_061*INP_062/INP_019 -> 100.8 | M21: 每 5 小時額度（SRC_ZP_376–378）× 每日窗口數 × 額度使用率 × 每 prompt 呼叫次數 × 每次呼叫 token（K）÷ 1000
A22: D14 | B22: 每訂閱者每日 token：Max | C22: M tok／日 | D22: =SRC_ZP_378*INP_022*INP_060*INP_061*INP_062/INP_019 -> 403.2 | E22: =SRC_ZP_378*INP_022*INP_060*INP_061*INP_062/INP_019 -> 403.2 | F22: =SRC_ZP_378*INP_022*INP_060*INP_061*INP_062/INP_019 -> 403.2 | G22: =SRC_ZP_378*INP_022*INP_060*INP_061*INP_062/INP_019 -> 403.2 | H22: =SRC_ZP_378*INP_022*INP_060*INP_061*INP_062/INP_019 -> 403.2 | I22: =SRC_ZP_378*INP_022*INP_060*INP_061*INP_062/INP_019 -> 403.2 | K22: =SRC_ZP_378*INP_022*INP_060*INP_061*INP_062/INP_019 -> 403.2 | L22: =SRC_ZP_378*INP_022*INP_060*INP_061*INP_062/INP_019 -> 403.2 | M22: 每 5 小時額度（SRC_ZP_376–378）× 每日窗口數 × 額度使用率 × 每 prompt 呼叫次數 × 每次呼叫 token（K）÷ 1000
A23: D15 | B23: Coding Plan token：Lite | C23: T | D23: =D17*D20*INP_007/INP_016 -> 160.26595 | E23: =K23+L23 -> 1337.745 | F23: =F17*F20*INP_007/INP_016 -> 2003.3244 | G23: =G17*G20*INP_007/INP_016 -> 2604.3217 | H23: =H17*H20*INP_007/INP_016 -> 3125.1861 | I23: =I17*I20*INP_007/INP_016 -> 3593.964 | K23: =K17*K20*INP_008/INP_016 -> 529.82899 | L23: =L17*L20*INP_009/INP_016 -> 807.91603 | M23: 訂閱者（萬）× 每日 token（M）× 天數 ÷ 100（萬 × M → T）
A24: D16 | B24: Coding Plan token：Pro | C24: T | D24: =D18*D21*INP_007/INP_016 -> 400.66488 | E24: =K24+L24 -> 3344.3626 | F24: =F18*F21*INP_007/INP_016 -> 5008.311 | G24: =G18*G21*INP_007/INP_016 -> 6510.8043 | H24: =H18*H21*INP_007/INP_016 -> 7812.9652 | I24: =I18*I21*INP_007/INP_016 -> 8984.9099 | K24: =K18*K21*INP_008/INP_016 -> 1324.5725 | L24: =L18*L21*INP_009/INP_016 -> 2019.7901 | M24: 訂閱者（萬）× 每日 token（M）× 天數 ÷ 100（萬 × M → T）
A25: D17 | B25: Coding Plan token：Max | C25: T | D25: =D19*D22*INP_007/INP_016 -> 534.21984 | E25: =K25+L25 -> 4459.1501 | F25: =F19*F22*INP_007/INP_016 -> 6677.748 | G25: =G19*G22*INP_007/INP_016 -> 8681.0724 | H25: =H19*H22*INP_007/INP_016 -> 10417.287 | I25: =I19*I22*INP_007/INP_016 -> 11979.88 | K25: =K19*K22*INP_008/INP_016 -> 1766.0966 | L25: =L19*L22*INP_009/INP_016 -> 2693.0534 | M25: 訂閱者（萬）× 每日 token（M）× 天數 ÷ 100（萬 × M → T）
A26: D18 | B26: Coding Plan token 合計 | C26: T | D26: =D23+D24+D25 -> 1095.1507 | E26: =E23+E24+E25 -> 9141.2577 | F26: =F23+F24+F25 -> 13689.383 | G26: =G23+G24+G25 -> 17796.198 | H26: =H23+H24+H25 -> 21355.438 | I26: =I23+I24+I25 -> 24558.754 | K26: =K23+K24+K25 -> 3620.4981 | L26: =L23+L24+L25 -> 5520.7596
A27: D19 | B27: Coding Plan token：Sol | C27: T | D27: =D26*INP_063 -> 985.6356 | E27: =E26*INP_063 -> 8227.1319 | F27: =F26*INP_063 -> 12320.445 | G27: =G26*INP_063 -> 16016.579 | H27: =H26*INP_063 -> 19219.894 | I27: =I26*INP_063 -> 22102.878 | K27: =K26*INP_063 -> 3258.4483 | L27: =L26*INP_063 -> 4968.6836 | M27: Coding Plan 以 GLM-5.x 旗艦為主（D24r）
A28: D20 | B28: Coding Plan token：Luna | C28: T | D28: =D26*(1-INP_063) -> 109.51507 | E28: =E26*(1-INP_063) -> 914.12577 | F28: =F26*(1-INP_063) -> 1368.9383 | G28: =G26*(1-INP_063) -> 1779.6198 | H28: =H26*(1-INP_063) -> 2135.5438 | I28: =I26*(1-INP_063) -> 2455.8754 | K28: =K26*(1-INP_063) -> 362.04981 | L28: =L26*(1-INP_063) -> 552.07596
A29: 三、智譜清言（C 端；無單列收入，免費 token 耗算力；年度）
A30: D21 | B30: 智譜清言月活用戶 | C30: 百萬人 | D30: =INP_064 -> 10 | E30: =D30*(1+INP_065) -> 11 | F30: =E30*(1+INP_065) -> 12.1 | G30: =F30*(1+INP_065) -> 13.31 | H30: =G30*(1+INP_065) -> 14.641 | I30: =H30*(1+INP_065) -> 16.1051 | M30: 2025 Inputs（QuestMobile 未進前 20，SRC_ZP_434；Assumed 區間）；之後 ×（1＋年增率）
A31: D22 | B31: 智譜清言 token | C31: T | D31: =D30*INP_066*INP_067*INP_007/INP_018 -> 10.95 | E31: =E30*INP_066*INP_067*INP_007/INP_018 -> 12.045 | F31: =F30*INP_066*INP_067*INP_007/INP_018 -> 13.2495 | G31: =G30*INP_066*INP_067*INP_007/INP_018 -> 14.57445 | H31: =H30*INP_066*INP_067*INP_007/INP_018 -> 16.031895 | I31: =I30*INP_066*INP_067*INP_007/INP_018 -> 17.635085 | M31: 用戶（百萬）× 每日任務 × 每任務 token（K）× 天數 ÷ 1000（百萬 × K → T）
A32: D23 | B32: 智譜清言 token：Sol | C32: T | D32: =D31*INP_068 -> 3.285 | E32: =E31*INP_068 -> 3.6135 | F32: =F31*INP_068 -> 3.97485 | G32: =G31*INP_068 -> 4.372335 | H32: =H31*INP_068 -> 4.8095685 | I32: =I31*INP_068 -> 5.2905254
A33: D24 | B33: 智譜清言 token：Luna | C33: T | D33: =D31*(1-INP_068) -> 7.665 | E33: =E31*(1-INP_068) -> 8.4315 | F33: =F31*(1-INP_068) -> 9.27465 | G33: =G31*(1-INP_068) -> 10.202115 | H33: =H31*(1-INP_068) -> 11.222326 | I33: =I31*(1-INP_068) -> 12.344559
A34: 四、輸出：token 量（層級 × 付費／免費；供 Z3 推論 GW）
A35: D25 | B35: 付費 token：Sol | C35: T | D35: =D12+D27 -> 1025.5125 | E35: =E12+E27 -> 8609.4182 | F35: =F12+F27 -> 13309.611 | G35: =G12+G27 -> 18149.467 | H35: =H12+H27 -> 23359.032 | I35: =I12+I27 -> 29540.391 | M35: API 按量計費 Sol ＋ Coding Plan Sol
A36: D26 | B36: 付費 token：Luna | C36: T | D36: =D13+D28 -> 136.09967 | E36: =E13+E28 -> 1077.9628 | F36: =F13+F28 -> 1792.8666 | G36: =G13+G28 -> 2693.7151 | H36: =H13+H28 -> 3909.4598 | I36: =I13+I28 -> 5643.3808 | M36: API 按量計費 Luna ＋ Coding Plan Luna
A37: D27 | B37: 免費 token：Sol | C37: T | D37: =D32 -> 3.285 | E37: =E32 -> 3.6135 | F37: =F32 -> 3.97485 | G37: =G32 -> 4.372335 | H37: =H32 -> 4.8095685 | I37: =I32 -> 5.2905254 | M37: 智譜清言 Sol
A38: D28 | B38: 免費 token：Luna | C38: T | D38: =D33+D14 -> 27.603454 | E38: =E33+E14 -> 172.26849 | F38: =F33+F14 -> 433.20287 | G38: =G33+G14 -> 924.29734 | H38: =H33+H14 -> 1785.1384 | I38: =I33+I14 -> 3199.8499 | M38: 智譜清言 Luna ＋ 免費 API 型號
A39: D29 | B39: 付費 token 合計 | C39: T | D39: =D35+D36 -> 1161.6122 | E39: =E35+E36 -> 9687.381 | F39: =F35+F36 -> 15102.477 | G39: =G35+G36 -> 20843.182 | H39: =H35+H36 -> 27268.492 | I39: =I35+I36 -> 35183.772
A40: D30 | B40: 免費 token 合計 | C40: T | D40: =D37+D38 -> 30.888454 | E40: =E37+E38 -> 175.88199 | F40: =F37+F38 -> 437.17772 | G40: =G37+G38 -> 928.66967 | H40: =H37+H38 -> 1789.9479 | I40: =I37+I38 -> 3205.1405
A41: D31 | B41: token 合計（付費＋免費） | C41: T | D41: =D39+D40 -> 1192.5006 | E41: =E39+E40 -> 9863.263 | F41: =F39+F40 -> 15539.655 | G41: =G39+G40 -> 21771.852 | H41: =H39+H40 -> 29058.439 | I41: =I39+I40 -> 38388.912
...

Sheet Revenue
A1: Revenue — 營收：①開放平台及 API（按量計費＋Coding Plan 子列）②企業級智能體 ③企業級通用大模型 ④技術服務及其他；總額＝淨額；雲端 vs 本地化、企業 vs 個人
A2: API 牌價：2025＝GLM-4.7／GLM-4.5-Air 牌價；1H26＝GLM-4.7→GLM-5→GLM-5.1 依發布日天數加權；2H26＝GLM-5.2／5.3（Sol）、GLM-4.5-Air→GLM-5.3-Flash（Luna）；2027 起 ×（1＋年變動率）。輸入價依長上下文占比混合兩檔。有效單價＝［(1−輸出占比)×(快取命中×快取價＋(1−快取命中)×輸入價)＋輸出占比×輸出價］×(1−折扣與免費額度)。
A3: 金額 RMB 億；牌價 元／百萬 token；Coding Plan 價格 元／月。②③④＝本地化部署分部（不耗智譜算力，D4、D2r）。容量上限暫以 Inputs 佔位 1（Z3 接 Compute），只回乘雲端營收。
A5: 編號 | B5: 項目 | C5: 單位 | D5: 2025 | E5: 2026 | F5: 2027 | G5: 2028 | H5: 2029 | I5: 2030 | K5: 1H2026 | L5: 2H2026 | M5: 說明
B6: 年度 | D6: =INP_001 -> 2025 | E6: =INP_002 -> 2026 | F6: =INP_003 -> 2027 | G6: =INP_004 -> 2028 | H6: =INP_005 -> 2029 | I6: =INP_006 -> 2030 | K6: 1H2026（實際） | L6: 2H2026（驅動）
A7: 一、價格期間權重（由發布日推得的天數；Inputs Derived）
A8: R01 | B8: 1H26 GLM-4.7 期間占比 | C8: 比例 | K8: =INP_026/INP_008 -> 0.2320442 | M8: 2026-01-01～02-11 ÷ 181 天
A9: R02 | B9: 1H26 GLM-5 期間占比 | C9: 比例 | K9: =INP_027/INP_008 -> 0.29834254 | M9: 2026-02-12～04-06 ÷ 181 天
A10: R03 | B10: 1H26 GLM-5.1 期間占比（＝1 − 前兩者） | C10: 比例 | K10: =(1-K8-K9) -> 0.46961326 | M10: 2026-04-07～06-30（GLM-5.2 於 06-16 發布，牌價同 GLM-5.1 ≥32K 檔）
A11: R04 | B11: 2H26 GLM-5.3-Flash 期間占比（Luna） | C11: 比例 | L11: =INP_028/INP_009 -> 0.69565217 | M11: 2026-08-26～12-31 ÷ 184 天；之前 Luna 以 GLM-4.5-Air 計
A12: 二、API 牌價（元／百萬 token；層級 × 輸入／快取／輸出）
