Workbook

Sheet README
A1: 東京精密（7729.T）收支與估值模型 v0.1.1（AI 半導體 Project：設備與材料） 2026-10-25
A2: 模型命題：東京精密約八成營收來自半導體設備（探針台約七成、切割／研削／CMP 約三成），其餘為計測機器；HPC 已占設備營收四成半。問題是 AI 測試與先進封裝的增量能否撐過設備循環，並讓現價約 20 倍的公司指引本益比（低於日本設備同業的 30 倍以上）被重估？
A3: （約 20 倍＝現價 ¥15,520（2026-10-23 收盤）÷ 公司 FY2026 指引 EPS ¥758.83 ＝ 20.5 倍；見 Val 頁第 1 節）
A5: 驅動因子 → 推導量（因果方向：左邊決定右邊）
A6: PL 區塊｜markets/equipment 同字母情境的「測試與其他封裝設備」（CY）→ FY(t)＝3/4 × CY(t)＋1/4 × CY(t+1) → 探針台需求指數（FY2026＝1）× FY2026 探針台營收 → 探針台營收
A7: PL 區塊｜「晶圓前段設備」× w_cmp ＋「先進封裝設備〔AI〕」×（1 − w_cmp）→ 加工裝置需求指數 × FY2026 加工裝置營收 → 加工裝置營收
A8: PL 區塊｜公司特有：超額成長（A +3%／B 0／C −3% 每年）、中國變化（A 0／B −5%／C −20%，× 中國占比 45%）→ SPE 營收
A9: PL 區塊｜計測機器：FY2026 指引 41.5 ×（1＋年增；A 6%／B 4%／C 1%，Analogy：公司歷史）
A10: Hist → PL｜部門營業利益＝FY2026 錨點 ＋ 邊際利潤率（FY2018–FY2025 迴歸）× 營收變化；淨利＝營業利益 × 0.70（公司指引隱含）
A11: PL｜FY2026 錨點＝公司指引（2026-08-04 上修：營收 189.0、營業利益 44.0、淨利 30.8、EPS 758.83）×（1＋g_anc，基準 0）
A12: Val｜目標價＝0.5 × DCF（股東現金流＝EPS ×（1 − g／ROE），FY2027–32 明確期＋永續）＋ 0.5 × Comparable（日本設備同業前瞻 P/E 中位數 × 12 個月後前瞻 EPS）；規則值（10 年 P/E 分位 × FY2027 EPS；循環位置 A 中段、B 中段、C 見頂）為參考
A14: 會計年度：4 月到隔年 3 月（FY2025＝2025-04～2026-03，公司「2026年3月期」）。金額為日圓，未建匯率（公司前提 1 美元＝150 日圓，日圓計價比重高，匯率影響輕微）。
... A19: v0.1.1（2026-10-25）：補上檔空間級距、投資建議、重點觀察（數值不變）。Val 頁最後新增「上檔空間級距」「投資建議」兩列（依「上檔空間：加權目標價」固定規則）；README 頁最後新增投資建議與重點觀察三點。
A20: ="投資建議："&Val!B116&"（依上檔空間固定規則）" -> 投資建議：買進（依上檔空間固定規則）
A21: 重點觀察 1：目標價 ¥19,528（DCF 10,189、Comparable 28,867 各半），比現價 15,520（2026-10-23）高 25.8%，級距 25%–50%；Comparable 單獨為 +86.0%。主因是 Comparable 的倍數：同業（Disco、東京威力科創、Advantest、Lasertec、Kokusai Electric）前瞻 P/E 中位數 34.0 倍，東京精密自身前瞻 P/E 只有 21.9 倍、現價隱含 18.3 倍 12 個月後前瞻 EPS（849），Comparable 未扣本公司長期低於同業的折價；EPS 只比共識前瞻 EPS 801 高 5.9%。DCF 反而比現價低 34.3%（ROE 13.9%、再投資率 28.7%）。
A22: 重點觀察 2：共識目標價 20,900 只隱含 26.1 倍（比同業中位數低 23.3%），市場已給折價；若 Comparable 改用 26.1 倍，加權目標價約落在中立區。情境 FY2028 EPS A 1,077、B 831、C 562，現價隱含 P/E 的十年分位 A 44%、B 90%、C 100%。
A23: 重點觀察 3：FY2027 EPS 對 FY2026 錨點（實績低於指引 3% → −3.6%、高於 5% → +6.0%）與中國 SPE（−20% → −4.5%）最敏感，情境 C 為 −18.6%。下一個檢驗事件是 FY2026 第二季財報（約 2026-11 上旬，日期未確認）：上半年實績與全年指引是否維持。

Sheet In
A1: In — 輸入（藍字；基準欄 E，低 D、高 F）。金額：十億日圓（¥B）；EPS：日圓。每個輸入附標記與來源；找不到者寫「未找到」，公司未揭露者寫「公司不揭露」
A2: 標記：Verified（公司文件、交易所資料）／Interested-party（寫明是誰、立場）／Analogy（寫明對照與差異）／Assumed（一律給低／高區間）／Derived（寫明換算）。SemiAnalysis 未使用。公司原文（accretech.com、JPX 適時開示）以網頁擷取工具讀取；表格錯位處以算術核對
A3: 鍵 | B3: 項目 | C3: 單位 | D3: 低 | E3: 基準 | F3: 高 | G3: 標記 | H3: 來源1 | I3: 來源2／說明
A4: A. FY2025 實績（2025-04～2026-03；校準錨）
A5: a25_rev | B5: 營收 FY2025 | C5: ¥B | E5: 166.839 | G5: Verified | H5: 公司 2026年3月期 決算短信（JPX 適時開示，2026-05-13）：166,839 百萬日圓（+10.8%） | I5: 松井證券 決算情報（finance.matsui.co.jp/stock/7729/settlement）：166,839
A6: a25_gp | B6: 毛利 FY2025 | C6: ¥B | E6: 68.86 | G6: Verified | H6: 公司 2026年3月期 決算說明補足資料（FS_2026_4q_J_rev，2026-05）：68,860（毛利率 41.3%） | I6: FY2024 62,453（41.5%）
A7: a25_sga | B7: 銷管費 FY2025 | C7: ¥B | E7: 35.122 | G7: Verified | H7: 公司 2026年3月期 決算說明補足資料（FS_2026_4q_J_rev，2026-05）：35,122 | I7: 毛利 − 銷管費 ＝ 33,738 ＝ 營業利益（算術核對）
A8: a25_oi | B8: 營業利益 FY2025 | C8: ¥B | E8: 33.738 | G8: Verified | H8: 公司 2026年3月期 決算短信（JPX 適時開示，2026-05-13）：33,738（+13.6%） | I8: 松井證券 決算情報（finance.matsui.co.jp/stock/7729/settlement）：33,738
A9: a25_ni | B9: 淨利（歸屬母公司）FY2025 | C9: ¥B | E9: 24.739 | G9: Verified | H9: 公司 2026年3月期 決算短信（JPX 適時開示，2026-05-13）：24,739（−3.5%；FY2024 含較多營業外與特別利益，淨利 25,637） | I9: 松井證券 決算情報（finance.matsui.co.jp/stock/7729/settlement）：24,739
A10: a25_eps | B10: 基本 EPS FY2025 | C10: ¥ | E10: 610.02 | G10: Verified | H10: 公司 2026年3月期 決算短信（JPX 適時開示，2026-05-13）：基本 610.02（稀釋 606.14） | I10: 松井證券 決算情報（finance.matsui.co.jp/stock/7729/settlement）：610.02
A11: spe_25 | B11: 半導體製造裝置（SPE）營收 FY2025 | C11: ¥B | E11: 127.878 | G11: Verified | H11: 公司 2026年3月期 決算說明補足資料（FS_2026_4q_J_rev，2026-05）：127,878（FY2024 113,481） | I11: 公司 2026年度第1四半期 決算說明資料（BR_2027-3_1q_J_2，2026-08-04）：四季 235／359／274／411 億（合計 1,279）
A12: spe_op25 | B12: SPE 營業利益 FY2025 | C12: ¥B | E12: 28.404 | G12: Verified | H12: 公司 2026年3月期 決算說明補足資料（FS_2026_4q_J_rev，2026-05）：28,404（22.2%） | I12: 公司 2026年度第1四半期 決算說明資料（BR_2027-3_1q_J_2，2026-08-04）：四季 40／83／53／107 億
A13: met_25 | B13: 計測機器營收 FY2025 | C13: ¥B | E13: 38.96 | G13: Verified | H13: 公司 2026年3月期 決算說明補足資料（FS_2026_4q_J_rev，2026-05）：38,960（FY2024 37,053） | I13: 公司 2026年度第1四半期 決算說明資料（BR_2027-3_1q_J_2，2026-08-04）：四季 73／103／85／128 億
A14: met_op25 | B14: 計測機器營業利益 FY2025 | C14: ¥B | E14: 5.333 | G14: Verified | H14: 公司 2026年3月期 決算說明補足資料（FS_2026_4q_J_rev，2026-05）：5,333（13.7%） | I14: 公司 2026年度第1四半期 決算說明資料（BR_2027-3_1q_J_2，2026-08-04）：四季 5／18／9／21 億
A15: ord_25 | B15: 受注 FY2025（SPE＋計測） | C15: ¥B | E15: 163.096 | G15: Verified | H15: 公司 2026年3月期 決算說明補足資料（FS_2026_4q_J_rev，2026-05）：163,096（SPE 123,396、計測 39,700）；期末受注殘 79,359 | I15: 只作參考（未進推導）
A16: B. FY2026 錨點：公司指引（2026-08-04 修正，Interested-party）與第一季實績
A17: g26_rev | B17: 公司指引：FY2026 營收（2026-04～2027-03） | C17: ¥B | E17: 189 | G17: Interested-party | H17: 公司 2027年3月期 第1四半期 決算短信（JPX，2026-08-04）：189,000（+13.3%）；5 月原指引 181,500 | I17: 公司 2026年度第1四半期 決算說明資料（BR_2027-3_1q_J_2，2026-08-04）：上修理由＝受注殘與強勁詢價，主要上修下半；營收只含已確保材料的部分（公司 2026年度第1四半期 決算說明會 Q&A（QA_2027-3_1q_J，2026-08-04））
A18: g26_met | B18: 公司指引：FY2026 計測機器營收 | C18: ¥B | E18: =40+1.5 -> 41.5 | G18: Interested-party | H18: 公司 2026年3月期 決算說明補足資料（FS_2026_4q_J_rev，2026-05）：5 月原指引計測 400 億 | I18: 公司 2026年度第1四半期 決算說明資料（BR_2027-3_1q_J_2，2026-08-04）：計測通期 +15 億上修（下半為主）
A19: g26_spe | B19: 公司指引：FY2026 SPE 營收（＝營收 − 計測） | C19: ¥B | E19: =g26_rev-g26_met -> 147.5 | G19: Derived | H19: 189.0 − 41.5 ＝ 147.5 | I19: 5 月原指引 SPE 141.5 ＋ 上修 6.0（公司 2026年度第1四半期 決算說明資料（BR_2027-3_1q_J_2，2026-08-04）：SPE +60 億）＝ 147.5，相同
A20: g26_oi | B20: 公司指引：FY2026 營業利益 | C20: ¥B | E20: 44 | G20: Interested-party | H20: 公司 2027年3月期 第1四半期 決算短信（JPX，2026-08-04）：44,000（+30.4%）；5 月原指引 40,000 | I20: 上半 19,100、下半 24,900（Derived）
A21: g26_ni | B21: 公司指引：FY2026 淨利 | C21: ¥B | E21: 30.8 | G21: Interested-party | H21: 公司 2027年3月期 第1四半期 決算短信（JPX，2026-08-04）：30,800（+24.5%）；EPS 758.83 | I21: 5 月原指引 28,000／689.87
A22: g26_eps | B22: 公司指引：FY2026 EPS | C22: ¥ | E22: 758.83 | G22: Interested-party | H22: 公司 2027年3月期 第1四半期 決算短信（JPX，2026-08-04）：758.83 | I22: minkabu 轉載 758.81
A23: m_spe26 | B23: FY2026 SPE 營業利益率（公司說法） | C23: % | D23: 0.25 | E23: 0.255 | F23: 0.26 | G23: Interested-party | H23: 公司 2026年度第1四半期 決算說明會 Q&A（QA_2027-3_1q_J，2026-08-04）：通期半導體營業利益率假設「25-6%」（原文如此，應為 25–26%） | I23: 計測營業利益＝指引營業利益 − SPE（Derived）；基準取中點
A24: g_anc | B24: FY2026 實績相對公司指引（營收；兩部門同比例） | C24: % | D24: -0.03 | E24: 0 | F24: 0.05 | G24: Assumed | H24: 基準＝公司指引（第二季尚未公布）；高：公司稱受注約為產能 1.5 倍、營收只含已確保材料，材料增加可再多數百億日圓（公司 2026年度第1四半期 決算說明會 Q&A（QA_2027-3_1q_J，2026-08-04）） | I24: 低：營收認列遞延（交期 4–8 個月）。營業利益隨營收以邊際利潤率（v_s、v_m）變動
A25: q1_rev | B25: FY2026 第一季營收（2026-04～06） | C25: ¥B | E25: 36.716 | G25: Verified | H25: 公司 2027年3月期 第1四半期 決算短信（JPX，2026-08-04）：36,716（+18.9%） | I25: 松井證券 決算情報（finance.matsui.co.jp/stock/7729/settlement）：36,716
A26: q1_oi | B26: FY2026 第一季營業利益 | C26: ¥B | E26: 5.92 | G26: Verified | H26: 公司 2027年3月期 第1四半期 決算短信（JPX，2026-08-04）：5,920（+29.2%） | I26: 松井證券 決算情報（finance.matsui.co.jp/stock/7729/settlement）
A27: q1_ni | B27: FY2026 第一季淨利 | C27: ¥B | E27: 4.667 | G27: Verified | H27: 公司 2027年3月期 第1四半期 決算短信（JPX，2026-08-04）：4,667；EPS 115.01 | I27: 松井證券 決算情報（finance.matsui.co.jp/stock/7729/settlement）
A28: q1_ord | B28: FY2026 第一季受注（全社） | C28: ¥B | E28: 65.8 | G28: Interested-party | H28: 公司 2026年度第1四半期 決算說明資料（BR_2027-3_1q_J_2，2026-08-04）：658 億（+83%，SPE 532、計測 126；創新高；受注約一半來自中國） | I28: 第一季末受注殘約 1,085 億（說明資料表格錯位，參考值）
A29: gh1_rev | B29: 公司指引：FY2026 上半營收 | C29: ¥B | E29: 88.5 | G29: Interested-party | H29: 公司 2027年3月期 第1四半期 決算短信（JPX，2026-08-04）：88,500（營業利益 19,100、淨利 13,400） | I29: 第二季隱含營收 51.8（Derived）
A30: shares | B30: 加權平均股數（扣除員工持股信託） | C30: 百萬股 | E30: 40.58844 | G30: Verified | H30: 公司 2027年3月期 第1四半期 決算短信（JPX，2026-08-04）：第一季期中平均 40,588,440 股 | I30: FY2025 平均 40,554,349（公司 2026年3月期 決算短信（JPX 適時開示，2026-05-13））
A31: C. SPE 產品組合與客戶結構（公司說法；Interested-party）
A32: w_pr | B32: 探針台（prober）占 SPE 營收 | C32: % | D32: 0.7 | E32: 0.72 | F32: 0.74 | G32: Interested-party | H32: 公司 2026年度第1四半期 決算說明資料（BR_2027-3_1q_J_2，2026-08-04）：FY2026 上半 SPE 營收構成 探針台「7 割前半」、加工裝置（切割、研削、CMP 等）「2 割後半」 | I32: 公司不揭露金額；FY2025 構成比未找到，假設與 FY2026 上半相同（Assumed）
A33: w_cmp | B33: 加工裝置中屬晶圓前段（CMP 等）的比例 | C33: % | D33: 0.1 | E33: 0.2 | F33: 0.35 | G33: Assumed | H33: 未找到：公司不揭露切割機、研削機、CMP 各自金額 | I33: 前段部分跟 markets/equipment「晶圓前段設備」，其餘跟「先進封裝〔AI〕」
A34: hpc | B34: HPC（含生成 AI）占 SPE 營收（FY2026 第一季） | C34: % | E34: 0.45 | G34: Interested-party | H34: 公司 2026年度第1四半期 決算說明會 Q&A（QA_2027-3_1q_J，2026-08-04）：第一季 HPC 占 SPE 營收「4 割半ば」，其中邏輯 2／3、HBM 1／3；受注約 4 割 | I34: FY2025 第一季約 25%（QA_2026_1q_J，2025-08-04）。只作說明，未進推導（上游設備路徑已含 AI）
A35: chn | B35: 中國占 SPE 受注（FY2026 第一季） | C35: % | D35: 0.4 | E35: 0.45 | F35: 0.5 | G35: Interested-party | H35: 公司 2026年度第1四半期 決算說明資料（BR_2027-3_1q_J_2，2026-08-04）：第一季受注「半分弱」來自中國 | I35: 營收占比未找到（補足資料表格錯位）；以受注比代替
A36: D. 設備市場（markets/equipment 成品 Mkt 頁 5A／5B／5C，同字母情境；唯讀）
A37: tstA_25 | B37: 測試與其他封裝設備 CY2025（情境 A） | C37: US$B | E37: 14.735959 | G37: Derived | H37: markets/equipment/dist/20261023_半導體設備市場模型_v0.1.3.xlsx｜Mkt!C126:G126 | I37: markets/equipment v0.1.3：B、C 自 2028 起與 A 不同（設備市場模型的情境係數為 Assumed）
A38: tstA_26 | B38: 測試與其他封裝設備 CY2026（情境 A） | C38: US$B | E38: 18.65 | G38: Derived | H38: 同上
A39: tstA_27 | B39: 測試與其他封裝設備 CY2027（情境 A） | C39: US$B | E39: 21.634674 | G39: Derived | H39: 同上
A40: tstA_28 | B40: 測試與其他封裝設備 CY2028（情境 A） | C40: US$B | E40: 25.1 | G40: Derived | H40: 同上
...

Sheet Q
A1: Q — 季度實績（十億日圓；EPS 為日圓）。會計年度 4–3 月。來源1：松井證券季度表（百萬日圓）；來源2：公司決算說明資料（億日圓，部門）
A3: 項目 | B3: FY25 Q1 | C3: FY25 Q2 | D3: FY25 Q3 | E3: FY25 Q4 | F3: FY2025 | G3: FY26 Q1 | H3: FY26 Q2（公司上半指引隱含） | I3: 標記 | J3: 來源1 | K3: 來源2／說明
A4: 營收 | B4: 30.876 | C4: 46.194 | D4: 35.901 | E4: 53.868 | F4: =SUM(B4:E4) -> 166.839 | G4: 36.716 | H4: =gh1_rev-q1_rev -> 51.784 | I4: Verified／Interested-party（指引） | J4: 松井：30,876／46,194／35,901／53,868；36,716 | K4: 公司上半指引 88.5 − 第一季
A5: 營業利益 | B5: 4.581 | C5: 10.136 | D5: 6.215 | E5: 12.806 | F5: =SUM(B5:E5) -> 33.738 | G5: 5.92 | H5: =19.1-q1_oi -> 13.18 | I5: Verified／Interested-party（指引） | J5: 松井：4,581／10,136／6,215／12,806；5,920 | K5: 上半指引 19.1
A6: 淨利 | B6: 3.229 | C6: 6.383 | D6: 4.536 | E6: 10.591 | F6: =SUM(B6:E6) -> 24.739 | G6: 4.667 | H6: =13.4-q1_ni -> 8.733 | I6: Verified／Interested-party（指引） | J6: 松井：3,229／6,383／4,536／10,591；4,667 | K6: 上半指引 13.4
A7: EPS（基本） | B7: 79.77 | C7: 157.5 | D7: 111.88 | E7: 261.16 | F7: =SUM(B7:E7) -> 610.31 | G7: 115.01 | H7: =330.14-115.01 -> 215.13 | I7: Verified／Interested-party（指引） | J7: 松井 | K7: 上半指引 EPS 330.14
A8: SPE 營收 | B8: 23.5 | C8: 35.9 | D8: 27.4 | E8: 41.1 | F8: =SUM(B8:E8) -> 127.9 | G8: 28.5 | I8: Interested-party（公司說明資料，億日圓取整） | J8: 公司 2026年度第1四半期 決算說明資料（BR_2027-3_1q_J_2，2026-08-04）（億日圓） | K8: FY2025 合計 127.9（說明資料四季合計 1,279）
A9: SPE 營業利益 | B9: 4 | C9: 8.3 | D9: 5.3 | E9: 10.7 | F9: =SUM(B9:E9) -> 28.3 | G9: 5.4 | I9: Interested-party（公司說明資料，億日圓取整） | J9: 公司 2026年度第1四半期 決算說明資料（BR_2027-3_1q_J_2，2026-08-04）
A10: SPE 受注 | B10: 26.4 | C10: 34.9 | D10: 26 | E10: 36.1 | F10: =SUM(B10:E10) -> 123.4 | G10: 53.2 | I10: Interested-party（公司說明資料，億日圓取整） | J10: 公司 2026年度第1四半期 決算說明資料（BR_2027-3_1q_J_2，2026-08-04） | K10: 第一季 +102%：會社想定比多 100 億以上，約一半來自中國；第二季預期低於第一季（部分提前）
A11: 計測營收 | B11: 7.3 | C11: 10.3 | D11: 8.5 | E11: 12.8 | F11: =SUM(B11:E11) -> 38.9 | G11: 8.2 | I11: Interested-party（公司說明資料，億日圓取整） | J11: 公司 2026年度第1四半期 決算說明資料（BR_2027-3_1q_J_2，2026-08-04）
A12: 計測營業利益 | B12: 0.5 | C12: 1.8 | D12: 0.9 | E12: 2.1 | F12: =SUM(B12:E12) -> 5.3 | G12: 0.5 | I12: Interested-party（公司說明資料，億日圓取整） | J12: 公司 2026年度第1四半期 決算說明資料（BR_2027-3_1q_J_2，2026-08-04）
A13: 營業利益率 | B13: =B5/B4 -> 0.14836766 | C13: =C5/C4 -> 0.21942244 | D13: =D5/D4 -> 0.17311496 | E13: =E5/E4 -> 0.23772926 | F13: =F5/F4 -> 0.20221891 | G13: =G5/G4 -> 0.16123761 | H13: =H5/H4 -> 0.25451877
A14: 檢查：FY2025 四季合計 − 年度實績（營收、營業利益、淨利；應約為 0） | B14: =F4-a25_rev -> 0 | C14: =F5-a25_oi -> 0 | D14: =F6-a25_ni -> 0
A15: 第一季營收占公司全年指引 | B15: =q1_rev/g26_rev -> 0.19426455 | C15: FY2025 第一季占全年： | D15: =B4/a25_rev -> 0.18506464
A17: 公司揭露的結構（公司 2026年度第1四半期 決算說明會 Q&A（QA_2027-3_1q_J，2026-08-04）；Interested-party）：第一季 HPC 占 SPE 營收 4 割半ば（邏輯 2／3、HBM 1／3）；HPC 受注約 200 億日圓台半（邏輯 3／4、HBM 1／4）；受注約為產能 1.5 倍；探針台、切割機交期 4–8 個月、研削機 6 個月以上

Sheet Hist
A1: Hist — 年度實績（十億日圓；EPS 為日圓）。合併：roic.ai 年度資料（來源1），FY2018 起與公司決算短信、說明資料交叉；部門（SPE、計測）：公司說明資料（FY2018 起）。用途：邊際利潤率迴歸（In 頁 F 節）、十年平均淨利率、十年 P/E 的 EPS
A2: 會計年度 FY(t)＝t 年 4 月～t+1 年 3 月（例：FY2025＝2026年3月期）。過去十年無股票分割（各年 EPS 為公司公布值；roic.ai 加權股數 41–42 百萬股，穩定）
A5: 會計年度 | B5: 營收 | C5: 營業利益 | D5: 淨利 | E5: EPS（基本，日圓） | F5: 淨利率 | G5: 營業利益率 | H5: 標記 | I5: SPE 營收 | J5: SPE 營業利益 | K5: 計測營收 | L5: 計測營業利益 | M5: 來源1 | N5: 來源2
A6: FY2015（2016-03） | B6: 70.274 | C6: 13.219 | D6: 9.704 | E6: 234.58 | F6: =D6/B6 -> 0.13808806 | G6: =C6/B6 -> 0.18810655 | H6: Derived（營業利益＝roic 營收 × 營益率 18.81%） | M6: roic.ai | N6: 未找到
A7: FY2016（2017-03） | B7: 77.792 | C7: 13.66 | D7: 9.909 | E7: 239.31 | F7: =D7/B7 -> 0.12737814 | G7: =C7/B7 -> 0.17559646 | H7: Derived（營業利益＝營收 × 17.56%） | M7: roic.ai | N7: 未找到
A8: FY2017（2018-03） | B8: 88.194 | C8: 17.286 | D8: 12.717 | E8: 306.4 | F8: =D8/B8 -> 0.14419348 | G8: =C8/B8 -> 0.19599973 | H8: Derived（營業利益＝營收 × 19.60%） | M8: roic.ai | N8: 未找到
A9: FY2018（2019-03） | B9: 101.52 | C9: 20.221 | D9: 14.665 | E9: 352.92 | F9: =D9/B9 -> 0.14445429 | G9: =C9/B9 -> 0.19918243 | H9: Verified | I9: 69.117 | J9: 13.195 | K9: 32.403 | L9: 7.025 | M9: 公司 FY2020/3 決算短信（英文，2020-05-11） | N9: roic.ai；部門：公司 FY2023/3 第三季說明資料（2023-02-06）
A10: FY2019（2020-03） | B10: 87.927 | C10: 12.282 | D10: 7.156 | E10: 171.89 | F10: =D10/B10 -> 0.081385695 | G10: =C10/B10 -> 0.13968406 | H10: Verified | I10: 56.198 | J10: 7.915 | K10: 31.728 | L10: 4.366 | M10: 公司 FY2020/3 決算短信（2020-05-11） | N10: roic.ai
A11: FY2020（2021-03） | B11: 97.105 | C11: 15.566 | D11: 12.175 | E11: 293.83 | F11: =D11/B11 -> 0.12537974 | G11: =C11/B11 -> 0.16030071 | H11: Verified（營業利益 Derived：roic 營益率 16.03%；部門合計 15.561） | I11: 71.745 | J11: 13.565 | K11: 25.359 | L11: 1.996 | M11: roic.ai | N11: 部門：公司 FY2023/3 第三季說明資料
A12: FY2021（2022-03） | B12: 130.702 | C12: 28.327 | D12: 21.326 | E12: 522.52 | F12: =D12/B12 -> 0.16316506 | G12: =C12/B12 -> 0.21672966 | H12: Verified | I12: 101.145 | J12: 24.698 | K12: 29.556 | L12: 3.628 | M12: 松井證券 決算情報（finance.matsui.co.jp/stock/7729/settlement） | N12: 公司 FY2023/3 決算說明資料（2023-05-11）；roic.ai
A13: FY2022（2023-03） | B13: 146.801 | C13: 34.494 | D13: 23.63 | E13: 581.33 | F13: =D13/B13 -> 0.16096621 | G13: =C13/B13 -> 0.23497115 | H13: Verified | I13: 112.365 | J13: 29.866 | K13: 34.436 | L13: 4.628 | M13: 松井證券 決算情報（finance.matsui.co.jp/stock/7729/settlement） | N13: 公司 FY2023/3 決算說明資料（2023-05-11）
A14: FY2023（2024-03） | B14: 134.68 | C14: 25.307 | D14: 19.378 | E14: 480.49 | F14: =D14/B14 -> 0.14388179 | G14: =C14/B14 -> 0.18790466 | H14: Verified | I14: 100.055 | J14: 19.899 | K14: 34.624 | L14: 5.408 | M14: 松井證券 決算情報（finance.matsui.co.jp/stock/7729/settlement） | N14: 公司 FY2024/3 決算說明資料（2024-05-10）
A15: FY2024（2025-03） | B15: 150.534 | C15: 29.703 | D15: 25.637 | E15: 633.75 | F15: =D15/B15 -> 0.17030704 | G15: =C15/B15 -> 0.19731755 | H15: Verified | I15: 113.481 | J15: 24.311 | K15: 37.053 | L15: 5.392 | M15: 松井證券 決算情報（finance.matsui.co.jp/stock/7729/settlement） | N15: 公司 2026年3月期 決算說明補足資料（FS_2026_4q_J_rev，2026-05）
A16: FY2025（2026-03） | B16: 166.839 | C16: 33.738 | D16: 24.739 | E16: 610.02 | F16: =D16/B16 -> 0.14828068 | G16: =C16/B16 -> 0.20221891 | H16: Verified | I16: 127.878 | J16: 28.404 | K16: 38.96 | L16: 5.333 | M16: 公司 2026年3月期 決算短信（JPX 適時開示，2026-05-13） | N16: 松井證券 決算情報（finance.matsui.co.jp/stock/7729/settlement）；公司 2026年3月期 決算說明補足資料（FS_2026_4q_J_rev，2026-05）
A18: 檢查：FY2025 列 − In 頁 a25_*、部門合計 − 合併（應約為 0） | B18: =ABS(B16-a25_rev)+ABS(C16-a25_oi)+ABS(D16-a25_ni)+ABS(E16-a25_eps)+ABS(I16+K16-B16)+ABS(J16+L16-C16) -> 0.002
A20: 迴歸與 Analogy（In 頁同值）
A21: SPE 營業利益 ＝ 固定 ＋ 邊際 × 營收：邊際（FY2018–FY2025） | B21: =v_s -> 0.30078343
A22: R² | B22: =RSQ(J9:J16,I9:I16) -> 0.92026184
A23: 固定（¥B） | B23: =INTERCEPT(J9:J16,I9:I16) -> -8.0414161
A24: 計測營業利益：邊際（FY2018–FY2025） | B24: =v_m -> 0.24064585
A25: R² | B25: =RSQ(L9:L16,K9:K16) -> 0.48585035
A26: SPE 邊際（只用 FY2021–FY2025） | B26: =v_s2 -> 0.23779039
A27: 計測營收年複合 FY2018→FY2025 | B27: =(K16/K9)^(1/7)-1 -> 0.026675952
A28: 計測營收年複合 FY2020→FY2025 | B28: =(K16/K11)^(1/5)-1 -> 0.089675948
A29: SPE 營收年複合 FY2018→FY2025 | B29: =(I16/I9)^(1/7)-1 -> 0.091875179
A30: 十年平均淨利率 FY2016–FY2025 | B30: =nim10 -> 0.14093921
A31: 最大單年 SPE 營收下滑（FY2019） | B31: =I10/I9-1 -> -0.18691494

Sheet PL
A1: PL — 東京精密 損益（¥B；FY2025 實績；FY2026 錨定公司指引（2026-08-04 修正）；FY2027–FY2029 驅動推導；FY2030 起收斂法）。頂端為摘要，下方為三情境各一個完整推導區塊
A3: 情境／項目 | B3: 單位 | C3: FY2025A | D3: FY2026 | E3: FY2027 | F3: FY2028 | G3: FY2029 | H3: 說明
A4: 情境 A（順利）
A5: 營收 | B5: ¥B | C5: =C76 -> 166.838 | D5: =D76 -> 189 | E5: =E76 -> 219.67028 | F5: =F76 -> 251.40659 | G5: =G76 -> 272.55182
A6: 探針台 | B6: ¥B | C6: =C72 -> 92.07216 | D6: =D72 -> 106.2 | E6: =E72 -> 126.89594 | F6: =F72 -> 148.71573 | G6: =G72 -> 162.18763
A7: 加工裝置 | B7: ¥B | C7: =C73 -> 35.80584 | D7: =D73 -> 41.3 | E7: =E73 -> 48.78434 | F7: =F73 -> 56.061462 | G7: =G73 -> 60.937026
A8: 計測機器 | B8: ¥B | C8: =C75 -> 38.96 | D8: =D75 -> 41.5 | E8: =E75 -> 43.99 | F8: =F75 -> 46.6294 | G8: =G75 -> 49.427164
A9: 營業利益 | B9: ¥B | C9: =C81 -> 33.737 | D9: =D81 -> 44 | E9: =E81 -> 53.075369 | F9: =F81 -> 62.462399 | G9: =G81 -> 68.654282
A10: 營業利益率 | B10: % | C10: =C83 -> 0.20221412 | D10: =D83 -> 0.23280423 | E10: =E83 -> 0.24161379 | F10: =F83 -> 0.24845172 | G10: =G83 -> 0.25189442
A11: SPE 營業利益率 | B11: % | C11: =C82 -> 0.22211796 | D11: =D82 -> 0.255 | E11: =E82 -> 0.26234397 | F11: =F82 -> 0.26780585 | G11: =G82 -> 0.27051759
A12: 淨利 | B12: ¥B | C12: =C84 -> 24.739 | D12: =D84 -> 30.8 | E12: =E84 -> 37.152758 | F12: =F84 -> 43.72368 | G12: =G84 -> 48.057997
A13: EPS | B13: ¥ | C13: =C85 -> 610.02 | D13: =D85 -> 758.83675 | E13: =E85 -> 915.3532 | F13: =F85 -> 1077.2446 | G13: =G85 -> 1184.0316
A15: 情境 B（平平）
A16: 營收 | B16: ¥B | C16: =C105 -> 166.838 | D16: =D105 -> 189 | E16: =E105 -> 205.62949 | F16: =F105 -> 203.49955 | G16: =G105 -> 199.27172
A17: 探針台 | B17: ¥B | C17: =C101 -> 92.07216 | D17: =D101 -> 106.2 | E17: =E101 -> 117.12387 | F17: =F101 -> 114.34385 | G17: =G101 -> 110.00168
A18: 加工裝置 | B18: ¥B | C18: =C102 -> 35.80584 | D18: =D102 -> 41.3 | E18: =E102 -> 45.345617 | F18: =F102 -> 44.269303 | G18: =G102 -> 42.58819
A19: 計測機器 | B19: ¥B | C19: =C104 -> 38.96 | D19: =D104 -> 41.5 | E19: =E104 -> 43.16 | F19: =F104 -> 44.8864 | G19: =G104 -> 46.681856
A20: 營業利益 | B20: ¥B | C20: =C110 -> 33.737 | D20: =D110 -> 44 | E20: =E110 -> 48.902047 | F20: =F110 -> 48.157575 | G20: =G110 -> 46.77794
A21: 營業利益率 | B21: % | C21: =C112 -> 0.20221412 | D21: =D112 -> 0.23280423 | E21: =E112 -> 0.23781631 | F21: =F112 -> 0.23664708 | G21: =G112 -> 0.23474449
A22: SPE 營業利益率 | B22: % | C22: =C111 -> 0.22211796 | D22: =D111 -> 0.255 | E22: =E111 -> 0.25921836 | F22: =F111 -> 0.25820779 | G22: =G111 -> 0.25652718
A23: 淨利 | B23: ¥B | C23: =C113 -> 24.739 | D23: =D113 -> 30.8 | E23: =E113 -> 34.231433 | F23: =F113 -> 33.710302 | G23: =G113 -> 32.744558
A24: EPS | B24: ¥ | C24: =C114 -> 610.02 | D24: =D114 -> 758.83675 | E24: =E114 -> 843.37887 | F24: =F114 -> 830.53949 | G24: =G114 -> 806.7459
A26: 情境 C（不如預期）
A27: 營收 | B27: ¥B | C27: =C134 -> 166.838 | D27: =D134 -> 189 | E27: =E134 -> 186.52024 | F27: =F134 -> 154.88795 | G27: =G134 -> 151.93468
A28: 探針台 | B28: ¥B | C28: =C130 -> 92.07216 | D28: =D130 -> 106.2 | E28: =E130 -> 104.24558 | F28: =F130 -> 81.139771 | G28: =G130 -> 78.705578
A29: 加工裝置 | B29: ¥B | C29: =C131 -> 35.80584 | D29: =D131 -> 41.3 | E29: =E131 -> 40.359663 | F29: =F131 -> 31.414031 | G29: =G131 -> 30.47161
A30: 計測機器 | B30: ¥B | C30: =C133 -> 38.96 | D30: =D133 -> 41.5 | E30: =E133 -> 41.915 | F30: =F133 -> 42.33415 | G30: =G133 -> 42.757492
A31: 營業利益 | B31: ¥B | C31: =C139 -> 33.737 | D31: =D139 -> 44 | E31: =E139 -> 43.229172 | F31: =F139 -> 32.563959 | G31: =G139 -> 31.683971
A32: 營業利益率 | B32: % | C32: =C141 -> 0.20221412 | D32: =D141 -> 0.23280423 | E32: =E141 -> 0.23176666 | F32: =F141 -> 0.21024204 | G32: =G141 -> 0.2085368
A33: SPE 營業利益率 | B33: % | C33: =C140 -> 0.22211796 | D33: =D140 -> 0.255 | E33: =E140 -> 0.25408349 | F33: =F140 -> 0.23078496 | G33: =G140 -> 0.22892934
A34: 淨利 | B34: ¥B | C34: =C142 -> 24.739 | D34: =D142 -> 30.8 | E34: =E142 -> 30.260421 | F34: =F142 -> 22.794771 | G34: =G142 -> 22.17878
A35: EPS | B35: ¥ | C35: =C143 -> 610.02 | D35: =D143 -> 758.83675 | E35: =E143 -> 745.54283 | F35: =F143 -> 561.60748 | G35: =G143 -> 546.43095
A37: 核對：三情境 FY2025 − 實績（營收與營業利益；捨入差約 0.002） | C37: =C86+C115+C144 -> 0.006
A38: 核對：FY2026 營收、營業利益、EPS − 公司指引（g_anc＝0 時應為 0；EPS 差為股數捨入） | C38: =ABS(D5-g26_rev)+ABS(D9-g26_oi) -> 0 | D38: =D13-g26_eps -> 0.0067525335
A60: 情境 A（順利）：設備市場 A（見頂 2029）；SPE 超額成長 +3%/年；中國持平；計測 +6%
A61: 項目 | B61: 單位 | C61: CY2025／FY2025 | D61: CY2026／FY2026 | E61: CY2027／FY2027 | F61: CY2028／FY2028 | G61: CY2029／FY2029 | H61: CY2030 | J61: 說明
A62: A. 設備市場（日曆年；markets/equipment 情境 A）
A63: 測試與其他封裝設備 | B63: US$B | C63: =tstA_25 -> 14.735959 | D63: =tstA_26 -> 18.65 | E63: =tstA_27 -> 21.634674 | F63: =tstA_28 -> 25.1 | G63: =tstA_29 -> 27.108 | H63: =G63*(1+g_tail) -> 27.108 | J63: CY2030＝CY2029 ×（1＋g_tail）
A64: 先進封裝設備〔AI〕 | B64: US$B | C64: =apkA_25 -> 3.0565693 | D64: =apkA_26 -> 3.35 | E64: =apkA_27 -> 3.7953919 | F64: =apkA_28 -> 4.3 | G64: =apkA_29 -> 4.644 | H64: =G64*(1+g_tail) -> 4.644
A65: 晶圓前段設備 | B65: US$B | C65: =wfeA_25 -> 116.89683 | D65: =wfeA_26 -> 156.15705 | E65: =wfeA_27 -> 192.79547 | F65: =wfeA_28 -> 216.62863 | G65: =wfeA_29 -> 228.90369 | H65: =G65*(1+g_tail) -> 228.90369
...

Sheet Val
A1: Val — 估值（日圓）。目標價＝DCF 與 Comparable 加權（第 0 節）；跨公司規則值（十年年底 P/E 依循環位置取分位：見頂 25 分位、中段中位數、谷底 75 分位）保留為參考（第 5–6 節）
A2: P/E 定義（自算）：日曆年底收盤價 ÷ 「當期會計年度」公司公布的基本 EPS（例：2025-12 對 FY2025＝2026年3月期）。過去十年無股票分割
A4: 0. 目標價
A5: 0.1 DCF（股東權益現金流，FY2027–FY2032 明確期＋FY2032 後永續）
A6: 項目 | B6: A（順利） | C6: B（平平） | D6: C（不如預期） | E6: 說明
A7: 情境 EPS（FY2027–FY2032） | E7: PL 頁延伸區塊；FY2030 起為收斂法
A8: FY2027 | B8: =PL!E156 -> 915.3532 | C8: =PL!E163 -> 843.37887 | D8: =PL!E170 -> 745.54283
A9: FY2028 | B9: =PL!F156 -> 1077.2446 | C9: =PL!F163 -> 830.53949 | D9: =PL!F170 -> 561.60748
A10: FY2029 | B10: =PL!G156 -> 1184.0316 | C10: =PL!G163 -> 806.7459 | D10: =PL!G170 -> 546.43095
A11: FY2030 | B11: =PL!H156 -> 1274.103 | C11: =PL!H163 -> 787.20611 | D11: =PL!H170 -> 536.88146
A12: FY2031 | B12: =PL!I156 -> 1360.7878 | C12: =PL!I163 -> 783.24657 | D12: =PL!I170 -> 534.33758
A13: FY2032 | B13: =PL!J156 -> 1442.435 | C13: =PL!J163 -> 794.29627 | D13: =PL!J170 -> 538.60851
A14: 股東現金流＝EPS ×（1 − tp_g ÷ tp_roe） | E14: 模型無折舊與資本支出項目，故不用（淨利＋折舊－資本支出）；公司 FY2026 資本支出指引 150 億、折舊 62 億（擴產期），近年股東現金流可能低於此式（偏高估）
A15: 再投資率（tp_g ÷ tp_roe，上限 0.8） | B15: =MIN(tp_g/tp_roe,0.8) -> 0.28708134 | E15: ROE 為近三年平均（In 頁 tp_roe）
A16: FY2027 | B16: =B8*(1-$B$15) -> 652.57237 | C16: =C8*(1-$B$15) -> 601.26053 | D16: =D8*(1-$B$15) -> 531.5114
A17: FY2028 | B17: =B9*(1-$B$15) -> 767.98781 | C17: =C9*(1-$B$15) -> 592.1071 | D17: =D9*(1-$B$15) -> 400.38045
A18: FY2029 | B18: =B10*(1-$B$15) -> 844.11825 | C18: =C10*(1-$B$15) -> 575.14421 | D18: =D10*(1-$B$15) -> 389.56082
A19: FY2030 | B19: =B11*(1-$B$15) -> 908.33183 | C19: =C11*(1-$B$15) -> 561.21393 | D19: =D11*(1-$B$15) -> 382.75281
A20: FY2031 | B20: =B12*(1-$B$15) -> 970.131 | C20: =C12*(1-$B$15) -> 558.39109 | D20: =D12*(1-$B$15) -> 380.93923
A21: FY2032 | B21: =B13*(1-$B$15) -> 1028.3389 | C21: =C13*(1-$B$15) -> 566.26863 | D21: =D13*(1-$B$15) -> 383.98405
A22: DCF 情境每股價值（折現率 tp_r） | B22: =MAX(0,SUMPRODUCT(B16:B21,1/(1+tp_r)^{1;2;3;4;5;6})+B21*(1+tp_g)/(tp_r-tp_g)/(1+tp_r)^6) -> 13726.883 | C22: =MAX(0,SUMPRODUCT(C16:C21,1/(1+tp_r)^{1;2;3;4;5;6})+C21*(1+tp_g)/(tp_r-tp_g)/(1+tp_r)^6) -> 8058.231 | D22: =MAX(0,SUMPRODUCT(D16:D21,1/(1+tp_r)^{1;2;3;4;5;6})+D21*(1+tp_g)/(tp_r-tp_g)/(1+tp_r)^6) -> 5578.458 | E22: Σ 明確期現金流 ÷ (1＋r)^t ＋ 永續價值 ÷ (1＋r)^6；永續價值＝FY2032 現金流 ×(1＋g)÷(r−g)；基準日 2026 年底，t＝1 對 FY2027；低於 0 取 0；會計年度 4–3 月，FY2027＝2027-04～2028-03 仍以 t＝1 折現（略高估）
A23: DCF 情境價值推到 12 個月後（×(1＋tp_r)） | B23: =B22*(1+tp_r) -> 15099.572 | C23: =C22*(1+tp_r) -> 8864.0541 | D23: =D22*(1+tp_r) -> 6136.3038
A24: DCF 目標價（情境加權） | B24: =tp_wA*B23+tp_wB*C23+tp_wC*D23 -> 10189.159 | E24: Σ 權重 × 情境價值 ×(1＋r)；權重見 In 頁 tp_wA／tp_wB／tp_wC
A26: 0.2 Comparable（市場主流同業前瞻 P/E；非 A 股公司，同業不放 A 股）
A27: 同業與前瞻 P/E | B27: 代號 | C27: 前瞻 12 月 P/E | D27: 日期 | E27: 來源 | F27: 標記
A28: Disco | B28: 6146.T | C28: 26.01 | D28: 2026-10-23 | E28: stockanalysis.com statistics：Forward PE（分析師共識；價格日期如左） | F28: Interested-party
A29: 東京威力科創（Tokyo Electron） | B29: 8035.T | C29: 27.09 | D29: 2026-10-21 | E29: 同上 | F29: Interested-party
A30: Advantest | B30: 6857.T | C30: 37.69 | D30: 2026-10-21 | E30: 同上 | F30: Interested-party
A31: Lasertec | B31: 6920.T | C31: 34.02 | D31: 2026-10-23 | E31: 同上 | F31: Interested-party
A32: Kokusai Electric | B32: 6525.T | C32: 35.83 | D32: 2026-10-02 | E32: 同上（價格日期較舊） | F32: Interested-party
A33: 並列參考（不進目標價）：東京精密自身前瞻 P/E | C33: =sa_fpe -> 21.86 | D33: 2026-09-29 | E33: stockanalysis.com；本公司長期低於同業（見第 2 節十年 P/E）
A34: 同業前瞻 P/E 中位數 | B34: =MEDIAN(C28:C32) -> 34.02 | E34: 日本半導體設備同業：Disco（研削／切割同業）、東京威力科創（探針台同業）、Advantest（測試）、Lasertec、Kokusai Electric
A35: 12 個月後的前瞻 EPS（情境加權） | B35: =tp_wA*(5/12*B8+7/12*B9)+tp_wB*(5/12*C8+7/12*C9)+tp_wC*(5/12*D8+7/12*D9) -> 848.53102 | E35: 約 2027-10 時的未來 12 月（2027-11～2028-10）≈ 5／12 × FY2027（2027-04～2028-03）＋7／12 × FY2028（會計年度 4–3 月，依月份調整）
A36: Comparable 目標價 | B36: =B34*B35 -> 28867.025 | E36: 同業中位數 × 上列 EPS
A38: 0.3 結論
A39: 項目 | B39: 數值 | E39: 說明
A40: 目標價（DCF 與 Comparable 加權） | B40: =tp_w_dcf*B24+(1-tp_w_dcf)*B36 -> 19528.092 | E40: tp_w_dcf × DCF 目標價＋（1 − tp_w_dcf）× Comparable 目標價；tp_w_dcf 見 In 頁
A41: Comparable 目標價（市場主流同業法） | B41: =B36 -> 28867.025 | E41: 引用 0.2
A42: 市場共識目標價 | B42: =cons_tp -> 20900 | E42: minkabu（2026-10-23）：9 位分析師平均 20,900；stockanalysis（S&P Global）同值
A43: 上檔空間：加權目標價 | B43: =B40/px-1 -> 0.25825337 | E43: 現價＝In 頁 px（2026-10-23 收盤 15,520）
...

Sheet Recon
A1: Recon — FY2026 錨定公司指引（A 節為恆等式，不是檢驗）；B 節共識只作參考，未用於校準或錨點；C 節為結構檢查。差距＝模型 ÷ 對照 − 1
A3: 項目 | B3: 對照值 | C3: 模型 A | D3: 差距 A | E3: 模型 B | F3: 差距 B | G3: 模型 C | H3: 差距 C | I3: 對照來源 | J3: 說明
A4: A. FY2026 錨點（公司指引 2026-08-04）：差距為 0 是恆等式
A5: FY2026 營收 vs 公司指引 | B5: =g26_rev -> 189 | C5: =PL!D5 -> 189 | D5: =C5/B5-1 -> 0 | E5: =PL!D16 -> 189 | F5: =E5/B5-1 -> 0 | G5: =PL!D27 -> 189 | H5: =G5/B5-1 -> 0 | I5: 決算短信（第一季）189.0
A6: FY2026 營業利益 vs 公司指引 | B6: =g26_oi -> 44 | C6: =PL!D9 -> 44 | D6: =C6/B6-1 -> 0 | E6: =PL!D20 -> 44 | F6: =E6/B6-1 -> 0 | G6: =PL!D31 -> 44 | H6: =G6/B6-1 -> 0 | I6: 44.0
A7: FY2026 EPS vs 公司指引 | B7: =g26_eps -> 758.83 | C7: =PL!D13 -> 758.83675 | D7: =C7/B7-1 -> 8.8986117e-06 | E7: =PL!D24 -> 758.83675 | F7: =E7/B7-1 -> 8.8986117e-06 | G7: =PL!D35 -> 758.83675 | H7: =G7/B7-1 -> 8.8986117e-06 | I7: 758.83 | J7: 差異為股數捨入
A8: FY2026 營業利益率 vs FY2025 實績（百分點） | B8: =a25_oi/a25_rev -> 0.20221891 | C8: =PL!D10 -> 0.23280423 | D8: =C8-B8 -> 0.030585327 | E8: =PL!D21 -> 0.23280423 | F8: =E8-B8 -> 0.030585327 | G8: =PL!D32 -> 0.23280423 | H8: =G8-B8 -> 0.030585327 | I8: FY2025 20.2% | J8: 公司稱高溫控探針台、HRG 研削機、切割機量增改善組合
A9: A2. 第一季進度（只作合理性檢查）
A10: FY2026 上半指引隱含第二季營收 vs 第一季實績 | B10: =q1_rev -> 36.716 | C10: =gh1_rev-q1_rev -> 51.784 | D10: =C10/B10-1 -> 0.41039329 | E10: =gh1_rev-q1_rev -> 51.784 | F10: =E10/B10-1 -> 0.41039329 | G10: =gh1_rev-q1_rev -> 51.784 | H10: =G10/B10-1 -> 0.41039329 | I10: 上半指引 88.5 − 第一季 36.7 | J10: 第二季須 +41%；FY2025 第二季對第一季 +50%（Q 頁）
A11: FY2026 下半營收（指引隱含）vs FY2025 下半實績 | B11: =a25_rev-77.07 -> 89.769 | C11: =PL!D5-gh1_rev -> 100.5 | D11: =C11/B11-1 -> 0.11954015 | E11: =PL!D16-gh1_rev -> 100.5 | F11: =E11/B11-1 -> 0.11954015 | G11: =PL!D27-gh1_rev -> 100.5 | H11: =G11/B11-1 -> 0.11954015 | I11: FY2025 上半 77.07（松井） | J11: 下半 100.5 vs 89.8
A12: B. FY2026 vs 共識（參考）
A13: 營收 vs 共識（minkabu 2026-10-23） | B13: =cons_rev26 -> 192.141 | C13: =PL!D5 -> 189 | D13: =C13/B13-1 -> -0.01634737 | E13: =PL!D16 -> 189 | F13: =E13/B13-1 -> -0.01634737 | G13: =PL!D27 -> 189 | H13: =G13/B13-1 -> -0.01634737 | I13: minkabu 192.1；stockanalysis 189.7（區間 177.8–196.7）
A14: 淨利 vs 共識（minkabu） | B14: =cons_ni26 -> 32.556 | C14: =PL!D12 -> 30.8 | D14: =C14/B14-1 -> -0.05393783 | E14: =PL!D23 -> 30.8 | F14: =E14/B14-1 -> -0.05393783 | G14: =PL!D34 -> 30.8 | H14: =G14/B14-1 -> -0.05393783 | I14: minkabu 32.6
A15: EPS vs 共識（minkabu） | B15: =cons_eps26 -> 801.46 | C15: =PL!D13 -> 758.83675 | D15: =C15/B15-1 -> -0.053182002 | E15: =PL!D24 -> 758.83675 | F15: =E15/B15-1 -> -0.053182002 | G15: =PL!D35 -> 758.83675 | H15: =G15/B15-1 -> -0.053182002 | I15: minkabu 801.46 | J15: 共識高於公司指引 5.6%：市場預期再上修
A16: FY2027 EPS vs kabuyoho 12 個月後前瞻 EPS（2026-07-30；口徑不同，參考） | B16: =ks_12m -> 816.2 | C16: =PL!E13 -> 915.3532 | D16: =C16/B16-1 -> 0.1214815 | E16: =PL!E24 -> 843.37887 | F16: =E16/B16-1 -> 0.033299278 | G16: =PL!E35 -> 745.54283 | H16: =G16/B16-1 -> -0.086568445 | I16: kabuyoho 816.2 | J16: 早於 8-04 上修；12 個月後≈ FY2026 與 FY2027 混合
A17: FY2027 營收 vs 中期經營計畫目標（185.0） | B17: =mtp_rev -> 185 | C17: =PL!E5 -> 219.67028 | D17: =C17/B17-1 -> 0.18740691 | E17: =PL!E16 -> 205.62949 | F17: =E17/B17-1 -> 0.11151076 | G17: =PL!E27 -> 186.52024 | H17: =G17/B17-1 -> 0.0082175159 | I17: 公司 中期經營計畫（2025-05-09） | J17: 目標訂於 AI 需求加速前
A18: FY2027 營業利益 vs 中期經營計畫目標（45.0） | B18: =mtp_oi -> 45 | C18: =PL!E9 -> 53.075369 | D18: =C18/B18-1 -> 0.17945264 | E18: =PL!E20 -> 48.902047 | F18: =E18/B18-1 -> 0.086712149 | G18: =PL!E31 -> 43.229172 | H18: =G18/B18-1 -> -0.039351726 | I18: 同上
A19: C. 結構檢查
A20: FY2026 SPE 營收年增 vs 測試與其他封裝設備 CY2026 年增（百分點） | B20: =tstA_26/tstA_25-1 -> 0.26561159 | C20: =PL!D74/PL!C74-1 -> 0.15344313 | D20: =C20-B20 -> -0.11216846 | E20: =PL!D103/PL!C103-1 -> 0.15344313 | F20: =E20-B20 -> -0.11216846 | G20: =PL!D132/PL!C132-1 -> 0.15344313 | H20: =G20-B20 -> -0.11216846 | I20: markets/equipment（情境 A；2026 含口徑轉換） | J20: 公司指引 SPE +15.3%，低於市場 +26.6%：探針台產能滿載（受注約為產能 1.5 倍）
A21: FY2028 SPE 營收 ÷ FY2026（模型）vs 設備總額 CY2028 ÷ CY2026 | B21: =0 -> 0 | C21: =PL!F74/PL!D74-1-(tot_A_28/tot_A_26-1) -> 0.0073550879 | D21: =C21-B21 -> 0.0073550879 | E21: =PL!F103/PL!D103-1-(tot_B_28/tot_B_26-1) -> -0.14956202 | F21: =E21-B21 -> -0.14956202 | G21: =PL!F132/PL!D132-1-(tot_C_28/tot_C_26-1) -> -0.21684771 | H21: =G21-B21 -> -0.21684771 | I21: markets/equipment 設備總額（同字母） | J21: 差距欄＝模型 − 市場（百分點）。模型低於市場的原因：會計年度比日曆年晚一季、測試與封裝設備成長低於前段、超額成長與中國變數
A22: 參考：HPC 占 SPE 營收（FY2026 第一季，公司） | C22: =hpc -> 0.45 | J22: 邏輯 2／3、HBM 1／3；上游設備路徑已含 AI，未另行加計

Sheet Sens
A1: Sens — 一次動一個輸入（情境 A）：對 FY2027、FY2028 營收與 EPS 的影響。每個案例是一個完整推導區塊（本頁下方，與 PL 同一引擎）
A3: 案例 | B3: 設定 | C3: FY2027 營收 ¥B | D3: FY2027 EPS ¥ | E3: 相對基準 | F3: FY2028 營收 ¥B | G3: FY2028 EPS ¥ | H3: 相對基準 | I3: FY2026 EPS ¥ | J3: 相對基準
A4: 基準（情境 A） | B4: PL 區塊 A | C4: =PL!E76 -> 219.67028 | D4: =PL!E85 -> 915.3532 | E4: =D4/D$4-1 -> 0 | F4: =PL!F76 -> 251.40659 | G4: =PL!F85 -> 1077.2446 | H4: =G4/G$4-1 -> 0 | I4: =PL!D85 -> 758.83675 | J4: =I4/I$4-1 -> 0
A5: SPE 超額成長 +1%/年 | B5: exc_A 低 | C5: =E76 -> 216.25901 | D5: =E85 -> 897.65759 | E5: =D5/D$4-1 -> -0.019331995 | F5: =F76 -> 243.53129 | G5: =F85 -> 1036.3923 | H5: =G5/G$4-1 -> -0.037922988 | I5: =D85 -> 758.83675 | J5: =I5/I$4-1 -> 0
A6: SPE 超額成長 +5%/年 | B6: exc_A 高 | C6: =E116 -> 223.08155 | D6: =E125 -> 933.0488 | E6: =D6/D$4-1 -> 0.019331995 | F6: =F116 -> 259.43631 | G6: =F125 -> 1118.898 | H6: =G6/G$4-1 -> 0.038666576 | I6: =D125 -> 758.83675 | J6: =I6/I$4-1 -> 0
A7: 超額成長 0（與市場同步） | B7: exc＝0 | C7: =E156 -> 214.55338 | D7: =E165 -> 888.80979 | E7: =D7/D$4-1 -> -0.028997992 | F7: =F156 -> 239.65154 | G7: =F165 -> 1016.2665 | H7: =G7/G$4-1 -> -0.056605636 | I7: =D165 -> 758.83675 | J7: =I7/I$4-1 -> 0
A8: 中國 SPE −20%（情境 C 的值） | B8: chh＝chh_C | C8: =E196 -> 211.76467 | D8: =E205 -> 874.34364 | E8: =D8/D$4-1 -> -0.044801898 | F8: =F196 -> 232.97664 | G8: =F205 -> 981.64117 | H8: =G8/G$4-1 -> -0.088748157 | I8: =D205 -> 758.83675 | J8: =I8/I$4-1 -> 0
A9: 中國占比 40% | B9: chn 低（搭配 chh_C） | C9: =E236 -> 212.64307 | D9: =E245 -> 878.90025 | E9: =D9/D$4-1 -> -0.039823909 | F9: =F236 -> 235.02442 | G9: =F245 -> 992.26377 | H9: =G9/G$4-1 -> -0.078887251 | I9: =D245 -> 758.83675 | J9: =I9/I$4-1 -> 0
A10: 中國占比 50% | B10: chn 高（搭配 chh_C） | C10: =E276 -> 210.88626 | D10: =E285 -> 869.78702 | E10: =D10/D$4-1 -> -0.049779887 | F10: =F276 -> 230.92887 | G10: =F285 -> 971.01856 | H10: =G10/G$4-1 -> -0.098609063 | I10: =D285 -> 758.83675 | J10: =I10/I$4-1 -> 0
A11: 探針台占 SPE 70% | B11: w_pr 低 | C11: =E316 -> 219.62999 | D11: =E325 -> 915.14419 | E11: =D11/D$4-1 -> -0.00022833595 | F11: =F316 -> 251.27999 | G11: =F325 -> 1076.5879 | H11: =G11/G$4-1 -> -0.00060964518 | I11: =D325 -> 758.83675 | J11: =I11/I$4-1 -> 0
A12: 探針台占 SPE 74% | B12: w_pr 高 | C12: =E356 -> 219.71057 | D12: =E365 -> 915.56221 | E12: =D12/D$4-1 -> 0.00022833595 | F12: =F356 -> 251.53319 | G12: =F365 -> 1077.9014 | H12: =G12/G$4-1 -> 0.00060964518 | I12: =D365 -> 758.83675 | J12: =I12/I$4-1 -> 0
A13: 加工裝置前段比例 10% | B13: w_cmp 低 | C13: =E396 -> 219.37545 | D13: =E405 -> 913.8238 | E13: =D13/D$4-1 -> -0.0016708303 | F13: =F396 -> 251.13576 | G13: =F405 -> 1075.8397 | H13: =G13/G$4-1 -> -0.0013041762 | I13: =D405 -> 758.83675 | J13: =I13/I$4-1 -> 0
A14: 加工裝置前段比例 35% | B14: w_cmp 高 | C14: =E436 -> 220.11252 | D14: =E445 -> 917.6473 | E14: =D14/D$4-1 -> 0.0025062454 | F14: =F436 -> 251.81284 | G14: =F445 -> 1079.352 | H14: =G14/G$4-1 -> 0.0019562644 | I14: =D445 -> 758.83675 | J14: =I14/I$4-1 -> 0
A15: CY2030 設備市場 −10% | B15: g_tail 低 | C15: =E476 -> 219.67028 | D15: =E485 -> 915.3532 | E15: =D15/D$4-1 -> 0 | F15: =F476 -> 251.40659 | G15: =F485 -> 1077.2446 | H15: =G15/G$4-1 -> 0 | I15: =D485 -> 758.83675 | J15: =I15/I$4-1 -> 0
A16: CY2030 設備市場 +10% | B16: g_tail 高 | C16: =E516 -> 219.67028 | D16: =E525 -> 915.3532 | E16: =D16/D$4-1 -> 0 | F16: =F516 -> 251.40659 | G16: =F525 -> 1077.2446 | H16: =G16/G$4-1 -> 0 | I16: =D525 -> 758.83675 | J16: =I16/I$4-1 -> 0
A17: 計測年增 4% | B17: gmet_A 低 | C17: =E556 -> 218.84028 | D17: =E565 -> 911.90849 | E17: =D17/D$4-1 -> -0.0037632532 | F17: =F556 -> 249.66359 | G17: =F565 -> 1070.0108 | H17: =G17/G$4-1 -> -0.0067151713 | I17: =D565 -> 758.83675 | J17: =I17/I$4-1 -> 0
A18: 計測年增 8% | B18: gmet_A 高 | C18: =E596 -> 220.50028 | D18: =E605 -> 918.7979 | E18: =D18/D$4-1 -> 0.0037632532 | F18: =F596 -> 253.18279 | G18: =F605 -> 1084.6163 | H18: =G18/G$4-1 -> 0.0068430793 | I18: =D605 -> 758.83675 | J18: =I18/I$4-1 -> 0
A19: SPE 邊際利潤率只用 FY2021–25 | B19: v_s2 | C19: =E636 -> 219.67028 | D19: =E645 -> 884.73825 | E19: =D19/D$4-1 -> -0.033446049 | F19: =F636 -> 251.40659 | G19: =F645 -> 1015.0189 | H19: =G19/G$4-1 -> -0.057763782 | I19: =D645 -> 758.83675 | J19: =I19/I$4-1 -> 0
A20: 淨利÷營業利益 0.68 | B20: nioi 低 | C20: =E676 -> 219.67028 | D20: =E685 -> 889.20025 | E20: =D20/D$4-1 -> -0.028571429 | F20: =F676 -> 251.40659 | G20: =F685 -> 1046.4662 | H20: =G20/G$4-1 -> -0.028571429 | I20: =D685 -> 758.83675 | J20: =I20/I$4-1 -> 0
A21: 淨利÷營業利益 0.733（FY2025） | B21: nioi 高 | C21: =E716 -> 219.67028 | D21: =E725 -> 958.85617 | E21: =D21/D$4-1 -> 0.047525893 | F21: =F716 -> 251.40659 | G21: =F725 -> 1128.4417 | H21: =G21/G$4-1 -> 0.047525893 | I21: =D725 -> 758.83675 | J21: =I21/I$4-1 -> 0
A22: FY2026 實績低於指引 3% | B22: g_anc 低 | C22: =E756 -> 213.08017 | D22: =E765 -> 882.53641 | E22: =D22/D$4-1 -> -0.035851505 | F22: =F756 -> 243.86439 | G22: =F765 -> 1039.5711 | H22: =G22/G$4-1 -> -0.034972124 | I22: =D765 -> 730.71546 | J22: =I22/I$4-1 -> -0.037058427
A23: FY2026 實績高於指引 5% | B23: g_anc 高 | C23: =E796 -> 230.65379 | D23: =E805 -> 970.04785 | E23: =D23/D$4-1 -> 0.059752508 | F23: =F796 -> 263.97692 | G23: =F805 -> 1140.0339 | H23: =G23/G$4-1 -> 0.058286873 | I23: =D805 -> 805.70558 | J23: =I23/I$4-1 -> 0.061764044
A24: 情境 B | B24: 設備市場 B；超額 0；中國 −5%；計測 +4% | C24: =PL!E105 -> 205.62949 | D24: =PL!E114 -> 843.37887 | E24: =D24/D$4-1 -> -0.078630114 | F24: =PL!F105 -> 203.49955 | G24: =PL!F114 -> 830.53949 | H24: =G24/G$4-1 -> -0.22901497 | I24: =PL!D114 -> 758.83675 | J24: =I24/I$4-1 -> 0
A25: 情境 C | B25: 設備市場 C；超額 −3%；中國 −20%；計測 +1%；營益率 −1pt | C25: =PL!E134 -> 186.52024 | D25: =PL!E143 -> 745.54283 | E25: =D25/D$4-1 -> -0.18551349 | F25: =PL!F134 -> 154.88795 | G25: =PL!F143 -> 561.60748 | H25: =G25/G$4-1 -> -0.47866301 | I25: =PL!D143 -> 758.83675 | J25: =I25/I$4-1 -> 0
A27: 讀法：FY2026 錨定公司指引，只受 g_anc 影響；驅動參數從 FY2027 起作用。FY2026 SPE 營益率（m_spe26）只改變部門拆分，不改變合併營業利益與 EPS，故不列案例；g_tail 只影響 FY2029（CY2030 的 1/4）。
A60: 案例區塊：SPE 超額成長 +1%/年（情境 A）
A61: 項目 | B61: 單位 | C61: CY2025／FY2025 | D61: CY2026／FY2026 | E61: CY2027／FY2027 | F61: CY2028／FY2028 | G61: CY2029／FY2029 | H61: CY2030 | J61: 說明
A62: A. 設備市場（日曆年；markets/equipment 情境 A）
A63: 測試與其他封裝設備 | B63: US$B | C63: =tstA_25 -> 14.735959 | D63: =tstA_26 -> 18.65 | E63: =tstA_27 -> 21.634674 | F63: =tstA_28 -> 25.1 | G63: =tstA_29 -> 27.108 | H63: =G63*(1+g_tail) -> 27.108 | J63: CY2030＝CY2029 ×（1＋g_tail）
A64: 先進封裝設備〔AI〕 | B64: US$B | C64: =apkA_25 -> 3.0565693 | D64: =apkA_26 -> 3.35 | E64: =apkA_27 -> 3.7953919 | F64: =apkA_28 -> 4.3 | G64: =apkA_29 -> 4.644 | H64: =G64*(1+g_tail) -> 4.644
A65: 晶圓前段設備 | B65: US$B | C65: =wfeA_25 -> 116.89683 | D65: =wfeA_26 -> 156.15705 | E65: =wfeA_27 -> 192.79547 | F65: =wfeA_28 -> 216.62863 | G65: =wfeA_29 -> 228.90369 | H65: =G65*(1+g_tail) -> 228.90369
A66: B. 會計年度指數（FY(t)＝3/4 × CY(t)＋1/4 × CY(t+1)；FY2026＝1）
A67: 探針台需求指數（測試與其他封裝） | B67: x | C67: =(0.75*C63+0.25*D63)/(0.75*D63+0.25*E63) -> 0.81018418 | D67: =(0.75*D63+0.25*E63)/(0.75*D63+0.25*E63) -> 1 | E67: =(0.75*E63+0.25*F63)/(0.75*D63+0.25*E63) -> 1.1600748 | F67: =(0.75*F63+0.25*G63)/(0.75*D63+0.25*E63) -> 1.3199514 | G67: =(0.75*G63+0.25*H63)/(0.75*D63+0.25*E63) -> 1.3975956
A68: 加工裝置需求指數（前段 × w_cmp ＋ 先進封裝 ×（1 − w_cmp）） | B68: x | C68: =w_cmp*(0.75*C65+0.25*D65)/(0.75*D65+0.25*E65)+(1-w_cmp)*(0.75*C64+0.25*D64)/(0.75*D64+0.25*E64) -> 0.87669669 | D68: =w_cmp*(0.75*D65+0.25*E65)/(0.75*D65+0.25*E65)+(1-w_cmp)*(0.75*D64+0.25*E64)/(0.75*D64+0.25*E64) -> 1 | E68: =w_cmp*(0.75*E65+0.25*F65)/(0.75*D65+0.25*E65)+(1-w_cmp)*(0.75*E64+0.25*F64)/(0.75*D64+0.25*E64) -> 1.1468144 | F68: =w_cmp*(0.75*F65+0.25*G65)/(0.75*D65+0.25*E65)+(1-w_cmp)*(0.75*F64+0.25*G64)/(0.75*D64+0.25*E64) -> 1.2794989 | G68: =w_cmp*(0.75*G65+0.25*H65)/(0.75*D65+0.25*E65)+(1-w_cmp)*(0.75*G64+0.25*H64)/(0.75*D64+0.25*E64) -> 1.3502666
A69: 公司特有：超額成長係數（FY2027 起） | B69: x | D69: =(1+exc_A_lo)^0 -> 1 | E69: =(1+exc_A_lo)^1 -> 1.01 | F69: =(1+exc_A_lo)^2 -> 1.0201 | G69: =(1+exc_A_lo)^3 -> 1.030301
A70: 公司特有：中國係數（1 ＋ 中國占比 × 中國變化 × 生效比例） | B70: x | D70: =1 -> 1 | E70: =1+chn*chh_A*0.5 -> 1 | F70: =1+chn*chh_A -> 1 | G70: =1+chn*chh_A -> 1
A71: C. 營收（FY2025 實績；FY2026 公司指引 ×（1＋g_anc）；FY2027 起驅動推導）
A72: 探針台 | B72: ¥B | C72: =spe_25*w_pr -> 92.07216 | D72: =g26_spe*(1+g_anc)*w_pr -> 106.2 | E72: =$D72*E67*E69*E70 -> 124.43194 | F72: =$D72*F67*F69*F70 -> 142.99643 | G72: =$D72*G67*G69*G70 -> 152.92207 | J72: FY2025 依 FY2026 上半構成比拆分（Assumed）
A73: 加工裝置（切割、研削、CMP 等） | B73: ¥B | C73: =spe_25*(1-w_pr) -> 35.80584 | D73: =g26_spe*(1+g_anc)*(1-w_pr) -> 41.3 | E73: =$D73*E68*E69*E70 -> 47.837071 | F73: =$D73*F68*F69*F70 -> 53.905455 | G73: =$D73*G68*G69*G70 -> 57.455777
A74: 半導體製造裝置（SPE）營收 | B74: ¥B | C74: =C72+C73 -> 127.878 | D74: =D72+D73 -> 147.5 | E74: =E72+E73 -> 172.26901 | F74: =F72+F73 -> 196.90189 | G74: =G72+G73 -> 210.37785
...

Sheet Sources
A1: 來源（公司原文以網頁擷取工具讀取；表格錯位處以算術核對；版面與頁碼待人工複核）
A2: JPX：2026年3月期 決算短信（2026-05-13） | B2: https://www2.jpx.co.jp/disc/77290/081220260518539874_tse-acedjpsm-77290-20260518377290-ixbrl.htm
A3: JPX：2027年3月期 第1四半期 決算短信（2026-08-04；業績予想修正） | B3: https://www2.jpx.co.jp/disc/77290/081220260803507651_tse-qcedjpsm-77290-20260804377290-ixbrl.htm
A4: 公司：2026年3月期 決算補足資料（FS_2026_4q_J_rev） | B4: https://www.accretech.com/jp/ir/news/news-202605180003/main/0/link/FS_2026_4q_J_rev.pdf
A5: 公司：2026年度第1四半期 決算說明資料（2026-08-04） | B5: https://www.accretech.com/jp/ir/news/auto_20260804508092/main/0/link/BR_2027-3_1q_J_2.pdf
A6: 公司：2026年度第1四半期 Q&A（2026-08-04） | B6: https://www.accretech.com/jp/ir/news/news-202608041630/main/0/link/QA_2027-3_1q_J.pdf
A7: 公司：2025年度第1四半期 Q&A（2025-08-04） | B7: https://www.accretech.com/jp/ir/news/news3574518910588001242/main/0/link/QA_2026_1q_J.pdf
A8: 公司：中期經營計畫（2025-05-09；部門 FY2022/3–FY2025/3） | B8: https://www.accretech.com/en/ir/news/auto_20250509537325/pdfFile.pdf
A9: 公司：FY2024/3 決算說明資料（2024-05-10） | B9: https://www.accretech.com/en/ir/news/auto_20240509587976/pdfFile.pdf
A10: 公司：FY2023/3 決算說明資料（2023-05-11） | B10: https://www.accretech.com/en/ir/news/auto_20230511567918/main/0/link/BR_2023_4q_E_r.pdf
A11: 公司：FY2023/3 第三季說明資料（2023-02-06；部門 FY2019/3–FY2022/3） | B11: https://www.accretech.com/en/ir/news/auto_20230206501370/pdfFile.pdf
A12: 公司：FY2020/3 決算短信（英文，2020-05-11） | B12: https://www.accretech.com/en/ir/news/auto_20200510407802/main/0/link/FS_2020_4q_E_2.pdf
A13: 松井證券：決算情報（年度、季度） | B13: https://finance.matsui.co.jp/stock/7729/settlement/index
... A19: kabuyoho：目標株價、12 個月後前瞻 EPS（2026-07-30） | B19: https://kabuyoho.jp/reportTarget?bcode=7729
A20: 市場層：markets/equipment 成品（本 repo）；tools/cycle_position.py
A21: 未找到：探針台、切割機市占一手調查；切割／研削／CMP 個別金額；中國營收占比；共識 FY2027 EPS；FY2015–FY2017 部門資料
A22: 無法開啟（建置環境被擋或逾時）：finboard.jp、gyokaidigest、kabuyoho 共識頁、monex scouter（速率限制）
A23: SemiAnalysis | B23: 未使用
