Workbook

Sheet README
A1: 韓美半導體 Hanmi Semiconductor（042700.KS）收支與估值模型 v0.1（AI 半導體 Project 步驟 5：設備與材料） 2026-10-25
A2: v0.1（2026-10-25）：首版。樣板 advantest/（設備股，統一循環規則）。本版未做先驗，無 Andy 合理 P/E 對照。
A3: 模型命題：韓美的盈餘由 HBM 的 TC 鍵合需求決定——需求來自記憶體廠下一年的鍵合產能增量（HBM 位元 ÷ 晶粒容量 × 層數加權），韓美的份額集中在 SK 海力士與美光。股價取決於 HBM 位元成長在 2028 之後放緩、晶粒容量提高與混合鍵合導入時，TC 鍵合機的新機需求與韓美在 SK 海力士的份額能否守住。
A5: 會計年度＝日曆年。金額以億韓元（₩億）為主；EPS 為韓元。FY2026 為錨點：上半年實績（509＋2,511）＋下半年假設（h2f、m_h2）；第三季預定 2026-11 公布，建置日未納入。
A7: 驅動因子 → 推導量
A8: HBM 出貨位元（markets/memory，情境別）÷ 晶粒容量 → 核心晶粒數 × 層數加權 ×（1 − 混合鍵合占比）→ TC 鍵合產能需求；新機需求＝下一年產能增量＋汰換
A9: × 各記憶體廠占產能增量（t＋1 年 HBM 市占，讀三家記憶體模型）× 韓美在該廠份額 → 韓美可得需求 × 校準係數 k（FY2025–26 兩年營收）→ HBM TC 鍵合機營收；其他業務＝前一年 × 成長率
A10: 毛利率：FY2026 由錨點營業利益反推，之後沿用（C 扣價格競爭）；營業費用＝固定＋變動 × 營收；不寫死利益率
A11: 情境 A／B／C：HBM 位元讀 markets/memory（2028 ×1.0／0.8／0.6，2029 ×1.0／0.85／0.6）；混合鍵合 A 不納入、B 取 Disco 基準、C 取高值；C 另加韓華、ASMPT 搶份額與毛利率下調。Val：十年 P/E 分位，循環位置依設備股共用規則（見頂年 A 2029、B 2028、C 2027 → FY2027：A 中段、B 中段、C 見頂）；目標價＝三情境 0.3／0.5／0.2 加權
A13: 標記：Verified、Interested-party、Analogy、Assumed、Derived。SemiAnalysis 未使用。DART 原文未開啟，實績取自新聞稿報導與財務資料頁，原文待人工複核。
A14: 已知限制：(1) 公司不揭露產品別與 2025 客戶別營收，TC 鍵合機占比（60%）與中國比重（17%）取自 CGSI（賣方）；(2) 韓美在 SK 海力士、美光的份額為 Assumed，模型對它們最敏感；(3) 以 HBM 營收市占代替各廠產能增量占比（Analogy）；(4) 晶粒容量、層數、混合鍵合比例沿用 Disco 模型的 Assumed；(5) 鍵合機假設比產能早一年購入，實際交期可能更短，會讓模型的轉折早於實際；(6) 韓美自家混合鍵合機（2027 量產工廠）的營收不建模；(7) 十年 P/E 2016–2017 只有一個來源，companiesmarketcap 2021 年值與他源差異大。

Sheet In
A1: In — 輸入（藍字；基準欄 E，低 D、高 F）。金額：億韓元（₩億）；HBM 位元：EB；晶粒：百萬顆。每個輸入附兩個來源（來源2 找不到者寫「未找到」）
A2: 標記：Verified／Interested-party／Analogy／Assumed／Derived；Analogy、Assumed 給低／高區間，不當點估計（放情境或 Sens）。SemiAnalysis 未使用。公司（hanmisemi.com）不出具年度指引；DART 原文在建置環境無法開啟，實績取自 DART 轉載的財務資料頁（valueline、stockanalysis）與新聞稿報導，原文待人工複核
A3: 鍵 | B3: 項目 | C3: 單位 | D3: 低 | E3: 基準 | F3: 高 | G3: 標記 | H3: 來源1 | I3: 來源2／說明
A4: A. HBM 出貨位元（markets/memory，經 SK 海力士模型成品 Mkt 頁；情境 A／B／C 各一列；唯讀）
A5: hsA_25 | B5: HBM 出貨位元 2025（EB；A） | C5: EB | E5: 2.2251147 | G5: Derived | H5: skhynix/dist/20261025_SK海力士模型_v0.4.2.xlsx｜Mkt!C24:G24 | I5: markets/memory v0.4：出貨＝MIN(需求 × 情境顆數係數, 供給)；2028–29 隨情境，2025–27 三情境相同
A6: hsA_26 | B6: HBM 出貨位元 2026（EB；A） | C6: EB | E6: 3.782695 | G6: Derived | H6: skhynix/dist/20261025_SK海力士模型_v0.4.2.xlsx｜Mkt!C24:G24 | I6: 同上
A7: hsA_27 | B7: HBM 出貨位元 2027（EB；A） | C7: EB | E7: 5.8631772 | G7: Derived | H7: skhynix/dist/20261025_SK海力士模型_v0.4.2.xlsx｜Mkt!C24:G24 | I7: 同上
A8: hsA_28 | B8: HBM 出貨位元 2028（EB；A） | C8: EB | E8: 8.501607 | G8: Derived | H8: skhynix/dist/20261025_SK海力士模型_v0.4.2.xlsx｜Mkt!C24:G24 | I8: 同上
A9: hsA_29 | B9: HBM 出貨位元 2029（EB；A） | C9: EB | E9: 11.477169 | G9: Derived | H9: skhynix/dist/20261025_SK海力士模型_v0.4.2.xlsx｜Mkt!C24:G24 | I9: 同上
A10: hsB_25 | B10: HBM 出貨位元 2025（EB；B） | C10: EB | E10: 2.2251147 | G10: Derived | H10: skhynix/dist/20261025_SK海力士模型_v0.4.2.xlsx｜Mkt!C25:G25 | I10: markets/memory v0.4：出貨＝MIN(需求 × 情境顆數係數, 供給)；2028–29 隨情境，2025–27 三情境相同
A11: hsB_26 | B11: HBM 出貨位元 2026（EB；B） | C11: EB | E11: 3.782695 | G11: Derived | H11: skhynix/dist/20261025_SK海力士模型_v0.4.2.xlsx｜Mkt!C25:G25 | I11: 同上
A12: hsB_27 | B12: HBM 出貨位元 2027（EB；B） | C12: EB | E12: 5.8631772 | G12: Derived | H12: skhynix/dist/20261025_SK海力士模型_v0.4.2.xlsx｜Mkt!C25:G25 | I12: 同上
A13: hsB_28 | B13: HBM 出貨位元 2028（EB；B） | C13: EB | E13: 8.22296 | G13: Derived | H13: skhynix/dist/20261025_SK海力士模型_v0.4.2.xlsx｜Mkt!C25:G25 | I13: 同上
A14: hsB_29 | B14: HBM 出貨位元 2029（EB；B） | C14: EB | E14: 11.357964 | G14: Derived | H14: skhynix/dist/20261025_SK海力士模型_v0.4.2.xlsx｜Mkt!C25:G25 | I14: 同上
A15: hsC_25 | B15: HBM 出貨位元 2025（EB；C） | C15: EB | E15: 2.2251147 | G15: Derived | H15: skhynix/dist/20261025_SK海力士模型_v0.4.2.xlsx｜Mkt!C26:G26 | I15: markets/memory v0.4：出貨＝MIN(需求 × 情境顆數係數, 供給)；2028–29 隨情境，2025–27 三情境相同
A16: hsC_26 | B16: HBM 出貨位元 2026（EB；C） | C16: EB | E16: 3.782695 | G16: Derived | H16: skhynix/dist/20261025_SK海力士模型_v0.4.2.xlsx｜Mkt!C26:G26 | I16: 同上
... A19: hsC_29 | B19: HBM 出貨位元 2029（EB；C） | C19: EB | E19: 8.017386 | G19: Derived | H19: skhynix/dist/20261025_SK海力士模型_v0.4.2.xlsx｜Mkt!C26:G26 | I19: 同上
A20: g_tail | B20: CY2030 HBM 出貨位元相對 2029 的年增（市場層只到 2029；只用於 CY2029 的鍵合機購買） | C20: % | D20: 0 | E20: 0.1 | F20: 0.2 | G20: Assumed | H20: 無：市場層只到 2029；鍵合機在產能需要前一年購入，CY2029 的購買要看 CY2030 | I20: 與 Disco 模型的 g_tail 同值（Assumed）
A21: B. 晶粒、堆疊層數與混合鍵合（與 Disco 模型同一組假設，讀其成品；唯讀）
A22: den_25 | B22: DRAM 核心晶粒容量（組合平均）2025 | C22: Gb／顆 | D22: 22 | E22: 24 | F22: 24 | G22: Assumed | H22: disco/dist/20261025_Disco模型_v0.1.4.xlsx｜In!D37:F37 | I22: JEDEC HBM4：24Gb 或 32Gb 晶粒；容量愈大，同樣位元需要的晶粒（＝TC 鍵合次數）愈少
A23: den_26 | B23: DRAM 核心晶粒容量（組合平均）2026 | C23: Gb／顆 | D23: 24 | E23: 24 | F23: 26 | G23: Assumed | H23: disco/dist/20261025_Disco模型_v0.1.4.xlsx｜In!D38:F38 | I23: 同上
A24: den_27 | B24: DRAM 核心晶粒容量（組合平均）2027 | C24: Gb／顆 | D24: 24 | E24: 26 | F24: 28 | G24: Assumed | H24: disco/dist/20261025_Disco模型_v0.1.4.xlsx｜In!D39:F39 | I24: 同上
A25: den_28 | B25: DRAM 核心晶粒容量（組合平均）2028 | C25: Gb／顆 | D25: 24 | E25: 28 | F25: 32 | G25: Assumed | H25: disco/dist/20261025_Disco模型_v0.1.4.xlsx｜In!D40:F40 | I25: 同上
A26: den_29 | B26: DRAM 核心晶粒容量（組合平均）2029 | C26: Gb／顆 | D26: 26 | E26: 30 | F26: 32 | G26: Assumed | H26: disco/dist/20261025_Disco模型_v0.1.4.xlsx｜In!D41:F41 | I26: 同上
A27: den_30 | B27: DRAM 核心晶粒容量（組合平均）2030 | C27: Gb／顆 | D27: 28 | E27: 32 | F27: 32 | G27: Assumed | H27: disco/dist/20261025_Disco模型_v0.1.4.xlsx｜In!D42:F42 | I27: 同上
A28: stk_25 | B28: HBM 平均堆疊層數 2025 | C28: 層 | D28: 8 | E28: 10 | F28: 12 | G28: Assumed | H28: disco/dist/20261025_Disco模型_v0.1.4.xlsx｜In!D43:F43 | I28: 層數愈高，每顆晶粒的鍵合精度要求與時間愈高（見 beta）
A29: stk_26 | B29: HBM 平均堆疊層數 2026 | C29: 層 | D29: 10 | E29: 12 | F29: 12 | G29: Assumed | H29: disco/dist/20261025_Disco模型_v0.1.4.xlsx｜In!D44:F44 | I29: 同上
A30: stk_27 | B30: HBM 平均堆疊層數 2027 | C30: 層 | D30: 12 | E30: 12.5 | F30: 14 | G30: Assumed | H30: disco/dist/20261025_Disco模型_v0.1.4.xlsx｜In!D45:F45 | I30: 同上
A31: stk_28 | B31: HBM 平均堆疊層數 2028 | C31: 層 | D31: 12 | E31: 14 | F31: 16 | G31: Assumed | H31: disco/dist/20261025_Disco模型_v0.1.4.xlsx｜In!D46:F46 | I31: 同上
A32: stk_29 | B32: HBM 平均堆疊層數 2029 | C32: 層 | D32: 12 | E32: 15 | F32: 16 | G32: Assumed | H32: disco/dist/20261025_Disco模型_v0.1.4.xlsx｜In!D47:F47 | I32: 同上
A33: stk_30 | B33: HBM 平均堆疊層數 2030 | C33: 層 | D33: 14 | E33: 16 | F33: 16 | G33: Assumed | H33: disco/dist/20261025_Disco模型_v0.1.4.xlsx｜In!D48:F48 | I33: 同上
... A41: dlt | B41: 已裝機鍵合產能每年汰換／升級比例（新機需求＝產能增量＋汰換） | C41: %/年 | D41: 0.05 | E41: 0.1 | F41: 0.15 | G41: Assumed | H41: 無：公司不揭露裝機量與機齡；HBM3E→HBM4→HBM4E 換代需新機（TC BONDER 4、4.5） | I41: 與 Disco 模型的 dlt 同值（Assumed）
A42: C. 三家記憶體廠的 HBM 營收市占（讀 SK 海力士、三星、美光模型成品 In 頁；以營收市占代替產能增量占比，Analogy）
A43: ms_sk_25 | B43: SK 海力士 HBM 營收市占 2025 | C43: % | E43: 0.58 | G43: Interested-party | H43: skhynix/dist/20261025_SK海力士模型_v0.4.2.xlsx｜In!D26:F26 | I43: 各記憶體模型的 HBM 市占（賣方與公司說法）；本模型以 t＋1 年的市占（三家正規化）當 t 年鍵合產能增量的分配（Analogy：營收市占≈位元市占≈產能增量占比）
A44: ms_sk_26 | B44: SK 海力士 HBM 營收市占 2026 | C44: % | E44: 0.52 | G44: Interested-party | H44: skhynix/dist/20261025_SK海力士模型_v0.4.2.xlsx｜In!D27:F27 | I44: 同上
A45: ms_sk_27 | B45: SK 海力士 HBM 營收市占 2027 | C45: % | E45: 0.42 | G45: Interested-party | H45: skhynix/dist/20261025_SK海力士模型_v0.4.2.xlsx｜In!D28:F28 | I45: 同上
A46: ms_sk_28 | B46: SK 海力士 HBM 營收市占 2028 | C46: % | E46: 0.4 | G46: Interested-party | H46: skhynix/dist/20261025_SK海力士模型_v0.4.2.xlsx｜In!D29:F29 | I46: 同上
A47: ms_sk_29 | B47: SK 海力士 HBM 營收市占 2029 | C47: % | E47: 0.4 | G47: Interested-party | H47: skhynix/dist/20261025_SK海力士模型_v0.4.2.xlsx｜In!D47:F47 | I47: 同上
A48: ms_ss_25 | B48: 三星 HBM 營收市占 2025 | C48: % | E48: 0.17 | G48: Interested-party | H48: samsung/dist/20261025_三星電子模型_v0.2.2.xlsx｜In!D29:F29 | I48: 各記憶體模型的 HBM 市占（賣方與公司說法）；本模型以 t＋1 年的市占（三家正規化）當 t 年鍵合產能增量的分配（Analogy：營收市占≈位元市占≈產能增量占比）
A49: ms_ss_26 | B49: 三星 HBM 營收市占 2026 | C49: % | E49: 0.29 | G49: Interested-party | H49: samsung/dist/20261025_三星電子模型_v0.2.2.xlsx｜In!D30:F30 | I49: 同上
...

Sheet Q
A1: Q — 實績（億韓元；EPS 為韓元）。會計年度＝日曆年。藍字＝輸入；黑字＝公式（Derived）。公司只公布初步營收與營業利益（DART 公平揭露）；淨利與 EPS 取自財務資料頁的近 12 月數字
A2: FY2026 第三季（2026-07～09）：建置日 2026-10-25 尚未公布（去年第三季於 2025-10-31 公布；mydailybyte 列 2026-11-06，stockanalysis 估 2026-11-13）。公布後更新本頁 J 欄與 In 頁 h2f、m_h2
A3: 項目 | B3: FY2024 | C3: 25Q1 | D3: 25Q2 | E3: 25Q3 | F3: 25Q4 | G3: FY2025 | H3: 26Q1 | I3: 26Q2 | J3: 26Q3（未公布） | K3: 標記 | L3: 來源1 | M3: 來源2／說明
A4: 營收 | B4: 5589 | C4: =G4-D4-E4-F4 -> 1475 | D4: 1800 | E4: 1662 | F4: 830 | G4: 5767 | H4: 509 | I4: 2511 | J4: 未公布 | K4: Verified（25Q1 Derived） | L4: 公司初步實績（DART）：FY2025 5,767（亞洲經濟 2026-02-09）；25Q2 1,800（dealsite 2025-07-25）；26Q1 509（−65.5%）、26Q2 2,511（+39.5%；ddaily 2026-07-14） | M4: etfshopping 各季（DART 初步）：25Q3 1,662、25Q4 830、26Q2 2,512；butler.works：FY2024 5,589、FY2025 5,767；25Q1＝全年 − 其他三季（＝上半年 3,274 − 1,800）
A5: 毛利 | B5: 3143 | G5: 3320.6 | K5: Verified | L5: valueline（DART 轉載）FY2025：營收 5,766.8、銷貨成本 2,446.1、毛利 3,320.6 | M5: stockanalysis：FY2025 毛利 3,319.4、FY2024 3,143.0（季度毛利未找到）
A6: 營業利益 | B6: 2554 | C6: =G6-D6-E6-F6 -> 696.9 | D6: 863 | E6: 678 | F6: 276 | G6: 2513.9 | H6: 85 | I6: 1303 | J6: 未公布 | K6: Verified（25Q1 Derived） | L6: 公司初步實績：FY2025 營益率 43.6%；26Q1 85（−87.9%）、26Q2 1,303（+51.0%，營益率 51.9%） | M6: valueline FY2025 2,513.9；stockanalysis 2,511.8；etfshopping 各季；25Q1＝上半年 1,559 − 863
A7: 營業利益率 | B7: =B6/B4 -> 0.45696905 | C7: =C6/C4 -> 0.47247458 | D7: =D6/D4 -> 0.47944444 | E7: =E6/E4 -> 0.40794224 | F7: =F6/F4 -> 0.33253012 | G7: =G6/G4 -> 0.43591122 | H7: =H6/H4 -> 0.16699411 | I7: =I6/I4 -> 0.51891677 | K7: Derived | L7: — | M7: 公司：FY2025 43.6%、26Q2 51.9%
A8: 營業費用（毛利 − 營業利益） | B8: =B5-B6 -> 589 | G8: =G5-G6 -> 806.7 | K8: Derived | L8: — | M8: valueline FY2025 銷管費 806.7
A9: 淨利（歸屬母公司） | B9: 1526 | G9: 2140 | H9: 190 | K9: Verified | L9: valueline（近 12 月表）FY2025 2,140.0；26Q1 190（etfshopping） | M9: butler.works：FY2024 1,526、FY2025 2,140；stockanalysis FY2025 2,140.1；25 各季、26Q2 單季未找到（近 12 月 2026-06 為 2,220.3）
A10: EPS（韓元） | B10: 1584 | G10: 2231.7 | K10: Verified（來源不一致） | L10: valueline FY2025 2,231.7（DART 轉載） | M10: stockanalysis 2,248、etfshopping 2,256（差 0.7–1.1%，口徑未解：基本／稀釋或加權股數）；FY2024 stockanalysis 1,584、etfshopping 1,589
A11: 檢查：四季合計 − 全年（營收、營業利益；B、C 欄） | B11: =SUM(C4:F4)-G4 -> 0 | C11: =SUM(C6:F6)-G6 -> 0 | K11: — | L11: — | M11: —
A13: 客戶別營收（事業報告）
A14: 客戶 | B14: FY2024 | C14: 占營收 | G14: FY2025 | K14: 標記 | L14: 來源1 | M14: 來源2／說明
A15: SK 海力士 | B15: 2996 | C15: =B15/B4 -> 0.53605296 | G15: LS 證券估：TC 鍵合機營收的 40%（Interested-party） | K15: Verified | L15: 公司 2024 事業報告（newdaily 2025-04-02 報導）
A16: 美光 | B16: 1111 | C16: =B16/B4 -> 0.19878332 | G16: 未找到 | K16: Verified | L16: 公司 2024 事業報告（newdaily 2025-04-02 報導）
A17: 其他（中國、OSAT 等） | B17: =B4-B15-B16 -> 1482 | C17: =B17/B4 -> 0.26516371 | G17: CGSI 估中國 ₩589 億（Interested-party） | K17: Derived | L17: 營收 − 上兩列

Sheet Units
A1: Units — HBM 位元 → 核心晶粒 → TC 鍵合產能需求 → 新機需求 → 韓美可得需求（日曆年；三情境，引用 PL 區塊）
A3: 項目 | B3: 單位 | C3: 2025 | D3: 2026 | E3: 2027 | F3: 2028 | G3: 2029 | H3: 2030 | I3: 說明
A4: 情境 A
A5: HBM 出貨位元 | B5: EB | C5: =PL!C43 -> 2.2251147 | D5: =PL!D43 -> 3.782695 | E5: =PL!E43 -> 5.8631772 | F5: =PL!F43 -> 8.501607 | G5: =PL!G43 -> 11.477169 | H5: =PL!H43 -> 12.624886
A6: 核心晶粒數 | B6: 百萬顆 | C6: =PL!C45 -> 741.7049 | D6: =PL!D45 -> 1260.8983 | E6: =PL!E45 -> 1804.0545 | F6: =PL!F45 -> 2429.0306 | G6: =PL!G45 -> 3060.5785 | H6: =PL!H45 -> 3156.2216
A7: TC 鍵合產能需求 | B7: 百萬顆當量 | C7: =PL!C49 -> 741.7049 | D7: =PL!D49 -> 1323.9433 | E7: =PL!E49 -> 1916.8079 | F7: =PL!F49 -> 2671.9336 | G7: =PL!G49 -> 3443.1508 | H7: =PL!H49 -> 3629.6548
A8: 新機需求 | B8: 百萬顆當量 | C8: =PL!C50 -> 656.40884 | D8: =PL!D50 -> 725.25902 | E8: =PL!E50 -> 946.80648 | F8: =PL!F50 -> 1038.4106 | G8: =PL!G50 -> 530.81909
A9: 韓美加權份額 | B9: % | C9: =PL!C54 -> 0.412 | D9: =PL!D54 -> 0.339 | E9: =PL!E54 -> 0.33 | F9: =PL!F54 -> 0.33 | G9: =PL!G54 -> 0.33
A10: 韓美可得新機需求 | B10: 百萬顆當量 | C10: =PL!C55 -> 270.44044 | D10: =PL!D55 -> 245.86281 | E10: =PL!E55 -> 312.44614 | F10: =PL!F55 -> 342.67549 | G10: =PL!G55 -> 175.1703
A11: 三大廠 HBM TC 鍵合機市場 | B11: ₩億 | C11: =PL!C69 -> 9004.3989 | D11: =PL!D69 -> 9948.8629 | E11: =PL!E69 -> 12987.978 | F11: =PL!F69 -> 14244.572 | G11: =PL!G69 -> 7281.6004
A13: 情境 B
A14: HBM 出貨位元 | B14: EB | C14: =PL!C76 -> 2.2251147 | D14: =PL!D76 -> 3.782695 | E14: =PL!E76 -> 5.8631772 | F14: =PL!F76 -> 8.22296 | G14: =PL!G76 -> 11.357964 | H14: =PL!H76 -> 12.49376
A15: 核心晶粒數 | B15: 百萬顆 | C15: =PL!C78 -> 741.7049 | D15: =PL!D78 -> 1260.8983 | E15: =PL!E78 -> 1804.0545 | F15: =PL!F78 -> 2349.4171 | G15: =PL!G78 -> 3028.7903 | H15: =PL!H78 -> 3123.44
A16: TC 鍵合產能需求 | B16: 百萬顆當量 | C16: =PL!C82 -> 741.7049 | D16: =PL!D82 -> 1323.9433 | E16: =PL!E82 -> 1916.8079 | F16: =PL!F82 -> 2455.1409 | G16: =PL!G82 -> 2896.2807 | H16: =PL!H82 -> 2693.967
A17: 新機需求 | B17: 百萬顆當量 | C17: =PL!C83 -> 656.40884 | D17: =PL!D83 -> 725.25902 | E17: =PL!E83 -> 730.01376 | F17: =PL!F83 -> 686.65387 | G17: =PL!G83 -> 289.62807
A18: 韓美加權份額 | B18: % | C18: =PL!C87 -> 0.412 | D18: =PL!D87 -> 0.329 | E18: =PL!E87 -> 0.32 | F18: =PL!F87 -> 0.32 | G18: =PL!G87 -> 0.32
A19: 韓美可得新機需求 | B19: 百萬顆當量 | C19: =PL!C88 -> 270.44044 | D19: =PL!D88 -> 238.61022 | E19: =PL!E88 -> 233.6044 | F19: =PL!F88 -> 219.72924 | G19: =PL!G88 -> 92.680982
A20: 三大廠 HBM TC 鍵合機市場 | B20: ₩億 | C20: =PL!C102 -> 9132.6872 | D20: =PL!D102 -> 10090.607 | E20: =PL!E102 -> 10156.76 | F20: =PL!F102 -> 9553.4896 | G20: =PL!G102 -> 4029.6267
A22: 情境 C
A23: HBM 出貨位元 | B23: EB | C23: =PL!C109 -> 2.2251147 | D23: =PL!D109 -> 3.782695 | E23: =PL!E109 -> 5.8631772 | F23: =PL!F109 -> 6.16722 | G23: =PL!G109 -> 8.017386 | H23: =PL!H109 -> 8.8191246
A24: 核心晶粒數 | B24: 百萬顆 | C24: =PL!C111 -> 741.7049 | D24: =PL!D111 -> 1260.8983 | E24: =PL!E111 -> 1804.0545 | F24: =PL!F111 -> 1762.0629 | G24: =PL!G111 -> 2137.9696 | H24: =PL!H111 -> 2204.7811
A25: TC 鍵合產能需求 | B25: 百萬顆當量 | C25: =PL!C115 -> 741.7049 | D25: =PL!D115 -> 1323.9433 | E25: =PL!E115 -> 1820.9675 | F25: =PL!F115 -> 1647.5288 | G25: =PL!G115 -> 1683.6511 | H25: =PL!H115 -> 1521.299
A26: 新機需求 | B26: 百萬顆當量 | C26: =PL!C116 -> 656.40884 | D26: =PL!D116 -> 629.41862 | E26: =PL!E116 -> 182.09675 | F26: =PL!F116 -> 200.87517 | G26: =PL!G116 -> 168.36511
A27: 韓美加權份額 | B27: % | C27: =PL!C120 -> 0.412 | D27: =PL!D120 -> 0.257 | E27: =PL!E120 -> 0.25 | F27: =PL!F120 -> 0.25 | G27: =PL!G120 -> 0.25
A28: 韓美可得新機需求 | B28: 百萬顆當量 | C28: =PL!C121 -> 270.44044 | D28: =PL!D121 -> 161.76059 | E28: =PL!E121 -> 45.524189 | F28: =PL!F121 -> 50.218791 | G28: =PL!G121 -> 42.091276
A29: 三大廠 HBM TC 鍵合機市場 | B29: ₩億 | C29: =PL!C135 -> 10756.57 | D29: =PL!D135 -> 10314.281 | E29: =PL!E135 -> 2984.019 | F29: =PL!F135 -> 3291.7407 | G29: =PL!G135 -> 2758.9985
A31: 台數換算（顯示用；單價為 Interested-party，只影響台數，不影響營收）
A32: 情境 A：三大廠 TC 鍵合機台數＝市場 ÷ 單價 | B32: 台 | C32: =C11/asp -> 300.14663 | D32: =D11/asp -> 331.62876 | E32: =E11/asp -> 432.93259 | F32: =F11/asp -> 474.81907 | G32: =G11/asp -> 242.72001
A33: 情境 B：三大廠 TC 鍵合機台數＝市場 ÷ 單價 | B33: 台 | C33: =C20/asp -> 304.42291 | D33: =D20/asp -> 336.35357 | E33: =E20/asp -> 338.55868 | F33: =F20/asp -> 318.44965 | G33: =G20/asp -> 134.32089
A34: 情境 C：三大廠 TC 鍵合機台數＝市場 ÷ 單價 | B34: 台 | C34: =C29/asp -> 358.55232 | D34: =D29/asp -> 343.80937 | E34: =E29/asp -> 99.467299 | F34: =F29/asp -> 109.72469 | G34: =G29/asp -> 91.966616
I35: 對照：SK 海力士 2026-03 預計下約 100 台 HBM4 鍵合機（TrendForce 引 The Elec）

Sheet PL
A1: PL — 韓美半導體損益（₩億；FY2025 實績，FY2026 錨點＝上半年實績＋下半年假設，FY2027–FY2029 為模型）。三情境各一個完整推導區塊（見下方），本頁頂端為摘要
A3: 情境／項目 | B3: 單位 | C3: FY2025A | D3: FY2026（錨點） | E3: FY2027 | F3: FY2028 | G3: FY2029 | H3: 說明
A4: 情境 A
A5: 營收 | B5: ₩億 | C5: =C60 -> 5767 | D5: =D60 -> 7539.8 | E5: =E60 -> 8014.8364 | F5: =F60 -> 8876.969 | G5: =G60 -> 7080.3396 | H5: FY2026 為錨點（上半年實績＋下半年 h2f、m_h2），三情境相同；情境差異從 FY2027 起
A6: HBM TC 鍵合機 | B6: ₩億 | C6: =C58 -> 2871.966 | D6: =D58 -> 4210.5109 | E6: =E58 -> 4286.0326 | F6: =F58 -> 4700.7088 | G6: =G58 -> 2402.9281
A7: 其他業務 | B7: ₩億 | C7: =C57 -> 2895.034 | D7: =D57 -> 3329.2891 | E7: =E57 -> 3728.8038 | F7: =F57 -> 4176.2602 | G7: =G57 -> 4677.4115
A8: 毛利率 | B8: % | C8: =C63 -> 0.57579331 | D8: =D63 -> 0.59526718 | E8: =E63 -> 0.59526718 | F8: =F63 -> 0.59526718 | G8: =G63 -> 0.59526718
A9: 營業利益 | B9: ₩億 | C9: =C65 -> 2513.9 | D9: =D65 -> 3557.504 | E9: =E65 -> 3807.053 | F9: =F65 -> 4259.9538 | G9: =G65 -> 3316.1374
A10: 營業利益率 | B10: % | C10: =C66 -> 0.43591122 | D10: =D66 -> 0.47183002 | E10: =E66 -> 0.47500072 | F10: =F66 -> 0.47988833 | G10: =G66 -> 0.46835853
A11: 淨利 | B11: ₩億 | C11: =C67 -> 2140 | D11: =D67 -> 3028.3856 | E11: =E67 -> 3240.8184 | F11: =F67 -> 3626.3579 | G11: =G67 -> 2822.9182
A12: EPS | B12: ₩ | C12: =C68 -> 2231.7 | D12: =D68 -> 3158.1533 | E12: =E68 -> 3379.689 | F12: =F68 -> 3781.7491 | G12: =G68 -> 2943.8816
A14: 情境 B
A15: 營收 | B15: ₩億 | C15: =C93 -> 5767 | D15: =D93 -> 7539.8 | E15: =E93 -> 6845.7956 | F15: =F93 -> 6940.3995 | G15: =G93 -> 5483.426
A16: HBM TC 鍵合機 | B16: ₩億 | C16: =C91 -> 2871.966 | D16: =D91 -> 4210.5109 | E16: =E91 -> 3250.1633 | F16: =F91 -> 3057.1167 | G16: =G91 -> 1289.4805
A17: 其他業務 | B17: ₩億 | C17: =C90 -> 2895.034 | D17: =D90 -> 3329.2891 | E17: =E90 -> 3595.6322 | F17: =F90 -> 3883.2828 | G17: =G90 -> 4193.9454
A18: 毛利率 | B18: % | C18: =C96 -> 0.57579331 | D18: =D96 -> 0.59526718 | E18: =E96 -> 0.59526718 | F18: =F96 -> 0.59526718 | G18: =G96 -> 0.59526718
A19: 營業利益 | B19: ₩億 | C19: =C98 -> 2513.9 | D19: =D98 -> 3557.504 | E19: =E98 -> 3192.9253 | F19: =F98 -> 3242.6232 | G19: =G98 -> 2477.237
A20: 營業利益率 | B20: % | C20: =C99 -> 0.43591122 | D20: =D99 -> 0.47183002 | E20: =E99 -> 0.46640676 | F20: =F99 -> 0.46720988 | G20: =G99 -> 0.45176811
A21: 淨利 | B21: ₩億 | C21: =C100 -> 2140 | D21: =D100 -> 3028.3856 | E21: =E100 -> 2718.0318 | F21: =F100 -> 2760.338 | G21: =G100 -> 2108.79
A22: EPS | B22: ₩ | C22: =C101 -> 2231.7 | D22: =D101 -> 3158.1533 | E22: =E101 -> 2834.5008 | F22: =F101 -> 2878.6198 | G22: =G101 -> 2199.1526
A24: 情境 C
A25: 營收 | B25: ₩億 | C25: =C126 -> 5767 | D25: =D126 -> 7539.8 | E25: =E126 -> 3908.8294 | F25: =F126 -> 3827.6186 | G25: =G126 -> 3544.1989
A26: HBM TC 鍵合機 | B26: ₩億 | C26: =C124 -> 2871.966 | D26: =D124 -> 4210.5109 | E26: =E124 -> 746.00474 | F26: =F124 -> 822.93518 | G26: =G124 -> 689.74962
A27: 其他業務 | B27: ₩億 | C27: =C123 -> 2895.034 | D27: =D123 -> 3329.2891 | E27: =E123 -> 3162.8246 | F27: =F123 -> 3004.6834 | G27: =G123 -> 2854.4492
A28: 毛利率 | B28: % | C28: =C129 -> 0.57579331 | D28: =D129 -> 0.59526718 | E28: =E129 -> 0.59526718 | F28: =F129 -> 0.56526718 | G28: =G129 -> 0.54526718
A29: 營業利益 | B29: ₩億 | C29: =C131 -> 2513.9 | D29: =D131 -> 3557.504 | E29: =E131 -> 1650.0602 | F29: =F131 -> 1492.5695 | G29: =G131 -> 1281.3003
A30: 營業利益率 | B30: % | C30: =C132 -> 0.43591122 | D30: =D132 -> 0.47183002 | E30: =E132 -> 0.42213667 | F30: =F132 -> 0.3899473 | G30: =G132 -> 0.36152045
A31: 淨利 | B31: ₩億 | C31: =C133 -> 2140 | D31: =D133 -> 3028.3856 | E31: =E133 -> 1404.6418 | F31: =F133 -> 1270.5751 | G31: =G133 -> 1090.7286
A32: EPS | B32: ₩ | C32: =C134 -> 2231.7 | D32: =D134 -> 3158.1533 | E32: =E134 -> 1464.8313 | F32: =F134 -> 1325.0199 | G32: =G134 -> 1137.4669
A34: 核對：FY2026 三情境相同（營收、EPS 差額合計，應為 0） | C34: =ABS(D5-D15)+ABS(D5-D25)+ABS(D12-D32) -> 0
A40: 情境 A：基準顆數；不納入混合鍵合
A41: 項目 | B41: 單位 | C41: 2025 | D41: 2026 | E41: 2027 | F41: 2028 | G41: 2029 | H41: 2030 | I41: 說明
A42: A. 日曆年鍵合產能需求（本公司會計年度＝日曆年）
A43: HBM 出貨位元 | B43: EB | C43: =hsA_25 -> 2.2251147 | D43: =hsA_26 -> 3.782695 | E43: =hsA_27 -> 5.8631772 | F43: =hsA_28 -> 8.501607 | G43: =hsA_29 -> 11.477169 | H43: =G43*(1+g_tail) -> 12.624886 | I43: markets/memory；2030＝2029 ×（1＋g_tail）
A44: DRAM 晶粒容量 | B44: Gb | C44: =den_25 -> 24 | D44: =den_26 -> 24 | E44: =den_27 -> 26 | F44: =den_28 -> 28 | G44: =den_29 -> 30 | H44: =den_30 -> 32
A45: 核心晶粒數＝位元 × 8000 ÷ 容量 | B45: 百萬顆 | C45: =C43*8000/C44 -> 741.7049 | D45: =D43*8000/D44 -> 1260.8983 | E45: =E43*8000/E44 -> 1804.0545 | F45: =F43*8000/F44 -> 2429.0306 | G45: =G43*8000/G44 -> 3060.5785 | H45: =H43*8000/H44 -> 3156.2216 | I45: 1 EB＝8×10⁹ Gb；每顆核心晶粒鍵合一次
A46: 平均堆疊層數 | B46: 層 | C46: =stk_25 -> 10 | D46: =stk_26 -> 12 | E46: =stk_27 -> 12.5 | F46: =stk_28 -> 14 | G46: =stk_29 -> 15 | H46: =stk_30 -> 16
A47: 層數加權（每顆晶粒鍵合時間） | B47: x | C47: =1+beta*(C46-$C46)/4 -> 1 | D47: =1+beta*(D46-$C46)/4 -> 1.05 | E47: =1+beta*(E46-$C46)/4 -> 1.0625 | F47: =1+beta*(F46-$C46)/4 -> 1.1 | G47: =1+beta*(G46-$C46)/4 -> 1.125 | H47: =1+beta*(H46-$C46)/4 -> 1.15
A48: 混合鍵合占比 | B48: % | C48: =0 -> 0 | D48: =0 -> 0 | E48: =0 -> 0 | F48: =0 -> 0 | G48: =0 -> 0 | H48: =0 -> 0 | I48: 情境 A 不納入
A49: TC 鍵合產能需求（晶粒 × 層數加權 ×（1 − 混合鍵合）） | B49: 百萬顆當量 | C49: =C45*C47*(1-C48) -> 741.7049 | D49: =D45*D47*(1-D48) -> 1323.9433 | E49: =E45*E47*(1-E48) -> 1916.8079 | F49: =F45*F47*(1-F48) -> 2671.9336 | G49: =G45*G47*(1-G48) -> 3443.1508 | H49: =H45*H47*(1-H48) -> 3629.6548
...

Sheet Val
A1: Val — P/E 估值。跨公司規則：合理倍數＝10 年（2016–2025 年底）P/E 的分位，依循環位置：見頂年 25 分位、中段中位數、谷底 75 分位。循環位置依設備股共用規則（第 4 節）。本版未做先驗，無 Andy 合理 P/E 對照
A2: P/E 定義：日曆年底收盤價 ÷ 當年 EPS（本公司會計年度＝日曆年）。兩個來源各自取分位再平均（tools/valuation_rule.py 的多來源慣例）
A4: 0. 目標價與上檔空間
A5: 項目 | B5: 數值 | E5: 說明
A6: 目標價（12 個月，情境加權） | B6: =tp_wA*B8+tp_wB*B9+tp_wC*B10 -> 57464.43 | E6: 權重 × 三情境隱含價
A7: 上檔空間（目標價 ÷ 現價 − 1） | B7: =B6/px-1 -> -0.69514891 | E7: 現價見第 6 節
A8: 情境 A 隱含價（樂觀） | B8: =F44 -> 72899.892 | E8: Val!F44：FY2027 EPS × 規則倍數
A9: 情境 B 隱含價（基準） | B9: =F51 -> 61140.181 | E9: Val!F51：FY2027 EPS × 規則倍數
A10: 情境 C 隱含價（下檔） | B10: =F58 -> 25121.857 | E10: Val!F58：FY2027 EPS × 規則倍數
A11: 情境權重 A／B／C | B11: =tp_wA -> 0.3 | C11: =tp_wB -> 0.5 | D11: =tp_wC -> 0.2 | E11: In 頁 tp_wA／tp_wB／tp_wC（Assumed，Andy 可改）
A12: 目標價方法 | B12: P/E：各情境 FY2027 EPS（模型）× 依循環位置的十年（2016–2025 年底）P/E 分位（設備股共用規則：A、B 中段＝中位數，C 見頂＝25 分位），再以 0.3／0.5／0.2 加權。偏誤：十年樣本有 7 年在 HBM 需求出現前（2016–2022，倍數 7–35 倍），會把分位往下拉；2024–25 年 50 倍以上的高成長期只占兩年。照規則計算，不另換倍數
A14: 1. 十年 P/E（年底）— 兩個來源
A15: 年底 | B15: 來源1：companiesmarketcap | C15: 來源2：stockanalysis／券商報告 | D15: 兩者差距 | E15: 標記 | F15: 來源2 出處
A16: 2016-12 | B16: 23.2 | D16: =IF(C16="","",B16-C16) | E16: Interested-party（資料商／券商） | F16: 未找到（2016–2017 年的券商報告與財務頁未取得）
A17: 2017-12 | B17: 55 | D17: =IF(C17="","",B17-C17) | E17: Interested-party（資料商／券商） | F17: 未找到
A18: 2018-12 | B18: 7.16 | C18: 9.7 | D18: =IF(C18="","",B18-C18) -> -2.54 | E18: Interested-party（資料商／券商） | F18: SK 證券 2021-12-22 報告（年底 P/E 9.7）
A19: 2019-12 | B19: 19.7 | C19: 24.1 | D19: =IF(C19="","",B19-C19) -> -4.4 | E19: Interested-party（資料商／券商） | F19: SK 證券 2021-12-22 報告（24.1）
A20: 2020-12 | B20: 17.2 | C20: 18.78 | D20: =IF(C20="","",B20-C20) -> -1.58 | E20: Interested-party（資料商／券商） | F20: Hana 證券 2023-02-13 報告（18.78；SK 證券 18.8）
A21: 2021-12 | B21: 34.8 | C21: 17.93 | D21: =IF(C21="","",B21-C21) -> 16.87 | E21: Interested-party（資料商／券商） | F21: stockanalysis（年底市值 ÷ 淨利；Hana 18.06）
A22: 2022-12 | B22: 12.1 | C22: 12.13 | D22: =IF(C22="","",B22-C22) -> -0.03 | E22: Interested-party（資料商／券商） | F22: stockanalysis（Hana 11.59）
A23: 2023-12 | B23: 21.8 | C23: 22.48 | D23: =IF(C23="","",B23-C23) -> -0.68 | E23: Interested-party（資料商／券商） | F23: stockanalysis
A24: 2024-12 | B24: 51.5 | C24: 51.76 | D24: =IF(C24="","",B24-C24) -> -0.26 | E24: Interested-party（資料商／券商） | F24: stockanalysis
A25: 2025-12 | B25: 56.5 | C25: 56.47 | D25: =IF(C25="","",B25-C25) -> 0.03 | E25: Interested-party（資料商／券商） | F25: stockanalysis
A26: 說明：companiesmarketcap 以美元計價的年底股價 ÷ EPS；2021 年 34.8 與另兩個來源（17.9、18.1）差異大，原因未解（該站 2021 年 EPS 疑有口徑問題），照列不剔除。2022 年 1 比 1 無償配股，各來源 EPS 皆為調整後
A28: 2. 分位
A29: 統計 | B29: 採用（兩來源平均） | C29: 來源1 | D29: 來源2 | E29: 用途
A30: 25 分位 | B30: =ROUND(AVERAGE(C30,D30),2) -> 17.15 | C30: =PERCENTILE(B16:B25,0.25) -> 17.825 | D30: =PERCENTILE(C16:C25,0.25) -> 16.48 | E30: 見頂年
A31: 中位數 | B31: =ROUND(AVERAGE(C31,D31),2) -> 21.57 | C31: =PERCENTILE(B16:B25,0.5) -> 22.5 | D31: =PERCENTILE(C16:C25,0.5) -> 20.63 | E31: 中段
A32: 75 分位 | B32: =ROUND(AVERAGE(C32,D32),2) -> 39.17 | C32: =PERCENTILE(B16:B25,0.75) -> 47.325 | D32: =PERCENTILE(C16:C25,0.75) -> 31.015 | E32: 谷底
A33: 年數 | C33: =COUNT(B16:B25) -> 10 | D33: =COUNT(C16:C25) -> 8
A35: 4. 循環位置（設備股共用規則；見頂年度讀設備市場模型，不在本模型另訂）
A36: 循環位置（設備股共用規則）：各情境的見頂年度取自設備市場模型（markets/equipment 的 Mkt 頁「見頂年度」：A 2029、B 2028、C 2027）；會計年度 FY(t) 對照日曆年 t（FY(t) 有 3/4 落在 t 年）：t 早於見頂年＝中段（中位數）、等於＝見頂（25 分位）、晚於＝谷底（75 分位）。本公司會計年度＝日曆年，FY(t) 直接對照日曆年 t
A37: 情境 | B37: 設備市場見頂年度 | C37: FY2027 對照日曆年 | D37: 判定 | E37: 倍數 | F37: 規則
A38: A | B38: =pk_A -> 2029 | C38: 2027 | D38: =IF(C38<pk_A,"中段",IF(C38=pk_A,"見頂","谷底")) -> 中段 | E38: =IF(D38="見頂",pe_peak,IF(D38="谷底",pe_trough,pe_mid)) -> 21.57 | F38: tools/cycle_position.py
A39: B | B39: =pk_B -> 2028 | C39: 2027 | D39: =IF(C39<pk_B,"中段",IF(C39=pk_B,"見頂","谷底")) -> 中段 | E39: =IF(D39="見頂",pe_peak,IF(D39="谷底",pe_trough,pe_mid)) -> 21.57 | F39: tools/cycle_position.py
A40: C | B40: =pk_C -> 2027 | C40: 2027 | D40: =IF(C40<pk_C,"中段",IF(C40=pk_C,"見頂","谷底")) -> 見頂 | E40: =IF(D40="見頂",pe_peak,IF(D40="谷底",pe_trough,pe_mid)) -> 17.15 | F40: tools/cycle_position.py
A42: 5. 隱含股價（韓元）：規則值＝FY2027 EPS × 依循環位置的倍數；其餘倍數僅供參考
A43: 情境 | B43: EPS 年度 | C43: EPS | D43: 倍數類型 | E43: 倍數 | F43: 隱含股價 | G43: 相對現價 | H43: 備註
A44: A | B44: FY2027 | C44: =PL!E12 -> 3379.689 | D44: ="規則值："&D38 -> 規則值：中段 | E44: =E38 -> 21.57 | F44: =C44*E44 -> 72899.892 | G44: =F44/px-1 -> -0.61326317
A45: A | B45: FY2027 | C45: =PL!E12 -> 3379.689 | D45: 參考：25 分位 | E45: =pe_peak -> 17.15 | F45: =C45*E45 -> 57961.667 | G45: =F45/px-1 -> -0.69251105
...

Sheet Recon
A1: Recon — 本模型 vs 共識、賣方、競爭者估的市場規模、SEMI。只作事後對照，不為對上數字而調整參數。差距 > 10% 的原因見 README
A3: 項目 | B3: 對照值 | C3: 模型 A | D3: 差距 A | E3: 模型 B | F3: 差距 B | G3: 模型 C | H3: 差距 C | I3: 對照來源 | J3: 說明
A4: A. FY2026 vs 共識與賣方（校準未使用）
A5: 營收 | B5: =cons_rev26 -> 7280 | C5: =PL!D5 -> 7539.8 | D5: =C5/B5-1 -> 0.035686813 | E5: =PL!D15 -> 7539.8 | F5: =E5/B5-1 -> 0.035686813 | G5: =PL!D25 -> 7539.8 | H5: =G5/B5-1 -> 0.035686813 | I5: etfshopping 共識 ₩7,280 億 | J5: 錨點＝上半年 3,020 ＋ 0.9 × 2 × 第二季
A6: 營業利益 | B6: =cons_oi26 -> 3694 | C6: =PL!D9 -> 3557.504 | D6: =C6/B6-1 -> -0.036950731 | E6: =PL!D19 -> 3557.504 | F6: =E6/B6-1 -> -0.036950731 | G6: =PL!D29 -> 3557.504 | H6: =G6/B6-1 -> -0.036950731 | I6: 上上人證券（2026-06-09）
A7: EPS（韓元） | B7: =cons_eps26 -> 3400 | C7: =PL!D12 -> 3158.1533 | D7: =C7/B7-1 -> -0.071131371 | E7: =PL!D22 -> 3158.1533 | F7: =E7/B7-1 -> -0.071131371 | G7: =PL!D32 -> 3158.1533 | H7: =G7/B7-1 -> -0.071131371 | I7: alphadistill（2026-10-12，非券商共識） | J7: stockanalysis 遠期 EPS 約 4,006（隱含）
A8: B. FY2027 vs 第三方預估
A9: 營收 | B9: =cons_rev27 -> 9900 | C9: =PL!E5 -> 8014.8364 | D9: =C9/B9-1 -> -0.19042057 | E9: =PL!E15 -> 6845.7956 | F9: =E9/B9-1 -> -0.3085055 | G9: =PL!E25 -> 3908.8294 | H9: =G9/B9-1 -> -0.60516875 | I9: alphadistill
A10: EPS（韓元） | B10: =cons_eps27 -> 4650 | C10: =PL!E12 -> 3379.689 | D10: =C10/B10-1 -> -0.27318516 | E10: =PL!E22 -> 2834.5008 | F10: =E10/B10-1 -> -0.39042994 | G10: =PL!E32 -> 1464.8313 | H10: =G10/B10-1 -> -0.68498251 | I10: alphadistill
A11: C. 市場規模與市占
A12: TC 鍵合機市場 CY2025（US$M；模型＝三大廠 HBM，不含邏輯與中國） | B12: =tam25 -> 759 | C12: =PL!C70 -> 634.1126 | D12: =C12/B12-1 -> -0.16454203 | E12: =PL!C103 -> 643.14698 | F12: =E12/B12-1 -> -0.15263902 | G12: =PL!C136 -> 757.5049 | H12: =G12/B12-1 -> -0.0019698278 | I12: ASMPT 估（含邏輯用 TCB） | J12: 口徑：模型只含三大記憶體廠的 HBM 鍵合
A13: TC 鍵合機市場 CY2028（US$M） | B13: =tam28 -> 1600 | C13: =PL!F70 -> 1003.1389 | D13: =C13/B13-1 -> -0.3730382 | E13: =PL!F103 -> 672.78096 | F13: =E13/B13-1 -> -0.5795119 | G13: =PL!F136 -> 231.81273 | H13: =G13/B13-1 -> -0.85511705 | I13: ASMPT 估
A14: 韓美 HBM TC 鍵合機市占 CY2025（模型＝加權份額） | B14: =sh_claim -> 0.712 | C14: =PL!C54 -> 0.412 | D14: =C14-B14 -> -0.3 | E14: =PL!C87 -> 0.412 | F14: =E14-B14 -> -0.3 | G14: =PL!C120 -> 0.412 | H14: =G14-B14 -> -0.3 | I14: 公司引 TechInsights 71.2% | J14: 差距以百分點計
A15: D. 三大廠 HBM TC 鍵合機市場 vs SEMI 組裝與封裝設備（markets/equipment）
A16: CY2025：模型市場（US$B）vs SEMI 組裝與封裝 | B16: =semi_pkg25 -> 6.1131387 | C16: =PL!C70/1000 -> 0.6341126 | D16: =C16/B16-1 -> -0.89627054 | E16: =PL!C103/1000 -> 0.64314698 | F16: =E16/B16-1 -> -0.89479267 | G16: =PL!C136/1000 -> 0.7575049 | H16: =G16/B16-1 -> -0.87608577 | I16: SEMI（equipment 成品） | J16: 差距＝占 SEMI 組裝封裝的比例 − 1
A17: CY2028：同上 | B17: =semi_pkg28 -> 8.6 | C17: =PL!F70/1000 -> 1.0031389 | D17: =C17/B17-1 -> -0.88335594 | E17: =PL!F103/1000 -> 0.67278096 | F17: =E17/B17-1 -> -0.92176966 | G17: =PL!F136/1000 -> 0.23181273 | H17: =G17/B17-1 -> -0.97304503 | I17: SEMI 2026-07
A18: E. 其他資訊（非對帳）
A19: FY2026 上半年營收 ÷ 錨點全年 | C19: =(q1_rev+q2_rev)/PL!D5 -> 0.40054113
A20: CY2026 三大廠 TC 鍵合機台數（模型 A，市場 ÷ 單價） | C20: =Units!D32 -> 331.62876 | J20: 對照：SK 海力士 2026-03 預計約 100 台（The Elec）；HBM4 現有約 50 套

Sheet Sens
A1: Sens — 一次動一個輸入（情境 A）：對 FY2027、FY2028 營收與 EPS 的影響。每個案例是一個完整的推導區塊（本頁下方，與 PL 同一引擎；校準係數 k 在各區塊內重算）
A3: 案例 | B3: 設定 | C3: FY2027 營收 ₩億 | D3: FY2027 EPS ₩ | E3: 相對基準 | F3: FY2028 營收 ₩億 | G3: FY2028 EPS ₩ | H3: 相對基準
A4: 基準（情境 A） | B4: PL 區塊 A | C4: =PL!E60 -> 8014.8364 | D4: =PL!E68 -> 3379.689 | E4: =D4/D$4-1 -> 0 | F4: =PL!F60 -> 8876.969 | G4: =PL!F68 -> 3781.7491 | H4: =G4/G$4-1 -> 0
A5: SK 海力士份額 −10pt | B5: 35% | C5: =E80 -> 7731.4665 | D5: =E88 -> 3247.538 | E5: =D5/D$4-1 -> -0.039101528 | F5: =F80 -> 8566.183 | G5: =F88 -> 3636.8124 | H5: =G5/G$4-1 -> -0.038325307
A6: SK 海力士份額 +10pt | B6: 55% | C6: =E120 -> 8266.6325 | D6: =E128 -> 3497.1155 | E6: =D6/D$4-1 -> 0.034744743 | F6: =F120 -> 9153.1266 | G6: =F128 -> 3910.5366 | H6: =G6/G$4-1 -> 0.03405501
A7: 美光份額 −10pt | B7: 65% | C7: =E160 -> 7871.4619 | D7: =E168 -> 3312.8256 | E7: =D7/D$4-1 -> -0.019783898 | F7: =F160 -> 8719.723 | G7: =F168 -> 3708.4166 | H7: =G7/G$4-1 -> -0.019391159
A8: 美光份額 +10pt | B8: 85% | C8: =E200 -> 8150.375 | D8: =E208 -> 3442.8982 | E8: =D8/D$4-1 -> 0.018702645 | F8: =F200 -> 9025.6211 | G8: =F208 -> 3851.0737 | H8: =G8/G$4-1 -> 0.018331371
A9: 三星份額 10% | B9: 韓美打進三星 | C9: =E240 -> 8136.5611 | D9: =E248 -> 3436.456 | E9: =D9/D$4-1 -> 0.016796502 | F9: =F240 -> 9010.4707 | G9: =F248 -> 3844.0083 | H9: =G9/G$4-1 -> 0.016463068
A10: 混合鍵合 Disco 基準 | B10: 2028 5%、2029 15%、2030 25% | C10: =E280 -> 7410.0668 | D10: =E288 -> 3097.6516 | E10: =D10/D$4-1 -> -0.083450703 | F10: =F280 -> 7083.2775 | G10: =F288 -> 2945.2517 | H10: =G10/G$4-1 -> -0.22119325
A11: 混合鍵合 Disco 高值 | B11: 2028 15%、2029 30%、2030 40% | C11: =E320 -> 6783.2026 | D11: =E328 -> 2805.3102 | E11: =D11/D$4-1 -> -0.16995019 | F11: =F320 -> 5945.1939 | G11: =F328 -> 2414.5005 | H11: =G11/G$4-1 -> -0.36153868
A12: 晶粒容量 低 | B12: 各年取低值（晶粒較多） | C12: =E360 -> 9077.9706 | D12: =E368 -> 3875.4872 | E12: =D12/D$4-1 -> 0.14669935 | F12: =F360 -> 9178.2104 | G12: =F368 -> 3922.2345 | H12: =G12/G$4-1 -> 0.037148275
A13: 晶粒容量 高 | B13: 各年取高值（晶粒較少） | C13: =E400 -> 7476.6748 | D13: =E408 -> 3128.7146 | E13: =D13/D$4-1 -> -0.074259629 | F13: =F400 -> 9898.6275 | G13: =F408 -> 4258.2048 | H13: =G13/G$4-1 -> 0.1259882
A14: 堆疊層數 低 | C14: =E440 -> 7568.6472 | D14: =E448 -> 3171.6064 | E14: =D14/D$4-1 -> -0.061568575 | F14: =F440 -> 8345.4086 | G14: =F448 -> 3533.8531 | H14: =G14/G$4-1 -> -0.06555061
A15: 堆疊層數 高 | C15: =E480 -> 8232.1749 | D15: =E488 -> 3481.046 | E15: =D15/D$4-1 -> 0.029990019 | F15: =F480 -> 8655.3893 | G15: =F488 -> 3678.4142 | H15: =G15/G$4-1 -> -0.027324618
A16: 層數對鍵合時間 0 | B16: beta＝0 | C16: =E520 -> 7722.4183 | D16: =E528 -> 3243.3183 | E16: =D16/D$4-1 -> -0.040350077 | F16: =F520 -> 8512.3671 | G16: =F528 -> 3611.7151 | H16: =G16/G$4-1 -> -0.044961739
A17: 層數對鍵合時間 0.25 | B17: beta＝0.25 | C17: =E560 -> 8369.0009 | D17: =E568 -> 3544.8555 | E17: =D17/D$4-1 -> 0.048870313 | F17: =F560 -> 9318.5596 | G17: =F568 -> 3987.6871 | H17: =G17/G$4-1 -> 0.054455764
A18: 汰換比例 5% | C18: =E600 -> 7884.596 | D18: =E608 -> 3318.9508 | E18: =D18/D$4-1 -> -0.017971558 | F18: =F600 -> 8595.0245 | G18: =F608 -> 3650.2628 | H18: =G18/G$4-1 -> -0.034768647
A19: 汰換比例 15% | C19: =E640 -> 8127.3423 | D19: =E648 -> 3432.1567 | E19: =D19/D$4-1 -> 0.015524417 | F19: =F640 -> 9120.5219 | G19: =F648 -> 3895.3312 | H19: =G19/G$4-1 -> 0.03003429
A20: FY2026 下半年 ×0.7 | B20: 錨點營收較低 → k 較低 | C20: =E680 -> 7407.0136 | D20: =E688 -> 3142.0328 | E20: =D20/D$4-1 -> -0.070318955 | F20: =F680 -> 8210.339 | G20: =F688 -> 3521.6356 | H20: =G20/G$4-1 -> -0.068781261
A21: FY2026 下半年 ×1.1 | B21: 錨點營收較高 → k 較高 | C21: =E720 -> 8622.6592 | D21: =E728 -> 3622.3642 | E21: =D21/D$4-1 -> 0.07180399 | F21: =F720 -> 9543.5991 | G21: =F728 -> 4047.4931 | H21: =G21/G$4-1 -> 0.070270145
A22: 下半年營益率 42% | B22: 毛利率基準隨之下降 | C22: =E760 -> 8014.8364 | D22: =E768 -> 3123.7756 | E22: =D22/D$4-1 -> -0.075721006 | F22: =F760 -> 8876.969 | G22: =F768 -> 3498.3078 | H22: =G22/G$4-1 -> -0.074949796
A23: 下半年營益率 52% | C23: =E800 -> 8014.8364 | D23: =E808 -> 3550.298 | E23: =D23/D$4-1 -> 0.050480671 | F23: =F800 -> 8876.969 | G23: =F808 -> 3970.71 | H23: =G23/G$4-1 -> 0.049966531
A24: TC 鍵合機占 FY2025 營收 50% | B24: HBM 基期較低、其他較高 | C24: =E840 -> 8008.5687 | D24: =E848 -> 3376.766 | E24: =D24/D$4-1 -> -0.00086486688 | F24: =F840 -> 8884.4285 | G24: =F848 -> 3785.2279 | H24: =G24/G$4-1 -> 0.00091988512
A25: TC 鍵合機占 FY2025 營收 70% | C25: =E880 -> 8021.1041 | D25: =E888 -> 3382.612 | E25: =D25/D$4-1 -> 0.00086486688 | F25: =F880 -> 8869.5096 | G25: =F888 -> 3778.2703 | H25: =G25/G$4-1 -> -0.00091988512
A26: 其他業務成長 低 | B26: 7% | C26: =E920 -> 7848.3719 | D26: =E928 -> 3302.0575 | E26: =D26/D$4-1 -> -0.022970032 | F26: =F920 -> 8512.4119 | G26: =F928 -> 3611.736 | H26: =G26/G$4-1 -> -0.044956215
A27: 其他業務成長 高 | B27: 17% | C27: =E960 -> 8181.3008 | D27: =E968 -> 3457.3206 | E27: =D27/D$4-1 -> 0.022970032 | F27: =F960 -> 9258.1727 | G27: =F968 -> 3959.5254 | H27: =G27/G$4-1 -> 0.047009011
A28: 營業費用變動比例 30% | C28: =E1000 -> 8014.8364 | D28: =E1008 -> 3388.713 | E28: =D28/D$4-1 -> 0.0026700548 | F28: =F1000 -> 8876.969 | G28: =F1008 -> 3807.1504 | H28: =G28/G$4-1 -> 0.006716819
A29: 營業費用變動比例 70% | C29: =E1040 -> 8014.8364 | D29: =E1048 -> 3370.6651 | E29: =D29/D$4-1 -> -0.0026700548 | F29: =F1040 -> 8876.969 | G29: =F1048 -> 3756.3478 | H29: =G29/G$4-1 -> -0.006716819
A30: 淨利÷營業利益 0.72 | C30: =E1080 -> 8014.8364 | D30: =E1088 -> 2858.5347 | E30: =D30/D$4-1 -> -0.15420187 | F30: =F1080 -> 8876.969 | G30: =F1088 -> 3198.5963 | H30: =G30/G$4-1 -> -0.15420187
A31: 淨利÷營業利益 0.95 | B31: 含一次性投資評價益，不當基準 | C31: =E1120 -> 8014.8364 | D31: =E1128 -> 3771.6777 | E31: =D31/D$4-1 -> 0.11598364 | F31: =F1120 -> 8876.969 | G31: =F1128 -> 4220.3701 | H31: =G31/G$4-1 -> 0.11598364
A32: 顆數情境 B | B32: 2028 ×0.8、2029 ×0.85；混合鍵合基準；份額與其他成長 B | C32: =PL!E93 -> 6845.7956 | D32: =PL!E101 -> 2834.5008 | E32: =D32/D$4-1 -> -0.16131314 | F32: =PL!F93 -> 6940.3995 | G32: =PL!F101 -> 2878.6198 | H32: =G32/G$4-1 -> -0.23881259
A33: 顆數情境 C | B33: 2028–29 ×0.6；混合鍵合高值；份額回落、毛利率下調 | C33: =PL!E126 -> 3908.8294 | D33: =PL!E134 -> 1464.8313 | E33: =D33/D$4-1 -> -0.56657808 | F33: =PL!F126 -> 3827.6186 | G33: =PL!F134 -> 1325.0199 | H33: =G33/G$4-1 -> -0.64962777
A35: 讀法：鍵合機比產能早一年買，FY2027 的需求看 CY2027→2028 的產能增量，所以顆數情境（2028 起）直接影響 FY2027。晶粒容量的影響大，是因為同樣位元下，容量提高會減少需要鍵合的晶粒數；校準係數 k 由 FY2025–26 兩年營收推得，各案例內重算。
A60: 案例區塊：SK 海力士份額 −10pt（情境 A）
A61: 項目 | B61: 單位 | C61: 2025 | D61: 2026 | E61: 2027 | F61: 2028 | G61: 2029 | H61: 2030 | I61: 說明
A62: A. 日曆年鍵合產能需求（本公司會計年度＝日曆年）
A63: HBM 出貨位元 | B63: EB | C63: =hsA_25 -> 2.2251147 | D63: =hsA_26 -> 3.782695 | E63: =hsA_27 -> 5.8631772 | F63: =hsA_28 -> 8.501607 | G63: =hsA_29 -> 11.477169 | H63: =G63*(1+g_tail) -> 12.624886 | I63: markets/memory；2030＝2029 ×（1＋g_tail）
A64: DRAM 晶粒容量 | B64: Gb | C64: =den_25 -> 24 | D64: =den_26 -> 24 | E64: =den_27 -> 26 | F64: =den_28 -> 28 | G64: =den_29 -> 30 | H64: =den_30 -> 32
A65: 核心晶粒數＝位元 × 8000 ÷ 容量 | B65: 百萬顆 | C65: =C63*8000/C64 -> 741.7049 | D65: =D63*8000/D64 -> 1260.8983 | E65: =E63*8000/E64 -> 1804.0545 | F65: =F63*8000/F64 -> 2429.0306 | G65: =G63*8000/G64 -> 3060.5785 | H65: =H63*8000/H64 -> 3156.2216 | I65: 1 EB＝8×10⁹ Gb；每顆核心晶粒鍵合一次
A66: 平均堆疊層數 | B66: 層 | C66: =stk_25 -> 10 | D66: =stk_26 -> 12 | E66: =stk_27 -> 12.5 | F66: =stk_28 -> 14 | G66: =stk_29 -> 15 | H66: =stk_30 -> 16
...

Sheet Sources
A1: 來源（DART 原文在建置環境無法開啟；Naver、FnGuide 頁面被擋；數字取自新聞稿報導與財務資料頁，原文待人工複核）
A2: 亞洲經濟：2025 年創社最大營收 5,767、營益率 43.6%、TC 鍵合機市占 71.2%（2026-02-09） | B2: https://view.asiae.co.kr/en/article/2026020908430125470
A3: ddaily：2026 第二季營收 2,511、營業利益 1,303（2026-07-14） | B3: https://www.ddaily.co.kr/page/view/2026071411214300568
A4: THE FACT：第一季 509／85、目標營收撤回（2026-08） | B4: https://news.tf.co.kr/read/economy/2350287.htm
A5: dealsite：BofA 下半年約 ₩5,200 億、美光加單（2026-07-22） | B5: https://dealsite.co.kr/articles/165650
A6: dealsite：2025 第二季、LS 證券客戶比重（2025-07-25） | B6: https://dealsite.co.kr/articles/145326
A7: heraldcorp：SK 海力士 ₩442 億訂單、上上人證券預估（2026-06-09） | B7: https://biz.heraldcorp.com/article/10778245
A8: newdaily：2024 客戶別營收（SK 海力士 2,996、美光 1,111）、漲價 25%（2025-04-02） | B8: https://biz.newdaily.co.kr/site/data/html/2025/04/02/2025040200057.html
A9: etfshopping：各季初步實績、共識營收、2026-10-23 收盤 | B9: https://etfshopping.com/stock/042700/earnings
A10: valueline：近 12 月損益（毛利、銷管費、淨利、EPS） | B10: https://www.valueline.co.kr/finance/income/042700
A11: stockanalysis：年度損益、年底市值 P/E（2021–2025） | B11: https://stockanalysis.com/quote/krx/042700/financials/ratios/
A12: butler.works：年度營收、營業利益、淨利 | B12: https://www.butler.works/ko/companies/00161383
A13: companiesmarketcap：年底 P/E（2016–2025） | B13: https://companiesmarketcap.com/hanmi-semiconductor/pe-ratio/
... A20: mydailybyte：週報（第三季 2026-11-06 公布） | B20: https://www.mydailybyte.com/littlebit/plus/weekly-report-042700-2026-10-19
A21: 市場層與上游成品：skhynix／samsung／micron／disco／markets/equipment 的 dist（本 repo）
A22: SemiAnalysis | B22: 未使用
