Workbook

Sheet README
A1: ASML（ASML.AS／ASML ADR）收支與估值模型 v0.2（AI 半導體 Project 步驟 5：設備與材料） 2026-10-25
A2: 模型命題：ASML 是 EUV 唯一供應者，營收由晶圓廠的微影設備支出與裝機基礎服務決定。2026 年 AI 帶動記憶體與先進邏輯擴產，營收約 +36%、毛利率升到 56%；股價約 25 倍前瞻本益比，問題是設備支出在 2027 年後放緩、中國營收占比續降時，產能 +30% 與漲價能否撐住盈餘成長。
A4: 會計年度＝日曆年（FY2026＝2026-01～12）；金額以歐元為主（Q 頁 €M，PL 頁 €B）。FY2026 錨點＝前三季實績（含 2026-10-14 公布的第三季）＋第四季公司指引中點，三情境相同；FY2027–FY2029 由驅動推導。第四季財報預定 2027-01 下旬公布。
A6: 驅動因子 → 推導量
A7: 系統營收（非中國）＝FY2026 錨點 × 晶圓前段設備指數（markets/equipment：邏輯＝先進邏輯＋其他代工邏輯，記憶體＝DRAM 含 HBM＋NAND；FY2026＝1）× 微影強度與價格係數（Assumed +3%／年）；邏輯與記憶體分開，權重＝FY2026 指引成長推得的邏輯占比
A8: 中國系統營收：FY2026＝錨點 × 20%（公司：2026 年約 20%），之後 × (1＋情境別年成長)；系統營收＝MIN(需求, 產能上限)，產能＝FY2026 ×（2027 +30%、2028 +15%、2029 +10%）× 強度係數
A9: IBM：前一年 × (1＋情境別成長)。毛利率＝FY2026 錨點毛利率＋斜率 × ln(營收比)（FY2025 與 FY2026 兩點推導）；營業費用＝FY2026 ×［固定＋變動 × 營收比］（兩點推導）；不寫死利益率
A10: 情境 A／B／C：設備市場模型的三情境（A 續增；B 2028 持平、2029 −5%；C 2028 −20%）＋中國年成長（0%／−10%／−25%）＋IBM 年成長（+12%／+8%／+3%）
A11: Val：P/E 規則——10 年（2016–2025 年底）P/E 分位，見頂年 25 分位、中段中位數、谷底 75 分位；循環位置依設備股共用規則（各情境見頂年度讀設備市場模型：A 2029、B 2028、C 2027 → FY2027：A 中段、B 中段、C 見頂）。本版未做先驗，無 Andy 合理 P/E 對照。Recon：公司指引、共識、2030 目標、微影占設備支出、產能。Sens：強度與價格、中國、IBM、毛利率斜率、營業費用等
A13: 標記：Verified、Interested-party、Analogy、Assumed、Derived。SemiAnalysis 未使用。實績取自 SEC 6-K；法說內容取自公司逐字稿與第三方轉述。
A14: 已知限制：(1) 設備市場的其他代工與記憶體廠含中國廠，本模型另以中國系統營收列處理，指數的中國成分重疊；(2) 微影強度與價格（g_int）無直接實證，只有 FY2025 一年可比；(3) 毛利率、營業費用都只有兩點，毛利率對規模的斜率可能高估（FY2026 的 +2.9pt 含漲價與產品組合）；(4) 指數只連結設備支出的成長，匯率變動不進營收；(5) 產能上限以系統總額近似，未分 EUV／DUV；(6) Euronext 年底收盤價未找到，10 年 P/E 用 ADR 價格與 ECB 匯率換算；(7) 2028–29 依設備市場情境係數（Assumed）。
A15: v0.2（2026-10-25）估值 v2：Val 頁新增「0. 目標價」（放在既有內容之後，不位移既有列）＝0.5 × DCF 目標價（股東現金流＝EPS ×（1 − g／ROE），FY2027–32 明確期＋永續，r 10%、g 4%，情境權重 A 0.3／B 0.5／C 0.2）＋0.5 × Comparable 目標價（同業前瞻 P/E 中位數 × 12 個月後前瞻 EPS）；另列 Comparable 單獨目標價、市場共識目標價與差距拆解、歷史分位檢查。原「0. 目標價與上檔空間」改名「舊法：規則值情境加權（參考）」，不再叫目標價。
A16: 預估期間延伸到 FY2032：FY2027–FY2029 由驅動因子推導；FY2030 起為收斂法，非驅動因子推導（PL 頁底部延伸區塊，灰底）。情境對應：A＝順利、B＝平平、C＝不如預期（原為顆數情境）。本版未做先驗，無 Andy 合理 P/E 對照。

Sheet In
A1: In — 輸入（藍字；基準欄 E，低 D、高 F）。金額：Q 頁與指引為百萬歐元（€M），驅動與 PL 為十億歐元（€B）；設備市場為十億美元（US$B）。每個輸入附兩個來源（來源2 找不到者寫「未找到」）；公司原文算一個
A2: 標記：Verified／Interested-party／Analogy／Assumed／Derived；Analogy、Assumed 給低／高區間，不當點估計（放情境或 Sens）。SemiAnalysis 未使用。公司數字取自 SEC 6-K（ASML 新聞稿、財務報表、簡報）與法說逐字稿；asml.com 的 PDF 經搜尋引擎摘錄讀取
A3: 鍵 | B3: 項目 | C3: 單位 | D3: 低 | E3: 基準 | F3: 高 | G3: 標記 | H3: 來源1 | I3: 來源2／說明
A4: A. 晶圓前段設備支出（markets/equipment 成品，三情境；唯讀，不自行重估）
A5: laA_25 | B5: 先進邏輯設備 2025（情境 A） | C5: US$B | E5: 36.032336 | G5: Derived | H5: markets/equipment/dist/20261023_半導體設備市場模型_v0.1.3.xlsx｜Mkt!C120:G120 | I5: 設備市場模型：公司資本支出 × 設備占比＋其他廠；2025–2027 三情境相同，2028–29 依情境係數
A6: laA_26 | B6: 先進邏輯設備 2026（情境 A） | C6: US$B | E6: 50.324843 | G6: Derived | H6: 同上 | I6: 同上
A7: laA_27 | B7: 先進邏輯設備 2027（情境 A） | C7: US$B | E7: 60.776431 | G7: Derived | H7: 同上 | I7: 同上
A8: laA_28 | B8: 先進邏輯設備 2028（情境 A） | C8: US$B | E8: 70.016145 | G8: Derived | H8: 同上 | I8: 同上
A9: laA_29 | B9: 先進邏輯設備 2029（情境 A） | C9: US$B | E9: 74.209437 | G9: Derived | H9: 同上 | I9: 同上
A10: laB_25 | B10: 先進邏輯設備 2025（情境 B） | C10: US$B | E10: 36.032336 | G10: Derived | H10: markets/equipment/dist/20261023_半導體設備市場模型_v0.1.3.xlsx｜Mkt!C139:G139 | I10: 同上
A11: laB_26 | B11: 先進邏輯設備 2026（情境 B） | C11: US$B | E11: 50.324843 | G11: Derived | H11: 同上 | I11: 同上
A12: laB_27 | B12: 先進邏輯設備 2027（情境 B） | C12: US$B | E12: 60.776431 | G12: Derived | H12: 同上 | I12: 同上
A13: laB_28 | B13: 先進邏輯設備 2028（情境 B） | C13: US$B | E13: 60.776431 | G13: Derived | H13: 同上 | I13: 同上
A14: laB_29 | B14: 先進邏輯設備 2029（情境 B） | C14: US$B | E14: 57.737609 | G14: Derived | H14: 同上 | I14: 同上
A15: laC_25 | B15: 先進邏輯設備 2025（情境 C） | C15: US$B | E15: 36.032336 | G15: Derived | H15: markets/equipment/dist/20261023_半導體設備市場模型_v0.1.3.xlsx｜Mkt!C158:G158 | I15: 同上
A16: laC_26 | B16: 先進邏輯設備 2026（情境 C） | C16: US$B | E16: 50.324843 | G16: Derived | H16: 同上 | I16: 同上
... A87: pk_C | B87: 情境 C：設備市場見頂年度（日曆年；循環位置規則用） | C87: 年 | E87: 2027 | G87: Derived | H87: markets/equipment/dist/20261023_半導體設備市場模型_v0.1.3.xlsx｜Mkt!C28 | I87: 同上
A88: B. FY2026 第四季公司指引（2026-10-14）與全年指引；FY2026 錨點＝前三季實績＋第四季指引中點
A89: g_q4_rev | B89: 第四季營收指引（14.2–15.2 中點） | C89: €M | D89: 14200 | E89: 14700 | F89: 15200 | G89: Interested-party | H89: ASML Q3 2026 新聞稿（SEC 6-K，2026-10-14）：Q4 €14.2–15.2B | I89: 簡報（6-K 附件）同；stockhub.kr 摘要同
A90: g_q4_ibm | B90: 第四季裝機基礎管理（IBM）營收指引 | C90: €M | E90: 3700 | G90: Interested-party | H90: ASML Q3 2026 簡報：Q4 IBM 約 €3.7B | I90: 法說逐字稿（Benzinga）同
A91: g_q4_gm | B91: 第四季毛利率指引 | C91: % | D91: 0.56 | E91: 0.57 | F91: 0.58 | G91: Interested-party | H91: ASML Q3 2026 新聞稿：約 57% | I91: stockhub.kr 摘要同；低／高 ±1pt 為 Assumed
A92: g_q4_rd | B92: 第四季研發費用指引 | C92: €M | E92: 1200 | G92: Interested-party | H92: 同上：約 €1.2B | I92: 同上
A93: g_q4_sga | B93: 第四季銷管費用指引 | C93: €M | E93: 400 | G93: Interested-party | H93: 同上：約 €0.4B | I93: 同上
A94: g_fy_rev | B94: FY2026 營收指引（44–45 中點） | C94: €M | D94: 44000 | E94: 44500 | F94: 45000 | G94: Interested-party | H94: ASML Q3 2026 新聞稿：€44–45B（7 月 €43–45B、4 月 €36–40B、1 月 €34–39B） | I94: aiweekly 2026-10-15：下緣上調至 €44B
A95: g_fy_gm | B95: FY2026 毛利率指引 | C95: % | E95: 0.56 | G95: Interested-party | H95: 同上：約 56%（7 月 54–56%、1 月 51–53%） | I95: 法說逐字稿（Benzinga）同
A96: g_tax | B96: FY2026 有效稅率指引 | C96: % | E96: 0.17 | G96: Interested-party | H96: Q3 2026 簡報：約 17%（Q3 實際 16.1%） | I96: 法說逐字稿同
A97: g_euv | B97: FY2026 EUV 系統營收成長（指引「超過 45%」） | C97: % | E97: 0.45 | G97: Interested-party | H97: Q3 2026 法說：EUV 營收成長超過 45%；Low-NA EUV 出貨約 65 台（2025：44 台） | I97: Q2 2026 法說同（超過 45%、約 65 台）
A98: g_log | B98: FY2026 邏輯系統營收成長（指引） | C98: % | E98: 0.1 | G98: Interested-party | H98: Q3 2026 法說：邏輯約 +10%、記憶體約 +75% | I98: Q2 2026 法說：記憶體超過 +75%、先進邏輯代工超過 +25%（口徑不同）
A99: g_mem | B99: FY2026 記憶體系統營收成長（指引） | C99: % | E99: 0.75 | G99: Interested-party | H99: 同上 | I99: 同上
A100: g_ibm26 | B100: FY2026 IBM 成長（指引） | C100: % | E100: 0.5 | G100: Interested-party | H100: Q3 2026 法說：約 +50%（7 月：超過 +30%） | I100: 錨點值見 Q 頁（由前三季＋第四季指引推得，對照用）
A101: sh_q4 | B101: 第四季加權平均股數（基本） | C101: 百萬股 | D101: 380 | E101: 381.5 | F101: 383.1 | G101: Assumed | H101: 無：公司未給；Q3 2026 加權 383.1M（6-K），Q3 買回約 2.8M 股 | I101: 高＝Q3 值（不再買回）；基準＝Q3 再減約 0.4%
A102: C. 系統營收的組成（FY2026 錨點的拆分）
A103: a25_log | B103: FY2025 邏輯系統營收 | C103: €M | E103: 16100 | G103: Verified | H103: ASML Q4 2025 法說逐字稿（2026-01-28）：邏輯 €16.1B（+22%） | I103: 記憶體 €8.4B；兩者合計 24.5 與 6-K 系統營收 24,474 相符
A104: a25_mem | B104: FY2025 記憶體系統營收 | C104: €M | E104: 8400 | G104: Verified | H104: 同上：記憶體 €8.4B（−2%） | I104: 同上
A105: log_sh26 | B105: FY2026 邏輯占系統營收（指引成長推得） | C105: % | E105: =a25_log*(1+g_log)/(a25_log*(1+g_log)+a25_mem*(1+g_mem)) -> 0.54643629 | G105: Derived | H105: 16.1×1.10 ÷（16.1×1.10＋8.4×1.75） | I105: Q1–Q3 2026 單季：49%／51%／54%（法說）
A106: cn_sh26 | B106: FY2026 中國占系統營收 | C106: % | D106: 0.17 | E106: 0.2 | F106: 0.23 | G106: Interested-party | H106: 公司：2026 年中國約占總營收 20%（Q4 2025、Q3 2026 法說）；本模型套用於系統營收（Assumed） | I106: aiweekly 2026-10-15：Q3 占系統出貨 23%、Q2 14%；低／高＝17%／23%（Assumed）
A107: cn_tot25 | B107: FY2025 中國占總營收 | C107: % | E107: 0.33 | G107: Interested-party | H107: Caixin 2026-01-29（公司 FY2025 揭露）：33%，高於公司 2025-07 預估的約 25% | I107: 2024 約 36%（Caixin 時間軸，AI 生成，弱）；第二來源：未找到
A108: D. 驅動：設備支出指數 × 微影強度與價格 → 系統需求；產能上限；中國；IBM
A109: g_int | B109: 微影強度與價格提升（每年；相對晶圓前段設備支出） | C109: %/年 | D109: 0 | E109: 0.03 | F109: 0.06 | G109: Assumed | H109: 無直接實證。公司：關鍵產品漲價自 2027 生效、2028 全年生效（Q3 2026 法說）；EUV 層數增加 | I109: Analogy：ASML 系統營收（美元）÷ SEMI WFE 2025＝23.7%（Recon）；只有一年可比，不作校準
A110: cap_27 | B110: 2027 產能成長（Low-NA EUV 與 DUV 浸潤式） | C110: % | D110: 0.2 | E110: 0.3 | F110: 0.35 | G110: Interested-party | H110: Q2、Q3 2026 法說：2027 產能約 +30% | I110: Q1 2026 法說：Low-NA EUV 2027「至少 80 台」（2026 約 65 台 → +23%）；低＝20%（Assumed）
...

Sheet Q
A1: Q — 實績（百萬歐元；EPS 為歐元）。會計年度＝日曆年。藍字＝輸入（SEC 6-K 公司財報）；黑字＝公式（Derived）。FY2026 錨點＝前三季實績＋第四季公司指引（2026-10-14）
A2: FY2026 第三季（2026-10-14 公布）已納入；第四季與全年 2026 財報預定 2027-01 下旬公布（公司慣例：1 月第四個週三；確切日期：未找到），屆時以實績取代 J 欄指引
A3: 項目 | B3: 9M 2025（1–9月） | C3: Q3 2025 | D3: H1 2025（Derived） | E3: Q4 2025 | F3: FY2025 | G3: Q1 2026 | H3: Q2 2026 | I3: Q3 2026 | J3: Q4 2026（指引） | K3: FY2026 錨點 | L3: 標記 | M3: 來源1（公司） | N3: 來源2／說明
A4: 系統營收（net system sales） | B4: 16890.3 | C4: 5553.8 | D4: =B4-C4 -> 11336.5 | E4: 7584 | F4: =B4+E4 -> 24474.3 | G4: 6279.4 | H4: 6564.8 | I4: 8373.2 | J4: =J6-J5 -> 11000 | K4: =SUM(G4:J4) -> 32217.4 | L4: Verified | M4: SEC 6-K：Q3 2026 財務報表（季度摘要表 Q3 2025–Q3 2026、9M 2025／2026） | N4: Q4 2025 簡報：FY2025 €24,474M；Q3 2026 簡報：Q3 €8.4B
A5: 裝機基礎管理（IBM；net service and field option sales） | B5: 6058.9 | C5: 1962.2 | D5: =B5-C5 -> 4096.7 | E5: 2134.1 | F5: =B5+E5 -> 8193 | G5: 2487.5 | H5: 2761.7 | I5: 3288.8 | J5: =g_q4_ibm -> 3700 | K5: =SUM(G5:J5) -> 12238 | L5: Verified／Interested-party | M5: SEC 6-K：Q3 2026 財務報表（季度摘要表 Q3 2025–Q3 2026、9M 2025／2026）；J 欄＝公司指引 | N5: Q4 2025 簡報：FY2025 IBM €8.2B（+26%）
A6: 營收 | B6: =B4+B5 -> 22949.2 | C6: =C4+C5 -> 7516 | D6: =D4+D5 -> 15433.2 | E6: =E4+E5 -> 9718.1 | F6: =F4+F5 -> 32667.3 | G6: =G4+G5 -> 8766.9 | H6: =H4+H5 -> 9326.5 | I6: =I4+I5 -> 11662 | J6: =g_q4_rev -> 14700 | K6: =SUM(G6:J6) -> 44455.4 | L6: Derived | M6: 系統＋IBM；J 欄＝指引中點 | N6: stockanalysis：FY2025 €32,667M；Q3 2026 新聞稿 €11,662M
A7: 毛利 | B7: 12189.5 | C7: 3880.3 | D7: =B7-C7 -> 8309.2 | E7: 5068.6 | F7: =B7+E7 -> 17258.1 | G7: 4645 | H7: 5035.4 | I7: 6699.8 | J7: =J6*g_q4_gm -> 8379 | K7: =SUM(G7:J7) -> 24759.2 | L7: Verified | M7: SEC 6-K：Q3 2026 財務報表（季度摘要表 Q3 2025–Q3 2026、9M 2025／2026） | N7: stockanalysis：FY2025 毛利率 52.83%
A8: 毛利率 | B8: =B7/B6 -> 0.53115141 | C8: =C7/C6 -> 0.51627195 | D8: =D7/D6 -> 0.53839774 | E8: =E7/E6 -> 0.52156286 | F8: =F7/F6 -> 0.52829894 | G8: =G7/G6 -> 0.52983381 | H8: =H7/H6 -> 0.53990243 | I8: =I7/I6 -> 0.57449837 | ... K8: =K7/K6 -> 0.55694471 | L8: Derived | M8: — | N8: 公司：FY2025 52.8%；Q3 2026 57.5%；FY2026 指引約 56%
A9: 研發費用 | B9: 3436.5 | C9: 1108.7 | D9: =B9-C9 -> 2327.8 | E9: 1262.3 | F9: =B9+E9 -> 4698.8 | G9: 1184.9 | H9: 1276.6 | I9: 1174.4 | J9: =g_q4_rd -> 1200 | K9: =SUM(G9:J9) -> 4835.9 | L9: Verified | M9: SEC 6-K：Q3 2026 財務報表（季度摘要表 Q3 2025–Q3 2026、9M 2025／2026） | N9: —
A10: 銷管費用 | B10: 882.5 | C10: 303.2 | D10: =B10-C10 -> 579.3 | E10: 375.2 | F10: =B10+E10 -> 1257.7 | G10: 302.3 | H10: 302.7 | I10: 352.6 | J10: =g_q4_sga -> 400 | K10: =SUM(G10:J10) -> 1357.6 | L10: Verified | M10: SEC 6-K：Q3 2026 財務報表（季度摘要表 Q3 2025–Q3 2026、9M 2025／2026） | N10: —
A11: 營業利益 | B11: =B7-B9-B10 -> 7870.5 | C11: =C7-C9-C10 -> 2468.4 | D11: =D7-D9-D10 -> 5402.1 | E11: =E7-E9-E10 -> 3431.1 | F11: =F7-F9-F10 -> 11301.6 | G11: =G7-G9-G10 -> 3157.8 | H11: =H7-H9-H10 -> 3456.1 | I11: =I7-I9-I10 -> 5172.8 | ... K11: =K7-K9-K10 -> 18565.7 | L11: Derived | M11: 毛利 − 研發 − 銷管 | N11: 公司：Q3 2026 營業利益 €5,172.8M（營業利益率 44.4%）；FY2025 營業利益率 34.6%
A12: 營業利益（公司公布；核對用） | B12: 7870.5 | C12: 2468.4 | D12: =B12-C12 -> 5402.1 | E12: 3431.1 | F12: =B12+E12 -> 11301.6 | G12: 3157.8 | H12: 3456.1 | I12: 5172.8 | L12: Verified | M12: SEC 6-K：Q3 2026 財務報表（季度摘要表 Q3 2025–Q3 2026、9M 2025／2026） | N12: stockhub.kr：Q3 2026 營業利益 €5.2B
A13: 權益投資評價益（Mistral AI；一次性） | B13: 0 | C13: 0 | D13: =B13-C13 -> 0 | E13: 0 | F13: =B13+E13 -> 0 | G13: 0 | H13: 0 | I13: 509.7 | J13: 0 | K13: =SUM(G13:J13) -> 509.7 | L13: Verified | M13: SEC 6-K：Q3 2026 財務報表（季度摘要表 Q3 2025–Q3 2026、9M 2025／2026）：Gain on equity investments | N13: Q3 2026 法說：初始投資的評價上升約 €0.5B
A14: 淨利 | B14: 6769.8 | C14: 2124.5 | D14: =B14-C14 -> 4645.3 | E14: 2839.6 | F14: =B14+E14 -> 9609.4 | G14: 2756.7 | H14: 2917.6 | I14: 4960.4 | J14: =J11*nioi -> 5763.9735 | K14: =SUM(G14:J14) -> 16398.673 | L14: Verified／Derived | M14: SEC 6-K：Q3 2026 財務報表（季度摘要表 Q3 2025–Q3 2026、9M 2025／2026）；J 欄＝第四季營業利益 × 淨利÷營業利益（FY2025 實績比例） | N14: Q4 2025 簡報：FY2025 €9,609M
A15: 加權平均股數（基本，百萬股） | B15: 389.2 | C15: 387.3 | E15: 386.5 | F15: =F14/F16 -> 388.57258 | G15: 385.4 | H15: 384.5 | I15: 383.1 | J15: =sh_q4 -> 381.5 | K15: =AVERAGE(G15:J15) -> 383.625 | L15: Verified／Derived | M15: SEC 6-K：Q3 2026 財務報表（季度摘要表 Q3 2025–Q3 2026、9M 2025／2026）；FY2025＝淨利 ÷ 基本 EPS | N15: J 欄為 Assumed（In 頁 sh_q4）
A16: EPS（基本，歐元） | B16: 17.39 | C16: 5.49 | D16: =B16-C16 -> 11.9 | E16: 7.35 | F16: 24.73 | G16: 7.15 | H16: 7.59 | I16: 12.95 | J16: =J14/J15 -> 15.108712 | K16: =K14/K15 -> 42.746624 | L16: Verified／Derived | M16: SEC 6-K：Q3 2026 財務報表（季度摘要表 Q3 2025–Q3 2026、9M 2025／2026）；FY2025 基本 24.73（Q4 2025 簡報） | N16: 稀釋 EPS：FY2025 24.71、Q3 2026 12.93；FY2026 錨點＝淨利 ÷ 四季平均股數
A17: 微影系統銷售台數（新＋二手） | B17: 225 | C17: 72 | D17: =B17-C17 -> 153 | E17: 102 | F17: =B17+E17 -> 327 | G17: 79 | H17: 91 | I17: 121 | L17: Verified | M17: SEC 6-K：Q3 2026 財務報表（季度摘要表 Q3 2025–Q3 2026、9M 2025／2026） | N17: Q4 2025 簡報：FY2025 327 台
A18: 檢查：營業利益（自算 − 公布） | B18: =B11-B12 -> 0 | C18: =C11-C12 -> 0 | D18: =D11-D12 -> 0 | E18: =E11-E12 -> 0 | F18: =F11-F12 -> 0 | G18: =G11-G12 -> 0 | H18: =H11-H12 -> 0 | I18: =I11-I12 -> 0 | L18: — | M18: — | N18: 應為 0
A21: 系統營收的組成（€M；公司法說）
A22: 項目 | B22: FY2025 | C22: Q1 2026 | D22: Q2 2026 | E22: Q3 2026 | F22: Q4 2026（Derived） | G22: FY2026 錨點 | L22: 標記 | M22: 來源1（公司） | N22: 來源2／說明
A23: EUV 系統營收 | B23: 11600 | C23: 4100 | D23: 3800 | E23: 4100 | F23: =G23-SUM(C23:E23) -> 4820 | G23: =B23*(1+g_euv) -> 16820 | L23: Verified／Derived | M23: Q4 2025 簡報：FY2025 €11.6B（+39%，48 台 NXE＋EXE）；Q1 法說「超過 €4.1B」（含 2 台 High-NA）、Q2 €3.8B（1 台）、Q3 €4.1B（1 台） | N23: FY2026＝FY2025 × (1＋45%)（公司「超過 45%」，故為下限）；Q4＝全年 − 前三季
A24: 非 EUV 系統營收（DUV＋量測檢測） | B24: =Q!F4-B23 -> 12874.3 | C24: =Q!G4-C23 -> 2179.4 | D24: =Q!H4-D23 -> 2764.8 | E24: =Q!I4-E23 -> 4273.2 | F24: =Q!J4-F23 -> 6180 | G24: =Q!K4-G23 -> 15397.4 | L24: Derived | M24: 系統營收 − EUV | N24: 公司：FY2025 DUV €12.0B（279 台，47% 浸潤式）、量測檢測 €825M；Q2 非 EUV €2.8B、Q3 €4.3B
A25: EUV 占系統營收 | B25: =B23/Q!F4 -> 0.47396657 | C25: =C23/Q!G4 -> 0.65292862 | D25: =D23/Q!H4 -> 0.57884475 | E25: =E23/Q!I4 -> 0.48965748 | F25: =F23/Q!J4 -> 0.43818182 | G25: =G23/Q!K4 -> 0.52207813 | L25: Derived | M25: — | N25: —
A26: 邏輯占系統營收 | B26: =a25_log/Q!F4 -> 0.65783291 | C26: 0.49 | D26: 0.51 | E26: 0.54 | G26: =log_sh26 -> 0.54643629 | L26: Verified／Derived | M26: Q1、Q2、Q3 2026 法說：49%／51%／54%；FY2025＝€16.1B ÷ 24,474 | N26: FY2026＝指引成長推得（In 頁 log_sh26）
A27: 中國占比 | B27: =cn_tot25 -> 0.33 | D27: 0.14 | E27: 0.23 | G27: =cn_sh26 -> 0.2 | L27: Interested-party | M27: FY2025 占總營收 33%（Caixin，公司揭露）；Q2、Q3 占系統出貨 14%／23%（aiweekly 2026-10-15） | N27: FY2026：公司約 20%（總營收），本模型套用於系統營收；Q1：未找到
A29: 讀法：FY2026 錨點營收 44,455 與指引中點 44,500 差 −0.1%；毛利率 55.7%（指引約 56%）。前三季淨利含 Mistral AI 評價益 509.7（一次性），FY2026 EPS 為報告口徑；FY2027 起淨利 ÷ 營業利益用 FY2025 實績比例（不含此項）。

Sheet Units
A1: Units — 晶圓前段設備支出（markets/equipment，US$B；三情境）→ 邏輯與記憶體指數（FY2026＝1）。ASML 會計年度＝日曆年，不需 3/4、1/4 轉換
A3: 項目 | B3: 單位 | C3: CY2025 | D3: CY2026 | E3: CY2027 | F3: CY2028 | G3: CY2029 | H3: 說明
A4: 情境 A
A5: 邏輯晶圓前段設備（先進邏輯＋其他代工與邏輯） | B5: US$B | C5: =laA_25+loA_25 -> 65.601346 | D5: =laA_26+loA_26 -> 82.259373 | E5: =laA_27+loA_27 -> 95.265723 | F5: =laA_28+loA_28 -> 107.26458 | G5: =laA_29+loA_29 -> 114.43775
A6: 記憶體晶圓前段設備（DRAM 含 HBM＋NAND） | B6: US$B | C6: =drA_25+naA_25 -> 38.548711 | D6: =drA_26+naA_26 -> 56.869852 | E6: =drA_27+naA_27 -> 76.50676 | F6: =drA_28+naA_28 -> 85.742221 | G6: =drA_29+naA_29 -> 89.505606
A7: 晶圓前段設備合計 | B7: US$B | C7: =wfA_25 -> 116.89683 | D7: =wfA_26 -> 156.15705 | E7: =wfA_27 -> 192.79547 | F7: =wfA_28 -> 216.62863 | G7: =wfA_29 -> 228.90369
A8: 邏輯指數（2026＝1） | B8: x | C8: =C5/$D5 -> 0.79749387 | D8: =D5/$D5 -> 1 | E8: =E5/$D5 -> 1.1581139 | F8: =F5/$D5 -> 1.30398 | G8: =G5/$D5 -> 1.3911819
A9: 記憶體指數（2026＝1） | B9: x | C9: =C6/$D6 -> 0.67784089 | D9: =D6/$D6 -> 1 | E9: =E6/$D6 -> 1.3452956 | F9: =F6/$D6 -> 1.507692 | G9: =G6/$D6 -> 1.5738674
A10: 其他（類比、功率、光罩、廠務）＝合計 − 邏輯 − 記憶體 | B10: US$B | C10: =C7-C5-C6 -> 12.746775 | D10: =D7-D5-D6 -> 17.027825 | E10: =E7-E5-E6 -> 21.022986 | F10: =F7-F5-F6 -> 23.621824 | G10: =G7-G5-G6 -> 24.960332 | H10: 不進 ASML 的需求指數（其他前段的微影含量低；Assumed）
A12: 情境 B
A13: 邏輯晶圓前段設備（先進邏輯＋其他代工與邏輯） | B13: US$B | C13: =laB_25+loB_25 -> 65.601346 | D13: =laB_26+loB_26 -> 82.259373 | E13: =laB_27+loB_27 -> 95.265723 | F13: =laB_28+loB_28 -> 95.265723 | G13: =laB_29+loB_29 -> 90.502437
A14: 記憶體晶圓前段設備（DRAM 含 HBM＋NAND） | B14: US$B | C14: =drB_25+naB_25 -> 38.548711 | D14: =drB_26+naB_26 -> 56.869852 | E14: =drB_27+naB_27 -> 76.50676 | F14: =drB_28+naB_28 -> 76.50676 | G14: =drB_29+naB_29 -> 72.681422
A15: 晶圓前段設備合計 | B15: US$B | C15: =wfB_25 -> 116.89683 | D15: =wfB_26 -> 156.15705 | E15: =wfB_27 -> 192.79547 | F15: =wfB_28 -> 192.79547 | G15: =wfB_29 -> 183.1557
A16: 邏輯指數（2026＝1） | B16: x | C16: =C13/$D13 -> 0.79749387 | D16: =D13/$D13 -> 1 | E16: =E13/$D13 -> 1.1581139 | F16: =F13/$D13 -> 1.1581139 | G16: =G13/$D13 -> 1.1002082
A17: 記憶體指數（2026＝1） | B17: x | C17: =C14/$D14 -> 0.67784089 | D17: =D14/$D14 -> 1 | E17: =E14/$D14 -> 1.3452956 | F17: =F14/$D14 -> 1.3452956 | G17: =G14/$D14 -> 1.2780308
A18: 其他（類比、功率、光罩、廠務）＝合計 − 邏輯 − 記憶體 | B18: US$B | C18: =C15-C13-C14 -> 12.746775 | D18: =D15-D13-D14 -> 17.027825 | E18: =E15-E13-E14 -> 21.022986 | F18: =F15-F13-F14 -> 21.022986 | G18: =G15-G13-G14 -> 19.971837 | H18: 不進 ASML 的需求指數（其他前段的微影含量低；Assumed）
A20: 情境 C
A21: 邏輯晶圓前段設備（先進邏輯＋其他代工與邏輯） | B21: US$B | C21: =laC_25+loC_25 -> 65.601346 | D21: =laC_26+loC_26 -> 82.259373 | E21: =laC_27+loC_27 -> 95.265723 | F21: =laC_28+loC_28 -> 76.212579 | G21: =laC_29+loC_29 -> 76.212579
A22: 記憶體晶圓前段設備（DRAM 含 HBM＋NAND） | B22: US$B | C22: =drC_25+naC_25 -> 38.548711 | D22: =drC_26+naC_26 -> 56.869852 | E22: =drC_27+naC_27 -> 76.50676 | F22: =drC_28+naC_28 -> 61.205408 | G22: =drC_29+naC_29 -> 61.205408
A23: 晶圓前段設備合計 | B23: US$B | C23: =wfC_25 -> 116.89683 | D23: =wfC_26 -> 156.15705 | E23: =wfC_27 -> 192.79547 | F23: =wfC_28 -> 154.23638 | G23: =wfC_29 -> 154.23638
A24: 邏輯指數（2026＝1） | B24: x | C24: =C21/$D21 -> 0.79749387 | D24: =D21/$D21 -> 1 | E24: =E21/$D21 -> 1.1581139 | F24: =F21/$D21 -> 0.92649112 | G24: =G21/$D21 -> 0.92649112
A25: 記憶體指數（2026＝1） | B25: x | C25: =C22/$D22 -> 0.67784089 | D25: =D22/$D22 -> 1 | E25: =E22/$D22 -> 1.3452956 | F25: =F22/$D22 -> 1.0762365 | G25: =G22/$D22 -> 1.0762365
A26: 其他（類比、功率、光罩、廠務）＝合計 − 邏輯 − 記憶體 | B26: US$B | C26: =C23-C21-C22 -> 12.746775 | D26: =D23-D21-D22 -> 17.027825 | E26: =E23-E21-E22 -> 21.022986 | F26: =F23-F21-F22 -> 16.818389 | G26: =G23-G21-G22 -> 16.818389 | H26: 不進 ASML 的需求指數（其他前段的微影含量低；Assumed）
A28: 讀法：邏輯指數 2027 約 1.16、記憶體約 1.35（三情境相同）；2028–29 依設備市場情境係數。設備市場的其他代工與記憶體廠含中國廠（中芯、長鑫等）；本模型另以中國系統營收列處理中國，指數的中國成分重疊（限制，見 README）。

Sheet PL
A1: PL — ASML 損益（€B；EPS 為歐元）。FY2025 為實績，FY2026 為錨點（前三季實績＋第四季公司指引；三情境相同），FY2027–FY2029 為模型。三情境各一個完整推導區塊（見下方），本頁頂端為摘要
A3: 情境／項目 | B3: 單位 | C3: FY2025A | D3: FY2026（錨點） | E3: FY2027 | F3: FY2028 | G3: FY2029 | H3: 說明
A4: 情境 A
A5: 營收 | B5: €B | C5: =C66 -> 32.6673 | D5: =D66 -> 44.4554 | E5: =E66 -> 53.148469 | F5: =F66 -> 59.976717 | G5: =G66 -> 65.151681
A6: 系統營收 | B6: €B | C6: =C62 -> 24.4743 | D6: =D62 -> 32.2174 | E6: =E62 -> 39.441909 | F6: =F62 -> 44.62537 | G6: =G62 -> 47.958173
A7: 裝機基礎管理（IBM） | B7: €B | C7: =C65 -> 8.193 | D7: =D65 -> 12.238 | E7: =E65 -> 13.70656 | F7: =F65 -> 15.351347 | G7: =G65 -> 17.193509
A8: 中國占系統營收 | B8: % | D8: =D64 -> 0.2 | E8: =E64 -> 0.16336633 | F8: =F64 -> 0.14439051 | G8: =G64 -> 0.13435625
A9: 毛利率 | B9: % | C9: =C69 -> 0.52829894 | D9: =D69 -> 0.55694471 | E9: =E69 -> 0.57354978 | F9: =F69 -> 0.58478703 | G9: =G69 -> 0.59248155
A10: 營業利益 | B10: €B | C10: =C72 -> 11.3016 | D10: =D72 -> 18.5657 | E10: =E72 -> 24.115018 | F10: =F72 -> 28.56805 | G10: =G72 -> 31.99157
A11: 營業利益率 | B11: % | C11: =C73 -> 0.34596064 | D11: =D73 -> 0.41762531 | E11: =E73 -> 0.45372931 | F11: =F73 -> 0.476319 | G11: =G73 -> 0.49103215
A12: 淨利 | B12: €B | C12: =C74 -> 9.6094 | D12: =D74 -> 16.398673 | E12: =E74 -> 20.504252 | F12: =F74 -> 24.290527 | G12: =G74 -> 27.20144
A13: EPS | B13: € | C13: =C76 -> 24.73 | D13: =D76 -> 42.746624 | E13: =E76 -> 54.289295 | F13: =F76 -> 64.963888 | G13: =G76 -> 73.483828
A15: 情境 B
A16: 營收 | B16: €B | C16: =C100 -> 32.6673 | D16: =D100 -> 44.4554 | E16: =E100 -> 52.014601 | F16: =F100 -> 53.482004 | G16: =G100 -> 53.371284
A17: 系統營收 | B17: €B | C17: =C96 -> 24.4743 | D17: =D96 -> 32.2174 | E17: =E96 -> 38.797561 | F17: =F96 -> 39.207601 | G17: =G96 -> 37.954929
A18: 裝機基礎管理（IBM） | B18: €B | C18: =C99 -> 8.193 | D18: =D99 -> 12.238 | E18: =E99 -> 13.21704 | F18: =F99 -> 14.274403 | G18: =G99 -> 15.416355
A19: 中國占系統營收 | B19: % | D19: =D98 -> 0.2 | E19: =E98 -> 0.14947156 | F19: =F98 -> 0.13311752 | G19: =G98 -> 0.12375987
A20: 毛利率 | B20: % | C20: =C103 -> 0.52829894 | D20: =D103 -> 0.55694471 | E20: =E103 -> 0.57154485 | F20: =F103 -> 0.5741314 | G20: =G103 -> 0.57393873
A21: 營業利益 | B21: €B | C21: =C106 -> 11.3016 | D21: =D106 -> 18.5657 | E21: =E106 -> 23.3832 | F21: =F106 -> 24.330718 | G21: =G106 -> 24.259093
A22: 營業利益率 | B22: % | C22: =C107 -> 0.34596064 | D22: =D107 -> 0.41762531 | E22: =E107 -> 0.44955069 | F22: =F107 -> 0.4549328 | G22: =G107 -> 0.45453456
A23: 淨利 | B23: €B | C23: =C108 -> 9.6094 | D23: =D108 -> 16.398673 | E23: =E108 -> 19.88201 | F23: =F108 -> 20.687655 | G23: =G108 -> 20.626755
A24: EPS | B24: € | C24: =C110 -> 24.73 | D24: =D110 -> 42.746624 | E24: =E110 -> 52.641777 | F24: =F110 -> 55.328174 | G24: =G110 -> 55.722523
A26: 情境 C
A27: 營收 | B27: €B | C27: =C134 -> 32.6673 | D27: =D134 -> 44.4554 | E27: =E134 -> 50.436179 | F27: =F134 -> 43.798458 | G27: =G134 -> 44.097563
A28: 系統營收 | B28: €B | C28: =C130 -> 24.4743 | D28: =D130 -> 32.2174 | E28: =E130 -> 37.831039 | F28: =F130 -> 30.815163 | G28: =G130 -> 30.72477
A29: 裝機基礎管理（IBM） | B29: €B | C29: =C133 -> 8.193 | D29: =D133 -> 12.238 | E29: =E133 -> 12.60514 | F29: =F133 -> 12.983294 | G29: =G133 -> 13.372793
A30: 中國占系統營收 | B30: % | D30: =D132 -> 0.2 | E30: =E132 -> 0.12774193 | F30: =F132 -> 0.11761929 | G30: =G132 -> 0.088473994
A31: 毛利率 | B31: % | C31: =C137 -> 0.52829894 | D31: =D137 -> 0.55694471 | E31: =E137 -> 0.56867985 | F31: =F137 -> 0.55556056 | G31: =G137 -> 0.55619332
A32: 營業利益 | B32: €B | C32: =C140 -> 11.3016 | D32: =D140 -> 18.5657 | E32: =E140 -> 22.368295 | F32: =F140 -> 18.152403 | G32: =G140 -> 18.340464
A33: 營業利益率 | B33: % | C33: =C141 -> 0.34596064 | D33: =D141 -> 0.41762531 | E33: =E141 -> 0.44349702 | F33: =F141 -> 0.41445303 | G33: =G141 -> 0.41590653
A34: 淨利 | B34: €B | C34: =C142 -> 9.6094 | D34: =D142 -> 16.398673 | E34: =E142 -> 19.019068 | F34: =F142 -> 15.434426 | G34: =G142 -> 15.594328
A35: EPS | B35: € | C35: =C144 -> 24.73 | D35: =D144 -> 42.746624 | E35: =E144 -> 50.356959 | F35: =F144 -> 41.278656 | G35: =G144 -> 42.127583
A37: 核對：FY2026 錨點 EPS − Q 頁（三情境，應為 0） | D37: =ABS(D13-a26_eps)+ABS(D24-a26_eps)+ABS(D35-a26_eps) -> 0
A50: 情境 A：基準（設備支出續增；中國持平；IBM +12%）
A51: 項目 | B51: 單位 | C51: FY2025A | D51: FY2026（錨點） | E51: FY2027 | F51: FY2028 | G51: FY2029 | H51: 說明
A52: A. 設備市場連結（Units 頁；情境別）
A53: 邏輯晶圓前段設備指數（2026＝1） | B53: x | C53: =Units!C8 -> 0.79749387 | D53: =Units!D8 -> 1 | E53: =Units!E8 -> 1.1581139 | F53: =Units!F8 -> 1.30398 | G53: =Units!G8 -> 1.3911819
A54: 記憶體晶圓前段設備指數（2026＝1） | B54: x | C54: =Units!C9 -> 0.67784089 | D54: =Units!D9 -> 1 | E54: =Units!E9 -> 1.3452956 | F54: =Units!F9 -> 1.507692 | G54: =Units!G9 -> 1.5738674
A55: 微影強度與價格係數（2026＝1） | B55: x | D55: =(1+g_int)^0 -> 1 | E55: =(1+g_int)^1 -> 1.03 | F55: =(1+g_int)^2 -> 1.0609 | G55: =(1+g_int)^3 -> 1.092727 | H55: (1＋g_int)^(t−2026)
A56: B. 系統營收（€B）
...

Sheet Val
A1: Val — P/E 估值（歐元）。跨公司規則：合理倍數＝10 年（2016–2025 年底）P/E 的分位，依循環位置：見頂年 25 分位、中段中位數、谷底 75 分位。循環位置依設備股共用規則（第 4 節；ASML 會計年度＝日曆年）
A2: P/E 定義（自算）：年底 ADR 收盤價（美元，未調整）÷（當年基本 EPS（歐元）× ECB 年底歐元兌美元）。ADR 與阿姆斯特丹普通股 1：1；當年即年底所在會計年度（會計年度＝日曆年）
A3: 目標價（DCF 與 Comparable 加權）：見本頁第 80 列起「0. 目標價」（估值 v2 新增，放在既有內容之後以免位移既有列）；原「0. 目標價與上檔空間」改名為「舊法：規則值情境加權（參考）」
A4: 舊法：規則值情境加權（參考）
A5: 項目 | B5: 數值 | E5: 說明
A6: 規則值情境加權價（12 個月；參考） | B6: =tp_wA*F55+tp_wB*F62+tp_wC*F69 -> 1829.1279 | E6: 權重 × 各情境隱含價（第 5 節規則值）
A7: 相對現價（規則值情境加權價 ÷ 現價 − 1） | B7: =B6/px-1 -> 0.29983505 | E7: 現價＝In 頁 px（2026-10-23 收盤）
A8: 情境 A 隱含價（樂觀） | B8: =F55 -> 1924.1569 | E8: ="FY2027 EPS × "&D49&" 倍數（第 5 節）" -> FY2027 EPS × 中段 倍數（第 5 節）
A9: 情境 B 隱含價（基準） | B9: =F62 -> 1865.7645 | E9: ="FY2027 EPS × "&D50&" 倍數（第 5 節）" -> FY2027 EPS × 中段 倍數（第 5 節）
A10: 情境 C 隱含價（下檔） | B10: =F69 -> 1594.9928 | E10: ="FY2027 EPS × "&D51&" 倍數（第 5 節）" -> FY2027 EPS × 見頂 倍數（第 5 節）
A11: 情境權重 A／B／C | B11: =tp_wA -> 0.3 | C11: =tp_wB -> 0.5 | D11: =tp_wC -> 0.2 | E11: ="合計 "&TEXT(B11+C11+D11,"0%")&"；In 頁 tp_wA／tp_wB／tp_wC（Assumed，Andy 可改）" -> 合計 100%；In 頁 tp_wA／tp_wB／tp_wC（Assumed，Andy 可改）
A12: 規則值方法 | B12: P/E：各情境 FY2027 EPS × 十年（2016–2025 年底）P/E 依循環位置取分位（設備股共用規則：A、B 中段＝中位數，C 見頂＝25 分位）。十年倍數含 2019–2021 年 EUV 量產與疫情後設備熱潮的高倍數（43–49x），偏誤方向為高估；隱含價約為 FY2027 年底的價格、未折現，當作 12 個月目標價時偏高
A14: 1. 價格與市場隱含倍數
A15: 項目 | B15: A | C15: B | D15: C | E15: 說明
A16: 現價（2026-10-23 收盤，Euronext Amsterdam） | B16: =px -> 1407.2
A17: 現價 ÷ FY2026 EPS（錨點） | B17: =px/PL!D13 -> 32.919559 | C17: =px/PL!D24 -> 32.919559 | D17: =px/PL!D35 -> 32.919559 | E17: FY2026 三情境相同（錨點）
A18: 現價 ÷ FY2027 EPS（模型） | B18: =px/PL!E13 -> 25.920396 | C18: =px/PL!E24 -> 26.73162 | D18: =px/PL!E35 -> 27.944499
A19: 現價 ÷ FY2028 EPS（模型） | B19: =px/PL!F13 -> 21.661265 | C19: =px/PL!F24 -> 25.433697 | D19: =px/PL!F35 -> 34.090258
A20: 現價 ÷ FY2029 EPS（模型） | B20: =px/PL!G13 -> 19.149792 | C20: =px/PL!G24 -> 25.253702 | D20: =px/PL!G35 -> 33.403293
A21: 前瞻 P/E（stockanalysis） | B21: =sa_fpe -> 24.48 | E21: 近 12 月 P/E 40.24（同站）
A22: 現價 ÷ 共識 FY2027 EPS | B22: =px/cons_eps27 -> 25.160021
A24: 2. 10 年 P/E（年底）
A25: 年底 | B25: ADR 收盤價 US$（未調整） | C25: 基本 EPS € | D25: ECB 年底 US$/€ | E25: EPS 換美元 | F25: P/E 自算 | G25: companiesmarketcap P/E | H25: 自算 − cmc | I25: 標記 | J25: 來源／說明
A26: 2016-12 | B26: 112.2 | C26: 3.46 | D26: 1.0541 | E26: =C26*D26 -> 3.647186 | F26: =B26/E26 -> 30.763443 | G26: 27.3 | H26: =F26-G26 -> 3.4634434 | I26: Verified／Interested-party | J26: 價格：digrin（未調整 Real price）；EPS：Q4 2017 新聞稿（6-K）：2016 基本 3.46；匯率：ECB 參考匯率
A27: 2017-12 | B27: 173.82 | C27: 4.93 | D27: 1.1993 | E27: =C27*D27 -> 5.912549 | F27: =B27/E27 -> 29.398488 | G27: 28.4 | H27: =F27-G27 -> 0.99848786 | I27: Verified／Interested-party | J27: 價格：digrin（未調整 Real price）；EPS：同上：2017 基本 4.93；匯率：ECB 參考匯率
A28: 2018-12 | B28: 155.62 | C28: 6.1 | D28: 1.145 | E28: =C28*D28 -> 6.9845 | F28: =B28/E28 -> 22.280765 | G28: 20.4 | H28: =F28-G28 -> 1.8807646 | I28: Verified／Interested-party | J28: 價格：digrin（未調整 Real price）；EPS：Q4 2019 新聞稿（6-K）：2018 基本 6.10；匯率：ECB 參考匯率
A29: 2019-12 | B29: 295.94 | C29: 6.16 | D29: 1.1234 | E29: =C29*D29 -> 6.920144 | F29: =B29/E29 -> 42.765006 | G29: 41 | H29: =F29-G29 -> 1.765006 | I29: Verified／Interested-party | J29: 價格：digrin（未調整 Real price）；EPS：同上：2019 基本 6.16；匯率：ECB 參考匯率
A30: 2020-12 | B30: 487.72 | C30: 8.49 | D30: 1.2271 | E30: =C30*D30 -> 10.418079 | F30: =B30/E30 -> 46.814773 | G30: 46.9 | H30: =F30-G30 -> -0.085227334 | I30: Verified／Interested-party | J30: 價格：digrin（未調整 Real price）；EPS：Q4 2020 新聞稿（6-K）：基本 8.49；匯率：ECB 參考匯率
A31: 2021-12 | B31: 796.14 | C31: 14.36 | D31: 1.1326 | E31: =C31*D31 -> 16.264136 | F31: =B31/E31 -> 48.950648 | G31: 46.1 | H31: =F31-G31 -> 2.8506482 | I31: Verified／Interested-party | J31: 價格：digrin（未調整 Real price）；EPS：Q4 2022 新聞稿（6-K）：2021 基本 14.36；匯率：ECB 參考匯率
A32: 2022-12 | B32: 546.4 | C32: 14.14 | D32: 1.0666 | E32: =C32*D32 -> 15.081724 | F32: =B32/E32 -> 36.22928 | G32: 36.2 | H32: =F32-G32 -> 0.029279889 | I32: Verified／Interested-party | J32: 價格：digrin（未調整 Real price）；EPS：同上：2022 基本 14.14；匯率：ECB 參考匯率
A33: 2023-12 | B33: 756.92 | C33: 19.91 | D33: 1.105 | E33: =C33*D33 -> 22.00055 | F33: =B33/E33 -> 34.404594 | G33: 34.6 | H33: =F33-G33 -> -0.19540557 | I33: Verified／Interested-party | J33: 價格：digrin（未調整 Real price）；EPS：Q4 2024 新聞稿（6-K）：2023 基本 19.91；匯率：ECB 參考匯率
A34: 2024-12 | B34: 693.08 | C34: 19.25 | D34: 1.0389 | E34: =C34*D34 -> 19.998825 | F34: =B34/E34 -> 34.656036 | G34: 33.4 | H34: =F34-G34 -> 1.256036 | I34: Verified／Interested-party | J34: 價格：digrin（未調整 Real price）；EPS：同上：2024 基本 19.25；匯率：ECB 參考匯率
A35: 2025-12 | B35: 1069.86 | C35: 24.73 | D35: 1.175 | E35: =C35*D35 -> 29.05775 | F35: =B35/E35 -> 36.818405 | G35: 37.5 | H35: =F35-G35 -> -0.68159527 | I35: Verified／Interested-party | J35: 價格：digrin（未調整 Real price）；EPS：Q4 2025 簡報（6-K）：基本 24.73；匯率：ECB 參考匯率
A36: 來源：ADR 年底收盤價＝digrin.com（Real price；Macrotrends 的調整後價格作數量級對照）；EPS＝ASML 各年第四季新聞稿（SEC 6-K），2021–2025 另以 stockanalysis 稀釋 EPS（14.34、14.13、19.89、19.24、24.71）交叉；匯率＝ECB 各年最後營業日參考匯率。cmc（companiesmarketcap）為美元計價 TTM 口徑，作第二來源對照（差距見 H 欄）。Euronext 年底收盤價：未找到（改用 ADR，口徑相同）。
A38: 3. 分位
A39: 統計 | B39: P/E 自算 | C39: cmc P/E（參考） | D39: 用途
A40: 25 分位 | B40: =PERCENTILE(F26:F35,0.25) -> 31.673731 | C40: =PERCENTILE(G26:G35,0.25) -> 29.65 | D40: 見頂年
A41: 中位數 | B41: =PERCENTILE(F26:F35,0.5) -> 35.442658 | C41: =PERCENTILE(G26:G35,0.5) -> 35.4 | D41: 中段
A42: 75 分位 | B42: =PERCENTILE(F26:F35,0.75) -> 41.278356 | C42: =PERCENTILE(G26:G35,0.75) -> 40.125 | D42: 谷底
A43: 年數 | B43: =COUNT(F26:F35) -> 10 | C43: =COUNT(G26:G35) -> 10
...

Sheet Recon
A1: Recon — 本模型 vs 公司指引、共識、公司 2030 目標、設備市場與產能。只作事後對照，不為對上數字而調整參數。差距 > 10% 的原因見 README
A3: 項目 | B3: 對照值 | C3: 模型 A | D3: 差距 A | E3: 模型 B | F3: 差距 B | G3: 模型 C | H3: 差距 C | I3: 對照來源 | J3: 說明
A4: A. FY2026 錨點 vs 公司全年指引（錨點用第四季指引，故差距小；非獨立檢驗）
A5: 營收（€B） | B5: =g_fy_rev/1000 -> 44.5 | C5: =PL!D5 -> 44.4554 | D5: =C5/B5-1 -> -0.0010022472 | E5: =PL!D16 -> 44.4554 | F5: =E5/B5-1 -> -0.0010022472 | G5: =PL!D27 -> 44.4554 | H5: =G5/B5-1 -> -0.0010022472 | I5: Q3 2026 新聞稿：€44–45B 中點
A6: 毛利率（差距以百分點計） | B6: =g_fy_gm -> 0.56 | C6: =PL!D9 -> 0.55694471 | D6: =C6-B6 -> -0.0030552869 | E6: =PL!D20 -> 0.55694471 | F6: =E6-B6 -> -0.0030552869 | G6: =PL!D31 -> 0.55694471 | H6: =G6-B6 -> -0.0030552869 | I6: 同上：約 56%
A7: IBM 成長（差距以百分點計） | B7: =g_ibm26 -> 0.5 | C7: =PL!D65/PL!C65-1 -> 0.49371415 | D7: =C7-B7 -> -0.0062858538 | E7: =PL!D99/PL!C99-1 -> 0.49371415 | F7: =E7-B7 -> -0.0062858538 | G7: =PL!D133/PL!C133-1 -> 0.49371415 | H7: =G7-B7 -> -0.0062858538 | I7: Q3 2026 法說：約 +50%
A8: 系統營收（€B）vs 指引成長推得（邏輯 +10%、記憶體 +75%） | B8: =(a25_log*(1+g_log)+a25_mem*(1+g_mem))/1000 -> 32.41 | C8: =PL!D6 -> 32.2174 | D8: =C8/B8-1 -> -0.0059426103 | E8: =PL!D17 -> 32.2174 | F8: =E8/B8-1 -> -0.0059426103 | G8: =PL!D28 -> 32.2174 | H8: =G8/B8-1 -> -0.0059426103 | I8: Q3 2026 法說 | J8: 獨立檢驗：錨點系統營收（由第四季總營收與 IBM 指引推得）vs 邏輯／記憶體成長指引
A9: B. vs 共識（stockanalysis 2026-10-17；eulerpool）
A10: FY2026 營收（€B） | B10: =cons_rev26/1000 -> 44.46 | C10: =PL!D5 -> 44.4554 | D10: =C10/B10-1 -> -0.00010346379 | E10: =PL!D16 -> 44.4554 | F10: =E10/B10-1 -> -0.00010346379 | G10: =PL!D27 -> 44.4554 | H10: =G10/B10-1 -> -0.00010346379 | I10: stockanalysis 44.46B
A11: FY2026 EPS（€） | B11: =cons_eps26 -> 41.21 | C11: =PL!D13 -> 42.746624 | D11: =C11/B11-1 -> 0.037287639 | E11: =PL!D24 -> 42.746624 | F11: =E11/B11-1 -> 0.037287639 | G11: =PL!D35 -> 42.746624 | H11: =G11/B11-1 -> 0.037287639 | I11: stockanalysis 41.21（non-GAAP；eulerpool 41.24） | J11: 模型為報告口徑，含 Mistral 評價益約 €1.3／股
A12: FY2027 營收（€B） | B12: =cons_rev27/1000 -> 57.21 | C12: =PL!E5 -> 53.148469 | D12: =C12/B12-1 -> -0.070993368 | E12: =PL!E16 -> 52.014601 | F12: =E12/B12-1 -> -0.09081277 | G12: =PL!E27 -> 50.436179 | H12: =G12/B12-1 -> -0.11840274 | I12: stockanalysis 57.21B
A13: FY2027 EPS（€） | B13: =cons_eps27 -> 55.93 | C13: =PL!E13 -> 54.289295 | D13: =C13/B13-1 -> -0.029334976 | E13: =PL!E24 -> 52.641777 | F13: =E13/B13-1 -> -0.058791756 | G13: =PL!E35 -> 50.356959 | H13: =G13/B13-1 -> -0.09964315 | I13: stockanalysis 55.93（eulerpool 隱含 56.7）
A14: FY2028 EPS（€；eulerpool P/E 18.80 隱含） | B14: =px/eul_pe28 -> 74.851064 | C14: =PL!F13 -> 64.963888 | D14: =C14/B14-1 -> -0.13209132 | E14: =PL!F24 -> 55.328174 | F14: =E14/B14-1 -> -0.26082315 | G14: =PL!F35 -> 41.278656 | H14: =G14/B14-1 -> -0.44852279 | I14: eulerpool（單一來源）
A15: C. FY2029 vs 公司 2030 目標（2024 投資人日；目標年較模型末年晚一年）
A16: 營收（€B）vs 目標下緣 44 | B16: =t30_rev_lo/1000 -> 44 | C16: =PL!G5 -> 65.151681 | D16: =C16/B16-1 -> 0.48072003 | E16: =PL!G16 -> 53.371284 | F16: =E16/B16-1 -> 0.21298374 | G16: =PL!G27 -> 44.097563 | H16: =G16/B16-1 -> 0.0022173445 | I16: 公司：€44–60B
A17: 營收（€B）vs 目標上緣 60 | B17: =t30_rev_hi/1000 -> 60 | C17: =PL!G5 -> 65.151681 | D17: =C17/B17-1 -> 0.085861358 | E17: =PL!G16 -> 53.371284 | F17: =E17/B17-1 -> -0.11047859 | G17: =PL!G27 -> 44.097563 | H17: =G17/B17-1 -> -0.26504061 | I17: 同上
A18: 毛利率 vs 目標中點 58%（百分點） | B18: =(t30_gm_lo+t30_gm_hi)/2 -> 0.58 | C18: =PL!G9 -> 0.59248155 | D18: =C18-B18 -> 0.012481551 | E18: =PL!G20 -> 0.57393873 | F18: =E18-B18 -> -0.0060612705 | G18: =PL!G31 -> 0.55619332 | H18: =G18-B18 -> -0.023806679 | I18: 公司：56–60%
A19: D. 微影占晶圓前段設備（ASML 系統營收換美元 ÷ 設備市場模型；FY2025 對照 SEMI 實績）
A20: FY2025：ASML 占 SEMI 晶圓前段設備實績（百分點） | B20: =a25_sys/1000*fx_25/semi_wfe_25 -> 0.23658433 | C20: =PL!C81 -> 0.23658433 | D20: =C20-B20 -> 0 | E20: =PL!C115 -> 0.23658433 | F20: =E20-B20 -> 0 | G20: =PL!C149 -> 0.23658433 | H20: =G20-B20 -> 0 | I20: SEMI 2025 實績（設備市場模型） | J20: 設備市場 2025 以 SEMI 實績校準，差距必為 0（恆等式）；比例本身約 23.7%
A21: FY2026：ASML 占晶圓前段設備（各情境） | B21: =PL!C81 -> 0.23658433 | C21: =PL!D81 -> 0.23932435 | D21: =C21-B21 -> 0.0027400129 | E21: =PL!D115 -> 0.23932435 | F21: =E21-B21 -> 0.0027400129 | G21: =PL!D149 -> 0.23932435 | H21: =G21-B21 -> 0.0027400129 | I21: 對照值＝FY2025 比例 | J21: 比例上升＝微影強度與價格（g_int）＋記憶體比重上升；FY2026 起匯率 Assumed
A22: FY2027：ASML 占晶圓前段設備（各情境） | B22: =PL!C81 -> 0.23658433 | C22: =PL!E81 -> 0.23731167 | D22: =C22-B22 -> 0.00072733748 | E22: =PL!E115 -> 0.2334348 | F22: =E22-B22 -> -0.0031495362 | G22: =PL!E149 -> 0.22761949 | H22: =G22-B22 -> -0.0089648467 | I22: 對照值＝FY2025 比例 | J22: 比例上升＝微影強度與價格（g_int）＋記憶體比重上升；FY2026 起匯率 Assumed
A23: FY2028：ASML 占晶圓前段設備（各情境） | B23: =PL!C81 -> 0.23658433 | C23: =PL!F81 -> 0.23895932 | D23: =C23-B23 -> 0.0023749878 | E23: =PL!F115 -> 0.2359019 | F23: =E23-B23 -> -0.00068243449 | G23: =PL!F149 -> 0.23175849 | H23: =G23-B23 -> -0.0048258432 | I23: 對照值＝FY2025 比例 | J23: 比例上升＝微影強度與價格（g_int）＋記憶體比重上升；FY2026 起匯率 Assumed
A24: FY2029：ASML 占晶圓前段設備（各情境） | B24: =PL!C81 -> 0.23658433 | C24: =PL!G81 -> 0.24303445 | D24: =C24-B24 -> 0.0064501119 | E24: =PL!G115 -> 0.2403841 | F24: =E24-B24 -> 0.0037997697 | G24: =PL!G149 -> 0.23107865 | H24: =G24-B24 -> -0.0055056836 | I24: 對照值＝FY2025 比例 | J24: 比例上升＝微影強度與價格（g_int）＋記憶體比重上升；FY2026 起匯率 Assumed
A25: E. 產能與 EUV 台數
A26: FY2027 隱含 Low-NA EUV 台數 vs 公司 2027 產能「至少 80 台」 | B26: =euv_cap27 -> 80 | C26: =PL!E79 -> 85.877501 | D26: =C26/B26-1 -> 0.07346876 | E26: =PL!E113 -> 84.266631 | F26: =E26/B26-1 -> 0.053332885 | G26: =PL!E147 -> 81.850326 | H26: =G26/B26-1 -> 0.023129072 | I26: Q1 2026 法說 | J26: 由 EUV 占比、High-NA 台數與單價（皆 Assumed）推得；超過產能代表 EUV 占比或單價假設偏高
A27: FY2027：系統需求 ÷ 產能上限 | B27: =1 -> 1 | C27: =PL!E60/PL!E61 -> 0.9142961 | D27: =C27-B27 -> -0.085703905 | E27: =PL!E94/PL!E95 -> 0.89935958 | F27: =E27-B27 -> -0.10064042 | G27: =PL!E128/PL!E129 -> 0.8769548 | H27: =G27-B27 -> -0.1230452 | I27: 產能上限＝FY2026 × 產能成長 × 強度係數 | J27: >100%＝產能限制生效（系統營收取上限）
A28: FY2028：系統需求 ÷ 產能上限 | B28: =1 -> 1 | C28: =PL!F60/PL!F61 -> 0.87332461 | D28: =C28-B28 -> -0.12667539 | E28: =PL!F94/PL!F95 -> 0.76729813 | F28: =E28-B28 -> -0.23270187 | G28: =PL!F128/PL!F129 -> 0.60305697 | H28: =G28-B28 -> -0.39694303 | I28: 產能上限＝FY2026 × 產能成長 × 強度係數 | J28: >100%＝產能限制生效（系統營收取上限）
A29: FY2029：系統需求 ÷ 產能上限 | B29: =1 -> 1 | C29: =PL!G60/PL!G61 -> 0.82837424 | D29: =C29-B29 -> -0.17162576 | E29: =PL!G94/PL!G95 -> 0.65558973 | F29: =E29-B29 -> -0.34441027 | G29: =PL!G128/PL!G129 -> 0.53070429 | H29: =G29-B29 -> -0.46929571 | I29: 產能上限＝FY2026 × 產能成長 × 強度係數 | J29: >100%＝產能限制生效（系統營收取上限）
A30: F. 中國占比路徑
A31: FY2025 中國占總營收 33% vs 模型 FY2029 中國占系統營收（百分點） | B31: =cn_tot25 -> 0.33 | C31: =PL!G8 -> 0.13435625 | D31: =C31-B31 -> -0.19564375 | E31: =PL!G19 -> 0.12375987 | F31: =E31-B31 -> -0.20624013 | G31: =PL!G30 -> 0.088473994 | H31: =G31-B31 -> -0.24152601 | I31: Caixin（公司揭露） | J31: 口徑不同（總營收 vs 系統），只看方向

Sheet Sens
A1: Sens — 一次動一個輸入（情境 A）：對 FY2027、FY2028 營收與 EPS 的影響。每個案例是一個完整的推導區塊（本頁下方，與 PL 同一引擎）
A3: 案例 | B3: 設定 | C3: FY2027 營收 €B | D3: FY2027 EPS € | E3: 相對基準 | F3: FY2028 營收 €B | G3: FY2028 EPS € | H3: 相對基準
A4: 基準（情境 A） | B4: PL 區塊 A | C4: =PL!E66 -> 53.148469 | D4: =PL!E76 -> 54.289295 | E4: =D4/D$4-1 -> 0 | F4: =PL!F66 -> 59.976717 | G4: =PL!F76 -> 64.963888 | H4: =G4/G$4-1 -> 0
A5: 微影強度與價格 0%／年 | B5: g_int＝0 | C5: =E66 -> 52.18735 | D5: =E76 -> 52.892451 | E5: =D5/D$4-1 -> -0.02572964 | F5: =F66 -> 57.784921 | G5: =F76 -> 61.69461 | H5: =G5/G$4-1 -> -0.050324549
A6: 微影強度與價格 +6%／年 | B6: g_int＝6% | C6: =E106 -> 54.109589 | D6: =E116 -> 55.689777 | E6: =D6/D$4-1 -> 0.025796652 | F6: =F106 -> 62.233296 | G6: =F116 -> 68.347485 | H6: =G6/G$4-1 -> 0.052084278
A7: 中國占 FY2026 系統 17% | B7: 非中國基期較大 | C7: =E146 -> 53.419389 | D7: =E156 -> 54.683696 | E7: =D7/D$4-1 -> 0.0072647977 | F7: =F146 -> 60.442016 | G7: =F156 -> 65.660127 | H7: =G7/G$4-1 -> 0.010717324
A8: 中國占 FY2026 系統 23% | B8: 非中國基期較小 | C8: =E186 -> 52.87755 | D8: =E196 -> 53.895183 | E8: =D8/D$4-1 -> -0.0072594735 | F8: =F186 -> 59.511419 | G8: =F196 -> 64.268412 | H8: =G8/G$4-1 -> -0.010705576
A9: 中國年成長 −10% | B9: 情境 A 基準 0% | C9: =E226 -> 52.504121 | D9: =E236 -> 53.352425 | E9: =D9/D$4-1 -> -0.017256994 | F9: =F226 -> 58.752456 | G9: =F236 -> 63.135655 | H9: =G9/G$4-1 -> -0.028142299
A10: 中國年成長 +10% | C10: =E266 -> 53.792817 | D10: =E276 -> 55.2278 | E10: =D10/D$4-1 -> 0.017287112 | F10: =F266 -> 61.329848 | G10: =F276 -> 66.99071 | H10: =G10/G$4-1 -> 0.031199205
A11: IBM 年成長 +8% | B11: 基準 +12% | C11: =E306 -> 52.658949 | D11: =E316 -> 53.577392 | E11: =D11/D$4-1 -> -0.013113143 | F11: =F306 -> 58.899773 | G11: =F316 -> 63.355366 | H11: =G11/G$4-1 -> -0.024760254
A12: IBM 年成長 +16% | C12: =E346 -> 53.637989 | D12: =E356 -> 55.002142 | E12: =D12/D$4-1 -> 0.013130526 | F12: =F346 -> 61.092823 | G12: =F356 -> 66.635216 | H12: =G12/G$4-1 -> 0.025727023
A13: 毛利率斜率 ×0.5 | B13: 營收規模帶動毛利率的效果減半 | C13: =E386 -> 53.148469 | D13: =E396 -> 53.295886 | E13: =D13/D$4-1 -> -0.018298425 | F13: =F386 -> 59.976717 | G13: =F396 -> 63.065218 | H13: =G13/G$4-1 -> -0.029226549
A14: 毛利率斜率 ×1.5 | C14: =E426 -> 53.148469 | D14: =E436 -> 55.282703 | E14: =D14/D$4-1 -> 0.018298425 | F14: =F426 -> 59.976717 | G14: =F436 -> 66.862558 | H14: =G14/G$4-1 -> 0.029226549
A15: 營業費用全固定（phi＝0） | C15: =E466 -> 53.148469 | D15: =E476 -> 54.682758 | E15: =D15/D$4-1 -> 0.007247531 | F15: =F466 -> 59.976717 | G15: =F476 -> 65.673506 | H15: =G15/G$4-1 -> 0.010923266
A16: 營業費用變動比例 40% | B16: 營業費用隨營收成長較多 | C16: =E506 -> 53.148469 | D16: =E516 -> 53.592143 | E16: =D16/D$4-1 -> -0.012841415 | F16: =F506 -> 59.976717 | G16: =F516 -> 63.706564 | H16: =G16/G$4-1 -> -0.019354204
A17: 2027 產能 +20% | B17: Low-NA「至少 80 台」的下緣口徑 | C17: =E546 -> 53.148469 | D17: =E556 -> 54.289295 | E17: =D17/D$4-1 -> 0 | F17: =F546 -> 59.976717 | G17: =F556 -> 64.963888 | H17: =G17/G$4-1 -> 0
A18: 2028 產能 0% | C18: =E586 -> 53.148469 | D18: =E596 -> 54.289295 | E18: =D18/D$4-1 -> 0 | F18: =F586 -> 59.784619 | G18: =F596 -> 64.676668 | H18: =G18/G$4-1 -> -0.0044212261
A19: 淨利÷營業利益 0.80 | C19: =E626 -> 53.148469 | D19: =E636 -> 51.079642 | E19: =D19/D$4-1 -> -0.059121277 | F19: =F626 -> 59.976717 | G19: =F636 -> 61.12314 | H19: =G19/G$4-1 -> -0.059121277
A20: 淨利÷營業利益 0.87 | C20: =E666 -> 53.148469 | D20: =E676 -> 55.549111 | E20: =D20/D$4-1 -> 0.023205611 | F20: =F666 -> 59.976717 | G20: =F676 -> 66.471415 | H20: =G20/G$4-1 -> 0.023205611
A21: 買回 0%／年 | C21: =E706 -> 53.148469 | D21: =E716 -> 53.746402 | E21: =D21/D$4-1 -> -0.01 | F21: =F706 -> 59.976717 | G21: =F716 -> 63.671107 | H21: =G21/G$4-1 -> -0.0199
A22: 買回 2%／年 | C22: =E746 -> 53.148469 | D22: =E756 -> 54.843267 | E22: =D22/D$4-1 -> 0.010204082 | F22: =F746 -> 59.976717 | G22: =F756 -> 66.296446 | H22: =G22/G$4-1 -> 0.020512287
A23: 情境 B | B23: 設備支出 2028 持平；中國 −10%；IBM +8% | C23: =PL!E100 -> 52.014601 | D23: =PL!E110 -> 52.641777 | E23: =D23/D$4-1 -> -0.030347009 | F23: =PL!F100 -> 53.482004 | G23: =PL!F110 -> 55.328174 | H23: =G23/G$4-1 -> -0.14832417
A24: 情境 C | B24: 設備支出 2028 −20%；中國 −25%；IBM +3% | C24: =PL!E134 -> 50.436179 | D24: =PL!E144 -> 50.356959 | E24: =D24/D$4-1 -> -0.072432995 | F24: =PL!F134 -> 43.798458 | G24: =PL!F144 -> 41.278656 | H24: =G24/G$4-1 -> -0.36459075
A26: 讀法：FY2027 三個設備情境相同（設備市場模型 2027 年三情境相同），B、C 在 FY2027 的差異只來自中國與 IBM；設備情境的差異從 FY2028 才出現。產能上限在基準下未生效（Recon），所以產能案例對 EPS 影響為 0 時，代表需求低於產能。
A50: 案例區塊：微影強度與價格 0%／年（情境 A）
A51: 項目 | B51: 單位 | C51: FY2025A | D51: FY2026（錨點） | E51: FY2027 | F51: FY2028 | G51: FY2029 | H51: 說明
A52: A. 設備市場連結（Units 頁；情境別）
A53: 邏輯晶圓前段設備指數（2026＝1） | B53: x | C53: =Units!C8 -> 0.79749387 | D53: =Units!D8 -> 1 | E53: =Units!E8 -> 1.1581139 | F53: =Units!F8 -> 1.30398 | G53: =Units!G8 -> 1.3911819
A54: 記憶體晶圓前段設備指數（2026＝1） | B54: x | C54: =Units!C9 -> 0.67784089 | D54: =Units!D9 -> 1 | E54: =Units!E9 -> 1.3452956 | F54: =Units!F9 -> 1.507692 | G54: =Units!G9 -> 1.5738674
A55: 微影強度與價格係數（2026＝1） | B55: x | D55: =(1+g_int_lo)^0 -> 1 | E55: =(1+g_int_lo)^1 -> 1 | F55: =(1+g_int_lo)^2 -> 1 | G55: =(1+g_int_lo)^3 -> 1 | H55: (1＋g_int)^(t−2026)
A56: B. 系統營收（€B）
A57: 非中國 邏輯系統需求 | B57: €B | D57: =a26_sys/1000*(1-cn_sh26)*log_sh26 -> 14.083805 | E57: =$D57*E53*E55 -> 16.31065 | F57: =$D57*F53*F55 -> 18.365001 | G57: =$D57*G53*G55 -> 19.593134 | H57: FY2026＝錨點系統營收 ×（1−中國占比）× 邏輯占比；之後 × 邏輯指數 × 強度係數
A58: 非中國 記憶體系統需求 | B58: €B | D58: =a26_sys/1000*(1-cn_sh26)*(1-log_sh26) -> 11.690115 | E58: =$D58*E54*E55 -> 15.72666 | F58: =$D58*F54*F55 -> 17.625093 | G58: =$D58*G54*G55 -> 18.398691
A59: 中國系統需求 | B59: €B | D59: =a26_sys/1000*cn_sh26 -> 6.44348 | E59: =D59*(1+g_cn_A) -> 6.44348 | F59: =E59*(1+g_cn_A) -> 6.44348 | G59: =F59*(1+g_cn_A) -> 6.44348 | H59: FY2026＝錨點 × 中國占比；之後 × (1＋中國年成長)
A60: 系統需求合計 | B60: €B | D60: =D57+D58+D59 -> 32.2174 | E60: =E57+E58+E59 -> 38.48079 | F60: =F57+F58+F59 -> 42.433574 | G60: =G57+G58+G59 -> 44.435305
A61: 系統產能上限（FY2026 錨點 × 產能成長 × 強度係數） | B61: €B | D61: =a26_sys/1000 -> 32.2174 | E61: =$D61*(1+cap_27)*E55 -> 41.88262 | F61: =$D61*(1+cap_27)*(1+cap_28)*F55 -> 48.165013 | G61: =$D61*(1+cap_27)*(1+cap_28)*(1+cap_29)*G55 -> 52.981514 | H61: 公司稱 2026 產能已滿（供不應求）；上限只在需求超過時生效
A62: 系統營收＝MIN(需求, 產能) | B62: €B | C62: =a25_sys/1000 -> 24.4743 | D62: =a26_sys/1000 -> 32.2174 | E62: =MIN(E60,E61) -> 38.48079 | F62: =MIN(F60,F61) -> 42.433574 | G62: =MIN(G60,G61) -> 44.435305
A63: 產能限制生效（1＝是） | E63: =IF(E60>E61,1,0) -> 0 | F63: =IF(F60>F61,1,0) -> 0 | G63: =IF(G60>G61,1,0) -> 0
A64: 中國占系統營收 | B64: % | D64: =D59/D60 -> 0.2 | E64: =E59/E60 -> 0.16744667 | F64: =F59/F60 -> 0.15184863 | G64: =G59/G60 -> 0.14500812 | H64: 產能限制時各組成同比例縮減
A65: 裝機基礎管理（IBM）營收 | B65: €B | C65: =a25_ibm/1000 -> 8.193 | D65: =a26_ibm/1000 -> 12.238 | E65: =D65*(1+g_ibm_A) -> 13.70656 | F65: =E65*(1+g_ibm_A) -> 15.351347 | G65: =F65*(1+g_ibm_A) -> 17.193509
...

Sheet Sources
A1: 來源（SEC 6-K 為公司原文；asml.com 的 PDF 與第三方頁面經搜尋引擎摘錄或擷取讀取）
A2: 公司：Q3 2026 新聞稿（SEC 6-K，2026-10-14） | B2: https://www.sec.gov/Archives/edgar/data/0000937966/000162828026065813/pressreleasefinancialresul.htm
A3: 公司：Q3 2026 財務報表（季度摘要 Q3 2025–Q3 2026、9M） | B3: https://www.sec.gov/Archives/edgar/data/0000937966/000162828026065813/financial_statementsxusx.htm
A4: 公司：Q3 2026 簡報（第四季與全年 2026 指引、IBM、稅率） | B4: https://www.sec.gov/Archives/edgar/data/0000937966/000162828026065813/a2026_10x14xpresentation.htm
A5: Q3 2026 法說逐字稿（Benzinga；EUV €4.1B、邏輯 54%、中國約 20%、Mistral 評價益） | B5: https://www.benzinga.com/news/26/10/62356129
A6: stockhub.kr：Q3 2026 摘要（營業利益 €5.2B、稀釋 EPS 12.93） | B6: https://www.stockhub.kr/en/insights/asml-cy2026-q3-earnings-20261014
A7: aiweekly：Q3 2026 中國占系統出貨 23%（Q2 14%） | B7: https://aiweekly.co/alerts/asml-q3-china-equipment-sales-soar-109-qoq-to-23-of-system-shipments-as-memory
A8: 公司：Q2 2026 法說逐字稿（2026-07-15） | B8: https://ourbrand.asml.com/asset/1fd3908a-0381-47b5-9b69-a3094f656651/2026_07_15-ASML-Transcript-investor-call-Q2-2026.pdf
A9: 公司：Q1 2026 法說逐字稿（2026-04-15；2027 Low-NA 至少 80 台） | B9: https://ourbrand.asml.com/asset/8e1f7393-33dd-4737-a436-cfe1b68cc577/2026_04_15-ASML-Transcript-investor-call-Q1-2026.pdf
A10: 公司：Q4 2025 簡報（SEC 6-K，2026-01-28；FY2025 EUV、DUV、IBM、買回 €12B） | B10: https://www.sec.gov/Archives/edgar/data/937966/000162828026003701/a2026_01x28xpresentation.htm
A11: 公司：Q4 2025 法說逐字稿（邏輯 €16.1B、記憶體 €8.4B） | B11: https://ourbrand.asml.com/m/285dcba22c2bf203/original/2026_01_28-ASML-Transcript-investor-call-Q4-2025.pdf
A12: Caixin：ASML 2025 中國占 33%、2026 約 20%（2026-01-29） | B12: https://www.caixinglobal.com/2026-01-29/asml-expects-china-revenue-drop-following-backlog-fueled-surge-102409285.html
A13: 公司：Q4 2024 新聞稿（6-K；2023、2024 EPS） | B13: https://www.sec.gov/Archives/edgar/data/937966/000093796625000003/pressreleasequarterlyresul.htm
... A29: SemiAnalysis | B29: 未使用
