Workbook

Sheet ①變動列
A1: 分類 | B1: ID／儲存格 | C1: 項目 | D1: M1 基準 | E1: v0.2 | F1: 說明
A2: 公式改變 | B2: Demand!D01@2026 | C2: API 綜合實收單價 | D2: =Inputs!$E$12 | E2: =Inputs!$E$12*(1-0.5*Inputs!$D$33*Inputs!$D$34)
A3: 新增列 | B3: Demand!D09 | C3: 2026 下半年 API 綜合實收單價（含 M3.1 Flash 降價的已觀測部分） | D3: — | E3: （新列）
A4: 新增列 | B4: Revenue!R15 | C4: 對照：Bloomberg 共識（另一獨立點；S062 與 Yahoo 同源） | D4: — | E4: （新列）
A5: 新增列 | B5: Revenue!R16 | C5: 模型 ÷ Bloomberg 共識 | D5: — | E5: （新列）
A6: 新增列 | B6: Revenue!R17 | C6: 對照：2027 共識（Yahoo 24 位） | D6: — | E6: （新列）
A7: 新增列 | B7: Revenue!R18 | C7: 對照：2027 共識（stockanalysis／S&P） | D7: — | E7: （新列）
A8: 新增列 | B8: Revenue!R19 | C8: 模型 ÷ 2027 共識平均 | D8: — | E8: （新列）
A9: 新增列 | B9: Revenue!R20 | C9: 對照：1H26 已實現營收占 Bloomberg 全年共識 | D9: — | E9: （新列）
A10: 新增列 | B10: Revenue!R21 | C10: 對照：Bloomberg 共識隱含 2H26 ÷ 1H26 | D10: — | E10: （新列）
A11: 新增列 | B11: Revenue!R22 | C11: 對照：AI 原生產品付費用戶（9M25 期間，S074） | D11: — | E11: （新列）
A12: 新增列 | B12: Revenue!R23 | C12: 對照：AI 原生 ARPPU＝(訂閱＋儲值) ÷ 付費用戶 | D12: — | E12: （新列）
A13: 新增列 | B13: Revenue!R24 | C13: 驗算：海螺 ARPPU＝(訂閱＋儲值) ÷ 付費用戶（S105） | D13: — | E13: （新列）
A14: 新增列 | B14: Revenue!R25 | C14: 驗算：Talkie／星野 ARPPU＝(訂閱＋儲值) ÷ 付費用戶（S107） | D14: — | E14: （新列）
... A16: 新增列 | B16: Revenue!R27 | C16: 消費端 2026 營收：模型 ÷ 1H26 實際年化 | D16: — | E16: （新列）
A17: 公式改變 | B17: Compute!C10@2026 | C17: 校準期 API 推論 MW（token 換算） | D17: =(2*SRC_MM!$E$12/Demand!$E$7)/(E11*E12) | E17: =(2*SRC_MM!$E$12/Inputs!$E$12)/(E11*E12)
A18: 公式改變 | B18: Compute!C13@2026 | C18: API 推論 MW（有效；年均） | D18: =0.5*E16+0.5*(Inputs!$D$15/Demand!$E$7)/(E11*E12*E18*Inputs!$D$32) | E18: =0.5*E16+0.5*(Inputs!$D$15/Demand!$E$13)/(E11*E12*E18*Inputs!$D$32)
A19: 新增列 | B19: Compute!C31 | C19: 每 MW 可容納 Hopper 級 GPU 數（1,000 kW ÷ 每張 kW；Analogy，Tokenomics 官方 GPU／MW 不在快照） | D19: — | E19: （新列）
A20: 新增列 | B20: Compute!C32 | C20: 證據價 A：AutoDL H800 單卡（口徑明確） | D20: — | E20: （新列）
A21: 新增列 | B21: Compute!C33 | C21: 證據價 B：SMM H20 96G 1 年約（整機 8 卡口徑） | D21: — | E21: （新列）
A22: 新增列 | B22: Compute!C34 | C22: 證據價 C：SMM H100 80G 現貨 | D22: — | E22: （新列）
A23: 新增列 | B23: Compute!C35 | C23: 隱含每 MW 年租金：A（H800） | D23: — | E23: （新列）
A24: 新增列 | B24: Compute!C36 | C24: 隱含每 MW 年租金：B（H20） | D24: — | E24: （新列）
A25: 新增列 | B25: Compute!C37 | C25: 隱含每 MW 年租金：C（H100） | D25: — | E25: （新列）
A26: 新增列 | B26: Compute!C38 | C26: 證據價 ÷ TK 持有成本：A（H800） | D26: — | E26: （新列）
A27: 新增列 | B27: Compute!C39 | C27: 證據價 ÷ TK 持有成本：B（H20） | D27: — | E27: （新列）
A28: 新增列 | B28: Compute!C40 | C28: 證據價 ÷ TK 持有成本：C（H100） | D28: — | E28: （新列）
A29: 新增列 | B29: Compute!C41 | C29: 對照：I02（合約價基準）÷ TK 持有成本 | D29: — | E29: （新列）
A30: 新增列 | B30: Compute!C42 | C30: 證據落在 I02 區間（8–20）外的個數（0–3） | D30: — | E30: （新列）
... A56: 新增列 | B56: PxQ!X23 | C56: 2026 全年平均折減 | D56: — | E56: （新列）
A57: 新增列 | B57: PxQ!六、對照 | D57: — | E57: （新列）
A58: 新增列 | B58: PxQ!X24 | C58: 合約價 I02 ÷ h（算力成本中雲端租用溢價） | D58: — | E58: （新列）
A59: 新增列 | B59: PxQ!X25 | C59: 每 MW 營收 ÷ h（＝X05，與 PnL 每 MW 營收同口徑） | D59: — | E59: （新列）
A60: 新增列 | B60: PxQ!X26 | C60: 營收 ÷ 算力支出（合約價口徑，＝Compute C26） | D60: — | E60: （新列）
A61: 新增列 | B61: PxQ!X27 | C61: 分解檢查：X26 × X24 − X05（應＝0） | D61: — | E61: （新列）
A62: 新增列 | B62: PxQ!X28 | C62: 比值＝1 所需的合約價 I02（＝I02 ÷ 比值；what must be true） | D62: — | E62: （新列）
A63: 新增列 | B63: Funding!F20 | C63: 對照：公告經營活動現金流（FY2025；1H26 現金流量表未取得） | D63: — | E63: （新列）
A64: 新增列 | B64: Funding!F21 | C64: 對照：經營現金流 − 模型經調整淨利（FY2025；負＝實際流出較多） | D64: — | E64: （新列）
A65: 新增列 | B65: Funding!F22 | C65: 對照：1H26 物業廠房設備增額 | D65: — | E65: （新列）
A66: 新增列 | B66: Funding!F23 | C66: 對照：1H26 合約負債增額 | D66: — | E66: （新列）
...

Sheet ②關鍵輸出前後值
A1: 輸出 | B1: 年 | C1: v0.1（2026-10-08） | D1: M1（TK 同步 v19.0） | E1: v0.2 資料更新（不含 M3.1 降價；I31=0） | F1: v0.2 成品（基準，含 M3.1 已觀測降價） | G1: 新機制（PxQ／D2／η 對照）對此值的影響
A2: η 2025 | B2: 2025 | C2: 3.4231902 | D2: 2.2472095 | E2: 2.2472095 | F2: 2.2472095 | G2: 0（新機制不改既有數值）
A3: η 1H26 | B3: 2026 | C3: 0.80080799 | D3: 0.52227188 | E3: 0.52227188 | F3: 0.52227188 | G3: 0（新機制不改既有數值）
A4: API 全年平均單價 $/M | B4: 2026 | C4: 0.22 | D4: 0.22 | E4: 0.22 | F4: 0.209 | G4: 0（新機制不改既有數值）
A5: 營收 2026 $M | B5: 2026 | C5: 465.49 | D5: 465.49 | E5: 465.49 | F5: 465.49 | G5: 0（新機制不改既有數值）
A6: 營收 2030 $M | B6: 2030 | C6: 1944.0637 | D6: 1944.0637 | E6: 1944.0637 | F6: 1944.0637 | G6: 0（新機制不改既有數值）
A7: API 推論 MW 2026 | B7: 2026 | C7: 17.16908 | D7: 17.16908 | E7: 17.16908 | F7: 18.614033 | G7: 0（新機制不改既有數值）
A8: API 推論 MW 2030 | B8: 2030 | C8: 29.399896 | D8: 29.1988 | E8: 29.1988 | F8: 30.735579 | G8: 0（新機制不改既有數值）
A9: 總 MW 2026 | B9: 2026 | C9: 68.609122 | D9: 68.609122 | E9: 68.609122 | F9: 70.054075 | G9: 0（新機制不改既有數值）
A10: 總 MW 2030 | B10: 2030 | C10: 246.96539 | D10: 246.76429 | E10: 246.76429 | F10: 248.30107 | G10: 0（新機制不改既有數值）
A11: 每 MW 營收 2030 $M | B11: 2030 | C11: 7.8718064 | D11: 7.8782214 | E11: 7.8782214 | F11: 7.8294617 | G11: 0（新機制不改既有數值）
A12: 每 MW 全成本 2030 $M | B12: 2030 | C12: 15.479773 | D12: 15.482609 | E12: 15.482609 | F12: 15.461054 | G12: 0（新機制不改既有數值）
A13: 覆蓋率 2027 | B13: 2027 | C13: 0.46606692 | D13: 0.46634448 | E13: 0.46634448 | F13: 0.46241549 | G13: 0（新機制不改既有數值）
... A19: 反向檢驗 折現價值÷市值 | B19: 2030 | C19: 0.75074141 | D19: 0.75123015 | E19: 0.88985098 | F19: 0.88197135 | G19: 0（新機制不改既有數值）
A20: 回本比值 2025（新） | B20: 2025 | E20: 0.39562933 | F20: 0.39562933 | G20: 無（新輸出）
A21: 回本比值 2026（新） | B21: 2026 | E21: 0.7088146 | F21: 0.69419441 | G21: 無（新輸出）
A22: 回本比值 2030（新） | B22: 2030 | E22: 0.87505167 | F22: 0.86963582 | G22: 無（新輸出）
A23: 比值＝1 所需合約價 $M（新） | B23: 2030 | E23: 13.713476 | F23: 13.79888 | G23: 無（新輸出）

Sheet ③已套用的預設
A1: # | B1: 問題 | C1: 預設 | D1: 替代 | E1: 影響方向／量化
A2: D1 | B2: 產能層 | C2: 維持 `IF_TokGW` × `IF_Util`；Prod 層敏感度未做（快照只含 8 個名稱，缺 `IF_ProdDerate`／`IF_UtilActual`，且本段依指示不重取快照） | D2: 主值改 Prod 層 | E2: M1 引用審視報告估 API MW −3%～−6%、覆蓋率幾乎不變；本段未量化，列為待補
A3: D2 | B3: 合約價 I02 | C3: 維持 12（Analogy 8–20）；Compute 第七節並列「證據價 ÷ TK 持有成本」；3 項證據中 H20 一項落區間外（樣本 2 台、口徑不明），H800、H100 在區間內 | D3: 直接改用中國租價 | E3: I02＝5.5／9.2／13.4（H20／H800／H100 證據）：2030 回本比值 0.40／0.67／0.97（基準 0.87）；覆蓋率與融資 0 影響（被 η 校準吸收）。回本比值與 I02 成正比
A4: D3 | B4: 中國晶片世代 | C4: 維持 Hopper 代理；持有成本取 Hopper（TK07）與 GB200（TK08）、占比用 v0.1 I05 | D4: 請 Tokenomics 新增世代 | E4: 缺口，不量化
A5: D4 | B5: η | C5: 維持總校準係數；Compute 第八節並列 η−1，Tokenomics 服務端落差分解無 `IF_` 等義名稱（OpenAI v0.6.2 交接檔同列為缺口）→ 不引用 | D5: 逐項拆解入模 | E5: 0（只對照）
A6: D5 | B6: A 股上市情境、機率加權 | C6: v0.2 不做 | D6: 做 | E6: 缺席會低估再融資彈性；現價已低於 IPO 價，A 股情境價值更高，需另案
A7: D6 | B7: P×Q 的 MW 口徑 | C7: 模型自身年均上線 MW（Compute C21）× v0.1 機隊組合；h＝Hopper 占比 × TK07 ＋ GB200 占比 × TK08 | D7: 用 Tokenomics 預設組合 | E7: 比值與 I02 成正比（所有 MW ∝ 1/I02）：基準 2030 為 0.87；比值＝1 需 I02≈13.8
A8: D7 | B8: 金額單位 | C8: 維持 US$M；人民幣以 S096（期末中間價 6.8109）、S097（1H26 平均 6.90，Assumed 6.85–6.98）換算 | D8: 人民幣 | E8: V07 智譜倍數 139.5→135.6（用 S097 取代 7.10）
A9: D8 | B9: 單價路徑 | C9: 只更新已觀測的 2026 年：I30＝0.50（觀測）、I31＝0.20（Assumed 0–1）；上半年維持降價前 I07 校準 η；2027 起 I08 不改 | D9: 全年 −50% 或改 I08 | E9: I31＝0（v0.1 行為）／0.20／0.5／1：覆蓋率 2030 0.509／0.506／0.502／0.494；累計融資 3,159／3,249／3,409／3,780；回本比值 2030 0.88／0.87／0.86／0.84
A10: E1 | B10: P×Q 的 P | C10: 取 MiniMax 實收單價（Demand D01）；Tokenomics 有效牌價（`IF_PxEffMix`）為 OpenAI 層級牌價且不在快照 → 不列 | D10: 取 TK 有效牌價 | E10: 實際／所需 m×L 水準因此與 OpenAI 頁不可直接比較；比值（營收÷C）不受影響
A11: E2 | B11: 市值基準 | C11: 10-21 推算收盤價 HK$171.9（Derived，±0.5） | D11: 10-22 盤中 162 | E11: 市值 −5.8%；反向檢驗 0.88 往下
A12: E3 | B12: 共識 | C12: Revenue R13 維持 S062（452，與 Yahoo 同源）；另列 Bloomberg 363.8 為獨立點（R15） | D12: 改用 Bloomberg 為主 | E12: 模型 465 對 452＝1.03x、對 363.8＝1.28x；僅對照，不反推
... A20: E11 | B20: 成品檔 | C20: `dist/` 放 v0_2；v0.1 移 `dist/_待刪除/`（不刪） | D20: 直接覆蓋 | E20: 無
