Workbook

Sheet README
A1: Amkor Technology（AMKR）收支與估值模型 v0.2.2（AI 半導體 Project：封測次產業） 2026-10-25
A2: 版本：v0.2.1（2026-10-25：補上檔空間級距、投資建議、重點觀察，數值不變）；v0.2（2026-10-25：tp_w_dcf 改 0.5；Comparable 同業移除 A 股；v0.1 初版）。Amkor 為全球第二大封測廠，承接台積電 CoWoS 後段（oS、測試）與 2.5D／HDFO 委外；亞利桑那廠為美國第一座量產先進封裝廠。日月光模型待 10-29 法說後建立，本版未讀。
A3: 模型命題：Amkor 的 AI 先進封裝營收＝AI 加速器顆數（tsmc 成品）× 後段委外比例 × Amkor 份額 × 每顆封測金額（隨封裝面積上升），FY2026 約占營收一成；其餘九成是通訊（Apple 占 29.8%）、車用與工業、消費與非 AI 運算。毛利率只有 14–19%，資本支出 2026 年約 US$2.75B（營收的三成以上），亞利桑那的啟動成本與折舊是 2027–29 毛利率的關鍵。
A4: 核心問題：AI 封裝的高成長能不能抵過通訊（Apple）停滯與亞利桑那折舊，讓 EPS 在 FY2027–28 持續成長；約 14 倍前瞻 P/E 隱含什麼路徑。
A6: 會計年度＝日曆年，FY(t)＝CY(t)，不平移。預測期 FY2027–FY2029（三年）。金額：百萬美元；EPS：美元（稀釋）。口徑：歸屬母公司淨利（GAAP）。3Q26 財報 2026-10-26 公布，本版未納入。
A8: 驅動因子 → 推導量（全部唯讀上游，不修改）
A9: AI 先進封裝：tsmc 成品的加速器顆數 × 情境係數（2028–29）× 後段委外比例（Assumed）× Amkor 份額（Assumed）× 每顆封測金額（FY2026 校準，之後 × 封裝面積指數 ^ 0.5；面積指數＝tsmc 成品 CoWoS 片數 ÷ 顆數）。FY2026 的 AI 金額由運算營收與公司「AI 封裝約三倍」說法反推。
A10: 其他終端：通訊依情境（A +3%／B 0%／C −6% 於 FY2027），車用與工業 +10%、消費 +3%（公司投資人日 CAGR），非 AI 運算 +3%。亞利桑那第一期營收 FY2028–29 依情境（Assumed）。
A11: 毛利：本業毛利＝FY2026 錨點＋現金流通率 40%（Assumed）× 營收增量 − 本業折舊增量（資本支出率 14%、年限 7 年）；亞利桑那毛利＝營收 × 55% − 固定現金成本 − 折舊（第一期 US$3.5B × (1 − 補助 35%) ÷ 12 年）。營業費用彈性 0.5；營業外、稅率 20%、股數持平。
A12: 校準：FY2026 ＝ 1H26 實績＋3Q26 公司指引（終端市場季增說法、毛利率 19%、營業費用 140）＋4Q26 假設。不用券商數字（只在 Recon 對帳）。
A13: 估值：Val 第 0 節目標價＝0.5 × DCF 目標價（股東現金流＝EPS ×（1 − g／ROE），FY2027–32 明確期＋永續，r 10%、g 4%，三情境權重 0.3／0.5／0.2）＋0.5 × Comparable 目標價（日月光、力成、京元電、矽格、南茂前瞻 P/E 中位數 × 12 個月後前瞻 EPS；不放 A 股）；另列 Comparable 單獨目標價、市場共識目標價與差距拆解。十年 P/E 規則值 × FY2027 EPS 保留為參考（不是目標價）。情境對應：A＝順利、B＝平平、C＝不如預期（原為顆數情境）。本版未做先驗，無 Andy 合理 P/E 對照。
A14: 預估期間：FY2027–FY2029 由驅動因子推導；FY2030 起為收斂法，非驅動因子推導（營收年增由 FY2029 線性收斂到 fade_g、淨利率收斂到 fade_m，FY2032 達到；PL 頁灰底）。
... A18: v0.2.1（2026-10-25）：補上檔空間級距、投資建議、重點觀察（Val 頁 0.3 結論加「上檔空間級距」「投資建議」兩列、README 頁加重點觀察三點；數值不變，既有儲存格位置不變）。
A19: ="投資建議："&Val!B50&"（依上檔空間固定規則）" -> 投資建議：強力買進（依上檔空間固定規則）
A20: ="重點觀察 1：目標價 US$"&TEXT(Val!$B$39,"0.00")&"（DCF "&TEXT(Val!$B$24,"0.00")&"、Comparable（相對倍數調整後）"&TEXT(tp_comp_adj,"0.00")&"；DCF 權重 "&TEXT(tp_w_dcf,"0%")&"），比現價 "&TEXT(px,"0.00")&"（2026-10-23）"&IF(Val!$B$42>=0,"高 "&TEXT(Val!$B$42,"0.0%"),"低 "&TEXT(-Val!$B$42,"0.0%"))&"，級距 "&Val!$B$49&"、投資建議 "&Val!$B$50&"。相對倍數調整係數 "&TEXT(rm_factor,"0.00")&"（本公司 10 年前瞻倍數中位數 ÷ 同業的中位數，夾在 0.5–2.0；Val 第 0.5 節），調整前加權上檔空間 "&TEXT((tp_w_dcf*Val!$B$24+(1-tp_w_dcf)*Val!$B$35)/px-1,"+0.0%;−0.0%")&"；Comparable 單獨（市場主流同業法、未調整）為 "&TEXT(Val!$B$43,"+0.0%;−0.0%")&"。"&"以下為 2026-10-29 相對倍數調整前撰寫的說明，其中數字為調整前：主因是倍數：本模型 12 個月後前瞻 EPS 3.23 比共識前瞻 EPS 2.80 高 15.3%（期間差約一年），台美封測同業（日月光、力成、京元電、矽格、南茂）前瞻 P/E 中位數 23.3 倍，現價只隱含 14.0 倍、共識目標價 76.40 隱含 27.3 倍；DCF 36.0 低於現價（−8.4%），因近三年 R"&"OE 8.9% 低於折現率 10%（可發放比例只 55%）。" -> 重點觀察 1：目標價 US$66.40（DCF 36.01、Comparable（相對倍數調整後）96.79；DCF 權重 50%），比現價 39.30（2026-10-23）高 69.0%，級距 大於 50%、投資建議 強力買進。相對倍數調整係數 1.28（本公司 10 年前瞻倍數中位數 ÷ 同業的中位數，夾在 0.5–2.0；Val 第 0.5 節），調整前加權上檔空間 +41.7%；Comparable 單獨（市場主流同業法、未調整）為 +91.7%。以下為 2026-10-29 相對倍數調整前撰寫的說明，其中數字為調整前：主因是倍數：本模型 12 個月後前瞻 EPS 3.23 比共識前瞻 EPS 2.80 高 15.3%（期間差約一年），台美封測同業（日月光、力成、京元電、矽格、南茂）前瞻 P/E 中位數 23.3 倍，現價只隱含 14.0 倍、共識目標價 76.40 隱含 27.3 倍；DCF 36.0 低於現價（−8.4%），因近三年 ROE 8.9% 低於折現率 10%（可發放比例只 55%）。
A21: 重點觀察 2：最敏感的是現金流通率、委外比例與份額：現金流通率 30% 時 FY2028 EPS −16.9%、委外比例低 −16.2%、Amkor 份額低（28%）−15.7%、AI 部署 ×0.8 −12.8%；情境 C FY2028 EPS 2.32，比情境 A 的 4.00 低 42.0%。
A22: 重點觀察 3：追蹤 3Q26 財報（2026-10-26）：本版 3Q26 用公司指引（毛利率 19%），AI 先進封裝金額公司未揭露、由「約三倍」說法反推；亞利桑那廠固定成本與折舊從 FY2028 起影響毛利率（固定成本高案例 FY2028 EPS −4.0%）。
A23: v0.2.2（2026-10-28）：分部原則重建（數值不變）。Q 頁最後追加核對列「檢查：分部合計 − 合併營收」；官方分部與子列宣告見 segments.json。
A25: 2026-10-29：加權目標價中的 Comparable 改用相對倍數調整後的值（Val 第 0.5 節：同業前瞻倍數中位數 × 本公司 10 年相對同業的倍數比，Bloomberg 前瞻倍數；Andy 2026-10-27「照建議做」、10-29 資料取回）。「Comparable 目標價（市場主流同業法）」維持不調整。重點觀察 1 的第一句已改為公式；重點觀察 2、3 與其他說明中的目標價與上檔空間數字為調整前撰寫，以 Val 頁為準。

Sheet In
A1: In — 輸入（藍字；基準欄 E，低 D、高 F）。金額：百萬美元（US$M）；顆數：百萬顆；比例：%。每個輸入附兩個來源（找不到者寫「未找到」）；公司原文算一個
A2: 標記：Verified／Interested-party／Analogy／Assumed／Derived；Analogy、Assumed 給低／高區間，不當點估計（放情境或 Sens）。SemiAnalysis 未使用。公司原文＝SEC 8-K 新聞稿、10-K、投資人日簡報；法說內容經 Motley Fool 逐字稿與 MarketBeat 摘要；公司指引與目標為 Interested-party；券商與資料商為 Interested-party
A3: 鍵 | B3: 項目 | C3: 單位 | D3: 低 | E3: 基準 | F3: 高 | G3: 標記 | H3: 來源1 | I3: 來源2／說明
A4: A. AI 加速器顆數、封裝面積與部署規模（讀 tsmc、markets/network、markets/chip_bridge 成品；唯讀，不自行重估）
A5: units_26 | B5: AI 加速器顆數 2026（情境 A 基準） | C5: 百萬顆 | E5: 15.2 | G5: Derived | H5: tsmc/dist/20261028_台積電個股模型_v0.4.xlsx｜In!E5:E36（八類加速器加總；2029＝2028 × (1＋各類 2029 成長)，與台積電模型 CoWoS 頁同口徑） | I5: NVIDIA、AMD、Google TPU、AWS Trainium、其他 ASIC 合計；台積電模型讀 markets/memory 的同一份顆數
A6: units_27 | B6: AI 加速器顆數 2027（情境 A 基準） | C6: 百萬顆 | E6: 23.7 | G6: Derived | H6: 同上 | I6: 同上
A7: units_28 | B7: AI 加速器顆數 2028（情境 A 基準） | C7: 百萬顆 | E7: 26.5 | G7: Derived | H7: 同上 | I7: 同上
A8: units_29 | B8: AI 加速器顆數 2029（情境 A 基準） | C8: 百萬顆 | E8: 30.15 | G8: Derived | H8: 同上 | I8: 同上
A9: um28_A | B9: 情境 A：2028 顆數 ÷ 基準 | C9: x | E9: 1 | G9: Assumed | H9: tsmc/dist/20261028_台積電個股模型_v0.4.xlsx｜In!E37 | I9: A＝基準；B＝AI 資本支出消化；C＝明顯下修（與台積電、廣達、NVIDIA 模型相同）
A10: um29_A | B10: 情境 A：2029 顆數 ÷ 基準 | C10: x | E10: 1 | G10: Assumed | H10: tsmc/dist/20261028_台積電個股模型_v0.4.xlsx｜In!E38 | I10: 同上
A11: um28_B | B11: 情境 B：2028 顆數 ÷ 基準 | C11: x | E11: 0.8 | G11: Assumed | H11: tsmc/dist/20261028_台積電個股模型_v0.4.xlsx｜In!E39 | I11: 同上
A12: um29_B | B12: 情境 B：2029 顆數 ÷ 基準 | C12: x | E12: 0.85 | G12: Assumed | H12: tsmc/dist/20261028_台積電個股模型_v0.4.xlsx｜In!E40 | I12: 同上
A13: um28_C | B13: 情境 C：2028 顆數 ÷ 基準 | C13: x | E13: 0.6 | G13: Assumed | H13: tsmc/dist/20261028_台積電個股模型_v0.4.xlsx｜In!E41 | I13: 同上
A14: um29_C | B14: 情境 C：2029 顆數 ÷ 基準 | C14: x | E14: 0.6 | G14: Assumed | H14: tsmc/dist/20261028_台積電個股模型_v0.4.xlsx｜In!E42 | I14: 同上
A15: ar_26 | B15: 封裝面積指數 2026（加速器用 CoWoS 片數 ÷ 顆數，2026＝1） | C15: x | E15: 1 | G15: Derived | H15: tsmc/dist/20261028_台積電個股模型_v0.4.xlsx｜CoWoS!B13:E13 減 tsmc/dist/20261028_台積電個股模型_v0.4.xlsx｜CoWoS!B12:E12，除以顆數 | I15: 每片封裝數下降＝單顆封裝面積變大（Rubin、Rubin Ultra）；台積電模型的每片封裝數為 Derived／Assumed
A16: ar_27 | B16: 封裝面積指數 2027（加速器用 CoWoS 片數 ÷ 顆數，2026＝1） | C16: x | E16: 1.278156 | G16: Derived | H16: 同上 | I16: 同上
... A26: capit_vr | B26: 每 GW IT 資本支出（VR200；2027 起） | C26: US$B | E26: 37.586352 | G26: Derived | H26: markets/chip_bridge/dist/20261027_晶片內容橋接表_v0.2.2.xlsx｜In!E10（GB300）、H10（VR200） | I26: 同上
A27: vr26 | B27: 2026 年部署中 Rubin 世代占比（混合每 GW IT 資本支出用） | C27: % | D27: 0.15 | E27: 0.22 | F27: 0.3 | G27: Interested-party | H27: TrendForce 2026 組合 Rubin 22%（經 markets/memory）；原在台達電、廣達、奇鋐、雙鴻、健策、台光電、勝宏、光寶等模型各自寫入，值相同 | I27: Siliconomics In 頁 M11（v0.4 起；CF22：與台達電、廣達等同一混合口徑）
A28: tam_gw | B28: OSAT 先進封裝可服務市場 ÷ 每 GW 部署（Recon 用） | C28: US$B/GW | E28: 0.5 | G28: Interested-party | H28: 公司投資人日簡報（SEC 8-K）：約 US$0.5B／GW installed（公司投資人日 2026-05-21） | I28: 第二來源：未找到
A29: B. AI 先進封裝（2.5D、HDFO、AI 測試）：營收＝顆數 × 後段委外比例 × Amkor 份額 × 每顆封測金額（FY2026 以公司「三倍」說法校準）
A30: tri | B30: FY2026 AI 先進封裝營收 ÷ FY2025（公司：約三倍） | C30: x | D30: 2.5 | E30: 3 | F30: 3.2 | G30: Interested-party | H30: 1Q26 法說逐字稿（Motley Fool）：Advanced AI packaging revenue still on track to triple in 2026（1Q26 法說） | I30: 4Q25 法說逐字稿（Motley Fool）：2.5D and HDFO … nearly triple over the course of this year（4Q25 法說）；低＝供應受限時
A31: g_pc26 | B31: FY2026 非 AI 運算（PC、儲存、基礎設施）年增 | C31: % | D31: -0.1 | E31: -0.03 | F31: 0.05 | G31: Assumed | H31: 公司：PC／筆電疲弱（1Q26、4Q25 法說）；運算成長由資料中心帶動 | I31: 非 AI 運算金額未揭露：未找到
A32: out_26 | B32: AI 加速器後段（oS、測試）委外比例 2026 | C32: % | D32: 0.4 | E32: 0.5 | F32: 0.6 | G32: Assumed | H32: 台積電 CoWoS 2027 需求 ÷ 產能約 96%（台積電模型）；台積電與 Amkor 十年合作（2026-06-16）、NVIDIA 與 Amkor 多年合作 US$1.5B（2026-07-23） | I32: FY2026 只影響拆分（每顆金額由校準吸收）；FY2027 起的相對變化才影響營收；委外比例的量化：未找到
A33: out_27 | B33: AI 加速器後段（oS、測試）委外比例 2027 | C33: % | D33: 0.45 | E33: 0.55 | F33: 0.65 | G33: Assumed | H33: 同上 | I33: Rubin 世代 CoWoS 緊、美國產能需求 → 委外上升（Assumed）
A34: out_28 | B34: AI 加速器後段（oS、測試）委外比例 2028 | C34: % | D34: 0.45 | E34: 0.6 | F34: 0.7 | G34: Assumed | H34: 同上 | I34: Rubin 世代 CoWoS 緊、美國產能需求 → 委外上升（Assumed）
A35: out_29 | B35: AI 加速器後段（oS、測試）委外比例 2029 | C35: % | D35: 0.45 | E35: 0.6 | F35: 0.75 | G35: Assumed | H35: 同上 | I35: Rubin 世代 CoWoS 緊、美國產能需求 → 委外上升（Assumed）
A36: sh_26 | B36: Amkor 占委外後段的份額 2026 | C36: % | D36: 0.28 | E36: 0.35 | F36: 0.4 | G36: Assumed | H36: Amkor 為全球第二大封測廠；競爭者日月光（含矽品）、京元電（測試） | I36: 份額的量化：未找到（日月光模型待 10-29 法說後建立）；FY2026 只影響拆分
A37: sh_27 | B37: Amkor 占委外後段的份額 2027 | C37: % | D37: 0.28 | E37: 0.35 | F37: 0.4 | G37: Assumed | H37: 同上 | I37: NVIDIA 合作與美國產能（Assumed）
A38: sh_28 | B38: Amkor 占委外後段的份額 2028 | C38: % | D38: 0.28 | E38: 0.37 | F38: 0.45 | G38: Assumed | H38: 同上 | I38: NVIDIA 合作與美國產能（Assumed）
A39: sh_29 | B39: Amkor 占委外後段的份額 2029 | C39: % | D39: 0.28 | E39: 0.38 | F39: 0.45 | G39: Assumed | H39: 同上 | I39: NVIDIA 合作與美國產能（Assumed）
A40: el | B40: 每顆封測金額對封裝面積的彈性 | C40: x | D40: 0.3 | E40: 0.5 | F40: 1 | G40: Assumed | H40: 封裝面積大 → 基板上封裝、測試時間與良率成本上升；後段金額不與面積等比例 | I40: 第二來源：未找到
A41: C. 其他終端市場成長（FY2027–FY2029）
A42: g_cm27_A | B42: 通訊年增 FY2027（情境 A） | C42: % | D42: -0.02 | E42: 0.03 | F42: 0.06 | G42: Assumed | H42: Apple 新機與高階組合；SiP 移轉越南後回到正常季節性 | I42: Apple 占 FY2025 營收 29.8%、Qualcomm 11.1%（10-K）；投資人日通訊 2025–30 CAGR 約 4%
A43: g_cmL_A | B43: 通訊年增 FY2028–29（情境 A） | C43: % | D43: -0.02 | E43: 0.04 | F43: 0.06 | G43: Assumed | H43: 同上 | I43: 同上
A44: g_cm27_B | B44: 通訊年增 FY2027（情境 B） | C44: % | D44: -0.05 | E44: 0 | F44: 0.04 | G44: Assumed | H44: 通訊逆風延續到 1H27（公司：一項逆風到 4Q 與明年上半年） | I44: 同上
A45: g_cmL_B | B45: 通訊年增 FY2028–29（情境 B） | C45: % | D45: -0.05 | E45: 0.03 | F45: 0.04 | G45: Assumed | H45: 同上 | I45: 同上
A46: g_cm27_C | B46: 通訊年增 FY2027（情境 C） | C46: % | D46: -0.12 | E46: -0.06 | F46: 0.02 | G46: Assumed | H46: Apple 分散封測供應或自行轉移（客戶集中風險） | I46: 同上
A47: g_cmL_C | B47: 通訊年增 FY2028–29（情境 C） | C47: % | D47: -0.12 | E47: 0 | F47: 0.02 | G47: Assumed | H47: 同上 | I47: 同上
A48: g_au | B48: 車用與工業年增 FY2027–29 | C48: % | D48: 0.04 | E48: 0.1 | F48: 0.14 | G48: Interested-party | H48: 公司投資人日簡報（SEC 8-K）：車用與工業 2025–30 CAGR 約 10%（公司） | I48: 公司：ADAS 與資訊娛樂帶動先進車用強勁成長（1Q26、2Q26 法說）
A49: g_cs | B49: 消費年增 FY2027–29 | C49: % | D49: -0.03 | E49: 0.03 | F49: 0.06 | G49: Interested-party | H49: 公司投資人日簡報（SEC 8-K）：消費 2025–30 CAGR 約 3%（公司） | I49: 第二來源：未找到
...

Sheet Q
A1: Q — 實績與 FY2026 錨點（百萬美元；EPS 為美元、稀釋；股數為百萬股）。藍字＝輸入（SEC 8-K 新聞稿）；黑字＝公式。1Q26＝1H26 − 2Q26（Derived）
A2: FY2026 錨點＝1Q、2Q26 實績＋3Q26 公司指引（營收依各終端市場季增說法、毛利率與營業費用指引）＋4Q26 假設。3Q26 財報 2026-10-26 公布，本版尚未納入，屆時以實績取代 E 欄
A3: 項目 | B3: FY2025A | C3: 1Q26（實績） | D3: 2Q26（實績） | E3: 3Q26（指引） | F3: 4Q26（模型） | G3: FY2026 錨點 | H3: 標記 | I3: 來源1（公司） | J3: 來源2／說明
A4: 營收 | B4: 6708 | C4: =3582.7-D4 -> 1684.7 | D4: 1898 | E4: =SUM(E5:E8) -> 2020.2312 | F4: =SUM(F5:F8) -> 2077.5318 | G4: =SUM(C4:F4) -> 7680.463 | H4: Verified／Derived | I4: FY2025：4Q25 新聞稿（SEC 8-K）；1H26、2Q26：2Q26 新聞稿（SEC 8-K） | J4: stockanalysis：FY2025 6,708；1H26 3,582.7、2Q26 1,898.0（公司）
A5: 通訊（手機、平板） | B5: =B4*0.46 -> 3085.68 | C5: =C4*0.44 -> 741.268 | D5: =D4*0.42 -> 797.16 | E5: =D5*(1+g3_cm) -> 733.3872 | F5: =E5*(1+q4_cm) -> 770.05656 | G5: =SUM(C5:F5) -> 3041.8718 | H5: Derived（占比 × 營收）／Interested-party | I5: FY2025：4Q25 新聞稿（SEC 8-K）；1H26、2Q26：2Q26 新聞稿（SEC 8-K） | J5: 占比：FY2025 46%、1Q26 44%、2Q26 42%（公司）
A6: 運算（資料中心、基礎設施、PC、儲存） | B6: =B4*0.2 -> 1341.6 | C6: =C4*0.21 -> 353.787 | D6: =D4*0.22 -> 417.56 | E6: =D6*(1+g3_cp) -> 542.828 | F6: =E6*(1+q4_cp) -> 569.9694 | G6: =SUM(C6:F6) -> 1884.1444 | H6: Derived／Interested-party | I6: FY2025：4Q25 新聞稿（SEC 8-K）；1H26、2Q26：2Q26 新聞稿（SEC 8-K） | J6: 占比：20%、21%、22%（公司）
A7: 車用、工業與其他 | B7: =B4*0.19 -> 1274.52 | C7: =C4*0.21 -> 353.787 | D7: =D4*0.22 -> 417.56 | E7: =D7*(1+g3_au) -> 438.438 | F7: =E7*(1+q4_au) -> 447.20676 | G7: =SUM(C7:F7) -> 1656.9918 | H7: Derived／Interested-party | I7: FY2025：4Q25 新聞稿（SEC 8-K）；1H26、2Q26：2Q26 新聞稿（SEC 8-K） | J7: 占比：19%、21%、22%（公司）
A8: 消費 | B8: =B4*0.15 -> 1006.2 | C8: =C4*0.14 -> 235.858 | D8: =D4*0.14 -> 265.72 | E8: =D8*(1+g3_cs) -> 305.578 | F8: =E8*(1+q4_cs) -> 290.2991 | G8: =SUM(C8:F8) -> 1097.4551 | H8: Derived／Interested-party | I8: FY2025：4Q25 新聞稿（SEC 8-K）；1H26、2Q26：2Q26 新聞稿（SEC 8-K） | J8: 占比：15%、14%、14%（公司）
A9: 毛利 | B9: 938.6 | C9: =557.6-D9 -> 239 | D9: 318.6 | E9: =E4*q3_gm -> 383.84393 | F9: =F4*q4_gm -> 384.34339 | G9: =SUM(C9:F9) -> 1325.7873 | H9: Verified／Interested-party（3Q）／Assumed（4Q） | I9: FY2025：4Q25 新聞稿（SEC 8-K）；1H26、2Q26：2Q26 新聞稿（SEC 8-K） | J9: FY2025 含 4Q25 資產出售約 30（公司法說）
A10: 毛利率 | B10: =B9/B4 -> 0.13992248 | C10: =C9/C4 -> 0.14186502 | D10: =D9/D4 -> 0.16786091 | E10: =E9/E4 -> 0.19 | F10: =F9/F4 -> 0.185 | G10: =G9/G4 -> 0.17261815 | H10: Derived | I10: — | J10: 公司：FY2025 14.0%、1Q26 14.2%、2Q26 16.8%
A11: 營業費用（銷管＋研發） | B11: =304.5+166.7 -> 471.2 | C11: =(175.9+81.6)-D11 -> 138.8 | D11: =78.9+39.8 -> 118.7 | E11: =q3_opx -> 140 | F11: =q4_opx -> 140 | G11: =SUM(C11:F11) -> 537.5 | H11: Verified／Interested-party | I11: FY2025：4Q25 新聞稿（SEC 8-K）；1H26、2Q26：2Q26 新聞稿（SEC 8-K） | J11: 2Q26 含不動產處分利益 21（降低費用）
A12: 營業利益 | B12: =B9-B11 -> 467.4 | C12: =C9-C11 -> 100.2 | D12: =D9-D11 -> 199.9 | E12: =E9-E11 -> 243.84393 | F12: =F9-F11 -> 244.34339 | G12: =SUM(C12:F12) -> 788.28731 | H12: Derived | I12: FY2025：4Q25 新聞稿（SEC 8-K）；1H26、2Q26：2Q26 新聞稿（SEC 8-K） | J12: 公司：FY2025 467.4、1H26 300.1、2Q26 199.9（核對見第 31 列）
A13: 營業外淨額（其他收益 − 利息費用） | B13: =52.7-75.4 -> -22.7 | C13: =(34-34.7)-D13 -> -4 | D13: =20.3-17 -> 3.3 | E13: =q_nonop -> 0 | F13: =q_nonop -> 0 | G13: =SUM(C13:F13) -> -0.7 | H13: Verified／Assumed | I13: FY2025：4Q25 新聞稿（SEC 8-K）；1H26、2Q26：2Q26 新聞稿（SEC 8-K） | J13: 其他收益含利息收入與匯兌（公司）
A14: 稅前利益 | B14: =B12+B13 -> 444.7 | C14: =C12+C13 -> 96.2 | D14: =D12+D13 -> 203.2 | E14: =E12+E13 -> 243.84393 | F14: =F12+F13 -> 244.34339 | G14: =SUM(C14:F14) -> 787.58731 | H14: Derived | I14: — | J14: —
A15: 所得稅 | B15: 68.5 | C15: =40.6-D15 -> 12.3 | D15: 28.3 | E15: =E14*q_tax -> 48.768786 | F15: =F14*q_tax -> 48.868677 | G15: =SUM(C15:F15) -> 138.23746 | H15: Verified／Interested-party | I15: FY2025：4Q25 新聞稿（SEC 8-K）；1H26、2Q26：2Q26 新聞稿（SEC 8-K） | J15: FY2025 有效稅率 15.4%（含遞延稅資產一次性利益）
A16: 非控制權益 | B16: =B14-B15-B17 -> 2.3 | C16: =C14-C15-C17 -> 0.6 | D16: =D14-D15-D17 -> 1.1 | E16: =q_nci -> 1 | F16: =q_nci -> 1 | G16: =SUM(C16:F16) -> 3.7 | H16: Derived | I16: 稅後 − 歸屬母公司淨利 | J16: —
A17: 歸屬母公司淨利 | B17: 373.9 | C17: =257.1-D17 -> 83.3 | D17: 173.8 | E17: =E14-E15-E16 -> 194.07514 | F17: =F14-F15-F16 -> 194.47471 | G17: =SUM(C17:F17) -> 645.64985 | H17: Verified／Derived | I17: FY2025：4Q25 新聞稿（SEC 8-K）；1H26、2Q26：2Q26 新聞稿（SEC 8-K） | J17: 1Q26 83（公司）
A18: 稀釋股數（百萬股） | B18: 248.5 | C18: =2*249.83-D18 -> 249.682 | D18: 249.978 | E18: =q_sh -> 250 | F18: =q_sh -> 250 | G18: =AVERAGE(C18:F18) -> 249.915 | H18: Verified／Derived | I18: FY2025：4Q25 新聞稿（SEC 8-K）；1H26、2Q26：2Q26 新聞稿（SEC 8-K） | J18: 1Q26＝2 × 1H26 加權 − 2Q26（Derived）
A19: EPS（稀釋） | B19: =B17/B18 -> 1.5046278 | C19: =C17/C18 -> 0.33362437 | D19: =D17/D18 -> 0.69526118 | E19: =E17/E18 -> 0.77630057 | F19: =F17/F18 -> 0.77789884 | G19: =G17/G18 -> 2.5834778 | H19: Derived | I19: 淨利 ÷ 股數 | J19: —
A20: 公司揭露 EPS | B20: 1.5 | C20: 0.33 | D20: 0.7 | H20: Verified | I20: FY2025：4Q25 新聞稿（SEC 8-K）；1H26、2Q26：2Q26 新聞稿（SEC 8-K） | J20: —
A21: 折舊攤提 | B21: 642 | C21: =350.6-D21 -> 170.6 | D21: 180 | E21: =q_da3 -> 190 | F21: =q_da4 -> 200 | G21: =SUM(C21:F21) -> 740.6 | H21: Verified／Assumed | I21: FY2025：4Q25 新聞稿（SEC 8-K）；1H26、2Q26：2Q26 新聞稿（SEC 8-K） | J21: 投資人日：LTM 1Q26 659
A22: 現金毛利（毛利＋折舊攤提） | B22: =B9+B21 -> 1580.6 | C22: =C9+C21 -> 409.6 | D22: =D9+D21 -> 498.6 | E22: =E9+E21 -> 573.84393 | F22: =F9+F21 -> 584.34339 | G22: =SUM(C22:F22) -> 2066.3873 | H22: Derived | I22: 假設折舊攤提全數在銷貨成本（近似） | J22: —
A24: FY2026 錨點的檢查（參考；校準未使用券商數字）
A25: FY2026 營收年增 | B25: =G4/B4-1 -> 0.14497064
A26: FY2026 運算年增（公司 2026-02 說法：超過 20%） | B26: =G6/B6-1 -> 0.40440101
A27: 現金毛利增量 ÷ 營收增量（FY2025 扣除資產出售利益；In 頁 ft 的對照） | B27: =(G22-(B22-gain25))/(G4-B4) -> 0.53039273
A28: 營業費用彈性（扣除 2Q26 處分利益；In 頁 phi 的對照） | B28: =((G11+opx_gain)/B11-1)/(G4/B4-1) -> 1.2779943
A29: 3Q26 營收 ÷ 指引中點 − 1 | B29: =E4/g3_rev-1 -> 0.0101156
A30: 3Q26 EPS ÷ 指引中點 − 1 | B30: =E19/g3_eps-1 -> 0.0081825579
A31: FY2025 營業利益 自算 − 公司公布 467.4（應為 0） | B31: =B12-467.4 -> 0
A32: 1H26 營業利益 自算 − 公司公布 300.1（應為 0） | B32: =C12+D12-300.1 -> 0
A34: 檢查：分部合計 − 合併營收 | B34: =ROUND(B5+B6+B7+B8-B4,3) -> 0 | C34: =ROUND(C5+C6+C7+C8-C4,3) -> 0 | D34: =ROUND(D5+D6+D7+D8-D4,3) -> 0 | E34: =ROUND(E5+E6+E7+E8-E4,3) -> 0 | F34: =ROUND(F5+F6+F7+F8-F4,3) -> 0 | G34: =ROUND(G5+G6+G7+G8-G4,3) -> 0
A35: 分部原則第 3 條（2026-10-28 追加）：終端市場別營收（公司揭露比重 × 營收）；分部宣告見 segments.json

Sheet Units
A1: Units — AI 加速器顆數（tsmc 成品）→ Amkor AI 先進封裝營收（情境 A）。部署 GW＝AI IT 資本支出（markets/network）÷ 每 GW IT 資本支出（Tokenomics，經橋接表），只作 Recon
A3: 項目 | B3: 單位 | C3: CY2026 | D3: CY2027 | E3: CY2028 | F3: CY2029 | G3: 說明
A4: AI 加速器顆數（情境 A） | B4: 百萬顆 | C4: =PL!D63 -> 15.2 | D4: =PL!E63 -> 23.7 | E4: =PL!F63 -> 26.5 | F4: =PL!G63 -> 30.15 | G4: tsmc 成品 In 頁（台積電模型與 HBM、網通同一份）
A5: 封裝面積指數（2026＝1） | B5: x | C5: =PL!D64 -> 1 | D5: =PL!E64 -> 1.278156 | E5: =PL!F64 -> 1.428615 | F5: =PL!G64 -> 1.431796 | G5: 加速器用 CoWoS 片數 ÷ 顆數（tsmc 成品 CoWoS 頁）
A6: 後段委外比例 | B6: % | C6: =PL!D65 -> 0.5 | D6: =PL!E65 -> 0.55 | E6: =PL!F65 -> 0.6 | F6: =PL!G65 -> 0.6 | G6: Assumed
A7: Amkor 份額（占委外後段） | B7: % | C7: =PL!D66 -> 0.35 | D7: =PL!E66 -> 0.35 | E7: =PL!F66 -> 0.37 | F7: =PL!G66 -> 0.38 | G7: Assumed
A8: 每顆封測金額 | B8: US$／顆 | C8: =PL!D68 -> 323.78555 | D8: =PL!E68 -> 366.05757 | E8: =PL!F68 -> 387.00365 | F8: =PL!G68 -> 387.43427 | G8: FY2026 校準；之後隨封裝面積
A9: Amkor AI 先進封裝營收 | B9: US$M | C9: =PL!D67 -> 861.26956 | D9: =PL!E67 -> 1670.0461 | E9: =PL!F67 -> 2276.7425 | F9: =PL!G67 -> 2663.3007 | G9: 顆數 × 委外 × 份額 × 每顆金額
A10: 每顆加速器的 Amkor AI 營收 | B10: US$／顆 | C10: =PL!D69 -> 56.662471 | D10: =PL!E69 -> 70.466082 | E10: =PL!F69 -> 85.914811 | F10: =PL!G69 -> 88.335013
A11: 部署 GW（AI IT 資本支出 ÷ 每 GW IT 資本支出） | B11: GW | C11: =itc_26/(capit_gb*(1-vr26)+capit_vr*vr26) -> 23.399538 | D11: =itc_27/capit_vr -> 41.646766 | E11: =itc_28/capit_vr -> 52.792138 | F11: =itc_29/capit_vr -> 60.138592 | G11: 2026 依 vr26 混合 GB300 與 VR200（v0.4 起，與其他模型同口徑）、2027 起用 VR200
A12: OSAT 先進封裝市場（GW × US$0.5B） | B12: US$M | C12: =C11*tam_gw*1000 -> 11699.769 | D12: =D11*tam_gw*1000 -> 20823.383 | E12: =E11*tam_gw*1000 -> 26396.069 | F12: =F11*tam_gw*1000 -> 30069.296 | G12: 公司投資人日口徑（Interested-party）
A13: Amkor AI 營收 ÷ OSAT 先進封裝市場 | B13: % | C13: =C9/C12 -> 0.073614236 | D13: =D9/D12 -> 0.08020052 | E13: =E9/E12 -> 0.086253088 | F13: =F9/F12 -> 0.088572099 | G13: 隱含市占（對照用）
A15: 讀法：AI 先進封裝 FY2026 以公司「約三倍」說法與運算營收反推，不是公司揭露數字；委外比例與份額是 Assumed，只有相對變化影響 FY2027 起的營收。每顆封測金額隨封裝面積上升（彈性 0.5），所以 Rubin 世代單顆金額高於 Blackwell。

Sheet PL
A1: PL — Amkor 損益（百萬美元；EPS 美元、稀釋；歸屬母公司）。FY2025A 實績、FY2026 錨點（1H26 實績＋3Q26 指引＋4Q26 假設；三情境相同），FY2027 起為模型。FY(t)＝CY(t)。三情境各一個完整推導區塊（本頁下方），頂端為摘要
A2: 灰底＝FY2030–FY2032 收斂法（上游只到 2029）：營收年增線性收斂到 fade_g、淨利率線性收斂到 fade_m（In 頁 I 節），非驅動因子推導
A3: 情境／項目 | B3: 單位 | C3: FY2025A | D3: FY2026（錨點） | E3: FY2027 | F3: FY2028 | G3: FY2029 | H3: FY2030（收斂） | I3: FY2031（收斂） | J3: FY2032（收斂） | K3: 說明
A4: 情境 A
A5: 營收 | B5: US$M | C5: =C77 -> 6708 | D5: =D77 -> 7680.463 | E5: =E77 -> 8809.8048 | F5: =F77 -> 9939.6136 | G5: =G77 -> 11074.49 | H5: =H77 -> 12138.948 | I5: =I77 -> 13086.502 | J5: =J77 -> 13871.693
A6: 營收年增 | B6: % | D6: =D78 -> 0.14497064 | E6: =E78 -> 0.14704085 | F6: =F78 -> 0.12824447 | G6: =G78 -> 0.11417708 | H6: =H78 -> 0.096118052 | I6: =I78 -> 0.078059026 | J6: =J78 -> 0.06
A7: AI 先進封裝 | B7: US$M | C7: =C67 -> 287.08985 | D7: =D67 -> 861.26956 | E7: =E67 -> 1670.0461 | F7: =F67 -> 2276.7425 | G7: =G67 -> 2663.3007
A8: 運算合計 | B8: US$M | C8: =C72 -> 1341.6 | D8: =D72 -> 1884.1444 | E8: =E72 -> 2723.6072 | F8: =F72 -> 3361.9104 | G8: =G72 -> 3781.0236
A9: 通訊 | B9: US$M | C9: =C73 -> 3085.68 | D9: =D73 -> 3041.8718 | E9: =E73 -> 3133.1279 | F9: =F73 -> 3258.453 | G9: =G73 -> 3388.7912
A10: 車用、工業與其他 | B10: US$M | C10: =C74 -> 1274.52 | D10: =D74 -> 1656.9918 | E10: =E74 -> 1822.6909 | F10: =F74 -> 2004.96 | G10: =G74 -> 2205.456
A11: 亞利桑那廠 | B11: US$M | C11: =C76 -> 0 | D11: =D76 -> 0 | E11: =E76 -> 0 | F11: =F76 -> 150 | G11: =G76 -> 500
A12: 毛利率 | B12: % | C12: =C90 -> 0.13992248 | D12: =D90 -> 0.17261815 | E12: =E90 -> 0.18069588 | F12: =F90 -> 0.19422352 | G12: =G90 -> 0.2049996
A13: 營業利益率 | B13: % | C13: =C94 -> 0.069677996 | D13: =D94 -> 0.10263539 | E13: =E94 -> 0.11263976 | F13: =F94 -> 0.13003527 | G13: =G94 -> 0.14410025
A14: 歸屬母公司淨利 | B14: US$M | C14: =C99 -> 373.9 | D14: =D99 -> 645.64985 | E14: =E99 -> 774.86745 | F14: =F99 -> 999.00028 | G14: =G99 -> 1225.6694 | H14: =H99 -> 1343.4783 | I14: =I99 -> 1448.3489 | J14: =J99 -> 1535.2499
A15: 淨利率 | B15: % | C15: =C103 -> 0.055739416 | D15: =D103 -> 0.084063923 | E15: =E103 -> 0.087955121 | F15: =F103 -> 0.10050695 | G15: =G103 -> 0.11067502 | H15: =H103 -> 0.11067502 | I15: =I103 -> 0.11067502 | J15: =J103 -> 0.11067502
A16: EPS | B16: US$ | C16: =C101 -> 1.5046278 | D16: =D101 -> 2.5834778 | E16: =E101 -> 3.100524 | F16: =F101 -> 3.9973602 | G16: =G101 -> 4.904345 | H16: =H101 -> 5.3757411 | I16: =I101 -> 5.7953662 | J16: =J101 -> 6.1430881
A17: EPS 年增 | B17: % | D17: =D102 -> 0.71702121 | E17: =E102 -> 0.20013572 | F17: =F102 -> 0.28925313 | G17: =G102 -> 0.22689592 | H17: =H102 -> 0.096118052 | I17: =I102 -> 0.078059026 | J17: =J102 -> 0.06
A19: 情境 B
A20: 營收 | B20: US$M | C20: =C123 -> 6708 | D20: =D123 -> 7680.463 | E20: =E123 -> 8718.5487 | F20: =F123 -> 9308.94 | G20: =G123 -> 10413.325 | H20: =H123 -> 11375.774 | I20: =I123 -> 12128.99 | J20: =J123 -> 12614.15
A21: 營收年增 | B21: % | D21: =D124 -> 0.14497064 | E21: =E124 -> 0.13515926 | F21: =F124 -> 0.067716693 | G21: =G124 -> 0.11863705 | H21: =H124 -> 0.092424698 | I21: =I124 -> 0.066212349 | J21: =J124 -> 0.04
A22: AI 先進封裝 | B22: US$M | C22: =C113 -> 287.08985 | D22: =D113 -> 861.26956 | E22: =E113 -> 1670.0461 | F22: =F113 -> 1821.394 | G22: =G113 -> 2263.8056
A23: 運算合計 | B23: US$M | C23: =C118 -> 1341.6 | D23: =D118 -> 1884.1444 | E23: =E118 -> 2723.6072 | F23: =F118 -> 2906.5619 | G23: =G118 -> 3381.5285
A24: 通訊 | B24: US$M | C24: =C119 -> 3085.68 | D24: =D119 -> 3041.8718 | E24: =E119 -> 3041.8718 | F24: =F119 -> 3133.1279 | G24: =G119 -> 3227.1218
A25: 車用、工業與其他 | B25: US$M | C25: =C120 -> 1274.52 | D25: =D120 -> 1656.9918 | E25: =E120 -> 1822.6909 | F25: =F120 -> 2004.96 | G25: =G120 -> 2205.456
A26: 亞利桑那廠 | B26: US$M | C26: =C122 -> 0 | D26: =D122 -> 0 | E26: =E122 -> 0 | F26: =F122 -> 100 | G26: =G122 -> 400
A27: 毛利率 | B27: % | C27: =C136 -> 0.13992248 | D27: =D136 -> 0.17261815 | E27: =E136 -> 0.17840045 | F27: =F136 -> 0.1796727 | G27: =G136 -> 0.19244362
A28: 營業利益率 | B28: % | C28: =C140 -> 0.069677996 | D28: =D140 -> 0.10263539 | E28: =E140 -> 0.11001255 | F28: =F140 -> 0.11345345 | G28: =G140 -> 0.12973581
A29: 歸屬母公司淨利 | B29: US$M | C29: =C145 -> 373.9 | D29: =D145 -> 645.64985 | E29: =E145 -> 748.31983 | F29: =F145 -> 809.90509 | G29: =G145 -> 1029.7849 | H29: =H145 -> 1053.2285 | I29: =I145 -> 1046.4815 | J29: =J145 -> 1008.7977
A30: 淨利率 | B30: % | C30: =C149 -> 0.055739416 | D30: =D149 -> 0.084063923 | E30: =E149 -> 0.085830779 | F30: =F149 -> 0.087002934 | G30: =G149 -> 0.098891078 | H30: =H149 -> 0.092585218 | I30: =I149 -> 0.086279358 | J30: =J149 -> 0.079973498
A31: EPS | B31: US$ | C31: =C147 -> 1.5046278 | D31: =D147 -> 2.5834778 | E31: =E147 -> 2.9942974 | F31: =F147 -> 3.2407222 | G31: =G147 -> 4.1205408 | H31: =H147 -> 4.2143468 | I31: =I147 -> 4.1873497 | J31: =J147 -> 4.0365632
A32: EPS 年增 | B32: % | D32: =D148 -> 0.71702121 | E32: =E148 -> 0.15901804 | F32: =F148 -> 0.082298045 | G32: =G148 -> 0.27148843 | H32: =H148 -> 0.022765459 | I32: =I148 -> -0.0064060015 | J32: =J148 -> -0.036010005
A34: 情境 C
A35: 營收 | B35: US$M | C35: =C169 -> 6708 | D35: =D169 -> 7680.463 | E35: =E169 -> 8536.0364 | F35: =F169 -> 8529.823 | G35: =G169 -> 9229.7377 | H35: =H169 -> 9796.1667 | I35: =I169 -> 10194.724 | J35: =J169 -> 10398.618
A36: 營收年增 | B36: % | D36: =D170 -> 0.14497064 | E36: =E170 -> 0.11139606 | F36: =F170 -> -0.00072789836 | G36: =G170 -> 0.082055002 | H36: =H170 -> 0.061370002 | I36: =I170 -> 0.040685001 | J36: =J170 -> 0.02
A37: AI 先進封裝 | B37: US$M | C37: =C159 -> 287.08985 | D37: =D159 -> 861.26956 | E37: =E159 -> 1670.0461 | F37: =F159 -> 1366.0455 | G37: =G159 -> 1597.9804
A38: 運算合計 | B38: US$M | C38: =C164 -> 1341.6 | D38: =D164 -> 1884.1444 | E38: =E164 -> 2723.6072 | F38: =F164 -> 2451.2134 | G38: =G164 -> 2715.7034
A39: 通訊 | B39: US$M | C39: =C165 -> 3085.68 | D39: =D165 -> 3041.8718 | E39: =E165 -> 2859.3595 | F39: =F165 -> 2859.3595 | G39: =G165 -> 2859.3595
A40: 車用、工業與其他 | B40: US$M | C40: =C166 -> 1274.52 | D40: =D166 -> 1656.9918 | E40: =E166 -> 1822.6909 | F40: =F166 -> 2004.96 | G40: =G166 -> 2205.456
A41: 亞利桑那廠 | B41: US$M | C41: =C168 -> 0 | D41: =D168 -> 0 | E41: =E168 -> 0 | F41: =F168 -> 50 | G41: =G168 -> 250
A42: 毛利率 | B42: % | C42: =C182 -> 0.13992248 | D42: =D182 -> 0.17261815 | E42: =E182 -> 0.17366234 | F42: =F182 -> 0.1590966 | G42: =G182 -> 0.1653085
...

Sheet Val
A1: Val — P/E 估值（美元）。結論用「現價 ÷ FY2027、FY2028 EPS（模型）」；目標價＝DCF 與 Comparable 加權（第 0 節）；十年 P/E 規則值（第 3 節，年底落後 P/E）只作參考
A2: 循環位置：Amkor 不是設備股，不套設備市場見頂年；以本模型營收最高的會計年度為見頂年（比照廣達、NVIDIA、Arista；FY(t)＝CY(t)）。營收到 FY2029 仍在增加時，見頂年未知，判為中段
A4: 0. 目標價
A5: 0.1 DCF（股東權益現金流，FY2027–FY2032 明確期＋FY2032 後永續）
A6: 項目 | B6: A（順利） | C6: B（平平） | D6: C（不如預期） | E6: 說明
A7: 情境 EPS（FY2027–FY2032） | E7: PL 頁各情境；FY2030 起為收斂法
A8: FY2027 | B8: =PL!E16 -> 3.100524 | C8: =PL!E31 -> 2.9942974 | D8: =PL!E46 -> 2.7818442
A9: FY2028 | B9: =PL!F16 -> 3.9973602 | C9: =PL!F31 -> 3.2407222 | D9: =PL!F46 -> 2.3173418
A10: FY2029 | B10: =PL!G16 -> 4.904345 | C10: =PL!G31 -> 4.1205408 | D10: =PL!G46 -> 2.7158996
A11: FY2030 | B11: =PL!H16 -> 5.3757411 | C11: =PL!H31 -> 4.2143468 | D11: =PL!H46 -> 2.7194727
A12: FY2031 | B12: =PL!I16 -> 5.7953662 | C12: =PL!I31 -> 4.1873497 | D12: =PL!I46 -> 2.6603771
A13: FY2032 | B13: =PL!J16 -> 6.1430881 | C13: =PL!J31 -> 4.0365632 | D13: =PL!J46 -> 2.5404525
A14: 股東現金流＝EPS ×（1 − tp_g ÷ tp_roe）
A15: 再投資率（tp_g ÷ tp_roe，上限 0.8） | B15: =MIN(tp_g/tp_roe,0.8) -> 0.44826298 | E15: ROE 為近三年平均（In 頁 tp_roe）
A16: FY2027 | B16: =B8*(1-$B$15) -> 1.7106739 | C16: =C8*(1-$B$15) -> 1.6520647 | D16: =D8*(1-$B$15) -> 1.5348464
A17: FY2028 | B17: =B9*(1-$B$15) -> 2.2054916 | C17: =C9*(1-$B$15) -> 1.7880264 | D17: =D9*(1-$B$15) -> 1.2785633
A18: FY2029 | B18: =B10*(1-$B$15) -> 2.7059087 | C18: =C10*(1-$B$15) -> 2.2734549 | D18: =D10*(1-$B$15) -> 1.4984623
A19: FY2030 | B19: =B11*(1-$B$15) -> 2.9659953 | C19: =C11*(1-$B$15) -> 2.3252111 | D19: =D11*(1-$B$15) -> 1.5004338
A20: FY2031 | B20: =B12*(1-$B$15) -> 3.1975181 | C20: =C12*(1-$B$15) -> 2.3103158 | D20: =D12*(1-$B$15) -> 1.4678285
A21: FY2032 | B21: =B13*(1-$B$15) -> 3.3893691 | C21: =C13*(1-$B$15) -> 2.2271213 | D21: =D13*(1-$B$15) -> 1.4016617
A22: DCF 情境每股價值（折現率 tp_r） | B22: =SUMPRODUCT(B16:B21,1/(1+tp_r)^{1;2;3;4;5;6})+B21*(1+tp_g)/(tp_r-tp_g)/(1+tp_r)^6 -> 44.497616 | C22: =SUMPRODUCT(C16:C21,1/(1+tp_r)^{1;2;3;4;5;6})+C21*(1+tp_g)/(tp_r-tp_g)/(1+tp_r)^6 -> 30.758125 | D22: =SUMPRODUCT(D16:D21,1/(1+tp_r)^{1;2;3;4;5;6})+D21*(1+tp_g)/(tp_r-tp_g)/(1+tp_r)^6 -> 20.019378 | E22: Σ 明確期現金流 ÷ (1＋r)^t ＋ 永續價值 ÷ (1＋r)^6；永續價值＝FY2032 現金流 ×(1＋g)÷(r−g)；基準日 2026 年底
A23: DCF 情境價值推到 12 個月後（×(1＋tp_r)） | B23: =B22*(1+tp_r) -> 48.947377 | C23: =C22*(1+tp_r) -> 33.833938 | D23: =D22*(1+tp_r) -> 22.021316
A24: DCF 目標價（情境加權） | B24: =tp_wA*B23+tp_wB*C23+tp_wC*D23 -> 36.005445 | E24: Σ 權重 × 情境價值 ×(1＋r)；權重見 In 頁
A26: 0.2 Comparable（市場主流同業前瞻 P/E）
A27: 同業與前瞻 P/E | B27: 代號 | C27: 前瞻 12 月 P/E | D27: 日期 | E27: 來源 | F27: 標記
A28: 日月光投控（ASE Technology） | B28: ASX／3711.TW | C28: 27.37 | D28: 2026-10-23 | E28: stockanalysis.com forward PE（分析師共識；價格日期如左） | F28: Interested-party
A29: 力成（Powertech） | B29: 6239.TW | C29: 20.6 | D29: 2026-10-02 | E29: stockanalysis.com forward PE（分析師共識；價格日期如左） | F29: Interested-party
A30: 京元電子（KYEC） | B30: 2449.TW | C30: 26.13 | D30: 2026-10-06 | E30: stockanalysis.com forward PE（分析師共識；價格日期如左） | F30: Interested-party
A31: 矽格（Sigurd） | B31: 6257.TW | C31: 23.3 | D31: 2026-10-02 | E31: stockanalysis.com forward PE（分析師共識；價格日期如左） | F31: Interested-party
A32: 南茂（ChipMOS） | B32: IMOS／8150.TW | C32: 22.08 | D32: 2026-10-08 | E32: stockanalysis.com forward PE（分析師共識；價格日期如左） | F32: Interested-party
A33: 同業前瞻 P/E 中位數 | B33: =MEDIAN(C28:C32) -> 23.3 | E33: 台美封測同業：日月光、力成、京元電、矽格、南茂（不放 A 股：長電、通富有結構性溢價）
A34: 12 個月後的前瞻 EPS（情境加權） | B34: =tp_wA*(2/12*B8+10/12*B9)+tp_wB*(2/12*C8+10/12*C9)+tp_wC*(2/12*D8+10/12*D9) -> 3.2331437 | E34: 約 2027-10 時的未來 12 月 EPS ≈ 2／12 × FY2027＋10／12 × FY2028（會計年度＝日曆年）
A35: Comparable 目標價 | B35: =B33*B34 -> 75.332249 | E35: 同業中位數 × 前瞻 EPS
A37: 0.3 結論
A38: 項目 | B38: 數值 | E38: 說明
A39: 目標價（DCF 與 Comparable 加權） | B39: =tp_w_dcf*B24+(1-tp_w_dcf)*tp_comp_adj -> 66.3976 | E39: tp_w_dcf × DCF＋（1 − tp_w_dcf）× Comparable；tp_w_dcf 見 In 頁
A40: Comparable 目標價（市場主流同業法） | B40: =B35 -> 75.332249
A41: 市場共識目標價 | B41: =cons_tp -> 76.4 | E41: stockanalysis：11 位分析師平均 76.40（中位數 73.50），2026-10-23 擷取；stocksguide 13 位 71.40
A42: 上檔空間：加權目標價 | B42: =B39/px-1 -> 0.68950636 | E42: 現價＝In 頁 px（2026-10-23 收盤）
A43: 上檔空間：Comparable 目標價 | B43: =B40/px-1 -> 0.91685111
...

Sheet Recon
A1: Recon — 本模型 vs 公司指引、公司長期目標、共識與市場口徑。只作事後對照，不為對上數字而調參數。共識 FY2027 只有單一來源且年度標示不明
A3: 項目 | B3: 對照值 | C3: 模型 A | D3: 差距 A | E3: 模型 B | F3: 差距 B | G3: 模型 C | H3: 差距 C | I3: 對照來源 | J3: 說明
A4: A. FY2026 錨點 vs 公司指引與共識（錨點用 3Q 指引，非獨立檢驗）
A5: 3Q26 營收（各終端市場季增說法加總）vs 指引中點 | B5: =g3_rev -> 2000 | C5: =Q!E4 -> 2020.2312 | D5: =C5/B5-1 -> 0.0101156 | E5: =Q!E4 -> 2020.2312 | F5: =E5/B5-1 -> 0.0101156 | G5: =Q!E4 -> 2020.2312 | H5: =G5/B5-1 -> 0.0101156 | I5: 2Q26 新聞稿：1,950–2,050 | J5: 共識 3Q26 2,040（MarketBeat）
A6: 3Q26 EPS vs 指引中點 | B6: =g3_eps -> 0.77 | C6: =Q!E19 -> 0.77630057 | D6: =C6/B6-1 -> 0.0081825579 | E6: =Q!E19 -> 0.77630057 | F6: =E6/B6-1 -> 0.0081825579 | G6: =Q!E19 -> 0.77630057 | H6: =G6/B6-1 -> 0.0081825579 | I6: 2Q26 新聞稿：0.72–0.82
A7: FY2026 營收 vs 共識 | B7: =cons_rev26 -> 7670 | C7: =PL!D77 -> 7680.463 | D7: =C7/B7-1 -> 0.0013641486 | E7: =PL!D123 -> 7680.463 | F7: =E7/B7-1 -> 0.0013641486 | G7: =PL!D169 -> 7680.463 | H7: =G7/B7-1 -> 0.0013641486 | I7: stockanalysis（11 位） | J7: tickflow 7.47B（7 位）
A8: FY2026 EPS vs 共識（non-GAAP） | B8: =cons_eps26 -> 2.57 | C8: =PL!D101 -> 2.5834778 | D8: =C8/B8-1 -> 0.0052442761 | E8: =PL!D147 -> 2.5834778 | F8: =E8/B8-1 -> 0.0052442761 | G8: =PL!D193 -> 2.5834778 | H8: =G8/B8-1 -> 0.0052442761 | I8: stockanalysis（11 位） | J8: 模型為 GAAP
A9: FY2027 EPS vs 共識（MarketBeat，年度標示不明） | B9: =cons_eps27 -> 2.72 | C9: =PL!E101 -> 3.100524 | D9: =C9/B9-1 -> 0.13989852 | E9: =PL!E147 -> 2.9942974 | F9: =E9/B9-1 -> 0.10084462 | G9: =PL!E193 -> 2.7818442 | H9: =G9/B9-1 -> 0.02273683 | I9: MarketBeat（單一來源）
A10: FY2026 運算年增 vs 公司「超過 20%」（2026-02）（百分點） | B10: 0.2 | C10: =Q!G6/Q!B6-1 -> 0.40440101 | D10: =C10-B10 -> 0.20440101 | E10: =Q!G6/Q!B6-1 -> 0.40440101 | F10: =E10-B10 -> 0.20440101 | G10: =Q!G6/Q!B6-1 -> 0.40440101 | H10: =G10-B10 -> 0.20440101 | I10: 4Q25 法說 | J10: 3Q26 指引運算近 +30% 季增，已高於年初說法
A11: B. vs 公司長期目標（投資人日 2026-05-21；2Q26 財報前訂定）
A12: FY2028 營收 vs 目標 9.0B（±0.5B） | B12: =t28_rev -> 9000 | C12: =PL!F77 -> 9939.6136 | D12: =C12/B12-1 -> 0.10440151 | E12: =PL!F123 -> 9308.94 | F12: =E12/B12-1 -> 0.034326663 | G12: =PL!F169 -> 8529.823 | H12: =G12/B12-1 -> -0.052241888 | I12: 投資人日
A13: FY2028 毛利率 vs 目標 17.5%（±1pt）（百分點） | B13: =t28_gm -> 0.175 | C13: =PL!F90 -> 0.19422352 | D13: =C13-B13 -> 0.019223518 | E13: =PL!F136 -> 0.1796727 | F13: =E13-B13 -> 0.0046727014 | G13: =PL!F182 -> 0.1590966 | H13: =G13-B13 -> -0.015903398 | I13: 投資人日
A14: FY2028 EPS vs 目標 2.50（±0.25） | B14: =t28_eps -> 2.5 | C14: =PL!F101 -> 3.9973602 | D14: =C14/B14-1 -> 0.59894409 | E14: =PL!F147 -> 3.2407222 | F14: =E14/B14-1 -> 0.29628888 | G14: =PL!F193 -> 2.3173418 | H14: =G14/B14-1 -> -0.073063285 | I14: 投資人日 | J14: FY2026 錨點已高於 2028 目標
A15: FY2029 營收 vs 2030 目標 11B（目標年晚一年） | B15: =t30_rev -> 11000 | C15: =PL!G77 -> 11074.49 | D15: =C15/B15-1 -> 0.0067717832 | E15: =PL!G123 -> 10413.325 | F15: =E15/B15-1 -> -0.05333408 | G15: =PL!G169 -> 9229.7377 | H15: =G15/B15-1 -> -0.16093294 | I15: 投資人日
A16: FY2029 毛利率 vs 2030 目標 22%（百分點） | B16: =t30_gm -> 0.22 | C16: =PL!G90 -> 0.2049996 | D16: =C16-B16 -> -0.015000401 | E16: =PL!G136 -> 0.19244362 | F16: =E16-B16 -> -0.027556379 | G16: =PL!G182 -> 0.1653085 | H16: =G16-B16 -> -0.054691496 | I16: 投資人日
A17: FY2029 EPS vs 2030 目標 5.0 | B17: =t30_eps -> 5 | C17: =PL!G101 -> 4.904345 | D17: =C17/B17-1 -> -0.019131006 | E17: =PL!G147 -> 4.1205408 | F17: =E17/B17-1 -> -0.17589185 | G17: =PL!G193 -> 2.7158996 | H17: =G17/B17-1 -> -0.45682009 | I17: 投資人日
A18: 運算 FY2025–29 年均成長 vs 投資人日 2025–30 約 24%（百分點） | B18: 0.24 | C18: =(PL!G72/PL!C72)^(1/4)-1 -> 0.29567651 | D18: =C18-B18 -> 0.055676509 | E18: =(PL!G118/PL!C118)^(1/4)-1 -> 0.26000567 | F18: =E18-B18 -> 0.020005675 | G18: =(PL!G164/PL!C164)^(1/4)-1 -> 0.19279228 | H18: =G18-B18 -> -0.04720772 | I18: 投資人日
A19: C. AI 先進封裝的市場口徑
A20: FY2026 Amkor AI 營收 ÷ OSAT 先進封裝市場（GW × 0.5B） | C20: =Units!C13 -> 0.073614236 | E20: =Units!C13 -> 0.073614236 | G20: =Units!C13 -> 0.073614236 | I20: 投資人日 0.5B／GW；部署 GW 讀網通模型與橋接表 | J20: 隱含市占
A21: FY2027 Amkor AI 營收 ÷ OSAT 先進封裝市場 | C21: =Units!D13 -> 0.08020052 | E21: =Units!D13 -> 0.08020052 | G21: =Units!D13 -> 0.08020052 | I21: 同上 | J21: 情境 A
A22: 台積電 CoWoS 2027 需求 ÷ 可用產能（tsmc 成品） | C22: =cow_util27 -> 0.96254755 | E22: =cow_util27 -> 0.96254755 | G22: =cow_util27 -> 0.96254755 | I22: tsmc/dist CoWoS 頁 | J22: 接近 100% → 後段委外需求上升（本模型委外比例 Assumed 上升的依據之一）
A23: FY2026 每顆加速器 Amkor AI 營收（US$） | C23: =PL!D69 -> 56.662471 | E23: =PL!D115 -> 56.662471 | G23: =PL!D161 -> 56.662471 | I23: — | J23: 對照：台積電模型每顆台積電內容 1.1–6.0 千美元（邏輯＋CoWoS）
A24: D. 亞利桑那
A25: FY2027 亞利桑那對毛利率的影響 vs 公司對營業利益率 −1～−2%（取 −1.5%）（百分點） | B25: -0.015 | C25: =PL!E91 -> -0.013621187 | D25: =C25-B25 -> 0.0013788129 | E25: =PL!E137 -> -0.013763759 | F25: =E25-B25 -> 0.0012362413 | G25: =PL!E183 -> -0.014058047 | H25: =G25-B25 -> 0.00094195307 | I25: 1Q26 法說：2027 起 1–2%、2028 改善；2029 損益兩平（投資人日）
A26: FY2028 亞利桑那對毛利率的影響 vs 公司對營業利益率 −1～−2%（取 −1.5%）（百分點） | B26: -0.015 | C26: =PL!F91 -> -0.011297388 | D26: =C26-B26 -> 0.0037026125 | E26: =PL!F137 -> -0.015016926 | F26: =E26-B26 -> -1.6926438e-05 | G26: =PL!F183 -> -0.01961256 | H26: =G26-B26 -> -0.0046125601 | I26: 1Q26 法說：2027 起 1–2%、2028 改善；2029 損益兩平（投資人日）
A27: FY2029 亞利桑那對毛利率的影響 vs 公司對營業利益率 −1～−2%（取 −1.5%）（百分點） | B27: -0.015 | C27: =PL!G91 -> -0.0013168402 | D27: =C27-B27 -> 0.01368316 | E27: =PL!G137 -> -0.0066821436 | F27: =E27-B27 -> 0.0083178564 | G27: =PL!G183 -> -0.016477536 | H27: =G27-B27 -> -0.0014775359 | I27: 1Q26 法說：2027 起 1–2%、2028 改善；2029 損益兩平（投資人日）
A28: E. 客戶集中
A29: FY2027 通訊 ÷ 營收 vs FY2025 Apple 占營收 29.8%（百分點） | B29: =apple -> 0.298 | C29: =PL!E80 -> 0.35564101 | D29: =C29-B29 -> 0.057641013 | E29: =PL!E126 -> 0.34889657 | F29: =E29-B29 -> 0.050896573 | G29: =PL!E172 -> 0.33497508 | H29: =G29-B29 -> 0.036975078 | I29: 10-K | J29: 通訊含 Android 與 Qualcomm；只看方向

Sheet Sens
A1: Sens — 一次動一個輸入（情境 A；FY2026 恆等於錨點，AI 拆分與每顆金額在每個案例內重算）：對 FY2027、FY2028 營收、毛利率與 EPS 的影響。每個案例是一個完整推導區塊（本頁下方）
A3: 案例 | B3: 設定 | C3: FY2027 營收 | D3: FY2027 毛利率 | E3: FY2027 EPS | F3: FY2027 EPS 相對基準 | G3: FY2028 營收 | H3: FY2028 毛利率 | I3: FY2028 EPS | J3: FY2028 EPS 相對基準
A4: 基準（情境 A） | B4: PL 區塊 A | C4: =PL!E77 -> 8809.8048 | D4: =PL!E90 -> 0.18069588 | E4: =PL!E101 -> 3.100524 | F4: =E4/E$4-1 -> 0 | G4: =PL!F77 -> 9939.6136 | H4: =PL!F90 -> 0.19422352 | I4: =PL!F101 -> 3.9973602 | J4: =I4/I$4-1 -> 0
A5: AI 部署 ×0.8 | B5: FY2027 起顆數 ×0.8 | C5: =E57 -> 8475.7956 | D5: =E70 -> 0.17205367 | E5: =E81 -> 2.711721 | F5: =E5/E$4-1 -> -0.12539912 | G5: =F57 -> 9484.2651 | H5: =F70 -> 0.18504834 | I5: =F81 -> 3.4857749 | J5: =I5/I$4-1 -> -0.12798079
A6: AI 部署 ×1.2 | B6: ×1.2 | C6: =E103 -> 9143.8141 | D6: =E116 -> 0.18870672 | E6: =E127 -> 3.489327 | F6: =E6/E$4-1 -> 0.12539912 | G6: =F103 -> 10394.962 | H6: =F116 -> 0.20259486 | I6: =F127 -> 4.509248 | J6: =I6/I$4-1 -> 0.12805645
A7: 委外比例 低 | B7: 2027 45%、2028–29 45% | C7: =E149 -> 8506.1601 | D7: =E162 -> 0.17286738 | E7: =E173 -> 2.7470667 | F7: =E7/E$4-1 -> -0.1139992 | G7: =F149 -> 9370.428 | H7: =F162 -> 0.18237218 | I7: =F173 -> 3.3506942 | J7: =I7/I$4-1 -> -0.16177326
A8: 委外比例 高 | B8: 2027 65%、2028 70%、2029 75% | C8: =E195 -> 9113.4496 | D8: =E208 -> 0.18800273 | E8: =E219 -> 3.4539812 | F8: =E8/E$4-1 -> 0.1139992 | G8: =F195 -> 10319.071 | H8: =F208 -> 0.2012019 | I8: =F219 -> 4.4222303 | J8: =I8/I$4-1 -> 0.10628767
A9: Amkor 份額 低 | B9: 28%（日月光、矽品搶單） | C9: =E241 -> 8475.7956 | D9: =E254 -> 0.17205367 | E9: =E265 -> 2.711721 | F9: =E9/E$4-1 -> -0.12539912 | G9: =F241 -> 9385.8114 | H9: =F254 -> 0.18279357 | I9: =F265 -> 3.3706324 | J9: =I9/I$4-1 -> -0.15678543
A10: Amkor 份額 高 | B10: 2027 40%、2028–29 45% | C10: =E287 -> 9048.3829 | D10: =E300 -> 0.18647826 | E10: =E311 -> 3.3782404 | F10: =E10/E$4-1 -> 0.089570801 | G10: =F287 -> 10431.882 | H10: =F300 -> 0.20347647 | I10: =F311 -> 4.5588539 | J10: =I10/I$4-1 -> 0.14046611
A11: 每顆金額彈性 0.3 | B11: 封裝面積帶動較少 | C11: =E333 -> 8729.812 | D11: =E346 -> 0.17868636 | E11: =E357 -> 3.0074085 | F11: =E11/E$4-1 -> -0.030032179 | G11: =F333 -> 9782.8467 | H11: =F346 -> 0.19108956 | I11: =F357 -> 3.818935 | J11: =I11/I$4-1 -> -0.04463576
A12: 每顆金額彈性 1.0 | B12: 與面積等比例 | C12: =E379 -> 9027.8387 | D12: =E392 -> 0.18599236 | E12: =E403 -> 3.354326 | F12: =E12/E$4-1 -> 0.081857798 | G12: =F379 -> 10384.14 | H12: =F392 -> 0.20261251 | I12: =F403 -> 4.5042036 | J12: =I12/I$4-1 -> 0.12679451
A13: AI 三倍 → 2.5 倍 | B13: FY2026 AI 拆分較大、基期較高 | C13: =E425 -> 8892.5336 | D13: =E438 -> 0.18273611 | E13: =E449 -> 3.1968243 | F13: =E13/E$4-1 -> 0.031059376 | G13: =F425 -> 10083.637 | H13: =F438 -> 0.19699851 | I13: =F449 -> 4.160733 | J13: =I13/I$4-1 -> 0.040870156
A14: 通訊 情境 C 路徑 | B14: FY2027 −6%、之後 0% | C14: =E471 -> 8536.0364 | D14: =E484 -> 0.17366234 | E14: =E495 -> 2.7818442 | F14: =E14/E$4-1 -> -0.10278256 | G14: =F471 -> 9540.52 | H14: =F484 -> 0.1861895 | I14: =F495 -> 3.5477537 | J14: =I14/I$4-1 -> -0.11247586
A15: 車用與工業 +4% | B15: 基準 +10% | C15: =E517 -> 8710.3853 | D15: =E530 -> 0.17819277 | E15: =E541 -> 2.9847948 | F15: =E15/E$4-1 -> -0.037325671 | G15: =F517 -> 9726.8558 | H15: =F530 -> 0.18992694 | I15: =F541 -> 3.7546308 | J15: =I15/I$4-1 -> -0.060722433
A16: 車用與工業 +14% | C16: =E563 -> 8876.0845 | D16: =E576 -> 0.18233348 | E16: =E587 -> 3.1776767 | F16: =E16/E$4-1 -> 0.024883781 | G16: =F563 -> 10088.08 | H16: =F576 -> 0.19712053 | I16: =F587 -> 4.1670113 | J16: =I16/I$4-1 -> 0.042440782
A17: 現金流通率 30% | B17: 基準 40% | C17: =E609 -> 8809.8048 | D17: =E622 -> 0.16787674 | E17: =E633 -> 2.7390117 | F17: =E17/E$4-1 -> -0.11659716 | G17: =F609 -> 9939.6136 | H17: =F622 -> 0.17300387 | I17: =F633 -> 3.3222025 | J17: =I17/I$4-1 -> -0.1689009
A18: 現金流通率 50% | C18: =E655 -> 8809.8048 | D18: =E668 -> 0.19351503 | E18: =E679 -> 3.4620363 | F18: =E18/E$4-1 -> 0.11659716 | G18: =F655 -> 9939.6136 | H18: =F668 -> 0.21544316 | I18: =F679 -> 4.672518 | J18: =I18/I$4-1 -> 0.1689009
A19: 本業資本支出率 18% | B19: 折舊上升較快 | C19: =E701 -> 8809.8048 | D19: =E714 -> 0.18069588 | E19: =E725 -> 3.100524 | F19: =E19/E$4-1 -> 0 | G19: =F701 -> 9939.6136 | H19: =F714 -> 0.18915876 | I19: =F725 -> 3.8362119 | J19: =I19/I$4-1 -> -0.040313696
A20: 本業折舊年限 5 年 | B20: 基準 7 年 | C20: =E747 -> 8809.8048 | D20: =E760 -> 0.17771609 | E20: =E771 -> 3.0164908 | F20: =E20/E$4-1 -> -0.027102884 | G20: =F747 -> 9939.6136 | H20: =F760 -> 0.18965499 | I20: =F771 -> 3.8520008 | J20: =I20/I$4-1 -> -0.036363856
A21: 亞利桑那固定成本 高 | B21: 2027 170、2028–29 150 | C21: =E793 -> 8809.8048 | D21: =E806 -> 0.17502039 | E21: =E817 -> 2.9404696 | F21: =E21/E$4-1 -> -0.051621732 | G21: =F793 -> 9939.6136 | H21: =F806 -> 0.18919314 | I21: =F817 -> 3.8373058 | J21: =I21/I$4-1 -> -0.040040029
A22: 亞利桑那補助 20% | B22: 基準 35% | C22: =E839 -> 8809.8048 | D22: =E852 -> 0.18069588 | E22: =E863 -> 3.100524 | F22: =E22/E$4-1 -> 0 | G22: =F839 -> 9939.6136 | H22: =F852 -> 0.19202273 | I22: =F863 -> 3.9273364 | J22: =I22/I$4-1 -> -0.017517513
A23: 營業費用彈性 1.0 | B23: 基準 0.5 | C23: =E885 -> 8809.8048 | D23: =E898 -> 0.18069588 | E23: =E909 -> 2.9690836 | F23: =E23/E$4-1 -> -0.042392962 | G23: =F885 -> 9939.6136 | H23: =F898 -> 0.19422352 | I23: =F909 -> 3.7259969 | J23: =I23/I$4-1 -> -0.067885646
A24: 稅率 25% | B24: 基準 20% | C24: =E931 -> 8809.8048 | D24: =E944 -> 0.18069588 | E24: =E955 -> 2.905991 | F24: =E24/E$4-1 -> -0.062741977 | G24: =F931 -> 9939.6136 | H24: =F944 -> 0.19422352 | I24: =F955 -> 3.746775 | J24: =I24/I$4-1 -> -0.062687688
A25: 營業外 −40 | B25: 每年再 −40 | C25: =E977 -> 8809.8048 | D25: =E990 -> 0.18069588 | E25: =E1001 -> 2.9724804 | F25: =E25/E$4-1 -> -0.041297386 | G25: =F977 -> 9939.6136 | H25: =F990 -> 0.19422352 | I25: =F1001 -> 3.8693167 | J25: =I25/I$4-1 -> -0.032032023
A26: 情境 B | B26: CY2028 顆數 ×0.8、CY2029 ×0.85；通訊較弱 | C26: =PL!E123 -> 8718.5487 | D26: =PL!E136 -> 0.17840045 | E26: =PL!E147 -> 2.9942974 | F26: =E26/E$4-1 -> -0.034260854 | G26: =PL!F123 -> 9308.94 | H26: =PL!F136 -> 0.1796727 | I26: =PL!F147 -> 3.2407222 | J26: =I26/I$4-1 -> -0.18928443
A27: 情境 C | B27: CY2028–29 顆數 ×0.6；通訊 −6% | C27: =PL!E169 -> 8536.0364 | D27: =PL!E182 -> 0.17366234 | E27: =PL!E193 -> 2.7818442 | F27: =E27/E$4-1 -> -0.10278256 | G27: =PL!F169 -> 8529.823 | H27: =PL!F182 -> 0.1590966 | I27: =PL!F193 -> 2.3173418 | J27: =I27/I$4-1 -> -0.42028197
A29: 讀法：顆數情境 B、C 的差異從 FY2028 起；FY2027 只差通訊與亞利桑那啟動成本。委外比例、份額、彈性只影響 AI 先進封裝（FY2026 約占營收一成），所以單項影響小於流通率與通訊；毛利率對流通率最敏感。
A31: 目標價參數（只改 DCF 參數；PL 收斂法的 fade_g 不隨 tp_g 變動）
A32: 案例 | B32: 設定 | C32: DCF 目標價 | D32: Comparable 目標價（相對倍數調整後） | E32: 加權目標價 | F32: 相對基準
A33: 基準 | B33: r 10%、g 4%、DCF 權重 0.5 | C33: =(tp_wA*(Val!B8*(1-MIN(tp_g/tp_roe,0.8))/(1+tp_r)^1+Val!B9*(1-MIN(tp_g/tp_roe,0.8))/(1+tp_r)^2+Val!B10*(1-MIN(tp_g/tp_roe,0.8))/(1+tp_r)^3+Val!B11*(1-MIN(tp_g/tp_roe,0.8))/(1+tp_r)^4+Val!B12*(1-MIN(tp_g/tp_roe,0.8))/(1+tp_r)^5+Val!B13*(1-MIN(tp_g/tp_roe,0.8))/(1+tp_r)^6+Val!B13*(1-MIN(tp_g/tp_roe,0.8))*(1+tp_g)/(tp_r-tp_g)/(1+tp_r)^6)+tp_wB*(Val!C8*(1-MIN(tp_g/tp_roe,0.8))/(1+tp_r)^1+Val!C9*(1-MIN(tp_g/tp_roe,0.8))/(1+tp_r)^2+Val!C10*(1-MIN(tp_g/tp_roe,0.8))/(1+tp_r)^3+Val!C11*(1-MIN(tp_g/tp_roe,0.8))/(1+tp_r)^4+Val!C12*(1-MIN(tp_g/tp_roe,0.8))/(1+tp_r)^5+Val!C13*(1-MIN(tp_g/tp_roe,0.8))/(1+tp_r)^6+Val!C13*(1-MIN(tp_g/tp_roe,0.8))*(1+tp_g)/(tp_r-tp_g)/(1+tp_r)^6)+tp_wC*(Val!D8*(1-MIN(tp_g/tp_roe,0.8))/(1+tp_r)^1+Val!D9*(1-MIN(tp_g/tp_roe,0.8))/(1+tp_r)^2+Val!D10*(1-MIN(tp_g/tp_roe,0.8))/(1+tp_r)^3+Val!D11*(1-MIN(tp_g/tp_roe,0.8))/(1+tp_r)^4+Val!D12*(1-MIN(tp_g/tp_roe,0.8))/(1+tp_r)^5+Val!D13*(1-MIN(tp_g/tp_roe,0.8))/(1+tp_r)^6+Val!D13*(1-MIN(tp_g/tp_roe,0.8))*(1+tp_g)/(tp_r-tp_g)/(1+tp_r)^6))*(1+tp_r) -> 36.005445 | D33: =tp_comp_adj -> 96.789755 | E33: =tp_w_dcf*C33+(1-tp_w_dcf)*D33 -> 66.3976 | F33: =E33/E$33-1 -> 0
A34: 折現率 +1pt | B34: r 11% | C34: =(tp_wA*(Val!B8*(1-MIN(tp_g/tp_roe,0.8))/(1+(tp_r+0.01))^1+Val!B9*(1-MIN(tp_g/tp_roe,0.8))/(1+(tp_r+0.01))^2+Val!B10*(1-MIN(tp_g/tp_roe,0.8))/(1+(tp_r+0.01))^3+Val!B11*(1-MIN(tp_g/tp_roe,0.8))/(1+(tp_r+0.01))^4+Val!B12*(1-MIN(tp_g/tp_roe,0.8))/(1+(tp_r+0.01))^5+Val!B13*(1-MIN(tp_g/tp_roe,0.8))/(1+(tp_r+0.01))^6+Val!B13*(1-MIN(tp_g/tp_roe,0.8))*(1+tp_g)/((tp_r+0.01)-tp_g)/(1+(tp_r+0.01))^6)+tp_wB*(Val!C8*(1-MIN(tp_g/tp_roe,0.8))/(1+(tp_r+0.01))^1+Val!C9*(1-MIN(tp_g/tp_roe,0.8))/(1+(tp_r+0.01))^2+Val!C10*(1-MIN(tp_g/tp_roe,0.8))/(1+(tp_r+0.01))^3+Val!C11*(1-MIN(tp_g/tp_roe,0.8))/(1+(tp_r+0.01))^4+Val!C12*(1-MIN(tp_g/tp_roe,0.8))/(1+(tp_r+0.01))^5+Val!C13*(1-MIN(tp_g/tp_roe,0.8))/(1+(tp_r+0.01))^6+Val!C13*(1-MIN(tp_g/tp_roe,0.8))*(1+tp_g)/((tp_r+0.01)-tp_g)/(1+(tp_r+0.01))^6)+tp_wC*(Val!D8*(1-MIN(tp_g/tp_roe,0.8))/(1+(tp_r+0.01))^1+Val!D9*(1-MIN(tp_g/tp_roe,0.8))/(1+(tp_r+0.01))^2+Val!D10*(1-MIN(tp_g/tp_roe,0.8))/(1+(tp_r+0.01))^3+Val!D11*(1-MIN(tp_g/tp_roe,0.8))/(1+(tp_r+0.01))^4+Val!D12*(1-MIN(tp_g/tp_roe,0.8))/(1+(tp_r+0.01))^5+Val!D13*(1-MIN(tp_g/tp_roe,0.8))/(1+(tp_r+0.01))^6+Val!D13*(1-MIN(tp_g/tp_roe,0.8))*(1+tp_g)/((tp_r+0.01)-tp_g)/(1+(tp_r+0.01))^6))*(1+(tp_r+0.01)) -> 31.094876 | D34: =tp_comp_adj -> 96.789755 | E34: =tp_w_dcf*C34+(1-tp_w_dcf)*D34 -> 63.942315 | F34: =E34/E$33-1 -> -0.036978519
A35: 折現率 −1pt | B35: r 9% | C35: =(tp_wA*(Val!B8*(1-MIN(tp_g/tp_roe,0.8))/(1+(tp_r-0.01))^1+Val!B9*(1-MIN(tp_g/tp_roe,0.8))/(1+(tp_r-0.01))^2+Val!B10*(1-MIN(tp_g/tp_roe,0.8))/(1+(tp_r-0.01))^3+Val!B11*(1-MIN(tp_g/tp_roe,0.8))/(1+(tp_r-0.01))^4+Val!B12*(1-MIN(tp_g/tp_roe,0.8))/(1+(tp_r-0.01))^5+Val!B13*(1-MIN(tp_g/tp_roe,0.8))/(1+(tp_r-0.01))^6+Val!B13*(1-MIN(tp_g/tp_roe,0.8))*(1+tp_g)/((tp_r-0.01)-tp_g)/(1+(tp_r-0.01))^6)+tp_wB*(Val!C8*(1-MIN(tp_g/tp_roe,0.8))/(1+(tp_r-0.01))^1+Val!C9*(1-MIN(tp_g/tp_roe,0.8))/(1+(tp_r-0.01))^2+Val!C10*(1-MIN(tp_g/tp_roe,0.8))/(1+(tp_r-0.01))^3+Val!C11*(1-MIN(tp_g/tp_roe,0.8))/(1+(tp_r-0.01))^4+Val!C12*(1-MIN(tp_g/tp_roe,0.8))/(1+(tp_r-0.01))^5+Val!C13*(1-MIN(tp_g/tp_roe,0.8))/(1+(tp_r-0.01))^6+Val!C13*(1-MIN(tp_g/tp_roe,0.8))*(1+tp_g)/((tp_r-0.01)-tp_g)/(1+(tp_r-0.01))^6)+tp_wC*(Val!D8*(1-MIN(tp_g/tp_roe,0.8))/(1+(tp_r-0.01))^1+Val!D9*(1-MIN(tp_g/tp_roe,0.8))/(1+(tp_r-0.01))^2+Val!D10*(1-MIN(tp_g/tp_roe,0.8))/(1+(tp_r-0.01))^3+Val!D11*(1-MIN(tp_g/tp_roe,0.8))/(1+(tp_r-0.01))^4+Val!D12*(1-MIN(tp_g/tp_roe,0.8))/(1+(tp_r-0.01))^5+Val!D13*(1-MIN(tp_g/tp_roe,0.8))/(1+(tp_r-0.01))^6+Val!D13*(1-MIN(tp_g/tp_roe,0.8))*(1+tp_g)/((tp_r-0.01)-tp_g)/(1+(tp_r-0.01))^6))*(1+(tp_r-0.01)) -> 42.878767 | D35: =tp_comp_adj -> 96.789755 | E35: =tp_w_dcf*C35+(1-tp_w_dcf)*D35 -> 69.834261 | F35: =E35/E$33-1 -> 0.051758808
A36: 長期成長 +1pt | B36: g 5% | C36: =(tp_wA*(Val!B8*(1-MIN((tp_g+0.01)/tp_roe,0.8))/(1+tp_r)^1+Val!B9*(1-MIN((tp_g+0.01)/tp_roe,0.8))/(1+tp_r)^2+Val!B10*(1-MIN((tp_g+0.01)/tp_roe,0.8))/(1+tp_r)^3+Val!B11*(1-MIN((tp_g+0.01)/tp_roe,0.8))/(1+tp_r)^4+Val!B12*(1-MIN((tp_g+0.01)/tp_roe,0.8))/(1+tp_r)^5+Val!B13*(1-MIN((tp_g+0.01)/tp_roe,0.8))/(1+tp_r)^6+Val!B13*(1-MIN((tp_g+0.01)/tp_roe,0.8))*(1+(tp_g+0.01))/(tp_r-(tp_g+0.01))/(1+tp_r)^6)+tp_wB*(Val!C8*(1-MIN((tp_g+0.01)/tp_roe,0.8))/(1+tp_r)^1+Val!C9*(1-MIN((tp_g+0.01)/tp_roe,0.8))/(1+tp_r)^2+Val!C10*(1-MIN((tp_g+0.01)/tp_roe,0.8))/(1+tp_r)^3+Val!C11*(1-MIN((tp_g+0.01)/tp_roe,0.8))/(1+tp_r)^4+Val!C12*(1-MIN((tp_g+0.01)/tp_roe,0.8))/(1+tp_r)^5+Val!C13*(1-MIN((tp_g+0.01)/tp_roe,0.8))/(1+tp_r)^6+Val!C13*(1-MIN((tp_g+0.01)/tp_roe,0.8))*(1+(tp_g+0.01))/(tp_r-(tp_g+0.01))/(1+tp_r)^6)+tp_wC*(Val!D8*(1-MIN((tp_g+0.01)/tp_roe,0.8))/(1+tp_r)^1+Val!D9*(1-MIN((tp_g+0.01)/tp_roe,0.8))/(1+tp_r)^2+Val!D10*(1-MIN((tp_g+0.01)/tp_roe,0.8))/(1+tp_r)^3+Val!D11*(1-MIN((tp_g+0.01)/tp_roe,0.8))/(1+tp_r)^4+Val!D12*(1-MIN((tp_g+0.01)/tp_roe,0.8))/(1+tp_r)^5+Val!D13*(1-MIN((tp_g+0.01)/tp_roe,0.8))/(1+tp_r)^6+Val!D13*(1-MIN((tp_g+0.01)/tp_roe,0.8))*(1+(tp_g+0.01))/(tp_r-(tp_g+0.01))/(1+tp_r)^6))*(1+tp_r) -> 33.065908 | D36: =tp_comp_adj -> 96.789755 | E36: =tp_w_dcf*C36+(1-tp_w_dcf)*D36 -> 64.927832 | F36: =E36/E$33-1 -> -0.022135868
A37: 長期成長 −1pt | B37: g 3% | C37: =(tp_wA*(Val!B8*(1-MIN((tp_g-0.01)/tp_roe,0.8))/(1+tp_r)^1+Val!B9*(1-MIN((tp_g-0.01)/tp_roe,0.8))/(1+tp_r)^2+Val!B10*(1-MIN((tp_g-0.01)/tp_roe,0.8))/(1+tp_r)^3+Val!B11*(1-MIN((tp_g-0.01)/tp_roe,0.8))/(1+tp_r)^4+Val!B12*(1-MIN((tp_g-0.01)/tp_roe,0.8))/(1+tp_r)^5+Val!B13*(1-MIN((tp_g-0.01)/tp_roe,0.8))/(1+tp_r)^6+Val!B13*(1-MIN((tp_g-0.01)/tp_roe,0.8))*(1+(tp_g-0.01))/(tp_r-(tp_g-0.01))/(1+tp_r)^6)+tp_wB*(Val!C8*(1-MIN((tp_g-0.01)/tp_roe,0.8))/(1+tp_r)^1+Val!C9*(1-MIN((tp_g-0.01)/tp_roe,0.8))/(1+tp_r)^2+Val!C10*(1-MIN((tp_g-0.01)/tp_roe,0.8))/(1+tp_r)^3+Val!C11*(1-MIN((tp_g-0.01)/tp_roe,0.8))/(1+tp_r)^4+Val!C12*(1-MIN((tp_g-0.01)/tp_roe,0.8))/(1+tp_r)^5+Val!C13*(1-MIN((tp_g-0.01)/tp_roe,0.8))/(1+tp_r)^6+Val!C13*(1-MIN((tp_g-0.01)/tp_roe,0.8))*(1+(tp_g-0.01))/(tp_r-(tp_g-0.01))/(1+tp_r)^6)+tp_wC*(Val!D8*(1-MIN((tp_g-0.01)/tp_roe,0.8))/(1+tp_r)^1+Val!D9*(1-MIN((tp_g-0.01)/tp_roe,0.8))/(1+tp_r)^2+Val!D10*(1-MIN((tp_g-0.01)/tp_roe,0.8))/(1+tp_r)^3+Val!D11*(1-MIN((tp_g-0.01)/tp_roe,0.8))/(1+tp_r)^4+Val!D12*(1-MIN((tp_g-0.01)/tp_roe,0.8))/(1+tp_r)^5+Val!D13*(1-MIN((tp_g-0.01)/tp_roe,0.8))/(1+tp_r)^6+Val!D13*(1-MIN((tp_g-0.01)/tp_roe,0.8))*(1+(tp_g-0.01))/(tp_r-(tp_g-0.01))/(1+tp_r)^6))*(1+tp_r) -> 38.602052 | D37: =tp_comp_adj -> 96.789755 | E37: =tp_w_dcf*C37+(1-tp_w_dcf)*D37 -> 67.695903 | F37: =E37/E$33-1 -> 0.019553469
A38: DCF 權重 0.3 | B38: Comparable 0.7 | C38: =(tp_wA*(Val!B8*(1-MIN(tp_g/tp_roe,0.8))/(1+tp_r)^1+Val!B9*(1-MIN(tp_g/tp_roe,0.8))/(1+tp_r)^2+Val!B10*(1-MIN(tp_g/tp_roe,0.8))/(1+tp_r)^3+Val!B11*(1-MIN(tp_g/tp_roe,0.8))/(1+tp_r)^4+Val!B12*(1-MIN(tp_g/tp_roe,0.8))/(1+tp_r)^5+Val!B13*(1-MIN(tp_g/tp_roe,0.8))/(1+tp_r)^6+Val!B13*(1-MIN(tp_g/tp_roe,0.8))*(1+tp_g)/(tp_r-tp_g)/(1+tp_r)^6)+tp_wB*(Val!C8*(1-MIN(tp_g/tp_roe,0.8))/(1+tp_r)^1+Val!C9*(1-MIN(tp_g/tp_roe,0.8))/(1+tp_r)^2+Val!C10*(1-MIN(tp_g/tp_roe,0.8))/(1+tp_r)^3+Val!C11*(1-MIN(tp_g/tp_roe,0.8))/(1+tp_r)^4+Val!C12*(1-MIN(tp_g/tp_roe,0.8))/(1+tp_r)^5+Val!C13*(1-MIN(tp_g/tp_roe,0.8))/(1+tp_r)^6+Val!C13*(1-MIN(tp_g/tp_roe,0.8))*(1+tp_g)/(tp_r-tp_g)/(1+tp_r)^6)+tp_wC*(Val!D8*(1-MIN(tp_g/tp_roe,0.8))/(1+tp_r)^1+Val!D9*(1-MIN(tp_g/tp_roe,0.8))/(1+tp_r)^2+Val!D10*(1-MIN(tp_g/tp_roe,0.8))/(1+tp_r)^3+Val!D11*(1-MIN(tp_g/tp_roe,0.8))/(1+tp_r)^4+Val!D12*(1-MIN(tp_g/tp_roe,0.8))/(1+tp_r)^5+Val!D13*(1-MIN(tp_g/tp_roe,0.8))/(1+tp_r)^6+Val!D13*(1-MIN(tp_g/tp_roe,0.8))*(1+tp_g)/(tp_r-tp_g)/(1+tp_r)^6))*(1+tp_r) -> 36.005445 | D38: =tp_comp_adj -> 96.789755 | E38: =0.3*C38+(1-0.3)*D38 -> 78.554462 | F38: =E38/E$33-1 -> 0.18309189
A39: DCF 權重 0.7 | B39: Comparable 0.3 | C39: =(tp_wA*(Val!B8*(1-MIN(tp_g/tp_roe,0.8))/(1+tp_r)^1+Val!B9*(1-MIN(tp_g/tp_roe,0.8))/(1+tp_r)^2+Val!B10*(1-MIN(tp_g/tp_roe,0.8))/(1+tp_r)^3+Val!B11*(1-MIN(tp_g/tp_roe,0.8))/(1+tp_r)^4+Val!B12*(1-MIN(tp_g/tp_roe,0.8))/(1+tp_r)^5+Val!B13*(1-MIN(tp_g/tp_roe,0.8))/(1+tp_r)^6+Val!B13*(1-MIN(tp_g/tp_roe,0.8))*(1+tp_g)/(tp_r-tp_g)/(1+tp_r)^6)+tp_wB*(Val!C8*(1-MIN(tp_g/tp_roe,0.8))/(1+tp_r)^1+Val!C9*(1-MIN(tp_g/tp_roe,0.8))/(1+tp_r)^2+Val!C10*(1-MIN(tp_g/tp_roe,0.8))/(1+tp_r)^3+Val!C11*(1-MIN(tp_g/tp_roe,0.8))/(1+tp_r)^4+Val!C12*(1-MIN(tp_g/tp_roe,0.8))/(1+tp_r)^5+Val!C13*(1-MIN(tp_g/tp_roe,0.8))/(1+tp_r)^6+Val!C13*(1-MIN(tp_g/tp_roe,0.8))*(1+tp_g)/(tp_r-tp_g)/(1+tp_r)^6)+tp_wC*(Val!D8*(1-MIN(tp_g/tp_roe,0.8))/(1+tp_r)^1+Val!D9*(1-MIN(tp_g/tp_roe,0.8))/(1+tp_r)^2+Val!D10*(1-MIN(tp_g/tp_roe,0.8))/(1+tp_r)^3+Val!D11*(1-MIN(tp_g/tp_roe,0.8))/(1+tp_r)^4+Val!D12*(1-MIN(tp_g/tp_roe,0.8))/(1+tp_r)^5+Val!D13*(1-MIN(tp_g/tp_roe,0.8))/(1+tp_r)^6+Val!D13*(1-MIN(tp_g/tp_roe,0.8))*(1+tp_g)/(tp_r-tp_g)/(1+tp_r)^6))*(1+tp_r) -> 36.005445 | D39: =tp_comp_adj -> 96.789755 | E39: =0.7*C39+(1-0.7)*D39 -> 54.240738 | F39: =E39/E$33-1 -> -0.18309189
A40: 案例區塊：AI 部署 ×0.8（情境 A）
A41: 項目 | B41: 單位 | C41: FY2025A | D41: FY2026（錨點） | E41: FY2027 | F41: FY2028 | G41: FY2029 | H41: FY2030（收斂） | I41: FY2031（收斂） | J41: FY2032（收斂） | K41: 說明
A42: A. AI 加速器 → Amkor AI 先進封裝（D 欄＝FY2026 校準年）
A43: AI 加速器顆數（含情境係數） | B43: 百萬顆 | D43: =units_26 -> 15.2 | E43: =units_27*0.8 -> 18.96 | F43: =units_28*um28_A*0.8 -> 21.2 | G43: =units_29*um29_A*0.8 -> 24.12
...

Sheet Sources
A1: 來源（SEC 申報為公司原文；法說內容經逐字稿與摘要；券商與資料商皆為 Interested-party）
A2: 公司：2Q26 新聞稿（SEC 8-K，2026-07-27；1H26、2Q26 損益、終端市場占比、3Q26 指引、資本支出） | B2: https://www.sec.gov/Archives/edgar/data/0001047127/000104712726000043/amkr6302026erex-991.htm
A3: 公司：4Q25 新聞稿（SEC 8-K，2026-02-09；FY2025 損益、終端市場占比、先進／主流產品） | B3: https://www.sec.gov/Archives/edgar/data/1047127/000104712726000007/amkr123125erex-991.htm
A4: 公司：FY2025 10-K（Apple 29.8%、Qualcomm 11.1%、前十大 72%、2.5D 與 HDFO 說明） | B4: https://www.sec.gov/Archives/edgar/data/1047127/000104712726000014/amkr-20251231.htm
A5: 公司：投資人日簡報（SEC 8-K，2026-05-21；2028、2030 目標、終端市場 CAGR、亞利桑那、0.5B／GW） | B5: https://www.sec.gov/Archives/edgar/data/0001047127/000104712726000036/ex-991amkorinvestorprese.htm
A6: 公司：4Q25 法說逐字稿（Motley Fool；2.5D 與 HDFO 近三倍、亞利桑那第一期約一半、資產出售 30） | B6: https://www.fool.com/earnings/call-transcripts/2026/02/09/amkor-amkr-q4-2025-earnings-call-transcript/
A7: 公司：1Q26 法說逐字稿（Motley Fool；AI 封裝三倍、亞利桑那稀釋 1–2%、CHIPS 400M＋35% 抵減） | B7: https://www.fool.com/earnings/call-transcripts/2026/04/27/amkor-amkr-q1-2026-earnings-call-transcript/
A8: 公司（摘要）：MarketBeat 2Q26 法說重點（3Q 各終端市場、營業費用 140、NVIDIA、台積電合作） | B8: https://www.marketbeat.com/instant-alerts/amkor-technology-q2-earnings-call-highlights-2026-07-27/
A9: 公司：亞利桑那第二期、投資擴大至約 US$12B（2026-09-08） | B9: https://ir.amkor.com/node/24686
A10: 公司：亞利桑那 US$7B 計畫（Business Wire 2025-10-06） | B10: https://www.businesswire.com/news/home/20251006108489/en
A11: 公司：與 NVIDIA 策略合作（Business Wire 2026-07-23）；Reuters 經 The Star：US$1.5B | B11: https://www.thestar.com.my/tech/tech-news/2026/07/24/nvidia-amkor-strike-15-billion-chip-packaging-deal
A12: 公司：與台積電長期合作（Business Wire 2026-06-16） | B12: https://www.businesswire.com/news/home/20260616574153/en/
A13: 媒體：Manufacturing Dive（亞利桑那 2027 年中完工、2028 年初投產、CHIPS 407M） | B13: https://www.manufacturingdive.com/news/amkor-arizona-7-billion-semiconductor-tsmc-apple-nvidia/802297/
... A25: SemiAnalysis | B25: 未使用
