Workbook

Sheet README
A1: AMD（AMD）收支與估值模型 v0.2（AI 半導體 Project：運算層，GPU 側非 NVIDIA 份額） 2026-10-25
A2: 本版：運算層第三個模型，複製 nvidia/ 的結構，匯入 nvidia/accel_share.py 的份額函式（AMD 為 GPU 側非 NVIDIA 份額）；Val 頁第 0 節為情境加權目標價。
A3: 模型命題：AMD 的資料中心 GPU 營收＝加速器市場（本專案加速器數量層 × 各平台每顆價）× AMD 金額份額；OpenAI、Meta 各 6 GW 與 Anthropic、Oracle 大單在 2026 下半年起放量，但每 GW 附帶認股權證稀釋，HBM 漲價又壓 GPU 毛利率。股價約為 FY2027 共識 EPS 的 33 倍：要多少大單如期放量、毛利率守住多少，才撐得住現價。
A4: 核心問題：以市場層顆數推得的 AMD 資料中心 GPU 營收與 EPS，能否支撐現價與公司「2027 年資料中心逾一倍、EPS 逾 $20」的說法；差距來自顆數、售價還是毛利率。
A6: 會計年度：AMD 會計年度約在 12 月最後一個週六結束，等於日曆年（FY2026＝CY2026），上游市場層直接對照，不平移。預測期 FY2027–FY2029；FY2026 為錨點（Q1、Q2 實績＋Q3 指引＋Q4 假設）。
A8: 驅動因子 → 推導量（全部唯讀上游，不修改）
A9: 資料中心 GPU：加速器市場金額（Units 頁，markets/memory UNITS × 情境係數 × NVIDIA 模型同一套每顆價）× AMD 金額份額 × k_rec（FY2026 校準）× 世代售價係數（基準 1.0）；HBM 漲價依吸收比例轉嫁或壓毛利率。資料中心非 GPU（EPYC CPU 等）、Client、Gaming、Embedded：FY2026 錨點 × 簡化成長率（Assumed）。
A10: 毛利率：GPU 毛利率（Assumed 50%）＋非 GPU 毛利率（FY2026 校準到錨點，Derived）；FY2027 起變化來自 GPU 占比上升與 HBM 價格（markets/memory 2027 +80%）。營業費用彈性（FY2026 推得）、稅率 13%（公司）、股數＋OpenAI／Meta 認股權證（各 160M 股，依 GW 線性歸屬，Assumed）。
A11: EPS 口徑：non-GAAP（公司口徑，排除股票薪酬與併購攤銷）；共識同口徑。
A12: 校準：k_rec＝FY2026 錨點 GPU 營收 ÷（AMD 市場層 CY2026 顆數 × pa_amd）；錨點 GPU 本身含 Assumed 拆分（公司不揭露）。不用共識、不用公司對 2027 的說法；後者只在 Recon 對帳。
A13: 估值：目標價＝十年 non-GAAP P/E 中位數 × FY2027 EPS（各情境），權重 A 0.3／B 0.5／C 0.2（Andy 可改）；依循環位置取分位的規則值不適用（落後倍數含高成長期溢價，比照 NVIDIA），保留計算。循環位置（共用規則，不平移）：見頂年度 A 2029、B 2028、C 2027 → FY2027：A 中段、B 中段、C 見頂。本版未做先驗，無 Andy 合理 P/E 對照。
A15: 標記：Verified、Interested-party、Analogy、Assumed、Derived。SemiAnalysis 未使用。公司原文＝8-K 新聞稿、簡報與 10-Q（sec.gov，已抓取）；法說逐字稿只經摘要（標二手）。
... A18: 情境對應（v0.2 延伸期）：A＝順利（市場層基準顆數）、B＝平平（AI 資本支出消化：CY2028 ×0.8、CY2029 ×0.85）、C＝不如預期（CY2028–29 ×0.6）；FY2027 三情境相同，情境差從 FY2028 起。本版未做先驗，無 Andy 合理 P/E 對照。

Sheet In
A1: In — 輸入（藍字；基準欄 E，低 D、高 F）。金額：十億美元（US$B）；每顆價格：千美元（US$K）；顆數：百萬顆；股數：十億股。每個輸入附兩個來源（找不到者寫「未找到」）；公司原文算一個
A2: 標記：Verified／Interested-party／Analogy／Assumed／Derived；Analogy、Assumed 給低／高區間。SemiAnalysis 未單獨使用。公司原文＝AMD 8-K 新聞稿與簡報（sec.gov 已逐頁抓取）；法說逐字稿只經摘要（二手）
A3: 鍵 | B3: 項目 | C3: 單位 | D3: 低 | E3: 基準 | F3: 高 | G3: 標記 | H3: 來源1 | I3: 來源2／說明
A4: A. 加速器顆數（markets/memory 與 HBM、台積電、網通、NVIDIA 模型同一份；情境係數讀台積電模型成品，不另訂）
A5: u_bw_26 | B5: NVIDIA Blackwell（B200／B300） 顆數 2026 | C5: 百萬顆 | E5: 5.4 | G5: Interested-party | H5: markets/memory/market.py UNITS：顆數：Morgan Stanley 2026-07（2026 5.4M）；AC Research 2027 約 2.4M；2028 Assumed。GB：B200 186、B300 288 組合 [Derived] | I5: 台積電模型 tsmc/dist/20261025_台積電模型_v0.3.xlsx｜In!E5（值相同，建置時檢查）
A6: u_bw_27 | B6: NVIDIA Blackwell（B200／B300） 顆數 2027 | C6: 百萬顆 | E6: 2.4 | G6: Interested-party | H6: 同上 | I6: 同上
A7: u_bw_28 | B7: NVIDIA Blackwell（B200／B300） 顆數 2028 | C7: 百萬顆 | E7: 0.5 | G7: Interested-party | H7: 同上 | I7: 同上
A8: g29_bw | B8: NVIDIA Blackwell（B200／B300） 2029 顆數成長 | C8: % | E8: -0.5 | G8: Assumed | H8: tsmc/dist/20261025_台積電模型_v0.3.xlsx｜In!E8 | I8: markets/memory 無 2029；沿用台積電模型
A9: u_rb_26 | B9: NVIDIA Rubin 顆數 2026 | C9: 百萬顆 | E9: 1.7 | G9: Interested-party | H9: markets/memory/market.py UNITS：2026：TrendForce 組合 Rubin 22% × 約 7.6M [Derived]；2027：Morgan Stanley 約 7.0M；2028 Assumed | I9: 台積電模型 tsmc/dist/20261025_台積電模型_v0.3.xlsx｜In!E9（值相同，建置時檢查）
A10: u_rb_27 | B10: NVIDIA Rubin 顆數 2027 | C10: 百萬顆 | E10: 7 | G10: Interested-party | H10: 同上 | I10: 同上
A11: u_rb_28 | B11: NVIDIA Rubin 顆數 2028 | C11: 百萬顆 | E11: 7 | G11: Interested-party | H11: 同上 | I11: 同上
A12: g29_rb | B12: NVIDIA Rubin 2029 顆數成長 | C12: % | E12: 0.15 | G12: Assumed | H12: tsmc/dist/20261025_台積電模型_v0.3.xlsx｜In!E12 | I12: markets/memory 無 2029；沿用台積電模型
A13: u_ru_26 | B13: NVIDIA Rubin Ultra 顆數 2026 | C13: 百萬顆 | E13: 0 | G13: Assumed | H13: markets/memory/market.py UNITS：時程 Assumed；GB：NVIDIA 1 TB／封裝 | I13: 台積電模型 tsmc/dist/20261025_台積電模型_v0.3.xlsx｜In!E13（值相同，建置時檢查）
A14: u_ru_27 | B14: NVIDIA Rubin Ultra 顆數 2027 | C14: 百萬顆 | E14: 0.3 | G14: Assumed | H14: 同上 | I14: 同上
A15: u_ru_28 | B15: NVIDIA Rubin Ultra 顆數 2028 | C15: 百萬顆 | E15: 2 | G15: Assumed | H15: 同上 | I15: 同上
A16: g29_ru | B16: NVIDIA Rubin Ultra 2029 顆數成長 | C16: % | E16: 0.15 | G16: Assumed | H16: tsmc/dist/20261025_台積電模型_v0.3.xlsx｜In!E16 | I16: markets/memory 無 2029；沿用台積電模型
... A45: gb_amd_28 | B45: AMD Instinct 每顆 HBM 2028 | C45: GB | E45: 432 | G45: Interested-party | H45: 同上 | I45: 同上
A46: B. 各平台每顆售價（金額份額用；與 NVIDIA 模型同一套價格，讀 NVIDIA 成品 In 頁；模組層級）
A47: pm_bw | B47: 每顆售價：NVIDIA Blackwell（B200／B300） | C47: US$K | D47: 37.6 | E47: 40.4 | F47: 47 | G47: Derived | H47: nvidia/dist/20261025_NVIDIA模型_v0.2.xlsx｜In!D56:F56 | I47: markets/chip_bridge/dist/20261023_晶片內容橋接表_v0.2.1.xlsx｜Rack!B6
A48: pm_rb | B48: 每顆售價：NVIDIA Rubin | C48: US$K | D48: 50 | E48: 55 | F48: 60 | G48: Derived | H48: nvidia/dist/20261025_NVIDIA模型_v0.2.xlsx｜In!D57:F57 | I48: markets/chip_bridge/dist/20261023_晶片內容橋接表_v0.2.1.xlsx｜Rack!C6
A49: pm_ru | B49: 每顆售價：NVIDIA Rubin Ultra | C49: US$K | D49: 60 | E49: 75 | F49: 100 | G49: Derived | H49: nvidia/dist/20261025_NVIDIA模型_v0.2.xlsx｜In!D58:F58 | I49: 無：未發布。基準＝VR200 55 ×（VR200／GB300 的 1.36 倍外推）＝75
A50: pm_hp | B50: 每顆售價：NVIDIA Hopper（H200 等） | C50: US$K | D50: 25 | E50: 30 | F50: 35 | G50: Derived | H50: nvidia/dist/20261025_NVIDIA模型_v0.2.xlsx｜In!D59:F59 | I50: 無：2026 出貨僅 0.5M，影響小
A51: pa_amd | B51: 每顆售價：AMD Instinct | C51: US$K | D51: 20 | E51: 30 | F51: 45 | G51: Derived | H51: nvidia/dist/20261025_NVIDIA模型_v0.2.xlsx｜In!D145:F145 | I51: MI355X：HSBC 約 $23K（自 $25K 下修）、其他報導 $20–25K；MI455X 無官方價，部落格 $15–50K（finviz、gpusmith、MikeLongTerm；賣方有目標價誘因）
A52: pa_tpu | B52: 每顆售價：Google TPU | C52: US$K | D52: 8 | E52: 12 | F52: 18 | G52: Derived | H52: nvidia/dist/20261025_NVIDIA模型_v0.2.xlsx｜In!D146:F146 | I52: 無：每顆 ASP 未找到（只有租用價代理：Ironwood $1.03–1.60／小時，SemiAnalysis，不可單獨使用）
A53: pa_trn | B53: 每顆售價：AWS Trainium | C53: US$K | D53: 5 | E53: 8 | F53: 12 | G53: Derived | H53: nvidia/dist/20261025_NVIDIA模型_v0.2.xlsx｜In!D147:F147 | I53: 無：每顆 ASP 未找到
A54: pa_oth | B54: 每顆售價：其他 ASIC（MTIA、Maia、Ascend 等） | C54: US$K | D54: 5 | E54: 8 | F54: 12 | G54: Derived | H54: nvidia/dist/20261025_NVIDIA模型_v0.2.xlsx｜In!D148:F148 | I54: 無：未找到（Maia、MTIA 皆無 ASP）
A55: C. HBM 價格路徑（情境別；讀 NVIDIA 成品 In 頁，原始來源 skhynix 成品 Mkt 頁；唯讀）
A56: hbm_A_26 | B56: HBM 混合單價 2026（A） | C56: US$/GB | E56: 14.6 | G56: Derived | H56: nvidia/dist/20261025_NVIDIA模型_v0.2.xlsx｜In!D79:F79 | I56: markets/memory：2026 BofA $14.6/GB；2027 +80% 三情境相同；2028–29 依情境
A57: hbm_A_27 | B57: HBM 混合單價 2027（A） | C57: US$/GB | E57: 26.28 | G57: Derived | H57: nvidia/dist/20261025_NVIDIA模型_v0.2.xlsx｜In!D80:F80 | I57: 同上
A58: hbm_A_28 | B58: HBM 混合單價 2028（A） | C58: US$/GB | E58: 28.908 | G58: Derived | H58: nvidia/dist/20261025_NVIDIA模型_v0.2.xlsx｜In!D81:F81 | I58: 同上
A59: hbm_A_29 | B59: HBM 混合單價 2029（A） | C59: US$/GB | E59: 27.4626 | G59: Derived | H59: nvidia/dist/20261025_NVIDIA模型_v0.2.xlsx｜In!D82:F82 | I59: 同上
A60: hbm_B_26 | B60: HBM 混合單價 2026（B） | C60: US$/GB | E60: 14.6 | G60: Derived | H60: nvidia/dist/20261025_NVIDIA模型_v0.2.xlsx｜In!D83:F83 | I60: 同上
A61: hbm_B_27 | B61: HBM 混合單價 2027（B） | C61: US$/GB | E61: 26.28 | G61: Derived | H61: nvidia/dist/20261025_NVIDIA模型_v0.2.xlsx｜In!D84:F84 | I61: 同上
A62: hbm_B_28 | B62: HBM 混合單價 2028（B） | C62: US$/GB | E62: 19.71 | G62: Derived | H62: nvidia/dist/20261025_NVIDIA模型_v0.2.xlsx｜In!D85:F85 | I62: 同上
A63: hbm_B_29 | B63: HBM 混合單價 2029（B） | C63: US$/GB | E63: 19.71 | G63: Derived | H63: nvidia/dist/20261025_NVIDIA模型_v0.2.xlsx｜In!D86:F86 | I63: 同上
A64: hbm_C_26 | B64: HBM 混合單價 2026（C） | C64: US$/GB | E64: 14.6 | G64: Derived | H64: nvidia/dist/20261025_NVIDIA模型_v0.2.xlsx｜In!D87:F87 | I64: 同上
A65: hbm_C_27 | B65: HBM 混合單價 2027（C） | C65: US$/GB | E65: 26.28 | G65: Derived | H65: nvidia/dist/20261025_NVIDIA模型_v0.2.xlsx｜In!D88:F88 | I65: 同上
A66: hbm_C_28 | B66: HBM 混合單價 2028（C） | C66: US$/GB | E66: 15.768 | G66: Derived | H66: nvidia/dist/20261025_NVIDIA模型_v0.2.xlsx｜In!D89:F89 | I66: 同上
A67: hbm_C_29 | B67: HBM 混合單價 2029（C） | C67: US$/GB | E67: 16.5564 | G67: Derived | H67: nvidia/dist/20261025_NVIDIA模型_v0.2.xlsx｜In!D90:F90 | I67: 同上
A68: D. AMD 資料中心 GPU（Instinct）：公司不拆分 GPU 與 CPU，拆分比例為 Assumed
...

Sheet Q
A1: Q — 實績（十億美元；EPS 為美元；股數為十億股；non-GAAP 公司口徑）。會計年度＝日曆年。藍字＝輸入；黑字＝公式。實績取自 AMD 8-K 新聞稿（sec.gov）；第二來源＝後續季度新聞稿的比較欄（同一公司不同文件）與 10-Q
A2: FY2026 錨點＝Q1、Q2 實績＋Q3 指引中點＋Q4 假設（I、J 欄，假設見 In 頁 F 節）。資料中心 GPU／非 GPU 拆分公司不揭露，為 Assumed（In 頁 D 節）。EPS 口徑：non-GAAP（排除股票薪酬、併購無形資產攤銷、投資損益等；公司口徑），共識亦為此口徑
A3: 項目 | B3: Q1 2025 | C3: Q2 2025 | D3: Q3 2025 | E3: Q4 2025 | F3: FY2025 全年 | G3: Q1 2026 | H3: Q2 2026 | I3: Q3 2026（指引中點） | J3: Q4 2026（假設） | K3: FY2026 錨點 | L3: 標記 | M3: 來源1（公司） | N3: 來源2／說明
A4: 營收 | B4: 7.438 | C4: 7.685 | D4: 9.246 | E4: 10.27 | F4: =SUM(B4:E4) -> 34.639 | G4: 10.253 | H4: 11.536 | I4: =q3_rev -> 13 | J4: =J5+J8+J9+J10 -> 14.854175 | K4: =SUM(G4:J4) -> 49.643175 | L4: Verified／Interested-party（Q3 指引）／Derived（Q4＝各段合計） | M4: AMD 8-K 新聞稿：Q1 2026 https://www.sec.gov/Archives/edgar/data/2488/000000248826000072/q12026991.htm；Q2 2026 https://www.sec.gov/Archives/edgar/data/2488/000000248826000121/q22026991.htm；Q4 2025（含 Q3 2025、全年）https://www.sec.gov/Archives/edgar/data/2488/000000248826000014/q42025991.htm | N4: Q1、Q2 2025 見 Q1、Q2 2026 稿比較欄；Q2 2025 毛利、利息、其他收益為全年 − 其餘三季（Derived）
A5: Data Center | B5: 3.674 | C5: 3.24 | D5: 4.341 | E5: 5.38 | F5: =SUM(B5:E5) -> 16.635 | G5: 5.775 | H5: 6.718 | I5: =I4-I8-I9-I10 -> 8.15932 | J5: =I5*(1+q4_dc) -> 10.19915 | K5: =SUM(G5:J5) -> 30.85147 | L5: Verified／Derived（Q3＝指引 − 其他段）／Assumed（Q4） | M5: AMD 8-K 新聞稿：Q1 2026 https://www.sec.gov/Archives/edgar/data/2488/000000248826000072/q12026991.htm；Q2 2026 https://www.sec.gov/Archives/edgar/data/2488/000000248826000121/q22026991.htm；Q4 2025（含 Q3 2025、全年）https://www.sec.gov/Archives/edgar/data/2488/000000248826000014/q42025991.htm | N5: Q1、Q2 2025 見 Q1、Q2 2026 稿比較欄；Q2 2025 毛利、利息、其他收益為全年 − 其餘三季（Derived）；FY2025 合計 16.635＝公司全年值
A6: 其中：資料中心 GPU（Instinct；Assumed 拆分） | F6: =gpu25 -> 6.5 | G6: =G5*gs_q1 -> 2.4255 | H6: =H5*gs_q2 -> 2.88874 | I6: =I5-I7 -> 4.0237192 | J6: =J5-J7 -> 5.8154132 | K6: =SUM(G6:J6) -> 15.153372 | L6: Assumed／Derived | M6: 公司不揭露 GPU 與 CPU 拆分；FY2025 為全年估計（In 頁 gpu25），各季：未找到 | N6: Q3、Q4＝資料中心 − 非 GPU
A7: 其中：資料中心非 GPU（EPYC CPU、DPU、FPGA 等） | F7: =F5-F6 -> 10.135 | G7: =G5-G6 -> 3.3495 | H7: =H5-H6 -> 3.82926 | I7: =H7*(1+ng_q3) -> 4.1356008 | J7: =I7*(1+ng_q4) -> 4.3837368 | K7: =SUM(G7:J7) -> 15.698098 | L7: Derived／Assumed（Q3、Q4 季增） | M7: 資料中心 − GPU | N7: —
A8: Client | B8: 2.294 | C8: 2.499 | D8: 2.75 | E8: 3.097 | F8: =SUM(B8:E8) -> 10.64 | G8: 2.885 | H8: 3.062 | I8: =H8*(1+q3_cli) -> 3.12324 | J8: =I8*(1+q4_cli) -> 2.967078 | K8: =SUM(G8:J8) -> 12.037318 | L8: Verified／Assumed（I、J） | M8: AMD 8-K 新聞稿：Q1 2026 https://www.sec.gov/Archives/edgar/data/2488/000000248826000072/q12026991.htm；Q2 2026 https://www.sec.gov/Archives/edgar/data/2488/000000248826000121/q22026991.htm；Q4 2025（含 Q3 2025、全年）https://www.sec.gov/Archives/edgar/data/2488/000000248826000014/q42025991.htm | N8: Q1、Q2 2025 見 Q1、Q2 2026 稿比較欄；Q2 2025 毛利、利息、其他收益為全年 − 其餘三季（Derived）
A9: Gaming | B9: 0.647 | C9: 1.122 | D9: 1.298 | E9: 0.843 | F9: =SUM(B9:E9) -> 3.91 | G9: 0.72 | H9: 0.779 | I9: =H9*(1+q3_gam) -> 0.6232 | J9: =I9*(1+q4_gam) -> 0.56088 | K9: =SUM(G9:J9) -> 2.68308 | L9: Verified／Assumed（I、J） | M9: AMD 8-K 新聞稿：Q1 2026 https://www.sec.gov/Archives/edgar/data/2488/000000248826000072/q12026991.htm；Q2 2026 https://www.sec.gov/Archives/edgar/data/2488/000000248826000121/q22026991.htm；Q4 2025（含 Q3 2025、全年）https://www.sec.gov/Archives/edgar/data/2488/000000248826000014/q42025991.htm | N9: Q1、Q2 2025 見 Q1、Q2 2026 稿比較欄；Q2 2025 毛利、利息、其他收益為全年 − 其餘三季（Derived）
A10: Embedded | B10: 0.823 | C10: 0.824 | D10: 0.857 | E10: 0.95 | F10: =SUM(B10:E10) -> 3.454 | G10: 0.873 | H10: 0.977 | I10: =H10*(1+q3_emb) -> 1.09424 | J10: =I10*(1+q4_emb) -> 1.1270672 | K10: =SUM(G10:J10) -> 4.0713072 | L10: Verified／Assumed（I、J） | M10: AMD 8-K 新聞稿：Q1 2026 https://www.sec.gov/Archives/edgar/data/2488/000000248826000072/q12026991.htm；Q2 2026 https://www.sec.gov/Archives/edgar/data/2488/000000248826000121/q22026991.htm；Q4 2025（含 Q3 2025、全年）https://www.sec.gov/Archives/edgar/data/2488/000000248826000014/q42025991.htm | N10: Q1、Q2 2025 見 Q1、Q2 2026 稿比較欄；Q2 2025 毛利、利息、其他收益為全年 − 其餘三季（Derived）
A11: 檢查：營收 − 各段合計（應為 0） | B11: =B4-B5-B8-B9-B10 -> 0 | C11: =C4-C5-C8-C9-C10 -> 0 | D11: =D4-D5-D8-D9-D10 -> 0 | E11: =E4-E5-E8-E9-E10 -> 0 | F11: =F4-F5-F8-F9-F10 -> 0 | G11: =G4-G5-G8-G9-G10 -> 0 | H11: =H4-H5-H8-H9-H10 -> 0 | I11: =I4-I5-I8-I9-I10 -> 0 | ... K11: =K4-K5-K8-K9-K10 -> 0 | L11: — | M11: — | N11: —
A12: 毛利（non-GAAP） | B12: 3.992 | C12: 3.326 | D12: 4.992 | E12: 5.855 | F12: =SUM(B12:E12) -> 18.165 | G12: 5.685 | H12: 6.488 | I12: =I4*q3_gm -> 7.28 | J12: =J4*q4_gm -> 8.2440672 | K12: =SUM(G12:J12) -> 27.697067 | L12: Verified（Q2 2025 Derived；Q2 2026＝營業利益＋營業費用）／Interested-party（I）／Assumed（J） | M12: AMD 8-K 新聞稿：Q1 2026 https://www.sec.gov/Archives/edgar/data/2488/000000248826000072/q12026991.htm；Q2 2026 https://www.sec.gov/Archives/edgar/data/2488/000000248826000121/q22026991.htm；Q4 2025（含 Q3 2025、全年）https://www.sec.gov/Archives/edgar/data/2488/000000248826000014/q42025991.htm | N12: FY2025 合計 18.165＝公司全年值
A13: 毛利率（non-GAAP） | B13: =B12/B4 -> 0.53670341 | C13: =C12/C4 -> 0.43279115 | D13: =D12/D4 -> 0.53990915 | E13: =E12/E4 -> 0.57010711 | F13: =F12/F4 -> 0.5244089 | G13: =G12/G4 -> 0.55447186 | H13: =H12/H4 -> 0.56241331 | I13: =I12/I4 -> 0.56 | ... K13: =K12/K4 -> 0.55792296 | L13: Derived | M13: — | N13: 公司：Q2 2025 43%（含 MI308 費用 $0.8B）、FY2025 52%、Q2 2026 56%
A14: 營業費用（non-GAAP） | B14: 2.213 | C14: 2.429 | D14: 2.754 | E14: 3.001 | F14: =SUM(B14:E14) -> 10.397 | G14: 3.145 | H14: 3.394 | I14: =q3_opx -> 3.65 | J14: =I14*(1+q4_opx_g) -> 3.8325 | K14: =SUM(G14:J14) -> 14.0215 | L14: Verified／Interested-party（I）／Assumed（J） | M14: AMD 8-K 新聞稿：Q1 2026 https://www.sec.gov/Archives/edgar/data/2488/000000248826000072/q12026991.htm；Q2 2026 https://www.sec.gov/Archives/edgar/data/2488/000000248826000121/q22026991.htm；Q4 2025（含 Q3 2025、全年）https://www.sec.gov/Archives/edgar/data/2488/000000248826000014/q42025991.htm | N14: Q1、Q2 2025 見 Q1、Q2 2026 稿比較欄；Q2 2025 毛利、利息、其他收益為全年 − 其餘三季（Derived）
A15: 營業利益（non-GAAP） | B15: 1.779 | C15: 0.897 | D15: 2.238 | E15: 2.854 | F15: =SUM(B15:E15) -> 7.768 | G15: 2.54 | H15: 3.094 | I15: =I12-I14 -> 3.63 | J15: =J12-J14 -> 4.4115672 | K15: =SUM(G15:J15) -> 13.675567 | L15: Verified／Derived（I、J） | M15: AMD 8-K 新聞稿：Q1 2026 https://www.sec.gov/Archives/edgar/data/2488/000000248826000072/q12026991.htm；Q2 2026 https://www.sec.gov/Archives/edgar/data/2488/000000248826000121/q22026991.htm；Q4 2025（含 Q3 2025、全年）https://www.sec.gov/Archives/edgar/data/2488/000000248826000014/q42025991.htm | N15: Q1、Q2 2025 見 Q1、Q2 2026 稿比較欄；Q2 2025 毛利、利息、其他收益為全年 − 其餘三季（Derived）
A16: 檢查：毛利 − 營業費用 − 營業利益（實績應為 0） | B16: =B12-B14-B15 -> 0 | C16: =C12-C14-C15 -> 0 | D16: =D12-D14-D15 -> 0 | E16: =E12-E14-E15 -> 0 | G16: =G12-G14-G15 -> 0 | H16: =H12-H14-H15 -> 0 | L16: — | M16: — | N16: —
A17: 利息費用 | B17: -0.02 | C17: -0.038 | D17: -0.037 | E17: -0.036 | F17: =SUM(B17:E17) -> -0.131 | G17: -0.037 | H17: -0.037 | L17: Verified（Q2 2025 Derived） | M17: AMD 8-K 新聞稿：Q1 2026 https://www.sec.gov/Archives/edgar/data/2488/000000248826000072/q12026991.htm；Q2 2026 https://www.sec.gov/Archives/edgar/data/2488/000000248826000121/q22026991.htm；Q4 2025（含 Q3 2025、全年）https://www.sec.gov/Archives/edgar/data/2488/000000248826000014/q42025991.htm | N17: Q1、Q2 2025 見 Q1、Q2 2026 稿比較欄；Q2 2025 毛利、利息、其他收益為全年 − 其餘三季（Derived）
A18: 其他收益淨額（GAAP） | B18: 0.039 | C18: 0.098 | D18: 0.082 | E18: 0.358 | F18: =SUM(B18:E18) -> 0.577 | G18: 0.165 | H18: 0.598 | L18: Verified（Q2 2025 Derived） | M18: AMD 8-K 新聞稿：Q1 2026 https://www.sec.gov/Archives/edgar/data/2488/000000248826000072/q12026991.htm；Q2 2026 https://www.sec.gov/Archives/edgar/data/2488/000000248826000121/q22026991.htm；Q4 2025（含 Q3 2025、全年）https://www.sec.gov/Archives/edgar/data/2488/000000248826000014/q42025991.htm | N18: Q1、Q2 2025 見 Q1、Q2 2026 稿比較欄；Q2 2025 毛利、利息、其他收益為全年 − 其餘三季（Derived）
A19: 長期投資（利得）損失（non-GAAP 調節，排除） | B19: 0.002 | C19: -0.061 | D19: -0.026 | E19: -0.28 | F19: =SUM(B19:E19) -> -0.365 | G19: -0.066 | H19: -0.483 | L19: Verified（Q2 2025 Derived） | M19: AMD 8-K 新聞稿：Q1 2026 https://www.sec.gov/Archives/edgar/data/2488/000000248826000072/q12026991.htm；Q2 2026 https://www.sec.gov/Archives/edgar/data/2488/000000248826000121/q22026991.htm；Q4 2025（含 Q3 2025、全年）https://www.sec.gov/Archives/edgar/data/2488/000000248826000014/q42025991.htm | N19: non-GAAP 調節表「(Gains) losses on long-term investments, net」
A20: 非營業淨額（non-GAAP）＝利息＋其他收益＋調節 | B20: =B17+B18+B19 -> 0.021 | C20: =C17+C18+C19 -> -0.001 | D20: =D17+D18+D19 -> 0.019 | E20: =E17+E18+E19 -> 0.042 | F20: =SUM(B20:E20) -> 0.081 | G20: =G17+G18+G19 -> 0.062 | H20: =H17+H18+H19 -> 0.078 | I20: =q3_oth -> 0.055 | J20: =q3_oth -> 0.055 | K20: =SUM(G20:J20) -> 0.25 | L20: Derived／Interested-party（I）／Assumed（J＝Q3 指引） | M20: AMD 8-K 新聞稿：Q1 2026 https://www.sec.gov/Archives/edgar/data/2488/000000248826000072/q12026991.htm；Q2 2026 https://www.sec.gov/Archives/edgar/data/2488/000000248826000121/q22026991.htm；Q4 2025（含 Q3 2025、全年）https://www.sec.gov/Archives/edgar/data/2488/000000248826000014/q42025991.htm | N20: Q1、Q2 2025 見 Q1、Q2 2026 稿比較欄；Q2 2025 毛利、利息、其他收益為全年 − 其餘三季（Derived）
A21: 稅前利益（non-GAAP） | B21: =B15+B20 -> 1.8 | C21: =C15+C20 -> 0.896 | D21: =D15+D20 -> 2.257 | E21: =E15+E20 -> 2.896 | F21: =SUM(B21:E21) -> 7.849 | G21: =G15+G20 -> 2.602 | H21: =H15+H20 -> 3.172 | I21: =I15+I20 -> 3.685 | J21: =J15+J20 -> 4.4665672 | K21: =SUM(G21:J21) -> 13.925567 | L21: Derived | M21: AMD 8-K 新聞稿：Q1 2026 https://www.sec.gov/Archives/edgar/data/2488/000000248826000072/q12026991.htm；Q2 2026 https://www.sec.gov/Archives/edgar/data/2488/000000248826000121/q22026991.htm；Q4 2025（含 Q3 2025、全年）https://www.sec.gov/Archives/edgar/data/2488/000000248826000014/q42025991.htm | N21: Q1、Q2 2025 見 Q1、Q2 2026 稿比較欄；Q2 2025 毛利、利息、其他收益為全年 − 其餘三季（Derived）
A22: 淨利（non-GAAP） | B22: 1.566 | C22: 0.781 | D22: 1.965 | E22: 2.519 | F22: =SUM(B22:E22) -> 6.831 | G22: 2.265 | H22: 2.76 | I22: =I21*(1-tx_26) -> 3.20595 | J22: =J21*(1-tx_26) -> 3.8859135 | K22: =SUM(G22:J22) -> 12.116863 | L22: Verified／Derived（I、J） | M22: AMD 8-K 新聞稿：Q1 2026 https://www.sec.gov/Archives/edgar/data/2488/000000248826000072/q12026991.htm；Q2 2026 https://www.sec.gov/Archives/edgar/data/2488/000000248826000121/q22026991.htm；Q4 2025（含 Q3 2025、全年）https://www.sec.gov/Archives/edgar/data/2488/000000248826000014/q42025991.htm | N22: Q1、Q2 2025 見 Q1、Q2 2026 稿比較欄；Q2 2025 毛利、利息、其他收益為全年 − 其餘三季（Derived）；FY2025 合計 6.831＝公司全年值
A23: 有效稅率（non-GAAP；1 − 淨利 ÷ 稅前） | B23: =1-B22/B21 -> 0.13 | C23: =1-C22/C21 -> 0.12834821 | D23: =1-D22/D21 -> 0.12937528 | E23: =1-E22/E21 -> 0.13017956 | F23: =1-F22/F21 -> 0.12969805 | G23: =1-G22/G21 -> 0.12951576 | H23: =1-H22/H21 -> 0.12988651 | I23: =tx_26 -> 0.13 | J23: =tx_26 -> 0.13 | K23: =1-K22/K21 -> 0.12988367 | L23: Derived／Interested-party（13%） | M23: — | N23: 公司 FY2026 non-GAAP 稅率 13%（Q2 2026 簡報）
A24: 稀釋股數（十億股） | B24: 1.626 | C24: 1.63 | D24: 1.641 | E24: 1.649 | F24: 1.636 | G24: 1.65 | H24: 1.659 | I24: =q3_sh -> 1.661 | J24: =I24*(1+q4_sh) -> 1.664322 | K24: =AVERAGE(G24:J24) -> 1.6585805 | L24: Verified／Interested-party（I）／Assumed（J） | M24: AMD 8-K 新聞稿：Q1 2026 https://www.sec.gov/Archives/edgar/data/2488/000000248826000072/q12026991.htm；Q2 2026 https://www.sec.gov/Archives/edgar/data/2488/000000248826000121/q22026991.htm；Q4 2025（含 Q3 2025、全年）https://www.sec.gov/Archives/edgar/data/2488/000000248826000014/q42025991.htm | N24: Q2 2025 1.630 見 Q2 2026 10-Q；FY2025 1.636（公司全年值）
A25: EPS（non-GAAP，模型算）＝淨利 ÷ 股數 | B25: =B22/B24 -> 0.96309963 | C25: =C22/C24 -> 0.4791411 | D25: =D22/D24 -> 1.1974406 | E25: =E22/E24 -> 1.5275925 | F25: =F22/F24 -> 4.1754279 | G25: =G22/G24 -> 1.3727273 | H25: =H22/H24 -> 1.6636528 | I25: =I22/I24 -> 1.9301325 | ... K25: =K22/K24 -> 7.3055625 | L25: Derived | M25: — | N25: FY2026 Q3、Q4 為指引與假設推得
A26: EPS（non-GAAP 稀釋，公司） | B26: 0.96 | C26: 0.48 | D26: 1.2 | E26: 1.53 | F26: 4.17 | G26: 1.37 | H26: 1.66 | L26: Verified | M26: AMD 8-K 新聞稿：Q1 2026 https://www.sec.gov/Archives/edgar/data/2488/000000248826000072/q12026991.htm；Q2 2026 https://www.sec.gov/Archives/edgar/data/2488/000000248826000121/q22026991.htm；Q4 2025（含 Q3 2025、全年）https://www.sec.gov/Archives/edgar/data/2488/000000248826000014/q42025991.htm | N26: Q1、Q2 2025 見 Q1、Q2 2026 稿比較欄；Q2 2025 毛利、利息、其他收益為全年 − 其餘三季（Derived）
A27: 檢查：模型算 EPS − 公司 EPS（四捨五入差） | B27: =B25-B26 -> 0.003099631 | C27: =C25-C26 -> -0.00085889571 | D27: =D25-D26 -> -0.002559415 | E27: =E25-E26 -> -0.0024075197 | F27: =F25-F26 -> 0.0054278729 | G27: =G25-G26 -> 0.0027272727 | H27: =H25-H26 -> 0.0036528029 | L27: — | M27: — | N27: —
A28: EPS（GAAP 稀釋，公司；參考） | B28: 0.44 | C28: 0.54 | D28: 0.75 | E28: 0.92 | F28: 2.65 | G28: 0.84 | H28: 1.38 | L28: Verified | M28: AMD 8-K 新聞稿：Q1 2026 https://www.sec.gov/Archives/edgar/data/2488/000000248826000072/q12026991.htm；Q2 2026 https://www.sec.gov/Archives/edgar/data/2488/000000248826000121/q22026991.htm；Q4 2025（含 Q3 2025、全年）https://www.sec.gov/Archives/edgar/data/2488/000000248826000014/q42025991.htm | N28: GAAP 含併購無形資產攤銷（FY2025 $2.25B）、股票薪酬（$1.64B）
A29: 檢查：FY2025 四季合計 − 公司全年值（營收 34.639、營業利益 7.768、淨利 6.831，應為 0） | F29: =(F4-34.639)+(F15-7.768)+(F22-6.831) -> 0 | L29: — | M29: — | N29: —
A31: FY2026 錨點與共識的距離（參考；校準時未使用共識）
A32: FY2026 營收 ÷ 共識營收 − 1 | B32: =K4/cons_rev26-1 -> -0.026604408
A33: FY2026 EPS ÷ 共識 EPS − 1 | B33: =K25/cons_eps26-1 -> -0.037475297
A34: FY2026 營收年增 | B34: =K4/F4-1 -> 0.43315844
A35: FY2026 營業費用年增 | B35: =K14/F14-1 -> 0.34861018
A36: 營業費用彈性（營業費用年增 ÷ 營收年增；In 頁 phi 的依據） | B36: =B35/B34 -> 0.80480984

Sheet Units
A1: Units — 加速器顆數（百萬顆；日曆年；與 HBM、台積電、網通、NVIDIA 模型同一份）與金額份額（模組層級每顆價 × 顆數；價格與 NVIDIA 模型相同）。AMD 會計年度＝日曆年
A3: 項目 | B3: 單位 | C3: CY2026（FY2026） | D3: CY2027（FY2027） | E3: CY2028（FY2028） | F3: CY2029（FY2029） | G3: 說明
A4: 情境 A：基準
A5: 顆數
A6: NVIDIA Blackwell（B200／B300） | B6: 百萬顆 | C6: =u_bw_26 -> 5.4 | D6: =u_bw_27 -> 2.4 | E6: =u_bw_28*um28_A -> 0.5 | F6: =u_bw_28*(1+g29_bw)*um29_A -> 0.25
A7: NVIDIA Rubin | B7: 百萬顆 | C7: =u_rb_26 -> 1.7 | D7: =u_rb_27 -> 7 | E7: =u_rb_28*um28_A -> 7 | F7: =u_rb_28*(1+g29_rb)*um29_A -> 8.05
A8: NVIDIA Rubin Ultra | B8: 百萬顆 | C8: =u_ru_26 -> 0 | D8: =u_ru_27 -> 0.3 | E8: =u_ru_28*um28_A -> 2 | F8: =u_ru_28*(1+g29_ru)*um29_A -> 2.3
A9: NVIDIA Hopper（H200 等） | B9: 百萬顆 | C9: =u_hp_26 -> 0.5 | D9: =u_hp_27 -> 0 | E9: =u_hp_28*um28_A -> 0 | F9: =u_hp_28*(1+g29_hp)*um29_A -> 0
A10: AMD Instinct | B10: 百萬顆 | C10: =u_amd_26 -> 0.75 | D10: =u_amd_27 -> 1.5 | E10: =u_amd_28*um28_A -> 2 | F10: =u_amd_28*(1+g29_amd)*um29_A -> 2.3
A11: Google TPU | B11: 百萬顆 | C11: =u_tpu_26 -> 3.85 | D11: =u_tpu_27 -> 5.5 | E11: =u_tpu_28*um28_A -> 7 | F11: =u_tpu_28*(1+g29_tpu)*um29_A -> 8.05
A12: AWS Trainium | B12: 百萬顆 | C12: =u_trn_26 -> 2 | D12: =u_trn_27 -> 2.5 | E12: =u_trn_28*um28_A -> 3 | F12: =u_trn_28*(1+g29_trn)*um29_A -> 3.45
A13: 其他 ASIC（MTIA、Maia、Ascend 等） | B13: 百萬顆 | C13: =u_oth_26 -> 1 | D13: =u_oth_27 -> 4.5 | E13: =u_oth_28*um28_A -> 5 | F13: =u_oth_28*(1+g29_oth)*um29_A -> 5.75
A14: 合計 | B14: 百萬顆 | C14: =SUM(C6:C13) -> 15.2 | D14: =SUM(D6:D13) -> 23.7 | E14: =SUM(E6:E13) -> 26.5 | F14: =SUM(F6:F13) -> 30.15
A15: 金額（顆數 × 每顆售價）
A16: NVIDIA Blackwell（B200／B300） | B16: US$B | C16: =u_bw_26*(pm_bw) -> 218.16 | D16: =u_bw_27*(pm_bw) -> 96.96 | E16: =u_bw_28*um28_A*(pm_bw) -> 20.2 | F16: =u_bw_28*(1+g29_bw)*um29_A*(pm_bw) -> 10.1
A17: NVIDIA Rubin | B17: US$B | C17: =u_rb_26*(pm_rb) -> 93.5 | D17: =u_rb_27*(pm_rb) -> 385 | E17: =u_rb_28*um28_A*(pm_rb) -> 385 | F17: =u_rb_28*(1+g29_rb)*um29_A*(pm_rb) -> 442.75
A18: NVIDIA Rubin Ultra | B18: US$B | C18: =u_ru_26*(pm_ru) -> 0 | D18: =u_ru_27*(pm_ru) -> 22.5 | E18: =u_ru_28*um28_A*(pm_ru) -> 150 | F18: =u_ru_28*(1+g29_ru)*um29_A*(pm_ru) -> 172.5
A19: NVIDIA Hopper（H200 等） | B19: US$B | C19: =u_hp_26*(pm_hp) -> 15 | D19: =u_hp_27*(pm_hp) -> 0 | E19: =u_hp_28*um28_A*(pm_hp) -> 0 | F19: =u_hp_28*(1+g29_hp)*um29_A*(pm_hp) -> 0
A20: AMD Instinct | B20: US$B | C20: =u_amd_26*(pa_amd) -> 22.5 | D20: =u_amd_27*(pa_amd) -> 45 | E20: =u_amd_28*um28_A*(pa_amd) -> 60 | F20: =u_amd_28*(1+g29_amd)*um29_A*(pa_amd) -> 69
A21: Google TPU | B21: US$B | C21: =u_tpu_26*(pa_tpu) -> 46.2 | D21: =u_tpu_27*(pa_tpu) -> 66 | E21: =u_tpu_28*um28_A*(pa_tpu) -> 84 | F21: =u_tpu_28*(1+g29_tpu)*um29_A*(pa_tpu) -> 96.6
A22: AWS Trainium | B22: US$B | C22: =u_trn_26*(pa_trn) -> 16 | D22: =u_trn_27*(pa_trn) -> 20 | E22: =u_trn_28*um28_A*(pa_trn) -> 24 | F22: =u_trn_28*(1+g29_trn)*um29_A*(pa_trn) -> 27.6
A23: 其他 ASIC（MTIA、Maia、Ascend 等） | B23: US$B | C23: =u_oth_26*(pa_oth) -> 8 | D23: =u_oth_27*(pa_oth) -> 36 | E23: =u_oth_28*um28_A*(pa_oth) -> 40 | F23: =u_oth_28*(1+g29_oth)*um29_A*(pa_oth) -> 46
A24: 合計 | B24: US$B | C24: =SUM(C16:C23) -> 419.36 | D24: =SUM(D16:D23) -> 671.46 | E24: =SUM(E16:E23) -> 763.2 | F24: =SUM(F16:F23) -> 864.55
A25: 顆數份額
A26: NVIDIA | B26: % | C26: =(C6+C7+C8+C9)/C14 -> 0.5 | D26: =(D6+D7+D8+D9)/D14 -> 0.4092827 | E26: =(E6+E7+E8+E9)/E14 -> 0.35849057 | F26: =(F6+F7+F8+F9)/F14 -> 0.35157546
A27: AMD | B27: % | C27: =(C10)/C14 -> 0.049342105 | D27: =(D10)/D14 -> 0.063291139 | E27: =(E10)/E14 -> 0.075471698 | F27: =(F10)/F14 -> 0.07628524
A28: Google TPU | B28: % | C28: =(C11)/C14 -> 0.25328947 | D28: =(D11)/D14 -> 0.23206751 | E28: =(E11)/E14 -> 0.26415094 | F28: =(F11)/F14 -> 0.26699834
A29: AWS Trainium | B29: % | C29: =(C12)/C14 -> 0.13157895 | D29: =(D12)/D14 -> 0.10548523 | E29: =(E12)/E14 -> 0.11320755 | F29: =(F12)/F14 -> 0.11442786
A30: 其他 ASIC | B30: % | C30: =(C13)/C14 -> 0.065789474 | D30: =(D13)/D14 -> 0.18987342 | E30: =(E13)/E14 -> 0.18867925 | F30: =(F13)/F14 -> 0.1907131
A31: 金額份額
A32: NVIDIA | B32: % | C32: =(C16+C17+C18+C19)/C24 -> 0.77894887 | D32: =(D16+D17+D18+D19)/D24 -> 0.75128824 | E32: =(E16+E17+E18+E19)/E24 -> 0.72746331 | F32: =(F16+F17+F18+F19)/F24 -> 0.72332427
A33: AMD | B33: % | C33: =(C20)/C24 -> 0.053653186 | D33: =(D20)/D24 -> 0.06701814 | E33: =(E20)/E24 -> 0.078616352 | F33: =(F20)/F24 -> 0.079810306
A34: Google TPU | B34: % | C34: =(C21)/C24 -> 0.11016787 | D34: =(D21)/D24 -> 0.098293271 | E34: =(E21)/E24 -> 0.11006289 | F34: =(F21)/F24 -> 0.11173443
A35: AWS Trainium | B35: % | C35: =(C22)/C24 -> 0.038153377 | D35: =(D22)/D24 -> 0.02978584 | E35: =(E22)/E24 -> 0.031446541 | F35: =(F22)/F24 -> 0.031924122
A36: 其他 ASIC | B36: % | C36: =(C23)/C24 -> 0.019076688 | D36: =(D23)/D24 -> 0.053614512 | E36: =(E23)/E24 -> 0.052410901 | F36: =(F23)/F24 -> 0.053206871
A38: 情境 B：2028 顆數 ×0.8、2029 ×0.85
A39: 顆數
A40: NVIDIA Blackwell（B200／B300） | B40: 百萬顆 | C40: =u_bw_26 -> 5.4 | D40: =u_bw_27 -> 2.4 | E40: =u_bw_28*um28_B -> 0.4 | F40: =u_bw_28*(1+g29_bw)*um29_B -> 0.2125
A41: NVIDIA Rubin | B41: 百萬顆 | C41: =u_rb_26 -> 1.7 | D41: =u_rb_27 -> 7 | E41: =u_rb_28*um28_B -> 5.6 | F41: =u_rb_28*(1+g29_rb)*um29_B -> 6.8425
A42: NVIDIA Rubin Ultra | B42: 百萬顆 | C42: =u_ru_26 -> 0 | D42: =u_ru_27 -> 0.3 | E42: =u_ru_28*um28_B -> 1.6 | F42: =u_ru_28*(1+g29_ru)*um29_B -> 1.955
...

Sheet PL
A1: PL — AMD 損益（US$B；non-GAAP；FY2025A 實績、FY2026 錨點，FY2027 起為模型）。會計年度＝日曆年。三情境各一個完整推導區塊（本頁下方），頂端為摘要。FY2026、FY2027 三情境相同（情境係數從 CY2028 才開始）
A3: 情境／項目 | B3: 單位 | C3: FY2025A | D3: FY2026 | E3: FY2027 | F3: FY2028 | G3: FY2029 | H3: 說明
A4: 情境 A
A5: 營收 | B5: US$B | C5: =C95 -> 34.639 | D5: =D95 -> 49.643175 | E5: =E95 -> 75.668419 | F5: =F95 -> 93.833597 | G5: =G95 -> 105.10784
A6: 營收年增 | B6: % | D6: =D101 -> 0.43315844 | E6: =E101 -> 0.52424615 | F6: =F101 -> 0.24006288 | G6: =G101 -> 0.1201514
A7: Data Center | B7: US$B | C7: =C96 -> 16.635 | D7: =D96 -> 30.85147 | E7: =E96 -> 56.376771 | F7: =F96 -> 73.96363 | G7: =G96 -> 84.579458
A8: 資料中心 GPU | B8: US$B | C8: =C97 -> 6.5 | D8: =D97 -> 15.153372 | E8: =E97 -> 32.829625 | F8: =F97 -> 44.529697 | G8: =G97 -> 50.730435
A9: 資料中心非 GPU | B9: US$B | C9: =C98 -> 10.135 | D9: =D98 -> 15.698098 | E9: =E98 -> 23.547146 | F9: =F98 -> 29.433933 | G9: =G98 -> 33.849023
A10: Client＋Gaming | B10: US$B | C10: =C99 -> 14.55 | D10: =D99 -> 14.720398 | E10: =E99 -> 14.81321 | F10: =F99 -> 14.943685 | G10: =G99 -> 15.109468
A11: Embedded | B11: US$B | C11: =C100 -> 3.454 | D11: =D100 -> 4.0713072 | E11: =E100 -> 4.4784379 | F11: =F100 -> 4.9262817 | G11: =G100 -> 5.4189099
A12: 毛利率 | B12: % | C12: =C103 -> 0.5244089 | D12: =D103 -> 0.55792296 | E12: =E103 -> 0.49718814 | F12: =F103 -> 0.47793437 | G12: =G103 -> 0.4823363
A13: 營業利益 | B13: US$B | C13: =C106 -> 7.768 | D13: =D106 -> 13.675567 | E13: =E106 -> 17.68401 | F13: =F106 -> 21.056861 | G13: =G106 -> 24.607468
A14: 營業利益率 | B14: % | C14: =C107 -> 0.2242559 | D14: =D107 -> 0.27547729 | E14: =E107 -> 0.23370398 | F14: =F107 -> 0.22440642 | G14: =G107 -> 0.2341164
A15: 淨利（non-GAAP） | B15: US$B | C15: =C110 -> 6.831 | D15: =D110 -> 12.116863 | E15: =E110 -> 15.559089 | F15: =F110 -> 18.493469 | G15: =G110 -> 21.582497
A16: 稀釋股數 | B16: 十億股 | C16: =C113 -> 1.636 | D16: =D113 -> 1.6585805 | E16: =E113 -> 1.701833 | F16: =F113 -> 1.771918 | G16: =G113 -> 1.8421705
A17: EPS（non-GAAP） | B17: US$ | C17: =C114 -> 4.1754279 | D17: =D114 -> 7.3055625 | E17: =E114 -> 9.1425476 | F17: =F114 -> 10.436978 | G17: =G114 -> 11.715798
A18: EPS 年增 | B18: % | D18: =D115 -> 0.74965602 | E18: =E115 -> 0.2514502 | F18: =F115 -> 0.14158314 | G18: =G115 -> 0.12252778
A20: 情境 B
A21: 營收 | B21: US$B | C21: =C143 -> 34.639 | D21: =D143 -> 49.643175 | E21: =E143 -> 75.668419 | F21: =F143 -> 82.808439 | G21: =G143 -> 95.315758
A22: 營收年增 | B22: % | D22: =D149 -> 0.43315844 | E22: =E149 -> 0.52424615 | F22: =F149 -> 0.094359313 | G22: =G149 -> 0.15103919
A23: Data Center | B23: US$B | C23: =C144 -> 16.635 | D23: =D144 -> 30.85147 | E23: =E144 -> 56.376771 | F23: =F144 -> 62.938471 | G23: =G144 -> 74.787381
A24: 資料中心 GPU | B24: US$B | C24: =C145 -> 6.5 | D24: =D145 -> 15.153372 | E24: =E145 -> 32.829625 | F24: =F145 -> 33.504538 | G24: =G145 -> 40.938358
A25: 資料中心非 GPU | B25: US$B | C25: =C146 -> 10.135 | D25: =D146 -> 15.698098 | E25: =E146 -> 23.547146 | F25: =F146 -> 29.433933 | G25: =G146 -> 33.849023
A26: Client＋Gaming | B26: US$B | C26: =C147 -> 14.55 | D26: =D147 -> 14.720398 | E26: =E147 -> 14.81321 | F26: =F147 -> 14.943685 | G26: =G147 -> 15.109468
A27: Embedded | B27: US$B | C27: =C148 -> 3.454 | D27: =D148 -> 4.0713072 | E27: =E148 -> 4.4784379 | F27: =F148 -> 4.9262817 | G27: =G148 -> 5.4189099
A28: 毛利率 | B28: % | C28: =C151 -> 0.5244089 | D28: =D151 -> 0.55792296 | E28: =E151 -> 0.49718814 | F28: =F151 -> 0.52831285 | G28: =G151 -> 0.52492447
A29: 營業利益 | B29: US$B | C29: =C154 -> 7.768 | D29: =D154 -> 13.675567 | E29: =E154 -> 17.68401 | F29: =F154 -> 22.297258 | G29: =G154 -> 25.974472
A30: 營業利益率 | B30: % | C30: =C155 -> 0.2242559 | D30: =D155 -> 0.27547729 | E30: =E155 -> 0.23370398 | F30: =F155 -> 0.26926311 | G30: =G155 -> 0.27250973
A31: 淨利（non-GAAP） | B31: US$B | C31: =C158 -> 6.831 | D31: =D158 -> 12.116863 | E31: =E158 -> 15.559089 | F31: =F158 -> 19.572614 | G31: =G158 -> 22.771791
A32: 稀釋股數 | B32: 十億股 | C32: =C161 -> 1.636 | D32: =D161 -> 1.6585805 | E32: =E161 -> 1.701833 | F32: =F161 -> 1.7612513 | G32: =G161 -> 1.8195038
A33: EPS（non-GAAP） | B33: US$ | C33: =C162 -> 4.1754279 | D33: =D162 -> 7.3055625 | E33: =E162 -> 9.1425476 | F33: =F162 -> 11.112903 | G33: =G162 -> 12.515385
A34: EPS 年增 | B34: % | D34: =D163 -> 0.74965602 | E34: =E163 -> 0.2514502 | F34: =F163 -> 0.21551489 | G34: =G163 -> 0.12620305
A36: 情境 C
A37: 營收 | B37: US$B | C37: =C191 -> 34.639 | D37: =D191 -> 49.643175 | E37: =E191 -> 75.668419 | F37: =F191 -> 73.751126 | G37: =G191 -> 82.648382
A38: 營收年增 | B38: % | D38: =D197 -> 0.43315844 | E38: =E197 -> 0.52424615 | F38: =F197 -> -0.025338077 | G38: =G197 -> 0.12063891
A39: Data Center | B39: US$B | C39: =C192 -> 16.635 | D39: =D192 -> 30.85147 | E39: =E192 -> 56.376771 | F39: =F192 -> 53.881159 | G39: =G192 -> 62.120004
A40: 資料中心 GPU | B40: US$B | C40: =C193 -> 6.5 | D40: =D193 -> 15.153372 | E40: =E193 -> 32.829625 | F40: =F193 -> 24.447226 | G40: =G193 -> 28.270981
A41: 資料中心非 GPU | B41: US$B | C41: =C194 -> 10.135 | D41: =D194 -> 15.698098 | E41: =E194 -> 23.547146 | F41: =F194 -> 29.433933 | G41: =G194 -> 33.849023
A42: Client＋Gaming | B42: US$B | C42: =C195 -> 14.55 | D42: =D195 -> 14.720398 | E42: =E195 -> 14.81321 | F42: =F195 -> 14.943685 | G42: =G195 -> 15.109468
A43: Embedded | B43: US$B | C43: =C196 -> 3.454 | D43: =D196 -> 4.0713072 | E43: =E196 -> 4.4784379 | F43: =F196 -> 4.9262817 | G43: =G196 -> 5.4189099
...

Sheet Val
A1: Val — P/E 估值（美元；non-GAAP EPS）。目標價＝十年 non-GAAP P/E 中位數 × FY2027 EPS（各情境），情境加權（第 0 節）。結論另看「現價 ÷ FY2027、FY2028 EPS」。跨公司規則：合理倍數＝10 年（2016–2025 年底）P/E 的分位，依循環位置：見頂年 25 分位、中段中位數、谷底 75 分位；AMD 會計年度＝日曆年，用共用規則 classify（不平移），見頂年度讀設備市場模型
A2: 依循環位置取分位的規則值：不適用（保留計算，不進結論；比照 NVIDIA 模型）。理由：歷史倍數是落後倍數（年底價 ÷ 當年 non-GAAP EPS），含高成長期溢價與 EPS 低谷年（2016 為虧損、2022 年 18.5x、2019 年 71.7x）；GAAP 倍數另受 Xilinx 併購攤銷扭曲（2023 年 283x），只列參考。本版未做先驗，無 Andy 合理 P/E 對照
A3: 0. 目標價（DCF 與 Comparable 加權；v0.2 新增，Andy 2026-10-25）
A4: 0.1 DCF（股東權益現金流，FY2027–FY2032 明確期＋FY2032 後永續）
A5: 項目 | B5: A | C5: B | D5: C | E5: 說明 | F5: 折現年數 t | G5: 期內占比（基準日後）
A6: 情境 EPS（FY2027–FY2032） | E6: 引用 PL 頁延伸表（上游結束後為收斂法）；三情境欄 B／C／D＝A／B／C
A7: FY2027 | B7: =PL!E223 -> 9.1425476 | C7: =PL!E232 -> 9.1425476 | D7: =PL!E241 -> 9.1425476 | F7: 1 | G7: 1
A8: FY2028 | B8: =PL!F223 -> 10.436978 | C8: =PL!F232 -> 11.112903 | D8: =PL!F241 -> 9.9142281 | F8: 2 | G8: 1
A9: FY2029 | B9: =PL!G223 -> 11.715798 | C9: =PL!G232 -> 12.515385 | D9: =PL!G241 -> 10.946623 | F9: 3 | G9: 1
A10: FY2030 | B10: =PL!H223 -> 12.397046 | C10: =PL!H232 -> 13.04622 | D10: =PL!H241 -> 10.869156 | F10: 4 | G10: 1
A11: FY2031 | B11: =PL!I223 -> 12.878819 | C11: =PL!I232 -> 13.132096 | D11: =PL!I241 -> 10.405838 | F11: 5 | G11: 1
A12: FY2032 | B12: =PL!J223 -> 13.130937 | C12: =PL!J232 -> 12.747983 | D12: =PL!J241 -> 9.5879868 | F12: 6 | G12: 1
A13: 股東現金流＝EPS ×（1 − tp_g ÷ tp_roe） | B13: =1-MIN(0.8,tp_g/tp_roe) -> 0.8 | E13: B 欄＝可發放比例（1 − 再投資率；再投資率＝tp_g ÷ tp_roe，上限 0.8）；下列六列＝EPS × 可發放比例 × 期內占比
A14: FY2027 股東現金流 | B14: =B7*$B$13*$G$7 -> 7.3140381 | C14: =C7*$B$13*$G$7 -> 7.3140381 | D14: =D7*$B$13*$G$7 -> 7.3140381
A15: FY2028 股東現金流 | B15: =B8*$B$13*$G$8 -> 8.3495826 | C15: =C8*$B$13*$G$8 -> 8.8903222 | D15: =D8*$B$13*$G$8 -> 7.9313825
A16: FY2029 股東現金流 | B16: =B9*$B$13*$G$9 -> 9.3726384 | C16: =C9*$B$13*$G$9 -> 10.012308 | D16: =D9*$B$13*$G$9 -> 8.7572987
A17: FY2030 股東現金流 | B17: =B10*$B$13*$G$10 -> 9.9176366 | C17: =C10*$B$13*$G$10 -> 10.436976 | D17: =D10*$B$13*$G$10 -> 8.6953244
A18: FY2031 股東現金流 | B18: =B11*$B$13*$G$11 -> 10.303055 | C18: =C11*$B$13*$G$11 -> 10.505677 | D18: =D11*$B$13*$G$11 -> 8.3246703
A19: FY2032 股東現金流 | B19: =B12*$B$13*$G$12 -> 10.504749 | C19: =C12*$B$13*$G$12 -> 10.198387 | D19: =D12*$B$13*$G$12 -> 7.6703894
A20: 永續價值（FY2032 年底；FY2032 現金流 ×(1＋tp_g) ÷ (tp_r − tp_g)） | B20: =B19*(1+tp_g)/(tp_r-tp_g) -> 182.08232 | C20: =C19*(1+tp_g)/(tp_r-tp_g) -> 176.77203 | D20: =D19*(1+tp_g)/(tp_r-tp_g) -> 132.95342
A21: DCF 情境每股價值（折現率 tp_r） | B21: =MAX(0,B14/(1+tp_r)^$F$7+B15/(1+tp_r)^$F$8+B16/(1+tp_r)^$F$9+B17/(1+tp_r)^$F$10+B18/(1+tp_r)^$F$11+B19/(1+tp_r)^$F$12+B20/(1+tp_r)^$F$12) -> 142.47306 | C21: =MAX(0,C14/(1+tp_r)^$F$7+C15/(1+tp_r)^$F$8+C16/(1+tp_r)^$F$9+C17/(1+tp_r)^$F$10+C18/(1+tp_r)^$F$11+C19/(1+tp_r)^$F$12+C20/(1+tp_r)^$F$12) -> 140.71062 | D21: =MAX(0,D14/(1+tp_r)^$F$7+D15/(1+tp_r)^$F$8+D16/(1+tp_r)^$F$9+D17/(1+tp_r)^$F$10+D18/(1+tp_r)^$F$11+D19/(1+tp_r)^$F$12+D20/(1+tp_r)^$F$12) -> 110.26994 | E21: 基準日 2026 年底；明確期現金流與永續價值依 F 欄年數折現；小於 0 時取 0（Andy 2026-10-25 12:22）
A22: 其中：永續價值現值占比 | B22: =B20/(1+tp_r)^$F$12/B21 -> 0.72140464 | C22: =C20/(1+tp_r)^$F$12/C21 -> 0.70913771 | D22: =D20/(1+tp_r)^$F$12/D21 -> 0.6805911
A23: DCF 目標價（情境加權） | B23: =(tp_wA*B21+tp_wB*C21+tp_wC*D21)*(1+tp_r) -> 148.66633 | E23: Σ 權重 × 情境價值 ×(1＋tp_r)：推到約 12 個月後
A25: 0.2 Comparable（市場主流同業前瞻 P/E）
A26: 同業與前瞻 P/E | B26: 代號 | C26: 前瞻 12 月 P/E | D26: 日期 | E26: 來源 | F26: 標記
A27: NVIDIA | B27: NVDA | C27: 17.44 | D27: 2026-10-23 | E27: stockanalysis.com 統計頁（Forward PE） | F27: Interested-party（資料商彙整賣方預估）
A28: Broadcom | B28: AVGO | C28: 18.52 | D28: 2026-10-23 | E28: 同上 | F28: Interested-party（同上）
A29: Intel | B29: INTC | C29: 50.64 | D29: 2026-10-23 | E29: 同上 | F29: Interested-party（同上）
A30: Qualcomm | B30: QCOM | C30: 18.98 | D30: 2026-10-23 | E30: 同上 | F30: Interested-party（同上）
A31: Marvell | B31: MRVL | C31: 40.44 | D31: 2026-10-23 | E31: 同上 | F31: Interested-party（同上）
A32: 同業選擇 | E32: 券商常用的 CPU／GPU／AI 半導體同業（NVIDIA、Intel 為直接競爭者）；不含 A 股（Andy 11:53）。前瞻 P/E 口徑為資料商的未來 12 個月共識 EPS，各家 GAAP／non-GAAP 口徑不一
A33: 同業前瞻 P/E 中位數 | B33: =MEDIAN(C27:C31) -> 18.98
A34: 各情境 12 個月後的前瞻 EPS | B34: =2/12*PL!E223+10/12*PL!F223 -> 10.22124 | C34: =2/12*PL!E232+10/12*PL!F232 -> 10.78451 | D34: =2/12*PL!E241+10/12*PL!F241 -> 9.7856147 | E34: 會計年度＝日曆年：約 12 個月後（2027-10 底）的未來 12 個月＝2027-11～2028-10（2/12 × FY2027＋10/12 × FY2028）
A35: 12 個月後的前瞻 EPS（情境加權） | B35: =tp_wA*B34+tp_wB*C34+tp_wC*D34 -> 10.41575
A36: Comparable 目標價 | B36: =B33*B35 -> 197.69093 | E36: 同業前瞻 P/E 中位數 × 12 個月後的前瞻 EPS（情境加權）
A38: 0.3 結論
A39: 項目 | B39: 數值 | C39: 對照 | D39: 對照 | E39: 說明
A40: 目標價（DCF 與 Comparable 加權） | B40: =tp_w_dcf*B23+(1-tp_w_dcf)*B36 -> 173.17863 | E40: ="DCF 權重 "&TEXT(tp_w_dcf,"0%")&"、Comparable 權重 "&TEXT(1-tp_w_dcf,"0%")&"（In 頁 tp_w_dcf，Andy 可改）" -> DCF 權重 50%、Comparable 權重 50%（In 頁 tp_w_dcf，Andy 可改）
A41: Comparable 目標價（市場主流同業法） | B41: =B36 -> 197.69093
A42: 市場共識目標價 | B42: =cons_tp -> 637.61 | E42: stockanalysis.com：55 位分析師平均目標價（2026-10-25 頁面）；Interested-party
...

Sheet Recon
A1: Recon — 本模型 vs 公司指引、大單、共識、市場層。只作事後對照，不為對上數字而調整參數。公司對 2027 的說法（資料中心逾一倍、伺服器 CPU 逾 70%）與共識只放在這裡，不用於校準
A3: 項目 | B3: 對照值 | C3: 模型 A | D3: 差距 A | E3: 模型 B | F3: 差距 B | G3: 模型 C | H3: 差距 C | I3: 對照來源 | J3: 說明
A4: A. FY2026 錨點與 FY2027–28 vs 公司說法與共識（校準時未使用）
A5: FY2026 營收 vs 共識（S&P Global，stockanalysis） | B5: =cons_rev26 -> 51 | C5: =PL!D5 -> 49.643175 | D5: =C5/B5-1 -> -0.026604408 | E5: =PL!D21 -> 49.643175 | F5: =E5/B5-1 -> -0.026604408 | G5: =PL!D37 -> 49.643175 | H5: =G5/B5-1 -> -0.026604408 | I5: stockanalysis（二手） | J5: 另一來源 tickflow 47.15
A6: FY2026 EPS vs 共識 | B6: =cons_eps26 -> 7.59 | C6: =PL!D17 -> 7.3055625 | D6: =C6/B6-1 -> -0.037475297 | E6: =PL!D33 -> 7.3055625 | F6: =E6/B6-1 -> -0.037475297 | G6: =PL!D49 -> 7.3055625 | H6: =G6/B6-1 -> -0.037475297 | I6: stockanalysis（二手） | J6: tickflow 6.81
A7: FY2027 資料中心營收 vs 公司「逾一倍」（FY2026 錨點 × 2） | B7: =a26_dc*(1+g_dc27) -> 61.70294 | C7: =PL!E7 -> 56.376771 | D7: =C7/B7-1 -> -0.086319531 | E7: =PL!E23 -> 56.376771 | F7: =E7/B7-1 -> -0.086319531 | G7: =PL!E39 -> 56.376771 | H7: =G7/B7-1 -> -0.086319531 | I7: 公司 Q2 2026 法說（二手）
A8: FY2027 資料中心非 GPU 年增 vs 公司伺服器 CPU「逾 70%」（百分點） | B8: =g_srv27 -> 0.7 | C8: =PL!E84/PL!D84-1 -> 0.5 | D8: =C8-B8 -> -0.2 | E8: =PL!E132/PL!D132-1 -> 0.5 | F8: =E8-B8 -> -0.2 | G8: =PL!E180/PL!D180-1 -> 0.5 | H8: =G8-B8 -> -0.2 | I8: 同上 | J8: 非 GPU 含 DPU、FPGA；基準 50%（Assumed）
A9: FY2027 營收 vs 共識（stockanalysis「Revenue Next Year」） | B9: =cons_rev27 -> 89.17 | C9: =PL!E5 -> 75.668419 | D9: =C9/B9-1 -> -0.15141394 | E9: =PL!E21 -> 75.668419 | F9: =E9/B9-1 -> -0.15141394 | G9: =PL!E37 -> 75.668419 | H9: =G9/B9-1 -> -0.15141394 | I9: stockanalysis（二手） | J9: tickflow 四季合計 67.1
A10: FY2027 EPS vs 共識（stockanalysis 15.76） | B10: =cons_eps27 -> 15.76 | C10: =PL!E17 -> 9.1425476 | D10: =C10/B10-1 -> -0.41988911 | E10: =PL!E33 -> 9.1425476 | F10: =E10/B10-1 -> -0.41988911 | G10: =PL!E49 -> 9.1425476 | H10: =G10/B10-1 -> -0.41988911 | I10: stockanalysis（二手） | J10: 差距超過 30% 的原因見 README
A11: FY2027 EPS vs 共識（tickflow 四季合計 11.23） | B11: =cons_eps27_lo -> 11.23 | C11: =PL!E17 -> 9.1425476 | D11: =C11/B11-1 -> -0.18588178 | E11: =PL!E33 -> 9.1425476 | F11: =E11/B11-1 -> -0.18588178 | G11: =PL!E49 -> 9.1425476 | H11: =G11/B11-1 -> -0.18588178 | I11: tickflow（二手；可能較舊）
A12: FY2028 EPS vs 共識約 $20（Motley Fool，二手） | B12: =cons_eps28 -> 20 | C12: =PL!F17 -> 10.436978 | D12: =C12/B12-1 -> -0.47815109 | E12: =PL!F33 -> 11.112903 | F12: =E12/B12-1 -> -0.44435486 | G12: =PL!F49 -> 9.9142281 | H12: =G12/B12-1 -> -0.50428859 | I12: ts2.tech 轉述（二手） | J12: tickflow 四季合計 14.41
A13: FY2029 EPS vs 公司策略期間 EPS 逾 $20 | B13: =lt_eps -> 20 | C13: =PL!G17 -> 11.715798 | D13: =C13/B13-1 -> -0.4142101 | E13: =PL!G33 -> 12.515385 | F13: =E13/B13-1 -> -0.37423075 | G13: =PL!G49 -> 10.946623 | H13: =G13/B13-1 -> -0.45266883 | I13: 公司 2025-11 分析師日（二手） | J13: 公司 Q2 2026 稱將顯著超過
A14: FY2027 資料中心 GPU 營收 vs 公司「2027 年資料中心 AI 數百億美元」（下限 20） | B14: 20 | C14: =PL!E8 -> 32.829625 | D14: =C14/B14-1 -> 0.64148124 | E14: =PL!E24 -> 32.829625 | F14: =E14/B14-1 -> 0.64148124 | G14: =PL!E40 -> 32.829625 | H14: =G14/B14-1 -> 0.64148124 | I14: 公司分析師日（二手）
A15: FY2027 毛利率 vs FY2026 錨點（百分點） | B15: =a26_gp/a26_rev -> 0.55792296 | C15: =PL!E12 -> 0.49718814 | D15: =C15-B15 -> -0.060734824 | E15: =PL!E28 -> 0.49718814 | F15: =E15-B15 -> -0.060734824 | G15: =PL!E44 -> 0.49718814 | H15: =G15-B15 -> -0.060734824 | I15: Q 頁 | J15: HBM 漲價（2027 +80%，三情境相同）× 吸收比例 0.5 壓 GPU 毛利率
A16: B. 認列係數 k_rec 與每顆售價
A17: k_rec（Derived） | C17: =k_rec -> 0.67348322 | E17: =k_rec -> 0.67348322 | G17: =k_rec -> 0.67348322 | I17: 錨點 GPU ÷ 市場層顆數 × pa_amd | J17: FY2027 起沿用
A18: FY2026 隱含每顆認列售價 vs HSBC MI355X（US$K） | B18: =p355 -> 23 | C18: =p_real26 -> 20.204496 | D18: =C18/B18-1 -> -0.12154363 | E18: =p_real26 -> 20.204496 | F18: =E18/B18-1 -> -0.12154363 | G18: =p_real26 -> 20.204496 | H18: =G18/B18-1 -> -0.12154363 | I18: HSBC（finviz 轉述，Interested-party） | J18: 若 k_rec 全歸售價層；與 MI355X 價接近＝2026 的水準差主要是售價（MI355X 為主）
A19: AMD 認列顆數 FY2026 vs 市場層（百萬顆） | B19: =u_amd_26 -> 0.75 | C19: =PL!D77 -> 0.50511241 | D19: =C19/B19-1 -> -0.32651678 | E19: =PL!D125 -> 0.50511241 | F19: =E19/B19-1 -> -0.32651678 | G19: =PL!D173 -> 0.50511241 | H19: =G19/B19-1 -> -0.32651678 | I19: markets/memory UNITS
A20: FY2026 GPU 營收 vs FY2025（Assumed 6.5）年增 | C20: =PL!D97/PL!C97-1 -> 1.3312881 | E20: =PL!D145/PL!C145-1 -> 1.3312881 | G20: =PL!D193/PL!C193-1 -> 1.3312881 | I20: Q 頁（皆含 Assumed 拆分）
A21: C. 大單（Interested-party）：認列顆數換算 GW
A22: FY2027 AMD 認列顆數 ÷ 每 GW GPU 數 → 隱含 GW | B22: =gw_27-gw_26 -> 2 | C22: =PL!E77*1000000/gpw -> 3.4627099 | D22: =C22/B22-1 -> 0.73135493 | E22: =PL!E125*1000000/gpw -> 3.4627099 | F22: =E22/B22-1 -> 0.73135493 | G22: =PL!E173*1000000/gpw -> 3.4627099 | H22: =G22/B22-1 -> 0.73135493 | I22: 對照值＝In 頁假設的 2027 年新歸屬 GW | J22: 每 GW 顆數以 VR200 NVL72 為 Analogy；每顆認列售價低於市場層時，顆數高估、GW 偏高
A23: FY2028 隱含 GW | B23: =gw_28-gw_27 -> 2 | C23: =PL!F77*1000000/gpw -> 4.6169465 | D23: =C23/B23-1 -> 1.3084732 | E23: =PL!F125*1000000/gpw -> 3.6935572 | F23: =E23/B23-1 -> 0.84677859 | G23: =PL!F173*1000000/gpw -> 2.7701679 | H23: =G23/B23-1 -> 0.38508394 | I23: 同上
A24: 已宣布大單合計 GW（OpenAI 6＋Meta 6＋Anthropic 2＋Oracle 首批） | B24: =openai_gw+meta_gw+anth_gw+orcl_u*1000000/gpw -> 14.171383 | C24: =SUM(PL!E77:G77)*1000000/gpw -> 13.389145 | D24: =C24/B24-1 -> -0.055198449 | E24: =SUM(PL!E125:G125)*1000000/gpw -> 11.669332 | F24: =E24/B24-1 -> -0.17655658 | G24: =SUM(PL!E173:G173)*1000000/gpw -> 9.4185708 | H24: =G24/B24-1 -> -0.33538098 | I24: 公司、Oracle 新聞稿 | J24: 模型值＝FY2027–29 認列顆數累計換算 GW；大單為多年期、上限值
A25: 認股權證稀釋占 FY2029 股數 | C25: =PL!G112/PL!G113 -> 0.07237839 | E25: =PL!G160/PL!G161 -> 0.060822443 | G25: =PL!G208/PL!G209 -> 0.04472179 | I25: In 頁 G 節 | J25: 上限 0.32B 股（約為 FY2026 股數的 19%）
A26: D. 份額（Units 頁，模組層級）
A27: 2027 年 AMD 金額份額 | C27: =Units!D33 -> 0.06701814 | E27: =Units!D67 -> 0.06701814 | G27: =Units!D101 -> 0.06701814 | I27: accel_share（NVIDIA 模型同一套價格）
A28: 2027 年 AMD 顆數份額 | C28: =Units!D27 -> 0.063291139 | E28: =Units!D61 -> 0.063291139 | G28: =Units!D95 -> 0.063291139 | I28: 同上 | J28: 公司目標「雙位數份額」（2025 分析師日，二手）
A29: 2027 年 NVIDIA 金額份額 | C29: =Units!D32 -> 0.75128824 | E29: =Units!D66 -> 0.75128824 | G29: =Units!D100 -> 0.75128824 | I29: 同上 | J29: 與 NVIDIA 模型 Units 頁的 CY2027 值相同（同一份顆數與價格）
A30: E. 預留
A31: R4 產業部署路徑（markets/deploy_path/，尚未建立）：上線後以 AMD 資料中心 GPU 營收 ÷ 部署 GW 對照 IT capex | J31: 預留列：本版無數值

Sheet Sens
A1: Sens — 一次動一個輸入（情境 A）：對 FY2027、FY2028、FY2029 的營收、EPS 與隱含股價（十年 P/E 中位數 × EPS，與目標價同法）的影響。每個案例是一個完整的推導區塊（本頁下方，與 PL 同一引擎）
A3: 案例 | B3: 設定 | C3: FY2027 營收 | D3: FY2027 EPS | E3: FY2027 EPS 相對基準 | F3: FY2027 隱含價（中位數 P/E） | G3: 隱含價相對基準 | H3: FY2028 營收 | I3: FY2028 EPS | J3: FY2028 EPS 相對基準 | K3: FY2028 隱含價（中位數 P/E） | L3: 隱含價相對基準 | M3: FY2029 EPS | N3: FY2029 EPS 年增（對 FY2028）
A4: 基準（情境 A） | B4: PL 區塊 A | C4: =PL!E95 -> 75.668419 | D4: =PL!E114 -> 9.1425476 | E4: =D4/D$4-1 -> 0 | F4: =D4*pe_mid -> 471.57261 | G4: =F4/F$4-1 -> 0 | H4: =PL!F95 -> 93.833597 | I4: =PL!F114 -> 10.436978 | J4: =I4/I$4-1 -> 0 | K4: =I4*pe_mid -> 538.33934 | L4: =K4/K$4-1 -> 0 | M4: =PL!G114 -> 11.715798 | N4: =M4/I4-1 -> 0.12252778
A5: AMD 顆數係數 低（×0.8） | B5: FY2027 起 AMD 認列顆數 ×0.8（大單延後） | C5: =E65 -> 69.102494 | D5: =E84 -> 8.6141753 | E5: =D5/D$4-1 -> -0.057792679 | F5: =D5*pe_mid -> 444.31916 | G5: =F5/F$4-1 -> -0.057792679 | H5: =F65 -> 84.927658 | I5: =F84 -> 9.8125405 | J5: =I5/I$4-1 -> -0.059829362 | K5: =I5*pe_mid -> 506.13084 | L5: =K5/K$4-1 -> -0.059829362 | M5: =G84 -> 10.947532 | N5: =M5/I5-1 -> 0.11566744
A6: AMD 顆數係數 高（×1.2） | B6: ×1.2（OpenAI、Meta、Anthropic、Oracle 提前放量） | C6: =E113 -> 82.234344 | D6: =E132 -> 9.6709199 | E6: =D6/D$4-1 -> 0.057792679 | F6: =D6*pe_mid -> 498.82605 | G6: =F6/F$4-1 -> 0.057792679 | H6: =F113 -> 102.73954 | I6: =F132 -> 11.063325 | J6: =I6/I$4-1 -> 0.060012254 | K6: =I6*pe_mid -> 570.64629 | L6: =K6/K$4-1 -> 0.060012254 | M6: =G132 -> 12.486515 | N6: =M6/I6-1 -> 0.12864039
A7: 世代售價係數 高（隨 HBM 容量） | B7: FY2027 ×1.25、FY2028 起 ×1.5（Analogy） | C7: =E161 -> 83.875825 | D7: =E180 -> 9.803013 | E7: =D7/D$4-1 -> 0.072240849 | F7: =D7*pe_mid -> 505.63941 | G7: =F7/F$4-1 -> 0.072240849 | H7: =F161 -> 116.09845 | I7: =F180 -> 12.050906 | J7: =I7/I$4-1 -> 0.15463553 | K7: =I7*pe_mid -> 621.58573 | L7: =K7/K$4-1 -> 0.15463553 | M7: =G180 -> 13.69403 | N7: =M7/I7-1 -> 0.13634861
A8: 對照：FY2027 起每顆＝市場層 pa_amd（k_rec 只解釋 2026 售價） | B8: 世代係數＝1 ÷ k_rec | C8: =E209 -> 91.584812 | D8: =E228 -> 10.42337 | E8: =D8/D$4-1 -> 0.14009465 | F8: =D8*pe_mid -> 537.63741 | G8: =F8/F$4-1 -> 0.14009465 | H8: =F209 -> 115.4224 | I8: =F228 -> 11.957785 | J8: =I8/I$4-1 -> 0.14571329 | K8: =I8*pe_mid -> 616.78253 | L8: =K8/K$4-1 -> 0.14571329 | M8: =G228 -> 13.587275 | N8: =M8/I8-1 -> 0.13627022
A9: HBM 吸收比例 0（全額轉嫁） | B9: 吸收比例 0.0 | C9: =E257 -> 78.191299 | D9: =E276 -> 10.139103 | E9: =D9/D$4-1 -> 0.10900192 | F9: =D9*pe_mid -> 522.97492 | G9: =F9/F$4-1 -> 0.10900192 | H9: =F257 -> 97.954301 | I9: =F276 -> 12.02139 | J9: =I9/I$4-1 -> 0.15180752 | K9: =I9*pe_mid -> 620.06329 | L9: =K9/K$4-1 -> 0.15180752 | M9: =G276 -> 13.29887 | N9: =M9/I9-1 -> 0.10626725
A10: HBM 吸收比例 1（全額吸收） | B10: 吸收比例 1.0 | C10: =E305 -> 73.145539 | D10: =E324 -> 8.1459924 | E10: =D10/D$4-1 -> -0.10900192 | F10: =D10*pe_mid -> 420.17029 | G10: =F10/F$4-1 -> -0.10900192 | H10: =F305 -> 89.712893 | I10: =F324 -> 8.8535131 | J10: =I10/I$4-1 -> -0.15171681 | K10: =I10*pe_mid -> 456.66421 | L10: =K10/K$4-1 -> -0.15171681 | M10: =G324 -> 10.133292 | N10: =M10/I10-1 -> 0.14455036
A11: GPU 毛利率 低（40%） | B11: FY2026 GPU 毛利率 40%（非 GPU 毛利率重新校準） | C11: =E353 -> 75.668419 | D11: =E372 -> 8.5554099 | E11: =D11/D$4-1 -> -0.064220361 | F11: =D11*pe_mid -> 441.28804 | G11: =F11/F$4-1 -> -0.064220361 | H11: =F353 -> 93.833597 | I11: =F372 -> 9.5165165 | J11: =I11/I$4-1 -> -0.088192361 | K11: =I11*pe_mid -> 490.86192 | L11: =K11/K$4-1 -> -0.088192361 | M11: =G372 -> 10.649453 | N11: =M11/I11-1 -> 0.11904947
A12: GPU 毛利率 高（55%） | B12: 55% | C12: =E401 -> 75.668419 | D12: =E420 -> 9.4361165 | E12: =D12/D$4-1 -> 0.03211018 | F12: =D12*pe_mid -> 486.71489 | G12: =F12/F$4-1 -> 0.03211018 | H12: =F401 -> 93.833597 | I12: =F420 -> 10.897209 | J12: =I12/I$4-1 -> 0.04409618 | K12: =I12*pe_mid -> 562.07804 | L12: =K12/K$4-1 -> 0.04409618 | M12: =G420 -> 12.248971 | N12: =M12/I12-1 -> 0.12404659
A13: 資料中心 CPU 成長 低 | B13: FY2027 +30%、FY2028 +10%、FY2029 +5% | C13: =E449 -> 72.528799 | D13: =E468 -> 8.5710708 | E13: =D13/D$4-1 -> -0.062507398 | F13: =D13*pe_mid -> 442.09583 | G13: =F13/F$4-1 -> -0.062507398 | H13: =F449 -> 86.847944 | I13: =F468 -> 9.178059 | J13: =I13/I$4-1 -> -0.12062105 | K13: =I13*pe_mid -> 473.40428 | L13: =K13/K$4-1 -> -0.12062105 | M13: =G468 -> 9.9059426 | N13: =M13/I13-1 -> 0.079306922
A14: 資料中心 CPU 成長 高（公司說法） | B14: FY2027 +70%、FY2028 +40%、FY2029 +25% | C14: =E497 -> 78.808038 | D14: =E516 -> 9.7140245 | E14: =D14/D$4-1 -> 0.062507398 | F14: =D14*pe_mid -> 501.04938 | G14: =F14/F$4-1 -> 0.062507398 | H14: =F497 -> 101.76114 | I14: =F516 -> 11.871827 | J14: =I14/I$4-1 -> 0.13747741 | K14: =I14*pe_mid -> 612.34883 | L14: =K14/K$4-1 -> 0.13747741 | M14: =G516 -> 13.996876 | N14: =M14/I14-1 -> 0.17899932
A15: 營業費用率 −2pt | B15: 營業費用額外 −2% × 營收 | C15: =E545 -> 75.668419 | D15: =E564 -> 9.916202 | E15: =D15/D$4-1 -> 0.08462131 | F15: =D15*pe_mid -> 511.4777 | G15: =F15/F$4-1 -> 0.08462131 | H15: =F545 -> 93.833597 | I15: =F564 -> 11.358412 | J15: =I15/I$4-1 -> 0.088285468 | K15: =I15*pe_mid -> 585.86688 | L15: =K15/K$4-1 -> 0.088285468 | M15: =G564 -> 12.708581 | N15: =M15/I15-1 -> 0.11886959
A16: 營業費用率 +2pt | B16: +2% × 營收 | C16: =E593 -> 75.668419 | D16: =E612 -> 8.3688933 | E16: =D16/D$4-1 -> -0.08462131 | F16: =D16*pe_mid -> 431.66751 | G16: =F16/F$4-1 -> -0.08462131 | H16: =F593 -> 93.833597 | I16: =F612 -> 9.5155447 | J16: =I16/I$4-1 -> -0.088285468 | K16: =I16*pe_mid -> 490.8118 | L16: =K16/K$4-1 -> -0.088285468 | M16: =G612 -> 10.723015 | N16: =M16/I16-1 -> 0.12689446
A17: 認股權證不歸屬 | B17: OpenAI、Meta 認股權證 0 股 | C17: =E641 -> 75.668419 | D17: =E660 -> 9.2880862 | E17: =D17/D$4-1 -> 0.015918817 | F17: =D17*pe_mid -> 479.07948 | G17: =F17/F$4-1 -> 0.015918817 | H17: =F641 -> 93.833597 | I17: =F660 -> 10.930476 | J17: =I17/I$4-1 -> 0.047283616 | K17: =I17*pe_mid -> 563.79397 | L17: =K17/K$4-1 -> 0.047283616 | M17: =G660 -> 12.629932 | N17: =M17/I17-1 -> 0.15547867
A18: 認股權證歸屬加速（×1.5） | B18: 已歸屬 GW ×1.5 | C18: =E689 -> 75.668419 | D18: =E708 -> 9.0714754 | E18: =D18/D$4-1 -> -0.0077737846 | F18: =D18*pe_mid -> 467.9067 | G18: =F18/F$4-1 -> -0.0077737846 | H18: =F689 -> 93.833597 | I18: =F708 -> 10.206571 | J18: =I18/I$4-1 -> -0.022076055 | K18: =I18*pe_mid -> 526.45493 | L18: =K18/K$4-1 -> -0.022076055 | M18: =G708 -> 11.306621 | N18: =M18/I18-1 -> 0.10777857
A19: 顆數情境 B | B19: CY2028 ×0.8、CY2029 ×0.85；記憶體 B 路徑 | C19: =PL!E143 -> 75.668419 | D19: =PL!E162 -> 9.1425476 | E19: =D19/D$4-1 -> 0 | F19: =D19*pe_mid -> 471.57261 | G19: =F19/F$4-1 -> 0 | H19: =PL!F143 -> 82.808439 | I19: =PL!F162 -> 11.112903 | J19: =I19/I$4-1 -> 0.064762475 | K19: =I19*pe_mid -> 573.20352 | L19: =K19/K$4-1 -> 0.064762475 | M19: =PL!G162 -> 12.515385 | N19: =M19/I19-1 -> 0.12620305
A20: 顆數情境 C | B20: CY2028–29 ×0.6；記憶體 C 路徑 | C20: =PL!E191 -> 75.668419 | D20: =PL!E210 -> 9.1425476 | E20: =D20/D$4-1 -> 0 | F20: =D20*pe_mid -> 471.57261 | G20: =F20/F$4-1 -> 0 | H20: =PL!F191 -> 73.751126 | I20: =PL!F210 -> 9.9142281 | J20: =I20/I$4-1 -> -0.050086344 | K20: =I20*pe_mid -> 511.37589 | L20: =K20/K$4-1 -> -0.050086344 | M20: =PL!G210 -> 10.946623 | N20: =M20/I20-1 -> 0.1041327
A22: 讀法：FY2027 三情境相同；顆數、售價、吸收比例與 CPU 成長從 FY2027 起作用，情境 B、C 從 FY2028 起。隱含價欄＝EPS × 十年 non-GAAP P/E 中位數（與目標價同法），只反映 EPS 變動。
A24: 目標價參數敏感度（v0.2）：加權目標價（Val 第 0 節）一次動一個參數；PL 延伸期的收斂路徑不隨 tp_g 變動，tp_g 只改再投資率與永續成長
A25: 參數 | B25: 設定（低／高） | C25: 低：加權目標價 | D25: 低：相對基準 | E25: 高：加權目標價 | F25: 高：相對基準 | G25: 基準加權目標價
A26: tp_r ±1pt | B26: 折現率 −1pt／＋1pt | C26: =tp_w_dcf*(tp_wA*(MAX(0,Val!B7*Val!$G$7*(1-MIN(0.8,tp_g/tp_roe))/(1+(tp_r-0.01))^Val!$F$7+Val!B8*Val!$G$8*(1-MIN(0.8,tp_g/tp_roe))/(1+(tp_r-0.01))^Val!$F$8+Val!B9*Val!$G$9*(1-MIN(0.8,tp_g/tp_roe))/(1+(tp_r-0.01))^Val!$F$9+Val!B10*Val!$G$10*(1-MIN(0.8,tp_g/tp_roe))/(1+(tp_r-0.01))^Val!$F$10+Val!B11*Val!$G$11*(1-MIN(0.8,tp_g/tp_roe))/(1+(tp_r-0.01))^Val!$F$11+Val!B12*Val!$G$12*(1-MIN(0.8,tp_g/tp_roe))/(1+(tp_r-0.01))^Val!$F$12+Val!B12*(1-MIN(0.8,tp_g/tp_roe))*(1+tp_g)/((tp_r-0.01)-tp_g)/(1+(tp_r-0.01))^Val!$F$12))+tp_wB*(MAX(0,Val!C7*Val!$G$7*(1-MIN(0.8,tp_g/tp_roe))/(1+(tp_r-0.01))^Val!$F$7+Val!C8*Val!$G$8*(1-MIN(0.8,tp_g/tp_roe))/(1+(tp_r-0.01))^Val!$F$8+Val!C9*Val!$G$9*(1-MIN(0.8,tp_g/tp_roe))/(1+(tp_r-0.01))^Val!$F$9+Val!C10*Val!$G$10*(1-MIN(0.8,tp_g/tp_roe))/(1+(tp_r-0.01))^Val!$F$10+Val!C11*Val!$G$11*(1-MIN(0.8,tp_g/tp_roe))/(1+(tp_r-0.01))^Val!$F$11+Val!C12*Val!$G$12*(1-MIN(0.8,tp_g/tp_roe))/(1+(tp_r-0.01))^Val!$F$12+Val!C12*(1-MIN(0.8,tp_g/tp_roe))*(1+tp_g)/((tp_r-0.01)-tp_g)/(1+(tp_r-0.01))^Val!$F$12))+tp_wC*(MAX(0,Val!D7*Val!$G$7*(1-MIN(0.8,tp_g/tp_roe))/(1+(tp_r-0.01))^Val!$F$7+Val!D8*Val!$G$8*(1-MIN(0.8,tp_g/tp_roe))/(1+(tp_r-0.01))^Val!$F$8+Val!D9*Val!$G$9*(1-MIN(0.8,tp_g/tp_roe))/(1+(tp_r-0.01))^Val!$F$9+Val!D10*Val!$G$10*(1-MIN(0.8,tp_g/tp_roe))/(1+(tp_r-0.01))^Val!$F$10+Val!D11*Val!$G$11*(1-MIN(0.8,tp_g/tp_roe))/(1+(tp_r-0.01))^Val!$F$11+Val!D12*Val!$G$12*(1-MIN(0.8,tp_g/tp_roe))/(1+(tp_r-0.01))^Val!$F$12+Val!D12*(1-MIN(0.8,tp_g/tp_roe))*(1+tp_g)/((tp_r-0.01)-tp_g)/(1+(tp_r-0.01))^Val!$F$12)))*(1+(tp_r-0.01))+(1-tp_w_dcf)*Val!$B$36 -> 187.14286 | D26: =C26/G26-1 -> 0.08063481 | E26: =tp_w_dcf*(tp_wA*(MAX(0,Val!B7*Val!$G$7*(1-MIN(0.8,tp_g/tp_roe))/(1+(tp_r+0.01))^Val!$F$7+Val!B8*Val!$G$8*(1-MIN(0.8,tp_g/tp_roe))/(1+(tp_r+0.01))^Val!$F$8+Val!B9*Val!$G$9*(1-MIN(0.8,tp_g/tp_roe))/(1+(tp_r+0.01))^Val!$F$9+Val!B10*Val!$G$10*(1-MIN(0.8,tp_g/tp_roe))/(1+(tp_r+0.01))^Val!$F$10+Val!B11*Val!$G$11*(1-MIN(0.8,tp_g/tp_roe))/(1+(tp_r+0.01))^Val!$F$11+Val!B12*Val!$G$12*(1-MIN(0.8,tp_g/tp_roe))/(1+(tp_r+0.01))^Val!$F$12+Val!B12*(1-MIN(0.8,tp_g/tp_roe))*(1+tp_g)/((tp_r+0.01)-tp_g)/(1+(tp_r+0.01))^Val!$F$12))+tp_wB*(MAX(0,Val!C7*Val!$G$7*(1-MIN(0.8,tp_g/tp_roe))/(1+(tp_r+0.01))^Val!$F$7+Val!C8*Val!$G$8*(1-MIN(0.8,tp_g/tp_roe))/(1+(tp_r+0.01))^Val!$F$8+Val!C9*Val!$G$9*(1-MIN(0.8,tp_g/tp_roe))/(1+(tp_r+0.01))^Val!$F$9+Val!C10*Val!$G$10*(1-MIN(0.8,tp_g/tp_roe))/(1+(tp_r+0.01))^Val!$F$10+Val!C11*Val!$G$11*(1-MIN(0.8,tp_g/tp_roe))/(1+(tp_r+0.01))^Val!$F$11+Val!C12*Val!$G$12*(1-MIN(0.8,tp_g/tp_roe))/(1+(tp_r+0.01))^Val!$F$12+Val!C12*(1-MIN(0.8,tp_g/tp_roe))*(1+tp_g)/((tp_r+0.01)-tp_g)/(1+(tp_r+0.01))^Val!$F$12))+tp_wC*(MAX(0,Val!D7*Val!$G$7*(1-MIN(0.8,tp_g/tp_roe))/(1+(tp_r+0.01))^Val!$F$7+Val!D8*Val!$G$8*(1-MIN(0.8,tp_g/tp_roe))/(1+(tp_r+0.01))^Val!$F$8+Val!D9*Val!$G$9*(1-MIN(0.8,tp_g/tp_roe))/(1+(tp_r+0.01))^Val!$F$9+Val!D10*Val!$G$10*(1-MIN(0.8,tp_g/tp_roe))/(1+(tp_r+0.01))^Val!$F$10+Val!D11*Val!$G$11*(1-MIN(0.8,tp_g/tp_roe))/(1+(tp_r+0.01))^Val!$F$11+Val!D12*Val!$G$12*(1-MIN(0.8,tp_g/tp_roe))/(1+(tp_r+0.01))^Val!$F$12+Val!D12*(1-MIN(0.8,tp_g/tp_roe))*(1+tp_g)/((tp_r+0.01)-tp_g)/(1+(tp_r+0.01))^Val!$F$12)))*(1+(tp_r+0.01))+(1-tp_w_dcf)*Val!$B$36 -> 163.19812 | F26: =E26/G26-1 -> -0.057631295 | G26: =Val!$B$40 -> 173.17863
A27: tp_g ±1pt | B27: 長期成長 −1pt／＋1pt | C27: =tp_w_dcf*(tp_wA*(MAX(0,Val!B7*Val!$G$7*(1-MIN(0.8,(tp_g-0.01)/tp_roe))/(1+tp_r)^Val!$F$7+Val!B8*Val!$G$8*(1-MIN(0.8,(tp_g-0.01)/tp_roe))/(1+tp_r)^Val!$F$8+Val!B9*Val!$G$9*(1-MIN(0.8,(tp_g-0.01)/tp_roe))/(1+tp_r)^Val!$F$9+Val!B10*Val!$G$10*(1-MIN(0.8,(tp_g-0.01)/tp_roe))/(1+tp_r)^Val!$F$10+Val!B11*Val!$G$11*(1-MIN(0.8,(tp_g-0.01)/tp_roe))/(1+tp_r)^Val!$F$11+Val!B12*Val!$G$12*(1-MIN(0.8,(tp_g-0.01)/tp_roe))/(1+tp_r)^Val!$F$12+Val!B12*(1-MIN(0.8,(tp_g-0.01)/tp_roe))*(1+(tp_g-0.01))/(tp_r-(tp_g-0.01))/(1+tp_r)^Val!$F$12))+tp_wB*(MAX(0,Val!C7*Val!$G$7*(1-MIN(0.8,(tp_g-0.01)/tp_roe))/(1+tp_r)^Val!$F$7+Val!C8*Val!$G$8*(1-MIN(0.8,(tp_g-0.01)/tp_roe))/(1+tp_r)^Val!$F$8+Val!C9*Val!$G$9*(1-MIN(0.8,(tp_g-0.01)/tp_roe))/(1+tp_r)^Val!$F$9+Val!C10*Val!$G$10*(1-MIN(0.8,(tp_g-0.01)/tp_roe))/(1+tp_r)^Val!$F$10+Val!C11*Val!$G$11*(1-MIN(0.8,(tp_g-0.01)/tp_roe))/(1+tp_r)^Val!$F$11+Val!C12*Val!$G$12*(1-MIN(0.8,(tp_g-0.01)/tp_roe))/(1+tp_r)^Val!$F$12+Val!C12*(1-MIN(0.8,(tp_g-0.01)/tp_roe))*(1+(tp_g-0.01))/(tp_r-(tp_g-0.01))/(1+tp_r)^Val!$F$12))+tp_wC*(MAX(0,Val!D7*Val!$G$7*(1-MIN(0.8,(tp_g-0.01)/tp_roe))/(1+tp_r)^Val!$F$7+Val!D8*Val!$G$8*(1-MIN(0.8,(tp_g-0.01)/tp_roe))/(1+tp_r)^Val!$F$8+Val!D9*Val!$G$9*(1-MIN(0.8,(tp_g-0.01)/tp_roe))/(1+tp_r)^Val!$F$9+Val!D10*Val!$G$10*(1-MIN(0.8,(tp_g-0.01)/tp_roe))/(1+tp_r)^Val!$F$10+Val!D11*Val!$G$11*(1-MIN(0.8,(tp_g-0.01)/tp_roe))/(1+tp_r)^Val!$F$11+Val!D12*Val!$G$12*(1-MIN(0.8,(tp_g-0.01)/tp_roe))/(1+tp_r)^Val!$F$12+Val!D12*(1-MIN(0.8,(tp_g-0.01)/tp_roe))*(1+(tp_g-0.01))/(tp_r-(tp_g-0.01))/(1+tp_r)^Val!$F$12)))*(1+tp_r)+(1-tp_w_dcf)*Val!$B$36 -> 169.37116 | D27: =C27/G27-1 -> -0.021985832 | E27: =tp_w_dcf*(tp_wA*(MAX(0,Val!B7*Val!$G$7*(1-MIN(0.8,(tp_g+0.01)/tp_roe))/(1+tp_r)^Val!$F$7+Val!B8*Val!$G$8*(1-MIN(0.8,(tp_g+0.01)/tp_roe))/(1+tp_r)^Val!$F$8+Val!B9*Val!$G$9*(1-MIN(0.8,(tp_g+0.01)/tp_roe))/(1+tp_r)^Val!$F$9+Val!B10*Val!$G$10*(1-MIN(0.8,(tp_g+0.01)/tp_roe))/(1+tp_r)^Val!$F$10+Val!B11*Val!$G$11*(1-MIN(0.8,(tp_g+0.01)/tp_roe))/(1+tp_r)^Val!$F$11+Val!B12*Val!$G$12*(1-MIN(0.8,(tp_g+0.01)/tp_roe))/(1+tp_r)^Val!$F$12+Val!B12*(1-MIN(0.8,(tp_g+0.01)/tp_roe))*(1+(tp_g+0.01))/(tp_r-(tp_g+0.01))/(1+tp_r)^Val!$F$12))+tp_wB*(MAX(0,Val!C7*Val!$G$7*(1-MIN(0.8,(tp_g+0.01)/tp_roe))/(1+tp_r)^Val!$F$7+Val!C8*Val!$G$8*(1-MIN(0.8,(tp_g+0.01)/tp_roe))/(1+tp_r)^Val!$F$8+Val!C9*Val!$G$9*(1-MIN(0.8,(tp_g+0.01)/tp_roe))/(1+tp_r)^Val!$F$9+Val!C10*Val!$G$10*(1-MIN(0.8,(tp_g+0.01)/tp_roe))/(1+tp_r)^Val!$F$10+Val!C11*Val!$G$11*(1-MIN(0.8,(tp_g+0.01)/tp_roe))/(1+tp_r)^Val!$F$11+Val!C12*Val!$G$12*(1-MIN(0.8,(tp_g+0.01)/tp_roe))/(1+tp_r)^Val!$F$12+Val!C12*(1-MIN(0.8,(tp_g+0.01)/tp_roe))*(1+(tp_g+0.01))/(tp_r-(tp_g+0.01))/(1+tp_r)^Val!$F$12))+tp_wC*(MAX(0,Val!D7*Val!$G$7*(1-MIN(0.8,(tp_g+0.01)/tp_roe))/(1+tp_r)^Val!$F$7+Val!D8*Val!$G$8*(1-MIN(0.8,(tp_g+0.01)/tp_roe))/(1+tp_r)^Val!$F$8+Val!D9*Val!$G$9*(1-MIN(0.8,(tp_g+0.01)/tp_roe))/(1+tp_r)^Val!$F$9+Val!D10*Val!$G$10*(1-MIN(0.8,(tp_g+0.01)/tp_roe))/(1+tp_r)^Val!$F$10+Val!D11*Val!$G$11*(1-MIN(0.8,(tp_g+0.01)/tp_roe))/(1+tp_r)^Val!$F$11+Val!D12*Val!$G$12*(1-MIN(0.8,(tp_g+0.01)/tp_roe))/(1+tp_r)^Val!$F$12+Val!D12*(1-MIN(0.8,(tp_g+0.01)/tp_roe))*(1+(tp_g+0.01))/(tp_r-(tp_g+0.01))/(1+tp_r)^Val!$F$12)))*(1+tp_r)+(1-tp_w_dcf)*Val!$B$36 -> 178.97512 | F27: =E27/G27-1 -> 0.03347115 | G27: =Val!$B$40 -> 173.17863
