Workbook

Sheet README
A1: Lumentum（LITE）收支與估值模型 v0.2.2（AI 半導體 Project：網通次產業內複製——雷射與光元件） 2026-10-26
A2: 版本：v0.2.1（2026-10-25：補上檔空間級距、投資建議、重點觀察，數值不變）；v0.2（2026-10-25：三情境延伸到 FY2032、目標價＝DCF 與 Comparable 加權；v0.1 初版）。Lumentum 的雷射有效份額（上游元件口徑）在本模型 Units 頁建立；不可與中際旭創等光模組廠份額相加。
A3: 模型命題：Lumentum 的雷射晶片營收＝高速光模組數量（本專案網通模型金額 ÷ 模組單價）× 每模組 EML／CW 雷射數 × 雷射單價 × Lumentum 份額；光模組、OCS（Google TPU）、CPO 外部光源另推；電信與 DCI、工業與 3D 感測依成長率推。股價約 35 倍共識 FY2027 EPS，遠高於十年 non-GAAP P/E 中位數。
A4: 核心問題：EML 供給缺口收斂、矽光以較少 CW 雷射替代、OCS 與 CPO 放量時程——哪一條路徑決定 FY2028 獲利，現價隱含的倍數與獲利要多少才合理？
A6: 會計年度 6 月底結束：FY2027＝2026-07～2027-06（FY(t) 後半年在日曆年 t）。市場層為日曆年，先算 CY2026–CY2029 產品營收，再換成 FY2027–FY2029（FY(t)＝CY(t−1) 下半年＋CY(t) 上半年，上半年占比 h＝47%）。口徑：公司 non-GAAP；EPS 以 non-GAAP 稀釋股數（含可轉債假設轉換）。
A8: 驅動因子 → 推導量（全部唯讀上游，不修改）
A9: 雷射晶片：markets/network 可插拔光模組市場 × 情境顆數係數 ÷ 模組單價 × 每模組雷射數 × 雷射單價 × 有效份額（CY2026 以產品拆分殘差校準）× 份額相對值。光模組：可插拔市場 × 份額。OCS：Google TPU 顆數（網通模型 Units）× 每顆 TPU 營收。CPO：CPO 光學市場 × 份額。
A10: CY2026 錨點＝FY2026 第三、四季實績＋FY2027 第一季指引中點＋第二季季增 12%（Assumed）。產品拆分（OCS、CPO、電信與 DCI、工業與 3D 感測、光模組）為 Assumed／公司展望，雷射晶片＝殘差。毛利率 FY2027 起為輸入路徑；營業費用彈性 phi（Derived）；稅率 16.5%；營業外淨收入由第一季指引推導。
A11: 估值：目標價（Val 第 0 節）＝0.5 × DCF（股東現金流＝EPS ×（1 − g／ROE），FY2027–32 明確期＋永續，r 10%、g 4%，情境權重 0.3／0.5／0.2）＋0.5 × Comparable（美股光通訊同業前瞻 P/E 中位數 × 12 個月後前瞻 EPS）。舊法規則值情境加權保留參考（不是目標價）；規則值＝FY2027 EPS × 十年 P/E 依循環位置取分位（年底股價 ÷ 近 12 月 non-GAAP EPS，推導）。本版未做先驗，無 Andy 合理 P/E 對照。
A12: 標記：Verified、Interested-party、Analogy、Assumed、Derived。SemiAnalysis 未使用。公司不揭露產品別營收；法說內容多經第三方轉述。
A14: 已知限制：(1) 產品拆分、雷射單價、每模組雷射數皆為 Assumed，雷射份額由殘差推得；(2) CY2026 下半年第二季為假設，FY2027 第一季財報約 11-05 公布；(3) 網通模型 CY2028 可插拔光模組只 +12%，比券商出貨預測保守；(4) 未設 EML 產能上限（公司 EML 出貨年增約 50%）；(5) 十年 P/E 為推導序列、多數年份在 AI 前，規則值偏低；(6) R4 產業部署路徑未建（Recon 預留列）。
A15: v0.2（2026-10-25）：Val 頁最前面新增「0. 目標價」（0.1 DCF、0.2 Comparable、0.3 結論），既有內容整體下移；原「0. 目標價與上檔空間」改名「舊法：規則值情境加權（參考）」保留。PL 三情境延伸到 FY2032（FY2030 起為收斂法，非驅動因子推導；灰底），說明欄移到 K 欄。In 頁新增 K 節（tp_r、tp_g、tp_roe、tp_w_dcf、收斂法參數、共識目標價）。Sens 加目標價參數列。FY2026–FY2029 既有數字不變。
A16: v0.2.1（2026-10-25）：補上檔空間級距、投資建議、重點觀察（Val 頁 0.3 結論加「上檔空間級距」「投資建議」兩列、README 頁加重點觀察三點；數值不變，既有儲存格位置不變）。
A17: ="投資建議："&Val!B50&"（依上檔空間固定規則）" -> 投資建議：中立（依上檔空間固定規則）
A18: 重點觀察 1：目標價 US$623（DCF 387、Comparable 860 各半），比現價 756.17（2026-10-23）低 17.6%，級距 0%～−25%；Comparable 單獨為 +13.7%。DCF 拉低：DCF 單獨 −48.8%（ROE 用預設 20%），而本模型 12 個月後前瞻 EPS 29.30 比共識前瞻 EPS 23.60 高 24.2%（共識 FY2028 只有單一來源）；共識目標價 1,165.03 隱含 49.4 倍，比同業中位數 29.3 倍高 68.3%，市場給 EML／CW 雷射供給缺口的溢價，Comparable 未計入。
A19: 重點觀察 2：最敏感的是 AI 市場與毛利率：AI 市場 ×0.8 時 FY2028 EPS −12.7%、毛利率低（FY2028 46%）−11.3%、雷射單價低 −9.5%、每模組雷射數低（矽光替代）−7.9%；情境 C FY2028 EPS 25.04，比情境 A 的 32.73 低 23.5%。現價 ÷ FY2028 EPS 23.1～30.2 倍，在十年分位 76%～80%。
A20: 重點觀察 3：追蹤 FY2027 Q1 財報（約 2026-11-05）：產品別營收（雷射、光模組、OCS）公司不揭露，本版為 Assumed 拆分。網通 CPO 已改三情境（v0.2.2；A＝替代快、C＝慢）：CPO 快對 Lumentum 外部光源是加分，情境 A FY2028 EPS 由 31.43 升到 32.73（+4.1%）、C 由 25.45 降到 25.04（−1.6%）、B 不變；CPO 外部光源份額低／高時 FY2028 EPS −8.2%／+5.4%。
A21: v0.2.2（2026-10-26）：網通模型 v0.2.3 的 CPO 滲透改三情境（A＝替代快、B＝平平、C＝慢），本模型 A／B／C 改讀同字母的可插拔與 CPO 市場（In 頁末新增 B、C 兩組；情境 A 沿用 A 節 mpl_／mcp_，數值改為網通情境 A）；FY2027 起三情境不再相同。其他輸入不變。

Sheet In
A1: In — 輸入（藍字；基準欄 E，低 D、高 F）。公司金額：十億美元（US$B；Q 頁百萬美元）；比例：%。每個輸入附兩個來源（找不到者寫「未找到」）；公司原文算一個
A2: 標記：Verified／Interested-party／Analogy／Assumed／Derived；Analogy、Assumed 給低／高區間。SemiAnalysis 未使用。公司不揭露產品別營收（只有元件／系統兩個部門），產品拆分為 Assumed；口徑為公司 non-GAAP
A3: 鍵 | B3: 項目 | C3: 單位 | D3: 低 | E3: 基準 | F3: 高 | G3: 標記 | H3: 來源1 | I3: 來源2／說明
A4: A. AI 光學市場與 TPU 顆數（讀 markets/network 成品；日曆年；情境 A 基準，B／C 依顆數係數縮放）
A5: mpl_26 | B5: AI 可插拔光模組市場 CY2026 | C5: US$B | E5: 29.753262 | G5: Derived | H5: markets/network/dist/20261026_AI網通市場模型_v0.2.3.xlsx｜Mkt!C45:F45 | I5: 加速器顆數 × 每顆光學內容 − CPO（網通模型；日曆年）
A6: mpl_27 | B6: AI 可插拔光模組市場 CY2027 | C6: US$B | E6: 53.560715 | G6: Derived | H6: markets/network/dist/20261026_AI網通市場模型_v0.2.3.xlsx｜Mkt!C45:F45 | I6: 同上
A7: mpl_28 | B7: AI 可插拔光模組市場 CY2028 | C7: US$B | E7: 57.9915 | G7: Derived | H7: markets/network/dist/20261026_AI網通市場模型_v0.2.3.xlsx｜Mkt!C45:F45 | I7: 同上
A8: mpl_29 | B8: AI 可插拔光模組市場 CY2029 | C8: US$B | E8: 72.9348 | G8: Derived | H8: markets/network/dist/20261026_AI網通市場模型_v0.2.3.xlsx｜Mkt!C45:F45 | I8: 同上
A9: mcp_26 | B9: AI CPO 光學市場 CY2026 | C9: US$B | E9: 0.300538 | G9: Derived | H9: markets/network/dist/20261026_AI網通市場模型_v0.2.3.xlsx｜Mkt!C44:F44 | I9: 共同封裝光學；外部光源（ELS）與超高功率雷射屬此
A10: mcp_27 | B10: AI CPO 光學市場 CY2027 | C10: US$B | E10: 2.818985 | G10: Derived | H10: markets/network/dist/20261026_AI網通市場模型_v0.2.3.xlsx｜Mkt!C44:F44 | I10: 同上
A11: mcp_28 | B11: AI CPO 光學市場 CY2028 | C11: US$B | E11: 6.4435 | G11: Derived | H11: markets/network/dist/20261026_AI網通市場模型_v0.2.3.xlsx｜Mkt!C44:F44 | I11: 同上
A12: mcp_29 | B12: AI CPO 光學市場 CY2029 | C12: US$B | E12: 11.74736 | G12: Derived | H12: markets/network/dist/20261026_AI網通市場模型_v0.2.3.xlsx｜Mkt!C44:F44 | I12: 同上
A13: tpu_26 | B13: Google TPU 顆數 CY2026 | C13: 百萬顆 | E13: 3.85 | G13: Derived | H13: markets/network/dist/20261026_AI網通市場模型_v0.2.3.xlsx｜Units!B9:E9 | I13: OCS（光路交換）的主要用戶是 Google TPU 叢集
A14: tpu_27 | B14: Google TPU 顆數 CY2027 | C14: 百萬顆 | E14: 5.5 | G14: Derived | H14: markets/network/dist/20261026_AI網通市場模型_v0.2.3.xlsx｜Units!B9:E9 | I14: 同上
A15: tpu_28 | B15: Google TPU 顆數 CY2028 | C15: 百萬顆 | E15: 7 | G15: Derived | H15: markets/network/dist/20261026_AI網通市場模型_v0.2.3.xlsx｜Units!B9:E9 | I15: 同上
A16: tpu_29 | B16: Google TPU 顆數 CY2029 | C16: 百萬顆 | E16: 8.05 | G16: Derived | H16: markets/network/dist/20261026_AI網通市場模型_v0.2.3.xlsx｜Units!B9:E9 | I16: 同上
... A26: um29_C | B26: 情境 C：CY2029 顆數 ÷ 基準 | C26: x | E26: 0.6 | G26: Assumed | H26: tsmc/dist/20261028_台積電個股模型_v0.4.xlsx｜In!E42 | I26: 同上
A27: B. 雷射晶片（EML／CW）：高速光模組數量 × 每模組雷射數 × 雷射單價 × Lumentum 份額（上游元件口徑，不可與光模組廠份額相加）
A28: asp_26 | B28: 光模組平均單價 CY2026（把網通模型金額換成模組數） | C28: $/個 | D28: 420 | E28: 500 | F28: 600 | G28: Assumed | H28: 800G 為主、1.6T 比重上升（每個模組單價上升）vs 每 Gb 降價（下壓） | I28: https://www.kgi.com.hk/en/-/media/files/kgishk/research-reports/us-daily/optical-networking-industry_20260818_tc.pdf：800G＋1.6T 出貨 2026 年 67.2M、2027 年 107.5M（凱基；只在 Recon 對照）
A29: asp_27 | B29: 光模組平均單價 CY2027（把網通模型金額換成模組數） | C29: $/個 | D29: 440 | E29: 520 | F29: 640 | G29: Assumed | H29: 同上 | I29: —
A30: asp_28 | B30: 光模組平均單價 CY2028（把網通模型金額換成模組數） | C30: $/個 | D30: 450 | E30: 540 | F30: 680 | G30: Assumed | H30: 同上 | I30: —
A31: asp_29 | B31: 光模組平均單價 CY2029（把網通模型金額換成模組數） | C31: $/個 | D31: 450 | E31: 560 | F31: 720 | G31: Assumed | H31: 同上 | I31: —
A32: lpm_26 | B32: 每模組雷射數 CY2026（EML 與 CW 加權） | C32: 顆 | E32: 5.5 | G32: Assumed | H32: EML 方案（DR8／2×FR4）每模組 8 顆；矽光方案每模組 1–4 顆高功率 CW（業界常識，未找到第一手來源） | I32: （網址見 Sources）：公司 FY2026 第四季約 20% 光模組改用自製 CW 雷射
A33: lpm_27 | B33: 每模組雷射數 CY2027（EML 與 CW 加權） | C33: 顆 | D33: 4.5 | E33: 5.5 | F33: 6 | G33: Assumed | H33: 矽光比重上升使每模組雷射數下降 | I33: —
A34: lpm_28 | B34: 每模組雷射數 CY2028（EML 與 CW 加權） | C34: 顆 | D34: 4 | E34: 5 | F34: 6 | G34: Assumed | H34: 矽光比重上升使每模組雷射數下降 | I34: —
A35: lpm_29 | B35: 每模組雷射數 CY2029（EML 與 CW 加權） | C35: 顆 | D35: 3.5 | E35: 4.8 | F35: 6 | G35: Assumed | H35: 矽光比重上升使每模組雷射數下降 | I35: —
A36: lasp_26 | B36: 雷射平均單價 CY2026（EML 與 CW 加權） | C36: $/顆 | E36: 13 | G36: Assumed | H36: （網址見 Sources）：光學元件與雷射約占光模組成本 25–35%（次級來源） | I36: 雷射單價：未找到；本列×每模組雷射數＝每模組雷射內容（2026 約占模組單價 14%）
A37: lasp_27 | B37: 雷射平均單價 CY2027（EML 與 CW 加權） | C37: $/顆 | D37: 12 | E37: 15 | F37: 17 | G37: Assumed | H37: 200G EML 比重上升（公司：2027 年中占 EML 出貨 50% 以上） | I37: —
A38: lasp_28 | B38: 雷射平均單價 CY2028（EML 與 CW 加權） | C38: $/顆 | D38: 11 | E38: 15 | F38: 18 | G38: Assumed | H38: 200G EML 比重上升（公司：2027 年中占 EML 出貨 50% 以上） | I38: —
A39: lasp_29 | B39: 雷射平均單價 CY2029（EML 與 CW 加權） | C39: $/顆 | D39: 10 | E39: 14 | F39: 18 | G39: Assumed | H39: 200G EML 比重上升（公司：2027 年中占 EML 出貨 50% 以上） | I39: —
A40: lrel_27 | B40: 雷射份額 CY2027 ÷ CY2026（相對值） | C40: x | D40: 0.85 | E40: 0.95 | F40: 1 | G40: Assumed | H40: https://www.trendforce.com/presscenter/news/20260603-13077.html：EML 前三大（Lumentum、Broadcom、三菱電機）合計約 72%；CW 由 Broadcom、住友電工領先（TrendForce，Interested-party） | I40: https://www.kgi.com.hk/en/-/media/files/kgishk/research-reports/us-daily/optical-networking-industry_20260818_tc.pdf：Lumentum 是唯一量產 200G EML 的供應商；EML 供需缺口約 30%（凱基）
A41: lrel_28 | B41: 雷射份額 CY2028 ÷ CY2026 | C41: x | D41: 0.8 | E41: 0.95 | F41: 1.05 | G41: Assumed | H41: Greensboro（第五座 InP 廠）2028 年初量產（公司） | I41: Coherent 擴 6 吋 InP、中國 EML 廠追趕（下壓）
A42: lrel_29 | B42: 雷射份額 CY2029 ÷ CY2026 | C42: x | D42: 0.7 | E42: 0.9 | F42: 1.05 | G42: Assumed | H42: 同上 | I42: —
A43: C. 光模組、OCS、CPO（另推）
A44: mrel_27 | B44: 光模組份額 CY2027 ÷ CY2026（相對值） | C44: x | D44: 0.8 | E44: 1 | F44: 1.2 | G44: Assumed | H44: https://www.marketbeat.com/instant-alerts/lumentum-q4-earnings-call-highlights-2026-08-11/：800G 出貨創新高、1.6T 開始量產（公司） | I44: 公司估光模組供給缺口約 30%（vocus 轉述法說，Interested-party）
A45: mrel_28 | B45: 光模組份額 CY2028 ÷ CY2026 | C45: x | D45: 0.7 | E45: 1 | F45: 1.3 | G45: Assumed | H45: 中際旭創、新易盛、Coherent 為主要競爭者 | I45: —
A46: mrel_29 | B46: 光模組份額 CY2029 ÷ CY2026 | C46: x | D46: 0.6 | E46: 1 | F46: 1.3 | G46: Assumed | H46: 同上 | I46: —
A47: ocsk_27 | B47: OCS 每顆 TPU 營收 CY2027 ÷ CY2026（相對值） | C47: x | D47: 1.2 | E47: 1.6 | F47: 2 | G47: Assumed | H47: https://www.zacks.com/stock/news/2973530/lumentum-q4-earnings-call-focuses-on-ai-optics-ocs-npo-ramps：2H CY2026 OCS 約 4 億美元（追上原展望、未超前）；FY2027 第一季首度超過 1 億美元（公司） | I47: https://s21.q4cdn.com/377324469/files/doc_financials/2026/q4/Q4-FY26-Earnings-Presentation_final.pdf：多年期、數十億美元的 OCS 採購協議（公司）
A48: ocsk_28 | B48: OCS 每顆 TPU 營收 CY2028 ÷ CY2026 | C48: x | D48: 1.2 | E48: 1.8 | F48: 2.4 | G48: Assumed | H48: 2H CY2026 年化 8 億美元 ÷ CY2026 約 5 億美元 ≈ 1.6（推導） | I48: https://www.kgi.com.hk/en/-/media/files/kgishk/research-reports/us-daily/optical-networking-industry_20260818_tc.pdf：Coherent 把 OCS 市場規模由 20 億上調到 40 億美元（Interested-party）
A49: ocsk_29 | B49: OCS 每顆 TPU 營收 CY2029 ÷ CY2026 | C49: x | D49: 1 | E49: 1.8 | F49: 2.4 | G49: Assumed | H49: 同上；Coherent 等競爭者加入（下壓） | I49: —
...

Sheet Q
A1: Q — 實績與錨點（百萬美元；EPS 為美元；股數為百萬股）。藍字＝輸入；黑字＝公式。口徑：公司 non-GAAP（GAAP 含 FY2026 可轉債清償損失 77.6 億美元等非現金項目，不用於預測）
A2: CY2026 錨點＝FY2026 第三季（2026-01～03）＋第四季（04～06）實績＋FY2027 第一季（07～09）指引中點＋第二季（10～12，季增假設）。FY2027 第一季財報（約 2026-11-05）公布後以實績取代第一季、並以新指引取代第二季
A3: 項目 | B3: FY2025A | C3: FY2026A | D3: FY26 Q3（實績） | E3: FY26 Q4（實績） | F3: FY27 Q1（指引） | G3: FY27 Q2（假設） | H3: CY2026 錨點 | I3: 2H CY2026 | J3: 標記 | K3: 說明
A4: 營收 | B4: =a25_rev_in -> 1645 | C4: =a26_rev_in -> 3014 | D4: =q3_26 -> 808.4 | E4: =q4_26 -> 1006.3 | F4: =q1g -> 1250 | G4: =F4*(1+q_g) -> 1400 | H4: =D4+E4+F4+G4 -> 4464.7 | I4: =F4+G4 -> 2650 | J4: Verified／Interested-party（指引）／Assumed（Q2） | K4: FY(t) 由 CY(t−1) 7 月起算；CY2026＝FY2026 後兩季＋FY2027 前兩季
A5: 毛利率（non-GAAP） | B5: =a25_gm_in -> 0.347 | C5: =a26_gm_in -> 0.46 | J5: Verified
A6: 毛利 | B6: =B4*B5 -> 570.815 | C6: =C4*C5 -> 1386.44 | J6: Derived
A7: 營業費用（研發＋銷管，non-GAAP） | B7: =a25_opx_in -> 411.4 | C7: =a26_opx_in -> 489.7 | J7: Verified
A8: 營業利益（non-GAAP） | B8: =B6-B7 -> 159.415 | C8: =C6-C7 -> 896.74 | F8: =F4*om_g -> 500 | J8: Derived | K8: FY2026 公司揭露營業利益率 29.8%；FY2027 第一季＝指引營業利益率 × 營收
A9: 營業利益率 | B9: =B8/B4 -> 0.096908815 | C9: =C8/C4 -> 0.29752488 | F9: =F8/F4 -> 0.4 | J9: Derived
A10: 淨利（non-GAAP） | B10: =a25_ni_in -> 146.4 | C10: =a26_ni_in -> 782.3 | F10: =eps_g*sh_q1 -> 428.4 | J10: Verified／Derived（Q1 指引）
A11: 淨利 ÷ 營業利益（營業外與稅） | B11: =B10/B8 -> 0.91835775 | C11: =C10/C8 -> 0.87238218 | F11: =F10/F8 -> 0.8568 | J11: Derived | K11: FY2027 起＝（營業利益＋營業外）×（1 − 稅率）
A12: 稀釋股數（non-GAAP） | B12: =B10/B13 -> 71.067961 | C12: =C10/C13 -> 90.230681 | F12: =sh_q1 -> 102 | J12: Derived | K12: 淨利 ÷ EPS；公司揭露 FY2025 71.2、FY2026 90.2
A13: EPS（non-GAAP） | B13: =a25_eps_in -> 2.06 | C13: =a26_eps_in -> 8.67 | F13: =eps_g -> 4.2 | J13: Verified
A14: 產品拆分：OCS | H14: =(ocs_1h+ocs_2h)*1000 -> 500 | J14: Assumed／Interested-party | K14: 2H CY2026 公司展望 4 億美元＋1H 假設
A15: 產品拆分：CPO／超高功率雷射 | H15: =cpo_a26*1000 -> 50 | J15: Interested-party
A16: 產品拆分：電信與 DCI 元件 | H16: =tel_a26*1000 -> 750 | J16: Assumed
A17: 產品拆分：工業雷射與 3D 感測 | H17: =ind_a26*1000 -> 300 | J17: Assumed
A18: 產品拆分：光模組（收發器） | H18: =xcvr_a26*1000 -> 1000 | J18: Assumed
A19: 產品拆分：雷射晶片（EML／CW；殘差） | H19: =H4-SUM(H14:H18) -> 1864.7 | J19: Derived（殘差） | K19: 元件部門（約 64.5%）≈ 雷射晶片＋電信與 DCI＋3D 感測＋CPO 雷射（Recon 對照）
A20: AI 相關（雷射晶片＋光模組＋OCS＋CPO）÷ 營收 | H20: =(H19+H18+H14+H15)/H4 -> 0.76482182 | J20: Derived
A22: 參考與推導（校準未使用共識）
A23: FY2026 營收年增 | B23: =C4/B4-1 -> 0.83221884
A24: FY2026 營業費用年增 | B24: =C7/B7-1 -> 0.19032572
A25: 2H CY2026 ÷ CY2026（FY2027 換算用） | B25: =I4/H4 -> 0.59354492
A26: 營業費用彈性（營業費用年增 ÷ 營收年增；In 頁 phi 的依據） | B26: =B24/B23 -> 0.22869672
A27: 元件部門占 FY2026 第四季營收（公司揭露 64.5%） | B27: =649.4/1006.3 -> 0.64533439
A28: 1H CY2026 ÷ CY2026 | B28: =(D4+E4)/H4 -> 0.40645508

Sheet Units
A1: Units — 高速光模組數量、每模組雷射數與 Lumentum 份額（日曆年；情境 A）。雷射份額是上游元件口徑（占光模組內雷射金額），不可與中際旭創等光模組廠份額相加
A3: 項目 | B3: 單位 | C3: CY2026 | D3: CY2027 | E3: CY2028 | F3: CY2029 | G3: 說明
A4: 高速光模組數量（情境 A） | B4: 百萬個 | C4: =PL!C65 -> 59.506524 | D4: =PL!D65 -> 103.00137 | E4: =PL!E65 -> 107.39167 | F4: =PL!F65 -> 130.24071 | G4: 網通模型可插拔金額 ÷ 平均單價（Assumed）
A5: 每模組雷射數 | B5: 顆 | C5: =PL!C66 -> 5.5 | D5: =PL!D66 -> 5.5 | E5: =PL!E66 -> 5 | F5: =PL!F66 -> 4.8 | G5: EML 方案 8 顆、矽光 1–4 顆
A6: 光模組雷射市場 | B6: US$B | C6: =PL!C68 -> 4.2547165 | D6: =PL!D68 -> 8.4976134 | E6: =PL!E68 -> 8.054375 | F6: =PL!F68 -> 8.752176
A7: Lumentum 雷射有效份額 | B7: % | C7: =PL!C71 -> 0.43826657 | D7: =PL!D71 -> 0.41635324 | E7: =PL!E71 -> 0.41635324 | F7: =PL!F71 -> 0.39443991 | G7: CY2026 以錨點殘差校準
A8: Lumentum 雷射晶片營收 | B8: US$B | C8: =PL!C72 -> 1.8647 | D8: =PL!D72 -> 3.5380089 | E8: =PL!E72 -> 3.3534652 | F8: =PL!F72 -> 3.4522076
A9: Lumentum 光模組份額（模組廠口徑） | B9: % | C9: =PL!C74 -> 0.03360976 | D9: =PL!D74 -> 0.03360976 | E9: =PL!E74 -> 0.03360976 | F9: =PL!F74 -> 0.03360976 | G9: 與中際旭創份額同口徑
A10: OCS 每顆 TPU 營收 | B10: $/顆 | C10: =PL!C77 -> 129.87013 | D10: =PL!D77 -> 207.79221 | E10: =PL!E77 -> 233.76623 | F10: =PL!F77 -> 233.76623
A11: OCS 營收 | B11: US$B | C11: =PL!C78 -> 0.5 | D11: =PL!D78 -> 1.1428571 | E11: =PL!E78 -> 1.6363636 | F11: =PL!F78 -> 1.8818182
A12: Lumentum 占 CPO 光學金額 | B12: % | C12: =PL!C80 -> 0.16636831 | D12: =PL!D80 -> 0.25 | E12: =PL!E80 -> 0.25 | F12: =PL!F80 -> 0.2
A13: Lumentum AI 相關營收 ÷ AI IT 資本支出 | B13: % | C13: =PL!C82/itc_26 -> 0.0043673338 | D13: =PL!D82/itc_27 -> 0.0045905229 | E13: =PL!E82/itc_28 -> 0.0043087939 | F13: =PL!F82/itc_29 -> 0.0044836588 | G13: markets/network 的 AI IT 資本支出
A15: 讀法：雷射有效份額由 CY2026 產品拆分的殘差推得（拆分為 Assumed），是最需要每季檢查的輸入；每模組雷射數隨矽光比重上升而下降，單價隨 200G EML 比重上升而上升。

Sheet PL
A1: PL — Lumentum 損益（US$B；non-GAAP）。FY2025A、FY2026A 實績，FY2027 起為模型（會計年度 6 月底結束；FY2027＝2026-07～2027-06）。三情境各一個完整推導區塊（本頁下方），頂端為摘要。FY2027 三情境只差在網通 CPO 情境（A 替代快、C 慢），顆數係數從 CY2028 開始
A2: 灰底＝FY2030–FY2032 收斂法，非驅動因子推導（上游市場層只到 2029）：營收年增由 FY2029 線性收斂到 fade_g（A＝tp_g＋2pt、B＝tp_g、C＝tp_g−2pt），淨利率由 FY2029 線性收斂到 fade_m（In 頁 K 節），FY2032 達到；股數依 sh_g
A3: 情境／項目 | B3: 單位 | C3: FY2025A | D3: FY2026A（錨點） | E3: FY2027 | F3: FY2028 | G3: FY2029 | H3: FY2030（收斂） | I3: FY2031（收斂） | J3: FY2032（收斂） | K3: 說明
A4: 情境 A
A5: 營收 | B5: US$B | C5: =C93 -> 1.645 | D5: =D93 -> 3.014 | E5: =E93 -> 6.6131693 | F5: =F93 -> 9.14381 | G5: =G93 -> 10.746305 | H5: =H93 -> 12.216791 | I5: =I93 -> 13.419145 | J5: =J93 -> 14.224294
A6: 營收年增 | B6: % | D6: =D97 -> 0.83221884 | E6: =E97 -> 1.1941504 | F6: =F97 -> 0.38266686 | G6: =G97 -> 0.17525462 | H6: =H97 -> 0.13683641 | I6: =I97 -> 0.098418207 | J6: =J97 -> 0.06
A7: AI 相關營收 | B7: US$B | E7: =E91 -> 5.4040921 | F7: =F91 -> 7.8268594 | G7: =G91 -> 9.2947505
A8: 電信、DCI、工業與 3D 感測 | B8: US$B | E8: =E92 -> 1.2090772 | F8: =F92 -> 1.3169506 | G8: =G92 -> 1.4515545
A9: AI 相關 ÷ 營收 | B9: % | E9: =E98 -> 0.8171713 | F9: =F98 -> 0.85597353 | G9: =G98 -> 0.86492525
A10: 毛利率 | B10: % | C10: =C99 -> 0.347 | D10: =D99 -> 0.46 | E10: =E99 -> 0.52 | F10: =F99 -> 0.51 | G10: =G99 -> 0.49
A11: 營業利益率 | B11: % | C11: =C104 -> 0.096908815 | D11: =D104 -> 0.29752488 | E11: =E104 -> 0.42572807 | F11: =F104 -> 0.43585191 | G11: =G104 -> 0.42438022
A12: 淨利率 | B12: % | C12: =C106 -> 0.08899696 | D12: =D106 -> 0.25955541 | E12: =E106 -> 0.36207584 | F12: =F106 -> 0.3687046 | G12: =G106 -> 0.35841469 | H12: =H106 -> 0.35841469 | I12: =I106 -> 0.35841469 | J12: =J106 -> 0.35841469
A13: 淨利（non-GAAP） | B13: US$B | C13: =C105 -> 0.1464 | D13: =D105 -> 0.7823 | E13: =E105 -> 2.3944689 | F13: =F105 -> 3.3713648 | G13: =G105 -> 3.8516335 | H13: =H105 -> 4.3786773 | I13: =I105 -> 4.8096188 | J13: =J105 -> 5.098196
A14: EPS（non-GAAP） | B14: US$ | C14: =C108 -> 2.06 | D14: =D108 -> 8.67 | E14: =E108 -> 23.475185 | F14: =F108 -> 32.725343 | G14: =G108 -> 37.01707 | H14: =H108 -> 41.665696 | I14: =I108 -> 45.313227 | J14: =J108 -> 47.556456
A15: EPS 年增 | B15: % | D15: =D109 -> 3.2087379 | E15: =E109 -> 1.7076338 | F15: =F109 -> 0.39403983 | G15: =G109 -> 0.13114385 | H15: =H109 -> 0.12558061 | I15: =I109 -> 0.087542779 | J15: =J109 -> 0.04950495
A17: 情境 B
A18: 營收 | B18: US$B | C18: =C145 -> 1.645 | D18: =D145 -> 3.014 | E18: =E145 -> 6.5334968 | F18: =F145 -> 8.0582066 | G18: =G145 -> 8.6295495 | H18: =H145 -> 9.1525117 | I18: =I145 -> 9.6128891 | J18: =J145 -> 9.9974047
A19: 營收年增 | B19: % | D19: =D149 -> 0.83221884 | E19: =E149 -> 1.1677163 | F19: =F149 -> 0.23336812 | G19: =G149 -> 0.07090199 | H19: =H149 -> 0.060601327 | I19: =I149 -> 0.050300663 | J19: =J149 -> 0.04
A20: AI 相關營收 | B20: US$B | E20: =E143 -> 5.3244196 | F20: =F143 -> 6.741256 | G20: =G143 -> 7.1779951
A21: 電信、DCI、工業與 3D 感測 | B21: US$B | E21: =E144 -> 1.2090772 | F21: =F144 -> 1.3169506 | G21: =G144 -> 1.4515545
A22: AI 相關 ÷ 營收 | B22: % | E22: =E150 -> 0.8149418 | F22: =F150 -> 0.83657026 | G22: =G150 -> 0.83179255
A23: 毛利率 | B23: % | C23: =C151 -> 0.347 | D23: =D151 -> 0.46 | E23: =E151 -> 0.52 | F23: =F151 -> 0.51 | G23: =G151 -> 0.49
A24: 營業利益率 | B24: % | C24: =C156 -> 0.096908815 | D24: =D156 -> 0.29752488 | E24: =E156 -> 0.42503159 | F24: =F156 -> 0.42889127 | G24: =G156 -> 0.41303319
A25: 淨利率 | B25: % | C25: =C158 -> 0.08899696 | D25: =D158 -> 0.25955541 | E25: =E158 -> 0.36157468 | F25: =F158 -> 0.36353484 | G25: =G158 -> 0.34993512 | H25: =H158 -> 0.33827062 | I25: =I158 -> 0.32660611 | J25: =J158 -> 0.31494161
A26: 淨利（non-GAAP） | B26: US$B | C26: =C157 -> 0.1464 | D26: =D157 -> 0.7823 | E26: =E157 -> 2.362347 | F26: =F157 -> 2.9294389 | G26: =G157 -> 3.0197824 | H26: =H157 -> 3.0960258 | I26: =I157 -> 3.1396283 | J26: =J157 -> 3.1485987
A27: EPS（non-GAAP） | B27: US$ | C27: =C160 -> 2.06 | D27: =D160 -> 8.67 | E27: =E160 -> 23.160265 | F27: =F160 -> 28.435633 | G27: =G160 -> 29.022361 | H27: =H160 -> 29.460511 | I27: =I160 -> 29.579619 | J27: =J160 -> 29.370428
A28: EPS 年增 | B28: % | D28: =D161 -> 3.2087379 | E28: =E161 -> 1.6713108 | F28: =F161 -> 0.22777666 | G28: =G161 -> 0.020633548 | H28: =H161 -> 0.01509698 | I28: =I161 -> 0.0040429695 | J28: =J161 -> -0.0070721358
A30: 情境 C
A31: 營收 | B31: US$B | C31: =C197 -> 1.645 | D31: =D197 -> 3.014 | E31: =E197 -> 6.4936606 | F31: =F197 -> 7.2000012 | G31: =G197 -> 6.529818 | H31: =H197 -> 6.1681488 | I31: =I197 -> 6.0590117 | J31: =J197 -> 6.1801919
A32: 營收年增 | B32: % | D32: =D201 -> 0.83221884 | E32: =E201 -> 1.1544992 | F32: =F201 -> 0.10877388 | G32: =G201 -> -0.093080987 | H32: =H201 -> -0.055387325 | I32: =I201 -> -0.017693662 | J32: =J201 -> 0.02
A33: AI 相關營收 | B33: US$B | E33: =E195 -> 5.2845834 | F33: =F195 -> 5.8830505 | G33: =G195 -> 5.0782635
A34: 電信、DCI、工業與 3D 感測 | B34: US$B | E34: =E196 -> 1.2090772 | F34: =F196 -> 1.3169506 | G34: =G196 -> 1.4515545
A35: AI 相關 ÷ 營收 | B35: % | E35: =E202 -> 0.81380653 | F35: =F202 -> 0.81709022 | G35: =G202 -> 0.77770368
A36: 毛利率 | B36: % | C36: =C203 -> 0.347 | D36: =D203 -> 0.46 | E36: =E203 -> 0.52 | F36: =F203 -> 0.51 | G36: =G203 -> 0.49
A37: 營業利益率 | B37: % | C37: =C208 -> 0.096908815 | D37: =D208 -> 0.29752488 | E37: =E208 -> 0.42467694 | F37: =F208 -> 0.42188976 | G37: =G208 -> 0.39284663
A38: 淨利率 | B38: % | C38: =C210 -> 0.08899696 | D38: =D210 -> 0.25955541 | E38: =E210 -> 0.36131949 | F38: =F210 -> 0.3583335 | G38: =G210 -> 0.33470399 | H38: =H210 -> 0.31239039 | I38: =I210 -> 0.2900768 | J38: =J210 -> 0.2677632
A39: 淨利（non-GAAP） | B39: US$B | C39: =C209 -> 0.1464 | D39: =D209 -> 0.7823 | E39: =E209 -> 2.3462861 | F39: =F209 -> 2.5800016 | G39: =G209 -> 2.1855562 | H39: =H209 -> 1.9268704 | I39: =I209 -> 1.7575787 | J39: =J209 -> 1.6548279
A40: EPS（non-GAAP） | B40: US$ | C40: =C212 -> 2.06 | D40: =D212 -> 8.67 | E40: =E212 -> 23.002805 | F40: =F212 -> 25.043697 | G40: =G212 -> 21.004824 | H40: =H212 -> 18.335309 | I40: =I212 -> 16.55881 | J40: =J212 -> 15.436392
A41: EPS 年增 | B41: % | D41: =D213 -> 3.2087379 | E41: =E213 -> 1.6531494 | F41: =F213 -> 0.088723606 | G41: =G213 -> -0.16127302 | H41: =H213 -> -0.1270906 | I41: =I213 -> -0.096889506 | J41: =J213 -> -0.067783701
A43: 核對（應為 0）：CY2026 模型營收 − 錨點；雷射晶片營收 − 殘差（校準恆等式）
...

Sheet Val
A1: Val — P/E 估值（美元；non-GAAP EPS）。目標價＝DCF 與 Comparable 加權（第 0 節）；舊法規則值情境加權保留參考；另列「現價 ÷ FY2027、FY2028 EPS（模型）」、市場隱含 EPS 與十年 P/E 規則值。十年 P/E 用年底股價 ÷ 近 12 月 non-GAAP EPS（推導；與模型 EPS 同口徑）
A2: 循環位置：Lumentum 不是設備股，不套設備市場見頂年；以本模型營收最高的會計年度為見頂年（比照中際旭創）。營收到 FY2029 仍在增加時，見頂年未知，判為中段
A4: 0. 目標價
A5: 0.1 DCF（股東權益現金流，FY2027–FY2032 明確期＋FY2032 後永續）
A6: 項目 | B6: A（順利） | C6: B（平平） | D6: C（不如預期） | E6: 說明
A7: 情境 EPS（FY2027–FY2032） | E7: PL 頁各情境；FY2030 起為收斂法（PL 頁灰底）
A8: FY2027 | B8: =PL!E14 -> 23.475185 | C8: =PL!E27 -> 23.160265 | D8: =PL!E40 -> 23.002805
A9: FY2028 | B9: =PL!F14 -> 32.725343 | C9: =PL!F27 -> 28.435633 | D9: =PL!F40 -> 25.043697
A10: FY2029 | B10: =PL!G14 -> 37.01707 | C10: =PL!G27 -> 29.022361 | D10: =PL!G40 -> 21.004824
A11: FY2030 | B11: =PL!H14 -> 41.665696 | C11: =PL!H27 -> 29.460511 | D11: =PL!H40 -> 18.335309
A12: FY2031 | B12: =PL!I14 -> 45.313227 | C12: =PL!I27 -> 29.579619 | D12: =PL!I40 -> 16.55881
A13: FY2032 | B13: =PL!J14 -> 47.556456 | C13: =PL!J27 -> 29.370428 | D13: =PL!J40 -> 15.436392
A14: 股東現金流＝EPS ×（1 − tp_g ÷ tp_roe）
A15: 再投資率（tp_g ÷ tp_roe，上限 0.8） | B15: =IF(tp_roe<=tp_g,0.8,MIN(tp_g/tp_roe,0.8)) -> 0.2 | E15: ROE＝In 頁 tp_roe；tp_roe ≤ tp_g 時取上限 0.8
A16: FY2027 | B16: =B8*(1-$B$15) -> 18.780148 | C16: =C8*(1-$B$15) -> 18.528212 | D16: =D8*(1-$B$15) -> 18.402244
A17: FY2028 | B17: =B9*(1-$B$15) -> 26.180274 | C17: =C9*(1-$B$15) -> 22.748506 | D17: =D9*(1-$B$15) -> 20.034957
A18: FY2029 | B18: =B10*(1-$B$15) -> 29.613656 | C18: =C10*(1-$B$15) -> 23.217889 | D18: =D10*(1-$B$15) -> 16.803859
A19: FY2030 | B19: =B11*(1-$B$15) -> 33.332557 | C19: =C11*(1-$B$15) -> 23.568409 | D19: =D11*(1-$B$15) -> 14.668247
A20: FY2031 | B20: =B12*(1-$B$15) -> 36.250582 | C20: =C12*(1-$B$15) -> 23.663695 | D20: =D12*(1-$B$15) -> 13.247048
A21: FY2032 | B21: =B13*(1-$B$15) -> 38.045165 | C21: =C13*(1-$B$15) -> 23.496342 | D21: =D13*(1-$B$15) -> 12.349114
A22: DCF 情境每股價值（折現率 tp_r） | B22: =SUMPRODUCT(B16:B21,1/(1+tp_r)^{1;2;3;4;5;6})+B21*(1+tp_g)/(tp_r-tp_g)/(1+tp_r)^6 -> 499.95154 | C22: =SUMPRODUCT(C16:C21,1/(1+tp_r)^{1;2;3;4;5;6})+C21*(1+tp_g)/(tp_r-tp_g)/(1+tp_r)^6 -> 327.03535 | D22: =SUMPRODUCT(D16:D21,1/(1+tp_r)^{1;2;3;4;5;6})+D21*(1+tp_g)/(tp_r-tp_g)/(1+tp_r)^6 -> 191.95324 | E22: Σ 明確期現金流 ÷ (1＋r)^t ＋ 永續價值 ÷ (1＋r)^6；永續價值＝FY2032 現金流 ×(1＋g)÷(r−g)；基準日 2026 年底，t＝1 對 FY2027
A23: DCF 情境價值推到 12 個月後（×(1＋tp_r)） | B23: =B22*(1+tp_r) -> 549.9467 | C23: =C22*(1+tp_r) -> 359.73889 | D23: =D22*(1+tp_r) -> 211.14856
A24: DCF 目標價（情境加權） | B24: =tp_wA*B23+tp_wB*C23+tp_wC*D23 -> 387.08317 | E24: Σ 權重 × 情境價值 ×(1＋r)；權重見 In 頁
A26: 0.2 Comparable（市場主流同業前瞻 P/E）
A27: 同業與前瞻 P/E | B27: 代號 | C27: 前瞻 12 月 P/E | D27: 日期 | E27: 來源 | F27: 標記
A28: Coherent | B28: COHR | C28: 22.3 | D28: 2026-10-23 | E28: stockanalysis forward PE（分析師共識；價格日期如左） | F28: Interested-party
A29: Fabrinet | B29: FN | C29: 17.27 | D29: 2026-10-23 | E29: stockanalysis forward PE（分析師共識；價格日期如左） | F29: Interested-party
A30: Applied Optoelectronics | B30: AAOI | C30: 29.34 | D30: 2026-10-23 | E30: stockanalysis forward PE（分析師共識；價格日期如左） | F30: Interested-party
A31: Ciena | B31: CIEN | C31: 30.77 | D31: 2026-10-23 | E31: stockanalysis forward PE（分析師共識；價格日期如左） | F31: Interested-party
A32: Corning | B32: GLW | C32: 32.89 | D32: 2026-10-23 | E32: stockanalysis forward PE（分析師共識；價格日期如左） | F32: Interested-party
A33: 同業前瞻 P/E 中位數 | B33: =MEDIAN(C28:C32) -> 29.34 | E33: 美股光通訊同業（不放 A 股）
A34: 12 個月後的前瞻 EPS（情境加權） | B34: =tp_wA*(8/12*B9+4/12*B10)+tp_wB*(8/12*C9+4/12*C10)+tp_wC*(8/12*D9+4/12*D10) -> 29.301861 | E34: 約 2027-10 時的未來 12 月（2027-11～2028-10）≈ 8／12 × FY2028＋4／12 × FY2029（會計年度 6 月底結束）
A35: Comparable 目標價 | B35: =B33*B34 -> 859.71661 | E35: 同業中位數 × 前瞻 EPS
A37: 0.3 結論
A38: 項目 | B38: 數值 | E38: 說明
A39: 目標價（DCF 與 Comparable 加權） | B39: =tp_w_dcf*B24+(1-tp_w_dcf)*B35 -> 623.39989 | E39: tp_w_dcf × DCF＋（1 − tp_w_dcf）× Comparable；tp_w_dcf 見 In 頁
A40: Comparable 目標價（市場主流同業法） | B40: =B35 -> 859.71661
A41: 市場共識目標價 | B41: =cons_tp -> 1165.03 | E41: stockanalysis：27 位分析師平均 1,165.03（2026-10-23）
A42: 上檔空間：加權目標價 | B42: =B39/px-1 -> -0.17558236 | E42: 現價＝In 頁 px
A43: 上檔空間：Comparable 目標價 | B43: =B40/px-1 -> 0.13693562
...

Sheet Recon
A1: Recon — 本模型 vs 公司指引、共識、券商與研調。只作事後對照，不為對上數字而調參數。共識區間寬（FY2027 EPS 19.05–25.27），FY2028 共識只有單一來源、5 家
A3: 項目 | B3: 對照值 | C3: 模型 A | D3: 差距 A | E3: 模型 B | F3: 差距 B | G3: 模型 C | H3: 差距 C | I3: 對照來源 | J3: 說明
A4: A. 共識與券商（校準未使用）
A5: FY2027 營收 vs 共識 | B5: =cons_rev27 -> 6.3 | C5: =PL!E93 -> 6.6131693 | D5: =C5/B5-1 -> 0.049709412 | E5: =PL!E145 -> 6.5334968 | F5: =E5/B5-1 -> 0.037062985 | G5: =PL!E197 -> 6.4936606 | H5: =G5/B5-1 -> 0.030739771 | I5: stockanalysis（23 家；56–72 億美元） | J5: FY2027 上半年＝指引＋季增假設
A6: FY2027 EPS vs 共識 | B6: =cons_eps27 -> 21.79 | C6: =PL!E108 -> 23.475185 | D6: =C6/B6-1 -> 0.077337535 | E6: =PL!E160 -> 23.160265 | F6: =E6/B6-1 -> 0.062885037 | G6: =PL!E212 -> 23.002805 | H6: =G6/B6-1 -> 0.055658788 | I6: stockanalysis（23 家；19.05–25.27）
A7: FY2028 EPS vs 共識（單一來源） | B7: =cons_eps28 -> 23.6 | C7: =PL!F108 -> 32.725343 | D7: =C7/B7-1 -> 0.38666707 | E7: =PL!F160 -> 28.435633 | F7: =E7/B7-1 -> 0.20489969 | G7: =PL!F212 -> 25.043697 | H7: =G7/B7-1 -> 0.061173593 | I7: tickflow（5 家；13.23–35.39） | J7: 該頁年度與季度數字不一致；可信度低
A8: FY2028 淨利 vs trefis 轉述共識 | B8: =cons_ni28 -> 2.4 | C8: =PL!F105 -> 3.3713648 | D8: =C8/B8-1 -> 0.40473534 | E8: =PL!F157 -> 2.9294389 | F8: =E8/B8-1 -> 0.22059954 | G8: =PL!F209 -> 2.5800016 | H8: =G8/B8-1 -> 0.075000685 | I8: trefis（2026-10-08） | J8: 口徑未說明
A9: B. 數量、份額與產品（機制檢查）
A10: CY2026 高速光模組數量 vs 凱基 800G＋1.6T 出貨（百萬個） | B10: =kgi_m26 -> 67.2 | C10: =PL!C65 -> 59.506524 | D10: =C10/B10-1 -> -0.11448625 | E10: =PL!C117 -> 59.506524 | F10: =E10/B10-1 -> -0.11448625 | G10: =PL!C169 -> 59.506524 | H10: =G10/B10-1 -> -0.11448625 | I10: 凱基 2026-08-18 | J10: 差距＝網通模型金額 ÷ 本模型單價 vs 券商數量；凱基 2028 年遠高於網通模型（網通模型 2028 年保守）
A11: CY2027 高速光模組數量 vs 凱基 800G＋1.6T 出貨（百萬個） | B11: =kgi_m27 -> 107.5 | C11: =PL!D65 -> 103.00137 | D11: =C11/B11-1 -> -0.041847674 | E11: =PL!D117 -> 105.16983 | F11: =E11/B11-1 -> -0.021676047 | G11: =PL!D169 -> 106.25405 | H11: =G11/B11-1 -> -0.011590233 | I11: 凱基 2026-08-18 | J11: 差距＝網通模型金額 ÷ 本模型單價 vs 券商數量；凱基 2028 年遠高於網通模型（網通模型 2028 年保守）
A12: CY2028 高速光模組數量 vs 凱基 800G＋1.6T 出貨（百萬個） | B12: =kgi_m28 -> 151.1 | C12: =PL!E65 -> 107.39167 | D12: =C12/B12-1 -> -0.28926759 | E12: =PL!E117 -> 90.686296 | F12: =E12/B12-1 -> -0.39982597 | G12: =PL!E169 -> 69.446611 | H12: =G12/B12-1 -> -0.54039304 | I12: 凱基 2026-08-18 | J12: 差距＝網通模型金額 ÷ 本模型單價 vs 券商數量；凱基 2028 年遠高於網通模型（網通模型 2028 年保守）
A13: CY2026 雷射有效份額 vs EML 前三大合計 72%（百分點） | B13: =tf_eml3 -> 0.72 | C13: =PL!C71 -> 0.43826657 | D13: =C13-B13 -> -0.28173343 | E13: =PL!C123 -> 0.43826657 | F13: =E13-B13 -> -0.28173343 | G13: =PL!C175 -> 0.43826657 | H13: =G13-B13 -> -0.28173343 | I13: TrendForce | J13: 有效份額含 CW、以金額計；EML 前三大合計的三分之一約 24%，Lumentum 為 EML 第一、200G 唯一量產
A14: CY2026 雷射晶片 ÷ 營收 | C14: =PL!C72/(c26_rev/1000) -> 0.41765404 | E14: =PL!C124/(c26_rev/1000) -> 0.41765404 | G14: =PL!C176/(c26_rev/1000) -> 0.41765404 | I14: Q 頁殘差
A15: CY2026 元件類（雷射＋電信與 DCI＋CPO＋3D 感測一半）÷ 營收 vs 元件部門 64.5%（百分點） | B15: =Q!B27 -> 0.64533439 | C15: =(PL!C72+PL!C83+PL!C81+PL!C84/2)/(c26_rev/1000) -> 0.6304343 | D15: =C15-B15 -> -0.014900098 | E15: =(PL!C124+PL!C135+PL!C133+PL!C136/2)/(c26_rev/1000) -> 0.6304343 | F15: =E15-B15 -> -0.014900098 | G15: =(PL!C176+PL!C187+PL!C185+PL!C188/2)/(c26_rev/1000) -> 0.6304343 | H15: =G15-B15 -> -0.014900098 | I15: 公司 FY2026 第四季部門 | J15: 3D 感測（元件）與工業雷射（系統）各半，Assumed
A16: CY2027 OCS 營收 vs Coherent 估 OCS 市場 40 億美元（占比） | C16: =PL!D78/4 -> 0.28571429 | E16: =PL!D130/4 -> 0.28571429 | G16: =PL!D182/4 -> 0.28571429 | I16: 凱基轉述 Coherent
A17: CY2027 AI 相關營收 ÷ AI IT 資本支出 | C17: =PL!D82/itc_27 -> 0.0045905229 | E17: =PL!D134/itc_27 -> 0.0044822303 | G17: =PL!D186/itc_27 -> 0.0044280839 | I17: markets/network | J17: 每 1 美元 AI IT 資本支出分到的 Lumentum 營收
A18: CY2028 雷射有效份額 | C18: =PL!E71 -> 0.41635324 | E18: =PL!E123 -> 0.41635324 | G18: =PL!E175 -> 0.41635324 | I18: —
A19: C. 校準
A20: FY2025 EPS（淨利 ÷ 推導股數）vs 公司揭露（股數由 EPS 推導，恆等） | B20: =a25_eps_in -> 2.06 | C20: =Q!B13 -> 2.06 | D20: =C20/B20-1 -> 0 | E20: =Q!B13 -> 2.06 | F20: =E20/B20-1 -> 0 | G20: =Q!B13 -> 2.06 | H20: =G20/B20-1 -> 0 | I20: 公司 | J20: 公司揭露稀釋股數 71.2（推導 71.1）
A21: FY2026 EPS vs 公司揭露 8.67 | B21: =a26_eps_in -> 8.67 | C21: =PL!D108 -> 8.67 | D21: =C21/B21-1 -> 0 | E21: =PL!D160 -> 8.67 | F21: =E21/B21-1 -> 0 | G21: =PL!D212 -> 8.67 | H21: =G21/B21-1 -> 0 | I21: 公司 | J21: 公司揭露稀釋股數 90.2
A22: FY2027 第一季營業外淨收入（推導，年化 US$B） | C22: =oi_oth -> 0.052215569 | E22: =oi_oth -> 0.052215569 | G22: =oi_oth -> 0.052215569 | I22: Q1 指引
A23: D. 預留
A24: R4 產業部署路徑（markets/deploy_path/，尚未建立）：上線後以 Lumentum AI 營收 ÷ 部署 GW 計算每 GW 營收 | J24: 預留列：本版無數值
A25: FY2027 第一季財報（約 2026-11-05）：公布後以實績取代 Q 頁第一季、以新指引取代第二季 | J25: 預留列：本版無數值

Sheet Sens
A1: Sens — 一次動一個輸入（情境 A；份額在每個案例內依 CY2026 錨點重算，CY2026 恆等於錨點）：對 FY2027、FY2028 的營收、AI 相關營收、毛利率與 EPS 的影響。每個案例是一個完整推導區塊（本頁下方）
A3: 案例 | B3: 設定 | C3: FY2027 營收 | D3: FY2027 AI 相關營收 | E3: FY2027 毛利率 | F3: FY2027 EPS | G3: FY2027 EPS 相對基準 | H3: FY2028 營收 | I3: FY2028 AI 相關營收 | J3: FY2028 毛利率 | K3: FY2028 EPS | L3: FY2028 EPS 相對基準
A4: 基準（情境 A） | B4: PL 區塊 A | C4: =PL!E93 -> 6.6131693 | D4: =PL!E91 -> 5.4040921 | E4: =PL!E99 -> 0.52 | F4: =PL!E108 -> 23.475185 | G4: =F4/F$4-1 -> 0 | H4: =PL!F93 -> 9.14381 | I4: =PL!F91 -> 7.8268594 | J4: =PL!F99 -> 0.51 | K4: =PL!F108 -> 32.725343 | L4: =K4/K$4-1 -> 0
A5: 雷射份額流失（低） | B5: 雷射份額相對值 CY2027 0.85、CY2028 0.80、CY2029 0.70（Broadcom、Coherent、中國 EML 追趕） | C5: =E73 -> 6.438131 | D5: =E71 -> 5.2290538 | E5: =E79 -> 0.52 | F5: =E88 -> 22.783314 | G5: =F5/F$4-1 -> -0.029472429 | H5: =F73 -> 8.697564 | I5: =F71 -> 7.3806133 | J5: =F79 -> 0.51 | K5: =F88 -> 30.974317 | L5: =K5/K$4-1 -> -0.053506719
A6: 雷射份額 高 | B6: 相對值 1.00／1.05／1.05（Greensboro 擴產） | C6: =E125 -> 6.7006885 | D6: =E123 -> 5.4916113 | E6: =E131 -> 0.52 | F6: =E140 -> 23.82112 | G6: =F6/F$4-1 -> 0.014736214 | H6: =F125 -> 9.4084101 | I6: =F123 -> 8.0914595 | J6: =F131 -> 0.51 | K6: =F140 -> 33.765552 | L6: =K6/K$4-1 -> 0.031786057
A7: 每模組雷射數 低（矽光替代） | B7: CY2027 4.5、CY2028 4.0、CY2029 3.5 顆 | C7: =E177 -> 6.3108304 | D7: =E175 -> 5.1017532 | E7: =E183 -> 0.52 | F7: =E192 -> 22.280135 | G7: =F7/F$4-1 -> -0.050906922 | H7: =F177 -> 8.4876489 | I7: =F175 -> 7.1706982 | J7: =F183 -> 0.51 | K7: =F192 -> 30.154837 | L7: =K7/K$4-1 -> -0.078547858
A8: 雷射單價 低 | B8: CY2027 $12、CY2028 $11、CY2029 $10 | C8: =E229 -> 6.2805965 | D8: =E227 -> 5.0715193 | E8: =E235 -> 0.52 | F8: =E244 -> 22.160631 | G8: =F8/F$4-1 -> -0.055997614 | H8: =F229 -> 8.3484801 | I8: =F227 -> 7.0315295 | J8: =F235 -> 0.51 | K8: =F244 -> 29.60715 | L8: =K8/K$4-1 -> -0.095283734
A9: 雷射單價 高 | B9: $17／$18／$18 | C9: =E281 -> 6.8348845 | D9: =E279 -> 5.6258074 | E9: =E287 -> 0.52 | F9: =E296 -> 24.351554 | G9: =F9/F$4-1 -> 0.037331743 | H9: =F281 -> 9.709055 | I9: =F279 -> 8.3921044 | J9: =F287 -> 0.51 | K9: =F296 -> 34.944942 | L9: =K9/K$4-1 -> 0.067825077
A10: 光模組單價 高（模組數少） | B10: CY2027 $640、CY2028 $680、CY2029 $720 | C10: =E333 -> 6.3013823 | D10: =E331 -> 5.0923051 | E10: =E339 -> 0.52 | F10: =E348 -> 22.24279 | G10: =F10/F$4-1 -> -0.052497763 | H10: =F333 -> 8.4677233 | I10: =F331 -> 7.1507727 | J10: =F339 -> 0.51 | K10: =F348 -> 30.076841 | L10: =K10/K$4-1 -> -0.080931224
A11: 光模組份額 低 | B11: 相對值 0.80／0.70／0.60 | C11: =E385 -> 6.443954 | D11: =E383 -> 5.2348768 | E11: =E391 -> 0.52 | F11: =E400 -> 22.806331 | G11: =F11/F$4-1 -> -0.028491964 | H11: =F385 -> 8.6781724 | I11: =F383 -> 7.3612218 | J11: =F391 -> 0.51 | K11: =F400 -> 30.897104 | L11: =K11/K$4-1 -> -0.055866159
A12: 光模組份額 高 | B12: 相對值 1.20／1.30／1.30 | C12: =E437 -> 6.7823846 | D12: =E435 -> 5.5733074 | E12: =E443 -> 0.52 | F12: =E452 -> 24.144039 | G12: =F12/F$4-1 -> 0.028491964 | H12: =F437 -> 9.6094476 | I12: =F435 -> 8.292497 | J12: =F443 -> 0.51 | K12: =F452 -> 34.554838 | L12: =K12/K$4-1 -> 0.055904538
A13: OCS 低 | B13: 每顆 TPU 營收相對值 1.2／1.2／1.0 | C13: =E489 -> 6.4788836 | D13: =E487 -> 5.2698064 | E13: =E495 -> 0.52 | F13: =E504 -> 22.944396 | G13: =F13/F$4-1 -> -0.022610625 | H13: =F489 -> 8.7360178 | I13: =F487 -> 7.4190672 | J13: =F495 -> 0.51 | K13: =F504 -> 31.122951 | L13: =K13/K$4-1 -> -0.048964853
A14: OCS 高 | B14: 2.0／2.4／2.4 | C14: =E541 -> 6.747455 | D14: =E539 -> 5.5383778 | E14: =E547 -> 0.52 | F14: =E556 -> 24.005973 | G14: =F14/F$4-1 -> 0.022610625 | H14: =F541 -> 9.5516022 | I14: =F539 -> 8.2346516 | J14: =F547 -> 0.51 | K14: =F556 -> 34.32869 | L14: =K14/K$4-1 -> 0.048994047
A15: CPO 份額 低 | B15: 10% | C15: =E593 -> 6.4144309 | D15: =E591 -> 5.2053537 | E15: =E599 -> 0.52 | F15: =E608 -> 22.689635 | G15: =F15/F$4-1 -> -0.033462981 | H15: =F593 -> 8.465434 | I15: =F591 -> 7.1484833 | J15: =F599 -> 0.51 | K15: =F608 -> 30.058106 | L15: =K15/K$4-1 -> -0.081503716
A16: CPO 份額 高 | B16: 35%／35%／30% | C16: =E645 -> 6.7456616 | D16: =E643 -> 5.5365844 | E16: =E651 -> 0.52 | F16: =E660 -> 23.998885 | G16: =F16/F$4-1 -> 0.022308654 | H16: =F645 -> 9.5960607 | I16: =F643 -> 8.2791101 | J16: =F651 -> 0.51 | K16: =F660 -> 34.504943 | L16: =K16/K$4-1 -> 0.054379875
A17: 毛利率 低 | B17: FY2027 49%、FY2028 46%、FY2029 42% | C17: =E697 -> 6.6131693 | D17: =E695 -> 5.4040921 | E17: =E703 -> 0.49 | F17: =E712 -> 21.851068 | G17: =F17/F$4-1 -> -0.0691844 | H17: =F697 -> 9.14381 | I17: =F695 -> 7.8268594 | J17: =F703 -> 0.46 | K17: =F712 -> 29.019712 | L17: =K17/K$4-1 -> -0.11323428
A18: 毛利率 高 | B18: 54%／54%／53% | C18: =E749 -> 6.6131693 | D18: =E747 -> 5.4040921 | E18: =E755 -> 0.54 | F18: =E764 -> 24.557929 | G18: =F18/F$4-1 -> 0.046122933 | H18: =F749 -> 9.14381 | I18: =F747 -> 7.8268594 | J18: =F755 -> 0.54 | K18: =F764 -> 34.948721 | L18: =K18/K$4-1 -> 0.067940568
A19: AI 市場 ×0.8 | B19: CY2027 起可插拔光模組市場 ×0.8 | C19: =E801 -> 6.1113812 | D19: =E799 -> 4.902304 | E19: =E807 -> 0.52 | F19: =E816 -> 21.491776 | G19: =F19/F$4-1 -> -0.084489578 | H19: =F801 -> 8.0795245 | I19: =F799 -> 6.7625739 | J19: =F807 -> 0.51 | K19: =F816 -> 28.558254 | L19: =K19/K$4-1 -> -0.12733522
A20: AI 市場 ×1.2 | B20: ×1.2 | C20: =E853 -> 7.1149574 | D20: =E851 -> 5.9058803 | E20: =E859 -> 0.52 | F20: =E868 -> 25.458593 | G20: =F20/F$4-1 -> 0.084489578 | H20: =F853 -> 10.208096 | I20: =F851 -> 8.8911449 | J20: =F859 -> 0.51 | K20: =F868 -> 36.898418 | L20: =K20/K$4-1 -> 0.12751815
A21: 上半年占比 44% | B21: 日曆年上半年占 44%（會計年度換算） | C21: =E905 -> 6.360201 | D21: =E903 -> 5.1885189 | E21: =E911 -> 0.52 | F21: =E920 -> 22.475282 | G21: =F21/F$4-1 -> -0.042594034 | H21: =F905 -> 9.0983929 | I21: =F903 -> 7.7859391 | J21: =F911 -> 0.51 | K21: =F920 -> 32.565991 | L21: =K21/K$4-1 -> -0.0048693573
A22: 營業費用率 +2pt | B22: 營業費用額外 +2% × 營收 | C22: =E957 -> 6.6131693 | D22: =E955 -> 5.4040921 | E22: =E963 -> 0.52 | F22: =E972 -> 22.392441 | G22: =F22/F$4-1 -> -0.046122933 | H22: =F957 -> 9.14381 | I22: =F955 -> 7.8268594 | J22: =F963 -> 0.51 | K22: =F972 -> 31.243091 | L22: =K22/K$4-1 -> -0.045293712
A23: 顆數情境 B | B23: CY2028 ×0.8、CY2029 ×0.85；CPO 情境 B | C23: =PL!E145 -> 6.5334968 | D23: =PL!E143 -> 5.3244196 | E23: =PL!E151 -> 0.52 | F23: =PL!E160 -> 23.160265 | G23: =F23/F$4-1 -> -0.013415014 | H23: =PL!F145 -> 8.0582066 | I23: =PL!F143 -> 6.741256 | J23: =PL!F151 -> 0.51 | K23: =PL!F160 -> 28.435633 | L23: =K23/K$4-1 -> -0.1310822
A24: 顆數情境 C | B24: CY2028–29 ×0.6；CPO 情境 C | C24: =PL!E197 -> 6.4936606 | D24: =PL!E195 -> 5.2845834 | E24: =PL!E203 -> 0.52 | F24: =PL!E212 -> 23.002805 | G24: =F24/F$4-1 -> -0.020122522 | H24: =PL!F197 -> 7.2000012 | I24: =PL!F195 -> 5.8830505 | J24: =PL!F203 -> 0.51 | K24: =PL!F212 -> 25.043697 | L24: =K24/K$4-1 -> -0.2347308
A26: 讀法：FY2027 有一半來自 CY2026 下半年（指引＋假設），所以 FY2027 對各輸入的敏感度約只有 FY2028 的一半；顆數情境 B、C 的差異從 FY2028 起。雷射份額、單價、每模組雷射數三者相乘，是雷射晶片營收的三條路徑。
A28: 目標價參數（只改 DCF 參數與權重；PL 收斂法的 fade_g 不隨 tp_g 變動）
A29: 案例 | B29: 設定 | C29: DCF 目標價 | D29: Comparable 目標價 | E29: 加權目標價 | F29: 相對基準
A30: 基準 | B30: r 10%、g 4%、DCF 權重 0.5 | C30: =(tp_wA*(Val!B8*(1-IF(tp_roe<=tp_g,0.8,MIN(tp_g/tp_roe,0.8)))/(1+tp_r)^1+Val!B9*(1-IF(tp_roe<=tp_g,0.8,MIN(tp_g/tp_roe,0.8)))/(1+tp_r)^2+Val!B10*(1-IF(tp_roe<=tp_g,0.8,MIN(tp_g/tp_roe,0.8)))/(1+tp_r)^3+Val!B11*(1-IF(tp_roe<=tp_g,0.8,MIN(tp_g/tp_roe,0.8)))/(1+tp_r)^4+Val!B12*(1-IF(tp_roe<=tp_g,0.8,MIN(tp_g/tp_roe,0.8)))/(1+tp_r)^5+Val!B13*(1-IF(tp_roe<=tp_g,0.8,MIN(tp_g/tp_roe,0.8)))/(1+tp_r)^6+Val!B13*(1-IF(tp_roe<=tp_g,0.8,MIN(tp_g/tp_roe,0.8)))*(1+tp_g)/(tp_r-tp_g)/(1+tp_r)^6)+tp_wB*(Val!C8*(1-IF(tp_roe<=tp_g,0.8,MIN(tp_g/tp_roe,0.8)))/(1+tp_r)^1+Val!C9*(1-IF(tp_roe<=tp_g,0.8,MIN(tp_g/tp_roe,0.8)))/(1+tp_r)^2+Val!C10*(1-IF(tp_roe<=tp_g,0.8,MIN(tp_g/tp_roe,0.8)))/(1+tp_r)^3+Val!C11*(1-IF(tp_roe<=tp_g,0.8,MIN(tp_g/tp_roe,0.8)))/(1+tp_r)^4+Val!C12*(1-IF(tp_roe<=tp_g,0.8,MIN(tp_g/tp_roe,0.8)))/(1+tp_r)^5+Val!C13*(1-IF(tp_roe<=tp_g,0.8,MIN(tp_g/tp_roe,0.8)))/(1+tp_r)^6+Val!C13*(1-IF(tp_roe<=tp_g,0.8,MIN(tp_g/tp_roe,0.8)))*(1+tp_g)/(tp_r-tp_g)/(1+tp_r)^6)+tp_wC*(Val!D8*(1-IF(tp_roe<=tp_g,0.8,MIN(tp_g/tp_roe,0.8)))/(1+tp_r)^1+Val!D9*(1-IF(tp_roe<=tp_g,0.8,MIN(tp_g/tp_roe,0.8)))/(1+tp_r)^2+Val!D10*(1-IF(tp_roe<=tp_g,0.8,MIN(tp_g/tp_roe,0.8)))/(1+tp_r)^3+Val!D11*(1-IF(tp_roe<=tp_g,0.8,MIN(tp_g/tp_roe,0.8)))/(1+tp_r)^4+Val!D12*(1-IF(tp_roe<=tp_g,0.8,MIN(tp_g/tp_roe,0.8)))/(1+tp_r)^5+Val!D13*(1-IF(tp_roe<=tp_g,0.8,MIN(tp_g/tp_roe,0.8)))/(1+tp_r)^6+Val!D13*(1-IF(tp_roe<=tp_g,0.8,MIN(tp_g/tp_roe,0.8)))*(1+tp_g)/(tp_r-tp_g)/(1+tp_r)^6))*(1+tp_r) -> 387.08317 | D30: =Val!B35 -> 859.71661 | E30: =tp_w_dcf*C30+(1-tp_w_dcf)*D30 -> 623.39989 | F30: =E30/E$30-1 -> 0
A31: 折現率 +1pt | B31: r 11% | C31: =(tp_wA*(Val!B8*(1-IF(tp_roe<=tp_g,0.8,MIN(tp_g/tp_roe,0.8)))/(1+(tp_r+0.01))^1+Val!B9*(1-IF(tp_roe<=tp_g,0.8,MIN(tp_g/tp_roe,0.8)))/(1+(tp_r+0.01))^2+Val!B10*(1-IF(tp_roe<=tp_g,0.8,MIN(tp_g/tp_roe,0.8)))/(1+(tp_r+0.01))^3+Val!B11*(1-IF(tp_roe<=tp_g,0.8,MIN(tp_g/tp_roe,0.8)))/(1+(tp_r+0.01))^4+Val!B12*(1-IF(tp_roe<=tp_g,0.8,MIN(tp_g/tp_roe,0.8)))/(1+(tp_r+0.01))^5+Val!B13*(1-IF(tp_roe<=tp_g,0.8,MIN(tp_g/tp_roe,0.8)))/(1+(tp_r+0.01))^6+Val!B13*(1-IF(tp_roe<=tp_g,0.8,MIN(tp_g/tp_roe,0.8)))*(1+tp_g)/((tp_r+0.01)-tp_g)/(1+(tp_r+0.01))^6)+tp_wB*(Val!C8*(1-IF(tp_roe<=tp_g,0.8,MIN(tp_g/tp_roe,0.8)))/(1+(tp_r+0.01))^1+Val!C9*(1-IF(tp_roe<=tp_g,0.8,MIN(tp_g/tp_roe,0.8)))/(1+(tp_r+0.01))^2+Val!C10*(1-IF(tp_roe<=tp_g,0.8,MIN(tp_g/tp_roe,0.8)))/(1+(tp_r+0.01))^3+Val!C11*(1-IF(tp_roe<=tp_g,0.8,MIN(tp_g/tp_roe,0.8)))/(1+(tp_r+0.01))^4+Val!C12*(1-IF(tp_roe<=tp_g,0.8,MIN(tp_g/tp_roe,0.8)))/(1+(tp_r+0.01))^5+Val!C13*(1-IF(tp_roe<=tp_g,0.8,MIN(tp_g/tp_roe,0.8)))/(1+(tp_r+0.01))^6+Val!C13*(1-IF(tp_roe<=tp_g,0.8,MIN(tp_g/tp_roe,0.8)))*(1+tp_g)/((tp_r+0.01)-tp_g)/(1+(tp_r+0.01))^6)+tp_wC*(Val!D8*(1-IF(tp_roe<=tp_g,0.8,MIN(tp_g/tp_roe,0.8)))/(1+(tp_r+0.01))^1+Val!D9*(1-IF(tp_roe<=tp_g,0.8,MIN(tp_g/tp_roe,0.8)))/(1+(tp_r+0.01))^2+Val!D10*(1-IF(tp_roe<=tp_g,0.8,MIN(tp_g/tp_roe,0.8)))/(1+(tp_r+0.01))^3+Val!D11*(1-IF(tp_roe<=tp_g,0.8,MIN(tp_g/tp_roe,0.8)))/(1+(tp_r+0.01))^4+Val!D12*(1-IF(tp_roe<=tp_g,0.8,MIN(tp_g/tp_roe,0.8)))/(1+(tp_r+0.01))^5+Val!D13*(1-IF(tp_roe<=tp_g,0.8,MIN(tp_g/tp_roe,0.8)))/(1+(tp_r+0.01))^6+Val!D13*(1-IF(tp_roe<=tp_g,0.8,MIN(tp_g/tp_roe,0.8)))*(1+tp_g)/((tp_r+0.01)-tp_g)/(1+(tp_r+0.01))^6))*(1+(tp_r+0.01)) -> 334.85216 | D31: =Val!B35 -> 859.71661 | E31: =tp_w_dcf*C31+(1-tp_w_dcf)*D31 -> 597.28438 | F31: =E31/E$30-1 -> -0.041892058
A32: 折現率 −1pt | B32: r 9% | C32: =(tp_wA*(Val!B8*(1-IF(tp_roe<=tp_g,0.8,MIN(tp_g/tp_roe,0.8)))/(1+(tp_r-0.01))^1+Val!B9*(1-IF(tp_roe<=tp_g,0.8,MIN(tp_g/tp_roe,0.8)))/(1+(tp_r-0.01))^2+Val!B10*(1-IF(tp_roe<=tp_g,0.8,MIN(tp_g/tp_roe,0.8)))/(1+(tp_r-0.01))^3+Val!B11*(1-IF(tp_roe<=tp_g,0.8,MIN(tp_g/tp_roe,0.8)))/(1+(tp_r-0.01))^4+Val!B12*(1-IF(tp_roe<=tp_g,0.8,MIN(tp_g/tp_roe,0.8)))/(1+(tp_r-0.01))^5+Val!B13*(1-IF(tp_roe<=tp_g,0.8,MIN(tp_g/tp_roe,0.8)))/(1+(tp_r-0.01))^6+Val!B13*(1-IF(tp_roe<=tp_g,0.8,MIN(tp_g/tp_roe,0.8)))*(1+tp_g)/((tp_r-0.01)-tp_g)/(1+(tp_r-0.01))^6)+tp_wB*(Val!C8*(1-IF(tp_roe<=tp_g,0.8,MIN(tp_g/tp_roe,0.8)))/(1+(tp_r-0.01))^1+Val!C9*(1-IF(tp_roe<=tp_g,0.8,MIN(tp_g/tp_roe,0.8)))/(1+(tp_r-0.01))^2+Val!C10*(1-IF(tp_roe<=tp_g,0.8,MIN(tp_g/tp_roe,0.8)))/(1+(tp_r-0.01))^3+Val!C11*(1-IF(tp_roe<=tp_g,0.8,MIN(tp_g/tp_roe,0.8)))/(1+(tp_r-0.01))^4+Val!C12*(1-IF(tp_roe<=tp_g,0.8,MIN(tp_g/tp_roe,0.8)))/(1+(tp_r-0.01))^5+Val!C13*(1-IF(tp_roe<=tp_g,0.8,MIN(tp_g/tp_roe,0.8)))/(1+(tp_r-0.01))^6+Val!C13*(1-IF(tp_roe<=tp_g,0.8,MIN(tp_g/tp_roe,0.8)))*(1+tp_g)/((tp_r-0.01)-tp_g)/(1+(tp_r-0.01))^6)+tp_wC*(Val!D8*(1-IF(tp_roe<=tp_g,0.8,MIN(tp_g/tp_roe,0.8)))/(1+(tp_r-0.01))^1+Val!D9*(1-IF(tp_roe<=tp_g,0.8,MIN(tp_g/tp_roe,0.8)))/(1+(tp_r-0.01))^2+Val!D10*(1-IF(tp_roe<=tp_g,0.8,MIN(tp_g/tp_roe,0.8)))/(1+(tp_r-0.01))^3+Val!D11*(1-IF(tp_roe<=tp_g,0.8,MIN(tp_g/tp_roe,0.8)))/(1+(tp_r-0.01))^4+Val!D12*(1-IF(tp_roe<=tp_g,0.8,MIN(tp_g/tp_roe,0.8)))/(1+(tp_r-0.01))^5+Val!D13*(1-IF(tp_roe<=tp_g,0.8,MIN(tp_g/tp_roe,0.8)))/(1+(tp_r-0.01))^6+Val!D13*(1-IF(tp_roe<=tp_g,0.8,MIN(tp_g/tp_roe,0.8)))*(1+tp_g)/((tp_r-0.01)-tp_g)/(1+(tp_r-0.01))^6))*(1+(tp_r-0.01)) -> 460.18299 | D32: =Val!B35 -> 859.71661 | E32: =tp_w_dcf*C32+(1-tp_w_dcf)*D32 -> 659.9498 | F32: =E32/E$30-1 -> 0.058629965
A33: 長期成長 +1pt | B33: g 5% | C33: =(tp_wA*(Val!B8*(1-IF(tp_roe<=(tp_g+0.01),0.8,MIN((tp_g+0.01)/tp_roe,0.8)))/(1+tp_r)^1+Val!B9*(1-IF(tp_roe<=(tp_g+0.01),0.8,MIN((tp_g+0.01)/tp_roe,0.8)))/(1+tp_r)^2+Val!B10*(1-IF(tp_roe<=(tp_g+0.01),0.8,MIN((tp_g+0.01)/tp_roe,0.8)))/(1+tp_r)^3+Val!B11*(1-IF(tp_roe<=(tp_g+0.01),0.8,MIN((tp_g+0.01)/tp_roe,0.8)))/(1+tp_r)^4+Val!B12*(1-IF(tp_roe<=(tp_g+0.01),0.8,MIN((tp_g+0.01)/tp_roe,0.8)))/(1+tp_r)^5+Val!B13*(1-IF(tp_roe<=(tp_g+0.01),0.8,MIN((tp_g+0.01)/tp_roe,0.8)))/(1+tp_r)^6+Val!B13*(1-IF(tp_roe<=(tp_g+0.01),0.8,MIN((tp_g+0.01)/tp_roe,0.8)))*(1+(tp_g+0.01))/(tp_r-(tp_g+0.01))/(1+tp_r)^6)+tp_wB*(Val!C8*(1-IF(tp_roe<=(tp_g+0.01),0.8,MIN((tp_g+0.01)/tp_roe,0.8)))/(1+tp_r)^1+Val!C9*(1-IF(tp_roe<=(tp_g+0.01),0.8,MIN((tp_g+0.01)/tp_roe,0.8)))/(1+tp_r)^2+Val!C10*(1-IF(tp_roe<=(tp_g+0.01),0.8,MIN((tp_g+0.01)/tp_roe,0.8)))/(1+tp_r)^3+Val!C11*(1-IF(tp_roe<=(tp_g+0.01),0.8,MIN((tp_g+0.01)/tp_roe,0.8)))/(1+tp_r)^4+Val!C12*(1-IF(tp_roe<=(tp_g+0.01),0.8,MIN((tp_g+0.01)/tp_roe,0.8)))/(1+tp_r)^5+Val!C13*(1-IF(tp_roe<=(tp_g+0.01),0.8,MIN((tp_g+0.01)/tp_roe,0.8)))/(1+tp_r)^6+Val!C13*(1-IF(tp_roe<=(tp_g+0.01),0.8,MIN((tp_g+0.01)/tp_roe,0.8)))*(1+(tp_g+0.01))/(tp_r-(tp_g+0.01))/(1+tp_r)^6)+tp_wC*(Val!D8*(1-IF(tp_roe<=(tp_g+0.01),0.8,MIN((tp_g+0.01)/tp_roe,0.8)))/(1+tp_r)^1+Val!D9*(1-IF(tp_roe<=(tp_g+0.01),0.8,MIN((tp_g+0.01)/tp_roe,0.8)))/(1+tp_r)^2+Val!D10*(1-IF(tp_roe<=(tp_g+0.01),0.8,MIN((tp_g+0.01)/tp_roe,0.8)))/(1+tp_r)^3+Val!D11*(1-IF(tp_roe<=(tp_g+0.01),0.8,MIN((tp_g+0.01)/tp_roe,0.8)))/(1+tp_r)^4+Val!D12*(1-IF(tp_roe<=(tp_g+0.01),0.8,MIN((tp_g+0.01)/tp_roe,0.8)))/(1+tp_r)^5+Val!D13*(1-IF(tp_roe<=(tp_g+0.01),0.8,MIN((tp_g+0.01)/tp_roe,0.8)))/(1+tp_r)^6+Val!D13*(1-IF(tp_roe<=(tp_g+0.01),0.8,MIN((tp_g+0.01)/tp_roe,0.8)))*(1+(tp_g+0.01))/(tp_r-(tp_g+0.01))/(1+tp_r)^6))*(1+tp_r) -> 417.59887 | D33: =Val!B35 -> 859.71661 | E33: =tp_w_dcf*C33+(1-tp_w_dcf)*D33 -> 638.65774 | F33: =E33/E$30-1 -> 0.024475225
A34: 長期成長 −1pt | B34: g 3% | C34: =(tp_wA*(Val!B8*(1-IF(tp_roe<=(tp_g-0.01),0.8,MIN((tp_g-0.01)/tp_roe,0.8)))/(1+tp_r)^1+Val!B9*(1-IF(tp_roe<=(tp_g-0.01),0.8,MIN((tp_g-0.01)/tp_roe,0.8)))/(1+tp_r)^2+Val!B10*(1-IF(tp_roe<=(tp_g-0.01),0.8,MIN((tp_g-0.01)/tp_roe,0.8)))/(1+tp_r)^3+Val!B11*(1-IF(tp_roe<=(tp_g-0.01),0.8,MIN((tp_g-0.01)/tp_roe,0.8)))/(1+tp_r)^4+Val!B12*(1-IF(tp_roe<=(tp_g-0.01),0.8,MIN((tp_g-0.01)/tp_roe,0.8)))/(1+tp_r)^5+Val!B13*(1-IF(tp_roe<=(tp_g-0.01),0.8,MIN((tp_g-0.01)/tp_roe,0.8)))/(1+tp_r)^6+Val!B13*(1-IF(tp_roe<=(tp_g-0.01),0.8,MIN((tp_g-0.01)/tp_roe,0.8)))*(1+(tp_g-0.01))/(tp_r-(tp_g-0.01))/(1+tp_r)^6)+tp_wB*(Val!C8*(1-IF(tp_roe<=(tp_g-0.01),0.8,MIN((tp_g-0.01)/tp_roe,0.8)))/(1+tp_r)^1+Val!C9*(1-IF(tp_roe<=(tp_g-0.01),0.8,MIN((tp_g-0.01)/tp_roe,0.8)))/(1+tp_r)^2+Val!C10*(1-IF(tp_roe<=(tp_g-0.01),0.8,MIN((tp_g-0.01)/tp_roe,0.8)))/(1+tp_r)^3+Val!C11*(1-IF(tp_roe<=(tp_g-0.01),0.8,MIN((tp_g-0.01)/tp_roe,0.8)))/(1+tp_r)^4+Val!C12*(1-IF(tp_roe<=(tp_g-0.01),0.8,MIN((tp_g-0.01)/tp_roe,0.8)))/(1+tp_r)^5+Val!C13*(1-IF(tp_roe<=(tp_g-0.01),0.8,MIN((tp_g-0.01)/tp_roe,0.8)))/(1+tp_r)^6+Val!C13*(1-IF(tp_roe<=(tp_g-0.01),0.8,MIN((tp_g-0.01)/tp_roe,0.8)))*(1+(tp_g-0.01))/(tp_r-(tp_g-0.01))/(1+tp_r)^6)+tp_wC*(Val!D8*(1-IF(tp_roe<=(tp_g-0.01),0.8,MIN((tp_g-0.01)/tp_roe,0.8)))/(1+tp_r)^1+Val!D9*(1-IF(tp_roe<=(tp_g-0.01),0.8,MIN((tp_g-0.01)/tp_roe,0.8)))/(1+tp_r)^2+Val!D10*(1-IF(tp_roe<=(tp_g-0.01),0.8,MIN((tp_g-0.01)/tp_roe,0.8)))/(1+tp_r)^3+Val!D11*(1-IF(tp_roe<=(tp_g-0.01),0.8,MIN((tp_g-0.01)/tp_roe,0.8)))/(1+tp_r)^4+Val!D12*(1-IF(tp_roe<=(tp_g-0.01),0.8,MIN((tp_g-0.01)/tp_roe,0.8)))/(1+tp_r)^5+Val!D13*(1-IF(tp_roe<=(tp_g-0.01),0.8,MIN((tp_g-0.01)/tp_roe,0.8)))/(1+tp_r)^6+Val!D13*(1-IF(tp_roe<=(tp_g-0.01),0.8,MIN((tp_g-0.01)/tp_roe,0.8)))*(1+(tp_g-0.01))/(tp_r-(tp_g-0.01))/(1+tp_r)^6))*(1+tp_r) -> 366.98811 | D34: =Val!B35 -> 859.71661 | E34: =tp_w_dcf*C34+(1-tp_w_dcf)*D34 -> 613.35236 | F34: =E34/E$30-1 -> -0.016117309
A35: DCF 權重 0.3 | B35: Comparable 0.7 | C35: =(tp_wA*(Val!B8*(1-IF(tp_roe<=tp_g,0.8,MIN(tp_g/tp_roe,0.8)))/(1+tp_r)^1+Val!B9*(1-IF(tp_roe<=tp_g,0.8,MIN(tp_g/tp_roe,0.8)))/(1+tp_r)^2+Val!B10*(1-IF(tp_roe<=tp_g,0.8,MIN(tp_g/tp_roe,0.8)))/(1+tp_r)^3+Val!B11*(1-IF(tp_roe<=tp_g,0.8,MIN(tp_g/tp_roe,0.8)))/(1+tp_r)^4+Val!B12*(1-IF(tp_roe<=tp_g,0.8,MIN(tp_g/tp_roe,0.8)))/(1+tp_r)^5+Val!B13*(1-IF(tp_roe<=tp_g,0.8,MIN(tp_g/tp_roe,0.8)))/(1+tp_r)^6+Val!B13*(1-IF(tp_roe<=tp_g,0.8,MIN(tp_g/tp_roe,0.8)))*(1+tp_g)/(tp_r-tp_g)/(1+tp_r)^6)+tp_wB*(Val!C8*(1-IF(tp_roe<=tp_g,0.8,MIN(tp_g/tp_roe,0.8)))/(1+tp_r)^1+Val!C9*(1-IF(tp_roe<=tp_g,0.8,MIN(tp_g/tp_roe,0.8)))/(1+tp_r)^2+Val!C10*(1-IF(tp_roe<=tp_g,0.8,MIN(tp_g/tp_roe,0.8)))/(1+tp_r)^3+Val!C11*(1-IF(tp_roe<=tp_g,0.8,MIN(tp_g/tp_roe,0.8)))/(1+tp_r)^4+Val!C12*(1-IF(tp_roe<=tp_g,0.8,MIN(tp_g/tp_roe,0.8)))/(1+tp_r)^5+Val!C13*(1-IF(tp_roe<=tp_g,0.8,MIN(tp_g/tp_roe,0.8)))/(1+tp_r)^6+Val!C13*(1-IF(tp_roe<=tp_g,0.8,MIN(tp_g/tp_roe,0.8)))*(1+tp_g)/(tp_r-tp_g)/(1+tp_r)^6)+tp_wC*(Val!D8*(1-IF(tp_roe<=tp_g,0.8,MIN(tp_g/tp_roe,0.8)))/(1+tp_r)^1+Val!D9*(1-IF(tp_roe<=tp_g,0.8,MIN(tp_g/tp_roe,0.8)))/(1+tp_r)^2+Val!D10*(1-IF(tp_roe<=tp_g,0.8,MIN(tp_g/tp_roe,0.8)))/(1+tp_r)^3+Val!D11*(1-IF(tp_roe<=tp_g,0.8,MIN(tp_g/tp_roe,0.8)))/(1+tp_r)^4+Val!D12*(1-IF(tp_roe<=tp_g,0.8,MIN(tp_g/tp_roe,0.8)))/(1+tp_r)^5+Val!D13*(1-IF(tp_roe<=tp_g,0.8,MIN(tp_g/tp_roe,0.8)))/(1+tp_r)^6+Val!D13*(1-IF(tp_roe<=tp_g,0.8,MIN(tp_g/tp_roe,0.8)))*(1+tp_g)/(tp_r-tp_g)/(1+tp_r)^6))*(1+tp_r) -> 387.08317 | D35: =Val!B35 -> 859.71661 | E35: =0.3*C35+(1-0.3)*D35 -> 717.92657 | F35: =E35/E$30-1 -> 0.1516309
A36: DCF 權重 0.7 | B36: Comparable 0.3 | C36: =(tp_wA*(Val!B8*(1-IF(tp_roe<=tp_g,0.8,MIN(tp_g/tp_roe,0.8)))/(1+tp_r)^1+Val!B9*(1-IF(tp_roe<=tp_g,0.8,MIN(tp_g/tp_roe,0.8)))/(1+tp_r)^2+Val!B10*(1-IF(tp_roe<=tp_g,0.8,MIN(tp_g/tp_roe,0.8)))/(1+tp_r)^3+Val!B11*(1-IF(tp_roe<=tp_g,0.8,MIN(tp_g/tp_roe,0.8)))/(1+tp_r)^4+Val!B12*(1-IF(tp_roe<=tp_g,0.8,MIN(tp_g/tp_roe,0.8)))/(1+tp_r)^5+Val!B13*(1-IF(tp_roe<=tp_g,0.8,MIN(tp_g/tp_roe,0.8)))/(1+tp_r)^6+Val!B13*(1-IF(tp_roe<=tp_g,0.8,MIN(tp_g/tp_roe,0.8)))*(1+tp_g)/(tp_r-tp_g)/(1+tp_r)^6)+tp_wB*(Val!C8*(1-IF(tp_roe<=tp_g,0.8,MIN(tp_g/tp_roe,0.8)))/(1+tp_r)^1+Val!C9*(1-IF(tp_roe<=tp_g,0.8,MIN(tp_g/tp_roe,0.8)))/(1+tp_r)^2+Val!C10*(1-IF(tp_roe<=tp_g,0.8,MIN(tp_g/tp_roe,0.8)))/(1+tp_r)^3+Val!C11*(1-IF(tp_roe<=tp_g,0.8,MIN(tp_g/tp_roe,0.8)))/(1+tp_r)^4+Val!C12*(1-IF(tp_roe<=tp_g,0.8,MIN(tp_g/tp_roe,0.8)))/(1+tp_r)^5+Val!C13*(1-IF(tp_roe<=tp_g,0.8,MIN(tp_g/tp_roe,0.8)))/(1+tp_r)^6+Val!C13*(1-IF(tp_roe<=tp_g,0.8,MIN(tp_g/tp_roe,0.8)))*(1+tp_g)/(tp_r-tp_g)/(1+tp_r)^6)+tp_wC*(Val!D8*(1-IF(tp_roe<=tp_g,0.8,MIN(tp_g/tp_roe,0.8)))/(1+tp_r)^1+Val!D9*(1-IF(tp_roe<=tp_g,0.8,MIN(tp_g/tp_roe,0.8)))/(1+tp_r)^2+Val!D10*(1-IF(tp_roe<=tp_g,0.8,MIN(tp_g/tp_roe,0.8)))/(1+tp_r)^3+Val!D11*(1-IF(tp_roe<=tp_g,0.8,MIN(tp_g/tp_roe,0.8)))/(1+tp_r)^4+Val!D12*(1-IF(tp_roe<=tp_g,0.8,MIN(tp_g/tp_roe,0.8)))/(1+tp_r)^5+Val!D13*(1-IF(tp_roe<=tp_g,0.8,MIN(tp_g/tp_roe,0.8)))/(1+tp_r)^6+Val!D13*(1-IF(tp_roe<=tp_g,0.8,MIN(tp_g/tp_roe,0.8)))*(1+tp_g)/(tp_r-tp_g)/(1+tp_r)^6))*(1+tp_r) -> 387.08317 | D36: =Val!B35 -> 859.71661 | E36: =0.7*C36+(1-0.7)*D36 -> 528.8732 | F36: =E36/E$30-1 -> -0.1516309
A40: 案例區塊：雷射份額流失（低）（情境 A）
A41: A. 日曆年產品營收（C 欄＝CY2026 錨點；D–F＝CY2027–CY2029）
A42: 項目 | B42: 單位 | C42: CY2026（錨點） | D42: CY2027 | E42: CY2028 | F42: CY2029 | H42: 說明
A43: AI 可插拔光模組市場 × 情境顆數係數 | B43: US$B | C43: =mpl_26*1 -> 29.753262 | D43: =mpl_27*1*1 -> 53.560715 | E43: =mpl_28*um28_A*1 -> 57.9915 | F43: =mpl_29*um29_A*1 -> 72.9348
A44: 光模組平均單價 | B44: $/個 | C44: =asp_26 -> 500 | D44: =asp_27 -> 520 | E44: =asp_28 -> 540 | F44: =asp_29 -> 560
A45: 高速光模組數量 ＝ 市場 ÷ 單價 | B45: 百萬個 | C45: =C43*1000/C44 -> 59.506524 | D45: =D43*1000/D44 -> 103.00137 | E45: =E43*1000/E44 -> 107.39167 | F45: =F43*1000/F44 -> 130.24071
A46: 每模組雷射數（EML／CW） | B46: 顆 | C46: =lpm_26 -> 5.5 | D46: =lpm_27 -> 5.5 | E46: =lpm_28 -> 5 | F46: =lpm_29 -> 4.8
...

Sheet Sources
A1: 來源（公司原文＝SEC 8-K 新聞稿、10-K、法說簡報；法說內容經第三方轉述者待人工複核）
A2: 公司：FY2026 第四季與全年新聞稿（SEC 8-K EX-99.1） | B2: https://www.sec.gov/Archives/edgar/data/0001633978/000162828026055726/lite_ex991xq4fy26.htm
A3: 公司：FY2026 第四季法說簡報 | B3: https://s21.q4cdn.com/377324469/files/doc_financials/2026/q4/Q4-FY26-Earnings-Presentation_final.pdf
A4: 公司：FY2026 10-K（部門定義、客戶集中度、股數） | B4: https://www.sec.gov/Archives/edgar/data/0001633978/000162828026057358/lite-20260627.htm
A5: 公司：歷年新聞稿（FY2016–FY2024 non-GAAP EPS；SEC 8-K） | B5: https://www.sec.gov/Archives/edgar/data/1633978/000162828024037191/lite_ex991xq4fy24.htm；…/000162828022022980/lite_ex991xq4fy22.htm；…/000162828021017219/lite_ex991xq4fy21.htm；…/000163397819000068/lite_ex991xq4fy19.htm；…/000163397818000056/lite_ex991xq4fy18.htm；…/000163397817000058/lite_ex991xq4fy17.htm
A6: 二手：法說重點（MarketBeat、Zacks、Crux Capital、PhotonCap、vocus） | B6: https://www.marketbeat.com/instant-alerts/lumentum-q4-earnings-call-highlights-2026-08-11/；https://www.zacks.com/stock/news/2973530/lumentum-q4-earnings-call-focuses-on-ai-optics-ocs-npo-ramps；https://cruxcapitalgroup.substack.com/p/lite-earnings-breakdown；https://photoncap.net/p/the-8-companies-behind-lumentums
A7: 券商：凱基 2026-08-18 光通訊產業報告（OCS、超高功率雷射、800G／1.6T 出貨、歷史 P/E） | B7: https://www.kgi.com.hk/en/-/media/files/kgishk/research-reports/us-daily/optical-networking-industry_20260818_tc.pdf
A8: 研調：TrendForce 2026-06-03（EML、CW 產能與份額） | B8: https://www.trendforce.com/presscenter/news/20260603-13077.html
A9: 券商：愛建證券 10-12 通信行業報告（光模組成本結構） | B9: https://pdf.dfcfw.com/pdf/H3_AP202610121830372080_1.pdf
A10: 共識：stockanalysis（2026-10-21）、tickflow（2026-10-24）、trefis（2026-10-08） | B10: https://stockanalysis.com/stocks/lite/forecast/；https://www.tickflow.io/stock/LITE/forecast；https://www.trefis.com/stock/lite/articles/617928/what-is-the-true-hidden-price-of-lumentum-stock/2026-10-08
A11: 價格：vcpscanner（10-23）、investsmart（年內高低點）、digrin（年底股價） | B11: https://www.vcpscanner.com/valuation/lite/estimates；https://www.investsmart.com.au/security/nasdaq/lite/lumentum-holdings/share-price；https://www.digrin.com/stocks/detail/LITE/price
A12: 資料商：companiesmarketcap GAAP 年底 P/E | B12: https://companiesmarketcap.com/lumentum/pe-ratio/
A13: 市場層：markets/network、tsmc 成品（本 repo，唯讀）
A14: 待補（人工）：FY2027 第一季財報（約 11-05）；產品別營收（雷射、光模組、OCS）；Lumentum 個別 EML／CW 份額；雷射單價；FY2028 共識第二來源；52 週高點；FY2018 non-GAAP EPS 複核 | B14: 未找到
A15: SemiAnalysis | B15: 未使用
