Workbook

Sheet README
A1: SpaceX（Nasdaq: SPCX，含 xAI）個股模型 v0.1（2026-10-30；2026Q3）— 命題模組＋官方營收分部 → 損益表
A3: 命題：SI 分部的算力投入（9M26 SI 資本支出約 400 億美元、名目算力 1.7 GW）能否由 SI 營收（對外算力出租＋Grok／Cursor／X）回本；Connectivity（Starlink）現金流與 IPO 資金能支撐多久；加計 AI 折舊與 Cursor 收購獎酬後的每股價值是否高於現價。
A4: 核心問題：FY2028 SI 每 GW 年營收 ÷ Tokenomics 每 GW 年持有成本（與 OpenAI PxQ 頁同口徑）；收支關卡＝FY2026–FY2030 自由現金流合計（扣融資租賃、失敗售後租回本金與以融資取得 PP&E）。
A5: ="投資建議："&Val!B14&"（加權目標價 US$"&TEXT(Val!B8,"0.00")&"，上檔空間 "&TEXT(Val!B11,"+0.0%;-0.0%")&"；現價 "&TEXT(px,"0.00")&"，2026-10-29 收盤）" -> 投資建議：強力放空（加權目標價 US$27.52，上檔空間 -80.9%；現價 143.89，2026-10-29 收盤）
A6: ="重點觀察 1：目標價 "&TEXT(Val!B8,"0.0")&"＝DCF "&TEXT(Val!B6,"0.0")&"、分部加總 "&TEXT(Val!B7,"0.0")&" 各半；情境 A／B／C 為 "&TEXT(Val!B17,"0.0")&"／"&TEXT(Val!C17,"0.0")&"／"&TEXT(Val!D17,"0.0")&"；市場共識目標價 "&TEXT(cons_tp,"0")&"，現價隱含 NTM EV/EBITDA "&TEXT(Val!B149,"0")&" 倍。" -> 重點觀察 1：目標價 27.5＝DCF 20.7、分部加總 34.4 各半；情境 A／B／C 為 39.1／26.7／17.6；市場共識目標價 245，現價隱含 NTM EV/EBITDA 26 倍。
A7: ="重點觀察 2：S2 核心問題比值（FY2028 SI 每 GW 年營收 ÷ Tokenomics 持有成本）A／B／C＝"&TEXT(Val!B24,"0.00")&"／"&TEXT(Val!C24,"0.00")&"／"&TEXT(Val!D24,"0.00")&"（2026Q3 校準 "&TEXT(k0,"0.00")&"）；SI 名目算力 FY2028 年底 "&TEXT(Thesis!I25,"0.0")&" GW，FY2027 SI 投資 "&TEXT(Thesis!H43,"0")&"。" -> 重點觀察 2：S2 核心問題比值（FY2028 SI 每 GW 年營收 ÷ Tokenomics 持有成本）A／B／C＝1.73／1.56／1.43（2026Q3 校準 1.87）；SI 名目算力 FY2028 年底 5.4 GW，FY2027 SI 投資 75。
A8: ="重點觀察 3：收支關卡（FY2026–2030 自由現金流，收支關卡口徑）B "&TEXT(CF!C6,"0.0")&"（公司口徑 "&TEXT(CF!C7,"0.0")&"），"&CF!C10&"；情境 B 合併營業利益率 FY2028 "&TEXT(PL!I120,"0.0%")&"（新增 AI 折舊 "&TEXT(PL!I106,"0.0")&"）。" -> 重點觀察 3：收支關卡（FY2026–2030 自由現金流，收支關卡口徑）B -96.9（公司口徑 -53.7），需要舉債；情境 B 合併營業利益率 FY2028 20.0%（新增 AI 折舊 18.5）。
A10: 驅動 → 推導對照表（每頁輸入、推導量、因果方向）
A11: 頁 | B11: 輸入（In 頁鍵） | C11: 推導量 | D11: 因果方向
A12: Thesis | B12: gw_0、si_cx_rr → pace、ext_sh、mix0_*、selfb、Tokenomics IF_HoldEcon／OpexGW／CapexIT／Facility | C12: SI 名目算力、對外／自用 GW、SI 投資、AI 折舊、自用增量成本、影子效益 | D12: SI 投資 ÷ 每 GW 投資 → GW；GW → 投資 → 折舊 → SI 營業利益
A13: Seg | B13: k30_A／B／C、conv_k、g27_nr、gl_nr、gl_ads、nl_*、g_rpl、gl_ld、nadd_A／B／C、g_arpu、gl_eg | C13: 三分部、六條子列、兩條 SI 命題子列、合併營收；非 AI 資本支出 | D13: 對外 GW × k × 持有成本；發射 × 每次收入；訂戶 × ARPU
A14: PL | B14: m_spl、m_cn、m_so、sbc_*、sbc_cur_left、da_*、tax | C14: 分部調整後 EBITDA、分部營業利益、合併營業利益、淨利、EPS | D14: 分部營收 → EBITDA − 折舊 − 股權報酬 → 營業利益 → EPS
A15: CF | B15: wc_k、cx_cn、cx_spl、fin_sh、mat_*、lease_*、spec_*、min_cash | C15: 公司口徑 FCF、收支關卡口徑 FCF、新債、淨現金 | D15: 淨利＋折舊＋SBC − 資本支出 → FCF → 舉債
A16: Val | B16: rf、beta、erp、kd、g_tv、ronic、同業倍數、evs_space、tp_w*、w_dcf | C16: DCF、分部加總、目標價、上檔空間、投資建議 | D16: 無槓桿 FCF 折現＋分部 EBITDA × 倍數 → 情境加權 → 50／50
A17: Sens | B17: In 頁敏感度低／高值 | C17: 加權目標價變動 | D17: 一次改一個輸入、整本重算
A19: 本版要點（v0.1：首版）
A20: 官方分部 Space、Connectivity、SI；子列＝10-Q 附註 3 收入拆分；SI S&I 之下以 Customer B 衍生 72% 拆「對外雲端服務」與「Grok／Cursor／X」命題子列（審查第 4 條）。
A21: SI 名目算力以實際值為錨（2025Q2 0.4 → 2026Q3 1.7 GW，IT 口徑），未來路徑由 SI 投資季速（含以融資取得 PP&E）÷ Tokenomics 每 GW 投資推算（審查第 3 條）。
A22: 收支關卡口徑扣融資租賃本金、Valor 失敗售後租回本金與以融資取得 PP&E，並列公司口徑 FCF（審查第 2 條）。
A23: 歷史欄：Q 頁 2025Q2–2026Q3 與 9M；FY2025* 為二手轉述 S-1（Space 資本支出未取得）。Cursor 2026-08-14 併入，預測以備考全季為起點（審查第 8 條）。
A24: Tesla 合併評估（董事會特別委員會）不建模，列事件風險；EchoStar 頻譜按成本（價值中性），交割發行股數列 Sens。
A26: 工作表：README → In → Q → Thesis → Seg → PL → CF → Val → Recon → Sens → Sources。藍字＝輸入、黑字＝公式；黃底＝判斷題。建置：bash spacex/make_v01.sh
A27: 數字標記：Verified（經查核）／Interested-party（公司或賣方自述）／Analogy／Assumed（給區間）／Derived（換算）／二手轉述 S-1。本模型是研究整理，不構成投資建議。

Sheet In
A1: In — 輸入（藍字；基準欄 E 進主模型；D／F＝敏感度低／高，只用於 Sens 頁、不進目標價；情境 A／B／C 的驅動見本頁最後一節「情境驅動對照」）。金額 US$B；每股 US$；股數十億股；GW＝IT 口徑名目算力（不乘 PUE）。標記：Verified／Interested-party／Analogy／Assumed／Derived（Analogy、Assumed 一律給低／高區間）
A2: 事實來源：spacex/data/spacex_facts_2026q3.json（10-Q 2026Q3 與 Q3／Q2 財報新聞稿兩讀核對；FY2025 為媒體轉述 S-1，標「二手轉述 S-1」）；Tokenomics v21.7 快照 spacex/data/tokenomics_snapshot_v21.7.json。黃底＝判斷題（Andy 可改；報告「待 Project 判斷」逐條列出預設）
A3: 鍵 | B3: 項目 | C3: 單位 | D3: 敏感度低 | E3: 基準 | F3: 敏感度高 | G3: 標記 | H3: 來源 | I3: 說明
A4: A. 現價、股數與資產負債（評價日 2026-09-30；10-Q 2026Q3）
A5: px | B5: 現價（2026-10-29 收盤） | C5: US$ | E5: 143.89 | G5: Verified | H5: MarketBeat SPCX 預測頁 https://www.marketbeat.com/stocks/NASDAQ/SPCX/forecast/（4:00 PM 收盤 143.89）；Equibles https://equibles.com/stocks/spcx/summary（10-29 收盤 143.89、跌 1.34；2026-10-30 讀取） | I5: 兩來源一致（審查第 7 條）；Digrin 月線 10 月 143.89 亦同。A 段候選 Robinhood 140.40 為盤中價，不採
A6: px_val | B6: 評價日股價（2026-09-30 收盤；WACC 權益權重用） | C6: US$ | E6: 150.86 | G6: Derived | H6: Digrin SPCX 月線 https://www.digrin.com/stocks/detail/SPCX/price（2026 年 9 月收盤 150.86；2026-10-30 讀取） | I6: 單一來源（第二來源未取得：StockAnalysis 歷史頁逾時）；只影響 WACC 權重，負債占比 < 2%，對目標價影響極小
A7: sh_out | B7: 流通股數（10-Q 封面 2026-10-15，A＋B 股） | C7: 十億股 | E7: 13.581064 | G7: Verified | H7: mag/extract/docs/2026Q3/spacex_2026Q3_10-Q.pdf 第 2 頁 10-Q 封面（2026-10-22；事實總帳 sh.out.AB.20261015；Derived） | I7: A 8,246.5M＋B 5,334.5M（審查第 6 條；稀釋項列 Sens，不進基準）
A8: sh_dil_9m | B8: 9M26 稀釋加權股數 | C8: 十億股 | E8: 7.274 | G8: Verified | H8: mag/extract/docs/2026Q3/spacex_2026Q3_10-Q.pdf 第 6 頁 合併損益表（2026-10-22；事實總帳 is.shDil.9m2026；Verified） | I8: IPO 在 2026-06，加權股數低於期末
A9: dil_perf | B9: 潛在稀釋：績效／市場條件獎酬（未計入稀釋股數） | C9: 十億股 | E9: 1.333 | G9: Verified | H9: mag/extract/docs/2026Q3/spacex_2026Q3_10-Q.pdf 第 31 頁 附註 13（2026-10-22；事實總帳 sh.perfAwards.20260930；Verified） | I9: 受獎人未見原文；Sens 用
A10: dil_opt | B10: 潛在稀釋：選擇權 | C10: 十億股 | E10: 0.508 | G10: Verified | H10: mag/extract/docs/2026Q3/spacex_2026Q3_10-Q.pdf 第 30 頁 附註 12 保留股數表（2026-10-22；事實總帳 sh.options.20260930；Verified） | I10: Sens 用
A11: dil_rsu | B11: 潛在稀釋：RSU | C11: 十億股 | E11: 0.142 | G11: Verified | H11: mag/extract/docs/2026Q3/spacex_2026Q3_10-Q.pdf 第 30 頁 附註 12（2026-10-22；事實總帳 sh.rsu.20260930；Verified） | I11: Sens 用
A12: dil_echo | B12: 潛在稀釋：EchoStar 頻譜交割發行 A 股（約） | C12: 十億股 | E12: 0.2618 | G12: Verified | H12: mag/extract/docs/2026Q3/spacex_2026Q3_10-Q.pdf 第 58 頁 MD&A Material Cash Commitments — Spectrum Transaction（2026-10-22；事實總帳 spectrum.echostar.shares；Verified） | I12: 固定每股 42.40；預計 2027-11-30 交割；Sens 用
A13: dil_x | B13: 評價股數加入上述潛在稀釋（1＝是；Sens 用） | C13: x | E13: 0 | F13: 1 | G13: Assumed | H13: 審查第 6 條：稀釋項列 Sens，不進基準 | I13: 高＝四項全部加入（約 2.24B 股，＋16.5%）
A14: cash_0 | B14: 現金＋有價證券（2026-09-30） | C14: US$B | E14: 89.855 | G14: Verified | H14: 10-Q 資產負債表：現金 51.294＋有價證券 38.561（事實總帳 bs.cash.20260930、bs.mktSec.20260930） | I14: 6-30 為 100.009
A15: cash_ye25 | B15: 現金＋有價證券（2025-12-31） | C15: US$B | E15: 24.747 | G15: Verified | H15: 10-Q 資產負債表比較欄（事實總帳 bs.cash.20251231、bs.mktSec.20251231）
A16: debt_0 | B16: 債務本金（2026-09-30；含失敗售後租回 12.897） | C16: US$B | E16: 38.006 | G16: Verified | H16: mag/extract/docs/2026Q3/spacex_2026Q3_10-Q.pdf 第 20 頁 附註 9 Debt 表（2026-10-22；事實總帳 debt.totalDebt.principal.20260930；Verified） | I16: SpaceX Notes 25.000＋其他融資 12.979（其中 Valor 失敗售後租回 12.897）＋X 票據 0.027
A17: debt_ye25 | B17: 債務本金（2025-12-31） | C17: US$B | E17: 22.049 | G17: Verified | H17: mag/extract/docs/2026Q3/spacex_2026Q3_10-Q.pdf 第 20 頁 附註 9 Debt 表（2025-12-31）（2026-10-22；事實總帳 debt.totalDebt.principal.20251231；Verified）
A18: slb_0 | B18: 其中：Valor 失敗售後租回債務（2026-09-30） | C18: US$B | E18: 12.897 | G18: Verified | H18: 10-Q 附註 9、附註 17：直接寫明為 Valor Transactions（失敗售後租回；審查第 1 條），流動 2.181＋非流動 10.716 | I18: 關係人（董事 Antonio Gracias）；利息 2026Q3 0.351
A19: fin_lease | B19: 融資租賃負債（2026-09-30） | C19: US$B | E19: 0.983 | G19: Verified | H19: mag/extract/docs/2026Q3/spacex_2026Q3_10-Q.pdf 第 20 頁 附註 9 Debt 表（2026-10-22；事實總帳 debt.finLease.principal.20260930；Verified） | I19: 計入 WACC 負債與淨負債
A20: btc | B20: 數位資產（比特幣 18,712 枚，2026-09-30 帳面） | C20: US$B | E20: 1.573 | G20: Verified | H20: mag/extract/docs/2026Q3/spacex_2026Q3_10-Q.pdf 第 5 頁 合併資產負債表（2026-10-22；事實總帳 bs.digital.20260930；Verified） | I20: 評價時加入（類現金持有）
A21: legal | B21: 訴訟準備（類債） | C21: US$B | E21: 0.35 | G21: Verified | H21: mag/extract/docs/2026Q3/spacex_2026Q3_10-Q.pdf 第 35 頁 10-Q 附註（2026-10-22；事實總帳 legal.accrual；Verified）
A22: B. 折現率與目標價規則
A23: rf | B23: 無風險利率（10 年美債，2026-10-27） | C23: % | E23: 0.0499 | G23: Verified | H23: 美國財政部每日殖利率曲線 10 Yr https://home.treasury.gov/resource-center/data-chart-center/interest-rates/TextView?type=daily_treasury_yield_curve&field_tdr_date_value_month=202610（Alphabet v0.3.2 同值，2026-10-29 讀取）
A24: beta | B24: β（2026-06 上市，歷史不足；判斷） | C24: x | D24: 1.1 | E24: 1.3 | F24: 1.6 | G24: Assumed | H24: 判斷：上市僅約 4 個月，無 3–5 年月資料 β；以高成長、高資本支出的大型科技股區間 1.1–1.6 取 1.3（Alphabet Blume 調整後 1.19 為下緣對照） | I24: Sens：1.1／1.6
A25: erp | B25: 股權風險溢酬 | C25: % | D25: 0.04 | E25: 0.05 | F25: 0.06 | G25: Assumed | H25: 同 Alphabet v0.3.2（S9）
A26: kd | B26: 稅前債務成本（SpaceX Notes 有效利率） | C26: % | E26: 0.06072 | G26: Verified | H26: mag/extract/docs/2026Q3/spacex_2026Q3_10-Q.pdf 第 21 頁 附註 9（2026-10-22；事實總帳 debt.spacexNotes.eir；Verified） | I26: 五批加權票面 5.855%；有效 6.072%
A27: tax_w | B27: WACC 用稅率（美國聯邦法定） | C27: % | E27: 0.21 | G27: Assumed | H27: 淨營業虧損抵減期間實際稅盾低於法定；負債占比 < 2%，影響極小
A28: wacc_adj | B28: WACC 調整（Sens 格：±1pt） | C28: % | D28: -0.01 | E28: 0 | F28: 0.01 | G28: Assumed | H28: Sens 用
A29: g_tv | B29: 永續成長率（FY2032 後） | C29: % | D29: 0.02 | E29: 0.03 | F29: 0.04 | G29: Assumed | H29: 同 Alphabet v0.3.2（S9）
A30: ronic_sp | B30: 永續期新投資報酬率 RONIC 相對 WACC 的差 | C30: % | E30: 0 | F30: 0.05 | G30: Assumed | H30: 同 Alphabet v0.3.2：RONIC＝WACC；終值＝NOPAT(FY2033) ×(1 − g ÷ RONIC) ÷ (WACC − g) | I30: Sens：WACC＋5pt
A31: mid | B31: 期中慣例：年度現金流距年初 | C31: 年 | E31: 0.5 | G31: Derived | H31: 年度現金流平均發生在年中
A32: t_val | B32: 評價日（2026-09-30）的年份小數 | C32: 年 | E32: 2026.75 | G32: Derived | H32: 年度折現年數＝年度＋mid − t_val
A33: t_q4 | B33: Q4 26 現金流折現年數（期中） | C33: 年 | E33: 0.125 | G33: Derived | H33: 2026-10-01～12-31 的中點
A34: tp_wA | B34: 情境權重 A | C34: % | E34: 0.25 | G34: Assumed | H34: 工作單 S9（同 Alphabet：A 25%／B 50%／C 25%）
A35: tp_wB | B35: 情境權重 B | C35: % | E35: 0.5 | G35: Assumed | H35: 同上
A36: tp_wC | B36: 情境權重 C | C36: % | E36: 0.25 | G36: Assumed | H36: 同上
A37: w_dcf | B37: 目標價中 DCF 的權重（其餘＝分部加總 SOTP） | C37: % | D37: 0.3 | E37: 0.5 | F37: 0.7 | G37: Assumed | H37: 工作單 S9（DCF 50%＋分部加總 50%）
A38: t_tgt | B38: 目標時點距評價日（2026-09-30 → 2027-10-30） | C38: 年 | E38: 1.0822 | G38: Derived | H38: 395 天 ÷ 365（工作單 S9：目標價時點 2027-10-30）
A39: w_ntm27 | B39: 目標時點 NTM 中 FY2027 的權重 | C39: % | E39: 0.1699 | G39: Derived | H39: (2027-12-31 − 2027-10-30) ÷ 365＝62 天；FY2028 權重＝1 − 本值
A40: cons_tp | B40: 市場共識目標價（平均） | C40: US$ | D40: 75 | E40: 244.97 | F40: 800 | G40: Interested-party | H40: MarketBeat 預測頁 https://www.marketbeat.com/stocks/NASDAQ/SPCX/forecast/（含 2026-10-26 Bernstein 動作，頁面約 2026-10-27～29；46 位分析師；data/consensus_spcx_20261030.json） | I40: 賣方多有承銷關係，只作對照；低／高＝最低／最高目標價（只作對照，不進模型）
...

Sheet Q
A1: Q — 實績（US$B；EPS 美元；股數十億股；GW、訂戶、次數為原單位）。資料取自 data/spacex_facts_2026q3.json（10-Q 2026Q3、Q3 新聞稿、Q2 新聞稿兩讀核對）；FY2025* 為媒體轉述 S-1（二手，待 424B4 原文；Space 資本支出未取得）
A2: 核對列（實績必須為 0）：子列合計＝分部、分部合計＝合併（營收、營業利益、分部調整後 EBITDA、資本支出）、分部調整後 EBITDA 恆等式、損益表恆等式
A3: 項目 | B3: 2025Q2 | C3: 2025Q3 | D3: 2026Q1 | E3: 2026Q2 | F3: 2026Q3 | G3: 9M25 | H3: 9M26 | I3: FY2025* | J3: 標記 | K3: 來源
A4: 營收（官方分部與子列）
A5: Launch Services | B5: 0.49 | C5: 1 | D5: 0.33 | E5: 0.648 | F5: 1.13 | G5: 2.056 | H5: 2.108 | J5: Verified／Interested-party（KPI） | K5: 10-Q 2026Q3 附註 3、18（四期）；Q3 新聞稿（2026Q2 欄）；Q2 新聞稿（2026Q1、2025Q2）；FY2025＝媒體轉述 S-1（事實總帳 seg.*／is.*）
A6: Launch & Development | B6: 0.256 | C6: 0.666 | D6: 0.289 | E6: 0.314 | F6: 0.637 | G6: 1.221 | H6: 1.24 | J6: Verified／Interested-party（KPI） | K6: 10-Q 2026Q3 附註 3、18（四期）；Q3 新聞稿（2026Q2 欄）；Q2 新聞稿（2026Q1、2025Q2）；FY2025＝媒體轉述 S-1（事實總帳 seg.*／is.*）
A7: Space（分部） | B7: 0.746 | C7: 1.666 | D7: 0.619 | E7: 0.962 | F7: 1.767 | G7: 3.277 | H7: 3.348 | I7: 4.086 | J7: Verified／Interested-party（KPI） | K7: 10-Q 2026Q3 附註 3、18（四期）；Q3 新聞稿（2026Q2 欄）；Q2 新聞稿（2026Q1、2025Q2）；FY2025＝媒體轉述 S-1（事實總帳 seg.*／is.*）
A8: 檢查：Space 子列合計 − Space | B8: =B5+B6-B7 -> 0 | C8: =C5+C6-C7 -> 0 | D8: =D5+D6-D7 -> 0 | E8: =E5+E6-E7 -> 0 | F8: =F5+F6-F7 -> 0 | G8: =G5+G6-G7 -> 0 | H8: =H5+H6-H7 -> 0 | J8: — | K8: —
A9: Consumer | B9: 1.721 | C9: 1.986 | D9: 2.148 | E9: 2.485 | F9: 3.121 | G9: 5.198 | H9: 7.754 | J9: Verified／Interested-party（KPI） | K9: 10-Q 2026Q3 附註 3、18（四期）；Q3 新聞稿（2026Q2 欄）；Q2 新聞稿（2026Q1、2025Q2）；FY2025＝媒體轉述 S-1（事實總帳 seg.*／is.*）
A10: Enterprise & Government | B10: 0.867 | C10: 1.111 | D10: 1.109 | E10: 1.806 | F10: 2.127 | G10: 2.961 | H10: 5.042 | J10: Verified／Interested-party（KPI） | K10: 10-Q 2026Q3 附註 3、18（四期）；Q3 新聞稿（2026Q2 欄）；Q2 新聞稿（2026Q1、2025Q2）；FY2025＝媒體轉述 S-1（事實總帳 seg.*／is.*）
A11: Connectivity（分部） | B11: 2.588 | C11: 3.097 | D11: 3.257 | E11: 4.291 | F11: 5.248 | G11: 8.159 | H11: 12.796 | I11: 11.387 | J11: Verified／Interested-party（KPI） | K11: 10-Q 2026Q3 附註 3、18（四期）；Q3 新聞稿（2026Q2 欄）；Q2 新聞稿（2026Q1、2025Q2）；FY2025＝媒體轉述 S-1（事實總帳 seg.*／is.*）
A12: 檢查：Connectivity 子列合計 − Connectivity | B12: =B9+B10-B11 -> 0 | C12: =C9+C10-C11 -> 0 | D12: =D9+D10-D11 -> 0 | E12: =E9+E10-E11 -> 0 | F12: =F9+F10-F11 -> 0 | G12: =G9+G10-G11 -> 0 | H12: =H9+H10-H11 -> 0 | J12: — | K12: —
A13: Advertising | B13: 0.426 | C13: 0.454 | D13: 0.343 | E13: 0.367 | F13: 0.538 | G13: 1.323 | H13: 1.248 | J13: Verified／Interested-party（KPI） | K13: 10-Q 2026Q3 附註 3、18（四期）；Q3 新聞稿（2026Q2 欄）；Q2 新聞稿（2026Q1、2025Q2）；FY2025＝媒體轉述 S-1（事實總帳 seg.*／is.*）
A14: SI Solutions & Infrastructure | B14: 0.311 | C14: 0.359 | D14: 0.475 | E14: 2.194 | F14: 7.022 | G14: 0.955 | H14: 9.691 | J14: Verified／Interested-party（KPI） | K14: 10-Q 2026Q3 附註 3、18（四期）；Q3 新聞稿（2026Q2 欄）；Q2 新聞稿（2026Q1、2025Q2）；FY2025＝媒體轉述 S-1（事實總帳 seg.*／is.*）
A15: SI（分部） | B15: 0.737 | C15: 0.813 | D15: 0.818 | E15: 2.561 | F15: 7.56 | G15: 2.278 | H15: 10.939 | I15: 3.201 | J15: Verified／Interested-party（KPI） | K15: 10-Q 2026Q3 附註 3、18（四期）；Q3 新聞稿（2026Q2 欄）；Q2 新聞稿（2026Q1、2025Q2）；FY2025＝媒體轉述 S-1（事實總帳 seg.*／is.*）
A16: 檢查：SI 子列合計 − SI | B16: =B13+B14-B15 -> 0 | C16: =C13+C14-C15 -> 0 | D16: =D13+D14-D15 -> 0 | E16: =E13+E14-E15 -> 0 | F16: =F13+F14-F15 -> 0 | G16: =G13+G14-G15 -> 0 | H16: =H13+H14-H15 -> 0 | J16: — | K16: —
A17: 合併營收 | B17: 4.071 | C17: 5.576 | D17: 4.694 | E17: 7.814 | F17: 14.575 | G17: 13.714 | H17: 27.083 | I17: 18.674 | J17: Verified／Interested-party（KPI） | K17: 10-Q 2026Q3 附註 3、18（四期）；Q3 新聞稿（2026Q2 欄）；Q2 新聞稿（2026Q1、2025Q2）；FY2025＝媒體轉述 S-1（事實總帳 seg.*／is.*）
A18: 檢查：分部合計 − 合併營收 | B18: =B7+B11+B15-B17 -> 0 | C18: =C7+C11+C15-C17 -> 0 | D18: =D7+D11+D15-D17 -> 0 | E18: =E7+E11+E15-E17 -> 0 | F18: =F7+F11+F15-F17 -> 0 | G18: =G7+G11+G15-G17 -> 0 | H18: =H7+H11+H15-H17 -> 0 | I18: =I7+I11+I15-I17 -> 0 | J18: — | K18: —
A20: 分部營業利益（損失）
A21: Space：分部營業利益 | B21: -0.369 | C21: 0.259 | D21: -0.662 | E21: -0.542 | F21: -0.007 | G21: -0.181 | H21: -1.211 | I21: -0.657 | J21: Verified／Interested-party（KPI） | K21: 10-Q 2026Q3 附註 3、18（四期）；Q3 新聞稿（2026Q2 欄）；Q2 新聞稿（2026Q1、2025Q2）；FY2025＝媒體轉述 S-1（事實總帳 seg.*／is.*）
A22: Connectivity：分部營業利益 | B22: 0.923 | C22: 1.19 | D22: 1.188 | E22: 1.656 | F22: 2.367 | G22: 3.147 | H22: 5.211 | I22: 4.423 | J22: Verified／Interested-party（KPI） | K22: 10-Q 2026Q3 附註 3、18（四期）；Q3 新聞稿（2026Q2 欄）；Q2 新聞稿（2026Q1、2025Q2）；FY2025＝媒體轉述 S-1（事實總帳 seg.*／is.*）
A23: SI（原 AI）：分部營業利益 | B23: -1.524 | C23: -1.722 | D23: -2.469 | E23: -1.257 | F23: 0.431 | G23: -4.182 | H23: -3.295 | I23: -6.355 | J23: Verified／Interested-party（KPI） | K23: 10-Q 2026Q3 附註 3、18（四期）；Q3 新聞稿（2026Q2 欄）；Q2 新聞稿（2026Q1、2025Q2）；FY2025＝媒體轉述 S-1（事實總帳 seg.*／is.*）
A24: 合計：分部營業利益 | B24: -0.97 | C24: -0.273 | D24: -1.943 | E24: -0.143 | F24: 2.791 | G24: -1.216 | H24: 0.705 | I24: -2.589 | J24: Verified／Interested-party（KPI） | K24: 10-Q 2026Q3 附註 3、18（四期）；Q3 新聞稿（2026Q2 欄）；Q2 新聞稿（2026Q1、2025Q2）；FY2025＝媒體轉述 S-1（事實總帳 seg.*／is.*）
A25: 檢查：分部合計 − 合併（分部營業利益） | B25: =B21+B22+B23-B24 -> 0 | C25: =C21+C22+C23-C24 -> 0 | D25: =D21+D22+D23-D24 -> 0 | E25: =E21+E22+E23-E24 -> 0 | F25: =F21+F22+F23-F24 -> 0 | G25: =G21+G22+G23-G24 -> 0 | H25: =H21+H22+H23-H24 -> 0 | I25: =I21+I22+I23-I24 -> 0 | J25: — | K25: —
A27: 分部調整後 EBITDA（公司定義，不含 SBC）
A28: Space：分部調整後 EBITDA | B28: -0.093 | C28: 0.674 | D28: -0.351 | E28: -0.205 | F28: 0.357 | G28: 0.803 | H28: -0.199 | I28: 0.653 | J28: Verified／Interested-party（KPI） | K28: 10-Q 2026Q3 附註 3、18（四期）；Q3 新聞稿（2026Q2 欄）；Q2 新聞稿（2026Q1、2025Q2）；FY2025＝媒體轉述 S-1（事實總帳 seg.*／is.*）
A29: Connectivity：分部調整後 EBITDA | B29: 1.583 | C29: 1.923 | D29: 2.087 | E29: 2.597 | F29: 3.499 | G29: 5.123 | H29: 8.183 | I29: 7.168 | J29: Verified／Interested-party（KPI） | K29: 10-Q 2026Q3 附註 3、18（四期）；Q3 新聞稿（2026Q2 欄）；Q2 新聞稿（2026Q1、2025Q2）；FY2025＝媒體轉述 S-1（事實總帳 seg.*／is.*）
A30: SI（原 AI）：分部調整後 EBITDA | B30: -0.276 | C30: -0.428 | D30: -0.609 | E30: 1.146 | F30: 4.953 | G30: -0.813 | H30: 5.49 | I30: -1.237 | J30: Verified／Interested-party（KPI） | K30: 10-Q 2026Q3 附註 3、18（四期）；Q3 新聞稿（2026Q2 欄）；Q2 新聞稿（2026Q1、2025Q2）；FY2025＝媒體轉述 S-1（事實總帳 seg.*／is.*）
A31: 合計：分部調整後 EBITDA | B31: 1.214 | C31: 2.169 | D31: 1.127 | E31: 3.538 | F31: 8.809 | G31: 5.113 | H31: 13.474 | I31: 6.584 | J31: Verified／Interested-party（KPI） | K31: 10-Q 2026Q3 附註 3、18（四期）；Q3 新聞稿（2026Q2 欄）；Q2 新聞稿（2026Q1、2025Q2）；FY2025＝媒體轉述 S-1（事實總帳 seg.*／is.*）
A32: 檢查：分部合計 − 合併（分部調整後 EBITDA） | B32: =B28+B29+B30-B31 -> 0 | C32: =C28+C29+C30-C31 -> 0 | D32: =D28+D29+D30-D31 -> 0 | E32: =E28+E29+E30-E31 -> 0 | F32: =F28+F29+F30-F31 -> 0 | G32: =G28+G29+G30-G31 -> 0 | H32: =H28+H29+H30-H31 -> 0 | I32: =I28+I29+I30-I31 -> 0 | J32: — | K32: —
A34: 分部資本支出（購置不動產與設備）
A35: Space：分部資本支出 | B35: 0.946 | C35: 1.113 | D35: 1.052 | E35: 1.174 | F35: 1.606 | G35: 2.818 | H35: 3.832 | J35: Verified／Interested-party（KPI） | K35: 10-Q 2026Q3 附註 3、18（四期）；Q3 新聞稿（2026Q2 欄）；Q2 新聞稿（2026Q1、2025Q2）；FY2025＝媒體轉述 S-1（事實總帳 seg.*／is.*）
A36: Connectivity：分部資本支出 | B36: 1.13 | C36: 1.007 | D36: 1.332 | E36: 1.367 | F36: 1.543 | G36: 2.951 | H36: 4.242 | I36: 4.178 | J36: Verified／Interested-party（KPI） | K36: 10-Q 2026Q3 附註 3、18（四期）；Q3 新聞稿（2026Q2 欄）；Q2 新聞稿（2026Q1、2025Q2）；FY2025＝媒體轉述 S-1（事實總帳 seg.*／is.*）
A37: SI（原 AI）：分部資本支出 | B37: 0.749 | C37: 4.76 | D37: 7.723 | E37: 15.828 | F37: 16.444 | G37: 8.077 | H37: 39.995 | I37: 12.727 | J37: Verified／Interested-party（KPI） | K37: 10-Q 2026Q3 附註 3、18（四期）；Q3 新聞稿（2026Q2 欄）；Q2 新聞稿（2026Q1、2025Q2）；FY2025＝媒體轉述 S-1（事實總帳 seg.*／is.*）
A38: 合計：分部資本支出 | B38: 2.825 | C38: 6.88 | D38: 10.107 | E38: 18.369 | F38: 19.593 | G38: 13.846 | H38: 48.069 | I38: 20.737 | J38: Verified／Interested-party（KPI） | K38: 10-Q 2026Q3 附註 3、18（四期）；Q3 新聞稿（2026Q2 欄）；Q2 新聞稿（2026Q1、2025Q2）；FY2025＝媒體轉述 S-1（事實總帳 seg.*／is.*）
A39: 檢查：分部合計 − 合併（分部資本支出） | B39: =B35+B36+B37-B38 -> 0 | C39: =C35+C36+C37-C38 -> 0 | D39: =D35+D36+D37-D38 -> 0 | E39: =E35+E36+E37-E38 -> 0 | F39: =F35+F36+F37-F38 -> 0 | G39: =G35+G36+G37-G38 -> 0 | H39: =H35+H36+H37-H38 -> 0 | J39: — | K39: —
A41: 分部調整後 EBITDA 調節項（折舊攤銷、股權報酬、收購相關、重組、減損）
A42: Space：折舊攤銷 | B42: 0.146 | C42: 0.264 | D42: 0.166 | E42: 0.158 | F42: 0.185 | G42: 0.572 | H42: 0.509 | J42: Verified／Interested-party（KPI） | K42: 10-Q 2026Q3 附註 3、18（四期）；Q3 新聞稿（2026Q2 欄）；Q2 新聞稿（2026Q1、2025Q2）；FY2025＝媒體轉述 S-1（事實總帳 seg.*／is.*）
A43: Space：股權報酬（一般） | B43: 0.125 | C43: 0.151 | D43: 0.145 | E43: 0.179 | F43: 0.179 | G43: 0.383 | H43: 0.503 | J43: Verified／Interested-party（KPI） | K43: 10-Q 2026Q3 附註 3、18（四期）；Q3 新聞稿（2026Q2 欄）；Q2 新聞稿（2026Q1、2025Q2）；FY2025＝媒體轉述 S-1（事實總帳 seg.*／is.*）
A44: Connectivity：折舊攤銷 | B44: 0.569 | C44: 0.628 | D44: 0.783 | E44: 0.805 | F44: 0.986 | G44: 1.706 | H44: 2.574 | J44: Verified／Interested-party（KPI） | K44: 10-Q 2026Q3 附註 3、18（四期）；Q3 新聞稿（2026Q2 欄）；Q2 新聞稿（2026Q1、2025Q2）；FY2025＝媒體轉述 S-1（事實總帳 seg.*／is.*）
...

Sheet Thesis
A1: Thesis — 命題模組：SI 名目算力（IT 口徑 GW；2026-09-30 1.7）由 SI 投資季速 ÷ Tokenomics 每 GW 資本支出推進；對外出租 GW（× ext_sh）× 每 GW 年營收（k × Tokenomics 持有成本，k 由 2026Q3 校準值收斂，情境軸，見 Seg 頁）→ SI 對外雲端服務子列；同一套 GW 推出 SI 投資、AI 折舊、營運成本；自用 GW → 讀法 2 影子效益
A2: 三情境共用（情境軸是 k 與 Starlink 淨增，在 Seg 頁）。名目算力為 IT 口徑，與 Tokenomics Interface 第 1 列 IT 關鍵電力同口徑，不乘 PUE（審查第 3 條）；含對外出租、推定不含第三方雲（S6）。對外出租占比以 Customer B 衍生 72% 為起點，營收與 GW 同比例（審查第 4 條）
A4: A. 校準與起始值（單一數值，C 欄）
A5: 項目 | B5: 單位 | C5: 數值 | N5: 說明
A6: 評價日機隊每 GW 年持有成本（Tokenomics IF_HoldEcon 依機隊占比加權） | B6: US$B/GW-年 | C6: =mix0_h*he_h+mix0_b2*he_b2+mix0_b3*he_b3 -> 9.7081157
A7: 評價日機隊每 GW 年營運費用（IF_OpexGW 加權，不含折舊） | B7: US$B/GW-年 | C7: =mix0_h*opx_h+mix0_b2*opx_b2+mix0_b3*opx_b3 -> 1.8850838
A8: 2026Q3 每 GW 年營收＝SI S&I × 4 ÷ 平均在役 GW | B8: US$B/GW-年 | C8: =ssi_q3*4/avg_gw_q3 -> 18.12129 | N8: 審查第 4 條：2026Q3 年化 ÷ 平均在役 GW 校準；對外出租營收與 GW 同比例，故＝對外每 GW 年營收
A9: 校準 k0＝2026Q3 每 GW 年營收 ÷ 評價日機隊持有成本 | B9: x | C9: =rev_gw0/he0 -> 1.8666125 | N9: S2 核心問題比值的起點（FY2028 比值見 Seg 頁各情境）
A10: 2026Q3 對外雲端服務營收（SI S&I × ext_sh） | B10: US$B | C10: =ext_sh*ssi_q3 -> 5.05584 | N10: Customer B 衍生 5.028（事實總帳 cust.B.rev.2026q3）
A11: 9M26 對外雲端服務營收（(Q2＋Q3 SI S&I) × ext_sh；雲端服務自 Q2 開始） | B11: US$B | C11: =ext_sh*ssi_h2 -> 6.63552 | N11: Customer B 9M 衍生 6.554
A12: 2026Q3 SI 其他收入（Grok／Cursor／X 訂閱、資料授權、API） | B12: US$B | C12: =ssi_q3-rent_q3 -> 1.96616 | N12: 含 Cursor 約 1.5 月 0.608
A13: SI 其他 EBITDA 率（2026Q3 校準：(SI 調整後 EBITDA − 對外出租 EBITDA) ÷ (SI 營收 − 對外出租)） | B13: % | C13: =(sie_q3-(rent_q3-ext_sh*avg_gw_q3*opex0/4))/(si_q3-rent_q3) -> 0.1689582 | N13: 對外出租 EBITDA＝營收 − 對外 GW × Tokenomics 營運費用；殘差含 Grok 訓練人力、評價日自用 GW 營運
A14: SI 其他 EBITDA 率（預測期採用） | B14: % | C14: =m_so0+m_so_adj -> 0.1689582
A15: 每 GW 投資（2026 新增：GB300 錨 IT＋自建 × 機房） | B15: US$B/GW | C15: =cit_b3+selfb*cfac -> 43.640224 | N15: Tokenomics IF_CapexIT｜GB300＋selfb × IF_CapexFacility
A16: 對照：PP&E（伺服器與網通＋資料中心基礎設施，2026-09-30）÷ 名目算力 | B16: US$B/GW | C16: =(43.206+6.333)/gw_0 -> 29.140588 | N16: 毛額 43.206＋6.333 ÷ 1.7；含 Hopper 舊機隊、機房可能部分租用 → 低於 Tokenomics
A18: B. SI 名目算力（GW，期末；IT 口徑）— 依 Tokenomics 世代錨分桶
A19: 項目 | B19: 單位 | C19: FY2025* | D19: 9M25A | E19: 9M26A | F19: Q4 26E | G19: FY2026E | H19: FY2027E | I19: FY2028E | J19: FY2029E | K19: FY2030E | L19: FY2031E | M19: FY2032E | N19: 說明
A20: SI 名目算力新增（FY2029 起收斂到 g × 期初 GW） | B20: GW | F20: =pace*0.25 -> 0.40675777 | G20: =F20 -> 0.40675777 | H20: =pace -> 1.6270311 | I20: =pace -> 1.6270311 | J20: =pace+(g_tv*I25-pace)*MIN(1,(2029-2028)/conv_mw) -> 1.2604794 | K20: =pace+(g_tv*J25-pace)*MIN(1,(2030-2028)/conv_mw) -> 0.91283502 | L20: =pace+(g_tv*K25-pace)*MIN(1,(2031-2028)/conv_mw) -> 0.57627579 | M20: =pace+(g_tv*L25-pace)*MIN(1,(2032-2028)/conv_mw) -> 0.2433123 | N20: Q4 26 與 FY2027–28＝pace（SI 投資季速 × 4 ÷ 每 GW 投資）；FY2029–32 線性收斂（同 Alphabet 修正一 F5）
A21: 期末 GW：Hopper 錨 | B21: GW | E21: =gw_0*mix0_h -> 0.51 | F21: =E21+F20*0 -> 0.51 | G21: =F21 -> 0.51 | H21: =F21+H20*0 -> 0.51 | I21: =H21+I20*0 -> 0.51 | J21: =I21+J20*0 -> 0.51 | K21: =J21+K20*0 -> 0.51 | L21: =K21+L20*0 -> 0.51 | M21: =L21+M20*0 -> 0.51 | N21: 評價日 1.7 GW × 機隊占比（mix0）；新增：2026 GB300 錨、2027 GB300／VR200 各半、2028 起 VR200 錨
A22: 期末 GW：GB200 錨 | B22: GW | E22: =gw_0*mix0_b2 -> 0.68 | F22: =E22+F20*0 -> 0.68 | G22: =F22 -> 0.68 | H22: =F22+H20*0 -> 0.68 | I22: =H22+I20*0 -> 0.68 | J22: =I22+J20*0 -> 0.68 | K22: =J22+K20*0 -> 0.68 | L22: =K22+L20*0 -> 0.68 | M22: =L22+M20*0 -> 0.68
A23: 期末 GW：GB300 錨 | B23: GW | E23: =gw_0*mix0_b3 -> 0.51 | F23: =E23+F20*1 -> 0.91675777 | G23: =F23 -> 0.91675777 | H23: =F23+H20*am_27 -> 1.7302733 | I23: =H23+I20*0 -> 1.7302733 | J23: =I23+J20*0 -> 1.7302733 | K23: =J23+K20*0 -> 1.7302733 | L23: =K23+L20*0 -> 1.7302733 | M23: =L23+M20*0 -> 1.7302733
A24: 期末 GW：VR200 錨 | B24: GW | E24: =gw_0*0 -> 0 | F24: =E24+F20*0 -> 0 | G24: =F24 -> 0 | H24: =F24+H20*(1-am_27) -> 0.81351553 | I24: =H24+I20*1 -> 2.4405466 | J24: =I24+J20*1 -> 3.701026 | K24: =J24+K20*1 -> 4.6138611 | L24: =K24+L20*1 -> 5.1901368 | M24: =L24+M20*1 -> 5.4334492
A25: 期末 SI 名目算力 | B25: GW | E25: =E21+E22+E23+E24 -> 1.7 | F25: =F21+F22+F23+F24 -> 2.1067578 | G25: =G21+G22+G23+G24 -> 2.1067578 | H25: =H21+H22+H23+H24 -> 3.7337888 | I25: =I21+I22+I23+I24 -> 5.3608199 | J25: =J21+J22+J23+J24 -> 6.6212993 | K25: =K21+K22+K23+K24 -> 7.5341344 | L25: =L21+L22+L23+L24 -> 8.1104101 | M25: =M21+M22+M23+M24 -> 8.3537224
A26: 平均在役 GW：Hopper 錨 | B26: GW | F26: =(E21+F21)/2 -> 0.51 | H26: =(F21+H21)/2 -> 0.51 | I26: =(H21+I21)/2 -> 0.51 | J26: =(I21+J21)/2 -> 0.51 | K26: =(J21+K21)/2 -> 0.51 | L26: =(K21+L21)/2 -> 0.51 | M26: =(L21+M21)/2 -> 0.51
A27: 平均在役 GW：GB200 錨 | B27: GW | F27: =(E22+F22)/2 -> 0.68 | H27: =(F22+H22)/2 -> 0.68 | I27: =(H22+I22)/2 -> 0.68 | J27: =(I22+J22)/2 -> 0.68 | K27: =(J22+K22)/2 -> 0.68 | L27: =(K22+L22)/2 -> 0.68 | M27: =(L22+M22)/2 -> 0.68
A28: 平均在役 GW：GB300 錨 | B28: GW | F28: =(E23+F23)/2 -> 0.71337888 | H28: =(F23+H23)/2 -> 1.3235155 | I28: =(H23+I23)/2 -> 1.7302733 | J28: =(I23+J23)/2 -> 1.7302733 | K28: =(J23+K23)/2 -> 1.7302733 | L28: =(K23+L23)/2 -> 1.7302733 | M28: =(L23+M23)/2 -> 1.7302733
A29: 平均在役 GW：VR200 錨 | B29: GW | F29: =(E24+F24)/2 -> 0 | H29: =(F24+H24)/2 -> 0.40675777 | I29: =(H24+I24)/2 -> 1.6270311 | J29: =(I24+J24)/2 -> 3.0707863 | K29: =(J24+K24)/2 -> 4.1574435 | L29: =(K24+L24)/2 -> 4.901999 | M29: =(L24+M24)/2 -> 5.311793
A30: 平均在役 GW | B30: GW | F30: =F26+F27+F28+F29 -> 1.9033789 | H30: =H26+H27+H28+H29 -> 2.9202733 | I30: =I26+I27+I28+I29 -> 4.5473044 | J30: =J26+J27+J28+J29 -> 5.9910596 | K30: =K26+K27+K28+K29 -> 7.0777168 | L30: =L26+L27+L28+L29 -> 7.8222723 | M30: =M26+M27+M28+M29 -> 8.2320663
A31: 平均在役 GW：對外出租（× ext_sh） | B31: GW | F31: =F30*ext_sh -> 1.3704328 | H31: =H30*ext_sh -> 2.1025968 | I31: =I30*ext_sh -> 3.2740591 | J31: =J30*ext_sh -> 4.3135629 | K31: =K30*ext_sh -> 5.0959561 | L31: =L30*ext_sh -> 5.632036 | M31: =M30*ext_sh -> 5.9270877
A32: 平均在役 GW：自用（×(1 − ext_sh)） | B32: GW | F32: =F30*(1-ext_sh) -> 0.53294609 | H32: =H30*(1-ext_sh) -> 0.81767652 | I32: =I30*(1-ext_sh) -> 1.2732452 | J32: =J30*(1-ext_sh) -> 1.6774967 | K32: =K30*(1-ext_sh) -> 1.9817607 | L32: =L30*(1-ext_sh) -> 2.1902362 | M32: =M30*(1-ext_sh) -> 2.3049786
A33: 在役機隊每 GW 年持有成本（IF_HoldEcon 依平均在役 GW 加權） | B33: US$B/GW-年 | F33: =(F26*he_h+F27*he_b2+F28*he_b3+F29*he_vr)/F30 -> 9.8340183 | H33: =(H26*he_h+H27*he_b2+H28*he_b3+H29*he_vr)/H30 -> 10.386996 | I33: =(I26*he_h+I27*he_b2+I28*he_b3+I29*he_vr)/I30 -> 10.925025 | J33: =(J26*he_h+J27*he_b2+J28*he_b3+J29*he_vr)/J30 -> 11.238413 | K33: =(K26*he_h+K27*he_b2+K28*he_b3+K29*he_vr)/K30 -> 11.389958 | L33: =(L26*he_h+L27*he_b2+L28*he_b3+L29*he_vr)/L30 -> 11.469486 | M33: =(M26*he_h+M27*he_b2+M28*he_b3+M29*he_vr)/M30 -> 11.507119 | N33: k × 本列＝每 GW 年營收（Seg 頁）；S2 核心問題的分母
A34: 在役機隊每 GW 年營運費用（IF_OpexGW 加權） | B34: US$B/GW-年 | F34: =(F26*opx_h+F27*opx_b2+F28*opx_b3+F29*opx_vr)/F30 -> 1.8955073 | H34: =(H26*opx_h+H27*opx_b2+H28*opx_b3+H29*opx_vr)/H30 -> 1.9412882 | I34: =(I26*opx_h+I27*opx_b2+I28*opx_b3+I29*opx_vr)/I30 -> 1.9858317 | J34: =(J26*opx_h+J27*opx_b2+J28*opx_b3+J29*opx_vr)/J30 -> 2.011777 | K34: =(K26*opx_h+K27*opx_b2+K28*opx_b3+K29*opx_vr)/K30 -> 2.0243235 | L34: =(L26*opx_h+L27*opx_b2+L28*opx_b3+L29*opx_vr)/L30 -> 2.0309075 | M34: =(M26*opx_h+M27*opx_b2+M28*opx_b3+M29*opx_vr)/M30 -> 2.0340232
A35: 對外出租營運費用（對外 GW × 營運費用；含電費） | B35: US$B | F35: =F31*F34*0.25 -> 0.64941633 | G35: =F35 -> 0.64941633 | H35: =H31*H34*1 -> 4.0817464 | I35: =I31*I34*1 -> 6.5017303 | J35: =J31*J34*1 -> 8.6779269 | K35: =K31*K34*1 -> 10.315864 | L35: =L31*L34*1 -> 11.438144 | M35: =M31*M34*1 -> 12.055834
A36: 自用增量營運費用（相對評價日自用機隊；Tokenomics IF_OpexGW） | B36: US$B | F36: =(1-ext_sh)*((F26*opx_h+F27*opx_b2+F28*opx_b3+F29*opx_vr)-($E$21*opx_h+$E$22*opx_b2+$E$23*opx_b3+$E$24*opx_vr))*0.25 -> 0.028225824 | G36: =F36 -> 0.028225824 | H36: =(1-ext_sh)*((H26*opx_h+H27*opx_b2+H28*opx_b3+H29*opx_vr)-($E$21*opx_h+$E$22*opx_b2+$E$23*opx_b3+$E$24*opx_vr))*1 -> 0.69004594 | I36: =(1-ext_sh)*((I26*opx_h+I27*opx_b2+I28*opx_b3+I29*opx_vr)-($E$21*opx_h+$E$22*opx_b2+$E$23*opx_b3+$E$24*opx_vr))*1 -> 1.6311508 | J36: =(1-ext_sh)*((J26*opx_h+J27*opx_b2+J28*opx_b3+J29*opx_vr)-($E$21*opx_h+$E$22*opx_b2+$E$23*opx_b3+$E$24*opx_vr))*1 -> 2.4774495 | K36: =(1-ext_sh)*((K26*opx_h+K27*opx_b2+K28*opx_b3+K29*opx_vr)-($E$21*opx_h+$E$22*opx_b2+$E$23*opx_b3+$E$24*opx_vr))*1 -> 3.1144248 | L36: =(1-ext_sh)*((L26*opx_h+L27*opx_b2+L28*opx_b3+L29*opx_vr)-($E$21*opx_h+$E$22*opx_b2+$E$23*opx_b3+$E$24*opx_vr))*1 -> 3.5508674 | M36: =(1-ext_sh)*((M26*opx_h+M27*opx_b2+M28*opx_b3+M29*opx_vr)-($E$21*opx_h+$E$22*opx_b2+$E$23*opx_b3+$E$24*opx_vr))*1 -> 3.79108 | N36: 評價日自用機隊的營運費用已在 2026Q3 校準的 SI 其他 EBITDA 率內
A38: C. SI 投資（新增 GW × Tokenomics 每 GW 成本；汰換只換 IT；含以其他融資取得之 PP&E）
A39: SI IT 投資（成長） | B39: US$B | F39: =F20*(1*cit_b3+0*cit_vr) -> 13.112741 | G39: =F39 -> 13.112741 | H39: =H20*(am_27*cit_b3+(1-am_27)*cit_vr) -> 56.802564 | I39: =I20*(0*cit_b3+1*cit_vr) -> 61.154162 | J39: =J20*(0*cit_b3+1*cit_vr) -> 47.376824 | K39: =K20*(0*cit_b3+1*cit_vr) -> 34.310138 | L39: =L20*(0*cit_b3+1*cit_vr) -> 21.660105 | M39: =M20*(0*cit_b3+1*cit_vr) -> 9.1452219
A40: SI 機房投資（自建比例 × IF_CapexFacility） | B40: US$B | F40: =F20*selfb*cfac -> 4.6382588 | G40: =F40 -> 4.6382588 | H40: =H20*selfb*cfac -> 18.553035 | I40: =I20*selfb*cfac -> 18.553035 | J40: =J20*selfb*cfac -> 14.373247 | K40: =K20*selfb*cfac -> 10.409058 | L40: =L20*selfb*cfac -> 6.5712728 | M40: =M20*selfb*cfac -> 2.7744902
A41: 汰換 GW（6 年前上線，換成 VR200 錨 IT） | B41: GW | F41: 0 | G41: =F41 -> 0 | H41: 0 | I41: 0 | J41: 0 | K41: =gw_ye24 -> 0.15 | L41: =gw_ye25-gw_ye24 -> 0.65 | M41: =gw_0-gw_ye25+F20 -> 1.3067578 | N41: IT 壽命 6 年：2024 年底在役 → 2030 汰換，以此類推；汰換後 GW 照常在役
A42: SI 汰換投資（只含 IT） | B42: US$B | F42: =F41*cit_vr -> 0 | G42: =F42 -> 0 | H42: =H41*cit_vr -> 0 | I42: =I41*cit_vr -> 0 | J42: =J41*cit_vr -> 0 | K42: =K41*cit_vr -> 5.6379528 | L42: =L41*cit_vr -> 24.431129 | M42: =M41*cit_vr -> 49.116257
A43: SI 投資合計（現金資本支出＋以其他融資取得） | B43: US$B | E43: =Q!H37+ppefin_9m -> 43.916 | F43: =F39+F40+F42 -> 17.751 | G43: =E43+F43 -> 61.667 | H43: =H39+H40+H42 -> 75.355599 | I43: =I39+I40+I42 -> 79.707197 | J43: =J39+J40+J42 -> 61.750071 | K43: =K39+K40+K42 -> 50.357149 | L43: =L39+L40+L42 -> 52.662506 | M43: =M39+M40+M42 -> 61.035969 | N43: 9M26＝SI 資本支出 39.995＋以其他融資取得 3.921（推定全屬 SI）
...

Sheet Seg
A1: Seg — 營收分部層：官方分部 Space（Launch Services、Launch & Development）、Connectivity（Consumer、Enterprise & Government）、SI（Advertising、SI Solutions & Infrastructure）；SI S&I 之下的命題子列＝SI 對外雲端服務＋Grok／Cursor／X 訂閱、資料授權與 API（子列合計＝SI S&I）。情境軸：SI 每 GW 年營收的 k（FY2030 到達）與 Starlink 消費訂戶淨增
A2: 成長路徑：起始年增＝9M26 對 9M25 年增（Q 頁；近四季需 2025Q4，只有二手），FY2030 收斂到長期值（conv_n）。Space＝客戶發射 × 每次收入＋發射與開發；Connectivity＝平均消費訂戶 × ARPU × 3 × 係數（含 Kits）＋企業與政府；SI 對外出租＝對外 GW × k × 持有成本（Thesis）；SI 其他以 Q4 26 備考全季（含 Cursor 全季）為基期
A4: 情境 A（算力租金維持高檔、Starlink 增長快）
A5: 項目 | B5: 單位 | C5: FY2025* | D5: 9M25A | E5: 9M26A | F5: Q4 26E | G5: FY2026E | H5: FY2027E | I5: FY2028E | J5: FY2029E | K5: FY2030E | L5: FY2031E | M5: FY2032E | N5: 說明
A6: k＝每 GW 年營收 ÷ 持有成本（Q4 26＝校準 k0，FY2030＝情境值） | B6: x | F6: =k0 -> 1.8666125 | H6: =k0+(k30_A-k0)*MIN(1,(2027-2026)/conv_k) -> 1.7999594 | I6: =k0+(k30_A-k0)*MIN(1,(2028-2026)/conv_k) -> 1.7333063 | J6: =k0+(k30_A-k0)*MIN(1,(2029-2026)/conv_k) -> 1.6666531 | K6: =k0+(k30_A-k0)*MIN(1,(2030-2026)/conv_k) -> 1.6 | L6: =k0+(k30_A-k0)*MIN(1,(2031-2026)/conv_k) -> 1.6 | M6: =k0+(k30_A-k0)*MIN(1,(2032-2026)/conv_k) -> 1.6
A7: 對外每 GW 年營收＝k × 在役機隊持有成本 | B7: US$B/GW-年 | F7: =F6*Thesis!F33 -> 18.356302 | H7: =H6*Thesis!H33 -> 18.696171 | I7: =I6*Thesis!I33 -> 18.936414 | J7: =J6*Thesis!J33 -> 18.730536 | K7: =K6*Thesis!K33 -> 18.223933 | L7: =L6*Thesis!L33 -> 18.351177 | M7: =M6*Thesis!M33 -> 18.41139
A8: SI 對外雲端服務（命題子列） | B8: US$B | E8: =Thesis!C11 -> 6.63552 | F8: =Thesis!F31*F7*0.25 -> 6.2890195 | G8: =E8+F8 -> 12.924539 | H8: =Thesis!H31*H7*1 -> 39.310508 | I8: =Thesis!I31*I7*1 -> 61.998941 | J8: =Thesis!J31*J7*1 -> 80.795347 | K8: =Thesis!K31*K7*1 -> 92.868364 | L8: =Thesis!L31*L7*1 -> 103.35449 | M8: =Thesis!M31*M7*1 -> 109.12592 | N8: 對外 GW × 每 GW 年營收；9M26＝(Q2＋Q3 SI S&I) × ext_sh（Customer B 衍生）
A9: SI 其他收入年增 | B9: % | H9: =g27_nr+(gl_nr-g27_nr)*MIN(1,(2027-2027)/(conv_n-1)) -> 0.5 | I9: =g27_nr+(gl_nr-g27_nr)*MIN(1,(2028-2027)/(conv_n-1)) -> 0.38333333 | J9: =g27_nr+(gl_nr-g27_nr)*MIN(1,(2029-2027)/(conv_n-1)) -> 0.26666667 | K9: =g27_nr+(gl_nr-g27_nr)*MIN(1,(2030-2027)/(conv_n-1)) -> 0.15 | L9: =g27_nr+(gl_nr-g27_nr)*MIN(1,(2031-2027)/(conv_n-1)) -> 0.15 | M9: =g27_nr+(gl_nr-g27_nr)*MIN(1,(2032-2027)/(conv_n-1)) -> 0.15 | N9: FY2027＝g27_nr（以 Q4 26 備考年化為基期），FY2030 收斂到 gl_nr
A10: Grok／Cursor／X 訂閱、資料授權與 API（命題子列） | B10: US$B | E10: =Q!H14-E8 -> 3.05548 | F10: =nr_q3+cur_pf -> 2.50516 | G10: =E10+F10 -> 5.56064 | H10: =F10*4*(1+H9)^0.625 -> 12.91078 | I10: =H10*(1+I9) -> 17.859913 | J10: =I10*(1+J9) -> 22.622556 | K10: =J10*(1+K9) -> 26.01594 | L10: =K10*(1+L9) -> 29.918331 | M10: =L10*(1+M9) -> 34.406081 | N10: Q4 26＝2026Q3 值＋Cursor 備考補足（審查第 8 條：以備考全季為起點）；FY2027＝Q4 26 × 4 ×(1＋年增)^0.625
A11: SI Solutions & Infrastructure | B11: US$B | D11: =Q!G14 -> 0.955 | E11: =Q!H14 -> 9.691 | F11: =F8+F10 -> 8.7941795 | G11: =E11+F11 -> 18.485179 | H11: =H8+H10 -> 52.221288 | I11: =I8+I10 -> 79.858854 | J11: =J8+J10 -> 103.4179 | K11: =K8+K10 -> 118.8843 | L11: =L8+L10 -> 133.27282 | M11: =M8+M10 -> 143.532
A12: Advertising 年增 | B12: % | F12: =g0_ads -> -0.056689342 | H12: =g0_ads+(gl_ads-g0_ads)*MIN(1,(2027-2026)/conv_n) -> -0.035017007 | I12: =g0_ads+(gl_ads-g0_ads)*MIN(1,(2028-2026)/conv_n) -> -0.013344671 | J12: =g0_ads+(gl_ads-g0_ads)*MIN(1,(2029-2026)/conv_n) -> 0.0083276644 | K12: =g0_ads+(gl_ads-g0_ads)*MIN(1,(2030-2026)/conv_n) -> 0.03 | L12: =g0_ads+(gl_ads-g0_ads)*MIN(1,(2031-2026)/conv_n) -> 0.03 | M12: =g0_ads+(gl_ads-g0_ads)*MIN(1,(2032-2026)/conv_n) -> 0.03 | N12: 起點＝9M 年增（Q 頁），FY2030 收斂到 gl_ads
A13: Advertising | B13: US$B | D13: =Q!G13 -> 1.323 | E13: =Q!H13 -> 1.248 | F13: =ads_q3*(1+F12)^0.25 -> 0.53020762 | G13: =E13+F13 -> 1.7782076 | H13: =G13*(1+H12) -> 1.7159401 | I13: =H13*(1+I12) -> 1.6930415 | J13: =I13*(1+J12) -> 1.7071405 | K13: =J13*(1+K12) -> 1.7583547 | L13: =K13*(1+L12) -> 1.8111054 | M13: =L13*(1+M12) -> 1.8654386
A14: SI (Super Intelligence; formerly AI) | B14: US$B | C14: =Q!I15 -> 3.201 | D14: =Q!G15 -> 2.278 | E14: =Q!H15 -> 10.939 | F14: =F13+F11 -> 9.3243871 | G14: =E14+F14 -> 20.263387 | H14: =H13+H11 -> 53.937229 | I14: =I13+I11 -> 81.551895 | J14: =J13+J11 -> 105.12504 | K14: =K13+K11 -> 120.64266 | L14: =L13+L11 -> 135.08393 | M14: =M13+M11 -> 145.39744
A15: 客戶發射次數 | B15: 次 | E15: =Q!H57 -> 29 | F15: =nl_q4 -> 12 | G15: =E15+F15 -> 41 | H15: =nl_27 -> 48 | I15: =H15*(1+g_nl) -> 50.4 | J15: =I15*(1+g_nl) -> 52.92 | K15: =J15*(1+g_nl) -> 55.566 | L15: =K15*(1+g_nl) -> 58.3443 | M15: =L15*(1+g_nl) -> 61.261515
A16: 每次客戶發射收入 | B16: US$B／次 | E16: =rpl0 -> 0.072689655 | F16: =rpl0 -> 0.072689655 | H16: =rpl0*(1+g_rpl)^(2027-2026) -> 0.074870345 | I16: =rpl0*(1+g_rpl)^(2028-2026) -> 0.077116455 | J16: =rpl0*(1+g_rpl)^(2029-2026) -> 0.079429949 | K16: =rpl0*(1+g_rpl)^(2030-2026) -> 0.081812847 | L16: =rpl0*(1+g_rpl)^(2031-2026) -> 0.084267233 | M16: =rpl0*(1+g_rpl)^(2032-2026) -> 0.08679525
A17: Launch Services | B17: US$B | D17: =Q!G5 -> 2.056 | E17: =Q!H5 -> 2.108 | F17: =F15*F16 -> 0.87227586 | G17: =E17+F17 -> 2.9802759 | H17: =H15*H16 -> 3.5937766 | I17: =I15*I16 -> 3.8866693 | J17: =J15*J16 -> 4.2034329 | K17: =K15*K16 -> 4.5460127 | L17: =L15*L16 -> 4.9165127 | M17: =M15*M16 -> 5.3172085
A18: Launch & Development 年增 | B18: % | F18: =g0_ld -> 0.015561016 | H18: =g0_ld+(gl_ld-g0_ld)*MIN(1,(2027-2026)/conv_n) -> 0.031670762 | I18: =g0_ld+(gl_ld-g0_ld)*MIN(1,(2028-2026)/conv_n) -> 0.047780508 | J18: =g0_ld+(gl_ld-g0_ld)*MIN(1,(2029-2026)/conv_n) -> 0.063890254 | K18: =g0_ld+(gl_ld-g0_ld)*MIN(1,(2030-2026)/conv_n) -> 0.08 | L18: =g0_ld+(gl_ld-g0_ld)*MIN(1,(2031-2026)/conv_n) -> 0.08 | M18: =g0_ld+(gl_ld-g0_ld)*MIN(1,(2032-2026)/conv_n) -> 0.08
A19: Launch & Development | B19: US$B | D19: =Q!G6 -> 1.221 | E19: =Q!H6 -> 1.24 | F19: =ld_9m/3*(1+F18)^0.25 -> 0.41493201 | G19: =E19+F19 -> 1.654932 | H19: =G19*(1+H18) -> 1.707345 | I19: =H19*(1+I18) -> 1.7889228 | J19: =I19*(1+J18) -> 1.9032175 | K19: =J19*(1+K18) -> 2.0554749 | L19: =K19*(1+L18) -> 2.2199129 | M19: =L19*(1+M18) -> 2.3975059 | N19: Q4 26＝9M26 季均 ×(1＋年增)^0.25（里程碑收入不規則）
A20: Space | B20: US$B | C20: =Q!I7 -> 4.086 | D20: =Q!G7 -> 3.277 | E20: =Q!H7 -> 3.348 | F20: =F17+F19 -> 1.2872079 | G20: =E20+F20 -> 4.6352079 | H20: =H17+H19 -> 5.3011215 | I20: =I17+I19 -> 5.6755921 | J20: =J17+J19 -> 6.1066504 | K20: =K17+K19 -> 6.6014876 | L20: =L17+L19 -> 7.1364256 | M20: =M17+M19 -> 7.7147144
A21: Starlink 消費訂戶（期末，百萬） | B21: 百萬 | E21: =subs_q3 -> 13.6 | F21: =E21+nadd_q4 -> 15.2 | H21: =F21+nadd_A -> 22.2 | I21: =H21+nadd_A*(1-nadd_dec)^(2028-2027) -> 28.5 | J21: =I21+nadd_A*(1-nadd_dec)^(2029-2027) -> 34.17 | K21: =J21+nadd_A*(1-nadd_dec)^(2030-2027) -> 39.273 | L21: =K21+nadd_A*(1-nadd_dec)^(2031-2027) -> 43.8657 | M21: =L21+nadd_A*(1-nadd_dec)^(2032-2027) -> 47.99913
A22: 平均消費訂戶 | B22: 百萬 | F22: =(E21+F21)/2 -> 14.4 | H22: =(F21+H21)/2 -> 18.7 | I22: =(H21+I21)/2 -> 25.35 | J22: =(I21+J21)/2 -> 31.335 | K22: =(J21+K21)/2 -> 36.7215 | L22: =(K21+L21)/2 -> 41.56935 | M22: =(L21+M21)/2 -> 45.932415
A23: 消費 ARPU（美元／月） | B23: US$ | F23: =arpu0*(1+g_arpu)^0.25 -> 68.652382 | H23: =arpu0*(1+g_arpu)^(2027+0.5-2026.75) -> 67.962391 | I23: =arpu0*(1+g_arpu)^(2028+0.5-2026.75) -> 66.603143 | J23: =arpu0*(1+g_arpu)^(2029+0.5-2026.75) -> 65.27108 | K23: =arpu0*(1+g_arpu)^(2030+0.5-2026.75) -> 63.965658 | L23: =arpu0*(1+g_arpu)^(2031+0.5-2026.75) -> 62.686345 | M23: =arpu0*(1+g_arpu)^(2032+0.5-2026.75) -> 61.432618
A24: Consumer | B24: US$B | D24: =Q!G9 -> 5.198 | E24: =Q!H9 -> 7.754 | F24: =F22*F23/1000*12*0.25*uplift -> 3.4934362 | G24: =E24+F24 -> 11.247436 | H24: =H22*H23/1000*12*1*uplift -> 17.964079 | I24: =I22*I23/1000*12*1*uplift -> 23.865327 | J24: =J22*J23/1000*12*1*uplift -> 28.909807 | K24: =K22*K23/1000*12*1*uplift -> 33.201827 | L24: =L22*L23/1000*12*1*uplift -> 36.833321 | M24: =M22*M23/1000*12*1*uplift -> 39.885313 | N24: 平均訂戶 × ARPU × 月數 × uplift（2026Q3 校準，含 Kits）
A25: Enterprise & Government 年增 | B25: % | F25: =g0_eg+g0_eg_adj -> 0.70280311 | H25: =g0_eg+g0_eg_adj+(gl_eg-g0_eg+g0_eg_adj)*MIN(1,(2027-2026)/conv_n) -> 0.55210233 | I25: =g0_eg+g0_eg_adj+(gl_eg-g0_eg+g0_eg_adj)*MIN(1,(2028-2026)/conv_n) -> 0.40140155 | J25: =g0_eg+g0_eg_adj+(gl_eg-g0_eg+g0_eg_adj)*MIN(1,(2029-2026)/conv_n) -> 0.25070078 | K25: =g0_eg+g0_eg_adj+(gl_eg-g0_eg+g0_eg_adj)*MIN(1,(2030-2026)/conv_n) -> 0.1 | L25: =g0_eg+g0_eg_adj+(gl_eg-g0_eg+g0_eg_adj)*MIN(1,(2031-2026)/conv_n) -> 0.1 | M25: =g0_eg+g0_eg_adj+(gl_eg-g0_eg+g0_eg_adj)*MIN(1,(2032-2026)/conv_n) -> 0.1 | N25: 起點＝9M 年增 +70%（Q 頁），FY2030 收斂到 gl_eg
A26: Enterprise & Government | B26: US$B | D26: =Q!G10 -> 2.961 | E26: =Q!H10 -> 5.042 | F26: =eg_q3*(1+F25)^0.25 -> 2.4297333 | G26: =E26+F26 -> 7.4717333 | H26: =G26*(1+H25) -> 11.596895 | I26: =H26*(1+I25) -> 16.251906 | J26: =I26*(1+J25) -> 20.326272 | K26: =J26*(1+K25) -> 22.358899 | L26: =K26*(1+L25) -> 24.594789 | M26: =L26*(1+M25) -> 27.054267
A27: Connectivity | B27: US$B | C27: =Q!I11 -> 11.387 | D27: =Q!G11 -> 8.159 | E27: =Q!H11 -> 12.796 | F27: =F24+F26 -> 5.9231694 | G27: =E27+F27 -> 18.719169 | H27: =H24+H26 -> 29.560973 | I27: =I24+I26 -> 40.117233 | J27: =J24+J26 -> 49.236079 | K27: =K24+K26 -> 55.560726 | L27: =L24+L26 -> 61.42811 | M27: =M24+M26 -> 66.939581
A28: 合併營收 | B28: US$B | C28: =Q!I17 -> 18.674 | D28: =Q!G17 -> 13.714 | E28: =Q!H17 -> 27.083 | F28: =F20+F27+F14 -> 16.534764 | G28: =E28+F28 -> 43.617764 | H28: =H20+H27+H14 -> 88.799324 | I28: =I20+I27+I14 -> 127.34472 | J28: =J20+J27+J14 -> 160.46777 | K28: =K20+K27+K14 -> 182.80487 | L28: =L20+L27+L14 -> 203.64846 | M28: =M20+M27+M14 -> 220.05174
A29: 檢查：Space 子列合計 − Space | B29: US$B | D29: =D17+D19-D20 -> 0 | E29: =E17+E19-E20 -> 0 | F29: =F17+F19-F20 -> 0 | G29: =G17+G19-G20 -> 0 | H29: =H17+H19-H20 -> 0 | I29: =I17+I19-I20 -> 0 | J29: =J17+J19-J20 -> 0 | K29: =K17+K19-K20 -> 0 | ... M29: =M17+M19-M20 -> 0
A30: 檢查：Connectivity 子列合計 − Connectivity | B30: US$B | D30: =D24+D26-D27 -> 0 | E30: =E24+E26-E27 -> 0 | F30: =F24+F26-F27 -> 0 | G30: =G24+G26-G27 -> 0 | H30: =H24+H26-H27 -> 0 | I30: =I24+I26-I27 -> 0 | J30: =J24+J26-J27 -> 0 | K30: =K24+K26-K27 -> 0 | ... M30: =M24+M26-M27 -> 0
A31: 檢查：SI 子列合計 − SI | B31: US$B | D31: =D13+D11-D14 -> 0 | E31: =E13+E11-E14 -> 0 | F31: =F13+F11-F14 -> 0 | G31: =G13+G11-G14 -> 0 | H31: =H13+H11-H14 -> 0 | I31: =I13+I11-I14 -> 0 | J31: =J13+J11-J14 -> 0 | K31: =K13+K11-K14 -> 0 | ... M31: =M13+M11-M14 -> 0
A32: 檢查：SI S&I 命題子列合計 − SI Solutions & Infrastructure | B32: US$B | E32: =E8+E10-E11 -> 0 | F32: =F8+F10-F11 -> 0 | G32: =G8+G10-G11 -> 0 | H32: =H8+H10-H11 -> 0 | I32: =I8+I10-I11 -> 0 | J32: =J8+J10-J11 -> 0 | K32: =K8+K10-K11 -> 0 | L32: =L8+L10-L11 -> 0 | M32: =M8+M10-M11 -> 0
A33: 檢查：分部合計 − 合併營收 | B33: US$B | C33: =C20+C27+C14-C28 -> 0 | D33: =D20+D27+D14-D28 -> 0 | E33: =E20+E27+E14-E28 -> 0 | F33: =F20+F27+F14-F28 -> 0 | G33: =G20+G27+G14-G28 -> 0 | H33: =H20+H27+H14-H28 -> 0 | I33: =I20+I27+I14-I28 -> 0 | J33: =J20+J27+J14-J28 -> 0 | ... M33: =M20+M27+M14-M28 -> 0
A34: 檢查：實績欄合併營收 − Q 頁 | B34: US$B | C34: =C28-Q!I17 -> 0 | D34: =D28-Q!G17 -> 0 | E34: =E28-Q!H17 -> 0
A35: S2 核心問題：SI 每 GW 年營收 ÷ Tokenomics 每 GW 年持有成本（＝k） | B35: x | F35: =F6 -> 1.8666125 | H35: =H6 -> 1.7999594 | I35: =I6 -> 1.7333063 | J35: =J6 -> 1.6666531 | K35: =K6 -> 1.6 | L35: =L6 -> 1.6 | M35: =M6 -> 1.6 | N35: 工作單 S2：與 OpenAI PxQ 頁同口徑；FY2028 欄為核心問題比值（> 1＝租金高於打平持有成本）
A36: Space 資本支出占營收 | B36: % | F36: =cx_sp0 -> 1.1445639 | H36: =cx_sp0+(cx_spl-cx_sp0)*MIN(1,(2027-2026)/conv_n) -> 0.93342294 | I36: =cx_sp0+(cx_spl-cx_sp0)*MIN(1,(2028-2026)/conv_n) -> 0.72228196 | J36: =cx_sp0+(cx_spl-cx_sp0)*MIN(1,(2029-2026)/conv_n) -> 0.51114098 | K36: =cx_sp0+(cx_spl-cx_sp0)*MIN(1,(2030-2026)/conv_n) -> 0.3 | L36: =cx_sp0+(cx_spl-cx_sp0)*MIN(1,(2031-2026)/conv_n) -> 0.3 | M36: =cx_sp0+(cx_spl-cx_sp0)*MIN(1,(2032-2026)/conv_n) -> 0.3
A37: 資本支出：Space | B37: US$B | F37: =F20*F36 -> 1.4732917 | G37: =F37 -> 1.4732917 | H37: =H20*H36 -> 4.9481884 | I37: =I20*I36 -> 4.0993778 | J37: =J20*J36 -> 3.1213593 | K37: =K20*K36 -> 1.9804463 | L37: =L20*L36 -> 2.1409277 | M37: =M20*M36 -> 2.3144143
A38: 資本支出：Connectivity（營收 × cx_cn） | B38: US$B | F38: =F27*cx_cn -> 1.963589 | G38: =F38 -> 1.963589 | H38: =H27*cx_cn -> 9.7997538 | I38: =I27*cx_cn -> 13.299258 | J38: =J27*cx_cn -> 16.322245 | K38: =K27*cx_cn -> 18.418928 | L38: =L27*cx_cn -> 20.364023 | M38: =M27*cx_cn -> 22.19113
A39: 新增折舊：Space（年限 life_sp） | B39: US$B | F39: =($F$37/life_sp*IF((0)<0,0,IF((0)=0,phi_0,IF((0)<life_sp,1,IF((0)=life_sp,1-phi_0,0)))))*0.25 -> 0.009208073 | G39: =F39 -> 0.009208073 | H39: =($F$37/life_sp*IF((1)<0,0,IF((1)=0,phi_0,IF((1)<life_sp,1,IF((1)=life_sp,1-phi_0,0))))+$H$37/life_sp*IF((0)<0,0,IF((0)=0,phi_0,IF((0)<life_sp,1,IF((0)=life_sp,1-phi_0,0))))) -> 0.27103388 | I39: =($F$37/life_sp*IF((2)<0,0,IF((2)=0,phi_0,IF((2)<life_sp,1,IF((2)=life_sp,1-phi_0,0))))+$H$37/life_sp*IF((1)<0,0,IF((1)=0,phi_0,IF((1)<life_sp,1,IF((1)=life_sp,1-phi_0,0))))+$I$37/life_sp*IF((0)<0,0,IF((0)=0,phi_0,IF((0)<life_sp,1,IF((0)=life_sp,1-phi_0,0))))) -> 0.74463246 | J39: =($F$37/life_sp*IF((3)<0,0,IF((3)=0,phi_0,IF((3)<life_sp,1,IF((3)=life_sp,1-phi_0,0))))+$H$37/life_sp*IF((2)<0,0,IF((2)=0,phi_0,IF((2)<life_sp,1,IF((2)=life_sp,1-phi_0,0))))+$I$37/life_sp*IF((1)<0,0,IF((1)=0,phi_0,IF((1)<life_sp,1,IF((1)=life_sp,1-phi_0,0))))+$J$37/life_sp*IF((0)<0,0,IF((0)=0,phi_0,IF((0)<life_sp,1,IF((0)=life_sp,1-phi_0,0))))) -> 1.1301198 | K39: =($F$37/life_sp*IF((4)<0,0,IF((4)=0,phi_0,IF((4)<life_sp,1,IF((4)=life_sp,1-phi_0,0))))+$H$37/life_sp*IF((3)<0,0,IF((3)=0,phi_0,IF((3)<life_sp,1,IF((3)=life_sp,1-phi_0,0))))+$I$37/life_sp*IF((2)<0,0,IF((2)=0,phi_0,IF((2)<life_sp,1,IF((2)=life_sp,1-phi_0,0))))+$J$37/life_sp*IF((1)<0,0,IF((1)=0,phi_0,IF((1)<life_sp,1,IF((1)=life_sp,1-phi_0,0))))+$K$37/life_sp*IF((0)<0,0,IF((0)=0,phi_0,IF((0)<life_sp,1,IF((0)=life_sp,1-phi_0,0))))) -> 1.4137329 | L39: =($F$37/life_sp*IF((5)<0,0,IF((5)=0,phi_0,IF((5)<life_sp,1,IF((5)=life_sp,1-phi_0,0))))+$H$37/life_sp*IF((4)<0,0,IF((4)=0,phi_0,IF((4)<life_sp,1,IF((4)=life_sp,1-phi_0,0))))+$I$37/life_sp*IF((3)<0,0,IF((3)=0,phi_0,IF((3)<life_sp,1,IF((3)=life_sp,1-phi_0,0))))+$J$37/life_sp*IF((2)<0,0,IF((2)=0,phi_0,IF((2)<life_sp,1,IF((2)=life_sp,1-phi_0,0))))+$K$37/life_sp*IF((1)<0,0,IF((1)=0,phi_0,IF((1)<life_sp,1,IF((1)=life_sp,1-phi_0,0))))+$L$37/life_sp*IF((0)<0,0,IF((0)=0,phi_0,IF((0)<life_sp,1,IF((0)=life_sp,1-phi_0,0))))) -> 1.6157895 | M39: =($F$37/life_sp*IF((6)<0,0,IF((6)=0,phi_0,IF((6)<life_sp,1,IF((6)=life_sp,1-phi_0,0))))+$H$37/life_sp*IF((5)<0,0,IF((5)=0,phi_0,IF((5)<life_sp,1,IF((5)=life_sp,1-phi_0,0))))+$I$37/life_sp*IF((4)<0,0,IF((4)=0,phi_0,IF((4)<life_sp,1,IF((4)=life_sp,1-phi_0,0))))+$J$37/life_sp*IF((3)<0,0,IF((3)=0,phi_0,IF((3)<life_sp,1,IF((3)=life_sp,1-phi_0,0))))+$K$37/life_sp*IF((2)<0,0,IF((2)=0,phi_0,IF((2)<life_sp,1,IF((2)=life_sp,1-phi_0,0))))+$L$37/life_sp*IF((1)<0,0,IF((1)=0,phi_0,IF((1)<life_sp,1,IF((1)=life_sp,1-phi_0,0))))+$M$37/life_sp*IF((0)<0,0,IF((0)=0,phi_0,IF((0)<life_sp,1,IF((0)=life_sp,1-phi_0,0))))) -> 1.8342195
A40: 新增折舊：Connectivity（年限 life_cn） | B40: US$B | F40: =($F$38/life_cn*IF((0)<0,0,IF((0)=0,phi_0,IF((0)<life_cn,1,IF((0)=life_cn,1-phi_0,0)))))*0.25 -> 0.020454052 | G40: =F40 -> 0.020454052 | H40: =($F$38/life_cn*IF((1)<0,0,IF((1)=0,phi_0,IF((1)<life_cn,1,IF((1)=life_cn,1-phi_0,0))))+$H$38/life_cn*IF((0)<0,0,IF((0)=0,phi_0,IF((0)<life_cn,1,IF((0)=life_cn,1-phi_0,0))))) -> 0.73558791 | I40: =($F$38/life_cn*IF((2)<0,0,IF((2)=0,phi_0,IF((2)<life_cn,1,IF((2)=life_cn,1-phi_0,0))))+$H$38/life_cn*IF((1)<0,0,IF((1)=0,phi_0,IF((1)<life_cn,1,IF((1)=life_cn,1-phi_0,0))))+$I$38/life_cn*IF((0)<0,0,IF((0)=0,phi_0,IF((0)<life_cn,1,IF((0)=life_cn,1-phi_0,0))))) -> 2.5146929 | J40: =($F$38/life_cn*IF((3)<0,0,IF((3)=0,phi_0,IF((3)<life_cn,1,IF((3)=life_cn,1-phi_0,0))))+$H$38/life_cn*IF((2)<0,0,IF((2)=0,phi_0,IF((2)<life_cn,1,IF((2)=life_cn,1-phi_0,0))))+$I$38/life_cn*IF((1)<0,0,IF((1)=0,phi_0,IF((1)<life_cn,1,IF((1)=life_cn,1-phi_0,0))))+$J$38/life_cn*IF((0)<0,0,IF((0)=0,phi_0,IF((0)<life_cn,1,IF((0)=life_cn,1-phi_0,0))))) -> 4.8571936 | K40: =($F$38/life_cn*IF((4)<0,0,IF((4)=0,phi_0,IF((4)<life_cn,1,IF((4)=life_cn,1-phi_0,0))))+$H$38/life_cn*IF((3)<0,0,IF((3)=0,phi_0,IF((3)<life_cn,1,IF((3)=life_cn,1-phi_0,0))))+$I$38/life_cn*IF((2)<0,0,IF((2)=0,phi_0,IF((2)<life_cn,1,IF((2)=life_cn,1-phi_0,0))))+$J$38/life_cn*IF((1)<0,0,IF((1)=0,phi_0,IF((1)<life_cn,1,IF((1)=life_cn,1-phi_0,0))))+$K$38/life_cn*IF((0)<0,0,IF((0)=0,phi_0,IF((0)<life_cn,1,IF((0)=life_cn,1-phi_0,0))))) -> 7.6649296 | L40: =($F$38/life_cn*IF((5)<0,0,IF((5)=0,phi_0,IF((5)<life_cn,1,IF((5)=life_cn,1-phi_0,0))))+$H$38/life_cn*IF((4)<0,0,IF((4)=0,phi_0,IF((4)<life_cn,1,IF((4)=life_cn,1-phi_0,0))))+$I$38/life_cn*IF((3)<0,0,IF((3)=0,phi_0,IF((3)<life_cn,1,IF((3)=life_cn,1-phi_0,0))))+$J$38/life_cn*IF((2)<0,0,IF((2)=0,phi_0,IF((2)<life_cn,1,IF((2)=life_cn,1-phi_0,0))))+$K$38/life_cn*IF((1)<0,0,IF((1)=0,phi_0,IF((1)<life_cn,1,IF((1)=life_cn,1-phi_0,0))))+$L$38/life_cn*IF((0)<0,0,IF((0)=0,phi_0,IF((0)<life_cn,1,IF((0)=life_cn,1-phi_0,0))))) -> 10.815797 | M40: =($F$38/life_cn*IF((6)<0,0,IF((6)=0,phi_0,IF((6)<life_cn,1,IF((6)=life_cn,1-phi_0,0))))+$H$38/life_cn*IF((5)<0,0,IF((5)=0,phi_0,IF((5)<life_cn,1,IF((5)=life_cn,1-phi_0,0))))+$I$38/life_cn*IF((4)<0,0,IF((4)=0,phi_0,IF((4)<life_cn,1,IF((4)=life_cn,1-phi_0,0))))+$J$38/life_cn*IF((3)<0,0,IF((3)=0,phi_0,IF((3)<life_cn,1,IF((3)=life_cn,1-phi_0,0))))+$K$38/life_cn*IF((2)<0,0,IF((2)=0,phi_0,IF((2)<life_cn,1,IF((2)=life_cn,1-phi_0,0))))+$L$38/life_cn*IF((1)<0,0,IF((1)=0,phi_0,IF((1)<life_cn,1,IF((1)=life_cn,1-phi_0,0))))+$M$38/life_cn*IF((0)<0,0,IF((0)=0,phi_0,IF((0)<life_cn,1,IF((0)=life_cn,1-phi_0,0))))) -> 14.204114
A42: 情境 B（租金向持有成本部分收斂；基準）
...

Sheet PL
A1: PL — 分部營收 → 分部調整後 EBITDA（公司定義，不含 SBC）− 折舊攤銷 − 股權報酬（含 Cursor 收購後服務期獎酬）→ 分部營業利益 → 合併 → 利息 → 稅 → 淨利 → EPS（三情境；US$B，EPS 美元）。實績欄 FY2025*（二手轉述 S-1，只有分部營收與營業利益）、9M25A、9M26A 取自 Q 頁；FY2026E＝9M 實績＋Q4 模型
A2: 分部調整後 EBITDA：Space＝營收 × 利益率（9M26 −5.9% → FY2030 m_spl）；Connectivity＝營收 × m_cn（9M26）；SI＝對外出租營收 − 對外 GW 營運費用（Tokenomics）＋SI 其他收入 × m_so（2026Q3 校準） − 自用增量營運費用。折舊：Space／Connectivity 基礎折舊（2026Q3 × 4，直線遞減到 0）＋新增資本支出折舊；SI＝基礎折舊（汰換遞減）＋新增 AI 折舊。三分部合計＝合併（無公司層級調節項）
A4: 分部對帳彙總（三情境 × 全部年度取絕對值最大者；實績欄同列）
A5: 項目 | B5: 單位 | C5: FY2025* | D5: 9M25A | E5: 9M26A | F5: Q4 26E | G5: FY2026E | H5: FY2027E | I5: FY2028E | J5: FY2029E | K5: FY2030E | L5: FY2031E | M5: FY2032E | N5: 說明
A6: 檢查：Space 子列合計 − Space | B6: US$B | D6: =MAX(ABS(D28),ABS(D90),ABS(D152)) -> 0 | E6: =MAX(ABS(E28),ABS(E90),ABS(E152)) -> 0 | F6: =MAX(ABS(F28),ABS(F90),ABS(F152)) -> 0 | G6: =MAX(ABS(G28),ABS(G90),ABS(G152)) -> 0 | H6: =MAX(ABS(H28),ABS(H90),ABS(H152)) -> 0 | I6: =MAX(ABS(I28),ABS(I90),ABS(I152)) -> 0 | J6: =MAX(ABS(J28),ABS(J90),ABS(J152)) -> 0 | K6: =MAX(ABS(K28),ABS(K90),ABS(K152)) -> 0 | ... M6: =MAX(ABS(M28),ABS(M90),ABS(M152)) -> 0 | N6: 三情境各區塊同名核對列的最大絕對值；必須為 0（tools/segment_check 讀本列）
A7: 檢查：Connectivity 子列合計 − Connectivity | B7: US$B | D7: =MAX(ABS(D29),ABS(D91),ABS(D153)) -> 0 | E7: =MAX(ABS(E29),ABS(E91),ABS(E153)) -> 0 | F7: =MAX(ABS(F29),ABS(F91),ABS(F153)) -> 0 | G7: =MAX(ABS(G29),ABS(G91),ABS(G153)) -> 0 | H7: =MAX(ABS(H29),ABS(H91),ABS(H153)) -> 0 | I7: =MAX(ABS(I29),ABS(I91),ABS(I153)) -> 0 | J7: =MAX(ABS(J29),ABS(J91),ABS(J153)) -> 0 | K7: =MAX(ABS(K29),ABS(K91),ABS(K153)) -> 0 | ... M7: =MAX(ABS(M29),ABS(M91),ABS(M153)) -> 0 | N7: 三情境各區塊同名核對列的最大絕對值；必須為 0（tools/segment_check 讀本列）
A8: 檢查：SI 子列合計 − SI | B8: US$B | D8: =MAX(ABS(D30),ABS(D92),ABS(D154)) -> 0 | E8: =MAX(ABS(E30),ABS(E92),ABS(E154)) -> 0 | F8: =MAX(ABS(F30),ABS(F92),ABS(F154)) -> 0 | G8: =MAX(ABS(G30),ABS(G92),ABS(G154)) -> 0 | H8: =MAX(ABS(H30),ABS(H92),ABS(H154)) -> 0 | I8: =MAX(ABS(I30),ABS(I92),ABS(I154)) -> 0 | J8: =MAX(ABS(J30),ABS(J92),ABS(J154)) -> 0 | K8: =MAX(ABS(K30),ABS(K92),ABS(K154)) -> 0 | ... M8: =MAX(ABS(M30),ABS(M92),ABS(M154)) -> 0 | N8: 三情境各區塊同名核對列的最大絕對值；必須為 0（tools/segment_check 讀本列）
A9: 檢查：SI S&I 命題子列合計 − SI Solutions & Infrastructure | B9: US$B | E9: =MAX(ABS(E31),ABS(E93),ABS(E155)) -> 0 | F9: =MAX(ABS(F31),ABS(F93),ABS(F155)) -> 0 | G9: =MAX(ABS(G31),ABS(G93),ABS(G155)) -> 0 | H9: =MAX(ABS(H31),ABS(H93),ABS(H155)) -> 0 | I9: =MAX(ABS(I31),ABS(I93),ABS(I155)) -> 0 | J9: =MAX(ABS(J31),ABS(J93),ABS(J155)) -> 0 | K9: =MAX(ABS(K31),ABS(K93),ABS(K155)) -> 0 | L9: =MAX(ABS(L31),ABS(L93),ABS(L155)) -> 0 | M9: =MAX(ABS(M31),ABS(M93),ABS(M155)) -> 0 | N9: 三情境各區塊同名核對列的最大絕對值；必須為 0（tools/segment_check 讀本列）
A10: 檢查：分部合計 − 合併營收 | B10: US$B | C10: =MAX(ABS(C32),ABS(C94),ABS(C156)) -> 0 | D10: =MAX(ABS(D32),ABS(D94),ABS(D156)) -> 0 | E10: =MAX(ABS(E32),ABS(E94),ABS(E156)) -> 0 | F10: =MAX(ABS(F32),ABS(F94),ABS(F156)) -> 0 | G10: =MAX(ABS(G32),ABS(G94),ABS(G156)) -> 0 | H10: =MAX(ABS(H32),ABS(H94),ABS(H156)) -> 0 | I10: =MAX(ABS(I32),ABS(I94),ABS(I156)) -> 0 | J10: =MAX(ABS(J32),ABS(J94),ABS(J156)) -> 0 | ... M10: =MAX(ABS(M32),ABS(M94),ABS(M156)) -> 0 | N10: 三情境各區塊同名核對列的最大絕對值；必須為 0（tools/segment_check 讀本列）
A11: 檢查：分部營業利益合計 − 合併營業利益 | B11: US$B | C11: =MAX(ABS(C55),ABS(C117),ABS(C179)) -> 0 | D11: =MAX(ABS(D55),ABS(D117),ABS(D179)) -> 0 | E11: =MAX(ABS(E55),ABS(E117),ABS(E179)) -> 0 | F11: =MAX(ABS(F55),ABS(F117),ABS(F179)) -> 0 | G11: =MAX(ABS(G55),ABS(G117),ABS(G179)) -> 0 | H11: =MAX(ABS(H55),ABS(H117),ABS(H179)) -> 0 | I11: =MAX(ABS(I55),ABS(I117),ABS(I179)) -> 0 | J11: =MAX(ABS(J55),ABS(J117),ABS(J179)) -> 0 | ... M11: =MAX(ABS(M55),ABS(M117),ABS(M179)) -> 0 | N11: 三情境各區塊同名核對列的最大絕對值；必須為 0（tools/segment_check 讀本列）
A13: 情境 A（算力租金維持高檔、Starlink 增長快）
A14: 項目 | B14: 單位 | C14: FY2025* | D14: 9M25A | E14: 9M26A | F14: Q4 26E | G14: FY2026E | H14: FY2027E | I14: FY2028E | J14: FY2029E | K14: FY2030E | L14: FY2031E | M14: FY2032E | N14: 說明
A15: Launch Services | B15: US$B | D15: =Seg!D17 -> 2.056 | E15: =Seg!E17 -> 2.108 | F15: =Seg!F17 -> 0.87227586 | G15: =Seg!G17 -> 2.9802759 | H15: =Seg!H17 -> 3.5937766 | I15: =Seg!I17 -> 3.8866693 | J15: =Seg!J17 -> 4.2034329 | K15: =Seg!K17 -> 4.5460127 | ... M15: =Seg!M17 -> 5.3172085
A16: Launch & Development | B16: US$B | D16: =Seg!D19 -> 1.221 | E16: =Seg!E19 -> 1.24 | F16: =Seg!F19 -> 0.41493201 | G16: =Seg!G19 -> 1.654932 | H16: =Seg!H19 -> 1.707345 | I16: =Seg!I19 -> 1.7889228 | J16: =Seg!J19 -> 1.9032175 | K16: =Seg!K19 -> 2.0554749 | ... M16: =Seg!M19 -> 2.3975059
A17: Space | B17: US$B | C17: =Seg!C20 -> 4.086 | D17: =Seg!D20 -> 3.277 | E17: =Seg!E20 -> 3.348 | F17: =Seg!F20 -> 1.2872079 | G17: =Seg!G20 -> 4.6352079 | H17: =Seg!H20 -> 5.3011215 | I17: =Seg!I20 -> 5.6755921 | J17: =Seg!J20 -> 6.1066504 | ... M17: =Seg!M20 -> 7.7147144
A18: Consumer | B18: US$B | D18: =Seg!D24 -> 5.198 | E18: =Seg!E24 -> 7.754 | F18: =Seg!F24 -> 3.4934362 | G18: =Seg!G24 -> 11.247436 | H18: =Seg!H24 -> 17.964079 | I18: =Seg!I24 -> 23.865327 | J18: =Seg!J24 -> 28.909807 | K18: =Seg!K24 -> 33.201827 | ... M18: =Seg!M24 -> 39.885313
A19: Enterprise & Government | B19: US$B | D19: =Seg!D26 -> 2.961 | E19: =Seg!E26 -> 5.042 | F19: =Seg!F26 -> 2.4297333 | G19: =Seg!G26 -> 7.4717333 | H19: =Seg!H26 -> 11.596895 | I19: =Seg!I26 -> 16.251906 | J19: =Seg!J26 -> 20.326272 | K19: =Seg!K26 -> 22.358899 | ... M19: =Seg!M26 -> 27.054267
A20: Connectivity | B20: US$B | C20: =Seg!C27 -> 11.387 | D20: =Seg!D27 -> 8.159 | E20: =Seg!E27 -> 12.796 | F20: =Seg!F27 -> 5.9231694 | G20: =Seg!G27 -> 18.719169 | H20: =Seg!H27 -> 29.560973 | I20: =Seg!I27 -> 40.117233 | J20: =Seg!J27 -> 49.236079 | ... M20: =Seg!M27 -> 66.939581
A21: Advertising | B21: US$B | D21: =Seg!D13 -> 1.323 | E21: =Seg!E13 -> 1.248 | F21: =Seg!F13 -> 0.53020762 | G21: =Seg!G13 -> 1.7782076 | H21: =Seg!H13 -> 1.7159401 | I21: =Seg!I13 -> 1.6930415 | J21: =Seg!J13 -> 1.7071405 | K21: =Seg!K13 -> 1.7583547 | ... M21: =Seg!M13 -> 1.8654386
A22: SI 對外雲端服務（命題子列） | B22: US$B | E22: =Seg!E8 -> 6.63552 | F22: =Seg!F8 -> 6.2890195 | G22: =Seg!G8 -> 12.924539 | H22: =Seg!H8 -> 39.310508 | I22: =Seg!I8 -> 61.998941 | J22: =Seg!J8 -> 80.795347 | K22: =Seg!K8 -> 92.868364 | L22: =Seg!L8 -> 103.35449 | M22: =Seg!M8 -> 109.12592
A23: Grok／Cursor／X 訂閱、資料授權與 API（命題子列） | B23: US$B | E23: =Seg!E10 -> 3.05548 | F23: =Seg!F10 -> 2.50516 | G23: =Seg!G10 -> 5.56064 | H23: =Seg!H10 -> 12.91078 | I23: =Seg!I10 -> 17.859913 | J23: =Seg!J10 -> 22.622556 | K23: =Seg!K10 -> 26.01594 | L23: =Seg!L10 -> 29.918331 | M23: =Seg!M10 -> 34.406081
A24: SI Solutions & Infrastructure | B24: US$B | D24: =Seg!D11 -> 0.955 | E24: =Seg!E11 -> 9.691 | F24: =Seg!F11 -> 8.7941795 | G24: =Seg!G11 -> 18.485179 | H24: =Seg!H11 -> 52.221288 | I24: =Seg!I11 -> 79.858854 | J24: =Seg!J11 -> 103.4179 | K24: =Seg!K11 -> 118.8843 | ... M24: =Seg!M11 -> 143.532
A25: SI (Super Intelligence; formerly AI) | B25: US$B | C25: =Seg!C14 -> 3.201 | D25: =Seg!D14 -> 2.278 | E25: =Seg!E14 -> 10.939 | F25: =Seg!F14 -> 9.3243871 | G25: =Seg!G14 -> 20.263387 | H25: =Seg!H14 -> 53.937229 | I25: =Seg!I14 -> 81.551895 | J25: =Seg!J14 -> 105.12504 | ... M25: =Seg!M14 -> 145.39744
A26: 合併營收 | B26: US$B | C26: =Seg!C28 -> 18.674 | D26: =Seg!D28 -> 13.714 | E26: =Seg!E28 -> 27.083 | F26: =Seg!F28 -> 16.534764 | G26: =Seg!G28 -> 43.617764 | H26: =Seg!H28 -> 88.799324 | I26: =Seg!I28 -> 127.34472 | J26: =Seg!J28 -> 160.46777 | ... M26: =Seg!M28 -> 220.05174
A27: 合併營收年增 | B27: % | E27: =E26/D26-1 -> 0.97484323 | G27: =G26/C26-1 -> 1.3357483 | H27: =H26/G26-1 -> 1.0358522 | I27: =I26/H26-1 -> 0.43407309 | J27: =J26/I26-1 -> 0.26010543 | K27: =K26/J26-1 -> 0.13919991 | L27: =L26/K26-1 -> 0.11402098 | M27: =M26/L26-1 -> 0.080547016
A28: 檢查：Space 子列合計 − Space | B28: US$B | D28: =D15+D16-D17 -> 0 | E28: =E15+E16-E17 -> 0 | F28: =F15+F16-F17 -> 0 | G28: =G15+G16-G17 -> 0 | H28: =H15+H16-H17 -> 0 | I28: =I15+I16-I17 -> 0 | J28: =J15+J16-J17 -> 0 | K28: =K15+K16-K17 -> 0 | ... M28: =M15+M16-M17 -> 0
A29: 檢查：Connectivity 子列合計 − Connectivity | B29: US$B | D29: =D18+D19-D20 -> 0 | E29: =E18+E19-E20 -> 0 | F29: =F18+F19-F20 -> 0 | G29: =G18+G19-G20 -> 0 | H29: =H18+H19-H20 -> 0 | I29: =I18+I19-I20 -> 0 | J29: =J18+J19-J20 -> 0 | K29: =K18+K19-K20 -> 0 | ... M29: =M18+M19-M20 -> 0
A30: 檢查：SI 子列合計 − SI | B30: US$B | D30: =D21+D24-D25 -> 0 | E30: =E21+E24-E25 -> 0 | F30: =F21+F24-F25 -> 0 | G30: =G21+G24-G25 -> 0 | H30: =H21+H24-H25 -> 0 | I30: =I21+I24-I25 -> 0 | J30: =J21+J24-J25 -> 0 | K30: =K21+K24-K25 -> 0 | ... M30: =M21+M24-M25 -> 0
A31: 檢查：SI S&I 命題子列合計 − SI Solutions & Infrastructure | B31: US$B | E31: =E22+E23-E24 -> 0 | F31: =F22+F23-F24 -> 0 | G31: =G22+G23-G24 -> 0 | H31: =H22+H23-H24 -> 0 | I31: =I22+I23-I24 -> 0 | J31: =J22+J23-J24 -> 0 | K31: =K22+K23-K24 -> 0 | L31: =L22+L23-L24 -> 0 | M31: =M22+M23-M24 -> 0
A32: 檢查：分部合計 − 合併營收 | B32: US$B | C32: =C17+C20+C25-C26 -> 0 | D32: =D17+D20+D25-D26 -> 0 | E32: =E17+E20+E25-E26 -> 0 | F32: =F17+F20+F25-F26 -> 0 | G32: =G17+G20+G25-G26 -> 0 | H32: =H17+H20+H25-H26 -> 0 | I32: =I17+I20+I25-I26 -> 0 | J32: =J17+J20+J25-J26 -> 0 | ... M32: =M17+M20+M25-M26 -> 0
A33: Space 調整後 EBITDA 率（9M26 → FY2030 m_spl） | B33: % | F33: =m_sp0 -> -0.059438471 | H33: =m_sp0+(m_spl-m_sp0)*MIN(1,(2027-2026)/conv_n) -> 0.005421147 | I33: =m_sp0+(m_spl-m_sp0)*MIN(1,(2028-2026)/conv_n) -> 0.070280765 | J33: =m_sp0+(m_spl-m_sp0)*MIN(1,(2029-2026)/conv_n) -> 0.13514038 | K33: =m_sp0+(m_spl-m_sp0)*MIN(1,(2030-2026)/conv_n) -> 0.2 | L33: =m_sp0+(m_spl-m_sp0)*MIN(1,(2031-2026)/conv_n) -> 0.2 | M33: =m_sp0+(m_spl-m_sp0)*MIN(1,(2032-2026)/conv_n) -> 0.2
A34: Space 分部調整後 EBITDA | B34: US$B | C34: =Q!I28 -> 0.653 | D34: =Q!G28 -> 0.803 | E34: =Q!H28 -> -0.199 | F34: =F17*F33 -> -0.076509667 | G34: =E34+F34 -> -0.27550967 | H34: =H17*H33 -> 0.028738159 | I34: =I17*I33 -> 0.39888495 | J34: =J17*J33 -> 0.82525507 | K34: =K17*K33 -> 1.3202975 | L34: =L17*L33 -> 1.4272851 | M34: =M17*M33 -> 1.5429429
A35: Connectivity 分部調整後 EBITDA | B35: US$B | C35: =Q!I29 -> 7.168 | D35: =Q!G29 -> 5.123 | E35: =Q!H29 -> 8.183 | F35: =F20*m_cn -> 3.7878474 | G35: =E35+F35 -> 11.970847 | H35: =H20*m_cn -> 18.904146 | I35: =I20*m_cn -> 25.654839 | J35: =J20*m_cn -> 31.486311 | K35: =K20*m_cn -> 35.530902 | L35: =L20*m_cn -> 39.283075 | M35: =M20*m_cn -> 42.807642
A36: SI 對外出租 EBITDA（營收 − 對外 GW × Tokenomics 營運費用） | B36: US$B | F36: =F22-Thesis!F35 -> 5.6396031 | G36: =F36 -> 5.6396031 | H36: =H22-Thesis!H35 -> 35.228762 | I36: =I22-Thesis!I35 -> 55.49721 | J36: =J22-Thesis!J35 -> 72.11742 | K36: =K22-Thesis!K35 -> 82.5525 | L36: =L22-Thesis!L35 -> 91.916346 | M36: =M22-Thesis!M35 -> 97.07009
A37: SI 其他 EBITDA（(SI 其他收入＋廣告) × m_so − 自用增量營運費用） | B37: US$B | F37: =(F23+F21)*m_so-Thesis!F36 -> 0.48462444 | G37: =F37 -> 0.48462444 | H37: =(H23+H21)*m_so-Thesis!H36 -> 1.7812585 | I37: =(I23+I21)*m_so-Thesis!I36 -> 1.6724813 | J37: =(J23+J21)*m_so-Thesis!J36 -> 1.6332524 | K37: =(K23+K21)*m_so-Thesis!K36 -> 1.5782701 | L37: =(L23+L21)*m_so-Thesis!L36 -> 1.8100812 | M37: =(M23+M21)*m_so-Thesis!M36 -> 2.3372907
A38: SI 分部調整後 EBITDA | B38: US$B | C38: =Q!I30 -> -1.237 | D38: =Q!G30 -> -0.813 | E38: =Q!H30 -> 5.49 | F38: =F36+F37 -> 6.1242276 | G38: =E38+F38 -> 11.614228 | H38: =H36+H37 -> 37.01002 | I38: =I36+I37 -> 57.169692 | J38: =J36+J37 -> 73.750672 | K38: =K36+K37 -> 84.13077 | L38: =L36+L37 -> 93.726427 | M38: =M36+M37 -> 99.407381
A39: 合併調整後 EBITDA（分部合計） | B39: US$B | C39: =C34+C35+C38 -> 6.584 | D39: =D34+D35+D38 -> 5.113 | E39: =E34+E35+E38 -> 13.474 | F39: =F34+F35+F38 -> 9.8355653 | G39: =G34+G35+G38 -> 23.309565 | H39: =H34+H35+H38 -> 55.942904 | I39: =I34+I35+I38 -> 83.223415 | J39: =J34+J35+J38 -> 106.06224 | ... M39: =M34+M35+M38 -> 143.75797
A40: Space 折舊攤銷（基礎遞減＋新增） | B40: US$B | D40: =Q!G42 -> 0.572 | E40: =Q!H42 -> 0.509 | F40: =da_sp0*0.25*MAX(0,1-(2026.875-t_val)/rem_sp)+Seg!F39 -> 0.18958307 | G40: =E40+F40 -> 0.69858307 | H40: =da_sp0*1*MAX(0,1-(2027.5-t_val)/rem_sp)+Seg!H39 -> 0.90003388 | I40: =da_sp0*1*MAX(0,1-(2028.5-t_val)/rem_sp)+Seg!I39 -> 1.2256325 | J40: =da_sp0*1*MAX(0,1-(2029.5-t_val)/rem_sp)+Seg!J39 -> 1.4631198 | K40: =da_sp0*1*MAX(0,1-(2030.5-t_val)/rem_sp)+Seg!K39 -> 1.5987329 | L40: =da_sp0*1*MAX(0,1-(2031.5-t_val)/rem_sp)+Seg!L39 -> 1.6527895 | M40: =da_sp0*1*MAX(0,1-(2032.5-t_val)/rem_sp)+Seg!M39 -> 1.8342195
A41: Connectivity 折舊攤銷（基礎遞減＋新增） | B41: US$B | D41: =Q!G44 -> 1.706 | E41: =Q!H44 -> 2.574 | F41: =da_cn0*0.25*MAX(0,1-(2026.875-t_val)/rem_cn)+Seg!F40 -> 0.96537072 | G41: =E41+F41 -> 3.5393707 | H41: =da_cn0*1*MAX(0,1-(2027.5-t_val)/rem_cn)+Seg!H40 -> 3.6935879 | I41: =da_cn0*1*MAX(0,1-(2028.5-t_val)/rem_cn)+Seg!I40 -> 4.1580262 | J41: =da_cn0*1*MAX(0,1-(2029.5-t_val)/rem_cn)+Seg!J40 -> 5.1858603 | K41: =da_cn0*1*MAX(0,1-(2030.5-t_val)/rem_cn)+Seg!K40 -> 7.6649296 | L41: =da_cn0*1*MAX(0,1-(2031.5-t_val)/rem_cn)+Seg!L40 -> 10.815797 | M41: =da_cn0*1*MAX(0,1-(2032.5-t_val)/rem_cn)+Seg!M40 -> 14.204114
