Workbook

Sheet 導覽
A1: 預付款，能把 Backlog 變成現金嗎？｜Nebius 收支與評價模型 — Excel 版 v0.2（更新 2026-10-07；與 HTML v0.2 同步；市價截至 2026-10-06 收盤）
A3: 這個活頁簿在回答什麼
A4: 一句話：預付款，能把 Backlog 變成現金嗎？——Nebius 的營收＝已連網 MW × 每 MW 年收入；客戶預付款能支應多少擴張資本支出，剩下的缺口要靠多少資產擔保融資、可轉債與新股（答案見「摘要」）。
A5: 所有分頁用同一組數字，改任何一個輸入，後面全部會跟著動。
A7: 分頁結構（依模組分組，分頁標籤顏色相同者為同一模組）
A8: 摘要 一頁摘要：結論、與市場共識的差異、現價隱含什麼、驗證點（全部活公式）。
A9: 輸入與假設 所有可調參數（A 情境 → B 產能與收入 → C 利潤率 → D 支出 → E 融資 → F 評價 → G 1H 實際 → H 情境區間運算表 → I 市場共識 → J 季度追蹤輸入）。
A10: 各期收支 類現金流量：來源（含客戶預付）、用途、融資前缺口、期前融資瀑布。
A11: 季度追蹤 焦點季的模型／共識／指引／實際與差距（由年度模型拆分，只用於追蹤；實際數填在輸入與假設 J 區）。
A12: 運營_產能與收入 已連網 MW → 在役 MW → 營收（MW × 每 MW 年收入 × 利用率）；RPO 排程只作對照與產能瓶頸旗標。
A13: 資產負債_既有債務／新債與新股／租賃承諾 類資產負債表：季報債務明細、每期現金與總債務與股數、租賃承諾。
A14: 損益 類損益表（FY26＝1H 實際＋下半年模型）。
... A42: DCF 以融資後股數計每股，並加回新股募得現金的現值；EV/EBITDA 用錨定年末淨負債與錨定年末股數。

Sheet 摘要
A1: 預付款，能把 Backlog 變成現金嗎？｜一頁摘要 — 結論、與市場的差異、現價隱含什麼、驗證點（全部依輸入連動）
A2: ="模型端＝目前情境：" & CHOOSE(輸入與假設!$C$5,"保守 已簽約 3.5 GW","基準 合約 5 GW","積極 每年 >1 GW") & "（預設＝基準）；共識＝data/consensus_nbis_20261007.json（2026-10-07）" -> 模型端＝目前情境：基準 合約 5 GW（預設＝基準）；共識＝data/consensus_nbis_20261007.json（2026-10-07）
A4: 1｜結論
A5: 結論｜評等代碼（1＝買進、0＝中立、−1＝賣出） | C5: =評價_DCF與目標價!C76 -> -1
A6: 結論｜評等 | C6: =CHOOSE(C5+2,"賣出","中立","買進") -> 賣出
A7: 結論｜點位（加權目標價） | B7: US$ | C7: =評價_DCF與目標價!C49 -> 61.719948
A8: 結論｜現價 | B8: US$ | C8: =輸入與假設!$C$124 -> 249.87
A9: 結論｜空間 | B9: % | C9: =C7/C8-1 -> -0.75299176
A10: 結論｜情境區間（下緣／上緣） | B10: US$ | C10: =評價_DCF與目標價!C81 -> 63.801411 | D10: =評價_DCF與目標價!D81 -> 154.55838
A11: 結論｜方法區間（下緣／上緣） | B11: US$ | C11: =評價_DCF與目標價!C83 -> 44.881826 | D11: =評價_DCF與目標價!D83 -> 61.719948
A12: 結論｜賣出門檻價 | B12: US$ | C12: =評價_DCF與目標價!$C$77 -> 212.3895
A13: 結論｜點位 − 賣出門檻 | B13: US$ | C13: =C7-C12 -> -150.66955
A14: 結論｜結論句 | C14: =C6&"：點位 $"&TEXT(C7,"0.0")&"，較現價 $"&TEXT(C8,"0.00")&" "&IF(C9>=0,"高","低")&" "&TEXT(ABS(C9)*100,"0")&"%；情境區間 $"&TEXT(C10,"0.0")&"–$"&TEXT(D10,"0.0")&"，方法區間 $"&TEXT(C11,"0.0")&"–$"&TEXT(D11,"0.0")&"；點位"&IF(C13<0,"低於","高於")&"賣出門檻 $"&TEXT(C12,"0.0")&" 達 $"&TEXT(ABS(C13),"0.0")&"。" -> 賣出：點位 $61.7，較現價 $249.87 低 75%；情境區間 $63.8–$154.6，方法區間 $44.9–$61.7；點位低於賣出門檻 $212.4 達 $150.7。
A15: 結論｜情境判斷句 | C15: =評價_DCF與目標價!C89 -> 情境區間上緣 $154.6 低於現價 $249.87：賣出在三個擴張情境下都成立。
A17: 2｜與市場的差異（模型：目前情境 vs 共識；FY26–FY28）
A18: 項目 | B18: 單位 | C18: FY26 | D18: FY27 | E18: FY28
A19: 差異｜營收｜模型 | B19: US$bn | C19: =損益!C26 -> 3.0345 | D19: =損益!D26 -> 10.8054 | E19: =損益!E26 -> 22.8201
A20: 差異｜營收｜共識 | B20: US$bn | C20: =輸入與假設!$C$228 -> 3.379 | D20: =輸入與假設!$D$228 -> 11.418 | E20: =輸入與假設!$E$228 -> 21.458
A21: 差異｜營收｜差距 | B21: % | C21: =C19/C20-1 -> -0.10195324 | D21: =D19/D20-1 -> -0.053652128 | E21: =E19/E20-1 -> 0.063477491
A22: 差異｜調整後 EBITDA｜模型 | B22: US$bn | C22: =輸入與假設!$C$197+損益!C19 -> 1.2921404 | D22: =損益!D31 -> 5.1563473 | E22: =損益!E31 -> 10.939518
A23: 差異｜調整後 EBITDA｜共識 | B23: US$bn | C23: =輸入與假設!$C$229 -> 1.338 | D23: =輸入與假設!$D$229 -> 6.194 | E23: =輸入與假設!$E$229 -> 13.404
A24: 差異｜調整後 EBITDA｜差距 | B24: % | C24: =C22/C23-1 -> -0.034274738 | D24: =D22/D23-1 -> -0.16752545 | E24: =E22/E23-1 -> -0.18386166 | I24: FY26 模型＝1H 實際調整後 EBITDA（輸入與假設 G 區，報導轉述 [Verified]）＋2H 模型
A25: 差異｜調整後 EBITDA｜差距（金額） | B25: US$bn | C25: =C22-C23 -> -0.0458596 | D25: =D22-D23 -> -1.0376527 | E25: =E22-E23 -> -2.4644817 | I25: 與 HTML 一頁摘要、市場共識分頁同一呈現；判斷門檻仍用上一列比例
A26: 差異｜EBITDA 率｜模型 | B26: % | C26: =C22/C19 -> 0.42581658 | D26: =D22/D19 -> 0.47720097 | E26: =E22/E19 -> 0.47938082
A27: 差異｜EBITDA 率｜共識 | B27: % | C27: =輸入與假設!$C$230 -> 0.396 | D27: =輸入與假設!$D$230 -> 0.542 | E27: =輸入與假設!$E$230 -> 0.625
A28: 差異｜EBITDA 率｜差距（百分點） | B28: pt | C28: =C26-C27 -> 0.029816576 | D28: =D26-D27 -> -0.064799031 | E28: =E26-E27 -> -0.14561918 | I28: EBITDA 率以百分點列差距，不納入判斷
A29: 差異｜CapEx（毛額）｜模型 | B29: US$bn | C29: =輸入與假設!$C$181+輸入與假設!C$90 -> 29.0696 | D29: =輸入與假設!D$90 -> 29.1508 | E29: =輸入與假設!E$90 -> 29.1508
A30: 差異｜CapEx（毛額）｜共識 | B30: US$bn | C30: =輸入與假設!$C$234 -> 22.489 | D30: =輸入與假設!$D$234 -> 27.243 | E30: =輸入與假設!$E$234 -> 38.39
A31: 差異｜CapEx（毛額）｜差距 | B31: % | C31: =C29/C30-1 -> 0.29261417 | D31: =D29/D30-1 -> 0.070028998 | E31: =E29/E30-1 -> -0.24066684 | I31: 共識 CapEx 口徑未揭露；FY26＝1H 實際毛額＋2H 模型毛額
A32: 差異｜淨負債｜模型 | B32: US$bn | C32: =資產負債_新債與新股!C24 -> 6.04982 | D32: =資產負債_新債與新股!D24 -> 20.741161 | E32: =資產負債_新債與新股!E24 -> 26.790802
A33: 差異｜淨負債｜共識 | B33: US$bn | C33: =輸入與假設!$C$236 -> 15.446 | D33: =輸入與假設!$D$236 -> 31.876 | E33: =輸入與假設!$E$236 -> 38.685
A34: 差異｜淨負債｜差距 | B34: % | C34: =C32/C33-1 -> -0.60832448 | D34: =D32/D33-1 -> -0.34931732 | E34: =E32/E33-1 -> -0.30746279 | I34: 共識淨負債不含租賃、口徑未揭露：只列不判斷
A35: 差異｜淨負債｜差距（金額） | B35: US$bn | C35: =C32-C33 -> -9.39618 | D35: =D32-D33 -> -11.134839 | E35: =E32-E33 -> -11.894198 | I35: 與 HTML 一頁摘要、市場共識分頁同一呈現；判斷門檻仍用上一列比例
A36: 差異｜分歧項目（超過門檻者） | C36: =MID(IF(ABS(C21)>輸入與假設!$C$273,"、營收 "&IF(C21<0,"−","+")&TEXT(ABS(C21)*100,"0.0")&"%","")&IF(ABS(C24)>輸入與假設!$C$273,"、EBITDA "&IF(C25<0,"−","+")&"$"&TEXT(ABS(C25),"#,##0.00")&"bn"&"／"&IF(C28<0,"−","+")&TEXT(ABS(C28)*100,"0.0")&"pt","")&IF(ABS(C31)>輸入與假設!$C$273,"、CapEx "&IF(C31<0,"−","+")&TEXT(ABS(C31)*100,"0.0")&"%",""),2,999) -> 營收 −10.2%、CapEx +29.3% | D36: =MID(IF(ABS(D21)>輸入與假設!$C$273,"、營收 "&IF(D21<0,"−","+")&TEXT(ABS(D21)*100,"0.0")&"%","")&IF(ABS(D24)>輸入與假設!$C$273,"、EBITDA "&IF(D25<0,"−","+")&"$"&TEXT(ABS(D25),"#,##0.00")&"bn"&"／"&IF(D28<0,"−","+")&TEXT(ABS(D28)*100,"0.0")&"pt","")&IF(ABS(D31)>輸入與假設!$C$273,"、CapEx "&IF(D31<0,"−","+")&TEXT(ABS(D31)*100,"0.0")&"%",""),2,999) -> 營收 −5.4%、EBITDA −$1.04bn／−6.5pt、CapEx +7.0% | E36: =MID(IF(ABS(E21)>輸入與假設!$C$273,"、營收 "&IF(E21<0,"−","+")&TEXT(ABS(E21)*100,"0.0")&"%","")&IF(ABS(E24)>輸入與假設!$C$273,"、EBITDA "&IF(E25<0,"−","+")&"$"&TEXT(ABS(E25),"#,##0.00")&"bn"&"／"&IF(E28<0,"−","+")&TEXT(ABS(E28)*100,"0.0")&"pt","")&IF(ABS(E31)>輸入與假設!$C$273,"、CapEx "&IF(E31<0,"−","+")&TEXT(ABS(E31)*100,"0.0")&"%",""),2,999) -> 營收 +6.3%、EBITDA −$2.46bn／−14.6pt、CapEx −24.1% | I36: 營收、EBITDA、CapEx 任一項差距絕對值超過門檻即列出（與 HTML 判斷句同一規則）
A37: 差異｜分歧起始年（1＝FY26…3＝FY28；0＝無） | C37: =IF(C36<>"",1,IF(D36<>"",2,IF(E36<>"",3,0))) -> 1
A38: 差異｜判斷句 | C38: =CHOOSE(C37+1,"FY26–FY28 營收、EBITDA、CapEx 與共識差距皆在 "&IF(ROUND(ABS(輸入與假設!$C$273)*100,4)=INT(ROUND(ABS(輸入與假設!$C$273)*100,4)),TEXT(ROUND(ABS(輸入與假設!$C$273)*100,4),"0"),TEXT(ROUND(ABS(輸入與假設!$C$273)*100,4),"0.0"))&"%"&" 以內。","分歧始於 FY26（"&C36&"）"&"；FY27 "&IF(D36="","回到 "&IF(ROUND(ABS(輸入與假設!$C$273)*100,4)=INT(ROUND(ABS(輸入與假設!$C$273)*100,4)),TEXT(ROUND(ABS(輸入與假設!$C$273)*100,4),"0"),TEXT(ROUND(ABS(輸入與假設!$C$273)*100,4),"0.0"))&"%"&" 以內",D36)&"；FY28 "&IF(E36="","回到 "&IF(ROUND(ABS(輸入與假設!$C$273)*100,4)=INT(ROUND(ABS(輸入與假設!$C$273)*100,4)),TEXT(ROUND(ABS(輸入與假設!$C$273)*100,4),"0"),TEXT(ROUND(ABS(輸入與假設!$C$273)*100,4),"0.0"))&"%"&" 以內",E36)&"。","FY26 營收、EBITDA、CapEx 與共識差距在 "&IF(ROUND(ABS(輸入與假設!$C$273)*100,4)=INT(ROUND(ABS(輸入與假設!$C$273)*100,4)),TEXT(ROUND(ABS(輸入與假設!$C$273)*100,4),"0"),TEXT(ROUND(ABS(輸入與假設!$C$273)*100,4),"0.0"))&"%"&" 以內；分歧始於 FY27（"&D36&"）"&"；FY28 "&IF(E36="","回到 "&IF(ROUND(ABS(輸入與假設!$C$273)*100,4)=INT(ROUND(ABS(輸入與假設!$C$273)*100,4)),TEXT(ROUND(ABS(輸入與假設!$C$273)*100,4),"0"),TEXT(ROUND(ABS(輸入與假設!$C$273)*100,4),"0.0"))&"%"&" 以內",E36)&"。","FY26–FY27 營收、EBITDA、CapEx 與共識差距在 "&IF(ROUND(ABS(輸入與假設!$C$273)*100,4)=INT(ROUND(ABS(輸入與假設!$C$273)*100,4)),TEXT(ROUND(ABS(輸入與假設!$C$273)*100,4),"0"),TEXT(ROUND(ABS(輸入與假設!$C$273)*100,4),"0.0"))&"%"&" 以內；分歧始於 FY28（"&E36&"）。") -> 分歧始於 FY26（營收 −10.2%、CapEx +29.3%）；FY27 營收 −5.4%、EBITDA −$1.04bn／−6.5pt、CapEx +7.0%；FY28 營收 +6.3%、EBITDA −$2.46bn／−14.6pt、CapEx −24.1%。
A39: 差異原因｜FY26｜營收 | C39: =IF(ABS(C21)>輸入與假設!$C$273,"觀點","") -> 觀點 | D39: =IF(ABS(C21)>輸入與假設!$C$273,"營收＝可計費 MW × 每 MW 年收入（Tokenomics 正向推導）；首期以最新季實際營收年化校準期初可計費 MW，可計費 MW 依爬坡係數（60%／80%／100%）收斂到已連網 MW（v0.1c）；年底已連網 "&IF((輸入與假設!C$39)<0,"−","")&TEXT(ABS((輸入與假設!C$39)),"#,##0")&" MW（目前情境）；共識未揭露 MW 假設","") -> 營收＝可計費 MW × 每 MW 年收入（Tokenomics 正向推導）；首期以最新季實際營收年化校準期初可計費 MW，可計費 MW 依爬坡係數（60%／80%／100%）收斂到已連網 MW（v0.1c）；年底已連網 750 MW（目前情境）；共識未揭露 MW 假設 | I39: C＝類型、D＝原因（需附原因時顯示；EBITDA 以利潤率差、其餘以比例門檻判斷）
A40: 差異原因｜FY26｜EBITDA | C40: =IF(ABS(C28)>輸入與假設!$C$274,"觀點","") -> 觀點 | D40: =IF(ABS(C28)>輸入與假設!$C$274,"營收差距 "&IF((C21)<0,"−","+")&TEXT(ABS((C21))*100,"#,##0.0")&"%"&"；EBITDA 率 "&IF((C26)<0,"−","")&TEXT(ABS((C26))*100,"#,##0.0")&"%"&" 對共識 "&IF((C27)<0,"−","")&TEXT(ABS((C27))*100,"#,##0.0")&"%"&"（模型由 "&IF((輸入與假設!$C$50)<0,"−","")&TEXT(ABS((輸入與假設!$C$50))*100,"#,##0")&"%"&" 走向穩態 "&IF((輸入與假設!$C$51)<0,"−","")&TEXT(ABS((輸入與假設!$C$51))*100,"#,##0")&"%"&"，取可觀察 neocloud 區間）","") -> 營收差距 −10.2%；EBITDA 率 42.6% 對共識 39.6%（模型由 50% 走向穩態 47%，取可觀察 neocloud 區間）
A41: 差異原因｜FY26｜CapEx | C41: =IF(ABS(C31)>輸入與假設!$C$273,"觀點","") -> 觀點 | D41: =IF(ABS(C31)>輸入與假設!$C$273,"CapEx 依新增 MW 計算：新增 "&IF((輸入與假設!C$83)<0,"−","")&TEXT(ABS((輸入與假設!C$83)),"#,##0")&" MW × 每 MW $"&IF((輸入與假設!C$69)<0,"−","")&TEXT(ABS((輸入與假設!C$69)),"#,##0")&"m（含次年預建）；共識口徑未揭露","") -> CapEx 依新增 MW 計算：新增 580 MW × 每 MW $50m（含次年預建）；共識口徑未揭露
A42: 差異原因｜FY26｜淨負債 | C42: =IF(ABS(C34)>輸入與假設!$C$273,"觀點","") -> 觀點 | D42: =IF(ABS(C34)>輸入與假設!$C$273,"淨負債隨 CapEx、客戶預付與融資需求而定（模型 CapEx 差距 "&IF((C31)<0,"−","+")&TEXT(ABS((C31))*100,"#,##0.0")&"%"&"）；共識淨負債口徑未揭露","") -> 淨負債隨 CapEx、客戶預付與融資需求而定（模型 CapEx 差距 +29.3%）；共識淨負債口徑未揭露
...

Sheet 輸入與假設
A1: 輸入（依類別排序；點左側 ＋／− 展開或收合。藍字可改；黃底為最關鍵假設）
A2: A 情境 → B 產能與收入 → C 利潤率 → D 支出（CapEx／折舊／租賃／JV）→ E 融資 → F 評價 → G 參考：1H26 實際 → H 情境區間運算表 → I 市場共識 → J 季度追蹤輸入。灰底『▸』為明細子區，預設收合
A4: A｜情境與規模（管理層擴張力道）
A5: 情境選擇（1＝保守 已簽約 3.5 GW、2＝基準 合約 5 GW、3＝積極 每年 >1 GW） | C5: 2 | D5: =CHOOSE(C5,"保守 已簽約 3.5 GW","基準 合約 5 GW","積極 每年 >1 GW") -> 基準 合約 5 GW | I5: 三情境改變擴張力道（已連網 MW 路徑）與每 MW 年收入（Tokenomics 正向推導三情境值）；其餘假設相同（對照表 r1 第 4 節第 1 條）
A6: ▸ 情境路徑明細（已連網 MW、在役比例、表外租金基準）
A7: 已連網 MW 路徑 | B7: 單位 | C7: FY26 | D7: FY27 | E7: FY28 | F7: FY29 | G7: FY30 | I7: FY31 新增 MW
A8: 首期期末已連網 MW（三情境共用） | B8: MW | C8: 750 | I8: 2026 年底 connected 目標 0.8–1.0 GW 中點 ÷ PUE 1.2 [Interested-party／Derived]
A9: 保守 已簽約 3.5 GW｜合約 MW 上限 | B9: MW | C9: 2917 | D9: 2917 | E9: 2917 | F9: 2917 | G9: 2917 | I9: company.json → scenarios.mwPath.contracted
A10: 保守 已簽約 3.5 GW｜併網速度 | B10: MW／年 | C10: 580 | I10: company.json → scenarios.mwPath.pace
A11: 保守 已簽約 3.5 GW | B11: MW | C11: =MIN(C9,輸入與假設!$C$8) -> 750 | D11: =MIN(D9,C11+輸入與假設!$C$10*D$37) -> 1330 | E11: =MIN(E9,D11+輸入與假設!$C$10*E$37) -> 1910 | F11: =MIN(F9,E11+輸入與假設!$C$10*F$37) -> 2490 | G11: =MIN(G9,F11+輸入與假設!$C$10*G$37) -> 2917 | I11: 0 | J11: 只交付已簽約電力（>3.5 GW ÷1.2＝2,917 MW-IT），依歷史併網速度；I 欄＝FY31 新增 MW
A12: 基準 合約 5 GW｜合約 MW 上限 | B12: MW | C12: 4167 | D12: 4167 | E12: 4167 | F12: 4167 | G12: 4167 | I12: company.json → scenarios.mwPath.contracted
A13: 基準 合約 5 GW｜併網速度 | B13: MW／年 | C13: 580 | I13: company.json → scenarios.mwPath.pace
A14: 基準 合約 5 GW | B14: MW | C14: =MIN(C12,輸入與假設!$C$8) -> 750 | D14: =MIN(D12,C14+輸入與假設!$C$13*D$37) -> 1330 | E14: =MIN(E12,D14+輸入與假設!$C$13*E$37) -> 1910 | F14: =MIN(F12,E14+輸入與假設!$C$13*F$37) -> 2490 | G14: =MIN(G12,F14+輸入與假設!$C$13*G$37) -> 3070 | I14: 580 | J14: 2026 年底 5 GW 合約目標（÷1.2＝4,167 MW-IT）依歷史併網速度實現；I 欄＝FY31 新增 MW
A15: 積極 每年 >1 GW｜合約 MW 上限 | B15: MW | C15: 4167 | D15: 5000 | E15: 5833.3333 | F15: 6666.6667 | G15: 7500 | I15: company.json → scenarios.mwPath.contracted
A16: 積極 每年 >1 GW｜併網速度 | B16: MW／年 | C16: 833.3333 | I16: company.json → scenarios.mwPath.pace
A17: 積極 每年 >1 GW | B17: MW | C17: =MIN(C15,輸入與假設!$C$8) -> 750 | D17: =MIN(D15,C17+輸入與假設!$C$16*D$37) -> 1583.3333 | E17: =MIN(E15,D17+輸入與假設!$C$16*E$37) -> 2416.6666 | F17: =MIN(F15,E17+輸入與假設!$C$16*F$37) -> 3249.9999 | G17: =MIN(G15,F17+輸入與假設!$C$16*G$37) -> 4083.3332 | I17: 833.3333 | J17: 2027 起每年部署 >1 GW 全數實現（÷1.2＝833 MW-IT／年）；I 欄＝FY31 新增 MW
A18: 每 MW 年收入｜保守 已簽約 3.5 GW | B18: US$bn/MW | C18: 0.01162 | D18: 0.01162 | E18: 0.01162 | F18: 0.01162 | G18: 0.01162 | I18: Tokenomics 正向推導三情境（data/permw_tokenomics_20261007.json）；不用公司 ACV [Derived]
A19: 每 MW 年收入｜基準 合約 5 GW | B19: US$bn/MW | C19: 0.0174 | D19: 0.0174 | E19: 0.0174 | F19: 0.0174 | G19: 0.0174 | I19: Tokenomics 正向推導三情境（data/permw_tokenomics_20261007.json）；不用公司 ACV [Derived]
A20: 每 MW 年收入｜積極 每年 >1 GW | B20: US$bn/MW | C20: 0.0242 | D20: 0.0242 | E20: 0.0242 | F20: 0.0242 | G20: 0.0242 | I20: Tokenomics 正向推導三情境（data/permw_tokenomics_20261007.json）；不用公司 ACV [Derived]
A21: 在役／已連網比例 | B21: % | C21: 0.75 | D21: 0.85 | E21: 0.9 | F21: 0.9 | G21: 0.9 | I21: 三情境共用；新連網產能自驗收到可計費需數季 [Assumed]
A22: 可計費爬坡係數 | B22: % | C22: 0.6 | D22: 0.8 | E22: 1 | F22: 1 | G22: 1 | I22: v0.1c 首期營收校準：可計費 MW＝已連網 × 在役比例 × 爬坡係數，逐步收斂（60%／80%／100%）；60% 為能讓基準 FY26 落入公司指引的保守值 [Assumed]
A23: 表外現金租金（積極路徑） | B23: US$bn | C23: 0.05 | D23: 0.5 | E23: 1 | F23: 1 | G23: 1 | I23: 已簽約未起租租賃的現金路徑；其他情境依 MW 比例縮放（起算 0 MW）
A24: 表外租金起算 MW | B24: MW | C24: 0 | I24: 表外租金依超過此值的 MW 等比例縮放（company.json → scenarios.leaseRampFloorMw）
A25: B｜產能與收入（MW、每 MW 年收入、利用率、信用；RPO 只作對照）
A26: 6/30 RPO | B26: US$bn | C26: 37.4906 | I26: 季報 RPO 37.4906（只作對照與債務上限的 backlog）[Interested-party]
A27: Q3 初新增承諾 | B27: US$bn | C27: 0 | I27: 評價日後新簽、尚未進 RPO 的承諾；未揭露，取 0 [Assumed]
A28: 五期認列比例（至 2030 末） | B28: % | C28: 0.82 | I28: 季報桶 36／40／24（後段假設 49–72 個月）線性分攤後五期合計 82% [Derived]
A29: RPO 桶權重合計 | B29: % | C29: 0.82 | I29: 下方權重列的合計，用於歸一化
A30: 2025-12-31 主動電力 | B30: MW | C30: 170 | I30: Q4 2025 股東信與 20-F：active power 約 170 MW（IT 口徑）[Interested-party]
A31: 最新已申報季營收（單季） | B31: US$bn | C31: 0.5823 | I31: 期初可計費 MW 校準用：季報營收 [Interested-party]（company.json → latestQuarter.revenue）
A32: 6/30 Billable MW | B32: MW | C32: =ROUND(輸入與假設!$C$31*4/C42,0) -> 134 | I32: v0.1c 校準：＝最新季營收 × 4 ÷ 首期每 MW 年收入（對齊已實現年化營收；季末在役 MW 未揭露，不用內插值）[Derived]
A33: 收入用平均在役 MW（1=是） | C33: 1 | I33: 0＝用期末存量全期化；建議 1
A34: 營收驅動（mw＝MW × 每 MW 年收入；rpo＝RPO 排程） | C34: mw | I34: mw：新產能簽約率固定 100%，營收＝容量上限；RPO 只作對照與產能瓶頸旗標（company.json → defaults.revenueDriver）
A35: 每 MW 年收入倍數（整體） | B35: % | C35: 1 | I35: 反向 DCF 與壓力測試用；預設 100%。以『目標搜尋』調整此格即可反解市價隱含單價
A36: 項目 | B36: 單位 | C36: FY26 | D36: FY27 | E36: FY28 | F36: FY29 | G36: FY30 | I36: 來源／標籤
A37: 模型期長度（年） | C37: 0.5 | D37: 1 | E37: 1 | F37: 1 | G37: 1 | I37: 勿改。由 calendar_q.py 推算；只用於容量上限、電力、維護等年率換算 [Derived]
A38: RPO 桶權重 | B38: % | C38: 0.09 | D38: 0.18 | E38: 0.19 | F38: 0.2 | G38: 0.16 | H38: =SUM(C38:G38) -> 0.82 | I38: 季報 36%／24m、40%／25-48m、24%／之後（假設 49–72m）桶內線性分攤 [Derived]
A39: Accepted MW（期末主動電力） | B39: MW | C39: =CHOOSE(輸入與假設!$C$5,C11,C14,C17) -> 750 | D39: =CHOOSE(輸入與假設!$C$5,D11,D14,D17) -> 1330 | E39: =CHOOSE(輸入與假設!$C$5,E11,E14,E17) -> 1910 | F39: =CHOOSE(輸入與假設!$C$5,F11,F14,F17) -> 2490 | G39: =CHOOSE(輸入與假設!$C$5,G11,G14,G17) -> 3070 | I39: ＝依 A 區情境選擇器（已連網 MW-IT）
A40: Billable MW | B40: MW | C40: =ROUND(C39*C21*C22,0) -> 338 | D40: =ROUND(D39*D21*D22,0) -> 904 | E40: =ROUND(E39*E21*E22,0) -> 1719 | F40: =ROUND(F39*F21*F22,0) -> 2241 | G40: =ROUND(G39*G21*G22,0) -> 2763 | I40: ＝已連網 × 在役比例 × 爬坡係數（A 區）
A41: 利用率 | B41: % | C41: 1 | D41: 1 | E41: 1 | F41: 1 | G41: 1 | I41: 100%：每 MW 年收入已含可計費利用率（路徑 B 80／85／90%），不重複扣除 [Derived]
...

Sheet 各期收支
A1: 支出與資金 — 五層支出、四層來源、現金橋
A2: FY26 欄＝1H 實際（季報現金流量表口徑）＋下半年模型；FY27 以後為純模型。瀑布以「融資前現金」決定需求並直接由各支出列加總，因此沒有循環參照
A4: 項目 | B4: 單位 | C4: FY26 | D4: FY27 | E4: FY28 | F4: FY29 | G4: FY30 | I4: 公式／來源說明
A5: 支出（五層）
A6: ① 毛 CapEx（認列，備忘） | B6: US$bn | C6: =輸入與假設!$C$181+輸入與假設!C$90 -> 29.0696 | D6: =輸入與假設!D$90 -> 29.1508 | E6: =輸入與假設!E$90 -> 29.1508 | F6: =輸入與假設!F$90 -> 29.1508 | G6: =輸入與假設!G$90 -> 37.695 | I6: FY26＝1H 實際認列 8.1303＋2H 模型；對照公司全年指引 20–25。備忘列：用途合計採現金口徑，不用這一列
A7: 客戶預付率 | B7: % | C7: =輸入與假設!C$75 -> 0.385 | D7: =輸入與假設!D$75 -> 0.385 | E7: =輸入與假設!E$75 -> 0.385 | F7: =輸入與假設!F$75 -> 0.385 | G7: =輸入與假設!G$75 -> 0.385
A8: 客戶預付金額（抵減，2H 起） | B8: US$bn | C8: =輸入與假設!C$86*C7 -> 8.0616305 | D8: =輸入與假設!D$86*D7 -> 11.223058 | E8: =輸入與假設!E$86*E7 -> 11.223058 | F8: =輸入與假設!F$86*F7 -> 11.223058 | G8: =輸入與假設!G$86*G7 -> 11.223058 | I8: ＝成長型 CapEx × 預付比率（汰換 CapEx 不計）；1H 的預付已含在實際 CFO 內，不重複計入
A9: 合約負債期初（客戶預付餘額） | B9: US$bn | C9: =輸入與假設!$C$73 -> 5.9752 | D9: =C11 -> 13.040964 | E9: =D11 -> 19.917034 | F9: =E11 -> 24.501081 | G9: =F11 -> 27.557112 | I9: FY26 期初＝6/30 季報遞延營收
A10: 預付認列（非現金營收） | B10: US$bn | C10: =MIN(C9,C9/輸入與假設!$C$72*運營_產能與收入!C7) -> 0.99586667 | D10: =MIN(D9,D9/輸入與假設!$C$72*運營_產能與收入!D7) -> 4.3469879 | E10: =MIN(E9,E9/輸入與假設!$C$72*運營_產能與收入!E7) -> 6.6390113 | F10: =MIN(F9,F9/輸入與假設!$C$72*運營_產能與收入!F7) -> 8.1670269 | G10: =MIN(G9,G9/輸入與假設!$C$72*運營_產能與收入!G7) -> 9.1857039 | I10: ＝期初合約負債 ÷ 認列年數 × 期間長度；這部分營收已在預付時收現，自營運來源扣除
A11: 合約負債期末 | B11: US$bn | C11: =C9+C8-C10 -> 13.040964 | D11: =D9+D8-D10 -> 19.917034 | E11: =E9+E8-E10 -> 24.501081 | F11: =F9+F8-F10 -> 27.557112 | G11: =G9+G8-G10 -> 29.594466 | I11: ＝期初＋預付流入−認列
A12: ① CapEx（用途用：1H 現金／2H 毛額） | B12: US$bn | C12: =輸入與假設!$C$180+輸入與假設!C$90 -> 29.0696 | D12: =輸入與假設!D$90 -> 29.1508 | E12: =輸入與假設!E$90 -> 29.1508 | F12: =輸入與假設!F$90 -> 29.1508 | G12: =輸入與假設!G$90 -> 37.695 | I12: 1H 採現金流量表的現金購置 8.1303；2H 起採毛額，客戶預付在來源端抵回（避免重複計入）
A13: ② 在帳現金租金（備忘，1H 已含在 CFO） | B13: US$bn | C13: =輸入與假設!C$76 -> 0.0916 | D13: =輸入與假設!D$76 -> 0.2352 | E13: =輸入與假設!E$76 -> 0.2342 | F13: =輸入與假設!F$76 -> 0.2414 | G13: =輸入與假設!G$76 -> 0.2427 | I13: 見『租賃與承諾』頁；2030 後尚有 1.13。FY26 欄僅 2H：1H 租金 0.0 已含在實際 CFO 內
A14: ② 表外現金租金（未起租） | B14: US$bn | C14: =輸入與假設!C$77 -> 0.05 | D14: =輸入與假設!D$77 -> 0.42000001 | E14: =輸入與假設!E$77 -> 0.79034485 | F14: =輸入與假設!F$77 -> 0.76615387 | G14: =輸入與假設!G$77 -> 0.75183676 | I14: 已簽約未起租租賃 12.0541 的現金路徑
A15: 租金合計 | B15: US$bn | C15: =C13+C14 -> 0.1416 | D15: =D13+D14 -> 0.65520001 | E15: =E13+E14 -> 1.0245448 | F15: =F13+F14 -> 1.0075539 | G15: =G13+G14 -> 0.99453676
A16: ③ 存量債務利息（備忘，1H 已含在 CFO） | B16: US$bn | C16: =輸入與假設!C$121 -> 0.060375 | D16: =輸入與假設!D$121 -> 0.12075 | E16: =輸入與假設!E$121 -> 0.12075 | F16: =輸入與假設!F$121 -> 0.12075 | G16: =輸入與假設!G$121 -> 0.112125 | I16: ="6/30 債務餘額的利息。FY26 全年利息＝1H 實際 0.1828＋2H "&TEXT(C16,"0.0")&"＝"&TEXT(0.1828+C16,"0.00")&"（見下方備忘）" -> 6/30 債務餘額的利息。FY26 全年利息＝1H 實際 0.1828＋2H 0.1＝0.24（見下方備忘）
A17: 期初累積現金 | B17: US$bn | C17: =輸入與假設!$C$178 -> 3.6781 | D17: =C47 -> 2 | E17: =D47 -> 2 | F17: =E47 -> 2 | G17: =F47 -> 2 | I17: FY26 自 2025-12-31 的 3.127 起算；之後＝前期期末累積現金
A18: 新債利率 | B18: % | C18: =IF(輸入與假設!$C$115=1,輸入與假設!C$120+MAX(0,輸入與假設!$C$114-450)/100*0.004,輸入與假設!C$120) -> 0.065 | D18: =IF(輸入與假設!$C$115=1,輸入與假設!D$120+MAX(0,輸入與假設!$C$114-450)/100*0.004,輸入與假設!D$120) -> 0.065 | E18: =IF(輸入與假設!$C$115=1,輸入與假設!E$120+MAX(0,輸入與假設!$C$114-450)/100*0.004,輸入與假設!E$120) -> 0.065 | F18: =IF(輸入與假設!$C$115=1,輸入與假設!F$120+MAX(0,輸入與假設!$C$114-450)/100*0.004,輸入與假設!F$120) -> 0.065 | G18: =IF(輸入與假設!$C$115=1,輸入與假設!G$120+MAX(0,輸入與假設!$C$114-450)/100*0.004,輸入與假設!G$120) -> 0.065 | I18: CDS 開關：＋MAX(0,CDS−450)×0.4bp/bp
A19: ③ 新債利息（瀑布） | B19: US$bn | C19: =C74 -> 0.044844151 | D19: =D74 -> 0.82462547 | E19: =E74 -> 0.99785213 | F19: =F74 -> 1.1028521 | G19: =G74 -> 1.227965 | I19: ＝新債利率×期間長度×(期初新債＋本期舉借)；見下方「期前融資瀑布」
A20: 利息合計 | B20: US$bn | C20: =C16+C19 -> 0.10521915 | D20: =D16+D19 -> 0.94537547 | E20: =E16+E19 -> 1.1186021 | F20: =F16+F19 -> 1.2236021 | G20: =G16+G19 -> 1.34009
A21: ④ JV／策略投資出資 | B21: US$bn | C21: =輸入與假設!$C$182+輸入與假設!C$80 -> 0.2516 | D21: =輸入與假設!D$80 -> 0 | E21: =輸入與假設!E$80 -> 0 | F21: =輸入與假設!F$80 -> 0 | G21: =輸入與假設!G$80 -> 0 | I21: FY26＝1H 實際 0.2516（JV 0.000＋策略投資 0.252）＋2H 模型。NBIS 不發股息
A22: 電力（overlay） | B22: US$bn | C22: =IF(輸入與假設!$C$56=1,運營_產能與收入!C9*8760*輸入與假設!C$58*輸入與假設!C$57/1000000000*運營_產能與收入!C7,0) -> 0 | D22: =IF(輸入與假設!$C$56=1,運營_產能與收入!D9*8760*輸入與假設!D$58*輸入與假設!D$57/1000000000*運營_產能與收入!D7,0) -> 0 | E22: =IF(輸入與假設!$C$56=1,運營_產能與收入!E9*8760*輸入與假設!E$58*輸入與假設!E$57/1000000000*運營_產能與收入!E7,0) -> 0 | F22: =IF(輸入與假設!$C$56=1,運營_產能與收入!F9*8760*輸入與假設!F$58*輸入與假設!F$57/1000000000*運營_產能與收入!F7,0) -> 0 | G22: =IF(輸入與假設!$C$56=1,運營_產能與收入!G9*8760*輸入與假設!G$58*輸入與假設!G$57/1000000000*運營_產能與收入!G7,0) -> 0 | I22: ＝已連網 MW×8760×PUE×電價÷1e9×期間係數。EBITDA 率已含電費，預設關閉
A23: 維護（overlay） | B23: US$bn | C23: =IF(輸入與假設!$C$56=1,運營_產能與收入!C9*輸入與假設!C$59/1000*運營_產能與收入!C7,0) -> 0 | D23: =IF(輸入與假設!$C$56=1,運營_產能與收入!D9*輸入與假設!D$59/1000*運營_產能與收入!D7,0) -> 0 | E23: =IF(輸入與假設!$C$56=1,運營_產能與收入!E9*輸入與假設!E$59/1000*運營_產能與收入!E7,0) -> 0 | F23: =IF(輸入與假設!$C$56=1,運營_產能與收入!F9*輸入與假設!F$59/1000*運營_產能與收入!F7,0) -> 0 | G23: =IF(輸入與假設!$C$56=1,運營_產能與收入!G9*輸入與假設!G$59/1000*運營_產能與收入!G7,0) -> 0
A24: ⑤ 排程還本（季報到期表） | B24: US$bn | C24: =輸入與假設!$C$184+IF(輸入與假設!$C$99=1,輸入與假設!C$119,0)+資產負債_既有債務!C42 -> 0.0467 | D24: =IF(輸入與假設!$C$99=1,輸入與假設!D$119,0)+資產負債_既有債務!D42 -> 0 | E24: =IF(輸入與假設!$C$99=1,輸入與假設!E$119,0)+資產負債_既有債務!E42 -> 0 | F24: =IF(輸入與假設!$C$99=1,輸入與假設!F$119,0)+資產負債_既有債務!F42 -> 0 | G24: =IF(輸入與假設!$C$99=1,輸入與假設!G$119,0)+資產負債_既有債務!G42 -> 3.795 | I24: FY26＝1H 實際還款 0.0＋2H 到期表 0.0467
A25: ⑥ capped call 支出（1H 實際） | B25: US$bn | C25: =輸入與假設!$C$185 -> 0 | D25: =0 -> 0 | E25: =0 -> 0 | F25: =0 -> 0 | G25: =0 -> 0 | I25: 可轉債配套 capped call 現金支出（未見揭露，0）
A26: 用途合計（現金口徑） | B26: US$bn | C26: =C12+C15+C20+C21+C22+C23+C24+C25 -> 29.614719 | D26: =D12+D15+D20+D21+D22+D23+D24+D25 -> 30.751375 | E26: =E12+E15+E20+E21+E22+E23+E24+E25 -> 31.293947 | F26: =F12+F15+F20+F21+F22+F23+F24+F25 -> 31.381956 | G26: =G12+G15+G20+G21+G22+G23+G24+G25 -> 43.824627 | I26: FY26 的 1H 部分採季報現金流量表口徑（現金購置、還款、JV、capped call）；1H 的利息與租金已含在 CFO 內，不重複列
A27: 來源（四層）
A28: Ⓐ0 1H26 實際營運現金流（CFO） | B28: US$bn | C28: =輸入與假設!$C$179 -> 4.5041 | D28: =0 -> 0 | E28: =0 -> 0 | F28: =0 -> 0 | G28: =0 -> 0 | I28: 季報實際值，取代模型推算；已含 1H 的利息、租金與客戶預付
A29: Ⓐ RPO 現金（2H 起） | B29: US$bn | C29: =運營_產能與收入!C37 -> 1.1591353 | D29: =運營_產能與收入!D37 -> 3.698963 | E29: =運營_產能與收入!E37 -> 3.7356529 | F29: =運營_產能與收入!F37 -> 3.7560722 | G29: =運營_產能與收入!G37 -> 2.9193725
A30: Ⓑ 新簽約現金 | B30: US$bn | C30: =運營_產能與收入!C38 -> 0 | D30: =運營_產能與收入!D38 -> 2.2238216 | E30: =運營_產能與收入!E38 -> 8.2319748 | F30: =運營_產能與收入!F38 -> 13.502147 | G30: =運營_產能與收入!G38 -> 18.268322
A31: Ⓒ 非算力服務現金 | B31: US$bn | C31: =輸入與假設!C$54 -> 0 | D31: =輸入與假設!D$54 -> 0 | E31: =輸入與假設!E$54 -> 0 | F31: =輸入與假設!F$54 -> 0 | G31: =輸入與假設!G$54 -> 0
A32: Ⓒ2 其他事業 EBITDA（2H 起） | B32: US$bn | C32: =輸入與假設!C$47 -> -0.094 | D32: =輸入與假設!D$47 -> -0.141 | E32: =輸入與假設!E$47 -> -0.094 | F32: =輸入與假設!F$47 -> -0.047 | G32: =輸入與假設!G$47 -> 0 | I32: Avride＋TripleTen 燒錢（負值），視為現金（v0.1b）
A33: Ⓓ 客戶預付（2H 起） | B33: US$bn | C33: =C8 -> 8.0616305 | D33: =D8 -> 11.223058 | E33: =E8 -> 11.223058 | F33: =F8 -> 11.223058 | G33: =G8 -> 11.223058
A34: Ⓓ2 減：預付認列（非現金營收） | B34: US$bn | C34: =-C10 -> -0.99586667 | D34: =-D10 -> -4.3469879 | E34: =-E10 -> -6.6390113 | F34: =-F10 -> -8.1670269 | G34: =-G10 -> -9.1857039 | I34: 營收中由合約負債轉入的部分已在預付時收現，不重複計入服務現金（v0.1b）
A35: 營運來源合計 | B35: US$bn | C35: =C28+C29+C30+C31+C32+C33+C34 -> 12.634999 | D35: =D28+D29+D30+D31+D32+D33+D34 -> 12.657855 | E35: =E28+E29+E30+E31+E32+E33+E34 -> 16.457674 | F35: =F28+F29+F30+F31+F32+F33+F34 -> 20.267251 | G35: =G28+G29+G30+G31+G32+G33+G34 -> 23.225048
A36: Ⓔ 股權／可轉債（融資） | B36: US$bn | C36: =輸入與假設!$C$186+IF(輸入與假設!$C$96=1,輸入與假設!$C$95,0) -> 10.4911 | D36: =0 -> 0 | E36: =0 -> 0 | F36: =0 -> 0 | G36: =0 -> 0 | I36: FY26＝1H 股權 4.811（ATM 淨 2.811＋NVIDIA 預付認股權證 2.0）＋2H 期後可轉債淨現金 5.68（2026-08）
A37: Ⓕ 1H26 實際借款（融資） | B37: US$bn | C37: =輸入與假設!$C$183 -> 4.3375 | D37: =0 -> 0 | E37: =0 -> 0 | F37: =0 -> 0 | G37: =0 -> 0 | I37: 季報：H1 借款 4.3375（2026-03 可轉債）
A38: Ⓖ 瀑布：新債（額度＋資產層） | B38: US$bn | C38: =C66 -> 1.37982 | D38: =D66 -> 9.691341 | E38: =E66 -> 1.049641 | F38: =F66 -> 0 | G38: =G66 -> 0 | I38: 見下方「期前融資瀑布」
A39: Ⓖ2 瀑布：可轉債 | B39: US$bn | C39: =C69 -> 0 | D39: =D69 -> 5 | E39: =E69 -> 5 | F39: =F69 -> 5 | G39: =G69 -> 5 | I39: 資產擔保融資用罄後、股權之前；每年不超過可轉債上限（v0.1b）
A40: Ⓗ 瀑布：股權募資 | B40: US$bn | C40: =C72 -> 0 | D40: =D72 -> 3.4021798 | E40: =E72 -> 8.7866316 | F40: =F72 -> 6.1147054 | G40: =G72 -> 15.431971 | I40: 債務與可轉債用罄後的殘差；每年不超過股權吸收上限
A41: Ⓘ 瀑布：高息債（股權上限溢出） | B41: US$bn | C41: =C73 -> 0 | D41: =D73 -> 0 | E41: =E73 -> 0 | F41: =F73 -> 0 | G41: =G73 -> 0.16760739 | I41: 股權超過每年上限的部分；不受 backlog 上限約束
...

Sheet 季度追蹤
A1: 季度追蹤 — 焦點季的模型／共識／指引／實際與差距（由年度模型拆分；只用於追蹤，不影響年度數字與目標價）
A2: 設定與實際數在『輸入與假設』J 區，共識在 I 區；缺資料顯示「不適用」，實際數空白＝待公布。差距超過門檻的項目附差異原因（拆法＝所屬期間合計差距在門檻內）。第 2 區為 6 季路徑與拆分明細（預設收合）。
A4: 1｜焦點季（『輸入與假設』J 區選擇）：模型／共識／指引／實際與差距
A5: 指標 | B5: 單位 | C5: 模型 | D5: 共識 | E5: 模型 vs 共識 | F5: 指引（低） | G5: 指引（高） | H5: 模型 vs 指引中點 | I5: 實際 | J5: 實際 vs 模型 | K5: 實際 vs 共識 | L5: 實際 vs 指引中點 | M5: 利潤率 pt：模型 vs 共識 | N5: 模型 vs 指引 | O5: 實際 vs 模型 | P5: 實際 vs 共識 | Q5: 實際 vs 指引
A6: 焦點｜營收 | B6: US$bn | C6: =INDEX($C$22:$H$22,輸入與假設!$C$279) -> 0.8785 | D6: =INDEX($C$32:$H$32,輸入與假設!$C$279) -> 0.8994 | E6: =INDEX($C$42:$H$42,輸入與假設!$C$279) -> -0.023237714 | F6: 不適用 | G6: 不適用 | H6: =INDEX($C$43:$H$43,輸入與假設!$C$279) -> 不適用 | I6: =IF(ISNUMBER(INDEX($C$36:$H$36,輸入與假設!$C$279)),INDEX($C$36:$H$36,輸入與假設!$C$279),"待公布") -> 待公布 | J6: =INDEX($C$44:$H$44,輸入與假設!$C$279) | K6: =INDEX($C$45:$H$45,輸入與假設!$C$279) | L6: =INDEX($C$46:$H$46,輸入與假設!$C$279)
A7: 焦點｜調整後 EBITDA | B7: US$bn | C7: =INDEX($C$28:$H$28,輸入與假設!$C$279) -> 0.39232984 | D7: =INDEX($C$33:$H$33,輸入與假設!$C$279) -> 0.3624 | E7: =INDEX($C$47:$H$47,輸入與假設!$C$279) -> 0.029929844 | F7: 不適用 | G7: 不適用 | H7: =INDEX($C$48:$H$48,輸入與假設!$C$279) -> 不適用 | I7: =IF(ISNUMBER(INDEX($C$37:$H$37,輸入與假設!$C$279)),INDEX($C$37:$H$37,輸入與假設!$C$279),"待公布") -> 待公布 | J7: =INDEX($C$49:$H$49,輸入與假設!$C$279) | K7: =INDEX($C$50:$H$50,輸入與假設!$C$279) | L7: =INDEX($C$51:$H$51,輸入與假設!$C$279) | M7: =INDEX($C$52:$H$52,輸入與假設!$C$279) -> 0.043655312 | N7: =INDEX($C$53:$H$53,輸入與假設!$C$279) -> 不適用 | O7: =INDEX($C$54:$H$54,輸入與假設!$C$279) | P7: =INDEX($C$55:$H$55,輸入與假設!$C$279) | Q7: =INDEX($C$56:$H$56,輸入與假設!$C$279)
A8: 焦點｜EBITDA 率 | B8: % | C8: =INDEX($C$27:$H$27,輸入與假設!$C$279) -> 0.4465906 | D8: =INDEX($C$34:$H$34,輸入與假設!$C$279) -> 0.40293529 | E8: =INDEX($C$57:$H$57,輸入與假設!$C$279) -> 0.043655312 | F8: 不適用 | G8: 不適用 | H8: =INDEX($C$58:$H$58,輸入與假設!$C$279) -> 不適用 | I8: =IF(ISNUMBER(INDEX($C$38:$H$38,輸入與假設!$C$279)),INDEX($C$38:$H$38,輸入與假設!$C$279),"待公布") -> 待公布 | J8: =INDEX($C$59:$H$59,輸入與假設!$C$279) | K8: =INDEX($C$60:$H$60,輸入與假設!$C$279) | L8: =INDEX($C$61:$H$61,輸入與假設!$C$279)
A9: 焦點｜調整後營業利益 | B9: US$bn | C9: =INDEX($C$30:$H$30,輸入與假設!$C$279) -> -0.57688641 | D9: 不適用 | E9: =INDEX($C$62:$H$62,輸入與假設!$C$279) -> 不適用 | F9: 不適用 | G9: 不適用 | H9: =INDEX($C$63:$H$63,輸入與假設!$C$279) -> 不適用 | I9: =IF(ISNUMBER(INDEX($C$39:$H$39,輸入與假設!$C$279)),INDEX($C$39:$H$39,輸入與假設!$C$279),"待公布") -> 待公布 | J9: =INDEX($C$64:$H$64,輸入與假設!$C$279) | K9: =INDEX($C$65:$H$65,輸入與假設!$C$279) | L9: =INDEX($C$66:$H$66,輸入與假設!$C$279) | M9: =INDEX($C$67:$H$67,輸入與假設!$C$279) -> 不適用 | N9: =INDEX($C$68:$H$68,輸入與假設!$C$279) -> 不適用 | O9: =INDEX($C$69:$H$69,輸入與假設!$C$279) | P9: =INDEX($C$70:$H$70,輸入與假設!$C$279) | Q9: =INDEX($C$71:$H$71,輸入與假設!$C$279)
A10: 焦點｜CapEx（毛額） | B10: US$bn | C10: =INDEX($C$31:$H$31,輸入與假設!$C$279) -> 10.46965 | D10: 不適用 | E10: =INDEX($C$72:$H$72,輸入與假設!$C$279) -> 不適用 | F10: 不適用 | G10: 不適用 | H10: =INDEX($C$73:$H$73,輸入與假設!$C$279) -> 不適用 | I10: =IF(ISNUMBER(INDEX($C$40:$H$40,輸入與假設!$C$279)),INDEX($C$40:$H$40,輸入與假設!$C$279),"待公布") -> 待公布 | J10: =INDEX($C$74:$H$74,輸入與假設!$C$279) | K10: =INDEX($C$75:$H$75,輸入與假設!$C$279) | L10: =INDEX($C$76:$H$76,輸入與假設!$C$279)
A11: 焦點｜季末已連網 MW-IT | B11: MW | C11: =INDEX($C$19:$H$19,輸入與假設!$C$279) -> 605 | D11: 不適用 | E11: =INDEX($C$77:$H$77,輸入與假設!$C$279) -> 不適用 | F11: 不適用 | G11: 不適用 | H11: =INDEX($C$78:$H$78,輸入與假設!$C$279) -> 不適用 | I11: =IF(ISNUMBER(INDEX($C$41:$H$41,輸入與假設!$C$279)),INDEX($C$41:$H$41,輸入與假設!$C$279),"待公布") -> 待公布 | J11: =INDEX($C$79:$H$79,輸入與假設!$C$279) | K11: =INDEX($C$80:$H$80,輸入與假設!$C$279) | L11: =INDEX($C$81:$H$81,輸入與假設!$C$279)
A12: 焦點｜季度 | C12: =INDEX($C$16:$H$16,輸入與假設!$C$279) -> Q3'26
A13: 焦點｜差異原因 | C13: =IF(INDEX($C$118:$H$118,輸入與假設!$C$279)="","無（差距皆在 "&IF(ROUND(ABS(輸入與假設!$C$273)*100,4)=INT(ROUND(ABS(輸入與假設!$C$273)*100,4)),TEXT(ROUND(ABS(輸入與假設!$C$273)*100,4),"0"),TEXT(ROUND(ABS(輸入與假設!$C$273)*100,4),"0.0"))&"%"&" 以內）",INDEX($C$118:$H$118,輸入與假設!$C$279)) -> 調整後 EBITDA vs 共識 +$0.03bn／+4.4pt：拆法（分配 +$0.088bn（Q3'26 占 2H26 42.3%，共識合計 32.9%）；水準 −$0.058bn）
A15: 2｜6 季路徑、共識、指引、實際與差距（明細；第 1 區以焦點季引用本區）
A16: 項目 | B16: 單位 | C16: Q3'26 | D16: Q4'26 | E16: Q1'27 | F16: Q2'27 | G16: Q3'27 | H16: Q4'27
A17: 所屬期間 | C17: =輸入與假設!C$278 -> 1 | D17: =輸入與假設!D$278 -> 1 | E17: =輸入與假設!E$278 -> 2 | F17: =輸入與假設!F$278 -> 2 | G17: =輸入與假設!G$278 -> 2 | H17: =輸入與假設!H$278 -> 2 | J17: 1＝2H26、2＝FY27
A18: 季序 | C18: 1 | D18: 2 | E18: 3 | F18: 4 | G18: 5 | H18: 6 | J18: EBITDA 率直線的 x 軸
A19: 季末已連網 MW-IT（模型） | B19: MW | C19: =輸入與假設!$C$281+(輸入與假設!C$39-輸入與假設!$C$281)*1/2 -> 605 | D19: =輸入與假設!$C$281+(輸入與假設!C$39-輸入與假設!$C$281)*2/2 -> 750 | E19: =輸入與假設!C$39+(輸入與假設!D$39-輸入與假設!C$39)*1/4 -> 895 | F19: =輸入與假設!C$39+(輸入與假設!D$39-輸入與假設!C$39)*2/4 -> 1040 | G19: =輸入與假設!C$39+(輸入與假設!D$39-輸入與假設!C$39)*3/4 -> 1185 | H19: =輸入與假設!C$39+(輸入與假設!D$39-輸入與假設!C$39)*4/4 -> 1330 | J19: 期初與期末 Accepted 之間線性內插；第 1 期起點見 J 區
A20: 平均在役 MW（Billable，拆分依據） | B20: MW | C20: =輸入與假設!$C$32+(輸入與假設!C$40-輸入與假設!$C$32)*1/4 -> 185 | D20: =輸入與假設!$C$32+(輸入與假設!C$40-輸入與假設!$C$32)*3/4 -> 287 | E20: =輸入與假設!C$40+(輸入與假設!D$40-輸入與假設!C$40)*1/8 -> 408.75 | F20: =輸入與假設!C$40+(輸入與假設!D$40-輸入與假設!C$40)*3/8 -> 550.25 | G20: =輸入與假設!C$40+(輸入與假設!D$40-輸入與假設!C$40)*5/8 -> 691.75 | H20: =輸入與假設!C$40+(輸入與假設!D$40-輸入與假設!C$40)*7/8 -> 833.25 | J20: 期初與期末 Billable 之間線性內插的季平均
A21: 季內新增 Accepted MW | B21: MW | C21: =C19-輸入與假設!$C$281 -> 145 | D21: =D19-C19 -> 145 | E21: =E19-輸入與假設!C$39 -> 145 | F21: =F19-E19 -> 145 | G21: =G19-F19 -> 145 | H21: =H19-G19 -> 145 | J21: CapEx 拆分依據
A22: 營收（模型） | B22: US$bn | C22: =輸入與假設!$C$280+1*(損益!C8-2*輸入與假設!$C$280)/3 -> 0.8785 | D22: =輸入與假設!$C$280+2*(損益!C8-2*輸入與假設!$C$280)/3 -> 1.1747 | E22: =損益!D8*E20/(E20+F20+G20+H20) -> 1.7780625 | F22: =損益!D8*F20/(E20+F20+G20+H20) -> 2.3935875 | G22: =損益!D8*G20/(E20+F20+G20+H20) -> 3.0091125 | H22: =損益!D8*H20/(E20+F20+G20+H20) -> 3.6246375 | J22: 拆分方法見『輸入與假設』J 區與 HTML「拆分方法」
A23: EBITDA 率直線｜各期營收合計 S | C23: =C22+D22 -> 2.0532 | D23: =E22+F22+G22+H22 -> 10.8054 | J23: 欄＝期間（2H26、FY27）
A24: EBITDA 率直線｜營收 × 季序合計 T | C24: =C22*C18+D22*D18 -> 3.2279 | D24: =E22*E18+F22*F18+G22*G18+H22*H18 -> 51.701925 | J24: 欄＝期間（2H26、FY27）
A25: EBITDA 率直線｜年度 EBITDA E | C25: =損益!C19 -> 0.9264404 | D25: =損益!D19 -> 5.1563473 | J25: 欄＝期間（2H26、FY27）
A26: EBITDA 率直線｜截距 a／斜率 b | C26: =(C25*D24-C24*D25)/(C23*D24-C24*D23) -> 0.43850294 | D26: =(C23*D25-D23*C25)/(C23*D24-C24*D23) -> 0.0080876617 | J26: 解兩式：Σ營收×(a＋b×季序)＝各期年度 EBITDA
A27: EBITDA 率（模型） | B27: % | C27: =$C$26+$D$26*C18 -> 0.4465906 | D27: =$C$26+$D$26*D18 -> 0.45467826 | E27: =$C$26+$D$26*E18 -> 0.46276593 | F27: =$C$26+$D$26*F18 -> 0.47085359 | G27: =$C$26+$D$26*G18 -> 0.47894125 | H27: =$C$26+$D$26*H18 -> 0.48702891 | J27: 跨季一條直線，季度 EBITDA 加總＝年度
A28: 調整後 EBITDA（模型） | B28: US$bn | C28: =C22*C27 -> 0.39232984 | D28: =D22*D27 -> 0.53411056 | E28: =E22*E27 -> 0.82282674 | F28: =F22*F27 -> 1.1270293 | G28: =G22*G27 -> 1.4411881 | H28: =H22*H27 -> 1.7653033
A29: 車隊折舊（模型） | B29: US$bn | C29: =(輸入與假設!C$88+輸入與假設!C$86*1/4)/輸入與假設!$C$65*輸入與假設!C$37/2 -> 0.96921625 | D29: =(輸入與假設!C$88+輸入與假設!C$86*3/4)/輸入與假設!$C$65*輸入與假設!C$37/2 -> 1.4926987 | E29: =(輸入與假設!D$88+輸入與假設!D$86*1/8)/輸入與假設!$C$65*輸入與假設!D$37/4 -> 1.9366325 | F29: =(輸入與假設!D$88+輸入與假設!D$86*3/8)/輸入與假設!$C$65*輸入與假設!D$37/4 -> 2.3010175 | G29: =(輸入與假設!D$88+輸入與假設!D$86*5/8)/輸入與假設!$C$65*輸入與假設!D$37/4 -> 2.6654025 | H29: =(輸入與假設!D$88+輸入與假設!D$86*7/8)/輸入與假設!$C$65*輸入與假設!D$37/4 -> 3.0297875 | J29: 依期內平均 PP&E（與年度車隊折舊公式相同）
A30: 調整後營業利益（模型） | B30: US$bn | C30: =C28-C29 -> -0.57688641 | D30: =D28-D29 -> -0.95858819 | E30: =E28-E29 -> -1.1138058 | F30: =F28-F29 -> -1.1739882 | G30: =G28-G29 -> -1.2242144 | H30: =H28-H29 -> -1.2644842 | J30: ＝調整後 EBITDA − 車隊折舊（未扣 SBC）
A31: CapEx（毛額）（模型） | B31: US$bn | C31: =IF((C21+D21)>0,輸入與假設!C$90*C21/(C21+D21),輸入與假設!C$90/2) -> 10.46965 | D31: =IF((C21+D21)>0,輸入與假設!C$90*D21/(C21+D21),輸入與假設!C$90/2) -> 10.46965 | E31: =IF((E21+F21+G21+H21)>0,輸入與假設!D$90*E21/(E21+F21+G21+H21),輸入與假設!D$90/4) -> 7.2877 | F31: =IF((E21+F21+G21+H21)>0,輸入與假設!D$90*F21/(E21+F21+G21+H21),輸入與假設!D$90/4) -> 7.2877 | G31: =IF((E21+F21+G21+H21)>0,輸入與假設!D$90*G21/(E21+F21+G21+H21),輸入與假設!D$90/4) -> 7.2877 | H31: =IF((E21+F21+G21+H21)>0,輸入與假設!D$90*H21/(E21+F21+G21+H21),輸入與假設!D$90/4) -> 7.2877 | J31: 依季內新增 Accepted MW
A32: 共識｜營收 | B32: US$bn | C32: =IF(ISNUMBER(輸入與假設!$C$244),輸入與假設!$C$244,"不適用") -> 0.8994 | D32: =IF(ISNUMBER(輸入與假設!$D$244),輸入與假設!$D$244,"不適用") -> 1.521 | E32: 不適用 | F32: 不適用 | G32: 不適用 | H32: 不適用 | J32: I 區季度共識 [Interested-party]
A33: 共識｜調整後 EBITDA | B33: US$bn | C33: =IF(ISNUMBER(輸入與假設!$C$245),輸入與假設!$C$245,"不適用") -> 0.3624 | D33: =IF(ISNUMBER(輸入與假設!$D$245),輸入與假設!$D$245,"不適用") -> 0.74 | E33: 不適用 | F33: 不適用 | G33: 不適用 | H33: 不適用 | J33: I 區季度共識 [Interested-party]
A34: 共識｜EBITDA 率 [Derived] | B34: % | C34: =IF(AND(ISNUMBER(輸入與假設!$C$245),ISNUMBER(輸入與假設!$C$244)),輸入與假設!$C$245/輸入與假設!$C$244,"不適用") -> 0.40293529 | D34: =IF(AND(ISNUMBER(輸入與假設!$D$245),ISNUMBER(輸入與假設!$D$244)),輸入與假設!$D$245/輸入與假設!$D$244,"不適用") -> 0.48652202 | E34: 不適用 | F34: 不適用 | G34: 不適用 | H34: 不適用 | J34: ＝共識 EBITDA ÷ 共識營收
A35: 共識 EBIT（口徑未揭露） | B35: US$bn | C35: =IF(ISNUMBER(輸入與假設!$C$246),輸入與假設!$C$246,"不適用") -> -0.2239 | D35: =IF(ISNUMBER(輸入與假設!$D$246),輸入與假設!$D$246,"不適用") -> -0.1615 | E35: 不適用 | F35: 不適用 | G35: 不適用 | H35: 不適用 | J35: 口徑未揭露：只列不比較
A36: 實際｜營收 | B36: US$bn | C36: =IF(ISNUMBER(輸入與假設!C$282),輸入與假設!C$282,"") | D36: =IF(ISNUMBER(輸入與假設!D$282),輸入與假設!D$282,"") | E36: =IF(ISNUMBER(輸入與假設!E$282),輸入與假設!E$282,"") | F36: =IF(ISNUMBER(輸入與假設!F$282),輸入與假設!F$282,"") | G36: =IF(ISNUMBER(輸入與假設!G$282),輸入與假設!G$282,"") | H36: =IF(ISNUMBER(輸入與假設!H$282),輸入與假設!H$282,"")
A37: 實際｜調整後 EBITDA | B37: US$bn | C37: =IF(ISNUMBER(輸入與假設!C$283),輸入與假設!C$283,"") | D37: =IF(ISNUMBER(輸入與假設!D$283),輸入與假設!D$283,"") | E37: =IF(ISNUMBER(輸入與假設!E$283),輸入與假設!E$283,"") | F37: =IF(ISNUMBER(輸入與假設!F$283),輸入與假設!F$283,"") | G37: =IF(ISNUMBER(輸入與假設!G$283),輸入與假設!G$283,"") | H37: =IF(ISNUMBER(輸入與假設!H$283),輸入與假設!H$283,"")
A38: 實際｜EBITDA 率 | B38: % | C38: =IF(AND(ISNUMBER(輸入與假設!C$283),ISNUMBER(輸入與假設!C$282)),輸入與假設!C$283/輸入與假設!C$282,"") | D38: =IF(AND(ISNUMBER(輸入與假設!D$283),ISNUMBER(輸入與假設!D$282)),輸入與假設!D$283/輸入與假設!D$282,"") | E38: =IF(AND(ISNUMBER(輸入與假設!E$283),ISNUMBER(輸入與假設!E$282)),輸入與假設!E$283/輸入與假設!E$282,"") | F38: =IF(AND(ISNUMBER(輸入與假設!F$283),ISNUMBER(輸入與假設!F$282)),輸入與假設!F$283/輸入與假設!F$282,"") | G38: =IF(AND(ISNUMBER(輸入與假設!G$283),ISNUMBER(輸入與假設!G$282)),輸入與假設!G$283/輸入與假設!G$282,"") | H38: =IF(AND(ISNUMBER(輸入與假設!H$283),ISNUMBER(輸入與假設!H$282)),輸入與假設!H$283/輸入與假設!H$282,"") | J38: ＝實際 EBITDA ÷ 實際營收
A39: 實際｜調整後營業利益 | B39: US$bn | C39: =IF(ISNUMBER(輸入與假設!C$284),輸入與假設!C$284,"") | D39: =IF(ISNUMBER(輸入與假設!D$284),輸入與假設!D$284,"") | E39: =IF(ISNUMBER(輸入與假設!E$284),輸入與假設!E$284,"") | F39: =IF(ISNUMBER(輸入與假設!F$284),輸入與假設!F$284,"") | G39: =IF(ISNUMBER(輸入與假設!G$284),輸入與假設!G$284,"") | H39: =IF(ISNUMBER(輸入與假設!H$284),輸入與假設!H$284,"")
A40: 實際｜CapEx（毛額） | B40: US$bn | C40: =IF(ISNUMBER(輸入與假設!C$285),輸入與假設!C$285,"") | D40: =IF(ISNUMBER(輸入與假設!D$285),輸入與假設!D$285,"") | E40: =IF(ISNUMBER(輸入與假設!E$285),輸入與假設!E$285,"") | F40: =IF(ISNUMBER(輸入與假設!F$285),輸入與假設!F$285,"") | G40: =IF(ISNUMBER(輸入與假設!G$285),輸入與假設!G$285,"") | H40: =IF(ISNUMBER(輸入與假設!H$285),輸入與假設!H$285,"")
A41: 實際｜季末 connected power（IT） | B41: MW | C41: =IF(ISNUMBER(輸入與假設!C$286),輸入與假設!C$286,"") | D41: =IF(ISNUMBER(輸入與假設!D$286),輸入與假設!D$286,"") | E41: =IF(ISNUMBER(輸入與假設!E$286),輸入與假設!E$286,"") | F41: =IF(ISNUMBER(輸入與假設!F$286),輸入與假設!F$286,"") | G41: =IF(ISNUMBER(輸入與假設!G$286),輸入與假設!G$286,"") | H41: =IF(ISNUMBER(輸入與假設!H$286),輸入與假設!H$286,"")
A42: 差距｜營收｜模型 vs 共識 | B42: % | C42: =IF(AND(ISNUMBER(C22),ISNUMBER(C32),C32<>0),C22/(C32)-1,"不適用") -> -0.023237714 | D42: =IF(AND(ISNUMBER(D22),ISNUMBER(D32),D32<>0),D22/(D32)-1,"不適用") -> -0.22767916 | E42: =IF(AND(ISNUMBER(E22),ISNUMBER(E32),E32<>0),E22/(E32)-1,"不適用") -> 不適用 | F42: =IF(AND(ISNUMBER(F22),ISNUMBER(F32),F32<>0),F22/(F32)-1,"不適用") -> 不適用 | G42: =IF(AND(ISNUMBER(G22),ISNUMBER(G32),G32<>0),G22/(G32)-1,"不適用") -> 不適用 | H42: =IF(AND(ISNUMBER(H22),ISNUMBER(H32),H32<>0),H22/(H32)-1,"不適用") -> 不適用
...

Sheet 運營_產能與收入
A1: 產能與收入 — 已連網 MW × 每 MW 年收入（RPO 排程只作對照與產能瓶頸旗標）
A2: 兩條線獨立產生後相減：排程>容量→瓶頸（收不到）；容量>排程→剩餘產能（要靠新簽約賣掉）
A3: FY26 欄口徑：MW 為年底存量；標示「（模型期）」的收入列只含 2026 下半年——RPO 桶自 2026-06-30 起算，1H 收入已實現、不再受產能約束。1H 實際單列，兩者相加即 FY26 全年（見本頁「FY26 全年」列）。
A5: 項目 | B5: 單位 | C5: FY26 | D5: FY27 | E5: FY28 | F5: FY29 | G5: FY30 | I5: 公式／來源說明
A6: 模型期間 | C6: ="2026-07-01~12-31" -> 2026-07-01~12-31 | D6: ="2027 全年" -> 2027 全年 | E6: ="2028 全年" -> 2028 全年 | F6: ="2029 全年" -> 2029 全年 | G6: ="2030 全年" -> 2030 全年 | I6: FY26 的模型期只有下半年；1H 已實現的營收單列於下方
A7: 模型期長度（年） | C7: =輸入與假設!C$37 -> 0.5 | D7: =輸入與假設!D$37 -> 1 | E7: =輸入與假設!E$37 -> 1 | F7: =輸入與假設!F$37 -> 1 | G7: =輸入與假設!G$37 -> 1 | I7: 只用於下方三處：容量上限、電力、維護——把年率換算成該期金額
A8: （A）機房：容量上限
A9: Accepted MW（已驗收，單調不減） | B9: MW | C9: =MAX(0,輸入與假設!C$39) -> 750 | D9: =MAX(輸入與假設!D$39,C9) -> 1330 | E9: =MAX(輸入與假設!E$39,D9) -> 1910 | F9: =MAX(輸入與假設!F$39,E9) -> 2490 | G9: =MAX(輸入與假設!G$39,F9) -> 3070 | I9: 引擎規則：不得低於前期（產能不會消失）
A10: Billable MW（上限為 Accepted） | B10: MW | C10: =MIN(MAX(0,輸入與假設!C$40),C9) -> 338 | D10: =MIN(MAX(0,輸入與假設!D$40),D9) -> 904 | E10: =MIN(MAX(0,輸入與假設!E$40),E9) -> 1719 | F10: =MIN(MAX(0,輸入與假設!F$40),F9) -> 2241 | G10: =MIN(MAX(0,輸入與假設!G$40),G9) -> 2763 | I10: 引擎規則：可計費不得超過已驗收
A11: 期初在役 MW | B11: MW | C11: =輸入與假設!$C$32 -> 134 | D11: =C10 -> 338 | E11: =D10 -> 904 | F11: =E10 -> 1719 | G11: =F10 -> 2241 | I11: 前期期末＝本期期初
A12: 平均在役 MW（FY26 欄為下半年平均） | B12: MW | C12: =IF(輸入與假設!$C$33=1,(C11+C10)/2,C10) -> 236 | D12: =IF(輸入與假設!$C$33=1,(D11+D10)/2,D10) -> 621 | E12: =IF(輸入與假設!$C$33=1,(E11+E10)/2,E10) -> 1311.5 | F12: =IF(輸入與假設!$C$33=1,(F11+F10)/2,F10) -> 1980 | G12: =IF(輸入與假設!$C$33=1,(G11+G10)/2,G10) -> 2502 | I12: 開關在輸入頁：1＝(期初+期末)/2，0＝期末全期化
A13: 利用率 | B13: % | C13: =輸入與假設!C$41 -> 1 | D13: =輸入與假設!D$41 -> 1 | E13: =輸入與假設!E$41 -> 1 | F13: =輸入與假設!F$41 -> 1 | G13: =輸入與假設!G$41 -> 1
A14: 每 MW 年收入 | B14: US$bn/MW | C14: =輸入與假設!C$42 -> 0.0174 | D14: =輸入與假設!D$42 -> 0.0174 | E14: =輸入與假設!E$42 -> 0.0174 | F14: =輸入與假設!F$42 -> 0.0174 | G14: =輸入與假設!G$42 -> 0.0174
A15: 容量上限（模型期最多能交付的收入） | B15: US$bn | C15: =C12*輸入與假設!C$42*輸入與假設!$C$35*輸入與假設!C$41*C7 -> 2.0532 | D15: =D12*輸入與假設!D$42*輸入與假設!$C$35*輸入與假設!D$41*D7 -> 10.8054 | E15: =E12*輸入與假設!E$42*輸入與假設!$C$35*輸入與假設!E$41*E7 -> 22.8201 | F15: =F12*輸入與假設!F$42*輸入與假設!$C$35*輸入與假設!F$41*F7 -> 34.452 | G15: =G12*輸入與假設!G$42*輸入與假設!$C$35*輸入與假設!G$41*G7 -> 43.5348 | I15: ＝平均在役 MW × 每 MW 年收入 × 利用率 × 期間係數。只看機房，不看合約
A16: （B）合約：排程 RPO
A17: 排程 RPO（模型期，依季報桶分攤） | B17: US$bn | C17: =(輸入與假設!$C$26+輸入與假設!$C$27)*(輸入與假設!C$38/輸入與假設!$C$29)*輸入與假設!$C$28 -> 3.374154 | D17: =(輸入與假設!$C$26+輸入與假設!$C$27)*(輸入與假設!D$38/輸入與假設!$C$29)*輸入與假設!$C$28 -> 6.748308 | E17: =(輸入與假設!$C$26+輸入與假設!$C$27)*(輸入與假設!E$38/輸入與假設!$C$29)*輸入與假設!$C$28 -> 7.123214 | F17: =(輸入與假設!$C$26+輸入與假設!$C$27)*(輸入與假設!F$38/輸入與假設!$C$29)*輸入與假設!$C$28 -> 7.49812 | G17: =(輸入與假設!$C$26+輸入與假設!$C$27)*(輸入與假設!G$38/輸入與假設!$C$29)*輸入與假設!$C$28 -> 5.998496 | I17: ＝(6/30 RPO＋Q3 新增)×本期權重÷權重合計×五期認列比例。只看合約，不看機房
A18: （C）兩條線相減
A19: 產能瓶頸（模型期：排程 − 容量） | B19: US$bn | C19: =MAX(0,C17-C15) -> 1.320954 | D19: =MAX(0,D17-D15) -> 0 | E19: =MAX(0,E17-E15) -> 0 | F19: =MAX(0,F17-F15) -> 0 | G19: =MAX(0,G17-G15) -> 0 | I19: 合約有、機房沒有 → 本期收不到，且不遞延到下期（保守處理）
A20: 期初 RPO 轉換收入（模型期） | B20: US$bn | C20: =C17-C19 -> 2.0532 | D20: =D17-D19 -> 6.748308 | E20: =E17-E19 -> 7.123214 | F20: =F17-F19 -> 7.49812 | G20: =G17-G19 -> 5.998496 | I20: ＝排程 − 瓶頸。當瓶頸>0 時，此值恆等於容量上限
A21: 未被期初 RPO 占用的產能 | B21: US$bn | C21: =MAX(0,C15-C17) -> 0 | D21: =MAX(0,D15-D17) -> 4.057092 | E21: =MAX(0,E15-E17) -> 15.696886 | F21: =MAX(0,F15-F17) -> 26.95388 | G21: =MAX(0,G15-G17) -> 37.536304 | I21: 容量 − 排程。機房有、期初合約沒占滿 → 要靠新簽約
A22: 新產能簽約率 | B22: % | C22: =IF(輸入與假設!$C$34="mw",1,輸入與假設!C$43) -> 1 | D22: =IF(輸入與假設!$C$34="mw",1,輸入與假設!D$43) -> 1 | E22: =IF(輸入與假設!$C$34="mw",1,輸入與假設!E$43) -> 1 | F22: =IF(輸入與假設!$C$34="mw",1,輸入與假設!F$43) -> 1 | G22: =IF(輸入與假設!$C$34="mw",1,輸入與假設!G$43) -> 1 | I22: MW 驅動時固定 100%
A23: 新簽約收入 | B23: US$bn | C23: =C21*C22 -> 0 | D23: =D21*D22 -> 4.057092 | E23: =E21*E22 -> 15.696886 | F23: =F21*F22 -> 26.95388 | G23: =G21*G22 -> 37.536304 | I23: 超出期初 RPO 的產能收入（MW 驅動，簽約率 100%）
A24: 未售產能（浪費） | B24: US$bn | C24: =MAX(0,C15-C20-C23) -> 0 | D24: =MAX(0,D15-D20-D23) -> 0 | E24: =MAX(0,E15-E20-E23) -> 0 | F24: =MAX(0,F15-F20-F23) -> 0 | G24: =MAX(0,G15-G20-G23) -> 0 | I24: 蓋好但賣不掉（MW 驅動時為 0）
A25: 損益用算力收入（模型期＝RPO 轉換＋新簽約） | B25: US$bn | C25: =C20+C23 -> 2.0532 | D25: =D20+D23 -> 10.8054 | E25: =E20+E23 -> 22.8201 | F25: =F20+F23 -> 34.452 | G25: =G20+G23 -> 43.5348 | I25: 損益與評價頁的算力收入由此連結，確保現金與損益同一組數字
A26: 核對：算力收入 − 平均在役 MW × 每 MW × 利用率 × 期間 | B26: US$bn | C26: =C25-C12*輸入與假設!C$42*輸入與假設!$C$35*輸入與假設!C$41*C7 -> 0 | D26: =D25-D12*輸入與假設!D$42*輸入與假設!$C$35*輸入與假設!D$41*D7 -> 0 | E26: =E25-E12*輸入與假設!E$42*輸入與假設!$C$35*輸入與假設!E$41*E7 -> 0 | F26: =F25-F12*輸入與假設!F$42*輸入與假設!$C$35*輸入與假設!F$41*F7 -> 0 | G26: =G25-G12*輸入與假設!G$42*輸入與假設!$C$35*輸入與假設!G$41*G7 -> 0 | I26: MW 驅動時應為 0：營收可追溯為 MW × 每 MW 年收入 × 利用率（v0.1b）
A27: 1H26 實際營收（季報，已實現） | B27: US$bn | C27: =輸入與假設!$C$189 -> 0.9813 | D27: =0 -> 0 | E27: =0 -> 0 | F27: =0 -> 0 | G27: =0 -> 0 | I27: 2026-01-01 至 06-30 已認列營收。已實現，不受下半年產能約束，故不進入上方的瓶頸計算
A28: FY26 全年總營收（1H 實際＋模型期算力＋服務） | B28: US$bn | C28: =C27+C25+輸入與假設!C$46 -> 3.0345 | D28: =D27+D25+輸入與假設!D$46 -> 10.8054 | E28: =E27+E25+輸入與假設!E$46 -> 22.8201 | F28: =F27+F25+輸入與假設!F$46 -> 34.452 | G28: =G27+G25+輸入與假設!G$46 -> 43.5348 | I28: FY26 欄對照公司全年指引 3.0–3.4；FY27 以後即為該年度總營收
A29: （D）收入 → 現金：三道折扣
A30: 客戶違約率 | B30: % | C30: =輸入與假設!C$44 -> 0.005 | D30: =輸入與假設!D$44 -> 0.01 | E30: =輸入與假設!E$44 -> 0.015 | F30: =輸入與假設!F$44 -> 0.02 | G30: =輸入與假設!G$44 -> 0.025
A31: 回收率 | B31: % | C31: =輸入與假設!C$45 -> 0.5 | D31: =輸入與假設!D$45 -> 0.5 | E31: =輸入與假設!E$45 -> 0.5 | F31: =輸入與假設!F$45 -> 0.5 | G31: =輸入與假設!G$45 -> 0.5
A32: 信用損失（期初 RPO 部分） | B32: US$bn | C32: =C20*輸入與假設!C$44*(1-輸入與假設!C$45) -> 0.005133 | D32: =D20*輸入與假設!D$44*(1-輸入與假設!D$45) -> 0.03374154 | E32: =E20*輸入與假設!E$44*(1-輸入與假設!E$45) -> 0.053424105 | F32: =F20*輸入與假設!F$44*(1-輸入與假設!F$45) -> 0.0749812 | G32: =G20*輸入與假設!G$44*(1-輸入與假設!G$45) -> 0.0749812 | I32: ＝收入 × 違約率 × (1−回收率)
A33: 收現（期初 RPO 部分） | B33: US$bn | C33: =C20-C32 -> 2.048067 | D33: =D20-D32 -> 6.7145665 | E33: =E20-E32 -> 7.0697899 | F33: =F20-F32 -> 7.4231388 | G33: =G20-G32 -> 5.9235148
A34: EBITDA 率（損益與資金共用） | B34: % | C34: =輸入與假設!C$53 -> 0.497 | D34: =輸入與假設!D$53 -> 0.49025 | E34: =輸入與假設!E$53 -> 0.4835 | F34: =輸入與假設!F$53 -> 0.47675 | G34: =輸入與假設!G$53 -> 0.47 | I34: 起始→穩態線性爬升
A35: 模型期總營收（算力＋服務） | B35: US$bn | C35: =C25+輸入與假設!C$46 -> 2.0532 | D35: =D25+輸入與假設!D$46 -> 10.8054 | E35: =E25+輸入與假設!E$46 -> 22.8201 | F35: =F25+輸入與假設!F$46 -> 34.452 | G35: =G25+輸入與假設!G$46 -> 43.5348
A36: EBITDAR 率（EBITDA 率＋租金÷營收） | B36: % | C36: =輸入與假設!C$53+各期收支!C15/MAX(0.01,C35) -> 0.56596552 | D36: =輸入與假設!D$53+各期收支!D15/MAX(0.01,D35) -> 0.55088635 | E36: =輸入與假設!E$53+各期收支!E15/MAX(0.01,E35) -> 0.5283966 | F36: =輸入與假設!F$53+各期收支!F15/MAX(0.01,F35) -> 0.50599515 | G36: =輸入與假設!G$53+各期收支!G15/MAX(0.01,G35) -> 0.49284464 | I36: 租金前的 EBITDA 率。EBITDA 已扣租金，而資金模型把租金列在支出端，所以要加回，避免重複扣除
A37: RPO 現金（可支應資本用途） | B37: US$bn | C37: =C33*C36 -> 1.1591353 | D37: =D33*D36 -> 3.698963 | E37: =E33*E36 -> 3.7356529 | F37: =F33*F36 -> 3.7560722 | G37: =G33*G36 -> 2.9193725 | I37: ×EBITDAR 率。租金與利息在支出頁單獨列示
A38: 新簽約現金 | B38: US$bn | C38: =C23*(1-輸入與假設!C$44*(1-輸入與假設!C$45))*C36 -> 0 | D38: =D23*(1-輸入與假設!D$44*(1-輸入與假設!D$45))*D36 -> 2.2238216 | E38: =E23*(1-輸入與假設!E$44*(1-輸入與假設!E$45))*E36 -> 8.2319748 | F38: =F23*(1-輸入與假設!F$44*(1-輸入與假設!F$45))*F36 -> 13.502147 | G38: =G23*(1-輸入與假設!G$44*(1-輸入與假設!G$45))*G36 -> 18.268322 | I38: 同樣扣信用損失、乘 EBITDAR 率
A40: 讀法：FY26（2H）與 FY27 瓶頸>0，合約多於機房；FY28 起反轉，收入愈來愈靠『新簽約收入』這一列。
A41: 把『新產能簽約率』調到 0，就能看到只靠期初 RPO 的資金缺口有多大——這是最重要的一個壓力測試。

Sheet 運營_站點
A1: 站點租賃 — 公司揭露 vs 季報總額（檢驗租金路徑用）
A2: 季報不揭露逐站租金；下表為具名站點（company.json → defaults.sites），有租約金額者用來檢驗『每 MW 年租金』與模型租金路徑是否一致
A4: 站點 | B4: 營運方 | C4: 契約 MW | D4: 已驗收 MW | E4: 合約總值 $bn | F4: 年期 | G4: 年租金 $bn | H4: 每 MW 年租金 $m | I4: 時程 | J4: 季報對應 | K4: 說明
A5: Lappeenranta, Finland | B5: Nebius 自建（自有） | C5: 258 | D5: 0 | E5: 未揭露 | F5: 未揭露 | I5: 2027 | J5: — | K5: Q1 股東信：滿載 310 MW（口徑不明，÷1.2 換 IT 約 258 MW）、2027 可用 [Interested-party]
A6: Independence, Missouri | B6: Nebius 自建（greenfield） | C6: 1000 | D6: 0 | E6: 未揭露 | F6: 未揭露 | I6: 2027 | J6: — | K6: 最高 1.2 GW（÷1.2 換 IT 約 1,000 MW）；預計 2027 營運 [Interested-party]
A7: Pennsylvania | B7: Nebius 自建（自有） | C7: 1000 | D7: 0 | E7: 未揭露 | F7: 未揭露 | I7: 2027 起 | J7: — | K7: 最高 1.2 GW 電力與土地（÷1.2 換 IT 約 1,000 MW）；2027 起分期 [Interested-party]
A8: Vineland, New Jersey | B8: build-to-suit（Microsoft 專用） | C8: 0 | D8: 0 | E8: 未揭露 | F8: 未揭露 | I8: 2026 | J8: — | K8: Microsoft 5 年合約（TCV 約 $17.4B）；Q2 股東信：已交付全部 tranche；MW 未揭露
A9: Alabama | B9: Nebius 自建 | C9: 0 | D9: 0 | E9: 未揭露 | F9: 未揭露 | I9: 2027 | J9: — | K9: 施工中、預計 2027 營運；MW 未揭露
A10: Mäntsälä, Finland | B10: Nebius 自建（既有） | C10: 0 | D10: 0 | E10: 未揭露 | F10: 未揭露 | I10: 既有 | J10: — | K10: 既有自有站點；MW 未揭露
A11: 具名站點合計 | C11: =SUM(C5:C10) -> 2258 | D11: =SUM(D5:D10) -> 0 | E11: =SUM(E5:E10) -> 0 | G11: =SUM(G5:G10) -> 0 | H11: =IF(I11>0,G11/I11*1000,0) -> 0 | I11: =SUMPRODUCT(ISNUMBER(G5:G10)*C5:C10) -> 0 | K11: 加權每 MW 年租金＝具名站點的市場基準（I 欄＝有租約金額站點的契約 MW；沒有時為 0，不適用）
A13: 對帳：具名站點 vs 季報租賃承諾總額
A14: 季報在帳租賃（未折現，已起租） | E14: 2.1751 | K14: company.json → leases.facts.onBal
A15: 季報未起租租賃（未折現） | E15: 12.0541 | K15: company.json → leases.facts.notCommenced
A16: 季報單站按造價計租上限 | E16: 0 | K16: company.json → leases.facts.singleCap（無則 0）
A17: 季報已揭露租賃承諾合計 | E17: =SUM(E14:E16) -> 14.2292 | K17: 未折現金額
A18: 減：具名站點合約總值 | E18: =-E11 -> 0
A19: ＝ 未具名站點（殘差） | E19: =E17+E18 -> 14.2292 | K19: 未具名站點；公司不揭露逐站租金，殘差大是必然
A20: 殘差占季報總額 | E20: =IF(E17<>0,E19/E17,0) -> 1
A22: 檢驗：模型租金路徑 ÷ 在役 MW vs 市場基準
A23: 項目 | B23: 單位 | C23: FY26 | D23: FY27 | E23: FY28 | F23: FY29 | G23: FY30
A24: 模型租金（在帳＋表外） | B24: US$bn | C24: =各期收支!C15 -> 0.1416 | D24: =各期收支!D15 -> 0.65520001 | E24: =各期收支!E15 -> 1.0245448 | F24: =各期收支!F15 -> 1.0075539 | G24: =各期收支!G15 -> 0.99453676
A25: 平均在役 MW（已連網） | B25: MW | C25: =(輸入與假設!C$82+輸入與假設!C$39)/2 -> 460 | D25: =(輸入與假設!D$82+輸入與假設!D$39)/2 -> 1040 | E25: =(輸入與假設!E$82+輸入與假設!E$39)/2 -> 1620 | F25: =(輸入與假設!F$82+輸入與假設!F$39)/2 -> 2200 | G25: =(輸入與假設!G$82+輸入與假設!G$39)/2 -> 2780
A26: 模型期長度（年） | B26: 年 | C26: =輸入與假設!C$37 -> 0.5 | D26: =輸入與假設!D$37 -> 1 | E26: =輸入與假設!E$37 -> 1 | F26: =輸入與假設!F$37 -> 1 | G26: =輸入與假設!G$37 -> 1
A27: 模型每 MW 年租金 | B27: US$m/MW | C27: =C24/C26/C25*1000 -> 0.61565217 | D27: =D24/D26/D25*1000 -> 0.63000001 | E27: =E24/E26/E25*1000 -> 0.63243509 | F27: =F24/F26/F25*1000 -> 0.45797903 | G27: =G24/G26/G25*1000 -> 0.35774704 | K27: FY26 欄只含下半年租金、MW 取全年平均，略有低估
A28: 第三方租賃占比 | C28: 0.25 | K28: 其餘為自建，成本走 CapEx（company.json → leases.facts.share）[Assumed]
A29: 基準租金（MW×市場基準×占比） | B29: US$bn | C29: =C25*運營_站點!$H$11/1000*$C$28*C26 -> 0 | D29: =D25*運營_站點!$H$11/1000*$C$28*D26 -> 0 | E29: =E25*運營_站點!$H$11/1000*$C$28*E26 -> 0 | F29: =F25*運營_站點!$H$11/1000*$C$28*F26 -> 0 | G29: =G25*運營_站點!$H$11/1000*$C$28*G26 -> 0 | K29: 具名站點有租約金額時才有意義；否則為 0
A30: 差額（基準 − 模型） | B30: US$bn | C30: =C29-C24 -> -0.1416 | D30: =D29-D24 -> -0.65520001 | E30: =E29-E24 -> -1.0245448 | F30: =F29-F24 -> -1.0075539 | G30: =G29-G24 -> -0.99453676 | K30: 正值＝模型租金可能低估的金額
A31: 五期差額合計 | C31: =SUM(C30:G30) -> -3.8234355

Sheet 資產負債_既有債務
A1: 債務明細 — 季報（2026-06-30）逐筆＋存量利息推導
A2: 有效利率為現金票息口徑（可轉債＝票息 ÷ 到期累積倍數，本金以到期累積本金計）。本頁算出的存量利息連回『輸入』頁，再進入支出與資金頁
A4: 工具 | B4: 類別 | C4: 到期 | D4: 有效利率 | E4: 6/30 本金 | F4: 年化利息 | I4: 備註
A5: 其他借款（流動） | B5: 追索 | C5: 2026-12 | D5: 0 | E5: 0.0467 | F5: =D5*E5 -> 0 | I5: 資產負債表 Debt, current；附註未逐項拆解 [Interested-party]
A6: 合計（6/30） | E6: =SUM(E5:E5) -> 0.0467 | F6: =SUM(F5:F5) -> 0 | I6: 應等於最新季報本金合計 10.0885（company.json → latestQuarter.debtPrincipal）
A7: 加權有效利率 | D7: =F6/E6 -> 0 | I7: ＝年化利息 ÷ 本金（company.json → debt.instruments 的有效利率）
A9: 評價日後新發可轉債 | D9: 0 | E9: 0 | F9: =D9*E9 -> 0 | I9: company.json → debt.convertible（期後新發；不在五期還本表內，只計利息）
A11: 可轉債逐檔（若轉換法：有效轉換價 < 判斷價 → 視為轉股，不計利息與還本）
A12: 可轉債 | B12: 到期 | C12: 票息 | D12: 原始本金 | E12: 到期累積倍數 | F12: 轉換價 | G12: 到期所屬模型期 | I12: 備註
A13: 2.00% 2029（2025-06） | B13: 2029-06 | C13: 0.02 | D13: 0.0875 | E13: 1.2 | F13: 51.45 | G13: 3 | I13: 2025-06 發行；原始 500 已轉換 12.5、以股換債 400 → 87.5；轉換率 19.4363 股／$1,000 [Verified 20-F／Interested-party 2026-08]
A14: 3.00% 2031（2025-06） | B14: 2031-06 | C14: 0.03 | D14: 0.0875 | E14: 1.25 | F14: 51.45 | G14: 5 | I14: 同上；原始 500 → 87.5 [Verified／Interested-party]
A15: 1.00% 2030（2025-09） | B15: 2030-09 | C15: 0.01 | D15: 1.58125 | E15: 1.15 | F15: 138.75 | G15: 4 | I15: 基本 1,375＋超額配售 206.25；轉換率 7.2072 [Verified 20-F]
A16: 2.75% 2032（2025-09） | B16: 2032-09 | C16: 0.0275 | D16: 1.58125 | E16: 1.15 | F16: 138.75 | G16: 5 | I16: 同上 [Verified 20-F]
A17: 1.25% 2031（2026-03） | B17: 2031-03 | C17: 0.0125 | D17: 2.5875 | E17: 1.2 | F17: 183.22 | G17: 5 | I17: 轉換率 5.4579 [Interested-party Q2 6-K]
A18: 2.625% 2033（2026-03） | B18: 2033-03 | C18: 0.02625 | D18: 1.75 | E18: 1.2 | F18: 180.31 | G18: 5 | I18: 轉換率 5.546 [Interested-party Q2 6-K]
A19: 0.50% 2030（2026-08） | B19: 2030-02 | C19: 0.005 | D19: 3.45 | E19: 1.1 | F19: 313.46 | G19: 4 | I19: 2026-08-24 交割；轉換率 3.1902；有效轉換價（含累積）約 $344.81 [Interested-party]
A20: 4.50% 2034（2026-08） | B20: 2034-02 | C20: 0.045 | D20: 2.3 | E20: 1.25 | F20: 324.65 | G20: 5 | I20: 2026-08-24 交割；轉換率 3.0802；有效轉換價約 $405.82 [Interested-party]
I21: 到期所屬模型期：0＝首期 … 4＝末期、5＝模型期後（建置時依期末日推算）
A23: 可轉債（推導） | C23: 到期本金 | D23: 若轉換股數 | E23: 有效轉換價 | F23: 融資分類 | G23: 評價第一輪 | H23: 評價第二輪 | I23: 說明
A24: =A13 -> 2.00% 2029（2025-06） | C24: =D13*E13 -> 0.105 | D24: =D13/F13 -> 0.0017006803 | E24: =F13*E13 -> 61.74 | F24: =IF(E24<輸入與假設!$C$103,1,0) -> 1 | G24: =IF(E24<輸入與假設!$C$124,1,0) -> 1 | H24: =IF(E24<評價_DCF與目標價!$C$64,1,0) -> 1
A25: =A14 -> 3.00% 2031（2025-06） | C25: =D14*E14 -> 0.109375 | D25: =D14/F14 -> 0.0017006803 | E25: =F14*E14 -> 64.3125 | F25: =IF(E25<輸入與假設!$C$103,1,0) -> 1 | G25: =IF(E25<輸入與假設!$C$124,1,0) -> 1 | H25: =IF(E25<評價_DCF與目標價!$C$64,1,0) -> 0
A26: =A15 -> 1.00% 2030（2025-09） | C26: =D15*E15 -> 1.8184375 | D26: =D15/F15 -> 0.011396396 | E26: =F15*E15 -> 159.5625 | F26: =IF(E26<輸入與假設!$C$103,1,0) -> 1 | G26: =IF(E26<輸入與假設!$C$124,1,0) -> 1 | H26: =IF(E26<評價_DCF與目標價!$C$64,1,0) -> 0
A27: =A16 -> 2.75% 2032（2025-09） | C27: =D16*E16 -> 1.8184375 | D27: =D16/F16 -> 0.011396396 | E27: =F16*E16 -> 159.5625 | F27: =IF(E27<輸入與假設!$C$103,1,0) -> 1 | G27: =IF(E27<輸入與假設!$C$124,1,0) -> 1 | H27: =IF(E27<評價_DCF與目標價!$C$64,1,0) -> 0
A28: =A17 -> 1.25% 2031（2026-03） | C28: =D17*E17 -> 3.105 | D28: =D17/F17 -> 0.014122367 | E28: =F17*E17 -> 219.864 | F28: =IF(E28<輸入與假設!$C$103,1,0) -> 1 | G28: =IF(E28<輸入與假設!$C$124,1,0) -> 1 | H28: =IF(E28<評價_DCF與目標價!$C$64,1,0) -> 0
A29: =A18 -> 2.625% 2033（2026-03） | C29: =D18*E18 -> 2.1 | D29: =D18/F18 -> 0.0097055072 | E29: =F18*E18 -> 216.372 | F29: =IF(E29<輸入與假設!$C$103,1,0) -> 1 | G29: =IF(E29<輸入與假設!$C$124,1,0) -> 1 | H29: =IF(E29<評價_DCF與目標價!$C$64,1,0) -> 0
A30: =A19 -> 0.50% 2030（2026-08） | C30: =D19*E19 -> 3.795 | D30: =D19/F19 -> 0.011006189 | E30: =F19*E19 -> 344.806 | F30: =IF(E30<輸入與假設!$C$103,1,0) -> 0 | G30: =IF(E30<輸入與假設!$C$124,1,0) -> 0 | H30: =IF(E30<評價_DCF與目標價!$C$64,1,0) -> 0
A31: =A20 -> 4.50% 2034（2026-08） | C31: =D20*E20 -> 2.875 | D31: =D20/F20 -> 0.0070845526 | E31: =F20*E20 -> 405.8125 | F31: =IF(E31<輸入與假設!$C$103,1,0) -> 0 | G31: =IF(E31<輸入與假設!$C$124,1,0) -> 0 | H31: =IF(E31<評價_DCF與目標價!$C$64,1,0) -> 0
A32: 合計 | C32: =SUM(C24:C31) -> 15.72625 | D32: =SUM(D24:D31) -> 0.068112769 | I32: 分類 1＝轉股（若轉換法）、0＝債務。融資分類判斷價＝股權發行價；評價第一輪＝現價；第二輪＝MIN(現價, 第一輪加權目標價)
A34: 存量利息推導（本金依季報到期表遞減）
A35: 項目 | B35: 單位 | C35: FY26 | D35: FY27 | E35: FY28 | F35: FY29 | G35: FY30 | I35: 公式／來源說明
A36: 期初本金 | B36: US$bn | C36: =E6 -> 0.0467 | D36: =C38 -> 0 | E36: =D38 -> 0 | F36: =E38 -> 0 | G36: =F38 -> 0 | I36: FY26 期初為 6/30 本金（模型期起點）
A37: 排程還本 | B37: US$bn | C37: =輸入與假設!C$119 -> 0.0467 | D37: =輸入與假設!D$119 -> 0 | E37: =輸入與假設!E$119 -> 0 | F37: =輸入與假設!F$119 -> 0 | G37: =輸入與假設!G$119 -> 0 | I37: 季報到期表
A38: 期末本金 | B38: US$bn | C38: =C36-C37 -> 0 | D38: =D36-D37 -> 0 | E38: =E36-E37 -> 0 | F38: =F36-F37 -> 0 | G38: =G36-G37 -> 0
A39: 平均本金 | B39: US$bn | C39: =(C36+C38)/2 -> 0.02335 | D39: =(D36+D38)/2 -> 0 | E39: =(E36+E38)/2 -> 0 | F39: =(F36+F38)/2 -> 0 | G39: =(G36+G38)/2 -> 0
A40: 存量債務利息 | B40: US$bn | C40: =C39*資產負債_既有債務!$D$7*輸入與假設!C$37 -> 0 | D40: =D39*資產負債_既有債務!$D$7*輸入與假設!D$37 -> 0 | E40: =E39*資產負債_既有債務!$D$7*輸入與假設!E$37 -> 0 | F40: =F39*資產負債_既有債務!$D$7*輸入與假設!F$37 -> 0 | G40: =G39*資產負債_既有債務!$D$7*輸入與假設!G$37 -> 0 | I40: ＝平均本金×加權有效利率×期間長度。限制：假設利率組合不變；可轉債折價攤銷（非現金）不計
A41: 期後新發可轉債利息 | B41: US$bn | C41: =資產負債_既有債務!$F$9*輸入與假設!C$37 -> 0 | D41: =資產負債_既有債務!$F$9*輸入與假設!D$37 -> 0 | E41: =資產負債_既有債務!$F$9*輸入與假設!E$37 -> 0 | F41: =資產負債_既有債務!$F$9*輸入與假設!F$37 -> 0 | G41: =資產負債_既有債務!$F$9*輸入與假設!G$37 -> 0
A42: 可轉債到期還本（債務處理） | B42: US$bn | C42: =IF(輸入與假設!$C$99=1,SUMPRODUCT((1-資產負債_既有債務!$F$24:$F$31)*資產負債_既有債務!$C$24:$C$31*(資產負債_既有債務!$G$13:$G$20=0)),0) -> 0 | D42: =IF(輸入與假設!$C$99=1,SUMPRODUCT((1-資產負債_既有債務!$F$24:$F$31)*資產負債_既有債務!$C$24:$C$31*(資產負債_既有債務!$G$13:$G$20=1)),0) -> 0 | E42: =IF(輸入與假設!$C$99=1,SUMPRODUCT((1-資產負債_既有債務!$F$24:$F$31)*資產負債_既有債務!$C$24:$C$31*(資產負債_既有債務!$G$13:$G$20=2)),0) -> 0 | F42: =IF(輸入與假設!$C$99=1,SUMPRODUCT((1-資產負債_既有債務!$F$24:$F$31)*資產負債_既有債務!$C$24:$C$31*(資產負債_既有債務!$G$13:$G$20=3)),0) -> 0 | G42: =IF(輸入與假設!$C$99=1,SUMPRODUCT((1-資產負債_既有債務!$F$24:$F$31)*資產負債_既有債務!$C$24:$C$31*(資產負債_既有債務!$G$13:$G$20=4)),0) -> 3.795 | I42: 融資分類為債務的可轉債，到期當期以到期累積本金現金還本
A43: 可轉債期末餘額（債務處理） | B43: US$bn | C43: =IF(輸入與假設!$C$99=1,SUMPRODUCT((1-資產負債_既有債務!$F$24:$F$31)*資產負債_既有債務!$C$24:$C$31*(資產負債_既有債務!$G$13:$G$20>0)),SUMPRODUCT((1-資產負債_既有債務!$F$24:$F$31)*資產負債_既有債務!$C$24:$C$31)) -> 6.67 | D43: =IF(輸入與假設!$C$99=1,SUMPRODUCT((1-資產負債_既有債務!$F$24:$F$31)*資產負債_既有債務!$C$24:$C$31*(資產負債_既有債務!$G$13:$G$20>1)),SUMPRODUCT((1-資產負債_既有債務!$F$24:$F$31)*資產負債_既有債務!$C$24:$C$31)) -> 6.67 | E43: =IF(輸入與假設!$C$99=1,SUMPRODUCT((1-資產負債_既有債務!$F$24:$F$31)*資產負債_既有債務!$C$24:$C$31*(資產負債_既有債務!$G$13:$G$20>2)),SUMPRODUCT((1-資產負債_既有債務!$F$24:$F$31)*資產負債_既有債務!$C$24:$C$31)) -> 6.67 | F43: =IF(輸入與假設!$C$99=1,SUMPRODUCT((1-資產負債_既有債務!$F$24:$F$31)*資產負債_既有債務!$C$24:$C$31*(資產負債_既有債務!$G$13:$G$20>3)),SUMPRODUCT((1-資產負債_既有債務!$F$24:$F$31)*資產負債_既有債務!$C$24:$C$31)) -> 6.67 | G43: =IF(輸入與假設!$C$99=1,SUMPRODUCT((1-資產負債_既有債務!$F$24:$F$31)*資產負債_既有債務!$C$24:$C$31*(資產負債_既有債務!$G$13:$G$20>4)),SUMPRODUCT((1-資產負債_既有債務!$F$24:$F$31)*資產負債_既有債務!$C$24:$C$31)) -> 2.875 | I43: 到期累積本金；關閉攤還時維持全額
A44: 可轉債票息（債務處理） | B44: US$bn | C44: =IF(輸入與假設!$C$99=1,SUMPRODUCT((1-資產負債_既有債務!$F$24:$F$31)*資產負債_既有債務!$D$13:$D$20*資產負債_既有債務!$C$13:$C$20*((資產負債_既有債務!$G$13:$G$20>0)+0.5*(資產負債_既有債務!$G$13:$G$20=0))),SUMPRODUCT((1-資產負債_既有債務!$F$24:$F$31)*資產負債_既有債務!$D$13:$D$20*資產負債_既有債務!$C$13:$C$20))*輸入與假設!C$37 -> 0.060375 | D44: =IF(輸入與假設!$C$99=1,SUMPRODUCT((1-資產負債_既有債務!$F$24:$F$31)*資產負債_既有債務!$D$13:$D$20*資產負債_既有債務!$C$13:$C$20*((資產負債_既有債務!$G$13:$G$20>1)+0.5*(資產負債_既有債務!$G$13:$G$20=1))),SUMPRODUCT((1-資產負債_既有債務!$F$24:$F$31)*資產負債_既有債務!$D$13:$D$20*資產負債_既有債務!$C$13:$C$20))*輸入與假設!D$37 -> 0.12075 | E44: =IF(輸入與假設!$C$99=1,SUMPRODUCT((1-資產負債_既有債務!$F$24:$F$31)*資產負債_既有債務!$D$13:$D$20*資產負債_既有債務!$C$13:$C$20*((資產負債_既有債務!$G$13:$G$20>2)+0.5*(資產負債_既有債務!$G$13:$G$20=2))),SUMPRODUCT((1-資產負債_既有債務!$F$24:$F$31)*資產負債_既有債務!$D$13:$D$20*資產負債_既有債務!$C$13:$C$20))*輸入與假設!E$37 -> 0.12075 | F44: =IF(輸入與假設!$C$99=1,SUMPRODUCT((1-資產負債_既有債務!$F$24:$F$31)*資產負債_既有債務!$D$13:$D$20*資產負債_既有債務!$C$13:$C$20*((資產負債_既有債務!$G$13:$G$20>3)+0.5*(資產負債_既有債務!$G$13:$G$20=3))),SUMPRODUCT((1-資產負債_既有債務!$F$24:$F$31)*資產負債_既有債務!$D$13:$D$20*資產負債_既有債務!$C$13:$C$20))*輸入與假設!F$37 -> 0.12075 | G44: =IF(輸入與假設!$C$99=1,SUMPRODUCT((1-資產負債_既有債務!$F$24:$F$31)*資產負債_既有債務!$D$13:$D$20*資產負債_既有債務!$C$13:$C$20*((資產負債_既有債務!$G$13:$G$20>4)+0.5*(資產負債_既有債務!$G$13:$G$20=4))),SUMPRODUCT((1-資產負債_既有債務!$F$24:$F$31)*資產負債_既有債務!$D$13:$D$20*資產負債_既有債務!$C$13:$C$20))*輸入與假設!G$37 -> 0.112125 | I44: ＝原始本金 × 票息 × 期間長度；到期當期計半期
A45: FY26 新增借款利息校準 | B45: US$bn | C45: =0 -> 0 | D45: =0 -> 0 | E45: =0 -> 0 | F45: =0 -> 0 | G45: =0 -> 0 | I45: 讓首期模型利息對上公司季度利息指引的校準值（company.json → defaults.intCal）；無指引時為 0
...

Sheet 資產負債_新債與新股
A1: 新債與新股（類資產負債表：現金、債務、股本、槓桿）
A2: 全部為連結公式。FY26 欄的現金自 2026-06-30 起算（模型期），與 HTML『資產與負債 → 新債與新股』同口徑
A4: 項目 | B4: 單位 | C4: FY26 | D4: FY27 | E4: FY28 | F4: FY29 | G4: FY30 | I4: 公式／來源說明
A5: 現金
A6: 期初現金 | B6: US$bn | C6: =輸入與假設!$C$94 -> 8.0421 | D6: =各期收支!C47 -> 2 | E6: =各期收支!D47 -> 2 | F6: =各期收支!E47 -> 2 | G6: =各期收支!F47 -> 2 | I6: FY26＝6/30 現金（模型期起點）
A7: 營運收支淨額（含期後股權／可轉債，不含瀑布） | B7: US$bn | C7: =各期收支!C83-輸入與假設!$C$94 -> -7.3770759 | D7: =各期收支!D83-各期收支!C83 -> -17.268895 | E7: =各期收支!E83-各期收支!D83 -> -13.83842 | F7: =各期收支!F83-各期收支!E83 -> -10.011853 | G7: =各期收支!G83-各期收支!F83 -> -19.371614 | I7: ＝融資前累積現金的當期變動；負值即當期外部資金需求
A8: ＋ 瀑布：新債（額度＋資產層） | B8: US$bn | C8: =各期收支!C66 -> 1.37982 | D8: =各期收支!D66 -> 9.691341 | E8: =各期收支!E66 -> 1.049641 | F8: =各期收支!F66 -> 0 | G8: =各期收支!G66 -> 0
A9: ＋ 瀑布：可轉債 | B9: US$bn | C9: =各期收支!C69 -> 0 | D9: =各期收支!D69 -> 5 | E9: =各期收支!E69 -> 5 | F9: =各期收支!F69 -> 5 | G9: =各期收支!G69 -> 5
A10: ＋ 瀑布：高息債 | B10: US$bn | C10: =各期收支!C73 -> 0 | D10: =各期收支!D73 -> 0 | E10: =各期收支!E73 -> 0 | F10: =各期收支!F73 -> 0 | G10: =各期收支!G73 -> 0.16760739
A11: ＋ 瀑布：股權募資 | B11: US$bn | C11: =各期收支!C72 -> 0 | D11: =各期收支!D72 -> 3.4021798 | E11: =各期收支!E72 -> 8.7866316 | F11: =各期收支!F72 -> 6.1147054 | G11: =各期收支!G72 -> 15.431971
A12: − 新融資利息（新債＋可轉債＋高息債） | B12: US$bn | C12: =-各期收支!C74 -> -0.044844151 | D12: =-各期收支!D74 -> -0.82462547 | E12: =-各期收支!E74 -> -0.99785213 | F12: =-各期收支!F74 -> -1.1028521 | G12: =-各期收支!G74 -> -1.227965
A13: 期末現金 | B13: US$bn | C13: =SUM(C6:C12) -> 2 | D13: =SUM(D6:D12) -> 2 | E13: =SUM(E6:E12) -> 2 | F13: =SUM(F6:F12) -> 2 | G13: =SUM(G6:G12) -> 2 | I13: 應等於『各期收支』期末累積現金（見下列驗算）
A14: 驗算：與各期收支期末現金差異 | B14: US$bn | C14: =C13-各期收支!C47 -> 0 | D14: =D13-各期收支!D47 -> 0 | E14: =E13-各期收支!E47 -> 0 | F14: =F13-各期收支!F47 -> 0 | G14: =G13-各期收支!G47 -> 0 | I14: 應為 0
A15: 債務
A16: 既有債務期初（季報本金） | B16: US$bn | C16: =資產負債_既有債務!$E$6+SUMPRODUCT((1-資產負債_既有債務!$F$24:$F$31)*資產負債_既有債務!$C$24:$C$31) -> 6.7167 | D16: =C18 -> 6.67 | E16: =D18 -> 6.67 | F16: =E18 -> 6.67 | G16: =F18 -> 6.67 | I16: FY26＝其他借款＋債務處理可轉債到期本金（轉股處理者不列）
A17: − 排程還本（模型期） | B17: US$bn | C17: =-IF(輸入與假設!$C$99=1,輸入與假設!C$119,0)-資產負債_既有債務!C42 -> -0.0467 | D17: =-IF(輸入與假設!$C$99=1,輸入與假設!D$119,0)-資產負債_既有債務!D42 -> 0 | E17: =-IF(輸入與假設!$C$99=1,輸入與假設!E$119,0)-資產負債_既有債務!E42 -> 0 | F17: =-IF(輸入與假設!$C$99=1,輸入與假設!F$119,0)-資產負債_既有債務!F42 -> 0 | G17: =-IF(輸入與假設!$C$99=1,輸入與假設!G$119,0)-資產負債_既有債務!G42 -> -3.795
A18: 既有債務期末 | B18: US$bn | C18: =各期收支!C62-0 -> 6.67 | D18: =各期收支!D62-0 -> 6.67 | E18: =各期收支!E62-0 -> 6.67 | F18: =各期收支!F62-0 -> 6.67 | G18: =各期收支!G62-0 -> 2.875 | I18: ＝依到期表遞減（關閉攤還時維持期初）
A19: ＋ 期後新發可轉債 | B19: US$bn | C19: =0 -> 0 | D19: =0 -> 0 | E19: =0 -> 0 | F19: =0 -> 0 | G19: =0 -> 0
A20: ＋ 瀑布新債餘額 | B20: US$bn | C20: =各期收支!C78 -> 1.37982 | D20: =各期收支!D78 -> 11.071161 | E20: =各期收支!E78 -> 12.120802 | F20: =各期收支!F78 -> 12.120802 | G20: =各期收支!G78 -> 12.120802
A21: ＋ 瀑布可轉債餘額 | B21: US$bn | C21: =各期收支!C81 -> 0 | D21: =各期收支!D81 -> 5 | E21: =各期收支!E81 -> 10 | F21: =各期收支!F81 -> 15 | G21: =各期收支!G81 -> 20
A22: ＋ 高息債餘額 | B22: US$bn | C22: =各期收支!C80 -> 0 | D22: =各期收支!D80 -> 0 | E22: =各期收支!E80 -> 0 | F22: =各期收支!F80 -> 0 | G22: =各期收支!G80 -> 0.16760739
A23: 總債務 | B23: US$bn | C23: =SUM(C18:C22) -> 8.04982 | D23: =SUM(D18:D22) -> 22.741161 | E23: =SUM(E18:E22) -> 28.790802 | F23: =SUM(F18:F22) -> 33.790802 | G23: =SUM(G18:G22) -> 35.163409 | I23: 應等於『各期收支』期末總債務
A24: 淨負債（總債務 − 期末現金） | B24: US$bn | C24: =C23-C13 -> 6.04982 | D24: =D23-D13 -> 20.741161 | E24: =E23-E13 -> 26.790802 | F24: =F23-F13 -> 31.790802 | G24: =G23-G13 -> 33.163409
A25: 股本
A26: 基礎股數（含 ATM 上限、SBC 稀釋） | B26: bn | C26: =損益!C20 -> 0.32100068 | D26: =損益!D20 -> 0.32421069 | E26: =損益!E20 -> 0.32745279 | F26: =損益!F20 -> 0.33072732 | G26: =損益!G20 -> 0.3340346
A27: ＋ 本期新股 | B27: bn | C27: =各期收支!C76 -> 0 | D27: =各期收支!D76 -> 0.015128666 | E27: =各期收支!E76 -> 0.039072013 | F27: =各期收支!F76 -> 0.027190608 | G27: =各期收支!G76 -> 0.068622222
A28: 總股數（期末） | B28: bn | C28: =損益!C21 -> 0.32100068 | D28: =損益!D21 -> 0.33933935 | E28: =損益!E21 -> 0.38165347 | F28: =損益!F21 -> 0.41211861 | G28: =損益!G21 -> 0.4840481 | I28: ＝基礎股數＋累計新股
A29: 槓桿
A30: 期末 backlog | B30: US$bn | C30: =各期收支!C61 -> 34.116446 | D30: =各期收支!D61 -> 35.482322 | E30: =各期收支!E61 -> 47.581604 | F30: =各期收支!F61 -> 46.900586 | G30: =各期收支!G61 -> 35.113058
A31: 債務上限（債務／backlog × 期末 backlog） | B31: US$bn | C31: =各期收支!C63 -> 17.058223 | D31: =各期收支!D63 -> 17.741161 | E31: =各期收支!E63 -> 23.790802 | F31: =各期收支!F63 -> 23.450293 | G31: =各期收支!G63 -> 17.556529
A32: 總債務 ÷ 期末 backlog | B32: x | C32: =C23/MAX(0.01,C30) -> 0.23595131 | D32: =D23/MAX(0.01,D30) -> 0.64091524 | E32: =E23/MAX(0.01,E30) -> 0.60508263 | F32: =F23/MAX(0.01,F30) -> 0.72047718 | G32: =G23/MAX(0.01,G30) -> 1.001434 | I32: 高息債不受 backlog 上限約束
A33: 總債務 ÷ EBITDA（年化） | B33: x | C33: =C23/MAX(0.01,損益!C19/輸入與假設!C$37) -> 4.3444889 | D33: =D23/MAX(0.01,損益!D19/輸入與假設!D$37) -> 4.4103237 | E33: =E23/MAX(0.01,損益!E19/輸入與假設!E$37) -> 2.6318162 | F33: =F23/MAX(0.01,損益!F19/輸入與假設!F$37) -> 2.0631836 | G33: =G23/MAX(0.01,損益!G19/輸入與假設!G$37) -> 1.7185278 | I33: FY26 模型期 EBITDA 以半年×2 年化

Sheet 資產負債_租賃承諾
A1: 租賃與承諾 — 季報（2026-06-30）原始揭露
A2: 本頁為硬編碼的申報數字（藍字），支出與資金頁的租金與還本列由此而來
A4: 在帳租賃到期表（未折現）
