Workbook

Sheet README
A1: Lam Research（LRCX）收支與估值模型 v0.2.1（AI 半導體 Project 步驟 5：設備與材料） 2026-10-25
A2: 模型命題：Lam 的系統營收跟著晶圓前段設備（WFE）的記憶體與代工邏輯支出走，記憶體占系統營收近一半（DRAM 與 NAND 升級）、中國占營收約三分之一。核心問題：WFE 在 2027 年後放緩、或對中國的出口管制加嚴時，FY2027 以後的 EPS 還撐得住現在約 25 倍的遠期本益比嗎？
A4: 會計年度：7 月到隔年 6 月（FY2027＝2026-07～2027-06）；FY(t)＝CY(t−1) 下半＋CY(t) 上半（上半占比 h1，基準 50%）。FY2026 已結束（實績）；FY2027 第一季（2026-09 季）已於 2026-10-21 公布並納入，12 月季用公司指引。金額十億美元。
A6: 驅動因子 → 推導量
A7: 系統營收（日曆年）＝ k（份額係數）× 設備市場模型的 WFE 分項（代工與邏輯、DRAM、NAND；三情境；markets/equipment）；k 由 CY2026（FY26 Q3–Q4 實績＋FY27 Q1 實績＋Q2 指引）× 客戶別占比校準
A8: CSBG（服務、備件、升級、Reliant）另推：CY2026 錨點 × 年增（CY2027 公司稱逾 15%；之後依情境 Assumed）
A9: 毛利率＝截距＋斜率 × ln 營收（FY2026 與 FY2027 上半年化兩點推導）；營業費用＝固定＋變動 × 營收（同兩點）；稅率 16.5%（公司說法）；股數 1.253B 起每年 −1.5%
A10: 情境 A／B／C：WFE 分項讀設備市場模型 A（2029 見頂）／B（2028 持平）／C（2028 −20%）；情境 C 另加出口管制：中國系統營收 −20%（CY2028 起，Assumed；2022 管制類比約三到四成）
A11: Val：P/E 規則——10 年（2016–2025 年底）當期 P/E 分位，見頂年 25 分位、中段中位數、谷底 75 分位；循環位置依設備股共用規則（各情境見頂年度：A 2029、B 2028、C 2027 → FY2027：A 中段、B 中段、C 見頂）。第 0 節：情境加權目標價。本版未做先驗，無 Andy 合理 P/E 對照。
A13: 標記：Verified、Interested-party、Analogy、Assumed、Derived。SemiAnalysis 未使用。
A14: 已知限制：(1) k 只在 CY2026 一點校準，之後份額不變（漂移只在 Sens）；公司稱連續三年優於 WFE，若延續則模型偏低；(2) 客戶別占比為「設備與升級營收」口徑（10-Q），套用於系統營收；DRAM／NAND 拆分來自法說摘要；(3) 中國以總營收占比代用系統營收占比，出口管制折損為 Assumed；(4) 設備市場模型的 WFE 以 SEMI 2025 實績校準，與公司 WFE 口徑不同，只用成長率；(5) CY→FY 以上下半各半轉換，成長年下半較高（h1 區間 45–55%）；(6) CSBG 成長無由下而上（裝機量 × 每腔體支出）推導；(7) NAND 升級潮公司稱 2027 年結束，模型的 NAND 隨設備市場模型 NAND 支出成長，可能高估 CY2028 後的 NAND。
A15: v0.2（2026-10-25）估值 v2：Val 頁新增「0. 目標價」（放在既有內容之後，不位移既有列）＝0.5 × DCF 目標價（股東現金流＝EPS ×（1 − g／ROE），FY2027–32 明確期＋永續，r 10%、g 4%，情境權重 A 0.3／B 0.5／C 0.2）＋0.5 × Comparable 目標價（同業前瞻 P/E 中位數 × 12 個月後前瞻 EPS）；另列 Comparable 單獨目標價、市場共識目標價與差距拆解、歷史分位檢查。原「0. 目標價與上檔空間」改名「舊法：規則值情境加權（參考）」，不再叫目標價。
... A17: v0.2.1：補上檔空間級距、投資建議、重點觀察（數值不變）。Val 頁最後新增「上檔空間級距」「投資建議」兩列（第 138、139 列，依「上檔空間：加權目標價」的固定規則）；重點觀察見下方三列。
A18: ="投資建議："&Val!B139&"（依上檔空間固定規則）" -> 投資建議：中立（依上檔空間固定規則）
A19: 重點觀察 1：目標價 US$203（DCF 147、Comparable 259 各半），比現價 230.10（2026-10-23）低 11.8%，級距 0%～−25%；Comparable 單獨為 +12.5%。DCF 比現價低 36.2%，因情境 B、C 的 EPS 在 FY2029 後依收斂法下滑（C 的 FY2032 EPS 5.25 只有 FY2027 9.42 的 56%），不是 ROE（近三年 56.3%）。
A20: 重點觀察 2：與市場的主要差異在 EPS：本模型前瞻 EPS 10.07 比共識 FY2028 EPS 12.15 低 17.1%（期間約晚四個月），情境 A 的 FY2028 EPS 10.68 也比共識低 12.1%；共識目標價 364.03 隱含 30.0 倍，比同業前瞻 P/E 中位數 25.7 倍高 16.6%。
A21: 重點觀察 3：出口管制與設備市場情境最敏感：中國系統營收 −40% 使 FY2028 EPS −11.8%、設備情境 C 使 −18.2%。下一個檢驗點是 FY2027 第二季（12 月季）財報（預計 2027-01 下旬），檢驗 CY2027 上半年的權重（45%～55% 時 FY2027 EPS ±6.6%）。

Sheet In
A1: In — 輸入（藍字；基準欄 E，低 D、高 F）。金額：十億美元（US$B）；EPS 美元。每個輸入附兩個來源（來源2 找不到者寫「未找到」）；公司原文算一個
A2: 標記：Verified／Interested-party／Analogy／Assumed／Derived；Analogy、Assumed 給低／高區間。SemiAnalysis 未使用。公司財報（8-K 新聞稿、10-K、10-Q）取自 SEC EDGAR 原文；法說內容取自逐字稿摘要（Motley Fool、MarketBeat、TIKR）
A3: 鍵 | B3: 項目 | C3: 單位 | D3: 低 | E3: 基準 | F3: 高 | G3: 標記 | H3: 來源1 | I3: 來源2／說明
A4: A. 晶圓前段設備市場（讀 markets/equipment 成品 Mkt 頁 5A／5B／5C；三情境；日曆年 US$B；唯讀，不另估）
A5: advA_25 | B5: 先進邏輯〔AI〕 CY2025（情境 A） | C5: US$B | E5: 36.032336 | G5: Derived | H5: markets/equipment/dist/20261023_半導體設備市場模型_v0.1.3.xlsx｜Mkt!C120:G120 | I5: markets/equipment：公司資本支出 × 設備占比＋其他廠；2028 起 B、C 乘情境係數（Assumed）
A6: advA_26 | B6: 先進邏輯〔AI〕 CY2026（情境 A） | C6: US$B | E6: 50.324843 | G6: Derived | H6: 同上
A7: advA_27 | B7: 先進邏輯〔AI〕 CY2027（情境 A） | C7: US$B | E7: 60.776431 | G7: Derived | H7: 同上
A8: advA_28 | B8: 先進邏輯〔AI〕 CY2028（情境 A） | C8: US$B | E8: 70.016145 | G8: Derived | H8: 同上
A9: advA_29 | B9: 先進邏輯〔AI〕 CY2029（情境 A） | C9: US$B | E9: 74.209437 | G9: Derived | H9: 同上
A10: oflA_25 | B10: 其他代工與邏輯 CY2025（情境 A） | C10: US$B | E10: 29.569009 | G10: Derived | H10: markets/equipment/dist/20261023_半導體設備市場模型_v0.1.3.xlsx｜Mkt!C121:G121 | I10: markets/equipment：公司資本支出 × 設備占比＋其他廠；2028 起 B、C 乘情境係數（Assumed）
A11: oflA_26 | B11: 其他代工與邏輯 CY2026（情境 A） | C11: US$B | E11: 31.93453 | G11: Derived | H11: 同上
A12: oflA_27 | B12: 其他代工與邏輯 CY2027（情境 A） | C12: US$B | E12: 34.489292 | G12: Derived | H12: 同上
A13: oflA_28 | B13: 其他代工與邏輯 CY2028（情境 A） | C13: US$B | E13: 37.248436 | G13: Derived | H13: 同上
A14: oflA_29 | B14: 其他代工與邏輯 CY2029（情境 A） | C14: US$B | E14: 40.228311 | G14: Derived | H14: 同上
A15: dramA_25 | B15: DRAM（含 HBM）〔AI〕 CY2025（情境 A） | C15: US$B | E15: 26.376109 | G15: Derived | H15: markets/equipment/dist/20261023_半導體設備市場模型_v0.1.3.xlsx｜Mkt!C122:G122 | I15: markets/equipment：公司資本支出 × 設備占比＋其他廠；2028 起 B、C 乘情境係數（Assumed）
A16: dramA_26 | B16: DRAM（含 HBM）〔AI〕 CY2026（情境 A） | C16: US$B | E16: 39.365947 | G16: Derived | H16: 同上
A17: dramA_27 | B17: DRAM（含 HBM）〔AI〕 CY2027（情境 A） | C17: US$B | E17: 53.258733 | G17: Derived | H17: 同上
A18: dramA_28 | B18: DRAM（含 HBM）〔AI〕 CY2028（情境 A） | C18: US$B | E18: 59.5609 | G18: Derived | H18: 同上
A19: dramA_29 | B19: DRAM（含 HBM）〔AI〕 CY2029（情境 A） | C19: US$B | E19: 61.831293 | G19: Derived | H19: 同上
A20: nandA_25 | B20: NAND CY2025（情境 A） | C20: US$B | E20: 12.172602 | G20: Derived | H20: markets/equipment/dist/20261023_半導體設備市場模型_v0.1.3.xlsx｜Mkt!C123:G123 | I20: markets/equipment：公司資本支出 × 設備占比＋其他廠；2028 起 B、C 乘情境係數（Assumed）
A21: nandA_26 | B21: NAND CY2026（情境 A） | C21: US$B | E21: 17.503905 | G21: Derived | H21: 同上
A22: nandA_27 | B22: NAND CY2027（情境 A） | C22: US$B | E22: 23.248027 | G22: Derived | H22: 同上
A23: nandA_28 | B23: NAND CY2028（情境 A） | C23: US$B | E23: 26.181322 | G23: Derived | H23: 同上
A24: nandA_29 | B24: NAND CY2029（情境 A） | C24: US$B | E24: 27.674313 | G24: Derived | H24: 同上
A25: wfeA_25 | B25: 晶圓前段設備合計 CY2025（情境 A） | C25: US$B | E25: 116.89683 | G25: Derived | H25: markets/equipment/dist/20261023_半導體設備市場模型_v0.1.3.xlsx｜Mkt!C127:G127 | I25: markets/equipment：公司資本支出 × 設備占比＋其他廠；2028 起 B、C 乘情境係數（Assumed）
A26: wfeA_26 | B26: 晶圓前段設備合計 CY2026（情境 A） | C26: US$B | E26: 156.15705 | G26: Derived | H26: 同上
A27: wfeA_27 | B27: 晶圓前段設備合計 CY2027（情境 A） | C27: US$B | E27: 192.79547 | G27: Derived | H27: 同上
A28: wfeA_28 | B28: 晶圓前段設備合計 CY2028（情境 A） | C28: US$B | E28: 216.62863 | G28: Derived | H28: 同上
A29: wfeA_29 | B29: 晶圓前段設備合計 CY2029（情境 A） | C29: US$B | E29: 228.90369 | G29: Derived | H29: 同上
A30: advB_25 | B30: 先進邏輯〔AI〕 CY2025（情境 B） | C30: US$B | E30: 36.032336 | G30: Derived | H30: markets/equipment/dist/20261023_半導體設備市場模型_v0.1.3.xlsx｜Mkt!C139:G139 | I30: markets/equipment：公司資本支出 × 設備占比＋其他廠；2028 起 B、C 乘情境係數（Assumed）
A31: advB_26 | B31: 先進邏輯〔AI〕 CY2026（情境 B） | C31: US$B | E31: 50.324843 | G31: Derived | H31: 同上
A32: advB_27 | B32: 先進邏輯〔AI〕 CY2027（情境 B） | C32: US$B | E32: 60.776431 | G32: Derived | H32: 同上
A33: advB_28 | B33: 先進邏輯〔AI〕 CY2028（情境 B） | C33: US$B | E33: 60.776431 | G33: Derived | H33: 同上
A34: advB_29 | B34: 先進邏輯〔AI〕 CY2029（情境 B） | C34: US$B | E34: 57.737609 | G34: Derived | H34: 同上
A35: oflB_25 | B35: 其他代工與邏輯 CY2025（情境 B） | C35: US$B | E35: 29.569009 | G35: Derived | H35: markets/equipment/dist/20261023_半導體設備市場模型_v0.1.3.xlsx｜Mkt!C140:G140 | I35: markets/equipment：公司資本支出 × 設備占比＋其他廠；2028 起 B、C 乘情境係數（Assumed）
A36: oflB_26 | B36: 其他代工與邏輯 CY2026（情境 B） | C36: US$B | E36: 31.93453 | G36: Derived | H36: 同上
A37: oflB_27 | B37: 其他代工與邏輯 CY2027（情境 B） | C37: US$B | E37: 34.489292 | G37: Derived | H37: 同上
A38: oflB_28 | B38: 其他代工與邏輯 CY2028（情境 B） | C38: US$B | E38: 34.489292 | G38: Derived | H38: 同上
A39: oflB_29 | B39: 其他代工與邏輯 CY2029（情境 B） | C39: US$B | E39: 32.764828 | G39: Derived | H39: 同上
A40: dramB_25 | B40: DRAM（含 HBM）〔AI〕 CY2025（情境 B） | C40: US$B | E40: 26.376109 | G40: Derived | H40: markets/equipment/dist/20261023_半導體設備市場模型_v0.1.3.xlsx｜Mkt!C141:G141 | I40: markets/equipment：公司資本支出 × 設備占比＋其他廠；2028 起 B、C 乘情境係數（Assumed）
...

Sheet Q
A1: Q — 實績（十億美元；EPS 美元；GAAP）。會計年度 7–6 月：FY2026＝2025-07～2026-06。藍字＝輸入；黑字＝公式（Derived）。來源：Lam 8-K 新聞稿（Exhibit 99.1）、10-K、10-Q（SEC EDGAR 原文）
A2: FY2027 第一季（2026-07～09）已於 2026-10-21 公布並納入（G 欄）；H 欄為 12 月季指引（2026-10-21）。下一次財報：FY2027 第二季，預計 2027-01 下旬（公司尚未公告日期）
A3: 項目 | B3: FY2025 全年 | C3: FY26 Q1（7–9月） | D3: FY26 Q2（10–12月） | E3: FY26 Q3（1–3月） | F3: FY26 Q4（4–6月） | G3: FY27 Q1（7–9月） | H3: FY27 Q2（指引） | I3: FY2026 全年 | J3: 標記 | K3: 來源1（公司） | L3: 來源2／說明
A4: 系統營收（新的先進製程設備） | B4: 11.49128 | C4: 3.547565 | D4: 3.357493 | E4: 3.730582 | F4: 4.249848 | G4: 5.732907 | H4: =H6-H5 -> 6.113489 | I4: 14.885488 | J4: Verified | K4: 各季 8-K 新聞稿（2025-07-30、2025-10-22、2026-01-28、2026-04-22、2026-07-29、2026-10-21）：Systems revenue | L4: FY2026 10-K（2026-08-07）：FY2026 14,885.5、FY2025 11,491.3（百萬美元）；四季合計＝全年（見檢查列）
A5: 客戶支援與其他（CSBG：服務、備件、升級、Reliant 成熟製程設備） | B5: 6.944311 | C5: 1.776608 | D5: 1.987298 | E5: 2.110906 | F5: 2.47239 | G5: 2.486511 | H5: =G5*(1+csq2_g) -> 2.486511 | I5: 8.347202 | J5: Verified | K5: 各季 8-K 新聞稿（2025-07-30、2025-10-22、2026-01-28、2026-04-22、2026-07-29、2026-10-21）：Customer support-related revenue and other | L5: FY2026 10-K（2026-08-07）；Q2 指引欄＝Q1 × (1＋csq2_g)（Assumed）
A6: 營收 | B6: 18.435591 | C6: 5.324173 | D6: 5.344791 | E6: 5.841488 | F6: 6.722238 | G6: 8.219418 | H6: =g_q2rev -> 8.6 | I6: 23.23269 | J6: Verified | K6: 各季 8-K 新聞稿（2025-07-30、2025-10-22、2026-01-28、2026-04-22、2026-07-29、2026-10-21） | L6: FY2026 10-K（2026-08-07）：23,232.7、18,435.6
A7: 檢查：系統＋CSBG − 營收（應為 0） | B7: =B4+B5-B6 -> 0 | C7: =C4+C5-C6 -> 0 | D7: =D4+D5-D6 -> 0 | E7: =E4+E5-E6 -> 0 | F7: =F4+F5-F6 -> 0 | G7: =G4+G5-G6 -> 0 | H7: =H4+H5-H6 -> 0 | I7: =I4+I5-I6 -> 0 | J7: — | K7: — | L7: —
A8: 毛利 | B8: 8.979059 | C8: 2.684879 | D8: 2.651162 | E8: 2.910527 | F8: 3.47874 | G8: 4.298853 | H8: =H6*g_q2gm -> 4.515 | I8: 11.725308 | J8: Verified | K8: 各季 8-K 新聞稿（2025-07-30、2025-10-22、2026-01-28、2026-04-22、2026-07-29、2026-10-21） | L8: FY2026 10-K（2026-08-07）
A9: 毛利率 | B9: =B8/B6 -> 0.48705024 | C9: =C8/C6 -> 0.50428095 | D9: =D8/D6 -> 0.49602725 | E9: =E8/E6 -> 0.49825096 | F9: =F8/F6 -> 0.5174973 | G9: =G8/G6 -> 0.52301185 | H9: =H8/H6 -> 0.525 | I9: =I8/I6 -> 0.50469007 | J9: Derived | K9: — | L9: 公司：FY2026 50.5%、FY27 Q1 52.3%（GAAP）
A10: 研發費用 | B10: 2.096387 | C10: 0.576446 | D10: 0.573305 | E10: 0.5832 | F10: 0.642922 | G10: 0.666398 | I10: 2.375873 | J10: Verified | K10: 各季 8-K 新聞稿（2025-07-30、2025-10-22、2026-01-28、2026-04-22、2026-07-29、2026-10-21） | L10: FY2026 10-K（2026-08-07）
A11: 銷管費用 | B11: 0.981704 | C11: 0.279345 | D11: 0.267654 | E11: 0.280311 | F11: 0.32233 | G11: 0.348728 | I11: 1.14964 | J11: Verified | K11: 各季 8-K 新聞稿（2025-07-30、2025-10-22、2026-01-28、2026-04-22、2026-07-29、2026-10-21） | L11: FY2026 10-K（2026-08-07）
A12: 營業費用 | B12: =B10+B11 -> 3.078091 | C12: =C10+C11 -> 0.855791 | D12: =D10+D11 -> 0.840959 | E12: =E10+E11 -> 0.863511 | F12: =F10+F11 -> 0.965252 | G12: =G10+G11 -> 1.015126 | H12: =H8-H13 -> 1.032 | I12: =I10+I11 -> 3.525513 | J12: Derived | K12: — | L12: Q2 指引欄＝毛利 − 營業利益
A13: 營業利益 | B13: 5.900968 | C13: 1.829088 | D13: 1.810203 | E13: 2.047016 | F13: 2.513488 | G13: 3.283727 | H13: =H6*g_q2om -> 3.483 | I13: 8.199795 | J13: Verified | K13: 各季 8-K 新聞稿（2025-07-30、2025-10-22、2026-01-28、2026-04-22、2026-07-29、2026-10-21） | L13: FY2026 10-K（2026-08-07）
A14: 營業利益率 | B14: =B13/B6 -> 0.32008564 | C14: =C13/C6 -> 0.34354406 | D14: =D13/D6 -> 0.33868546 | E14: =E13/E6 -> 0.35042715 | F14: =F13/F6 -> 0.37390643 | G14: =G13/G6 -> 0.39950846 | H14: =H13/H6 -> 0.405 | I14: =I13/I6 -> 0.35294213 | J14: Derived | K14: — | L14: 公司：FY2026 35.3%、FY27 Q1 40.0%
A15: 業外收益淨額 | B15: 0.057161 | C15: 0.030074 | D15: 0.02641 | E15: -0.03546 | F15: 0.041654 | G15: 0.028493 | I15: 0.062678 | J15: Verified | K15: 各季 8-K 新聞稿（2025-07-30、2025-10-22、2026-01-28、2026-04-22、2026-07-29、2026-10-21） | L15: FY2026 10-K（2026-08-07）
A16: 所得稅 | B16: 0.599912 | C16: 0.290502 | D16: 0.242619 | E16: 0.186096 | F16: 0.27786 | G16: 0.559082 | I16: 0.997077 | J16: Verified | K16: 各季 8-K 新聞稿（2025-07-30、2025-10-22、2026-01-28、2026-04-22、2026-07-29、2026-10-21） | L16: FY2026 10-K（2026-08-07）
A17: 淨利 | B17: 5.358217 | C17: 1.56866 | D17: 1.593994 | E17: 1.82546 | F17: 2.277282 | G17: 2.753138 | H17: =H18*H19 -> 2.91949 | I17: 7.265396 | J17: Verified | K17: 各季 8-K 新聞稿（2025-07-30、2025-10-22、2026-01-28、2026-04-22、2026-07-29、2026-10-21） | L17: FY2026 10-K（2026-08-07）；Q2 指引欄＝指引 EPS × 指引股數（Derived）
A18: EPS（稀釋，美元） | B18: 4.15 | C18: 1.24 | D18: 1.26 | E18: 1.45 | F18: 1.81 | G18: 2.19 | H18: =g_q2eps -> 2.33 | I18: 5.76 | J18: Verified | K18: 各季 8-K 新聞稿（2025-07-30、2025-10-22、2026-01-28、2026-04-22、2026-07-29、2026-10-21） | L18: FY2026 10-K（2026-08-07）；非 GAAP FY2026 5.82（各季 1.26＋1.27＋1.47＋1.82）
A19: 稀釋股數（十億股） | B19: 1.290142 | C19: 1.269313 | D19: 1.261739 | E19: 1.257325 | F19: 1.256032 | G19: 1.255768 | H19: =sh_27 -> 1.253 | I19: 1.261102 | J19: Verified | K19: 各季 8-K 新聞稿（2025-07-30、2025-10-22、2026-01-28、2026-04-22、2026-07-29、2026-10-21） | L19: FY2026 10-K（2026-08-07）
A20: EPS（基本，美元；Val 的十年 P/E 用） | B20: 4.17 | C20: 1.24 | D20: 1.27 | E20: 1.46 | F20: 1.82 | G20: 2.2 | I20: 5.79 | J20: Verified | K20: 各季 8-K 新聞稿（2025-07-30、2025-10-22、2026-01-28、2026-04-22、2026-07-29、2026-10-21） | L20: FY2026 10-K（2026-08-07）
A21: 檢查：四季合計 − 全年（系統、CSBG、營收、毛利、營業利益、淨利依序在 B–G 欄） | B21: =SUM(C4:F4)-I4 -> 0 | C21: =SUM(C5:F5)-I5 -> 0 | D21: =SUM(C6:F6)-I6 -> 0 | E21: =SUM(C8:F8)-I8 -> 0 | F21: =SUM(C13:F13)-I13 -> 0 | G21: =SUM(C17:F17)-I17 -> 0 | J21: — | K21: — | L21: —
A23: 地區與客戶別（占比）
A24: 中國占營收 | B24: 0.34 | C24: 0.43 | D24: 0.35 | E24: 0.34 | F24: 0.26 | G24: 0.35 | I24: 0.34 | J24: Verified | K24: 各季 8-K 新聞稿（2025-07-30、2025-10-22、2026-01-28、2026-04-22、2026-07-29、2026-10-21）：Region revenue | L24: FY2026 10-K（2026-08-07）：FY2026、FY2025 皆 34%；管理層稱 12 月季中國占比將「明顯下降」（FQ1-27 法說）
A25: 代工（Foundry）占系統營收 | B25: 0.45 | C25: 0.6 | D25: 0.59 | E25: 0.54 | F25: 0.44 | G25: 0.46 | H25: =G25 -> 0.46 | I25: 0.54 | J25: Verified | K25: 各季 10-Q 與 FY2026 10-K：設備與升級營收的客戶別占比 | L25: 法說稱占「系統營收」，數字與 10-Q 相同；Q2 指引欄沿用 Q1（Assumed）
A26: 邏輯／IDM 占系統營收 | B26: 0.13 | C26: 0.06 | D26: 0.07 | E26: 0.07 | F26: 0.1 | G26: 0.08 | H26: =G26 -> 0.08 | I26: 0.07 | J26: Verified | K26: 同上 | L26: 同上
A27: DRAM 占系統營收 | C27: 0.16 | D27: 0.23 | E27: 0.27 | F27: 0.23 | G27: 0.2 | H27: =G27 -> 0.2 | J27: Interested-party | K27: 法說逐字稿摘要（TIKR FQ2-26；MarketBeat FQ4-26；Motley Fool FQ1-27）：Q1 16%、Q2 23%、Q3 27%、Q4 23%、FY27 Q1 20% | L27: 10-Q 只揭露記憶體合計；DRAM＋NAND＝記憶體（見檢查列）。FY2025 全年 DRAM／NAND 拆分：未找到
A28: NAND（非揮發性記憶體）占系統營收 | C28: 0.18 | D28: 0.11 | E28: 0.12 | F28: 0.23 | G28: 0.26 | H28: =G28 -> 0.26 | J28: Interested-party | K28: 同上：Q1 18%、Q2 11%、Q3 12%、Q4 23%、FY27 Q1 26% | L28: 同上
A29: 記憶體占系統營收（10-Q） | B29: 0.42 | C29: 0.34 | D29: 0.34 | E29: 0.39 | F29: 0.46 | G29: 0.46 | H29: =G29 -> 0.46 | I29: 0.39 | J29: Verified | K29: 10-Q／10-K：Memory | L29: —
A30: 檢查：代工＋邏輯＋記憶體 − 1；DRAM＋NAND − 記憶體（C–H 欄） | B30: =B25+B26+B29-1 -> 0 | C30: =C27+C28-C29 -> 0 | D30: =D27+D28-D29 -> 0 | E30: =E27+E28-E29 -> 0 | F30: =F27+F28-F29 -> 0 | G30: =G27+G28-G29 -> 0 | H30: =H27+H28-H29 -> 0 | I30: =I25+I26+I29-1 -> 0 | J30: — | K30: — | L30: B、I 欄為三項合計 − 1
A32: CY2025 對照用：FY2025 下半（2025-01～06）
A33: 項目 | B33: FY25 Q3（1–3月） | C33: FY25 Q4（4–6月） | J33: 標記 | K33: 來源1（公司） | L33: 來源2／說明
A34: 系統營收 | B34: 3.035276 | C34: 3.437625 | J34: Verified | K34: 8-K 2025-04-23、2025-07-30；FY26 Q3 與 Q1 新聞稿的前期比較欄 | L34: —
A35: CSBG | B35: 1.684899 | C35: 1.733768 | J35: Verified | K35: 8-K 2025-04-23、2025-07-30；FY26 Q3 與 Q1 新聞稿的前期比較欄 | L35: —
A36: 營收 | B36: 4.720175 | C36: 5.171393 | J36: Verified | K36: 8-K 2025-04-23、2025-07-30；FY26 Q3 與 Q1 新聞稿的前期比較欄 | L36: —

Sheet Units
A1: Units — 日曆年系統營收依客戶別的錨點：CY2026＝FY26 Q3＋Q4（實績）＋FY27 Q1（實績）＋FY27 Q2（指引）；各季系統營收 × 客戶別占比；再除以設備市場模型的 CY2026 分項，得到份額係數 k
A3: 項目 | B3: 單位 | C3: FY26 Q3 | D3: FY26 Q4 | E3: FY27 Q1 | F3: FY27 Q2（指引） | G3: CY2026 | H3: 說明
A4: 系統營收 | B4: US$B | C4: =Q!E4 -> 3.730582 | D4: =Q!F4 -> 4.249848 | E4: =Q!G4 -> 5.732907 | F4: =Q!H4 -> 6.113489 | G4: =SUM(C4:F4) -> 19.826826 | H4: Q2 指引欄＝指引營收 − CSBG 推估
A5: 代工與邏輯 | B5: US$B | C5: =Q!E4*(Q!E25+Q!E26) -> 2.275655 | D5: =Q!F4*(Q!F25+Q!F26) -> 2.2949179 | E5: =Q!G4*(Q!G25+Q!G26) -> 3.0957698 | F5: =Q!H4*(Q!H25+Q!H26) -> 3.3012841 | G5: =SUM(C5:F5) -> 10.967627
A6: DRAM | B6: US$B | C6: =Q!E4*Q!E27 -> 1.0072571 | D6: =Q!F4*Q!F27 -> 0.97746504 | E6: =Q!G4*Q!G27 -> 1.1465814 | F6: =Q!H4*Q!H27 -> 1.2226978 | G6: =SUM(C6:F6) -> 4.3540014
A7: NAND | B7: US$B | C7: =Q!E4*Q!E28 -> 0.44766984 | D7: =Q!F4*Q!F28 -> 0.97746504 | E7: =Q!G4*Q!G28 -> 1.4905558 | F7: =Q!H4*Q!H28 -> 1.5895071 | G7: =SUM(C7:F7) -> 4.5051978
A8: 檢查：三項 − 系統營收（應為 0） | B8: US$B | C8: =C5+C6+C7-C4 -> 0 | D8: =D5+D6+D7-D4 -> 0 | E8: =E5+E6+E7-E4 -> 0 | F8: =F5+F6+F7-F4 -> 0 | G8: =G5+G6+G7-G4 -> 0
A9: CSBG | B9: US$B | C9: =Q!E5 -> 2.110906 | D9: =Q!F5 -> 2.47239 | E9: =Q!G5 -> 2.486511 | F9: =Q!H5 -> 2.486511 | G9: =SUM(C9:F9) -> 9.556318
A11: CY2025 與 CY2026 年增（對照公司說法）
A12: CY2025 系統營收（FY25 Q3＋Q4＋FY26 Q1＋Q2） | B12: US$B | G12: =Q!B34+Q!C34+Q!C4+Q!D4 -> 13.377959
A13: CY2025 CSBG | B13: US$B | G13: =Q!B35+Q!C35+Q!C5+Q!D5 -> 7.182573
A14: CY2026 系統營收年增 | B14: % | G14: =G4/G12-1 -> 0.48205163 | H14: 公司：well over 40%（含 12 月季指引中點）
A15: CY2026 CSBG 年增 | B15: % | G15: =G9/G13-1 -> 0.33048672 | H15: 公司：逾 30%
A16: CY2026 下半系統營收（FY27 Q1＋Q2） | B16: US$B | G16: =E4+F4 -> 11.846396
A17: CY2026 下半 CSBG | B17: US$B | G17: =E9+F9 -> 4.973022
A19: 份額係數 k＝CY2026 Lam 系統營收（客戶別）÷ 設備市場模型 CY2026 分項（三情境 CY2026 相同）
A20: 分項 | B20: 單位 | C20: Lam CY2026 | D20: WFE 分項 CY2026 | E20: k | H20: 說明
A21: 代工與邏輯 | B21: US$B | C21: =cy26_fl -> 10.967627 | D21: =advA_26+oflA_26 -> 82.259373 | E21: =C21/D21 -> 0.13332981 | H21: Derived：只用公司實績與指引，未用共識；k 是「系統營收 ÷ 模型 WFE 分項」，不是嚴格市占（口徑：系統營收不含升級與 Reliant；WFE 模型為設備市場模型由下而上值）
A22: DRAM（含 HBM） | B22: US$B | C22: =cy26_dram -> 4.3540014 | D22: =dramA_26 -> 39.365947 | E22: =C22/D22 -> 0.11060324 | H22: Derived：只用公司實績與指引，未用共識；k 是「系統營收 ÷ 模型 WFE 分項」，不是嚴格市占（口徑：系統營收不含升級與 Reliant；WFE 模型為設備市場模型由下而上值）
A23: NAND | B23: US$B | C23: =cy26_nand -> 4.5051978 | D23: =nandA_26 -> 17.503905 | E23: =C23/D23 -> 0.25738244 | H23: Derived：只用公司實績與指引，未用共識；k 是「系統營收 ÷ 模型 WFE 分項」，不是嚴格市占（口徑：系統營收不含升級與 Reliant；WFE 模型為設備市場模型由下而上值）
A24: 合計：Lam 系統營收 ÷ 模型晶圓前段設備 | C24: =cy26_sys -> 19.826826 | D24: =wfeA_26 -> 156.15705 | E24: =C24/D24 -> 0.12696722
A25: 對照：Lam（系統＋CSBG）÷ 公司估 CY2026 WFE | C25: =cy26_sys+cy26_cs -> 29.383144 | D25: =co_wfe26 -> 155 | E25: =C25/D25 -> 0.18956867 | H25: CSBG 不屬 WFE，僅供量級參考

Sheet PL
A1: PL — Lam Research 損益（US$B；FY2025、FY2026 為實績，FY2027 起為模型；FY2027 上半錨定 Q1 實績＋Q2 指引）。三情境各一個完整推導區塊（見下方），本頁頂端為摘要
A3: 情境／項目 | B3: 單位 | C3: FY2025A | D3: FY2026A | E3: FY2027 | F3: FY2028 | G3: FY2029 | H3: 說明
A4: 情境 A
A5: 營收 | B5: US$B | C5: =C52 -> 18.435591 | D5: =D52 -> 23.23269 | E5: =E52 -> 34.602293 | F5: =F52 -> 37.751047 | G5: =G52 -> 41.470747
A6: 系統營收 | B6: US$B | C6: =C50 -> 11.49128 | D6: =D50 -> 14.885488 | E6: =E50 -> 24.134388 | F6: =F50 -> 26.101895 | G6: =G50 -> 28.423697
A7: CSBG | B7: US$B | C7: =C51 -> 6.944311 | D7: =D51 -> 8.347202 | E7: =E51 -> 10.467905 | F7: =F51 -> 11.649152 | G7: =G51 -> 13.04705
A8: 毛利率 | B8: % | C8: =C53 -> 0.48705024 | D8: =D53 -> 0.50469007 | E8: =E53 -> 0.52550385 | F8: =F53 -> 0.53005437 | G8: =G53 -> 0.53496444
A9: 營業利益 | B9: US$B | C9: =C56 -> 5.900968 | D9: =D56 -> 8.199795 | E9: =E56 -> 14.036729 | F9: =F56 -> 15.691106 | G9: =G56 -> 17.663077
A10: 營業利益率 | B10: % | C10: =C57 -> 0.32008564 | D10: =D57 -> 0.35294213 | E10: =E57 -> 0.40565894 | F10: =F57 -> 0.41564691 | G10: =G57 -> 0.42591653
A11: 淨利 | B11: US$B | C11: =C58 -> 5.358217 | D11: =D58 -> 7.265396 | E11: =E58 -> 11.804169 | F11: =F58 -> 13.185573 | G11: =G58 -> 14.832169
A12: EPS（稀釋） | B12: US$ | C12: =C60 -> 4.15 | D12: =D60 -> 5.76 | E12: =E60 -> 9.4207254 | F12: =F60 -> 10.683455 | G12: =G60 -> 12.200599
A14: 情境 B
A15: 營收 | B15: US$B | C15: =C76 -> 18.435591 | D15: =D76 -> 23.23269 | E15: =E76 -> 34.602293 | F15: =F76 -> 35.895442 | G15: =G76 -> 35.96021
A16: 系統營收 | B16: US$B | C16: =C74 -> 11.49128 | D16: =D74 -> 14.885488 | E16: =E74 -> 24.134388 | F16: =F74 -> 24.575983 | G16: =G74 -> 23.961584
A17: CSBG | B17: US$B | C17: =C75 -> 6.944311 | D17: =D75 -> 8.347202 | E17: =E75 -> 10.467905 | F17: =F75 -> 11.319459 | G17: =G75 -> 11.998626
A18: 毛利率 | B18: % | C18: =C77 -> 0.48705024 | D18: =D77 -> 0.50469007 | E18: =E77 -> 0.52550385 | F18: =F77 -> 0.52742088 | G18: =G77 -> 0.52751507
A19: 營業利益 | B19: US$B | C19: =C80 -> 5.900968 | D19: =D80 -> 8.199795 | E19: =E80 -> 14.036729 | F19: =F80 -> 14.714421 | G19: =G80 -> 14.748428
A20: 營業利益率 | B20: % | C20: =C81 -> 0.32008564 | D20: =D81 -> 0.35294213 | E20: =E81 -> 0.40565894 | F20: =F81 -> 0.40992449 | G20: =G81 -> 0.41013186
A21: 淨利 | B21: US$B | C21: =C82 -> 5.358217 | D21: =D82 -> 7.265396 | E21: =E82 -> 11.804169 | F21: =F82 -> 12.370041 | G21: =G82 -> 12.398437
A22: EPS（稀釋） | B22: US$ | C22: =C84 -> 4.15 | D22: =D84 -> 5.76 | E22: =E84 -> 9.4207254 | F22: =F84 -> 10.02268 | G22: =G84 -> 10.198667
A24: 情境 C
A25: 營收 | B25: US$B | C25: =C100 -> 18.435591 | D25: =D100 -> 23.23269 | E25: =E100 -> 34.602293 | F25: =F100 -> 32.274838 | G25: =G100 -> 28.824025
A26: 系統營收 | B26: US$B | C26: =C98 -> 11.49128 | D26: =D98 -> 14.885488 | E26: =E98 -> 24.134388 | F26: =F98 -> 21.449918 | G26: =G98 -> 18.323853
A27: CSBG | B27: US$B | C27: =C99 -> 6.944311 | D27: =D99 -> 8.347202 | E27: =E99 -> 10.467905 | F27: =F99 -> 10.824919 | G27: =G99 -> 10.500172
A28: 毛利率 | B28: % | C28: =C101 -> 0.48705024 | D28: =D101 -> 0.50469007 | E28: =E101 -> 0.52550385 | F28: =F101 -> 0.52186567 | G28: =G101 -> 0.51595745
A29: 營業利益 | B29: US$B | C29: =C104 -> 5.900968 | D29: =D104 -> 8.199795 | E29: =E104 -> 14.036729 | F29: =F104 -> 12.823426 | G29: =G104 -> 11.040868
A30: 營業利益率 | B30: % | C30: =C105 -> 0.32008564 | D30: =D105 -> 0.35294213 | E30: =E105 -> 0.40565894 | F30: =F105 -> 0.39731961 | G30: =G105 -> 0.38304393
A31: 淨利 | B31: US$B | C31: =C106 -> 5.358217 | D31: =D106 -> 7.265396 | E31: =E106 -> 11.804169 | F31: =F106 -> 10.791061 | G31: =G106 -> 9.3026246
A32: EPS（稀釋） | B32: US$ | C32: =C108 -> 4.15 | D32: =D108 -> 5.76 | E32: =E108 -> 9.4207254 | F32: =F108 -> 8.7433292 | G32: =G108 -> 7.6521234
A34: 核對：FY2025、FY2026 模型＝實績（營收、EPS 差的絕對值合計，應為 0）
C35: =ABS(C5-a25_rev)+ABS(C12-a25_eps)+ABS(D5-a26_rev)+ABS(D12-a26_eps)+ABS(C15-a25_rev)+ABS(C22-a25_eps)+ABS(D15-a26_rev)+ABS(D22-a26_eps)+ABS(C25-a25_rev)+ABS(C32-a25_eps)+ABS(D25-a26_rev)+ABS(D32-a26_eps) -> 0
A40: 情境 A：設備市場續增（markets/equipment A：2029 見頂）
A41: 項目 | B41: 單位 | C41: FY2025 | D41: CY2026／FY2026 | E41: CY2027／FY2027 | F41: CY2028／FY2028 | G41: CY2029／FY2029 | H41: 說明
A42: A. 日曆年（D＝CY2026 … G＝CY2029）
A43: 系統營收：代工與邏輯 | B43: US$B | D43: =cy26_fl -> 10.967627 | E43: =k_fl*(advA_27+oflA_27)*(1+drift)^1 -> 12.701761 | F43: =k_fl*(advA_28+oflA_28)*(1+drift)^2 -> 14.301566 | G43: =k_fl*(advA_29+oflA_29)*(1+drift)^3 -> 15.257963 | H43: CY2026＝錨點（實績＋指引）；之後＝k × 設備市場模型分項 × (1＋份額漂移)^年
A44: 系統營收：DRAM | B44: US$B | D44: =cy26_dram -> 4.3540014 | E44: =k_dram*dramA_27*(1+drift)^1 -> 5.8905886 | F44: =k_dram*dramA_28*(1+drift)^2 -> 6.5876287 | G44: =k_dram*dramA_29*(1+drift)^3 -> 6.8387415 | H44: CY2026＝錨點（實績＋指引）；之後＝k × 設備市場模型分項 × (1＋份額漂移)^年
A45: 系統營收：NAND | B45: US$B | D45: =cy26_nand -> 4.5051978 | E45: =k_nand*nandA_27*(1+drift)^1 -> 5.9836339 | F45: =k_nand*nandA_28*(1+drift)^2 -> 6.7386124 | G45: =k_nand*nandA_29*(1+drift)^3 -> 7.1228821 | H45: CY2026＝錨點（實績＋指引）；之後＝k × 設備市場模型分項 × (1＋份額漂移)^年
A46: 出口管制：中國系統營收折損 | B46: US$B | E46: =-cn_sh*0*(E43+E44+E45) -> 0 | F46: =-cn_sh*0*(F43+F44+F45) -> 0 | G46: =-cn_sh*0*(G43+G44+G45) -> 0 | H46: −中國占比 × 折損比例 × 系統營收；情境 C 自 CY2028 起 cutC，其餘為 0（Sens 另設）
A47: 系統營收 CY | B47: US$B | D47: =SUM(D43:D46) -> 19.826826 | E47: =SUM(E43:E46) -> 24.575983 | F47: =SUM(F43:F46) -> 27.627807 | G47: =SUM(G43:G46) -> 29.219587
A48: CSBG CY | B48: US$B | D48: =cy26_cs -> 9.556318 | E48: =D48*(1+g_cs27) -> 10.989766 | F48: =E48*(1+g_cs_A) -> 12.308538 | G48: =F48*(1+g_cs_A) -> 13.785562 | H48: CY2026＝錨點；CY2027 公司稱逾 15%；之後依情境
...

Sheet Val
A1: Val — P/E 估值。跨公司規則：合理倍數＝10 年（2016–2025 年底）P/E 的分位，依循環位置：見頂年 25 分位、中段中位數、谷底 75 分位。循環位置依設備股共用規則（見第 4 節）
A2: P/E 定義（自算）：日曆年底收盤價 ÷ 「當期會計年度」公司公布的基本 EPS（年底所在會計年度，例如 2025-12 對 FY2026＝2025-07～2026-06）。價格與 EPS 皆為 2024-10 的 10 比 1 分割調整後
A3: 目標價（DCF 與 Comparable 加權）：見本頁第 94 列起「0. 目標價」（估值 v2 新增，放在既有內容之後以免位移既有列）；原「0. 目標價與上檔空間」改名為「舊法：規則值情境加權（參考）」
A4: 舊法：規則值情境加權（參考）
A5: 項目 | B5: 數值 | C5: 說明
A6: 規則值情境加權價（12 個月；參考） | B6: =tp_wA*B8+tp_wB*B9+tp_wC*B10 -> 154.25592 | C6: ＝權重 A × 情境 A 隱含價＋權重 B × 情境 B 隱含價＋權重 C × 情境 C 隱含價
A7: 相對現價（規則值情境加權價 ÷ 現價 − 1） | B7: =B6/px-1 -> -0.32961356 | C7: 現價：stockanalysis 2026-10-23 收盤
A8: 情境 A 隱含價（樂觀） | B8: =F61 -> 163.31512 | C8: ＝第 5 節規則值（FY2027 EPS × 依循環位置的倍數）
A9: 情境 B 隱含價（基準） | B9: =F68 -> 163.31512 | C9: 同上
A10: 情境 C 隱含價（下檔） | B10: =F75 -> 118.01913 | C10: 同上
A11: 情境權重 A／B／C | B11: =tp_wA -> 0.3 | C11: =tp_wB -> 0.5 | D11: =tp_wC -> 0.2 | E11: In 頁 tp_wA／tp_wB／tp_wC（Assumed；Andy 可改）
A12: 規則值方法 | B12: P/E：模型 FY2027 稀釋 EPS（A／B／C 各自）× 依設備股共用循環規則的 10 年（2016–2025 年底）當期 P/E 分位（A、B 中段＝中位數，C 見頂＝25 分位）；樣本含 2018、2022 記憶體下行年的低倍數與 2023、2025 年底的 AI 高倍數，未調整
A13: 檢查：權重合計 − 1（應為 0） | B13: =tp_wA+tp_wB+tp_wC-1 -> 0
A16: 1. 公司公布 EPS（會計年度，美元，分割調整後）— 兩個來源
A17: 會計年度（6 月結束） | B17: 來源1：10-K 基本 EPS（分割調整） | C17: 來源2：10-K 稀釋 EPS（分割調整） | D17: 基本 ÷ 稀釋 − 1 | E17: 原始基本 EPS（分割前） | F17: 標記 | G17: 說明
A18: FY2016 | B18: =E18/10 -> 0.575 | C18: 0.522 | D18: =B18/C18-1 -> 0.10153257 | E18: 5.75 | F18: Verified | G18: SEC XBRL（各年 10-K）：分割前基本 EPS ÷ 10；稀釋同理
A19: FY2017 | B19: =E19/10 -> 1.047 | C19: 0.924 | D19: =B19/C19-1 -> 0.13311688 | E19: 10.47 | F19: Verified | G19: SEC XBRL（各年 10-K）：分割前基本 EPS ÷ 10；稀釋同理
A20: FY2018 | B20: =E20/10 -> 1.473 | C20: 1.317 | D20: =B20/C20-1 -> 0.11845103 | E20: 14.73 | F20: Verified | G20: SEC XBRL（各年 10-K）：分割前基本 EPS ÷ 10；稀釋同理
A21: FY2019 | B21: =E21/10 -> 1.437 | C21: 1.37 | D21: =B21/C21-1 -> 0.048905109 | E21: 14.37 | F21: Verified | G21: SEC XBRL（各年 10-K）：分割前基本 EPS ÷ 10；稀釋同理
A22: FY2020 | B22: =E22/10 -> 1.555 | C22: 1.51 | D22: =B22/C22-1 -> 0.029801325 | E22: 15.55 | F22: Verified | G22: SEC XBRL（各年 10-K）：分割前基本 EPS ÷ 10；稀釋同理
A23: FY2021 | B23: =E23/10 -> 2.722 | C23: 2.69 | D23: =B23/C23-1 -> 0.011895911 | E23: 27.22 | F23: Verified | G23: SEC XBRL（各年 10-K）：分割前基本 EPS ÷ 10；稀釋同理
A24: FY2022 | B24: =E24/10 -> 3.292 | C24: 3.275 | D24: =B24/C24-1 -> 0.0051908397 | E24: 32.92 | F24: Verified | G24: SEC XBRL（各年 10-K）：分割前基本 EPS ÷ 10；稀釋同理
A25: FY2023 | B25: 3.33 | C25: 3.32 | D25: =B25/C25-1 -> 0.0030120482 | E25: =B25*10 -> 33.3 | F25: Verified | G25: FY2025／FY2026 10-K（分割後重編）；E 欄為 ×10 還原（Derived）
A26: FY2024 | B26: 2.91 | C26: 2.9 | D26: =B26/C26-1 -> 0.0034482759 | E26: =B26*10 -> 29.1 | F26: Verified | G26: FY2025／FY2026 10-K（分割後重編）；E 欄為 ×10 還原（Derived）
A27: FY2025 | B27: 4.17 | C27: 4.15 | D27: =B27/C27-1 -> 0.0048192771 | E27: =B27*10 -> 41.7 | F27: Verified | G27: FY2025／FY2026 10-K（分割後重編）；E 欄為 ×10 還原（Derived）
A28: FY2026 | B28: 5.79 | C28: 5.76 | D28: =B28/C28-1 -> 0.0052083333 | E28: =B28*10 -> 57.9 | F28: Verified | G28: FY2025／FY2026 10-K（分割後重編）；E 欄為 ×10 還原（Derived）
A29: 全部年度統一用基本 EPS（Basic，比照樣板）。來源2 為同一份 10-K 的稀釋 EPS（非獨立來源，只作口徑對照）；獨立的第二個 EPS 來源：未找到（macrotrends、stockanalysis 頁面未取得年度表）
A30: 2. 10 年 P/E（年底）
A31: 年底 | B31: 收盤價 US$（分割調整，未還原股利） | C31: 當期 FY EPS（基本） | D31: 前期 FY EPS（基本） | E31: P/E 當期（自算） | F31: P/E 前期（自算） | G31: companiesmarketcap P/E | H31: 自算當期 − cmc | I31: macrotrends 年底價（還原股利） | J31: 標記 | K31: 來源／說明
A32: 2016-12 | B32: =105.73/10 -> 10.573 | C32: =B19 -> 1.047 | D32: =B18 -> 0.575 | E32: =B32/C32 -> 10.098376 | F32: =B32/D32 -> 18.387826 | G32: 15.1 | H32: =E32-G32 -> -5.0016237 | I32: 9.3223 | J32: Verified／Derived | K32: 收盤價：digrin「Real price」（分割前原價 ÷ 10）
A33: 2017-12 | B33: =184.07/10 -> 18.407 | C33: =B20 -> 1.473 | D33: =B19 -> 1.047 | E33: =B33/C33 -> 12.496266 | F33: =B33/D33 -> 17.580707 | G33: 15.9 | H33: =E33-G33 -> -3.4037339 | I33: 16.4265 | J33: Verified／Derived | K33: 收盤價：digrin「Real price」（分割前原價 ÷ 10）
A34: 2018-12 | B34: =136.17/10 -> 13.617 | C34: =B21 -> 1.437 | D34: =B20 -> 1.473 | E34: =B34/C34 -> 9.4759916 | F34: =B34/D34 -> 9.2443992 | G34: 6.83 | H34: =E34-G34 -> 2.6459916 | I34: 12.4183 | J34: Verified／Derived | K34: 收盤價：digrin「Real price」（分割前原價 ÷ 10）
A35: 2019-12 | B35: =292.4/10 -> 29.24 | C35: =B22 -> 1.555 | D35: =B21 -> 1.437 | E35: =B35/C35 -> 18.803859 | F35: =B35/D35 -> 20.347947 | G35: 19.4 | H35: =E35-G35 -> -0.59614148 | I35: 27.2375 | J35: Verified／Derived | K35: 收盤價：digrin「Real price」（分割前原價 ÷ 10）
A36: 2020-12 | B36: =472.27/10 -> 47.227 | C36: =B23 -> 2.722 | D36: =B22 -> 1.555 | E36: =B36/C36 -> 17.35011 | F36: =B36/D36 -> 30.371061 | G36: 21.9 | H36: =E36-G36 -> -4.5498898 | I36: 44.7187 | J36: Verified／Derived | K36: 收盤價：digrin「Real price」（分割前原價 ÷ 10）
A37: 2021-12 | B37: =719.15/10 -> 71.915 | C37: =B24 -> 3.292 | D37: =B23 -> 2.722 | E37: =B37/C37 -> 21.845383 | F37: =B37/D37 -> 26.419912 | G37: 21.3 | H37: =E37-G37 -> 0.54538275 | I37: 68.7159 | J37: Verified／Derived | K37: 收盤價：digrin「Real price」（分割前原價 ÷ 10）
A38: 2022-12 | B38: =420.3/10 -> 42.03 | C38: =B25 -> 3.33 | D38: =B24 -> 3.292 | E38: =B38/C38 -> 12.621622 | F38: =B38/D38 -> 12.767315 | G38: 11 | H38: =E38-G38 -> 1.6216216 | I38: 40.7327 | J38: Verified／Derived | K38: 收盤價：digrin「Real price」（分割前原價 ÷ 10）
A39: 2023-12 | B39: =783.26/10 -> 78.326 | C39: =B26 -> 2.91 | D39: =B25 -> 3.33 | E39: =B39/C39 -> 26.916151 | F39: =B39/D39 -> 23.521321 | G39: 29.7 | H39: =E39-G39 -> -2.7838488 | I39: 76.8336 | J39: Verified／Derived | K39: 收盤價：digrin「Real price」（分割前原價 ÷ 10）
A40: 2024-12 | B40: 72.23 | C40: =B27 -> 4.17 | D40: =B26 -> 2.91 | E40: =B40/C40 -> 17.321343 | F40: =B40/D40 -> 24.821306 | G40: 21.7 | H40: =E40-G40 -> -4.3786571 | I40: 71.5745 | J40: Verified／Derived | K40: 收盤價：digrin（分割後）
A41: 2025-12 | B41: 171.18 | C41: =B28 -> 5.79 | D41: =B27 -> 4.17 | E41: =B41/C41 -> 29.564767 | F41: =B41/D41 -> 41.05036 | G41: 34.9 | H41: =E41-G41 -> -5.3352332 | I41: 171.18 | J41: Verified／Derived | K41: 收盤價：digrin（分割後）
A42: 收盤價來源1：digrin 年底原價（2016–2023 為分割前，公式 ÷ 10）；來源2：macrotrends 年底價（分割與股利還原，故早年較低；2025 相同）。companiesmarketcap 為 TTM 口徑，只作對照（差距見 H 欄）。
...

Sheet Recon
A1: Recon — 本模型 vs 公司說法、共識、設備市場模型。只作事後對照，不為對上數字而調整參數。差距 > 10% 的原因見 README
A3: 項目 | B3: 對照值 | C3: 模型 A | D3: 差距 A | E3: 模型 B | F3: 差距 B | G3: 模型 C | H3: 差距 C | I3: 對照來源 | J3: 說明
A4: A. FY2027、FY2028 vs 共識（校準未使用共識）
A5: FY2027 營收 | B5: =cons_rev27 -> 35.39 | C5: =PL!E5 -> 34.602293 | D5: =C5/B5-1 -> -0.02225791 | E5: =PL!E15 -> 34.602293 | F5: =E5/B5-1 -> -0.02225791 | G5: =PL!E25 -> 34.602293 | H5: =G5/B5-1 -> -0.02225791 | I5: Yahoo（29 位） | J5: stockanalysis 34.9
A6: FY2027 EPS（Yahoo） | B6: =cons_eps27 -> 9.63 | C6: =PL!E12 -> 9.4207254 | D6: =C6/B6-1 -> -0.02173153 | E6: =PL!E22 -> 9.4207254 | F6: =E6/B6-1 -> -0.02173153 | G6: =PL!E32 -> 9.4207254 | H6: =G6/B6-1 -> -0.02173153 | I6: Yahoo（9.63） | J6: 共識多為非 GAAP；Lam 非 GAAP 與 GAAP 差約 0.01／季
A7: FY2027 EPS（stockanalysis） | B7: =cons_eps27b -> 9.48 | C7: =PL!E12 -> 9.4207254 | D7: =C7/B7-1 -> -0.0062525981 | E7: =PL!E22 -> 9.4207254 | F7: =E7/B7-1 -> -0.0062525981 | G7: =PL!E32 -> 9.4207254 | H7: =G7/B7-1 -> -0.0062525981 | I7: stockanalysis（9.48）
A8: FY2028 營收 | B8: =cons_rev28 -> 42.68 | C8: =PL!F5 -> 37.751047 | D8: =C8/B8-1 -> -0.11548624 | E8: =PL!F15 -> 35.895442 | F8: =E8/B8-1 -> -0.1589634 | G8: =PL!F25 -> 32.274838 | H8: =G8/B8-1 -> -0.24379481 | I8: Yahoo（28 位；區間 36.5–49.2）
A9: FY2028 EPS | B9: =cons_eps28 -> 12.15 | C9: =PL!F12 -> 10.683455 | D9: =C9/B9-1 -> -0.1207033 | E9: =PL!F22 -> 10.02268 | F9: =E9/B9-1 -> -0.17508809 | G9: =PL!F32 -> 8.7433292 | H9: =G9/B9-1 -> -0.28038443 | I9: Yahoo（12.15；區間 10.41–15.12）
A10: B. 公司說法（法說，Interested-party）
A11: CY2026 系統營收年增（公司：well over 40%） | B11: =co_sys26 -> 0.4 | C11: =Units!G14 -> 0.48205163 | D11: =C11-B11 -> 0.082051634 | E11: =Units!G14 -> 0.48205163 | F11: =E11-B11 -> 0.082051634 | G11: =Units!G14 -> 0.48205163 | H11: =G11-B11 -> 0.082051634 | I11: FQ1-27 法說 | J11: 模型值＝實績＋指引（含 Q2 拆分假設），非獨立檢驗
A12: CY2026 CSBG 年增（公司：逾 30%） | B12: =co_cs26 -> 0.3 | C12: =Units!G15 -> 0.33048672 | D12: =C12-B12 -> 0.030486721 | E12: =Units!G15 -> 0.33048672 | F12: =E12-B12 -> 0.030486721 | G12: =Units!G15 -> 0.33048672 | H12: =G12-B12 -> 0.030486721 | I12: FQ1-27 法說 | J12: 同上；Q2 CSBG＝Q1 持平時
A13: FY2027 毛利率 vs Q2 指引 52.5% | B13: =g_q2gm -> 0.525 | C13: =PL!E8 -> 0.52550385 | D13: =C13-B13 -> 0.00050385404 | E13: =PL!E18 -> 0.52550385 | F13: =E13-B13 -> 0.00050385404 | G13: =PL!E28 -> 0.52550385 | H13: =G13-B13 -> 0.00050385404 | I13: 8-K 2026-10-21 | J13: 公司稱近期維持目前水準；長期 mid-50s
A14: FY2029 毛利率 vs 公司長期目標（mid-50s，取 55%） | B14: =0.55 -> 0.55 | C14: =PL!G8 -> 0.53496444 | D14: =C14-B14 -> -0.015035555 | E14: =PL!G18 -> 0.52751507 | F14: =E14-B14 -> -0.02248493 | G14: =PL!G28 -> 0.51595745 | H14: =G14-B14 -> -0.034042547 | I14: FQ4-26／FQ1-27 法說
A15: C. 設備市場（WFE，US$B）
A16: CY2026 晶圓前段（公司 mid-$150B vs 設備市場模型） | B16: =co_wfe26 -> 155 | C16: =wfeA_26 -> 156.15705 | D16: =C16/B16-1 -> 0.0074648424 | E16: =wfeB_26 -> 156.15705 | F16: =E16/B16-1 -> 0.0074648424 | G16: =wfeC_26 -> 156.15705 | H16: =G16/B16-1 -> 0.0074648424 | I16: FQ1-27 法說 | J16: 口徑不同（公司 CY2025 約 110、SEMI 116.9）
A17: CY2027 晶圓前段（公司 >$200B vs 設備市場模型） | B17: =co_wfe27 -> 200 | C17: =wfeA_27 -> 192.79547 | D17: =C17/B17-1 -> -0.036022653 | E17: =wfeB_27 -> 192.79547 | F17: =E17/B17-1 -> -0.036022653 | G17: =wfeC_27 -> 192.79547 | H17: =G17/B17-1 -> -0.036022653 | I17: FQ1-27 法說 | J17: 下限值
A18: CY2026／CY2025 晶圓前段成長：公司（155÷110）vs 模型 | B18: =co_wfe26/co_wfe25-1 -> 0.40909091 | C18: =wfeA_26/wfeA_25-1 -> 0.33585357 | D18: =C18-B18 -> -0.073237335 | E18: =wfeB_26/wfeB_25-1 -> 0.33585357 | F18: =E18-B18 -> -0.073237335 | G18: =wfeC_26/wfeC_25-1 -> 0.33585357 | H18: =G18-B18 -> -0.073237335 | I18: FQ2-26、FQ1-27 法說
A19: D. 其他資訊（非對帳）
A20: FY2027 上半（Q1 實績＋Q2 指引）÷ 模型 FY2027 全年營收（A） | C20: =(q1_rev+g_q2rev)/PL!E5 -> 0.48607814
A21: FY2027 上半 EPS（Q1 實績＋Q2 指引）÷ 模型 FY2027 EPS（A） | C21: =(q1_eps+g_q2eps)/PL!E12 -> 0.4797932
A22: Lam 系統營收 ÷ 模型晶圓前段（CY2026） | C22: =Units!E24 -> 0.12696722

Sheet Sens
A1: Sens — 一次動一個輸入（情境 A）：對 FY2027、FY2028 營收與 EPS 的影響。每個案例是一個完整的推導區塊（本頁下方，與 PL 同一引擎）
A3: 案例 | B3: 設定 | C3: FY2027 營收 US$B | D3: FY2027 EPS US$ | E3: 相對基準 | F3: FY2028 營收 US$B | G3: FY2028 EPS US$ | H3: 相對基準
A4: 基準（情境 A） | B4: PL 區塊 A | C4: =PL!E52 -> 34.602293 | D4: =PL!E60 -> 9.4207254 | E4: =D4/D$4-1 -> 0 | F4: =PL!F52 -> 37.751047 | G4: =PL!F60 -> 10.683455 | H4: =G4/G$4-1 -> 0
A5: 份額漂移 −2%／年 | B5: CY2027 起每年相對 WFE 分項 −2% | C5: =E62 -> 34.356533 | D5: =E70 -> 9.3350856 | E5: =D5/D$4-1 -> -0.0090905665 | F5: =F62 -> 36.958257 | G5: =F70 -> 10.400741 | H5: =G5/G$4-1 -> -0.026462808
A6: 份額漂移 +2%／年 | B6: 每年 +2% | C6: =E92 -> 34.848052 | D6: =E100 -> 9.5064259 | E6: =D6/D$4-1 -> 0.0090970178 | F6: =F92 -> 38.554889 | G6: =F100 -> 10.970711 | H6: =G6/G$4-1 -> 0.026887931
A7: 出口管制：中國系統營收 −20%（CY2027 起） | B7: cn_sh 34% × 20% | C7: =E122 -> 33.766709 | D7: =E130 -> 9.1298009 | E7: =D7/D$4-1 -> -0.030881327 | F7: =F122 -> 35.976118 | G7: =F130 -> 10.051339 | H7: =G7/G$4-1 -> -0.059167753
A8: 出口管制：中國系統營收 −40%（CY2027 起） | B8: cn_sh 34% × 40%（2022 管制類比上緣） | C8: =E152 -> 32.931126 | D8: =E160 -> 8.8395964 | E8: =D8/D$4-1 -> -0.061686225 | F8: =F152 -> 34.201189 | G8: =F160 -> 9.4223196 | H8: =G8/G$4-1 -> -0.11804565
A9: 上半年占比 45% | B9: FY(t) 中 CY(t) 上半的權重 | C9: =E182 -> 32.824005 | D9: =E190 -> 8.8024456 | E9: =D9/D$4-1 -> -0.065629742 | F9: =F182 -> 37.532517 | G9: =F190 -> 10.605466 | H9: =G9/G$4-1 -> -0.007299926
A10: 上半年占比 55% | C10: =E212 -> 36.38058 | D10: =E220 -> 10.042189 | E10: =D10/D$4-1 -> 0.065967665 | F10: =F212 -> 37.969577 | G10: =F220 -> 10.761488 | H10: =G10/G$4-1 -> 0.0073041116
A11: CSBG CY2027 +10% | B11: 公司稱逾 15% | C11: =E242 -> 34.363385 | D11: =E250 -> 9.3374725 | E11: =D11/D$4-1 -> -0.0088372056 | F11: =F242 -> 37.244562 | G11: =F250 -> 10.50277 | H11: =G11/G$4-1 -> -0.016912551
A12: CSBG CY2027 +20% | C12: =E272 -> 34.841201 | D12: =E280 -> 9.5040357 | E12: =D12/D$4-1 -> 0.0088433022 | F12: =F272 -> 38.257532 | G12: =F280 -> 10.86438 | H12: =G12/G$4-1 -> 0.016935035
A13: CSBG CY2028–29 +8% | C13: =E302 -> 34.602293 | D13: =E310 -> 9.4207254 | E13: =D13/D$4-1 -> 0 | F13: =F302 -> 37.531252 | G13: =F310 -> 10.605015 | H13: =G13/G$4-1 -> -0.0073421881
A14: CSBG CY2028–29 +16% | C14: =E332 -> 34.602293 | D14: =E340 -> 9.4207254 | E14: =D14/D$4-1 -> 0 | F14: =F332 -> 37.970842 | G14: =F340 -> 10.76194 | H14: =G14/G$4-1 -> 0.0073464223
A15: 營業費用變動比例 低（15%） | B15: FY2026 營業費用中變動部分 15% | C15: =E362 -> 34.602293 | D15: =E370 -> 9.6623615 | E15: =D15/D$4-1 -> 0.025649414 | F15: =F362 -> 37.751047 | G15: =F370 -> 10.99671 | H15: =G15/G$4-1 -> 0.029321489
A16: 營業費用變動比例 高（50%） | B16: 變動 50% | C16: =E392 -> 34.602293 | D16: =E400 -> 9.2599489 | E16: =D16/D$4-1 -> -0.017066255 | F16: =F392 -> 37.751047 | G16: =F400 -> 10.475026 | H16: =G16/G$4-1 -> -0.01950953
A17: 稅率 13% | C17: =E422 -> 34.602293 | D17: =E430 -> 9.8156061 | E17: =D17/D$4-1 -> 0.041916168 | F17: =F422 -> 37.751047 | G17: =F430 -> 11.131264 | H17: =G17/G$4-1 -> 0.041916168
A18: 稅率 19% | C18: =E452 -> 34.602293 | D18: =E460 -> 9.1386677 | E18: =D18/D$4-1 -> -0.02994012 | F18: =F452 -> 37.751047 | G18: =F460 -> 10.363591 | H18: =G18/G$4-1 -> -0.02994012
A19: 庫藏股 0%／年 | C19: =E482 -> 34.602293 | D19: =E490 -> 9.4207254 | E19: =D19/D$4-1 -> 0 | F19: =F482 -> 37.751047 | G19: =F490 -> 10.523203 | H19: =G19/G$4-1 -> -0.015
A20: 庫藏股 3%／年 | C20: =E512 -> 34.602293 | D20: =E520 -> 9.4207254 | E20: =D20/D$4-1 -> 0 | F20: =F512 -> 37.751047 | G20: =F520 -> 10.848663 | H20: =G20/G$4-1 -> 0.015463918
A21: 業外收益 0 | C21: =E542 -> 34.602293 | D21: =E550 -> 9.3540853 | E21: =D21/D$4-1 -> -0.0070737721 | F21: =F542 -> 37.751047 | G21: =F550 -> 10.6158 | H21: =G21/G$4-1 -> -0.0063326787
A22: 業外收益 0.2 | C22: =E572 -> 34.602293 | D22: =E580 -> 9.4873654 | E22: =D22/D$4-1 -> 0.0070737721 | F22: =F572 -> 37.751047 | G22: =F580 -> 10.75111 | H22: =G22/G$4-1 -> 0.0063326787
A23: 設備市場情境 B | B23: WFE 分項讀 markets/equipment B；CSBG 成長 B | C23: =PL!E76 -> 34.602293 | D23: =PL!E84 -> 9.4207254 | E23: =D23/D$4-1 -> 0 | F23: =PL!F76 -> 35.895442 | G23: =PL!F84 -> 10.02268 | H23: =G23/G$4-1 -> -0.061850335
A24: 設備市場情境 C | B24: WFE 分項讀 C；出口管制 −20%（CY2028 起）；CSBG 成長 C | C24: =PL!E100 -> 34.602293 | D24: =PL!E108 -> 9.4207254 | E24: =D24/D$4-1 -> 0 | F24: =PL!F100 -> 32.274838 | G24: =PL!F108 -> 8.7433292 | H24: =G24/G$4-1 -> -0.18160097
A26: 讀法：FY2027 上半已錨定（Q1 實績＋Q2 指引），只有下半（CY2027 上半）隨輸入變動，所以 FY2027 的敏感度小、FY2028 才明顯；設備市場 B、C 的係數從 CY2028 開始。
A50: 案例區塊：份額漂移 −2%／年（情境 A）
A51: 項目 | B51: 單位 | C51: FY2025 | D51: CY2026／FY2026 | E51: CY2027／FY2027 | F51: CY2028／FY2028 | G51: CY2029／FY2029 | H51: 說明
A52: A. 日曆年（D＝CY2026 … G＝CY2029）
A53: 系統營收：代工與邏輯 | B53: US$B | D53: =cy26_fl -> 10.967627 | E53: =k_fl*(advA_27+oflA_27)*(1+drift_lo)^1 -> 12.447726 | F53: =k_fl*(advA_28+oflA_28)*(1+drift_lo)^2 -> 13.735224 | G53: =k_fl*(advA_29+oflA_29)*(1+drift_lo)^3 -> 14.360673 | H53: CY2026＝錨點（實績＋指引）；之後＝k × 設備市場模型分項 × (1＋份額漂移)^年
A54: 系統營收：DRAM | B54: US$B | D54: =cy26_dram -> 4.3540014 | E54: =k_dram*dramA_27*(1+drift_lo)^1 -> 5.7727768 | F54: =k_dram*dramA_28*(1+drift_lo)^2 -> 6.3267586 | G54: =k_dram*dramA_29*(1+drift_lo)^3 -> 6.4365688 | H54: CY2026＝錨點（實績＋指引）；之後＝k × 設備市場模型分項 × (1＋份額漂移)^年
A55: 系統營收：NAND | B55: US$B | D55: =cy26_nand -> 4.5051978 | E55: =k_nand*nandA_27*(1+drift_lo)^1 -> 5.8639612 | F55: =k_nand*nandA_28*(1+drift_lo)^2 -> 6.4717633 | G55: =k_nand*nandA_29*(1+drift_lo)^3 -> 6.7039996 | H55: CY2026＝錨點（實績＋指引）；之後＝k × 設備市場模型分項 × (1＋份額漂移)^年
A56: 出口管制：中國系統營收折損 | B56: US$B | E56: =-cn_sh*0*(E53+E54+E55) -> 0 | F56: =-cn_sh*0*(F53+F54+F55) -> 0 | G56: =-cn_sh*0*(G53+G54+G55) -> 0 | H56: −中國占比 × 折損比例 × 系統營收；情境 C 自 CY2028 起 cutC，其餘為 0（Sens 另設）
A57: 系統營收 CY | B57: US$B | D57: =SUM(D53:D56) -> 19.826826 | E57: =SUM(E53:E56) -> 24.084464 | F57: =SUM(F53:F56) -> 26.533746 | G57: =SUM(G53:G56) -> 27.501241
A58: CSBG CY | B58: US$B | D58: =cy26_cs -> 9.556318 | E58: =D58*(1+g_cs27) -> 10.989766 | F58: =E58*(1+g_cs_A) -> 12.308538 | G58: =F58*(1+g_cs_A) -> 13.785562 | H58: CY2026＝錨點；CY2027 公司稱逾 15%；之後依情境
A59: B. 會計年度（C＝FY2025 … G＝FY2029；FY(t)＝CY(t−1) 下半＋CY(t) 上半）
A60: 系統營收 | B60: US$B | C60: =a25_sys -> 11.49128 | D60: =a26_sys -> 14.885488 | E60: =h2s26+h1s*E57 -> 23.888628 | F60: =(1-h1s)*E57+h1s*F57 -> 25.309105 | G60: =(1-h1s)*F57+h1s*G57 -> 27.017494 | H60: FY2027＝CY2026 下半（FY27 Q1 實績＋Q2 指引）＋ h1 × CY2027
A61: CSBG | B61: US$B | C61: =a25_cs -> 6.944311 | D61: =a26_cs -> 8.347202 | E61: =h2c26+h1s*E58 -> 10.467905 | F61: =(1-h1s)*E58+h1s*F58 -> 11.649152 | G61: =(1-h1s)*F58+h1s*G58 -> 13.04705
A62: 營收 | B62: US$B | C62: =C60+C61 -> 18.435591 | D62: =D60+D61 -> 23.23269 | E62: =E60+E61 -> 34.356533 | F62: =F60+F61 -> 36.958257 | G62: =G60+G61 -> 40.064544
A63: 毛利率 | B63: % | C63: =a25_gp/a25_rev -> 0.48705024 | D63: =a26_gp/a26_rev -> 0.50469007 | E63: =gm_a+gm_b*LN(E62) -> 0.52513144 | F63: =gm_a+gm_b*LN(F62) -> 0.52894543 | G63: =gm_a+gm_b*LN(G62) -> 0.53316204 | H63: 截距＋斜率 × ln 營收（兩點推導）
A64: 毛利 | B64: US$B | C64: =C62*C63 -> 8.979059 | D64: =D62*D63 -> 11.725308 | E64: =E62*E63 -> 18.041695 | F64: =F62*F63 -> 19.548901 | G64: =G62*G63 -> 21.360894
A65: 營業費用 | B65: US$B | C65: =a25_opx -> 3.078091 | D65: =a26_opx -> 3.525513 | E65: =opex_fix+opex_var*E62 -> 4.1334771 | F65: =opex_fix+opex_var*F62 -> 4.2756721 | G65: =opex_fix+opex_var*G62 -> 4.4454436 | H65: 固定＋變動 × 營收
...

Sheet Sources
A1: 來源（公司財報取自 SEC EDGAR 原文；法說取自逐字稿摘要）
A2: 公司：FY27 Q1 8-K 新聞稿（2026-10-21） | B2: https://www.sec.gov/Archives/edgar/data/707549/000070754926000052/lrcx_exhibitx991xq1x2027.htm
A3: 公司：FY27 Q1 10-Q（2026-10-22） | B3: https://www.sec.gov/Archives/edgar/data/707549/000070754926000054/lrcx-20260927.htm
A4: 公司：FY2026 10-K（2026-08-07） | B4: https://www.sec.gov/Archives/edgar/data/707549/000070754926000037/lrcx-20260628.htm
A5: 公司：FY26 Q4 8-K 新聞稿（2026-07-29） | B5: https://www.sec.gov/Archives/edgar/data/707549/000070754926000033/lrcx_exhibitx991xq4x2026.htm
A6: 公司：FY26 Q3 8-K 新聞稿（2026-04-22） | B6: https://www.sec.gov/Archives/edgar/data/707549/000070754926000020/lrcx_exhibitx991xq3x2026.htm
A7: 公司：FY26 Q2 8-K 新聞稿（2026-01-28） | B7: https://www.sec.gov/Archives/edgar/data/707549/000070754926000006/lrcx_exhibitx991xq2x2026.htm
A8: 公司：FY26 Q1 8-K 新聞稿（2025-10-22） | B8: https://www.sec.gov/Archives/edgar/data/707549/000070754925000082/lrcx_exhibitx991xq1x2026.htm
A9: 公司：FY25 Q4 8-K 新聞稿（2025-07-30） | B9: https://www.sec.gov/Archives/edgar/data/707549/000070754925000068/lrcx_exhibitx991xq4x2025.htm
A10: 公司：10-Q（FY26 Q1、Q2、Q3：客戶別占比） | B10: https://www.sec.gov/Archives/edgar/data/707549/000070754926000022/lrcx-20260329.htm
A11: SEC XBRL：EPS 歷史（基本、稀釋） | B11: https://data.sec.gov/api/xbrl/companyconcept/CIK0000707549/us-gaap/EarningsPerShareBasic.json
A12: Motley Fool：FQ1-27 法說逐字稿（WFE、客戶別、CSBG、稅率） | B12: https://www.fool.com/earnings/call-transcripts/2026/10/21/lam-research-lrcx-q1-2027-earnings-call-transcript/
A13: MarketBeat：FQ4-26 法說重點（6 月季客戶別、WFE low-$150B） | B13: https://www.marketbeat.com/instant-alerts/lam-research-q4-earnings-call-highlights-2026-07-29/
... A24: SemiAnalysis | B24: 未使用
