Workbook

Sheet README
A1: 三星電子 收支與估值模型 v0.3.2（記憶體樣板 v0.4.1） 2026-10-25
A2: 模型命題：三星電子 2026 年的獲利幾乎全部來自記憶體，盈餘由一般 DRAM 價格循環與 HBM 份額追趕兩條線決定；股價取決於循環見頂的年度、見頂時累積的淨值，以及非記憶體事業（手機、晶圓代工、面板、家電）在谷底時能撐住多少。
A4: 驅動因子 → 推導量
A5: Path（共用市場層）：一般 DRAM、NAND 合約價季增 → 季度指數（情境 A／B／C）；各公司依會計年度取平均，算年均價變動
A6: Mkt（共用市場層）：加速器顆數 × 每顆 GB × 情境顆數係數（2028–29，與台積電、Advantest 同一套）→ 需求位元；MIN(需求, 供給（三情境相同）) → 出貨；× 單價（依情境）→ HBM 市場（日曆年）
A7: Q：最後實績季 × 公司指引 × TrendForce 季價 → 基準年剩餘季度
A8: Y：前一年 × (1＋位元) × 價格指數比 → 一般 DRAM、NAND；Σ 各季 HBM 市場 × 市占 → HBM；成本量 × (1 − 年降)＋折舊 → 營業利益 → 淨利 → 權益 → 每股淨值
A9: Val：第 0 節目標價＝DCF（股東現金流，FY2027–FY2032 明確期＋永續）與 Comparable（同業前瞻 P/B × 前瞻每股淨值）加權；另有每股淨值 × P/B（主）、EPS × P/E（對照）與十年倍數規則值
A10: Sens：各收入線同幅變動對營業利益的影響
A11: 非記憶體事業（只有三星）：營收與營業利益為輸入，不建模
A12: Recon：與共識、公司指引事後對照
A14: 情境：A＝2027–28 高檔持平、2029 緩降（BofA、TrendForce 型）；B＝2027 Q2 見頂、2028 回落約一半、2029 溫和回升（Citi、Bernstein 型）；C＝2028 回到 2025 年價格水準、2029 自谷底回升（完整循環）（目標價對應：A＝順利、B＝平平、C＝不如預期；2030–2032 為收斂法）
... A26: v0.3.2（2026-10-28）：分部原則重建。Q 頁第 20 列起新增官方報告分部 DX／DS／SDC／Harman、內部抵銷（差額）與合併營收（2025Q1～2026Q2 實績），核對列「分部合計 − 合併營收」；記憶體營收屬 DS。損益、EPS、目標價與 v0.3.1 相同。
A27: ="投資建議："&Val!B185&"（依上檔空間固定規則）" -> 投資建議：強力買進（依上檔空間固定規則）
A28: 重點觀察 1：目標價 ₩477,143（DCF 486,542、Comparable 467,744 各半），比現價 215,500（2026-10-23）高 121.4%，級距 大於 50%；Comparable 單獨為 +117.1%。主因是倍數不是 EPS：本模型 2028 年底每股淨值 241,105 只比共識 232,055 高 3.9%（前瞻 EPS 78,917 比共識高 5.2%），但現價只隱含 0.89 倍前瞻 P/B，記憶體同業中位數 1.94 倍、共識目標價 478,906 隱含 2.06 倍；同業倍數未扣三星的集團折價，Comparable 偏高估。
A29: 重點觀察 2：DCF 情境價值 A 818,535、B 394,410、C 218,882（現價的 3.80／1.83／1.02 倍），對應 2028 EPS A 129,982、B 59,278、C 36,498；收斂期用的 ROE 為 2023–2025 平均 8.0%，低於折現率 10%，再投資率約五成，壓低 2030 年後的股東現金流。
A30: 重點觀察 3：2028 B 營業利益對一般 DRAM 收入最敏感（±20% → ±15.2%），NAND ±30% → ±9.2%、HBM ±30% → ±7.3%；折現率 ±1pt 使加權目標價 −4.1%／+5.6%。下一個檢驗事件是 3Q26 確定財報與法說（約 2026-10-30，日期未確認；2026-10-08 初步財報已納入）。

Sheet In
A1: In — 輸入（藍字＝基準值；低／高供敏感度）。每列具名範圍＝鍵（指向 E 欄）。單位：兆韓元
A3: 鍵 | B3: 項目 | C3: 單位 | D3: 低 | E3: 基準 | F3: 高 | G3: 標記 | H3: 來源／說明
A4: A. 匯率、股價
A5: fx | B5: 美元兌韓元 | C5: KRW/USD | D5: 1350 | E5: 1420 | F5: 1500 | G5: Derived | H5: 同 SK 海力士
A6: px | B6: 普通股股價（2026-10-23 收盤） | C6: KRW | E6: 215500 | G6: Verified | H6: markets/invest_map/data/prices.csv（tradersunion，單一來源）；MarketScreener 2026-10-23 收盤 215,500（第二來源，本次核對）；v0.2.2 為 10-08 的 262,000
A7: B. 基準年剩餘季度（公司指引＋TrendForce）
A8: q3_db | B8: Q3 DRAM 位元季增 | C8: % | D8: 0.03 | E8: 0.05 | F8: 0.07 | G8: Verified | H8: 公司 Q2 法說：中個位數
A9: q3_dp | B9: Q3 DRAM ASP 季增 | C9: % | D9: 0.08 | E9: 0.1 | F9: 0.15 | G9: Derived | H9: 以 2026Q3 初步財報校準：合併營收 195 兆（+13.7%）− 非記憶體約 55 兆 → 記憶體約 140 兆（+16%）；TrendForce 產業 +13–18%，三星年約價格帶使實現價較低
A10: q3_nb | B10: Q3 NAND 位元季增 | C10: % | D10: 0.06 | E10: 0.08 | F10: 0.09 | G10: Verified | H10: 公司：高個位數
A11: q3_np | B11: Q3 NAND ASP 季增 | C11: % | D11: 0.08 | E11: 0.1 | F11: 0.15 | G11: Derived | H11: 同上校準；TrendForce +10–15%
A12: q4_db | B12: Q4 DRAM 位元季增 | C12: % | D12: 0 | E12: 0.05 | F12: 0.08 | G12: Assumed | H12: P4 全面量產
A13: q4_dp | B13: Q4 DRAM ASP 季增 | C13: % | D13: 0.05 | E13: 0.1 | F13: 0.15 | G13: Interested-party | H13: TrendForce +10–15%
A14: q4_nb | B14: Q4 NAND 位元季增 | C14: % | D14: 0 | E14: 0.05 | F14: 0.08 | G14: Assumed
A15: q4_np | B15: Q4 NAND ASP 季增 | C15: % | D15: 0.1 | E15: 0.175 | F15: 0.2 | G15: Interested-party | H15: TrendForce +15–20%
A16: da_q3 | B16: Q3 記憶體折舊 | C16: 兆韓元 | E16: 6.6 | G16: Assumed | H16: 未揭露
A17: da_q4 | B17: Q4 記憶體折舊 | C17: 兆韓元 | E17: 7 | G17: Assumed
A18: costdn_q | B18: 單位成本季降 | C18: % | D18: 0.01 | E18: 0.03 | F18: 0.05 | G18: Assumed
A19: opex_fix_q | B19: 記憶體營業費用固定部分（每季） | C19: 兆韓元 | E19: 1 | G19: Assumed | H19: 約 7% 營收
A20: nonop_q | B20: 每季業外淨收益 | C20: 兆韓元 | D20: 0.5 | E20: 1.5 | F20: 2.5 | G20: Assumed | H20: 淨現金約 168 兆 × 約 3%
A21: nm_op_q | B21: 非記憶體事業每季營業利益（Q3、Q4） | C21: 兆韓元 | D21: -1 | E21: 2 | F21: 4 | G21: Assumed | H21: MX 新機季節性、SDC、晶圓代工虧損；Q1 1.5、Q2 −1.7 [Derived]
A22: C. 年度驅動
A23: cb_1 | B23: 一般 DRAM 位元成長 2027 | C23: % | D23: 0.1 | E23: 0.15 | F23: 0.2 | G23: Derived | H23: P4 提前全面量產、P5 提前 6 個月（TrendForce）；HBM 晶圓占比上升
A24: cb_2 | B24: 一般 DRAM 位元成長 2028 | C24: % | D24: 0.12 | E24: 0.18 | F24: 0.22 | G24: Derived | H24: P5 投產
A25: cb_3 | B25: 一般 DRAM 位元成長 2029 | C25: % | D25: 0.1 | E25: 0.15 | F25: 0.2 | G25: Assumed
A26: nb_1 | B26: NAND 位元成長 2027 | C26: % | D26: 0.1 | E26: 0.15 | F26: 0.2 | G26: Assumed
A27: nb_2 | B27: NAND 位元成長 2028 | C27: % | D27: 0.12 | E27: 0.18 | F27: 0.22 | G27: Assumed
A28: nb_3 | B28: NAND 位元成長 2029 | C28: % | D28: 0.12 | E28: 0.18 | F28: 0.22 | G28: Assumed
A29: sh25 | B29: HBM 營收市占 2025 | C29: % | D29: 0.15 | E29: 0.17 | F29: 0.22 | G29: Interested-party | H29: Counterpoint 2Q25 15%、3Q25 22%
A30: sh26 | B30: HBM 營收市占 2026 | C30: % | D30: 0.25 | E30: 0.29 | F30: 0.33 | G30: Interested-party | H30: Counterpoint 1Q26 21%、2Q26 33%；下半年 HBM4 放量
A31: sh27 | B31: HBM 營收市占 2027 | C31: % | D31: 0.33 | E31: 0.38 | F31: 0.41 | G31: Interested-party | H31: UBS 2027 位元 41%（SK 39%、美光 20%）；與 SK 42%、美光 20% 加總約 100%
A32: sh28 | B32: HBM 營收市占 2028 | C32: % | D32: 0.35 | E32: 0.4 | F32: 0.45 | G32: Assumed | H32: 公司目標：HBM 份額向 DRAM 份額（約 39%）靠攏
A33: sh29 | B33: HBM 營收市占 2029 | C33: % | D33: 0.35 | E33: 0.4 | F33: 0.45 | G33: Assumed
A34: other_y | B34: 其他記憶體營收 | C34: 兆韓元 | E34: 0 | G34: Derived | H34: DRAM＋NAND 已涵蓋
A35: w_c | B35: 成本權重：一般 DRAM | C35: % | E35: 0.55 | G35: Assumed
A36: w_h | B36: 成本權重：HBM | C36: % | E36: 0.15 | G36: Assumed
A37: w_n | B37: 成本權重：NAND | C37: % | E37: 0.3 | G37: Assumed
A38: costdn_y | B38: 單位成本年降 | C38: % | D38: 0.05 | E38: 0.1 | F38: 0.15 | G38: Assumed
A39: da_life | B39: 新增資本支出轉為折舊的年數 | C39: 年 | D39: 4 | E39: 5 | F39: 6 | G39: Assumed
A40: da_cogs | B40: 折舊計入營業成本比例 | C40: % | E40: 0.9 | G40: Assumed
A41: opex_fix_y | B41: 記憶體營業費用固定部分（年） | C41: 兆韓元 | E41: 4 | G41: Assumed
...

Sheet Path
A1: Path — 記憶體合約價指數（2025Q1＝1；季增來自 In 頁 M1）。共用市場層：所有記憶體公司用同一條路徑，再依各自會計年度取平均
A3: 路徑 | B3: 情境 | C3: 2025Q1 | D3: 2025Q2 | E3: 2025Q3 | F3: 2025Q4 | G3: 2026Q1 | H3: 2026Q2 | I3: 2026Q3 | J3: 2026Q4 | K3: 2027Q1 | L3: 2027Q2 | M3: 2027Q3 | N3: 2027Q4 | O3: 2028Q1 | P3: 2028Q2 | Q3: 2028Q3 | R3: 2028Q4 | S3: 2029Q1 | T3: 2029Q2 | U3: 2029Q3 | V3: 2029Q4
A4: 一般 DRAM | B4: A | C4: 1 | D4: =C4*(1+cq_1) -> 0.975 | E4: =D4*(1+cq_2) -> 1.096875 | F4: =E4*(1+cq_3) -> 1.6178906 | G4: =F4*(1+cq_4) -> 3.1548867 | H4: =G4*(1+cq_5) -> 5.0635932 | I4: =H4*(1+cq_6) -> 5.8484501 | J4: =I4*(1+cq_7) -> 6.5795064 | K4: =J4*(1+cqA_8) -> 6.7768916 | L4: =K4*(1+cqA_9) -> 6.7768916 | M4: =L4*(1+cqA_10) -> 6.6413538 | N4: =M4*(1+cqA_11) -> 6.4421131 | O4: =N4*(1+cqA_12) -> 6.2488497 | P4: =O4*(1+cqA_13) -> 6.0613843 | Q4: =P4*(1+cqA_14) -> 5.9401566 | R4: =Q4*(1+cqA_15) -> 5.8213534 | S4: =R4*(1+cqA_16) -> 5.6467128 | T4: =S4*(1+cqA_17) -> 5.4773114 | U4: =T4*(1+cqA_18) -> 5.3677652 | V4: =U4*(1+cqA_19) -> 5.2604099
A5: 一般 DRAM | B5: B | C5: 1 | D5: =C5*(1+cq_1) -> 0.975 | E5: =D5*(1+cq_2) -> 1.096875 | F5: =E5*(1+cq_3) -> 1.6178906 | G5: =F5*(1+cq_4) -> 3.1548867 | H5: =G5*(1+cq_5) -> 5.0635932 | I5: =H5*(1+cq_6) -> 5.8484501 | J5: =I5*(1+cq_7) -> 6.5795064 | K5: =J5*(1+cqB_8) -> 6.9084817 | L5: =K5*(1+cqB_9) -> 7.0466513 | M5: =L5*(1+cqB_10) -> 6.4829192 | N5: =M5*(1+cqB_11) -> 5.5104814 | O5: =N5*(1+cqB_12) -> 4.132861 | P5: =O5*(1+cqB_13) -> 3.5129319 | Q5: =P5*(1+cqB_14) -> 3.1616387 | R5: =Q5*(1+cqB_15) -> 3.0035567 | S5: =R5*(1+cqB_16) -> 3.1537346 | T5: =S5*(1+cqB_17) -> 3.3114213 | U5: =T5*(1+cqB_18) -> 3.4107639 | V5: =U5*(1+cqB_19) -> 3.5130869
A6: 一般 DRAM | B6: C | C6: 1 | D6: =C6*(1+cq_1) -> 0.975 | E6: =D6*(1+cq_2) -> 1.096875 | F6: =E6*(1+cq_3) -> 1.6178906 | G6: =F6*(1+cq_4) -> 3.1548867 | H6: =G6*(1+cq_5) -> 5.0635932 | I6: =H6*(1+cq_6) -> 5.8484501 | J6: =I6*(1+cq_7) -> 6.5795064 | K6: =J6*(1+cqC_8) -> 6.9084817 | L6: =K6*(1+cqC_9) -> 7.0466513 | M6: =L6*(1+cqC_10) -> 6.4829192 | N6: =M6*(1+cqC_11) -> 5.5104814 | O6: =N6*(1+cqC_12) -> 3.5818129 | P6: =O6*(1+cqC_13) -> 2.507269 | Q6: =P6*(1+cqC_14) -> 1.8804518 | R6: =Q6*(1+cqC_15) -> 1.5043614 | S6: =R6*(1+cqC_16) -> 1.5043614 | T6: =S6*(1+cqC_17) -> 1.5795795 | U6: =T6*(1+cqC_18) -> 1.7059458 | V6: =U6*(1+cqC_19) -> 1.8765404
A8: NAND | B8: A | C8: 1 | D8: =C8*(1+nq_1) -> 1 | E8: =D8*(1+nq_2) -> 1.05 | F8: =E8*(1+nq_3) -> 1.365 | G8: =F8*(1+nq_4) -> 2.559375 | H8: =G8*(1+nq_5) -> 4.4149219 | I8: =H8*(1+nq_6) -> 5.0771602 | J8: =I8*(1+nq_7) -> 5.9656632 | K8: =J8*(1+nqA_8) -> 6.1446331 | L8: =K8*(1+nqA_9) -> 6.1446331 | M8: =L8*(1+nqA_10) -> 5.8374014 | N8: =M8*(1+nqA_11) -> 5.4287833 | O8: =N8*(1+nqA_12) -> 5.1573442 | P8: =O8*(1+nqA_13) -> 4.899477 | Q8: =P8*(1+nqA_14) -> 4.6545031 | R8: =Q8*(1+nqA_15) -> 4.4217779 | S8: =R8*(1+nqA_16) -> 4.2891246 | T8: =S8*(1+nqA_17) -> 4.1604509 | U8: =T8*(1+nqA_18) -> 4.0356373 | V8: =U8*(1+nqA_19) -> 3.9145682
A9: NAND | B9: B | C9: 1 | D9: =C9*(1+nq_1) -> 1 | E9: =D9*(1+nq_2) -> 1.05 | F9: =E9*(1+nq_3) -> 1.365 | G9: =F9*(1+nq_4) -> 2.559375 | H9: =G9*(1+nq_5) -> 4.4149219 | I9: =H9*(1+nq_6) -> 5.0771602 | J9: =I9*(1+nq_7) -> 5.9656632 | K9: =J9*(1+nqB_8) -> 6.2639463 | L9: =K9*(1+nqB_9) -> 6.3892253 | M9: =L9*(1+nqB_10) -> 5.7503027 | N9: =M9*(1+nqB_11) -> 4.6002422 | O9: =N9*(1+nqB_12) -> 3.2201695 | P9: =O9*(1+nqB_13) -> 2.4151272 | Q9: =P9*(1+nqB_14) -> 1.9321017 | R9: =Q9*(1+nqB_15) -> 1.7388915 | S9: =R9*(1+nqB_16) -> 1.8258361 | T9: =S9*(1+nqB_17) -> 1.9171279 | U9: =T9*(1+nqB_18) -> 1.9746418 | V9: =U9*(1+nqB_19) -> 2.033881
A10: NAND | B10: C | C10: 1 | D10: =C10*(1+nq_1) -> 1 | E10: =D10*(1+nq_2) -> 1.05 | F10: =E10*(1+nq_3) -> 1.365 | G10: =F10*(1+nq_4) -> 2.559375 | H10: =G10*(1+nq_5) -> 4.4149219 | I10: =H10*(1+nq_6) -> 5.0771602 | J10: =I10*(1+nq_7) -> 5.9656632 | K10: =J10*(1+nqC_8) -> 6.2639463 | L10: =K10*(1+nqC_9) -> 6.3892253 | M10: =L10*(1+nqC_10) -> 5.7503027 | N10: =M10*(1+nqC_11) -> 4.6002422 | O10: =N10*(1+nqC_12) -> 2.9901574 | P10: =O10*(1+nqC_13) -> 1.9436023 | Q10: =P10*(1+nqC_14) -> 1.4577017 | R10: =Q10*(1+nqC_15) -> 1.1661614 | S10: =R10*(1+nqC_16) -> 1.1661614 | T10: =S10*(1+nqC_17) -> 1.2244695 | U10: =T10*(1+nqC_18) -> 1.322427 | V10: =U10*(1+nqC_19) -> 1.4546697
A12: 年均指數
A13: 路徑 | B13: 情境 | C13: 2025 | D13: 2026 | E13: 2027 | F13: 2028 | G13: 2029 | H13: 2026÷2025 | I13: 2027÷2026 | J13: 2028÷2027 | K13: 2029÷2028
A14: 一般 DRAM | B14: A | C14: =AVERAGE(C4:F4) -> 1.1724414 | D14: =AVERAGE(G4:J4) -> 5.1616091 | E14: =AVERAGE(K4:N4) -> 6.6593125 | F14: =AVERAGE(O4:R4) -> 6.017936 | G14: =AVERAGE(S4:V4) -> 5.4380499 | H14: =D14/C14-1 -> 3.4024453 | I14: =E14/D14-1 -> 0.29016211 | J14: =F14/E14-1 -> -0.096312722 | K14: =G14/F14-1 -> -0.09635964
A15: 一般 DRAM | B15: B | C15: =AVERAGE(C5:F5) -> 1.1724414 | D15: =AVERAGE(G5:J5) -> 5.1616091 | E15: =AVERAGE(K5:N5) -> 6.4871334 | F15: =AVERAGE(O5:R5) -> 3.4527471 | G15: =AVERAGE(S5:V5) -> 3.3472517 | H15: =D15/C15-1 -> 3.4024453 | I15: =E15/D15-1 -> 0.25680447 | J15: =F15/E15-1 -> -0.46775458 | K15: =G15/F15-1 -> -0.030554048
A16: 一般 DRAM | B16: C | C16: =AVERAGE(C6:F6) -> 1.1724414 | D16: =AVERAGE(G6:J6) -> 5.1616091 | E16: =AVERAGE(K6:N6) -> 6.4871334 | F16: =AVERAGE(O6:R6) -> 2.3684738 | G16: =AVERAGE(S6:V6) -> 1.6666068 | H16: =D16/C16-1 -> 3.4024453 | I16: =E16/D16-1 -> 0.25680447 | J16: =F16/E16-1 -> -0.63489671 | K16: =G16/F16-1 -> -0.29633724
A17: NAND | B17: A | C17: =AVERAGE(C8:F8) -> 1.10375 | D17: =AVERAGE(G8:J8) -> 4.5042801 | E17: =AVERAGE(K8:N8) -> 5.8888627 | F17: =AVERAGE(O8:R8) -> 4.7832755 | G17: =AVERAGE(S8:V8) -> 4.0999453 | H17: =D17/C17-1 -> 3.0808879 | I17: =E17/D17-1 -> 0.30739267 | J17: =F17/E17-1 -> -0.18774205 | K17: =G17/F17-1 -> -0.14285823
A18: NAND | B18: B | C18: =AVERAGE(C9:F9) -> 1.10375 | D18: =AVERAGE(G9:J9) -> 4.5042801 | E18: =AVERAGE(K9:N9) -> 5.7509291 | F18: =AVERAGE(O9:R9) -> 2.3265725 | G18: =AVERAGE(S9:V9) -> 1.9378717 | H18: =D18/C18-1 -> 3.0808879 | I18: =E18/D18-1 -> 0.27676989 | J18: =F18/E18-1 -> -0.59544407 | K18: =G18/F18-1 -> -0.16707013
A19: NAND | B19: C | C19: =AVERAGE(C10:F10) -> 1.10375 | D19: =AVERAGE(G10:J10) -> 4.5042801 | E19: =AVERAGE(K10:N10) -> 5.7509291 | F19: =AVERAGE(O10:R10) -> 1.8894057 | G19: =AVERAGE(S10:V10) -> 1.2919319 | H19: =D19/C19-1 -> 3.0808879 | I19: =E19/D19-1 -> 0.27676989 | J19: =F19/E19-1 -> -0.67146079 | K19: =G19/F19-1 -> -0.31622315

Sheet Mkt
A1: Mkt — 加速器數量層（最小版）與 HBM 市場（日曆年）。需求＝顆數 × GB × 情境顆數係數（2028–29）；供給三情境相同；出貨＝MIN(需求, 供給)；市場＝出貨 × 單價（單價依情境）
A3: 項目 | B3: 單位 | C3: 2025 | D3: 2026 | E3: 2027 | F3: 2028 | G3: 2029 | H3: 說明
A4: 需求：加速器裝載的 HBM（PB）
A5: NVIDIA Blackwell（B200／B300） | B5: PB | D5: =u_bw_26*g_bw_26 -> 1404 | E5: =u_bw_27*g_bw_27 -> 672 | F5: =u_bw_28*g_bw_28 -> 144
A6: NVIDIA Rubin | B6: PB | D6: =u_rb_26*g_rb_26 -> 489.6 | E6: =u_rb_27*g_rb_27 -> 2016 | F6: =u_rb_28*g_rb_28 -> 2016
A7: NVIDIA Rubin Ultra | B7: PB | D7: =u_ru_26*g_ru_26 -> 0 | E7: =u_ru_27*g_ru_27 -> 307.2 | F7: =u_ru_28*g_ru_28 -> 2048
A8: NVIDIA Hopper（H200 等） | B8: PB | D8: =u_hp_26*g_hp_26 -> 70.5 | E8: =u_hp_27*g_hp_27 -> 0 | F8: =u_hp_28*g_hp_28 -> 0
A9: AMD Instinct | B9: PB | D9: =u_amd_26*g_amd_26 -> 216 | E9: =u_amd_27*g_amd_27 -> 540 | F9: =u_amd_28*g_amd_28 -> 864
A10: Google TPU | B10: PB | D10: =u_tpu_26*g_tpu_26 -> 739.2 | E10: =u_tpu_27*g_tpu_27 -> 1375 | F10: =u_tpu_28*g_tpu_28 -> 2016
A11: AWS Trainium | B11: PB | D11: =u_trn_26*g_trn_26 -> 220 | E11: =u_trn_27*g_trn_27 -> 360 | F11: =u_trn_28*g_trn_28 -> 600
A12: 其他 ASIC（MTIA、Maia、Ascend 等） | B12: PB | D12: =u_oth_26*g_oth_26 -> 150 | E12: =u_oth_27*g_oth_27 -> 900 | F12: =u_oth_28*g_oth_28 -> 1250
A13: 需求合計（裝載） | B13: EB | D13: =SUM(D5:D12)/1000 -> 3.2893 | E13: =SUM(E5:E12)/1000 -> 6.1702 | F13: =SUM(F5:F12)/1000 -> 8.938 | G13: =F13*(1+hbm_dem29) -> 11.6194
A14: 需求 × 出貨係數（基準＝情境 A） | B14: EB | D14: =D13*hbm_gross -> 3.782695 | E14: =E13*hbm_gross -> 7.09573 | F14: =F13*hbm_gross -> 10.2787 | G14: =G13*hbm_gross -> 13.36231
A15: 加速器顆數合計 | B15: 百萬顆 | D15: =u_bw_26+u_rb_26+u_ru_26+u_hp_26+u_amd_26+u_tpu_26+u_trn_26+u_oth_26 -> 15.2 | E15: =u_bw_27+u_rb_27+u_ru_27+u_hp_27+u_amd_27+u_tpu_27+u_trn_27+u_oth_27 -> 23.7 | F15: =u_bw_28+u_rb_28+u_ru_28+u_hp_28+u_amd_28+u_tpu_28+u_trn_28+u_oth_28 -> 26.5 | H15: JPMorgan 2027：GPU 10.9M、ASIC 12.5M；情境 A 基準
A16: 每顆平均 HBM | B16: GB | D16: =D13*1000/D15 -> 216.40132 | E16: =E13*1000/E15 -> 260.34599 | F16: =F13*1000/F15 -> 337.28302
A17: 供給（三情境相同） | B17: EB | C17: =D17/(1+hbm_g26) -> 2.2251147 | D17: =D14 -> 3.782695 | E17: =D17*(1+hbm_sup27) -> 5.8631772 | F17: =E17*(1+hbm_sup28) -> 8.501607 | G17: =F17*(1+hbm_sup29) -> 11.477169 | H17: 2026 供給＝需求出貨（年中已成交）；供給不隨需求情境變（產能 2027 前已訂定）
A18: 顆數係數（A；2028–29 ÷ 基準，與台積電、Advantest 同一套） | B18: x | D18: 1 | E18: 1 | F18: =um28_A -> 1 | G18: =um29_A -> 1 | H18: 2026–27 無情境差異
A19: 顆數係數（B；2028–29 ÷ 基準，與台積電、Advantest 同一套） | B19: x | D19: 1 | E19: 1 | F19: =um28_B -> 0.8 | G19: =um29_B -> 0.85 | H19: 2026–27 無情境差異
A20: 顆數係數（C；2028–29 ÷ 基準，與台積電、Advantest 同一套） | B20: x | D20: 1 | E20: 1 | F20: =um28_C -> 0.6 | G20: =um29_C -> 0.6 | H20: 2026–27 無情境差異
A21: 需求 × 出貨係數（A） | B21: EB | D21: =D14*D18 -> 3.782695 | E21: =E14*E18 -> 7.09573 | F21: =F14*F18 -> 10.2787 | G21: =G14*G18 -> 13.36231
A22: 需求 × 出貨係數（B） | B22: EB | D22: =D14*D19 -> 3.782695 | E22: =E14*E19 -> 7.09573 | F22: =F14*F19 -> 8.22296 | G22: =G14*G19 -> 11.357964
A23: 需求 × 出貨係數（C） | B23: EB | D23: =D14*D20 -> 3.782695 | E23: =E14*E20 -> 7.09573 | F23: =F14*F20 -> 6.16722 | G23: =G14*G20 -> 8.017386
A24: 出貨＝MIN(需求, 供給)（A） | B24: EB | C24: =C17 -> 2.2251147 | D24: =MIN(D21,D17) -> 3.782695 | E24: =MIN(E21,E17) -> 5.8631772 | F24: =MIN(F21,F17) -> 8.501607 | G24: =MIN(G21,G17) -> 11.477169 | H24: 需求低於供給時出貨＝需求（閒置產能）
A25: 出貨＝MIN(需求, 供給)（B） | B25: EB | C25: =C17 -> 2.2251147 | D25: =MIN(D22,D17) -> 3.782695 | E25: =MIN(E22,E17) -> 5.8631772 | F25: =MIN(F22,F17) -> 8.22296 | G25: =MIN(G22,G17) -> 11.357964
A26: 出貨＝MIN(需求, 供給)（C） | B26: EB | C26: =C17 -> 2.2251147 | D26: =MIN(D23,D17) -> 3.782695 | E26: =MIN(E23,E17) -> 5.8631772 | F26: =MIN(F23,F17) -> 6.16722 | G26: =MIN(G23,G17) -> 8.017386
A27: 需求 − 供給（A；>0＝短缺） | B27: EB | D27: =D21-D17 -> 0 | E27: =E21-E17 -> 1.2325527 | F27: =F21-F17 -> 1.777093 | G27: =G21-G17 -> 1.8851405
A28: 需求 − 供給（B；>0＝短缺） | B28: EB | D28: =D22-D17 -> 0 | E28: =E22-E17 -> 1.2325527 | F28: =F22-F17 -> -0.27864701 | G28: =G22-G17 -> -0.11920597
A29: 需求 − 供給（C；>0＝短缺） | B29: EB | D29: =D23-D17 -> 0 | E29: =E23-E17 -> 1.2325527 | F29: =F23-F17 -> -2.334387 | G29: =G23-G17 -> -3.4597835
A30: HBM 單價（A） | B30: $/GB | C30: =hbm_mkt25/C24 -> 15.729526 | D30: =hbm_p26 -> 14.6 | E30: =D30*(1+hbm_p27) -> 26.28 | F30: =E30*(1+hbm_p28_A) -> 28.908 | G30: =F30*(1+hbm_p29_A) -> 27.4626
A31: HBM 單價（B） | B31: $/GB | C31: =hbm_mkt25/C24 -> 15.729526 | D31: =hbm_p26 -> 14.6 | E31: =D31*(1+hbm_p27) -> 26.28 | F31: =E31*(1+hbm_p28_B) -> 19.71 | G31: =F31*(1+hbm_p29_B) -> 19.71
A32: HBM 單價（C） | B32: $/GB | C32: =hbm_mkt25/C24 -> 15.729526 | D32: =hbm_p26 -> 14.6 | E32: =D32*(1+hbm_p27) -> 26.28 | F32: =E32*(1+hbm_p28_C) -> 15.768 | G32: =F32*(1+hbm_p29_C) -> 16.5564
A33: HBM 市場（A） | B33: $B | C33: =C24*C30 -> 35 | D33: =D24*D30 -> 55.227347 | E33: =E24*E30 -> 154.0843 | F33: =F24*F30 -> 245.76446 | G33: =G24*G30 -> 315.19291
A34: HBM 市場（B） | B34: $B | C34: =C25*C31 -> 35 | D34: =D25*D31 -> 55.227347 | E34: =E25*E31 -> 154.0843 | F34: =F25*F31 -> 162.07454 | G34: =G25*G31 -> 223.86546
A35: HBM 市場（C） | B35: $B | C35: =C26*C32 -> 35 | D35: =D26*D32 -> 55.227347 | E35: =E26*E32 -> 154.0843 | F35: =F26*F32 -> 97.244725 | G35: =G26*G32 -> 132.73905
A37: 對帳（樣板驗收 2）
A38: 由下而上：NVIDIA 裝載 HBM × 單價（2026） | B38: $B | D38: =(D5+D6+D7+D8)/1000*hbm_p26 -> 28.67586
A39: 由上而下：NVIDIA 資料中心營收 × 每顆 HBM ÷ 每顆 NVIDIA 內容（2026） | B39: $B | D39: =nv_dc26*nv_hbm/nv_content -> 38.972897 | H39: 橋接表 v0.2；與顆數預測獨立
A40: 差距 | B40: % | D40: =D38/D39-1 -> -0.26421021
A41: 由營收推得 NVIDIA 顆數 vs 顆數預測 | B41: 百萬顆 | D41: =nv_dc26/nv_content -> 8.7383178 | E41: =u_bw_26+u_rb_26+u_hp_26 -> 7.6 | H41: D＝營收推得；E＝顆數預測（2026）
A42: 已發布：SK 海力士自估 2026／BofA 2026／BofA 2027 | B42: $B | D42: =pub26_lo -> 54.6 | E42: =pub26_hi -> 77.4 | F42: =pub27 -> 152.8
...

Sheet Q
A1: Q — 季度損益（兆韓元）。實績：三星 IR 季度簡報（2025Q1–2026Q2）、2026Q3 初步財報（2026-10-08）；推估季：實績 × 公司指引 × TrendForce 價格
A3: 項目 | B3: 2025Q1 | C3: 2025Q2 | D3: 2025Q3 | E3: 2025Q4 | F3: 2026Q1 | G3: 2026Q2 | H3: 2026Q3E | I3: 2026Q4E | J3: 2026 合計
A4: 記憶體營收 | B4: 19.1 | C4: 21.2 | D4: 26.7 | E4: 37.1 | F4: 74.8 | G4: 120.8 | H4: =H5+H6+H7 -> 140.79965 | I4: =I5+I6+I7 -> 166.24006 | J4: =SUM(F4:I4) -> 502.6397
A5: DRAM（含 HBM） | F5: =F4*0.68 -> 50.864 | G5: =G4*0.68 -> 82.144 | H5: =G5*(1+q3_db)*(1+q3_dp) -> 94.87632 | I5: =H5*(1+q4_db)*(1+q4_dp) -> 109.58215 | J5: =SUM(F5:I5) -> 337.46647
A6: NAND | F6: =F4*0.32 -> 23.936 | G6: =G4*0.32 -> 38.656 | H6: =G6*(1+q3_nb)*(1+q3_np) -> 45.923328 | I6: =H6*(1+q4_nb)*(1+q4_np) -> 56.657906 | J6: =SUM(F6:I6) -> 165.17323
A7: 其他 | F7: =F4-F5-F6 -> 0 | G7: =G4-G5-G6 -> 0 | H7: =other_y/4 -> 0 | I7: =other_y/4 -> 0 | J7: =SUM(F7:I7) -> 0
A8: 營業成本 | F8: =F4*(1-0.745-0.07) -> 13.838 | G8: =G4*(1-0.755-0.07) -> 21.14 | H8: =(G8-da_cogs*G13)*((w_c+w_h)*H14/G14+w_n*H15/G15)*(1-costdn_q)+da_cogs*da_q3 -> 21.831248 | I8: =(H8-da_cogs*H13)*((w_c+w_h)*I14/H14+w_n*I15/H15)*(1-costdn_q)+da_cogs*da_q4 -> 22.485236 | J8: =SUM(F8:I8) -> 79.294484
A9: 營業費用 | F9: =F4-F8-F10 -> 5.262 | G9: =G4-G8-G10 -> 8.46 | H9: =opex_fix_q+opex_var*H4 -> 9.4479789 | I9: =opex_fix_q+opex_var*I4 -> 10.974403 | J9: =SUM(F9:I9) -> 34.144382
A10: 記憶體營業利益 | B10: 3.1 | C10: 2.4 | D10: 9 | E10: 18.4 | F10: 55.7 | G10: 91.2 | H10: =H4-H8-H9 -> 109.52042 | I10: =I4-I8-I9 -> 132.78042 | J10: =SUM(F10:I10) -> 389.20084
A11: 記憶體營業利益率 | B11: =IF(B4=0,"",B10/B4) -> 0.16230366 | C11: =IF(C4=0,"",C10/C4) -> 0.11320755 | D11: =IF(D4=0,"",D10/D4) -> 0.33707865 | E11: =IF(E4=0,"",E10/E4) -> 0.49595687 | F11: =IF(F4=0,"",F10/F4) -> 0.74465241 | G11: =IF(G4=0,"",G10/G4) -> 0.75496689 | H11: =IF(H4=0,"",H10/H4) -> 0.77784584 | I11: =IF(I4=0,"",I10/I4) -> 0.79872697 | J11: =J10/J4 -> 0.77431376
A12: 淨利（合併，含非記憶體事業） | B12: 8 | C12: 4.9 | D12: 12 | E12: 19.3 | F12: 47.1 | G12: 71.3 | H12: =(H10+nonop_q+nm_op_q)*(1-tax) -> 90.416337 | I12: =(I10+nonop_q+nm_op_q)*(1-tax) -> 109.02433 | J12: =SUM(F12:I12) -> 317.84067
A13: 折舊攤銷 | B13: 5 | C13: 5 | D13: 5 | E13: 5 | F13: 6 | G13: 6.3 | H13: =da_q3 -> 6.6 | I13: =da_q4 -> 7 | J13: =SUM(F13:I13) -> 25.9
A14: DRAM 位元指數（最後實績季＝1） | G14: 1 | H14: =G14*(1+q3_db) -> 1.05 | I14: =H14*(1+q4_db) -> 1.1025
A15: NAND 位元指數 | G15: 1 | H15: =G15*(1+q3_nb) -> 1.08 | I15: =H15*(1+q4_nb) -> 1.134
A18: 三星只揭露記憶體營收，不揭露記憶體營業利益與 DRAM／NAND 拆分。記憶體營業利益＝DS 營業利益＋晶圓代工與 LSI 虧損估計（2025 每季約 2 兆、2026 約 2 兆）[Derived／Assumed]；DRAM 68%／NAND 32% 依 TrendForce 2Q26 三星 DRAM 營收約 82 兆推得 [Derived]；營業費用約 7% 營收、折舊為 Assumed。淨利為合併歸屬母公司。
A20: 官方報告分部（兆韓元；分部營收含內部銷售；三星 IR 季度簡報）
A21: DX（裝置體驗：MX／網路、VD／DA） | B21: 51.7 | C21: 43.6 | D21: 48.4 | E21: 44.3 | F21: 52.7 | G21: 48
A22: DS（裝置解決方案） | B22: 25.1 | C22: 27.9 | D22: 33.1 | E22: 44 | F22: 81.7 | G22: 127.5
A23: SDC（三星顯示器） | B23: 5.9 | C23: 6.4 | D23: 8.1 | E23: 9.5 | F23: 6.7 | G23: 7.5
A24: Harman | B24: 3.4 | C24: 3.8 | E24: 4.6 | F24: 3.8 | G24: 4.6
A25: 內部抵銷 [Derived＝合併營收 − 四分部合計] | B25: -7 | C25: -7.1 | E25: -8.6 | F25: -11 | G25: -16.1
A26: 合併營收 | B26: 79.1 | C26: 74.6 | D26: 86.1 | E26: 93.8 | F26: 133.9 | G26: 171.5
A27: 檢查：分部合計 − 合併營收 | B27: =B21+B22+B23+B24+B25-B26 -> 0 | C27: =C21+C22+C23+C24+C25-C26 -> 0 | E27: =E21+E22+E23+E24+E25-E26 -> 0 | F27: =F21+F22+F23+F24+F25-F26 -> 0 | G27: =G21+G22+G23+G24+G25-G26 -> 0
A28: 來源：2026Q1 簡報（韓文版，含 2025Q1、2025Q4）、2026Q2 簡報（含 2025Q2；第三方轉存 gelonghui，三星官網原檔未取得）、2025Q3 財報新聞稿（news.samsungsemiconductor.com）。
A29: 2025Q3：DX 未揭露 [Derived]＝2025Q2 DX × 1.11（新聞稿：季增 11%）；Harman 未揭露，該季不計核對。三星不揭露內部抵銷，故抵銷列為差額，核對列只驗證分部表本身。
A30: 記憶體（第 4 列「記憶體營收」）屬 DS；DS 其餘為晶圓代工與 System LSI。推估季不拆分部：非記憶體事業以 In 頁 nm_rev／nm_op 整體輸入。

Sheet Y
A1: Y — 年度（兆韓元；股數百萬股）。情境 A：2027–28 高檔持平、2029 緩降（BofA、TrendForce 型）；B：2027 Q2 見頂、2028 回落約一半、2029 溫和回升（Citi、Bernstein 型）；C：2028 回到 2025 年價格水準、2029 自谷底回升（完整循環）
A2: 灰底＝2030–2032 收斂法（上游市場層只到 2029）：合併營收年增由 2029 線性收斂到 fade_g、淨利率收斂到 fade_m（In 頁目標價參數），股數固定；非驅動因子推導，只算營收、淨利、EPS
A3: 項目 | B3: 2025 實績 | C3: 2026（基準） | D3: 2027 A | E3: 2028 A | F3: 2029 A | G3: 2027 B | H3: 2028 B | I3: 2029 B | J3: 2027 C | K3: 2028 C | L3: 2029 C | M3: 2030 A 收斂 | N3: 2031 A 收斂 | O3: 2032 A 收斂 | P3: 2030 B 收斂 | Q3: 2031 B 收斂 | R3: 2032 B 收斂 | S3: 2030 C 收斂 | T3: 2031 C 收斂 | U3: 2032 C 收斂 | V3: 說明
A4: 記憶體營收 | B4: =SUM(Q!B4:E4) -> 104.1 | C4: =Q!J4 -> 502.6397 | D4: =D5+D6+D7+D8 -> 798.43361 | E4: =E5+E6+E7+E8 -> 875.55174 | F4: =F5+F6+F7+F8 -> 937.21932 | G4: =G5+G6+G7+G8 -> 780.54362 | H4: =H5+H6+H7+H8 -> 493.51838 | I4: =I5+I6+I7+I8 -> 559.44566 | J4: =J5+J6+J7+J8 -> 780.54362 | K4: =K5+K6+K7+K8 -> 345.22633 | L4: =L5+L6+L7+L8 -> 309.83883
A5: 一般 DRAM | C5: =Q!J5-C6 -> 314.72385 | D5: =C5*(1+cb_1)*(AVERAGE(Path!K4:N4)/AVERAGE(Path!G4:J4)) -> 466.9515 | E5: =D5*(1+cb_2)*(AVERAGE(Path!O4:R4)/AVERAGE(Path!K4:N4)) -> 497.9342 | F5: =E5*(1+cb_3)*(AVERAGE(Path!S4:V4)/AVERAGE(Path!O4:R4)) -> 517.44645 | G5: =C5*(1+cb_1)*(AVERAGE(Path!K5:N5)/AVERAGE(Path!G5:J5)) -> 454.87829 | H5: =G5*(1+cb_2)*(AVERAGE(Path!O5:R5)/AVERAGE(Path!K5:N5)) -> 285.68613 | I5: =H5*(1+cb_3)*(AVERAGE(Path!S5:V5)/AVERAGE(Path!O5:R5)) -> 318.50085 | J5: =C5*(1+cb_1)*(AVERAGE(Path!K6:N6)/AVERAGE(Path!G6:J6)) -> 454.87829 | K5: =J5*(1+cb_2)*(AVERAGE(Path!O6:R6)/AVERAGE(Path!K6:N6)) -> 195.97152 | L5: =K5*(1+cb_3)*(AVERAGE(Path!S6:V6)/AVERAGE(Path!O6:R6)) -> 158.58254 | V5: 前一年 × (1＋位元) × 會計年度價格指數平均比（Path）
A6: HBM | C6: =(Mkt!D33/4*sh26+Mkt!D33/4*sh26+Mkt!D33/4*sh26+Mkt!D33/4*sh26)*fx/1000 -> 22.742621 | D6: =(Mkt!E33/4*sh27+Mkt!E33/4*sh27+Mkt!E33/4*sh27+Mkt!E33/4*sh27)*fx/1000 -> 83.143887 | E6: =(Mkt!F33/4*sh28+Mkt!F33/4*sh28+Mkt!F33/4*sh28+Mkt!F33/4*sh28)*fx/1000 -> 139.59421 | F6: =(Mkt!G33/4*sh29+Mkt!G33/4*sh29+Mkt!G33/4*sh29+Mkt!G33/4*sh29)*fx/1000 -> 179.02958 | G6: =(Mkt!E34/4*sh27+Mkt!E34/4*sh27+Mkt!E34/4*sh27+Mkt!E34/4*sh27)*fx/1000 -> 83.143887 | H6: =(Mkt!F34/4*sh28+Mkt!F34/4*sh28+Mkt!F34/4*sh28+Mkt!F34/4*sh28)*fx/1000 -> 92.05834 | I6: =(Mkt!G34/4*sh29+Mkt!G34/4*sh29+Mkt!G34/4*sh29+Mkt!G34/4*sh29)*fx/1000 -> 127.15558 | J6: =(Mkt!E35/4*sh27+Mkt!E35/4*sh27+Mkt!E35/4*sh27+Mkt!E35/4*sh27)*fx/1000 -> 83.143887 | K6: =(Mkt!F35/4*sh28+Mkt!F35/4*sh28+Mkt!F35/4*sh28+Mkt!F35/4*sh28)*fx/1000 -> 55.235004 | L6: =(Mkt!G35/4*sh29+Mkt!G35/4*sh29+Mkt!G35/4*sh29+Mkt!G35/4*sh29)*fx/1000 -> 75.39578 | V6: Σ 會計年度各季：HBM 市場 ÷ 4 × 市占 × 匯率（Mkt）
A7: NAND | C7: =Q!J6 -> 165.17323 | D7: =C7*(1+nb_1)*(AVERAGE(Path!K8:N8)/AVERAGE(Path!G8:J8)) -> 248.33822 | E7: =D7*(1+nb_2)*(AVERAGE(Path!O8:R8)/AVERAGE(Path!K8:N8)) -> 238.02333 | F7: =E7*(1+nb_3)*(AVERAGE(Path!S8:V8)/AVERAGE(Path!O8:R8)) -> 240.7433 | G7: =C7*(1+nb_1)*(AVERAGE(Path!K9:N9)/AVERAGE(Path!G9:J9)) -> 242.52144 | H7: =G7*(1+nb_2)*(AVERAGE(Path!O9:R9)/AVERAGE(Path!K9:N9)) -> 115.77392 | I7: =H7*(1+nb_3)*(AVERAGE(Path!S9:V9)/AVERAGE(Path!O9:R9)) -> 113.78923 | J7: =C7*(1+nb_1)*(AVERAGE(Path!K10:N10)/AVERAGE(Path!G10:J10)) -> 242.52144 | K7: =J7*(1+nb_2)*(AVERAGE(Path!O10:R10)/AVERAGE(Path!K10:N10)) -> 94.019808 | L7: =K7*(1+nb_3)*(AVERAGE(Path!S10:V10)/AVERAGE(Path!O10:R10)) -> 75.860511
A8: 其他 | C8: =Q!J7 -> 0 | D8: =other_y -> 0 | E8: =other_y -> 0 | F8: =other_y -> 0 | G8: =other_y -> 0 | H8: =other_y -> 0 | I8: =other_y -> 0 | J8: =other_y -> 0 | K8: =other_y -> 0 | L8: =other_y -> 0
A9: HBM ÷ 營收 | C9: =C6/C4 -> 0.045246369 | D9: =D6/D4 -> 0.10413375 | E9: =E6/E4 -> 0.15943571 | F9: =F6/F4 -> 0.19102207 | G9: =G6/G4 -> 0.10652049 | H9: =H6/H4 -> 0.18653477 | I9: =I6/I4 -> 0.22728853 | J9: =J6/J4 -> 0.10652049 | ... L9: =L6/L4 -> 0.2433387
A10: 折舊攤銷 | B10: =SUM(Q!B13:E13) -> 20 | C10: =Q!J13 -> 25.9 | D10: =C10+(C21-C10)/da_life -> 31.22 | E10: =D10+(D21-D10)/da_life -> 36.976 | F10: =E10+(E21-E10)/da_life -> 42.7808 | G10: =C10+(C21-C10)/da_life -> 31.22 | H10: =G10+(G21-G10)/da_life -> 36.976 | I10: =H10+(H21-H10)/da_life -> 42.7808 | J10: =C10+(C21-C10)/da_life -> 31.22 | K10: =J10+(J21-J10)/da_life -> 36.976 | L10: =K10+(K21-K10)/da_life -> 42.7808
A11: 成本量指數（÷ 前一年） | D11: =w_c*(1+cb_1)+w_h*D31/C31+w_n*(1+nb_1) -> 1.2821552 | E11: =w_c*(1+cb_2)+w_h*E31/D31+w_n*(1+nb_2) -> 1.2319474 | F11: =w_c*(1+cb_3)+w_h*F31/E31+w_n*(1+nb_3) -> 1.189 | G11: =w_c*(1+cb_1)+w_h*G31/C31+w_n*(1+nb_1) -> 1.2821552 | H11: =w_c*(1+cb_2)+w_h*H31/G31+w_n*(1+nb_2) -> 1.2244434 | I11: =w_c*(1+cb_3)+w_h*I31/H31+w_n*(1+nb_3) -> 1.1936875 | J11: =w_c*(1+cb_1)+w_h*J31/C31+w_n*(1+nb_1) -> 1.2821552 | K11: =w_c*(1+cb_2)+w_h*K31/J31+w_n*(1+nb_2) -> 1.1690826 | L11: =w_c*(1+cb_3)+w_h*L31/K31+w_n*(1+nb_3) -> 1.1815
A12: 營業成本 | C12: =Q!J8 -> 79.294484 | D12: =(C12-da_cogs*C10)*D11*(1-costdn_y)+da_cogs*D10 -> 92.700716 | E12: =(D12-da_cogs*D10)*E11*(1-costdn_y)+da_cogs*E10 -> 104.90683 | F12: =(E12-da_cogs*E10)*F11*(1-costdn_y)+da_cogs*F10 -> 115.15231 | G12: =(C12-da_cogs*C10)*G11*(1-costdn_y)+da_cogs*G10 -> 92.700716 | H12: =(G12-da_cogs*G10)*H11*(1-costdn_y)+da_cogs*H10 -> 104.47053 | I12: =(H12-da_cogs*H10)*I11*(1-costdn_y)+da_cogs*I10 -> 114.98577 | J12: =(C12-da_cogs*C10)*J11*(1-costdn_y)+da_cogs*J10 -> 92.700716 | K12: =(J12-da_cogs*J10)*K11*(1-costdn_y)+da_cogs*K10 -> 101.25172 | L12: =(K12-da_cogs*K10)*L11*(1-costdn_y)+da_cogs*L10 -> 110.78215 | V12: 現金成本 × 量 × (1 − 年降)＋折舊
A13: 營業費用 | C13: =Q!J9 -> 34.144382 | D13: =opex_fix_y*(1+opex_g)^1+opex_var*D4 -> 52.306016 | E13: =opex_fix_y*(1+opex_g)^2+opex_var*E4 -> 57.373104 | F13: =opex_fix_y*(1+opex_g)^3+opex_var*F4 -> 61.557159 | G13: =opex_fix_y*(1+opex_g)^1+opex_var*G4 -> 51.232617 | H13: =opex_fix_y*(1+opex_g)^2+opex_var*H4 -> 34.451103 | I13: =opex_fix_y*(1+opex_g)^3+opex_var*I4 -> 38.89074 | J13: =opex_fix_y*(1+opex_g)^1+opex_var*J4 -> 51.232617 | K13: =opex_fix_y*(1+opex_g)^2+opex_var*K4 -> 25.55358 | L13: =opex_fix_y*(1+opex_g)^3+opex_var*L4 -> 23.91433
A14: 記憶體營業利益 | B14: =SUM(Q!B10:E10) -> 32.9 | C14: =Q!J10 -> 389.20084 | D14: =D4-D12-D13 -> 653.42687 | E14: =E4-E12-E13 -> 713.2718 | F14: =F4-F12-F13 -> 760.50986 | G14: =G4-G12-G13 -> 636.61029 | H14: =H4-H12-H13 -> 354.59675 | I14: =I4-I12-I13 -> 405.56916 | J14: =J4-J12-J13 -> 636.61029 | K14: =K4-K12-K13 -> 218.42104 | L14: =L4-L12-L13 -> 175.14235
A15: 記憶體營業利益率 | B15: =B14/B4 -> 0.31604227 | C15: =C14/C4 -> 0.77431376 | D15: =D14/D4 -> 0.81838599 | E15: =E14/E4 -> 0.81465409 | F15: =F14/F4 -> 0.81145346 | G15: =G14/G4 -> 0.8155986 | H15: =H14/H4 -> 0.71850767 | I15: =I14/I4 -> 0.72494826 | ... L15: =L14/L4 -> 0.56526922
A16: 非記憶體事業營收 | C16: =nm_rev_0 -> 224.8 | D16: =nm_rev_1 -> 230 | E16: =nm_rev_2 -> 240 | F16: =nm_rev_3 -> 250 | G16: =nm_rev_1 -> 230 | H16: =nm_rev_2 -> 240 | I16: =nm_rev_3 -> 250 | J16: =nm_rev_1 -> 230 | K16: =nm_rev_2 -> 240 | L16: =nm_rev_3 -> 250
A17: 非記憶體事業營業利益 | C17: =nm_op_0 -> 3.8 | D17: =nm_op_1 -> 6 | E17: =nm_op_2 -> 8 | F17: =nm_op_3 -> 8 | G17: =nm_op_1 -> 6 | H17: =nm_op_2 -> 8 | I17: =nm_op_3 -> 8 | J17: =nm_op_1 -> 6 | K17: =nm_op_2 -> 8 | L17: =nm_op_3 -> 8
A18: 合併營收 | C18: =C4+C16 -> 727.4397 | D18: =D4+D16 -> 1028.4336 | E18: =E4+E16 -> 1115.5517 | F18: =F4+F16 -> 1187.2193 | G18: =G4+G16 -> 1010.5436 | H18: =H4+H16 -> 733.51838 | I18: =I4+I16 -> 809.44566 | J18: =J4+J16 -> 1010.5436 | ... L18: =L4+L16 -> 559.83883 | M18: =F18*(1+M32) -> 1261.8116 | N18: =M18*(1+N32) -> 1339.3053 | O18: =N18*(1+O32) -> 1419.6637 | P18: =I18*(1+P32) -> 876.096 | Q18: =P18*(1+Q32) -> 929.68711 | R18: =Q18*(1+R32) -> 966.87459 | S18: =L18*(1+S32) -> 547.38031 | T18: =S18*(1+T32) -> 546.76347 | U18: =T18*(1+U32) -> 557.69874 | V18: 2030 起為收斂法：合併營收年增由 2029 線性收斂到 fade_g、淨利率收斂到 fade_m（2032 達到），非驅動因子推導
A19: 合併營業利益 | C19: =C14+C17 -> 393.00084 | D19: =D14+D17 -> 659.42687 | E19: =E14+E17 -> 721.2718 | F19: =F14+F17 -> 768.50986 | G19: =G14+G17 -> 642.61029 | H19: =H14+H17 -> 362.59675 | I19: =I14+I17 -> 413.56916 | J19: =J14+J17 -> 642.61029 | ... L19: =L14+L17 -> 183.14235
A20: 淨利（合併） | B20: =SUM(Q!B12:E12) -> 44.2 | C20: =Q!J12 -> 317.84067 | D20: =(D19+rf*C26)*(1-tax) -> 534.78304 | E20: =(E19+rf*D26)*(1-tax) -> 590.33102 | F20: =(F19+rf*E26)*(1-tax) -> 634.85714 | G20: =(G19+rf*C26)*(1-tax) -> 521.32977 | H20: =(H19+rf*G26)*(1-tax) -> 303.22953 | I20: =(I19+rf*H26)*(1-tax) -> 347.29793 | J20: =(J19+rf*C26)*(1-tax) -> 521.32977 | K20: =(K19+rf*J26)*(1-tax) -> 194.28896 | L20: =(L19+rf*K26)*(1-tax) -> 161.6492 | M20: =M18*M33 -> 515.36093 | N20: =N18*N33 -> 377.83925 | O20: =O18*O33 -> 221.18686 | P20: =P18*P33 -> 288.51251 | Q20: =Q18*Q33 -> 213.43354 | R20: =R18*R33 -> 125.5344 | S20: =S18*S33 -> 124.31973 | T20: =T18*T33 -> 90.485486 | U20: =U18*U33 -> 57.927163 | V20: （營業利益＋淨現金 × 收益率）× (1 − 稅率)
A21: 資本支出 | C21: =cap_0 -> 52.5 | D21: =cap_1 -> 60 | E21: =cap_2 -> 66 | F21: =cap_3 -> 66 | G21: =cap_1 -> 60 | H21: =cap_2 -> 66 | I21: =cap_3 -> 66 | J21: =cap_1 -> 60 | K21: =cap_2 -> 66 | L21: =cap_3 -> 66
A22: 自由現金流（淨利＋折舊 − 資本支出） | C22: =C20+C10-C21 -> 291.24067 | D22: =D20+D10-D21 -> 506.00304 | E22: =E20+E10-E21 -> 561.30702 | F22: =F20+F10-F21 -> 611.63794 | G22: =G20+G10-G21 -> 492.54977 | H22: =H20+H10-H21 -> 274.20553 | I22: =I20+I10-I21 -> 324.07873 | J22: =J20+J10-J21 -> 492.54977 | ... L22: =L20+L10-L21 -> 138.43
A23: 股利 | C23: =div_0 -> 32.5 | D23: =dps_1*C27/1000000 -> 9.76389 | E23: =dps_2*D27/1000000 -> 8.3713082 | F23: =dps_3*E27/1000000 -> 6.8124406 | G23: =dps_1*C27/1000000 -> 9.76389 | H23: =dps_2*G27/1000000 -> 8.4098194 | I23: =dps_3*H27/1000000 -> 7.6730278 | J23: =dps_1*C27/1000000 -> 9.76389 | K23: =dps_2*J27/1000000 -> 8.4098194 | L23: =dps_3*K27/1000000 -> 7.9848805
A24: 買回 | C24: =bb_0 -> 15 | D24: =MAX(0,payout*D22-D23) -> 243.23763 | E24: =MAX(0,payout*E22-E23) -> 272.2822 | F24: =MAX(0,payout*F22-F23) -> 299.00653 | G24: =MAX(0,payout*G22-G23) -> 236.51099 | H24: =MAX(0,payout*H22-H23) -> 128.69295 | I24: =MAX(0,payout*I22-I23) -> 154.36634 | J24: =MAX(0,payout*J22-J23) -> 236.51099 | K24: =MAX(0,payout*K22-K23) -> 74.222661 | L24: =MAX(0,payout*L22-L23) -> 61.230118 | V24: 回饋比例 × FCF − 股利
A25: 期末權益 | C25: =eq_last+(Q!H12+Q!I12)+extra_eq-C24-C23 -> 717.00067 | D25: =C25+D20-D23-D24 -> 998.78219 | E25: =D25+E20-E23-E24 -> 1308.4597 | F25: =E25+F20-F23-F24 -> 1637.4979 | G25: =C25+G20-G23-G24 -> 992.05555 | H25: =G25+H20-H23-H24 -> 1158.1823 | I25: =H25+I20-I23-I24 -> 1343.4409 | J25: =C25+J20-J23-J24 -> 992.05555 | K25: =J25+K20-K23-K24 -> 1103.712 | L25: =K25+L20-L23-L24 -> 1196.1462
A26: 期末淨現金 | C26: =nc_last+(Q!H12+Q!I12)+(Q!H13+Q!I13)-capex_rem+extra_eq-C24-C23 -> 301.73067 | D26: =C26+D22-D23-D24 -> 554.73219 | E26: =D26+E22-E23-E24 -> 835.3857 | F26: =E26+F22-F23-F24 -> 1141.2047 | G26: =C26+G22-G23-G24 -> 548.00555 | H26: =G26+H22-H23-H24 -> 685.10832 | I26: =H26+I22-I23-I24 -> 847.14768 | J26: =C26+J22-J23-J24 -> 548.00555 | K26: =J26+K22-K23-K24 -> 630.63803 | L26: =K26+L22-L23-L24 -> 699.85303
A27: 期末流通股數 | C27: =sh_last+extra_sh-bb_sh_0 -> 6509.26 | D27: =C27-D24/bb_px*1000000 -> 5580.8721 | E27: =D27-E24/bb_px*1000000 -> 4541.6271 | F27: =E27-F24/bb_px*1000000 -> 3400.3808 | G27: =C27-G24/bb_px*1000000 -> 5606.5463 | H27: =G27-H24/bb_px*1000000 -> 5115.3518 | I27: =H27-I24/bb_px*1000000 -> 4526.1673 | J27: =C27-J24/bb_px*1000000 -> 5606.5463 | K27: =J27-K24/bb_px*1000000 -> 5323.2537 | L27: =K27-L24/bb_px*1000000 -> 5089.5509 | M27: =F27 -> 3400.3808 | N27: =M27 -> 3400.3808 | O27: =N27 -> 3400.3808 | P27: =I27 -> 4526.1673 | Q27: =P27 -> 4526.1673 | R27: =Q27 -> 4526.1673 | S27: =L27 -> 5089.5509 | T27: =S27 -> 5089.5509 | U27: =T27 -> 5089.5509
A28: 每股淨值 BVPS | C28: =C25/C27*1000000 -> 110150.87 | D28: =D25/D27*1000000 -> 178965.25 | E28: =E25/E27*1000000 -> 288103.73 | F28: =F25/F27*1000000 -> 481563.09 | G28: =G25/G27*1000000 -> 176945.93 | H28: =H25/H27*1000000 -> 226413.03 | I28: =I25/I27*1000000 -> 296816.44 | J28: =J25/J27*1000000 -> 176945.93 | ... L28: =L25/L27*1000000 -> 235019.99
A29: 每股盈餘 EPS（期末股數） | C29: =C20/C27*1000000 -> 48829.002 | D29: =D20/D27*1000000 -> 95824.277 | E29: =E20/E27*1000000 -> 129982.27 | F29: =F20/F27*1000000 -> 186701.78 | G29: =G20/G27*1000000 -> 92985.902 | H29: =H20/H27*1000000 -> 59278.333 | I29: =I20/I27*1000000 -> 76731.128 | J29: =J20/J27*1000000 -> 92985.902 | ... U29: =U20/U27*1000000 -> 11381.586
A30: ROE（期末權益） | C30: =C20/C25 -> 0.44329201 | D30: =D20/D25 -> 0.53543509 | E30: =E20/E25 -> 0.45116485 | F30: =F20/F25 -> 0.38769952 | G30: =G20/G25 -> 0.52550461 | H30: =H20/H25 -> 0.26181502 | I30: =I20/I25 -> 0.25851374 | J30: =J20/J25 -> 0.52550461 | ... L30: =L20/L25 -> 0.13514167
A31: HBM 出貨位元（EB，公司） | C31: =(Mkt!D24/4*sh26+Mkt!D24/4*sh26+Mkt!D24/4*sh26+Mkt!D24/4*sh26) -> 1.0969815 | D31: =(Mkt!E24/4*sh27+Mkt!E24/4*sh27+Mkt!E24/4*sh27+Mkt!E24/4*sh27) -> 2.2280074 | E31: =(Mkt!F24/4*sh28+Mkt!F24/4*sh28+Mkt!F24/4*sh28+Mkt!F24/4*sh28) -> 3.4006428 | F31: =(Mkt!G24/4*sh29+Mkt!G24/4*sh29+Mkt!G24/4*sh29+Mkt!G24/4*sh29) -> 4.5908678 | G31: =(Mkt!E25/4*sh27+Mkt!E25/4*sh27+Mkt!E25/4*sh27+Mkt!E25/4*sh27) -> 2.2280074 | H31: =(Mkt!F25/4*sh28+Mkt!F25/4*sh28+Mkt!F25/4*sh28+Mkt!F25/4*sh28) -> 3.289184 | I31: =(Mkt!G25/4*sh29+Mkt!G25/4*sh29+Mkt!G25/4*sh29+Mkt!G25/4*sh29) -> 4.5431854 | J31: =(Mkt!E26/4*sh27+Mkt!E26/4*sh27+Mkt!E26/4*sh27+Mkt!E26/4*sh27) -> 2.2280074 | K31: =(Mkt!F26/4*sh28+Mkt!F26/4*sh28+Mkt!F26/4*sh28+Mkt!F26/4*sh28) -> 2.466888 | L31: =(Mkt!G26/4*sh29+Mkt!G26/4*sh29+Mkt!G26/4*sh29+Mkt!G26/4*sh29) -> 3.2069544
A32: 合併營收年增 | D32: =D18/C18-1 -> 0.41377162 | E32: =E18/D18-1 -> 0.084709537 | F32: =F18/E18-1 -> 0.064244068 | G32: =G18/C18-1 -> 0.38917853 | H32: =H18/G18-1 -> -0.27413486 | I32: =I18/H18-1 -> 0.10351108 | J32: =J18/C18-1 -> 0.38917853 | K32: =K18/J18-1 -> -0.42087969 | L32: =L18/K18-1 -> -0.043380655 | M32: =$F32+(fade_gA-$F32)*1/3 -> 0.062829378 | N32: =$F32+(fade_gA-$F32)*2/3 -> 0.061414689 | O32: =$F32+(fade_gA-$F32)*3/3 -> 0.06 | P32: =$I32+(fade_gB-$I32)*1/3 -> 0.082340719 | Q32: =$I32+(fade_gB-$I32)*2/3 -> 0.06117036 | R32: =$I32+(fade_gB-$I32)*3/3 -> 0.04 | S32: =$L32+(fade_gC-$L32)*1/3 -> -0.02225377 | T32: =$L32+(fade_gC-$L32)*2/3 -> -0.0011268849 | U32: =$L32+(fade_gC-$L32)*3/3 -> 0.02
A33: 淨利率（淨利 ÷ 合併營收） | C33: =C20/C18 -> 0.4369306 | D33: =D20/D18 -> 0.51999763 | E33: =E20/E18 -> 0.529183 | F33: =F20/F18 -> 0.53474293 | G33: =G20/G18 -> 0.51589041 | H33: =H20/H18 -> 0.4133905 | I33: =I20/I18 -> 0.4290565 | J33: =J20/J18 -> 0.51589041 | ... L33: =L20/L18 -> 0.28874238 | M33: =$F33+(fade_mA-$F33)*1/3 -> 0.40842939 | N33: =$F33+(fade_mA-$F33)*2/3 -> 0.28211584 | O33: =$F33+(fade_mA-$F33)*3/3 -> 0.1558023 | P33: =$I33+(fade_mB-$I33)*1/3 -> 0.32931608 | Q33: =$I33+(fade_mB-$I33)*2/3 -> 0.22957567 | R33: =$I33+(fade_mB-$I33)*3/3 -> 0.12983525 | S33: =$L33+(fade_mC-$L33)*1/3 -> 0.22711765 | T33: =$L33+(fade_mC-$L33)*2/3 -> 0.16549292 | U33: =$L33+(fade_mC-$L33)*3/3 -> 0.1038682

Sheet Val
A1: Val — 估值（P/B 主、P/E 對照）。隱含股價 ÷ 目前股價 − 1
A3: 方法 | B3: 倍數 | C3: 基準 | D3: 情境 | E3: 每股基準 | F3: 隱含股價 | G3: 相對目前
A4: P/B 1.0x（谷底） | B4: =pb_1 -> 1 | C4: 2026 期末 BVPS | D4: 共用 | E4: =Y!C28 -> 110150.87 | F4: =B4*E4 -> 110150.87 | G4: =F4/px-1 -> -0.48885906
A5: P/B 歷史中位 1.4x | B5: =pb_2 -> 1.4 | C5: 2026 期末 BVPS | D5: 共用 | E5: =Y!C28 -> 110150.87 | F5: =B5*E5 -> 154211.22 | G5: =F5/px-1 -> -0.28440268
A6: P/B 前高 2.0x | B6: =pb_3 -> 2 | C6: 2026 期末 BVPS | D6: 共用 | E6: =Y!C28 -> 110150.87 | F6: =B6*E6 -> 220301.75 | G6: =F6/px-1 -> 0.022281881
A7: P/B 1.0x（谷底） | B7: =pb_1 -> 1 | C7: 2027 期末 BVPS | D7: A | E7: =Y!D28 -> 178965.25 | F7: =B7*E7 -> 178965.25 | G7: =F7/px-1 -> -0.16953479
A8: P/B 歷史中位 1.4x | B8: =pb_2 -> 1.4 | C8: 2027 期末 BVPS | D8: A | E8: =Y!D28 -> 178965.25 | F8: =B8*E8 -> 250551.35 | G8: =F8/px-1 -> 0.16265129
A9: P/B 前高 2.0x | B9: =pb_3 -> 2 | C9: 2027 期末 BVPS | D9: A | E9: =Y!D28 -> 178965.25 | F9: =B9*E9 -> 357930.51 | G9: =F9/px-1 -> 0.66093042
A10: P/B 1.0x（谷底） | B10: =pb_1 -> 1 | C10: 2027 期末 BVPS | D10: B | E10: =Y!G28 -> 176945.93 | F10: =B10*E10 -> 176945.93 | G10: =F10/px-1 -> -0.17890519
A11: P/B 歷史中位 1.4x | B11: =pb_2 -> 1.4 | C11: 2027 期末 BVPS | D11: B | E11: =Y!G28 -> 176945.93 | F11: =B11*E11 -> 247724.3 | G11: =F11/px-1 -> 0.14953273
A12: P/B 前高 2.0x | B12: =pb_3 -> 2 | C12: 2027 期末 BVPS | D12: B | E12: =Y!G28 -> 176945.93 | F12: =B12*E12 -> 353891.86 | G12: =F12/px-1 -> 0.64218962
A13: P/B 1.0x（谷底） | B13: =pb_1 -> 1 | C13: 2027 期末 BVPS | D13: C | E13: =Y!J28 -> 176945.93 | F13: =B13*E13 -> 176945.93 | G13: =F13/px-1 -> -0.17890519
A14: P/B 歷史中位 1.4x | B14: =pb_2 -> 1.4 | C14: 2027 期末 BVPS | D14: C | E14: =Y!J28 -> 176945.93 | F14: =B14*E14 -> 247724.3 | G14: =F14/px-1 -> 0.14953273
A15: P/B 前高 2.0x | B15: =pb_3 -> 2 | C15: 2027 期末 BVPS | D15: C | E15: =Y!J28 -> 176945.93 | F15: =B15*E15 -> 353891.86 | G15: =F15/px-1 -> 0.64218962
A16: P/B 1.0x（谷底） | B16: =pb_1 -> 1 | C16: 2028 期末 BVPS | D16: A | E16: =Y!E28 -> 288103.73 | F16: =B16*E16 -> 288103.73 | G16: =F16/px-1 -> 0.33690826
A17: P/B 歷史中位 1.4x | B17: =pb_2 -> 1.4 | C17: 2028 期末 BVPS | D17: A | E17: =Y!E28 -> 288103.73 | F17: =B17*E17 -> 403345.22 | G17: =F17/px-1 -> 0.87167156
A18: P/B 前高 2.0x | B18: =pb_3 -> 2 | C18: 2028 期末 BVPS | D18: A | E18: =Y!E28 -> 288103.73 | F18: =B18*E18 -> 576207.46 | G18: =F18/px-1 -> 1.6738165
A19: P/B 1.0x（谷底） | B19: =pb_1 -> 1 | C19: 2028 期末 BVPS | D19: B | E19: =Y!H28 -> 226413.03 | F19: =B19*E19 -> 226413.03 | G19: =F19/px-1 -> 0.050640519
A20: P/B 歷史中位 1.4x | B20: =pb_2 -> 1.4 | C20: 2028 期末 BVPS | D20: B | E20: =Y!H28 -> 226413.03 | F20: =B20*E20 -> 316978.24 | G20: =F20/px-1 -> 0.47089673
A21: P/B 前高 2.0x | B21: =pb_3 -> 2 | C21: 2028 期末 BVPS | D21: B | E21: =Y!H28 -> 226413.03 | F21: =B21*E21 -> 452826.06 | G21: =F21/px-1 -> 1.101281
A22: P/B 1.0x（谷底） | B22: =pb_1 -> 1 | C22: 2028 期末 BVPS | D22: C | E22: =Y!K28 -> 207337.86 | F22: =B22*E22 -> 207337.86 | G22: =F22/px-1 -> -0.037875354
A23: P/B 歷史中位 1.4x | B23: =pb_2 -> 1.4 | C23: 2028 期末 BVPS | D23: C | E23: =Y!K28 -> 207337.86 | F23: =B23*E23 -> 290273.01 | G23: =F23/px-1 -> 0.3469745
A24: P/B 前高 2.0x | B24: =pb_3 -> 2 | C24: 2028 期末 BVPS | D24: C | E24: =Y!K28 -> 207337.86 | F24: =B24*E24 -> 414675.72 | G24: =F24/px-1 -> 0.92424929
A25: P/B 1.0x（谷底） | B25: =pb_1 -> 1 | C25: 2029 期末 BVPS | D25: A | E25: =Y!F28 -> 481563.09 | F25: =B25*E25 -> 481563.09 | G25: =F25/px-1 -> 1.2346315
A26: P/B 歷史中位 1.4x | B26: =pb_2 -> 1.4 | C26: 2029 期末 BVPS | D26: A | E26: =Y!F28 -> 481563.09 | F26: =B26*E26 -> 674188.32 | G26: =F26/px-1 -> 2.1284841
A27: P/B 前高 2.0x | B27: =pb_3 -> 2 | C27: 2029 期末 BVPS | D27: A | E27: =Y!F28 -> 481563.09 | F27: =B27*E27 -> 963126.18 | G27: =F27/px-1 -> 3.469263
A28: P/B 1.0x（谷底） | B28: =pb_1 -> 1 | C28: 2029 期末 BVPS | D28: B | E28: =Y!I28 -> 296816.44 | F28: =B28*E28 -> 296816.44 | G28: =F28/px-1 -> 0.37733847
A29: P/B 歷史中位 1.4x | B29: =pb_2 -> 1.4 | C29: 2029 期末 BVPS | D29: B | E29: =Y!I28 -> 296816.44 | F29: =B29*E29 -> 415543.02 | G29: =F29/px-1 -> 0.92827386
A30: P/B 前高 2.0x | B30: =pb_3 -> 2 | C30: 2029 期末 BVPS | D30: B | E30: =Y!I28 -> 296816.44 | F30: =B30*E30 -> 593632.88 | G30: =F30/px-1 -> 1.7546769
A31: P/B 1.0x（谷底） | B31: =pb_1 -> 1 | C31: 2029 期末 BVPS | D31: C | E31: =Y!L28 -> 235019.99 | F31: =B31*E31 -> 235019.99 | G31: =F31/px-1 -> 0.090580018
A32: P/B 歷史中位 1.4x | B32: =pb_2 -> 1.4 | C32: 2029 期末 BVPS | D32: C | E32: =Y!L28 -> 235019.99 | F32: =B32*E32 -> 329027.99 | G32: =F32/px-1 -> 0.52681202
A33: P/B 前高 2.0x | B33: =pb_3 -> 2 | C33: 2029 期末 BVPS | D33: C | E33: =Y!L28 -> 235019.99 | F33: =B33*E33 -> 470039.99 | G33: =F33/px-1 -> 1.18116
A34: P/E 4x | B34: =pe_1 -> 4 | C34: 2027 EPS | D34: A | E34: =Y!D29 -> 95824.277 | F34: =B34*E34 -> 383297.11 | G34: =F34/px-1 -> 0.77864087
A35: P/E 8x | B35: =pe_2 -> 8 | C35: 2027 EPS | D35: A | E35: =Y!D29 -> 95824.277 | F35: =B35*E35 -> 766594.22 | G35: =F35/px-1 -> 2.5572817
A36: P/E 12x | B36: =pe_3 -> 12 | C36: 2027 EPS | D36: A | E36: =Y!D29 -> 95824.277 | F36: =B36*E36 -> 1149891.3 | G36: =F36/px-1 -> 4.3359226
A37: P/E 4x | B37: =pe_1 -> 4 | C37: 2027 EPS | D37: B | E37: =Y!G29 -> 92985.902 | F37: =B37*E37 -> 371943.61 | G37: =F37/px-1 -> 0.72595643
A38: P/E 8x | B38: =pe_2 -> 8 | C38: 2027 EPS | D38: B | E38: =Y!G29 -> 92985.902 | F38: =B38*E38 -> 743887.22 | G38: =F38/px-1 -> 2.4519129
A39: P/E 12x | B39: =pe_3 -> 12 | C39: 2027 EPS | D39: B | E39: =Y!G29 -> 92985.902 | F39: =B39*E39 -> 1115830.8 | G39: =F39/px-1 -> 4.1778693
A40: P/E 4x | B40: =pe_1 -> 4 | C40: 2027 EPS | D40: C | E40: =Y!J29 -> 92985.902 | F40: =B40*E40 -> 371943.61 | G40: =F40/px-1 -> 0.72595643
A41: P/E 8x | B41: =pe_2 -> 8 | C41: 2027 EPS | D41: C | E41: =Y!J29 -> 92985.902 | F41: =B41*E41 -> 743887.22 | G41: =F41/px-1 -> 2.4519129
...

Sheet Sens
A1: Sens — 一次只動一個價格或份額輸入；Δ營業利益＝Δ營收 × (1 − 營業費用變動率)（成本只隨量變動，所以這是精確值，不是近似）
A3: 欄 | B3: 輸入變動 | C3: Δ營收 | D3: 營業利益 | E3: 相對基準
A4: 2027 A | B4: 基準 | D4: =Y!D14 -> 653.42687
A5: 2027 A | B5: 一般 DRAM 收入 −20% | C5: =-0.2*Y!D5 -> -93.390301 | D5: =D4+C5*(1-opex_var) -> 565.63999 | E5: =D5/D4-1 -> -0.13434844
A6: 2027 A | B6: 一般 DRAM 收入 +20% | C6: =0.2*Y!D5 -> 93.390301 | D6: =D4+C6*(1-opex_var) -> 741.21376 | E6: =D6/D4-1 -> 0.13434844
A7: 2027 A | B7: HBM 收入 −30%（價格或份額） | C7: =-0.3*Y!D6 -> -24.943166 | D7: =D4+C7*(1-opex_var) -> 629.9803 | E7: =D7/D4-1 -> -0.035882479
A8: 2027 A | B8: HBM 收入 +30% | C8: =0.3*Y!D6 -> 24.943166 | D8: =D4+C8*(1-opex_var) -> 676.87345 | E8: =D8/D4-1 -> 0.035882479
A9: 2027 A | B9: NAND 收入 −30% | C9: =-0.3*Y!D7 -> -74.501465 | D9: =D4+C9*(1-opex_var) -> 583.3955 | E9: =D9/D4-1 -> -0.10717554
A10: 2027 A | B10: NAND 收入 +30% | C10: =0.3*Y!D7 -> 74.501465 | D10: =D4+C10*(1-opex_var) -> 723.45825 | E10: =D10/D4-1 -> 0.10717554
A12: 2028 B | B12: 基準 | D12: =Y!H14 -> 354.59675
A13: 2028 B | B13: 一般 DRAM 收入 −20% | C13: =-0.2*Y!H5 -> -57.137226 | D13: =D12+C13*(1-opex_var) -> 300.88775 | E13: =D13/D12-1 -> -0.15146499
A14: 2028 B | B14: 一般 DRAM 收入 +20% | C14: =0.2*Y!H5 -> 57.137226 | D14: =D12+C14*(1-opex_var) -> 408.30574 | E14: =D14/D12-1 -> 0.15146499
A15: 2028 B | B15: HBM 收入 −30%（價格或份額） | C15: =-0.3*Y!H6 -> -27.617502 | D15: =D12+C15*(1-opex_var) -> 328.63629 | E15: =D15/D12-1 -> -0.073211196
A16: 2028 B | B16: HBM 收入 +30% | C16: =0.3*Y!H6 -> 27.617502 | D16: =D12+C16*(1-opex_var) -> 380.5572 | E16: =D16/D12-1 -> 0.073211196
A17: 2028 B | B17: NAND 收入 −30% | C17: =-0.3*Y!H7 -> -34.732175 | D17: =D12+C17*(1-opex_var) -> 321.9485 | E17: =D17/D12-1 -> -0.092071472
A18: 2028 B | B18: NAND 收入 +30% | C18: =0.3*Y!H7 -> 34.732175 | D18: =D12+C18*(1-opex_var) -> 387.24499 | E18: =D18/D12-1 -> 0.092071472
A20: 2028 C | B20: 基準 | D20: =Y!K14 -> 218.42104
A21: 2028 C | B21: 一般 DRAM 收入 −20% | C21: =-0.2*Y!K5 -> -39.194305 | D21: =D20+C21*(1-opex_var) -> 181.57839 | E21: =D21/D20-1 -> -0.16867719
A22: 2028 C | B22: 一般 DRAM 收入 +20% | C22: =0.2*Y!K5 -> 39.194305 | D22: =D20+C22*(1-opex_var) -> 255.26368 | E22: =D22/D20-1 -> 0.16867719
A23: 2028 C | B23: HBM 收入 −30%（價格或份額） | C23: =-0.3*Y!K6 -> -16.570501 | D23: =D20+C23*(1-opex_var) -> 202.84476 | E23: =D23/D20-1 -> -0.071313054
A24: 2028 C | B24: HBM 收入 +30% | C24: =0.3*Y!K6 -> 16.570501 | D24: =D20+C24*(1-opex_var) -> 233.99731 | E24: =D24/D20-1 -> 0.071313054
A25: 2028 C | B25: NAND 收入 −30% | C25: =-0.3*Y!K7 -> -28.205942 | D25: =D20+C25*(1-opex_var) -> 191.90745 | E25: =D25/D20-1 -> -0.12138751
A26: 2028 C | B26: NAND 收入 +30% | C26: =0.3*Y!K7 -> 28.205942 | D26: =D20+C26*(1-opex_var) -> 244.93462 | E26: =D26/D20-1 -> 0.12138751
A28: 2029 C | B28: 基準 | D28: =Y!L14 -> 175.14235
A29: 2029 C | B29: 一般 DRAM 收入 −20% | C29: =-0.2*Y!L5 -> -31.716508 | D29: =D28+C29*(1-opex_var) -> 145.32884 | E29: =D29/D28-1 -> -0.17022449
A30: 2029 C | B30: 一般 DRAM 收入 +20% | C30: =0.2*Y!L5 -> 31.716508 | D30: =D28+C30*(1-opex_var) -> 204.95587 | E30: =D30/D28-1 -> 0.17022449
A31: 2029 C | B31: HBM 收入 −30%（價格或份額） | C31: =-0.3*Y!L6 -> -22.618734 | D31: =D28+C31*(1-opex_var) -> 153.88074 | E31: =D31/D28-1 -> -0.12139616
A32: 2029 C | B32: HBM 收入 +30% | C32: =0.3*Y!L6 -> 22.618734 | D32: =D28+C32*(1-opex_var) -> 196.40396 | E32: =D32/D28-1 -> 0.12139616
A33: 2029 C | B33: NAND 收入 −30% | C33: =-0.3*Y!L7 -> -22.758153 | D33: =D28+C33*(1-opex_var) -> 153.74969 | E33: =D33/D28-1 -> -0.12214444
A34: 2029 C | B34: NAND 收入 +30% | C34: =0.3*Y!L7 -> 22.758153 | D34: =D28+C34*(1-opex_var) -> 196.53502 | E34: =D34/D28-1 -> 0.12214444
A36: 讀法：哪一條收入線的同幅變動對營業利益影響最大，就是該年度的主要驅動。價格路徑本身的情境差異見 Y 頁 A／B／C 欄。
A38: 目標價參數（只改 DCF 參數；Y 頁收斂法的 fade_g 不隨 tp_g 變動）
A39: 案例 | B39: 設定 | C39: DCF 目標價 | D39: Comparable 目標價 | E39: 加權目標價 | F39: 相對基準
A40: 基準 | B40: r 10%、g 4%、DCF 權重 0.5 | C40: =(tp_wA*(Val!B138/(1+tp_r)^1+Val!B139/(1+tp_r)^2+Val!B140/(1+tp_r)^3+Val!B133*(1-MIN(tp_g/tp_roe,0.8))/(1+tp_r)^4+Val!B134*(1-MIN(tp_g/tp_roe,0.8))/(1+tp_r)^5+Val!B135*(1-MIN(tp_g/tp_roe,0.8))/(1+tp_r)^6+Val!B135*(1-MIN(tp_g/tp_roe,0.8))*(1+tp_g)/(tp_r-tp_g)/(1+tp_r)^6)+tp_wB*(Val!C138/(1+tp_r)^1+Val!C139/(1+tp_r)^2+Val!C140/(1+tp_r)^3+Val!C133*(1-MIN(tp_g/tp_roe,0.8))/(1+tp_r)^4+Val!C134*(1-MIN(tp_g/tp_roe,0.8))/(1+tp_r)^5+Val!C135*(1-MIN(tp_g/tp_roe,0.8))/(1+tp_r)^6+Val!C135*(1-MIN(tp_g/tp_roe,0.8))*(1+tp_g)/(tp_r-tp_g)/(1+tp_r)^6)+tp_wC*(Val!D138/(1+tp_r)^1+Val!D139/(1+tp_r)^2+Val!D140/(1+tp_r)^3+Val!D133*(1-MIN(tp_g/tp_roe,0.8))/(1+tp_r)^4+Val!D134*(1-MIN(tp_g/tp_roe,0.8))/(1+tp_r)^5+Val!D135*(1-MIN(tp_g/tp_roe,0.8))/(1+tp_r)^6+Val!D135*(1-MIN(tp_g/tp_roe,0.8))*(1+tp_g)/(tp_r-tp_g)/(1+tp_r)^6))*(1+tp_r) -> 486542.25 | D40: =Val!B156 -> 467744.1 | E40: =tp_w_dcf*C40+(1-tp_w_dcf)*D40 -> 477143.17 | F40: =E40/E$40-1 -> 0
A41: 折現率 +1pt | B41: r 11% | C41: =(tp_wA*(Val!B138/(1+(tp_r+0.01))^1+Val!B139/(1+(tp_r+0.01))^2+Val!B140/(1+(tp_r+0.01))^3+Val!B133*(1-MIN(tp_g/tp_roe,0.8))/(1+(tp_r+0.01))^4+Val!B134*(1-MIN(tp_g/tp_roe,0.8))/(1+(tp_r+0.01))^5+Val!B135*(1-MIN(tp_g/tp_roe,0.8))/(1+(tp_r+0.01))^6+Val!B135*(1-MIN(tp_g/tp_roe,0.8))*(1+tp_g)/((tp_r+0.01)-tp_g)/(1+(tp_r+0.01))^6)+tp_wB*(Val!C138/(1+(tp_r+0.01))^1+Val!C139/(1+(tp_r+0.01))^2+Val!C140/(1+(tp_r+0.01))^3+Val!C133*(1-MIN(tp_g/tp_roe,0.8))/(1+(tp_r+0.01))^4+Val!C134*(1-MIN(tp_g/tp_roe,0.8))/(1+(tp_r+0.01))^5+Val!C135*(1-MIN(tp_g/tp_roe,0.8))/(1+(tp_r+0.01))^6+Val!C135*(1-MIN(tp_g/tp_roe,0.8))*(1+tp_g)/((tp_r+0.01)-tp_g)/(1+(tp_r+0.01))^6)+tp_wC*(Val!D138/(1+(tp_r+0.01))^1+Val!D139/(1+(tp_r+0.01))^2+Val!D140/(1+(tp_r+0.01))^3+Val!D133*(1-MIN(tp_g/tp_roe,0.8))/(1+(tp_r+0.01))^4+Val!D134*(1-MIN(tp_g/tp_roe,0.8))/(1+(tp_r+0.01))^5+Val!D135*(1-MIN(tp_g/tp_roe,0.8))/(1+(tp_r+0.01))^6+Val!D135*(1-MIN(tp_g/tp_roe,0.8))*(1+tp_g)/((tp_r+0.01)-tp_g)/(1+(tp_r+0.01))^6))*(1+(tp_r+0.01)) -> 447679.29 | D41: =Val!B156 -> 467744.1 | E41: =tp_w_dcf*C41+(1-tp_w_dcf)*D41 -> 457711.7 | F41: =E41/E$40-1 -> -0.040724624
A42: 折現率 −1pt | B42: r 9% | C42: =(tp_wA*(Val!B138/(1+(tp_r-0.01))^1+Val!B139/(1+(tp_r-0.01))^2+Val!B140/(1+(tp_r-0.01))^3+Val!B133*(1-MIN(tp_g/tp_roe,0.8))/(1+(tp_r-0.01))^4+Val!B134*(1-MIN(tp_g/tp_roe,0.8))/(1+(tp_r-0.01))^5+Val!B135*(1-MIN(tp_g/tp_roe,0.8))/(1+(tp_r-0.01))^6+Val!B135*(1-MIN(tp_g/tp_roe,0.8))*(1+tp_g)/((tp_r-0.01)-tp_g)/(1+(tp_r-0.01))^6)+tp_wB*(Val!C138/(1+(tp_r-0.01))^1+Val!C139/(1+(tp_r-0.01))^2+Val!C140/(1+(tp_r-0.01))^3+Val!C133*(1-MIN(tp_g/tp_roe,0.8))/(1+(tp_r-0.01))^4+Val!C134*(1-MIN(tp_g/tp_roe,0.8))/(1+(tp_r-0.01))^5+Val!C135*(1-MIN(tp_g/tp_roe,0.8))/(1+(tp_r-0.01))^6+Val!C135*(1-MIN(tp_g/tp_roe,0.8))*(1+tp_g)/((tp_r-0.01)-tp_g)/(1+(tp_r-0.01))^6)+tp_wC*(Val!D138/(1+(tp_r-0.01))^1+Val!D139/(1+(tp_r-0.01))^2+Val!D140/(1+(tp_r-0.01))^3+Val!D133*(1-MIN(tp_g/tp_roe,0.8))/(1+(tp_r-0.01))^4+Val!D134*(1-MIN(tp_g/tp_roe,0.8))/(1+(tp_r-0.01))^5+Val!D135*(1-MIN(tp_g/tp_roe,0.8))/(1+(tp_r-0.01))^6+Val!D135*(1-MIN(tp_g/tp_roe,0.8))*(1+tp_g)/((tp_r-0.01)-tp_g)/(1+(tp_r-0.01))^6))*(1+(tp_r-0.01)) -> 540048.1 | D42: =Val!B156 -> 467744.1 | E42: =tp_w_dcf*C42+(1-tp_w_dcf)*D42 -> 503896.1 | F42: =E42/E$40-1 -> 0.056068967
A43: 長期成長 +1pt | B43: g 5% | C43: =(tp_wA*(Val!B138/(1+tp_r)^1+Val!B139/(1+tp_r)^2+Val!B140/(1+tp_r)^3+Val!B133*(1-MIN((tp_g+0.01)/tp_roe,0.8))/(1+tp_r)^4+Val!B134*(1-MIN((tp_g+0.01)/tp_roe,0.8))/(1+tp_r)^5+Val!B135*(1-MIN((tp_g+0.01)/tp_roe,0.8))/(1+tp_r)^6+Val!B135*(1-MIN((tp_g+0.01)/tp_roe,0.8))*(1+(tp_g+0.01))/(tp_r-(tp_g+0.01))/(1+tp_r)^6)+tp_wB*(Val!C138/(1+tp_r)^1+Val!C139/(1+tp_r)^2+Val!C140/(1+tp_r)^3+Val!C133*(1-MIN((tp_g+0.01)/tp_roe,0.8))/(1+tp_r)^4+Val!C134*(1-MIN((tp_g+0.01)/tp_roe,0.8))/(1+tp_r)^5+Val!C135*(1-MIN((tp_g+0.01)/tp_roe,0.8))/(1+tp_r)^6+Val!C135*(1-MIN((tp_g+0.01)/tp_roe,0.8))*(1+(tp_g+0.01))/(tp_r-(tp_g+0.01))/(1+tp_r)^6)+tp_wC*(Val!D138/(1+tp_r)^1+Val!D139/(1+tp_r)^2+Val!D140/(1+tp_r)^3+Val!D133*(1-MIN((tp_g+0.01)/tp_roe,0.8))/(1+tp_r)^4+Val!D134*(1-MIN((tp_g+0.01)/tp_roe,0.8))/(1+tp_r)^5+Val!D135*(1-MIN((tp_g+0.01)/tp_roe,0.8))/(1+tp_r)^6+Val!D135*(1-MIN((tp_g+0.01)/tp_roe,0.8))*(1+(tp_g+0.01))/(tp_r-(tp_g+0.01))/(1+tp_r)^6))*(1+tp_r) -> 453788.93 | D43: =Val!B156 -> 467744.1 | E43: =tp_w_dcf*C43+(1-tp_w_dcf)*D43 -> 460766.52 | F43: =E43/E$40-1 -> -0.034322311
A44: 長期成長 −1pt | B44: g 3% | C44: =(tp_wA*(Val!B138/(1+tp_r)^1+Val!B139/(1+tp_r)^2+Val!B140/(1+tp_r)^3+Val!B133*(1-MIN((tp_g-0.01)/tp_roe,0.8))/(1+tp_r)^4+Val!B134*(1-MIN((tp_g-0.01)/tp_roe,0.8))/(1+tp_r)^5+Val!B135*(1-MIN((tp_g-0.01)/tp_roe,0.8))/(1+tp_r)^6+Val!B135*(1-MIN((tp_g-0.01)/tp_roe,0.8))*(1+(tp_g-0.01))/(tp_r-(tp_g-0.01))/(1+tp_r)^6)+tp_wB*(Val!C138/(1+tp_r)^1+Val!C139/(1+tp_r)^2+Val!C140/(1+tp_r)^3+Val!C133*(1-MIN((tp_g-0.01)/tp_roe,0.8))/(1+tp_r)^4+Val!C134*(1-MIN((tp_g-0.01)/tp_roe,0.8))/(1+tp_r)^5+Val!C135*(1-MIN((tp_g-0.01)/tp_roe,0.8))/(1+tp_r)^6+Val!C135*(1-MIN((tp_g-0.01)/tp_roe,0.8))*(1+(tp_g-0.01))/(tp_r-(tp_g-0.01))/(1+tp_r)^6)+tp_wC*(Val!D138/(1+tp_r)^1+Val!D139/(1+tp_r)^2+Val!D140/(1+tp_r)^3+Val!D133*(1-MIN((tp_g-0.01)/tp_roe,0.8))/(1+tp_r)^4+Val!D134*(1-MIN((tp_g-0.01)/tp_roe,0.8))/(1+tp_r)^5+Val!D135*(1-MIN((tp_g-0.01)/tp_roe,0.8))/(1+tp_r)^6+Val!D135*(1-MIN((tp_g-0.01)/tp_roe,0.8))*(1+(tp_g-0.01))/(tp_r-(tp_g-0.01))/(1+tp_r)^6))*(1+tp_r) -> 513605.06 | D44: =Val!B156 -> 467744.1 | E44: =tp_w_dcf*C44+(1-tp_w_dcf)*D44 -> 490674.58 | F44: =E44/E$40-1 -> 0.028359214
A45: DCF 權重 0.3 | B45: Comparable 0.7 | C45: =(tp_wA*(Val!B138/(1+tp_r)^1+Val!B139/(1+tp_r)^2+Val!B140/(1+tp_r)^3+Val!B133*(1-MIN(tp_g/tp_roe,0.8))/(1+tp_r)^4+Val!B134*(1-MIN(tp_g/tp_roe,0.8))/(1+tp_r)^5+Val!B135*(1-MIN(tp_g/tp_roe,0.8))/(1+tp_r)^6+Val!B135*(1-MIN(tp_g/tp_roe,0.8))*(1+tp_g)/(tp_r-tp_g)/(1+tp_r)^6)+tp_wB*(Val!C138/(1+tp_r)^1+Val!C139/(1+tp_r)^2+Val!C140/(1+tp_r)^3+Val!C133*(1-MIN(tp_g/tp_roe,0.8))/(1+tp_r)^4+Val!C134*(1-MIN(tp_g/tp_roe,0.8))/(1+tp_r)^5+Val!C135*(1-MIN(tp_g/tp_roe,0.8))/(1+tp_r)^6+Val!C135*(1-MIN(tp_g/tp_roe,0.8))*(1+tp_g)/(tp_r-tp_g)/(1+tp_r)^6)+tp_wC*(Val!D138/(1+tp_r)^1+Val!D139/(1+tp_r)^2+Val!D140/(1+tp_r)^3+Val!D133*(1-MIN(tp_g/tp_roe,0.8))/(1+tp_r)^4+Val!D134*(1-MIN(tp_g/tp_roe,0.8))/(1+tp_r)^5+Val!D135*(1-MIN(tp_g/tp_roe,0.8))/(1+tp_r)^6+Val!D135*(1-MIN(tp_g/tp_roe,0.8))*(1+tp_g)/(tp_r-tp_g)/(1+tp_r)^6))*(1+tp_r) -> 486542.25 | D45: =Val!B156 -> 467744.1 | E45: =0.3*C45+(1-0.3)*D45 -> 473383.54 | F45: =E45/E$40-1 -> -0.0078794567
A46: DCF 權重 0.7 | B46: Comparable 0.3 | C46: =(tp_wA*(Val!B138/(1+tp_r)^1+Val!B139/(1+tp_r)^2+Val!B140/(1+tp_r)^3+Val!B133*(1-MIN(tp_g/tp_roe,0.8))/(1+tp_r)^4+Val!B134*(1-MIN(tp_g/tp_roe,0.8))/(1+tp_r)^5+Val!B135*(1-MIN(tp_g/tp_roe,0.8))/(1+tp_r)^6+Val!B135*(1-MIN(tp_g/tp_roe,0.8))*(1+tp_g)/(tp_r-tp_g)/(1+tp_r)^6)+tp_wB*(Val!C138/(1+tp_r)^1+Val!C139/(1+tp_r)^2+Val!C140/(1+tp_r)^3+Val!C133*(1-MIN(tp_g/tp_roe,0.8))/(1+tp_r)^4+Val!C134*(1-MIN(tp_g/tp_roe,0.8))/(1+tp_r)^5+Val!C135*(1-MIN(tp_g/tp_roe,0.8))/(1+tp_r)^6+Val!C135*(1-MIN(tp_g/tp_roe,0.8))*(1+tp_g)/(tp_r-tp_g)/(1+tp_r)^6)+tp_wC*(Val!D138/(1+tp_r)^1+Val!D139/(1+tp_r)^2+Val!D140/(1+tp_r)^3+Val!D133*(1-MIN(tp_g/tp_roe,0.8))/(1+tp_r)^4+Val!D134*(1-MIN(tp_g/tp_roe,0.8))/(1+tp_r)^5+Val!D135*(1-MIN(tp_g/tp_roe,0.8))/(1+tp_r)^6+Val!D135*(1-MIN(tp_g/tp_roe,0.8))*(1+tp_g)/(tp_r-tp_g)/(1+tp_r)^6))*(1+tp_r) -> 486542.25 | D46: =Val!B156 -> 467744.1 | E46: =0.7*C46+(1-0.7)*D46 -> 480902.8 | F46: =E46/E$40-1 -> 0.0078794567
...

Sheet Recon
A1: Recon — 本模型（正向推導）vs 共識或公司指引（只作事後對照，不用來回推參數）；兆韓元
A3: 項目 | B3: 本模型 | C3: 對照值 | D3: 差距 | E3: 對照來源
A4: 2026Q3E 合併營業利益 vs 公司初步財報 | B4: =Q!H10+nm_op_q -> 111.52042 | C4: 107.4 | D4: =B4/C4-1 -> 0.038365186 | E4: 三星 2026-10-08 初步財報（約 107.4 兆）[Verified]
A5: 2026E 合併營收 vs 共識 | B5: =Y!C18 -> 727.4397 | C5: 711.7 | D5: =B5/C5-1 -> 0.022115644 | E5: MarketScreener 2026-10-06
A6: 2026E 合併營業利益 vs 共識 | B6: =Y!C19 -> 393.00084 | C6: 373.7 | D6: =B6/C6-1 -> 0.051647945 | E6: MarketScreener；KB 381
A7: 2026E 淨利 vs 共識 | B7: =Y!C20 -> 317.84067 | C7: 303.3 | D7: =B7/C7-1 -> 0.047941542 | E7: MarketScreener
A8: 2027E 合併營業利益（A）vs 共識 | B8: =Y!D19 -> 659.42687 | C8: 568.7 | D8: =B8/C8-1 -> 0.1595338 | E8: MarketScreener；FnGuide 544.7；KB 574
A9: 2027E 淨利（A）vs 共識 | B9: =Y!D20 -> 534.78304 | C9: 454.7 | D9: =B9/C9-1 -> 0.1761228 | E9: MarketScreener
A10: 2028E 合併營業利益（A）vs 共識 | B10: =Y!E19 -> 721.2718 | C10: 578.4 | D10: =B10/C10-1 -> 0.24701211 | E10: MarketScreener；FnGuide 543.9
A11: 2027E EPS（A）vs 共識（第 0 節差距拆解用） | B11: =Y!D29 -> 95824.277 | C11: =cons_eps27 -> 72279 | D11: =B11/C11-1 -> 0.32575544 | E11: MarketScreener 預估頁（2026-10-25 擷取；頁面為 10-23 收盤）
A12: 2028E EPS（A）vs 共識（第 0 節差距拆解用） | B12: =Y!E29 -> 129982.27 | C12: =cons_eps28 -> 75531 | D12: =B12/C12-1 -> 0.72091293 | E12: MarketScreener 預估頁（2026-10-25 擷取；頁面為 10-23 收盤）
A13: 2028E 年底每股淨值（A）vs 共識 | B13: =Y!E28 -> 288103.73 | C13: =cons_bvps28 -> 232055 | D13: =B13/C13-1 -> 0.24153209 | E13: MarketScreener 預估頁（2026-10-25 擷取；頁面為 10-23 收盤）

Sheet Feedback
A1: Feedback — 回饋算力收支
A3: 每顆加速器 HBM 金額（GB300，2026 價） | B3: =nv_hbm -> 4.46 | C3: $K
A4: 全市場每顆加速器平均 HBM 2026／2027 | B4: =TEXT(Mkt!D16,"0")&" ／ "&TEXT(Mkt!E16,"0") -> 216 ／ 260 | C4: GB
A5: HBM 市場 2026／2027（A） | B5: =TEXT(Mkt!D33,"0")&" ／ "&TEXT(Mkt!E33,"0") -> 55 ／ 154 | C5: $B
A6: 2027 HBM 需求缺口（三情境相同） | B6: =Mkt!E27 -> 1.2325527 | C6: EB
A7: 三星電子 HBM 毛利率 | B7: 無法由公開資料分離 | C7: —

Sheet Sources
A1: 來源
A2: 三星 2026Q3 初步財報（2026-10-08） | B2: https://news.samsung.com/global/samsung-electronics-announces-earnings-guidance-for-third-quarter-2026
A3: 三星 IR 2Q26 簡報 | B3: https://images.samsung.com/is/content/samsung/assets/global/ir/docs/2026_2Q_conference_eng.pdf
A4: 三星 IR 1Q26 簡報 | B4: https://images.samsung.com/is/content/samsung/assets/global/ir/docs/2026_1Q_conference_eng.pdf
A5: 三星 IR 4Q25 簡報 | B5: https://images.samsung.com/is/content/samsung/assets/global/ir/docs/2025_4Q_conference_eng.pdf
A6: 三星 2Q26 資產負債表 | B6: https://images.samsung.com/kdp/ir/financial-info/2026/2026_con_quarter02_bs.pdf
A7: 三星 2026 股東回饋（2026-08-21） | B7: https://news.samsung.com/global/samsung-electronics-to-implement-largest-ever-shareholder-return-in-2026-estimated-at-krw-90-to-110-trillion
A8: TrendForce 2Q26 法說摘要 | B8: https://www.trendforce.com/news/?p=61735
A9: FN News（TrendForce 2Q26 DRAM 營收） | B9: https://www.fnnews.com/news/202609071940555902
A10: MarketScreener 共識 | B10: https://www.marketscreener.com/quote/stock/SAMSUNG-ELECTRONICS-CO-6494906/finances/
A11: companiesmarketcap P/B | B11: https://companiesmarketcap.com/samsung/pb-ratio/
A12: Seoul Economic Daily（P4、資本支出） | B12: https://en.sedaily.com/finance/2026/04/22/samsung-accelerates-p4-fab-advances-full-production-by-six
A13: markets/memory/market.py（共用市場層） | B13: 本 repo
A14: markets/chip_bridge v0.2 | B14: 本 repo
