Workbook

Sheet README
A1: 景碩（Kinsus，3189.TW）收支與估值模型 v0.1（AI 半導體 Project：載板與 PCB 次產業——ABF／BT 載板第二梯隊；樣板＝nanya_pcb/、unimicron/） 2026-10-26
A2: 版本：v0.1（初版）。AI 加速器載板的每顆金額、Ibiden 份額與非 NVIDIA 權重讀 ibiden/dist，欣興份額讀 unimicron/dist，南電份額讀 nanya_pcb/dist（本專案權威）；四家份額合計在 Units 頁檢查。
A3: 模型命題：景碩的 ABF 載板營收＝MIN（需求, 產能）；需求＝NVIDIA CPU（Grace→Vera）載板（加速器顆數 × CPU 比例 × 每顆金額 × 景碩份額，公司目標 2027 年 80–100%）＋GPU 與 ASIC 加速器載板（與 Ibiden、欣興、南電同口徑，份額個位數）＋其他 AI＋非 AI ABF（伺服器與 PC CPU）；產能依公司規劃 4,000→8,000 萬顆／月（2029 年）。BT 與其他載板（約四成營收）以漲價為主；晶碩（隱形眼鏡）約 15% 營收、約 69% 淨利屬非控制權益。
A4: 核心問題：Vera CPU 載板份額、ABF 與 BT 漲價與 K6 新產能，能不能讓 EPS 從 FY2025 的 3.51 元升到 FY2027 二十多元；約 986 元的股價（近 12 月 P/E 166 倍、前瞻 P/E 45 倍）隱含什麼路徑。
A5: ="投資建議："&Val!B49&"（依上檔空間固定規則；加權目標價上檔空間 "&TEXT(Val!B42,"0.0%")&"，級距 "&Val!B48&"）" -> 投資建議：中立（依上檔空間固定規則；加權目標價上檔空間 -7.9%，級距 0%～−25%）
A6: 重點觀察 1：目標價 NT$908（DCF 529、Comparable 1,287 各半），比現價 986（2026-10-22）低 7.9%，級距 0%～−25%（中立）；Comparable 單獨為 +30.5%，市場共識目標價 1,092。兩法差距來自 DCF：2026–28 年資本支出合計 440 億（K6 新廠與 ABF 擴產），情境 B 每股股東現金流 FY2027 只有 10.37（EPS 26.21 的 40%）；本模型 12 個月後前瞻 EPS 30.44 比共識前瞻 EPS 22.06 高 38%（期間差約一年），共識目標價隱含 49.5 倍、比同業中位數 42.3 倍高 17%。
A7: 重點觀察 2：FY2027–28 ABF 需求滿足率約 86%／88%（產能受限），EPS 由價格與產能決定、而非 AI 份額：漲價年度化 8%／22%（基準 15%）使 FY2027 EPS −11.4%／+11.4%，ABF 溢價取 Ibiden 低／高值使 FY2028 EPS −15.2%／+15.7%，ABF 產能低值 −13.2%；AI 部署 ×0.8、Vera CPU 或 GPU 份額高低對 FY2027–28 EPS 的影響都在 0.3% 以內。
A8: 重點觀察 3：份額說法與上游衝突：券商稱景碩 Rubin GPU 份額 15–20%、Vera CPU 80–100%，但 Ibiden、欣興、南電模型的 NVIDIA 份額已合計約 94–97%，本模型 GPU 取 2%→6%。下一個檢驗點是 3Q26 財報與法說（stockanalysis 估 2026-11-06）：本模型 3Q26 毛利率 31%、EPS 4.30（永豐 4.29、美系毛利率 27.8%），FY2026 EPS 13.69 比主串共識 10.42 高 31%。
A9: 會計年度＝日曆年，FY(t)＝CY(t)，不平移。預測期 FY2027–FY2029 由驅動因子推導；FY2030 起為收斂法，非驅動因子推導（延伸到 FY2032；PL 頁灰底）。金額：十億新台幣；EPS：新台幣（基本、歸屬母公司）。3Q26 財報約 10 月底～11 月初公布，本版只納入 3Q26 營收實績。
A11: 驅動因子 → 推導量（全部唯讀上游，不修改）
A12: 加速器與 CPU 載板：markets/network 的 NVIDIA 與非 NVIDIA 顆數 × tsmc 同字母情境係數 × 每顆 NVIDIA 載板金額（Ibiden 模型 US$215 × 面積層數 +18%／年 × Ibiden 溢價指數）× 景碩份額（GPU 2%→6%、非 NVIDIA 金額 3%→6%、NVIDIA CPU 35%→70–75%；CPU 顆數＝NVIDIA × 0.4、CPU 載板金額＝GPU × 0.3）× 漲價年度化 1.15。
A13: 其他 AI 載板＝FY2026 AI 載板（ABF × 25%）− 加速器與 CPU 載板（校準殘差），之後 × 交換晶片與交換器市場成長 ^ 0.5 × 情境係數 × 溢價 × 漲價年度化；非 AI ABF 量 +6%／年 × 漲價年度化。ABF 產能指數 1.20／1.50／1.85（公司規劃，Interested-party）× 組合 +5%／年。BT 與其他載板年增依情境（A 28%／10%／5%、B 20%／5%／3%、C 12%／0%／−3%）；晶碩 +10%／年。
A14: 毛利＝FY2026 錨點＋ABF 現金毛利增量（50%）＋BT 增量（45%）＋晶碩增量（45%）＋漲價溢價營收 − 折舊增量；折舊＝前一年 ×（1 − 1／8 年）＋前一年資本支出 ÷ 8 年；資本支出 170／160／120 億（三情境相同）。營業費用彈性 0.6；業外每年 4 億；稅率 12%；非控制權益＝晶碩營收 × 25% × 68.8%；股數持平 5.27 億股。
A15: 校準：FY2026 ＝ 1Q26、2Q26 財報實績（EPS 1.17、2.57）＋3Q26 營收實績 145.4 億＋3Q26 毛利率 31%、4Q26 營收季增 12%、毛利率 32%（Assumed）。不用券商數字（只在 Recon 對帳）。
A16: 估值：Val 第 0 節目標價＝0.5 × DCF 目標價（股東現金流＝每股（淨利＋折舊－資本支出），FY2027–32 明確期＋永續，r 10%、g 4%，三情境權重 0.3／0.5／0.2，負值取 0）＋0.5 × Comparable 目標價（欣興、南電、Ibiden、三星電機、AT&S 前瞻 P/E 中位數 × 12 個月後前瞻 EPS；無 A 股）；另列 Comparable 單獨目標價、市場共識目標價、差距拆解與上檔空間級距。十年 P/E 規則值 × FY2027 EPS 保留為參考（不是目標價）。本版未做先驗，無 Andy 合理 P/E 對照。
A17: 情境與行業一致：A／B／C 讀 tsmc 同字母顆數係數（＝markets/memory SCEN_UNITS，建置時核對）；交換器市場讀 markets/network（單一路徑 × 同字母係數）；公司特有變數只有 BT 與其他載板年增隨情境，A 最有利、C 最不利。
A18: 標記：Verified、Interested-party、Analogy、Assumed、Derived。SemiAnalysis 未使用。公司數字經資料商與媒體轉載（公司原文待人工複核）；券商與資料商為 Interested-party。
A20: 已知限制：(1) 公司不揭露 ABF／BT 與 AI 拆分，產品組合取媒體與法說摘要、AI 占比取高盛轉述；(2) 券商稱景碩 Rubin GPU 份額 15–20%，與 Ibiden、欣興、南電模型的份額合計（94–97%）衝突，本模型取剩餘空間（Sens 列高值）；(3) Vera CPU 份額與 CPU 載板金額比為公司說法與 Assumed；(4) 毛利用現金流通率近似，未建分廠稼動率；(5) 客戶贊助設備的金額與會計處理未知，資本支出可能高估；(6) 晶碩持股比例由非控制權益推得（約 31%），未取得原文；(7) 十年 P/E 2023–24 年約 900 倍、2019 年虧損不計；(8) FactSet 共識為 2026-06，主串提供的共識 EPS 口徑未查證；(9) 3Q26 財報（約 10 月底～11 月初）後更新錨點。

Sheet In
A1: In — 輸入（藍字；基準欄 E，低 D、高 F）。金額：十億新台幣（NT$B）；顆數：百萬顆；比例：%。每個輸入附兩個來源（找不到者寫「未找到」）；公司原文算一個
A2: 標記：Verified／Interested-party／Analogy／Assumed／Derived；Analogy、Assumed 給低／高區間，不當點估計（放情境或 Sens）。SemiAnalysis 未使用。公司數字經資料商（stockanalysis）與媒體轉載；公司說法為 Interested-party；券商、媒體、資料商為 Interested-party
A3: 鍵 | B3: 項目 | C3: 單位 | D3: 低 | E3: 基準 | F3: 高 | G3: 標記 | H3: 來源1 | I3: 來源2／說明
A4: A. AI 加速器顆數、AI IT 資本支出與交換器市場（讀 markets/network、tsmc 成品；唯讀，不自行重估）
A5: u_bw_26 | B5: NVIDIA Blackwell（B200／B300） 顆數 2026 | C5: 百萬顆 | E5: 5.4 | G5: Derived | H5: markets/network/dist/20261026_AI網通市場模型_v0.2.3.xlsx｜In!E5 | I5: 唯讀上游；與 Ibiden、欣興、南電、台積電模型同一份顆數
A6: u_bw_27 | B6: NVIDIA Blackwell（B200／B300） 顆數 2027 | C6: 百萬顆 | E6: 2.4 | G6: Derived | H6: markets/network/dist/20261026_AI網通市場模型_v0.2.3.xlsx｜In!E6 | I6: 唯讀上游；與 Ibiden、欣興、南電、台積電模型同一份顆數
A7: u_bw_28 | B7: NVIDIA Blackwell（B200／B300） 顆數 2028 | C7: 百萬顆 | E7: 0.5 | G7: Derived | H7: markets/network/dist/20261026_AI網通市場模型_v0.2.3.xlsx｜In!E7 | I7: 唯讀上游；與 Ibiden、欣興、南電、台積電模型同一份顆數
A8: g29_bw | B8: NVIDIA Blackwell（B200／B300） 2029 顆數成長 | C8: % | E8: -0.5 | G8: Derived | H8: markets/network/dist/20261026_AI網通市場模型_v0.2.3.xlsx｜In!E8 | I8: 同上
A9: u_rb_26 | B9: NVIDIA Rubin 顆數 2026 | C9: 百萬顆 | E9: 1.7 | G9: Derived | H9: markets/network/dist/20261026_AI網通市場模型_v0.2.3.xlsx｜In!E9 | I9: 唯讀上游；與 Ibiden、欣興、南電、台積電模型同一份顆數
A10: u_rb_27 | B10: NVIDIA Rubin 顆數 2027 | C10: 百萬顆 | E10: 7 | G10: Derived | H10: markets/network/dist/20261026_AI網通市場模型_v0.2.3.xlsx｜In!E10 | I10: 唯讀上游；與 Ibiden、欣興、南電、台積電模型同一份顆數
A11: u_rb_28 | B11: NVIDIA Rubin 顆數 2028 | C11: 百萬顆 | E11: 7 | G11: Derived | H11: markets/network/dist/20261026_AI網通市場模型_v0.2.3.xlsx｜In!E11 | I11: 唯讀上游；與 Ibiden、欣興、南電、台積電模型同一份顆數
A12: g29_rb | B12: NVIDIA Rubin 2029 顆數成長 | C12: % | E12: 0.15 | G12: Derived | H12: markets/network/dist/20261026_AI網通市場模型_v0.2.3.xlsx｜In!E12 | I12: 同上
A13: u_ru_26 | B13: NVIDIA Rubin Ultra 顆數 2026 | C13: 百萬顆 | E13: 0 | G13: Derived | H13: markets/network/dist/20261026_AI網通市場模型_v0.2.3.xlsx｜In!E13 | I13: 唯讀上游；與 Ibiden、欣興、南電、台積電模型同一份顆數
A14: u_ru_27 | B14: NVIDIA Rubin Ultra 顆數 2027 | C14: 百萬顆 | E14: 0.3 | G14: Derived | H14: markets/network/dist/20261026_AI網通市場模型_v0.2.3.xlsx｜In!E14 | I14: 唯讀上游；與 Ibiden、欣興、南電、台積電模型同一份顆數
A15: u_ru_28 | B15: NVIDIA Rubin Ultra 顆數 2028 | C15: 百萬顆 | E15: 2 | G15: Derived | H15: markets/network/dist/20261026_AI網通市場模型_v0.2.3.xlsx｜In!E15 | I15: 唯讀上游；與 Ibiden、欣興、南電、台積電模型同一份顆數
A16: g29_ru | B16: NVIDIA Rubin Ultra 2029 顆數成長 | C16: % | E16: 0.15 | G16: Derived | H16: markets/network/dist/20261026_AI網通市場模型_v0.2.3.xlsx｜In!E16 | I16: 同上
... A50: um29_C | B50: 情境 C：2029 顆數 ÷ 基準 | C50: x | E50: 0.6 | G50: Assumed | H50: tsmc/dist/20261028_台積電個股模型_v0.4.xlsx｜In!E42 | I50: 同上
A51: B. 每顆加速器載板金額與份額（口徑與 Ibiden、欣興、南電一致；三者數字唯讀取自各自 dist）
A52: v26 | B52: FY2026 每顆 NVIDIA 加速器載板金額（全市場；Ibiden 模型校準） | C52: US$ | E52: 215.3086 | G52: Derived | H52: ibiden/dist/20261025_Ibiden模型_v0.2.1.xlsx｜Units!C8 | I52: Ibiden 模型：Ibiden 每顆營收 ÷ 份額 70%（BofA，Interested-party）
A53: g_asp | B53: 每顆載板金額年增（面積、層數；Ibiden 模型） | C53: % | D53: 0.1 | E53: 0.18 | F53: 0.22 | G53: Analogy | H53: ibiden/dist/20261025_Ibiden模型_v0.2.1.xlsx｜In!E50 | I53: Ibiden 路線圖 2026 年 90×90 mm → 2028 年 110×110 mm（經 Ibiden 模型）
A54: ibpp_27 | B54: ABF 價格溢價指數 2027（FY2026＝1；Ibiden 模型） | C54: x | D54: 0.95 | E54: 1 | F54: 1.05 | G54: Assumed | H54: ibiden/dist/20261025_Ibiden模型_v0.2.1.xlsx｜In!E55 | I54: 全市場短缺溢價；新產能到位後回落（Ibiden 模型；欣興、南電模型同值）
A55: ibrel_27 | B55: Ibiden NVIDIA 份額 2027 ÷ 2026（Ibiden 模型） | C55: x | E55: 0.95 | G55: Assumed | H55: ibiden/dist/20261025_Ibiden模型_v0.2.1.xlsx｜In!E51 | I55: Units 頁份額合計檢查用
A56: ibpp_28 | B56: ABF 價格溢價指數 2028（FY2026＝1；Ibiden 模型） | C56: x | D56: 0.85 | E56: 0.95 | F56: 1.05 | G56: Assumed | H56: ibiden/dist/20261025_Ibiden模型_v0.2.1.xlsx｜In!E56 | I56: 同上
A57: ibrel_28 | B57: Ibiden NVIDIA 份額 2028 ÷ 2026（Ibiden 模型） | C57: x | E57: 0.88 | G57: Assumed | H57: ibiden/dist/20261025_Ibiden模型_v0.2.1.xlsx｜In!E52 | I57: Units 頁份額合計檢查用
A58: ibpp_29 | B58: ABF 價格溢價指數 2029（FY2026＝1；Ibiden 模型） | C58: x | D58: 0.75 | E58: 0.9 | F58: 1 | G58: Assumed | H58: ibiden/dist/20261025_Ibiden模型_v0.2.1.xlsx｜In!E57 | I58: 同上
A59: ibrel_29 | B59: Ibiden NVIDIA 份額 2029 ÷ 2026（Ibiden 模型） | C59: x | E59: 0.85 | G59: Assumed | H59: ibiden/dist/20261025_Ibiden模型_v0.2.1.xlsx｜In!E53 | I59: Units 頁份額合計檢查用
A60: ib_sh26 | B60: Ibiden 占 NVIDIA 加速器載板 FY2026（Ibiden 模型假設） | C60: % | D60: 0.7 | E60: 0.7 | F60: 0.8 | G60: Interested-party | H60: ibiden/dist/20261025_Ibiden模型_v0.2.1.xlsx｜Units!C8（列標籤：假設 FY2026 份額 70%） | I60: BofA：Ibiden 70–80%
A61: ib_w_ot | B61: Ibiden 非 NVIDIA 權重（份額 × 每顆金額，相對 NVIDIA；Ibiden 模型） | C61: x | D61: 0.2 | E61: 0.4 | F61: 0.6 | G61: Assumed | H61: ibiden/dist/20261025_Ibiden模型_v0.2.1.xlsx｜In!E48 | I61: Units 頁：÷ v_ot 即 Ibiden 非 NVIDIA 份額
A62: v_ot | B62: 非 NVIDIA 加速器每顆載板金額 ÷ NVIDIA（欣興、南電模型同值） | C62: x | D62: 0.6 | E62: 0.8 | F62: 1 | G62: Assumed | H62: TPU、Trainium、MI 系列封裝面積接近 GPU；量化：未找到 | I62: 與欣興、南電模型 v_ot 相同
A63: un_nv_26 | B63: 欣興占 NVIDIA 加速器載板 2026（欣興模型） | C63: % | E63: 0.25 | G63: Assumed | H63: unimicron/dist/20261025_欣興模型_v0.1.1.xlsx｜In!E59 | I63: Units 頁份額合計檢查用
A64: un_ot_26 | B64: 欣興占非 NVIDIA 加速器載板（金額）2026（欣興模型） | C64: % | E64: 0.3 | G64: Assumed | H64: unimicron/dist/20261025_欣興模型_v0.1.1.xlsx｜In!E63 | I64: 同上
A65: np_nv_26 | B65: 南電占 NVIDIA 加速器載板 2026（南電模型） | C65: % | E65: 0.02 | G65: Assumed | H65: nanya_pcb/dist/20261025_南電模型_v0.1.1.xlsx｜In!E71 | I65: 同上
A66: np_ot_26 | B66: 南電占非 NVIDIA 加速器載板（金額）2026（南電模型） | C66: % | E66: 0.05 | G66: Assumed | H66: nanya_pcb/dist/20261025_南電模型_v0.1.1.xlsx｜In!E75 | I66: 同上
A67: un_nv_27 | B67: 欣興占 NVIDIA 加速器載板 2027（欣興模型） | C67: % | E67: 0.27 | G67: Assumed | H67: unimicron/dist/20261025_欣興模型_v0.1.1.xlsx｜In!E60 | I67: Units 頁份額合計檢查用
A68: un_ot_27 | B68: 欣興占非 NVIDIA 加速器載板（金額）2027（欣興模型） | C68: % | E68: 0.31 | G68: Assumed | H68: unimicron/dist/20261025_欣興模型_v0.1.1.xlsx｜In!E64 | I68: 同上
A69: np_nv_27 | B69: 南電占 NVIDIA 加速器載板 2027（南電模型） | C69: % | E69: 0.03 | G69: Assumed | H69: nanya_pcb/dist/20261025_南電模型_v0.1.1.xlsx｜In!E72 | I69: 同上
A70: np_ot_27 | B70: 南電占非 NVIDIA 加速器載板（金額）2027（南電模型） | C70: % | E70: 0.06 | G70: Assumed | H70: nanya_pcb/dist/20261025_南電模型_v0.1.1.xlsx｜In!E76 | I70: 同上
A71: un_nv_28 | B71: 欣興占 NVIDIA 加速器載板 2028（欣興模型） | C71: % | E71: 0.29 | G71: Assumed | H71: unimicron/dist/20261025_欣興模型_v0.1.1.xlsx｜In!E61 | I71: Units 頁份額合計檢查用
A72: un_ot_28 | B72: 欣興占非 NVIDIA 加速器載板（金額）2028（欣興模型） | C72: % | E72: 0.32 | G72: Assumed | H72: unimicron/dist/20261025_欣興模型_v0.1.1.xlsx｜In!E65 | I72: 同上
A73: np_nv_28 | B73: 南電占 NVIDIA 加速器載板 2028（南電模型） | C73: % | E73: 0.04 | G73: Assumed | H73: nanya_pcb/dist/20261025_南電模型_v0.1.1.xlsx｜In!E73 | I73: 同上
...

Sheet Q
A1: Q — FY2025 實績、1Q26／2Q26 實績、3Q26 營收實績與 FY2026 錨點（十億新台幣；EPS 新台幣、基本；股數十億股）。藍字＝輸入；黑字＝公式
A2: FY2026 錨點＝1Q、2Q26 財報實績＋3Q26 營收實績（月營收）與 3Q26 毛利率、費用假設＋4Q26 假設。3Q26 財報約 10 月底～11 月初公布（stockanalysis 估 2026-11-06），屆時以實績取代 E 欄（毛利率、費用、業外、淨利）
A3: 項目 | B3: FY2025A | C3: 1Q26（實績） | D3: 2Q26（實績） | E3: 3Q26（營收實績） | F3: 4Q26（模型） | G3: FY2026 錨點 | H3: 標記 | I3: 來源1（公司） | J3: 來源2／說明
A4: 營收 | B4: 39.351 | C4: 11.105 | D4: 12.496 | E4: =q3_rev -> 14.54 | F4: =E4*(1+q4_g) -> 16.2848 | G4: =SUM(C4:F4) -> 54.4258 | H4: Verified／Assumed（4Q） | I4: stockanalysis 年度與季損益表（公司財報轉載） | J4: FY2025 393.51 億（nstock 同）；1Q26 111.05 億（brodog 同）；1H26＝前 9 月 381.41 − 3Q（TechNews）
A5: 毛利 | B5: 8.314 | C5: 2.349 | D5: 3.261 | E5: =E4*q3_gm -> 4.5074 | F5: =F4*q4_gm -> 5.211136 | G5: =SUM(C5:F5) -> 15.328536 | H5: Verified／Assumed | I5: stockanalysis 年度與季損益表（公司財報轉載） | J5: 2Q26 毛利率 26.09%（nstock 同；經濟日報 26.1%）
A6: 毛利率 | B6: =B5/B4 -> 0.21127799 | C6: =C5/C4 -> 0.21152634 | D6: =D5/D4 -> 0.26096351 | E6: =E5/E4 -> 0.31 | F6: =F5/F4 -> 0.32 | G6: =G5/G4 -> 0.28164099 | H6: Derived | I6: — | J6: FY2025 21.1%（brodog 同）
A7: 營業費用 | B7: =B5-B8 -> 5.644 | C7: =C5-C8 -> 1.45836 | D7: =D5-D8 -> 1.582 | E7: =q3_opx -> 1.7 | F7: =q4_opx -> 1.8 | G7: =SUM(C7:F7) -> 6.54036 | H7: Derived／Assumed | I7: 毛利 − 營業利益 | J7: —
A8: 營業利益 | B8: 2.67 | C8: 0.89064 | D8: 1.679 | E8: =E5-E7 -> 2.8074 | F8: =F5-F7 -> 3.411136 | G8: =SUM(C8:F8) -> 8.788176 | H8: Verified／Derived | I8: stockanalysis 年度與季損益表（公司財報轉載） | J8: 2Q26 營業利益率 13.43%（nstock 同）
A9: 營業外淨額 | B9: =B10-B8 -> 0.417 | C9: =C10-C8 -> 0.07382 | D9: =D10-D8 -> 0.105 | E9: =q_nonop -> 0.1 | F9: =q_nonop -> 0.1 | G9: =SUM(C9:F9) -> 0.37882 | H9: Derived／Assumed | I9: 稅前利益 − 營業利益 | J9: —
A10: 稅前利益 | B10: 3.087 | C10: 0.96446 | D10: 1.784 | E10: =E8+E9 -> 2.9074 | F10: =F8+F9 -> 3.511136 | G10: =SUM(C10:F10) -> 9.166996 | H10: Verified／Derived | I10: stockanalysis 年度與季損益表（公司財報轉載） | J10: —
A11: 所得稅 | B11: 0.36988 | C11: 0.08866 | D11: 0.10087 | E11: =E10*q_tax -> 0.261666 | F11: =F10*q_tax -> 0.31600224 | G11: =SUM(C11:F11) -> 0.76719824 | H11: Verified／Assumed | I11: stockanalysis 年度與季損益表（公司財報轉載） | J11: —
A12: 合併淨利（含非控制權益） | B12: =B10-B11 -> 2.71712 | C12: =C10-C11 -> 0.8758 | D12: =D10-D11 -> 1.68313 | E12: =E10-E11 -> 2.645734 | F12: =F10-F11 -> 3.1951338 | G12: =SUM(C12:F12) -> 8.3997978 | H12: Derived | I12: 稅前 − 所得稅 | J12: stockanalysis：FY2025 27.17、1Q26 8.76、2Q26 16.83 億
A13: 非控制權益（主要為晶碩） | B13: =B12-B14 -> 1.12112 | C13: =C12-C14 -> 0.32657 | D13: =D12-D14 -> 0.37213 | E13: =E19*nm_lens*nci_sh -> 0.37844727 | F13: =F19*nm_lens*nci_sh -> 0.36124512 | G13: =SUM(C13:F13) -> 1.4383924 | H13: Derived | I13: 合併淨利 − 歸屬母公司淨利；3Q、4Q26＝晶碩營收 × 晶碩淨利率 × 非控制比例 | J13: stockanalysis：FY2025 11.21、1Q26 3.27、2Q26 3.73 億
A14: 歸屬母公司淨利 | B14: 1.596 | C14: 0.54923 | D14: 1.311 | E14: =E12-E13 -> 2.2672867 | F14: =F12-F13 -> 2.8338886 | G14: =SUM(C14:F14) -> 6.9614054 | H14: Verified／Derived | I14: stockanalysis 年度與季損益表（公司財報轉載） | J14: 旺得富 2026-10-14（永豐、玉山投顧；8 月自結、4Q26 預估）：8 月自結 EPS 1.55
A15: 加權股數（十億股） | B15: =B14/B16 -> 0.45470085 | C15: =C14/C16 -> 0.46942735 | D15: =D14/D16 -> 0.51011673 | E15: =q_sh -> 0.52691 | F15: =q_sh -> 0.52691 | G15: =AVERAGE(C15:F15) -> 0.50834102 | H15: Derived | I15: 淨利 ÷ EPS | J15: 2026 年初現增 7,000 萬股（每股 145 元）
A16: EPS（基本） | B16: 3.51 | C16: 1.17 | D16: 2.57 | E16: =E14/E15 -> 4.3029867 | F16: =F14/F15 -> 5.3783163 | G16: =G14/G15 -> 13.694361 | H16: Verified／Derived | I16: stockanalysis 年度與季損益表（公司財報轉載） | J16: FY2025 3.51（wantgoo 同）；1H26 3.74（nstock、經濟日報同）
A17: 折舊攤提（年度） | B17: =1.709+1.772+1.787+1.89 -> 7.158 | G17: =da26 -> 8.32 | H17: Verified／Derived | I17: stockanalysis 季現金流量表（四季加總） | J17: EBITDA 口徑 71.08 億
A18: 資本支出（年度） | B18: =2.368+1.277+1.08+1.391 -> 6.116 | G18: =capex26 -> 11 | H18: Verified／Assumed | I18: FY2025：stockanalysis 季現金流量表（四季加總）；FY2026：In 頁 capex26 | J18: —
A19: 晶碩營收（合併於景碩） | B19: 7.039 | C19: 1.886 | D19: 2.115 | E19: =q3_lens -> 2.2 | F19: =q4_lens -> 2.1 | G19: =SUM(C19:F19) -> 8.301 | H19: Verified／Assumed | I19: stockanalysis 晶碩（6491）季損益表 | J19: FY2025 70.39 億（優分析同）
A21: FY2026 產品別（錨點營收 × In 頁 C 節占比；晶碩取實績＋假設）
A22: ABF 載板 | G22: =G4*mx_abf -> 22.858836 | H22: Derived
A23: BT 與其他載板（含類載板） | G23: =G4-G22-G24 -> 23.265964 | H23: Derived
A24: 晶碩（隱形眼鏡） | G24: =G19 -> 8.301 | H24: Derived
A26: 檢查（參考；校準未使用券商數字）
A27: 1H26 營收 自算 − （前 9 月累計 38.141 − 3Q26）（應為 0） | B27: =C4+D4-(38.141-q3_rev) -> 0
A28: FY2026 營收年增 | B28: =G4/B4-1 -> 0.38308556
A29: FY2026 歸屬母公司淨利 ÷ 合併淨利 | B29: =G14/G12 -> 0.82875869
A30: FY2026 EPS ÷ 永豐 13.21 − 1 | B30: =G16/13.21-1 -> 0.036666227
A31: 3Q26 EPS ÷ 永豐估 4.29 − 1 | B31: =E16/4.29-1 -> 0.0030272078
A32: 4Q26 EPS ÷ 永豐估 5.39 − 1 | B32: =F16/5.39-1 -> -0.0021676623
A33: 4Q26 營收年化 ÷ FY2026 營收（漲價年度化 carry 的對照） | B33: =F4*4/G4 -> 1.1968441

Sheet Units
A1: Units — 景碩在 AI 加速器與 NVIDIA CPU 載板的份額與每顆金額（口徑與 Ibiden、欣興、南電模型一致；情境 A）。份額合計＝Ibiden（ibiden/dist）＋欣興（unimicron/dist）＋南電（nanya_pcb/dist）＋景碩，其餘為三星電機、AT&S 等
A3: 項目 | B3: 單位 | C3: CY2026 | D3: CY2027 | E3: CY2028 | F3: CY2029 | G3: 說明
A4: NVIDIA 加速器顆數 | B4: 百萬顆 | C4: =PL!D63 -> 7.6 | D4: =PL!E63 -> 9.7 | E4: =PL!F63 -> 9.5 | F4: =PL!G63 -> 10.6 | G4: markets/network
A5: 非 NVIDIA 加速器顆數 | B5: 百萬顆 | C5: =PL!D64 -> 7.6 | D5: =PL!E64 -> 14 | E5: =PL!F64 -> 17 | F5: =PL!G64 -> 19.55
A6: NVIDIA CPU（Grace／Vera）顆數 | B6: 百萬顆 | C6: =PL!D65 -> 3.04 | D6: =PL!E65 -> 3.88 | E6: =PL!F65 -> 3.8 | F6: =PL!G65 -> 4.24 | G6: NVIDIA 加速器 × cpu_r（Analogy）
A7: 每顆 NVIDIA 加速器載板金額（全市場） | B7: US$ | C7: =PL!D69 -> 215.3086 | D7: =PL!E69 -> 254.06414 | E7: =PL!F69 -> 284.8059 | F7: =PL!G69 -> 318.38302 | G7: Ibiden 模型 Units 頁同值（FY2026 校準 × 面積層數 × 溢價）
A8: 景碩份額：NVIDIA（GPU） | B8: % | C8: =PL!D70 -> 0.02 | D8: =PL!E70 -> 0.03 | E8: =PL!F70 -> 0.05 | F8: =PL!G70 -> 0.06 | G8: Assumed（券商稱 Rubin 15–20%，與上游合計衝突）
A9: Ibiden 份額：NVIDIA（70% × Ibiden 份額相對值） | B9: % | C9: =ib_sh26*1 -> 0.7 | D9: =ib_sh26*ibrel_27 -> 0.665 | E9: =ib_sh26*ibrel_28 -> 0.616 | F9: =ib_sh26*ibrel_29 -> 0.595 | G9: Ibiden 模型
A10: 欣興份額：NVIDIA | B10: % | C10: =un_nv_26 -> 0.25 | D10: =un_nv_27 -> 0.27 | E10: =un_nv_28 -> 0.29 | F10: =un_nv_29 -> 0.3 | G10: 欣興模型
A11: 南電份額：NVIDIA | B11: % | C11: =np_nv_26 -> 0.02 | D11: =np_nv_27 -> 0.03 | E11: =np_nv_28 -> 0.04 | F11: =np_nv_29 -> 0.04 | G11: 南電模型
A12: 合計：Ibiden＋欣興＋南電＋景碩（NVIDIA） | B12: % | C12: =C8+C9+C10+C11 -> 0.99 | D12: =D8+D9+D10+D11 -> 0.995 | E12: =E8+E9+E10+E11 -> 0.996 | F12: =F8+F9+F10+F11 -> 0.995 | G12: 應 ≤ 100%；其餘為三星電機等
A13: 景碩份額：非 NVIDIA（金額） | B13: % | C13: =PL!D71 -> 0.03 | D13: =PL!E71 -> 0.05 | E13: =PL!F71 -> 0.06 | F13: =PL!G71 -> 0.06 | G13: Assumed
A14: Ibiden 份額：非 NVIDIA（Ibiden 權重 × 份額相對值 ÷ v_ot） | B14: % | C14: =ib_w_ot*1/v_ot -> 0.5 | D14: =ib_w_ot*ibrel_27/v_ot -> 0.475 | E14: =ib_w_ot*ibrel_28/v_ot -> 0.44 | F14: =ib_w_ot*ibrel_29/v_ot -> 0.425 | G14: 與欣興、南電模型同算法
A15: 欣興份額：非 NVIDIA（金額） | B15: % | C15: =un_ot_26 -> 0.3 | D15: =un_ot_27 -> 0.31 | E15: =un_ot_28 -> 0.32 | F15: =un_ot_29 -> 0.33 | G15: 欣興模型
A16: 南電份額：非 NVIDIA（金額） | B16: % | C16: =np_ot_26 -> 0.05 | D16: =np_ot_27 -> 0.06 | E16: =np_ot_28 -> 0.07 | F16: =np_ot_29 -> 0.07 | G16: 南電模型
A17: 合計：Ibiden＋欣興＋南電＋景碩（非 NVIDIA） | B17: % | C17: =C13+C14+C15+C16 -> 0.88 | D17: =D13+D14+D15+D16 -> 0.895 | E17: =E13+E14+E15+E16 -> 0.89 | F17: =F13+F14+F15+F16 -> 0.885 | G17: 應 ≤ 100%；其餘為三星電機、AT&S
A18: 景碩份額：NVIDIA CPU（Grace／Vera） | B18: % | C18: =PL!D72 -> 0.35 | D18: =PL!E72 -> 0.7 | E18: =PL!F72 -> 0.75 | F18: =PL!G72 -> 0.7 | G18: 公司與券商說法（Interested-party）；其餘主要為 Ibiden
A19: 每顆 NVIDIA 加速器的景碩營收（GPU＋CPU 載板） | B19: US$ | C19: =PL!D69*(PL!D70+cpu_r*v_cpu*PL!D72)*PL!D68 -> 13.349133 | D19: =PL!E69*(PL!E70+cpu_r*v_cpu*PL!E72)*PL!E68 -> 33.307809 | E19: =PL!F69*(PL!F70+cpu_r*v_cpu*PL!F72)*PL!F68 -> 45.853751 | F19: =PL!G69*(PL!G70+cpu_r*v_cpu*PL!G72)*PL!G68 -> 52.724228 | G19: Ibiden、欣興、南電對照值見各自 dist Units 頁
A20: 景碩加速器與 CPU 載板營收 | B20: US$M | C20: =PL!D73 -> 140.7257 | D20: =PL!E73 -> 486.70306 | E20: =PL!F73 -> 702.87249 | F20: =PL!G73 -> 902.46304
A21: 景碩 AI 載板營收（含網通 ASIC 等其他 AI） | B21: NT$B | C21: =PL!D83 -> 5.714709 | D21: =PL!E83 -> 15.167099 | E21: =PL!F83 -> 21.780506 | F21: =PL!G83 -> 28.920161
A22: 景碩 AI 載板營收 ÷ AI IT 資本支出 | B22: % | C22: =PL!D83/fx/itc_26 -> 0.0002248923 | D22: =PL!E83/fx/itc_27 -> 0.00029813138 | E22: =PL!F83/fx/itc_28 -> 0.00033774208 | F22: =PL!G83/fx/itc_29 -> 0.00039367144 | G22: × 每 GW IT capex 即每 GW 營收
A23: 每 GW 景碩 AI 載板營收（VR200 每 GW IT capex 37.59B） | B23: US$M | C23: =PL!D83/fx/itc_26*37.59*1000 -> 8.4537016 | D23: =PL!E83/fx/itc_27*37.59*1000 -> 11.206759 | E23: =PL!F83/fx/itc_28*37.59*1000 -> 12.695725 | F23: =PL!G83/fx/itc_29*37.59*1000 -> 14.798109 | G23: Tokenomics IF_CapexIT（VR200 基準，經橋接表；與 Ibiden、欣興、南電模型相同係數）
A25: 讀法：景碩的 AI 曝險以 NVIDIA CPU（Grace→Vera）載板為主，GPU 與 ASIC 加速器載板份額小；券商稱 Rubin GPU 份額 15–20%，但 Ibiden、欣興、南電模型的份額已合計 94–97%，本模型取剩餘空間，兩者不能同時成立（見 README）。

Sheet PL
A1: PL — 景碩損益（十億新台幣；EPS 新台幣、基本；歸屬母公司）。FY2025A 實績、FY2026 錨點（1H26 實績＋3Q26 營收實績＋假設；三情境相同），FY2027–FY2029 由驅動因子推導，FY2030 起為收斂法。三情境各一個完整推導區塊（本頁下方），頂端為摘要
A2: 灰底＝FY2030–FY2032 收斂法（上游顆數只到 2029）：營收年增線性收斂到 fade_g、淨利率線性收斂到 fade_m（In 頁 I 節），非驅動因子推導
A3: 情境／項目 | B3: 單位 | C3: FY2025A | D3: FY2026（錨點） | E3: FY2027 | F3: FY2028 | G3: FY2029 | H3: FY2030（收斂） | I3: FY2031（收斂） | J3: FY2032（收斂） | K3: 說明
A4: 情境 A
A5: 營收 | B5: NT$B | C5: =C88 -> 39.351 | D5: =D88 -> 54.4258 | E5: =E88 -> 72.033987 | F5: =F88 -> 84.102246 | G5: =G88 -> 96.11307 | H5: =H88 -> 107.18608 | I5: =I88 -> 116.57601 | J5: =J88 -> 123.57057
A6: 營收年增 | B6: % | D6: =D89 -> 0.38308556 | E6: =E89 -> 0.32352648 | F6: =F89 -> 0.16753562 | G6: =G89 -> 0.14281216 | H6: =H89 -> 0.11520811 | I6: =I89 -> 0.087604055 | J6: =J89 -> 0.06
A7: ABF 載板 | B7: NT$B | D7: =D81 -> 22.858836 | E7: =E81 -> 33.122453 | F7: =F81 -> 41.299559 | G7: =G81 -> 50.668038
A8: AI 載板 | B8: NT$B | D8: =D83 -> 5.714709 | E8: =E83 -> 15.167099 | F8: =F83 -> 21.780506 | G8: =G83 -> 28.920161
A9: ABF 需求滿足率 | B9: % | D9: =D82 -> 1 | E9: =E82 -> 0.85916169 | F9: =F82 -> 0.88111743 | G9: =G82 -> 0.9261601
A10: 毛利率 | B10: % | C10: =C98 -> 0.21127799 | D10: =D98 -> 0.28164099 | E10: =E98 -> 0.35525676 | F10: =F98 -> 0.36172503 | G10: =G98 -> 0.36644065
A11: 折舊攤提 | B11: NT$B | C11: =C94 -> 7.158 | D11: =D94 -> 8.32 | E11: =E94 -> 8.655 | F11: =F94 -> 9.698125 | G11: =G94 -> 10.485859 | H11: =H94 -> 11.693915 | I11: =I94 -> 12.71835 | J11: =J94 -> 13.481451
A12: 營業利益率 | B12: % | C12: =C101 -> 0.067850881 | D12: =D101 -> 0.16147077 | E12: =E101 -> 0.24683645 | F12: =F101 -> 0.25952783 | G12: =G101 -> 0.2693519
A13: 歸屬母公司淨利 | B13: NT$B | C13: =C107 -> 1.596 | D13: =D107 -> 6.9614054 | E13: =E107 -> 14.428194 | F13: =F107 -> 17.831829 | G13: =G107 -> 21.233048 | H13: =H107 -> 23.679267 | I13: =I107 -> 25.753667 | J13: =J107 -> 27.298887
A14: 淨利率 | B14: % | C14: =C111 -> 0.040558054 | D14: =D111 -> 0.12790635 | E14: =E111 -> 0.20029704 | F14: =F111 -> 0.21202559 | G14: =G111 -> 0.22091738 | H14: =H111 -> 0.22091738 | I14: =I111 -> 0.22091738 | J14: =J111 -> 0.22091738
A15: EPS | B15: NT$ | C15: =C109 -> 3.51 | D15: =D109 -> 13.694361 | E15: =E109 -> 27.382654 | F15: =F109 -> 33.842266 | G15: =G109 -> 40.297295 | H15: =H109 -> 44.93987 | I15: =I109 -> 48.876785 | J15: =J109 -> 51.809392
A16: EPS 年增 | B16: % | D16: =D110 -> 2.9015273 | E16: =E110 -> 0.99955694 | F16: =F110 -> 0.2359016 | G16: =G110 -> 0.19073867 | H16: =H110 -> 0.11520811 | I16: =I110 -> 0.087604055 | J16: =J110 -> 0.06
A18: 情境 B
A19: 營收 | B19: NT$B | C19: =C145 -> 39.351 | D19: =D145 -> 54.4258 | E19: =E145 -> 70.17271 | F19: =F145 -> 80.658884 | G19: =G145 -> 91.266963 | H19: =H145 -> 100.48601 | I19: =I145 -> 107.57087 | J19: =J145 -> 111.8737
A20: 營收年增 | B20: % | D20: =D146 -> 0.38308556 | E20: =E146 -> 0.28932804 | F20: =F146 -> 0.14943378 | G20: =G146 -> 0.1315178 | H20: =H146 -> 0.10101187 | I20: =I146 -> 0.070505934 | J20: =J146 -> 0.04
A21: ABF 載板 | B21: NT$B | D21: =D138 -> 22.858836 | E21: =E138 -> 33.122453 | F21: =F138 -> 41.299559 | G21: =G138 -> 50.023764
A22: AI 載板 | B22: NT$B | D22: =D140 -> 5.714709 | E22: =E140 -> 15.167099 | F22: =F140 -> 19.478963 | G22: =G140 -> 26.541995
A23: ABF 需求滿足率 | B23: % | D23: =D139 -> 1 | E23: =E139 -> 0.85916169 | F23: =F139 -> 0.98501233 | G23: =G139 -> 1
A24: 毛利率 | B24: % | C24: =C155 -> 0.21127799 | D24: =D155 -> 0.28164099 | E24: =E155 -> 0.35274377 | F24: =F155 -> 0.35860949 | G24: =G155 -> 0.36244927
A25: 折舊攤提 | B25: NT$B | C25: =C151 -> 7.158 | D25: =D151 -> 8.32 | E25: =E151 -> 8.655 | F25: =F151 -> 9.698125 | G25: =G151 -> 10.485859 | H25: =H151 -> 11.545056 | I25: =I151 -> 12.359051 | J25: =J151 -> 12.853413
A26: 營業利益率 | B26: % | C26: =C158 -> 0.067850881 | D26: =D158 -> 0.16147077 | E26: =E158 -> 0.24336014 | F26: =F158 -> 0.25491409 | G26: =G158 -> 0.26357493
A27: 歸屬母公司淨利 | B27: NT$B | C27: =C164 -> 1.596 | D27: =D164 -> 6.9614054 | E27: =E164 -> 13.809226 | F27: =F164 -> 16.717936 | G27: =G164 -> 19.620399 | H27: =H164 -> 20.882216 | I27: =I164 -> 21.58369 | J27: =J164 -> 21.645358
A28: 淨利率 | B28: % | C28: =C168 -> 0.040558054 | D28: =D168 -> 0.12790635 | E28: =E168 -> 0.19678913 | F28: =F168 -> 0.20726714 | G28: =G168 -> 0.21497811 | H28: =H168 -> 0.20781217 | I28: =I168 -> 0.20064624 | J28: =J168 -> 0.1934803
A29: EPS | B29: NT$ | C29: =C166 -> 3.51 | D29: =D166 -> 13.694361 | E29: =E166 -> 26.207941 | F29: =F166 -> 31.728257 | G29: =G166 -> 37.236718 | H29: =H166 -> 39.631467 | I29: =I166 -> 40.962764 | J29: =J166 -> 41.079801
A30: EPS 年增 | B30: % | D30: =D167 -> 2.9015273 | E30: =E167 -> 0.91377617 | F30: =F167 -> 0.21063523 | G30: =G167 -> 0.17361373 | H30: =H167 -> 0.064311473 | I30: =I167 -> 0.033591937 | J30: =J167 -> 0.0028571429
A32: 情境 C
A33: 營收 | B33: NT$B | C33: =C202 -> 39.351 | D33: =D202 -> 54.4258 | E33: =E202 -> 68.311433 | F33: =F202 -> 73.086214 | G33: =G202 -> 78.542069 | H33: =H202 -> 82.974438 | I33: =I202 -> 86.145433 | J33: =J202 -> 87.868341
A34: 營收年增 | B34: % | D34: =D203 -> 0.38308556 | E34: =E203 -> 0.25512961 | F34: =F203 -> 0.069897243 | G34: =G203 -> 0.074649579 | H34: =H203 -> 0.056433053 | I34: =I203 -> 0.038216526 | J34: =J203 -> 0.02
A35: ABF 載板 | B35: NT$B | D35: =D195 -> 22.858836 | E35: =E195 -> 33.122453 | F35: =F195 -> 36.984124 | G35: =G195 -> 42.217295
A36: AI 載板 | B36: NT$B | D36: =D197 -> 5.714709 | E36: =E197 -> 15.167099 | F36: =F197 -> 14.831512 | G36: =G197 -> 18.735526
A37: ABF 需求滿足率 | B37: % | D37: =D196 -> 1 | E37: =E196 -> 0.85916169 | F37: =F196 -> 1 | G37: =G196 -> 1
A38: 毛利率 | B38: % | C38: =C212 -> 0.21127799 | D38: =D212 -> 0.28164099 | E38: =E212 -> 0.35009384 | F38: =F212 -> 0.34379228 | G38: =G212 -> 0.34161469
A39: 折舊攤提 | B39: NT$B | C39: =C208 -> 7.158 | D39: =D208 -> 8.32 | E39: =E208 -> 8.655 | F39: =F208 -> 9.698125 | G39: =G208 -> 10.485859 | H39: =H208 -> 11.077608 | I39: =I208 -> 11.500956 | J39: =J208 -> 11.730975
A40: 營業利益率 | B40: % | C40: =C215 -> 0.067850881 | D40: =D215 -> 0.16147077 | E40: =E215 -> 0.2396944 | F40: =F215 -> 0.23627783 | G40: =G215 -> 0.23708761
A41: 歸屬母公司淨利 | B41: NT$B | C41: =C221 -> 1.596 | D41: =D221 -> 6.9614054 | E41: =E221 -> 13.190259 | F41: =F221 -> 13.820594 | G41: =G221 -> 14.838187 | H41: =H221 -> 14.630515 | I41: =I221 -> 14.104668 | J41: =J221 -> 13.280087
A42: 淨利率 | B42: % | C42: =C225 -> 0.040558054 | D42: =D225 -> 0.12790635 | E42: =E225 -> 0.19309006 | F42: =F225 -> 0.18909988 | G42: =G225 -> 0.18892025 | H42: =H225 -> 0.17632556 | I42: =I225 -> 0.16373088 | J42: =J225 -> 0.1511362
...

Sheet Val
A1: Val — P/E 估值（新台幣）。結論用「現價 ÷ FY2027、FY2028 EPS（模型）」；目標價＝DCF 與 Comparable 加權（第 0 節）；十年 P/E 規則值（第 3 節，年底落後 P/E）只作參考
A2: 循環位置：景碩不是設備股，不套設備市場見頂年；以本模型營收最高的會計年度為見頂年（比照 Ibiden、欣興、南電；FY(t)＝CY(t)）。營收到 FY2029 仍在增加時，見頂年未知，判為中段
A4: 0. 目標價
A5: 0.1 DCF（股東權益現金流，FY2027–FY2032 明確期＋FY2032 後永續）
A6: 項目 | B6: A（順利） | C6: B（平平） | D6: C（不如預期） | E6: 說明
A7: 情境 EPS（FY2027–FY2032） | E7: PL 頁各情境；FY2030 起為收斂法
A8: FY2027 | B8: =PL!E15 -> 27.382654 | C8: =PL!E29 -> 26.207941 | D8: =PL!E43 -> 25.033229
A9: FY2028 | B9: =PL!F15 -> 33.842266 | C9: =PL!F29 -> 31.728257 | D9: =PL!F43 -> 26.229516
A10: FY2029 | B10: =PL!G15 -> 40.297295 | C10: =PL!G29 -> 37.236718 | D10: =PL!G43 -> 28.160762
A11: FY2030 | B11: =PL!H15 -> 44.93987 | C11: =PL!H29 -> 39.631467 | D11: =PL!H43 -> 27.766629
A12: FY2031 | B12: =PL!I15 -> 48.876785 | C12: =PL!I29 -> 40.962764 | D12: =PL!I43 -> 26.768646
A13: FY2032 | B13: =PL!J15 -> 51.809392 | C13: =PL!J29 -> 41.079801 | D13: =PL!J43 -> 25.20371
A14: 股東現金流＝EPS ×（1 − tp_g ÷ tp_roe） | E14: 方法：景碩資本密集且模型有資本支出與折舊，改用每股（淨利＋折舊－資本支出）（PL 頁「每股股東現金流」；FY2030 起資本支出率收斂到穩態更新）
A15: 參考：再投資率（tp_g ÷ tp_roe，上限 0.8） | B15: =MIN(tp_g/tp_roe,0.8) -> 0.8 | E15: ROE 為近三年平均（In 頁 tp_roe）；本模型不採用，只作對照（第 25 列）
A16: FY2027 | B16: =PL!E114 -> 11.545035 | C16: =PL!E171 -> 10.370322 | D16: =PL!E228 -> 9.1956093
A17: FY2028 | B17: =PL!F114 -> 21.882207 | C17: =PL!F171 -> 19.768198 | D17: =PL!F228 -> 14.269456
A18: FY2029 | B18: =PL!G114 -> 37.423672 | C18: =PL!G171 -> 34.363095 | D18: =PL!G228 -> 25.287139
A19: FY2030 | B19: =PL!H114 -> 41.546833 | C19: =PL!H171 -> 36.281622 | D19: =PL!H228 -> 24.552416
A20: FY2031 | B20: =PL!I114 -> 44.981655 | C20: =PL!I171 -> 37.177673 | D20: =PL!I228 -> 23.246356
A21: FY2032 | B21: =PL!J114 -> 47.463413 | C21: =PL!J171 -> 36.936281 | D21: =PL!J228 -> 21.422027
A22: DCF 情境每股價值（折現率 tp_r） | B22: =MAX(0,SUMPRODUCT(B16:B21,1/(1+tp_r)^{1;2;3;4;5;6})+B21*(1+tp_g)/(tp_r-tp_g)/(1+tp_r)^6) -> 604.18812 | C22: =MAX(0,SUMPRODUCT(C16:C21,1/(1+tp_r)^{1;2;3;4;5;6})+C21*(1+tp_g)/(tp_r-tp_g)/(1+tp_r)^6) -> 481.68974 | D22: =MAX(0,SUMPRODUCT(D16:D21,1/(1+tp_r)^{1;2;3;4;5;6})+D21*(1+tp_g)/(tp_r-tp_g)/(1+tp_r)^6) -> 292.04487 | E22: Σ 明確期現金流 ÷ (1＋r)^t ＋ 永續價值 ÷ (1＋r)^6；永續價值＝FY2032 現金流 ×(1＋g)÷(r−g)；基準日 2026 年底；< 0 時取 0（股東有限責任）
A23: DCF 情境價值推到 12 個月後（×(1＋tp_r)） | B23: =B22*(1+tp_r) -> 664.60693 | C23: =C22*(1+tp_r) -> 529.85871 | D23: =D22*(1+tp_r) -> 321.24935
A24: DCF 目標價（情境加權） | B24: =tp_wA*B23+tp_wB*C23+tp_wC*D23 -> 528.56131 | E24: Σ 權重 × 情境價值 ×(1＋r)；權重見 In 頁
A25: 參考：EPS ×（1 − g／ROE）法的 DCF 目標價（情境加權） | B25: =(tp_wA*MAX(0,SUMPRODUCT(B8:B13,1/(1+tp_r)^{1;2;3;4;5;6})+B13*(1+tp_g)/(tp_r-tp_g)/(1+tp_r)^6)+tp_wB*MAX(0,SUMPRODUCT(C8:C13,1/(1+tp_r)^{1;2;3;4;5;6})+C13*(1+tp_g)/(tp_r-tp_g)/(1+tp_r)^6)+tp_wC*MAX(0,SUMPRODUCT(D8:D13,1/(1+tp_r)^{1;2;3;4;5;6})+D13*(1+tp_g)/(tp_r-tp_g)/(1+tp_r)^6))*(1-B15)*(1+tp_r) -> 121.95205 | E25: 近三年 ROE 約 4%（遠低於 g 的 4% 所需）→ 再投資率上限 80%；不進目標價
A26: 0.2 Comparable（市場主流同業前瞻 P/E）
A27: 同業與前瞻 P/E | B27: 代號 | C27: 前瞻 12 月 P/E | D27: 日期 | E27: 來源 | F27: 標記
A28: 欣興（Unimicron） | B28: 3037.TW | C28: 42.28 | D28: 2026-10-22 | E28: stockanalysis.com forward PE（分析師共識；價格日期如左；與欣興、南電、Ibiden 模型同一組數字） | F28: Interested-party
A29: 南電（Nan Ya PCB） | B29: 8046.TW | C29: 33.73 | D29: 2026-09-07 | E29: stockanalysis.com forward PE（分析師共識；價格日期如左；與欣興、南電、Ibiden 模型同一組數字） | F29: Interested-party
A30: Ibiden（揖斐電） | B30: 4062.T | C30: 53.97 | D30: 2026-10-16 | E30: stockanalysis.com forward PE（分析師共識；價格日期如左；與欣興、南電、Ibiden 模型同一組數字） | F30: Interested-party
A31: 三星電機（Samsung Electro-Mechanics） | B31: 009150.KS | C31: 43.4 | D31: 2026-08-28 | E31: stockanalysis.com forward PE（分析師共識；價格日期如左；與欣興、南電、Ibiden 模型同一組數字） | F31: Interested-party
A32: AT&S | B32: ATS.VI | C32: 14.91 | D32: 2026-10-23 | E32: stockanalysis.com forward PE（分析師共識；價格日期如左；與欣興、南電、Ibiden 模型同一組數字） | F32: Interested-party
A33: 同業前瞻 P/E 中位數 | B33: =MEDIAN(C28:C32) -> 42.28 | E33: ABF 載板同業：欣興、南電、Ibiden、三星電機、AT&S（無中國 A 股）；南電、三星電機價格日期較舊
A34: 12 個月後的前瞻 EPS（情境加權） | B34: =tp_wA*(2/12*B8+10/12*B9)+tp_wB*(2/12*C8+10/12*C9)+tp_wC*(2/12*D8+10/12*D9) -> 30.439829 | E34: 約 2027-10 時的未來 12 月 EPS ≈ 2／12 × FY2027＋10／12 × FY2028（會計年度＝日曆年）
A35: Comparable 目標價 | B35: =B33*B34 -> 1286.996 | E35: 同業中位數 × 前瞻 EPS
A37: 0.3 結論
A38: 項目 | B38: 數值 | E38: 說明
A39: 目標價（DCF 與 Comparable 加權） | B39: =tp_w_dcf*B24+(1-tp_w_dcf)*B35 -> 907.77863 | E39: tp_w_dcf × DCF＋（1 − tp_w_dcf）× Comparable；tp_w_dcf 見 In 頁（0.5）
A40: Comparable 目標價（市場主流同業法） | B40: =B35 -> 1286.996
A41: 市場共識目標價 | B41: =cons_tp -> 1092.15 | E41: stockanalysis：13 位分析師平均 1,092.15（頁面價格日期 2026-10-22）；10 月永豐 1,280、玉山 1,270
A42: 上檔空間：加權目標價 | B42: =B39/px-1 -> -0.079332021 | E42: 現價＝In 頁 px（2026-10-22 收盤）
...

Sheet Recon
A1: Recon — 本模型 vs 券商、共識與市場口徑。只作事後對照，不為對上數字而調參數。FactSet 共識為 2026-06（2Q26 財報前）；10 月券商數字取自媒體轉載（永豐、玉山、美系）
A3: 項目 | B3: 對照值 | C3: 模型 A | D3: 差距 A | E3: 模型 B | F3: 差距 B | G3: 模型 C | H3: 差距 C | I3: 對照來源 | J3: 說明
A4: A. EPS 與營收 vs 共識、券商
A5: FY2026 EPS vs 共識 10.42（主串補位排序表） | B5: =cons_eps26 -> 10.42 | C5: =PL!D109 -> 13.694361 | D5: =C5/B5-1 -> 0.31423809 | E5: =PL!D166 -> 13.694361 | F5: =E5/B5-1 -> 0.31423809 | G5: =PL!D223 -> 13.694361 | H5: =G5/B5-1 -> 0.31423809 | I5: 主串提供 | J5: 永豐 13.21、玉山 12.93、美系 10.6；FactSet 2026-06 平均 9.73
A6: FY2026 EPS vs 永豐 13.21（2026-10-14） | B6: 13.21 | C6: =PL!D109 -> 13.694361 | D6: =C6/B6-1 -> 0.036666227 | E6: =PL!D166 -> 13.694361 | F6: =E6/B6-1 -> 0.036666227 | G6: =PL!D223 -> 13.694361 | H6: =G6/B6-1 -> 0.036666227 | I6: 旺得富（永豐）
A7: FY2027 EPS vs 共識 26.47（主串補位排序表） | B7: =cons_eps27 -> 26.47 | C7: =PL!E109 -> 27.382654 | D7: =C7/B7-1 -> 0.034478818 | E7: =PL!E166 -> 26.207941 | F7: =E7/B7-1 -> -0.0099002085 | G7: =PL!E223 -> 25.033229 | H7: =G7/B7-1 -> -0.054279235 | I7: 主串提供
A8: FY2027 EPS vs 券商平均（永豐 36.03、玉山 42.41、美系 27.3） | B8: =bk_eps27 -> 35.246667 | C8: =PL!E109 -> 27.382654 | D8: =C8/B8-1 -> -0.22311365 | E8: =PL!E166 -> 26.207941 | F8: =E8/B8-1 -> -0.25644199 | G8: =PL!E223 -> 25.033229 | H8: =G8/B8-1 -> -0.28977032 | I8: 旺得富、經濟日報 | J8: 差距超過 30% 的原因見 README
A9: FY2027 EPS vs FactSet 平均 19.93（2026-06） | B9: =fs_eps27 -> 19.93 | C9: =PL!E109 -> 27.382654 | D9: =C9/B9-1 -> 0.37394151 | E9: =PL!E166 -> 26.207941 | F9: =E9/B9-1 -> 0.31499957 | G9: =PL!E223 -> 25.033229 | H9: =G9/B9-1 -> 0.25605763 | I9: 鉅亨（FactSet 13 位）
A10: FY2028 EPS vs FactSet 平均 34.39（2026-06） | B10: =fs_eps28 -> 34.39 | C10: =PL!F109 -> 33.842266 | D10: =C10/B10-1 -> -0.015927119 | E10: =PL!F166 -> 31.728257 | F10: =E10/B10-1 -> -0.077398743 | G10: =PL!F223 -> 26.229516 | H10: =G10/B10-1 -> -0.23729236 | I10: 鉅亨（FactSet）
A11: FY2028 EPS vs 券商平均（永豐 62.22、玉山 89.75、美系 51.5） | B11: =bk_eps28 -> 67.823333 | C11: =PL!F109 -> 33.842266 | D11: =C11/B11-1 -> -0.50102325 | E11: =PL!F166 -> 31.728257 | F11: =E11/B11-1 -> -0.5321926 | G11: =PL!F223 -> 26.229516 | H11: =G11/B11-1 -> -0.61326708 | I11: 旺得富、經濟日報
A12: FY2027 營收 vs FactSet 平均（2026-06） | B12: =fs_rev27 -> 70.348 | C12: =PL!E88 -> 72.033987 | D12: =C12/B12-1 -> 0.023966385 | E12: =PL!E145 -> 70.17271 | F12: =E12/B12-1 -> -0.0024917529 | G12: =PL!E202 -> 68.311433 | H12: =G12/B12-1 -> -0.028949891 | I12: 鉅亨（FactSet）
A13: FY2028 營收 vs FactSet 平均（2026-06） | B13: =fs_rev28 -> 93.549 | C13: =PL!F88 -> 84.102246 | D13: =C13/B13-1 -> -0.10098188 | E13: =PL!F145 -> 80.658884 | F13: =E13/B13-1 -> -0.13779 | G13: =PL!F202 -> 73.086214 | H13: =G13/B13-1 -> -0.21873869 | I13: 鉅亨（FactSet）
A14: 模型前瞻 12 月 EPS（0.2 × FY2026＋0.8 × FY2027）vs 頁面價格 ÷ 前瞻 P/E | B14: =cons_feps -> 22.058166 | C14: =0.2*PL!D109+0.8*PL!E109 -> 24.644996 | D14: =C14/B14-1 -> 0.11727313 | E14: =0.2*PL!D166+0.8*PL!E166 -> 23.705225 | F14: =E14/B14-1 -> 0.074668939 | G14: =0.2*PL!D223+0.8*PL!E223 -> 22.765455 | H14: =G14/B14-1 -> 0.032064749 | I14: stockanalysis（推導） | J14: 口徑不同，只作量級比較
A15: B. 錨點與毛利率
A16: 3Q26 毛利率（假設）vs 美系券商 27.8%（百分點） | B16: 0.278 | C16: =Q!E6 -> 0.31 | D16: =C16-B16 -> 0.032 | E16: =Q!E6 -> 0.31 | F16: =E16-B16 -> 0.032 | G16: =Q!E6 -> 0.31 | H16: =G16-B16 -> 0.032 | I16: 經濟日報 2026-10-12 | J16: 3Q26 財報約 10 月底～11 月初
A17: 3Q26 EPS（模型）vs 永豐估 4.29 | B17: 4.29 | C17: =Q!E16 -> 4.3029867 | D17: =C17/B17-1 -> 0.0030272078 | E17: =Q!E16 -> 4.3029867 | F17: =E17/B17-1 -> 0.0030272078 | G17: =Q!E16 -> 4.3029867 | H17: =G17/B17-1 -> 0.0030272078 | I17: 旺得富（永豐）
A18: 4Q26 營收（模型）vs 永豐估 173.14 億 | B18: 17.314 | C18: =Q!F4 -> 16.2848 | D18: =C18/B18-1 -> -0.059443225 | E18: =Q!F4 -> 16.2848 | F18: =E18/B18-1 -> -0.059443225 | G18: =Q!F4 -> 16.2848 | H18: =G18/B18-1 -> -0.059443225 | I18: 旺得富（永豐）
A19: 4Q26 毛利率（假設）vs 永豐估 33%（百分點） | B19: 0.33 | C19: =Q!F6 -> 0.32 | D19: =C19-B19 -> -0.01 | E19: =Q!F6 -> 0.32 | F19: =E19-B19 -> -0.01 | G19: =Q!F6 -> 0.32 | H19: =G19-B19 -> -0.01 | I19: 旺得富（永豐） | J19: 美系 29.3%
A20: FY2027 毛利率 vs 高盛「每年約 +5pt」推算（FY2026 錨點＋5pt） | B20: =Q!G6+0.05 -> 0.33164099 | C20: =PL!E98 -> 0.35525676 | D20: =C20-B20 -> 0.023615777 | E20: =PL!E155 -> 0.35274377 | F20: =E20-B20 -> 0.021102785 | G20: =PL!E212 -> 0.35009384 | H20: =G20-B20 -> 0.018452851 | I20: TechNews（高盛）
A21: FY2028 毛利率 vs 同上（FY2026 錨點＋10pt） | B21: =Q!G6+0.1 -> 0.38164099 | C21: =PL!F98 -> 0.36172503 | D21: =C21-B21 -> -0.019915954 | E21: =PL!F155 -> 0.35860949 | F21: =E21-B21 -> -0.023031493 | G21: =PL!F212 -> 0.34379228 | H21: =G21-B21 -> -0.037848709 | I21: TechNews（高盛）
A22: C. 產能、份額與 AI 口徑
A23: FY2027 ABF 需求滿足率（< 100%＝產能受限） | C23: =PL!E82 -> 0.85916169 | E23: =PL!E139 -> 0.85916169 | G23: =PL!E196 -> 0.85916169 | I23: PL 頁 | J23: 高盛：2027–28 年 ABF 可能短缺
A24: FY2028 ABF 需求滿足率 | C24: =PL!F82 -> 0.88111743 | E24: =PL!F139 -> 0.98501233 | G24: =PL!F196 -> 1 | I24: PL 頁
A25: FY2026 AI 載板占營收 vs 高盛 10%（百分點） | B25: 0.1 | C25: =PL!D91 -> 0.105 | D25: =C25-B25 -> 0.005 | E25: =PL!D148 -> 0.105 | F25: =E25-B25 -> 0.005 | G25: =PL!D205 -> 0.105 | H25: =G25-B25 -> 0.005 | I25: TechNews（高盛）
A26: FY2027 AI 載板占營收 vs 高盛 15–20% 中點（百分點） | B26: 0.175 | C26: =PL!E91 -> 0.21055476 | D26: =C26-B26 -> 0.035554759 | E26: =PL!E148 -> 0.21613956 | F26: =E26-B26 -> 0.041139562 | G26: =PL!E205 -> 0.2220287 | H26: =G26-B26 -> 0.047028702 | I26: TechNews（高盛）
A27: FY2027 份額合計：Ibiden＋欣興＋南電＋景碩（NVIDIA） | C27: =Units!D12 -> 0.995 | E27: =Units!D12 -> 0.995 | G27: =Units!D12 -> 0.995 | I27: Units 頁 | J27: 應 ≤ 100%
A28: FY2027 份額合計：Ibiden＋欣興＋南電＋景碩（非 NVIDIA） | C28: =Units!D17 -> 0.895 | E28: =Units!D17 -> 0.895 | G28: =Units!D17 -> 0.895 | I28: Units 頁 | J28: 應 ≤ 100%
A29: FY2027 每顆 NVIDIA 加速器的景碩營收（US$；GPU＋CPU 載板） | C29: =Units!D19 -> 33.307809 | E29: =Units!D19 -> 33.307809 | G29: =Units!D19 -> 33.307809 | I29: Units 頁 | J29: Ibiden 同期約 169（ibiden/dist Units 頁）
A30: FY2027 每 GW 景碩 AI 載板營收（US$M） | C30: =Units!D23 -> 11.206759 | E30: =Units!D23 -> 11.206759 | G30: =Units!D23 -> 11.206759 | I30: Units 頁
A31: D. 資本支出
A32: FY2026–FY2028 資本支出合計 vs 公司 ABF 擴產計畫 431 億（235＋196） | B32: 43.1 | C32: =PL!D93+PL!E93+PL!F93 -> 44 | D32: =C32/B32-1 -> 0.020881671 | E32: =PL!D150+PL!E150+PL!F150 -> 44 | F32: =E32/B32-1 -> 0.020881671 | G32: =PL!D207+PL!E207+PL!F207 -> 44 | H32: =G32/B32-1 -> 0.020881671 | I32: 工商時報 2026-08-06 | J32: 模型含晶碩；計畫期間與年度未完全對齊

Sheet Sens
A1: Sens — 一次動一個輸入（情境 A；FY2026 恆等於錨點，其他 AI 載板在每個案例內重新校準）：對 FY2027、FY2028 營收、毛利率與 EPS 的影響。每個案例是一個完整推導區塊（本頁下方）
A3: 案例 | B3: 設定 | C3: FY2027 營收 | D3: FY2027 毛利率 | E3: FY2027 EPS | F3: FY2027 EPS 相對基準 | G3: FY2028 營收 | H3: FY2028 毛利率 | I3: FY2028 EPS | J3: FY2028 EPS 相對基準
A4: 基準（情境 A） | B4: PL 區塊 A | C4: =PL!E88 -> 72.033987 | D4: =PL!E98 -> 0.35525676 | E4: =PL!E109 -> 27.382654 | F4: =ROUND(E4/E$4-1,8) -> 0 | G4: =PL!F88 -> 84.102246 | H4: =PL!F98 -> 0.36172503 | I4: =PL!F109 -> 33.842266 | J4: =ROUND(I4/I$4-1,8) -> 0
A5: AI 部署 ×0.8 | B5: FY2027 起顆數與其他 AI ×0.8 | C5: =E88 -> 72.033987 | D5: =E98 -> 0.35525676 | E5: =E109 -> 27.382654 | F5: =ROUND(E5/E$4-1,8) -> 0 | G5: =F88 -> 84.102246 | H5: =F98 -> 0.36235126 | I5: =F109 -> 33.930226 | J5: =ROUND(I5/I$4-1,8) -> 0.00259911
A6: AI 部署 ×1.2 | B6: ×1.2 | C6: =E145 -> 72.033987 | D6: =E155 -> 0.35525676 | E6: =E166 -> 27.382654 | F6: =ROUND(E6/E$4-1,8) -> 0 | G6: =F145 -> 84.102246 | H6: =F155 -> 0.36121831 | I6: =F166 -> 33.771091 | J6: =ROUND(I6/I$4-1,8) -> -0.00210314
A7: ABF 產能 低 | B7: 產能指數 1.10／1.30／1.55 | C7: =E202 -> 69.273783 | D7: =E212 -> 0.34689091 | E7: =E223 -> 25.109463 | F7: =ROUND(E7/E$4-1,8) -> -0.08301573 | G7: =F202 -> 78.595638 | H7: =F212 -> 0.34831337 | I7: =F223 -> 29.372383 | J7: =ROUND(I7/I$4-1,8) -> -0.13207991
A8: ABF 產能 高 | B8: 1.25／1.62／2.00 | C8: =E259 -> 73.41409 | D8: =E269 -> 0.35920379 | E8: =E280 -> 28.51925 | F8: =ROUND(E8/E$4-1,8) -> 0.04150786 | G8: =F259 -> 87.406211 | H8: =F269 -> 0.36896089 | I8: =F280 -> 36.528909 | J8: =ROUND(I8/I$4-1,8) -> 0.07938718
A9: ABF 溢價 低（Ibiden 低值） | B9: 0.95／0.85／0.75 | C9: =E316 -> 70.377865 | D9: =E326 -> 0.34576097 | E9: =E337 -> 25.483346 | F9: =ROUND(E9/E$4-1,8) -> -0.06936174 | G9: =F316 -> 79.754924 | H9: =F326 -> 0.33912195 | I9: =F337 -> 28.689008 | J9: =ROUND(I9/I$4-1,8) -> -0.15227286
A10: ABF 溢價 高（Ibiden 高值） | B10: 1.05／1.05／1.00 | C10: =E373 -> 73.69011 | D10: =E383 -> 0.36456842 | E10: =E394 -> 29.31183 | F10: =ROUND(E10/E$4-1,8) -> 0.07045247 | G10: =F373 -> 88.449568 | H10: =F383 -> 0.38326225 | I10: =F394 -> 39.170337 | J10: =ROUND(I10/I$4-1,8) -> 0.15743835
A11: 漲價年度化 8% | B11: 基準 15% | C11: =E430 -> 70.017838 | D11: =E440 -> 0.33669151 | E11: =E451 -> 24.258236 | F11: =ROUND(E11/E$4-1,8) -> -0.11410208 | G11: =F430 -> 81.58836 | H11: =F440 -> 0.34205862 | I11: =F451 -> 29.928522 | J11: =ROUND(I11/I$4-1,8) -> -0.11564663
A12: 漲價年度化 22% | C12: =E487 -> 74.050137 | D12: =E497 -> 0.37281107 | E12: =E508 -> 30.507072 | F12: =ROUND(E12/E$4-1,8) -> 0.11410208 | G12: =F487 -> 86.616133 | H12: =F497 -> 0.38024988 | I12: =F508 -> 37.756337 | J12: =ROUND(I12/I$4-1,8) -> 0.11565627
A13: ABF 現金毛利率 40% | B13: 基準 50% | C13: =E544 -> 72.033987 | D13: =E554 -> 0.34700608 | E13: =E565 -> 26.390056 | F13: =ROUND(E13/E$4-1,8) -> -0.03624918 | G13: =F544 -> 84.102246 | H13: =F554 -> 0.34501841 | I13: =F565 -> 31.495648 | J13: =ROUND(I13/I$4-1,8) -> -0.06933987
A14: ABF 現金毛利率 60% | C14: =E601 -> 72.033987 | D14: =E611 -> 0.36350745 | E14: =E622 -> 28.375253 | F14: =ROUND(E14/E$4-1,8) -> 0.03624918 | G14: =F601 -> 84.102246 | H14: =F611 -> 0.37843165 | I14: =F622 -> 36.188885 | J14: =ROUND(I14/I$4-1,8) -> 0.06933987
A15: BT 現金毛利率 30% | B15: 基準 45% | C15: =E658 -> 72.033987 | D15: =E668 -> 0.34169135 | E15: =E679 -> 25.750668 | F15: =ROUND(E15/E$4-1,8) -> -0.05959928 | G15: =F658 -> 84.102246 | H15: =F668 -> 0.34479472 | I15: =F679 -> 31.464229 | J15: =ROUND(I15/I$4-1,8) -> -0.07026827
A16: BT 現金毛利率 60% | C16: =E715 -> 72.033987 | D16: =E725 -> 0.36882217 | E16: =E736 -> 29.014641 | F16: =ROUND(E16/E$4-1,8) -> 0.05959928 | G16: =F715 -> 84.102246 | H16: =F725 -> 0.37865534 | I16: =F736 -> 36.220304 | J16: =ROUND(I16/I$4-1,8) -> 0.07026827
A17: BT 年增 走 C 路徑 | B17: 12%／0%／−3% | C17: =E772 -> 68.311433 | D17: =E782 -> 0.35009384 | E17: =E793 -> 25.033229 | F17: =ROUND(E17/E$4-1,8) -> -0.08579978 | G17: =F772 -> 77.401649 | H17: =F782 -> 0.35408314 | I17: =F793 -> 29.560208 | J17: =ROUND(I17/I$4-1,8) -> -0.12652989
A18: 非 AI ABF 年增 2% | B18: 基準 6% | C18: =E829 -> 72.033987 | D18: =E839 -> 0.35525676 | E18: =E850 -> 27.382654 | F18: =ROUND(E18/E$4-1,8) -> 0 | G18: =F829 -> 84.102246 | H18: =F839 -> 0.36151011 | I18: =F850 -> 33.812079 | J18: =ROUND(I18/I$4-1,8) -> -0.00089201
A19: 非 AI ABF 年增 10% | C19: =E886 -> 72.033987 | D19: =E896 -> 0.35525676 | E19: =E907 -> 27.382654 | F19: =ROUND(E19/E$4-1,8) -> 0 | G19: =F886 -> 84.102246 | H19: =F896 -> 0.36193285 | I19: =F907 -> 33.871457 | J19: =ROUND(I19/I$4-1,8) -> 0.00086255
A20: 折舊年限 6 年 | B20: 基準 8 年 | C20: =E943 -> 72.033987 | D20: =E953 -> 0.35370657 | E20: =E964 -> 27.196158 | F20: =ROUND(E20/E$4-1,8) -> -0.00681074 | G20: =F943 -> 84.102246 | H20: =F953 -> 0.35648422 | I20: =F964 -> 33.10614 | J20: =ROUND(I20/I$4-1,8) -> -0.02175168
A21: 折舊年限 10 年 | C21: =E1000 -> 72.033987 | D21: =E1010 -> 0.35618688 | E21: =E1021 -> 27.494552 | F21: =ROUND(E21/E$4-1,8) -> 0.00408644 | G21: =F1000 -> 84.102246 | H21: =F1010 -> 0.36492263 | I21: =F1021 -> 34.291402 | J21: =ROUND(I21/I$4-1,8) -> 0.01327144
A22: 資本支出 低 | B22: 100／90／70 億 | C22: =E1057 -> 72.033987 | D22: =E1067 -> 0.35525676 | E22: =E1078 -> 27.382654 | F22: =ROUND(E22/E$4-1,8) -> 0 | G22: =F1057 -> 84.102246 | H22: =F1067 -> 0.37212903 | I22: =F1078 -> 35.303617 | J22: =ROUND(I22/I$4-1,8) -> 0.04318121
A23: 資本支出 高 | B23: 220／220／160 億 | C23: =E1114 -> 72.033987 | D23: =E1124 -> 0.35525676 | E23: =E1135 -> 27.382654 | F23: =ROUND(E23/E$4-1,8) -> 0 | G23: =F1114 -> 84.102246 | H23: =F1124 -> 0.3542936 | I23: =F1135 -> 32.798445 | J23: =ROUND(I23/I$4-1,8) -> -0.03084372
A24: 景碩 NVIDIA GPU 份額 低 | B24: 1%→2% | C24: =E1171 -> 72.033987 | D24: =E1181 -> 0.35525676 | E24: =E1192 -> 27.382654 | F24: =ROUND(E24/E$4-1,8) -> 0 | G24: =F1171 -> 84.102246 | H24: =F1181 -> 0.36198154 | I24: =F1192 -> 33.878295 | J24: =ROUND(I24/I$4-1,8) -> 0.00106461
A25: 景碩 NVIDIA GPU 份額 高（券商說法） | B25: 10%→15% | C25: =E1228 -> 72.033987 | D25: =E1238 -> 0.35525676 | E25: =E1249 -> 27.382654 | F25: =ROUND(E25/E$4-1,8) -> 0 | G25: =F1228 -> 84.102246 | H25: =F1238 -> 0.36099331 | I25: =F1249 -> 33.739489 | J25: =ROUND(I25/I$4-1,8) -> -0.00303696
A26: 景碩 Vera CPU 份額 低 | B26: 50%→45% | C26: =E1285 -> 72.033987 | D26: =E1295 -> 0.35525676 | E26: =E1306 -> 27.382654 | F26: =ROUND(E26/E$4-1,8) -> 0 | G26: =F1285 -> 84.102246 | H26: =F1295 -> 0.36195985 | I26: =F1306 -> 33.875249 | J26: =ROUND(I26/I$4-1,8) -> 0.0009746
A27: 景碩 Vera CPU 份額 高 | B27: 90%→100% | C27: =E1342 -> 72.033987 | D27: =E1352 -> 0.35525676 | E27: =E1363 -> 27.382654 | F27: =ROUND(E27/E$4-1,8) -> 0 | G27: =F1342 -> 84.102246 | H27: =F1352 -> 0.36156459 | I27: =F1363 -> 33.81973 | J27: =ROUND(I27/I$4-1,8) -> -0.00066592
A28: 景碩 ASIC 份額 低 | B28: 2%→3% | C28: =E1399 -> 72.033987 | D28: =E1409 -> 0.35525676 | E28: =E1420 -> 27.382654 | F28: =ROUND(E28/E$4-1,8) -> 0 | G28: =F1399 -> 84.102246 | H28: =F1409 -> 0.36217268 | I28: =F1420 -> 33.905143 | J28: =ROUND(I28/I$4-1,8) -> 0.00185794
A29: 景碩 ASIC 份額 高 | B29: 8%→10% | C29: =E1456 -> 72.033987 | D29: =E1466 -> 0.35525676 | E29: =E1477 -> 27.382654 | F29: =ROUND(E29/E$4-1,8) -> 0 | G29: =F1456 -> 84.102246 | H29: =F1466 -> 0.36127003 | I29: =F1477 -> 33.778356 | J29: =ROUND(I29/I$4-1,8) -> -0.00188847
A30: CPU 載板金額比 0.20 | B30: 基準 0.30 | C30: =E1513 -> 72.033987 | D30: =E1523 -> 0.35525676 | E30: =E1534 -> 27.382654 | F30: =ROUND(E30/E$4-1,8) -> 0 | G30: =F1513 -> 84.102246 | H30: =F1523 -> 0.36193833 | I30: =F1534 -> 33.872227 | J30: =ROUND(I30/I$4-1,8) -> 0.00088529
A31: CPU 載板金額比 0.45 | C31: =E1570 -> 72.033987 | D31: =E1580 -> 0.35525676 | E31: =E1591 -> 27.382654 | F31: =ROUND(E31/E$4-1,8) -> 0 | G31: =F1570 -> 84.102246 | H31: =F1580 -> 0.36143427 | I31: =F1591 -> 33.801426 | J31: =ROUND(I31/I$4-1,8) -> -0.00120677
A32: 營業費用彈性 1.0 | B32: 基準 0.6 | C32: =E1627 -> 72.033987 | D32: =E1637 -> 0.35525676 | E32: =E1648 -> 25.969083 | F32: =ROUND(E32/E$4-1,8) -> -0.05162287 | G32: =F1627 -> 84.102246 | H32: =F1637 -> 0.36172503 | I32: =F1648 -> 31.317771 | J32: =ROUND(I32/I$4-1,8) -> -0.07459594
A33: 稅率 20% | B33: 基準 12% | C33: =E1684 -> 72.033987 | D33: =E1694 -> 0.35525676 | E33: =E1705 -> 24.622318 | F33: =ROUND(E33/E$4-1,8) -> -0.10080604 | G33: =F1684 -> 84.102246 | H33: =F1694 -> 0.36172503 | I33: =F1705 -> 30.467592 | J33: =ROUND(I33/I$4-1,8) -> -0.09971775
A34: 業外 0 | B34: 每年 0（基準 4 億） | C34: =E1741 -> 72.033987 | D34: =E1751 -> 0.35525676 | E34: =E1762 -> 26.714609 | F34: =ROUND(E34/E$4-1,8) -> -0.02439668 | G34: =F1741 -> 84.102246 | H34: =F1751 -> 0.36172503 | I34: =F1762 -> 33.174221 | J34: =ROUND(I34/I$4-1,8) -> -0.01973998
A35: 晶碩年增 3% | B35: 基準 10% | C35: =E1798 -> 71.452917 | D35: =E1808 -> 0.35448629 | E35: =E1819 -> 27.205625 | F35: =ROUND(E35/E$4-1,8) -> -0.00646501 | G35: =F1798 -> 82.864567 | H35: =F1808 -> 0.36040654 | I35: =F1819 -> 33.454086 | J35: =ROUND(I35/I$4-1,8) -> -0.01147028
A36: 情境 B | B36: tsmc 顆數係數 B；BT 年增較低 | C36: =PL!E145 -> 70.17271 | D36: =PL!E155 -> 0.35274377 | E36: =PL!E166 -> 26.207941 | F36: =ROUND(E36/E$4-1,8) -> -0.04289989 | G36: =PL!F145 -> 80.658884 | H36: =PL!F155 -> 0.35860949 | I36: =PL!F166 -> 31.728257 | J36: =ROUND(I36/I$4-1,8) -> -0.06246654
A37: 情境 C | B37: tsmc 顆數係數 C；BT 年增最低 | C37: =PL!E202 -> 68.311433 | D37: =PL!E212 -> 0.35009384 | E37: =PL!E223 -> 25.033229 | F37: =ROUND(E37/E$4-1,8) -> -0.08579978 | G37: =PL!F202 -> 73.086214 | H37: =PL!F212 -> 0.34379228 | I37: =PL!F223 -> 26.229516 | J37: =ROUND(I37/I$4-1,8) -> -0.22494801
A39: 讀法：漲價年度化與 ABF 溢價直接決定毛利（溢價全數落在毛利）；ABF 產能受限時，份額與部署的上修只部分轉成營收；FY2027 情境差只來自 BT 年增。
A41: 目標價參數（只改 DCF 參數；PL 收斂法的 fade_g 與資本支出率路徑不隨 tp_g 變動）
A42: 案例 | B42: 設定 | C42: DCF 目標價 | D42: Comparable 目標價 | E42: 加權目標價 | F42: 相對基準
A43: 基準 | B43: r 10%、g 4%、DCF 權重 0.5 | C43: =(tp_wA*MAX(0,SUMPRODUCT(Val!B16:B21,1/(1+tp_r)^{1;2;3;4;5;6})+Val!B21*(1+tp_g)/(tp_r-tp_g)/(1+tp_r)^6)+tp_wB*MAX(0,SUMPRODUCT(Val!C16:C21,1/(1+tp_r)^{1;2;3;4;5;6})+Val!C21*(1+tp_g)/(tp_r-tp_g)/(1+tp_r)^6)+tp_wC*MAX(0,SUMPRODUCT(Val!D16:D21,1/(1+tp_r)^{1;2;3;4;5;6})+Val!D21*(1+tp_g)/(tp_r-tp_g)/(1+tp_r)^6))*(1+tp_r) -> 528.56131 | D43: =Val!B35 -> 1286.996 | E43: =tp_w_dcf*C43+(1-tp_w_dcf)*D43 -> 907.77863 | F43: =E43/E$43-1 -> 0
...

Sheet Sources
A1: 來源（公司財報經資料商與媒體轉載；法說內容經媒體摘要；券商與資料商皆為 Interested-party）
A2: 資料商：stockanalysis（現價 986（2026-10-22）、股數、前瞻與近 12 月 P/E、目標價 1,092.15（13 位）、下次財報日估 2026-11-06） | B2: https://stockanalysis.com/quote/tpe/3189/
A3: 資料商：stockanalysis 年度與季損益表（營收、毛利、營業利益、稅前、所得稅、非控制權益、EPS、股數） | B3: https://stockanalysis.com/quote/tpe/3189/financials/income-statement/?p=quarterly
A4: 資料商：stockanalysis 季現金流量表（折舊攤提、資本支出、現金增資 101.59 億） | B4: https://stockanalysis.com/quote/tpe/3189/financials/cash-flow-statement/?p=quarterly
A5: 資料商：stockanalysis 比率頁（年度 P/E、ROE FY2021–25） | B5: https://stockanalysis.com/quote/tpe/3189/financials/ratios/
A6: 資料商：stockanalysis 晶碩（6491）季損益表（營收、淨利） | B6: https://stockanalysis.com/quote/tpe/6491/financials/?p=quarterly
A7: 資料商：nstock（股本 52.69 億、2Q26 毛利率、9 月營收、現價核對） | B7: https://www.nstock.tw/%E6%99%AF%E7%A2%A9%E5%81%9A%E4%BB%80%E9%BA%BC.html
A8: 媒體：TechNews 2026-10-06（9 月營收 51.81 億、前 9 月 381.41 億） | B8: https://finance.technews.tw/2026/10/06/kinsus-3189-202609-financial-report/
A9: 媒體：工商時報 2026-08-06（7 月營收、資本支出 196 億＋235 億） | B9: https://www.ctee.com.tw/news/20260806701841-430503
A10: 券商（媒體）：TechNews 2026-08-04 高盛（目標價 1,125；Vera CPU 100% 目標、AI 占營收、毛利率、客戶贊助設備、產能倍增） | B10: https://finance.technews.tw/2026/08/04/vera-cpu/
A11: 券商（媒體）：經濟日報 2026-08-07（2Q26 EPS、毛利率、ABF 產能 4,000→8,000 萬顆） | B11: https://money.udn.com/money/story/5607/9676971
A12: 券商（媒體）：經濟日報 2026-09-16（Vera CPU 80–100%、Rubin 15–20%、BT 記憶體逾五成） | B12: https://money.udn.com/money/amp/story/5607/9757810
A13: 券商（媒體）：經濟日報 2026-10-12（美系券商 EPS 2026–28、3Q／4Q26 毛利率） | B13: https://money.udn.com/money/story/5607/9808557
... A27: SemiAnalysis | B27: 未使用
