Workbook

Sheet README
A1: Kioxia（285A JP）收支與估值模型 v0.1（AI 半導體 Project：記憶體——NAND） 2026-10-25
A2: 模型命題：Kioxia 是全球第三、四大 NAND 廠（2Q26 營收市占 13.6%），與 SanDisk 共用四日市、北上合資產能；盈餘由 NAND 合約價循環、AI 推論帶動的企業級 SSD 位元與日圓匯率決定。問題是 2026 年的高價能維持多久（FY2027 起三情境分歧），以及現價約 2.6 倍前瞻 P/E 是否已反映循環見頂。
A3: 重點觀察
A4: ="1. 加權目標價 ¥"&TEXT(Val!B49,"#,##0")&"，相對現價 ¥"&TEXT(px,"#,##0")&"（2026-10-23 收盤）"&TEXT(Val!B52,"+0.0%;−0.0%")&"。主因是現價的倍數低於同業：Kioxia 現價 ÷ 2028-03 共識每股淨值 1.63x，同業中位數 "&TEXT(Val!B32,"0.00")&"x（SanDisk 2.86x、美光 3.35x），Comparable ¥"&TEXT(Val!B34,"#,##0")&"（"&TEXT(Val!B53,"+0%;−0%")&"）；DCF ¥"&TEXT(Val!B24,"#,##0")&" 也高於現價，因現價只有 FY2027 EPS（A）的 "&TEXT(Val!B85,"0.0")&" 倍。股價 10-09 至 10-23 已跌 27%（17,505 → 12,755）。" -> 1. 加權目標價 ¥22,268，相對現價 ¥12,755（2026-10-23 收盤）+74.6%。主因是現價的倍數低於同業：Kioxia 現價 ÷ 2028-03 共識每股淨值 1.63x，同業中位數 2.10x（SanDisk 2.86x、美光 3.35x），Comparable ¥20,357（+60%）；DCF ¥24,180 也高於現價，因現價只有 FY2027 EPS（A）的 2.4 倍。股價 10-09 至 10-23 已跌 27%（17,505 → 12,755）。
A5: ="2. 本模型 FY2026 EPS（A）¥"&TEXT(PL!D10,"#,##0")&"，比共識 ¥3,486 "&TEXT(PL!D10/cons_eps26-1,"+0%;−0%")&"；上半年已由第一季實績與第二季指引鎖定（淨利 ¥2,112B）。追蹤：2026-10-30 第二季財報（實績 vs 指引 ¥2,390B／¥1,890B）與第三季指引。" -> 2. 本模型 FY2026 EPS（A）¥3,492，比共識 ¥3,486 +0%；上半年已由第一季實績與第二季指引鎖定（淨利 ¥2,112B）。追蹤：2026-10-30 第二季財報（實績 vs 指引 ¥2,390B／¥1,890B）與第三季指引。
A6: ="3. 營收以美元計、成本以日圓計：匯率 145／170 日圓使 FY2028 EPS（A）變動 "&TEXT(Sens!H9,"+0%;−0%")&"／"&TEXT(Sens!H10,"+0%;−0%")&"；2027 起季價 ±20% 為 "&TEXT(Sens!H5,"+0%;−0%")&"／"&TEXT(Sens!H6,"+0%;−0%")&"。情境 C 的 FY2029 毛利率降到 "&TEXT(PL!G26,"0%")&"。追蹤：TrendForce 每季初的 NAND 合約價、日圓匯率、SanDisk 2026-10-29 財報（合資群位元）。" -> 3. 營收以美元計、成本以日圓計：匯率 145／170 日圓使 FY2028 EPS（A）變動 −13%／+9%；2027 起季價 ±20% 為 −28%／+31%。情境 C 的 FY2029 毛利率降到 51%。追蹤：TrendForce 每季初的 NAND 合約價、日圓匯率、SanDisk 2026-10-29 財報（合資群位元）。
A7: ="投資建議："&Val!B55&"（依上檔空間固定規則；上檔空間："&TEXT(Val!B52,"+0.0%;−0.0%")&"，級距："&Val!B54&"）" -> 投資建議：強力買進（依上檔空間固定規則；上檔空間：+74.6%，級距：大於 50%）
A9: 驅動因子 → 推導量（因果方向：左邊決定右邊）
A10: Units｜markets/nand 成品：Kioxia 季度營收（市場營收 × 份額，美元；同字母情境）與位元（季度出貨 × 份額）
A11: PL 區塊｜營收＝市場層 × 公司口徑係數 × 匯率；營業成本＝位元 × 每 EB 成本（日圓；第二季以指引校準，之後每年 × (1 − 成本年降)）；營業費用＝固定＋變動
A12: PL 區塊｜淨利＝（營業利益＋業外＋淨現金收益）×（1 − 稅率）；自由現金流＝淨利＋折舊 − 資本支出（¥470B／年）；股東回饋＝20% × FCF（以買回計）→ 股數 → EPS、每股淨值
A13: Val｜第 0 節目標價＝DCF（FY2027–FY2032＋永續）與 Comparable（同業前瞻 P/B × 約 2028 年底每股淨值）各半；第 5–6 節目前倍數、十年倍數規則值（美光 Analogy）
A15: 會計年度：4 月到隔年 3 月（FY2026＝2026-04～2027-03 ≈ CY2026Q2–CY2027Q1）。前瞻 EPS 依月份調整：12 個月後（約 2027-10）的未來 12 月＝5／12 FY2027＋7／12 FY2028。每股數字為 2026-10-01 一股分三股後。
A16: 情境：A＝順利、B＝平平、C＝不如預期，讀 markets/nand 同字母（價格＝markets/memory NAND_S；顆數＝SCEN_UNITS；合資群份額年變動）；公司特有變數（每位元成本年降 14%／12%／10%，與 SanDisk 同值）A 最有利、C 最不利。FY2026 的 B、C 略高於 A：上游 B、C 價格路徑 2027Q1 漲幅較大。FY2030 起為收斂法，非驅動因子推導。
A17: 十年歷史不足：2024-12 上市，只有兩個年底；十年 P/B、P/E 與十年平均淨利率以美光為 Analogy，tp_roe 只用 FY2024–FY2025。本版未做先驗，無 Andy 合理 P/E 對照。

Sheet In
A1: In — 輸入（藍字；基準欄 E，低 D、高 F）。金額：十億日圓（¥B）；每股：日圓（2026-10-01 一股分三股後）；股數：百萬股。每個輸入附標記與來源；找不到者寫「未找到」
A2: 標記：Verified（公司文件、交易所資料）／Interested-party（寫明是誰、立場）／Analogy（寫明對照與差異）／Assumed（給低／高區間）／Derived（寫明換算）。SemiAnalysis 未使用
A3: 鍵 | B3: 項目 | C3: 單位 | D3: 低 | E3: 基準 | F3: 高 | G3: 標記 | H3: 來源1 | I3: 來源2／說明
A4: A. 季度實績與公司指引（¥B；EPS 日圓，分割後）
A5: p1_rev | B5: FY2025 第1季營收 | C5: ¥B | E5: 342.8 | G5: Verified | H5: Kioxia FY2026 第一季財報（2026-07-31；SGX 轉載 Earnings Release FY2026 1Q）https://links.sgx.com/1.0.0/corporate-announcements/DOATO9EIE4EEQ2Y8/898078_Earnings-Release-FY2026-1Q-EN.pdf（前期欄：營收 342.8、營業利益 44.9、淨利 18.3） | I5: 四季合計 2,337.6＝公司 FY2025 營收（storagenewsletter 轉載決算；MarketScreener 2,337.6）
A6: p1_gp | B6: FY2025 第1季毛利 | C6: ¥B | E6: 71.2 | G6: Interested-party | H6: stockanalysis 季度損益（TYO:285A；2026-10-25 讀取）
A7: p1_op | B7: FY2025 第1季營業利益 | C7: ¥B | E7: 44.9 | G7: Verified | H7: Kioxia FY2026 第一季財報（2026-07-31；SGX 轉載 Earnings Release FY2026 1Q）https://links.sgx.com/1.0.0/corporate-announcements/DOATO9EIE4EEQ2Y8/898078_Earnings-Release-FY2026-1Q-EN.pdf（前期欄：營收 342.8、營業利益 44.9、淨利 18.3） | I7: 四季合計 869.0（公司 870.4，取整差）
A8: p1_ni | B8: FY2025 第1季淨利 | C8: ¥B | E8: 18.3 | G8: Verified | H8: Kioxia FY2026 第一季財報（2026-07-31；SGX 轉載 Earnings Release FY2026 1Q）https://links.sgx.com/1.0.0/corporate-announcements/DOATO9EIE4EEQ2Y8/898078_Earnings-Release-FY2026-1Q-EN.pdf（前期欄：營收 342.8、營業利益 44.9、淨利 18.3） | I8: 四季合計 554.5（公司 554.5）
A9: p2_rev | B9: FY2025 第2季營收 | C9: ¥B | E9: 448.3 | G9: Interested-party | H9: stockanalysis 季度損益（TYO:285A；2026-10-25 讀取） | I9: 四季合計 2,337.6＝公司 FY2025 營收（storagenewsletter 轉載決算；MarketScreener 2,337.6）
A10: p2_gp | B10: FY2025 第2季毛利 | C10: ¥B | E10: 122.1 | G10: Interested-party | H10: stockanalysis 季度損益（TYO:285A；2026-10-25 讀取）
A11: p2_op | B11: FY2025 第2季營業利益 | C11: ¥B | E11: 85.9 | G11: Interested-party | H11: stockanalysis 季度損益（TYO:285A；2026-10-25 讀取） | I11: 四季合計 869.0（公司 870.4，取整差）
A12: p2_ni | B12: FY2025 第2季淨利 | C12: ¥B | E12: 40.7 | G12: Interested-party | H12: stockanalysis 季度損益（TYO:285A；2026-10-25 讀取） | I12: 四季合計 554.5（公司 554.5）
A13: p3_rev | B13: FY2025 第3季營收 | C13: ¥B | E13: 543.6 | G13: Interested-party | H13: stockanalysis 季度損益（TYO:285A；2026-10-25 讀取） | I13: 四季合計 2,337.6＝公司 FY2025 營收（storagenewsletter 轉載決算；MarketScreener 2,337.6）
A14: p3_gp | B14: FY2025 第3季毛利 | C14: ¥B | E14: 176.6 | G14: Interested-party | H14: stockanalysis 季度損益（TYO:285A；2026-10-25 讀取）
A15: p3_op | B15: FY2025 第3季營業利益 | C15: ¥B | E15: 142.8 | G15: Interested-party | H15: stockanalysis 季度損益（TYO:285A；2026-10-25 讀取） | I15: 四季合計 869.0（公司 870.4，取整差）
A16: p3_ni | B16: FY2025 第3季淨利 | C16: ¥B | E16: 87.8 | G16: Interested-party | H16: stockanalysis 季度損益（TYO:285A；2026-10-25 讀取） | I16: 四季合計 554.5（公司 554.5）
A17: p4_rev | B17: FY2025 第4季營收 | C17: ¥B | E17: 1002.9 | G17: Interested-party | H17: stockanalysis 季度損益（TYO:285A；2026-10-25 讀取） | I17: 四季合計 2,337.6＝公司 FY2025 營收（storagenewsletter 轉載決算；MarketScreener 2,337.6）
A18: p4_gp | B18: FY2025 第4季毛利 | C18: ¥B | E18: 642.9 | G18: Interested-party | H18: stockanalysis 季度損益（TYO:285A；2026-10-25 讀取）
A19: p4_op | B19: FY2025 第4季營業利益 | C19: ¥B | E19: 595.4 | G19: Interested-party | H19: stockanalysis 季度損益（TYO:285A；2026-10-25 讀取） | I19: 四季合計 869.0（公司 870.4，取整差）
A20: p4_ni | B20: FY2025 第4季淨利 | C20: ¥B | E20: 407.7 | G20: Interested-party | H20: stockanalysis 季度損益（TYO:285A；2026-10-25 讀取） | I20: 四季合計 554.5（公司 554.5）
A21: q1_rev | B21: FY2026 第一季營收（2026-04～06） | C21: ¥B | E21: 1767.1 | G21: Verified | H21: Kioxia FY2026 第一季財報（2026-07-31；SGX 轉載 Earnings Release FY2026 1Q）https://links.sgx.com/1.0.0/corporate-announcements/DOATO9EIE4EEQ2Y8/898078_Earnings-Release-FY2026-1Q-EN.pdf | I21: SSD 與儲存 1,174.7、智慧裝置 525.7、其他 66.7；平均匯率 160 日圓
A22: q1_gp | B22: FY2026 第一季毛利 | C22: ¥B | E22: 1380.1 | G22: Interested-party | H22: stockanalysis 季度損益（TYO:285A；2026-10-25 讀取）：1,380,066 百萬日圓 | I22: 財報摘要未列毛利
A23: q1_op | B23: FY2026 第一季營業利益 | C23: ¥B | E23: 1270 | G23: Verified | H23: Kioxia FY2026 第一季財報（2026-07-31；SGX 轉載 Earnings Release FY2026 1Q）https://links.sgx.com/1.0.0/corporate-announcements/DOATO9EIE4EEQ2Y8/898078_Earnings-Release-FY2026-1Q-EN.pdf | I23: 含訴訟損失準備 36.6、股份報酬 19.4（non-GAAP 加回）
A24: q1_ni | B24: FY2026 第一季淨利（歸屬母公司） | C24: ¥B | E24: 842.2 | G24: Verified | H24: Kioxia FY2026 第一季財報（2026-07-31；SGX 轉載 Earnings Release FY2026 1Q）https://links.sgx.com/1.0.0/corporate-announcements/DOATO9EIE4EEQ2Y8/898078_Earnings-Release-FY2026-1Q-EN.pdf
A25: q1_eps | B25: FY2026 第一季基本 EPS（分割後） | C25: JPY | E25: =1539.91/3 -> 513.30333 | G25: Derived | H25: Kioxia FY2026 第一季財報（2026-07-31；SGX 轉載 Earnings Release FY2026 1Q）https://links.sgx.com/1.0.0/corporate-announcements/DOATO9EIE4EEQ2Y8/898078_Earnings-Release-FY2026-1Q-EN.pdf：基本 EPS ¥1,539.91（分割前）÷ 3 | I25: 2026-10-01 一股分三股（2026-07-31 董事會）
A26: g2_rev | B26: 公司指引：FY2026 第二季（2026-07～09）營收 | C26: ¥B | E26: 2390 | G26: Interested-party | H26: Kioxia FY2026 第一季財報（2026-07-31；SGX 轉載 Earnings Release FY2026 1Q）https://links.sgx.com/1.0.0/corporate-announcements/DOATO9EIE4EEQ2Y8/898078_Earnings-Release-FY2026-1Q-EN.pdf：¥2,390.0B（假設 1 美元＝162 日圓） | I26: 公司不提供全年計畫（立場：公司）
A27: g2_op | B27: 公司指引：FY2026 第二季營業利益 | C27: ¥B | E27: 1890 | G27: Interested-party | H27: Kioxia FY2026 第一季財報（2026-07-31；SGX 轉載 Earnings Release FY2026 1Q）https://links.sgx.com/1.0.0/corporate-announcements/DOATO9EIE4EEQ2Y8/898078_Earnings-Release-FY2026-1Q-EN.pdf：¥1,890.0B（non-GAAP 1,900.0）
A28: g2_ni | B28: 公司指引：FY2026 第二季淨利 | C28: ¥B | E28: 1270 | G28: Interested-party | H28: Kioxia FY2026 第一季財報（2026-07-31；SGX 轉載 Earnings Release FY2026 1Q）https://links.sgx.com/1.0.0/corporate-announcements/DOATO9EIE4EEQ2Y8/898078_Earnings-Release-FY2026-1Q-EN.pdf：¥1,270.0B；基本 EPS ¥2,317.46（分割前）
A29: g2_ox | B29: FY2026 第二季營業費用（推估；校準用） | C29: ¥B | D29: 55 | E29: 70 | F29: 90 | G29: Assumed | H29: 第一季毛利 − 營業利益＝110.1（含一次性 56.0）；第二季 GAAP 與 non-GAAP 營業利益差 10 | I29: 第二季營業成本＝營收 − 營業利益 − 本值（Derived），用於校準每 EB 成本
A30: a25_rev | B30: FY2025 營收（2025-04～2026-03） | C30: ¥B | E30: =p1_rev+p2_rev+p3_rev+p4_rev -> 2337.6 | G30: Derived | H30: 四季合計 | I30: 公司 2,337.6（storagenewsletter 轉載 FY25 決算，+37%）
A31: a25_ni | B31: FY2025 淨利 | C31: ¥B | E31: =p1_ni+p2_ni+p3_ni+p4_ni -> 554.5 | G31: Derived | H31: 四季合計 | I31: 公司 554.0（storagenewsletter）、MarketScreener 554.5
A32: a25_eps | B32: FY2025 EPS（分割後） | C32: JPY | E32: 341.4 | G32: Interested-party | H32: MarketScreener 預估頁（2026-10-25 擷取；頁面為 10-16 收盤；會計年度 3 月；每股數字已依分割調整，股數 1,644 百萬股）：341.4 | I32: ≈ 554.5 ÷ 平均約 1,624 百萬股（分割後，Derived）
A33: kx_k | B33: 公司營收 ÷ 市場層 Kioxia 營收（TrendForce 口徑 × 匯率） | C33: x | E33: =q1_rev/160/Units!H4 -> 1.0302589 | G33: Derived | H33: 第一季營收 ÷ 平均匯率 160 ÷ 市場層 2026Q2 Kioxia 營收（Units 頁） | I33: 公司營收含其他（¥66.7B）
A34: B. 成本、費用、稅、匯率（公司特有；隨情境者 A 最有利、C 最不利）
A35: cd_A | B35: 情境 A：每位元成本年降 | C35: % | D35: 0.1 | E35: 0.14 | F35: 0.18 | G35: Assumed | H35: A：BiCS10（332 層，北上 K2）FY2026 量產、密度約 +59% | I35: 與 sndk/ 同值（同一合資晶圓廠與 BiCS 世代）；以第二季指引校準的單位成本為起點
A36: cd_B | B36: 情境 B：每位元成本年降 | C36: % | D36: 0.08 | E36: 0.12 | F36: 0.16 | G36: Assumed | H36: B：轉換略延後 | I36: 同上
A37: cd_C | B37: 情境 C：每位元成本年降 | C37: % | D37: 0.06 | E37: 0.1 | F37: 0.14 | G37: Assumed | H37: C：需求轉弱、稼動率下降 | I37: 同上
A38: fx | B38: 匯率（FY2026 第三季起） | C38: ¥／$ | D38: 145 | E38: 160 | F38: 170 | G38: Assumed | H38: 第一季平均 160、第二季指引假設 162 | I38: 營收以美元計價（TrendForce 口徑 × 匯率）；成本以日圓計，不隨匯率
A39: ox_var | B39: 營業費用變動率（÷ 營收） | C39: % | D39: 0.005 | E39: 0.01 | F39: 0.02 | G39: Assumed | H39: FY2025 營業費用（毛利 − 營業利益）143.8 ÷ 營收 2,337.6 ≈ 6%，多為固定 | I39: 固定部分＝第二季營業費用 − 變動率 × 第二季營收（Derived）
A40: ox_g | B40: 營業費用固定部分年增 | C40: % | D40: 0.05 | E40: 0.1 | F40: 0.15 | G40: Assumed | H40: 研發（BiCS10、CBA）與人事
...

Sheet Q
A1: Q — 季度實績（¥B）與公司指引。會計年度 4–3 月；第一季＝4–6 月
A3: 項目 | B3: FY2025 第一季 | C3: FY2025 第二季 | D3: FY2025 第三季 | E3: FY2025 第四季 | F3: FY2025 | G3: FY2026 第一季 | H3: FY2026 第二季（指引） | I3: 標記 | J3: 來源
A4: 營收 | B4: =p1_rev -> 342.8 | C4: =p2_rev -> 448.3 | D4: =p3_rev -> 543.6 | E4: =p4_rev -> 1002.9 | F4: =SUM(B4:E4) -> 2337.6 | G4: =q1_rev -> 1767.1 | H4: =g2_rev -> 2390 | I4: Verified／Interested-party | J4: 公司財報（第一季前期欄）；stockanalysis 季度表；第二季為公司指引
A5: 毛利 | B5: =p1_gp -> 71.2 | C5: =p2_gp -> 122.1 | D5: =p3_gp -> 176.6 | E5: =p4_gp -> 642.9 | F5: =SUM(B5:E5) -> 1012.8 | G5: =q1_gp -> 1380.1 | I5: Verified／Interested-party | J5: 公司財報（第一季前期欄）；stockanalysis 季度表；第二季為公司指引
A6: 營業利益 | B6: =p1_op -> 44.9 | C6: =p2_op -> 85.9 | D6: =p3_op -> 142.8 | E6: =p4_op -> 595.4 | F6: =SUM(B6:E6) -> 869 | G6: =q1_op -> 1270 | H6: =g2_op -> 1890 | I6: Verified／Interested-party | J6: 公司財報（第一季前期欄）；stockanalysis 季度表；第二季為公司指引
A7: 淨利 | B7: =p1_ni -> 18.3 | C7: =p2_ni -> 40.7 | D7: =p3_ni -> 87.8 | E7: =p4_ni -> 407.7 | F7: =SUM(B7:E7) -> 554.5 | G7: =q1_ni -> 842.2 | H7: =g2_ni -> 1270 | I7: Verified／Interested-party | J7: 公司財報（第一季前期欄）；stockanalysis 季度表；第二季為公司指引
A8: 毛利率 | B8: =B5/B4 -> 0.20770128 | C8: =C5/C4 -> 0.27236226 | D8: =D5/D4 -> 0.32487123 | E8: =E5/E4 -> 0.64104098 | F8: =F5/F4 -> 0.43326489 | G8: =G5/G4 -> 0.78099711
A9: 營業利益率 | B9: =B6/B4 -> 0.13098016 | C9: =C6/C4 -> 0.19161276 | D9: =D6/D4 -> 0.26269316 | E9: =E6/E4 -> 0.59367833 | F9: =F6/F4 -> 0.3717488 | G9: =G6/G4 -> 0.71869164 | H9: =H6/H4 -> 0.79079498
A10: 季增：營收 | C10: =C4/B4-1 -> 0.30775963 | D10: =D4/C4-1 -> 0.21258086 | E10: =E4/D4-1 -> 0.84492274 | G10: =G4/E4-1 -> 0.76199023 | H10: =H4/G4-1 -> 0.35249844
A12: FY2026 第二季（2026-07～09）財報 2026-10-30 公布（公司公告）；本版 FY2026 第二季＝公司指引（固定），第三季起＝市場層推導

Sheet Units
A1: Units — 市場層 markets/nand 成品的 Kioxia 季度營收與位元（三情境；唯讀抄錄，藍字）。來源：markets/nand/dist/20261025_NAND市場模型_v0.1.xlsx
A2: C..Z＝CY2025Q1..CY2030Q4；營收為 TrendForce 口徑（$B，美元），位元為季度出貨 × 營收份額（EB）。合資群份額＝Kioxia＋SanDisk（與 sndk/ 模型讀同一列）
A3: 項目 | B3: 單位 | C3: 2025Q1 | D3: 2025Q2 | E3: 2025Q3 | F3: 2025Q4 | G3: 2026Q1 | H3: 2026Q2 | I3: 2026Q3 | J3: 2026Q4 | K3: 2027Q1 | L3: 2027Q2 | M3: 2027Q3 | N3: 2027Q4 | O3: 2028Q1 | P3: 2028Q2 | Q3: 2028Q3 | R3: 2028Q4 | S3: 2029Q1 | T3: 2029Q2 | U3: 2029Q3 | V3: 2029Q4 | W3: 2030Q1 | X3: 2030Q2 | Y3: 2030Q3 | Z3: 2030Q4 | AA3: 來源
A4: Kioxia 營收（情境 A） | B4: $B | C4: 1.92 | D4: 2.14 | E4: 2.84 | F4: 3.31 | G4: 5.96 | H4: 10.72 | I4: 14.319786 | J4: 17.646994 | K4: 19.444827 | L4: 20.560401 | M4: 20.652979 | N4: 20.309216 | O4: 20.400662 | P4: 20.49252 | Q4: 20.584792 | R4: 20.677479 | S4: 20.849997 | T4: 21.235847 | U4: 21.628838 | V4: 22.029101 | W4: 21.540765 | X4: 21.5582 | Y4: 21.57565 | Z4: 21.593113 | AA4: markets/nand/dist/20261025_NAND市場模型_v0.1.xlsx｜Mkt!C43:Z43
A5: Kioxia 營收（情境 B） | B5: $B | C5: 1.92 | D5: 2.14 | E5: 2.84 | F5: 3.31 | G5: 5.96 | H5: 10.72 | I5: 14.319786 | J5: 17.646994 | K5: 19.595468 | L5: 21.134079 | M5: 20.111911 | N5: 17.012605 | O5: 11.827513 | P5: 9.1858457 | Q5: 7.6098059 | R5: 7.0921929 | S5: 7.845464 | T5: 8.6321407 | U5: 9.3167901 | V5: 10.055742 | W5: 9.7210303 | X5: 9.7192853 | Y5: 9.7175405 | Z5: 9.7157961 | AA5: markets/nand/dist/20261025_NAND市場模型_v0.1.xlsx｜Mkt!C91:Z91
A6: Kioxia 營收（情境 C） | B6: $B | C6: 1.92 | D6: 2.14 | E6: 2.84 | F6: 3.31 | G6: 5.96 | H6: 10.72 | I6: 14.319786 | J6: 17.646994 | K6: 19.36854 | L6: 20.889333 | M6: 19.879002 | N6: 16.815588 | O6: 9.8959399 | P6: 6.4479488 | Q6: 4.8476808 | R6: 3.8875427 | S6: 4.1303339 | T6: 4.4945496 | U6: 5.0306216 | V6: 5.7349027 | W6: 5.5313594 | X6: 5.5184177 | Y6: 5.5055063 | Z6: 5.492625 | AA6: markets/nand/dist/20261025_NAND市場模型_v0.1.xlsx｜Mkt!C139:Z139
A7: Kioxia 位元（情境 A） | B7: EB | C7: 35.545444 | D7: 33.356174 | E7: 38.303462 | F7: 36.611793 | G7: 38.133315 | H7: 40.175758 | I7: 46.666796 | J7: 48.944548 | K7: 52.360098 | L7: 55.364063 | M7: 58.540369 | N7: 61.898904 | O7: 65.450123 | P7: 69.205079 | Q7: 73.175462 | R7: 77.37363 | S7: 80.432143 | T7: 84.454249 | U7: 88.677485 | V7: 93.111909 | W7: 94.004556 | X7: 97.135866 | Y7: 100.37148 | Z7: 103.71487 | AA7: markets/nand/dist/20261025_NAND市場模型_v0.1.xlsx｜Mkt!C47:Z47
A8: Kioxia 位元（情境 B） | B8: EB | C8: 35.545444 | D8: 33.356174 | E8: 38.303462 | F8: 36.611793 | G8: 38.133315 | H8: 40.175758 | I8: 46.666796 | J8: 48.944548 | K8: 51.760676 | L8: 54.730251 | M8: 57.870195 | N8: 61.190281 | O8: 60.772488 | P8: 62.93199 | Q8: 65.168228 | R8: 67.483929 | S8: 71.096653 | T8: 74.500593 | U8: 78.067507 | V8: 81.805196 | W8: 81.650416 | X8: 84.286839 | Y8: 87.008389 | Z8: 89.817816 | AA8: markets/nand/dist/20261025_NAND市場模型_v0.1.xlsx｜Mkt!C95:Z95
A9: Kioxia 位元（情境 C） | B9: EB | C9: 35.545444 | D9: 33.356174 | E9: 38.303462 | F9: 36.611793 | G9: 38.133315 | H9: 40.175758 | I9: 46.666796 | J9: 48.944548 | K9: 51.161254 | L9: 54.096439 | M9: 57.200021 | N9: 60.481658 | O9: 54.758976 | P9: 54.891675 | Q9: 55.024697 | R9: 55.15804 | S9: 58.602861 | T9: 60.733812 | U9: 62.942249 | V9: 65.23099 | W9: 64.958969 | X9: 66.911559 | Y9: 68.922841 | Z9: 70.994581 | AA9: markets/nand/dist/20261025_NAND市場模型_v0.1.xlsx｜Mkt!C143:Z143
A10: Kioxia＋SanDisk 合資群份額（情境 A） | B10: % | C10: 0.27907731 | D10: 0.25560769 | E10: 0.27406433 | F10: 0.2689697 | G10: 0.27096015 | H10: 0.25018083 | I10: 0.26205287 | J10: 0.26205287 | K10: 0.26205287 | L10: 0.26205287 | M10: 0.26205287 | N10: 0.26205287 | O10: 0.26205287 | P10: 0.26205287 | Q10: 0.26205287 | R10: 0.26205287 | S10: 0.26205287 | T10: 0.26205287 | U10: 0.26205287 | V10: 0.26205287 | W10: 0.26205287 | X10: 0.26205287 | Y10: 0.26205287 | Z10: 0.26205287 | AA10: markets/nand/dist/20261025_NAND市場模型_v0.1.xlsx｜Mkt!C46:Z46
A11: Kioxia＋SanDisk 合資群份額（情境 B） | B11: % | C11: 0.27907731 | D11: 0.25560769 | E11: 0.27406433 | F11: 0.2689697 | G11: 0.27096015 | H11: 0.25018083 | I11: 0.26205287 | J11: 0.26205287 | K11: 0.25905287 | L11: 0.25905287 | M11: 0.25905287 | N11: 0.25905287 | O11: 0.25605287 | P11: 0.25605287 | Q11: 0.25605287 | R11: 0.25605287 | S11: 0.25305287 | T11: 0.25305287 | U11: 0.25305287 | V11: 0.25305287 | W11: 0.25005287 | X11: 0.25005287 | Y11: 0.25005287 | Z11: 0.25005287 | AA11: markets/nand/dist/20261025_NAND市場模型_v0.1.xlsx｜Mkt!C94:Z94
A12: Kioxia＋SanDisk 合資群份額（情境 C） | B12: % | C12: 0.27907731 | D12: 0.25560769 | E12: 0.27406433 | F12: 0.2689697 | G12: 0.27096015 | H12: 0.25018083 | I12: 0.26205287 | J12: 0.26205287 | K12: 0.25605287 | L12: 0.25605287 | M12: 0.25605287 | N12: 0.25605287 | O12: 0.25005287 | P12: 0.25005287 | Q12: 0.25005287 | R12: 0.25005287 | S12: 0.24405287 | T12: 0.24405287 | U12: 0.24405287 | V12: 0.24405287 | W12: 0.23805287 | X12: 0.23805287 | Y12: 0.23805287 | Z12: 0.23805287 | AA12: markets/nand/dist/20261025_NAND市場模型_v0.1.xlsx｜Mkt!C142:Z142

Sheet PL
A1: PL — Kioxia 損益（¥B；FY2025 實績；FY2026＝第一季實績＋第二季指引＋第三、四季推導；FY2027–FY2029 由市場層 markets/nand 驅動；FY2030–FY2032 收斂法見底部）
A3: 情境／項目 | B3: 單位 | C3: FY2025A | D3: FY2026 | E3: FY2027 | F3: FY2028 | G3: FY2029 | H3: 說明
A4: 情境 A（順利）
A5: 營收 | B5: ¥B | C5: =C55 -> 2337.6 | D5: =D55 -> 10271.368 | E5: =E55 -> 13504.346 | F5: =F55 -> 13616.69 | G5: =G55 -> 14247.994
A6: 毛利率 | B6: % | C6: =C57 -> 0.43326489 | D6: =D57 -> 0.83461657 | E6: =E57 -> 0.86131944 | F6: =F57 -> 0.85278912 | G6: =G57 -> 0.85470626
A7: 營業利益 | B7: ¥B | C7: =C59 -> 869 | D7: =D59 -> 8235.8498 | E7: =E59 -> 11291.168 | F7: =F59 -> 11250.12 | G7: =G59 -> 11786.904
A8: 營業利益率 | B8: % | C8: =C60 -> 0.3717488 | D8: =D60 -> 0.80182596 | E8: =E60 -> 0.83611367 | F8: =F60 -> 0.82620078 | G8: =G60 -> 0.82726759
A9: 淨利 | B9: ¥B | C9: =C61 -> 554.5 | D9: =D61 -> 5543.9096 | E9: =E61 -> 7663.3049 | F9: =F61 -> 7676.2645 | G9: =G61 -> 8082.2201
A10: EPS | B10: JPY | C10: =C69 -> 341.4 | D10: =D69 -> 3491.5112 | E10: =E69 -> 5213.0769 | F10: =F69 -> 5677.6981 | G10: =G69 -> 6583.6244
A11: 每股淨值 | B11: JPY | D11: =D70 -> 3934.9622 | E11: =E70 -> 8490.6974 | F11: =F70 -> 13859.618 | G11: =G70 -> 20643.44
A12: 自由現金流 | B12: ¥B | D12: =D64 -> 5413.9096 | E12: =E64 -> 7513.3049 | F12: =F64 -> 7526.2645 | G12: =G64 -> 7932.2201
A14: 情境 B（平平）
A15: 營收 | B15: ¥B | C15: =C91 -> 2337.6 | D15: =D91 -> 10296.2 | E15: =E91 -> 11553.093 | F15: =F91 -> 5230.9636 | G15: =G91 -> 6218.7584
A16: 毛利率 | B16: % | C16: =C93 -> 0.43326489 | D16: =D93 -> 0.83477314 | E16: =E93 -> 0.83811592 | F16: =F93 -> 0.64233494 | G16: =G93 -> 0.68616158
A17: 營業利益 | B17: ¥B | C17: =C95 -> 869 | D17: =D95 -> 8257.9388 | E17: =E95 -> 9361.9568 | F17: =F95 -> 3081.8427 | G17: =G95 -> 3956.4194
A18: 營業利益率 | B18: % | C18: =C96 -> 0.3717488 | D18: =D96 -> 0.8020375 | E18: =E96 -> 0.81034199 | F18: =F96 -> 0.58915393 | G18: =G96 -> 0.63620729
A19: 淨利 | B19: ¥B | C19: =C97 -> 554.5 | D19: =D97 -> 5558.9301 | E19: =E97 -> 6351.5227 | F19: =F97 -> 2114.7815 | G19: =G97 -> 2720.182
A20: EPS | B20: JPY | C20: =C105 -> 341.4 | D20: =D105 -> 3501.4903 | E20: =E105 -> 4261.7685 | F20: =F105 -> 1448.9359 | G20: =G105 -> 1916.6466
A21: 每股淨值 | B21: JPY | D21: =D106 -> 3943.1978 | E21: =E106 -> 7669.973 | F21: =F106 -> 9026.4216 | G21: =G106 -> 10857.807
A22: 自由現金流 | B22: ¥B | D22: =D100 -> 5428.9301 | E22: =E100 -> 6201.5227 | F22: =F100 -> 1964.7815 | G22: =G100 -> 2570.182
A24: 情境 C（不如預期）
A25: 營收 | B25: ¥B | C25: =C127 -> 2337.6 | D25: =D127 -> 10258.793 | E25: =E127 -> 11123.476 | F25: =F127 -> 3183.6657 | G25: =G127 -> 3427.2893
A26: 毛利率 | B26: % | C26: =C129 -> 0.43326489 | D26: =D129 -> 0.83394874 | E26: =E129 -> 0.83330157 | F26: =F129 -> 0.48260457 | G26: =G129 -> 0.50912407
A27: 營業利益 | B27: ¥B | C27: =C131 -> 869 | D27: =D131 -> 8218.6289 | E27: =E131 -> 8952.6316 | F27: =F131 -> 1278.7367 | G27: =G131 -> 1462.1765
A28: 營業利益率 | B28: % | C28: =C132 -> 0.3717488 | D28: =D132 -> 0.80113019 | E28: =E132 -> 0.80484117 | F28: =F132 -> 0.40165546 | G28: =G132 -> 0.42662768
A29: 淨利 | B29: ¥B | C29: =C133 -> 554.5 | D29: =D133 -> 5532.1994 | E29: =E133 -> 6073.0362 | F29: =F133 -> 887.009 | G29: =G133 -> 1015.7574
A30: EPS | B30: JPY | C30: =C141 -> 341.4 | D30: =D141 -> 3483.7333 | E30: =E141 -> 4061.865 | F30: =F141 -> 597.88476 | G30: =G141 -> 690.98984
A31: 每股淨值 | B31: JPY | D31: =D142 -> 3928.5433 | E31: =E142 -> 7480.0806 | F31: =F142 -> 8042.9373 | G31: =G142 -> 8697.5262
A32: 自由現金流 | B32: ¥B | D32: =D136 -> 5402.1994 | E32: =E136 -> 5923.0362 | F32: =F136 -> 737.009 | G32: =G136 -> 865.75738
A34: 核對：三情境 FY2025、第一季、第二季 − 實績與指引（應為 0） | D34: =D73+D109+D145 -> 0
A40: 情境 A（順利）：markets/nand 情境 A（價格路徑 A、2028–29 顆數係數 A、合資群份額 A）；每位元成本年降 cd_A
A41: A. 季度 | B41: 單位 | C41: FY26 第1季（2026Q2） | D41: FY26 第2季（2026Q3） | E41: FY26 第3季（2026Q4） | F41: FY26 第4季（2027Q1） | G41: FY27 第1季（2027Q2） | H41: FY27 第2季（2027Q3） | I41: FY27 第3季（2027Q4） | J41: FY27 第4季（2028Q1） | K41: FY28 第1季（2028Q2） | L41: FY28 第2季（2028Q3） | M41: FY28 第3季（2028Q4） | N41: FY28 第4季（2029Q1） | O41: FY29 第1季（2029Q2） | P41: FY29 第2季（2029Q3） | Q41: FY29 第3季（2029Q4） | R41: FY29 第4季（2030Q1） | T41: 說明
A42: 市場層營收（TrendForce 口徑，美元，同字母情境） | B42: $B | C42: =Units!H4*1 -> 10.72 | D42: =Units!I4*1 -> 14.319786 | E42: =Units!J4*1*1 -> 17.646994 | F42: =Units!K4*1*1 -> 19.444827 | G42: =Units!L4*1*1 -> 20.560401 | H42: =Units!M4*1*1 -> 20.652979 | I42: =Units!N4*1*1 -> 20.309216 | J42: =Units!O4*1*1 -> 20.400662 | K42: =Units!P4*1*1 -> 20.49252 | L42: =Units!Q4*1*1 -> 20.584792 | ... R42: =Units!W4*1*1 -> 21.540765 | T42: markets/nand；Sens 可乘份額係數、價格係數（第三季起）
A43: 位元（市場層；同字母） | B43: EB | C43: =Units!H7*1 -> 40.175758 | D43: =Units!I7*1 -> 46.666796 | E43: =Units!J7*1 -> 48.944548 | F43: =Units!K7*1 -> 52.360098 | G43: =Units!L7*1 -> 55.364063 | H43: =Units!M7*1 -> 58.540369 | I43: =Units!N7*1 -> 61.898904 | J43: =Units!O7*1 -> 65.450123 | ... R43: =Units!W7*1 -> 94.004556
A44: 營收 | B44: ¥B | C44: =q1_rev -> 1767.1 | D44: =g2_rev -> 2390 | E44: =E42*kx_k*fx -> 2908.9555 | F44: =F42*kx_k*fx -> 3205.3129 | G44: =G42*kx_k*fx -> 3389.2057 | H44: =H42*kx_k*fx -> 3404.4663 | I44: =I42*kx_k*fx -> 3347.7999 | J44: =J42*kx_k*fx -> 3362.874 | K44: =K42*kx_k*fx -> 3378.0161 | L44: =L42*kx_k*fx -> 3393.2263 | ... R44: =R42*kx_k*fx -> 3550.8102 | T44: 第一季實績、第二季公司指引；之後＝市場層 × 公司口徑係數 × 匯率
A45: 每 EB 營業成本（第二季以指引校準，之後每年 × (1 − 成本年降)） | B45: ¥B/EB | C45: =C46/C43 -> 9.6326745 | D45: =D46/D43 -> 9.2142602 | E45: =$D45*(1-cd_A)^(1/4) -> 8.8732984 | F45: =$D45*(1-cd_A)^(2/4) -> 8.5449534 | G45: =$D45*(1-cd_A)^(3/4) -> 8.2287584 | H45: =$D45*(1-cd_A)^(4/4) -> 7.9242638 | I45: =$D45*(1-cd_A)^(5/4) -> 7.6310366 | J45: =$D45*(1-cd_A)^(6/4) -> 7.3486599 | K45: =$D45*(1-cd_A)^(7/4) -> 7.0767322 | L45: =$D45*(1-cd_A)^(8/4) -> 6.8148669 | M45: =$D45*(1-cd_A)^(9/4) -> 6.5626915 | N45: =$D45*(1-cd_A)^(10/4) -> 6.3198475 | O45: =$D45*(1-cd_A)^(11/4) -> 6.0859897 | P45: =$D45*(1-cd_A)^(12/4) -> 5.8607855 | Q45: =$D45*(1-cd_A)^(13/4) -> 5.6439147 | R45: =$D45*(1-cd_A)^(14/4) -> 5.4350689
A46: 營業成本 | B46: ¥B | C46: =q1_rev-q1_gp -> 387 | D46: =g2_rev-g2_op-g2_ox -> 430 | E46: =E43*E45 -> 434.29958 | F46: =F43*F45 -> 447.4146 | G46: =G43*G45 -> 455.5775 | H46: =H43*H45 -> 463.88933 | I46: =I43*I45 -> 472.3528 | J46: =J43*J45 -> 480.97069 | K46: =K43*K45 -> 489.74581 | L46: =L43*L45 -> 498.68103 | ... R46: =R43*R45 -> 510.92124 | T46: 第二季＝指引營收 − 指引營業利益 − 推估營業費用
A47: 毛利率 | B47: % | C47: =1-C46/C44 -> 0.78099711 | D47: =1-D46/D44 -> 0.82008368 | E47: =1-E46/E44 -> 0.85070257 | F47: =1-F46/F44 -> 0.86041469 | G47: =1-G46/G44 -> 0.86557986 | H47: =1-H46/H44 -> 0.86374095 | I47: =1-I46/I44 -> 0.8589065 | J47: =1-J46/J44 -> 0.8569763 | ... R47: =1-R46/R44 -> 0.85611136
A48: 營業費用 | B48: ¥B | C48: =q1_gp-q1_op -> 110.1 | D48: =g2_ox -> 70 | E48: =(g2_ox-ox_var*g2_rev)*(1+ox_g)^(1/4)+ox_var*E44 -> 76.301196 | F48: =(g2_ox-ox_var*g2_rev)*(1+ox_g)^(2/4)+ox_var*F44 -> 80.403217 | G48: =(g2_ox-ox_var*g2_rev)*(1+ox_g)^(3/4)+ox_var*G44 -> 83.408044 | H48: =(g2_ox-ox_var*g2_rev)*(1+ox_g)^(4/4)+ox_var*H44 -> 84.754663 | I48: =(g2_ox-ox_var*g2_rev)*(1+ox_g)^(5/4)+ox_var*I44 -> 85.410804 | J48: =(g2_ox-ox_var*g2_rev)*(1+ox_g)^(6/4)+ox_var*J44 -> 86.813837 | K48: =(g2_ox-ox_var*g2_rev)*(1+ox_g)^(7/4)+ox_var*K44 -> 88.247746 | L48: =(g2_ox-ox_var*g2_rev)*(1+ox_g)^(8/4)+ox_var*L44 -> 89.713263 | M48: =(g2_ox-ox_var*g2_rev)*(1+ox_g)^(9/4)+ox_var*M44 -> 91.211135 | N48: =(g2_ox-ox_var*g2_rev)*(1+ox_g)^(10/4)+ox_var*N44 -> 92.873036 | O48: =(g2_ox-ox_var*g2_rev)*(1+ox_g)^(11/4)+ox_var*O44 -> 94.919815 | P48: =(g2_ox-ox_var*g2_rev)*(1+ox_g)^(12/4)+ox_var*P44 -> 97.012383 | Q48: =(g2_ox-ox_var*g2_rev)*(1+ox_g)^(13/4)+ox_var*Q44 -> 99.151777 | R48: =(g2_ox-ox_var*g2_rev)*(1+ox_g)^(14/4)+ox_var*R44 -> 99.862069 | T48: 固定部分以第二季校準（Derived）
A49: 營業利益 | B49: ¥B | C49: =C44-C46-C48 -> 1270 | D49: =D44-D46-D48 -> 1890 | E49: =E44-E46-E48 -> 2398.3547 | F49: =F44-F46-F48 -> 2677.4951 | G49: =G44-G46-G48 -> 2850.2202 | H49: =H44-H46-H48 -> 2855.8223 | I49: =I44-I46-I48 -> 2790.0363 | J49: =J44-J46-J48 -> 2795.0895 | ... R49: =R44-R46-R48 -> 2940.0269
...

Sheet Val
A1: Val — 估值。第 0 節為目標價（DCF 與 Comparable 加權；Comparable 依記憶體慣例用前瞻 P/B）；第 5–6 節為目前倍數、十年倍數與規則值（舊法參考）
A2: Kioxia 2024-12 上市，只有兩個年底：十年 P/B、P/E 以美光（同為記憶體循環股）為 Analogy，見第 6 節。每股數字皆為 2026-10-01 一股分三股後
A4: 0. 目標價
A5: 0.1 DCF（股東權益現金流，FY2027–FY2032 明確期＋FY2032 後永續）
A6: 項目 | B6: A（順利） | C6: B（平平） | D6: C（不如預期） | E6: 說明
A7: 情境 EPS（FY2027–FY2032） | E7: PL 頁延伸區塊；FY2030 起為收斂法（灰底）
A8: FY2027 | B8: =PL!D156 -> 5213.0769 | C8: =PL!D163 -> 4261.7685 | D8: =PL!D170 -> 4061.865
A9: FY2028 | B9: =PL!E156 -> 5677.6981 | C9: =PL!E163 -> 1448.9359 | D9: =PL!E170 -> 597.88476
A10: FY2029 | B10: =PL!F156 -> 6583.6244 | C10: =PL!F163 -> 1916.6466 | D10: =PL!F170 -> 690.98984
A11: FY2030 | B11: =PL!G156 -> 5327.8954 | C11: =PL!G163 -> 1699.6401 | D11: =PL!G170 -> 583.65344
A12: FY2031 | B12: =PL!H156 -> 3944.2377 | C12: =PL!H163 -> 1324.7396 | D12: =PL!H170 -> 453.41189
A13: FY2032 | B13: =PL!I156 -> 2401.0335 | C13: =PL!I163 -> 829.43228 | D13: =PL!I170 -> 306.51067
A14: 股東現金流＝EPS ×（1 − tp_g ÷ tp_roe） | E14: 記憶體資本密集：FY2027–FY2029 改用每股（淨利＋折舊－資本支出）＝ PL 區塊每股自由現金流；收斂期（FY2030 起）用 EPS ×（1 − 再投資率）
A15: 再投資率（tp_g ÷ tp_roe，上限 0.8；FY2030 起用） | B15: =MIN(tp_g/tp_roe,0.8) -> 0.10447316 | E15: ROE 為 FY2024–FY2025 平均（In 頁 tp_roe）
A16: FY2027（淨利＋折舊－資本支出，每股） | B16: =PL!E72 -> 5111.0372 | C16: =PL!E108 -> 4161.1209 | D16: =PL!E144 -> 3961.5396
A17: FY2028（淨利＋折舊－資本支出，每股） | B17: =PL!F72 -> 5566.7516 | C17: =PL!F108 -> 1346.1639 | D17: =PL!F144 -> 496.77788
A18: FY2029（淨利＋折舊－資本支出，每股） | B18: =PL!G72 -> 6461.4372 | C18: =PL!G108 -> 1810.9562 | D18: =PL!G144 -> 588.94926
A19: FY2030（EPS ×（1 − 再投資率）） | B19: =B11*(1-$B$15) -> 4771.2734 | C19: =C11*(1-$B$15) -> 1522.0733 | D19: =D11*(1-$B$15) -> 522.67732
A20: FY2031（EPS ×（1 − 再投資率）） | B20: =B12*(1-$B$15) -> 3532.1707 | C20: =C12*(1-$B$15) -> 1186.3399 | D20: =D12*(1-$B$15) -> 406.04251
A21: FY2032（EPS ×（1 − 再投資率）） | B21: =B13*(1-$B$15) -> 2150.1899 | C21: =C13*(1-$B$15) -> 742.77886 | D21: =D13*(1-$B$15) -> 274.48853
A22: DCF 情境每股價值（折現率 tp_r） | B22: =MAX(0,SUMPRODUCT(B16:B21,1/(1+tp_r)^{1;2;3;4;5;6})+B21*(1+tp_g)/(tp_r-tp_g)/(1+tp_r)^6) -> 41805.282 | C22: =MAX(0,SUMPRODUCT(C16:C21,1/(1+tp_r)^{1;2;3;4;5;6})+C21*(1+tp_g)/(tp_r-tp_g)/(1+tp_r)^6) -> 15718.975 | D22: =MAX(0,SUMPRODUCT(D16:D21,1/(1+tp_r)^{1;2;3;4;5;6})+D21*(1+tp_g)/(tp_r-tp_g)/(1+tp_r)^6) -> 7904.1586 | E22: Σ 明確期現金流 ÷ (1＋r)^t ＋ 永續價值 ÷ (1＋r)^6；永續價值＝FY2032 現金流 ×(1＋g)÷(r−g)；基準日 2026 年底，t＝1 對 FY2027（2027-04～2028-03，t 以會計年度計，略低估）；FY2026 剩餘一季的現金流未計入；負值取 0
A23: DCF 情境價值推到 12 個月後（×(1＋tp_r)） | B23: =B22*(1+tp_r) -> 45985.81 | C23: =C22*(1+tp_r) -> 17290.873 | D23: =D22*(1+tp_r) -> 8694.5744
A24: DCF 目標價（情境加權） | B24: =tp_wA*B23+tp_wB*C23+tp_wC*D23 -> 24180.094 | E24: Σ 權重 × 情境價值 ×(1＋r)；權重見 In 頁 tp_wA／tp_wB／tp_wC
A26: 0.2 Comparable（市場主流同業前瞻 P/B；記憶體慣例）
A27: 同業與前瞻 P/B | B27: 代號 | C27: 前瞻 P/B | D27: 日期 | E27: 來源 | F27: 標記
A28: 美光 | B28: MU | C28: 3.35 | D28: 2026-10-23 | E28: MarketScreener：現價 ÷ FY2027E（2027-09）每股淨值（micron/ 模型同值） | F28: Interested-party
A29: SK 海力士 | B29: 000660.KS | C29: 1.35 | D29: 2026-10-23 | E29: MarketScreener：現價 ÷ 2027E 每股淨值（skhynix/ 模型同值） | F29: Interested-party
A30: 三星電子 | B30: 005930.KS | C30: 1.26 | D30: 2026-10-23 | E30: MarketScreener：現價 ÷ 2027E 每股淨值（samsung/ 模型同值） | F30: Interested-party
A31: SanDisk | B31: SNDK | C31: =1238.03/((313.8+553.1)/2) -> 2.8562233 | D31: 2026-10-23 | E31: 現價 1,238.03 ÷ MarketScreener 約 2027 年底每股淨值（FY2027、FY2028 年底平均；sndk/ 模型同口徑） | F31: Interested-party
A32: 同業前瞻 P/B 中位數 | B32: =MEDIAN(C28:C31) -> 2.1031117 | E32: 記憶體同業（美光、SK 海力士、三星、SanDisk；無 A 股）。WDC（硬碟）不列入 P/B（僅有落後 P/B），P/E 並列參考見下方。Kioxia 自身現價 ÷ FY2027 年底（2028-03）共識每股淨值 1.63x（sndk/ 同業表同值）
A33: 12 個月後的前瞻每股淨值（情境加權） | B33: =tp_wA*(0.25*PL!E70+0.75*PL!F70)+tp_wB*(0.25*PL!E106+0.75*PL!F106)+tp_wC*(0.25*PL!E142+0.75*PL!F142) -> 9679.3156 | E33: 同業倍數＝現價 ÷ 約 14 個月後（約 2027 年底）每股淨值；對應 12 個月後（約 2027-10）用約 2028 年底每股淨值＝¼ × FY2027 年底（2028-03）＋¾ × FY2028 年底（2029-03）（會計年度 3 月，依月份調整）
A34: Comparable 目標價 | B34: =B32*B33 -> 20356.682 | E34: 同業中位數 × 前瞻每股淨值
A35: 12 個月後的前瞻 EPS（情境加權） | B35: =tp_wA*(5/12*B8+7/12*B9)+tp_wB*(5/12*C8+7/12*C9)+tp_wC*(5/12*D8+7/12*D9) -> 3363.9485 | E35: 約 2027-10 時的未來 12 月（2027-11～2028-10）≈ 5／12 × FY2027（2027-04～2028-03）＋7／12 × FY2028（會計年度 3 月，依月份調整）
A37: 並列參考：同業前瞻 P/E（不進目標價）
A38: 同業與前瞻 P/E | B38: 代號 | C38: 前瞻 P/E | D38: 日期 | E38: 來源 | F38: 標記
A39: 美光 | B39: MU | C39: =877.55/173 -> 5.0725434 | D39: 2026-10-23 | E39: 現價 877.55 ÷ MarketScreener FY2027 共識 EPS 173（micron/ 模型 In 頁） | F39: Interested-party
A40: SK 海力士 | B40: 000660.KS | C40: =1277000/475721 -> 2.6843465 | D40: 2026-10-23 | E40: 現價 ÷ MarketScreener 2027 共識 EPS（skhynix/ 模型 In 頁） | F40: Interested-party
A41: 三星電子 | B41: 005930.KS | C41: =215500/72279 -> 2.9815022 | D41: 2026-10-23 | E41: 現價 ÷ MarketScreener 2027 共識 EPS（samsung/ 模型 In 頁） | F41: Interested-party
A42: SanDisk | B42: SNDK | C42: =1238.03/217.4 -> 5.6947102 | D42: 2026-10-23 | E42: 現價 1,238.03 ÷ MarketScreener FY2027（2027-06）共識 EPS 217.4 | F42: Interested-party
A43: Western Digital | B43: WDC | C43: 11.91 | D43: 2026-10-23 | E43: stockanalysis 統計頁 Forward P/E（硬碟為主，參考） | F43: Interested-party
...

Sheet Recon
A1: Recon — 本模型 vs 公司實績、指引與共識（共識只作對照，未用於校準）。差距＝模型 ÷ 對照 − 1（百分點列為相減）
A3: 項目 | B3: 對照值 | C3: 模型 A | D3: 差距 A | E3: 模型 B | F3: 差距 B | G3: 模型 C | H3: 差距 C | I3: 對照來源 | J3: 說明
A4: A. 實績與公司指引
A5: FY2025 營收（四季合計）vs 公司 2,337.6 | B5: 2337.6 | C5: =PL!C5 -> 2337.6 | D5: =C5/B5-1 -> 0 | E5: =PL!C15 -> 2337.6 | F5: =E5/B5-1 -> 0 | G5: =PL!C25 -> 2337.6 | H5: =G5/B5-1 -> 0 | I5: storagenewsletter 轉載 FY25 決算；MarketScreener
A6: FY2026 上半營收 vs 公司指引 4,157.1 | B6: 4157.1 | C6: =PL!C44+PL!D44 -> 4157.1 | D6: =C6/B6-1 -> 0 | E6: =PL!C80+PL!D80 -> 4157.1 | F6: =E6/B6-1 -> 0 | G6: =PL!C116+PL!D116 -> 4157.1 | H6: =G6/B6-1 -> 0 | I6: Kioxia FY2026 第一季財報（2026-07-31） | J6: 恆等式
A7: FY2026 第三季營收（推導）vs 第二季指引（季增） | B7: =g2_rev -> 2390 | C7: =PL!E44 -> 2908.9555 | D7: =C7/B7-1 -> 0.21713619 | E7: =PL!E80 -> 2908.9555 | F7: =E7/B7-1 -> 0.21713619 | G7: =PL!E116 -> 2908.9555 | H7: =G7/B7-1 -> 0.21713619 | I7: 公司第二季指引 | J7: 市場層 2026Q4 季價 +17.5%（markets/memory）
A8: FY2026 第二季毛利率（校準值）vs 第一季（百分點） | B8: =q1_gp/q1_rev -> 0.78099711 | C8: =PL!D47 -> 0.82008368 | D8: =C8-B8 -> 0.039086568 | E8: =PL!D83 -> 0.82008368 | F8: =E8-B8 -> 0.039086568 | G8: =PL!D119 -> 0.82008368 | H8: =G8-B8 -> 0.039086568 | I8: Kioxia FY2026 第一季財報（2026-07-31） | J8: 第二季營業費用為 Assumed（g2_ox）
A9: B. 共識（MarketScreener 2026-10-25 擷取；只作參考）
A10: FY2026 營收 vs 共識 | B10: =cons_rev26 -> 10071.4 | C10: =PL!D5 -> 10271.368 | D10: =C10/B10-1 -> 0.019855074 | E10: =PL!D15 -> 10296.2 | F10: =E10/B10-1 -> 0.022320661 | G10: =PL!D25 -> 10258.793 | H10: =G10/B10-1 -> 0.018606464 | I10: MarketScreener 預估頁（2026-10-25 擷取；頁面為 10-16 收盤；會計年度 3 月；每股數字已依分割調整，股數 1,644 百萬股）
A11: FY2026 淨利 vs 共識 | B11: =cons_ni26 -> 5573.9 | C11: =PL!D9 -> 5543.9096 | D11: =C11/B11-1 -> -0.0053805017 | E11: =PL!D19 -> 5558.9301 | F11: =E11/B11-1 -> -0.0026857085 | G11: =PL!D29 -> 5532.1994 | H11: =G11/B11-1 -> -0.0074813991 | I11: MarketScreener 預估頁（2026-10-25 擷取；頁面為 10-16 收盤；會計年度 3 月；每股數字已依分割調整，股數 1,644 百萬股）
A12: FY2026 EPS vs 共識 | B12: =cons_eps26 -> 3486 | C12: =PL!D10 -> 3491.5112 | D12: =C12/B12-1 -> 0.0015809424 | E12: =PL!D20 -> 3501.4903 | F12: =E12/B12-1 -> 0.0044435867 | G12: =PL!D30 -> 3483.7333 | H12: =G12/B12-1 -> -0.00065022494 | I12: MarketScreener 預估頁（2026-10-25 擷取；頁面為 10-16 收盤；會計年度 3 月；每股數字已依分割調整，股數 1,644 百萬股） | J12: 差距超過 30% 見 README
A13: FY2027 營收 vs 共識 | B13: =cons_rev27 -> 13477.2 | C13: =PL!E5 -> 13504.346 | D13: =C13/B13-1 -> 0.0020142168 | E13: =PL!E15 -> 11553.093 | F13: =E13/B13-1 -> -0.14276753 | G13: =PL!E25 -> 11123.476 | H13: =G13/B13-1 -> -0.17464486 | I13: MarketScreener 預估頁（2026-10-25 擷取；頁面為 10-16 收盤；會計年度 3 月；每股數字已依分割調整，股數 1,644 百萬股）
A14: FY2027 EPS vs 共識 | B14: =cons_eps27 -> 4871 | C14: =PL!E10 -> 5213.0769 | D14: =C14/B14-1 -> 0.070227245 | E14: =PL!E20 -> 4261.7685 | F14: =E14/B14-1 -> -0.12507319 | G14: =PL!E30 -> 4061.865 | H14: =G14/B14-1 -> -0.16611271 | I14: MarketScreener 預估頁（2026-10-25 擷取；頁面為 10-16 收盤；會計年度 3 月；每股數字已依分割調整，股數 1,644 百萬股）
A15: FY2028 EPS vs 共識 | B15: =cons_eps28 -> 5467 | C15: =PL!F10 -> 5677.6981 | D15: =C15/B15-1 -> 0.038539987 | E15: =PL!F20 -> 1448.9359 | F15: =E15/B15-1 -> -0.73496691 | G15: =PL!F30 -> 597.88476 | H15: =G15/B15-1 -> -0.8906375 | I15: MarketScreener 預估頁（2026-10-25 擷取；頁面為 10-16 收盤；會計年度 3 月；每股數字已依分割調整，股數 1,644 百萬股）
A16: FY2027 年底每股淨值 vs 共識 | B16: =cons_bv27 -> 7808 | C16: =PL!E11 -> 8490.6974 | D16: =C16/B16-1 -> 0.087435625 | E16: =PL!E21 -> 7669.973 | F16: =E16/B16-1 -> -0.017677636 | G16: =PL!E31 -> 7480.0806 | H16: =G16/B16-1 -> -0.041997873 | I16: MarketScreener 預估頁（2026-10-25 擷取；頁面為 10-16 收盤；會計年度 3 月；每股數字已依分割調整，股數 1,644 百萬股）
A17: C. 市場層一致性
A18: Kioxia 營收 ÷ 市場層（公司口徑係數 kx_k） | C18: =kx_k -> 1.0302589 | I18: In 頁
A19: Kioxia＋SanDisk 合資群份額 CY2027（市場層 Ann 頁，A／B／C） | C19: 0.26205287 | E19: 0.25905287 | G19: 0.25605287 | I19: markets/nand/dist/20261025_NAND市場模型_v0.1.xlsx｜Ann!F27（sndk/ 模型讀同一組列）

Sheet Sens
A1: Sens — 一次動一個輸入（情境 A）：對 FY2027、FY2028 營收與 EPS 的影響。每個案例為一個完整推導區塊（本頁下方，與 PL 同一引擎）
A3: 案例 | B3: 設定 | C3: FY2027 營收 ¥B | D3: FY2027 EPS | E3: 相對基準 | F3: FY2028 營收 ¥B | G3: FY2028 EPS | H3: 相對基準 | I3: FY2027 毛利率
A4: 基準（情境 A） | B4: PL 區塊 A | C4: =PL!E55 -> 13504.346 | D4: =PL!E69 -> 5213.0769 | E4: =D4/D$4-1 -> 0 | F4: =PL!F55 -> 13616.69 | G4: =PL!F69 -> 5677.6981 | H4: =G4/G$4-1 -> 0 | I4: =PL!E57 -> 0.86131944
A5: 市場層營收 −20%（價格；第三季起） | B5: 價格係數 0.8 | C5: =E75 -> 10803.477 | D5: =E89 -> 3864.0987 | E5: =D5/D$4-1 -> -0.25876814 | F5: =F75 -> 10893.352 | G5: =F89 -> 4097.4803 | H5: =G5/G$4-1 -> -0.27832015 | I5: =E77 -> 0.82664929
A6: 市場層營收 +20%（價格） | B6: 價格係數 1.2 | C6: =E125 -> 16205.215 | D6: =E139 -> 6640.4114 | E6: =D6/D$4-1 -> 0.27379886 | F6: =F125 -> 16340.028 | G6: =F139 -> 7431.6821 | H6: =G6/G$4-1 -> 0.3089252 | I6: =E127 -> 0.88443286
A7: 份額 ×0.9（營收與位元） | B7: 份額係數 0.9 | C7: =E175 -> 12153.911 | D7: =E189 -> 4529.2022 | E7: =D7/D$4-1 -> -0.13118448 | F7: =F175 -> 12255.021 | G7: =F189 -> 4867.5233 | H7: =G7/G$4-1 -> -0.14269424 | I7: =E177 -> 0.84591048
A8: 份額 ×1.1 | B8: 份額係數 1.1 | C8: =E225 -> 14854.781 | D8: =E239 -> 5916.529 | E8: =D8/D$4-1 -> 0.13493991 | F8: =F225 -> 14978.359 | G8: =F239 -> 6531.2259 | H8: =G8/G$4-1 -> 0.1503299 | I8: =E227 -> 0.87392676
A9: 匯率 145 日圓 | B9: fx 低 | C9: =E275 -> 12238.314 | D9: =E289 -> 4571.3862 | E9: =D9/D$4-1 -> -0.1230925 | F9: =F275 -> 12340.126 | G9: =F289 -> 4916.9517 | H9: =G9/G$4-1 -> -0.13398852 | I9: =E277 -> 0.84697317
A10: 匯率 170 日圓 | B10: fx 高 | C10: =E325 -> 14348.368 | D10: =E339 -> 5650.3872 | E10: =D10/D$4-1 -> 0.083887173 | F10: =F325 -> 14467.733 | G10: =F339 -> 6205.8539 | H10: =G10/G$4-1 -> 0.093022865 | I10: =E327 -> 0.86947712
A11: 每位元成本年降 10%（C 的值） | B11: cd_C | C11: =E375 -> 13504.346 | D11: =E389 -> 5162.9908 | E11: =D11/D$4-1 -> -0.0096077911 | F11: =F375 -> 13616.69 | G11: =F389 -> 5560.8523 | H11: =G11/G$4-1 -> -0.020579777 | I11: =E377 -> 0.8539928
A12: 每位元成本年降 18% | B12: cd_A 高 | C12: =E425 -> 13504.346 | D12: =E439 -> 5262.8047 | E12: =D12/D$4-1 -> 0.0095390522 | F12: =F425 -> 13616.69 | G12: =F439 -> 5789.1901 | H12: =G12/G$4-1 -> 0.019636838 | I12: =E427 -> 0.86857831
A13: 第二季營業費用 55（校準） | B13: g2_ox 低 | C13: =E475 -> 13504.346 | D13: =E489 -> 5213.8335 | E13: =D13/D$4-1 -> 0.00014514198 | F13: =F475 -> 13616.69 | G13: =F489 -> 5679.7412 | H13: =G13/G$4-1 -> 0.00035983769 | I13: =E477 -> 0.85648174
A14: 第二季營業費用 90 | B14: g2_ox 高 | C14: =E525 -> 13504.346 | D14: =E539 -> 5212.0681 | E14: =D14/D$4-1 -> -0.00019351667 | F14: =F525 -> 13616.69 | G14: =F539 -> 5674.9743 | H14: =G14/G$4-1 -> -0.00047973588 | I14: =E527 -> 0.86776969
A15: 營業費用變動率 2% | B15: ox_var 高 | C15: =E575 -> 13504.346 | D15: =E589 -> 5198.3071 | E15: =D15/D$4-1 -> -0.0028332141 | F15: =F575 -> 13616.69 | G15: =F589 -> 5665.3403 | H15: =G15/G$4-1 -> -0.0021765445 | I15: =E577 -> 0.86131944
A16: 稅率 35% | B16: tax 高 | C16: =E625 -> 13504.346 | D16: =E639 -> 4956.6316 | E16: =D16/D$4-1 -> -0.049192691 | F16: =F625 -> 13616.69 | G16: =F639 -> 5373.5076 | H16: =G16/G$4-1 -> -0.053576385 | I16: =E627 -> 0.86131944
A17: 稅率 28% | B17: tax 低 | C17: =E675 -> 13504.346 | D17: =E689 -> 5559.2897 | E17: =D17/D$4-1 -> 0.066412377 | F17: =F675 -> 13616.69 | G17: =F689 -> 6092.8396 | H17: =G17/G$4-1 -> 0.073117921 | I17: =E677 -> 0.86131944
A18: 股東回饋 ÷ FCF 50% | B18: payout 高 | C18: =E725 -> 13504.346 | D18: =E739 -> 6456.9398 | E18: =D18/D$4-1 -> 0.23860437 | F18: =F725 -> 13616.69 | G18: =F739 -> 8584.5118 | H18: =G18/G$4-1 -> 0.51197045 | I18: =E727 -> 0.86131944
A19: 股東回饋 0 | B19: payout 低 | C19: =E775 -> 13504.346 | D19: =E789 -> 4620.1656 | E19: =D19/D$4-1 -> -0.11373538 | F19: =F775 -> 13616.69 | G19: =F789 -> 4634.1536 | H19: =G19/G$4-1 -> -0.18379712 | I19: =E777 -> 0.86131944
A20: 情境 B | B20: markets/nand B；成本年降 12% | C20: =PL!E91 -> 11553.093 | D20: =PL!E105 -> 4261.7685 | E20: =D20/D$4-1 -> -0.18248502 | F20: =PL!F91 -> 5230.9636 | G20: =PL!F105 -> 1448.9359 | H20: =G20/G$4-1 -> -0.74480223 | I20: =PL!E93 -> 0.83811592
A21: 情境 C | B21: markets/nand C；成本年降 10% | C21: =PL!E127 -> 11123.476 | D21: =PL!E141 -> 4061.865 | E21: =D21/D$4-1 -> -0.22083156 | F21: =PL!F127 -> 3183.6657 | G21: =PL!F141 -> 597.88476 | H21: =G21/G$4-1 -> -0.89469592 | I21: =PL!E129 -> 0.83330157
A23: 讀法：第二季為公司指引（固定），價格與匯率係數只作用在第三季起；營業費用校準改變成本起點（第二季營業成本＝營收 − 營業利益 − 營業費用）。
A60: 案例區塊：市場層營收 −20%（價格；第三季起）（情境 A）
A61: A. 季度 | B61: 單位 | C61: FY26 第1季（2026Q2） | D61: FY26 第2季（2026Q3） | E61: FY26 第3季（2026Q4） | F61: FY26 第4季（2027Q1） | G61: FY27 第1季（2027Q2） | H61: FY27 第2季（2027Q3） | I61: FY27 第3季（2027Q4） | J61: FY27 第4季（2028Q1） | K61: FY28 第1季（2028Q2） | L61: FY28 第2季（2028Q3） | M61: FY28 第3季（2028Q4） | N61: FY28 第4季（2029Q1） | O61: FY29 第1季（2029Q2） | P61: FY29 第2季（2029Q3） | Q61: FY29 第3季（2029Q4） | R61: FY29 第4季（2030Q1） | T61: 說明
A62: 市場層營收（TrendForce 口徑，美元，同字母情境） | B62: $B | C62: =Units!H4*1 -> 10.72 | D62: =Units!I4*1 -> 14.319786 | E62: =Units!J4*1*0.8 -> 14.117595 | F62: =Units!K4*1*0.8 -> 15.555862 | G62: =Units!L4*1*0.8 -> 16.448321 | H62: =Units!M4*1*0.8 -> 16.522383 | I62: =Units!N4*1*0.8 -> 16.247373 | J62: =Units!O4*1*0.8 -> 16.32053 | K62: =Units!P4*1*0.8 -> 16.394016 | L62: =Units!Q4*1*0.8 -> 16.467833 | ... R62: =Units!W4*1*0.8 -> 17.232612 | T62: markets/nand；Sens 可乘份額係數、價格係數（第三季起）
A63: 位元（市場層；同字母） | B63: EB | C63: =Units!H7*1 -> 40.175758 | D63: =Units!I7*1 -> 46.666796 | E63: =Units!J7*1 -> 48.944548 | F63: =Units!K7*1 -> 52.360098 | G63: =Units!L7*1 -> 55.364063 | H63: =Units!M7*1 -> 58.540369 | I63: =Units!N7*1 -> 61.898904 | J63: =Units!O7*1 -> 65.450123 | ... R63: =Units!W7*1 -> 94.004556
A64: 營收 | B64: ¥B | C64: =q1_rev -> 1767.1 | D64: =g2_rev -> 2390 | E64: =E62*kx_k*fx -> 2327.1644 | F64: =F62*kx_k*fx -> 2564.2503 | G64: =G62*kx_k*fx -> 2711.3646 | H64: =H62*kx_k*fx -> 2723.5731 | I64: =I62*kx_k*fx -> 2678.2399 | J64: =J62*kx_k*fx -> 2690.2992 | K64: =K62*kx_k*fx -> 2702.4128 | L64: =L62*kx_k*fx -> 2714.581 | ... R64: =R62*kx_k*fx -> 2840.6482 | T64: 第一季實績、第二季公司指引；之後＝市場層 × 公司口徑係數 × 匯率
A65: 每 EB 營業成本（第二季以指引校準，之後每年 × (1 − 成本年降)） | B65: ¥B/EB | C65: =C66/C63 -> 9.6326745 | D65: =D66/D63 -> 9.2142602 | E65: =$D65*(1-cd_A)^(1/4) -> 8.8732984 | F65: =$D65*(1-cd_A)^(2/4) -> 8.5449534 | G65: =$D65*(1-cd_A)^(3/4) -> 8.2287584 | H65: =$D65*(1-cd_A)^(4/4) -> 7.9242638 | I65: =$D65*(1-cd_A)^(5/4) -> 7.6310366 | J65: =$D65*(1-cd_A)^(6/4) -> 7.3486599 | K65: =$D65*(1-cd_A)^(7/4) -> 7.0767322 | L65: =$D65*(1-cd_A)^(8/4) -> 6.8148669 | M65: =$D65*(1-cd_A)^(9/4) -> 6.5626915 | N65: =$D65*(1-cd_A)^(10/4) -> 6.3198475 | O65: =$D65*(1-cd_A)^(11/4) -> 6.0859897 | P65: =$D65*(1-cd_A)^(12/4) -> 5.8607855 | Q65: =$D65*(1-cd_A)^(13/4) -> 5.6439147 | R65: =$D65*(1-cd_A)^(14/4) -> 5.4350689
A66: 營業成本 | B66: ¥B | C66: =q1_rev-q1_gp -> 387 | D66: =g2_rev-g2_op-g2_ox -> 430 | E66: =E63*E65 -> 434.29958 | F66: =F63*F65 -> 447.4146 | G66: =G63*G65 -> 455.5775 | H66: =H63*H65 -> 463.88933 | I66: =I63*I65 -> 472.3528 | J66: =J63*J65 -> 480.97069 | K66: =K63*K65 -> 489.74581 | L66: =L63*L65 -> 498.68103 | ... R66: =R63*R65 -> 510.92124 | T66: 第二季＝指引營收 − 指引營業利益 − 推估營業費用
A67: 毛利率 | B67: % | C67: =1-C66/C64 -> 0.78099711 | D67: =1-D66/D64 -> 0.82008368 | E67: =1-E66/E64 -> 0.81337821 | F67: =1-F66/F64 -> 0.82551836 | G67: =1-G66/G64 -> 0.83197483 | H67: =1-H66/H64 -> 0.82967619 | I67: =1-I66/I64 -> 0.82363313 | J67: =1-J66/J64 -> 0.82122037 | ... R67: =1-R66/R64 -> 0.82013921
A68: 營業費用 | B68: ¥B | C68: =q1_gp-q1_op -> 110.1 | D68: =g2_ox -> 70 | E68: =(g2_ox-ox_var*g2_rev)*(1+ox_g)^(1/4)+ox_var*E64 -> 70.483285 | F68: =(g2_ox-ox_var*g2_rev)*(1+ox_g)^(2/4)+ox_var*F64 -> 73.992591 | G68: =(g2_ox-ox_var*g2_rev)*(1+ox_g)^(3/4)+ox_var*G64 -> 76.629633 | H68: =(g2_ox-ox_var*g2_rev)*(1+ox_g)^(4/4)+ox_var*H64 -> 77.945731 | I68: =(g2_ox-ox_var*g2_rev)*(1+ox_g)^(5/4)+ox_var*I64 -> 78.715204 | J68: =(g2_ox-ox_var*g2_rev)*(1+ox_g)^(6/4)+ox_var*J64 -> 80.088089 | K68: =(g2_ox-ox_var*g2_rev)*(1+ox_g)^(7/4)+ox_var*K64 -> 81.491714 | L68: =(g2_ox-ox_var*g2_rev)*(1+ox_g)^(8/4)+ox_var*L64 -> 82.92681 | M68: =(g2_ox-ox_var*g2_rev)*(1+ox_g)^(9/4)+ox_var*M64 -> 84.394125 | N68: =(g2_ox-ox_var*g2_rev)*(1+ox_g)^(10/4)+ox_var*N64 -> 85.99915 | O68: =(g2_ox-ox_var*g2_rev)*(1+ox_g)^(11/4)+ox_var*O64 -> 87.918721 | P68: =(g2_ox-ox_var*g2_rev)*(1+ox_g)^(12/4)+ox_var*P64 -> 89.881726 | Q68: =(g2_ox-ox_var*g2_rev)*(1+ox_g)^(13/4)+ox_var*Q64 -> 91.889161 | R68: =(g2_ox-ox_var*g2_rev)*(1+ox_g)^(14/4)+ox_var*R64 -> 92.760449 | T68: 固定部分以第二季校準（Derived）
A69: 營業利益 | B69: ¥B | C69: =C64-C66-C68 -> 1270 | D69: =D64-D66-D68 -> 1890 | E69: =E64-E66-E68 -> 1822.3815 | F69: =F64-F66-F68 -> 2042.8431 | G69: =G64-G66-G68 -> 2179.1575 | H69: =H64-H66-H68 -> 2181.738 | I69: =I64-I66-I68 -> 2127.1719 | J69: =J64-J66-J68 -> 2129.2405 | ... R69: =R64-R66-R68 -> 2236.9665
A71: 淨利 | B71: ¥B | C71: =q1_ni -> 842.2 | D71: =g2_ni -> 1270 | E71: =(E69+nonop_q+rf*nc_j/4)*(1-tax) -> 1229.2853 | F71: =(F69+nonop_q+rf*nc_j/4)*(1-tax) -> 1379.1992 | G71: =(G69+nonop_q+rf*$D87/4)*(1-tax) -> 1477.0351 | H71: =(H69+nonop_q+rf*$D87/4)*(1-tax) -> 1478.7899 | I71: =(I69+nonop_q+rf*$D87/4)*(1-tax) -> 1441.6849 | J71: =(J69+nonop_q+rf*$D87/4)*(1-tax) -> 1443.0915 | K71: =(K69+nonop_q+rf*$E87/4)*(1-tax) -> 1452.1465 | L71: =(L69+nonop_q+rf*$E87/4)*(1-tax) -> 1453.369 | M71: =(M69+nonop_q+rf*$E87/4)*(1-tax) -> 1454.496 | N71: =(N69+nonop_q+rf*$E87/4)*(1-tax) -> 1468.508 | O71: =(O69+nonop_q+rf*$F87/4)*(1-tax) -> 1505.6713 | P71: =(P69+nonop_q+rf*$F87/4)*(1-tax) -> 1535.6796 | Q71: =(Q69+nonop_q+rf*$F87/4)*(1-tax) -> 1566.2664 | R71: =(R69+nonop_q+rf*$F87/4)*(1-tax) -> 1531.8072 | T71: （營業利益＋業外＋淨現金 × 收益率 ÷ 4）×（1 − 稅率）；FY2026 用 2026-06-30 淨現金
A72: 季 EPS（稀釋，分割後） | B72: JPY | C72: =C71/(sh0+dil)*1000 -> 507.34333 | D72: =D71/(sh0+dil)*1000 -> 765.0511 | E72: =E71/(sh0+dil)*1000 -> 740.52448 | F72: =F71/(sh0+dil)*1000 -> 830.83296 | G72: =G71/(sh0+dil)*1000 -> 889.76954 | H72: =H71/(sh0+dil)*1000 -> 890.82661 | I72: =I71/(sh0+dil)*1000 -> 868.47451 | J72: =J71/(sh0+dil)*1000 -> 869.32185 | ... R72: =R71/(sh0+dil)*1000 -> 922.76441
A74: B. 年度（會計年度） | B74: 單位 | C74: FY2025A | D74: FY2026 | E74: FY2027 | F74: FY2028 | G74: FY2029 | T74: 說明
A75: 營收 | B75: ¥B | C75: =a25_rev -> 2337.6 | D75: =SUM(C64:F64) -> 9048.5147 | E75: =SUM(G64:J64) -> 10803.477 | F75: =SUM(K64:N64) -> 10893.352 | G75: =SUM(O64:R64) -> 11398.395 | T75: FY2026＝第一季實績＋第二季指引＋第三、四季推導
A76: 營業成本 | B76: ¥B | C76: =a25_rev-(p1_gp+p2_gp+p3_gp+p4_gp) -> 1324.8 | D76: =SUM(C66:F66) -> 1698.7142 | E76: =SUM(G66:J66) -> 1872.7903 | F76: =SUM(K66:N66) -> 2004.525 | G76: =SUM(O66:R66) -> 2070.1443
A77: 毛利率 | B77: % | C77: =1-C76/C75 -> 0.43326489 | D77: =1-D76/D75 -> 0.81226596 | E77: =1-E76/E75 -> 0.82664929 | F77: =1-F76/F75 -> 0.8159864 | G77: =1-G76/G75 -> 0.81838283
A78: 營業費用 | B78: ¥B | D78: =SUM(C68:F68) -> 324.57588 | E78: =SUM(G68:J68) -> 313.37866 | F78: =SUM(K68:N68) -> 334.8118 | G78: =SUM(O68:R68) -> 362.45006
A79: 營業利益 | B79: ¥B | C79: =p1_op+p2_op+p3_op+p4_op -> 869 | D79: =SUM(C69:F69) -> 7025.2247 | E79: =SUM(G69:J69) -> 8617.3078 | F79: =SUM(K69:N69) -> 8554.0154 | G79: =SUM(O69:R69) -> 8965.8007
A80: 營業利益率 | B80: % | C80: =C79/C75 -> 0.3717488 | D80: =D79/D75 -> 0.77639534 | E80: =E79/E75 -> 0.79764209 | F80: =F79/F75 -> 0.78525097 | G80: =G79/G75 -> 0.78658448
...

Sheet Sources
A1: 來源
A2: Kioxia FY2026 第一季財報（2026-07-31；SGX 轉載） | B2: https://links.sgx.com/1.0.0/corporate-announcements/DOATO9EIE4EEQ2Y8/898078_Earnings-Release-FY2026-1Q-EN.pdf
A3: Kioxia：第二季財報 2026-10-30 18:45（JST）公布（公司新聞頁） | B3: https://www.kioxia-holdings.com/en-jp/news/2026.html
A4: storagenewsletter：Kioxia FY25 決算（營收 2,337.6、營業利益 870、淨利 554） | B4: https://www.storagenewsletter.com/?p=302700
A5: stockanalysis：季度損益、歷史股價、共識 | B5: https://stockanalysis.com/quote/tyo/285A/financials/?p=quarterly
A6: MarketScreener：Kioxia 預估與共識目標價 | B6: https://uk.marketscreener.com/quote/stock/KIOXIA-HOLDINGS-CORPORATI-180030735/finances/
A7: MarketScreener：SanDisk 預估（同業 P/B、P/E） | B7: https://uk.marketscreener.com/quote/stock/SANDISK-CORPORATION-182801077/finances/
A8: TrendForce：Kioxia FY26–28 資本支出（2026-06-03） | B8: https://www.trendforce.com/news/2026/06/03/news-kioxia-targets-%C2%A5470b-yearly-capex-in-fy26-28-up-66-from-fy25-reportedly-weighing-third-kitakami-fab-and-ma/
A9: newsquawk：一股分三股公告（2026-07-31） | B9: https://www.newsquawk.com/headlines/kioxia-285a-jt-q1-jpy-net-profit-84217bln-exp-9736bln-revenue-177tln-prev-3428bln-yy-announces-a-3-for-1-stock-split-and-announces-a-share-buyback
A10: stockanalysis：WDC 統計（Forward P/E） | B10: https://stockanalysis.com/stocks/wdc/statistics/
A11: 市場層：markets/nand/dist/20261025_NAND市場模型_v0.1.xlsx（markets/nand v0.1） | B11: 本 repo
A12: 美光十年倍數與淨利率（Analogy）：micron/dist/20261025_美光模型_v0.4.xlsx | B12: 本 repo
A13: SemiAnalysis | B13: 未使用
