Workbook

Sheet README
A1: Kioxia（285A JP）收支與估值模型 v0.1（AI 半導體 Project：記憶體——NAND） 2026-10-25
A2: 模型命題：Kioxia 是全球第三、四大 NAND 廠（2Q26 營收市占 13.6%），與 SanDisk 共用四日市、北上合資產能；盈餘由 NAND 合約價循環、AI 推論帶動的企業級 SSD 位元與日圓匯率決定。問題是 2026 年的高價能維持多久（FY2027 起三情境分歧），以及現價約 2.6 倍前瞻 P/E 是否已反映循環見頂。
A3: 重點觀察
A4: ="1. 加權目標價 ¥"&TEXT(Val!B49,"#,##0")&"，相對現價 ¥"&TEXT(px,"#,##0")&"（2026-10-23 收盤）"&TEXT(Val!B52,"+0.0%;−0.0%")&"。主因是現價的倍數低於同業：Kioxia 現價 ÷ 2028-03 共識每股淨值 1.63x，同業中位數 "&TEXT(Val!B32,"0.00")&"x（SanDisk 2.86x、美光 3.35x），Comparable ¥"&TEXT(Val!B34,"#,##0")&"（"&TEXT(Val!B53,"+0%;−0%")&"）；DCF ¥"&TEXT(Val!B24,"#,##0")&" 也高於現價，因現價只有 FY2027 EPS（A）的 "&TEXT(Val!B85,"0.0")&" 倍。股價 10-09 至 10-23 已跌 27%（17,505 → 12,755）。" -> 1. 加權目標價 ¥20,500，相對現價 ¥12,755（2026-10-23 收盤）+60.7%。主因是現價的倍數低於同業：Kioxia 現價 ÷ 2028-03 共識每股淨值 1.63x，同業中位數 2.10x（SanDisk 2.86x、美光 3.35x），Comparable ¥18,948（+49%）；DCF ¥22,052 也高於現價，因現價只有 FY2027 EPS（A）的 2.7 倍。股價 10-09 至 10-23 已跌 27%（17,505 → 12,755）。
A5: ="2. 本模型 FY2026 EPS（A）¥"&TEXT(PL!D14,"#,##0")&"，比共識 ¥3,486 "&TEXT(PL!D14/cons_eps26-1,"+0%;−0%")&"；上半年已由兩季實績鎖定（淨利 ¥2,202B）。v0.3 滾入第二季（營收 ¥2,480.0B、營業利益 ¥1,994.7B，皆高於指引）。v0.4 對帳：模型第三季營收 ¥"&TEXT(Recon!C7,"#,##0")&"B，比指引 ¥2,500B "&TEXT(Recon!D7,"+0.0%;−0.0%")&"（v0.3 為 +21.5%）。原因是市場層把合約價當實現價（2026Q3 實現 +25%、2026Q4 改 +8.1%，兩季累計不變），且份額只用出貨提前的單一季（改取兩季平均）；餘差為匯率假設與公司出貨季別移動（同一會計年度內）。" -> 2. 本模型 FY2026 EPS（A）¥3,360，比共識 ¥3,486 −4%；上半年已由兩季實績鎖定（淨利 ¥2,202B）。v0.3 滾入第二季（營收 ¥2,480.0B、營業利益 ¥1,994.7B，皆高於指引）。v0.4 對帳：模型第三季營收 ¥2,671B，比指引 ¥2,500B +6.8%（v0.3 為 +21.5%）。原因是市場層把合約價當實現價（2026Q3 實現 +25%、2026Q4 改 +8.1%，兩季累計不變），且份額只用出貨提前的單一季（改取兩季平均）；餘差為匯率假設與公司出貨季別移動（同一會計年度內）。
A6: ="3. 營收以美元計、成本以日圓計：匯率 145／170 日圓使 FY2028 EPS（A）變動 "&TEXT(Sens!H9,"+0%;−0%")&"／"&TEXT(Sens!H10,"+0%;−0%")&"；2027 起季價 ±20% 為 "&TEXT(Sens!H5,"+0%;−0%")&"／"&TEXT(Sens!H6,"+0%;−0%")&"。情境 C 的 FY2029 毛利率降到 "&TEXT(PL!G38,"0%")&"。追蹤：TrendForce 每季初的 NAND 合約價、日圓匯率、SanDisk 2026-10-29 財報（合資群位元）。" -> 3. 營收以美元計、成本以日圓計：匯率 145／170 日圓使 FY2028 EPS（A）變動 −13%／+9%；2027 起季價 ±20% 為 −28%／+30%。情境 C 的 FY2029 毛利率降到 49%。追蹤：TrendForce 每季初的 NAND 合約價、日圓匯率、SanDisk 2026-10-29 財報（合資群位元）。
A7: ="投資建議："&Val!B55&"（依上檔空間固定規則；上檔空間："&TEXT(Val!B52,"+0.0%;−0.0%")&"，級距："&Val!B54&"）" -> 投資建議：強力買進（依上檔空間固定規則；上檔空間：+60.7%，級距：大於 50%）
A9: 驅動因子 → 推導量（因果方向：左邊決定右邊）
A10: Units｜markets/nand 成品：Kioxia 季度營收（市場營收 × 份額，美元；同字母情境）與位元（季度出貨 × 份額）
A11: PL 區塊｜營收＝市場層 × 公司口徑係數 × 匯率；營業成本＝位元 × 每 EB 成本（日圓；第二季以實績校準，之後每年 × (1 − 成本年降)）；營業費用＝固定＋變動
A12: PL 區塊｜淨利＝（營業利益＋業外＋淨現金收益）×（1 − 稅率）；自由現金流＝淨利＋折舊 − 資本支出（¥470B／年）；股東回饋＝20% × FCF（以買回計）→ 股數 → EPS、每股淨值
A13: Val｜第 0 節目標價＝DCF（FY2027–FY2032＋永續）與 Comparable（同業前瞻 P/B × 約 2028 年底每股淨值）各半；第 5–6 節目前倍數、十年倍數規則值（美光 Analogy）
A15: 會計年度：4 月到隔年 3 月（FY2026＝2026-04～2027-03 ≈ CY2026Q2–CY2027Q1）。前瞻 EPS 依月份調整：12 個月後（約 2027-10）的未來 12 月＝5／12 FY2027＋7／12 FY2028。每股數字為 2026-10-01 一股分三股後。
A16: 情境：A＝順利、B＝平平、C＝不如預期，讀 markets/nand 同字母（價格＝markets/memory NAND_S；顆數＝SCEN_UNITS；合資群份額年變動）；公司特有變數（每位元成本年降 14%／12%／10%，與 SanDisk 同值）A 最有利、C 最不利。FY2026 的 B、C 略高於 A：上游 B、C 價格路徑 2027Q1 漲幅較大。FY2030 起為收斂法，非驅動因子推導。
A17: 十年歷史不足：2024-12 上市，只有兩個年底；十年 P/B、P/E 與十年平均淨利率以美光為 Analogy，tp_roe 只用 FY2024–FY2025。本版未做先驗，無 Andy 合理 P/E 對照。
A19: 2026-10-29：加權目標價中的 Comparable 改用相對倍數調整後的值（Val 第 0.5 節：同業前瞻倍數中位數 × 本公司 10 年相對同業的倍數比，Bloomberg 前瞻倍數；Andy 2026-10-27「照建議做」、10-29 資料取回）。「Comparable 目標價（市場主流同業法）」維持不調整。重點觀察 1 的第一句已改為公式；重點觀察 2、3 與其他說明中的目標價與上檔空間數字為調整前撰寫，以 Val 頁為準。
A21: v0.2.1（2026-10-30）：依個股模型原則第 8 節調整 In 頁呈現（數值不變）。In 頁 D／F 欄名改「敏感度低」「敏感度高」（只用於 Sens 頁、不進目標價）；In 頁最後新增「情境驅動對照」一節，把上方各情境專屬輸入三情境並排（只引用上方各列，純展示）；HTML 驅動因子一節分「情境驅動」與「單一參數」兩張表。

Sheet In
A1: In — 輸入（藍字；基準欄 E，低 D、高 F）。金額：十億日圓（¥B）；每股：日圓（2026-10-01 一股分三股後）；股數：百萬股。每個輸入附標記與來源；找不到者寫「未找到」。【v0.2.1】基準欄 E 進主模型；D／F＝敏感度低／高，只用於 Sens 頁（一次動一個參數）、不進目標價；情境 A／B／C 的驅動見本頁最後一節「情境驅動對照」。
A2: 標記：Verified（公司文件、交易所資料）／Interested-party（寫明是誰、立場）／Analogy（寫明對照與差異）／Assumed（給低／高區間）／Derived（寫明換算）。SemiAnalysis 未使用
A3: 鍵 | B3: 項目 | C3: 單位 | D3: 敏感度低 | E3: 基準 | F3: 敏感度高 | G3: 標記 | H3: 來源1 | I3: 來源2／說明
A4: A. 季度實績與公司指引（¥B；EPS 日圓，分割後）
A5: p1_rev | B5: FY2025 第1季營收 | C5: ¥B | E5: 342.8 | G5: Verified | H5: Kioxia FY2026 第一季財報（2026-07-31；SGX 轉載 Earnings Release FY2026 1Q）https://links.sgx.com/1.0.0/corporate-announcements/DOATO9EIE4EEQ2Y8/898078_Earnings-Release-FY2026-1Q-EN.pdf（前期欄：營收 342.8、營業利益 44.9、淨利 18.3） | I5: 四季合計 2,337.6＝公司 FY2025 營收（storagenewsletter 轉載決算；MarketScreener 2,337.6）
A6: p1_gp | B6: FY2025 第1季毛利 | C6: ¥B | E6: 71.2 | G6: Interested-party | H6: stockanalysis 季度損益（TYO:285A；2026-10-25 讀取）
A7: p1_op | B7: FY2025 第1季營業利益 | C7: ¥B | E7: 44.9 | G7: Verified | H7: Kioxia FY2026 第一季財報（2026-07-31；SGX 轉載 Earnings Release FY2026 1Q）https://links.sgx.com/1.0.0/corporate-announcements/DOATO9EIE4EEQ2Y8/898078_Earnings-Release-FY2026-1Q-EN.pdf（前期欄：營收 342.8、營業利益 44.9、淨利 18.3） | I7: 四季合計 869.0（公司 870.4，取整差）
A8: p1_ni | B8: FY2025 第1季淨利 | C8: ¥B | E8: 18.3 | G8: Verified | H8: Kioxia FY2026 第一季財報（2026-07-31；SGX 轉載 Earnings Release FY2026 1Q）https://links.sgx.com/1.0.0/corporate-announcements/DOATO9EIE4EEQ2Y8/898078_Earnings-Release-FY2026-1Q-EN.pdf（前期欄：營收 342.8、營業利益 44.9、淨利 18.3） | I8: 四季合計 554.5（公司 554.5）
A9: p2_rev | B9: FY2025 第2季營收 | C9: ¥B | E9: 448.3 | G9: Interested-party | H9: stockanalysis 季度損益（TYO:285A；2026-10-25 讀取） | I9: 四季合計 2,337.6＝公司 FY2025 營收（storagenewsletter 轉載決算；MarketScreener 2,337.6）
A10: p2_gp | B10: FY2025 第2季毛利 | C10: ¥B | E10: 122.1 | G10: Interested-party | H10: stockanalysis 季度損益（TYO:285A；2026-10-25 讀取）
A11: p2_op | B11: FY2025 第2季營業利益 | C11: ¥B | E11: 85.9 | G11: Interested-party | H11: stockanalysis 季度損益（TYO:285A；2026-10-25 讀取） | I11: 四季合計 869.0（公司 870.4，取整差）
A12: p2_ni | B12: FY2025 第2季淨利 | C12: ¥B | E12: 40.7 | G12: Interested-party | H12: stockanalysis 季度損益（TYO:285A；2026-10-25 讀取） | I12: 四季合計 554.5（公司 554.5）
A13: p3_rev | B13: FY2025 第3季營收 | C13: ¥B | E13: 543.6 | G13: Interested-party | H13: stockanalysis 季度損益（TYO:285A；2026-10-25 讀取） | I13: 四季合計 2,337.6＝公司 FY2025 營收（storagenewsletter 轉載決算；MarketScreener 2,337.6）
A14: p3_gp | B14: FY2025 第3季毛利 | C14: ¥B | E14: 176.6 | G14: Interested-party | H14: stockanalysis 季度損益（TYO:285A；2026-10-25 讀取）
A15: p3_op | B15: FY2025 第3季營業利益 | C15: ¥B | E15: 142.8 | G15: Interested-party | H15: stockanalysis 季度損益（TYO:285A；2026-10-25 讀取） | I15: 四季合計 869.0（公司 870.4，取整差）
A16: p3_ni | B16: FY2025 第3季淨利 | C16: ¥B | E16: 87.8 | G16: Interested-party | H16: stockanalysis 季度損益（TYO:285A；2026-10-25 讀取） | I16: 四季合計 554.5（公司 554.5）
A17: p4_rev | B17: FY2025 第4季營收 | C17: ¥B | E17: 1002.9 | G17: Interested-party | H17: stockanalysis 季度損益（TYO:285A；2026-10-25 讀取） | I17: 四季合計 2,337.6＝公司 FY2025 營收（storagenewsletter 轉載決算；MarketScreener 2,337.6）
A18: p4_gp | B18: FY2025 第4季毛利 | C18: ¥B | E18: 642.9 | G18: Interested-party | H18: stockanalysis 季度損益（TYO:285A；2026-10-25 讀取）
A19: p4_op | B19: FY2025 第4季營業利益 | C19: ¥B | E19: 595.4 | G19: Interested-party | H19: stockanalysis 季度損益（TYO:285A；2026-10-25 讀取） | I19: 四季合計 869.0（公司 870.4，取整差）
A20: p4_ni | B20: FY2025 第4季淨利 | C20: ¥B | E20: 407.7 | G20: Interested-party | H20: stockanalysis 季度損益（TYO:285A；2026-10-25 讀取） | I20: 四季合計 554.5（公司 554.5）
A21: p1_ss | B21: FY2025 第1季營收：SSD 與儲存 | C21: ¥B | E21: 217.4 | G21: Interested-party | H21: blocksandfiles 2025-08-11（轉載 FY2025 第一季決算；分部 46.3 為其他） | I21: 官方分部：SSD & Storage（企業級、資料中心、PC 用 SSD）
A22: p1_sd | B22: FY2025 第1季營收：智慧裝置 | C22: ¥B | E22: 79 | G22: Interested-party | H22: blocksandfiles 2025-08-11（轉載 FY2025 第一季決算；分部 46.3 為其他） | I22: 官方分部：Smart Devices（手機、車用等嵌入式）
A23: p2_ss | B23: FY2025 第2季營收：SSD 與儲存 | C23: ¥B | E23: 246.6 | G23: Derived | H23: longportapp（轉載 FY2025 第二季決算）：SSD 與儲存占 55%、智慧裝置占 35% × 營收 448.3（Derived） | I23: 官方分部：SSD & Storage（企業級、資料中心、PC 用 SSD）
A24: p2_sd | B24: FY2025 第2季營收：智慧裝置 | C24: ¥B | E24: 156.9 | G24: Derived | H24: longportapp（轉載 FY2025 第二季決算）：SSD 與儲存占 55%、智慧裝置占 35% × 營收 448.3（Derived） | I24: 官方分部：Smart Devices（手機、車用等嵌入式）
A25: p3_ss | B25: FY2025 第3季營收：SSD 與儲存 | C25: ¥B | E25: 300.4 | G25: Interested-party | H25: blocksandfiles 2026-02-13（轉載 FY2025 第三季決算；其他 57.0） | I25: 官方分部：SSD & Storage（企業級、資料中心、PC 用 SSD）
A26: p3_sd | B26: FY2025 第3季營收：智慧裝置 | C26: ¥B | E26: 186.3 | G26: Interested-party | H26: blocksandfiles 2026-02-13（轉載 FY2025 第三季決算；其他 57.0） | I26: 官方分部：Smart Devices（手機、車用等嵌入式）
A27: p4_ss | B27: FY2025 第4季營收：SSD 與儲存 | C27: ¥B | E27: 600.3 | G27: Interested-party | H27: blocksandfiles 2026-05-21（轉載 FY2025 第四季決算；其他 65.2） | I27: 官方分部：SSD & Storage（企業級、資料中心、PC 用 SSD）
A28: p4_sd | B28: FY2025 第4季營收：智慧裝置 | C28: ¥B | E28: 337.3 | G28: Interested-party | H28: blocksandfiles 2026-05-21（轉載 FY2025 第四季決算；其他 65.2） | I28: 官方分部：Smart Devices（手機、車用等嵌入式）
A29: q1_ss | B29: FY2026 第一季營收：SSD 與儲存 | C29: ¥B | E29: 1174.7 | G29: Verified | H29: Kioxia FY2026 第一季財報（2026-07-31；SGX 轉載 Earnings Release FY2026 1Q）https://links.sgx.com/1.0.0/corporate-announcements/DOATO9EIE4EEQ2Y8/898078_Earnings-Release-FY2026-1Q-EN.pdf
A30: q1_sd | B30: FY2026 第一季營收：智慧裝置 | C30: ¥B | E30: 525.7 | G30: Verified | H30: Kioxia FY2026 第一季財報（2026-07-31；SGX 轉載 Earnings Release FY2026 1Q）https://links.sgx.com/1.0.0/corporate-announcements/DOATO9EIE4EEQ2Y8/898078_Earnings-Release-FY2026-1Q-EN.pdf | I30: 其他 66.7（零售、對 SanDisk 銷售）＝營收 − 兩主分部
A31: q1_rev | B31: FY2026 第一季營收（2026-04～06） | C31: ¥B | E31: 1767.1 | G31: Verified | H31: Kioxia FY2026 第一季財報（2026-07-31；SGX 轉載 Earnings Release FY2026 1Q）https://links.sgx.com/1.0.0/corporate-announcements/DOATO9EIE4EEQ2Y8/898078_Earnings-Release-FY2026-1Q-EN.pdf | I31: SSD 與儲存 1,174.7、智慧裝置 525.7、其他 66.7；平均匯率 160 日圓
A32: q1_gp | B32: FY2026 第一季毛利 | C32: ¥B | E32: 1380.1 | G32: Interested-party | H32: stockanalysis 季度損益（TYO:285A；2026-10-25 讀取）：1,380,066 百萬日圓 | I32: 財報摘要未列毛利
A33: q1_op | B33: FY2026 第一季營業利益 | C33: ¥B | E33: 1270 | G33: Verified | H33: Kioxia FY2026 第一季財報（2026-07-31；SGX 轉載 Earnings Release FY2026 1Q）https://links.sgx.com/1.0.0/corporate-announcements/DOATO9EIE4EEQ2Y8/898078_Earnings-Release-FY2026-1Q-EN.pdf | I33: 含訴訟損失準備 36.6、股份報酬 19.4（non-GAAP 加回）
A34: q1_ni | B34: FY2026 第一季淨利（歸屬母公司） | C34: ¥B | E34: 842.2 | G34: Verified | H34: Kioxia FY2026 第一季財報（2026-07-31；SGX 轉載 Earnings Release FY2026 1Q）https://links.sgx.com/1.0.0/corporate-announcements/DOATO9EIE4EEQ2Y8/898078_Earnings-Release-FY2026-1Q-EN.pdf
A35: q1_eps | B35: FY2026 第一季基本 EPS（分割後） | C35: JPY | E35: =1539.91/3 -> 513.30333 | G35: Derived | H35: Kioxia FY2026 第一季財報（2026-07-31；SGX 轉載 Earnings Release FY2026 1Q）https://links.sgx.com/1.0.0/corporate-announcements/DOATO9EIE4EEQ2Y8/898078_Earnings-Release-FY2026-1Q-EN.pdf：基本 EPS ¥1,539.91（分割前）÷ 3 | I35: 2026-10-01 一股分三股（2026-07-31 董事會）
A36: g2_rev | B36: FY2026 第二季（2026-07～09）營收實績 | C36: ¥B | E36: 2480 | G36: Verified | H36: Kioxia FY2026 第二季財報（2026-10-30；404K Research 法說整理、PANews／TechFlow 轉載）：¥2,480.0B（指引 2,390.0；平均匯率 161） | I36: v0.3 前為公司指引
A37: g2_op | B37: FY2026 第二季營業利益實績 | C37: ¥B | E37: 1994.7 | G37: Verified | H37: Kioxia FY2026 第二季財報（2026-10-30；404K Research 法說整理、PANews／TechFlow 轉載）：¥1,994.7B（non-GAAP 1,988.3；指引 1,890.0）
A38: g2_ni | B38: FY2026 第二季淨利實績 | C38: ¥B | E38: 1360 | G38: Verified | H38: Kioxia FY2026 第二季財報（2026-10-30；404K Research 法說整理、PANews／TechFlow 轉載）：約 ¥1.36T（non-GAAP 1,348.6；指引 1,270.0） | I38: 第二來源：TechFlow 2026-10-30（1.36 兆）
A39: g2_ox | B39: FY2026 第二季營業費用（推估；校準用） | C39: ¥B | D39: 50 | E39: 59 | F39: 70 | G39: Derived | H39: 毛利率約 82.8%（404K Research 依損益表推算）× 2,480.0 − 營業利益 1,994.7 ≈ 59 | I39: 第二季營業成本＝營收 − 營業利益 − 本值；公司損益表原文未取得
A40: a25_rev | B40: FY2025 營收（2025-04～2026-03） | C40: ¥B | E40: =p1_rev+p2_rev+p3_rev+p4_rev -> 2337.6 | G40: Derived | H40: 四季合計 | I40: 公司 2,337.6（storagenewsletter 轉載 FY25 決算，+37%）
...

Sheet Q
A1: Q — 季度實績（¥B）與公司指引。會計年度 4–3 月；第一季＝4–6 月
A3: 項目 | B3: FY2025 第一季 | C3: FY2025 第二季 | D3: FY2025 第三季 | E3: FY2025 第四季 | F3: FY2025 | G3: FY2026 第一季 | H3: FY2026 第二季 | I3: 標記 | J3: 來源
A4: 營收 | B4: =p1_rev -> 342.8 | C4: =p2_rev -> 448.3 | D4: =p3_rev -> 543.6 | E4: =p4_rev -> 1002.9 | F4: =SUM(B4:E4) -> 2337.6 | G4: =q1_rev -> 1767.1 | H4: =g2_rev -> 2480 | I4: Verified／Interested-party | J4: 公司財報（第一季前期欄）；stockanalysis 季度表；第二季為公司指引
A5: 毛利 | B5: =p1_gp -> 71.2 | C5: =p2_gp -> 122.1 | D5: =p3_gp -> 176.6 | E5: =p4_gp -> 642.9 | F5: =SUM(B5:E5) -> 1012.8 | G5: =q1_gp -> 1380.1 | I5: Verified／Interested-party | J5: 公司財報（第一季前期欄）；stockanalysis 季度表；第二季為公司指引
A6: 營業利益 | B6: =p1_op -> 44.9 | C6: =p2_op -> 85.9 | D6: =p3_op -> 142.8 | E6: =p4_op -> 595.4 | F6: =SUM(B6:E6) -> 869 | G6: =q1_op -> 1270 | H6: =g2_op -> 1994.7 | I6: Verified／Interested-party | J6: 公司財報（第一季前期欄）；stockanalysis 季度表；第二季為公司指引
A7: 淨利 | B7: =p1_ni -> 18.3 | C7: =p2_ni -> 40.7 | D7: =p3_ni -> 87.8 | E7: =p4_ni -> 407.7 | F7: =SUM(B7:E7) -> 554.5 | G7: =q1_ni -> 842.2 | H7: =g2_ni -> 1360 | I7: Verified／Interested-party | J7: 公司財報（第一季前期欄）；stockanalysis 季度表；第二季為公司指引
A8: 毛利率 | B8: =B5/B4 -> 0.20770128 | C8: =C5/C4 -> 0.27236226 | D8: =D5/D4 -> 0.32487123 | E8: =E5/E4 -> 0.64104098 | F8: =F5/F4 -> 0.43326489 | G8: =G5/G4 -> 0.78099711
A9: 營業利益率 | B9: =B6/B4 -> 0.13098016 | C9: =C6/C4 -> 0.19161276 | D9: =D6/D4 -> 0.26269316 | E9: =E6/E4 -> 0.59367833 | F9: =F6/F4 -> 0.3717488 | G9: =G6/G4 -> 0.71869164 | H9: =H6/H4 -> 0.80431452
A10: 季增：營收 | C10: =C4/B4-1 -> 0.30775963 | D10: =D4/C4-1 -> 0.21258086 | E10: =E4/D4-1 -> 0.84492274 | G10: =G4/E4-1 -> 0.76199023 | H10: =H4/G4-1 -> 0.40342935
A12: v0.3（2026-10-31）：FY2026 第二季（2026-07～09）實績已滾入（2026-10-30：營收 2,480.0、營業利益 1,994.7、淨利 1,360；平均匯率 161）；第三季起＝市場層推導。第三季指引：營收 2,500.0、營業利益約 2,000（假設 157 日圓）

Sheet Units
A1: Units — 市場層 markets/nand 成品的 Kioxia 季度營收與位元（三情境；唯讀抄錄，藍字）。來源：markets/nand/dist/20261031_NAND市場模型_v0.3.xlsx
A2: C..Z＝CY2025Q1..CY2030Q4；營收為 TrendForce 口徑（$B，美元），位元為季度出貨 × 營收份額（EB）。合資群份額＝Kioxia＋SanDisk（與 sndk/ 模型讀同一列）
A3: 項目 | B3: 單位 | C3: 2025Q1 | D3: 2025Q2 | E3: 2025Q3 | F3: 2025Q4 | G3: 2026Q1 | H3: 2026Q2 | I3: 2026Q3 | J3: 2026Q4 | K3: 2027Q1 | L3: 2027Q2 | M3: 2027Q3 | N3: 2027Q4 | O3: 2028Q1 | P3: 2028Q2 | Q3: 2028Q3 | R3: 2028Q4 | S3: 2029Q1 | T3: 2029Q2 | U3: 2029Q3 | V3: 2029Q4 | W3: 2030Q1 | X3: 2030Q2 | Y3: 2030Q3 | Z3: 2030Q4 | AA3: 來源
A4: Kioxia 營收（情境 A） | B4: $B | C4: 1.92 | D4: 2.14 | E4: 2.84 | F4: 3.31 | G4: 5.96 | H4: 10.72 | I4: 14.951317 | J4: 16.203565 | K4: 17.854345 | L4: 18.878671 | M4: 18.963676 | N4: 18.648031 | O4: 18.731998 | P4: 18.816342 | Q4: 18.901067 | R4: 18.986172 | S4: 19.187419 | T4: 19.560424 | U4: 19.940679 | V4: 20.328327 | W4: 20.059327 | X4: 20.160861 | Y4: 20.262908 | Z4: 20.365471 | AA4: markets/nand/dist/20261031_NAND市場模型_v0.3.xlsx｜Mkt!C43:Z43
A5: Kioxia 營收（情境 B） | B5: $B | C5: 1.92 | D5: 2.14 | E5: 2.84 | F5: 3.31 | G5: 5.96 | H5: 10.72 | I5: 14.951317 | J5: 16.203565 | K5: 17.97424 | L5: 19.385554 | M5: 18.447955 | N5: 15.60507 | O5: 10.837585 | P5: 8.4170171 | Q5: 6.9728873 | R5: 6.4985969 | S5: 7.2624323 | T5: 8.0276379 | U5: 8.7044508 | V5: 9.4383261 | W5: 9.0583649 | X5: 9.0586145 | Y5: 9.0588641 | Z5: 9.0591137 | AA5: markets/nand/dist/20261031_NAND市場模型_v0.3.xlsx｜Mkt!C91:Z91
A6: Kioxia 營收（情境 C） | B6: $B | C6: 1.92 | D6: 2.14 | E6: 2.84 | F6: 3.31 | G6: 5.96 | H6: 10.72 | I6: 14.951317 | J6: 16.203565 | K6: 17.74745 | L6: 19.140956 | M6: 18.215187 | N6: 15.408172 | O6: 9.0479482 | P6: 5.8954184 | Q6: 4.4322787 | R6: 3.5544157 | S6: 3.8038503 | T6: 4.1553937 | U6: 4.6691238 | V6: 5.3435212 | W6: 5.1151445 | X6: 5.1042459 | Y6: 5.0933705 | Z6: 5.0825183 | AA6: markets/nand/dist/20261031_NAND市場模型_v0.3.xlsx｜Mkt!C139:Z139
A7: Kioxia 位元（情境 A） | B7: EB | C7: 35.545444 | D7: 33.356174 | E7: 38.303462 | F7: 36.611793 | G7: 38.133315 | H7: 40.175758 | I7: 44.826902 | J7: 44.941148 | K7: 48.077324 | L7: 50.835581 | M7: 53.752082 | N7: 56.835907 | O7: 60.096655 | P7: 63.544476 | Q7: 67.190103 | R7: 71.044884 | S7: 74.01849 | T7: 77.791148 | U7: 81.756094 | V7: 85.923131 | W7: 87.539517 | X7: 90.839802 | Y7: 94.26451 | Z7: 97.818331 | AA7: markets/nand/dist/20261031_NAND市場模型_v0.3.xlsx｜Mkt!C47:Z47
A8: Kioxia 位元（情境 B） | B8: EB | C8: 35.545444 | D8: 33.356174 | E8: 38.303462 | F8: 36.611793 | G8: 38.133315 | H8: 40.175758 | I8: 44.826902 | J8: 44.941148 | K8: 47.478265 | L8: 50.202153 | M8: 53.082313 | N8: 56.127713 | O8: 55.686007 | P8: 57.664765 | Q8: 59.713836 | R8: 61.83572 | S8: 65.813141 | T8: 69.283369 | U8: 72.936576 | V8: 76.782412 | W8: 76.084452 | X8: 78.557421 | Y8: 81.110768 | Z8: 83.747107 | AA8: markets/nand/dist/20261031_NAND市場模型_v0.3.xlsx｜Mkt!C95:Z95
A9: Kioxia 位元（情境 C） | B9: EB | C9: 35.545444 | D9: 33.356174 | E9: 38.303462 | F9: 36.611793 | G9: 38.133315 | H9: 40.175758 | I9: 44.826902 | J9: 44.941148 | K9: 46.879205 | L9: 49.568724 | M9: 52.412545 | N9: 55.419519 | O9: 50.066631 | P9: 50.187959 | Q9: 50.309582 | R9: 50.431499 | S9: 53.970578 | T9: 56.150876 | U9: 58.419252 | V9: 60.779266 | W9: 60.07104 | X9: 61.88967 | Y9: 63.763358 | Z9: 65.693772 | AA9: markets/nand/dist/20261031_NAND市場模型_v0.3.xlsx｜Mkt!C143:Z143
A10: Kioxia＋SanDisk 合資群份額（情境 A） | B10: % | C10: 0.27907731 | D10: 0.25560769 | E10: 0.27406433 | F10: 0.2689697 | G10: 0.27096015 | H10: 0.25018083 | I10: 0.25187361 | J10: 0.24502666 | K10: 0.24502666 | L10: 0.24502666 | M10: 0.24502666 | N10: 0.24502666 | O10: 0.24502666 | P10: 0.24502666 | Q10: 0.24502666 | R10: 0.24502666 | S10: 0.24502666 | T10: 0.24502666 | U10: 0.24502666 | V10: 0.24502666 | W10: 0.24502666 | X10: 0.24502666 | Y10: 0.24502666 | Z10: 0.24502666 | AA10: markets/nand/dist/20261031_NAND市場模型_v0.3.xlsx｜Mkt!C46:Z46
A11: Kioxia＋SanDisk 合資群份額（情境 B） | B11: % | C11: 0.27907731 | D11: 0.25560769 | E11: 0.27406433 | F11: 0.2689697 | G11: 0.27096015 | H11: 0.25018083 | I11: 0.25187361 | J11: 0.24502666 | K11: 0.24202666 | L11: 0.24202666 | M11: 0.24202666 | N11: 0.24202666 | O11: 0.23902666 | P11: 0.23902666 | Q11: 0.23902666 | R11: 0.23902666 | S11: 0.23602666 | T11: 0.23602666 | U11: 0.23602666 | V11: 0.23602666 | W11: 0.23302666 | X11: 0.23302666 | Y11: 0.23302666 | Z11: 0.23302666 | AA11: markets/nand/dist/20261031_NAND市場模型_v0.3.xlsx｜Mkt!C94:Z94
A12: Kioxia＋SanDisk 合資群份額（情境 C） | B12: % | C12: 0.27907731 | D12: 0.25560769 | E12: 0.27406433 | F12: 0.2689697 | G12: 0.27096015 | H12: 0.25018083 | I12: 0.25187361 | J12: 0.24502666 | K12: 0.23902666 | L12: 0.23902666 | M12: 0.23902666 | N12: 0.23902666 | O12: 0.23302666 | P12: 0.23302666 | Q12: 0.23302666 | R12: 0.23302666 | S12: 0.22702666 | T12: 0.22702666 | U12: 0.22702666 | V12: 0.22702666 | W12: 0.22102666 | X12: 0.22102666 | Y12: 0.22102666 | Z12: 0.22102666 | AA12: markets/nand/dist/20261031_NAND市場模型_v0.3.xlsx｜Mkt!C142:Z142
A14: AI 企業級 SSD 占（企業級＋PC）SSD 位元需求（日曆年；markets/nand Ann 頁）
A15: 項目 | B15: 單位 | C15: CY2025 | D15: CY2026 | E15: CY2027 | F15: CY2028 | G15: CY2029 | H15: CY2030 | I15: 來源
A16: AI ÷（企業級＋PC）SSD（情境 A） | B16: % | C16: 0.31132075 | D16: 0.55407047 | E16: 0.67848272 | F16: 0.72045375 | G16: 0.75784396 | H16: 0.77509863 | I16: markets/nand/dist/20261031_NAND市場模型_v0.3.xlsx｜Ann!D6:I6 ÷（同列＋下一列＋PC 列）
A17: AI ÷（企業級＋PC）SSD（情境 B） | B17: % | C17: 0.31132075 | D17: 0.55407047 | E17: 0.67848272 | F17: 0.67339265 | G17: 0.72678592 | H17: 0.74551045 | I17: markets/nand/dist/20261031_NAND市場模型_v0.3.xlsx｜Ann!D33:I33 ÷（同列＋下一列＋PC 列）
A18: AI ÷（企業級＋PC）SSD（情境 C） | B18: % | C18: 0.31132075 | D18: 0.55407047 | E18: 0.67848272 | F18: 0.60727875 | G18: 0.65250524 | H18: 0.67403734 | I18: markets/nand/dist/20261031_NAND市場模型_v0.3.xlsx｜Ann!D60:I60 ÷（同列＋下一列＋PC 列）

Sheet PL
A1: PL — Kioxia 損益（¥B；FY2025 實績；FY2026＝第一、二季實績＋第三、四季推導；FY2027–FY2029 由市場層 markets/nand 驅動；FY2030–FY2032 收斂法見底部）
A3: 情境／項目 | B3: 單位 | C3: FY2025A | D3: FY2026 | E3: FY2027 | F3: FY2028 | G3: FY2029 | H3: 說明
A4: 情境 A（順利）
A5: 營收 | B5: ¥B | C5: =C77 -> 2337.6 | D5: =D77 -> 9861.2541 | E5: =E77 -> 12399.763 | F5: =F77 -> 12509.98 | G5: =G77 -> 13168.976
A6: SSD 與儲存 | B6: ¥B | C6: =C78 -> 1364.7 | D6: =D78 -> 6516.8417 | E6: =E78 -> 8431.839 | F6: =F78 -> 8756.9861 | G6: =G78 -> 9218.2833
A7: SSD 與儲存：AI 相關 | B7: ¥B | C7: =C79 -> 507.67957 | D7: =D79 -> 3813.4833 | E7: =E79 -> 5809.3303 | F7: =F79 -> 6390.8599 | G7: =G79 -> 7025.7849
A8: 智慧裝置 | B8: ¥B | C8: =C80 -> 759.5 | D8: =D80 -> 2953.9462 | E8: =E80 -> 3471.9337 | F8: =F80 -> 3252.5948 | G8: =G80 -> 3423.9338
A9: 其他 | B9: ¥B | C9: =C81 -> 213.4 | D9: =D81 -> 390.46617 | E9: =E81 -> 495.99053 | F9: =F81 -> 500.3992 | G9: =G81 -> 526.75904
A10: 毛利率 | B10: % | C10: =C84 -> 0.43326489 | D10: =D84 -> 0.83279289 | E10: =E84 -> 0.85686965 | F10: =F84 -> 0.84806522 | G10: =G84 -> 0.8500484
A11: 營業利益 | B11: ¥B | C11: =C86 -> 869 | D11: =D86 -> 7916.2468 | E11: =E86 -> 10348.646 | F11: =F86 -> 10316.608 | G11: =G86 -> 10878.249
A12: 營業利益率 | B12: % | C12: =C87 -> 0.3717488 | D12: =D87 -> 0.80276268 | E12: =E87 -> 0.83458413 | F12: =F87 -> 0.82467021 | G12: =G87 -> 0.82605123
A13: 淨利 | B13: ¥B | C13: =C88 -> 554.5 | D13: =D88 -> 5345.3836 | E13: =E88 -> 7021.3094 | F13: =F88 -> 7036.9038 | G13: =G88 -> 7456.2844
A14: EPS | B14: JPY | C14: =C96 -> 341.4 | D14: =D96 -> 3359.894 | E14: =E96 -> 4733.9079 | F14: =F96 -> 5116.9754 | G14: =G96 -> 5914.662
A15: 每股淨值 | B15: JPY | D15: =D97 -> 3826.3437 | E15: =E97 -> 7956.135 | F15: =F97 -> 12751.996 | G15: =G97 -> 18742.299
A16: 自由現金流 | B16: ¥B | D16: =D91 -> 5215.3836 | E16: =E91 -> 6871.3094 | F16: =F91 -> 6886.9038 | G16: =G91 -> 7306.2844
A18: 情境 B（平平）
A19: 營收 | B19: ¥B | C19: =C124 -> 2337.6 | D19: =D124 -> 9881.0179 | E19: =E124 -> 10595.374 | F19: =F124 -> 4805.2812 | G19: =G124 -> 5807.162
A20: SSD 與儲存 | B20: ¥B | C20: =C125 -> 1364.7 | D20: =D125 -> 6529.8858 | E20: =E125 -> 7204.8543 | F20: =F125 -> 3363.6969 | G20: =G125 -> 4065.0134
A21: SSD 與儲存：AI 相關 | B21: ¥B | C21: =C126 -> 507.67957 | D21: =D126 -> 3821.1164 | E21: =E126 -> 4879.2009 | F21: =F126 -> 2309.9884 | G21: =G126 -> 2973.4234
A22: 智慧裝置 | B22: ¥B | C22: =C127 -> 759.5 | D22: =D127 -> 2959.8754 | E22: =E127 -> 2966.7047 | F22: =F127 -> 1249.3731 | G22: =G127 -> 1509.8621
A23: 其他 | B23: ¥B | C23: =C128 -> 213.4 | D23: =D128 -> 391.25672 | E23: =E128 -> 423.81496 | F23: =F128 -> 192.21125 | G23: =G128 -> 232.28648
A24: 毛利率 | B24: % | C24: =C131 -> 0.43326489 | D24: =D131 -> 0.83293202 | E24: =E131 -> 0.83293536 | F24: =F131 -> 0.63083179 | G24: =G131 -> 0.67612737
A25: 營業利益 | B25: ¥B | C25: =C133 -> 869 | D25: =D133 -> 7933.883 | E25: =E133 -> 8566.9704 | F25: =F133 -> 2815.7 | G25: =G133 -> 3683.9811
A26: 營業利益率 | B26: % | C26: =C134 -> 0.3717488 | D26: =D134 -> 0.80294187 | E26: =E134 -> 0.80855762 | F26: =F134 -> 0.58595947 | G26: =G134 -> 0.6343858
A27: 淨利 | B27: ¥B | C27: =C135 -> 554.5 | D27: =D135 -> 5357.3762 | E27: =E135 -> 5809.8356 | F27: =F135 -> 1929.7612 | G27: =G135 -> 2529.8742
A28: EPS | B28: JPY | C28: =C143 -> 341.4 | D28: =D143 -> 3367.8301 | E28: =E143 -> 3868.0581 | F28: =F143 -> 1309.1147 | G28: =G143 -> 1760.7949
A29: 每股淨值 | B29: JPY | D29: =D144 -> 3832.893 | E29: =E144 -> 7209.6991 | F29: =F144 -> 8427.026 | G29: =G144 -> 10093.948
A30: 自由現金流 | B30: ¥B | D30: =D138 -> 5227.3762 | E30: =E138 -> 5659.8356 | F30: =F138 -> 1779.7612 | G30: =G138 -> 2379.8742
A32: 情境 C（不如預期）
A33: 營收 | B33: ¥B | C33: =C171 -> 2337.6 | D33: =D171 -> 9843.6334 | E33: =E171 -> 10189.221 | F33: =F171 -> 2915.3792 | G33: =G171 -> 3178.6673
A34: SSD 與儲存 | B34: ¥B | C34: =C172 -> 1364.7 | D34: =D172 -> 6505.212 | E34: =E172 -> 6928.6704 | F34: =F172 -> 2040.7655 | G34: =G172 -> 2225.0671
A35: SSD 與儲存：AI 相關 | B35: ¥B | C35: =C173 -> 507.67957 | D35: =D173 -> 3806.6779 | E35: =E173 -> 4577.6459 | F35: =F173 -> 1262.3877 | G35: =G173 -> 1463.8455
A36: 智慧裝置 | B36: ¥B | C36: =C174 -> 759.5 | D36: =D174 -> 2948.66 | E36: =E174 -> 2852.9819 | F36: =F174 -> 757.9986 | G36: =G174 -> 826.45349
A37: 其他 | B37: ¥B | C37: =C175 -> 213.4 | D37: =D175 -> 389.76133 | E37: =E175 -> 407.56885 | F37: =F175 -> 116.61517 | G37: =G175 -> 127.14669
A38: 毛利率 | B38: % | C38: =C178 -> 0.43326489 | D38: =D178 -> 0.83212343 | E38: =E178 -> 0.82798488 | F38: =F178 -> 0.46585568 | G38: =G178 -> 0.49344477
A39: 營業利益 | B39: ¥B | C39: =C180 -> 869 | D39: =D180 -> 7895.1587 | E39: =E180 -> 8182.2913 | F39: =F180 -> 1161.4209 | G39: =G180 -> 1352.3816
A40: 營業利益率 | B40: % | C40: =C181 -> 0.3717488 | D40: =D181 -> 0.80205737 | E40: =E181 -> 0.80303402 | F40: =F181 -> 0.39837729 | G40: =G181 -> 0.42545555
A41: 淨利 | B41: ¥B | C41: =C182 -> 554.5 | D41: =D182 -> 5331.0437 | E41: =E182 -> 5548.1105 | F41: =F182 -> 803.28436 | G41: =G182 -> 936.69152
A42: EPS | B42: JPY | C42: =C190 -> 341.4 | D42: =D190 -> 3350.407 | E42: =E190 -> 3682.7328 | F42: =F190 -> 536.8556 | G42: =G190 -> 631.21886
A43: 每股淨值 | B43: JPY | D43: =D191 -> 3818.5146 | E43: =E191 -> 7033.2463 | F43: =F191 -> 7536.3017 | G43: =G191 -> 8130.537
...

Sheet Val
A1: Val — 估值。第 0 節為目標價（DCF 與 Comparable 加權；Comparable 依記憶體慣例用前瞻 P/B）；第 5–6 節為目前倍數、十年倍數與規則值（舊法參考）
A2: Kioxia 2024-12 上市，只有兩個年底：十年 P/B、P/E 以美光（同為記憶體循環股）為 Analogy，見第 6 節。每股數字皆為 2026-10-01 一股分三股後
A4: 0. 目標價
A5: 0.1 DCF（股東權益現金流，FY2027–FY2032 明確期＋FY2032 後永續）
A6: 項目 | B6: A（順利） | C6: B（平平） | D6: C（不如預期） | E6: 說明
A7: 情境 EPS（FY2027–FY2032） | E7: PL 頁延伸區塊；FY2030 起為收斂法（灰底）
A8: FY2027 | B8: =PL!D205 -> 4733.9079 | C8: =PL!D212 -> 3868.0581 | D8: =PL!D219 -> 3682.7328
A9: FY2028 | B9: =PL!E205 -> 5116.9754 | C9: =PL!E212 -> 1309.1147 | D9: =PL!E219 -> 536.8556
A10: FY2029 | B10: =PL!F205 -> 5914.662 | C10: =PL!F212 -> 1760.7949 | D10: =PL!F219 -> 631.21886
A11: FY2030 | B11: =PL!G205 -> 4806.9026 | C11: =PL!G212 -> 1580.3184 | D11: =PL!G219 -> 538.31078
A12: FY2031 | B12: =PL!H205 -> 3567.2914 | C12: =PL!H212 -> 1240.4415 | D12: =PL!H219 -> 420.70425
A13: FY2032 | B13: =PL!I205 -> 2174.0587 | C13: =PL!I212 -> 778.53657 | D13: =PL!I219 -> 285.30959
A14: 股東現金流＝EPS ×（1 − tp_g ÷ tp_roe） | E14: 記憶體資本密集：FY2027–FY2029 改用每股（淨利＋折舊－資本支出）＝ PL 區塊每股自由現金流；收斂期（FY2030 起）用 EPS ×（1 − 再投資率）
A15: 再投資率（tp_g ÷ tp_roe，上限 0.8；FY2030 起用） | B15: =MIN(tp_g/tp_roe,0.8) -> 0.10447316 | E15: ROE 為 FY2024–FY2025 平均（In 頁 tp_roe）
A16: FY2027（淨利＋折舊－資本支出，每股） | B16: =PL!E99 -> 4632.7749 | C16: =PL!E146 -> 3768.1914 | D16: =PL!E193 -> 3583.1656
A17: FY2028（淨利＋折舊－資本支出，每股） | B17: =PL!F99 -> 5007.901 | C17: =PL!F146 -> 1207.3575 | D17: =PL!F193 -> 436.60674
A18: FY2029（淨利＋折舊－資本支出，每股） | B18: =PL!G99 -> 5795.6752 | C18: =PL!G146 -> 1656.3948 | D18: =PL!G193 -> 530.13667
A19: FY2030（EPS ×（1 − 再投資率）） | B19: =B11*(1-$B$15) -> 4304.7103 | C19: =C11*(1-$B$15) -> 1415.2175 | D19: =D11*(1-$B$15) -> 482.07175
A20: FY2031（EPS ×（1 − 再投資率）） | B20: =B12*(1-$B$15) -> 3194.6052 | C20: =C12*(1-$B$15) -> 1110.8486 | D20: =D12*(1-$B$15) -> 376.75194
A21: FY2032（EPS ×（1 − 再投資率）） | B21: =B13*(1-$B$15) -> 1946.928 | C21: =C13*(1-$B$15) -> 697.2004 | D21: =D13*(1-$B$15) -> 255.50239
A22: DCF 情境每股價值（折現率 tp_r） | B22: =MAX(0,SUMPRODUCT(B16:B21,1/(1+tp_r)^{1;2;3;4;5;6})+B21*(1+tp_g)/(tp_r-tp_g)/(1+tp_r)^6) -> 37776.676 | C22: =MAX(0,SUMPRODUCT(C16:C21,1/(1+tp_r)^{1;2;3;4;5;6})+C21*(1+tp_g)/(tp_r-tp_g)/(1+tp_r)^6) -> 14539.391 | D22: =MAX(0,SUMPRODUCT(D16:D21,1/(1+tp_r)^{1;2;3;4;5;6})+D21*(1+tp_g)/(tp_r-tp_g)/(1+tp_r)^6) -> 7223.8643 | E22: Σ 明確期現金流 ÷ (1＋r)^t ＋ 永續價值 ÷ (1＋r)^6；永續價值＝FY2032 現金流 ×(1＋g)÷(r−g)；基準日 2026 年底，t＝1 對 FY2027（2027-04～2028-03，t 以會計年度計，略低估）；FY2026 剩餘一季的現金流未計入；負值取 0
A23: DCF 情境價值推到 12 個月後（×(1＋tp_r)） | B23: =B22*(1+tp_r) -> 41554.344 | C23: =C22*(1+tp_r) -> 15993.33 | D23: =D22*(1+tp_r) -> 7946.2508
A24: DCF 目標價（情境加權） | B24: =tp_wA*B23+tp_wB*C23+tp_wC*D23 -> 22052.218 | E24: Σ 權重 × 情境價值 ×(1＋r)；權重見 In 頁 tp_wA／tp_wB／tp_wC
A26: 0.2 Comparable（市場主流同業前瞻 P/B；記憶體慣例）
A27: 同業與前瞻 P/B | B27: 代號 | C27: 前瞻 P/B | D27: 日期 | E27: 來源 | F27: 標記
A28: 美光 | B28: MU | C28: 3.35 | D28: 2026-10-23 | E28: MarketScreener：現價 ÷ FY2027E（2027-09）每股淨值（micron/ 模型同值） | F28: Interested-party
A29: SK 海力士 | B29: 000660.KS | C29: 1.35 | D29: 2026-10-23 | E29: MarketScreener：現價 ÷ 2027E 每股淨值（skhynix/ 模型同值） | F29: Interested-party
A30: 三星電子 | B30: 005930.KS | C30: 1.26 | D30: 2026-10-23 | E30: MarketScreener：現價 ÷ 2027E 每股淨值（samsung/ 模型同值） | F30: Interested-party
A31: SanDisk | B31: SNDK | C31: =1238.03/((313.8+553.1)/2) -> 2.8562233 | D31: 2026-10-23 | E31: 現價 1,238.03 ÷ MarketScreener 約 2027 年底每股淨值（FY2027、FY2028 年底平均；sndk/ 模型同口徑） | F31: Interested-party
A32: 同業前瞻 P/B 中位數 | B32: =MEDIAN(C28:C31) -> 2.1031117 | E32: 記憶體同業（美光、SK 海力士、三星、SanDisk；無 A 股）。WDC（硬碟）不列入 P/B（僅有落後 P/B），P/E 並列參考見下方。Kioxia 自身現價 ÷ FY2027 年底（2028-03）共識每股淨值 1.63x（sndk/ 同業表同值）
A33: 12 個月後的前瞻每股淨值（情境加權） | B33: =tp_wA*(0.25*PL!E97+0.75*PL!F97)+tp_wB*(0.25*PL!E144+0.75*PL!F144)+tp_wC*(0.25*PL!E191+0.75*PL!F191) -> 9009.3639 | E33: 同業倍數＝現價 ÷ 約 14 個月後（約 2027 年底）每股淨值；對應 12 個月後（約 2027-10）用約 2028 年底每股淨值＝¼ × FY2027 年底（2028-03）＋¾ × FY2028 年底（2029-03）（會計年度 3 月，依月份調整）
A34: Comparable 目標價 | B34: =B32*B33 -> 18947.698 | E34: 同業中位數 × 前瞻每股淨值
A35: 12 個月後的前瞻 EPS（情境加權） | B35: =tp_wA*(5/12*B8+7/12*B9)+tp_wB*(5/12*C8+7/12*C9)+tp_wC*(5/12*D8+7/12*D9) -> 3044.4073 | E35: 約 2027-10 時的未來 12 月（2027-11～2028-10）≈ 5／12 × FY2027（2027-04～2028-03）＋7／12 × FY2028（會計年度 3 月，依月份調整）
A37: 並列參考：同業前瞻 P/E（不進目標價）
A38: 同業與前瞻 P/E | B38: 代號 | C38: 前瞻 P/E | D38: 日期 | E38: 來源 | F38: 標記
A39: 美光 | B39: MU | C39: =877.55/173 -> 5.0725434 | D39: 2026-10-23 | E39: 現價 877.55 ÷ MarketScreener FY2027 共識 EPS 173（micron/ 模型 In 頁） | F39: Interested-party
A40: SK 海力士 | B40: 000660.KS | C40: =1277000/475721 -> 2.6843465 | D40: 2026-10-23 | E40: 現價 ÷ MarketScreener 2027 共識 EPS（skhynix/ 模型 In 頁） | F40: Interested-party
A41: 三星電子 | B41: 005930.KS | C41: =215500/72279 -> 2.9815022 | D41: 2026-10-23 | E41: 現價 ÷ MarketScreener 2027 共識 EPS（samsung/ 模型 In 頁） | F41: Interested-party
A42: SanDisk | B42: SNDK | C42: =1238.03/217.4 -> 5.6947102 | D42: 2026-10-23 | E42: 現價 1,238.03 ÷ MarketScreener FY2027（2027-06）共識 EPS 217.4 | F42: Interested-party
A43: Western Digital | B43: WDC | C43: 11.91 | D43: 2026-10-23 | E43: stockanalysis 統計頁 Forward P/E（硬碟為主，參考） | F43: Interested-party
...

Sheet Recon
A1: Recon — 本模型 vs 公司實績、指引與共識（共識只作對照，未用於校準）。差距＝模型 ÷ 對照 − 1（百分點列為相減）
A3: 項目 | B3: 對照值 | C3: 模型 A | D3: 差距 A | E3: 模型 B | F3: 差距 B | G3: 模型 C | H3: 差距 C | I3: 對照來源 | J3: 說明
A4: A. 實績與公司指引
A5: FY2025 營收（四季合計）vs 公司 2,337.6 | B5: 2337.6 | C5: =PL!C5 -> 2337.6 | D5: =C5/B5-1 -> 0 | E5: =PL!C19 -> 2337.6 | F5: =E5/B5-1 -> 0 | G5: =PL!C33 -> 2337.6 | H5: =G5/B5-1 -> 0 | I5: storagenewsletter 轉載 FY25 決算；MarketScreener
A6: FY2026 上半營收 vs 公司指引 4,157.1 | B6: 4157.1 | C6: =PL!C60+PL!D60 -> 4247.1 | D6: =C6/B6-1 -> 0.021649708 | E6: =PL!C107+PL!D107 -> 4247.1 | F6: =E6/B6-1 -> 0.021649708 | G6: =PL!C154+PL!D154 -> 4247.1 | H6: =G6/B6-1 -> 0.021649708 | I6: Kioxia FY2026 第一季財報（2026-07-31） | J6: 恆等式
A7: FY2026 第三季營收（推導）vs 第三季指引 2,500（假設 157 日圓） | B7: =g3_rev -> 2500 | C7: =PL!E60 -> 2671.0186 | D7: =C7/B7-1 -> 0.06840744 | E7: =PL!E107 -> 2671.0186 | F7: =E7/B7-1 -> 0.06840744 | G7: =PL!E154 -> 2671.0186 | H7: =G7/B7-1 -> 0.06840744 | I7: Kioxia 第二季財報（2026-10-30）第三季指引 | J7: v0.4：市場層 2026Q4 季價 +8.1%（實現價口徑；v0.3 為合約價 +17.5%、差距 +21.5%），份額取 2026Q3 實績與第三季指引的平均。餘差：匯率假設 160 對 157 約 +1.9%；其餘為公司稱 7–9 月提前出貨、部分遞延到 1–3 月（同一會計年度內）與產品組合
A8: FY2026 第二季毛利率（校準值）vs 第一季（百分點） | B8: =q1_gp/q1_rev -> 0.78099711 | C8: =PL!D69 -> 0.82810484 | D8: =C8-B8 -> 0.047107725 | E8: =PL!D116 -> 0.82810484 | F8: =E8-B8 -> 0.047107725 | G8: =PL!D163 -> 0.82810484 | H8: =G8-B8 -> 0.047107725 | I8: Kioxia FY2026 第一季財報（2026-07-31） | J8: 第二季營業費用為 Assumed（g2_ox）
A9: B. 共識（MarketScreener 2026-10-25 擷取；只作參考）
A10: FY2026 營收 vs 共識 | B10: =cons_rev26 -> 10071.4 | C10: =PL!D5 -> 9861.2541 | D10: =C10/B10-1 -> -0.020865605 | E10: =PL!D19 -> 9881.0179 | F10: =E10/B10-1 -> -0.018903243 | G10: =PL!D33 -> 9843.6334 | H10: =G10/B10-1 -> -0.022615192 | I10: MarketScreener 預估頁（2026-10-25 擷取；頁面為 10-16 收盤；會計年度 3 月；每股數字已依分割調整，股數 1,644 百萬股）
A11: FY2026 淨利 vs 共識 | B11: =cons_ni26 -> 5573.9 | C11: =PL!D13 -> 5345.3836 | D11: =C11/B11-1 -> -0.040997579 | E11: =PL!D27 -> 5357.3762 | F11: =E11/B11-1 -> -0.038846013 | G11: =PL!D41 -> 5331.0437 | H11: =G11/B11-1 -> -0.043570269 | I11: MarketScreener 預估頁（2026-10-25 擷取；頁面為 10-16 收盤；會計年度 3 月；每股數字已依分割調整，股數 1,644 百萬股）
A12: FY2026 EPS vs 共識 | B12: =cons_eps26 -> 3486 | C12: =PL!D14 -> 3359.894 | D12: =C12/B12-1 -> -0.03617499 | E12: =PL!D28 -> 3367.8301 | F12: =E12/B12-1 -> -0.033898413 | G12: =PL!D42 -> 3350.407 | H12: =G12/B12-1 -> -0.038896453 | I12: MarketScreener 預估頁（2026-10-25 擷取；頁面為 10-16 收盤；會計年度 3 月；每股數字已依分割調整，股數 1,644 百萬股） | J12: 差距超過 30% 見 README
A13: FY2027 營收 vs 共識 | B13: =cons_rev27 -> 13477.2 | C13: =PL!E5 -> 12399.763 | D13: =C13/B13-1 -> -0.079945153 | E13: =PL!E19 -> 10595.374 | F13: =E13/B13-1 -> -0.21382972 | G13: =PL!E33 -> 10189.221 | H13: =G13/B13-1 -> -0.24396601 | I13: MarketScreener 預估頁（2026-10-25 擷取；頁面為 10-16 收盤；會計年度 3 月；每股數字已依分割調整，股數 1,644 百萬股）
A14: FY2027 EPS vs 共識 | B14: =cons_eps27 -> 4871 | C14: =PL!E14 -> 4733.9079 | D14: =C14/B14-1 -> -0.028144543 | E14: =PL!E28 -> 3868.0581 | F14: =E14/B14-1 -> -0.20590062 | G14: =PL!E42 -> 3682.7328 | H14: =G14/B14-1 -> -0.24394728 | I14: MarketScreener 預估頁（2026-10-25 擷取；頁面為 10-16 收盤；會計年度 3 月；每股數字已依分割調整，股數 1,644 百萬股）
A15: FY2028 EPS vs 共識 | B15: =cons_eps28 -> 5467 | C15: =PL!F14 -> 5116.9754 | D15: =C15/B15-1 -> -0.064024986 | E15: =PL!F28 -> 1309.1147 | F15: =E15/B15-1 -> -0.76054239 | G15: =PL!F42 -> 536.8556 | H15: =G15/B15-1 -> -0.9018007 | I15: MarketScreener 預估頁（2026-10-25 擷取；頁面為 10-16 收盤；會計年度 3 月；每股數字已依分割調整，股數 1,644 百萬股）
A16: FY2027 年底每股淨值 vs 共識 | B16: =cons_bv27 -> 7808 | C16: =PL!E15 -> 7956.135 | D16: =C16/B16-1 -> 0.018972208 | E16: =PL!E29 -> 7209.6991 | F16: =E16/B16-1 -> -0.076626654 | G16: =PL!E43 -> 7033.2463 | H16: =G16/B16-1 -> -0.09922563 | I16: MarketScreener 預估頁（2026-10-25 擷取；頁面為 10-16 收盤；會計年度 3 月；每股數字已依分割調整，股數 1,644 百萬股）
A17: C. 市場層一致性
A18: Kioxia 營收 ÷ 市場層（公司口徑係數 kx_k） | C18: =kx_k -> 1.0302589 | I18: In 頁
A19: Kioxia＋SanDisk 合資群份額 CY2027（市場層 Ann 頁，A／B／C） | C19: 0.24502666 | E19: 0.24202666 | G19: 0.23902666 | I19: markets/nand/dist/20261031_NAND市場模型_v0.3.xlsx｜Ann!F27（sndk/ 模型讀同一組列）

Sheet Sens
A1: Sens — 一次動一個輸入（情境 A）：對 FY2027、FY2028 營收與 EPS 的影響。每個案例為一個完整推導區塊（本頁下方，與 PL 同一引擎）
A3: 案例 | B3: 設定 | C3: FY2027 營收 ¥B | D3: FY2027 EPS | E3: 相對基準 | F3: FY2028 營收 ¥B | G3: FY2028 EPS | H3: 相對基準 | I3: FY2027 毛利率
A4: 基準（情境 A） | B4: PL 區塊 A | C4: =PL!E77 -> 12399.763 | D4: =PL!E96 -> 4733.9079 | E4: =D4/D$4-1 -> 0 | F4: =PL!F77 -> 12509.98 | G4: =PL!F96 -> 5116.9754 | H4: =G4/G$4-1 -> 0 | I4: =PL!E84 -> 0.85686965
A5: 市場層營收 −20%（價格；第三季起） | B5: 價格係數 0.8 | C5: =E81 -> 9919.8105 | D5: =E100 -> 3515.2356 | E5: =D5/D$4-1 -> -0.25743473 | F5: =F81 -> 10007.984 | G5: =F100 -> 3708.082 | H5: =G5/G$4-1 -> -0.27533715 | I5: =E88 -> 0.82108706
A6: 市場層營收 +20%（價格） | B6: 價格係數 1.2 | C6: =E131 -> 14879.716 | D6: =E150 -> 6016.8322 | E6: =D6/D$4-1 -> 0.27100744 | F6: =F131 -> 15011.976 | G6: =F150 -> 6665.0126 | H6: =G6/G$4-1 -> 0.30252973 | I6: =E138 -> 0.88072471
A7: 份額 ×0.9（營收與位元） | B7: 份額係數 0.9 | C7: =E181 -> 11159.787 | D7: =E200 -> 4116.8458 | E7: =D7/D$4-1 -> -0.13034942 | F7: =F181 -> 11258.982 | G7: =F200 -> 4396.3352 | H7: =G7/G$4-1 -> -0.14083324 | I7: =E188 -> 0.84096628
A8: 份額 ×1.1 | B8: 份額係數 1.1 | C8: =E231 -> 13639.739 | D8: =E250 -> 5367.0251 | E8: =D8/D$4-1 -> 0.13374092 | F8: =F231 -> 13760.978 | G8: =F250 -> 5872.3438 | H8: =G8/G$4-1 -> 0.14762009 | I8: =E238 -> 0.8698815
A9: 匯率 145 日圓 | B9: fx 低 | C9: =E281 -> 11237.285 | D9: =E300 -> 4154.9534 | E9: =D9/D$4-1 -> -0.1222995 | F9: =F281 -> 11337.169 | G9: =F300 -> 4440.4032 | H9: =G9/G$4-1 -> -0.13222113 | I9: =E288 -> 0.84206306
A10: 匯率 170 日圓 | B10: fx 高 | C10: =E331 -> 13174.748 | D10: =E350 -> 5127.6851 | E10: =D10/D$4-1 -> 0.083182272 | F10: =F331 -> 13291.854 | G10: =F350 -> 5584.853 | H10: =G10/G$4-1 -> 0.091436359 | I10: =E338 -> 0.86528908
A11: 每位元成本年降 10%（C 的值） | B11: cd_C | C11: =E381 -> 12399.763 | D11: =E400 -> 4687.2351 | E11: =D11/D$4-1 -> -0.0098592677 | F11: =F381 -> 12509.98 | G11: =F400 -> 5009.3356 | H11: =G11/G$4-1 -> -0.02103583 | I11: =E388 -> 0.84930793
A12: 每位元成本年降 18% | B12: cd_A 高 | C12: =E431 -> 12399.763 | D12: =E450 -> 4780.2406 | E12: =D12/D$4-1 -> 0.0097873934 | F12: =F431 -> 12509.98 | G12: =F450 -> 5219.6277 | H12: =G12/G$4-1 -> 0.020061121 | I12: =E438 -> 0.86436144
A13: 第二季營業費用 50（校準） | B13: g2_ox 低 | C13: =E481 -> 12399.763 | D13: =E500 -> 4735.2355 | E13: =D13/D$4-1 -> 0.00028044175 | F13: =F481 -> 12509.98 | G13: =F500 -> 5119.2513 | H13: =G13/G$4-1 -> 0.00044477336 | I13: =E488 -> 0.8538479
A14: 第二季營業費用 70 | B14: g2_ox 高 | C14: =E531 -> 12399.763 | D14: =E550 -> 4732.2854 | E14: =D14/D$4-1 -> -0.0003427422 | F14: =F531 -> 12509.98 | G14: =F550 -> 5114.1941 | H14: =G14/G$4-1 -> -0.00054354041 | I14: =E538 -> 0.8605629
A15: 營業費用變動率 2% | B15: ox_var 高 | C15: =E581 -> 12399.763 | D15: =E600 -> 4727.0712 | E15: =D15/D$4-1 -> -0.0014441997 | F15: =F581 -> 12509.98 | G15: =F600 -> 5114.2816 | H15: =G15/G$4-1 -> -0.00052644314 | I15: =E588 -> 0.85686965
A16: 稅率 35% | B16: tax 高 | C16: =E631 -> 12399.763 | D16: =E650 -> 4503.1899 | E16: =D16/D$4-1 -> -0.04873732 | F16: =F631 -> 12509.98 | G16: =F650 -> 4847.4154 | H16: =G16/G$4-1 -> -0.052679558 | I16: =E638 -> 0.85686965
A17: 稅率 28% | B17: tax 低 | C17: =E681 -> 12399.763 | D17: =E700 -> 5045.0378 | E17: =D17/D$4-1 -> 0.065723681 | F17: =F681 -> 12509.98 | G17: =F700 -> 5484.0348 | H17: =G17/G$4-1 -> 0.071733672 | I17: =E688 -> 0.85686965
A18: 股東回饋 ÷ FCF 50% | B18: payout 高 | C18: =E731 -> 12399.763 | D18: =E750 -> 5755.7756 | E18: =D18/D$4-1 -> 0.21586133 | F18: =F731 -> 12509.98 | G18: =F750 -> 7388.8936 | H18: =G18/G$4-1 -> 0.44399631 | I18: =E738 -> 0.85686965
A19: 股東回饋 0 | B19: payout 低 | C19: =E781 -> 12399.763 | D19: =E800 -> 4233.2633 | E19: =D19/D$4-1 -> -0.10575715 | F19: =F781 -> 12509.98 | G19: =F800 -> 4248.3114 | H19: =G19/G$4-1 -> -0.16976122 | I19: =E788 -> 0.85686965
A20: 情境 B | B20: markets/nand B；成本年降 12% | C20: =PL!E124 -> 10595.374 | D20: =PL!E143 -> 3868.0581 | E20: =D20/D$4-1 -> -0.18290383 | F20: =PL!F124 -> 4805.2812 | G20: =PL!F143 -> 1309.1147 | H20: =G20/G$4-1 -> -0.74416239 | I20: =PL!E131 -> 0.83293536
A21: 情境 C | B21: markets/nand C；成本年降 10% | C21: =PL!E171 -> 10189.221 | D21: =PL!E190 -> 3682.7328 | E21: =D21/D$4-1 -> -0.2220523 | F21: =PL!F171 -> 2915.3792 | G21: =PL!F190 -> 536.8556 | H21: =G21/G$4-1 -> -0.89508341 | I21: =PL!E178 -> 0.82798488
A23: 讀法：第二季為公司指引（固定），價格與匯率係數只作用在第三季起；營業費用校準改變成本起點（第二季營業成本＝營收 − 營業利益 − 營業費用）。
A60: 案例區塊：市場層營收 −20%（價格；第三季起）（情境 A）
A61: A. 季度 | B61: 單位 | C61: FY26 第1季（2026Q2） | D61: FY26 第2季（2026Q3） | E61: FY26 第3季（2026Q4） | F61: FY26 第4季（2027Q1） | G61: FY27 第1季（2027Q2） | H61: FY27 第2季（2027Q3） | I61: FY27 第3季（2027Q4） | J61: FY27 第4季（2028Q1） | K61: FY28 第1季（2028Q2） | L61: FY28 第2季（2028Q3） | M61: FY28 第3季（2028Q4） | N61: FY28 第4季（2029Q1） | O61: FY29 第1季（2029Q2） | P61: FY29 第2季（2029Q3） | Q61: FY29 第3季（2029Q4） | R61: FY29 第4季（2030Q1） | T61: 說明
A62: 市場層營收（TrendForce 口徑，美元，同字母情境） | B62: $B | C62: =Units!H4*1 -> 10.72 | D62: =Units!I4*1 -> 14.951317 | E62: =Units!J4*1*0.8 -> 12.962852 | F62: =Units!K4*1*0.8 -> 14.283476 | G62: =Units!L4*1*0.8 -> 15.102937 | H62: =Units!M4*1*0.8 -> 15.170941 | I62: =Units!N4*1*0.8 -> 14.918425 | J62: =Units!O4*1*0.8 -> 14.985598 | K62: =Units!P4*1*0.8 -> 15.053074 | L62: =Units!Q4*1*0.8 -> 15.120853 | ... R62: =Units!W4*1*0.8 -> 16.047462 | T62: markets/nand；Sens 可乘份額係數、價格係數（第三季起）
A63: 位元（市場層；同字母） | B63: EB | C63: =Units!H7*1 -> 40.175758 | D63: =Units!I7*1 -> 44.826902 | E63: =Units!J7*1 -> 44.941148 | F63: =Units!K7*1 -> 48.077324 | G63: =Units!L7*1 -> 50.835581 | H63: =Units!M7*1 -> 53.752082 | I63: =Units!N7*1 -> 56.835907 | J63: =Units!O7*1 -> 60.096655 | ... R63: =Units!W7*1 -> 87.539517
A64: 營收 | B64: ¥B | C64: =q1_rev -> 1767.1 | D64: =g2_rev -> 2480 | E64: =E62*kx_k*fx -> 2136.8149 | F64: =F62*kx_k*fx -> 2354.5084 | G64: =G62*kx_k*fx -> 2489.5896 | H64: =H62*kx_k*fx -> 2500.7994 | I64: =I62*kx_k*fx -> 2459.1743 | J64: =J62*kx_k*fx -> 2470.2472 | K64: =K62*kx_k*fx -> 2481.37 | L64: =L62*kx_k*fx -> 2492.5429 | ... R64: =R62*kx_k*fx -> 2645.2864 | T64: 第一、二季實績；之後＝市場層 × 公司口徑係數 × 匯率
A65: SSD 與儲存 | B65: ¥B | C65: =q1_ss -> 1174.7 | D65: =D64*sssh_26 -> 1636.8 | E65: =E64*sssh_26 -> 1410.2978 | F65: =F64*sssh_26 -> 1553.9756 | G65: =G64*sssh_27 -> 1692.9209 | H65: =H64*sssh_27 -> 1700.5436 | I65: =I64*sssh_27 -> 1672.2385 | J65: =J64*sssh_27 -> 1679.7681 | K65: =K64*sssh_28 -> 1736.959 | L65: =L64*sssh_28 -> 1744.78 | M65: =M64*sssh_28 -> 1752.6362 | N65: =N64*sssh_28 -> 1771.2136 | O65: =O64*sssh_29 -> 1805.6461 | P65: =P64*sssh_29 -> 1840.7479 | Q65: =Q64*sssh_29 -> 1876.5322 | R65: =R64*sssh_29 -> 1851.7005 | T65: 官方分部；第一季實績，之後＝營收 × 占比（In）
A66: SSD 與儲存：AI 相關（＝SSD 與儲存 × AI 企業級 SSD 占比） | B66: ¥B | C66: =C65*(0.75*Units!D16+0.25*Units!E16) -> 687.40335 | D66: =D65*(0.75*Units!D16+0.25*Units!E16) -> 957.81204 | E66: =E65*(0.75*Units!D16+0.25*Units!E16) -> 825.26896 | F66: =F65*(0.75*Units!D16+0.25*Units!E16) -> 909.34538 | G66: =G65*(0.75*Units!E16+0.25*Units!F16) -> 1166.381 | H66: =H65*(0.75*Units!E16+0.25*Units!F16) -> 1171.6328 | I66: =I65*(0.75*Units!E16+0.25*Units!F16) -> 1152.1313 | J66: =J65*(0.75*Units!E16+0.25*Units!F16) -> 1157.319 | K66: =K65*(0.75*Units!F16+0.25*Units!G16) -> 1267.635 | L66: =L65*(0.75*Units!F16+0.25*Units!G16) -> 1273.3427 | M66: =M65*(0.75*Units!F16+0.25*Units!G16) -> 1279.0762 | N66: =N65*(0.75*Units!F16+0.25*Units!G16) -> 1292.634 | O66: =O65*(0.75*Units!G16+0.25*Units!H16) -> 1376.1869 | P66: =P65*(0.75*Units!G16+0.25*Units!H16) -> 1402.9401 | Q66: =Q65*(0.75*Units!G16+0.25*Units!H16) -> 1430.2133 | R66: =R65*(0.75*Units!G16+0.25*Units!H16) -> 1411.2876 | T66: 命題子列（Derived）：會計年度（4 月起）≈ 0.75 × 當年＋0.25 × 次年；假設公司 SSD 組合與產業（企業級＋PC）相同
A67: SSD 與儲存：非 AI | B67: ¥B | C67: =C65-C66 -> 487.29665 | D67: =D65-D66 -> 678.98796 | E67: =E65-E66 -> 585.02886 | F67: =F65-F66 -> 644.63019 | G67: =G65-G66 -> 526.53992 | H67: =H65-H66 -> 528.91077 | I67: =I65-I66 -> 520.10719 | J67: =J65-J66 -> 522.44908 | ... R67: =R65-R66 -> 440.41283
A68: 其他 | B68: ¥B | C68: =q1_rev-q1_ss-q1_sd -> 66.7 | D68: =D64*otsh_26 -> 99.2 | E68: =E64*otsh_26 -> 85.472595 | F68: =F64*otsh_26 -> 94.180337 | G68: =G64*otsh_27 -> 99.583582 | H68: =H64*otsh_27 -> 100.03198 | I68: =I64*otsh_27 -> 98.366973 | J68: =J64*otsh_27 -> 98.80989 | K68: =K64*otsh_28 -> 99.254801 | L68: =L64*otsh_28 -> 99.701716 | M68: =M64*otsh_28 -> 100.15064 | N68: =N64*otsh_28 -> 101.21221 | O68: =O64*otsh_29 -> 103.17978 | P68: =P64*otsh_29 -> 105.1856 | Q68: =Q64*otsh_29 -> 107.23041 | R68: =R64*otsh_29 -> 105.81145 | T68: 官方分部（零售、對 SanDisk 銷售）；實績＝營收 − 兩主分部
A69: 智慧裝置 | B69: ¥B | C69: =q1_sd -> 525.7 | D69: =D64-D65-D68 -> 744 | E69: =E64-E65-E68 -> 641.04446 | F69: =F64-F65-F68 -> 706.35253 | G69: =G64-G65-G68 -> 697.08508 | H69: =H64-H65-H68 -> 700.22384 | I69: =I64-I65-I68 -> 688.56881 | J69: =J64-J65-J68 -> 691.66923 | K69: =K64-K65-K68 -> 645.15621 | ... R69: =R64-R65-R68 -> 687.77446 | T69: 官方分部；預測季＝營收 − SSD 與儲存 − 其他
A70: 檢查：分部合計 − 營收（季） | B70: ¥B | C70: =C65+C69+C68-C64 -> 0 | D70: =D65+D69+D68-D64 -> 0 | E70: =E65+E69+E68-E64 -> 0 | F70: =F65+F69+F68-F64 -> 0 | G70: =G65+G69+G68-G64 -> 0 | H70: =H65+H69+H68-H64 -> 0 | I70: =I65+I69+I68-I64 -> 0 | J70: =J65+J69+J68-J64 -> 0 | ... R70: =R65+R69+R68-R64 -> 0
A71: 每 EB 營業成本（第二季以實績校準，之後每年 × (1 − 成本年降)） | B71: ¥B/EB | C71: =C72/C63 -> 9.6326745 | D71: =D72/D63 -> 9.5099143 | E71: =$D71*(1-cd_A)^(1/4) -> 9.1580122 | F71: =$D71*(1-cd_A)^(2/4) -> 8.8191318 | G71: =$D71*(1-cd_A)^(3/4) -> 8.4927911 | H71: =$D71*(1-cd_A)^(4/4) -> 8.1785263 | I71: =$D71*(1-cd_A)^(5/4) -> 7.8758905 | J71: =$D71*(1-cd_A)^(6/4) -> 7.5844533 | K71: =$D71*(1-cd_A)^(7/4) -> 7.3038004 | L71: =$D71*(1-cd_A)^(8/4) -> 7.0335326 | M71: =$D71*(1-cd_A)^(9/4) -> 6.7732658 | N71: =$D71*(1-cd_A)^(10/4) -> 6.5226298 | O71: =$D71*(1-cd_A)^(11/4) -> 6.2812683 | P71: =$D71*(1-cd_A)^(12/4) -> 6.0488381 | Q71: =$D71*(1-cd_A)^(13/4) -> 5.8250086 | R71: =$D71*(1-cd_A)^(14/4) -> 5.6094617
A72: 營業成本 | B72: ¥B | C72: =q1_rev-q1_gp -> 387 | D72: =g2_rev-g2_op-g2_ox -> 426.3 | E72: =E63*E71 -> 411.57158 | F72: =F63*F71 -> 424.00025 | G72: =G63*G71 -> 431.73597 | H72: =H63*H71 -> 439.61282 | I72: =I63*I71 -> 447.63338 | J72: =J63*J71 -> 455.80027 | K72: =K63*K71 -> 464.11617 | L72: =L63*L71 -> 472.58378 | ... R72: =R63*R71 -> 491.04957 | T72: 第二季＝實績營收 − 實績營業利益 − 推估營業費用
A73: 毛利率 | B73: % | C73: =1-C72/C64 -> 0.78099711 | D73: =1-D72/D64 -> 0.82810484 | E73: =1-E72/E64 -> 0.80739016 | F73: =1-F72/F64 -> 0.81991984 | G73: =1-G72/G64 -> 0.82658348 | H73: =1-H72/H64 -> 0.82421109 | I73: =1-I72/I64 -> 0.81797412 | J73: =1-J72/J64 -> 0.81548395 | ... R73: =1-R72/R64 -> 0.81436809
A74: 營業費用 | B74: ¥B | C74: =q1_gp-q1_op -> 110.1 | D74: =g2_ox -> 59 | E74: =(g2_ox-ox_var*g2_rev)*(1+ox_g)^(1/4)+ox_var*E64 -> 56.392837 | F74: =(g2_ox-ox_var*g2_rev)*(1+ox_g)^(2/4)+ox_var*F64 -> 59.414347 | G74: =(g2_ox-ox_var*g2_rev)*(1+ox_g)^(3/4)+ox_var*G64 -> 61.630098 | H74: =(g2_ox-ox_var*g2_rev)*(1+ox_g)^(4/4)+ox_var*H64 -> 62.627994 | I74: =(g2_ox-ox_var*g2_rev)*(1+ox_g)^(5/4)+ox_var*I64 -> 63.1189 | J74: =(g2_ox-ox_var*g2_rev)*(1+ox_g)^(6/4)+ox_var*J64 -> 64.158661 | K74: =(g2_ox-ox_var*g2_rev)*(1+ox_g)^(7/4)+ox_var*K64 -> 65.221323 | L74: =(g2_ox-ox_var*g2_rev)*(1+ox_g)^(8/4)+ox_var*L64 -> 66.307429 | M74: =(g2_ox-ox_var*g2_rev)*(1+ox_g)^(9/4)+ox_var*M64 -> 67.417533 | N74: =(g2_ox-ox_var*g2_rev)*(1+ox_g)^(10/4)+ox_var*N64 -> 68.704859 | O74: =(g2_ox-ox_var*g2_rev)*(1+ox_g)^(11/4)+ox_var*O64 -> 70.243329 | P74: =(g2_ox-ox_var*g2_rev)*(1+ox_g)^(12/4)+ox_var*P64 -> 71.816599 | Q74: =(g2_ox-ox_var*g2_rev)*(1+ox_g)^(13/4)+ox_var*Q64 -> 73.425462 | R74: =(g2_ox-ox_var*g2_rev)*(1+ox_g)^(14/4)+ox_var*R64 -> 74.194852 | T74: 固定部分以第二季校準（Derived）
A75: 營業利益 | B75: ¥B | C75: =C64-C72-C74 -> 1270 | D75: =D64-D72-D74 -> 1994.7 | E75: =E64-E72-E74 -> 1668.8505 | F75: =F64-F72-F74 -> 1871.0938 | G75: =G64-G72-G74 -> 1996.2235 | H75: =H64-H72-H74 -> 1998.5586 | I75: =I64-I72-I74 -> 1948.422 | J75: =J64-J72-J74 -> 1950.2883 | ... R75: =R64-R72-R74 -> 2080.0419
A77: 淨利 | B77: ¥B | C77: =q1_ni -> 842.2 | D77: =g2_ni -> 1360 | E77: =(E75+nonop_q+rf*nc_j/4)*(1-tax) -> 1124.8842 | F77: =(F75+nonop_q+rf*nc_j/4)*(1-tax) -> 1262.4097 | G77: =(G75+nonop_q+rf*$D98/4)*(1-tax) -> 1352.4616 | H77: =(H75+nonop_q+rf*$D98/4)*(1-tax) -> 1354.0495 | I77: =(I75+nonop_q+rf*$D98/4)*(1-tax) -> 1319.9566 | J77: =(J75+nonop_q+rf*$D98/4)*(1-tax) -> 1321.2256 | K77: =(K75+nonop_q+rf*$E98/4)*(1-tax) -> 1329.4806 | L77: =(L75+nonop_q+rf*$E98/4)*(1-tax) -> 1330.5816 | M77: =(M75+nonop_q+rf*$E98/4)*(1-tax) -> 1331.5955 | N77: =(N75+nonop_q+rf*$E98/4)*(1-tax) -> 1347.6859 | O77: =(O75+nonop_q+rf*$F98/4)*(1-tax) -> 1383.1803 | P77: =(P75+nonop_q+rf*$F98/4)*(1-tax) -> 1412.1958 | Q77: =(Q75+nonop_q+rf*$F98/4)*(1-tax) -> 1441.8016 | R77: =(R75+nonop_q+rf*$F98/4)*(1-tax) -> 1423.5845 | T77: （營業利益＋業外＋淨現金 × 收益率 ÷ 4）×（1 − 稅率）；FY2026 用 2026-06-30 淨現金
A78: 季 EPS（稀釋，分割後） | B78: JPY | C78: =C77/(sh0+dil)*1000 -> 507.34333 | D78: =D77/(sh0+dil)*1000 -> 819.26731 | E78: =E77/(sh0+dil)*1000 -> 677.63298 | F78: =F77/(sh0+dil)*1000 -> 760.47867 | G78: =G77/(sh0+dil)*1000 -> 814.72615 | H78: =H77/(sh0+dil)*1000 -> 815.6827 | I78: =I77/(sh0+dil)*1000 -> 795.14506 | J78: =J77/(sh0+dil)*1000 -> 795.90955 | ... R78: =R77/(sh0+dil)*1000 -> 857.57077
A80: B. 年度（會計年度） | B80: 單位 | C80: FY2025A | D80: FY2026 | E80: FY2027 | F80: FY2028 | G80: FY2029 | T80: 說明
...

Sheet Sources
A1: 來源
A2: Kioxia FY2026 第一季財報（2026-07-31；SGX 轉載） | B2: https://links.sgx.com/1.0.0/corporate-announcements/DOATO9EIE4EEQ2Y8/898078_Earnings-Release-FY2026-1Q-EN.pdf
A3: Kioxia：第二季財報 2026-10-30 18:45（JST）公布（公司新聞頁） | B3: https://www.kioxia-holdings.com/en-jp/news/2026.html
A4: storagenewsletter：Kioxia FY25 決算（營收 2,337.6、營業利益 870、淨利 554） | B4: https://www.storagenewsletter.com/?p=302700
A5: stockanalysis：季度損益、歷史股價、共識 | B5: https://stockanalysis.com/quote/tyo/285A/financials/?p=quarterly
A6: MarketScreener：Kioxia 預估與共識目標價 | B6: https://uk.marketscreener.com/quote/stock/KIOXIA-HOLDINGS-CORPORATI-180030735/finances/
A7: MarketScreener：SanDisk 預估（同業 P/B、P/E） | B7: https://uk.marketscreener.com/quote/stock/SANDISK-CORPORATION-182801077/finances/
A8: TrendForce：Kioxia FY26–28 資本支出（2026-06-03） | B8: https://www.trendforce.com/news/2026/06/03/news-kioxia-targets-%C2%A5470b-yearly-capex-in-fy26-28-up-66-from-fy25-reportedly-weighing-third-kitakami-fab-and-ma/
A9: newsquawk：一股分三股公告（2026-07-31） | B9: https://www.newsquawk.com/headlines/kioxia-285a-jt-q1-jpy-net-profit-84217bln-exp-9736bln-revenue-177tln-prev-3428bln-yy-announces-a-3-for-1-stock-split-and-announces-a-share-buyback
A10: stockanalysis：WDC 統計（Forward P/E） | B10: https://stockanalysis.com/stocks/wdc/statistics/
A11: 市場層：markets/nand/dist/20261031_NAND市場模型_v0.3.xlsx（markets/nand v0.1） | B11: 本 repo
A12: 美光十年倍數與淨利率（Analogy）：micron/dist/20261030_美光個股模型_v0.4.3.xlsx | B12: 本 repo
A13: SemiAnalysis | B13: 未使用
