Workbook

Sheet README
A1: 欣興電子（3037.TW）收支與估值模型 v0.1.1（AI 半導體 Project：載板與 PCB 次產業） 2026-10-25
A2: 版本：v0.1.1（2026-10-25：補上檔空間級距、投資建議、重點觀察，數值不變）。前版：v0.1（初版）。樣板：ibiden/。AI 加速器載板的每顆金額、Ibiden 份額與非 NVIDIA 權重讀 ibiden/dist（本專案權威），欣興份額與 Ibiden 合計在 Units 頁檢查。
A3: 模型命題：欣興的 ABF 載板營收＝MIN（需求, 產能）；需求＝AI 加速器顆數 × 每顆載板金額（面積與層數 × 溢價，與 Ibiden 同口徑）× 欣興份額，加上交換器、伺服器 CPU 等其他 AI 載板（隨 AI IT 資本支出）與非 AI ABF；產能依光復二廠、楊梅二廠時程擴張。BT、HDI／PCB、軟板另推。2026 年資本支出 537 億、2027–28 年仍在 400–550 億，擴產折舊是毛利率的關鍵。
A4: 核心問題：ABF 短缺與漲價能不能抵過擴產折舊，讓毛利率從 FY2026 約 25% 持續上升、EPS 在 FY2027–28 倍增；約 42 倍前瞻 P/E 隱含什麼路徑。
A6: 會計年度＝日曆年，FY(t)＝CY(t)，不平移。預測期 FY2027–FY2029 由驅動因子推導；FY2030 起為收斂法，非驅動因子推導（延伸到 FY2032；PL 頁灰底）。金額：十億新台幣；EPS：新台幣（基本、歸屬母公司）。3Q26 財報約 2026-10-29 公布，本版只納入 3Q26 營收實績。
A8: 驅動因子 → 推導量（全部唯讀上游，不修改）
A9: 加速器載板：markets/network 的 NVIDIA 與非 NVIDIA 顆數 × 情境係數（tsmc）× 每顆 NVIDIA 載板金額（Ibiden 模型 FY2026 校準 US$215 × 面積層數 +18%／年 × Ibiden 溢價指數）× 欣興份額（NVIDIA 25%→30%、非 NVIDIA 金額 30%→33%，Assumed；非 NVIDIA 每顆金額 ＝ 0.8 × NVIDIA）× 漲價年度化 1.05。
A10: 其他 AI 載板＝FY2026 AI 載板（ABF × 75%）− 加速器載板（校準殘差），之後 × AI IT 資本支出成長 ^ 0.5；非 AI ABF +3%。ABF 產能指數 1.35／1.70／2.00（Assumed）× 組合 +5%／年 × 溢價；營收＝MIN（需求, 產能）。BT +5%、AI HDI／PCB +20%／+15%／+10%（× 顆數情境係數）、非 AI HDI／PCB +2%、軟板與其他持平。
A11: 毛利＝FY2026 錨點＋ABF 現金毛利增量（50%）＋其他產品現金毛利增量（25%）＋漲價溢價營收 − 折舊增量；折舊＝前一年 ×（1 − 1／8 年）＋前一年資本支出 ÷ 8 年；資本支出依情境。營業費用彈性 0.6；業外每年 20 億；稅與少數股權 18%；股數持平（GDR 後 16.4 億股）。
A12: 校準：FY2026 ＝ 1H26 財報實績（EPS 11.70，含 2Q26 一次性業外約 89 億）＋3Q26 營收實績 526.5 億＋3Q26 毛利率 27%、4Q26 營收季增 5%、毛利率 28.5%（Assumed）。不用券商數字（只在 Recon 對帳）。
A13: 估值：Val 第 0 節目標價＝0.5 × DCF 目標價（股東現金流＝每股（淨利＋折舊－資本支出），FY2027–32 明確期＋永續，r 10%、g 4%，三情境權重 0.3／0.5／0.2）＋0.5 × Comparable 目標價（Ibiden、景碩、南電、三星電機、AT&S 前瞻 P/E 中位數 × 12 個月後前瞻 EPS；無 A 股）；另列 Comparable 單獨目標價、市場共識目標價與差距拆解。十年 P/E 規則值 × FY2027 EPS 保留為參考（不是目標價）。情境對應：A＝順利、B＝平平、C＝不如預期（原為顆數情境，另含資本支出路徑）。本版未做先驗，無 Andy 合理 P/E 對照。
A14: 預估期間：FY2027–FY2029 由驅動因子推導；FY2030 起為收斂法，非驅動因子推導（營收年增由 FY2029 線性收斂到 fade_g、淨利率收斂到 fade_m，FY2032 達到；十年平均淨利率未找到，依工作單以 FY2029 × 0.8 代替）。
... A18: v0.1.1：補上檔空間級距、投資建議、重點觀察（數值不變）。Val 頁最後新增「上檔空間級距」「投資建議」兩列（第 133、134 列，依「上檔空間：加權目標價」的固定規則）；重點觀察見下方三列。
A19: ="投資建議："&Val!B134&"（依上檔空間固定規則）" -> 投資建議：放空（依上檔空間固定規則）
A20: 重點觀察 1：目標價 NT$727（DCF 389、Comparable 1,065 各半），比現價 1,085（2026-10-22）低 33.0%，級距 −25%～−50%；Comparable 單獨為 −1.8%。主因是 DCF 不是 EPS：本模型前瞻 EPS 24.54 只比共識前瞻 EPS 25.66 低 4.4%，同業前瞻 P/E 中位數 43.4 倍與現價 ÷ 共識前瞻 EPS 42.3 倍相近；DCF 用每股（淨利＋折舊 − 資本支出），擴產期 FY2027 情境 A 每股現金流 9.16 只有 EPS 27.51 的 33%，DCF 比現價低 64.2%（改用 EPS ×（1 − g／ROE）只有 249，因 ROE 8.6% 低於折現率 10%）。
A21: 重點觀察 2：ABF 漲價路徑最敏感：ABF 溢價取 Ibiden 低值（2028 年 0.85）時 FY2028 EPS −24.1%、取高值 +24.1%；漲價年度化 0%（基準 5%）時 FY2027 EPS −11.1%，AI 部署 ×0.8 時 −19.4%。
A22: 重點觀察 3：情境分歧從 FY2028 開始：FY2027 EPS 三情境同為 27.51（比 2026-06 FactSet 共識 30.37 低 9.4%），FY2028 為 30.44／23.21／16.05。下一個檢驗點是 3Q26 財報與法說（約 2026-10-29）：ABF 報價與 2027 年資本支出。

Sheet In
A1: In — 輸入（藍字；基準欄 E，低 D、高 F）。金額：十億新台幣（NT$B）；顆數：百萬顆；比例：%。每個輸入附兩個來源（找不到者寫「未找到」）；公司原文算一個
A2: 標記：Verified／Interested-party／Analogy／Assumed／Derived；Analogy、Assumed 給低／高區間，不當點估計（放情境或 Sens）。SemiAnalysis 未使用。公司原文＝公開資訊觀測站財報與法說會（經工商時報、Quartr 轉載）；公司說法與指引為 Interested-party；券商、媒體、資料商為 Interested-party
A3: 鍵 | B3: 項目 | C3: 單位 | D3: 低 | E3: 基準 | F3: 高 | G3: 標記 | H3: 來源1 | I3: 來源2／說明
A4: A. AI 加速器顆數與 AI IT 資本支出（讀 markets/network、tsmc 成品；唯讀，不自行重估）
A5: u_bw_26 | B5: NVIDIA Blackwell（B200／B300） 顆數 2026 | C5: 百萬顆 | E5: 5.4 | G5: Derived | H5: markets/network/dist/20261026_AI網通市場模型_v0.2.3.xlsx｜In!E5 | I5: 唯讀上游；與 Ibiden、台積電模型同一份顆數
A6: u_bw_27 | B6: NVIDIA Blackwell（B200／B300） 顆數 2027 | C6: 百萬顆 | E6: 2.4 | G6: Derived | H6: markets/network/dist/20261026_AI網通市場模型_v0.2.3.xlsx｜In!E6 | I6: 唯讀上游；與 Ibiden、台積電模型同一份顆數
A7: u_bw_28 | B7: NVIDIA Blackwell（B200／B300） 顆數 2028 | C7: 百萬顆 | E7: 0.5 | G7: Derived | H7: markets/network/dist/20261026_AI網通市場模型_v0.2.3.xlsx｜In!E7 | I7: 唯讀上游；與 Ibiden、台積電模型同一份顆數
A8: g29_bw | B8: NVIDIA Blackwell（B200／B300） 2029 顆數成長 | C8: % | E8: -0.5 | G8: Derived | H8: markets/network/dist/20261026_AI網通市場模型_v0.2.3.xlsx｜In!E8 | I8: 同上
A9: u_rb_26 | B9: NVIDIA Rubin 顆數 2026 | C9: 百萬顆 | E9: 1.7 | G9: Derived | H9: markets/network/dist/20261026_AI網通市場模型_v0.2.3.xlsx｜In!E9 | I9: 唯讀上游；與 Ibiden、台積電模型同一份顆數
A10: u_rb_27 | B10: NVIDIA Rubin 顆數 2027 | C10: 百萬顆 | E10: 7 | G10: Derived | H10: markets/network/dist/20261026_AI網通市場模型_v0.2.3.xlsx｜In!E10 | I10: 唯讀上游；與 Ibiden、台積電模型同一份顆數
A11: u_rb_28 | B11: NVIDIA Rubin 顆數 2028 | C11: 百萬顆 | E11: 7 | G11: Derived | H11: markets/network/dist/20261026_AI網通市場模型_v0.2.3.xlsx｜In!E11 | I11: 唯讀上游；與 Ibiden、台積電模型同一份顆數
A12: g29_rb | B12: NVIDIA Rubin 2029 顆數成長 | C12: % | E12: 0.15 | G12: Derived | H12: markets/network/dist/20261026_AI網通市場模型_v0.2.3.xlsx｜In!E12 | I12: 同上
A13: u_ru_26 | B13: NVIDIA Rubin Ultra 顆數 2026 | C13: 百萬顆 | E13: 0 | G13: Derived | H13: markets/network/dist/20261026_AI網通市場模型_v0.2.3.xlsx｜In!E13 | I13: 唯讀上游；與 Ibiden、台積電模型同一份顆數
A14: u_ru_27 | B14: NVIDIA Rubin Ultra 顆數 2027 | C14: 百萬顆 | E14: 0.3 | G14: Derived | H14: markets/network/dist/20261026_AI網通市場模型_v0.2.3.xlsx｜In!E14 | I14: 唯讀上游；與 Ibiden、台積電模型同一份顆數
A15: u_ru_28 | B15: NVIDIA Rubin Ultra 顆數 2028 | C15: 百萬顆 | E15: 2 | G15: Derived | H15: markets/network/dist/20261026_AI網通市場模型_v0.2.3.xlsx｜In!E15 | I15: 唯讀上游；與 Ibiden、台積電模型同一份顆數
A16: g29_ru | B16: NVIDIA Rubin Ultra 2029 顆數成長 | C16: % | E16: 0.15 | G16: Derived | H16: markets/network/dist/20261026_AI網通市場模型_v0.2.3.xlsx｜In!E16 | I16: 同上
... A46: um29_C | B46: 情境 C：2029 顆數 ÷ 基準 | C46: x | E46: 0.6 | G46: Assumed | H46: tsmc/dist/20261025_台積電模型_v0.3.1.xlsx｜In!E42 | I46: 同上
A47: B. 每顆加速器載板金額與份額（口徑與 Ibiden 一致；Ibiden 數字唯讀取自 ibiden/dist）
A48: v26 | B48: FY2026 每顆 NVIDIA 加速器載板金額（全市場；Ibiden 模型校準） | C48: US$ | E48: 215.3086 | G48: Derived | H48: ibiden/dist/20261025_Ibiden模型_v0.2.1.xlsx｜Units!C8 | I48: Ibiden 模型：Ibiden 每顆營收 ÷ 份額 70%（BofA：Ibiden 占 GPU 載板 70–80%，Interested-party）
A49: g_asp | B49: 每顆載板金額年增（面積、層數；Ibiden 模型） | C49: % | D49: 0.1 | E49: 0.18 | F49: 0.22 | G49: Analogy | H49: ibiden/dist/20261025_Ibiden模型_v0.2.1.xlsx｜In!E50 | I49: Ibiden 路線圖 2026 年 90×90 mm → 2028 年 110×110 mm（Tom's Hardware，經 Ibiden 模型）
A50: ibpp_27 | B50: ABF 價格溢價指數 2027（FY2026＝1；Ibiden 模型） | C50: x | D50: 0.95 | E50: 1 | F50: 1.05 | G50: Assumed | H50: ibiden/dist/20261025_Ibiden模型_v0.2.1.xlsx｜In!E55 | I50: 全市場短缺溢價；新產能到位後回落（Ibiden 模型）
A51: ibrel_27 | B51: Ibiden NVIDIA 份額 2027 ÷ 2026（Ibiden 模型） | C51: x | E51: 0.95 | G51: Assumed | H51: ibiden/dist/20261025_Ibiden模型_v0.2.1.xlsx｜In!E51 | I51: Units 頁份額合計檢查用
A52: ibpp_28 | B52: ABF 價格溢價指數 2028（FY2026＝1；Ibiden 模型） | C52: x | D52: 0.85 | E52: 0.95 | F52: 1.05 | G52: Assumed | H52: ibiden/dist/20261025_Ibiden模型_v0.2.1.xlsx｜In!E56 | I52: 同上
A53: ibrel_28 | B53: Ibiden NVIDIA 份額 2028 ÷ 2026（Ibiden 模型） | C53: x | E53: 0.88 | G53: Assumed | H53: ibiden/dist/20261025_Ibiden模型_v0.2.1.xlsx｜In!E52 | I53: Units 頁份額合計檢查用
A54: ibpp_29 | B54: ABF 價格溢價指數 2029（FY2026＝1；Ibiden 模型） | C54: x | D54: 0.75 | E54: 0.9 | F54: 1 | G54: Assumed | H54: ibiden/dist/20261025_Ibiden模型_v0.2.1.xlsx｜In!E57 | I54: 同上
A55: ibrel_29 | B55: Ibiden NVIDIA 份額 2029 ÷ 2026（Ibiden 模型） | C55: x | E55: 0.85 | G55: Assumed | H55: ibiden/dist/20261025_Ibiden模型_v0.2.1.xlsx｜In!E53 | I55: Units 頁份額合計檢查用
A56: ib_sh26 | B56: Ibiden 占 NVIDIA 加速器載板 FY2026（Ibiden 模型假設） | C56: % | D56: 0.7 | E56: 0.7 | F56: 0.8 | G56: Interested-party | H56: ibiden/dist/20261025_Ibiden模型_v0.2.1.xlsx｜Units!C8（列標籤：假設 FY2026 份額 70%） | I56: BofA（經 thebuildout 2026-03-26）：Ibiden 70–80%
A57: ib_w_ot | B57: Ibiden 非 NVIDIA 權重（份額 × 每顆金額，相對 NVIDIA；Ibiden 模型） | C57: x | D57: 0.2 | E57: 0.4 | F57: 0.6 | G57: Assumed | H57: ibiden/dist/20261025_Ibiden模型_v0.2.1.xlsx｜In!E48 | I57: Units 頁：÷ v_ot 即 Ibiden 非 NVIDIA 份額
A58: v_ot | B58: 非 NVIDIA 加速器每顆載板金額 ÷ NVIDIA | C58: x | D58: 0.6 | E58: 0.8 | F58: 1 | G58: Assumed | H58: TPU、Trainium、MI 系列封裝面積接近 GPU，但層數與 CoWoS 規格不同；量化：未找到 | I58: Ibiden 權重 0.4 ÷ 0.8 ＝ Ibiden 非 NVIDIA 份額 50%（Units 頁合計檢查）
A59: sh_nv_26 | B59: 欣興占 NVIDIA 加速器載板 2026 | C59: % | D59: 0.2 | E59: 0.25 | F59: 0.3 | G59: Assumed | H59: 市場分析：欣興約占 Blackwell 載板供應鏈 30%（口袋學堂 2026-07，未經公司確認，Interested-party） | I59: Encyclopedia of Stocks 2026-03-04：欣興 2025 年約 30% NVIDIA AI 載板顆數（Interested-party）；與 Ibiden 70% 合計不超過 100%（Units 頁）
A60: sh_nv_27 | B60: 欣興占 NVIDIA 加速器載板 2027 | C60: % | D60: 0.22 | E60: 0.27 | F60: 0.32 | G60: Assumed | H60: Ibiden 份額相對值 0.95／0.88／0.85（Ibiden 模型）→ 由欣興、三星電機等分食 | I60: 光復二廠 2027、楊梅二廠 2028 量產，客戶全額預付（三立 2026-10-19，Interested-party）
A61: sh_nv_28 | B61: 欣興占 NVIDIA 加速器載板 2028 | C61: % | D61: 0.22 | E61: 0.29 | F61: 0.35 | G61: Assumed | H61: Ibiden 份額相對值 0.95／0.88／0.85（Ibiden 模型）→ 由欣興、三星電機等分食 | I61: 光復二廠 2027、楊梅二廠 2028 量產，客戶全額預付（三立 2026-10-19，Interested-party）
A62: sh_nv_29 | B62: 欣興占 NVIDIA 加速器載板 2029 | C62: % | D62: 0.22 | E62: 0.3 | F62: 0.36 | G62: Assumed | H62: Ibiden 份額相對值 0.95／0.88／0.85（Ibiden 模型）→ 由欣興、三星電機等分食 | I62: 光復二廠 2027、楊梅二廠 2028 量產，客戶全額預付（三立 2026-10-19，Interested-party）
A63: sh_ot_26 | B63: 欣興占非 NVIDIA 加速器載板（金額）2026 | C63: % | D63: 0.22 | E63: 0.3 | F63: 0.4 | G63: Assumed | H63: 欣興為 ASIC（TPU、Trainium 等）主要載板廠之一（第三方研究，Interested-party）；量化：未找到 | I63: 合計檢查：Ibiden 50%＋欣興 30%＝80%，其餘為三星電機、景碩、南電、AT&S（Units 頁）
A64: sh_ot_27 | B64: 欣興占非 NVIDIA 加速器載板（金額）2027 | C64: % | D64: 0.22 | E64: 0.31 | F64: 0.4 | G64: Assumed | H64: 同上 | I64: —
A65: sh_ot_28 | B65: 欣興占非 NVIDIA 加速器載板（金額）2028 | C65: % | D65: 0.22 | E65: 0.32 | F65: 0.4 | G65: Assumed | H65: 同上 | I65: —
A66: sh_ot_29 | B66: 欣興占非 NVIDIA 加速器載板（金額）2029 | C66: % | D66: 0.22 | E66: 0.33 | F66: 0.4 | G66: Assumed | H66: 同上 | I66: —
A67: C. FY2026 產品組合與 AI 占比（公司說法；Q2 組合推全年）
A68: mx_abf | B68: FY2026 ABF 載板 ÷ 營收 | C68: % | D68: 0.5 | E68: 0.53 | F68: 0.56 | G68: Interested-party | H68: 工商時報 2026-07-29（2Q26 法說：產品組合、稼動率、AI 占比、資本支出）：2Q26 ABF 52%（季增 22%）→ 1Q26 約 49%；下半年 AI 占比升 | I68: 富果 4Q25 法說摘要（2026-02-25，AI 摘要）：4Q25 載板（ABF＋BT）59%
A69: mx_bt | B69: FY2026 BT 載板 ÷ 營收 | C69: % | D69: 0.08 | E69: 0.09 | F69: 0.1 | G69: Interested-party | H69: 工商時報 2026-07-29（2Q26 法說：產品組合、稼動率、AI 占比、資本支出）：2Q26 BT 9% | I69: —
...

Sheet Q
A1: Q — FY2025 實績、1H26 實績、3Q26 營收實績與 FY2026 錨點（十億新台幣；EPS 新台幣、基本；股數十億股）。藍字＝輸入；黑字＝公式
A2: FY2026 錨點＝1Q、2Q26 財報實績＋3Q26 營收實績（月營收）與 3Q26 毛利率、費用假設＋4Q26 假設。3Q26 財報約 2026-10-29 公布，屆時以實績取代 E 欄（毛利率、費用、業外、淨利）
A3: 項目 | B3: FY2025A | C3: 1Q26（實績） | D3: 2Q26（實績） | E3: 3Q26（營收實績） | F3: 4Q26（模型） | G3: FY2026 錨點 | H3: 標記 | I3: 來源1（公司） | J3: 來源2／說明
A4: 營收 | B4: 131.241 | C4: =80.336-D4 -> 37.447 | D4: 42.889 | E4: =q3_rev -> 52.65 | F4: =E4*(1+q4_g) -> 55.2825 | G4: =SUM(C4:F4) -> 188.2685 | H4: Verified／Assumed（4Q） | I4: FY2025：stockanalysis 損益表（公司財報）；1H26、2Q26：工商時報 2026-07-29（公司財報） | J4: 1Q26 374.46 億（永豐 1Q26）；2Q26 428.89 億（Quartr 同）
A5: 毛利 | B5: 18.292 | C5: =C4*0.1796 -> 6.7254812 | D5: =D4*0.248 -> 10.636472 | E5: =E4*q3_gm -> 14.2155 | F5: =F4*q4_gm -> 15.755513 | G5: =SUM(C5:F5) -> 47.332966 | H5: Verified（毛利率 × 營收）／Assumed | I5: FY2025：stockanalysis 損益表（公司財報）；1H26、2Q26：工商時報 2026-07-29（公司財報） | J5: 毛利率：1Q26 17.96%、2Q26 24.8%（公司；Quartr 同）
A6: 毛利率 | B6: =B5/B4 -> 0.13937718 | C6: =C5/C4 -> 0.1796 | D6: =D5/D4 -> 0.248 | E6: =E5/E4 -> 0.27 | F6: =F5/F4 -> 0.285 | G6: =G5/G4 -> 0.25141203 | H6: Derived | I6: — | J6: FY2025 13.94%
A7: 營業費用 | B7: =B5-B8 -> 11.618 | C7: =C5-C8 -> 3.9684812 | D7: =D5-D8 -> 3.985472 | E7: =q3_opx -> 4.3 | F7: =q4_opx -> 4.4 | G7: =SUM(C7:F7) -> 16.653953 | H7: Derived／Assumed | I7: 毛利 − 營業利益 | J7: —
A8: 營業利益 | B8: 6.674 | C8: =9.408-D8 -> 2.757 | D8: 6.651 | E8: =E5-E7 -> 9.9155 | F8: =F5-F7 -> 11.355512 | G8: =SUM(C8:F8) -> 30.679012 | H8: Verified／Derived | I8: FY2025：stockanalysis 損益表（公司財報）；1H26、2Q26：工商時報 2026-07-29（公司財報） | J8: 1H26 94.08 億（口袋學堂；工商時報 94.07）
A9: 營業外淨額（FY2025＝淨利 − 營業利益，近似） | B9: =B11-B8 -> -0.001 | C9: =12.466-D9 -> 3.542 | D9: 8.924 | E9: =q_nonop -> 1 | F9: =q_nonop -> 1 | G9: =SUM(C9:F9) -> 14.466 | H9: Verified／Assumed | I9: FY2025：stockanalysis 損益表（公司財報）；1H26、2Q26：工商時報 2026-07-29（公司財報） | J9: 2Q26 含金融資產評價利益 92.1 億、湖口廠處分利益 5.6 億、欣興同泰減損 13.7 億（口袋學堂）
A10: 稅前利益 | C10: =C8+C9 -> 6.299 | D10: =D8+D9 -> 15.575 | E10: =E8+E9 -> 10.9155 | F10: =F8+F9 -> 12.355512 | G10: =SUM(C10:F10) -> 45.145012 | H10: Derived | I10: — | J10: 1H26 公布 218.75 億（核對見第 24 列）
A11: 歸屬母公司淨利 | B11: 6.673 | C11: =18.157-D11 -> 5.043 | D11: 13.114 | E11: =E10*(1-tax) -> 8.95071 | F11: =F10*(1-tax) -> 10.13152 | G11: =SUM(C11:F11) -> 37.23923 | H11: Verified／Derived | I11: FY2025：stockanalysis 損益表（公司財報）；1H26、2Q26：工商時報 2026-07-29（公司財報） | J11: 1Q26 50.43 億（永豐）；FY2025 業外與稅後淨利接近營業利益
A12: 所得稅與少數股權 | C12: =C10-C11 -> 1.256 | D12: =D10-D11 -> 2.461 | E12: =E10-E11 -> 1.96479 | F12: =F10-F11 -> 2.2239922 | G12: =SUM(C12:F12) -> 7.9057822 | H12: Derived | I12: — | J12: —
A13: 加權股數（十億股） | B13: =B11/B14 -> 1.523516 | C13: =C11/C14 -> 1.5375 | D13: =D11/D14 -> 1.5519527 | E13: =q_sh -> 1.64 | F13: =q_sh -> 1.64 | G13: =AVERAGE(C13:F13) -> 1.5923632 | H13: Derived | I13: 淨利 ÷ EPS；3Q 起含 GDR | J13: —
A14: EPS（基本） | B14: 4.38 | C14: 3.28 | D14: 8.45 | E14: =E11/E13 -> 5.45775 | F14: =F11/F13 -> 6.1777562 | G14: =G11/G13 -> 23.386141 | H14: Verified／Derived | I14: FY2025：stockanalysis 損益表（公司財報）；1H26、2Q26：工商時報 2026-07-29（公司財報） | J14: 1H26 11.70（工商時報）
A15: 折舊攤提（年度） | B15: 18.8 | G15: =da26 -> 20.8 | H15: Interested-party | I15: 富果 4Q25 法說摘要（2026-02-25，AI 摘要） | J15: stockanalysis 現金流量表 FY2025 18.46
A16: 資本支出（年度） | B16: 25.617 | G16: =capex26 -> 53.7 | H16: Verified／Interested-party | I16: FY2025：stockanalysis 現金流量表；FY2026：公司預算 537 億 | J16: —
A18: FY2026 產品別（錨點營收 × In 頁 C 節占比）
A19: ABF 載板 | G19: =G4*mx_abf -> 99.782305 | H19: Derived
A20: BT 載板 | G20: =G4*mx_bt -> 16.944165 | H20: Derived
A21: HDI＋PCB | G21: =G4*mx_pcb -> 58.363235 | H21: Derived
A22: 軟板與其他 | G22: =G4*(1-mx_abf-mx_bt-mx_pcb) -> 13.178795 | H22: Derived
A23: 檢查（參考；校準未使用券商數字）
A24: 1H26 稅前利益 自算 − 公司公布 21.875（應接近 0） | B24: =C10+D10-21.875 -> -0.001
A25: FY2026 營收年增 | B25: =G4/B4-1 -> 0.43452503
A26: FY2025→FY2026 現金毛利增量 ÷ 營收增量（含漲價；In 頁 ft_abf、ft_oth 的對照） | B26: =((G5+G15)-(B5+B15))/(G4-B4) -> 0.54431574
A27: FY2026 EPS ÷ 本土法人 23.42 − 1 | B27: =G14/23.42-1 -> -0.0014457105
A28: 4Q26 營收 ÷ 本土法人 57.92 − 1 | B28: =F4/57.92-1 -> -0.045536948

Sheet Units
A1: Units — 欣興在 AI 加速器載板的份額與每顆金額（口徑與 Ibiden 模型一致；情境 A）。份額合計＝Ibiden（ibiden/dist）＋欣興，其餘為三星電機、景碩、南電、AT&S 等
A3: 項目 | B3: 單位 | C3: CY2026 | D3: CY2027 | E3: CY2028 | F3: CY2029 | G3: 說明
A4: NVIDIA 加速器顆數 | B4: 百萬顆 | C4: =PL!D63 -> 7.6 | D4: =PL!E63 -> 9.7 | E4: =PL!F63 -> 9.5 | F4: =PL!G63 -> 10.6 | G4: markets/network
A5: 非 NVIDIA 加速器顆數 | B5: 百萬顆 | C5: =PL!D64 -> 7.6 | D5: =PL!E64 -> 14 | E5: =PL!F64 -> 17 | F5: =PL!G64 -> 19.55
A6: 每顆 NVIDIA 加速器載板金額（全市場） | B6: US$ | C6: =PL!D68 -> 215.3086 | D6: =PL!E68 -> 254.06414 | E6: =PL!F68 -> 284.8059 | F6: =PL!G68 -> 318.38302 | G6: Ibiden 模型 Units 頁同值（FY2026 校準 × 面積層數 × 溢價）
A7: 欣興份額：NVIDIA | B7: % | C7: =PL!D69 -> 0.25 | D7: =PL!E69 -> 0.27 | E7: =PL!F69 -> 0.29 | F7: =PL!G69 -> 0.3 | G7: Assumed
A8: Ibiden 份額：NVIDIA（70% × Ibiden 份額相對值） | B8: % | C8: =ib_sh26*1 -> 0.7 | D8: =ib_sh26*ibrel_27 -> 0.665 | E8: =ib_sh26*ibrel_28 -> 0.616 | F8: =ib_sh26*ibrel_29 -> 0.595 | G8: Ibiden 模型
A9: 合計：Ibiden＋欣興（NVIDIA） | B9: % | C9: =C7+C8 -> 0.95 | D9: =D7+D8 -> 0.935 | E9: =E7+E8 -> 0.906 | F9: =F7+F8 -> 0.895 | G9: 應 ≤ 100%；其餘為三星電機等
A10: 欣興份額：非 NVIDIA（金額） | B10: % | C10: =PL!D70 -> 0.3 | D10: =PL!E70 -> 0.31 | E10: =PL!F70 -> 0.32 | F10: =PL!G70 -> 0.33 | G10: Assumed
A11: Ibiden 份額：非 NVIDIA（Ibiden 權重 × 份額相對值 ÷ v_ot） | B11: % | C11: =ib_w_ot*1/v_ot -> 0.5 | D11: =ib_w_ot*ibrel_27/v_ot -> 0.475 | E11: =ib_w_ot*ibrel_28/v_ot -> 0.44 | F11: =ib_w_ot*ibrel_29/v_ot -> 0.425 | G11: Ibiden 模型的非 NVIDIA 權重假設份額相對值與 NVIDIA 同步
A12: 合計：Ibiden＋欣興（非 NVIDIA） | B12: % | C12: =C10+C11 -> 0.8 | D12: =D10+D11 -> 0.785 | E12: =E10+E11 -> 0.76 | F12: =F10+F11 -> 0.755 | G12: 應 ≤ 100%；其餘為景碩、南電、三星電機、AT&S
A13: 每顆 NVIDIA 加速器的欣興營收 | B13: US$ | C13: =PL!D68*PL!D69*PL!D67 -> 53.827149 | D13: =PL!E68*PL!E69*PL!E67 -> 72.027185 | E13: =PL!F68*PL!F69*PL!F67 -> 86.723398 | F13: =PL!G68*PL!G69*PL!G67 -> 100.29065 | G13: Ibiden 對照值見 ibiden/dist Units 頁
A14: 欣興加速器載板營收 | B14: US$M | C14: =PL!D71 -> 801.80921 | D14: =PL!E71 -> 1624.8799 | E14: =PL!F71 -> 2125.3213 | F14: =PL!G71 -> 2788.4813
A15: 欣興 AI 載板營收（含其他 AI） | B15: NT$B | C15: =PL!D81 -> 74.836729 | D15: =PL!E81 -> 123.23783 | E15: =PL!F81 -> 146.58476 | F15: =PL!G81 -> 169.00087
A16: 欣興 AI 載板營收 ÷ AI IT 資本支出 | B16: % | C16: =PL!D81/fx/itc_26 -> 0.0029450676 | D16: =PL!E81/fx/itc_27 -> 0.0024224187 | E16: =PL!F81/fx/itc_28 -> 0.0022730345 | F16: =PL!G81/fx/itc_29 -> 0.0023004995 | G16: × 每 GW IT capex 即每 GW 營收
A17: 每 GW 欣興 AI 載板營收（VR200 每 GW IT capex 37.59B） | B17: US$M | C17: =PL!D81/fx/itc_26*37.59*1000 -> 110.70509 | D17: =PL!E81/fx/itc_27*37.59*1000 -> 91.05872 | E17: =PL!F81/fx/itc_28*37.59*1000 -> 85.443365 | F17: =PL!G81/fx/itc_29*37.59*1000 -> 86.475776 | G17: Tokenomics IF_CapexIT（VR200 基準，經橋接表；與 Ibiden 模型相同係數）
A19: 讀法：欣興在 NVIDIA 加速器載板約占兩到三成、在 ASIC 約三成；加速器載板只占欣興 AI 載板約三成，其餘是交換器、伺服器 CPU 與網通 ASIC 載板（校準殘差，公司未揭露）。份額合計留給三星電機、景碩、南電、AT&S。

Sheet PL
A1: PL — 欣興損益（十億新台幣；EPS 新台幣、基本；歸屬母公司）。FY2025A 實績、FY2026 錨點（1H26 實績＋3Q26 營收實績＋假設；三情境相同），FY2027–FY2029 由驅動因子推導，FY2030 起為收斂法。三情境各一個完整推導區塊（本頁下方），頂端為摘要
A2: 灰底＝FY2030–FY2032 收斂法（上游顆數只到 2029）：營收年增線性收斂到 fade_g、淨利率線性收斂到 fade_m（In 頁 I 節），非驅動因子推導
A3: 情境／項目 | B3: 單位 | C3: FY2025A | D3: FY2026（錨點） | E3: FY2027 | F3: FY2028 | G3: FY2029 | H3: FY2030（收斂） | I3: FY2031（收斂） | J3: FY2032（收斂） | K3: 說明
A4: 情境 A
A5: 營收 | B5: NT$B | C5: =C88 -> 131.241 | D5: =D88 -> 188.2685 | E5: =E88 -> 245.84265 | F5: =F88 -> 278.51347 | G5: =G88 -> 308.3178 | H5: =H88 -> 336.47999 | I5: =I88 -> 361.94167 | J5: =J88 -> 383.65817
A6: 營收年增 | B6: % | D6: =D89 -> 0.43452503 | E6: =E89 -> 0.30580875 | F6: =F89 -> 0.13289317 | G6: =G89 -> 0.10701217 | H6: =H89 -> 0.091341446 | I6: =I89 -> 0.075670723 | J6: =J89 -> 0.06
A7: ABF 載板 | B7: NT$B | D7: =D79 -> 99.782305 | E7: =E79 -> 148.51349 | F7: =F79 -> 173.04952 | G7: =G79 -> 196.25957
A8: AI 載板 | B8: NT$B | D8: =D81 -> 74.836729 | E8: =E81 -> 123.23783 | F8: =F81 -> 146.58476 | G8: =G81 -> 169.00087
A9: ABF 需求滿足率 | B9: % | D9: =D80 -> 1 | E9: =E80 -> 0.98372057 | F9: =F80 -> 1 | G9: =G80 -> 1
A10: 毛利率 | B10: % | C10: =C98 -> 0.13937718 | D10: =D98 -> 0.25141203 | E10: =E98 -> 0.29584384 | F10: =F98 -> 0.28779177 | G10: =G98 -> 0.27895676
A11: 折舊攤提 | B11: NT$B | C11: =C94 -> 18.8 | D11: =D94 -> 20.8 | E11: =E94 -> 24.9125 | F11: =F94 -> 28.673437 | G11: =G94 -> 31.339258 | H11: =H94 -> 34.201831 | I11: =I94 -> 36.789908 | J11: =J94 -> 38.997303
A12: 營業利益率 | B12: % | C12: =C101 -> 0.050853011 | D12: =D101 -> 0.16295351 | E12: =E101 -> 0.21567179 | F12: =F101 -> 0.21138153 | G12: =G101 -> 0.20550108
A13: 歸屬母公司淨利 | B13: NT$B | C13: =C105 -> 6.673 | D13: =D105 -> 37.23923 | E13: =E105 -> 45.117487 | F13: =F105 -> 49.915535 | G13: =G105 -> 53.594905 | H13: =H105 -> 58.490342 | I13: =I105 -> 62.916348 | J13: =J105 -> 66.691329
A14: 淨利率 | B14: % | C14: =C109 -> 0.050845391 | D14: =D109 -> 0.19779852 | E14: =E109 -> 0.1835218 | F14: =F109 -> 0.17922126 | G14: =G109 -> 0.17383007 | H14: =H109 -> 0.17383007 | I14: =I109 -> 0.17383007 | J14: =J109 -> 0.17383007
A15: EPS | B15: NT$ | C15: =C107 -> 4.38 | D15: =D107 -> 23.386141 | E15: =E107 -> 27.510663 | F15: =F107 -> 30.436302 | G15: =G107 -> 32.67982 | H15: =H107 -> 35.664842 | I15: =I107 -> 38.363627 | J15: =J107 -> 40.665444
A16: EPS 年增 | B16: % | D16: =D108 -> 4.3393017 | E16: =E108 -> 0.17636606 | F16: =F108 -> 0.10634562 | G16: =G108 -> 0.073711936 | H16: =H108 -> 0.091341446 | I16: =I108 -> 0.075670723 | J16: =J108 -> 0.06
A18: 情境 B
A19: 營收 | B19: NT$B | C19: =C143 -> 131.241 | D19: =D143 -> 188.2685 | E19: =E143 -> 245.84265 | F19: =F143 -> 238.72615 | G19: =G143 -> 274.32961 | H19: =H143 -> 305.2629 | I19: =I143 -> 328.57882 | J19: =J143 -> 341.72197
A20: 營收年增 | B20: % | D20: =D144 -> 0.43452503 | E20: =E144 -> 0.30580875 | F20: =F144 -> -0.028947397 | G20: =G144 -> 0.14913936 | H20: =H144 -> 0.11275957 | I20: =I144 -> 0.076379786 | J20: =J144 -> 0.04
A21: ABF 載板 | B21: NT$B | D21: =D134 -> 99.782305 | E21: =E134 -> 148.51349 | F21: =F134 -> 143.73257 | G21: =G134 -> 170.90944
A22: AI 載板 | B22: NT$B | D22: =D136 -> 74.836729 | E22: =E136 -> 123.23783 | F22: =F136 -> 117.26781 | G22: =G136 -> 143.65074
A23: ABF 需求滿足率 | B23: % | D23: =D135 -> 1 | E23: =E135 -> 0.98372057 | F23: =F135 -> 1 | G23: =G135 -> 1
A24: 毛利率 | B24: % | C24: =C153 -> 0.13937718 | D24: =D153 -> 0.25141203 | E24: =E153 -> 0.29584384 | F24: =F153 -> 0.26720807 | G24: =G153 -> 0.26856773
A25: 折舊攤提 | B25: NT$B | C25: =C149 -> 18.8 | D25: =D149 -> 20.8 | E25: =E149 -> 24.9125 | F25: =F149 -> 27.798437 | G25: =G149 -> 29.573633 | H25: =H149 -> 32.908343 | I25: =I149 -> 35.421875 | J25: =J149 -> 36.83875
A26: 營業利益率 | B26: % | C26: =C156 -> 0.050853011 | D26: =D156 -> 0.16295351 | E26: =E156 -> 0.21567179 | F26: =F156 -> 0.18608005 | G26: =G156 -> 0.19165134
A27: 歸屬母公司淨利 | B27: NT$B | C27: =C160 -> 6.673 | D27: =D160 -> 37.23923 | E27: =E160 -> 45.117487 | F27: =F160 -> 38.066182 | G27: =G160 -> 44.752024 | H27: =H160 -> 48.138301 | I27: =I160 -> 50.028367 | J27: =J160 -> 50.171305
A28: 淨利率 | B28: % | C28: =C164 -> 0.050845391 | D28: =D164 -> 0.19779852 | E28: =E164 -> 0.1835218 | F28: =F164 -> 0.15945543 | G28: =G164 -> 0.16313231 | H28: =H164 -> 0.15769457 | I28: =I164 -> 0.15225682 | J28: =J164 -> 0.14681908
A29: EPS | B29: NT$ | C29: =C162 -> 4.38 | D29: =D162 -> 23.386141 | E29: =E162 -> 27.510663 | F29: =F162 -> 23.211086 | G29: =G162 -> 27.287819 | H29: =H162 -> 29.352623 | I29: =I162 -> 30.505102 | J29: =J162 -> 30.592259
A30: EPS 年增 | B30: % | D30: =D163 -> 4.3393017 | E30: =E163 -> 0.17636606 | F30: =F163 -> -0.15628764 | G30: =G163 -> 0.17563732 | H30: =H163 -> 0.075667587 | I30: =I163 -> 0.039263242 | J30: =J163 -> 0.0028571429
A32: 情境 C
A33: 營收 | B33: NT$B | C33: =C198 -> 131.241 | D33: =D198 -> 188.2685 | E33: =E198 -> 245.84265 | F33: =F198 -> 198.93883 | G33: =G198 -> 217.68265 | H33: =H198 -> 232.80709 | I33: =I198 -> 243.2228 | J33: =J198 -> 248.08725
A34: 營收年增 | B34: % | D34: =D199 -> 0.43452503 | E34: =E199 -> 0.30580875 | F34: =F199 -> -0.19078797 | G34: =G199 -> 0.094218975 | H34: =H199 -> 0.069479317 | I34: =I199 -> 0.044739658 | J34: =J199 -> 0.02
A35: ABF 載板 | B35: NT$B | D35: =D189 -> 99.782305 | E35: =E189 -> 148.51349 | F35: =F189 -> 114.41562 | G35: =G189 -> 128.65922
A36: AI 載板 | B36: NT$B | D36: =D191 -> 74.836729 | E36: =E191 -> 123.23783 | F36: =F191 -> 87.950854 | G36: =G191 -> 101.40052
A37: ABF 需求滿足率 | B37: % | D37: =D190 -> 1 | E37: =E190 -> 0.98372057 | F37: =F190 -> 1 | G37: =G190 -> 1
A38: 毛利率 | B38: % | C38: =C208 -> 0.13937718 | D38: =D208 -> 0.25141203 | E38: =E208 -> 0.29584384 | F38: =F208 -> 0.23901932 | G38: =G208 -> 0.24143537
A39: 折舊攤提 | B39: NT$B | C39: =C204 -> 18.8 | D39: =D204 -> 20.8 | E39: =E204 -> 24.9125 | F39: =F204 -> 26.798437 | G39: =G204 -> 27.198633 | H39: =H204 -> 29.088375 | I39: =I204 -> 30.389779 | J39: =J204 -> 30.997575
A40: 營業利益率 | B40: % | C40: =C211 -> 0.050853011 | D40: =D211 -> 0.16295351 | E40: =E211 -> 0.21567179 | F40: =F211 -> 0.15128641 | G40: =G211 -> 0.1567242
A41: 歸屬母公司淨利 | B41: NT$B | C41: =C215 -> 6.673 | D41: =D215 -> 37.23923 | E41: =E215 -> 45.117487 | F41: =F215 -> 26.319329 | G41: =G215 -> 29.615233 | H41: =H215 -> 29.561354 | I41: =I215 -> 28.677925 | J41: =J215 -> 27.001369
A42: 淨利率 | B42: % | C42: =C219 -> 0.050845391 | D42: =D219 -> 0.19779852 | E42: =E219 -> 0.1835218 | F42: =F219 -> 0.1322986 | G42: =G219 -> 0.13604775 | H42: =H219 -> 0.1269779 | I42: =I219 -> 0.11790805 | J42: =J219 -> 0.1088382
...

Sheet Val
A1: Val — P/E 估值（新台幣）。結論用「現價 ÷ FY2027、FY2028 EPS（模型）」；目標價＝DCF 與 Comparable 加權（第 0 節）；十年 P/E 規則值（第 3 節，年底落後 P/E）只作參考
A2: 循環位置：欣興不是設備股，不套設備市場見頂年；以本模型營收最高的會計年度為見頂年（比照 Ibiden、NVIDIA；FY(t)＝CY(t)）。營收到 FY2029 仍在增加時，見頂年未知，判為中段
A4: 0. 目標價
A5: 0.1 DCF（股東權益現金流，FY2027–FY2032 明確期＋FY2032 後永續）
A6: 項目 | B6: A（順利） | C6: B（平平） | D6: C（不如預期） | E6: 說明
A7: 情境 EPS（FY2027–FY2032） | E7: PL 頁各情境；FY2030 起為收斂法
A8: FY2027 | B8: =PL!E15 -> 27.510663 | C8: =PL!E29 -> 27.510663 | D8: =PL!E43 -> 27.510663
A9: FY2028 | B9: =PL!F15 -> 30.436302 | C9: =PL!F29 -> 23.211086 | D9: =PL!F43 -> 16.048371
A10: FY2029 | B10: =PL!G15 -> 32.67982 | C10: =PL!G29 -> 27.287819 | D10: =PL!G43 -> 18.058069
A11: FY2030 | B11: =PL!H15 -> 35.664842 | C11: =PL!H29 -> 29.352623 | D11: =PL!H43 -> 18.025216
A12: FY2031 | B12: =PL!I15 -> 38.363627 | C12: =PL!I29 -> 30.505102 | D12: =PL!I43 -> 17.48654
A13: FY2032 | B13: =PL!J15 -> 40.665444 | C13: =PL!J29 -> 30.592259 | D13: =PL!J43 -> 16.46425
A14: 股東現金流＝EPS ×（1 − tp_g ÷ tp_roe） | E14: 方法：欣興資本密集、模型有資本支出與折舊，改用每股（淨利＋折舊－資本支出）（PL 頁「每股股東現金流」；FY2030 起資本支出率收斂到穩態更新）
A15: 參考：再投資率（tp_g ÷ tp_roe，上限 0.8） | B15: =MIN(tp_g/tp_roe,0.8) -> 0.46296296 | E15: ROE 為近三年平均（In 頁 tp_roe）；本模型不採用，只作對照（第 25 列）
A16: FY2027 | B16: =PL!E112 -> 9.1646265 | C16: =PL!E167 -> 13.432919 | D16: =PL!E222 -> 18.310968
A17: FY2028 | B17: =PL!F112 -> 17.4323 | C17: =PL!F167 -> 14.551597 | D17: =PL!F222 -> 14.096199
A18: FY2029 | B18: =PL!G112 -> 24.3501 | C18: =PL!G167 -> 22.149791 | D18: =PL!G222 -> 17.569431
A19: FY2030 | B19: =PL!H112 -> 28.423675 | C19: =PL!H167 -> 24.404898 | D19: =PL!H222 -> 16.672574
A20: FY2031 | B20: =PL!I112 -> 32.563864 | C20: =PL!I167 -> 26.007924 | D20: =PL!I222 -> 15.20619
A21: FY2032 | B21: =PL!J112 -> 36.626404 | C21: =PL!J167 -> 26.776786 | D21: =PL!J222 -> 13.25376
A22: DCF 情境每股價值（折現率 tp_r） | B22: =SUMPRODUCT(B16:B21,1/(1+tp_r)^{1;2;3;4;5;6})+B21*(1+tp_g)/(tp_r-tp_g)/(1+tp_r)^6 -> 459.70154 | C22: =SUMPRODUCT(C16:C21,1/(1+tp_r)^{1;2;3;4;5;6})+C21*(1+tp_g)/(tp_r-tp_g)/(1+tp_r)^6 -> 350.80169 | D22: =SUMPRODUCT(D16:D21,1/(1+tp_r)^{1;2;3;4;5;6})+D21*(1+tp_g)/(tp_r-tp_g)/(1+tp_r)^6 -> 199.48473 | E22: Σ 明確期現金流 ÷ (1＋r)^t ＋ 永續價值 ÷ (1＋r)^6；永續價值＝FY2032 現金流 ×(1＋g)÷(r−g)；基準日 2026 年底
A23: DCF 情境價值推到 12 個月後（×(1＋tp_r)） | B23: =B22*(1+tp_r) -> 505.67169 | C23: =C22*(1+tp_r) -> 385.88186 | D23: =D22*(1+tp_r) -> 219.43321
A24: DCF 目標價（情境加權） | B24: =tp_wA*B23+tp_wB*C23+tp_wC*D23 -> 388.52908 | E24: Σ 權重 × 情境價值 ×(1＋r)；權重見 In 頁
A25: 參考：EPS ×（1 − g／ROE）法的 DCF 目標價（情境加權） | B25: =(tp_wA*(SUMPRODUCT(B8:B13,1/(1+tp_r)^{1;2;3;4;5;6})+B13*(1+tp_g)/(tp_r-tp_g)/(1+tp_r)^6)+tp_wB*(SUMPRODUCT(C8:C13,1/(1+tp_r)^{1;2;3;4;5;6})+C13*(1+tp_g)/(tp_r-tp_g)/(1+tp_r)^6)+tp_wC*(SUMPRODUCT(D8:D13,1/(1+tp_r)^{1;2;3;4;5;6})+D13*(1+tp_g)/(tp_r-tp_g)/(1+tp_r)^6))*(1-B15)*(1+tp_r) -> 249.49021 | E25: 近三年 ROE 約 9% → 再投資率約 46%；不進目標價
A26: 0.2 Comparable（市場主流同業前瞻 P/E）
A27: 同業與前瞻 P/E | B27: 代號 | C27: 前瞻 12 月 P/E | D27: 日期 | E27: 來源 | F27: 標記
A28: Ibiden（揖斐電） | B28: 4062.T | C28: 53.97 | D28: 2026-10-16 | E28: stockanalysis.com forward PE（分析師共識；價格日期如左） | F28: Interested-party
A29: 景碩（Kinsus） | B29: 3189.TW | C29: 44.7 | D29: 2026-10-22 | E29: stockanalysis.com forward PE（分析師共識；價格日期如左） | F29: Interested-party
A30: 南電（Nan Ya PCB） | B30: 8046.TW | C30: 33.73 | D30: 2026-09-07 | E30: stockanalysis.com forward PE（分析師共識；價格日期如左） | F30: Interested-party
A31: 三星電機（Samsung Electro-Mechanics） | B31: 009150.KS | C31: 43.4 | D31: 2026-08-28 | E31: stockanalysis.com forward PE（分析師共識；價格日期如左） | F31: Interested-party
A32: AT&S | B32: ATS.VI | C32: 14.91 | D32: 2026-10-23 | E32: stockanalysis.com forward PE（分析師共識；價格日期如左） | F32: Interested-party
A33: 同業前瞻 P/E 中位數 | B33: =MEDIAN(C28:C32) -> 43.4 | E33: ABF 載板同業：Ibiden、景碩、南電、三星電機、AT&S（無中國 A 股）；南電、三星電機價格日期較舊
A34: 12 個月後的前瞻 EPS（情境加權） | B34: =tp_wA*(2/12*B8+10/12*B9)+tp_wB*(2/12*C8+10/12*C9)+tp_wC*(2/12*D8+10/12*D9) -> 24.5402 | E34: 約 2027-10 時的未來 12 月 EPS ≈ 2／12 × FY2027＋10／12 × FY2028（會計年度＝日曆年）
A35: Comparable 目標價 | B35: =B33*B34 -> 1065.0447 | E35: 同業中位數 × 前瞻 EPS
A37: 0.3 結論
A38: 項目 | B38: 數值 | E38: 說明
A39: 目標價（DCF 與 Comparable 加權） | B39: =tp_w_dcf*B24+(1-tp_w_dcf)*B35 -> 726.78689 | E39: tp_w_dcf × DCF＋（1 − tp_w_dcf）× Comparable；tp_w_dcf 見 In 頁（0.5）
A40: Comparable 目標價（市場主流同業法） | B40: =B35 -> 1065.0447
A41: 市場共識目標價 | B41: =cons_tp -> 1317.37 | E41: stockanalysis：19 位分析師平均 1,317.37（2026-10-22 擷取）；本土法人 1,500（2026-10-19）
A42: 上檔空間：加權目標價 | B42: =B39/px-1 -> -0.33015033 | E42: 現價＝In 頁 px（2026-10-22 收盤）
...

Sheet Recon
A1: Recon — 本模型 vs 券商、共識與市場口徑。只作事後對照，不為對上數字而調參數。FactSet 共識為 2026-06（2Q26 財報前），10 月券商數字只有兩家
A3: 項目 | B3: 對照值 | C3: 模型 A | D3: 差距 A | E3: 模型 B | F3: 差距 B | G3: 模型 C | H3: 差距 C | I3: 對照來源 | J3: 說明
A4: A. EPS 與營收 vs 共識、券商
A5: FY2026 EPS vs 本土法人 23.42（2026-10-19） | B5: 23.42 | C5: =PL!D107 -> 23.386141 | D5: =C5/B5-1 -> -0.0014457105 | E5: =PL!D162 -> 23.386141 | F5: =E5/B5-1 -> -0.0014457105 | G5: =PL!D217 -> 23.386141 | H5: =G5/B5-1 -> -0.0014457105 | I5: 三立（本土法人） | J5: FactSet 2026-06 中位數 15.17 為 2Q26 一次性業外之前
A6: FY2026 EPS vs 美系券商 21（2026-10-12） | B6: 21 | C6: =PL!D107 -> 23.386141 | D6: =C6/B6-1 -> 0.11362578 | E6: =PL!D162 -> 23.386141 | F6: =E6/B6-1 -> 0.11362578 | G6: =PL!D217 -> 23.386141 | H6: =G6/B6-1 -> 0.11362578 | I6: 經濟日報（美系券商）
A7: FY2027 EPS vs 2026-10 券商平均（美系 37、本土 41.10） | B7: =bk_eps27 -> 39.05 | C7: =PL!E107 -> 27.510663 | D7: =C7/B7-1 -> -0.29550159 | E7: =PL!E162 -> 27.510663 | F7: =E7/B7-1 -> -0.29550159 | G7: =PL!E217 -> 27.510663 | H7: =G7/B7-1 -> -0.29550159 | I7: 經濟日報、三立 | J7: 差距超過 30% 的原因見 README
A8: FY2027 EPS vs FactSet 平均 30.37（2026-06） | B8: =cons_eps27 -> 30.37 | C8: =PL!E107 -> 27.510663 | D8: =C8/B8-1 -> -0.094150046 | E8: =PL!E162 -> 27.510663 | F8: =E8/B8-1 -> -0.094150046 | G8: =PL!E217 -> 27.510663 | H8: =G8/B8-1 -> -0.094150046 | I8: 鉅亨（FactSet 22 位）
A9: FY2028 EPS vs FactSet 平均 48.52（2026-06） | B9: =cons_eps28 -> 48.52 | C9: =PL!F107 -> 30.436302 | D9: =C9/B9-1 -> -0.37270607 | E9: =PL!F162 -> 23.211086 | F9: =E9/B9-1 -> -0.52161817 | G9: =PL!F217 -> 16.048371 | H9: =G9/B9-1 -> -0.66924214 | I9: 鉅亨（FactSet） | J9: 美系券商 2026-10：64.8
A10: FY2028 EPS vs 美系券商 64.8（2026-10） | B10: 64.8 | C10: =PL!F107 -> 30.436302 | D10: =C10/B10-1 -> -0.53030399 | E10: =PL!F162 -> 23.211086 | F10: =E10/B10-1 -> -0.64180422 | G10: =PL!F217 -> 16.048371 | H10: =G10/B10-1 -> -0.75233995 | I10: 經濟日報
A11: FY2027 營收 vs FactSet 平均（2026-06） | B11: =cons_rev27 -> 255.2 | C11: =PL!E88 -> 245.84265 | D11: =C11/B11-1 -> -0.036666714 | E11: =PL!E143 -> 245.84265 | F11: =E11/B11-1 -> -0.036666714 | G11: =PL!E198 -> 245.84265 | H11: =G11/B11-1 -> -0.036666714 | I11: 鉅亨（FactSet）
A12: FY2028 營收 vs FactSet 平均（2026-06） | B12: =cons_rev28 -> 326.5 | C12: =PL!F88 -> 278.51347 | D12: =C12/B12-1 -> -0.14697254 | E12: =PL!F143 -> 238.72615 | F12: =E12/B12-1 -> -0.26883262 | G12: =PL!F198 -> 198.93883 | H12: =G12/B12-1 -> -0.3906927 | I12: 鉅亨（FactSet）
A13: 模型前瞻 12 月 EPS（0.2 × FY2026＋0.8 × FY2027）vs 現價 ÷ 前瞻 P/E | B13: =cons_feps -> 25.662252 | C13: =0.2*PL!D107+0.8*PL!E107 -> 26.685759 | D13: =C13/B13-1 -> 0.039883761 | E13: =0.2*PL!D162+0.8*PL!E162 -> 26.685759 | F13: =E13/B13-1 -> 0.039883761 | G13: =0.2*PL!D217+0.8*PL!E217 -> 26.685759 | H13: =G13/B13-1 -> 0.039883761 | I13: stockanalysis（推導） | J13: 口徑不同，只作量級比較
A14: B. 錨點與毛利率
A15: 3Q26 毛利率（假設）vs 本土法人估 27.2%（百分點） | B15: 0.272 | C15: =Q!E6 -> 0.27 | D15: =C15-B15 -> -0.002 | E15: =Q!E6 -> 0.27 | F15: =E15-B15 -> -0.002 | G15: =Q!E6 -> 0.27 | H15: =G15-B15 -> -0.002 | I15: 三立（本土法人） | J15: 3Q26 財報約 10-29
A16: 4Q26 營收（假設）vs 本土法人估 579.2 億 | B16: 57.92 | C16: =Q!F4 -> 55.2825 | D16: =C16/B16-1 -> -0.045536948 | E16: =Q!F4 -> 55.2825 | F16: =E16/B16-1 -> -0.045536948 | G16: =Q!F4 -> 55.2825 | H16: =G16/B16-1 -> -0.045536948 | I16: 三立
A17: FY2027 毛利率 vs 4Q26 毛利率（假設）（百分點） | B17: =Q!F6 -> 0.285 | C17: =PL!E98 -> 0.29584384 | D17: =C17-B17 -> 0.010843837 | E17: =PL!E153 -> 0.29584384 | F17: =E17-B17 -> 0.010843837 | G17: =PL!E208 -> 0.29584384 | H17: =G17-B17 -> 0.010843837 | I17: Q 頁 | J17: 擴產折舊增量抵銷部分規模效益
A18: FY2028 毛利率 vs FY2026 錨點（百分點） | B18: =Q!G6 -> 0.25141203 | C18: =PL!F98 -> 0.28779177 | D18: =C18-B18 -> 0.036379739 | E18: =PL!F153 -> 0.26720807 | F18: =E18-B18 -> 0.015796042 | G18: =PL!F208 -> 0.23901932 | H18: =G18-B18 -> -0.012392707 | I18: Q 頁
A19: C. 產能、份額與 AI 口徑
A20: FY2027 ABF 需求滿足率（< 100%＝產能受限） | C20: =PL!E80 -> 0.98372057 | E20: =PL!E135 -> 0.98372057 | G20: =PL!E190 -> 0.98372057 | I20: PL 頁 | J20: 外資：ABF 供需缺口 2027 年 27%（永豐 1Q26 轉述）
A21: FY2028 ABF 需求滿足率 | C21: =PL!F80 -> 1 | E21: =PL!F135 -> 1 | G21: =PL!F190 -> 1 | I21: PL 頁
A22: FY2026 AI 占營收 vs 公司 2H26 約 70%（百分點） | B22: 0.7 | C22: =PL!D91 -> 0.599 | D22: =C22-B22 -> -0.101 | E22: =PL!D146 -> 0.599 | F22: =E22-B22 -> -0.101 | G22: =PL!D201 -> 0.599 | H22: =G22-B22 -> -0.101 | I22: 工商時報 2Q26 法說 | J22: 全年口徑低於下半年
A23: FY2027 份額合計：Ibiden＋欣興（NVIDIA） | C23: =Units!D9 -> 0.935 | E23: =Units!D9 -> 0.935 | G23: =Units!D9 -> 0.935 | I23: Units 頁 | J23: 應 ≤ 100%
A24: FY2027 份額合計：Ibiden＋欣興（非 NVIDIA） | C24: =Units!D12 -> 0.785 | E24: =Units!D12 -> 0.785 | G24: =Units!D12 -> 0.785 | I24: Units 頁 | J24: 應 ≤ 100%
A25: FY2027 每顆 NVIDIA 加速器的欣興營收（US$） | C25: =Units!D13 -> 72.027185 | E25: =Units!D13 -> 72.027185 | G25: =Units!D13 -> 72.027185 | I25: Units 頁 | J25: Ibiden 同期約 169（ibiden/dist Units 頁）
A26: FY2027 每 GW 欣興 AI 載板營收（US$M） | C26: =Units!D17 -> 91.05872 | E26: =Units!D17 -> 91.05872 | G26: =Units!D17 -> 91.05872 | I26: Units 頁 | J26: Ibiden 同期約 62（只含加速器載板）
A27: D. 資本支出
A28: FY2027 資本支出 vs 美系券商「逾 400 億」 | B28: 40 | C28: =PL!E93 -> 55 | D28: =C28/B28-1 -> 0.375 | E28: =PL!E148 -> 48 | F28: =E28/B28-1 -> 0.2 | G28: =PL!E203 -> 40 | H28: =G28/B28-1 -> 0 | I28: 經濟日報
A29: FY2028 資本支出 vs 美系券商「逾 400 億」 | B29: 40 | C29: =PL!F93 -> 50 | D29: =C29/B29-1 -> 0.25 | E29: =PL!F148 -> 42 | F29: =E29/B29-1 -> 0.05 | G29: =PL!F203 -> 30 | H29: =G29/B29-1 -> -0.25 | I29: 經濟日報

Sheet Sens
A1: Sens — 一次動一個輸入（情境 A；FY2026 恆等於錨點，其他 AI 載板在每個案例內重新校準）：對 FY2027、FY2028 營收、毛利率與 EPS 的影響。每個案例是一個完整推導區塊（本頁下方）
A3: 案例 | B3: 設定 | C3: FY2027 營收 | D3: FY2027 毛利率 | E3: FY2027 EPS | F3: FY2027 EPS 相對基準 | G3: FY2028 營收 | H3: FY2028 毛利率 | I3: FY2028 EPS | J3: FY2028 EPS 相對基準
A4: 基準（情境 A） | B4: PL 區塊 A | C4: =PL!E88 -> 245.84265 | D4: =PL!E98 -> 0.29584384 | E4: =PL!E107 -> 27.510663 | F4: =E4/E$4-1 -> 0 | G4: =PL!F88 -> 278.51347 | H4: =PL!F98 -> 0.28779177 | I4: =PL!F107 -> 30.436302 | J4: =I4/I$4-1 -> 0
A5: AI 部署 ×0.8 | B5: FY2027 起顆數與其他 AI ×0.8 | C5: =E78 -> 223.24493 | D5: =E88 -> 0.27272364 | E5: =E97 -> 22.186919 | F5: =E5/E$4-1 -> -0.19351565 | G5: =F78 -> 249.19651 | H5: =F88 -> 0.26297376 | I5: =F97 -> 23.865375 | J5: =I5/I$4-1 -> -0.2158911
A6: AI 部署 ×1.2 | B6: ×1.2 | C6: =E133 -> 245.84265 | D6: =E143 -> 0.29619227 | E6: =E152 -> 27.553493 | F6: =E6/E$4-1 -> 0.0015568472 | G6: =F133 -> 292.01339 | H6: =F143 -> 0.29753545 | I6: =F152 -> 33.476833 | J6: =I6/I$4-1 -> 0.099898191
A7: ABF 產能 低 | B7: 產能指數 1.25／1.50／1.70 | C7: =E188 -> 234.84166 | D7: =E198 -> 0.28535476 | E7: =E207 -> 24.943678 | F7: =E7/E$4-1 -> -0.093308746 | G7: =F188 -> 270.0664 | H7: =F198 -> 0.28118757 | I7: =F207 -> 28.546118 | J7: =I7/I$4-1 -> -0.06210295
A8: ABF 產能 高 | B8: 1.45／1.90／2.30 | C8: =E243 -> 248.30038 | D8: =E253 -> 0.29806018 | E8: =E262 -> 28.084151 | F8: =E8/E$4-1 -> 0.020846039 | G8: =F243 -> 278.51347 | H8: =F253 -> 0.28779177 | I8: =F262 -> 30.432623 | J8: =I8/I$4-1 -> -0.00012086635
A9: ABF 溢價 低（Ibiden 低值） | B9: 0.95／0.85／0.75 | C9: =E298 -> 238.41698 | D9: =E308 -> 0.27656819 | E9: =E317 -> 24.311482 | F9: =E9/E$4-1 -> -0.11628876 | G9: =F298 -> 263.08349 | H9: =F308 -> 0.24602041 | I9: =F317 -> 23.104645 | J9: =I9/I$4-1 -> -0.24088527
A10: ABF 溢價 高（Ibiden 高值） | B10: 1.05／1.05／1.00 | C10: =E353 -> 253.26833 | D10: =E363 -> 0.31418837 | E10: =E372 -> 30.735069 | F10: =E10/E$4-1 -> 0.11720568 | G10: =F353 -> 293.94344 | H10: =F363 -> 0.32517772 | I10: =F372 -> 37.771408 | J10: =I10/I$4-1 -> 0.2409986
A11: 漲價年度化 0% | B11: 基準 5% | C11: =E408 -> 238.77058 | D11: =E418 -> 0.27750807 | E11: =E427 -> 24.463204 | F11: =E11/E$4-1 -> -0.11077375 | G11: =F408 -> 271.53324 | H11: =F418 -> 0.26948324 | I11: =F427 -> 27.123767 | J11: =I11/I$4-1 -> -0.10883501
A12: 漲價年度化 10% | C12: =E463 -> 252.91473 | D12: =E473 -> 0.31333508 | E12: =E482 -> 30.580998 | F12: =E12/E$4-1 -> 0.11160528 | G12: =F463 -> 285.49369 | H12: =F473 -> 0.30520502 | I12: =F482 -> 33.748354 | J12: =I12/I$4-1 -> 0.10881914
A13: ABF 現金毛利率 40% | B13: 基準 50% | C13: =E518 -> 245.84265 | D13: =E528 -> 0.27840882 | E13: =E537 -> 25.367527 | F13: =E13/E$4-1 -> -0.077902003 | G13: =F518 -> 278.51347 | H13: =F528 -> 0.26135334 | I13: =F537 -> 26.754572 | J13: =I13/I$4-1 -> -0.12096508
A14: ABF 現金毛利率 60% | C14: =E573 -> 245.84265 | D14: =E583 -> 0.31327886 | E14: =E592 -> 29.653799 | F14: =E14/E$4-1 -> 0.077902003 | G14: =F573 -> 278.51347 | H14: =F583 -> 0.3142302 | I14: =F592 -> 34.118031 | J14: =I14/I$4-1 -> 0.12096508
A15: 其他產品現金毛利率 15% | B15: 基準 25% | C15: =E628 -> 245.84265 | D15: =E638 -> 0.29224683 | E15: =E647 -> 27.068515 | F15: =E15/E$4-1 -> -0.016071898 | G15: =F628 -> 278.51347 | H15: =F638 -> 0.28169592 | I15: =F647 -> 29.587414 | J15: =I15/I$4-1 -> -0.027890629
A16: 其他產品現金毛利率 35% | C16: =E683 -> 245.84265 | D16: =E693 -> 0.29944084 | E16: =E702 -> 27.952812 | F16: =E16/E$4-1 -> 0.016071898 | G16: =F683 -> 278.51347 | H16: =F693 -> 0.29388761 | I16: =F702 -> 31.285189 | J16: =I16/I$4-1 -> 0.027890629
A17: 折舊年限 6 年 | B17: 基準 8 年 | C17: =E738 -> 245.84265 | D17: =E748 -> 0.29026778 | E17: =E757 -> 26.825246 | F17: =E17/E$4-1 -> -0.024914582 | G17: =F738 -> 278.51347 | H17: =F748 -> 0.27918893 | I17: =F757 -> 29.238298 | J17: =I17/I$4-1 -> -0.039361007
A18: 折舊年限 10 年 | C18: =E793 -> 245.84265 | D18: =E803 -> 0.29918947 | E18: =E812 -> 27.921913 | F18: =E18/E$4-1 -> 0.014948749 | G18: =F793 -> 278.51347 | H18: =F803 -> 0.29315035 | I18: =F812 -> 31.18252 | J18: =I18/I$4-1 -> 0.024517392
A19: 資本支出 走 C 路徑 | B19: 400／300／280 億（折舊較低） | C19: =E848 -> 245.84265 | D19: =E858 -> 0.29584384 | E19: =E867 -> 27.510663 | F19: =E19/E$4-1 -> 0 | G19: =F848 -> 278.51347 | H19: =F858 -> 0.29452394 | I19: =F867 -> 31.373802 | J19: =I19/I$4-1 -> 0.030802034
A20: 欣興 NVIDIA 份額 低 | B20: 20%→22% | C20: =E903 -> 245.84265 | D20: =E913 -> 0.2958397 | E20: =E922 -> 27.510155 | F20: =E20/E$4-1 -> -1.8461312e-05 | G20: =F903 -> 276.27578 | H20: =F913 -> 0.28608314 | I20: =F922 -> 29.932102 | J20: =I20/I$4-1 -> -0.016565735
A21: 欣興 NVIDIA 份額 高 | B21: 30%→36% | C21: =E958 -> 245.84265 | D21: =E968 -> 0.29584795 | E21: =E977 -> 27.511169 | F21: =E21/E$4-1 -> 1.8399201e-05 | G21: =F958 -> 279.82785 | H21: =F968 -> 0.28878265 | I21: =F977 -> 30.732461 | J21: =I21/I$4-1 -> 0.0097304503
A22: 欣興 ASIC 份額 低 | B22: 22% | C22: =E1013 -> 244.61776 | D22: =E1023 -> 0.29466161 | E22: =E1032 -> 27.217383 | F22: =E22/E$4-1 -> -0.010660589 | G22: =F1013 -> 270.7042 | H22: =F1023 -> 0.28170614 | I22: =F1032 -> 28.678687 | J22: =I22/I$4-1 -> -0.057747331
A23: 欣興 ASIC 份額 高 | B23: 40% | C23: =E1068 -> 245.84265 | D23: =E1078 -> 0.29588243 | E23: =E1087 -> 27.515407 | F23: =E23/E$4-1 -> 0.00017245012 | G23: =F1068 -> 282.32702 | H23: =F1078 -> 0.29064126 | I23: =F1087 -> 31.295579 | J23: =I23/I$4-1 -> 0.028231985
A24: 其他 AI 彈性 0.3 | B24: 基準 0.5 | C24: =E1123 -> 238.90642 | D24: =E1133 -> 0.28918356 | E24: =E1142 -> 25.87312 | F24: =E24/E$4-1 -> -0.059523931 | G24: =F1123 -> 265.34079 | H24: =F1133 -> 0.27731904 | I24: =F1142 -> 27.479215 | J24: =I24/I$4-1 -> -0.097156571
A25: 其他 AI 彈性 0.8 | C25: =E1178 -> 245.84265 | D25: =E1188 -> 0.29608868 | E25: =E1197 -> 27.540759 | F25: =E25/E$4-1 -> 0.0010939714 | G25: =F1178 -> 292.01339 | H25: =F1188 -> 0.29753774 | I25: =F1197 -> 33.477168 | J25: =I25/I$4-1 -> 0.099909179
A26: AI HDI／PCB 成長 低 | B26: 每年 −10pt | C26: =E1233 -> 242.04904 | D26: =E1243 -> 0.29656234 | E26: =E1252 -> 27.137135 | F26: =E26/E$4-1 -> -0.013577577 | G26: =F1233 -> 269.97784 | H26: =F1243 -> 0.28898659 | I26: =F1252 -> 29.580517 | J26: =I26/I$4-1 -> -0.028117246
A27: AI HDI／PCB 成長 高 | B27: 每年 +10pt | C27: =E1288 -> 249.63626 | D27: =E1298 -> 0.29514717 | E27: =E1307 -> 27.884191 | F27: =E27/E$4-1 -> 0.013577577 | G27: =F1288 -> 287.80781 | H27: =F1298 -> 0.28657134 | I27: =F1307 -> 31.369836 | J27: =I27/I$4-1 -> 0.030671727
A28: 營業費用彈性 1.0 | B28: 基準 0.6 | C28: =E1343 -> 245.84265 | D28: =E1353 -> 0.29584384 | E28: =E1362 -> 26.492078 | F28: =E28/E$4-1 -> -0.037025095 | G28: =F1343 -> 278.51347 | H28: =F1353 -> 0.28779177 | I28: =F1362 -> 28.758497 | J28: =I28/I$4-1 -> -0.055125128
A29: 稅率 22% | B29: 基準 18% | C29: =E1398 -> 245.84265 | D29: =E1408 -> 0.29584384 | E29: =E1417 -> 26.16868 | F29: =E29/E$4-1 -> -0.048780488 | G29: =F1398 -> 278.51347 | H29: =F1408 -> 0.28779177 | I29: =F1417 -> 28.951604 | J29: =I29/I$4-1 -> -0.048780488
A30: 業外 0 | B30: 每年 0（基準 20 億） | C30: =E1453 -> 245.84265 | D30: =E1463 -> 0.29584384 | E30: =E1472 -> 26.510663 | F30: =E30/E$4-1 -> -0.036349542 | G30: =F1453 -> 278.51347 | H30: =F1463 -> 0.28779177 | I30: =F1472 -> 29.436302 | J30: =I30/I$4-1 -> -0.032855503
A31: 情境 B | B31: CY2028 顆數 ×0.8、CY2029 ×0.85；資本支出較低 | C31: =PL!E143 -> 245.84265 | D31: =PL!E153 -> 0.29584384 | E31: =PL!E162 -> 27.510663 | F31: =E31/E$4-1 -> 0 | G31: =PL!F143 -> 238.72615 | H31: =PL!F153 -> 0.26720807 | I31: =PL!F162 -> 23.211086 | J31: =I31/I$4-1 -> -0.23738808
A32: 情境 C | B32: CY2028–29 顆數 ×0.6；資本支出最低 | C32: =PL!E198 -> 245.84265 | D32: =PL!E208 -> 0.29584384 | E32: =PL!E217 -> 27.510663 | F32: =E32/E$4-1 -> 0 | G32: =PL!F198 -> 198.93883 | H32: =PL!F208 -> 0.23901932 | I32: =PL!F217 -> 16.048371 | J32: =I32/I$4-1 -> -0.47272269
A34: 讀法：ABF 產能受限時，顆數與份額的上修只部分轉成營收（滿足率 < 100%），產能與價格的影響較大；折舊年限與資本支出路徑直接改變毛利率；FY2027 三情境相同，差異從 FY2028 起。
A36: 目標價參數（只改 DCF 參數；PL 收斂法的 fade_g 與資本支出率路徑不隨 tp_g 變動）
A37: 案例 | B37: 設定 | C37: DCF 目標價 | D37: Comparable 目標價 | E37: 加權目標價 | F37: 相對基準
A38: 基準 | B38: r 10%、g 4%、DCF 權重 0.5 | C38: =(tp_wA*(SUMPRODUCT(Val!B16:B21,1/(1+tp_r)^{1;2;3;4;5;6})+Val!B21*(1+tp_g)/(tp_r-tp_g)/(1+tp_r)^6)+tp_wB*(SUMPRODUCT(Val!C16:C21,1/(1+tp_r)^{1;2;3;4;5;6})+Val!C21*(1+tp_g)/(tp_r-tp_g)/(1+tp_r)^6)+tp_wC*(SUMPRODUCT(Val!D16:D21,1/(1+tp_r)^{1;2;3;4;5;6})+Val!D21*(1+tp_g)/(tp_r-tp_g)/(1+tp_r)^6))*(1+tp_r) -> 388.52908 | D38: =Val!B35 -> 1065.0447 | E38: =tp_w_dcf*C38+(1-tp_w_dcf)*D38 -> 726.78689 | F38: =E38/E$38-1 -> 0
A39: 折現率 +1pt | B39: r 11% | C39: =(tp_wA*(SUMPRODUCT(Val!B16:B21,1/(1+(tp_r+0.01))^{1;2;3;4;5;6})+Val!B21*(1+tp_g)/((tp_r+0.01)-tp_g)/(1+(tp_r+0.01))^6)+tp_wB*(SUMPRODUCT(Val!C16:C21,1/(1+(tp_r+0.01))^{1;2;3;4;5;6})+Val!C21*(1+tp_g)/((tp_r+0.01)-tp_g)/(1+(tp_r+0.01))^6)+tp_wC*(SUMPRODUCT(Val!D16:D21,1/(1+(tp_r+0.01))^{1;2;3;4;5;6})+Val!D21*(1+tp_g)/((tp_r+0.01)-tp_g)/(1+(tp_r+0.01))^6))*(1+(tp_r+0.01)) -> 333.64042 | D39: =Val!B35 -> 1065.0447 | E39: =tp_w_dcf*C39+(1-tp_w_dcf)*D39 -> 699.34256 | F39: =E39/E$38-1 -> -0.037761179
A40: 折現率 −1pt | B40: r 9% | C40: =(tp_wA*(SUMPRODUCT(Val!B16:B21,1/(1+(tp_r-0.01))^{1;2;3;4;5;6})+Val!B21*(1+tp_g)/((tp_r-0.01)-tp_g)/(1+(tp_r-0.01))^6)+tp_wB*(SUMPRODUCT(Val!C16:C21,1/(1+(tp_r-0.01))^{1;2;3;4;5;6})+Val!C21*(1+tp_g)/((tp_r-0.01)-tp_g)/(1+(tp_r-0.01))^6)+tp_wC*(SUMPRODUCT(Val!D16:D21,1/(1+(tp_r-0.01))^{1;2;3;4;5;6})+Val!D21*(1+tp_g)/((tp_r-0.01)-tp_g)/(1+(tp_r-0.01))^6))*(1+(tp_r-0.01)) -> 465.41753 | D40: =Val!B35 -> 1065.0447 | E40: =tp_w_dcf*C40+(1-tp_w_dcf)*D40 -> 765.23111 | F40: =E40/E$38-1 -> 0.052896143
A41: 長期成長 +1pt | B41: g 5% | C41: =(tp_wA*(SUMPRODUCT(Val!B16:B21,1/(1+tp_r)^{1;2;3;4;5;6})+Val!B21*(1+(tp_g+0.01))/(tp_r-(tp_g+0.01))/(1+tp_r)^6)+tp_wB*(SUMPRODUCT(Val!C16:C21,1/(1+tp_r)^{1;2;3;4;5;6})+Val!C21*(1+(tp_g+0.01))/(tp_r-(tp_g+0.01))/(1+tp_r)^6)+tp_wC*(SUMPRODUCT(Val!D16:D21,1/(1+tp_r)^{1;2;3;4;5;6})+Val!D21*(1+(tp_g+0.01))/(tp_r-(tp_g+0.01))/(1+tp_r)^6))*(1+tp_r) -> 450.06191 | D41: =Val!B35 -> 1065.0447 | E41: =tp_w_dcf*C41+(1-tp_w_dcf)*D41 -> 757.55331 | F41: =E41/E$38-1 -> 0.042332101
A42: 長期成長 −1pt | B42: g 3% | C42: =(tp_wA*(SUMPRODUCT(Val!B16:B21,1/(1+tp_r)^{1;2;3;4;5;6})+Val!B21*(1+(tp_g-0.01))/(tp_r-(tp_g-0.01))/(1+tp_r)^6)+tp_wB*(SUMPRODUCT(Val!C16:C21,1/(1+tp_r)^{1;2;3;4;5;6})+Val!C21*(1+(tp_g-0.01))/(tp_r-(tp_g-0.01))/(1+tp_r)^6)+tp_wC*(SUMPRODUCT(Val!D16:D21,1/(1+tp_r)^{1;2;3;4;5;6})+Val!D21*(1+(tp_g-0.01))/(tp_r-(tp_g-0.01))/(1+tp_r)^6))*(1+tp_r) -> 344.57706 | D42: =Val!B35 -> 1065.0447 | E42: =tp_w_dcf*C42+(1-tp_w_dcf)*D42 -> 704.81088 | F42: =E42/E$38-1 -> -0.030237215
A43: DCF 權重 0.3 | C43: =(tp_wA*(SUMPRODUCT(Val!B16:B21,1/(1+tp_r)^{1;2;3;4;5;6})+Val!B21*(1+tp_g)/(tp_r-tp_g)/(1+tp_r)^6)+tp_wB*(SUMPRODUCT(Val!C16:C21,1/(1+tp_r)^{1;2;3;4;5;6})+Val!C21*(1+tp_g)/(tp_r-tp_g)/(1+tp_r)^6)+tp_wC*(SUMPRODUCT(Val!D16:D21,1/(1+tp_r)^{1;2;3;4;5;6})+Val!D21*(1+tp_g)/(tp_r-tp_g)/(1+tp_r)^6))*(1+tp_r) -> 388.52908 | D43: =Val!B35 -> 1065.0447 | E43: =0.3*C43+(1-0.3)*D43 -> 862.09001 | F43: =E43/E$38-1 -> 0.18616616
...

Sheet Sources
A1: 來源（公司財報經媒體與資料商轉載；法說內容經媒體摘要；券商與資料商皆為 Interested-party）
A2: 公司（轉載）：工商時報 2026-07-29 2Q26 財報（營收、營業利益、業外、淨利、資本支出） | B2: https://www.ctee.com.tw/news/20260729700548-430201
A3: 公司（轉載）：工商時報 2026-07-29 2Q26 法說（產品組合、應用別、稼動率、AI 占比、產能時程） | B3: https://www.ctee.com.tw/news/20260729701506-430201
A4: 公司（轉載）：Quartr 2Q26 摘要（營收、毛利率、營業利益、EBITDA、1H26） | B4: https://quartr.com/events/unimicron-technology-corp-3037-q2-2026_F9DCOIJX
A5: 公司（摘要）：富果 4Q25 法說摘要（FY2025、折舊 188 億 → 208 億、4Q25 產品組合、光復二廠） | B5: https://blog.fugle.tw/post/earnings-call-3037-2026-02-25
A6: 媒體：口袋學堂 2Q26 法說（業外明細、ABF 52%、Blackwell 約 30%） | B6: https://www.pocket.tw/school/articles/7708/
A7: 媒體：優分析 2Q26（資本支出 537 億） | B7: https://uanalyze.com.tw/articles/4246852366
A8: 媒體：永豐 豐學 1Q26（1Q26 營收、毛利率、EPS、ABF 供需缺口、私募與可轉債） | B8: https://www.sinotrade.com.tw/richclub/hotstock/欣興-3037--1Q26-EPS繳出3-28元改寫13季新高-T-glass缺料推升ABF漲價循環的預期差再放大-豐學PRIME盤後精選--69f16461f5cc3b01237ecb00
A9: 媒體：優分析 2026-04-10（GDR 董事會決議） | B9: https://uanalyze.com.tw/articles/7364850419
A10: 媒體：優分析 2026-07（GDR 5,000 萬單位、每單位 US$26.96–27.76） | B10: https://uanalyze.com.tw/articles/9347152010
A11: 媒體：TechNews 2026-10-08（9 月營收 186.51 億、前 9 月 1,329.86 億） | B11: https://finance.technews.tw/2026/10/08/unimicron-3037-202609-financial-report/
A12: 券商（媒體）：三立 2026-10-19 本土法人（目標價 1,500、EPS 2026 23.42／2027 41.10、Q3、Q4 預估、產能時程） | B12: https://www.mirrormedia.mg/external/setn_1923649
A13: 券商（媒體）：經濟日報 2026-10-12 美系券商（EPS 2026 21／2027 37／2028 64.8、資本支出逾 400 億） | B13: https://money.udn.com/money/story/5607/9808557
... A23: SemiAnalysis | B23: 未使用
