Workbook

Sheet README
A1: MiniMax（00100.HK，上海稀宇科技）收支模型 v0.1（2026-10-08）
A2: 命題：MiniMax 每 MW 算力（實體與 VR 等值）的營收，能否覆蓋每 MW 全成本（推論＋訓練算力、人事、其他）；若不能，缺口何時出現、由誰、以什麼條件補。FY2025–FY2030，曆年制（公司財年＝曆年）。
A3: 比照 OpenAI 收支模型 v0.6：同一分層（SRC／TK_Link／Inputs）、同一 MW 主軸（token → MW、η 校準、VR 等值）、同一命題口徑；MiniMax 為上市公司，另加 Funding 與 Valuation。
A5: 驅動 → 推導對照（因果方向由上而下）
A6: Demand：輸入＝API 實收單價（I07）、單價年變動（I08）、token 量年增（I09）｜推導＝API 計費 token（2025–26 由營收 ÷ 單價校準）
A7: Revenue：輸入＝2026 下半年企業端年化（I10）、消費端成長（I11、I12）｜推導＝企業端＝token × 單價；消費端＝成長路徑；產品與收費方式拆分只依 9M25 結構示意
A8: Compute：輸入＝TK 每 GW 產能（TK01–05）、利用率（TK06）、機隊組合（I05）、層級組合（I04）、模型效率（I06）、合約價（I02）、訓練 MW 成長（I17）｜推導＝API 推論 MW＝token ÷ 每 MW 產能 ÷ η；消費端與訓練 MW＝支出 ÷ 合約價；VR 等值 MW
A9: PnL：推導＝算力成本＝MW × 合約價；人事＝人數 × 每人成本；其他費用＝營收比例｜命題輸出＝每 MW 營收、每 MW 全成本、覆蓋率（P21–P23）
A10: Funding：輸入＝已完成融資（SRC）、預付與自建（I22）、可轉債轉股機率（I23）、最低現金（I24）｜推導＝各年期末現金、需新融資、稀釋
A11: Valuation：推導＝市值、EV、EV/營收、反向檢驗（I27、I28）
A12: 沿用 OpenAI／CRWV 核心的部分：MW 主軸、TK 每 GW 產能 × 利用率、η 校準（2025 唯一倒推）、VR 等值換算、合約價口徑。只沿用外殼的部分：消費端（影片為主，不走 token 換算）、Funding、Valuation。
A14: 圖例
... A29: 研究底稿與來源：minimax/data/research/financials.md、operations.md（repo YinchenChang/company-models）。

Sheet SRC_MM
A1: SRC_MM — MiniMax 公司財務與營運原始數據（單位見各列；US$ 除註明外）
A2: 一手＝公司公告／申報文件；二手（含一手公告轉載）＝媒體轉述公司公開說法；二手＝媒體或資料商。藍字可改。研究底稿：data/research/
A4: ID | B4: 項目 | C4: 期間 | D4: 單位 | E4: 值 | F4: 標記 | G4: 一手／二手 | H4: 來源
A5: S001 | B5: 營收 | C5: FY2024 | D5: $M | E5: 30.523 | F5: Verified | G5: 一手 | H5: HKEX 招股書 2025-12-31（Summary／附錄一會計師報告）
A6: S002 | B6: 營收 | C6: FY2025 | D6: $M | E6: 79.038 | F6: Verified | G6: 一手 | H6: FY2025 年度業績公告 2026-03-02
A7: S003 | B7: 營收 | C7: 1H2025 | D7: $M | E7: 30.429 | F7: Verified | G7: 一手 | H7: 1H2026 中期業績公告 2026-08-26
A8: S004 | B8: 營收 | C8: 1H2026 | D8: $M | E8: 116.573 | F8: Verified | G8: 一手 | H8: 1H2026 中期業績公告 2026-08-26
A9: S005 | B9: AI 原生產品營收（消費端） | C9: FY2025 | D9: $M | E9: 53.1 | F9: Verified | G9: 一手 | H9: FY2025 年度業績公告 2026-03-02
A10: S006 | B10: 開放平台及企業服務營收（API／企業端） | C10: FY2025 | D10: $M | E10: 26 | F10: Verified | G10: 一手 | H10: FY2025 年度業績公告 2026-03-02
A11: S007 | B11: AI 原生產品營收（消費端） | C11: 1H2026 | D11: $M | E11: 42.6 | F11: Verified | G11: 一手 | H11: 1H2026 中期業績公告 2026-08-26
A12: S008 | B12: 開放平台及企業服務營收（API／企業端） | C12: 1H2026 | D12: $M | E12: 73.9 | F12: Verified | G12: 一手 | H12: 1H2026 中期業績公告 2026-08-26
A13: S009 | B13: AI 原生產品營收 | C13: 9M2025 | D13: $M | E13: 38.02 | F13: Verified | G13: 一手 | H13: HKEX 招股書 2025-12-31（Summary／附錄一會計師報告）
A14: S010 | B14: 開放平台及企業服務營收 | C14: 9M2025 | D14: $M | E14: 15.417 | F14: Verified | G14: 一手 | H14: HKEX 招股書 2025-12-31（Summary／附錄一會計師報告）
A15: S011 | B15: Talkie／星野 營收 | C15: 9M2025 | D15: $M | E15: 18.75 | F15: Verified | G15: 一手 | H15: HKEX 招股書 2025-12-31（Summary／附錄一會計師報告）
A16: S012 | B16: 海螺 Hailuo（影片）營收 | C16: 9M2025 | D16: $M | E16: 17.464 | F16: Verified | G16: 一手 | H16: HKEX 招股書 2025-12-31（Summary／附錄一會計師報告）
... A81: S077 | B81: 人民幣兌美元（換算阿里雲上限用） | C81: 2026 | D81: RMB/$ | E81: 7.1 | F81: Assumed | G81: — | H81: 僅說明用

Sheet TK_Link
A1: TK_Link — Tokenomics 快照（第 0 層；本模型不重算物理層）
A2: Tokenomics v5.24（master bdb0de7，2026-10-07；取自 company-models/openai v0.6 TK_Link 快照，基準成本情境）
A4: ID | B4: Tokenomics 名稱 | C4: 世代 | D4: 說明 | E4: 單位 | F4: 值
A5: TK01 | B5: IF_TokGW_Luna | C5: Hopper H100 | D5: 每 GW 總產出（100% 利用率）：低層（Luna） | E5: M tok/GW/年 | F5: 7.4067251e+10
A6: TK02 | B6: IF_TokGW_Luna | C6: GB200 NVL72 | D6: 每 GW 總產出（100% 利用率）：低層（Luna） | E6: M tok/GW/年 | F6: 3.6230689e+11
A7: TK03 | B7: IF_TokGW_Sol | C7: Hopper H100 | D7: 每 GW 總產出（100% 利用率）：中層（Sol） | E7: M tok/GW/年 | F7: 2.149043e+10
A8: TK04 | B8: IF_TokGW_Sol | C8: GB200 NVL72 | D8: 每 GW 總產出（100% 利用率）：中層（Sol） | E8: M tok/GW/年 | F8: 1.041254e+11
A9: TK05 | B9: IF_TokGW_Sol | C9: VR200 NVL72 | D9: 每 GW 總產出（100% 利用率）：中層（Sol；VR 等值換算基準） | E9: M tok/GW/年 | F9: 2.3728734e+11
A10: TK06 | B10: IF_Util | C10: — | D10: 基準利用率（第 0 層；下游可覆寫） | E10: 比例 | F10: 0.6
A11: TK07 | B11: IF_HoldEcon | C11: Hopper H100 | D11: 每 GW 年持有成本（經濟口徑；供應商參考） | E11: $B/GW/年 | F11: 10.095795
A12: TK08 | B12: IF_HoldEcon | C12: GB200 NVL72 | D12: 每 GW 年持有成本（經濟口徑；供應商參考） | E12: $B/GW/年 | F12: 9.1709819
A13: TK09 | B13: IF_FullCost_Luna | C13: Hopper H100 | D13: 全成本 $/M（基準利用率）：低層 | E13: $/M | F13: 0.19228981
A14: TK10 | B14: IF_FullCost_Sol | C14: Hopper H100 | D14: 全成本 $/M（基準利用率）：中層 | E14: $/M | F14: 0.76713986
A15: TK11 | B15: IF_FullCost_Luna | C15: GB200 NVL72 | D15: 全成本 $/M（基準利用率）：低層 | E15: $/M | F15: 0.037219928
A16: TK12 | B16: IF_FullCost_Sol | C16: GB200 NVL72 | D16: 全成本 $/M（基準利用率）：中層 | E16: $/M | F16: 0.13889806

Sheet Inputs
A1: Inputs — 假設（藍字＝輸入；Analogy／Assumed 一律附區間）
A2: 純量放 D 欄；逐年路徑放 D–I（2025–2030）。低／高：純量為數值（供敏感度），逐年為文字描述（敏感度頁以整列調整重算）。
A5: ID | B5: 項目 | C5: 單位 | D5: 2025 | E5: 2026 | F5: 2027 | G5: 2028 | H5: 2029 | I5: 2030 | J5: 低 | K5: 高 | L5: 標記 | M5: 說明
A6: I01 | B6: 港幣兌美元 | C6: HK$/$ | D6: 7.78 | J6: 7.75 | K6: 7.85 | L6: Verified | M6: 聯繫匯率區間
A7: I02 | B7: 每 MW 年合約價（雲端租用、IT 關鍵電力口徑） | C7: $M/MW/年 | D7: 12 | J7: 8 | K7: 20 | L7: Analogy | M7: 同 OpenAI 模型 INP_229（$12B/GW/年）；中國 H800／H20 與國產晶片租價可能較低。Tokenomics Hopper 持有成本 10.1（TK07）為下限參考
A8: I03 | B8: 銷售成本中算力（推論雲端）占比 | C8: 比例 | D8: 0.9 | J8: 0.8 | K8: 0.95 | L8: Assumed | M8: 公司稱銷售成本主要為推論雲端；未揭露金額
A9: I04 | B9: API token 層級組合：低層（Luna）占比（其餘＝中層 Sol） | C9: 比例 | D9: 0.6 | J9: 0.3 | K9: 0.9 | L9: Analogy | M9: M2／M3 啟用參數 10B／23B，牌價 $0.30/$1.20 介於 Tokenomics Luna（$0.08）與 Sol（$1.6）之間
A10: I05 | B10: 機隊組合：Hopper 級占比（其餘＝Blackwell 級，含國產 ASIC 等值） | C10: 比例 | D10: 1 | E10: 0.85 | F10: 0.65 | G10: 0.45 | H10: 0.3 | I10: 0.2 | J10: 各年 −0.15 | K10: 各年 +0.15 | L10: Assumed | M10: 中國受出口管制，Hopper 級（H800／H20）汰換慢；海外雲可租 Blackwell。V1 比照 OpenAI 時變組合
A11: I06 | B11: 模型效率指數（同硬體每 MW token 產出，2025＝1） | C11: 倍 | D11: 1 | E11: 2 | F11: 2.6 | G11: 3.38 | H11: 4.39 | I11: 5.71 | J11: 2027 起年增 15% | K11: 2027 起年增 50% | L11: Interested-party | M11: 公司：M3 長上下文每 token 算力為前代 1/20；文字模型單位吞吐兩個月三倍。η 於 2026 以實際支出重新校準，2026 值相互抵銷；有作用的是 2027 起相對 2026 的年增（基準 30%）
A12: I07 | B12: API 綜合實收單價（含快取、訂閱方案） | C12: $/M | D12: 0.4 | E12: 0.22 | J12: 2025 0.25／2026 0.12 | K12: 2025 0.60／2026 0.35 | L12: Analogy | M12: 2025：Text-01／M1 牌價 $0.2–0.4 輸入、$1.1–2.2 輸出，混合後約 0.4；2026：公司稱 M3 綜合 $0.22（S058，未見一手）。Token Plan 滿用約 $0.012/M 會拉低
A13: I08 | B13: API 單價年變動（2027 起） | C13: 比例 | F13: -0.35 | G13: -0.25 | H13: -0.2 | I13: -0.15 | J13: 各年 −0.50 | K13: 各年 0 | L13: Assumed | M13: 2026 上半年中國大廠六次降價，下半年持平或回升（DeepSeek 8 月漲價）；基準仍假設逐年下降
A14: I09 | B14: API token 量年增（2027 起；不含價格效果） | C14: 比例 | F14: 2 | G14: 1 | H14: 0.6 | I14: 0.4 | J14: 0.8／0.5／0.3／0.2 | K14: 4.0／1.5／0.9／0.6 | L14: Assumed | M14: OpenRouter 份額由 4 月 9–10% 降至 10 月跌出前十（S）；2026 上半年 token 量 ×20（IP）
A15: I10 | B15: 2026 下半年企業端（API）平均年化營收 | C15: $M/年 | D15: 600 | J15: 350 | K15: 750 | L15: Interested-party | M15: 錨：2026-08 ARR >800 × B2B 80%＝640（S053×S054）；9 月同業降價、OpenRouter 份額下滑，基準略低於 640
A16: I11 | B16: 2026 下半年消費端營收 ÷ 上半年 | C16: 倍 | D16: 1.15 | J16: 0.95 | K16: 1.4 | L16: Assumed | M16: 1H26 消費端年增 101%
A17: I12 | B17: 消費端營收年增（2027 起） | C17: 比例 | F17: 0.5 | G17: 0.35 | H17: 0.25 | I17: 0.2 | J17: 各年 ×0.5 | K17: 各年 ×1.5 | L17: Assumed | M17: Talkie 6 月 MAU 32.9M（第三方）；影片 H3 開源後消費訂閱競爭加劇
A18: I13 | B18: 消費端算力成本 ÷ 消費端營收（2026 起） | C18: 比例 | E18: 0.85 | F18: 0.75 | G18: 0.68 | H18: 0.62 | I18: 0.55 | J18: 各年 −0.15 | K18: 各年 +0.15 | L18: Assumed | M18: 2025 由財報推得（Compute C12）；9M25 消費端毛利率約 5%
A19: I14 | B19: 其他銷售成本（非算力）占營收（2026 起） | C19: 比例 | D19: 0.05 | J19: 0.03 | K19: 0.08 | L19: Assumed | M19: 2025 由財報推得
A20: I15 | B20: 員工福利中研發人員占比（推 1H26 研發算力） | C20: 比例 | D20: 0.75 | J20: 0.6 | K20: 0.85 | L20: Assumed | M20: 2025-09 研發人員占 73.8%（招股書，二手）
A21: I16 | B21: 2026 下半年訓練算力支出 ÷ 上半年 | C21: 倍 | D21: 1.2 | J21: 1 | K21: 1.5 | L21: Assumed | M21: 7 月募資約 80% 用於算力與模型研發；M3 Pro（約 3T 參數）在研
A22: I17 | B22: 訓練 MW 年增（2027 起） | C22: 比例 | F22: 0.8 | G22: 0.5 | H22: 0.35 | I22: 0.25 | J22: 各年 ×0.5 | K22: 各年 ×1.5 | L22: Assumed | M22: 公司路線：3T → 10T 參數；阿里雲上限 2026–28 年增約 33%／25%
A23: I18 | B23: 平均員工數 | C23: 人 | E23: 560 | F23: 750 | G23: 950 | H23: 1100 | I23: 1250 | J23: 各年 ×0.8 | K23: 各年 ×1.3 | L23: Assumed | M23: 2025 底 428、2026-06 568
A24: I19 | B24: 每人年人事成本年增（2027 起；含 SBC） | C24: 比例 | D24: 0.08 | J24: 0.03 | K24: 0.15 | L24: Assumed | M24: 2026 每人成本由 1H26 推得
A25: I20 | B25: 其他營業費用（非人事、非算力：行銷、行政、上市費）占營收（2026 起） | C25: 比例 | E25: 0.35 | F25: 0.25 | G25: 0.2 | H25: 0.17 | I25: 0.15 | J25: 各年 ×0.7 | K25: 各年 ×1.3 | L25: Assumed | M25: 2025 約 80%（推得）；1H26 約 34%（推得）
A26: I21 | B26: 現金收益率（利息與理財） | C26: 比例 | D26: 0.03 | J26: 0.02 | K26: 0.04 | L26: Assumed | M26: FY2025 其他收入 40.4 ÷ 平均現金約 3.9%（含公允價值收益）
A27: I22 | B27: 算力預付與自建資本支出（超出 P&L 算力費用的現金時差） | C27: $M | E27: 322 | F27: 0 | G27: 0 | H27: 0 | I27: 0 | J27: 2026 322、其後 0 | K27: 2026 700、其後每年 300 | L27: Assumed | M27: 2026 基準＝1H26 物業廠房設備＋預付款增加（S050−S049）；公司稱自控核心集群即將上線
A28: I23 | B28: 可轉債到期轉股機率（其餘以現金贖回） | C28: 比例 | D28: 0 | J28: 0 | K28: 1 | L28: Assumed | M28: 轉換價 HK$335 高於 10-02 隱含股價約 HK$218
A29: I24 | B29: 最低現金水位 | C29: $M | D29: 300 | J29: 200 | K29: 500 | L29: Assumed | M29: 約一季燒錢
A30: I25 | B30: 新股發行折價 | C30: 比例 | D30: 0.1 | J30: 0.05 | K30: 0.2 | L30: Analogy | M30: 2026-07 配售折價 9.89%
A31: I26 | B31: Hopper 級每張 GPU 的 IT 電力（含網路、儲存） | C31: kW | D31: 1.4 | J31: 1.2 | K31: 1.7 | L31: Analogy | M31: 只用於 GPU 等值換算（顯示用）
A32: I29 | B32: 2026 下半年起 API 推論效率相對 1H26 校準值的改善 | C32: 倍 | D32: 1.3 | J32: 1 | K32: 2 | L32: Interested-party | M32: 公司：M3.1 推論成本約 M3 首發的 1/3、下半年文字毛利率改善；基準只採一部分
A33: I27 | B33: 反向檢驗：2030 年 EV/營收 退出倍數 | C33: 倍 | D33: 8 | J33: 5 | K33: 12 | L33: Assumed | M33: 軟體／AI 平台高成長倍數
A34: I28 | B34: 反向檢驗：股權折現率 | C34: 比例 | D34: 0.12 | J34: 0.1 | K34: 0.15 | L34: Assumed

Sheet Demand
A1: Demand — 需求：API 單價與 token 量
A2: 單位：$M＝百萬美元；MW＝IT 關鍵電力；T＝10^12 token。2025＝實際校準年；2026＝上半年實際＋下半年推估。黑字＝公式；綠字＝引用其他頁。
A4: ID | B4: 項目 | C4: 單位 | D4: FY2025 | E4: FY2026 | F4: FY2027 | G4: FY2028 | H4: FY2029 | I4: FY2030 | J4: 說明
B5: 年度 | D5: 2025 | E5: 2026 | F5: 2027 | G5: 2028 | H5: 2029 | I5: 2030
A6: 一、API 綜合實收單價（$/M tokens）
A7: D01 | B7: API 綜合實收單價 | C7: $/M | D7: =Inputs!$D$12 -> 0.4 | E7: =Inputs!$E$12 -> 0.22 | F7: =E7*(1+Inputs!$F$13) -> 0.143 | G7: =F7*(1+Inputs!$G$13) -> 0.10725 | H7: =G7*(1+Inputs!$H$13) -> 0.0858 | I7: =H7*(1+Inputs!$I$13) -> 0.07293 | J7: 2025–26：Inputs；2027 起逐年變動
A8: D02 | B8: API 單價年變動 | C8: 比例 | E8: =E7/D7-1 -> -0.45 | F8: =F7/E7-1 -> -0.35 | G8: =G7/F7-1 -> -0.25 | H8: =H7/G7-1 -> -0.2 | I8: =I7/H7-1 -> -0.15
A9: 二、API 計費 token 量（2025、2026 由營收與單價推得＝校準年；2027 起需求成長）
A10: D03 | B10: API 計費 token | C10: T/年 | D10: =Revenue!$D$7/D7 -> 65 | E10: =Revenue!$E$7/E7 -> 1699.5455 | F10: =E10*(1+Inputs!$F$14) -> 5098.6364 | G10: =F10*(1+Inputs!$G$14) -> 10197.273 | H10: =G10*(1+Inputs!$H$14) -> 16315.636 | I10: =H10*(1+Inputs!$I$14) -> 22841.891 | J10: $M ÷ $/M ＝ M 百萬 token；單位換算：$M/($/M)＝10^12 token＝T
A11: D04 | B11: API 計費 token（每日） | C11: T/日 | D11: =D10/365 -> 0.17808219 | E11: =E10/365 -> 4.6562889 | F11: =F10/365 -> 13.968867 | G11: =G10/365 -> 27.937733 | H11: =H10/365 -> 44.700374 | I11: =I10/365 -> 62.580523
A12: D05 | B12: API token 年增 | C12: 比例 | E12: =E10/D10-1 -> 25.146853 | F12: =F10/E10-1 -> 2 | G12: =G10/F10-1 -> 1 | H12: =H10/G10-1 -> 0.6 | I12: =I10/H10-1 -> 0.4
A13: 三、對照（只列差距，不校準）
A14: D06 | B14: 2026 ÷ 2025 token 倍數（模型） | C14: 倍 | E14: =E10/D10 -> 26.146853
A15: D07 | B15: 對照：公司稱 2026-07 ÷ 2026-01 token 倍數（S055） | C15: 倍 | E15: =SRC_MM!$E$59 -> 20 | J15: 月度時點 vs 年度平均，口徑不同
A16: D08 | B16: 對照：2026 下半年企業端 ARR 錨（S053 × S054） | C16: $M/年 | E16: =SRC_MM!$E$57*SRC_MM!$E$58 -> 640

Sheet Revenue
A1: Revenue — 營收：企業端（API）與消費端
A2: 單位：$M＝百萬美元；MW＝IT 關鍵電力；T＝10^12 token。2025＝實際校準年；2026＝上半年實際＋下半年推估。黑字＝公式；綠字＝引用其他頁。
A4: ID | B4: 項目 | C4: 單位 | D4: FY2025 | E4: FY2026 | F4: FY2027 | G4: FY2028 | H4: FY2029 | I4: FY2030 | J4: 說明
B5: 年度 | D5: 2025 | E5: 2026 | F5: 2027 | G5: 2028 | H5: 2029 | I5: 2030
A6: 一、企業端：開放平台及企業服務（API、Coding／Token／M Plan）
A7: R01 | B7: 企業端營收（API） | C7: $M | D7: =SRC_MM!$E$10 -> 26 | E7: =SRC_MM!$E$12+Inputs!$D$15/2 -> 373.9 | F7: =Demand!$F$10*Demand!$F$7 -> 729.105 | G7: =Demand!$G$10*Demand!$G$7 -> 1093.6575 | H7: =Demand!$H$10*Demand!$H$7 -> 1399.8816 | I7: =Demand!$I$10*Demand!$I$7 -> 1665.8591 | J7: 2025 實際；2026＝上半年實際＋下半年年化 ÷ 2；2027 起＝token × 單價
A8: 二、消費端：AI 原生產品（Talkie／星野、海螺、Agent、Audio）
A9: R02 | B9: 消費端營收 | C9: $M | D9: =SRC_MM!$E$9 -> 53.1 | E9: =SRC_MM!$E$11*(1+Inputs!$D$16) -> 91.59 | F9: =E9*(1+Inputs!$F$17) -> 137.385 | G9: =F9*(1+Inputs!$G$17) -> 185.46975 | H9: =G9*(1+Inputs!$H$17) -> 231.83719 | I9: =H9*(1+Inputs!$I$17) -> 278.20463
A10: R03 | B10: 其中 Talkie／星野（依 9M25 結構） | C10: $M | D10: =D9*SRC_MM!$E$15/SRC_MM!$E$13 -> 26.186875 | E10: =E9*SRC_MM!$E$15/SRC_MM!$E$13 -> 45.168661 | F10: =F9*SRC_MM!$E$15/SRC_MM!$E$13 -> 67.752992 | G10: =G9*SRC_MM!$E$15/SRC_MM!$E$13 -> 91.466539 | H10: =H9*SRC_MM!$E$15/SRC_MM!$E$13 -> 114.33317 | I10: =I9*SRC_MM!$E$15/SRC_MM!$E$13 -> 137.19981 | J10: 產品別 2025 後未揭露；僅示意
A11: R04 | B11: 其中 海螺 Hailuo（依 9M25 結構） | C11: $M | D11: =D9*SRC_MM!$E$16/SRC_MM!$E$13 -> 24.390805 | E11: =E9*SRC_MM!$E$16/SRC_MM!$E$13 -> 42.070693 | F11: =F9*SRC_MM!$E$16/SRC_MM!$E$13 -> 63.10604 | G11: =G9*SRC_MM!$E$16/SRC_MM!$E$13 -> 85.193154 | H11: =H9*SRC_MM!$E$16/SRC_MM!$E$13 -> 106.49144 | I11: =I9*SRC_MM!$E$16/SRC_MM!$E$13 -> 127.78973
A12: R05 | B12: 其中 Audio＋App／Agent（依 9M25 結構） | C12: $M | D12: =D9*SRC_MM!$E$17/SRC_MM!$E$13 -> 2.5223198 | E12: =E9*SRC_MM!$E$17/SRC_MM!$E$13 -> 4.3506454 | F12: =F9*SRC_MM!$E$17/SRC_MM!$E$13 -> 6.5259682 | G12: =G9*SRC_MM!$E$17/SRC_MM!$E$13 -> 8.810057 | H12: =H9*SRC_MM!$E$17/SRC_MM!$E$13 -> 11.012571 | I12: =I9*SRC_MM!$E$17/SRC_MM!$E$13 -> 13.215086
A13: R06 | B13: 其中 廣告（依 9M25 結構） | C13: $M | D13: =D9*SRC_MM!$E$18/SRC_MM!$E$13 -> 15.625534 | E13: =E9*SRC_MM!$E$18/SRC_MM!$E$13 -> 26.951839 | F13: =F9*SRC_MM!$E$18/SRC_MM!$E$13 -> 40.427759 | G13: =G9*SRC_MM!$E$18/SRC_MM!$E$13 -> 54.577474 | H13: =H9*SRC_MM!$E$18/SRC_MM!$E$13 -> 68.221843 | I13: =I9*SRC_MM!$E$18/SRC_MM!$E$13 -> 81.866211 | J13: 收費方式別 2025 後未揭露
A14: R07 | B14: 其中 訂閱（依 9M25 結構） | C14: $M | D14: =D9*SRC_MM!$E$19/SRC_MM!$E$13 -> 30.945205 | E14: =E9*SRC_MM!$E$19/SRC_MM!$E$13 -> 53.376108 | F14: =F9*SRC_MM!$E$19/SRC_MM!$E$13 -> 80.064162 | G14: =G9*SRC_MM!$E$19/SRC_MM!$E$13 -> 108.08662 | H14: =H9*SRC_MM!$E$19/SRC_MM!$E$13 -> 135.10827 | I14: =I9*SRC_MM!$E$19/SRC_MM!$E$13 -> 162.12993 | J14: 方案別（Standard／Pro 等）未揭露
A15: R08 | B15: 其中 儲值（依 9M25 結構） | C15: $M | D15: =D9*SRC_MM!$E$20/SRC_MM!$E$13 -> 6.5292609 | E15: =E9*SRC_MM!$E$20/SRC_MM!$E$13 -> 11.262053 | F15: =F9*SRC_MM!$E$20/SRC_MM!$E$13 -> 16.893079 | G15: =G9*SRC_MM!$E$20/SRC_MM!$E$13 -> 22.805657 | H15: =H9*SRC_MM!$E$20/SRC_MM!$E$13 -> 28.507071 | I15: =I9*SRC_MM!$E$20/SRC_MM!$E$13 -> 34.208486
A16: 三、總額
A17: R09 | B17: 總營收 | C17: $M | D17: =D7+D9 -> 79.1 | E17: =E7+E9 -> 465.49 | F17: =F7+F9 -> 866.49 | G17: =G7+G9 -> 1279.1273 | H17: =H7+H9 -> 1631.7188 | I17: =I7+I9 -> 1944.0637
A18: R10 | B18: 總營收年增 | C18: 比例 | D18: =D17/SRC_MM!$E$5-1 -> 1.5914884 | E18: =E17/D17-1 -> 4.8848293 | F18: =F17/E17-1 -> 0.86145782 | G18: =G17/F17-1 -> 0.47621698 | H18: =H17/G17-1 -> 0.27565009 | I18: =I17/H17-1 -> 0.19142082
A19: R11 | B19: 企業端占比 | C19: 比例 | D19: =D7/D17 -> 0.32869785 | E19: =E7/E17 -> 0.8032396 | F19: =F7/F17 -> 0.84144653 | G19: =G7/G17 -> 0.85500289 | H19: =H7/H17 -> 0.85791842 | I19: =I7/I17 -> 0.85689532
A20: R12 | B20: 檢查：2025 模型總額 − 實際營收（應為 0） | C20: $M | D20: =D17-SRC_MM!$E$6 -> 0.062
A21: 四、對照市場（只對照，不校準；皆 Interested-party）
A22: R13 | B22: 對照：賣方預估營收 | C22: $M | E22: =SRC_MM!$E$66 -> 452 | F22: =SRC_MM!$E$67 -> 880.1 | G22: =SRC_MM!$E$68 -> 2469.6 | I22: =SRC_MM!$E$69 -> 5800 | J22: 2026 共識平均；2027–28 Goldman；2030 Visible Alpha
A23: R14 | B23: 模型 ÷ 賣方預估 | C23: 倍 | E23: =E17/E22 -> 1.0298451 | F23: =F17/F22 -> 0.98453585 | G23: =G17/G22 -> 0.51794916 | I23: =I17/I22 -> 0.3351834

Sheet Compute
A1: Compute — 算力：token → MW（API）、支出 → MW（消費端、訓練）
A2: 單位：$M＝百萬美元；MW＝IT 關鍵電力；T＝10^12 token。2025＝實際校準年；2026＝上半年實際＋下半年推估。黑字＝公式；綠字＝引用其他頁。
A4: ID | B4: 項目 | C4: 單位 | D4: FY2025 | E4: FY2026 | F4: FY2027 | G4: FY2028 | H4: FY2029 | I4: FY2030 | J4: 說明
B5: 年度 | D5: 2025 | E5: 2026 | F5: 2027 | G5: 2028 | H5: 2029 | I5: 2030
A6: 一、機隊組合與每 MW 產能（Tokenomics；M tok/GW/年 ÷ 10^9 ＝ T/MW/年）
A7: C01 | B7: Hopper 級占比 | C7: 比例 | D7: =Inputs!$D$10 -> 1 | E7: =Inputs!$E$10 -> 0.85 | F7: =Inputs!$F$10 -> 0.65 | G7: =Inputs!$G$10 -> 0.45 | H7: =Inputs!$H$10 -> 0.3 | I7: =Inputs!$I$10 -> 0.2
A8: C02 | B8: Blackwell 級占比 | C8: 比例 | D8: =1-D7 -> 0 | E8: =1-E7 -> 0.15 | F8: =1-F7 -> 0.35 | G8: =1-G7 -> 0.55 | H8: =1-H7 -> 0.7 | I8: =1-I7 -> 0.8
A9: C03 | B9: 每 MW 年產能：低層（Luna；基準利用率） | C9: T/MW/年 | D9: =(D7*TK_Link!$F$5+D8*TK_Link!$F$6)/10^9*TK_Link!$F$10 -> 44.440351 | E9: =(E7*TK_Link!$F$5+E8*TK_Link!$F$6)/10^9*TK_Link!$F$10 -> 70.381919 | F9: =(F7*TK_Link!$F$5+F8*TK_Link!$F$6)/10^9*TK_Link!$F$10 -> 104.97068 | G9: =(G7*TK_Link!$F$5+G8*TK_Link!$F$6)/10^9*TK_Link!$F$10 -> 139.55943 | H9: =(H7*TK_Link!$F$5+H8*TK_Link!$F$6)/10^9*TK_Link!$F$10 -> 165.501 | I9: =(I7*TK_Link!$F$5+I8*TK_Link!$F$6)/10^9*TK_Link!$F$10 -> 182.79538
A10: C04 | B10: 每 MW 年產能：中層（Sol；基準利用率） | C10: T/MW/年 | D10: =(D7*TK_Link!$F$7+D8*TK_Link!$F$8)/10^9*TK_Link!$F$10 -> 12.894258 | E10: =(E7*TK_Link!$F$7+E8*TK_Link!$F$8)/10^9*TK_Link!$F$10 -> 20.331405 | F10: =(F7*TK_Link!$F$7+F8*TK_Link!$F$8)/10^9*TK_Link!$F$10 -> 30.247602 | G10: =(G7*TK_Link!$F$7+G8*TK_Link!$F$8)/10^9*TK_Link!$F$10 -> 40.163798 | H10: =(H7*TK_Link!$F$7+H8*TK_Link!$F$8)/10^9*TK_Link!$F$10 -> 47.600946 | I10: =(I7*TK_Link!$F$7+I8*TK_Link!$F$8)/10^9*TK_Link!$F$10 -> 52.559044
A11: C05 | B11: 每 MW 年產能：MiniMax 層級組合 | C11: T/MW/年 | D11: =Inputs!$D$9*D9+(1-Inputs!$D$9)*D10 -> 31.821914 | E11: =Inputs!$D$9*E9+(1-Inputs!$D$9)*E10 -> 50.361713 | F11: =Inputs!$D$9*F9+(1-Inputs!$D$9)*F10 -> 75.081446 | G11: =Inputs!$D$9*G9+(1-Inputs!$D$9)*G10 -> 99.801179 | H11: =Inputs!$D$9*H9+(1-Inputs!$D$9)*H10 -> 118.34098 | I11: =Inputs!$D$9*I9+(1-Inputs!$D$9)*I10 -> 130.70085
A12: C06 | B12: 模型效率指數 | C12: 倍 | D12: =Inputs!$D$11 -> 1 | E12: =Inputs!$E$11 -> 2 | F12: =Inputs!$F$11 -> 2.6 | G12: =Inputs!$G$11 -> 3.38 | H12: =Inputs!$H$11 -> 4.39 | I12: =Inputs!$I$11 -> 5.71
A13: C07 | B13: API 推論 MW（年度 token 換算，未除 η） | C13: MW | D13: =Demand!$D$10/(D11*D12) -> 2.0426176 | E13: =Demand!$E$10/(E11*E12) -> 16.873388 | F13: =Demand!$F$10/(F11*F12) -> 26.11849 | G13: =Demand!$G$10/(G11*G12) -> 30.229549 | H13: =Demand!$H$10/(H11*H12) -> 31.405401 | I13: =Demand!$I$10/(I11*I12) -> 30.606773
A14: 二、V2 有效產出係數 η：以實際算力支出校準（2025 全年；2026 以上半年年化，為最新實際）
A15: C08 | B15: 校準期 API 算力支出（年化） | C15: $M/年 | D15: =Revenue!$D$7*(1-SRC_MM!$E$22)*Inputs!$D$8 -> 7.1604 | E15: =(SRC_MM!$E$24*Inputs!$D$8-SRC_MM!$E$11*Inputs!$E$18)*2 -> 99.948 | J15: 2025＝API 營收 ×（1−9M25 分部毛利率）× 算力占比；2026＝（1H26 銷售成本 × 算力占比 − 消費端算力）× 2
A16: C09 | B16: 校準期 API 推論 MW（支出換算） | C16: MW | D16: =D15/Inputs!$D$7 -> 0.5967 | E16: =E15/Inputs!$D$7 -> 8.329
A17: C10 | B17: 校準期 API 推論 MW（token 換算） | C17: MW | D17: =D13 -> 2.0426176 | E17: =(2*SRC_MM!$E$12/Demand!$E$7)/(E11*E12) -> 6.6699298 | J17: 2026＝1H26 營收 ÷ 單價 × 2
A18: C11 | B18: η＝token 換算 MW ÷ 支出換算 MW | C18: 倍 | D18: =D17/D16 -> 3.4231902 | E18: =E17/E16 -> 0.80080799 | J18: <1：每 MW 實際產出的計費 token 少於 Tokenomics 推算（訂閱方案低價 token、免費額度、長上下文、M3 較大）
A19: C12 | B19: 採用的 η（2026 上半年＝校準值；2026 下半年起 × I29） | C19: 倍 | D19: =D18 -> 3.4231902 | E19: =E18 -> 0.80080799 | F19: =E18*Inputs!$D$32 -> 1.0410504 | G19: =E18*Inputs!$D$32 -> 1.0410504 | H19: =E18*Inputs!$D$32 -> 1.0410504 | I19: =E18*Inputs!$D$32 -> 1.0410504
A20: C13 | B20: API 推論 MW（有效；年均） | C20: MW | D20: =D13/D19 -> 0.5967 | E20: =0.5*E16+0.5*(Inputs!$D$15/Demand!$E$7)/(E11*E12*E18*Inputs!$D$32) -> 17.16908 | F20: =F13/F19 -> 25.088593 | G20: =G13/G19 -> 29.037546 | H20: =H13/H19 -> 30.167032 | I20: =I13/I19 -> 29.399896 | J20: 2026＝上半年實際 MW 與下半年 MW 的平均
A21: 三、消費端推論 MW（支出換算；影片生成為主，token 口徑不適用）
A22: C14 | B22: 消費端算力成本 ÷ 消費端營收 | C22: 比例 | D22: =(SRC_MM!$E$23*Inputs!$D$8-D15)/Revenue!$D$9 -> 0.86445763 | E22: =Inputs!$E$18 -> 0.85 | F22: =Inputs!$F$18 -> 0.75 | G22: =Inputs!$G$18 -> 0.68 | H22: =Inputs!$H$18 -> 0.62 | I22: =Inputs!$I$18 -> 0.55 | J22: 2025 由財報推得
A23: C15 | B23: 消費端算力支出 | C23: $M | D23: =D22*Revenue!$D$9 -> 45.9027 | E23: =E22*Revenue!$E$9 -> 77.8515 | F23: =F22*Revenue!$F$9 -> 103.03875 | G23: =G22*Revenue!$G$9 -> 126.11943 | H23: =H22*Revenue!$H$9 -> 143.73906 | I23: =I22*Revenue!$I$9 -> 153.01254
A24: C16 | B24: 消費端推論 MW | C24: MW | D24: =D23/Inputs!$D$7 -> 3.825225 | E24: =E23/Inputs!$D$7 -> 6.487625 | F24: =F23/Inputs!$D$7 -> 8.5865625 | G24: =G23/Inputs!$D$7 -> 10.509953 | H24: =H23/Inputs!$D$7 -> 11.978255 | I24: =I23/Inputs!$D$7 -> 12.751045
A25: 四、訓練（研發）MW
A26: C17 | B26: 1H2026 研發算力（推得）＝研發費用 − 員工福利 × 研發占比 | C26: $M | E26: =SRC_MM!$E$30-SRC_MM!$E$33*Inputs!$D$20 -> 245.195
A27: C18 | B27: 訓練算力支出 | C27: $M | D27: =SRC_MM!$E$31 -> 194.2 | E27: =E26*(1+Inputs!$D$21) -> 539.429 | F27: =F28*Inputs!$D$7 -> 970.9722 | G27: =G28*Inputs!$D$7 -> 1456.4583 | H27: =H28*Inputs!$D$7 -> 1966.2187 | I27: =I28*Inputs!$D$7 -> 2457.7734 | J27: 2025 實際；2026 上半年推得 × (1＋下半年倍數)
A28: C19 | B28: 訓練 MW | C28: MW | D28: =D27/Inputs!$D$7 -> 16.183333 | E28: =E27/Inputs!$D$7 -> 44.952417 | F28: =E28*(1+Inputs!$F$22) -> 80.91435 | G28: =F28*(1+Inputs!$G$22) -> 121.37153 | H28: =G28*(1+Inputs!$H$22) -> 163.85156 | I28: =H28*(1+Inputs!$I$22) -> 204.81445
A29: 五、總 MW（年均）與 VR 等值
A30: C20 | B30: 推論 MW 合計（API＋消費端） | C30: MW | D30: =D20+D24 -> 4.421925 | E30: =E20+E24 -> 23.656705 | F30: =F20+F24 -> 33.675156 | G30: =G20+G24 -> 39.547498 | H30: =H20+H24 -> 42.145287 | I30: =I20+I24 -> 42.150942
A31: C21 | B31: 總 MW | C31: MW | D31: =D30+D28 -> 20.605258 | E31: =E30+E28 -> 68.609122 | F31: =F30+F28 -> 114.58951 | G31: =G30+G28 -> 160.91902 | H31: =H30+H28 -> 205.99685 | I31: =I30+I28 -> 246.96539
A32: C22 | B32: 訓練占總 MW | C32: 比例 | D32: =D28/D31 -> 0.78539823 | E32: =E28/E31 -> 0.65519592 | F32: =F28/F31 -> 0.70612356 | G32: =G28/G31 -> 0.75423976 | H32: =H28/H31 -> 0.7954081 | I32: =I28/I31 -> 0.8293245
A33: C23 | B33: 機隊 VR200 等值係數（Sol 層級每 GW 產能比） | C33: 倍 | D33: =(D7*TK_Link!$F$7+D8*TK_Link!$F$8)/TK_Link!$F$9 -> 0.090567115 | E33: =(E7*TK_Link!$F$7+E8*TK_Link!$F$8)/TK_Link!$F$9 -> 0.1428044 | F33: =(F7*TK_Link!$F$7+F8*TK_Link!$F$8)/TK_Link!$F$9 -> 0.21245411 | G33: =(G7*TK_Link!$F$7+G8*TK_Link!$F$8)/TK_Link!$F$9 -> 0.28210382 | H33: =(H7*TK_Link!$F$7+H8*TK_Link!$F$8)/TK_Link!$F$9 -> 0.3343411 | I33: =(I7*TK_Link!$F$7+I8*TK_Link!$F$8)/TK_Link!$F$9 -> 0.36916595
A34: C24 | B34: 總 MW（VR 等值） | C34: MW | D34: =D31*D33 -> 1.8661588 | E34: =E31*E33 -> 9.7976843 | F34: =F31*F33 -> 24.345011 | G34: =G31*G33 -> 45.395871 | H34: =H31*H33 -> 68.873212 | I34: =I31*I33 -> 91.171214
A35: C25 | B35: Hopper 等值 GPU 數（顯示用） | C35: 張 | D35: =D31*1000/Inputs!$D$31 -> 14718.042 | E35: =E31*1000/Inputs!$D$31 -> 49006.515 | F35: =F31*1000/Inputs!$D$31 -> 81849.647 | G35: =G31*1000/Inputs!$D$31 -> 114942.16 | H35: =H31*1000/Inputs!$D$31 -> 147140.6 | I35: =I31*1000/Inputs!$D$31 -> 176403.85 | J35: MW × 1000 ÷ 每張 kW
A36: 六、對照（只列差距）
A37: C26 | B37: 總算力支出（推論＋訓練） | C37: $M | D37: =(D20+D24+D28)*Inputs!$D$7 -> 247.2631 | E37: =(E20+E24+E28)*Inputs!$D$7 -> 823.30946 | F37: =(F20+F24+F28)*Inputs!$D$7 -> 1375.0741 | G37: =(G20+G24+G28)*Inputs!$D$7 -> 1931.0283 | H37: =(H20+H24+H28)*Inputs!$D$7 -> 2471.9621 | I37: =(I20+I24+I28)*Inputs!$D$7 -> 2963.5847
A38: C27 | B38: 對照：阿里雲採購上限（S059–S061） | C38: $M | E38: =SRC_MM!$E$63 -> 300 | F38: =SRC_MM!$E$64 -> 400 | G38: =SRC_MM!$E$65 -> 500 | J38: 阿里雲之外尚有其他中國及海外雲、自建集群
A39: C28 | B39: 阿里雲上限占總算力支出 | C39: 比例 | E39: =E38/E37 -> 0.36438304 | F39: =F38/F37 -> 0.29089342 | G39: =G38/G37 -> 0.2589294
A40: C29 | B40: 對照：Tokenomics Hopper 每 MW 年持有成本（供應商口徑） | C40: $M/MW/年 | D40: =TK_Link!$F$11 -> 10.095795 | E40: =TK_Link!$F$11 -> 10.095795 | F40: =TK_Link!$F$11 -> 10.095795 | G40: =TK_Link!$F$11 -> 10.095795 | H40: =TK_Link!$F$11 -> 10.095795 | I40: =TK_Link!$F$11 -> 10.095795 | J40: 合約價 − 持有成本＝雲端毛利
A41: C30 | B41: 對照：每百萬 token API 推論成本（有效） | C41: $/M | D41: =D20*Inputs!$D$7/Demand!$D$10 -> 0.11016 | E41: =E20*Inputs!$D$7/Demand!$E$10 -> 0.12122592 | F41: =F20*Inputs!$D$7/Demand!$F$10 -> 0.059047772 | G41: =G20*Inputs!$D$7/Demand!$G$10 -> 0.034170955 | H41: =H20*Inputs!$D$7/Demand!$H$10 -> 0.022187574 | I41: =I20*Inputs!$D$7/Demand!$I$10 -> 0.015445252 | J41: 與 TK 全成本 $/M（TK09–TK12）比較

Sheet PnL
A1: PnL — 損益與命題：每 MW 營收 vs 每 MW 全成本
A2: 單位：$M＝百萬美元；MW＝IT 關鍵電力；T＝10^12 token。2025＝實際校準年；2026＝上半年實際＋下半年推估。黑字＝公式；綠字＝引用其他頁。
A4: ID | B4: 項目 | C4: 單位 | D4: FY2025 | E4: FY2026 | F4: FY2027 | G4: FY2028 | H4: FY2029 | I4: FY2030 | J4: 說明
B5: 年度 | D5: 2025 | E5: 2026 | F5: 2027 | G5: 2028 | H5: 2029 | I5: 2030
A6: 一、營收與銷售成本
A7: P01 | B7: 總營收 | C7: $M | D7: =Revenue!$D$17 -> 79.1 | E7: =Revenue!$E$17 -> 465.49 | F7: =Revenue!$F$17 -> 866.49 | G7: =Revenue!$G$17 -> 1279.1273 | H7: =Revenue!$H$17 -> 1631.7188 | I7: =Revenue!$I$17 -> 1944.0637
A8: P02 | B8: API 推論算力 | C8: $M | D8: =Compute!$D$20*Inputs!$D$7 -> 7.1604 | E8: =Compute!$E$20*Inputs!$D$7 -> 206.02896 | F8: =Compute!$F$20*Inputs!$D$7 -> 301.06312 | G8: =Compute!$G$20*Inputs!$D$7 -> 348.45055 | H8: =Compute!$H$20*Inputs!$D$7 -> 362.00439 | I8: =Compute!$I$20*Inputs!$D$7 -> 352.79875
A9: P03 | B9: 消費端推論算力 | C9: $M | D9: =Compute!$D$23 -> 45.9027 | E9: =Compute!$E$23 -> 77.8515 | F9: =Compute!$F$23 -> 103.03875 | G9: =Compute!$G$23 -> 126.11943 | H9: =Compute!$H$23 -> 143.73906 | I9: =Compute!$I$23 -> 153.01254
A10: P04 | B10: 其他銷售成本（非算力） | C10: $M | D10: =SRC_MM!$E$23*(1-Inputs!$D$8) -> 5.8959 | E10: =E7*Inputs!$D$19 -> 23.2745 | F10: =F7*Inputs!$D$19 -> 43.3245 | G10: =G7*Inputs!$D$19 -> 63.956362 | H10: =H7*Inputs!$D$19 -> 81.585939 | I10: =I7*Inputs!$D$19 -> 97.203186
A11: P05 | B11: 銷售成本合計 | C11: $M | D11: =D8+D9+D10 -> 58.959 | E11: =E8+E9+E10 -> 307.15496 | F11: =F8+F9+F10 -> 447.42637 | G11: =G8+G9+G10 -> 538.52634 | H11: =H8+H9+H10 -> 587.32938 | I11: =I8+I9+I10 -> 603.01448
A12: P06 | B12: 毛利 | C12: $M | D12: =D7-D11 -> 20.141 | E12: =E7-E11 -> 158.33504 | F12: =F7-F11 -> 419.06363 | G12: =G7-G11 -> 740.60091 | H12: =H7-H11 -> 1044.3894 | I12: =I7-I11 -> 1341.0492
A13: P07 | B13: 毛利率 | C13: 比例 | D13: =D12/D7 -> 0.25462705 | E13: =E12/E7 -> 0.34014703 | F13: =F12/F7 -> 0.48363355 | G13: =G12/G7 -> 0.57898923 | H13: =H12/H7 -> 0.64005478 | I13: =I12/I7 -> 0.68981753
A14: P08 | B14: 企業端（API）毛利率 | C14: 比例 | D14: =1-(D8+D10*Revenue!$D$7/D7)/Revenue!$D$7 -> 0.65006271 | E14: =1-(E8+E10*Revenue!$E$7/E7)/Revenue!$E$7 -> 0.39897309 | F14: =1-(F8+F10*Revenue!$F$7/F7)/Revenue!$F$7 -> 0.53707852 | G14: =1-(G8+G10*Revenue!$G$7/G7)/Revenue!$G$7 -> 0.63138969 | H14: =1-(H8+H10*Revenue!$H$7/H7)/Revenue!$H$7 -> 0.69140357 | I14: =1-(I8+I10*Revenue!$I$7/I7)/Revenue!$I$7 -> 0.73821813 | J14: 其他銷售成本按營收比例分攤
A15: P09 | B15: 消費端毛利率 | C15: 比例 | D15: =1-(D9+D10*Revenue!$D$9/D7)/Revenue!$D$9 -> 0.061005078 | E15: =1-(E9+E10*Revenue!$E$9/E7)/Revenue!$E$9 -> 0.1 | F15: =1-(F9+F10*Revenue!$F$9/F7)/Revenue!$F$9 -> 0.2 | G15: =1-(G9+G10*Revenue!$G$9/G7)/Revenue!$G$9 -> 0.27 | H15: =1-(H9+H10*Revenue!$H$9/H7)/Revenue!$H$9 -> 0.33 | I15: =1-(I9+I10*Revenue!$I$9/I7)/Revenue!$I$9 -> 0.4
A16: 二、營業費用（依成本性質：訓練算力／人事／其他）
A17: P10 | B17: 訓練算力（研發） | C17: $M | D17: =Compute!$D$27 -> 194.2 | E17: =Compute!$E$27 -> 539.429 | F17: =Compute!$F$27 -> 970.9722 | G17: =Compute!$G$27 -> 1456.4583 | H17: =Compute!$H$27 -> 1966.2187 | I17: =Compute!$I$27 -> 2457.7734
A18: P11 | B18: 每人年人事成本（含 SBC） | C18: $K/人 | E18: =SRC_MM!$E$33*2/AVERAGE(SRC_MM!$E$42,SRC_MM!$E$43)*1000 -> 276.70683 | F18: =E18*(1+Inputs!$D$24) -> 298.84337 | G18: =F18*(1+Inputs!$D$24) -> 322.75084 | H18: =G18*(1+Inputs!$D$24) -> 348.57091 | I18: =H18*(1+Inputs!$D$24) -> 376.45658 | J18: 2026＝1H26 員工福利 × 2 ÷ 平均人數
A19: P12 | B19: 人事成本（含 SBC） | C19: $M | D19: =SRC_MM!$E$32 -> 84.3 | E19: =Inputs!$E$23*E18/1000 -> 154.95582 | F19: =Inputs!$F$23*F18/1000 -> 224.13253 | G19: =Inputs!$G$23*G18/1000 -> 306.6133 | H19: =Inputs!$H$23*H18/1000 -> 383.428 | I19: =Inputs!$I$23*I18/1000 -> 470.57073
A20: P13 | B20: 其中 SBC | C20: $M | D20: =SRC_MM!$E$34 -> 24.031 | E20: =E19*SRC_MM!$E$35/SRC_MM!$E$33 -> 63.439679 | F20: =F19*SRC_MM!$E$35/SRC_MM!$E$33 -> 91.760964 | G20: =G19*SRC_MM!$E$35/SRC_MM!$E$33 -> 125.529 | H20: =H19*SRC_MM!$E$35/SRC_MM!$E$33 -> 156.97732 | I20: =I19*SRC_MM!$E$35/SRC_MM!$E$33 -> 192.65398 | J20: SBC 占人事比例沿用 1H26
A21: P14 | B21: 其他營業費用（行銷、行政、上市費等） | C21: $M | D21: =SRC_MM!$E$25+SRC_MM!$E$26+SRC_MM!$E$27-SRC_MM!$E$32-SRC_MM!$E$31 -> 62.98 | E21: =(SRC_MM!$E$28+SRC_MM!$E$29+SRC_MM!$E$30-SRC_MM!$E$33-Compute!$E$26)+(E7-SRC_MM!$E$8)*Inputs!$E$25 -> 162.09895 | F21: =F7*Inputs!$F$25 -> 216.6225 | G21: =G7*Inputs!$G$25 -> 255.82545 | H21: =H7*Inputs!$H$25 -> 277.39219 | I21: =I7*Inputs!$I$25 -> 291.60956 | J21: 2025＝三項費用 − 人事 − 研發算力；2026＝1H26 同法推得＋下半年營收 × 比例
A22: P15 | B22: 營業費用合計 | C22: $M | D22: =D17+D19+D21 -> 341.48 | E22: =E17+E19+E21 -> 856.48377 | F22: =F17+F19+F21 -> 1411.7272 | G22: =G17+G19+G21 -> 2018.8971 | H22: =H17+H19+H21 -> 2627.0389 | I22: =I17+I19+I21 -> 3219.9537
A23: P16 | B23: 營業虧損（負＝虧損） | C23: $M | D23: =D12-D22 -> -321.339 | E23: =E12-E22 -> -698.14873 | F23: =F12-F22 -> -992.6636 | G23: =G12-G22 -> -1278.2961 | H23: =H12-H22 -> -1582.6495 | I23: =I12-I22 -> -1878.9044
A24: P17 | B24: 利息與理財收益 | C24: $M | D24: =SRC_MM!$E$36 -> 40.369 | E24: =(Funding!$E$7+0.5*(Funding!$E$8+Funding!$E$9+Funding!$E$10+Funding!$E$11))*Inputs!$D$26 -> 73.797512 | F24: =(Funding!$F$7+0.5*(Funding!$F$8+Funding!$F$9+Funding!$F$10+Funding!$F$11))*Inputs!$D$26 -> 89.598677 | G24: =(Funding!$G$7+0.5*(Funding!$G$8+Funding!$G$9+Funding!$G$10+Funding!$G$11))*Inputs!$D$26 -> 40.195291 | H24: =(Funding!$H$7+0.5*(Funding!$H$8+Funding!$H$9+Funding!$H$10+Funding!$H$11))*Inputs!$D$26 -> 9 | I24: =(Funding!$I$7+0.5*(Funding!$I$8+Funding!$I$9+Funding!$I$10+Funding!$I$11))*Inputs!$D$26 -> 9 | J24: 2026 起＝(期初現金＋當年融資 ÷ 2) × 收益率（避免循環參照）
A25: P18 | B25: 經調整淨利（非 IFRS；不含 SBC、公允價值變動、稅） | C25: $M | D25: =D23+D24+D20 -> -256.939 | E25: =E23+E24+E20 -> -560.91154 | F25: =F23+F24+F20 -> -811.30396 | G25: =G23+G24+G20 -> -1112.5719 | H25: =H23+H24+H20 -> -1416.6722 | I25: =I23+I24+I20 -> -1677.2504
A26: P19 | B26: 檢查：2025 經調整淨利 − 實際（−250.9；差額＝財務成本等） | C26: $M | D26: =D25+SRC_MM!$E$38 -> -6.083
A27: 三、命題：每 MW 營收能否覆蓋每 MW 全成本
A28: P20 | B28: 總 MW（年均） | C28: MW | D28: =Compute!$D$31 -> 20.605258 | E28: =Compute!$E$31 -> 68.609122 | F28: =Compute!$F$31 -> 114.58951 | G28: =Compute!$G$31 -> 160.91902 | H28: =Compute!$H$31 -> 205.99685 | I28: =Compute!$I$31 -> 246.96539
A29: P21 | B29: 每 MW 營收 | C29: $M/MW/年 | D29: =D7/D28 -> 3.8388259 | E29: =E7/E28 -> 6.7846664 | F29: =F7/F28 -> 7.5616872 | G29: =G7/G28 -> 7.9488877 | H29: =H7/H28 -> 7.9210863 | I29: =I7/I28 -> 7.8718064
A30: P22 | B30: 每 MW 全成本（銷售成本＋營業費用，含 SBC） | C30: $M/MW/年 | D30: =(D11+D22)/D28 -> 19.433826 | E30: =(E11+E22)/E28 -> 16.960409 | F30: =(F11+F22)/F28 -> 16.224467 | G30: =(G11+G22)/G28 -> 15.892611 | H30: =(H11+H22)/H28 -> 15.603968 | I30: =(I11+I22)/I28 -> 15.479773
A31: P23 | B31: 覆蓋率＝每 MW 營收 ÷ 每 MW 全成本 | C31: 倍 | D31: =D29/D30 -> 0.19753321 | E31: =E29/E30 -> 0.40002965 | F31: =F29/F30 -> 0.46606692 | G31: =G29/G30 -> 0.50016249 | H31: =H29/H30 -> 0.5076328 | I31: =I29/I30 -> 0.50852208 | J31: ≥1 才算打平
A32: P24 | B32: 每 MW 全成本：算力部分（＝合約價） | C32: $M/MW/年 | D32: =Inputs!$D$7 -> 12 | E32: =Inputs!$D$7 -> 12 | F32: =Inputs!$D$7 -> 12 | G32: =Inputs!$D$7 -> 12 | H32: =Inputs!$D$7 -> 12 | I32: =Inputs!$D$7 -> 12
A33: P25 | B33: 每 MW 全成本：非算力部分（人事＋其他） | C33: $M/MW/年 | D33: =D30-D32 -> 7.4338258 | E33: =E30-E32 -> 4.9604085 | F33: =F30-F32 -> 4.2244665 | G33: =G30-G32 -> 3.8926107 | H33: =H30-H32 -> 3.6039685 | I33: =I30-I32 -> 3.4797729
A34: P26 | B34: 每 VR 等值 MW 營收 | C34: $M/MW/年 | D34: =D7/Compute!$D$34 -> 42.386532 | E34: =E7/Compute!$E$34 -> 47.510206 | F34: =F7/Compute!$F$34 -> 35.592097 | G34: =G7/Compute!$G$34 -> 28.177172 | H34: =H7/Compute!$H$34 -> 23.691632 | I34: =I7/Compute!$I$34 -> 21.323219
A35: P27 | B35: 每 VR 等值 MW 全成本 | C35: $M/MW/年 | D35: =(D11+D22)/Compute!$D$34 -> 214.57927 | E35: =(E11+E22)/Compute!$E$34 -> 118.76671 | F35: =(F11+F22)/Compute!$F$34 -> 76.366923 | G35: =(G11+G22)/Compute!$G$34 -> 56.336036 | H35: =(H11+H22)/Compute!$H$34 -> 46.670806 | I35: =(I11+I22)/Compute!$I$34 -> 41.931746
A36: P28 | B36: API 單位經濟：每推論 MW 的 API 營收 ÷ 合約價 | C36: 倍 | D36: =Revenue!$D$7/Compute!$D$20/Inputs!$D$7 -> 3.6310821 | E36: =Revenue!$E$7/Compute!$E$20/Inputs!$D$7 -> 1.8147934 | F36: =Revenue!$F$7/Compute!$F$20/Inputs!$D$7 -> 2.4217679 | G36: =Revenue!$G$7/Compute!$G$20/Inputs!$D$7 -> 3.1386304 | H36: =Revenue!$H$7/Compute!$H$20/Inputs!$D$7 -> 3.8670294 | I36: =Revenue!$I$7/Compute!$I$20/Inputs!$D$7 -> 4.7218395 | J36: >1＝推論本身賺錢
A37: P29 | B37: 訓練＋人事＋其他 占營收 | C37: 比例 | D37: =(D17+D19+D21)/D7 -> 4.317067 | E37: =(E17+E19+E21)/E7 -> 1.8399617 | F37: =(F17+F19+F21)/F7 -> 1.6292482 | G37: =(G17+G19+G21)/G7 -> 1.5783395 | H37: =(H17+H19+H21)/H7 -> 1.6099826 | I37: =(I17+I19+I21)/I7 -> 1.6563005
A38: P30 | B38: 打平旗標（覆蓋率 ≥ 1） | C38: 旗標 | D38: =IF(D31>=1,1,0) -> 0 | E38: =IF(E31>=1,1,0) -> 0 | F38: =IF(F31>=1,1,0) -> 0 | G38: =IF(G31>=1,1,0) -> 0 | H38: =IF(H31>=1,1,0) -> 0 | I38: =IF(I31>=1,1,0) -> 0
A39: 四、對照（只列差距，不校準）
A40: P31 | B40: 對照：1H2026 實際毛利率 | C40: 比例 | E40: =1-SRC_MM!$E$24/SRC_MM!$E$8 -> 0.17854049 | J40: 模型 2026 全年含下半年效率改善
A41: P32 | B41: 對照：1H2026 實際經調整淨虧損 × 2 | C41: $M | E41: =-SRC_MM!$E$39*2 -> -586.062
...

Sheet Funding
A1: Funding — 現金、缺口與融資來源
A2: 單位：$M＝百萬美元；MW＝IT 關鍵電力；T＝10^12 token。2025＝實際校準年；2026＝上半年實際＋下半年推估。黑字＝公式；綠字＝引用其他頁。
A4: ID | B4: 項目 | C4: 單位 | D4: FY2025 | E4: FY2026 | F4: FY2027 | G4: FY2028 | H4: FY2029 | I4: FY2030 | J4: 說明
B5: 年度 | D5: 2025 | E5: 2026 | F5: 2027 | G5: 2028 | H5: 2029 | I5: 2030
A6: 一、現金來源（2026 已完成的融資為實際；單位 $M）
A7: F01 | B7: 期初現金（公司口徑） | C7: $M | E7: =SRC_MM!$E$44 -> 1050.3 | F7: =E19 -> 2986.6226 | G7: =F19 -> 1339.843 | H7: =G19 -> 300 | I7: =H19 -> 300
A8: F02 | B8: IPO 淨募資 | C8: $M | D8: 0 | E8: =SRC_MM!$E$46/Inputs!$D$6 -> 680.3856 | F8: 0 | G8: 0 | H8: 0 | I8: 0 | J8: 2026-01；含超額配售
A9: F03 | B9: 配售新股淨額 | C9: $M | D9: 0 | E9: =SRC_MM!$E$47/Inputs!$D$6 -> 1213.8432 | F9: 0 | G9: 0 | H9: 0 | I9: 0 | J9: 2026-07；HK$268
A10: F04 | B10: 可轉債淨額 | C10: $M | D10: 0 | E10: =SRC_MM!$E$49/Inputs!$D$6 -> 826.90231 | F10: 0 | G10: 0 | H10: 0 | I10: 0 | J10: 2026-07；零息，2027 到期
A11: F05 | B11: 銀行借款淨增加 | C11: $M | D11: 0 | E11: =SRC_MM!$E$52-SRC_MM!$E$51 -> 98.103 | F11: 0 | G11: 0 | H11: 0 | I11: 0 | J11: 1H26 實際；其後假設不變
A12: 二、現金用途
A13: F06 | B13: 營運燒錢（＝經調整淨利；負＝流出） | C13: $M | E13: =PnL!$E$25 -> -560.91154 | F13: =PnL!$F$25 -> -811.30396 | G13: =PnL!$G$25 -> -1112.5719 | H13: =PnL!$H$25 -> -1416.6722 | I13: =PnL!$I$25 -> -1677.2504 | J13: 經調整淨利已排除 SBC；未計營運資金
A14: F07 | B14: 算力預付與自建資本支出（現金時差） | C14: $M | E14: =-Inputs!$E$27 -> -322 | F14: =-Inputs!$F$27 -> 0 | G14: =-Inputs!$G$27 -> 0 | H14: =-Inputs!$H$27 -> 0 | I14: =-Inputs!$I$27 -> 0
A15: F08 | B15: 可轉債到期現金贖回 | C15: $M | E15: 0 | F15: =-SRC_MM!$E$48/Inputs!$D$6*(1-Inputs!$D$28) -> -835.47558 | G15: 0 | H15: 0 | I15: 0
A16: F09 | B16: 期末現金（新融資前） | C16: $M | D16: =SRC_MM!$E$44 -> 1050.3 | E16: =E7+E8+E9+E10+E11+E13+E14+E15 -> 2986.6226 | F16: =F7+F8+F9+F10+F11+F13+F14+F15 -> 1339.843 | G16: =G7+G8+G9+G10+G11+G13+G14+G15 -> 227.27117 | H16: =H7+H8+H9+H10+H11+H13+H14+H15 -> -1116.6722 | I16: =I7+I8+I9+I10+I11+I13+I14+I15 -> -1377.2504
A17: F10 | B17: 需新融資（補足至最低現金） | C17: $M | E17: =MAX(0,Inputs!$D$29-E16) -> 0 | F17: =MAX(0,Inputs!$D$29-F16) -> 0 | G17: =MAX(0,Inputs!$D$29-G16) -> 72.72883 | H17: =MAX(0,Inputs!$D$29-H16) -> 1416.6722 | I17: =MAX(0,Inputs!$D$29-I16) -> 1677.2504
A18: F11 | B18: 累計需新融資（2026 起） | C18: $M | E18: =E17 -> 0 | F18: =E18+F17 -> 0 | G18: =F18+G17 -> 72.72883 | H18: =G18+H17 -> 1489.401 | I18: =H18+I17 -> 3166.6515
A19: F12 | B19: 期末現金（含新融資） | C19: $M | D19: =D16 -> 1050.3 | E19: =E16+E17 -> 2986.6226 | F19: =F16+F17 -> 1339.843 | G19: =G16+G17 -> 300 | H19: =H16+H17 -> 300 | I19: =I16+I17 -> 300
A20: F13 | B20: 新融資旗標年（第一個需融資的年度） | C20: 年 | E20: =IF(E17>0,E$5,9999) -> 9999 | F20: =IF(F17>0,F$5,9999) -> 9999 | G20: =IF(G17>0,G$5,9999) -> 2028 | H20: =IF(H17>0,H$5,9999) -> 2029 | I20: =IF(I17>0,I$5,9999) -> 2030
A21: F19 | B21: 首次需新融資年度（9999＝2030 年內不需要） | C21: 年 | E21: =MIN(E20,F20,G20,H20,I20) -> 2028
A22: F14 | B22: 累計新股稀釋（依現價 ×（1−折價）發行） | C22: 比例 | E22: =E18/(Valuation!$E$8*(1-Inputs!$D$30)) -> 0 | F22: =F18/(Valuation!$F$8*(1-Inputs!$D$30)) -> 0 | G22: =G18/(Valuation!$G$8*(1-Inputs!$D$30)) -> 0.0082560779 | H22: =H18/(Valuation!$H$8*(1-Inputs!$D$30)) -> 0.16907478 | I22: =I18/(Valuation!$I$8*(1-Inputs!$D$30)) -> 0.35947397 | J22: 占目前市值
A23: 三、已投入資金（誰在付錢；累計，$M）
A24: F15 | B24: 上市前創投與策略投資人（阿里巴巴、騰訊、米哈遊、紅杉、高瓴、IDG 等） | C24: $M | D24: =SRC_MM!$E$73 -> 1555 | J24: Pre-B 由阿里巴巴領投 654
A25: F16 | B25: IPO（基石：ADIA、Aspex、阿里巴巴等，占 56.5%） | C25: $M | E25: =E8 -> 680.3856
A26: F17 | B26: 2026-07 配售＋可轉債（承配人與債權人未具名） | C26: $M | E26: =E9+E10 -> 2040.7455
A27: F18 | B27: 累計外部資金 | C27: $M | E27: =D24+E25+E26 -> 4276.1311

Sheet Valuation
A1: Valuation — 市值、EV 與反向檢驗
A2: 單位：$M＝百萬美元；MW＝IT 關鍵電力；T＝10^12 token。2025＝實際校準年；2026＝上半年實際＋下半年推估。黑字＝公式；綠字＝引用其他頁。
A4: ID | B4: 項目 | C4: 單位 | D4: FY2025 | E4: FY2026 | F4: FY2027 | G4: FY2028 | H4: FY2029 | I4: FY2030 | J4: 說明
B5: 年度 | D5: 2025 | E5: 2026 | F5: 2027 | G5: 2028 | H5: 2029 | I5: 2030
A6: 一、市值與企業價值（以 2026-10-02 收盤；2026-10-08 股價未取得）
A7: V01 | B7: 隱含股價 | C7: HK$/股 | D7: =SRC_MM!$E$56/SRC_MM!$E$55 -> 218.04783 | E7: =SRC_MM!$E$56/SRC_MM!$E$55 -> 218.04783 | F7: =SRC_MM!$E$56/SRC_MM!$E$55 -> 218.04783 | G7: =SRC_MM!$E$56/SRC_MM!$E$55 -> 218.04783 | H7: =SRC_MM!$E$56/SRC_MM!$E$55 -> 218.04783 | I7: =SRC_MM!$E$56/SRC_MM!$E$55 -> 218.04783 | J7: 市值 ÷ 配售後股數
A8: V02 | B8: 市值 | C8: $M | D8: =SRC_MM!$E$56/Inputs!$D$6 -> 9787.9177 | E8: =SRC_MM!$E$56/Inputs!$D$6 -> 9787.9177 | F8: =SRC_MM!$E$56/Inputs!$D$6 -> 9787.9177 | G8: =SRC_MM!$E$56/Inputs!$D$6 -> 9787.9177 | H8: =SRC_MM!$E$56/Inputs!$D$6 -> 9787.9177 | I8: =SRC_MM!$E$56/Inputs!$D$6 -> 9787.9177
A9: V03 | B9: 淨現金（模型年底：現金 − 銀行借款 − 未轉股可轉債） | C9: $M | E9: =Funding!$E$19-SRC_MM!$E$52-SRC_MM!$E$48/Inputs!$D$6*(1-Inputs!$D$28) -> 2017.592 | F9: =Funding!$F$19-SRC_MM!$E$52 -> 1206.288 | G9: =Funding!$G$19-SRC_MM!$E$52 -> 166.445 | H9: =Funding!$H$19-SRC_MM!$E$52 -> 166.445 | I9: =Funding!$I$19-SRC_MM!$E$52 -> 166.445
A10: V04 | B10: 企業價值 EV（市值 − 淨現金） | C10: $M | E10: =E8-E9 -> 7770.3258 | F10: =E8-F9 -> 8581.6297 | G10: =E8-G9 -> 9621.4727 | H10: =E8-H9 -> 9621.4727 | I10: =E8-I9 -> 9621.4727 | J10: 市值固定為現值；只看各年淨現金變化
A11: V05 | B11: 2026 年底 EV ÷ 各年模型營收 | C11: 倍 | E11: =E10/Revenue!$E$17 -> 16.692788 | F11: =E10/Revenue!$F$17 -> 8.9675885 | G11: =E10/Revenue!$G$17 -> 6.0747089 | H11: =E10/Revenue!$H$17 -> 4.7620496 | I11: =E10/Revenue!$I$17 -> 3.9969501 | J11: 以 2026 年底 EV 對各年營收
A12: 二、同業對照（智譜 2513.HK）
A13: V06 | B13: 智譜市值 | C13: $M | E13: =SRC_MM!$E$74/Inputs!$D$6 -> 37493.573
A14: V07 | B14: 智譜 市值 ÷ 1H26 年化營收 | C14: 倍 | E14: =E13/(SRC_MM!$E$75/SRC_MM!$E$81*2) -> 139.52011
A15: V08 | B15: MiniMax 市值 ÷ 1H26 年化營收 | C15: 倍 | E15: =E8/(SRC_MM!$E$8*2) -> 41.981924
A16: 三、反向檢驗：以模型 2030 年營收與退出倍數，折回今天、扣除稀釋，是否支持現價
A17: V09 | B17: 2030 年 EV＝模型營收 × 退出倍數 | C17: $M | I17: =Revenue!$I$17*Inputs!$D$33 -> 15552.51
A18: V10 | B18: 2030 年股權價值＝EV＋淨現金 | C18: $M | I18: =I17+I9 -> 15718.955
A19: V11 | B19: 現有股東持有比例＝1 ÷（1＋累計稀釋） | C19: 比例 | I19: =1/(1+Funding!$I$22) -> 0.73557863
A20: V12 | B20: 現有股東價值折現至今 | C20: $M | I20: =I18*I19/(1+Inputs!$D$34)^4 -> 7348.1951 | J20: 折現 4 年
A21: V13 | B21: 折現價值 ÷ 目前市值 | C21: 倍 | I21: =I20/I8 -> 0.75074141 | J21: ≥1＝模型支持現價
A22: V14 | B22: 支持現價所需的 2030 營收 | C22: $M | I22: =(I8*(1+Inputs!$D$34)^4/I19-I9)/Inputs!$D$33 -> 2596.4329

Sheet Checks
A1: Checks — 檢查（全部應為 0；CHK_Errors 必須為 0）
A3: ID | B3: 檢查 | C3: 值（應為 0）
A4: K01 | B4: 2025 模型總營收 − 實際（分部捨入，容許 0.1） | C4: =MAX(0,ABS(Revenue!$D$20)-0.1) -> 0
A5: K02 | B5: 2025 銷售成本（模型）− 實際 | C5: =ABS(PnL!$D$11-SRC_MM!$E$23) -> 0
A6: K03 | B6: 2025 營業費用（模型）− 實際三項費用合計 | C6: =ABS(PnL!$D$22-(SRC_MM!$E$25+SRC_MM!$E$26+SRC_MM!$E$27)) -> 0
A7: K04 | B7: 2026 上半年營收：企業端＋消費端 − 總額（揭露捨入，容許 0.1） | C7: =MAX(0,ABS(SRC_MM!$E$11+SRC_MM!$E$12-SRC_MM!$E$8)-0.1) -> 0
A8: K05 | B8: 機隊組合各年介於 0–1 | C8: =SUMPRODUCT((Compute!$D$7:$I$7<0)+(Compute!$D$7:$I$7>1)) -> 0
A9: K06 | B9: 總 MW ＝ 推論＋訓練（各年合計差） | C9: =ABS(SUM(Compute!$D$31:$I$31)-SUM(Compute!$D$30:$I$30)-SUM(Compute!$D$28:$I$28)) -> 0
A10: K07 | B10: 2025 毛利率 − 實際（25.4%） | C10: =MAX(0,ABS(PnL!$D$13-(1-SRC_MM!$E$23/SRC_MM!$E$6))-0.001) -> 0
A11: K08 | B11: 期末現金不得低於最低水位（含新融資） | C11: =SUMPRODUCT((Funding!$E$19:$I$19<Inputs!$D$29-0.001)*1) -> 0
A13: CHK_Sum | B13: 檢查合計（應為 0） | C13: =SUM(C4:C11) -> 0
A14: CHK_Errors | B14: 計算頁錯誤值個數（應為 0） | C14: =SUMPRODUCT(--ISERROR(Demand!$D$6:$I$80))+SUMPRODUCT(--ISERROR(Revenue!$D$6:$I$80))+SUMPRODUCT(--ISERROR(Compute!$D$6:$I$80))+SUMPRODUCT(--ISERROR(PnL!$D$6:$I$80))+SUMPRODUCT(--ISERROR(Funding!$D$6:$I$80))+SUMPRODUCT(--ISERROR(Valuation!$D$6:$I$80)) -> 0

Sheet Sensitivity
A1: 敏感度（快照值：每列為改寫該項 Inputs 後由 LibreOffice 重算的結果；改 Inputs 後此頁不會自動更新，需重跑 scripts/sensitivity.py）
A3: 情境 | B3: 改寫 | C3: 2026 營收 $M | D3: 2030 營收 $M | E3: 2030 毛利率 | F3: 2030 覆蓋率（每 MW 營收÷全成本） | G3: 2030 經調整淨利 $M | H3: 至 2030 累計需新融資 $M | I3: 首次需新融資年 | J3: 折現價值÷市值
A4: 基準 | B4: — | C4: 465.49 | D4: 1944.0637 | E4: 0.68981753 | F4: 0.50852208 | G4: -1677.2504 | H4: 3166.6515 | I4: 2028 | J4: 0.75074141
A5: 合約價 $8M/MW | B5: I02=8 | C5: 465.49 | D5: 1944.0637 | E5: 0.68981753 | F5: 0.50852208 | G5: -1677.2504 | H5: 3166.6515 | I5: 2028 | J5: 0.75074141
A6: 合約價 $20M/MW | B6: I02=20 | C6: 465.49 | D6: 1944.0637 | E6: 0.68981753 | F6: 0.50852208 | G6: -1677.2504 | H6: 3166.6515 | I6: 2028 | J6: 0.75074141
A7: token 量成長低（0.8/0.5/0.3/0.2） | B7: I09@2027=0.8 I09@2028=0.5 I09@2029=0.3 I09@2030=0.2 | C7: 465.49 | D7: 800.27297 | E7: 0.62064094 | F7: 0.23874664 | G7: -2350.0489 | H7: 4648.2041 | I7: 2028 | J7: 0.27918124
A8: token 量成長高（4.0/1.5/0.9/0.6） | B8: I09@2027=4.0 I09@2028=1.5 I09@2029=0.9 I09@2030=0.6 | C8: 465.49 | D8: 4988.2229 | E8: 0.71935493 | F8: 0.98261108 | G8: 121.14151 | H8: 0 | I8: 9999 | J8: 2.6265086
A9: API 單價每年 −50% | B9: I08=-0.5 | C9: 465.49 | D9: 592.28062 | E9: 0.095993847 | F9: 0.16671697 | G9: -2758.6769 | H9: 5510.9327 | I9: 2028 | J9: 0.19590124
A10: API 單價持平 | B10: I08=0 | C10: 465.49 | D10: 5303.4206 | E10: 0.85462546 | F10: 1.179891 | G10: 1052.1151 | H10: 0 | I10: 9999 | J10: 2.9245197
A11: 2H26 企業端年化 350 | B11: I10=350 | C11: 340.49 | D11: 1387.1437 | E11: 0.67038533 | F11: 0.38599979 | G11: -2004.8409 | H11: 3978.645 | I11: 2028 | J11: 0.50379354
A12: 2H26 企業端年化 750 | B12: I10=750 | C12: 540.49 | D12: 2278.2157 | E12: 0.69691658 | F12: 0.5752248 | G12: -1480.6962 | H12: 2677.3103 | I12: 2029 | J12: 0.91583683
A13: 訓練 MW 2027 起不再成長 | B13: I17=0 | C13: 465.49 | D13: 1944.0637 | E13: 0.68981753 | F13: 1.0207075 | G13: 281.22107 | H13: 0 | I13: 9999 | J13: 1.1257197
A14: 訓練 MW 成長 ×0.5 | B14: I17=*0.5 | C14: 465.49 | D14: 1944.0637 | E14: 0.68981753 | F14: 0.7439838 | G14: -463.66271 | H14: 341.48439 | I14: 2030 | J14: 0.98252593
A15: 訓練 MW 成長 ×1.5 | B15: I17=*1.5 | C15: 465.49 | D15: 1944.0637 | E15: 0.68981753 | F15: 0.33987198 | G15: -3574.2705 | H15: 7107.1634 | I15: 2028 | J15: 0.56487487
... A28: 可轉債全數轉股 | B28: I23=1 | C28: 465.49 | D28: 1944.0637 | E28: 0.68981753 | F28: 0.50852208 | G28: -1677.2504 | H28: 2282.4773 | I28: 2029 | J28: 0.81058723
