Workbook

Sheet README
A1: Credo（CRDO）收支與估值模型 v0.2.3（AI 半導體 Project：網通次產業內複製——主動電纜 AEC、SerDes、光 DSP） 2026-10-26
A2: 版本：v0.2（2026-10-25：三情境延伸到 FY2032、目標價＝DCF 與 Comparable 加權；v0.1 初版）。Credo 在 AI 銅纜（AEC）與光學的份額在本模型 Units 頁建立，為本專案權威資料（規則第 13 條）。
A3: 模型命題：Credo 的 AEC 營收＝AI 銅纜市場（本專案網通模型：scale-up 背板與線纜＋scale-out DAC／AEC）× Credo 有效份額（AEC 滲透率 × Credo 占 AEC）；光學（光 DSP、矽光 PIC、ZeroFlap 光學）＝可插拔光模組市場 × 光學份額；線卡 PHY、重定時器與 SerDes IP 另依成長率推。股價自 52 週高點跌約 52%、只約 15 倍共識 FY2028 EPS：市場定價像是 AEC 成長在 FY2028 前後見頂。
A4: 核心問題：市場隱含的 FY2028 EPS 是否低於模型——要成立，AEC 份額（競爭、主動光纜自我替代）、客戶集中（前四大終端客戶占 84%）、銅轉光（AI 銅纜市場）三條路徑各要不利到什麼程度？
A6: 會計年度：FY(t) 於 t 年 4 月底／5 月初結束（FY2027＝2026-05-03～2027-05-01），8 個月落在日曆年 t−1；上游市場層為日曆年，FY(t) 市場＝8/12 × CY(t−1)＋4/12 × CY(t)。預測期 FY2028–FY2029（FY2027 為錨點）。口徑：公司 non-GAAP；十年 P/E 規則值用 GAAP 換算 EPS。
A8: 驅動因子 → 推導量（全部唯讀上游，不修改）
A9: AEC：markets/network 的 AI 銅纜市場（FY 加權）× 情境顆數係數 × Credo AEC 有效份額（FY2027 錨點校準）× 份額相對值（Assumed）。光學：可插拔光模組市場 × 光學有效份額（FY2027 以公司目標逾 6 億美元校準）× 相對值（Assumed）。
A10: 其他 IC 與 IP：FY2026 營收 × 7%（Assumed）× 成長率。毛利率：FY2028 起為輸入路徑（Assumed）。營業費用：彈性 phi（FY2027 錨點 Derived）。稅率：FY2028 起 13–14%（Assumed，OECD 最低稅）。
A11: 校準：FY2027 ＝ 1Q27 實績（營收 4.79 億美元、non-GAAP EPS 1.20）＋ 2Q27 指引中點（5.30 億美元）＋ 2H27（全年年增 85% 下緣減 1H）。產品線拆分公司未揭露：光學 FY2026 為假設、FY2027 用公司目標，AEC 為殘差。不用共識（只在 Recon 對帳）。
A12: 估值：目標價（Val 第 0 節）＝0.5 × DCF（股東現金流＝EPS ×（1 − g／ROE），FY2027–32 明確期＋永續，r 10%、g 4%，情境權重 0.3／0.5／0.2）＋0.5 × Comparable（美股高速連接晶片同業前瞻 P/E 中位數 × 12 個月後前瞻 EPS）。舊法規則值情境加權保留參考（不是目標價）；市場隱含 FY2028 EPS（Val 第 4 節）；十年 P/E 規則值（只有 2025 年一個正值）× 2027 年底近 12 月 GAAP 換算 EPS；循環位置以本模型營收最高年判定。Val 第 0 節為情境加權目標價。本版未做先驗，無 Andy 合理 P/E 對照。
A13: 標記：Verified、Interested-party、Analogy、Assumed、Derived。SemiAnalysis 未使用。客戶名稱（Amazon、xAI、Microsoft）只有券商與媒體來源；公司 10-K 只揭露未具名的客戶占比。
A15: 已知限制：(1) AEC 與光學份額相對值、毛利率路徑、FY2028 起稅率皆為 Assumed，是 FY2028–FY2029 EPS 最敏感的輸入（Sens）；(2) 產品線營收未揭露，AEC 為殘差；(3) 網通模型的銅纜市場以 NVIDIA 平台為主，Credo 客戶以 ASIC 與超大規模業者為主，份額校準吸收了這個口徑差；(4) 十年 P/E 只有 2025 年一個觀測值、含高成長期溢價，規則值與目標價明顯偏高；(5) 會計年度與日曆年以月數加權近似；(6) R4 產業部署路徑未建（Recon 預留列）。
... A17: v0.2.1（2026-10-25）：補上檔空間級距、投資建議、重點觀察（數值不變）。Val 頁末新增「上檔空間級距」「投資建議」兩列（Andy 2026-10-25 14:00、14:17 固定規則），README 頁末新增投資建議與重點觀察三點；既有儲存格位置與數值不變。
A18: ="投資建議："&Val!B130&"（依上檔空間固定規則）" -> 投資建議：買進（依上檔空間固定規則）
A19: 重點觀察 1：目標價 US$195（DCF 100、Comparable 289 各半），比現價 147.29（2026-10-23）高 32.1%，級距 25%–50%；Comparable 單獨為 +96.1%。上檔全部來自倍數：本模型 12 個月後前瞻 EPS 8.37 比共識 9.69 低 13.6%，但現價只隱含 15.2 倍共識前瞻 EPS，同業（Astera Labs、Marvell、Broadcom、MACOM）前瞻 P/E 中位數 34.5 倍、共識目標價 279.09 隱含 28.8 倍；DCF 100 反而比現價低 32.0%，因 B、C 情境 FY2029 起 EPS 下滑（FY2032 B 7.64、C 3.74），且 ROE 無同口徑資料、取 20%。
A20: 重點觀察 2：目標價對 DCF 權重最敏感：DCF 權重 0.3／0.7 時目標價 232.2／156.8（±19.4%），權重 0.7 時上檔空間只剩 +6.4%、落入中立。
A21: 重點觀察 3：FY2028 EPS 最敏感的是 AEC：最大客戶流失時 −24.7%、AEC 份額流失 −18.7%、AI 銅纜市場 ×0.8 時 −15.0%（Sens 頁）。光學的可插拔市場改讀同字母網通 CPO 情境（v0.2.2），情境 A FY2028 EPS 9.20 → 9.11（−0.9%）、C 7.81 → 7.84（+0.4%）。下一個檢驗點是 2Q FY27 財報（約 2026-12 初）的 AEC 營收與最大客戶占比。
A22: v0.2.3（2026-10-28）：分部原則重建（數值不變）。Q 頁最後追加核對列「檢查：分部合計 − 合併營收」；官方分部與子列宣告見 segments.json。
A23: v0.2.2（2026-10-26）：網通模型 v0.2.3 的 CPO 滲透改三情境（A＝替代快、B＝平平、C＝慢），本模型光學的可插拔市場 A／B／C 改讀同字母列（In 頁末新增 B、C；情境 A 沿用 mpl_，數值改為網通情境 A）。光學有效份額以 FY2027 錨點 ÷ 情境 B 市場校準（三情境同一份額；B 的 CPO 路徑＝v0.2.1，故情境 B 數值不變），所以 CPO 快 → 光學營收較少。銅纜（AEC）市場不受 CPO 影響。其他輸入不變。

Sheet In
A1: In — 輸入（藍字；基準欄 E，低 D、高 F）。金額：十億美元（US$B）；比例：%。每個輸入附兩個來源（找不到者寫「未找到」）；公司原文算一個
A2: 標記：Verified／Interested-party／Analogy／Assumed／Derived；Analogy、Assumed 給低／高區間。SemiAnalysis 未使用。公司原文＝SEC 8-K 新聞稿與 10-K；公司不揭露產品線營收（AEC、光學、IC、IP）與客戶名稱；客戶名稱只有券商與媒體來源
A3: 鍵 | B3: 項目 | C3: 單位 | D3: 低 | E3: 基準 | F3: 高 | G3: 標記 | H3: 來源1 | I3: 來源2／說明
A4: A. AI 銅纜與光模組市場（讀 markets/network 成品；日曆年 CY2026–CY2029；情境 A 基準，B／C 依顆數係數縮放）
A5: mcu_26 | B5: AI 銅纜市場 CY2026（scale-up 背板與線纜＋scale-out DAC／AEC） | C5: US$B | E5: 25.97546 | G5: Derived | H5: markets/network/dist/20261026_AI網通市場模型_v0.2.3.xlsx｜Mkt!C21:F21 | I5: 加速器顆數 × 每顆銅內容；scale-up 銅＝互連 × 銅占比、2029 年 scale-up 光學占 20%（網通模型）
A6: mcu_27 | B6: AI 銅纜市場 CY2027（scale-up 背板與線纜＋scale-out DAC／AEC） | C6: US$B | E6: 51.06612 | G6: Derived | H6: markets/network/dist/20261026_AI網通市場模型_v0.2.3.xlsx｜Mkt!C21:F21 | I6: 同上
A7: mcu_28 | B7: AI 銅纜市場 CY2028（scale-up 背板與線纜＋scale-out DAC／AEC） | C7: US$B | E7: 59.4676 | G7: Derived | H7: markets/network/dist/20261026_AI網通市場模型_v0.2.3.xlsx｜Mkt!C21:F21 | I7: 同上
A8: mcu_29 | B8: AI 銅纜市場 CY2029（scale-up 背板與線纜＋scale-out DAC／AEC） | C8: US$B | E8: 60.951534 | G8: Derived | H8: markets/network/dist/20261026_AI網通市場模型_v0.2.3.xlsx｜Mkt!C21:F21 | I8: 同上
A9: mso_26 | B9: 其中 scale-out 銅纜（DAC／AEC）CY2026 | C9: US$B | E9: 13.8758 | G9: Derived | H9: markets/network/dist/20261026_AI網通市場模型_v0.2.3.xlsx｜Mkt!C9:F9 | I9: Units、Recon 用（只作拆分參考）
A10: mso_27 | B10: 其中 scale-out 銅纜（DAC／AEC）CY2027 | C10: US$B | E10: 26.4567 | G10: Derived | H10: markets/network/dist/20261026_AI網通市場模型_v0.2.3.xlsx｜Mkt!C9:F9 | I10: 同上
A11: mso_28 | B11: 其中 scale-out 銅纜（DAC／AEC）CY2028 | C11: US$B | E11: 29.8375 | G11: Derived | H11: markets/network/dist/20261026_AI網通市場模型_v0.2.3.xlsx｜Mkt!C9:F9 | I11: 同上
A12: mso_29 | B12: 其中 scale-out 銅纜（DAC／AEC）CY2029 | C12: US$B | E12: 33.92475 | G12: Derived | H12: markets/network/dist/20261026_AI網通市場模型_v0.2.3.xlsx｜Mkt!C9:F9 | I12: 同上
A13: mpl_26 | B13: AI 可插拔光模組市場 CY2026 | C13: US$B | E13: 29.753262 | G13: Derived | H13: markets/network/dist/20261026_AI網通市場模型_v0.2.3.xlsx｜Mkt!C45:F45 | I13: 光 DSP、矽光 PIC、ZeroFlap 光學的市場基底
A14: mpl_27 | B14: AI 可插拔光模組市場 CY2027 | C14: US$B | E14: 53.560715 | G14: Derived | H14: markets/network/dist/20261026_AI網通市場模型_v0.2.3.xlsx｜Mkt!C45:F45 | I14: 同上
A15: mpl_28 | B15: AI 可插拔光模組市場 CY2028 | C15: US$B | E15: 57.9915 | G15: Derived | H15: markets/network/dist/20261026_AI網通市場模型_v0.2.3.xlsx｜Mkt!C45:F45 | I15: 同上
A16: mpl_29 | B16: AI 可插拔光模組市場 CY2029 | C16: US$B | E16: 72.9348 | G16: Derived | H16: markets/network/dist/20261026_AI網通市場模型_v0.2.3.xlsx｜Mkt!C45:F45 | I16: 同上
... A26: um29_C | B26: 情境 C：CY2029 顆數 ÷ 基準 | C26: x | E26: 0.6 | G26: Assumed | H26: tsmc/dist/20261028_台積電個股模型_v0.4.xlsx｜In!E42 | I26: 同上
A27: w8 | B27: FY(t) 落在日曆年 t−1 的比重（5–12 月） | C27: x | E27: =8/12 -> 0.66666667 | G27: Derived | H27: https://www.sec.gov/Archives/edgar/data/0001807794/000162828026043303/crdo-20260502.htm：FY2026 截至 2026-05-02、FY2025 截至 2025-05-03（52／53 週） | I27: FY(t) 市場＝w8 × CY(t−1)＋（1 − w8）× CY(t)
A28: B. AEC 份額（本專案為權威：Credo 在 AI 銅纜的份額，規則第 13 條）與客戶集中
A29: rel_a_28 | B29: AEC 有效份額 FY2028 ÷ FY2027（相對值；＝AEC 滲透率變化 × Credo 份額變化） | C29: x | D29: 0.75 | E29: 1 | F29: 1.15 | G29: Assumed | H29: https://invezz.com/en-ae/news/2026/04/13/credo-jumps-11percent-as-jefferies-backs-copper-tech-in-ai-boom-debate/：Jefferies（2026-04）AEC 2026 年 860 萬條、2027 年 1,230 萬條；Credo 份額樂觀情境約 70%（Interested-party） | I29: 1.6T 使被動 DAC 距離更短（AEC 滲透率上推）vs Astera Labs、Marvell、Broadcom 與線纜廠競爭（10-K 列名競爭者）
A30: rel_a_29 | B30: AEC 有效份額 FY2029 ÷ FY2027 | C30: x | D30: 0.6 | E30: 0.95 | F30: 1.2 | G30: Assumed | H30: 同上；ZeroFlap 主動光纜（ALC，2027 年出貨）可能部分自我替代 AEC | I30: https://www.tikr.com/blog/credo-stock-fell-22-last-week-as-it-launched-a-new-optical-cable-heres-where-it-could-go-by-2031：ALC 50 公尺、每端約 12 瓦（公司在 OCP 2026-10 發表）
A31: cr_aec_sh | B31: Credo 占 AEC 市場（Units 拆分用；不進損益） | C31: % | D31: 0.6 | E31: 0.75 | F31: 0.9 | G31: Assumed | H31: Invezz 轉述 Jefferies（網址見 Sources）：樂觀情境 2027 年約 70% | I31: 第一手 AEC 市場份額：未找到
A32: cust_top | B32: 最大終端客戶占營收（Sens「最大客戶流失」用） | C32: % | E32: 0.33 | G32: Interested-party | H32: https://www.yourwyominglink.com/credo-q1-earnings-call-highlights-optics-as-the-next-growth-engine/article_d01cfee6-9667-5ab6-8b08-fcf8fffa13d0.html：1Q27 前四大終端客戶 33%、28%、13%、10%（Zacks 轉述法說） | I32: https://www.sec.gov/Archives/edgar/data/0001807794/000162828026043303/crdo-20260502.htm：FY2026 終端客戶 D 33%（FY2025 63%）、B 32%、E 19%（公司，未具名）
A33: cl_28 | B33: 最大客戶流失情境：AEC 有效份額 FY2028 ÷ FY2027（Sens 用） | C33: x | E33: =rel_a_28*(1-cust_top) -> 0.67 | G33: Derived | H33: AEC 份額相對值 ×（1 − 最大客戶占比）；假設流失的客戶全是 AEC | I33: 客戶名稱：Amazon、xAI、Microsoft（Needham 等券商，Benzinga 2025-03；Interested-party）；公司未具名
A34: cl_29 | B34: 最大客戶流失情境：AEC 有效份額 FY2029 ÷ FY2027（Sens 用） | C34: x | E34: =rel_a_29*(1-cust_top) -> 0.6365 | G34: Derived | H34: 同上 | I34: https://www.benzinga.com/25/03/44149586/credo-expands-hyperscaler-partnerships-with-amazon-microsoft-xai-amid-nvidia-powered-ai-boom：Amazon 曾占單季營收 86%（FY2025 Q3）
A35: C. 光學（光 DSP、矽光 PIC〔DustPhotonics〕、ZeroFlap 光學；讀可插拔光模組市場）
A36: opt_26 | B36: FY2026 光學營收（未揭露） | C36: US$B | D36: 0.08 | E36: 0.15 | F36: 0.25 | G36: Assumed | H36: 公司不揭露產品線營收：未找到 | I36: Let's Data Science（網址見 Sources）：FY2027 光學三條產品線各逾 1 億美元、合計逾 6 億美元（公司法說，Interested-party）
A37: opt_27 | B37: FY2027 光學營收（公司目標「逾 6 億美元」） | C37: US$B | D37: 0.5 | E37: 0.6 | F37: 0.7 | G37: Interested-party | H37: https://www.itiger.com/news/1122940235：FY2027 光學逾 6 億美元（1Q27 法說重申） | I37: https://finance.yahoo.com/markets/stocks/articles/credo-makes-875-million-move-013700129.html：2026-04 宣布併購時為「逾 5 億美元」
A38: rel_o_28 | B38: 光學有效份額 FY2028 ÷ FY2027 | C38: x | D38: 0.9 | E38: 1.2 | F38: 1.6 | G38: Assumed | H38: https://www.yourwyominglink.com/credo-q1-earnings-call-highlights-optics-as-the-next-growth-engine/article_d01cfee6-9667-5ab6-8b08-fcf8fffa13d0.html：兩個次世代大型設計案預計 FY2028 量產；1.6T DSP 於 FY2027 後段開始貢獻（公司） | I38: DSP 競爭：Marvell、Broadcom 為主要供應商（10-K 列名競爭者）
A39: rel_o_29 | B39: 光學有效份額 FY2029 ÷ FY2027 | C39: x | D39: 0.9 | E39: 1.35 | F39: 2 | G39: Assumed | H39: 同上 | I39: —
A40: D. 其他營收（線卡 PHY、PCIe 重定時器、SerDes IP 授權與小晶片；網通模型未涵蓋）
A41: oth_s | B41: 其他 IC 與 IP ÷ 總營收（FY2026） | C41: % | D41: 0.04 | E41: 0.07 | F41: 0.1 | G41: Assumed | H41: 公司不揭露產品與 IP 授權拆分：未找到 | I41: 公司 FY2026 10-K（網址見 Sources）：未滿足履約義務約 3,190 萬美元，預計下一會計年度認列（IP 授權）
A42: g_oth | B42: 其他 IC 與 IP 年增（FY2027 起） | C42: % | D42: 0 | E42: 0.15 | F42: 0.3 | G42: Assumed | H42: 無 | I42: —
A43: E. FY2027 錨點（1Q27 實績＋2Q27 指引＋2H27 依全年指引推導）
A44: q1_rev | B44: 1Q27 營收（截至 2026-08-01） | C44: US$B | E44: 0.479003 | G44: Verified | H44: https://www.sec.gov/Archives/edgar/data/0001807794/000162828026059795/credoq12027ex-991.htm：479,003 千美元（年增 114.7%） | I44: https://pulse2.com/credo-reports-q1-fiscal-2027-revenue-of-479-million-up-115-year-over-year/：同值
A45: q1_gp | B45: 1Q27 non-GAAP 毛利（＝營業利益＋營業費用） | C45: US$B | E45: =0.230641+0.095154 -> 0.325795 | G45: Verified | H45: https://www.sec.gov/Archives/edgar/data/0001807794/000162828026059795/credoq12027ex-991.htm：non-GAAP 營業利益 230,641、營業費用 95,154 千美元；毛利率 68.0% | I45: GAAP 毛利率 64.5%（併購攤銷）
A46: q1_opx | B46: 1Q27 non-GAAP 營業費用 | C46: US$B | E46: 0.095154 | G46: Verified | H46: https://www.sec.gov/Archives/edgar/data/0001807794/000162828026059795/credoq12027ex-991.htm | I46: GAAP 188.4（含股票薪酬 82.3）
A47: q1_ninc | B47: 1Q27 其他收益（淨） | C47: US$B | E47: 0.00814 | G47: Verified | H47: https://www.sec.gov/Archives/edgar/data/0001807794/000162828026059795/credoq12027ex-991.htm：8,140 千美元 | I47: 現金與短期投資 7.64 億美元（DustPhotonics 現金對價後）
A48: q1_ni | B48: 1Q27 non-GAAP 淨利 | C48: US$B | E48: 0.236262 | G48: Verified | H48: https://www.sec.gov/Archives/edgar/data/0001807794/000162828026059795/credoq12027ex-991.htm：236,262 千美元 | I48: https://www.itiger.com/news/1122940235：同值（淨利率 49.3%）
A49: q1_sh | B49: 1Q27 non-GAAP 稀釋股數 | C49: 十億股 | E49: 0.197505 | G49: Verified | H49: https://www.sec.gov/Archives/edgar/data/0001807794/000162828026059795/credoq12027ex-991.htm：197,505 千股 | I49: GAAP 稀釋 194,378 千股
...

Sheet Q
A1: Q — 實績與 FY2027 錨點（十億美元；EPS 為美元；股數為十億股；non-GAAP）。藍字＝輸入；黑字＝公式。FY2027＝2026-05-03～2027-05-01
A2: FY2027 錨點＝1Q27 實績＋2Q27 指引中點＋2H27（全年營收＝FY2026 ×（1＋85%）減 1H；毛利率 gm_h2；營業費用＝FY2026 ×（1＋50%）減 1H）。產品線拆分（光學、其他 IC 與 IP）為假設，AEC 為殘差。2Q27 財報（約 2026-12 初）公布後以實績取代 2Q
A3: 項目 | B3: FY2025A | C3: FY2026A | D3: 1Q27（實績） | E3: 2Q27（指引） | F3: 2H27（推導） | G3: FY2027 錨點 | H3: 標記 | I3: 說明
A4: 營收 | B4: =a25_rev_in -> 0.436775 | C4: =a26_rev_in -> 1.335116 | D4: =q1_rev -> 0.479003 | E4: =q2_rev -> 0.53 | F4: =G4-D4-E4 -> 1.4609616 | G4: =C4*(1+g27) -> 2.4699646 | H4: Verified／Interested-party（指引） | I4: 2H27＝全年指引 − 1Q27 − 2Q27
A5: 毛利（non-GAAP） | B5: =a25_gp_in -> 0.284103 | C5: =a26_gp_in -> 0.909767 | D5: =q1_gp -> 0.325795 | E5: =E4*q2_gm -> 0.3604 | F5: =F4*gm_h2 -> 0.99345389 | G5: =D5+E5+F5 -> 1.6796489 | H5: Verified／Derived
A6: 毛利率 | B6: =B5/B4 -> 0.65045618 | C6: =C5/C4 -> 0.6814142 | D6: =D5/D4 -> 0.68015232 | E6: =E5/E4 -> 0.68 | F6: =F5/F4 -> 0.68 | G6: =G5/G4 -> 0.68002954 | H6: Derived
A7: 營業費用（non-GAAP） | B7: =a25_opx_in -> 0.168751 | C7: =a26_opx_in -> 0.270945 | D7: =q1_opx -> 0.095154 | E7: =q2_opx -> 0.1025 | F7: =G7-D7-E7 -> 0.2087635 | G7: =C7*(1+g_opx27) -> 0.4064175 | H7: Verified／Interested-party（指引） | I7: 2H27＝全年（年增約 50%）− 1H
A8: 營業費用率 | B8: =B7/B4 -> 0.38635682 | C8: =C7/C4 -> 0.20293742 | D8: =D7/D4 -> 0.19865011 | E8: =E7/E4 -> 0.19339623 | F8: =F7/F4 -> 0.14289458 | G8: =G7/G4 -> 0.16454386 | H8: Derived
A9: 營業利益（non-GAAP） | B9: =B5-B7 -> 0.115352 | C9: =C5-C7 -> 0.638822 | D9: =D5-D7 -> 0.230641 | E9: =E5-E7 -> 0.2579 | F9: =F5-F7 -> 0.78469039 | G9: =G5-G7 -> 1.2732314 | H9: Derived
A10: 其他收益（淨） | B10: =a25_ninc_in -> 0.017746 | C10: =a26_ninc_in -> 0.03043 | D10: =q1_ninc -> 0.00814 | E10: =q_oth -> 0.007 | F10: =2*q_oth -> 0.014 | G10: =D10+E10+F10 -> 0.02914 | H10: Verified／Assumed
A11: 稅前利益 | B11: =B9+B10 -> 0.133098 | C11: =C9+C10 -> 0.669252 | D11: =D9+D10 -> 0.238781 | E11: =E9+E10 -> 0.2649 | F11: =F9+F10 -> 0.79869039 | G11: =G9+G10 -> 1.3023714 | H11: Derived
A12: 所得稅（non-GAAP） | B12: =B11-a25_ni_in -> 0.003172 | C12: =C11-a26_ni_in -> 0.007709 | D12: =D11-q1_ni -> 0.002519 | E12: =E11*tx27 -> 0.0039735 | F12: =F11*tx27 -> 0.011980356 | G12: =D12+E12+F12 -> 0.018472856 | H12: Derived | I12: 實績＝稅前 − 淨利（推導）
A13: 有效稅率 | B13: =B12/B11 -> 0.023832064 | C13: =C12/C11 -> 0.01151883 | D13: =D12/D11 -> 0.010549416 | E13: =E12/E11 -> 0.015 | F13: =F12/F11 -> 0.015 | G13: =G12/G11 -> 0.014184015 | H13: Derived
A14: 淨利（non-GAAP） | B14: =a25_ni_in -> 0.129926 | C14: =a26_ni_in -> 0.661543 | D14: =q1_ni -> 0.236262 | E14: =E11-E12 -> 0.2609265 | F14: =F11-F12 -> 0.78671003 | G14: =D14+E14+F14 -> 1.2838985 | H14: Verified／Derived
A15: 淨利率 | B15: =B14/B4 -> 0.29746666 | C15: =C14/C4 -> 0.49549477 | D15: =D14/D4 -> 0.49323699 | E15: =E14/E4 -> 0.49231415 | F15: =F14/F4 -> 0.53848782 | G15: =G14/G4 -> 0.51980443 | H15: Derived | I15: 公司 FY2027 non-GAAP 淨利率目標約 50%
A16: 稀釋股數（non-GAAP） | B16: =a25_sh_in -> 0.184644 | C16: =a26_sh_in -> 0.191256 | D16: =q1_sh -> 0.197505 | G16: =sh_27 -> 0.199 | H16: Verified／Assumed
A17: EPS（non-GAAP） | B17: =B14/B16 -> 0.70365677 | C17: =C14/C16 -> 3.4589399 | D17: =D14/D16 -> 1.196233 | G17: =G14/G16 -> 6.4517514 | H17: Derived | I17: 公司揭露：FY2025 0.70、FY2026 3.46、1Q27 1.20
A18: 光學營收（光 DSP、矽光 PIC、ZeroFlap 光學） | C18: =opt_26 -> 0.15 | G18: =opt_27 -> 0.6 | H18: Assumed／Interested-party
A19: 其他 IC 與 IP（＝FY2026 營收 × oth_s × 成長） | C19: =C4*oth_s -> 0.09345812 | G19: =C19*(1+g_oth) -> 0.10747684 | H19: Assumed
A20: AEC（＝營收 − 光學 − 其他；殘差） | C20: =C4-C18-C19 -> 1.0916579 | G20: =G4-G18-G19 -> 1.7624878 | H20: Derived
A21: AEC ÷ 營收 | C21: =C20/C4 -> 0.81765021 | G21: =G20/G4 -> 0.71356803 | H21: Derived | I21: 公司：AEC 仍是最大業務；1Q27 營收年增額逾九成來自 AEC
A23: FY2027 錨點的檢查（參考；校準未使用共識）
A24: FY2027 營收 ÷ 共識 − 1 | B24: =G4/cons_rev27-1 -> -0.01201416
A25: FY2027 EPS ÷ 共識 − 1 | B25: =G17/cons_eps27-1 -> 0.022464567
A26: FY2027 營收年增 | B26: =G4/C4-1 -> 0.85
A27: FY2027 營業費用年增 | B27: =G7/C7-1 -> 0.5
A28: 營業費用彈性（營業費用年增 ÷ 營收年增；In 頁 phi 的依據） | B28: =B27/B26 -> 0.58823529
A29: 1Q27 EPS（模型）vs 公司揭露 1.20 | B29: =D17/q1_eps-1 -> -0.003139161
A30: FY2027 AEC 年增 | B30: =G20/C20-1 -> 0.6145056
A31: 2H27 每季平均營收 ÷ 2Q27 − 1 | B31: =F4/2/E4-1 -> 0.37826566
A33: 檢查：分部合計 − 合併營收 | C33: =ROUND(C18+C19+C20-C4,6) -> 0
A34: 分部原則第 3 條（2026-10-28 追加）；分部宣告見 segments.json

Sheet Units
A1: Units — Credo 在 AI 銅纜（AEC）與光學的份額（本專案權威，規則第 13 條）。市場取自 markets/network（加速器顆數 × 每顆內容；日曆年 → 會計年度月數加權）
A3: 項目 | B3: 單位 | C3: FY2027（錨點） | D3: FY2028 | E3: FY2029 | F3: 說明
A4: AI 銅纜市場（情境 A；FY 加權） | B4: US$B | C4: =PL!E63 -> 34.339013 | D4: =PL!F63 -> 53.866613 | E4: =PL!G63 -> 59.962245 | F4: markets/network Mkt 頁「銅」
A5: 其中 scale-out 銅纜（DAC／AEC） | B5: US$B | C5: =w8*mso_26+(1-w8)*mso_27 -> 18.069433 | D5: =w8*mso_27+(1-w8)*mso_28 -> 27.583633 | E5: =w8*mso_28+(1-w8)*mso_29 -> 31.199917 | F5: 其餘為 scale-up 背板與線纜
A6: Credo AEC 營收（情境 A） | B6: US$B | C6: =PL!E67 -> 1.7624878 | D6: =PL!F67 -> 2.7647634 | E6: =PL!G67 -> 2.923747 | F6: FY2027 為錨點殘差
A7: Credo AEC 有效份額（÷ 銅纜市場） | B7: % | C7: =PL!E66 -> 0.051326104 | D7: =PL!F66 -> 0.051326104 | E7: =PL!G66 -> 0.048759799 | F7: FY2027 校準
A8: Credo AEC ÷ scale-out 銅纜 | B8: % | C8: =PL!E67/C5 -> 0.097539736 | D8: =PL!F67/D5 -> 0.10023202 | E8: =PL!G67/E5 -> 0.093710089 | F8: 若 AEC 全在 scale-out
A9: 隱含 AEC 滲透率（＝有效份額 ÷ Credo 占 AEC） | B9: % | C9: =PL!E66/cr_aec_sh -> 0.068434805 | D9: =PL!F66/cr_aec_sh -> 0.068434805 | E9: =PL!G66/cr_aec_sh -> 0.065013065 | F9: Credo 占 AEC 75%（Assumed）
A10: AI 可插拔光模組市場（情境 A；FY 加權） | B10: US$B | C10: =PL!E69 -> 37.68908 | D10: =PL!F69 -> 55.037643 | E10: =PL!G69 -> 62.9726 | F10: markets/network Mkt 頁「其中可插拔」
A11: Credo 光學營收（情境 A） | B11: US$B | C11: =PL!E72 -> 0.6 | D11: =PL!F72 -> 1.0410393 | E11: =PL!G72 -> 1.3400205
A12: Credo 光學有效份額（÷ 可插拔市場） | B12: % | C12: =PL!E72/PL!E69 -> 0.015919731 | D12: =PL!F72/PL!F69 -> 0.018915041 | E12: =PL!G72/PL!G69 -> 0.021279422 | F12: 光 DSP 約占模組成本兩成（次級來源），換算 DSP 份額約為本列 5 倍
A13: Credo 營收 ÷ AI IT 資本支出（FY 加權） | B13: % | C13: =PL!E75/(w8*itc_26+(1-w8)*itc_27) -> 0.0023680623 | D13: =PL!F75/(w8*itc_27+(1-w8)*itc_28) -> 0.0023046503 | E13: =PL!G75/(w8*itc_28+(1-w8)*itc_29) -> 0.0021219924 | F13: markets/network 的 AI IT 資本支出
A15: 讀法：有效份額＝AEC 滲透率 × Credo 占 AEC；兩者都沒有第一手資料，只校準乘積（FY2027 錨點）。AEC 份額相對值、光學份額相對值是 Assumed，是最需要每季檢查的輸入。

Sheet PL
A1: PL — Credo 損益（US$B；non-GAAP）。FY2025A、FY2026A 實績、FY2027 錨點（1Q27 實績＋2Q27 指引＋2H27 依全年指引），FY2028 起為模型。FY(t) 截至 t 年 4 月底／5 月初。三情境各一個完整推導區塊（本頁下方），頂端為摘要。FY2027 三情境相同；FY2028 起光學可插拔市場讀同字母網通 CPO 情境，FY2028 只有 4/12 落在 CY2028，顆數情境 B、C 的差異主要在 FY2029
A2: 灰底＝FY2030–FY2032 收斂法，非驅動因子推導（上游市場層只到 2029）：營收年增由 FY2029 線性收斂到 fade_g（A＝tp_g＋2pt、B＝tp_g、C＝tp_g−2pt），淨利率由 FY2029 線性收斂到 fade_m（In 頁 K 節），FY2032 達到；股數依 sh_g
A3: 情境／項目 | B3: 單位 | C3: FY2025A | D3: FY2026A | E3: FY2027（錨點） | F3: FY2028 | G3: FY2029 | H3: FY2030（收斂） | I3: FY2031（收斂） | J3: FY2032（收斂） | K3: 說明
A4: 情境 A
A5: 營收 | B5: US$B | C5: =C75 -> 0.436775 | D5: =D75 -> 1.335116 | E5: =E75 -> 2.4699646 | F5: =F75 -> 3.9294011 | G5: =G75 -> 4.4059056 | H5: =H75 -> 4.8502161 | I5: =I75 -> 5.2402809 | J5: =J75 -> 5.5546978
A6: 營收年增 | B6: % | D6: =D76 -> 2.0567592 | E6: =E76 -> 0.85 | F6: =F76 -> 0.59087343 | G6: =G76 -> 0.12126646 | H6: =H76 -> 0.1008443 | I6: =I76 -> 0.080422152 | J6: =J76 -> 0.06
A7: AEC 營收 | B7: US$B | D7: =D67 -> 1.0916579 | E7: =E67 -> 1.7624878 | F7: =F67 -> 2.7647634 | G7: =G67 -> 2.923747
A8: 光學營收 | B8: US$B | D8: =D72 -> 0.15 | E8: =E72 -> 0.6 | F8: =F72 -> 1.0410393 | G8: =G72 -> 1.3400205
A9: 其他 IC 與 IP | B9: US$B | D9: =D74 -> 0.09345812 | E9: =E74 -> 0.10747684 | F9: =F74 -> 0.12359836 | G9: =G74 -> 0.14213812
A10: 毛利率 | B10: % | C10: =C80 -> 0.65045618 | D10: =D80 -> 0.6814142 | E10: =E80 -> 0.68002954 | F10: =F80 -> 0.67 | G10: =G80 -> 0.66
A11: 營業利益率 | B11: % | C11: =C85 -> 0.26409936 | D11: =D85 -> 0.47847678 | E11: =E85 -> 0.51548568 | F11: =F85 -> 0.53062072 | G11: =G85 -> 0.52682768
A12: 淨利率 | B12: % | C12: =C89 -> 0.29746666 | D12: =D89 -> 0.49549477 | E12: =E89 -> 0.51980443 | F12: =F89 -> 0.46828226 | G12: =G89 -> 0.45892758 | H12: =H89 -> 0.45892758 | I12: =I89 -> 0.45892758 | J12: =J89 -> 0.45892758
A13: 淨利 | B13: US$B | C13: =C88 -> 0.129926 | D13: =D88 -> 0.661543 | E13: =E88 -> 1.2838985 | F13: =F88 -> 1.8400688 | G13: =G88 -> 2.0219916 | H13: =H88 -> 2.225898 | I13: =I88 -> 2.4049095 | J13: =J88 -> 2.549204
A14: EPS（non-GAAP） | B14: US$ | C14: =C91 -> 0.70365677 | D14: =D91 -> 3.4589399 | E14: =E91 -> 6.4517514 | F14: =F91 -> 9.109928 | G14: =G91 -> 9.8626629 | H14: =H91 -> 10.696804 | I14: =I91 -> 11.38627 | J14: =J91 -> 11.89108
A15: EPS 年增 | B15: % | D15: =D92 -> 3.9156635 | E15: =E92 -> 0.86523955 | F15: =F92 -> 0.41200852 | G15: =G92 -> 0.082627974 | H15: =H92 -> 0.084575669 | I15: =I92 -> 0.064455322 | J15: =J92 -> 0.044334975
A17: 情境 B
A18: 營收 | B18: US$B | C18: =C110 -> 0.436775 | D18: =D110 -> 1.335116 | E18: =E110 -> 2.4699646 | F18: =F110 -> 3.6832605 | G18: =G110 -> 3.7005291 | H18: =H110 -> 3.761436 | I18: =I110 -> 3.8676193 | J18: =J110 -> 4.0223241
A19: 營收年增 | B19: % | D19: =D111 -> 2.0567592 | E19: =E111 -> 0.85 | F19: =F111 -> 0.49121994 | G19: =G111 -> 0.004688423 | H19: =H111 -> 0.016458949 | I19: =I111 -> 0.028229474 | J19: =J111 -> 0.04
A20: AEC 營收 | B20: US$B | D20: =D102 -> 1.0916579 | E20: =E102 -> 1.7624878 | F20: =F102 -> 2.5612807 | G20: =G102 -> 2.3885307
A21: 光學營收 | B21: US$B | D21: =D107 -> 0.15 | E21: =E107 -> 0.6 | F21: =F107 -> 0.9983814 | G21: =G107 -> 1.1698604
A22: 其他 IC 與 IP | B22: US$B | D22: =D109 -> 0.09345812 | E22: =E109 -> 0.10747684 | F22: =F109 -> 0.12359836 | G22: =G109 -> 0.14213812
A23: 毛利率 | B23: % | C23: =C115 -> 0.65045618 | D23: =D115 -> 0.6814142 | E23: =E115 -> 0.68002954 | F23: =F115 -> 0.67 | G23: =G115 -> 0.66
A24: 營業利益率 | B24: % | C24: =C120 -> 0.26409936 | D24: =D120 -> 0.47847678 | E24: =E120 -> 0.51548568 | F24: =F120 -> 0.52777465 | G24: =G120 -> 0.51804794
A25: 淨利率 | B25: % | C25: =C124 -> 0.29746666 | D25: =D124 -> 0.49549477 | E25: =E124 -> 0.51980443 | F25: =F124 -> 0.46625006 | G25: =G124 -> 0.4524932 | H25: =H124 -> 0.43741009 | I25: =I124 -> 0.42232699 | J25: =J124 -> 0.40724388
A26: 淨利 | B26: US$B | C26: =C123 -> 0.129926 | D26: =D123 -> 0.661543 | E26: =E123 -> 1.2838985 | F26: =F123 -> 1.7173204 | G26: =G123 -> 1.6744643 | H26: =H123 -> 1.6452901 | I26: =I123 -> 1.6334 | J26: =J123 -> 1.6380669
A27: EPS（non-GAAP） | B27: US$ | C27: =C126 -> 0.70365677 | D27: =D126 -> 3.4589399 | E27: =E126 -> 6.4517514 | F27: =F126 -> 8.5022175 | G27: =G126 -> 8.1675298 | H27: =H126 -> 7.9066274 | I27: =I126 -> 7.7334861 | J27: =J126 -> 7.6409673
A28: EPS 年增 | B28: % | D28: =D127 -> 3.9156635 | E28: =E127 -> 0.86523955 | F28: =F127 -> 0.31781542 | G28: =G127 -> -0.039364755 | H28: =H127 -> -0.031943858 | I28: =I127 -> -0.021898241 | J28: =J127 -> -0.011963406
A30: 情境 C
A31: 營收 | B31: US$B | C31: =C145 -> 0.436775 | D31: =D145 -> 1.335116 | E31: =E145 -> 2.4699646 | F31: =F145 -> 3.4145724 | G31: =G145 -> 2.7731624 | H31: =H145 -> 2.4443672 | I31: =I145 -> 2.3239048 | J31: =J145 -> 2.3703828
A32: 營收年增 | B32: % | D32: =D146 -> 2.0567592 | E32: =E146 -> 0.85 | F32: =F146 -> 0.38243778 | G32: =G146 -> -0.1878449 | H32: =H146 -> -0.11856327 | I32: =I146 -> -0.049281634 | J32: =J146 -> 0.02
A33: AEC 營收 | B33: US$B | D33: =D137 -> 1.0916579 | E33: =E137 -> 1.7624878 | F33: =F137 -> 2.357798 | G33: =G137 -> 1.7542482
A34: 光學營收 | B34: US$B | D34: =D142 -> 0.15 | E34: =E142 -> 0.6 | F34: =F142 -> 0.93317598 | G34: =G142 -> 0.87677605
A35: 其他 IC 與 IP | B35: US$B | D35: =D144 -> 0.09345812 | E35: =E144 -> 0.10747684 | F35: =F144 -> 0.12359836 | G35: =G144 -> 0.14213812
A36: 毛利率 | B36: % | C36: =C150 -> 0.65045618 | D36: =D150 -> 0.6814142 | E36: =E150 -> 0.68002954 | F36: =F150 -> 0.67 | G36: =G150 -> 0.66
A37: 營業利益率 | B37: % | C37: =C155 -> 0.26409936 | D37: =D155 -> 0.47847678 | E37: =E155 -> 0.51548568 | F37: =F155 -> 0.52419944 | G37: =G155 -> 0.48047695
A38: 淨利率 | B38: % | C38: =C159 -> 0.29746666 | D38: =D159 -> 0.49549477 | E38: =E159 -> 0.51980443 | F38: =F159 -> 0.46369722 | G38: =G159 -> 0.42251364 | H38: =H159 -> 0.39434606 | I38: =I159 -> 0.36617848 | J38: =J159 -> 0.33801091
A39: 淨利 | B39: US$B | C39: =C158 -> 0.129926 | D39: =D158 -> 0.661543 | E39: =E158 -> 1.2838985 | F39: =F158 -> 1.5833277 | G39: =G158 -> 1.1716989 | H39: =H158 -> 0.96392656 | I39: =I158 -> 0.85096392 | J39: =J158 -> 0.80121526
A40: EPS（non-GAAP） | B40: US$ | C40: =C161 -> 0.70365677 | D40: =D161 -> 3.4589399 | E40: =E161 -> 6.4517514 | F40: =F161 -> 7.8388382 | G40: =G161 -> 5.7151925 | H40: =H161 -> 4.632258 | I40: =I161 -> 4.0289688 | J40: =J161 -> 3.7373685
A41: EPS 年增 | B41: % | D41: =D162 -> 3.9156635 | E41: =E162 -> 0.86523955 | F41: =F162 -> 0.21499383 | G41: =G162 -> -0.27091331 | H41: =H162 -> -0.18948347 | I41: =I162 -> -0.13023654 | J41: =J162 -> -0.0723759
A43: 核對（應為 0）：FY2027 模型營收、AEC 營收、淨利 − 錨點（校準恆等式）
...

Sheet Val
A1: Val — P/E 估值（美元）。目標價＝DCF 與 Comparable 加權（第 0 節）；舊法規則值情境加權保留參考；另列「現價 ÷ FY2027、FY2028 EPS（模型，non-GAAP）」、市場隱含 EPS 與十年 P/E 規則值。Credo 2022-01 上市，年底 P/E 只有 2023–2025，且 2023、2024 為虧損（負值，不用）：規則值只有 2025 年一個觀測值
A2: 循環位置：Credo 不是設備股，不套設備市場見頂年；以本模型營收最高的會計年度為見頂年（比照 Arista、中際旭創）。營收到 FY2029 仍在增加時，見頂年未知，判為中段。規則值基準＝2027 年底的近 12 月 GAAP 換算 EPS（≈ ½ FY2027＋½ FY2028，× g2n），與年底 P/E 的計算口徑一致
A4: 0. 目標價
A5: 0.1 DCF（股東權益現金流，FY2027–FY2032 明確期＋FY2032 後永續）
A6: 項目 | B6: A（順利） | C6: B（平平） | D6: C（不如預期） | E6: 說明
A7: 情境 EPS（FY2027–FY2032） | E7: PL 頁各情境；FY2030 起為收斂法（PL 頁灰底）
A8: FY2027 | B8: =PL!E14 -> 6.4517514 | C8: =PL!E27 -> 6.4517514 | D8: =PL!E40 -> 6.4517514
A9: FY2028 | B9: =PL!F14 -> 9.109928 | C9: =PL!F27 -> 8.5022175 | D9: =PL!F40 -> 7.8388382
A10: FY2029 | B10: =PL!G14 -> 9.8626629 | C10: =PL!G27 -> 8.1675298 | D10: =PL!G40 -> 5.7151925
A11: FY2030 | B11: =PL!H14 -> 10.696804 | C11: =PL!H27 -> 7.9066274 | D11: =PL!H40 -> 4.632258
A12: FY2031 | B12: =PL!I14 -> 11.38627 | C12: =PL!I27 -> 7.7334861 | D12: =PL!I40 -> 4.0289688
A13: FY2032 | B13: =PL!J14 -> 11.89108 | C13: =PL!J27 -> 7.6409673 | D13: =PL!J40 -> 3.7373685
A14: 股東現金流＝EPS ×（1 − tp_g ÷ tp_roe）
A15: 再投資率（tp_g ÷ tp_roe，上限 0.8） | B15: =IF(tp_roe<=tp_g,0.8,MIN(tp_g/tp_roe,0.8)) -> 0.2 | E15: ROE＝In 頁 tp_roe；tp_roe ≤ tp_g 時取上限 0.8
A16: FY2027 | B16: =B8*(1-$B$15) -> 5.1614011 | C16: =C8*(1-$B$15) -> 5.1614011 | D16: =D8*(1-$B$15) -> 5.1614011
A17: FY2028 | B17: =B9*(1-$B$15) -> 7.2879424 | C17: =C9*(1-$B$15) -> 6.801774 | D17: =D9*(1-$B$15) -> 6.2710705
A18: FY2029 | B18: =B10*(1-$B$15) -> 7.8901303 | C18: =C10*(1-$B$15) -> 6.5340238 | D18: =D10*(1-$B$15) -> 4.572154
A19: FY2030 | B19: =B11*(1-$B$15) -> 8.5574434 | C19: =C11*(1-$B$15) -> 6.3253019 | D19: =D11*(1-$B$15) -> 3.7058064
A20: FY2031 | B20: =B12*(1-$B$15) -> 9.1090161 | C20: =C12*(1-$B$15) -> 6.1867889 | D20: =D12*(1-$B$15) -> 3.223175
A21: FY2032 | B21: =B13*(1-$B$15) -> 9.5128641 | C21: =C13*(1-$B$15) -> 6.1127738 | D21: =D13*(1-$B$15) -> 2.9898948
A22: DCF 情境每股價值（折現率 tp_r） | B22: =SUMPRODUCT(B16:B21,1/(1+tp_r)^{1;2;3;4;5;6})+B21*(1+tp_g)/(tp_r-tp_g)/(1+tp_r)^6 -> 126.58975 | C22: =SUMPRODUCT(C16:C21,1/(1+tp_r)^{1;2;3;4;5;6})+C21*(1+tp_g)/(tp_r-tp_g)/(1+tp_r)^6 -> 86.643562 | D22: =SUMPRODUCT(D16:D21,1/(1+tp_r)^{1;2;3;4;5;6})+D21*(1+tp_g)/(tp_r-tp_g)/(1+tp_r)^6 -> 48.783957 | E22: Σ 明確期現金流 ÷ (1＋r)^t ＋ 永續價值 ÷ (1＋r)^6；永續價值＝FY2032 現金流 ×(1＋g)÷(r−g)；基準日 2026 年底，t＝1 對 FY2027
A23: DCF 情境價值推到 12 個月後（×(1＋tp_r)） | B23: =B22*(1+tp_r) -> 139.24872 | C23: =C22*(1+tp_r) -> 95.307918 | D23: =D22*(1+tp_r) -> 53.662353
A24: DCF 目標價（情境加權） | B24: =tp_wA*B23+tp_wB*C23+tp_wC*D23 -> 100.16105 | E24: Σ 權重 × 情境價值 ×(1＋r)；權重見 In 頁
A26: 0.2 Comparable（市場主流同業前瞻 P/E）
A27: 同業與前瞻 P/E | B27: 代號 | C27: 前瞻 12 月 P/E | D27: 日期 | E27: 來源 | F27: 標記
A28: Astera Labs | B28: ALAB | C28: 45.77 | D28: 2026-10-23 | E28: stockanalysis forward PE（分析師共識；價格日期如左） | F28: Interested-party
A29: Marvell | B29: MRVL | C29: 40.44 | D29: 2026-10-23 | E29: stockanalysis forward PE（分析師共識；價格日期如左） | F29: Interested-party
A30: Broadcom | B30: AVGO | C30: 18.52 | D30: 2026-10-23 | E30: stockanalysis forward PE（分析師共識；價格日期如左） | F30: Interested-party
A31: MACOM | B31: MTSI | C31: 28.59 | D31: 2026-10-23 | E31: stockanalysis forward PE（分析師共識；價格日期如左） | F31: Interested-party
A33: 同業前瞻 P/E 中位數 | B33: =MEDIAN(C28:C31) -> 34.515 | E33: 美股高速連接晶片同業（Astera Labs、Marvell、Broadcom、MACOM；不放 A 股）
A34: 12 個月後的前瞻 EPS（情境加權） | B34: =tp_wA*(6/12*B9+6/12*B10)+tp_wB*(6/12*C9+6/12*C10)+tp_wC*(6/12*D9+6/12*D10) -> 8.3687285 | E34: 約 2027-10 時的未來 12 月（2027-11～2028-10）≈ 6／12 × FY2028＋6／12 × FY2029（會計年度 4 月底／5 月初結束）
A35: Comparable 目標價 | B35: =B33*B34 -> 288.84666 | E35: 同業中位數 × 前瞻 EPS
A37: 0.3 結論
A38: 項目 | B38: 數值 | E38: 說明
A39: 目標價（DCF 與 Comparable 加權） | B39: =tp_w_dcf*B24+(1-tp_w_dcf)*B35 -> 194.50386 | E39: tp_w_dcf × DCF＋（1 − tp_w_dcf）× Comparable；tp_w_dcf 見 In 頁
A40: Comparable 目標價（市場主流同業法） | B40: =B35 -> 288.84666
A41: 市場共識目標價 | B41: =cons_tp -> 279.09 | E41: In 頁 tp_street：20 家平均 279.09（2026-10-05）；10-23 為 284.05
A42: 上檔空間：加權目標價 | B42: =B39/px-1 -> 0.32055031 | E42: 現價＝In 頁 px
A43: 上檔空間：Comparable 目標價 | B43: =B40/px-1 -> 0.96107451
A44: 與市場共識目標價的差距：EPS 因素 | B44: =B34/cons_feps-1 -> -0.13635413 | E44: 本模型前瞻 EPS ÷ 共識前瞻 EPS − 1；共識前瞻 EPS＝In 頁 cons_feps
...

Sheet Recon
A1: Recon — 本模型 vs 共識、券商、研調。只作事後對照，不為對上數字而調參數。共識 FY2028 EPS 區間 8.69–11.31
A3: 項目 | B3: 對照值 | C3: 模型 A | D3: 差距 A | E3: 模型 B | F3: 差距 B | G3: 模型 C | H3: 差距 C | I3: 對照來源 | J3: 說明
A4: A. 共識與指引（校準未使用共識）
A5: 2Q27 營收（指引中點）vs 共識 | B5: =cons_q2 -> 0.53165 | C5: =Q!E4 -> 0.53 | D5: =C5/B5-1 -> -0.0031035456 | E5: =Q!E4 -> 0.53 | F5: =E5/B5-1 -> -0.0031035456 | G5: =Q!E4 -> 0.53 | H5: =G5/B5-1 -> -0.0031035456 | I5: Yahoo（17 家） | J5: 指引 5.25–5.35
A6: FY2027 營收 vs 共識 | B6: =cons_rev27 -> 2.5 | C6: =PL!E75 -> 2.4699646 | D6: =C6/B6-1 -> -0.01201416 | E6: =PL!E110 -> 2.4699646 | F6: =E6/B6-1 -> -0.01201416 | G6: =PL!E145 -> 2.4699646 | H6: =G6/B6-1 -> -0.01201416 | I6: Yahoo（19 家；2.47–2.58） | J6: 錨點＝公司「年增逾 85%」下緣
A7: FY2027 EPS vs 共識 | B7: =cons_eps27 -> 6.31 | C7: =PL!E91 -> 6.4517514 | D7: =C7/B7-1 -> 0.022464567 | E7: =PL!E126 -> 6.4517514 | F7: =E7/B7-1 -> 0.022464567 | G7: =PL!E161 -> 6.4517514 | H7: =G7/B7-1 -> 0.022464567 | I7: Yahoo（20 家；5.98–6.64）
A8: FY2027 淨利率 vs 公司目標約 50% | B8: 0.5 | C8: =PL!E89 -> 0.51980443 | D8: =C8-B8 -> 0.019804426 | E8: =PL!E124 -> 0.51980443 | F8: =E8-B8 -> 0.019804426 | G8: =PL!E159 -> 0.51980443 | H8: =G8-B8 -> 0.019804426 | I8: 公司 1Q27 法說
A9: FY2028 營收 vs 共識 | B9: =cons_rev28 -> 3.87 | C9: =PL!F75 -> 3.9294011 | D9: =C9/B9-1 -> 0.01534911 | E9: =PL!F110 -> 3.6832605 | F9: =E9/B9-1 -> -0.048253109 | G9: =PL!F145 -> 3.4145724 | H9: =G9/B9-1 -> -0.11768156 | I9: Yahoo（19 家；3.59–4.41）
A10: FY2028 EPS vs 共識 | B10: =cons_eps28 -> 9.69 | C10: =PL!F91 -> 9.109928 | D10: =C10/B10-1 -> -0.059862952 | E10: =PL!F126 -> 8.5022175 | F10: =E10/B10-1 -> -0.12257817 | G10: =PL!F161 -> 7.8388382 | H10: =G10/B10-1 -> -0.19103837 | I10: Yahoo（20 家；8.69–11.31） | J10: 模型 FY2028 稅率 13%（OECD 最低稅）；共識是否已含：未找到
A11: FY2028 AEC 營收 vs Jefferies 引述共識 | B11: =jef_aec -> 2.3 | C11: =PL!F67 -> 2.7647634 | D11: =C11/B11-1 -> 0.20207104 | E11: =PL!F102 -> 2.5612807 | F11: =E11/B11-1 -> 0.11360031 | G11: =PL!F137 -> 2.357798 | H11: =G11/B11-1 -> 0.025129576 | I11: Jefferies（Invezz 轉述，2026-04） | J11: 共識期間未明示
A12: B. 份額與市場（機制檢查）
A13: FY2027 隱含 AEC 單價（＝AEC 營收 ÷〔Jefferies 條數 × Credo 占 AEC〕；美元／條） | C13: =PL!E67*1000/((w8*jef_u26+(1-w8)*jef_u27)*cr_aec_sh) -> 238.98139 | E13: =PL!E102*1000/((w8*jef_u26+(1-w8)*jef_u27)*cr_aec_sh) -> 238.98139 | G13: =PL!E137*1000/((w8*jef_u26+(1-w8)*jef_u27)*cr_aec_sh) -> 238.98139 | I13: Jefferies 條數（FY 加權） | J13: 800G AEC 單價一般認知為數百美元（第一手：未找到）
A14: FY2027 Credo AEC ÷ scale-out 銅纜（網通模型） | C14: =Units!C8 -> 0.097539736 | E14: =Units!C8 -> 0.097539736 | G14: =Units!C8 -> 0.097539736 | I14: markets/network
A15: FY2028 AEC 有效份額（÷ 銅纜市場） | C15: =PL!F66 -> 0.051326104 | E15: =PL!F101 -> 0.051326104 | G15: =PL!F136 -> 0.051326104 | I15: —
A16: FY2028 Credo 營收 ÷ AI IT 資本支出 | C16: =PL!F75/(w8*itc_27+(1-w8)*itc_28) -> 0.0023046503 | E16: =PL!F110/(w8*itc_27+(1-w8)*itc_28) -> 0.0021602853 | G16: =PL!F145/(w8*itc_27+(1-w8)*itc_28) -> 0.0020026959 | I16: markets/network | J16: 每 1 美元 AI IT 資本支出分到的 Credo 營收
A17: C. 校準
A18: 1Q27 EPS（模型）vs 公司揭露 1.20 | B18: =q1_eps -> 1.2 | C18: =Q!D17 -> 1.196233 | D18: =C18/B18-1 -> -0.003139161 | E18: =Q!D17 -> 1.196233 | F18: =E18/B18-1 -> -0.003139161 | G18: =Q!D17 -> 1.196233 | H18: =G18/B18-1 -> -0.003139161 | I18: 公司 | J18: 淨利 ÷ 稀釋股數
A19: FY2026 EPS（模型）vs 公司揭露 3.46 | B19: =a26_eps_in -> 3.46 | C19: =PL!D91 -> 3.4589399 | D19: =C19/B19-1 -> -0.00030640166 | E19: =PL!D126 -> 3.4589399 | F19: =E19/B19-1 -> -0.00030640166 | G19: =PL!D161 -> 3.4589399 | H19: =G19/B19-1 -> -0.00030640166 | I19: 公司
A20: FY2027 營業費用彈性（Derived） | C20: =Q!B28 -> 0.58823529 | E20: =Q!B28 -> 0.58823529 | G20: =Q!B28 -> 0.58823529 | I20: Q 頁
A21: D. 預留
A22: R4 產業部署路徑（markets/deploy_path/，尚未建立）：上線後以 Credo 營收 ÷ 部署 GW 計算每 GW 營收 | J22: 預留列：本版無數值
A23: 2Q27 財報（約 2026-12 初）：公布後以實績取代 Q 頁 2Q 指引，並更新全年指引 | J23: 預留列：本版無數值

Sheet Sens
A1: Sens — 一次動一個輸入（情境 A；有效份額在每個案例內依 FY2027 錨點重算，FY2027 恆等於錨點）：對 FY2028、FY2029 的營收、AEC 營收、毛利率與 EPS 的影響。每個案例是一個完整推導區塊（本頁下方）
A3: 案例 | B3: 設定 | C3: FY2028 營收 | D3: FY2028 AEC 營收 | E3: FY2028 毛利率 | F3: FY2028 EPS | G3: FY2028 EPS 相對基準 | H3: FY2029 營收 | I3: FY2029 AEC 營收 | J3: FY2029 毛利率 | K3: FY2029 EPS | L3: FY2029 EPS 相對基準
A4: 基準（情境 A） | B4: PL 區塊 A | C4: =PL!F75 -> 3.9294011 | D4: =PL!F67 -> 2.7647634 | E4: =PL!F80 -> 0.67 | F4: =PL!F91 -> 9.109928 | G4: =F4/F$4-1 -> 0 | H4: =PL!G75 -> 4.4059056 | I4: =PL!G67 -> 2.923747 | J4: =PL!G80 -> 0.66 | K4: =PL!G91 -> 9.8626629 | L4: =K4/K$4-1 -> 0
A5: AEC 份額流失（低） | B5: AEC 有效份額相對值 FY2028 0.75、FY2029 0.60（Astera、Marvell、Broadcom 與線纜廠搶份額；或 ALC 自我替代） | C5: =F55 -> 3.2382102 | D5: =F47 -> 2.0735725 | E5: =F60 -> 0.67 | F5: =F71 -> 7.4034076 | G5: =F5/F$4-1 -> -0.18732535 | H5: =G55 -> 3.3287357 | I5: =G47 -> 1.846577 | J5: =G60 -> 0.66 | K5: =G71 -> 7.2917841 | L5: =K5/K$4-1 -> -0.26066782
A6: AEC 份額上升（高） | B6: FY2028 1.15、FY2029 1.20（1.6T 使 DAC 退場，AEC 滲透率上升） | C6: =F90 -> 4.3441156 | D6: =F82 -> 3.1794779 | E6: =F95 -> 0.67 | F6: =F106 -> 10.13384 | G6: =F6/F$4-1 -> 0.11239521 | H6: =G90 -> 5.1753127 | I6: =G82 -> 3.6931541 | J6: =G95 -> 0.66 | K6: =G106 -> 11.710799 | L6: =K6/K$4-1 -> 0.18738708
A7: 最大客戶流失 | B7: FY2028 起 AEC × (1 − 33%)（最大終端客戶轉用其他供應商或光學） | C7: =F125 -> 3.0170291 | D7: =F117 -> 1.8523915 | E7: =F130 -> 0.67 | F7: =F141 -> 6.857321 | G7: =F7/F$4-1 -> -0.24726946 | H7: =G125 -> 3.4410691 | I7: =G117 -> 1.9589105 | J7: =G130 -> 0.66 | K7: =G141 -> 7.5664429 | L7: =K7/K$4-1 -> -0.23281947
A8: 光學份額 低 | B8: 光學有效份額相對值 0.90（設計案延後） | C8: =F160 -> 3.6691412 | D8: =F152 -> 2.7647634 | E8: =F165 -> 0.67 | F8: =F176 -> 8.4673577 | G8: =F8/F$4-1 -> -0.070535167 | H8: =G160 -> 3.9592321 | I8: =G152 -> 2.923747 | J8: =G165 -> 0.66 | K8: =G176 -> 8.7936313 | L8: =K8/K$4-1 -> -0.10839179
A9: 光學份額 高 | B9: FY2028 1.60、FY2029 2.00 | C9: =F195 -> 4.2764142 | D9: =F187 -> 2.7647634 | E9: =F200 -> 0.67 | F9: =F211 -> 9.9666884 | G9: =F9/F$4-1 -> 0.09404689 | H9: =G195 -> 5.0511007 | I9: =G187 -> 2.923747 | J9: =G200 -> 0.66 | K9: =G211 -> 11.412098 | L9: =K9/K$4-1 -> 0.1571011
A10: 毛利率 低（價格戰） | B10: 毛利率 FY2028 63%、FY2029 60% | C10: =F230 -> 3.9294011 | D10: =F222 -> 2.7647634 | E10: =F235 -> 0.63 | F10: =F246 -> 8.4329314 | G10: =F10/F$4-1 -> -0.074314154 | H10: =G230 -> 4.4059056 | I10: =G222 -> 2.923747 | J10: =G235 -> 0.6 | K10: =G246 -> 8.7537441 | L10: =K10/K$4-1 -> -0.11243604
A11: 毛利率 高 | B11: 毛利率 69% | C11: =F265 -> 3.9294011 | D11: =F257 -> 2.7647634 | E11: =F270 -> 0.69 | F11: =F281 -> 9.4484263 | G11: =F11/F$4-1 -> 0.037157077 | H11: =G265 -> 4.4059056 | I11: =G257 -> 2.923747 | J11: =G270 -> 0.69 | K11: =G281 -> 10.417122 | L11: =K11/K$4-1 -> 0.05621802
A12: 稅率 17% | B12: FY2028 起 non-GAAP 稅率 17% | C12: =F300 -> 3.9294011 | D12: =F292 -> 2.7647634 | E12: =F305 -> 0.67 | F12: =F316 -> 8.6910807 | G12: =F12/F$4-1 -> -0.045977011 | H12: =G300 -> 4.4059056 | I12: =G292 -> 2.923747 | J12: =G305 -> 0.66 | K12: =G316 -> 9.5186165 | L12: =K12/K$4-1 -> -0.034883721
A13: 稅率 5% | B13: 全球最低稅延後或抵減 | C13: =F335 -> 3.9294011 | D13: =F327 -> 2.7647634 | E13: =F340 -> 0.67 | F13: =F351 -> 9.9476225 | G13: =F13/F$4-1 -> 0.091954023 | H13: =G335 -> 4.4059056 | I13: =G327 -> 2.923747 | J13: =G340 -> 0.66 | K13: =G351 -> 10.894802 | L13: =K13/K$4-1 -> 0.10465116
A14: AI 銅纜市場 ×0.8 | B14: FY2028 起銅纜市場 ×0.8（銅轉光提前） | C14: =F370 -> 3.3764484 | D14: =F362 -> 2.2118107 | E14: =F375 -> 0.67 | F14: =F386 -> 7.7447117 | G14: =F14/F$4-1 -> -0.14986028 | H14: =G370 -> 3.8211562 | I14: =G362 -> 2.3389976 | J14: =G375 -> 0.66 | K14: =G386 -> 8.4715281 | L14: =K14/K$4-1 -> -0.14105063
A15: AI 銅纜市場 ×1.2 | B15: ×1.2（scale-up 銅擴大） | C15: =F405 -> 4.4823537 | D15: =F397 -> 3.3177161 | E15: =F410 -> 0.67 | F15: =F421 -> 10.475144 | G15: =F15/F$4-1 -> 0.14986028 | H15: =G405 -> 4.990655 | I15: =G397 -> 3.5084964 | J15: =G410 -> 0.66 | K15: =G421 -> 11.252734 | L15: =K15/K$4-1 -> 0.14094276
A16: 營業費用彈性 0.9 | B16: 營業費用隨營收成長較多 | C16: =F440 -> 3.9294011 | D16: =F432 -> 2.7647634 | E16: =F445 -> 0.67 | F16: =F456 -> 8.7874546 | G16: =F16/F$4-1 -> -0.035398022 | H16: =G440 -> 4.4059056 | I16: =G432 -> 2.923747 | J16: =G445 -> 0.66 | K16: =G456 -> 9.4274737 | L16: =K16/K$4-1 -> -0.044124914
A17: 營業費用率 +2pt | B17: 營業費用額外 +2% × 營收 | C17: =F475 -> 3.9294011 | D17: =F467 -> 2.7647634 | E17: =F480 -> 0.67 | F17: =F491 -> 8.7714297 | G17: =F17/F$4-1 -> -0.037157077 | H17: =G475 -> 4.4059056 | I17: =G467 -> 2.923747 | J17: =G480 -> 0.66 | K17: =G491 -> 9.4930233 | L17: =K17/K$4-1 -> -0.03747868
A18: 顆數情境 B | B18: CY2028 ×0.8、CY2029 ×0.85；CPO 情境 B | C18: =PL!F110 -> 3.6832605 | D18: =PL!F102 -> 2.5612807 | E18: =PL!F115 -> 0.67 | F18: =PL!F126 -> 8.5022175 | G18: =F18/F$4-1 -> -0.066708596 | H18: =PL!G110 -> 3.7005291 | I18: =PL!G102 -> 2.3885307 | J18: =PL!G115 -> 0.66 | K18: =PL!G126 -> 8.1675298 | L18: =K18/K$4-1 -> -0.17187378
A19: 顆數情境 C | B19: CY2028–29 ×0.6；CPO 情境 C | C19: =PL!F145 -> 3.4145724 | D19: =PL!F137 -> 2.357798 | E19: =PL!F150 -> 0.67 | F19: =PL!F161 -> 7.8388382 | G19: =F19/F$4-1 -> -0.13952798 | H19: =PL!G145 -> 2.7731624 | I19: =PL!G137 -> 1.7542482 | J19: =PL!G150 -> 0.66 | K19: =PL!G161 -> 5.7151925 | L19: =K19/K$4-1 -> -0.42052237
A21: 讀法：FY2027 為錨點、各案例相同；顆數情境只影響 FY2028 的 4/12（CY2028），差異主要在 FY2029。「AEC 份額流失」「最大客戶流失」「AI 銅纜市場 ×0.8」是 FY2028 EPS 最大的三條不利路徑；FY2028 起稅率 17%（OECD 最低稅）影響較小；顆數情境 C 主要打在 FY2029。光學在 FY2029 前仍小於 AEC。
A23: 目標價參數（只改 DCF 參數與權重；PL 收斂法的 fade_g 不隨 tp_g 變動）
A24: 案例 | B24: 設定 | C24: DCF 目標價 | D24: Comparable 目標價 | E24: 加權目標價 | F24: 相對基準
A25: 基準 | B25: r 10%、g 4%、DCF 權重 0.5 | C25: =(tp_wA*(Val!B8*(1-IF(tp_roe<=tp_g,0.8,MIN(tp_g/tp_roe,0.8)))/(1+tp_r)^1+Val!B9*(1-IF(tp_roe<=tp_g,0.8,MIN(tp_g/tp_roe,0.8)))/(1+tp_r)^2+Val!B10*(1-IF(tp_roe<=tp_g,0.8,MIN(tp_g/tp_roe,0.8)))/(1+tp_r)^3+Val!B11*(1-IF(tp_roe<=tp_g,0.8,MIN(tp_g/tp_roe,0.8)))/(1+tp_r)^4+Val!B12*(1-IF(tp_roe<=tp_g,0.8,MIN(tp_g/tp_roe,0.8)))/(1+tp_r)^5+Val!B13*(1-IF(tp_roe<=tp_g,0.8,MIN(tp_g/tp_roe,0.8)))/(1+tp_r)^6+Val!B13*(1-IF(tp_roe<=tp_g,0.8,MIN(tp_g/tp_roe,0.8)))*(1+tp_g)/(tp_r-tp_g)/(1+tp_r)^6)+tp_wB*(Val!C8*(1-IF(tp_roe<=tp_g,0.8,MIN(tp_g/tp_roe,0.8)))/(1+tp_r)^1+Val!C9*(1-IF(tp_roe<=tp_g,0.8,MIN(tp_g/tp_roe,0.8)))/(1+tp_r)^2+Val!C10*(1-IF(tp_roe<=tp_g,0.8,MIN(tp_g/tp_roe,0.8)))/(1+tp_r)^3+Val!C11*(1-IF(tp_roe<=tp_g,0.8,MIN(tp_g/tp_roe,0.8)))/(1+tp_r)^4+Val!C12*(1-IF(tp_roe<=tp_g,0.8,MIN(tp_g/tp_roe,0.8)))/(1+tp_r)^5+Val!C13*(1-IF(tp_roe<=tp_g,0.8,MIN(tp_g/tp_roe,0.8)))/(1+tp_r)^6+Val!C13*(1-IF(tp_roe<=tp_g,0.8,MIN(tp_g/tp_roe,0.8)))*(1+tp_g)/(tp_r-tp_g)/(1+tp_r)^6)+tp_wC*(Val!D8*(1-IF(tp_roe<=tp_g,0.8,MIN(tp_g/tp_roe,0.8)))/(1+tp_r)^1+Val!D9*(1-IF(tp_roe<=tp_g,0.8,MIN(tp_g/tp_roe,0.8)))/(1+tp_r)^2+Val!D10*(1-IF(tp_roe<=tp_g,0.8,MIN(tp_g/tp_roe,0.8)))/(1+tp_r)^3+Val!D11*(1-IF(tp_roe<=tp_g,0.8,MIN(tp_g/tp_roe,0.8)))/(1+tp_r)^4+Val!D12*(1-IF(tp_roe<=tp_g,0.8,MIN(tp_g/tp_roe,0.8)))/(1+tp_r)^5+Val!D13*(1-IF(tp_roe<=tp_g,0.8,MIN(tp_g/tp_roe,0.8)))/(1+tp_r)^6+Val!D13*(1-IF(tp_roe<=tp_g,0.8,MIN(tp_g/tp_roe,0.8)))*(1+tp_g)/(tp_r-tp_g)/(1+tp_r)^6))*(1+tp_r) -> 100.16105 | D25: =Val!B35 -> 288.84666 | E25: =tp_w_dcf*C25+(1-tp_w_dcf)*D25 -> 194.50386 | F25: =E25/E$25-1 -> 0
A26: 折現率 +1pt | B26: r 11% | C26: =(tp_wA*(Val!B8*(1-IF(tp_roe<=tp_g,0.8,MIN(tp_g/tp_roe,0.8)))/(1+(tp_r+0.01))^1+Val!B9*(1-IF(tp_roe<=tp_g,0.8,MIN(tp_g/tp_roe,0.8)))/(1+(tp_r+0.01))^2+Val!B10*(1-IF(tp_roe<=tp_g,0.8,MIN(tp_g/tp_roe,0.8)))/(1+(tp_r+0.01))^3+Val!B11*(1-IF(tp_roe<=tp_g,0.8,MIN(tp_g/tp_roe,0.8)))/(1+(tp_r+0.01))^4+Val!B12*(1-IF(tp_roe<=tp_g,0.8,MIN(tp_g/tp_roe,0.8)))/(1+(tp_r+0.01))^5+Val!B13*(1-IF(tp_roe<=tp_g,0.8,MIN(tp_g/tp_roe,0.8)))/(1+(tp_r+0.01))^6+Val!B13*(1-IF(tp_roe<=tp_g,0.8,MIN(tp_g/tp_roe,0.8)))*(1+tp_g)/((tp_r+0.01)-tp_g)/(1+(tp_r+0.01))^6)+tp_wB*(Val!C8*(1-IF(tp_roe<=tp_g,0.8,MIN(tp_g/tp_roe,0.8)))/(1+(tp_r+0.01))^1+Val!C9*(1-IF(tp_roe<=tp_g,0.8,MIN(tp_g/tp_roe,0.8)))/(1+(tp_r+0.01))^2+Val!C10*(1-IF(tp_roe<=tp_g,0.8,MIN(tp_g/tp_roe,0.8)))/(1+(tp_r+0.01))^3+Val!C11*(1-IF(tp_roe<=tp_g,0.8,MIN(tp_g/tp_roe,0.8)))/(1+(tp_r+0.01))^4+Val!C12*(1-IF(tp_roe<=tp_g,0.8,MIN(tp_g/tp_roe,0.8)))/(1+(tp_r+0.01))^5+Val!C13*(1-IF(tp_roe<=tp_g,0.8,MIN(tp_g/tp_roe,0.8)))/(1+(tp_r+0.01))^6+Val!C13*(1-IF(tp_roe<=tp_g,0.8,MIN(tp_g/tp_roe,0.8)))*(1+tp_g)/((tp_r+0.01)-tp_g)/(1+(tp_r+0.01))^6)+tp_wC*(Val!D8*(1-IF(tp_roe<=tp_g,0.8,MIN(tp_g/tp_roe,0.8)))/(1+(tp_r+0.01))^1+Val!D9*(1-IF(tp_roe<=tp_g,0.8,MIN(tp_g/tp_roe,0.8)))/(1+(tp_r+0.01))^2+Val!D10*(1-IF(tp_roe<=tp_g,0.8,MIN(tp_g/tp_roe,0.8)))/(1+(tp_r+0.01))^3+Val!D11*(1-IF(tp_roe<=tp_g,0.8,MIN(tp_g/tp_roe,0.8)))/(1+(tp_r+0.01))^4+Val!D12*(1-IF(tp_roe<=tp_g,0.8,MIN(tp_g/tp_roe,0.8)))/(1+(tp_r+0.01))^5+Val!D13*(1-IF(tp_roe<=tp_g,0.8,MIN(tp_g/tp_roe,0.8)))/(1+(tp_r+0.01))^6+Val!D13*(1-IF(tp_roe<=tp_g,0.8,MIN(tp_g/tp_roe,0.8)))*(1+tp_g)/((tp_r+0.01)-tp_g)/(1+(tp_r+0.01))^6))*(1+(tp_r+0.01)) -> 86.879119 | D26: =Val!B35 -> 288.84666 | E26: =tp_w_dcf*C26+(1-tp_w_dcf)*D26 -> 187.86289 | F26: =E26/E$25-1 -> -0.034143097
A27: 折現率 −1pt | B27: r 9% | C27: =(tp_wA*(Val!B8*(1-IF(tp_roe<=tp_g,0.8,MIN(tp_g/tp_roe,0.8)))/(1+(tp_r-0.01))^1+Val!B9*(1-IF(tp_roe<=tp_g,0.8,MIN(tp_g/tp_roe,0.8)))/(1+(tp_r-0.01))^2+Val!B10*(1-IF(tp_roe<=tp_g,0.8,MIN(tp_g/tp_roe,0.8)))/(1+(tp_r-0.01))^3+Val!B11*(1-IF(tp_roe<=tp_g,0.8,MIN(tp_g/tp_roe,0.8)))/(1+(tp_r-0.01))^4+Val!B12*(1-IF(tp_roe<=tp_g,0.8,MIN(tp_g/tp_roe,0.8)))/(1+(tp_r-0.01))^5+Val!B13*(1-IF(tp_roe<=tp_g,0.8,MIN(tp_g/tp_roe,0.8)))/(1+(tp_r-0.01))^6+Val!B13*(1-IF(tp_roe<=tp_g,0.8,MIN(tp_g/tp_roe,0.8)))*(1+tp_g)/((tp_r-0.01)-tp_g)/(1+(tp_r-0.01))^6)+tp_wB*(Val!C8*(1-IF(tp_roe<=tp_g,0.8,MIN(tp_g/tp_roe,0.8)))/(1+(tp_r-0.01))^1+Val!C9*(1-IF(tp_roe<=tp_g,0.8,MIN(tp_g/tp_roe,0.8)))/(1+(tp_r-0.01))^2+Val!C10*(1-IF(tp_roe<=tp_g,0.8,MIN(tp_g/tp_roe,0.8)))/(1+(tp_r-0.01))^3+Val!C11*(1-IF(tp_roe<=tp_g,0.8,MIN(tp_g/tp_roe,0.8)))/(1+(tp_r-0.01))^4+Val!C12*(1-IF(tp_roe<=tp_g,0.8,MIN(tp_g/tp_roe,0.8)))/(1+(tp_r-0.01))^5+Val!C13*(1-IF(tp_roe<=tp_g,0.8,MIN(tp_g/tp_roe,0.8)))/(1+(tp_r-0.01))^6+Val!C13*(1-IF(tp_roe<=tp_g,0.8,MIN(tp_g/tp_roe,0.8)))*(1+tp_g)/((tp_r-0.01)-tp_g)/(1+(tp_r-0.01))^6)+tp_wC*(Val!D8*(1-IF(tp_roe<=tp_g,0.8,MIN(tp_g/tp_roe,0.8)))/(1+(tp_r-0.01))^1+Val!D9*(1-IF(tp_roe<=tp_g,0.8,MIN(tp_g/tp_roe,0.8)))/(1+(tp_r-0.01))^2+Val!D10*(1-IF(tp_roe<=tp_g,0.8,MIN(tp_g/tp_roe,0.8)))/(1+(tp_r-0.01))^3+Val!D11*(1-IF(tp_roe<=tp_g,0.8,MIN(tp_g/tp_roe,0.8)))/(1+(tp_r-0.01))^4+Val!D12*(1-IF(tp_roe<=tp_g,0.8,MIN(tp_g/tp_roe,0.8)))/(1+(tp_r-0.01))^5+Val!D13*(1-IF(tp_roe<=tp_g,0.8,MIN(tp_g/tp_roe,0.8)))/(1+(tp_r-0.01))^6+Val!D13*(1-IF(tp_roe<=tp_g,0.8,MIN(tp_g/tp_roe,0.8)))*(1+tp_g)/((tp_r-0.01)-tp_g)/(1+(tp_r-0.01))^6))*(1+(tp_r-0.01)) -> 118.7424 | D27: =Val!B35 -> 288.84666 | E27: =tp_w_dcf*C27+(1-tp_w_dcf)*D27 -> 203.79453 | F27: =E27/E$25-1 -> 0.047766025
A28: 長期成長 +1pt | B28: g 5% | C28: =(tp_wA*(Val!B8*(1-IF(tp_roe<=(tp_g+0.01),0.8,MIN((tp_g+0.01)/tp_roe,0.8)))/(1+tp_r)^1+Val!B9*(1-IF(tp_roe<=(tp_g+0.01),0.8,MIN((tp_g+0.01)/tp_roe,0.8)))/(1+tp_r)^2+Val!B10*(1-IF(tp_roe<=(tp_g+0.01),0.8,MIN((tp_g+0.01)/tp_roe,0.8)))/(1+tp_r)^3+Val!B11*(1-IF(tp_roe<=(tp_g+0.01),0.8,MIN((tp_g+0.01)/tp_roe,0.8)))/(1+tp_r)^4+Val!B12*(1-IF(tp_roe<=(tp_g+0.01),0.8,MIN((tp_g+0.01)/tp_roe,0.8)))/(1+tp_r)^5+Val!B13*(1-IF(tp_roe<=(tp_g+0.01),0.8,MIN((tp_g+0.01)/tp_roe,0.8)))/(1+tp_r)^6+Val!B13*(1-IF(tp_roe<=(tp_g+0.01),0.8,MIN((tp_g+0.01)/tp_roe,0.8)))*(1+(tp_g+0.01))/(tp_r-(tp_g+0.01))/(1+tp_r)^6)+tp_wB*(Val!C8*(1-IF(tp_roe<=(tp_g+0.01),0.8,MIN((tp_g+0.01)/tp_roe,0.8)))/(1+tp_r)^1+Val!C9*(1-IF(tp_roe<=(tp_g+0.01),0.8,MIN((tp_g+0.01)/tp_roe,0.8)))/(1+tp_r)^2+Val!C10*(1-IF(tp_roe<=(tp_g+0.01),0.8,MIN((tp_g+0.01)/tp_roe,0.8)))/(1+tp_r)^3+Val!C11*(1-IF(tp_roe<=(tp_g+0.01),0.8,MIN((tp_g+0.01)/tp_roe,0.8)))/(1+tp_r)^4+Val!C12*(1-IF(tp_roe<=(tp_g+0.01),0.8,MIN((tp_g+0.01)/tp_roe,0.8)))/(1+tp_r)^5+Val!C13*(1-IF(tp_roe<=(tp_g+0.01),0.8,MIN((tp_g+0.01)/tp_roe,0.8)))/(1+tp_r)^6+Val!C13*(1-IF(tp_roe<=(tp_g+0.01),0.8,MIN((tp_g+0.01)/tp_roe,0.8)))*(1+(tp_g+0.01))/(tp_r-(tp_g+0.01))/(1+tp_r)^6)+tp_wC*(Val!D8*(1-IF(tp_roe<=(tp_g+0.01),0.8,MIN((tp_g+0.01)/tp_roe,0.8)))/(1+tp_r)^1+Val!D9*(1-IF(tp_roe<=(tp_g+0.01),0.8,MIN((tp_g+0.01)/tp_roe,0.8)))/(1+tp_r)^2+Val!D10*(1-IF(tp_roe<=(tp_g+0.01),0.8,MIN((tp_g+0.01)/tp_roe,0.8)))/(1+tp_r)^3+Val!D11*(1-IF(tp_roe<=(tp_g+0.01),0.8,MIN((tp_g+0.01)/tp_roe,0.8)))/(1+tp_r)^4+Val!D12*(1-IF(tp_roe<=(tp_g+0.01),0.8,MIN((tp_g+0.01)/tp_roe,0.8)))/(1+tp_r)^5+Val!D13*(1-IF(tp_roe<=(tp_g+0.01),0.8,MIN((tp_g+0.01)/tp_roe,0.8)))/(1+tp_r)^6+Val!D13*(1-IF(tp_roe<=(tp_g+0.01),0.8,MIN((tp_g+0.01)/tp_roe,0.8)))*(1+(tp_g+0.01))/(tp_r-(tp_g+0.01))/(1+tp_r)^6))*(1+tp_r) -> 107.79225 | D28: =Val!B35 -> 288.84666 | E28: =tp_w_dcf*C28+(1-tp_w_dcf)*D28 -> 198.31946 | F28: =E28/E$25-1 -> 0.019617095
A29: 長期成長 −1pt | B29: g 3% | C29: =(tp_wA*(Val!B8*(1-IF(tp_roe<=(tp_g-0.01),0.8,MIN((tp_g-0.01)/tp_roe,0.8)))/(1+tp_r)^1+Val!B9*(1-IF(tp_roe<=(tp_g-0.01),0.8,MIN((tp_g-0.01)/tp_roe,0.8)))/(1+tp_r)^2+Val!B10*(1-IF(tp_roe<=(tp_g-0.01),0.8,MIN((tp_g-0.01)/tp_roe,0.8)))/(1+tp_r)^3+Val!B11*(1-IF(tp_roe<=(tp_g-0.01),0.8,MIN((tp_g-0.01)/tp_roe,0.8)))/(1+tp_r)^4+Val!B12*(1-IF(tp_roe<=(tp_g-0.01),0.8,MIN((tp_g-0.01)/tp_roe,0.8)))/(1+tp_r)^5+Val!B13*(1-IF(tp_roe<=(tp_g-0.01),0.8,MIN((tp_g-0.01)/tp_roe,0.8)))/(1+tp_r)^6+Val!B13*(1-IF(tp_roe<=(tp_g-0.01),0.8,MIN((tp_g-0.01)/tp_roe,0.8)))*(1+(tp_g-0.01))/(tp_r-(tp_g-0.01))/(1+tp_r)^6)+tp_wB*(Val!C8*(1-IF(tp_roe<=(tp_g-0.01),0.8,MIN((tp_g-0.01)/tp_roe,0.8)))/(1+tp_r)^1+Val!C9*(1-IF(tp_roe<=(tp_g-0.01),0.8,MIN((tp_g-0.01)/tp_roe,0.8)))/(1+tp_r)^2+Val!C10*(1-IF(tp_roe<=(tp_g-0.01),0.8,MIN((tp_g-0.01)/tp_roe,0.8)))/(1+tp_r)^3+Val!C11*(1-IF(tp_roe<=(tp_g-0.01),0.8,MIN((tp_g-0.01)/tp_roe,0.8)))/(1+tp_r)^4+Val!C12*(1-IF(tp_roe<=(tp_g-0.01),0.8,MIN((tp_g-0.01)/tp_roe,0.8)))/(1+tp_r)^5+Val!C13*(1-IF(tp_roe<=(tp_g-0.01),0.8,MIN((tp_g-0.01)/tp_roe,0.8)))/(1+tp_r)^6+Val!C13*(1-IF(tp_roe<=(tp_g-0.01),0.8,MIN((tp_g-0.01)/tp_roe,0.8)))*(1+(tp_g-0.01))/(tp_r-(tp_g-0.01))/(1+tp_r)^6)+tp_wC*(Val!D8*(1-IF(tp_roe<=(tp_g-0.01),0.8,MIN((tp_g-0.01)/tp_roe,0.8)))/(1+tp_r)^1+Val!D9*(1-IF(tp_roe<=(tp_g-0.01),0.8,MIN((tp_g-0.01)/tp_roe,0.8)))/(1+tp_r)^2+Val!D10*(1-IF(tp_roe<=(tp_g-0.01),0.8,MIN((tp_g-0.01)/tp_roe,0.8)))/(1+tp_r)^3+Val!D11*(1-IF(tp_roe<=(tp_g-0.01),0.8,MIN((tp_g-0.01)/tp_roe,0.8)))/(1+tp_r)^4+Val!D12*(1-IF(tp_roe<=(tp_g-0.01),0.8,MIN((tp_g-0.01)/tp_roe,0.8)))/(1+tp_r)^5+Val!D13*(1-IF(tp_roe<=(tp_g-0.01),0.8,MIN((tp_g-0.01)/tp_roe,0.8)))/(1+tp_r)^6+Val!D13*(1-IF(tp_roe<=(tp_g-0.01),0.8,MIN((tp_g-0.01)/tp_roe,0.8)))*(1+(tp_g-0.01))/(tp_r-(tp_g-0.01))/(1+tp_r)^6))*(1+tp_r) -> 95.175801 | D29: =Val!B35 -> 288.84666 | E29: =tp_w_dcf*C29+(1-tp_w_dcf)*D29 -> 192.01123 | F29: =E29/E$25-1 -> -0.012815288
A30: DCF 權重 0.3 | B30: Comparable 0.7 | C30: =(tp_wA*(Val!B8*(1-IF(tp_roe<=tp_g,0.8,MIN(tp_g/tp_roe,0.8)))/(1+tp_r)^1+Val!B9*(1-IF(tp_roe<=tp_g,0.8,MIN(tp_g/tp_roe,0.8)))/(1+tp_r)^2+Val!B10*(1-IF(tp_roe<=tp_g,0.8,MIN(tp_g/tp_roe,0.8)))/(1+tp_r)^3+Val!B11*(1-IF(tp_roe<=tp_g,0.8,MIN(tp_g/tp_roe,0.8)))/(1+tp_r)^4+Val!B12*(1-IF(tp_roe<=tp_g,0.8,MIN(tp_g/tp_roe,0.8)))/(1+tp_r)^5+Val!B13*(1-IF(tp_roe<=tp_g,0.8,MIN(tp_g/tp_roe,0.8)))/(1+tp_r)^6+Val!B13*(1-IF(tp_roe<=tp_g,0.8,MIN(tp_g/tp_roe,0.8)))*(1+tp_g)/(tp_r-tp_g)/(1+tp_r)^6)+tp_wB*(Val!C8*(1-IF(tp_roe<=tp_g,0.8,MIN(tp_g/tp_roe,0.8)))/(1+tp_r)^1+Val!C9*(1-IF(tp_roe<=tp_g,0.8,MIN(tp_g/tp_roe,0.8)))/(1+tp_r)^2+Val!C10*(1-IF(tp_roe<=tp_g,0.8,MIN(tp_g/tp_roe,0.8)))/(1+tp_r)^3+Val!C11*(1-IF(tp_roe<=tp_g,0.8,MIN(tp_g/tp_roe,0.8)))/(1+tp_r)^4+Val!C12*(1-IF(tp_roe<=tp_g,0.8,MIN(tp_g/tp_roe,0.8)))/(1+tp_r)^5+Val!C13*(1-IF(tp_roe<=tp_g,0.8,MIN(tp_g/tp_roe,0.8)))/(1+tp_r)^6+Val!C13*(1-IF(tp_roe<=tp_g,0.8,MIN(tp_g/tp_roe,0.8)))*(1+tp_g)/(tp_r-tp_g)/(1+tp_r)^6)+tp_wC*(Val!D8*(1-IF(tp_roe<=tp_g,0.8,MIN(tp_g/tp_roe,0.8)))/(1+tp_r)^1+Val!D9*(1-IF(tp_roe<=tp_g,0.8,MIN(tp_g/tp_roe,0.8)))/(1+tp_r)^2+Val!D10*(1-IF(tp_roe<=tp_g,0.8,MIN(tp_g/tp_roe,0.8)))/(1+tp_r)^3+Val!D11*(1-IF(tp_roe<=tp_g,0.8,MIN(tp_g/tp_roe,0.8)))/(1+tp_r)^4+Val!D12*(1-IF(tp_roe<=tp_g,0.8,MIN(tp_g/tp_roe,0.8)))/(1+tp_r)^5+Val!D13*(1-IF(tp_roe<=tp_g,0.8,MIN(tp_g/tp_roe,0.8)))/(1+tp_r)^6+Val!D13*(1-IF(tp_roe<=tp_g,0.8,MIN(tp_g/tp_roe,0.8)))*(1+tp_g)/(tp_r-tp_g)/(1+tp_r)^6))*(1+tp_r) -> 100.16105 | D30: =Val!B35 -> 288.84666 | E30: =0.3*C30+(1-0.3)*D30 -> 232.24098 | F30: =E30/E$25-1 -> 0.19401736
A31: DCF 權重 0.7 | B31: Comparable 0.3 | C31: =(tp_wA*(Val!B8*(1-IF(tp_roe<=tp_g,0.8,MIN(tp_g/tp_roe,0.8)))/(1+tp_r)^1+Val!B9*(1-IF(tp_roe<=tp_g,0.8,MIN(tp_g/tp_roe,0.8)))/(1+tp_r)^2+Val!B10*(1-IF(tp_roe<=tp_g,0.8,MIN(tp_g/tp_roe,0.8)))/(1+tp_r)^3+Val!B11*(1-IF(tp_roe<=tp_g,0.8,MIN(tp_g/tp_roe,0.8)))/(1+tp_r)^4+Val!B12*(1-IF(tp_roe<=tp_g,0.8,MIN(tp_g/tp_roe,0.8)))/(1+tp_r)^5+Val!B13*(1-IF(tp_roe<=tp_g,0.8,MIN(tp_g/tp_roe,0.8)))/(1+tp_r)^6+Val!B13*(1-IF(tp_roe<=tp_g,0.8,MIN(tp_g/tp_roe,0.8)))*(1+tp_g)/(tp_r-tp_g)/(1+tp_r)^6)+tp_wB*(Val!C8*(1-IF(tp_roe<=tp_g,0.8,MIN(tp_g/tp_roe,0.8)))/(1+tp_r)^1+Val!C9*(1-IF(tp_roe<=tp_g,0.8,MIN(tp_g/tp_roe,0.8)))/(1+tp_r)^2+Val!C10*(1-IF(tp_roe<=tp_g,0.8,MIN(tp_g/tp_roe,0.8)))/(1+tp_r)^3+Val!C11*(1-IF(tp_roe<=tp_g,0.8,MIN(tp_g/tp_roe,0.8)))/(1+tp_r)^4+Val!C12*(1-IF(tp_roe<=tp_g,0.8,MIN(tp_g/tp_roe,0.8)))/(1+tp_r)^5+Val!C13*(1-IF(tp_roe<=tp_g,0.8,MIN(tp_g/tp_roe,0.8)))/(1+tp_r)^6+Val!C13*(1-IF(tp_roe<=tp_g,0.8,MIN(tp_g/tp_roe,0.8)))*(1+tp_g)/(tp_r-tp_g)/(1+tp_r)^6)+tp_wC*(Val!D8*(1-IF(tp_roe<=tp_g,0.8,MIN(tp_g/tp_roe,0.8)))/(1+tp_r)^1+Val!D9*(1-IF(tp_roe<=tp_g,0.8,MIN(tp_g/tp_roe,0.8)))/(1+tp_r)^2+Val!D10*(1-IF(tp_roe<=tp_g,0.8,MIN(tp_g/tp_roe,0.8)))/(1+tp_r)^3+Val!D11*(1-IF(tp_roe<=tp_g,0.8,MIN(tp_g/tp_roe,0.8)))/(1+tp_r)^4+Val!D12*(1-IF(tp_roe<=tp_g,0.8,MIN(tp_g/tp_roe,0.8)))/(1+tp_r)^5+Val!D13*(1-IF(tp_roe<=tp_g,0.8,MIN(tp_g/tp_roe,0.8)))/(1+tp_r)^6+Val!D13*(1-IF(tp_roe<=tp_g,0.8,MIN(tp_g/tp_roe,0.8)))*(1+tp_g)/(tp_r-tp_g)/(1+tp_r)^6))*(1+tp_r) -> 100.16105 | D31: =Val!B35 -> 288.84666 | E31: =0.7*C31+(1-0.7)*D31 -> 156.76673 | F31: =E31/E$25-1 -> -0.19401736
A40: 案例區塊：AEC 份額流失（低）（情境 A）
A41: 項目 | B41: 單位 | C41: FY2025A | D41: FY2026A | E41: FY2027（錨點） | F41: FY2028 | G41: FY2029 | H41: 說明
A42: A. AEC（E 欄＝FY2027 校準年；F–G＝FY2028–FY2029；市場為日曆年月數加權）
A43: AI 銅纜市場（FY 加權）× 情境顆數係數 | B43: US$B | E43: =(w8*mcu_26*1+(1-w8)*mcu_27*1) -> 34.339013 | F43: =(w8*mcu_27*1+(1-w8)*mcu_28*um28_A) -> 53.866613 | G43: =(w8*mcu_28*um28_A+(1-w8)*mcu_29*um29_A) -> 59.962245 | H43: FY(t)＝8/12 × CY(t−1)＋4/12 × CY(t)；CY2028 起乘顆數係數
A44: Credo AEC 有效份額（FY2027 校準）＝ AEC 營收 ÷ 銅纜市場 | B44: % | E44: =a27_aec/E43 -> 0.051326104 | H44: Derived：＝AEC 滲透率 × Credo 占 AEC（拆分見 Units）
A45: AEC 有效份額相對值（÷ FY2027） | B45: x | E45: =1 -> 1 | F45: =RLO_28 -> 0.75 | G45: =RLO_29 -> 0.6
A46: AEC 有效份額 | B46: % | E46: =$E$44*E45 -> 0.051326104 | F46: =$E$44*F45 -> 0.038494578 | G46: =$E$44*G45 -> 0.030795662
A47: AEC 營收 | B47: US$B | D47: =a26_aec -> 1.0916579 | E47: =a27_aec -> 1.7624878 | F47: =F43*F46 -> 2.0735725 | G47: =G43*G46 -> 1.846577
A48: B. 光學（光 DSP、矽光 PIC、ZeroFlap 光學）
A49: AI 可插拔光模組市場（FY 加權）× 情境顆數係數 | B49: US$B | E49: =(w8*mpl_26*1+(1-w8)*mpl_27*1) -> 37.68908 | F49: =(w8*mpl_27*1+(1-w8)*mpl_28*um28_A) -> 55.037643 | G49: =(w8*mpl_28*um28_A+(1-w8)*mpl_29*um29_A) -> 62.9726
A50: Credo 光學有效份額（FY2027 校準）＝ 光學營收 ÷ 可插拔市場 | B50: % | E50: =a27_opt/(w8*mplB_26*1+(1-w8)*mplB_27*1) -> 0.015762535
A51: 光學有效份額相對值（÷ FY2027） | B51: x | E51: =1 -> 1 | F51: =rel_o_28 -> 1.2 | G51: =rel_o_29 -> 1.35
...

Sheet Sources
A1: 來源（公司原文＝SEC 8-K 新聞稿與 10-K）
A2: 公司：4Q26 與 FY2026 實績、1Q27 指引（8-K 附件 99.1） | B2: https://www.sec.gov/Archives/edgar/data/0001807794/000162828026039474/credoq42026ex-991.htm
A3: 公司：1Q27 實績、2Q27 指引（8-K 附件 99.1） | B3: https://www.sec.gov/Archives/edgar/data/0001807794/000162828026059795/credoq12027ex-991.htm
A4: 公司：FY2026 10-K（客戶集中、DustPhotonics、OECD 最低稅、股數、地區營收） | B4: https://www.sec.gov/Archives/edgar/data/0001807794/000162828026043303/crdo-20260502.htm
A5: 二手：4Q26 法說摘要（FY2027 年增逾 80%、光學逾 6 億美元、營業費用約 +50%） | B5: https://letsdatascience.com/news/credo-raises-guidance-as-optical-ramp-accelerates-30d77185
A6: 二手：1Q27 摘要（年增逾 85%、淨利率約 50%、AEC 占營收年增九成以上） | B6: https://www.itiger.com/news/1122940235
A7: 二手：1Q27 法說重點（Zacks；前四大終端客戶 33%、28%、13%、10%；五家超大規模客戶） | B7: https://www.yourwyominglink.com/credo-q1-earnings-call-highlights-optics-as-the-next-growth-engine/article_d01cfee6-9667-5ab6-8b08-fcf8fffa13d0.html
A8: 券商：Jefferies AEC 條數與份額（Invezz 轉述） | B8: https://invezz.com/en-ae/news/2026/04/13/credo-jumps-11percent-as-jefferies-backs-copper-tech-in-ai-boom-debate/
A9: 券商：Needham 等（客戶名稱 Amazon、Microsoft、xAI；Benzinga 2025-03） | B9: https://www.benzinga.com/25/03/44149586/credo-expands-hyperscaler-partnerships-with-amazon-microsoft-xai-amid-nvidia-powered-ai-boom
A10: 共識：Yahoo Finance 分析師預估（2026-10-01） | B10: https://finance.yahoo.com/quote/CRDO/analysis/
A11: 共識：StockAnalysis 預估與目標價（2026-10-05） | B11: https://stockanalysis.com/stocks/crdo/forecast/
A12: 價格：StockAnalysis（2026-10-23 收盤、52 週區間、股數） | B12: https://stockanalysis.com/stocks/crdo/
A13: 價格與評論：TIKR（10 月跌幅、OCP 發表 ALC、FY2027 共識 GAAP／調整後 EPS） | B13: https://www.tikr.com/blog/credo-stock-fell-22-last-week-as-it-launched-a-new-optical-cable-heres-where-it-could-go-by-2031
... A15: 資料商：StockAnalysis 會計年度末 P/E | B15: https://stockanalysis.com/stocks/crdo/financials/ratios/
A16: 市場層：markets/network、tsmc 成品（本 repo，唯讀）
A17: 待補（人工）：2Q27 財報；產品線營收拆分（AEC、光學、IC、IP）；客戶名稱第一手出處；AEC 市場份額第一手來源；共識 FY2028 是否含 OECD 最低稅；P/E 第二來源；前瞻 P/E 歷史（Bloomberg） | B17: 未找到
A18: SemiAnalysis | B18: 未使用
