Workbook

Sheet README
A1: Marvell（MRVL）收支與估值模型 v0.2.3（AI 半導體 Project：運算層，客製 ASIC＋光互連 DSP＋交換器） 2026-10-26
A2: 版本：v0.1（初版）。樣板 avgo/；ASIC 每顆規格（核心售價、HBM 代購）讀 Broadcom 模型（本專案權威），本模型只加 Marvell 份額與光晶片組。本版未做先驗。
A3: 模型命題：Marvell 的資料中心營收＝客製 XPU（市場層 ASIC 顆數 × Marvell 份額 × 每顆售價）＋光互連（AI 光模組數 × 每模組晶片組金額 × 份額）＋交換器與其他；公司一年內把 FY2028 營收展望從 $13B 上修到 $20B，市場層顆數推得出多少？
A4: 核心問題：以市場層顆數與光模組市場往前推，Marvell FY2028 營收與 EPS 離公司 $20B 展望與共識有多遠；差距要靠哪條產品線補上，現價隱含多少。
A6: 會計年度：FY(t)＝t−1 年 2 月～t 年 1 月底，FY(t) 直接取 CY(t−1)（與 NVIDIA 相同；不跨年加權）。FY2026A 實績；FY2027 錨點；預測 FY2028–FY2030（≈CY2027–29）。口徑：公司 non-GAAP（排除股票薪酬、攤銷、重組）。下次財報：Q3 FY27 約 2026-11-30～12 月初。
A8: 驅動因子 → 推導量（全部唯讀上游，不修改）
A9: 客製 XPU：Trainium、其他 ASIC（Maia 等）、Google TPU 的市場層顆數（markets/memory × 情境係數）× Marvell 份額（Assumed）×（核心售價＋代購比例 × HBM 金額；Broadcom 模型規格）× k_x（FY2027 校準）＋ XPU attach。
A10: 光互連：markets/network 的 AI 後端可插拔光模組金額 ÷ 平均單價 ＝ 模組數 ×（1 − 線性直驅）× 每模組晶片組金額 × Marvell 份額 × k_o ＋ 相干 DSP／DCI。交換器、AEC／retimer、儲存：公司說法 × Assumed 成長；通訊與其他：FY2027 錨點 × 低個位數成長。
A11: 毛利率：光互連、其他資料中心、attach、通訊、代購 HBM 各用 Assumed 毛利率；XPU 核心毛利率 m_core 為 FY2027 殘差（Derived）。營業費用彈性 0.5（公司說法）、稅率 13%（公司說法）。
A12: 校準：FY2027 ＝ Q1、Q2 實績＋Q3 指引＋Q4（全年約 $12B − 前三季；資料中心年增約 60%）。不用共識、不用公司 FY2028 起的展望（只在 Recon 對帳）。
A13: 估值：目標價＝三情境規則值隱含價的加權（A 0.3、B 0.5、C 0.2；Andy 可改）；規則值＝十年 non-GAAP P/E 依 FY2028 循環位置取分位 × FY2028 EPS。本版未做先驗，無 Andy 合理 P/E 對照。
A14: 標記：Verified、Interested-party、Analogy、Assumed、Derived。SemiAnalysis 未使用。公司原文＝SEC EDGAR 8-K；法說與投資人日內容只經二手轉述（標二手）。
... A18: v0.2.1（2026-10-25）：補上檔空間級距、投資建議、重點觀察（數值不變）。Val 頁末新增「上檔空間級距」「投資建議」兩列（Andy 2026-10-25 14:00、14:17 固定規則），README 頁末新增投資建議與重點觀察三點；既有儲存格位置與數值不變。
A19: ="投資建議："&Val!B151&"（依上檔空間固定規則）" -> 投資建議：強力放空（依上檔空間固定規則）
A20: ="重點觀察 1：目標價 US$"&TEXT(Val!$B$40,"#,##0.00")&"（DCF "&TEXT(Val!$B$23,"#,##0.00")&"、Comparable（相對倍數調整後）"&TEXT(tp_comp_adj,"#,##0.00")&"；DCF 權重 "&TEXT(tp_w_dcf,"0%")&"），比現價 "&TEXT(px,"#,##0.00")&"（2026-10-23）"&IF(Val!$B$43>=0,"高 "&TEXT(Val!$B$43,"0.0%"),"低 "&TEXT(-Val!$B$43,"0.0%"))&"，級距 "&Val!$B$150&"、投資建議 "&Val!$B$151&"。相對倍數調整係數 "&TEXT(rm_factor,"0.00")&"（本公司 10 年前瞻倍數中位數 ÷ 同業的中位數，夾在 0.5–2.0；Val 第 0.5 節），調整前加權上檔空間 "&TEXT((tp_w_dcf*Val!$B$23+(1-tp_w_dcf)*Val!$B$36)/px-1,"+0.0%;−0.0%")&"；Comparable 單獨（市場主流同業法、未調整）為 "&TEXT(Val!$B$44,"+0.0%;−0.0%")&"。"&"以下為 2026-10-29 相對倍數調整前撰寫的說明，其中數字為調整前：主因是倍數：本模型 FY2028 EPS（情境加權）6.50 比共識 7.33 低 11.3%，但現價隱含 31.2 倍共識 FY2028 EPS、共識目標價 341.44 隱含 46.6 倍，同業（Broadcom、NVIDIA、AMD、Astera Labs、Credo）前瞻 P/E 中位數 20.2 倍（共識隱含倍數高"&" 130.7%）。" -> 重點觀察 1：目標價 US$109.67（DCF 115.16、Comparable（相對倍數調整後）104.19；DCF 權重 50%），比現價 228.51（2026-10-23）低 52.0%，級距 小於 −50%、投資建議 強力放空。相對倍數調整係數 0.75（本公司 10 年前瞻倍數中位數 ÷ 同業的中位數，夾在 0.5–2.0；Val 第 0.5 節），調整前加權上檔空間 −44.4%；Comparable 單獨（市場主流同業法、未調整）為 −39.3%。以下為 2026-10-29 相對倍數調整前撰寫的說明，其中數字為調整前：主因是倍數：本模型 FY2028 EPS（情境加權）6.50 比共識 7.33 低 11.3%，但現價隱含 31.2 倍共識 FY2028 EPS、共識目標價 341.44 隱含 46.6 倍，同業（Broadcom、NVIDIA、AMD、Astera Labs、Credo）前瞻 P/E 中位數 20.2 倍（共識隱含倍數高 130.7%）。
A21: 重點觀察 2：情境分歧主要從 FY2029 起：FY2028 EPS 只因網通 CPO 情境（v0.2.2；A＝替代快 → 可插拔模組少 → 光晶片組少）略有差異，A／B／C 為 6.44／6.52／6.56；FY2029 A／B／C 為 8.38／6.93／5.08，DCF 價格帶 72～143；即使 A 情境 FY2029 EPS 8.38 乘同業中位數 20.2 倍（約 169）也低於現價。
A22: 重點觀察 3：FY2028 EPS 最敏感的是光互連：每模組光晶片組金額 ×0.8 時 −11.9%、光晶片組份額 −10pt 時 −9.4%；XPU 方面 TPU 份額 +5pt 可 +8.5%（Sens 頁）。下一個檢驗點是 Q3 FY27 財報（約 2026-11-30～12 月初）的資料中心營收與光互連成長。
A23: v0.2.3（2026-10-28）：分部原則重建（數值不變）。Q 頁最後追加核對列「檢查：分部合計 − 合併營收」；官方分部與子列宣告見 segments.json。
A24: v0.2.2（2026-10-26）：網通模型 v0.2.3 的 CPO 滲透改三情境（A＝替代快、B＝平平、C＝慢），本模型光互連的可插拔光模組市場 A／B／C 改讀同字母列（In 頁末新增 B、C；情境 A 沿用 plug_，數值改為網通情境 A）。CPO 快 → 可插拔模組數較少 → 光 DSP 營收較少；FY2027（≈CY2026）三情境相同。其他輸入不變。
A26: 2026-10-29：加權目標價中的 Comparable 改用相對倍數調整後的值（Val 第 0.5 節：同業前瞻倍數中位數 × 本公司 10 年相對同業的倍數比，Bloomberg 前瞻倍數；Andy 2026-10-27「照建議做」、10-29 資料取回）。「Comparable 目標價（市場主流同業法）」維持不調整。重點觀察 1 的第一句已改為公式；重點觀察 2、3 與其他說明中的目標價與上檔空間數字為調整前撰寫，以 Val 頁為準。
A28: v0.2.4（2026-10-30）：依個股模型原則第 8 節調整 In 頁呈現（數值不變）。In 頁 D／F 欄名改「敏感度低」「敏感度高」（只用於 Sens 頁、不進目標價）；In 頁最後新增「情境驅動對照」一節，把上方各情境專屬輸入三情境並排（只引用上方各列，純展示）；HTML 驅動因子一節分「情境驅動」與「單一參數」兩張表。

Sheet In
A1: In — 輸入（藍字；基準欄 E，低 D、高 F）。金額：十億美元（US$B）；每顆價格：千美元（US$K）；每模組金額：美元；顆數與模組數：百萬。每個輸入附兩個來源（找不到者寫「未找到」）；公司原文算一個。【v0.2.4】基準欄 E 進主模型；D／F＝敏感度低／高，只用於 Sens 頁（一次動一個參數）、不進目標價；情境 A／B／C 的驅動見本頁最後一節「情境驅動對照」。
A2: 標記：Verified／Interested-party／Analogy／Assumed／Derived；Analogy、Assumed 給低／高區間。SemiAnalysis 未使用。公司原文＝Marvell 8-K 新聞稿（SEC EDGAR、investor.marvell.com）；公司對 FY2027、FY2028 的展望與投資人日目標為 Interested-party，FY2027 全年展望只用來推第四季（錨點），FY2028 起只放 Recon 對帳，不作校準
A3: 鍵 | B3: 項目 | C3: 單位 | D3: 敏感度低 | E3: 基準 | F3: 敏感度高 | G3: 標記 | H3: 來源1 | I3: 來源2／說明
A4: A. 加速器顆數（markets/memory；與台積電、HBM、網通、NVIDIA、Broadcom 模型同一份；情境係數讀台積電模型成品，不另訂）
A5: u_trn_26 | B5: AWS Trainium 顆數 CY2026 | C5: 百萬顆 | E5: 2 | G5: Assumed | H5: tsmc/dist/20261030_台積電個股模型_v0.4.1.xlsx｜In!E29 | I5: markets/memory/market.py UNITS（值相同，建置時檢查）
A6: u_trn_27 | B6: AWS Trainium 顆數 CY2027 | C6: 百萬顆 | E6: 2.5 | G6: Assumed | H6: tsmc/dist/20261030_台積電個股模型_v0.4.1.xlsx｜In!E30 | I6: 同上
A7: u_trn_28 | B7: AWS Trainium 顆數 CY2028 | C7: 百萬顆 | E7: 3 | G7: Assumed | H7: tsmc/dist/20261030_台積電個股模型_v0.4.1.xlsx｜In!E31 | I7: 同上
A8: g29_trn | B8: AWS Trainium CY2029 顆數成長 | C8: % | E8: 0.15 | G8: Assumed | H8: tsmc/dist/20261030_台積電個股模型_v0.4.1.xlsx｜In!E32 | I8: markets/memory 無 2029；沿用台積電模型
A9: u_oth_26 | B9: 其他 ASIC（MTIA、Maia、Ascend 等） 顆數 CY2026 | C9: 百萬顆 | E9: 1 | G9: Derived／Assumed | H9: tsmc/dist/20261030_台積電個股模型_v0.4.1.xlsx｜In!E33 | I9: markets/memory/market.py UNITS（值相同，建置時檢查）
A10: u_oth_27 | B10: 其他 ASIC（MTIA、Maia、Ascend 等） 顆數 CY2027 | C10: 百萬顆 | E10: 4.5 | G10: Derived／Assumed | H10: tsmc/dist/20261030_台積電個股模型_v0.4.1.xlsx｜In!E34 | I10: 同上
A11: u_oth_28 | B11: 其他 ASIC（MTIA、Maia、Ascend 等） 顆數 CY2028 | C11: 百萬顆 | E11: 5 | G11: Derived／Assumed | H11: tsmc/dist/20261030_台積電個股模型_v0.4.1.xlsx｜In!E35 | I11: 同上
A12: g29_oth | B12: 其他 ASIC（MTIA、Maia、Ascend 等） CY2029 顆數成長 | C12: % | E12: 0.15 | G12: Assumed | H12: tsmc/dist/20261030_台積電個股模型_v0.4.1.xlsx｜In!E36 | I12: markets/memory 無 2029；沿用台積電模型
A13: u_tpu_26 | B13: Google TPU 顆數 CY2026 | C13: 百萬顆 | E13: 3.85 | G13: Interested-party | H13: tsmc/dist/20261030_台積電個股模型_v0.4.1.xlsx｜In!E25 | I13: markets/memory/market.py UNITS（值相同，建置時檢查）
A14: u_tpu_27 | B14: Google TPU 顆數 CY2027 | C14: 百萬顆 | E14: 5.5 | G14: Interested-party | H14: tsmc/dist/20261030_台積電個股模型_v0.4.1.xlsx｜In!E26 | I14: 同上
A15: u_tpu_28 | B15: Google TPU 顆數 CY2028 | C15: 百萬顆 | E15: 7 | G15: Interested-party | H15: tsmc/dist/20261030_台積電個股模型_v0.4.1.xlsx｜In!E27 | I15: 同上
A16: g29_tpu | B16: Google TPU CY2029 顆數成長 | C16: % | E16: 0.15 | G16: Assumed | H16: tsmc/dist/20261030_台積電個股模型_v0.4.1.xlsx｜In!E28 | I16: markets/memory 無 2029；沿用台積電模型
... A31: gb_tpu_28 | B31: Google TPU 每顆 HBM CY2028 | C31: GB | E31: 288 | G31: Derived／Assumed | H31: markets/memory/market.py UNITS | I31: 同上
A32: B. ASIC 每顆規格（權威在 Broadcom 模型 Units／In 頁，唯讀；本模型只加 Marvell 份額）與 Marvell 份額
A33: core_tpu | B33: TPU 每顆核心售價（不含 HBM） | C33: US$K | D33: 6 | E33: 8 | F33: 11 | G33: Assumed | H33: avgo/dist/20261030_Broadcom個股模型_v0.3.1.xlsx｜In!E56 | I33: Broadcom 模型的 ASIC 每顆規格（本專案權威，規則第 13 條）；本模型不另訂
A34: core_oth | B34: 其他 ASIC 每顆核心售價（不含 HBM） | C34: US$K | D34: 4 | E34: 6 | F34: 9 | G34: Assumed | H34: avgo/dist/20261030_Broadcom個股模型_v0.3.1.xlsx｜In!E57 | I34: Broadcom 模型的 ASIC 每顆規格（本專案權威，規則第 13 條）；本模型不另訂
A35: f_hbm | B35: HBM 由 ASIC 設計夥伴代購並計入營收的比例 | C35: x | D35: 0.3 | E35: 0.6 | F35: 1 | G35: Assumed | H35: avgo/dist/20261030_Broadcom個股模型_v0.3.1.xlsx｜In!E58 | I35: 沿用 Broadcom 模型；Marvell 客戶是否自購 HBM：未找到
A36: m_hbm | B36: 代購 HBM 的毛利率 | C36: x | D36: 0 | E36: 0.1 | F36: 0.2 | G36: Assumed | H36: avgo/dist/20261030_Broadcom個股模型_v0.3.1.xlsx｜In!E59 | I36: 沿用 Broadcom 模型
A37: pa_trn | B37: AWS Trainium 每顆（含 HBM，模組層級） | C37: US$K | E37: 8 | G37: Derived | H37: avgo/dist/20261030_Broadcom個股模型_v0.3.1.xlsx｜In!E123 | I37: Broadcom 模型讀自 NVIDIA 模型 In 頁
A38: core_trn | B38: Trainium 每顆核心售價（不含 HBM）＝ 每顆 − CY2026 HBM 金額 | C38: US$K | D38: 4.5 | E38: =pa_trn-gb_trn_26*hbm_A_26/1000 -> 6.394 | F38: 8 | G38: Derived | H38: pa_trn − 110 GB × CY2026 HBM 單價 | I38: 低／高 Assumed；Broadcom 模型無 Trainium 規格
A39: av_tpu_26 | B39: Broadcom 占 Google TPU 顆數 CY2026（對照；份額加總檢查用） | C39: % | E39: 0.9 | G39: Assumed | H39: avgo/dist/20261030_Broadcom個股模型_v0.3.1.xlsx｜In!E50 | I39: Broadcom 模型；Marvell＋Broadcom 不得超過 100%（建置時檢查）
A40: av_tpu_27 | B40: Broadcom 占 Google TPU 顆數 CY2027（對照；份額加總檢查用） | C40: % | E40: 0.8 | G40: Assumed | H40: avgo/dist/20261030_Broadcom個股模型_v0.3.1.xlsx｜In!E51 | I40: Broadcom 模型；Marvell＋Broadcom 不得超過 100%（建置時檢查）
A41: av_tpu_28 | B41: Broadcom 占 Google TPU 顆數 CY2028（對照；份額加總檢查用） | C41: % | E41: 0.75 | G41: Assumed | H41: avgo/dist/20261030_Broadcom個股模型_v0.3.1.xlsx｜In!E52 | I41: Broadcom 模型；Marvell＋Broadcom 不得超過 100%（建置時檢查）
A42: av_oth_26 | B42: Broadcom 占 其他 ASIC（MTIA、Maia、Ascend 等） 顆數 CY2026（對照；份額加總檢查用） | C42: % | E42: 0.35 | G42: Assumed | H42: avgo/dist/20261030_Broadcom個股模型_v0.3.1.xlsx｜In!E53 | I42: Broadcom 模型；Marvell＋Broadcom 不得超過 100%（建置時檢查）
A43: av_oth_27 | B43: Broadcom 占 其他 ASIC（MTIA、Maia、Ascend 等） 顆數 CY2027（對照；份額加總檢查用） | C43: % | E43: 0.55 | G43: Assumed | H43: avgo/dist/20261030_Broadcom個股模型_v0.3.1.xlsx｜In!E54 | I43: Broadcom 模型；Marvell＋Broadcom 不得超過 100%（建置時檢查）
A44: av_oth_28 | B44: Broadcom 占 其他 ASIC（MTIA、Maia、Ascend 等） 顆數 CY2028（對照；份額加總檢查用） | C44: % | E44: 0.55 | G44: Assumed | H44: avgo/dist/20261030_Broadcom個股模型_v0.3.1.xlsx｜In!E55 | I44: Broadcom 模型；Marvell＋Broadcom 不得超過 100%（建置時檢查）
A45: msh_trn_26 | B45: Marvell 占 AWS Trainium 顆數 CY2026 | C45: % | D45: 0.05 | E45: 0.1 | F45: 0.2 | G45: Assumed | H45: Marvell 供應 Trainium 2、Inferentia；Trainium 3 主供應商為世芯（Alchip），Marvell 做 Trainium 2.5（Dolphin Research 2026-03-06，二手） | I45: 各世代份額未揭露：未找到
A46: msh_trn_27 | B46: Marvell 占 AWS Trainium 顆數 CY2027 | C46: % | D46: 0.05 | E46: 0.1 | F46: 0.2 | G46: Assumed | H46: 同上 | I46: —
A47: msh_trn_28 | B47: Marvell 占 AWS Trainium 顆數 CY2028（CY2029 沿用） | C47: % | D47: 0 | E47: 0.08 | F47: 0.2 | G47: Assumed | H47: 同上 | I47: —
A48: msh_oth_26 | B48: Marvell 占 其他 ASIC（MTIA、Maia、Ascend 等） 顆數 CY2026 | C48: % | D48: 0.02 | E48: 0.05 | F48: 0.1 | G48: Assumed | H48: Microsoft：Maia 由 Marvell 設計，Maia 300 自 CY2027 起多 GW 部署（Motley Fool／Webull 轉述 Nadella，二手）；新 Tier 1 XPU 於 FY2028 量產（公司，Q4 FY26 法說） | I48: 其他 ASIC 含 MTIA、昇騰等非 Marvell 晶片；Broadcom 占 35%／55%／55%
A49: msh_oth_27 | B49: Marvell 占 其他 ASIC（MTIA、Maia、Ascend 等） 顆數 CY2027 | C49: % | D49: 0.03 | E49: 0.06 | F49: 0.12 | G49: Assumed | H49: 同上 | I49: —
A50: msh_oth_28 | B50: Marvell 占 其他 ASIC（MTIA、Maia、Ascend 等） 顆數 CY2028（CY2029 沿用） | C50: % | D50: 0.08 | E50: 0.15 | F50: 0.25 | G50: Assumed | H50: 同上 | I50: —
A51: msh_tpu_26 | B51: Marvell 占 Google TPU 顆數 CY2026 | C51: % | D51: 0 | E51: 0 | F51: 0.02 | G51: Assumed | H51: Google：擴大合作（2026-07，客製處理器與相關晶片）；認股權證協議（歸屬上限 $120B），主要營收影響在 FY2029 起（投資人日，二手） | I51: Google 案是否為 TPU 平台：未找到（可能為 Axion CPU 或其他）；Broadcom 占 TPU 75%（CY2028）
A52: msh_tpu_27 | B52: Marvell 占 Google TPU 顆數 CY2027 | C52: % | D52: 0 | E52: 0 | F52: 0.05 | G52: Assumed | H52: 同上 | I52: —
A53: msh_tpu_28 | B53: Marvell 占 Google TPU 顆數 CY2028（CY2029 沿用） | C53: % | D53: 0 | E53: 0.05 | F53: 0.15 | G53: Assumed | H53: 同上 | I53: —
A54: pfc | B54: CY2027 起 XPU 核心售價係數（Sens 用；基準 1） | C54: x | D54: 0.8 | E54: 1 | F54: 1.2 | G54: Assumed | H54: 無：新世代核心單價變化未揭露 | I54: Sens 用 ±20%
...

Sheet Q
A1: Q — 實績（十億美元；EPS 為美元；股數為十億股）。口徑：公司 non-GAAP（排除股票薪酬、攤銷、重組、併購費用）。藍字＝輸入；黑字＝公式。實績取自 Marvell 8-K 新聞稿（SEC EDGAR、investor.marvell.com）
A2: FY2027 錨點＝Q1、Q2 實績＋Q3 指引中點＋Q4（＝公司全年營收展望約 $12B − 前三季；資料中心依全年年增約 60% 推得）；假設見 In 頁 F 節。資料中心產品線拆分（客製、交換器、AEC、儲存）取公司法說說法，光互連為差額（Derived）
A3: 項目 | B3: FY2026A（～2026-01-31） | C3: FY27 Q1（～2026-05-02） | D3: FY27 Q2（～08-01） | E3: FY27 Q3（指引） | F3: FY27 Q4（推得） | G3: FY2027 錨點 | H3: 標記 | I3: 來源1（公司） | J3: 來源2／說明
A4: 營收 | B4: 8.1946 | C4: 2.4178 | D4: 2.7393 | E4: =q3_rev -> 3.15 | F4: =co_rev27-C4-D4-E4 -> 3.6929 | G4: =SUM(C4:F4) -> 12 | H4: Verified／Interested-party（Q3 指引、全年展望） | I4: FY2026：https://www.sec.gov/Archives/edgar/data/1835632/000183563226000006/q426_8kx1312026ex-991.htm；Q1 FY27：https://investor.marvell.com/sec-filings/all-sec-filings/content/0001835632-26-000014/q127_8kx522026ex-991.htm；Q2 FY27：https://investor.marvell.com/news-events/press-releases/detail/1031/marvell-technology-inc-reports-second-quarter-of-fiscal-year-2027-financial-results | J4: 交叉：Q2 FY27 稿的六個月合計（營收 5.1571、non-GAAP 營業利益 1.8501、non-GAAP 淨利 1.5839）＝Q1＋Q2（下方檢查列）；FY2026 資料中心＝四季加總（Q1 1.4406、Q2 1.4905、Q3 1.5179、Q4 1.6513）
A5: 資料中心 | B5: =1.4406+1.4905+1.5179+1.6513 -> 6.1003 | C5: 1.8327 | D5: 2.1715 | E5: =E4-E6 -> 2.668541 | F5: =B5*(1+co_dcg27)-C5-D5-E5 -> 3.087739 | G5: =SUM(C5:F5) -> 9.76048 | H5: Verified／Derived（Q3、Q4） | I5: FY2026：https://www.sec.gov/Archives/edgar/data/1835632/000183563226000006/q426_8kx1312026ex-991.htm；Q1 FY27：https://investor.marvell.com/sec-filings/all-sec-filings/content/0001835632-26-000014/q127_8kx522026ex-991.htm；Q2 FY27：https://investor.marvell.com/news-events/press-releases/detail/1031/marvell-technology-inc-reports-second-quarter-of-fiscal-year-2027-financial-results | J5: FY2026 四季：Q1 FY27 稿（Q1 FY26 比較欄）、Q3 FY26 稿（Q2、Q3）、Q4 FY26 稿（Q4）
A6: 通訊與其他（企業網通、電信、消費、車用／工業） | B6: =B4-B5 -> 2.0943 | C6: 0.5851 | D6: 0.5678 | E6: =(2.0745-1.5179)*(1+q3_cog) -> 0.481459 | F6: =F4-F5 -> 0.605161 | G6: =SUM(C6:F6) -> 2.23952 | H6: Verified／Derived | I6: FY2026：https://www.sec.gov/Archives/edgar/data/1835632/000183563226000006/q426_8kx1312026ex-991.htm；Q1 FY27：https://investor.marvell.com/sec-filings/all-sec-filings/content/0001835632-26-000014/q127_8kx522026ex-991.htm；Q2 FY27：https://investor.marvell.com/news-events/press-releases/detail/1031/marvell-technology-inc-reports-second-quarter-of-fiscal-year-2027-financial-results | J6: Q3 FY26 通訊與其他＝營收 2.0745 − 資料中心 1.5179；Q4 FY26 起公司只揭露兩類
A7: 資料中心：客製（XPU＋XPU attach） | B7: =cus26 -> 1.5 | G7: =cus26*(1+g_cus27) -> 1.875 | H7: Interested-party | I7: Q4 FY26 法說（2026-03-05）轉述：roic.ai 逐字稿（二手） | J7: FY2027＝FY2026 × (1＋g_cus27)
A8: 其中 XPU attach | B8: =att26 -> 0.2 | G8: =att27 -> 0.4 | H8: Interested-party | I8: Q4 FY26 法說（2026-03-05）轉述：roic.ai 逐字稿（二手） | J8: —
A9: 其中 XPU（＝客製 − attach） | B9: =B7-B8 -> 1.3 | G9: =G7-G8 -> 1.475 | H9: Derived | I9: — | J9: —
A10: 資料中心：交換器 | B10: =sw26 -> 0.3 | G10: =sw27 -> 0.65 | H10: Interested-party | I10: Q4 FY26 法說（2026-03-05）轉述：roic.ai 逐字稿（二手） | J10: —
A11: 資料中心：AEC 與 retimer | B11: =aec26 -> 0.2 | G11: =aec27 -> 0.45 | H11: Interested-party | I11: Q4 FY26 法說（2026-03-05）轉述：roic.ai 逐字稿（二手） | J11: —
A12: 資料中心：儲存與其他 | B12: =sto26 -> 0.65 | G12: =sto26*(1+g_sto) -> 0.6825 | H12: Assumed | I12: — | J12: —
A13: 資料中心：光互連（＝資料中心 − 上列；Derived） | B13: =B5-B7-B10-B11-B12 -> 3.4503 | G13: =G5-G7-G10-G11-G12 -> 6.10298 | H13: Derived | I13: — | J13: 含 PAM4 DSP、TIA／驅動器、相干 DSP／DCI、scale-up 光學
A14: 光互連年增（對照公司「超過 70%」） | G14: =G13/B13-1 -> 0.7688259 | H14: Derived | I14: — | J14: 公司 FY2027 說法：超過 70%（Q1 FY27 法說）
A15: non-GAAP 毛利 | B15: 4.8718 | C15: 1.4238 | D15: 1.614 | E15: =E4*q3_gm -> 1.827 | F15: =F4*q4_gm -> 2.141882 | G15: =SUM(C15:F15) -> 7.006682 | H15: Verified／Interested-party（Q3、Q4） | I15: FY2026：https://www.sec.gov/Archives/edgar/data/1835632/000183563226000006/q426_8kx1312026ex-991.htm；Q1 FY27：https://investor.marvell.com/sec-filings/all-sec-filings/content/0001835632-26-000014/q127_8kx522026ex-991.htm；Q2 FY27：https://investor.marvell.com/news-events/press-releases/detail/1031/marvell-technology-inc-reports-second-quarter-of-fiscal-year-2027-financial-results | J15: 交叉：Q2 FY27 稿的六個月合計（營收 5.1571、non-GAAP 營業利益 1.8501、non-GAAP 淨利 1.5839）＝Q1＋Q2（下方檢查列）；FY2026 資料中心＝四季加總（Q1 1.4406、Q2 1.4905、Q3 1.5179、Q4 1.6513）
A16: 毛利率 | B16: =B15/B4 -> 0.59451346 | C16: =C15/C4 -> 0.58888246 | D16: =D15/D4 -> 0.58920162 | E16: =E15/E4 -> 0.58 | F16: =F15/F4 -> 0.58 | G16: =G15/G4 -> 0.58389017 | H16: Derived | I16: — | J16: FY2026 59.5%；Q3 指引 57.5–58.5%
A17: non-GAAP 營業費用 | B17: 1.9808 | C17: 0.5769 | D17: 0.6108 | E17: =q3_opx -> 0.655 | F17: =co_opx27-C17-D17-E17 -> 0.7073 | G17: =SUM(C17:F17) -> 2.55 | H17: Verified／Interested-party | I17: FY2026：https://www.sec.gov/Archives/edgar/data/1835632/000183563226000006/q426_8kx1312026ex-991.htm；Q1 FY27：https://investor.marvell.com/sec-filings/all-sec-filings/content/0001835632-26-000014/q127_8kx522026ex-991.htm；Q2 FY27：https://investor.marvell.com/news-events/press-releases/detail/1031/marvell-technology-inc-reports-second-quarter-of-fiscal-year-2027-financial-results | J17: 交叉：Q2 FY27 稿的六個月合計（營收 5.1571、non-GAAP 營業利益 1.8501、non-GAAP 淨利 1.5839）＝Q1＋Q2（下方檢查列）；FY2026 資料中心＝四季加總（Q1 1.4406、Q2 1.4905、Q3 1.5179、Q4 1.6513）
A18: non-GAAP 營業利益 | B18: =B15-B17 -> 2.891 | C18: =C15-C17 -> 0.8469 | D18: =D15-D17 -> 1.0032 | E18: =E15-E17 -> 1.172 | F18: =F15-F17 -> 1.434582 | G18: =SUM(C18:F18) -> 4.456682 | H18: Derived | I18: FY2026：https://www.sec.gov/Archives/edgar/data/1835632/000183563226000006/q426_8kx1312026ex-991.htm；Q1 FY27：https://investor.marvell.com/sec-filings/all-sec-filings/content/0001835632-26-000014/q127_8kx522026ex-991.htm；Q2 FY27：https://investor.marvell.com/news-events/press-releases/detail/1031/marvell-technology-inc-reports-second-quarter-of-fiscal-year-2027-financial-results | J18: 公司揭露：FY2026 2.8910、Q1 0.8469、Q2 1.0032
A19: 營業利益率 | B19: =B18/B4 -> 0.3527933 | C19: =C18/C4 -> 0.35027711 | D19: =D18/D4 -> 0.36622495 | E19: =E18/E4 -> 0.37206349 | F19: =F18/F4 -> 0.38847031 | G19: =G18/G4 -> 0.37139017 | H19: Derived | I19: — | J19: 公司：Q4 FY27 進入 38–40% 目標區間
A20: non-GAAP 利息與其他淨損 | B20: 0.1514 | C20: 0.0401 | D20: 0.0303 | E20: =q3_oth -> 0.036 | F20: =q4_oth -> 0.036 | G20: =SUM(C20:F20) -> 0.1424 | H20: Verified／Interested-party | I20: FY2026：https://www.sec.gov/Archives/edgar/data/1835632/000183563226000006/q426_8kx1312026ex-991.htm；Q1 FY27：https://investor.marvell.com/sec-filings/all-sec-filings/content/0001835632-26-000014/q127_8kx522026ex-991.htm；Q2 FY27：https://investor.marvell.com/news-events/press-releases/detail/1031/marvell-technology-inc-reports-second-quarter-of-fiscal-year-2027-financial-results | J20: 交叉：Q2 FY27 稿的六個月合計（營收 5.1571、non-GAAP 營業利益 1.8501、non-GAAP 淨利 1.5839）＝Q1＋Q2（下方檢查列）；FY2026 資料中心＝四季加總（Q1 1.4406、Q2 1.4905、Q3 1.5179、Q4 1.6513）
A21: 稅前利益 | B21: =B18-B20 -> 2.7396 | C21: =C18-C20 -> 0.8068 | D21: =D18-D20 -> 0.9729 | E21: =E18-E20 -> 1.136 | F21: =F18-F20 -> 1.398582 | G21: =SUM(C21:F21) -> 4.314282 | H21: Derived | I21: FY2026：https://www.sec.gov/Archives/edgar/data/1835632/000183563226000006/q426_8kx1312026ex-991.htm；Q1 FY27：https://investor.marvell.com/sec-filings/all-sec-filings/content/0001835632-26-000014/q127_8kx522026ex-991.htm；Q2 FY27：https://investor.marvell.com/news-events/press-releases/detail/1031/marvell-technology-inc-reports-second-quarter-of-fiscal-year-2027-financial-results | J21: 交叉：Q2 FY27 稿的六個月合計（營收 5.1571、non-GAAP 營業利益 1.8501、non-GAAP 淨利 1.5839）＝Q1＋Q2（下方檢查列）；FY2026 資料中心＝四季加總（Q1 1.4406、Q2 1.4905、Q3 1.5179、Q4 1.6513）
A22: non-GAAP 稅率 | B22: 0.1 | C22: 0.11 | D22: 0.11 | E22: =q3_tx -> 0.11 | F22: =q4_tx -> 0.11 | G22: =G23/G21 -> 0.11 | H22: Verified／Interested-party | I22: FY2026：https://www.sec.gov/Archives/edgar/data/1835632/000183563226000006/q426_8kx1312026ex-991.htm；Q1 FY27：https://investor.marvell.com/sec-filings/all-sec-filings/content/0001835632-26-000014/q127_8kx522026ex-991.htm；Q2 FY27：https://investor.marvell.com/news-events/press-releases/detail/1031/marvell-technology-inc-reports-second-quarter-of-fiscal-year-2027-financial-results | J22: 交叉：Q2 FY27 稿的六個月合計（營收 5.1571、non-GAAP 營業利益 1.8501、non-GAAP 淨利 1.5839）＝Q1＋Q2（下方檢查列）；FY2026 資料中心＝四季加總（Q1 1.4406、Q2 1.4905、Q3 1.5179、Q4 1.6513）
A23: non-GAAP 所得稅 | B23: =B21*B22 -> 0.27396 | C23: =C21*C22 -> 0.088748 | D23: =D21*D22 -> 0.107019 | E23: =E21*E22 -> 0.12496 | F23: =F21*F22 -> 0.15384402 | G23: =SUM(C23:F23) -> 0.47457102 | H23: Derived | I23: FY2026：https://www.sec.gov/Archives/edgar/data/1835632/000183563226000006/q426_8kx1312026ex-991.htm；Q1 FY27：https://investor.marvell.com/sec-filings/all-sec-filings/content/0001835632-26-000014/q127_8kx522026ex-991.htm；Q2 FY27：https://investor.marvell.com/news-events/press-releases/detail/1031/marvell-technology-inc-reports-second-quarter-of-fiscal-year-2027-financial-results | J23: 交叉：Q2 FY27 稿的六個月合計（營收 5.1571、non-GAAP 營業利益 1.8501、non-GAAP 淨利 1.5839）＝Q1＋Q2（下方檢查列）；FY2026 資料中心＝四季加總（Q1 1.4406、Q2 1.4905、Q3 1.5179、Q4 1.6513）
A24: non-GAAP 淨利 | B24: =B21-B23 -> 2.46564 | C24: =C21-C23 -> 0.718052 | D24: =D21-D23 -> 0.865881 | E24: =E21-E23 -> 1.01104 | F24: =F21-F23 -> 1.244738 | G24: =SUM(C24:F24) -> 3.839711 | H24: Derived | I24: FY2026：https://www.sec.gov/Archives/edgar/data/1835632/000183563226000006/q426_8kx1312026ex-991.htm；Q1 FY27：https://investor.marvell.com/sec-filings/all-sec-filings/content/0001835632-26-000014/q127_8kx522026ex-991.htm；Q2 FY27：https://investor.marvell.com/news-events/press-releases/detail/1031/marvell-technology-inc-reports-second-quarter-of-fiscal-year-2027-financial-results | J24: 交叉：Q2 FY27 稿的六個月合計（營收 5.1571、non-GAAP 營業利益 1.8501、non-GAAP 淨利 1.5839）＝Q1＋Q2（下方檢查列）；FY2026 資料中心＝四季加總（Q1 1.4406、Q2 1.4905、Q3 1.5179、Q4 1.6513）
A25: 公司揭露 non-GAAP 淨利 | B25: 2.4656 | C25: 0.718 | D25: 0.8659 | H25: Verified | I25: FY2026：https://www.sec.gov/Archives/edgar/data/1835632/000183563226000006/q426_8kx1312026ex-991.htm；Q1 FY27：https://investor.marvell.com/sec-filings/all-sec-filings/content/0001835632-26-000014/q127_8kx522026ex-991.htm；Q2 FY27：https://investor.marvell.com/news-events/press-releases/detail/1031/marvell-technology-inc-reports-second-quarter-of-fiscal-year-2027-financial-results | J25: 交叉：Q2 FY27 稿的六個月合計（營收 5.1571、non-GAAP 營業利益 1.8501、non-GAAP 淨利 1.5839）＝Q1＋Q2（下方檢查列）；FY2026 資料中心＝四季加總（Q1 1.4406、Q2 1.4905、Q3 1.5179、Q4 1.6513）
A26: non-GAAP 稀釋股數（十億股） | B26: 0.8697 | C26: 0.8933 | D26: 0.9212 | E26: =q3_sh -> 0.921 | F26: =q4_sh -> 0.925 | G26: =AVERAGE(C26:F26) -> 0.915125 | H26: Verified／Interested-party（Q3）／Assumed（Q4） | I26: FY2026：https://www.sec.gov/Archives/edgar/data/1835632/000183563226000006/q426_8kx1312026ex-991.htm；Q1 FY27：https://investor.marvell.com/sec-filings/all-sec-filings/content/0001835632-26-000014/q127_8kx522026ex-991.htm；Q2 FY27：https://investor.marvell.com/news-events/press-releases/detail/1031/marvell-technology-inc-reports-second-quarter-of-fiscal-year-2027-financial-results | J26: 交叉：Q2 FY27 稿的六個月合計（營收 5.1571、non-GAAP 營業利益 1.8501、non-GAAP 淨利 1.5839）＝Q1＋Q2（下方檢查列）；FY2026 資料中心＝四季加總（Q1 1.4406、Q2 1.4905、Q3 1.5179、Q4 1.6513）
A27: non-GAAP EPS | B27: =B24/B26 -> 2.8350466 | C27: =C24/C26 -> 0.80381955 | D27: =D24/D26 -> 0.93994898 | E27: =E24/E26 -> 1.0977633 | F27: =F24/F26 -> 1.3456627 | G27: =G24/G26 -> 4.1958322 | H27: Derived | I27: 淨利 ÷ 稀釋股數 | J27: —
A28: 公司揭露 non-GAAP EPS | B28: 2.84 | C28: 0.8 | D28: 0.94 | H28: Verified | I28: FY2026：https://www.sec.gov/Archives/edgar/data/1835632/000183563226000006/q426_8kx1312026ex-991.htm；Q1 FY27：https://investor.marvell.com/sec-filings/all-sec-filings/content/0001835632-26-000014/q127_8kx522026ex-991.htm；Q2 FY27：https://investor.marvell.com/news-events/press-releases/detail/1031/marvell-technology-inc-reports-second-quarter-of-fiscal-year-2027-financial-results | J28: 交叉：Q2 FY27 稿的六個月合計（營收 5.1571、non-GAAP 營業利益 1.8501、non-GAAP 淨利 1.5839）＝Q1＋Q2（下方檢查列）；FY2026 資料中心＝四季加總（Q1 1.4406、Q2 1.4905、Q3 1.5179、Q4 1.6513）
A29: 檢查：淨利 − 公司揭露（應約為 0；四捨五入） | B29: =B24-B25 -> 4e-05 | C29: =C24-C25 -> 5.2e-05 | D29: =D24-D25 -> -1.9e-05 | H29: — | I29: — | J29: —
A30: 檢查：Q1＋Q2 − 六個月合計（營收、營業利益、淨利；應約為 0） | G30: =(C4+D4-5.1571)+(C18+D18-1.8501)+(C24+D24-1.5839) -> 3.3e-05 | H30: — | I30: https://investor.marvell.com/news-events/press-releases/detail/1031/marvell-technology-inc-reports-second-quarter-of-fiscal-year-2027-financial-results（六個月欄） | J30: —
A32: FY2027 錨點與共識、公司展望的距離（參考；校準未使用共識）
A33: FY2027 營收 ÷ 共識 − 1 | B33: =G4/cons_rev27-1 -> -0.0057995029
A34: FY2027 EPS ÷ 共識 − 1 | B34: =G27/cons_eps27-1 -> -0.005726957
A35: FY2027 資料中心年增 | B35: =G5/B5-1 -> 0.6
A36: FY2027 營收年增 | B36: =G4/B4-1 -> 0.46437898
A37: FY2027 營業費用年增 | B37: =G17/B17-1 -> 0.28735864
A38: 營業費用彈性（營業費用年增 ÷ 營收年增；FY2027 錨點） | B38: =B37/B36 -> 0.618802
A40: 檢查：分部合計 − 合併營收 | B40: =ROUND(B5+B6-B4,3) -> 0 | C40: =ROUND(C5+C6-C4,3) -> 0 | D40: =ROUND(D5+D6-D4,3) -> 0 | E40: =ROUND(E5+E6-E4,3) -> 0 | F40: =ROUND(F5+F6-F4,3) -> 0 | G40: =ROUND(G5+G6-G4,3) -> 0
A41: 分部原則第 3 條（2026-10-28 追加）：終端市場別（單一應報導部門）；分部宣告見 segments.json

Sheet Units
A1: Units — Marvell 的 XPU 與光晶片組規格（情境 A）。ASIC 核心售價、HBM 代購比例取自 Broadcom 模型（本專案權威，唯讀）；顆數：百萬顆（日曆年；與 HBM、台積電、網通、NVIDIA、Broadcom 模型同一份）；每顆價：US$K
A3: 項目 | B3: 單位 | C3: CY2026（FY2027） | D3: CY2027（FY2028） | E3: CY2028（FY2029） | F3: CY2029（FY2030） | G3: 說明
A4: 1. XPU 每顆規格（情境 A；Marvell 營收口徑＝核心售價＋代購 HBM，乘 k_x）
A5: Marvell 份額：AWS Trainium | B5: % | C5: =PL!D76 -> 0.1 | D5: =PL!E76 -> 0.1 | E5: =PL!F76 -> 0.08 | F5: =PL!G76 -> 0.08 | G5: In 頁 B 節（Assumed）
A6: Marvell 顆數：AWS Trainium | B6: 百萬顆 | C6: =PL!D79 -> 0.2 | D6: =PL!E79 -> 0.25 | E6: =PL!F79 -> 0.24 | F6: =PL!G79 -> 0.276 | G6: 市場層顆數 × 份額
A7: 每顆 HBM 金額：AWS Trainium | B7: US$K | C7: =PL!D89 -> 1.606 | D7: =PL!E89 -> 3.78432 | E7: =PL!F89 -> 5.7816 | F7: =PL!G89 -> 5.49252 | G7: 容量 × HBM 單價（情境 A）
A8: 每顆 Marvell 營收（校準後）：AWS Trainium | B8: US$K | C8: =PL!D92*PL!$D$96 -> 5.9070008 | D8: =PL!E92*PL!$D$96 -> 6.9563107 | E8: =PL!F92*PL!$D$96 -> 7.9184126 | F8: =PL!G92*PL!$D$96 -> 7.779161 | G8: （核心＋代購比例 × HBM）× k_x
A9: Marvell 份額：其他 ASIC（MTIA、Maia、Ascend 等） | B9: % | C9: =PL!D77 -> 0.05 | D9: =PL!E77 -> 0.06 | E9: =PL!F77 -> 0.15 | F9: =PL!G77 -> 0.15 | G9: In 頁 B 節（Assumed）
A10: Marvell 顆數：其他 ASIC（MTIA、Maia、Ascend 等） | B10: 百萬顆 | C10: =PL!D80 -> 0.05 | D10: =PL!E80 -> 0.27 | E10: =PL!F80 -> 0.75 | F10: =PL!G80 -> 0.8625 | G10: 市場層顆數 × 份額
A11: 每顆 HBM 金額：其他 ASIC（MTIA、Maia、Ascend 等） | B11: US$K | C11: =PL!D90 -> 2.19 | D11: =PL!E90 -> 5.256 | E11: =PL!F90 -> 7.227 | F11: =PL!G90 -> 6.86565 | G11: 容量 × HBM 單價（情境 A）
A12: 每顆 Marvell 營收（校準後）：其他 ASIC（MTIA、Maia、Ascend 等） | B12: US$K | C12: =PL!D93*PL!$D$96 -> 5.8719968 | D12: =PL!E93*PL!$D$96 -> 7.3489076 | E12: =PL!F93*PL!$D$96 -> 8.2983502 | F12: =PL!G93*PL!$D$96 -> 8.1242857 | G12: （核心＋代購比例 × HBM）× k_x
A13: Marvell 份額：Google TPU | B13: % | C13: =PL!D78 -> 0 | D13: =PL!E78 -> 0 | E13: =PL!F78 -> 0.05 | F13: =PL!G78 -> 0.05 | G13: In 頁 B 節（Assumed）
A14: Marvell 顆數：Google TPU | B14: 百萬顆 | C14: =PL!D81 -> 0 | D14: =PL!E81 -> 0 | E14: =PL!F81 -> 0.35 | F14: =PL!G81 -> 0.4025 | G14: 市場層顆數 × 份額
A15: 每顆 HBM 金額：Google TPU | B15: US$K | C15: =PL!D91 -> 2.8032 | D15: =PL!E91 -> 6.57 | E15: =PL!F91 -> 8.325504 | F15: =PL!G91 -> 7.9092288 | G15: 容量 × HBM 單價（情境 A）
A16: 每顆 Marvell 營收（校準後）：Google TPU | B16: US$K | C16: =PL!D94*PL!$D$96 -> 7.7730658 | D16: =PL!E94*PL!$D$96 -> 9.5875562 | E16: =PL!F94*PL!$D$96 -> 10.433193 | F16: =PL!G94*PL!$D$96 -> 10.232671 | G16: （核心＋代購比例 × HBM）× k_x
A18: 2. 份額加總檢查（Broadcom 模型份額＋Marvell 份額 ≤ 100%；其餘為 MediaTek、世芯、創意、華為等）
A19: Broadcom＋Marvell：Google TPU | B19: % | C19: =av_tpu_26+PL!D78 -> 0.9 | D19: =av_tpu_27+PL!E78 -> 0.8 | E19: =av_tpu_28+PL!F78 -> 0.8 | F19: =av_tpu_28+PL!G78 -> 0.8 | G19: Broadcom 份額讀 avgo 成品 In 頁
A20: Broadcom＋Marvell：其他 ASIC（MTIA、Maia、Ascend 等） | B20: % | C20: =av_oth_26+PL!D77 -> 0.4 | D20: =av_oth_27+PL!E77 -> 0.61 | E20: =av_oth_28+PL!F77 -> 0.7 | F20: =av_oth_28+PL!G77 -> 0.7 | G20: Broadcom 份額讀 avgo 成品 In 頁
A22: 3. 光晶片組（情境 A）
A23: 光模組數量 | B23: 百萬個 | C23: =PL!D105 -> 45.774249 | D23: =PL!E105 -> 66.950894 | E23: =PL!F105 -> 68.225294 | F23: =PL!G105 -> 85.805647
A24: 光晶片組市場 | B24: US$B | C24: =PL!D108 -> 5.5501277 | D24: =PL!E108 -> 8.4960684 | E24: =PL!F108 -> 8.2893732 | F24: =PL!G108 -> 9.481524
A25: Marvell AI 光晶片組（未校準） | B25: US$B | C25: =PL!D110 -> 3.607583 | D25: =PL!E110 -> 5.3525231 | E25: =PL!F110 -> 4.9736239 | F25: =PL!G110 -> 5.4992839
A26: Marvell 光互連（校準後，含相干） | B26: US$B | C26: =PL!D113 -> 6.10298 | D26: =PL!E113 -> 8.7545925 | E26: =PL!F113 -> 8.3633811 | F26: =PL!G113 -> 9.3000434
A27: Marvell 光互連 ÷ 光晶片組市場 | B27: % | C27: =C26/C24 -> 1.0996107 | D27: =D26/D24 -> 1.0304287 | E27: =E26/E24 -> 1.008928 | F27: =F26/F24 -> 0.98085956
A29: 4. 校準值（只用 FY2027 已發生的實績、當季指引與公司全年展望；不用共識、不用 FY2028 起的展望）
A30: XPU 校準係數 k_x | C30: =PL!D96 -> 0.80284343 | G30: FY2027 錨點 XPU ÷ 未校準由下而上；顆數、份額、核心單價的合併係數
A31: 光互連校準係數 k_o | C31: =PL!D112 -> 1.4422343 | G31: （錨點光互連 − 相干）÷ 未校準 AI 光晶片組
A32: XPU 核心毛利率 m_core | C32: =PL!D126 -> 0.43599463 | G32: 讓 FY2027 毛利率等於錨點的殘差（Derived）
A33: FY2027 錨點 XPU | C33: =a27_xpu -> 1.475 | G33: 客製 − attach
A34: FY2027 錨點光互連 | C34: =a27_ic -> 6.10298 | G34: 資料中心差額

Sheet PL
A1: PL — Marvell 損益（US$B；non-GAAP）。FY2026A 實績、FY2027 錨點（Q1、Q2 實績＋Q3 指引＋Q4 由全年展望推得），FY2028 起為由下而上。FY(t)≈CY(t−1)。三情境各一個完整推導區塊（本頁下方），頂端為摘要。FY2027 三情境相同；FY2028（≈CY2027）只差在網通 CPO 情境（A 替代快、C 慢）；顆數係數從 CY2028＝FY2029 開始；HBM 價格 2027 三情境相同
A3: 情境／項目 | B3: 單位 | C3: FY2026A | D3: FY2027（錨點） | E3: FY2028 | F3: FY2029 | G3: FY2030 | H3: 說明
A4: 情境 A
A5: 營收 | B5: US$B | C5: =C121 -> 8.1946 | D5: =D121 -> 12 | E5: =E121 -> 18.346206 | F5: =F121 -> 27.418043 | G5: =G121 -> 31.872151
A6: 營收年增 | B6: % | D6: =D123 -> 0.46437898 | E6: =E123 -> 0.52885048 | F6: =F123 -> 0.49448031 | G6: =G123 -> 0.16245171
A7: 資料中心 | B7: US$B | C7: =C118 -> 6.1003 | D7: =D118 -> 9.76048 | E7: =E118 -> 16.0395 | F7: =F118 -> 25.042137 | G7: =G118 -> 29.424967
A8: 客製（XPU＋attach） | B8: US$B | C8: =C102 -> 1.5 | D8: =D102 -> 1.875 | E8: =E102 -> 4.7232827 | F8: =F102 -> 13.275799 | G8: =G102 -> 15.522895
A9: 光互連 | B9: US$B | C9: =C113 -> 3.4503 | D9: =D113 -> 6.10298 | E9: =E113 -> 8.7545925 | F9: =F113 -> 8.3633811 | G9: =G113 -> 9.3000434
A10: 通訊與其他 | B10: US$B | C10: =C119 -> 2.0943 | D10: =D119 -> 2.23952 | E10: =E119 -> 2.3067056 | F10: =F119 -> 2.3759068 | G10: =G119 -> 2.447184
A11: 毛利率 | B11: % | C11: =C128 -> 0.59451346 | D11: =D128 -> 0.58389017 | E11: =E128 -> 0.55492562 | F11: =F128 -> 0.47685539 | G11: =G128 -> 0.48145488
A12: 營業利益率 | B12: % | C12: =C133 -> 0.3527933 | D12: =D133 -> 0.37139017 | E12: =E133 -> 0.37917896 | F12: =F133 -> 0.33018347 | G12: =G133 -> 0.34503161
A13: 淨利（non-GAAP） | B13: US$B | C13: =C136 -> 2.46564 | D13: =D136 -> 3.839711 | E13: =E136 -> 5.9216509 | F13: =F136 -> 7.7455968 | G13: =G136 -> 9.4368027
A14: EPS（non-GAAP） | B14: US$ | C14: =C138 -> 2.8350466 | D14: =D138 -> 4.1958322 | E14: =E138 -> 6.4386722 | F14: =F138 -> 8.3799677 | G14: =G138 -> 10.15889
A15: EPS 年增 | B15: % | D15: =D139 -> 0.47998706 | E15: =E139 -> 0.53453995 | F15: =F139 -> 0.30150555 | G15: =G139 -> 0.21228276
A17: 情境 B
A18: 營收 | B18: US$B | C18: =C193 -> 8.1946 | D18: =D193 -> 12 | E18: =E193 -> 18.508724 | F18: =F193 -> 21.924919 | G18: =G193 -> 27.097511
A19: 營收年增 | B19: % | D19: =D195 -> 0.46437898 | E19: =E195 -> 0.54239363 | F19: =F195 -> 0.18457218 | G19: =G195 -> 0.23592298
A20: 資料中心 | B20: US$B | C20: =C190 -> 6.1003 | D20: =D190 -> 9.76048 | E20: =E190 -> 16.202018 | F20: =F190 -> 19.549012 | G20: =G190 -> 24.650327
A21: 客製（XPU＋attach） | B21: US$B | C21: =C174 -> 1.5 | D21: =D174 -> 1.875 | E21: =E174 -> 4.7232827 | F21: =F174 -> 9.4285952 | G21: =G174 -> 11.966815
A22: 光互連 | B22: US$B | C22: =C185 -> 3.4503 | D22: =D185 -> 6.10298 | E22: =E185 -> 8.9171102 | F22: =F185 -> 7.2475607 | G22: =G185 -> 8.6532757
A23: 通訊與其他 | B23: US$B | C23: =C191 -> 2.0943 | D23: =D191 -> 2.23952 | E23: =E191 -> 2.3067056 | F23: =F191 -> 2.3759068 | G23: =G191 -> 2.447184
A24: 毛利率 | B24: % | C24: =C200 -> 0.59451346 | D24: =D200 -> 0.58389017 | E24: =E200 -> 0.55558482 | F24: =F200 -> 0.50431512 | G24: =G200 -> 0.50469176
A25: 營業利益率 | B25: % | C25: =C205 -> 0.3527933 | D25: =D205 -> 0.37139017 | E25: =E205 -> 0.38044838 | F25: =F205 -> 0.34282298 | G25: =G205 -> 0.35861308
A26: 淨利（non-GAAP） | B26: US$B | C26: =C208 -> 2.46564 | D26: =D208 -> 3.839711 | E26: =E208 -> 5.9957041 | F26: =F208 -> 6.4087385 | G26: =G208 -> 8.3237441
A27: EPS（non-GAAP） | B27: US$ | C27: =C210 -> 2.8350466 | D27: =D210 -> 4.1958322 | E27: =E210 -> 6.5191911 | F27: =F210 -> 6.9336195 | G27: =G210 -> 8.9606624
A28: EPS 年增 | B28: % | D28: =D211 -> 0.47998706 | E28: =E211 -> 0.55373015 | F28: =F211 -> 0.063570534 | G28: =G211 -> 0.29234988
A30: 情境 C
A31: 營收 | B31: US$B | C31: =C265 -> 8.1946 | D31: =D265 -> 12 | E31: =E265 -> 18.589982 | F31: =F265 -> 17.235827 | G31: =G265 -> 20.273585
A32: 營收年增 | B32: % | D32: =D267 -> 0.46437898 | E32: =E267 -> 0.5491652 | F32: =F267 -> -0.072843279 | G32: =G267 -> 0.17624673
A33: 資料中心 | B33: US$B | C33: =C262 -> 6.1003 | D33: =D262 -> 9.76048 | E33: =E262 -> 16.283277 | F33: =F262 -> 14.85992 | G33: =G262 -> 17.826401
A34: 客製（XPU＋attach） | B34: US$B | C34: =C246 -> 1.5 | D34: =D246 -> 1.875 | E34: =E246 -> 4.7232827 | F34: =F246 -> 6.6882893 | G34: =G246 -> 8.0946589
A35: 光互連 | B35: US$B | C35: =C257 -> 3.4503 | D35: =D257 -> 6.10298 | E35: =E257 -> 8.9983691 | F35: =F257 -> 5.8288748 | G35: =G257 -> 6.6544935
A36: 通訊與其他 | B36: US$B | C36: =C263 -> 2.0943 | D36: =D263 -> 2.23952 | E36: =E263 -> 2.3067056 | F36: =F263 -> 2.3759068 | G36: =G263 -> 2.447184
A37: 毛利率 | B37: % | C37: =C272 -> 0.59451346 | D37: =D272 -> 0.58389017 | E37: =E272 -> 0.55591009 | F37: =F272 -> 0.51982298 | G37: =G272 -> 0.51887093
A38: 營業利益率 | B38: % | C38: =C277 -> 0.3527933 | D38: =D277 -> 0.37139017 | E38: =E277 -> 0.38107477 | F38: =F277 -> 0.32182291 | G38: =G277 -> 0.33570485
A39: 淨利（non-GAAP） | B39: US$B | C39: =C280 -> 2.46564 | D39: =D280 -> 3.839711 | E39: =E280 -> 6.0327307 | F39: =F280 -> 4.6952891 | G39: =G280 -> 5.7906686
A40: EPS（non-GAAP） | B40: US$ | C40: =C282 -> 2.8350466 | D40: =D282 -> 4.1958322 | E40: =E282 -> 6.5594505 | F40: =F282 -> 5.0798372 | G40: =G282 -> 6.2337604
A41: EPS 年增 | B41: % | D41: =D283 -> 0.47998706 | E41: =E283 -> 0.56332525 | F41: =F283 -> -0.2255697 | G41: =G283 -> 0.22715752
A43: 核對（應為 0）：FY2027 由下而上營收 − 錨點；FY2027 由下而上毛利 − 錨點（k_x、k_o、m_core 校準恆等式）
A44: 情境 A：營收差（US$B） | D44: =D122-a27_rev -> 0
...

Sheet Val
A1: Val — P/E 估值（美元；non-GAAP EPS）。結論用「現價 ÷ FY2028 EPS（模型與共識）」與十年 P/E 規則值。GAAP EPS 多年為負（攤銷、併購），十年倍數改用「會計年度年底股價 ÷ 該年度 non-GAAP EPS」（Derived；與模型 EPS 同口徑）
A2: 循環位置：共用規則（tools/cycle_position.py classify_lag，lag＝1：FY(t) 對照日曆年 t−1，與 NVIDIA 相同），見頂年度讀設備市場模型（A 2029、B 2028、C 2027）；FY2028 判定 A 中段、B 中段、C 見頂
A3: 0. 目標價（DCF 與 Comparable 加權；v0.2 新增，Andy 2026-10-25）
A4: 0.1 DCF（股東權益現金流，FY2027–FY2032 明確期＋FY2032 後永續）
A5: 項目 | B5: A | C5: B | D5: C | E5: 說明 | F5: 折現年數 t | G5: 期內占比（基準日後）
A6: 情境 EPS（FY2027–FY2032） | E6: 引用 PL 頁延伸表（上游結束後為收斂法）；三情境欄 B／C／D＝A／B／C
A7: FY2027 | B7: =PL!D295 -> 4.1958322 | C7: =PL!D304 -> 4.1958322 | D7: =PL!D313 -> 4.1958322 | F7: 0.083333 | G7: 0.083333
A8: FY2028 | B8: =PL!E295 -> 6.4386722 | C8: =PL!E304 -> 6.5191911 | D8: =PL!E313 -> 6.5594505 | F8: 1.083333 | G8: 1
A9: FY2029 | B9: =PL!F295 -> 8.3799677 | C9: =PL!F304 -> 6.9336195 | D9: =PL!F313 -> 5.0798372 | F9: 2.083333 | G9: 1
A10: FY2030 | B10: =PL!G295 -> 10.15889 | C10: =PL!G304 -> 8.9606624 | D10: =PL!G313 -> 6.2337604 | F10: 3.083333 | G10: 1
A11: FY2031 | B11: =PL!H295 -> 11.232658 | C11: =PL!H304 -> 9.63885 | D11: =PL!H313 -> 6.130243 | F11: 4.083333 | G11: 1
A12: FY2032 | B12: =PL!I295 -> 11.847381 | C12: =PL!I304 -> 9.449556 | D12: =PL!I313 -> 5.5304348 | F12: 5.083333 | G12: 1
A13: 股東現金流＝EPS ×（1 − tp_g ÷ tp_roe） | B13: =1-MIN(0.8,tp_g/tp_roe) -> 0.8 | E13: B 欄＝可發放比例（1 − 再投資率；再投資率＝tp_g ÷ tp_roe，上限 0.8）；下列六列＝EPS × 可發放比例 × 期內占比
A14: FY2027 股東現金流 | B14: =B7*$B$13*$G$7 -> 0.27972103 | C14: =C7*$B$13*$G$7 -> 0.27972103 | D14: =D7*$B$13*$G$7 -> 0.27972103
A15: FY2028 股東現金流 | B15: =B8*$B$13*$G$8 -> 5.1509378 | C15: =C8*$B$13*$G$8 -> 5.2153529 | D15: =D8*$B$13*$G$8 -> 5.2475604
A16: FY2029 股東現金流 | B16: =B9*$B$13*$G$9 -> 6.7039741 | C16: =C9*$B$13*$G$9 -> 5.5468956 | D16: =D9*$B$13*$G$9 -> 4.0638698
A17: FY2030 股東現金流 | B17: =B10*$B$13*$G$10 -> 8.1271122 | C17: =C10*$B$13*$G$10 -> 7.1685299 | D17: =D10*$B$13*$G$10 -> 4.9870084
A18: FY2031 股東現金流 | B18: =B11*$B$13*$G$11 -> 8.9861266 | C18: =C11*$B$13*$G$11 -> 7.71108 | D18: =D11*$B$13*$G$11 -> 4.9041944
A19: FY2032 股東現金流 | B19: =B12*$B$13*$G$12 -> 9.4779047 | C19: =C12*$B$13*$G$12 -> 7.5596448 | D19: =D12*$B$13*$G$12 -> 4.4243479
A20: 永續價值（FY2032 年底；FY2032 現金流 ×(1＋tp_g) ÷ (tp_r − tp_g)） | B20: =B19*(1+tp_g)/(tp_r-tp_g) -> 164.28368 | C20: =C19*(1+tp_g)/(tp_r-tp_g) -> 131.03384 | D20: =D19*(1+tp_g)/(tp_r-tp_g) -> 76.688696
A21: DCF 情境每股價值（折現率 tp_r） | B21: =MAX(0,B14/(1+tp_r)^$F$7+B15/(1+tp_r)^$F$8+B16/(1+tp_r)^$F$9+B17/(1+tp_r)^$F$10+B18/(1+tp_r)^$F$11+B19/(1+tp_r)^$F$12+B20/(1+tp_r)^$F$12) -> 129.60532 | C21: =MAX(0,C14/(1+tp_r)^$F$7+C15/(1+tp_r)^$F$8+C16/(1+tp_r)^$F$9+C17/(1+tp_r)^$F$10+C18/(1+tp_r)^$F$11+C19/(1+tp_r)^$F$12+C20/(1+tp_r)^$F$12) -> 105.47236 | D21: =MAX(0,D14/(1+tp_r)^$F$7+D15/(1+tp_r)^$F$8+D16/(1+tp_r)^$F$9+D17/(1+tp_r)^$F$10+D18/(1+tp_r)^$F$11+D19/(1+tp_r)^$F$12+D20/(1+tp_r)^$F$12) -> 65.348963 | E21: 基準日 2026 年底；明確期現金流與永續價值依 F 欄年數折現；小於 0 時取 0（Andy 2026-10-25 12:22）
A22: 其中：永續價值現值占比 | B22: =B20/(1+tp_r)^$F$12/B21 -> 0.78083415 | C22: =C20/(1+tp_r)^$F$12/C21 -> 0.76530053 | D22: =D20/(1+tp_r)^$F$12/D21 -> 0.7229027
A23: DCF 目標價（情境加權） | B23: =(tp_wA*B21+tp_wB*C21+tp_wC*D21)*(1+tp_r) -> 115.15633 | E23: Σ 權重 × 情境價值 ×(1＋tp_r)：推到約 12 個月後
A25: 0.2 Comparable（市場主流同業前瞻 P/E）
A26: 同業與前瞻 P/E | B26: 代號 | C26: 前瞻 12 月 P/E | D26: 日期 | E26: 來源 | F26: 標記
A27: Broadcom | B27: AVGO | C27: 18.52 | D27: 2026-10-23 | E27: stockanalysis.com 統計頁（Forward PE） | F27: Interested-party（資料商彙整賣方預估）
A28: NVIDIA | B28: NVDA | C28: 17.44 | D28: 2026-10-23 | E28: 同上 | F28: Interested-party（同上）
A29: AMD | B29: AMD | C29: 46.49 | D29: 2026-10-23 | E29: 同上 | F29: Interested-party（同上）
A30: Astera Labs | B30: ALAB | C30: 45.77 | D30: 2026-10-23 | E30: 同上 | F30: Interested-party（同上）
A31: Credo | B31: CRDO | C31: 20.19 | D31: 2026-10-23 | E31: 同上 | F31: Interested-party（同上）
A32: 同業選擇 | E32: 券商常用的客製 ASIC 與 AI 互連同業（Broadcom 為直接競爭者；Astera Labs、Credo 為互連）；不含 A 股（Andy 11:53）。前瞻 P/E 口徑為資料商的未來 12 個月共識 EPS，各家 GAAP／non-GAAP 口徑不一
A33: 同業前瞻 P/E 中位數 | B33: =MEDIAN(C27:C31) -> 20.19
A34: 各情境 12 個月後的前瞻 EPS | B34: =0.25*PL!E295+0.75*PL!F295 -> 7.8946438 | C34: =0.25*PL!E304+0.75*PL!F304 -> 6.8300124 | D34: =0.25*PL!E313+0.75*PL!F313 -> 5.4497405 | E34: 會計年度 FY(t)＝t−1 年 2 月～t 年 1 月：約 12 個月後（2027-10 底）的未來 12 個月＝2027-11～2028-10＝FY2028 的 3 個月＋FY2029 的 9 個月（3/12 × FY2028＋9/12 × FY2029）
A35: 12 個月後的前瞻 EPS（情境加權） | B35: =tp_wA*B34+tp_wB*C34+tp_wC*D34 -> 6.8733475
A36: Comparable 目標價 | B36: =B33*B35 -> 138.77289 | E36: 同業前瞻 P/E 中位數 × 12 個月後的前瞻 EPS（情境加權）
A38: 0.3 結論
A39: 項目 | B39: 數值 | C39: 對照 | D39: 對照 | E39: 說明
A40: 目標價（DCF 與 Comparable 加權） | B40: =tp_w_dcf*B23+(1-tp_w_dcf)*tp_comp_adj -> 109.67095 | E40: ="DCF 權重 "&TEXT(tp_w_dcf,"0%")&"、Comparable 權重 "&TEXT(1-tp_w_dcf,"0%")&"（In 頁 tp_w_dcf，Andy 可改）" -> DCF 權重 50%、Comparable 權重 50%（In 頁 tp_w_dcf，Andy 可改）
A41: Comparable 目標價（市場主流同業法） | B41: =B36 -> 138.77289
A42: 市場共識目標價 | B42: =cons_tp -> 341.44 | E42: stockanalysis.com：46 位分析師平均目標價（2026-10-25 頁面）；Interested-party
...

Sheet Recon
A1: Recon — 本模型 vs 公司展望、投資人日目標、共識。只作事後對照，不為對上數字而調參數。公司 FY2028 起的展望（營收 $20B、資料中心 $18B、FY2029 客製 >$12B）為 Interested-party，不用於校準
A3: 項目 | B3: 對照值 | C3: 模型 A | D3: 差距 A | E3: 模型 B | F3: 差距 B | G3: 模型 C | H3: 差距 C | I3: 對照來源 | J3: 說明
A4: A. 營收 vs 公司展望（Interested-party；FY2028 起校準未使用）
A5: FY2027 營收 vs 公司展望 12 | B5: =co_rev27 -> 12 | C5: =PL!D121 -> 12 | D5: =C5/B5-1 -> 0 | E5: =PL!D193 -> 12 | F5: =E5/B5-1 -> 0 | G5: =PL!D265 -> 12 | H5: =G5/B5-1 -> 0 | I5: 公司（Q2 FY27 法說） | J5: 錨點：第四季由全年展望推得，恆等
A6: FY2028 營收 vs 投資人日 20 | B6: =co_rev28 -> 20 | C6: =PL!E121 -> 18.346206 | D6: =C6/B6-1 -> -0.082689711 | E6: =PL!E193 -> 18.508724 | F6: =E6/B6-1 -> -0.074563824 | G6: =PL!E265 -> 18.589982 | H6: =G6/B6-1 -> -0.07050088 | I6: 投資人日（二手） | J6: 公司展望一年內上修五次（$13B → $20B）
A7: FY2028 資料中心 vs 投資人日 18 | B7: =co_dc28 -> 18 | C7: =PL!E118 -> 16.0395 | D7: =C7/B7-1 -> -0.10891666 | E7: =PL!E190 -> 16.202018 | F7: =E7/B7-1 -> -0.099887893 | G7: =PL!E262 -> 16.283277 | H7: =G7/B7-1 -> -0.095373511 | I7: Stocktwits 轉述（單一來源）
A8: FY2028 客製 vs 「至少倍增」（FY2027 錨點 × 2） | B8: =2*a27_cus -> 3.75 | C8: =PL!E102 -> 4.7232827 | D8: =C8/B8-1 -> 0.25954206 | E8: =PL!E174 -> 4.7232827 | F8: =E8/B8-1 -> 0.25954206 | G8: =PL!E246 -> 4.7232827 | H8: =G8/B8-1 -> 0.25954206 | I8: 公司（Q2 FY27 法說）
A9: FY2029 客製 vs 投資人日 >12 | B9: =co_cus29 -> 12 | C9: =PL!F102 -> 13.275799 | D9: =C9/B9-1 -> 0.10631661 | E9: =PL!F174 -> 9.4285952 | F9: =E9/B9-1 -> -0.21428373 | G9: =PL!F246 -> 6.6882893 | H9: =G9/B9-1 -> -0.44264256 | I9: 投資人日（二手） | J9: 含 Google 認股權證案的機率加權部分
A10: FY2028 EPS vs 公司 3 月說法「遠高於 $5」 | B10: =co_eps28 -> 5 | C10: =PL!E138 -> 6.4386722 | D10: =C10/B10-1 -> 0.28773444 | E10: =PL!E210 -> 6.5191911 | F10: =E10/B10-1 -> 0.30383821 | G10: =PL!E282 -> 6.5594505 | H10: =G10/B10-1 -> 0.3118901 | I10: Q4 FY26 法說（當時營收展望 $15B）
A11: B. What must be true：要達到 FY2028 營收 $20B，非通訊部分需要是模型資料中心的幾倍
A12: FY2028：所需資料中心倍數（＝(20 − 模型通訊) ÷ 模型資料中心） | C12: =(co_rev28-PL!E119)/PL!E118 -> 1.1031076 | E12: =(co_rev28-PL!E191)/PL!E190 -> 1.0920426 | G12: =(co_rev28-PL!E263)/PL!E262 -> 1.086593 | I12: — | J12: 倍數 >1＝公司展望需要比市場層更多的 Marvell 出貨
A13: FY2028：差額（US$B） | C13: =co_rev28-PL!E121 -> 1.6537942 | E13: =co_rev28-PL!E193 -> 1.4912765 | G13: =co_rev28-PL!E265 -> 1.4100176 | I13: — | J13: 若全由客製補上，所需客製 ÷ 模型客製見下一列
A14: FY2028：所需客製倍數（差額全由客製補） | C14: =(co_rev28-PL!E121+PL!E102)/PL!E102 -> 1.3501366 | E14: =(co_rev28-PL!E193+PL!E174)/PL!E174 -> 1.3157288 | G14: =(co_rev28-PL!E265+PL!E246)/PL!E246 -> 1.2985249 | I14: —
A15: C. 共識（校準未使用）
A16: FY2027 營收 vs 共識 | B16: =cons_rev27 -> 12.07 | C16: =PL!D121 -> 12 | D16: =C16/B16-1 -> -0.0057995029 | E16: =PL!D193 -> 12 | F16: =E16/B16-1 -> -0.0057995029 | G16: =PL!D265 -> 12 | H16: =G16/B16-1 -> -0.0057995029 | I16: StockAnalysis | J16: 錨點
A17: FY2027 EPS vs 共識 | B17: =cons_eps27 -> 4.22 | C17: =PL!D138 -> 4.1958322 | D17: =C17/B17-1 -> -0.005726957 | E17: =PL!D210 -> 4.1958322 | F17: =E17/B17-1 -> -0.005726957 | G17: =PL!D282 -> 4.1958322 | H17: =G17/B17-1 -> -0.005726957 | I17: StockAnalysis | J17: 錨點（Q4 依全年展望與 In 頁假設）
A18: FY2028 營收 vs 共識 | B18: =cons_rev28 -> 19.71 | C18: =PL!E121 -> 18.346206 | D18: =C18/B18-1 -> -0.069193009 | E18: =PL!E193 -> 18.508724 | F18: =E18/B18-1 -> -0.060947563 | G18: =PL!E265 -> 18.589982 | H18: =G18/B18-1 -> -0.056824841 | I18: StockAnalysis
A19: FY2028 EPS vs 共識 | B19: =cons_eps28 -> 7.33 | C19: =PL!E138 -> 6.4386722 | D19: =C19/B19-1 -> -0.12159997 | E19: =PL!E210 -> 6.5191911 | F19: =E19/B19-1 -> -0.11061513 | G19: =PL!E282 -> 6.5594505 | H19: =G19/B19-1 -> -0.10512272 | I19: StockAnalysis | J19: 差距主要來自營收（共識已接近公司 $20B）
A20: FY2028 共識隱含毛利率（EPS × 股數 ÷（1−稅）＋利息＋營業費用，÷ 共識營收） | B20: =(cons_eps28*PL!E137/(1-tx_f)+int_f+PL!E131)/cons_rev28 -> 0.56433417 | C20: =PL!E128 -> 0.55492562 | D20: =C20-B20 -> -0.0094085467 | E20: =PL!E200 -> 0.55558482 | F20: =E20-B20 -> -0.0087493484 | G20: =PL!E272 -> 0.55591009 | H20: =G20-B20 -> -0.0084240714 | I20: 推導（共識無毛利率） | J20: 以模型營業費用估算
A21: D. 產品線（FY2027 錨點拆分的一致性）
A22: FY2027 光互連年增 vs 公司「超過 70%」 | B22: =co_icg27 -> 0.7 | C22: =Q!G14 -> 0.7688259 | D22: =C22-B22 -> 0.068825899 | E22: =Q!G14 -> 0.7688259 | F22: =E22-B22 -> 0.068825899 | G22: =Q!G14 -> 0.7688259 | H22: =G22-B22 -> 0.068825899 | I22: 公司（Q1 FY27 法說，二手） | J22: 光互連為資料中心差額；差額含 scale-up 光學、相干 DSP
A23: FY2027 資料中心年增 vs 公司約 60% | B23: =co_dcg27 -> 0.6 | C23: =Q!B35 -> 0.6 | D23: =C23-B23 -> 0 | E23: =Q!B35 -> 0.6 | F23: =E23-B23 -> 0 | G23: =Q!B35 -> 0.6 | H23: =G23-B23 -> 0 | I23: 公司（Q2 FY27 法說） | J23: 錨點恆等
A24: CY2026 Marvell 光互連 ÷ 光晶片組市場 | C24: =Units!C27 -> 1.0996107 | E24: =Units!C27 -> 1.0996107 | G24: =Units!C27 -> 1.0996107 | I24: — | J24: 含相干與 k_o；>100% 表示市場層光模組金額偏低或光互連含 AI 後端以外
A25: CY2026 光模組：本專案 vs LightCounting 26 | B25: =rep_opt26 -> 26 | C25: =plug_26 -> 29.753262 | D25: =C25/B25-1 -> 0.14435623 | E25: =plug_26 -> 29.753262 | F25: =E25/B25-1 -> 0.14435623 | G25: =plug_26 -> 29.753262 | H25: =G25/B25-1 -> 0.14435623 | I25: markets/network；LightCounting（含 scale-up）
A26: FY2028 客製 ÷ 資料中心 | C26: =PL!E102/PL!E118 -> 0.29447817 | E26: =PL!E174/PL!E190 -> 0.29152435 | G26: =PL!E246/PL!E262 -> 0.29006955 | I26: — | J26: 投資人日：FY2031 客製約 $30B ÷ 營收約 $80B
A27: E. 校準
A28: k_x（XPU 校準係數） | C28: =PL!D96 -> 0.80284343 | E28: =PL!D168 -> 0.80284343 | G28: =PL!D240 -> 0.80284343 | I28: FY2027 錨點 ÷ 未校準 | J28: 接近 1＝市場層顆數 × 份額 × Broadcom 模型單價與公司客製營收一致
A29: k_o（光互連校準係數） | C29: =PL!D112 -> 1.4422343 | E29: =PL!D184 -> 1.4422343 | G29: =PL!D256 -> 1.4422343 | I29: （錨點光互連 − 相干）÷ 未校準 | J29: 高於 1：光互連包含 AI 後端可插拔以外的產品，或市場層光學偏低
A30: m_core（XPU 核心毛利率，Derived） | C30: =PL!D126 -> 0.43599463 | E30: =PL!D198 -> 0.43599463 | G30: =PL!D270 -> 0.43599463 | I30: FY2027 毛利殘差 | J30: 客製毛利率低於公司平均（公司說法：客製稀釋毛利率；二手）
A31: FY2028 毛利率 vs FY2027 錨點（百分點） | B31: =a27_gp/a27_rev -> 0.58389017 | C31: =PL!E128 -> 0.55492562 | D31: =C31-B31 -> -0.028964547 | E31: =PL!E200 -> 0.55558482 | F31: =E31-B31 -> -0.028305349 | G31: =PL!E272 -> 0.55591009 | H31: =G31-B31 -> -0.027980072 | I31: 錨點 | J31: 公司：FY2028 與 FY2027 期末同區間（約 58%）
A32: FY2030 毛利率 vs 公司 FY2031 目標 56–59% 中點 | B32: =co_gm31 -> 0.575 | C32: =PL!G128 -> 0.48145488 | D32: =C32-B32 -> -0.093545118 | E32: =PL!G200 -> 0.50469176 | F32: =E32-B32 -> -0.070308244 | G32: =PL!G272 -> 0.51887093 | H32: =G32-B32 -> -0.056129072 | I32: 投資人日（二手） | J32: 模型偏低主要來自代購 HBM（Broadcom 模型的代購比例 0.6）；代購比例低時見 Sens
A33: F. 預留
A34: R4 產業部署路徑（markets/deploy_path/，尚未建立）：上線後以 Marvell 客製營收 ÷ 部署 GW 對照 Tokenomics 非 NVIDIA 加速器比例 | J34: 預留列：本版無數值

Sheet Sens
A1: Sens — 一次動一個輸入（情境 A；k_x、k_o、m_core 在每個案例內依 FY2027 錨點重算，FY2027 恆等於錨點）：對 FY2028、FY2029 的營收、資料中心、毛利率與 EPS 的影響。每個案例是一個完整推導區塊（本頁下方）
A3: 案例 | B3: 設定 | C3: FY2028 營收 | D3: FY2028 資料中心 | E3: FY2028 毛利率 | F3: FY2028 EPS | G3: FY2028 EPS 相對基準 | H3: FY2029 營收 | I3: FY2029 資料中心 | J3: FY2029 毛利率 | K3: FY2029 EPS | L3: FY2029 EPS 相對基準
A4: 基準（情境 A） | B4: PL 區塊 A | C4: =PL!E121 -> 18.346206 | D4: =PL!E118 -> 16.0395 | E4: =PL!E128 -> 0.55492562 | F4: =PL!E138 -> 6.4386722 | G4: =F4/F$4-1 -> 0 | H4: =PL!F121 -> 27.418043 | I4: =PL!F118 -> 25.042137 | J4: =PL!F128 -> 0.47685539 | K4: =PL!F138 -> 8.3799677 | L4: =K4/K$4-1 -> 0
A5: XPU 顆數係數 ×0.8 | B5: CY2027 起 Marvell XPU 顆數 ×0.8 | C5: =E91 -> 17.601549 | D5: =E88 -> 15.294844 | E5: =E98 -> 0.56430687 | F5: =E108 -> 6.2788195 | G5: =F5/F$4-1 -> -0.024826972 | H5: =F91 -> 25.062884 | I5: =F88 -> 22.686977 | J5: =F98 -> 0.49325128 | K5: =F108 -> 7.9070149 | L5: =K5/K$4-1 -> -0.056438495
A6: XPU 顆數係數 ×1.2 | B6: ×1.2 | C6: =E163 -> 19.090862 | D6: =E160 -> 16.784157 | E6: =E170 -> 0.54627622 | F6: =E180 -> 6.598525 | G6: =F6/F$4-1 -> 0.024826972 | H6: =F163 -> 29.773203 | I6: =F160 -> 27.397296 | J6: =F170 -> 0.46305344 | K6: =F180 -> 8.8562242 | L6: =K6/K$4-1 -> 0.056832748
A7: 其他 ASIC 份額 −3pt | B7: CY2027 起 Marvell 占其他 ASIC −3 個百分點 | C7: =E235 -> 17.354103 | D7: =E232 -> 15.047398 | E7: =E242 -> 0.5683423 | F7: =E252 -> 6.2378471 | G7: =F7/F$4-1 -> -0.031190462 | H7: =F235 -> 26.173291 | I7: =F232 -> 23.797384 | J7: =F242 -> 0.48550221 | K7: =F252 -> 8.1379163 | L7: =K7/K$4-1 -> -0.028884519
A8: 其他 ASIC 份額 +6pt | B8: +6 個百分點（Maia 放量較快） | C8: =E307 -> 20.330411 | D8: =E304 -> 18.023705 | E8: =E314 -> 0.53202057 | F8: =E324 -> 6.8403225 | G8: =F8/F$4-1 -> 0.062380924 | H8: =F307 -> 29.907548 | I8: =F304 -> 27.531642 | J8: =F314 -> 0.46172103 | K8: =F324 -> 8.8616616 | L8: =K8/K$4-1 -> 0.057481601
A9: Trainium 份額 −5pt | B9: CY2027 起 −5 個百分點 | C9: =E379 -> 17.476667 | D9: =E376 -> 15.169961 | E9: =E386 -> 0.56522375 | F9: =E396 -> 6.2398655 | G9: =F9/F$4-1 -> -0.030876967 | H9: =F379 -> 26.230281 | I9: =F376 -> 23.854375 | J9: =F386 -> 0.48405685 | K9: =F396 -> 8.1236863 | L9: =K9/K$4-1 -> -0.030582615
A10: TPU 份額 +5pt | B10: CY2027 起 +5 個百分點（Google 案提前） | C10: =E451 -> 20.982784 | D10: =E448 -> 18.676078 | E10: =E458 -> 0.52604506 | F10: =E468 -> 6.9844663 | G10: =F10/F$4-1 -> 0.084768113 | H10: =F451 -> 31.069661 | I10: =F448 -> 28.693754 | J10: =F458 -> 0.45687356 | K10: =F468 -> 9.1284296 | L10: =K10/K$4-1 -> 0.089315616
A11: 核心售價 ×0.8 | B11: CY2027 起 XPU 核心售價 ×0.8 | C11: =E523 -> 17.829415 | D11: =E520 -> 15.52271 | E11: =E530 -> 0.55837287 | F11: =E540 -> 6.2774723 | G11: =F11/F$4-1 -> -0.025036208 | H11: =F523 -> 25.99949 | I11: =F520 -> 23.623583 | J11: =F530 -> 0.47908479 | K11: =F540 -> 7.9163431 | L11: =K11/K$4-1 -> -0.055325341
A12: 核心售價 ×1.2 | B12: ×1.2 | C12: =E595 -> 18.862996 | D12: =E592 -> 16.556291 | E12: =E602 -> 0.55166726 | F12: =E612 -> 6.5998722 | G12: =F12/F$4-1 -> 0.025036208 | H12: =F595 -> 28.836597 | I12: =F592 -> 26.46069 | J12: =F602 -> 0.47484533 | K12: =F612 -> 8.8447839 | L12: =K12/K$4-1 -> 0.055467549
A13: HBM 代購比例 低 | B13: 代購比例取低值（k_x、m_core 重算） | C13: =E667 -> 18.01511 | D13: =E664 -> 15.708404 | E13: =E674 -> 0.56328661 | F13: =E684 -> 6.4406297 | G13: =F13/F$4-1 -> 0.00030402597 | H13: =F667 -> 25.790226 | I13: =F664 -> 23.414319 | J13: =F674 -> 0.5006416 | K13: =F684 -> 8.3624406 | L13: =K13/K$4-1 -> -0.0020915459
A14: HBM 代購比例 高 | B14: 代購比例取高值 | C14: =E739 -> 18.721434 | D14: =E736 -> 16.414728 | E14: =E746 -> 0.54580768 | F14: =E756 -> 6.4364538 | G14: =F14/F$4-1 -> -0.00034454965 | H14: =F739 -> 29.262833 | I14: =F736 -> 26.886926 | J14: =F746 -> 0.45309765 | K14: =F756 -> 8.4014445 | L14: =K14/K$4-1 -> 0.0025628786
A15: 光晶片組份額 −10pt | B15: CY2027 起 Marvell 占光晶片組 −10 個百分點 | C15: =E811 -> 17.120874 | D15: =E808 -> 14.814168 | E15: =E818 -> 0.54955258 | F15: =E828 -> 5.8315856 | G15: =F15/F$4-1 -> -0.094287542 | H15: =F811 -> 26.222522 | I15: =F808 -> 23.846615 | J15: =F818 -> 0.46987331 | K15: =F828 -> 7.7698076 | L15: =K15/K$4-1 -> -0.072811741
A16: 光晶片組份額 +5pt | B16: +5 個百分點 | C16: =E883 -> 18.958872 | D16: =E880 -> 16.652166 | E16: =E890 -> 0.55735169 | F16: =E900 -> 6.7422155 | G16: =F16/F$4-1 -> 0.047143771 | H16: =F883 -> 28.015804 | I16: =F880 -> 25.639898 | J16: =F890 -> 0.48012297 | K16: =F900 -> 8.6839677 | L16: =K16/K$4-1 -> 0.036276991
A17: 每模組晶片組 ×0.8 | B17: CY2027 起每模組光晶片組金額 ×0.8 | C17: =E955 -> 16.802287 | D17: =E952 -> 14.495582 | E17: =E962 -> 0.54802723 | F17: =E972 -> 5.6737431 | G17: =F17/F$4-1 -> -0.1188023 | H17: =F955 -> 25.983417 | I17: =F952 -> 23.60751 | J17: =F962 -> 0.46839979 | K17: =F972 -> 7.6470211 | L17: =K17/K$4-1 -> -0.087464127
A18: 線性直驅 +10pt | B18: CY2027 起 LPO 占比 +10 個百分點 | C18: =E1027 -> 17.524973 | D18: =E1024 -> 15.218267 | E18: =E1034 -> 0.55140758 | F18: =E1044 -> 6.031795 | G18: =F18/F$4-1 -> -0.063192714 | H18: =F1027 -> 26.621029 | I18: =F1024 -> 24.245122 | J18: =F1034 -> 0.47227035 | K18: =F1044 -> 7.9735317 | L18: =K18/K$4-1 -> -0.048500894
A19: 光互連 ×1.2 | B19: CY2027 起 Marvell AI 光晶片組 ×1.2 | C19: =E1099 -> 19.890124 | D19: =E1096 -> 17.583419 | E19: =E1106 -> 0.56075307 | F19: =E1116 -> 7.2036013 | G19: =F19/F$4-1 -> 0.1188023 | H19: =F1099 -> 28.85267 | I19: =F1096 -> 26.476763 | J19: =F1106 -> 0.48447012 | K19: =F1116 -> 9.1080757 | L19: =K19/K$4-1 -> 0.086886732
A20: XPU attach FY2028 低 | B20: FY2028 $0.6B | C20: =E1171 -> 17.946206 | D20: =E1168 -> 15.6395 | E20: =E1178 -> 0.55503541 | F20: =E1188 -> 6.2707643 | G20: =F20/F$4-1 -> -0.026078032 | H20: =F1171 -> 26.818043 | I20: =F1168 -> 24.442137 | J20: =F1178 -> 0.47521893 | K20: =F1188 -> 8.1194319 | L20: =K20/K$4-1 -> -0.031090311
A21: XPU attach FY2028 高 | B21: FY2028 $1.4B | C21: =E1243 -> 18.746206 | D21: =E1240 -> 16.4395 | E21: =E1250 -> 0.55482052 | F21: =E1260 -> 6.6065801 | G21: =F21/F$4-1 -> 0.026078032 | H21: =F1243 -> 28.018043 | I21: =F1240 -> 25.642137 | J21: =F1250 -> 0.47842176 | K21: =F1260 -> 8.6405066 | L21: =K21/K$4-1 -> 0.031090687
A22: 交換器 FY2028 年增 低 | B22: +40% | C22: =E1315 -> 18.086206 | D22: =E1312 -> 15.7795 | E22: =E1322 -> 0.55427765 | F22: =E1332 -> 6.3172346 | G22: =F22/F$4-1 -> -0.018860661 | H22: =F1315 -> 27.054043 | I22: =F1312 -> 24.678137 | J22: =F1322 -> 0.47519853 | K22: =F1332 -> 8.2047854 | L22: =K22/K$4-1 -> -0.020904883
A23: 通訊與其他 FY2028 −5% | B23: 低值 | C23: =E1387 -> 18.167044 | D23: =E1384 -> 16.0395 | E23: =E1394 -> 0.55467834 | F23: =E1404 -> 6.3583812 | G23: =F23/F$4-1 -> -0.012470119 | H23: =F1387 -> 27.233507 | I23: =F1384 -> 25.042137 | J23: =F1394 -> 0.47615647 | K23: =F1404 -> 8.294662 | L23: =K23/K$4-1 -> -0.010179715
A24: 營業費用率 +2pt | B24: 營業費用額外 +2% × 營收 | C24: =E1459 -> 18.346206 | D24: =E1456 -> 16.0395 | E24: =E1466 -> 0.55492562 | F24: =E1476 -> 6.0915767 | G24: =F24/F$4-1 -> -0.053907937 | H24: =F1459 -> 27.418043 | I24: =F1456 -> 25.042137 | J24: =F1466 -> 0.47685539 | K24: =F1476 -> 7.8638209 | L24: =K24/K$4-1 -> -0.061592924
A25: 顆數情境 B | B25: CY2028 ×0.8、CY2029 ×0.85；記憶體 B 路徑；CPO 情境 B | C25: =PL!E193 -> 18.508724 | D25: =PL!E190 -> 16.202018 | E25: =PL!E200 -> 0.55558482 | F25: =PL!E210 -> 6.5191911 | G25: =F25/F$4-1 -> 0.012505506 | H25: =PL!F193 -> 21.924919 | I25: =PL!F190 -> 19.549012 | J25: =PL!F200 -> 0.50431512 | K25: =PL!F210 -> 6.9336195 | L25: =K25/K$4-1 -> -0.17259591
A26: 顆數情境 C | B26: CY2028–29 ×0.6；記憶體 C 路徑；CPO 情境 C | C26: =PL!E265 -> 18.589982 | D26: =PL!E262 -> 16.283277 | E26: =PL!E272 -> 0.55591009 | F26: =PL!E282 -> 6.5594505 | G26: =F26/F$4-1 -> 0.018758258 | H26: =PL!F265 -> 17.235827 | I26: =PL!F262 -> 14.85992 | J26: =PL!F272 -> 0.51982298 | K26: =PL!F282 -> 5.0798372 | L26: =K26/K$4-1 -> -0.39381183
A28: 讀法：FY2028 三情境只差在網通 CPO 情境（A 替代快、C 慢）；顆數情境 B、C 的差異從 FY2029（CY2028）起。k_x、k_o 隨案例重算，所以 HBM 代購比例只改變營收組合與毛利率，不改 FY2027 水準。
A30: 目標價參數敏感度（v0.2）：加權目標價（Val 第 0 節）一次動一個參數；PL 延伸期的收斂路徑不隨 tp_g 變動，tp_g 只改再投資率與永續成長
A31: 參數 | B31: 設定（低／高） | C31: 低：加權目標價 | D31: 低：相對基準 | E31: 高：加權目標價 | F31: 高：相對基準 | G31: 基準加權目標價
A32: tp_r ±1pt | B32: 折現率 −1pt／＋1pt | C32: =tp_w_dcf*(tp_wA*(MAX(0,Val!B7*Val!$G$7*(1-MIN(0.8,tp_g/tp_roe))/(1+(tp_r-0.01))^Val!$F$7+Val!B8*Val!$G$8*(1-MIN(0.8,tp_g/tp_roe))/(1+(tp_r-0.01))^Val!$F$8+Val!B9*Val!$G$9*(1-MIN(0.8,tp_g/tp_roe))/(1+(tp_r-0.01))^Val!$F$9+Val!B10*Val!$G$10*(1-MIN(0.8,tp_g/tp_roe))/(1+(tp_r-0.01))^Val!$F$10+Val!B11*Val!$G$11*(1-MIN(0.8,tp_g/tp_roe))/(1+(tp_r-0.01))^Val!$F$11+Val!B12*Val!$G$12*(1-MIN(0.8,tp_g/tp_roe))/(1+(tp_r-0.01))^Val!$F$12+Val!B12*(1-MIN(0.8,tp_g/tp_roe))*(1+tp_g)/((tp_r-0.01)-tp_g)/(1+(tp_r-0.01))^Val!$F$12))+tp_wB*(MAX(0,Val!C7*Val!$G$7*(1-MIN(0.8,tp_g/tp_roe))/(1+(tp_r-0.01))^Val!$F$7+Val!C8*Val!$G$8*(1-MIN(0.8,tp_g/tp_roe))/(1+(tp_r-0.01))^Val!$F$8+Val!C9*Val!$G$9*(1-MIN(0.8,tp_g/tp_roe))/(1+(tp_r-0.01))^Val!$F$9+Val!C10*Val!$G$10*(1-MIN(0.8,tp_g/tp_roe))/(1+(tp_r-0.01))^Val!$F$10+Val!C11*Val!$G$11*(1-MIN(0.8,tp_g/tp_roe))/(1+(tp_r-0.01))^Val!$F$11+Val!C12*Val!$G$12*(1-MIN(0.8,tp_g/tp_roe))/(1+(tp_r-0.01))^Val!$F$12+Val!C12*(1-MIN(0.8,tp_g/tp_roe))*(1+tp_g)/((tp_r-0.01)-tp_g)/(1+(tp_r-0.01))^Val!$F$12))+tp_wC*(MAX(0,Val!D7*Val!$G$7*(1-MIN(0.8,tp_g/tp_roe))/(1+(tp_r-0.01))^Val!$F$7+Val!D8*Val!$G$8*(1-MIN(0.8,tp_g/tp_roe))/(1+(tp_r-0.01))^Val!$F$8+Val!D9*Val!$G$9*(1-MIN(0.8,tp_g/tp_roe))/(1+(tp_r-0.01))^Val!$F$9+Val!D10*Val!$G$10*(1-MIN(0.8,tp_g/tp_roe))/(1+(tp_r-0.01))^Val!$F$10+Val!D11*Val!$G$11*(1-MIN(0.8,tp_g/tp_roe))/(1+(tp_r-0.01))^Val!$F$11+Val!D12*Val!$G$12*(1-MIN(0.8,tp_g/tp_roe))/(1+(tp_r-0.01))^Val!$F$12+Val!D12*(1-MIN(0.8,tp_g/tp_roe))*(1+tp_g)/((tp_r-0.01)-tp_g)/(1+(tp_r-0.01))^Val!$F$12)))*(1+(tp_r-0.01))+(1-tp_w_dcf)*tp_comp_adj -> 120.75757 | D32: =C32/G32-1 -> 0.10108984 | E32: =tp_w_dcf*(tp_wA*(MAX(0,Val!B7*Val!$G$7*(1-MIN(0.8,tp_g/tp_roe))/(1+(tp_r+0.01))^Val!$F$7+Val!B8*Val!$G$8*(1-MIN(0.8,tp_g/tp_roe))/(1+(tp_r+0.01))^Val!$F$8+Val!B9*Val!$G$9*(1-MIN(0.8,tp_g/tp_roe))/(1+(tp_r+0.01))^Val!$F$9+Val!B10*Val!$G$10*(1-MIN(0.8,tp_g/tp_roe))/(1+(tp_r+0.01))^Val!$F$10+Val!B11*Val!$G$11*(1-MIN(0.8,tp_g/tp_roe))/(1+(tp_r+0.01))^Val!$F$11+Val!B12*Val!$G$12*(1-MIN(0.8,tp_g/tp_roe))/(1+(tp_r+0.01))^Val!$F$12+Val!B12*(1-MIN(0.8,tp_g/tp_roe))*(1+tp_g)/((tp_r+0.01)-tp_g)/(1+(tp_r+0.01))^Val!$F$12))+tp_wB*(MAX(0,Val!C7*Val!$G$7*(1-MIN(0.8,tp_g/tp_roe))/(1+(tp_r+0.01))^Val!$F$7+Val!C8*Val!$G$8*(1-MIN(0.8,tp_g/tp_roe))/(1+(tp_r+0.01))^Val!$F$8+Val!C9*Val!$G$9*(1-MIN(0.8,tp_g/tp_roe))/(1+(tp_r+0.01))^Val!$F$9+Val!C10*Val!$G$10*(1-MIN(0.8,tp_g/tp_roe))/(1+(tp_r+0.01))^Val!$F$10+Val!C11*Val!$G$11*(1-MIN(0.8,tp_g/tp_roe))/(1+(tp_r+0.01))^Val!$F$11+Val!C12*Val!$G$12*(1-MIN(0.8,tp_g/tp_roe))/(1+(tp_r+0.01))^Val!$F$12+Val!C12*(1-MIN(0.8,tp_g/tp_roe))*(1+tp_g)/((tp_r+0.01)-tp_g)/(1+(tp_r+0.01))^Val!$F$12))+tp_wC*(MAX(0,Val!D7*Val!$G$7*(1-MIN(0.8,tp_g/tp_roe))/(1+(tp_r+0.01))^Val!$F$7+Val!D8*Val!$G$8*(1-MIN(0.8,tp_g/tp_roe))/(1+(tp_r+0.01))^Val!$F$8+Val!D9*Val!$G$9*(1-MIN(0.8,tp_g/tp_roe))/(1+(tp_r+0.01))^Val!$F$9+Val!D10*Val!$G$10*(1-MIN(0.8,tp_g/tp_roe))/(1+(tp_r+0.01))^Val!$F$10+Val!D11*Val!$G$11*(1-MIN(0.8,tp_g/tp_roe))/(1+(tp_r+0.01))^Val!$F$11+Val!D12*Val!$G$12*(1-MIN(0.8,tp_g/tp_roe))/(1+(tp_r+0.01))^Val!$F$12+Val!D12*(1-MIN(0.8,tp_g/tp_roe))*(1+tp_g)/((tp_r+0.01)-tp_g)/(1+(tp_r+0.01))^Val!$F$12)))*(1+(tp_r+0.01))+(1-tp_w_dcf)*tp_comp_adj -> 101.75241 | F32: =E32/G32-1 -> -0.072202708 | G32: =Val!$B$40 -> 109.67095
A33: tp_g ±1pt | B33: 長期成長 −1pt／＋1pt | C33: =tp_w_dcf*(tp_wA*(MAX(0,Val!B7*Val!$G$7*(1-MIN(0.8,(tp_g-0.01)/tp_roe))/(1+tp_r)^Val!$F$7+Val!B8*Val!$G$8*(1-MIN(0.8,(tp_g-0.01)/tp_roe))/(1+tp_r)^Val!$F$8+Val!B9*Val!$G$9*(1-MIN(0.8,(tp_g-0.01)/tp_roe))/(1+tp_r)^Val!$F$9+Val!B10*Val!$G$10*(1-MIN(0.8,(tp_g-0.01)/tp_roe))/(1+tp_r)^Val!$F$10+Val!B11*Val!$G$11*(1-MIN(0.8,(tp_g-0.01)/tp_roe))/(1+tp_r)^Val!$F$11+Val!B12*Val!$G$12*(1-MIN(0.8,(tp_g-0.01)/tp_roe))/(1+tp_r)^Val!$F$12+Val!B12*(1-MIN(0.8,(tp_g-0.01)/tp_roe))*(1+(tp_g-0.01))/(tp_r-(tp_g-0.01))/(1+tp_r)^Val!$F$12))+tp_wB*(MAX(0,Val!C7*Val!$G$7*(1-MIN(0.8,(tp_g-0.01)/tp_roe))/(1+tp_r)^Val!$F$7+Val!C8*Val!$G$8*(1-MIN(0.8,(tp_g-0.01)/tp_roe))/(1+tp_r)^Val!$F$8+Val!C9*Val!$G$9*(1-MIN(0.8,(tp_g-0.01)/tp_roe))/(1+tp_r)^Val!$F$9+Val!C10*Val!$G$10*(1-MIN(0.8,(tp_g-0.01)/tp_roe))/(1+tp_r)^Val!$F$10+Val!C11*Val!$G$11*(1-MIN(0.8,(tp_g-0.01)/tp_roe))/(1+tp_r)^Val!$F$11+Val!C12*Val!$G$12*(1-MIN(0.8,(tp_g-0.01)/tp_roe))/(1+tp_r)^Val!$F$12+Val!C12*(1-MIN(0.8,(tp_g-0.01)/tp_roe))*(1+(tp_g-0.01))/(tp_r-(tp_g-0.01))/(1+tp_r)^Val!$F$12))+tp_wC*(MAX(0,Val!D7*Val!$G$7*(1-MIN(0.8,(tp_g-0.01)/tp_roe))/(1+tp_r)^Val!$F$7+Val!D8*Val!$G$8*(1-MIN(0.8,(tp_g-0.01)/tp_roe))/(1+tp_r)^Val!$F$8+Val!D9*Val!$G$9*(1-MIN(0.8,(tp_g-0.01)/tp_roe))/(1+tp_r)^Val!$F$9+Val!D10*Val!$G$10*(1-MIN(0.8,(tp_g-0.01)/tp_roe))/(1+tp_r)^Val!$F$10+Val!D11*Val!$G$11*(1-MIN(0.8,(tp_g-0.01)/tp_roe))/(1+tp_r)^Val!$F$11+Val!D12*Val!$G$12*(1-MIN(0.8,(tp_g-0.01)/tp_roe))/(1+tp_r)^Val!$F$12+Val!D12*(1-MIN(0.8,(tp_g-0.01)/tp_roe))*(1+(tp_g-0.01))/(tp_r-(tp_g-0.01))/(1+tp_r)^Val!$F$12)))*(1+tp_r)+(1-tp_w_dcf)*tp_comp_adj -> 106.19094 | D33: =C33/G33-1 -> -0.031731375 | E33: =tp_w_dcf*(tp_wA*(MAX(0,Val!B7*Val!$G$7*(1-MIN(0.8,(tp_g+0.01)/tp_roe))/(1+tp_r)^Val!$F$7+Val!B8*Val!$G$8*(1-MIN(0.8,(tp_g+0.01)/tp_roe))/(1+tp_r)^Val!$F$8+Val!B9*Val!$G$9*(1-MIN(0.8,(tp_g+0.01)/tp_roe))/(1+tp_r)^Val!$F$9+Val!B10*Val!$G$10*(1-MIN(0.8,(tp_g+0.01)/tp_roe))/(1+tp_r)^Val!$F$10+Val!B11*Val!$G$11*(1-MIN(0.8,(tp_g+0.01)/tp_roe))/(1+tp_r)^Val!$F$11+Val!B12*Val!$G$12*(1-MIN(0.8,(tp_g+0.01)/tp_roe))/(1+tp_r)^Val!$F$12+Val!B12*(1-MIN(0.8,(tp_g+0.01)/tp_roe))*(1+(tp_g+0.01))/(tp_r-(tp_g+0.01))/(1+tp_r)^Val!$F$12))+tp_wB*(MAX(0,Val!C7*Val!$G$7*(1-MIN(0.8,(tp_g+0.01)/tp_roe))/(1+tp_r)^Val!$F$7+Val!C8*Val!$G$8*(1-MIN(0.8,(tp_g+0.01)/tp_roe))/(1+tp_r)^Val!$F$8+Val!C9*Val!$G$9*(1-MIN(0.8,(tp_g+0.01)/tp_roe))/(1+tp_r)^Val!$F$9+Val!C10*Val!$G$10*(1-MIN(0.8,(tp_g+0.01)/tp_roe))/(1+tp_r)^Val!$F$10+Val!C11*Val!$G$11*(1-MIN(0.8,(tp_g+0.01)/tp_roe))/(1+tp_r)^Val!$F$11+Val!C12*Val!$G$12*(1-MIN(0.8,(tp_g+0.01)/tp_roe))/(1+tp_r)^Val!$F$12+Val!C12*(1-MIN(0.8,(tp_g+0.01)/tp_roe))*(1+(tp_g+0.01))/(tp_r-(tp_g+0.01))/(1+tp_r)^Val!$F$12))+tp_wC*(MAX(0,Val!D7*Val!$G$7*(1-MIN(0.8,(tp_g+0.01)/tp_roe))/(1+tp_r)^Val!$F$7+Val!D8*Val!$G$8*(1-MIN(0.8,(tp_g+0.01)/tp_roe))/(1+tp_r)^Val!$F$8+Val!D9*Val!$G$9*(1-MIN(0.8,(tp_g+0.01)/tp_roe))/(1+tp_r)^Val!$F$9+Val!D10*Val!$G$10*(1-MIN(0.8,(tp_g+0.01)/tp_roe))/(1+tp_r)^Val!$F$10+Val!D11*Val!$G$11*(1-MIN(0.8,(tp_g+0.01)/tp_roe))/(1+tp_r)^Val!$F$11+Val!D12*Val!$G$12*(1-MIN(0.8,(tp_g+0.01)/tp_roe))/(1+tp_r)^Val!$F$12+Val!D12*(1-MIN(0.8,(tp_g+0.01)/tp_roe))*(1+(tp_g+0.01))/(tp_r-(tp_g+0.01))/(1+tp_r)^Val!$F$12)))*(1+tp_r)+(1-tp_w_dcf)*tp_comp_adj -> 114.81653 | F33: =E33/G33-1 -> 0.046918292 | G33: =Val!$B$40 -> 109.67095
