Workbook

Sheet README
A1: Astera Labs（ALAB）收支與估值模型 v0.1.1（AI 半導體 Project：網通次產業內複製——PCIe／CXL 重定時器、Scorpio 交換晶片、AEC 模組；scale-up 互連） 2026-10-25
A2: 版本：v0.1（2026-10-25 初版；三情境延伸到 FY2032、目標價＝DCF 與 Comparable 加權）。Astera Labs 在非 NVIDIA scale-up 交換晶片（Scorpio X）與 PCIe／CXL／AEC 的份額在本模型 Units 頁建立，為本專案權威資料（規則第 13 條）。
A3: 模型命題：Astera Labs 的 Scorpio X 營收＝非 NVIDIA scale-up 交換晶片市場（本專案網通模型：AMD、Trainium、其他 ASIC 顆數 × 每顆 scale-up 交換晶片內容）× Astera 有效份額；PCIe 與訊號調節（Aries 重定時器、Scorpio P、Taurus AEC、Leo CXL）＝AI 加速器顆數 × 每顆內容 × 份額。3Q26 指引季增約 40%、Scorpio 成為最大產品線：成長重心正由重定時器轉到 scale-up 交換晶片。現價約 64 倍共識 FY2026 EPS、40 倍 FY2027。
A4: 核心問題：現價隱含的 FY2028 EPS 需要 Scorpio X 在非 NVIDIA scale-up 交換晶片維持多少份額、PCIe 等業務流失多少才成立？非 NVIDIA 加速器顆數（AMD、Trainium、其他 ASIC）與 NVLink Fusion 的競爭是主要不確定性。
A6: 會計年度：日曆年（12 月底結束）；上游市場層為日曆年，FY(t) 市場＝CY(t)。預測期 FY2027–FY2029（FY2026 為錨點），FY2030–FY2032 為收斂法。口徑：公司 non-GAAP；十年 P/E 規則值用 GAAP 換算 EPS。
A8: 驅動因子 → 推導量（全部唯讀上游，不修改）
A9: Scorpio X：markets/network 的非 NVIDIA scale-up 交換晶片市場 × 情境顆數係數 × Astera 有效份額（FY2026 錨點校準）× 份額相對值（Assumed）。PCIe 等：AI 加速器顆數 × 情境顆數係數 × 每顆內容 × 有效份額（FY2026 校準）× 相對值（Assumed）。
A10: 毛利率：FY2027 起為輸入路徑（Assumed；公司長期目標 70%）。營業費用：彈性 phi（FY2026 錨點 Derived）。稅率：約 12%（公司 non-GAAP 稅率）。股數：+1.5%／年。
A11: 校準：FY2026 ＝ 1Q26、2Q26 實績（營收 3.08、3.92 億美元；non-GAAP EPS 0.61、0.80）＋ 3Q26 指引中點（5.50 億美元）＋ 4Q26（季增 15%，Assumed）。產品線拆分公司未揭露：Scorpio X FY2026 為假設，PCIe 等為殘差。不用共識（只在 Recon 對帳）。
A12: 估值：目標價（Val 第 0 節）＝0.5 × DCF（股東現金流＝EPS ×（1 − g／ROE），FY2027–32 明確期＋永續，r 10%、g 4%，情境權重 0.3／0.5／0.2）＋0.5 × Comparable（美股高速連接晶片同業前瞻 P/E 中位數 × 12 個月後前瞻 EPS）。舊法規則值情境加權保留參考（不是目標價）；市場隱含 FY2028 EPS（Val 第 4 節）；十年 P/E 規則值（只有 2025 年一個正值）× FY2027 GAAP 換算 EPS；循環位置以本模型營收最高年判定。本版未做先驗，無 Andy 合理 P/E 對照。
A13: 標記：Verified、Interested-party、Analogy、Assumed、Derived。SemiAnalysis 未使用。客戶名稱公司未具名；10-K 只揭露單一終端客戶逾 70%、前三大約 86%（FY2025）。
A15: 已知限制：(1) Scorpio X FY2026 營收、兩條業務的份額相對值、毛利率路徑皆為 Assumed，是 FY2027–FY2029 EPS 最敏感的輸入（Sens）；(2) 產品線營收未揭露，PCIe 等為殘差；(3) 網通模型沒有 PCIe 重定時器與 PCIe 交換晶片的獨立列，本模型以加速器顆數 × 每顆內容代替；(4) 非 NVIDIA scale-up 交換晶片市場排除 NVIDIA（NVLink）與 TPU（ICI／光學電路交換），NVLink Fusion 若開放第三方交換晶片會改變分母；(5) 十年 P/E 只有 2025 年一個觀測值、含高成長期溢價，規則值明顯偏高；(6) R4 產業部署路徑未建（Recon 預留列）。
A16: v0.1.1（2026-10-25）：補上檔空間級距、投資建議、重點觀察（數值不變）。Val 頁末新增「上檔空間級距」「投資建議」兩列（Andy 2026-10-25 14:00、14:17 固定規則），README 頁末新增投資建議與重點觀察三點；既有儲存格位置與數值不變。
A17: ="投資建議："&Val!B130&"（依上檔空間固定規則）" -> 投資建議：放空（依上檔空間固定規則）
A18: 重點觀察 1：目標價 US$132（DCF 105、Comparable 160 各半），比現價 257.16（2026-10-23）低 48.5%，級距 −25%～−50%；Comparable 單獨為 −37.9%。EPS 與倍數兩個因素都在：本模型 12 個月後前瞻 EPS 6.33 比共識 8.21 低 22.9%；同業（Credo、Marvell、Broadcom、Rambus、MACOM）前瞻 P/E 中位數 25.2 倍，現價隱含 31.3 倍共識 EPS、共識目標價 388.36 隱含 47.3 倍（比同業高 87.5%）；Comparable 未給 Astera 的成長溢價（本身前瞻 P/E 約 46 倍）。
A19: 重點觀察 2：情境分歧從 FY2028 起：FY2027 EPS 三情境同為 6.90，FY2028 A／B／C 為 8.10／6.13／3.60，DCF 價格帶 52～139；Val 頁讀法：以同業約 25 倍計，現價隱含的 FY2028 EPS 比模型 A 高約三成，需要 Scorpio X 份額上升才達得到。
A20: 重點觀察 3：FY2027 EPS 最敏感的是 Scorpio X 份額（高 +18.7%、低 −14.0%）與 PCIe 等份額（高 +15.2%、低 −11.4%）；最大客戶 30% 轉單時 −12.8%（Sens 頁）。下一個檢驗點是 3Q26 財報（2026-11-03）的 Scorpio X 營收與客戶數。

Sheet In
A1: In — 輸入（藍字；基準欄 E，低 D、高 F）。金額：十億美元（US$B）；比例：%。每個輸入附兩個來源（找不到者寫「未找到」）；公司原文算一個
A2: 標記：Verified／Interested-party／Analogy／Assumed／Derived；Analogy、Assumed 給低／高區間。SemiAnalysis 未使用。公司原文＝SEC 8-K 新聞稿與 10-K；公司不揭露產品線營收（Aries、Taurus、Leo、Scorpio P／X）與客戶名稱
A3: 鍵 | B3: 項目 | C3: 單位 | D3: 低 | E3: 基準 | F3: 高 | G3: 標記 | H3: 來源1 | I3: 來源2／說明
A4: A. 市場（讀 markets/network 成品；日曆年 CY2026–CY2029＝會計年度；情境 A 基準，B／C 依顆數係數縮放）
A5: msx_26 | B5: 非 NVIDIA scale-up 交換晶片市場 CY2026（AMD、Trainium、其他 ASIC；不含 TPU） | C5: US$B | E5: 2.025 | G5: Derived | H5: markets/network/dist/20261026_AI網通市場模型_v0.2.3.xlsx｜Units!B8:E8、B10:E10、B11:E11 × In!E62（2026）／E68、E80、E86 | I5: 顆數 × 每顆 scale-up 交換晶片內容（網通模型 In 頁 c_*_su_sw）；NVIDIA 平台用自家 NVLink 交換晶片、TPU 用 ICI／光學電路交換，不列入 Scorpio X 可服務市場
A6: msx_27 | B6: 非 NVIDIA scale-up 交換晶片市場 CY2027（AMD、Trainium、其他 ASIC；不含 TPU） | C6: US$B | E6: 7.701 | G6: Derived | H6: 同上 | I6: 同上
A7: msx_28 | B7: 非 NVIDIA scale-up 交換晶片市場 CY2028（AMD、Trainium、其他 ASIC；不含 TPU） | C7: US$B | E7: 9.468 | G7: Derived | H7: 同上 | I7: 同上
A8: msx_29 | B8: 非 NVIDIA scale-up 交換晶片市場 CY2029（AMD、Trainium、其他 ASIC；不含 TPU） | C8: US$B | E8: 10.8882 | G8: Derived | H8: 同上 | I8: 同上
A9: msu_26 | B9: scale-up 交換晶片市場合計 CY2026（含 NVIDIA NVLink；Units、Recon 用） | C9: US$B | E9: 18.2761 | G9: Derived | H9: markets/network/dist/20261026_AI網通市場模型_v0.2.3.xlsx｜Mkt!C5:F5 | I9: 只作對照，不進損益
A10: msu_27 | B10: scale-up 交換晶片市場合計 CY2027（含 NVIDIA NVLink；Units、Recon 用） | C10: US$B | E10: 37.4157 | G10: Derived | H10: markets/network/dist/20261026_AI網通市場模型_v0.2.3.xlsx｜Mkt!C5:F5 | I10: 同上
A11: msu_28 | B11: scale-up 交換晶片市場合計 CY2028（含 NVIDIA NVLink；Units、Recon 用） | C11: US$B | E11: 44.9835 | G11: Derived | H11: markets/network/dist/20261026_AI網通市場模型_v0.2.3.xlsx｜Mkt!C5:F5 | I11: 同上
A12: msu_29 | B12: scale-up 交換晶片市場合計 CY2029（含 NVIDIA NVLink；Units、Recon 用） | C12: US$B | E12: 51.2458 | G12: Derived | H12: markets/network/dist/20261026_AI網通市場模型_v0.2.3.xlsx｜Mkt!C5:F5 | I12: 同上
A13: u_26 | B13: AI 加速器顆數合計 CY2026 | C13: 百萬顆 | E13: 15.2 | G13: Derived | H13: markets/network/dist/20261026_AI網通市場模型_v0.2.3.xlsx｜Units!B12 | I13: 網通模型 Units 頁（顆數取自 markets/memory，2029 為成長率）
A14: u_27 | B14: AI 加速器顆數合計 CY2027 | C14: 百萬顆 | E14: 23.7 | G14: Derived | H14: markets/network/dist/20261026_AI網通市場模型_v0.2.3.xlsx｜Units!C12 | I14: 同上
A15: u_28 | B15: AI 加速器顆數合計 CY2028 | C15: 百萬顆 | E15: 26.5 | G15: Derived | H15: markets/network/dist/20261026_AI網通市場模型_v0.2.3.xlsx｜Units!D12 | I15: 同上
A16: u_29 | B16: AI 加速器顆數合計 CY2029 | C16: 百萬顆 | E16: 30.15 | G16: Derived | H16: markets/network/dist/20261026_AI網通市場模型_v0.2.3.xlsx｜Units!E12 | I16: 同上
... A30: um29_C | B30: 情境 C：CY2029 顆數 ÷ 基準 | C30: x | E30: 0.6 | G30: Assumed | H30: tsmc/dist/20261025_台積電模型_v0.3.1.xlsx｜In!E42 | I30: 同上
A31: B. Scorpio X（scale-up 交換晶片；本專案為權威：Astera 在非 NVIDIA scale-up 交換晶片的份額，規則第 13 條）
A32: x_25 | B32: FY2025 Scorpio X 營收 | C32: US$B | D32: 0 | E32: 0 | F32: 0.02 | G32: Assumed | H32: https://www.tikr.com/blog/astera-labs-what-a-224-bull-case-looks-like：Scorpio X 在 FY2025「not meaningful」（Interested-party） | I32: https://www.fool.com/earnings/call-transcripts/2026/05/05/astera-labs-alab-q1-2026-earnings-transcript/：Scorpio X 初期量產於 1Q26 開始出貨（公司）
A33: x_26 | B33: FY2026 Scorpio X 營收（未揭露） | C33: US$B | D33: 0.28 | E33: 0.38 | F33: 0.5 | G33: Assumed | H33: 公司不揭露產品線營收：未找到；推估：Scorpio 1Q26 約占 20%（分析師於法說引述，公司未證實）、3Q26 成為最大產品線且 X 超過 P | I33: MarketBeat 法說摘要（網址見 Sources）：Scorpio 於 3Q26 成為最大產品線（提前一季）、X 系列 3Q26 超過 P 系列；逾 10 家客戶接洽 Scorpio X（公司）
A34: rel_x_27 | B34: Scorpio X 有效份額 FY2027 ÷ FY2026（相對值） | C34: x | D34: 0.7 | E34: 1 | F34: 1.4 | G34: Assumed | H34: https://www.marketbeat.com/instant-alerts/astera-labs-q2-earnings-call-highlights-2026-08-04/：第二家以後的客戶 2026 年底起出貨、2027 年初更多客戶量產（公司） | I34: 競爭：Broadcom Tomahawk Ultra、NVLink Fusion、其他 UALink 交換晶片（10-K 列名競爭者含 Broadcom、Marvell）
A35: rel_x_28 | B35: Scorpio X 有效份額 FY2028 ÷ FY2026 | C35: x | D35: 0.6 | E35: 1.1 | F35: 1.7 | G35: Assumed | H35: https://www.fool.com/earnings/call-transcripts/2026/05/05/astera-labs-alab-q1-2026-earnings-transcript/：現有設計案每顆加速器內容逾 1,000 美元（公司） | I35: 整合 CPO 的 Scorpio X 規劃 2028 年後（公司，Futurum 轉述）
A36: rel_x_29 | B36: Scorpio X 有效份額 FY2029 ÷ FY2026 | C36: x | D36: 0.5 | E36: 1.15 | F36: 2 | G36: Assumed | H36: 同上 | I36: —
A37: C. PCIe 與訊號調節（Aries 重定時器、Scorpio P PCIe 交換晶片、Taurus AEC 模組、Leo CXL；讀加速器顆數）
A38: c_pcie | B38: 每顆加速器 PCIe／CXL／AEC 可服務內容（只作份額顯示；不影響損益） | C38: US$/顆 | D38: 150 | E38: 250 | F38: 400 | G38: Assumed | H38: 第一手每顆內容：未找到 | I38: 損益＝FY2026 營收 × 顆數成長 × 相對值，與本列無關（校準時抵銷）
A39: rel_p_27 | B39: PCIe 等有效份額 × 每顆內容 FY2027 ÷ FY2026（相對值） | C39: x | D39: 0.65 | E39: 0.8 | F39: 1 | G39: Assumed | H39: https://www.sec.gov/Archives/edgar/data/1736297/000173629726000010/alab-20251231.htm：競爭者 Broadcom、Credo、Marvell、Microchip、Montage、Parade、Rambus（公司） | I39: PCIe 6／7 單價上升 vs 重定時器份額競爭、平台整合（每顆加速器重定時器數減少）；Aries FY2025 年增約 70%（TIKR，Interested-party）
A40: rel_p_28 | B40: PCIe 等有效份額 × 每顆內容 FY2028 ÷ FY2026 | C40: x | D40: 0.55 | E40: 0.75 | F40: 1 | G40: Assumed | H40: 同上；Taurus 3.2T 可服務市場 2030 年逾 40 億美元（公司，MarketBeat 轉述） | I40: Leo CXL 2027 年起兩家美國超大規模業者量產（公司）
A41: rel_p_29 | B41: PCIe 等有效份額 × 每顆內容 FY2029 ÷ FY2026 | C41: x | D41: 0.45 | E41: 0.7 | F41: 1 | G41: Assumed | H41: 同上 | I41: —
A42: cust_top | B42: 最大終端客戶占營收（FY2025；Sens「最大客戶部分轉單」用） | C42: % | E42: 0.7 | G42: Verified | H42: 公司 FY2025 10-K（網址見 Sources）：單一終端客戶「逾 70%」、前三大約 86%（FY2025，公司未具名） | I42: 客戶名稱：未找到（公司未具名）
A43: cl_loss | B43: 最大客戶部分轉單：其 PCIe 等內容轉給其他供應商或自製的比例（Sens 用） | C43: % | E43: 0.3 | G43: Assumed | H43: 無 | I43: —
A44: cl_27 | B44: 最大客戶部分轉單情境：PCIe 等相對值 FY2027（Sens 用） | C44: x | E44: =rel_p_27*(1-cust_top*cl_loss) -> 0.632 | G44: Derived | H44: 相對值 ×（1 − 最大客戶占比 × 轉單比例） | I44: 假設轉單只發生在 PCIe 等（Scorpio X 不變）
A45: cl_28 | B45: 最大客戶部分轉單情境：PCIe 等相對值 FY2028（Sens 用） | C45: x | E45: =rel_p_28*(1-cust_top*cl_loss) -> 0.5925 | G45: Derived | H45: 相對值 ×（1 − 最大客戶占比 × 轉單比例） | I45: 同上
A46: cl_29 | B46: 最大客戶部分轉單情境：PCIe 等相對值 FY2029（Sens 用） | C46: x | E46: =rel_p_29*(1-cust_top*cl_loss) -> 0.553 | G46: Derived | H46: 相對值 ×（1 − 最大客戶占比 × 轉單比例） | I46: 同上
A47: D. FY2026 錨點（1Q26、2Q26 實績＋3Q26 指引＋4Q26 假設）
A48: q1_rev | B48: 1Q26 營收（截至 2026-03-31） | C48: US$B | E48: 0.308361 | G48: Verified | H48: https://www.sec.gov/Archives/edgar/data/0001736297/000173629726000033/q226exhibit991.htm：308,361 千美元（2Q26 新聞稿比較欄） | I48: https://www.fool.com/earnings/call-transcripts/2026/05/05/astera-labs-alab-q1-2026-earnings-transcript/：1Q26 法說
A49: q1_gp | B49: 1Q26 non-GAAP 毛利 | C49: US$B | E49: 0.23564 | G49: Verified | H49: https://www.sec.gov/Archives/edgar/data/0001736297/000173629726000033/q226exhibit991.htm：235,640 千美元（毛利率 76.4%） | I49: https://www.fool.com/earnings/call-transcripts/2026/05/05/astera-labs-alab-q1-2026-earnings-transcript/：76.4%
A50: q1_opx | B50: 1Q26 non-GAAP 營業費用（＝毛利 − 營業利益） | C50: US$B | E50: =0.23564-0.111729 -> 0.123911 | G50: Verified | H50: https://www.sec.gov/Archives/edgar/data/0001736297/000173629726000033/q226exhibit991.htm：non-GAAP 營業利益 111,729 千美元 | I50: —
A51: q1_ninc | B51: 1Q26 利息與其他收益（non-GAAP） | C51: US$B | E51: 0.011581 | G51: Verified | H51: https://www.sec.gov/Archives/edgar/data/0001736297/000173629726000033/q226exhibit991.htm：11,581 千美元 | I51: —
A52: q1_ni | B52: 1Q26 non-GAAP 淨利 | C52: US$B | E52: 0.110069 | G52: Verified | H52: https://www.sec.gov/Archives/edgar/data/0001736297/000173629726000033/q226exhibit991.htm：110,069 千美元 | I52: —
A53: q1_sh | B53: 1Q26 稀釋股數 | C53: 十億股 | E53: 0.181157 | G53: Verified | H53: https://www.sec.gov/Archives/edgar/data/0001736297/000173629726000033/q226exhibit991.htm：181,157 千股 | I53: —
...

Sheet Q
A1: Q — 實績與 FY2026 錨點（十億美元；EPS 為美元；股數為十億股；non-GAAP）。藍字＝輸入；黑字＝公式。會計年度＝日曆年
A2: FY2026 錨點＝1Q26、2Q26 實績＋3Q26 指引中點（營收 5.50 億美元、毛利率 72%、營業費用 1.58 億美元）＋4Q26（季增 g_q4、毛利率 gm_q4，Assumed）。產品線拆分（Scorpio X）為假設，PCIe 與訊號調節為殘差。3Q26 財報（2026-11-03）公布後以實績取代 3Q
A3: 項目 | B3: FY2024A | C3: FY2025A | D3: 1Q26（實績） | E3: 2Q26（實績） | F3: 3Q26（指引） | G3: 4Q26（假設） | H3: FY2026 錨點 | I3: 標記 | J3: 說明
A4: 營收 | B4: =a24_rev_in -> 0.39629 | C4: =a25_rev_in -> 0.852525 | D4: =q1_rev -> 0.308361 | E4: =q2_rev -> 0.3924 | F4: =q3_rev -> 0.55 | G4: =F4*(1+g_q4) -> 0.6325 | H4: =SUM(D4:G4) -> 1.883261 | I4: Verified／Interested-party（指引）／Assumed | J4: 4Q26＝3Q26 ×（1＋g_q4）
A5: 毛利（non-GAAP） | B5: =a24_gp_in -> 0.303544 | C5: =a25_gp_in -> 0.646384 | D5: =q1_gp -> 0.23564 | E5: =q2_gp -> 0.289259 | F5: =F4*q3_gm -> 0.396 | G5: =G4*gm_q4 -> 0.4522375 | H5: =SUM(D5:G5) -> 1.3731365 | I5: Verified／Derived
A6: 毛利率 | B6: =B5/B4 -> 0.76596432 | C6: =C5/C4 -> 0.75819947 | D6: =D5/D4 -> 0.76416927 | E6: =E5/E4 -> 0.73715341 | F6: =F5/F4 -> 0.72 | G6: =G5/G4 -> 0.715 | H6: =H5/H4 -> 0.72912703 | I6: Derived
A7: 營業費用（non-GAAP） | B7: =a24_opx_in -> 0.18395 | C7: =a25_opx_in -> 0.311978 | D7: =q1_opx -> 0.123911 | E7: =q2_opx -> 0.135787 | F7: =q3_opx -> 0.158 | G7: =q4_opx -> 0.168 | H7: =SUM(D7:G7) -> 0.585698 | I7: Verified／Interested-party（指引）／Assumed
A8: 營業費用率 | B8: =B7/B4 -> 0.46418027 | C8: =C7/C4 -> 0.36594587 | D8: =D7/D4 -> 0.40183746 | E8: =E7/E4 -> 0.3460423 | F8: =F7/F4 -> 0.28727273 | G8: =G7/G4 -> 0.26561265 | H8: =H7/H4 -> 0.31100203 | I8: Derived
A9: 營業利益（non-GAAP） | B9: =B5-B7 -> 0.119594 | C9: =C5-C7 -> 0.334406 | D9: =D5-D7 -> 0.111729 | E9: =E5-E7 -> 0.153472 | F9: =F5-F7 -> 0.238 | G9: =G5-G7 -> 0.2842375 | H9: =H5-H7 -> 0.7874385 | I9: Derived
A10: 利息與其他收益 | B10: =a24_ninc_in -> 0.034288 | C10: =a25_ninc_in -> 0.04473 | D10: =q1_ninc -> 0.011581 | E10: =q2_ninc -> 0.012077 | F10: =q_oth -> 0.0125 | G10: =q_oth -> 0.0125 | H10: =SUM(D10:G10) -> 0.048658 | I10: Verified／Assumed
A11: 稅前利益 | B11: =B9+B10 -> 0.153882 | C11: =C9+C10 -> 0.379136 | D11: =D9+D10 -> 0.12331 | E11: =E9+E10 -> 0.165549 | F11: =F9+F10 -> 0.2505 | G11: =G9+G10 -> 0.2967375 | H11: =H9+H10 -> 0.8360965 | I11: Derived
A12: 所得稅（non-GAAP） | B12: =B11-a24_ni_in -> 0.010553 | C12: =C11-a25_ni_in -> 0.048121 | D12: =D11-q1_ni -> 0.013241 | E12: =E11-q2_ni -> 0.019733 | F12: =F11*tx_26 -> 0.03006 | G12: =G11*tx_26 -> 0.0356085 | H12: =SUM(D12:G12) -> 0.0986425 | I12: Derived | J12: 實績＝稅前 − 淨利（推導）
A13: 有效稅率 | B13: =B12/B11 -> 0.068578521 | C13: =C12/C11 -> 0.12692279 | D13: =D12/D11 -> 0.10737977 | E13: =E12/E11 -> 0.11919734 | F13: =F12/F11 -> 0.12 | G13: =G12/G11 -> 0.12 | H13: =H12/H11 -> 0.1179798 | I13: Derived
A14: 淨利（non-GAAP） | B14: =a24_ni_in -> 0.143329 | C14: =a25_ni_in -> 0.331015 | D14: =q1_ni -> 0.110069 | E14: =q2_ni -> 0.145816 | F14: =F11-F12 -> 0.22044 | G14: =G11-G12 -> 0.261129 | H14: =SUM(D14:G14) -> 0.737454 | I14: Verified／Derived
A15: 淨利率 | B15: =B14/B4 -> 0.36167705 | C15: =C14/C4 -> 0.388276 | D15: =D14/D4 -> 0.35694851 | E15: =E14/E4 -> 0.37160041 | F15: =F14/F4 -> 0.4008 | G15: =G14/G4 -> 0.41285217 | H15: =H14/H4 -> 0.39158354 | I15: Derived
A16: 稀釋股數（non-GAAP） | B16: =a24_sh_in -> 0.168913 | C16: =a25_sh_in -> 0.179551 | D16: =q1_sh -> 0.181157 | E16: =q2_sh -> 0.18334 | F16: =q3_sh -> 0.185 | G16: =q4_sh -> 0.1865 | H16: =AVERAGE(D16:G16) -> 0.18399925 | I16: Verified／Assumed | J16: 全年＝四季平均
A17: EPS（non-GAAP） | B17: =B14/B16 -> 0.84853741 | C17: =C14/C16 -> 1.8435709 | D17: =D14/D16 -> 0.607589 | E17: =E14/E16 -> 0.79533108 | F17: =F14/F16 -> 1.1915676 | G17: =G14/G16 -> 1.4001555 | H17: =H14/H16 -> 4.0079185 | I17: Derived | J17: 公司揭露：FY2024 0.84、FY2025 1.84、1Q26 0.61、2Q26 0.80；3Q26 指引 1.16–1.21
A18: Scorpio X 營收 | C18: =x_25 -> 0 | H18: =x_26 -> 0.38 | I18: Assumed
A19: PCIe 與訊號調節（Aries、Scorpio P、Taurus、Leo）＝營收 − Scorpio X（殘差） | C19: =C4-C18 -> 0.852525 | H19: =H4-H18 -> 1.503261 | I19: Derived
A20: Scorpio X ÷ 營收 | C20: =C18/C4 -> 0 | H20: =H18/H4 -> 0.20177766 | I20: Derived | J20: 公司：Scorpio 3Q26 成為最大產品線、X 超過 P
A23: FY2026 錨點的檢查（參考；校準未使用共識）
A24: FY2026 營收 ÷ 共識 − 1 | B24: =H4/cons_rev26-1 -> -0.013999476
A25: FY2026 EPS ÷ 共識 − 1 | B25: =H17/cons_eps26-1 -> -0.0054792778
A26: FY2026 營收年增 | B26: =H4/C4-1 -> 1.209039
A27: FY2026 營業費用年增 | B27: =H7/C7-1 -> 0.87736956
A28: 營業費用彈性（營業費用年增 ÷ 營收年增；In 頁 phi 的依據） | B28: =B27/B26 -> 0.72567513
A29: 2Q26 EPS（模型）vs 公司揭露 0.80 | B29: =E17/q2_eps-1 -> -0.0058361514
A30: 3Q26 EPS（模型）vs 指引中點 1.185 | B30: =F17/q3_eps-1 -> 0.0055422511
A31: 4Q26 營收 ÷ 共識 − 1 | B31: =G4/cons_q4-1 -> -0.035396746

Sheet Units
A1: Units — Astera Labs 在非 NVIDIA scale-up 交換晶片（Scorpio X）與 PCIe／CXL／AEC 的份額（本專案權威，規則第 13 條）。市場取自 markets/network（加速器顆數 × 每顆內容；日曆年＝會計年度）
A3: 項目 | B3: 單位 | C3: FY2026（錨點） | D3: FY2027 | E3: FY2028 | F3: FY2029 | G3: 說明
A4: scale-up 交換晶片市場合計（含 NVIDIA NVLink；情境 A） | B4: US$B | C4: =msu_26 -> 18.2761 | D4: =msu_27 -> 37.4157 | E4: =msu_28 -> 44.9835 | F4: =msu_29 -> 51.2458 | G4: markets/network Mkt 頁「scale-up 交換晶片」
A5: 其中非 NVIDIA、非 TPU（Scorpio X 可服務市場） | B5: US$B | C5: =PL!D63 -> 2.025 | D5: =PL!E63 -> 7.701 | E5: =PL!F63 -> 9.468 | F5: =PL!G63 -> 10.8882 | G5: AMD、Trainium、其他 ASIC
A6: Astera Scorpio X 營收（情境 A） | B6: US$B | C6: =PL!D67 -> 0.38 | D6: =PL!E67 -> 1.4451259 | E6: =PL!F67 -> 1.9543822 | F6: =PL!G67 -> 2.3497004 | G6: FY2026 為假設（公司未揭露）
A7: Scorpio X 有效份額（÷ 非 NVIDIA scale-up 交換晶片） | B7: % | C7: =PL!D66 -> 0.18765432 | D7: =PL!E66 -> 0.18765432 | E7: =PL!F66 -> 0.20641975 | F7: =PL!G66 -> 0.21580247 | G7: FY2026 校準
A8: Scorpio X ÷ scale-up 交換晶片合計 | B8: % | C8: =PL!D67/C4 -> 0.020792182 | D8: =PL!E67/D4 -> 0.038623517 | E8: =PL!F67/E4 -> 0.043446646 | F8: =PL!G67/F4 -> 0.045851571 | G8: 含 NVIDIA NVLink 的分母
A9: Scorpio X 每顆非 NVIDIA 加速器營收（美元／顆） | B9: US$/顆 | C9: =PL!D67*1000/nnu_26 -> 101.33333 | D9: =PL!E67*1000/nnu_27 -> 170.01481 | E9: =PL!F67*1000/nnu_28 -> 195.43822 | F9: =PL!G67*1000/nnu_29 -> 204.32178 | G9: 公司：現有設計案每顆加速器內容逾 1,000 美元（採用該平台者）
A10: AI 加速器顆數（情境 A） | B10: 百萬顆 | C10: =PL!D69 -> 15.2 | D10: =PL!E69 -> 23.7 | E10: =PL!F69 -> 26.5 | F10: =PL!G69 -> 30.15 | G10: markets/network Units 頁
A11: Astera PCIe 與訊號調節營收（情境 A） | B11: US$B | C11: =PL!D73 -> 1.503261 | D11: =PL!E73 -> 1.8751203 | E11: =PL!F73 -> 1.9656127 | F11: =PL!G73 -> 2.0872581 | G11: FY2026 為錨點殘差
A12: PCIe 等每顆加速器營收（美元／顆） | B12: US$/顆 | C12: =PL!D73*1000/PL!D69 -> 98.89875 | D12: =PL!E73*1000/PL!E69 -> 79.119 | E12: =PL!F73*1000/PL!F69 -> 74.174063 | F12: =PL!G73*1000/PL!G69 -> 69.229125 | G12: ＝c_pcie × 有效份額
A13: PCIe 等有效份額（÷ 顆數 × c_pcie） | B13: % | C13: =PL!D73/PL!D70 -> 0.395595 | D13: =PL!E73/PL!E70 -> 0.316476 | E13: =PL!F73/PL!F70 -> 0.29669625 | F13: =PL!G73/PL!G70 -> 0.2769165 | G13: c_pcie 250 美元／顆（Assumed）
A14: Astera 營收 ÷ AI IT 資本支出 | B14: % | C14: =PL!D75/itc_26 -> 0.0024086536 | D14: =PL!E75/itc_27 -> 0.0021210887 | E14: =PL!F75/itc_28 -> 0.0019755411 | F14: =PL!G75/itc_29 -> 0.001962917 | G14: markets/network 的 AI IT 資本支出
A16: 讀法：Scorpio X 的 FY2026 營收為假設（公司未揭露產品線），PCIe 等為殘差；兩者的份額相對值是 Assumed，是最需要每季檢查的輸入。每顆加速器營收 ＝ Astera 營收 ÷ 顆數，可直接與公司「每顆逾 1,000 美元」的說法對照。

Sheet PL
A1: PL — Astera Labs 損益（US$B；non-GAAP）。FY2025A 實績、FY2026 錨點（1Q26、2Q26 實績＋3Q26 指引＋4Q26 假設），FY2027 起為模型。會計年度＝日曆年。三情境各一個完整推導區塊（本頁下方），頂端為摘要。FY2026–FY2027 三情境相同（顆數係數 CY2028 起），差異在 FY2028 起
A2: 灰底＝FY2030–FY2032 收斂法，非驅動因子推導（上游市場層只到 2029）：營收年增由 FY2029 線性收斂到 fade_g（A＝tp_g＋2pt、B＝tp_g、C＝tp_g−2pt），淨利率由 FY2029 線性收斂到 fade_m（In 頁 K 節），FY2032 達到；股數依 sh_g
A3: 情境／項目 | B3: 單位 | C3: FY2025A | D3: FY2026（錨點） | E3: FY2027 | F3: FY2028 | G3: FY2029 | H3: FY2030（收斂） | I3: FY2031（收斂） | J3: FY2032（收斂） | K3: 說明
A4: 情境 A
A5: 營收 | B5: US$B | C5: =C75 -> 0.852525 | D5: =D75 -> 1.883261 | E5: =E75 -> 3.3202462 | F5: =F75 -> 3.9199949 | G5: =G75 -> 4.4369586 | H5: =H75 -> 4.9157912 | I5: =I75 -> 5.3285188 | J5: =J75 -> 5.6482299
A6: 營收年增 | B6: % | D6: =D76 -> 1.209039 | E6: =E76 -> 0.76303031 | F6: =F76 -> 0.18063379 | G6: =G76 -> 0.13187866 | H6: =H76 -> 0.10791911 | I6: =I76 -> 0.083959554 | J6: =J76 -> 0.06
A7: Scorpio X 營收 | B7: US$B | C7: =C67 -> 0 | D7: =D67 -> 0.38 | E7: =E67 -> 1.4451259 | F7: =F67 -> 1.9543822 | G7: =G67 -> 2.3497004
A8: PCIe 與訊號調節營收 | B8: US$B | C8: =C73 -> 0.852525 | D8: =D73 -> 1.503261 | E8: =E73 -> 1.8751203 | F8: =F73 -> 1.9656127 | G8: =G73 -> 2.0872581
A9: 毛利率 | B9: % | C9: =C79 -> 0.75819947 | D9: =D79 -> 0.72912703 | E9: =E79 -> 0.7 | F9: =F79 -> 0.695 | G9: =G79 -> 0.69
A10: 營業利益率 | B10: % | C10: =C84 -> 0.3922536 | D10: =D84 -> 0.418125 | E10: =E84 -> 0.42592211 | F10: =F84 -> 0.43242542 | G10: =G84 -> 0.43581795
A11: 淨利率 | B11: % | C11: =C88 -> 0.388276 | D11: =D88 -> 0.39158354 | E11: =E88 -> 0.38806349 | F11: =F88 -> 0.39175888 | G11: =G88 -> 0.3934365 | H11: =H88 -> 0.3934365 | I11: =I88 -> 0.3934365 | J11: =J88 -> 0.3934365
A12: 淨利 | B12: US$B | C12: =C87 -> 0.331015 | D12: =D87 -> 0.737454 | E12: =E87 -> 1.2884663 | F12: =F87 -> 1.5356928 | G12: =G87 -> 1.7456614 | H12: =H87 -> 1.9340517 | I12: =I87 -> 2.0964338 | J12: =J87 -> 2.2222198
A13: EPS（non-GAAP） | B13: US$ | C13: =C90 -> 1.8435709 | D13: =D90 -> 4.0079185 | E13: =E90 -> 6.8990768 | F13: =F90 -> 8.1013279 | G13: =G90 -> 9.072894 | H13: =H90 -> 9.9034804 | I13: =I90 -> 10.576327 | J13: =J90 -> 11.045229
A14: EPS 年增 | B14: % | D14: =D91 -> 1.1739975 | E14: =E91 -> 0.72136153 | F14: =F91 -> 0.17426261 | G14: =G91 -> 0.11992677 | H14: =H91 -> 0.09154592 | I14: =I91 -> 0.067940448 | J14: =J91 -> 0.044334975
A16: 情境 B
A17: 營收 | B17: US$B | C17: =C109 -> 0.852525 | D17: =D109 -> 1.883261 | E17: =E109 -> 3.3202462 | F17: =F109 -> 3.1359959 | G17: =G109 -> 3.7714148 | H17: =H109 -> 4.3311457 | I17: =I109 -> 4.7391701 | J17: =J109 -> 4.9287369
A18: 營收年增 | B18: % | D18: =D110 -> 1.209039 | E18: =E110 -> 0.76303031 | F18: =F110 -> -0.05549297 | G18: =G110 -> 0.20262108 | H18: =H110 -> 0.14841405 | I18: =I110 -> 0.094207027 | J18: =J110 -> 0.04
A19: Scorpio X 營收 | B19: US$B | C19: =C101 -> 0 | D19: =D101 -> 0.38 | E19: =E101 -> 1.4451259 | F19: =F101 -> 1.5635058 | G19: =G101 -> 1.9972454
A20: PCIe 與訊號調節營收 | B20: US$B | C20: =C107 -> 0.852525 | D20: =D107 -> 1.503261 | E20: =E107 -> 1.8751203 | F20: =F107 -> 1.5724901 | G20: =G107 -> 1.7741694
A21: 毛利率 | B21: % | C21: =C113 -> 0.75819947 | D21: =D113 -> 0.72912703 | E21: =E113 -> 0.7 | F21: =F113 -> 0.695 | G21: =G113 -> 0.69
A22: 營業利益率 | B22: % | C22: =C118 -> 0.3922536 | D22: =D118 -> 0.418125 | E22: =E118 -> 0.42592211 | F22: =F118 -> 0.40481911 | G22: =G118 -> 0.41323099
A23: 淨利率 | B23: % | C23: =C122 -> 0.388276 | D23: =D122 -> 0.39158354 | E23: =E122 -> 0.38806349 | F23: =F122 -> 0.37027145 | G23: =G122 -> 0.37530998 | H23: =H122 -> 0.36279965 | I23: =I122 -> 0.35028932 | J23: =J122 -> 0.33777899
A24: 淨利 | B24: US$B | C24: =C121 -> 0.331015 | D24: =D121 -> 0.737454 | E24: =E121 -> 1.2884663 | F24: =F121 -> 1.1611697 | G24: =G121 -> 1.4154496 | H24: =H121 -> 1.5713382 | I24: =I121 -> 1.6600807 | J24: =J121 -> 1.6648238
A25: EPS（non-GAAP） | B25: US$ | C25: =C124 -> 1.8435709 | D25: =D124 -> 4.0079185 | E25: =E124 -> 6.8990768 | F25: =F124 -> 6.125585 | G25: =G124 -> 7.3566524 | H25: =H124 -> 8.0461743 | I25: =I124 -> 8.3749636 | J25: =J124 -> 8.2747705
A26: EPS 年增 | B26: % | D26: =D125 -> 1.1739975 | E26: =E125 -> 0.72136153 | F26: =F125 -> -0.11211525 | G26: =G125 -> 0.2009714 | H26: =H125 -> 0.09372767 | I26: =I125 -> 0.040862808 | J26: =J125 -> -0.011963406
A28: 情境 C
A29: 營收 | B29: US$B | C29: =C143 -> 0.852525 | D29: =D143 -> 1.883261 | E29: =E143 -> 3.3202462 | F29: =F143 -> 2.3519969 | G29: =G143 -> 2.6621751 | H29: =H143 -> 2.913979 | I29: =I143 -> 3.0809293 | J29: =J143 -> 3.1425479
A30: 營收年增 | B30: % | D30: =D144 -> 1.209039 | E30: =E144 -> 0.76303031 | F30: =F144 -> -0.29161973 | G30: =G144 -> 0.13187866 | H30: =H144 -> 0.094585776 | I30: =I144 -> 0.057292888 | J30: =J144 -> 0.02
A31: Scorpio X 營收 | B31: US$B | C31: =C135 -> 0 | D31: =D135 -> 0.38 | E31: =E135 -> 1.4451259 | F31: =F135 -> 1.1726293 | G31: =G135 -> 1.4098203
A32: PCIe 與訊號調節營收 | B32: US$B | C32: =C141 -> 0.852525 | D32: =D141 -> 1.503261 | E32: =E141 -> 1.8751203 | F32: =F141 -> 1.1793676 | G32: =G141 -> 1.2523549
A33: 毛利率 | B33: % | C33: =C147 -> 0.75819947 | D33: =D147 -> 0.72912703 | E33: =E147 -> 0.7 | F33: =F147 -> 0.695 | G33: =G147 -> 0.69
A34: 營業利益率 | B34: % | C34: =C152 -> 0.3922536 | D34: =D152 -> 0.418125 | E34: =E152 -> 0.42592211 | F34: =F152 -> 0.30809215 | G34: =G152 -> 0.31545866
A35: 淨利率 | B35: % | C35: =C156 -> 0.388276 | D35: =D156 -> 0.39158354 | E35: =E156 -> 0.38806349 | F35: =F156 -> 0.2898286 | G35: =G156 -> 0.29413146 | H35: =H156 -> 0.2745227 | I35: =I156 -> 0.25491393 | J35: =J156 -> 0.23530517
A36: 淨利 | B36: US$B | C36: =C155 -> 0.331015 | D36: =D155 -> 0.737454 | E36: =E155 -> 1.2884663 | F36: =F155 -> 0.68167597 | G36: =G155 -> 0.78302947 | H36: =H155 -> 0.79995339 | I36: =I155 -> 0.78537181 | J36: =J155 -> 0.73945777
A37: EPS（non-GAAP） | B37: US$ | C37: =C158 -> 1.8435709 | D37: =D158 -> 4.0079185 | E37: =E158 -> 6.8990768 | F37: =F158 -> 3.5960842 | G37: =G158 -> 4.0697143 | H37: =H158 -> 4.0962312 | I37: =I158 -> 3.962133 | J37: =J158 -> 3.67537
A38: EPS 年增 | B38: % | D38: =D159 -> 1.1739975 | E38: =E159 -> 0.72136153 | F38: =F159 -> -0.47875864 | G38: =G159 -> 0.1317072 | H38: =H159 -> 0.0065156557 | I38: =I159 -> -0.032736978 | J38: =J159 -> -0.0723759
A40: 核對（應為 0）：FY2026 模型營收、Scorpio X 營收、淨利 − 錨點（校準恆等式）
A41: 情境 A：營收差（US$B） | D41: =D75-a26_rev -> 0
A42: 情境 A：Scorpio X 營收 − 市場 × 有效份額（US$B） | D42: =D67-D63*D66 -> 0
A43: 情境 A：（營業利益＋其他收益）×（1 − 稅率）− 淨利錨點 | D43: =(D83+D85)*(1-D86)-a26_ni -> 0
...

Sheet Val
A1: Val — P/E 估值（美元）。目標價＝DCF 與 Comparable 加權（第 0 節）；舊法規則值情境加權保留參考；另列「現價 ÷ FY2027、FY2028 EPS（模型，non-GAAP）」、市場隱含 EPS 與十年 P/E 規則值。Astera Labs 2024-03 上市，年底 P/E 只有 2024–2025，且 2024 為虧損（負值，不用）：規則值只有 2025 年一個觀測值（兩個來源）
A2: 循環位置：Astera Labs 不是設備股，不套設備市場見頂年；以本模型營收最高的會計年度為見頂年（比照 Arista、Credo）。營收到 FY2029 仍在增加時，見頂年未知，判為中段。規則值基準＝FY2027 GAAP 換算 EPS（non-GAAP × g2n），與年底 P/E 的計算口徑一致
A4: 0. 目標價
A5: 0.1 DCF（股東權益現金流，FY2027–FY2032 明確期＋FY2032 後永續）
A6: 項目 | B6: A（順利） | C6: B（平平） | D6: C（不如預期） | E6: 說明
A7: 情境 EPS（FY2027–FY2032） | E7: PL 頁各情境；FY2030 起為收斂法（PL 頁灰底）
A8: FY2027 | B8: =PL!E13 -> 6.8990768 | C8: =PL!E25 -> 6.8990768 | D8: =PL!E37 -> 6.8990768
A9: FY2028 | B9: =PL!F13 -> 8.1013279 | C9: =PL!F25 -> 6.125585 | D9: =PL!F37 -> 3.5960842
A10: FY2029 | B10: =PL!G13 -> 9.072894 | C10: =PL!G25 -> 7.3566524 | D10: =PL!G37 -> 4.0697143
A11: FY2030 | B11: =PL!H13 -> 9.9034804 | C11: =PL!H25 -> 8.0461743 | D11: =PL!H37 -> 4.0962312
A12: FY2031 | B12: =PL!I13 -> 10.576327 | C12: =PL!I25 -> 8.3749636 | D12: =PL!I37 -> 3.962133
A13: FY2032 | B13: =PL!J13 -> 11.045229 | C13: =PL!J25 -> 8.2747705 | D13: =PL!J37 -> 3.67537
A14: 股東現金流＝EPS ×（1 − tp_g ÷ tp_roe）
A15: 再投資率（tp_g ÷ tp_roe，上限 0.8） | B15: =IF(tp_roe<=tp_g,0.8,MIN(tp_g/tp_roe,0.8)) -> 0.14447401 | E15: ROE＝In 頁 tp_roe；tp_roe ≤ tp_g 時取上限 0.8
A16: FY2027 | B16: =B8*(1-$B$15) -> 5.9023395 | C16: =C8*(1-$B$15) -> 5.9023395 | D16: =D8*(1-$B$15) -> 5.9023395
A17: FY2028 | B17: =B9*(1-$B$15) -> 6.9308965 | C17: =C9*(1-$B$15) -> 5.2405972 | D17: =D9*(1-$B$15) -> 3.0765434
A18: FY2029 | B18: =B10*(1-$B$15) -> 7.7620966 | C18: =C10*(1-$B$15) -> 6.2938073 | D18: =D10*(1-$B$15) -> 3.4817464
A19: FY2030 | B19: =B11*(1-$B$15) -> 8.4726848 | C19: =C11*(1-$B$15) -> 6.8837112 | D19: =D11*(1-$B$15) -> 3.5044322
A20: FY2031 | B20: =B12*(1-$B$15) -> 9.0483228 | C20: =C12*(1-$B$15) -> 7.164999 | D20: =D12*(1-$B$15) -> 3.3897077
A21: FY2032 | B21: =B13*(1-$B$15) -> 9.44948 | C21: =C13*(1-$B$15) -> 7.0792812 | D21: =D13*(1-$B$15) -> 3.1443746
A22: DCF 情境每股價值（折現率 tp_r） | B22: =MAX(0,SUMPRODUCT(B16:B21,1/(1+tp_r)^{1;2;3;4;5;6})+B21*(1+tp_g)/(tp_r-tp_g)/(1+tp_r)^6) -> 126.12054 | C22: =MAX(0,SUMPRODUCT(C16:C21,1/(1+tp_r)^{1;2;3;4;5;6})+C21*(1+tp_g)/(tp_r-tp_g)/(1+tp_r)^6) -> 96.837311 | D22: =MAX(0,SUMPRODUCT(D16:D21,1/(1+tp_r)^{1;2;3;4;5;6})+D21*(1+tp_g)/(tp_r-tp_g)/(1+tp_r)^6) -> 47.562718 | E22: Σ 明確期現金流 ÷ (1＋r)^t ＋ 永續價值 ÷ (1＋r)^6；永續價值＝FY2032 現金流 ×(1＋g)÷(r−g)；基準日 2026 年底，t＝1 對 FY2027；小於 0 時取 0（股東有限責任）
A23: DCF 情境價值推到 12 個月後（×(1＋tp_r)） | B23: =B22*(1+tp_r) -> 138.73259 | C23: =C22*(1+tp_r) -> 106.52104 | D23: =D22*(1+tp_r) -> 52.31899
A24: DCF 目標價（情境加權） | B24: =tp_wA*B23+tp_wB*C23+tp_wC*D23 -> 105.3441 | E24: Σ 權重 × 情境價值 ×(1＋r)；權重見 In 頁
A26: 0.2 Comparable（市場主流同業前瞻 P/E）
A27: 同業與前瞻 P/E | B27: 代號 | C27: 前瞻 12 月 P/E | D27: 日期 | E27: 來源 | F27: 標記
A28: Credo | B28: CRDO | C28: 20.19 | D28: 2026-10-23 | E28: stockanalysis forward PE（分析師共識；價格日期如左） | F28: Interested-party
A29: Marvell | B29: MRVL | C29: 40.44 | D29: 2026-10-23 | E29: stockanalysis forward PE（分析師共識；價格日期如左） | F29: Interested-party
A30: Broadcom | B30: AVGO | C30: 18.52 | D30: 2026-10-23 | E30: stockanalysis forward PE（分析師共識；價格日期如左） | F30: Interested-party
A31: Rambus | B31: RMBS | C31: 25.23 | D31: 2026-10-23 | E31: stockanalysis forward PE（分析師共識；價格日期如左） | F31: Interested-party
A32: MACOM | B32: MTSI | C32: 28.59 | D32: 2026-10-23 | E32: stockanalysis forward PE（分析師共識；價格日期如左） | F32: Interested-party
A33: 同業前瞻 P/E 中位數 | B33: =MEDIAN(C28:C32) -> 25.23 | E33: 美股高速連接晶片同業（Credo、Marvell、Broadcom、Rambus、MACOM；10-K 列名競爭者為主；不放 A 股）
A34: 12 個月後的前瞻 EPS（情境加權） | B34: =tp_wA*(2/12*B8+10/12*B9)+tp_wB*(2/12*C8+10/12*C9)+tp_wC*(2/12*D8+10/12*D9) -> 6.3268525 | E34: 約 2027-10 時的未來 12 月（2027-11～2028-10）≈ 2／12 × FY2027＋10／12 × FY2028（會計年度＝日曆年）
A35: Comparable 目標價 | B35: =B33*B34 -> 159.62649 | E35: 同業中位數 × 前瞻 EPS
A37: 0.3 結論
A38: 項目 | B38: 數值 | E38: 說明
A39: 目標價（DCF 與 Comparable 加權） | B39: =tp_w_dcf*B24+(1-tp_w_dcf)*B35 -> 132.48529 | E39: tp_w_dcf × DCF＋（1 − tp_w_dcf）× Comparable；tp_w_dcf 見 In 頁
A40: Comparable 目標價（市場主流同業法） | B40: =B35 -> 159.62649
A41: 市場共識目標價 | B41: =cons_tp -> 388.36 | E41: In 頁 tp_street：stockanalysis 26 家平均 388.36（資料 2026-10-16；190–500）
A42: 上檔空間：加權目標價 | B42: =B39/px-1 -> -0.48481376 | E42: 現價＝In 頁 px
A43: 上檔空間：Comparable 目標價 | B43: =B40/px-1 -> -0.3792717
...

Sheet Recon
A1: Recon — 本模型 vs 共識、公司說法、市場層。只作事後對照，不為對上數字而調參數。共識 FY2027 EPS 區間 4.35–8.80
A3: 項目 | B3: 對照值 | C3: 模型 A | D3: 差距 A | E3: 模型 B | F3: 差距 B | G3: 模型 C | H3: 差距 C | I3: 對照來源 | J3: 說明
A4: A. 共識與指引（校準未使用共識）
A5: 3Q26 營收（指引中點）vs 共識 | B5: =cons_q3 -> 0.5508 | C5: =Q!F4 -> 0.55 | D5: =C5/B5-1 -> -0.0014524328 | E5: =Q!F4 -> 0.55 | F5: =E5/B5-1 -> -0.0014524328 | G5: =Q!F4 -> 0.55 | H5: =G5/B5-1 -> -0.0014524328 | I5: Yahoo（18 家） | J5: 指引 5.40–5.60
A6: 4Q26 營收（模型假設）vs 共識 | B6: =cons_q4 -> 0.65571 | C6: =Q!G4 -> 0.6325 | D6: =C6/B6-1 -> -0.035396746 | E6: =Q!G4 -> 0.6325 | F6: =E6/B6-1 -> -0.035396746 | G6: =Q!G4 -> 0.6325 | H6: =G6/B6-1 -> -0.035396746 | I6: Yahoo（18 家；6.09–7.38） | J6: 季增 15%（Assumed）
A7: FY2026 營收 vs 共識 | B7: =cons_rev26 -> 1.91 | C7: =PL!D75 -> 1.883261 | D7: =C7/B7-1 -> -0.013999476 | E7: =PL!D109 -> 1.883261 | F7: =E7/B7-1 -> -0.013999476 | G7: =PL!D143 -> 1.883261 | H7: =G7/B7-1 -> -0.013999476 | I7: Yahoo（21 家；1.86–1.99）
A8: FY2026 EPS vs 共識 | B8: =cons_eps26 -> 4.03 | C8: =PL!D90 -> 4.0079185 | D8: =C8/B8-1 -> -0.0054792778 | E8: =PL!D124 -> 4.0079185 | F8: =E8/B8-1 -> -0.0054792778 | G8: =PL!D158 -> 4.0079185 | H8: =G8/B8-1 -> -0.0054792778 | I8: Yahoo（21 家；3.90–4.33）
A9: FY2027 營收 vs 共識 | B9: =cons_rev27 -> 2.98 | C9: =PL!E75 -> 3.3202462 | D9: =C9/B9-1 -> 0.11417659 | E9: =PL!E109 -> 3.3202462 | F9: =E9/B9-1 -> 0.11417659 | G9: =PL!E143 -> 3.3202462 | H9: =G9/B9-1 -> 0.11417659 | I9: Yahoo（24 家；2.19–3.68）
A10: FY2027 EPS vs 共識 | B10: =cons_eps27 -> 6.4 | C10: =PL!E90 -> 6.8990768 | D10: =C10/B10-1 -> 0.077980743 | E10: =PL!E124 -> 6.8990768 | F10: =E10/B10-1 -> 0.077980743 | G10: =PL!E158 -> 6.8990768 | H10: =G10/B10-1 -> 0.077980743 | I10: Yahoo（23 家；4.35–8.80）
A11: FY2028 營收 vs 共識 | B11: =cons_rev28 -> 3.835 | C11: =PL!F75 -> 3.9199949 | D11: =C11/B11-1 -> 0.022162941 | E11: =PL!F109 -> 3.1359959 | F11: =E11/B11-1 -> -0.18226965 | G11: =PL!F143 -> 2.3519969 | H11: =G11/B11-1 -> -0.38670224 | I11: MarketScreener（26 家）
A12: FY2028 EPS vs 共識（推導） | B12: =cons_eps28 -> 8.5710676 | C12: =PL!F90 -> 8.1013279 | D12: =C12/B12-1 -> -0.054805277 | E12: =PL!F124 -> 6.125585 | F12: =E12/B12-1 -> -0.28531831 | G12: =PL!F158 -> 3.5960842 | H12: =G12/B12-1 -> -0.58043918 | I12: MarketScreener GAAP × non-GAAP／GAAP 比 | J12: 共識 non-GAAP FY2028：未找到
A13: FY2027 毛利率 vs 公司長期目標 70% | B13: 0.7 | C13: =PL!E79 -> 0.7 | D13: =C13-B13 -> 0 | E13: =PL!E113 -> 0.7 | F13: =E13-B13 -> 0 | G13: =PL!E147 -> 0.7 | H13: =G13-B13 -> 0 | I13: 公司 2Q26 法說
A14: B. 份額與市場（機制檢查）
A15: FY2028 Scorpio X 每顆非 NVIDIA 加速器營收（美元／顆）vs 公司「逾 1,000 美元」 | B15: 1000 | C15: =PL!F67*1000/nnu_28 -> 195.43822 | D15: =C15/B15-1 -> -0.80456178 | E15: =PL!F101*1000/nnu_28 -> 156.35058 | F15: =E15/B15-1 -> -0.84364942 | G15: =PL!F135*1000/nnu_28 -> 117.26293 | H15: =G15/B15-1 -> -0.88273707 | I15: 公司 1Q26 法說 | J15: 公司說法為採用平台的每顆內容；本列分母為全部非 NVIDIA、非 TPU 加速器
A16: FY2029 非 NVIDIA scale-up 交換晶片市場（網通模型）vs 公司 2030 年商用 scale-up 交換 200 億美元 | B16: =tam_su -> 20 | C16: =PL!G63 -> 10.8882 | D16: =C16/B16-1 -> -0.45559 | E16: =PL!G97 -> 9.25497 | F16: =E16/B16-1 -> -0.5372515 | G16: =PL!G131 -> 6.53292 | H16: =G16/B16-1 -> -0.673354 | I16: 公司 4Q25 新聞稿（Interested-party） | J16: 口徑不同：公司數字為 2030 年、含所有商用 scale-up 交換
A17: FY2027 Scorpio X 有效份額（÷ 非 NVIDIA scale-up 交換） | C17: =PL!E66 -> 0.18765432 | E17: =PL!E100 -> 0.18765432 | G17: =PL!E134 -> 0.18765432 | I17: —
A18: FY2028 Astera 營收 ÷ AI IT 資本支出 | C18: =PL!F75/itc_28 -> 0.0019755411 | E18: =PL!F109/itc_28 -> 0.0015804329 | G18: =PL!F143/itc_28 -> 0.0011853247 | I18: markets/network | J18: 每 1 美元 AI IT 資本支出分到的 Astera 營收
A19: C. 校準
A20: 2Q26 EPS（模型）vs 公司揭露 0.80 | B20: =q2_eps -> 0.8 | C20: =Q!E17 -> 0.79533108 | D20: =C20/B20-1 -> -0.0058361514 | E20: =Q!E17 -> 0.79533108 | F20: =E20/B20-1 -> -0.0058361514 | G20: =Q!E17 -> 0.79533108 | H20: =G20/B20-1 -> -0.0058361514 | I20: 公司 | J20: 淨利 ÷ 稀釋股數
A21: 3Q26 EPS（模型）vs 指引中點 | B21: =q3_eps -> 1.185 | C21: =Q!F17 -> 1.1915676 | D21: =C21/B21-1 -> 0.0055422511 | E21: =Q!F17 -> 1.1915676 | F21: =E21/B21-1 -> 0.0055422511 | G21: =Q!F17 -> 1.1915676 | H21: =G21/B21-1 -> 0.0055422511 | I21: 公司指引 1.16–1.21
A22: FY2025 EPS（模型）vs 公司揭露 1.84 | B22: =a25_eps_in -> 1.84 | C22: =PL!C90 -> 1.8435709 | D22: =C22/B22-1 -> 0.0019407106 | E22: =PL!C124 -> 1.8435709 | F22: =E22/B22-1 -> 0.0019407106 | G22: =PL!C158 -> 1.8435709 | H22: =G22/B22-1 -> 0.0019407106 | I22: 公司
A23: FY2026 營業費用彈性（Derived） | C23: =Q!B28 -> 0.72567513 | E23: =Q!B28 -> 0.72567513 | G23: =Q!B28 -> 0.72567513 | I23: Q 頁
A24: D. 預留
A25: R4 產業部署路徑（markets/deploy_path/，尚未建立）：上線後以 Astera 營收 ÷ 部署 GW 計算每 GW 營收 | J25: 預留列：本版無數值
A26: 3Q26 財報（2026-11-03）：公布後以實績取代 Q 頁 3Q 指引，並依 4Q26 指引更新 g_q4 | J26: 預留列：本版無數值

Sheet Sens
A1: Sens — 一次動一個輸入（情境 A；有效份額在每個案例內依 FY2026 錨點重算，FY2026 恆等於錨點）：對 FY2027、FY2028 的營收、Scorpio X 營收、毛利率與 EPS 的影響。每個案例是一個完整推導區塊（本頁下方）
A3: 案例 | B3: 設定 | C3: FY2027 營收 | D3: FY2027 Scorpio X 營收 | E3: FY2027 毛利率 | F3: FY2027 EPS | G3: FY2027 EPS 相對基準 | H3: FY2028 營收 | I3: FY2028 Scorpio X 營收 | J3: FY2028 毛利率 | K3: FY2028 EPS | L3: FY2028 EPS 相對基準
A4: 基準（情境 A） | B4: PL 區塊 A | C4: =PL!E75 -> 3.3202462 | D4: =PL!E67 -> 1.4451259 | E4: =PL!E79 -> 0.7 | F4: =PL!E90 -> 6.8990768 | G4: =F4/F$4-1 -> 0 | H4: =PL!F75 -> 3.9199949 | I4: =PL!F67 -> 1.9543822 | J4: =PL!F79 -> 0.695 | K4: =PL!F90 -> 8.1013279 | L4: =K4/K$4-1 -> 0
A5: Scorpio X 份額 低 | B5: Scorpio X 有效份額相對值 FY2027 0.70、FY2028 0.60、FY2029 0.50（Broadcom、NVLink Fusion、其他 UALink 交換晶片搶份額） | C5: =E55 -> 2.8867084 | D5: =E47 -> 1.0115881 | E5: =E59 -> 0.7 | F5: =E70 -> 5.9301453 | G5: =F5/F$4-1 -> -0.14044364 | H5: =F55 -> 3.0316393 | I5: =F47 -> 1.0660267 | J5: =F59 -> 0.695 | K5: =F70 -> 6.1057433 | L5: =K5/K$4-1 -> -0.24632808
A6: Scorpio X 份額 高 | B6: FY2027 1.40、FY2028 1.70、FY2029 2.00（逾 10 家客戶陸續量產） | C6: =E89 -> 3.8982966 | D6: =E81 -> 2.0231763 | E6: =E93 -> 0.7 | F6: =E104 -> 8.1909854 | G6: =F6/F$4-1 -> 0.18725819 | H6: =F89 -> 4.9860215 | I6: =F81 -> 3.0204089 | J6: =F93 -> 0.695 | K6: =F104 -> 10.510875 | L6: =K6/K$4-1 -> 0.29742617
A7: PCIe 等份額 低 | B7: PCIe 等相對值 FY2027 0.65、FY2028 0.55、FY2029 0.45（重定時器價格戰、平台整合） | C7: =E123 -> 2.9686612 | D7: =E115 -> 1.4451259 | E7: =E127 -> 0.7 | F7: =E138 -> 6.1133048 | G7: =F7/F$4-1 -> -0.11389523 | H7: =F123 -> 3.3958315 | I7: =F115 -> 1.9543822 | J7: =F127 -> 0.695 | K7: =F138 -> 6.9296181 | L7: =K7/K$4-1 -> -0.14463182
A8: PCIe 等份額 高 | B8: 相對值 1.00（PCIe 7 單價上升抵銷份額競爭） | C8: =E157 -> 3.7890263 | D8: =E149 -> 1.4451259 | E8: =E161 -> 0.7 | F8: =E172 -> 7.9467727 | G8: =F8/F$4-1 -> 0.15186031 | H8: =F157 -> 4.5751991 | I8: =F149 -> 1.9543822 | J8: =F161 -> 0.695 | K8: =F172 -> 9.5678678 | L8: =K8/K$4-1 -> 0.18102463
A9: 最大客戶部分轉單 | B9: 最大終端客戶（逾 70%）的 PCIe 等內容 30% 轉給他人或自製 | C9: =E191 -> 2.926471 | D9: =E183 -> 1.4451259 | E9: =E195 -> 0.7 | F9: =E206 -> 6.0190122 | G9: =F9/F$4-1 -> -0.12756266 | H9: =F191 -> 3.5072162 | I9: =F183 -> 1.9543822 | J9: =F195 -> 0.695 | K9: =F206 -> 7.1869037 | L9: =K9/K$4-1 -> -0.11287336
A10: 毛利率 低 | B10: 毛利率 FY2027 66%、FY2028 65%、FY2029 64% | C10: =E225 -> 3.3202462 | D10: =E217 -> 1.4451259 | E10: =E229 -> 0.66 | F10: =E240 -> 6.2732835 | G10: =F10/F$4-1 -> -0.090706808 | H10: =F225 -> 3.9199949 | I10: =F217 -> 1.9543822 | J10: =F229 -> 0.65 | K10: =F240 -> 7.2824247 | L10: =K10/K$4-1 -> -0.10108259
A11: 毛利率 高 | B11: 毛利率 72% | C11: =E259 -> 3.3202462 | D11: =E251 -> 1.4451259 | E11: =E263 -> 0.72 | F11: =E274 -> 7.2119734 | G11: =F11/F$4-1 -> 0.045353404 | H11: =F259 -> 3.9199949 | I11: =F251 -> 1.9543822 | J11: =F263 -> 0.72 | K11: =F274 -> 8.5562741 | L11: =K11/K$4-1 -> 0.056156992
A12: 稅率 15% | B12: FY2027 起 non-GAAP 稅率 15% | C12: =E293 -> 3.3202462 | D12: =E285 -> 1.4451259 | E12: =E297 -> 0.7 | F12: =E308 -> 6.663881 | G12: =F12/F$4-1 -> -0.034090909 | H12: =F293 -> 3.9199949 | I12: =F285 -> 1.9543822 | J12: =F297 -> 0.695 | K12: =F308 -> 7.8251462 | L12: =K12/K$4-1 -> -0.034090909
A13: 稅率 10% | B13: FY2027 起 10% | C13: =E327 -> 3.3202462 | D13: =E319 -> 1.4451259 | E13: =E331 -> 0.7 | F13: =E342 -> 7.055874 | G13: =F13/F$4-1 -> 0.022727273 | H13: =F327 -> 3.9199949 | I13: =F319 -> 1.9543822 | J13: =F331 -> 0.695 | K13: =F342 -> 8.2854489 | L13: =K13/K$4-1 -> 0.022727273
A14: 非 NVIDIA scale-up 交換市場 ×0.8 | B14: FY2027 起 ×0.8（NVLink Fusion、乙太網路 scale-up 搶占） | C14: =E361 -> 3.031221 | D14: =E353 -> 1.1561007 | E14: =E365 -> 0.7 | F14: =E376 -> 6.2531224 | G14: =F14/F$4-1 -> -0.093629096 | H14: =F361 -> 3.5291184 | I14: =F353 -> 1.5635058 | J14: =F365 -> 0.695 | K14: =F376 -> 7.2293163 | L14: =K14/K$4-1 -> -0.1076381
A15: 非 NVIDIA scale-up 交換市場 ×1.2 | B15: ×1.2 | C15: =E395 -> 3.6092714 | D15: =E387 -> 1.7341511 | E15: =E399 -> 0.7 | F15: =E410 -> 7.5450311 | G15: =F15/F$4-1 -> 0.093629096 | H15: =F395 -> 4.3108713 | I15: =F387 -> 2.3452587 | J15: =F399 -> 0.695 | K15: =F410 -> 8.9747592 | L15: =K15/K$4-1 -> 0.10781335
A16: 營業費用彈性 0.9 | B16: 營業費用隨營收成長較多 | C16: =E429 -> 3.3202462 | D16: =E421 -> 1.4451259 | E16: =E433 -> 0.7 | F16: =E444 -> 6.5319843 | G16: =F16/F$4-1 -> -0.053208924 | H16: =F429 -> 3.9199949 | I16: =F421 -> 1.9543822 | J16: =F433 -> 0.695 | K16: =F444 -> 7.5478378 | L16: =K16/K$4-1 -> -0.068320906
A17: 營業費用率 +2pt | B17: 營業費用額外 +2% × 營收 | C17: =E463 -> 3.3202462 | D17: =E455 -> 1.4451259 | E17: =E467 -> 0.7 | F17: =E478 -> 6.5861801 | G17: =F17/F$4-1 -> -0.045353404 | H17: =F463 -> 3.9199949 | I17: =F455 -> 1.9543822 | J17: =F467 -> 0.695 | K17: =F478 -> 7.7373709 | L17: =K17/K$4-1 -> -0.044925593
A18: 顆數情境 B | B18: CY2028 ×0.8、CY2029 ×0.85 | C18: =PL!E109 -> 3.3202462 | D18: =PL!E101 -> 1.4451259 | E18: =PL!E113 -> 0.7 | F18: =PL!E124 -> 6.8990768 | G18: =F18/F$4-1 -> 0 | H18: =PL!F109 -> 3.1359959 | I18: =PL!F101 -> 1.5635058 | J18: =PL!F113 -> 0.695 | K18: =PL!F124 -> 6.125585 | L18: =K18/K$4-1 -> -0.24387889
A19: 顆數情境 C | B19: CY2028–29 ×0.6 | C19: =PL!E143 -> 3.3202462 | D19: =PL!E135 -> 1.4451259 | E19: =PL!E147 -> 0.7 | F19: =PL!E158 -> 6.8990768 | G19: =F19/F$4-1 -> 0 | H19: =PL!F143 -> 2.3519969 | I19: =PL!F135 -> 1.1726293 | J19: =PL!F147 -> 0.695 | K19: =PL!F158 -> 3.5960842 | L19: =K19/K$4-1 -> -0.55611176
A21: 讀法：FY2026 為錨點、各案例相同；顆數情境自 CY2028 起，FY2027 不受影響。Scorpio X 份額高／低是 FY2027–FY2028 EPS 最大的單一變數，其次是 PCIe 等份額與毛利率；顆數情境 C 主要打在 FY2028 起。稅率影響較小。
A23: 目標價參數（只改 DCF 參數與權重；PL 收斂法的 fade_g 不隨 tp_g 變動）
A24: 案例 | B24: 設定 | C24: DCF 目標價 | D24: Comparable 目標價 | E24: 加權目標價 | F24: 相對基準
A25: 基準 | B25: r 10%、g 4%、DCF 權重 0.5 | C25: =(tp_wA*MAX(0,Val!B8*(1-IF(tp_roe<=tp_g,0.8,MIN(tp_g/tp_roe,0.8)))/(1+tp_r)^1+Val!B9*(1-IF(tp_roe<=tp_g,0.8,MIN(tp_g/tp_roe,0.8)))/(1+tp_r)^2+Val!B10*(1-IF(tp_roe<=tp_g,0.8,MIN(tp_g/tp_roe,0.8)))/(1+tp_r)^3+Val!B11*(1-IF(tp_roe<=tp_g,0.8,MIN(tp_g/tp_roe,0.8)))/(1+tp_r)^4+Val!B12*(1-IF(tp_roe<=tp_g,0.8,MIN(tp_g/tp_roe,0.8)))/(1+tp_r)^5+Val!B13*(1-IF(tp_roe<=tp_g,0.8,MIN(tp_g/tp_roe,0.8)))/(1+tp_r)^6+Val!B13*(1-IF(tp_roe<=tp_g,0.8,MIN(tp_g/tp_roe,0.8)))*(1+tp_g)/(tp_r-tp_g)/(1+tp_r)^6)+tp_wB*MAX(0,Val!C8*(1-IF(tp_roe<=tp_g,0.8,MIN(tp_g/tp_roe,0.8)))/(1+tp_r)^1+Val!C9*(1-IF(tp_roe<=tp_g,0.8,MIN(tp_g/tp_roe,0.8)))/(1+tp_r)^2+Val!C10*(1-IF(tp_roe<=tp_g,0.8,MIN(tp_g/tp_roe,0.8)))/(1+tp_r)^3+Val!C11*(1-IF(tp_roe<=tp_g,0.8,MIN(tp_g/tp_roe,0.8)))/(1+tp_r)^4+Val!C12*(1-IF(tp_roe<=tp_g,0.8,MIN(tp_g/tp_roe,0.8)))/(1+tp_r)^5+Val!C13*(1-IF(tp_roe<=tp_g,0.8,MIN(tp_g/tp_roe,0.8)))/(1+tp_r)^6+Val!C13*(1-IF(tp_roe<=tp_g,0.8,MIN(tp_g/tp_roe,0.8)))*(1+tp_g)/(tp_r-tp_g)/(1+tp_r)^6)+tp_wC*MAX(0,Val!D8*(1-IF(tp_roe<=tp_g,0.8,MIN(tp_g/tp_roe,0.8)))/(1+tp_r)^1+Val!D9*(1-IF(tp_roe<=tp_g,0.8,MIN(tp_g/tp_roe,0.8)))/(1+tp_r)^2+Val!D10*(1-IF(tp_roe<=tp_g,0.8,MIN(tp_g/tp_roe,0.8)))/(1+tp_r)^3+Val!D11*(1-IF(tp_roe<=tp_g,0.8,MIN(tp_g/tp_roe,0.8)))/(1+tp_r)^4+Val!D12*(1-IF(tp_roe<=tp_g,0.8,MIN(tp_g/tp_roe,0.8)))/(1+tp_r)^5+Val!D13*(1-IF(tp_roe<=tp_g,0.8,MIN(tp_g/tp_roe,0.8)))/(1+tp_r)^6+Val!D13*(1-IF(tp_roe<=tp_g,0.8,MIN(tp_g/tp_roe,0.8)))*(1+tp_g)/(tp_r-tp_g)/(1+tp_r)^6))*(1+tp_r) -> 105.3441 | D25: =Val!B35 -> 159.62649 | E25: =tp_w_dcf*C25+(1-tp_w_dcf)*D25 -> 132.48529 | F25: =E25/E$25-1 -> 0
A26: 折現率 +1pt | B26: r 11% | C26: =(tp_wA*MAX(0,Val!B8*(1-IF(tp_roe<=tp_g,0.8,MIN(tp_g/tp_roe,0.8)))/(1+(tp_r+0.01))^1+Val!B9*(1-IF(tp_roe<=tp_g,0.8,MIN(tp_g/tp_roe,0.8)))/(1+(tp_r+0.01))^2+Val!B10*(1-IF(tp_roe<=tp_g,0.8,MIN(tp_g/tp_roe,0.8)))/(1+(tp_r+0.01))^3+Val!B11*(1-IF(tp_roe<=tp_g,0.8,MIN(tp_g/tp_roe,0.8)))/(1+(tp_r+0.01))^4+Val!B12*(1-IF(tp_roe<=tp_g,0.8,MIN(tp_g/tp_roe,0.8)))/(1+(tp_r+0.01))^5+Val!B13*(1-IF(tp_roe<=tp_g,0.8,MIN(tp_g/tp_roe,0.8)))/(1+(tp_r+0.01))^6+Val!B13*(1-IF(tp_roe<=tp_g,0.8,MIN(tp_g/tp_roe,0.8)))*(1+tp_g)/((tp_r+0.01)-tp_g)/(1+(tp_r+0.01))^6)+tp_wB*MAX(0,Val!C8*(1-IF(tp_roe<=tp_g,0.8,MIN(tp_g/tp_roe,0.8)))/(1+(tp_r+0.01))^1+Val!C9*(1-IF(tp_roe<=tp_g,0.8,MIN(tp_g/tp_roe,0.8)))/(1+(tp_r+0.01))^2+Val!C10*(1-IF(tp_roe<=tp_g,0.8,MIN(tp_g/tp_roe,0.8)))/(1+(tp_r+0.01))^3+Val!C11*(1-IF(tp_roe<=tp_g,0.8,MIN(tp_g/tp_roe,0.8)))/(1+(tp_r+0.01))^4+Val!C12*(1-IF(tp_roe<=tp_g,0.8,MIN(tp_g/tp_roe,0.8)))/(1+(tp_r+0.01))^5+Val!C13*(1-IF(tp_roe<=tp_g,0.8,MIN(tp_g/tp_roe,0.8)))/(1+(tp_r+0.01))^6+Val!C13*(1-IF(tp_roe<=tp_g,0.8,MIN(tp_g/tp_roe,0.8)))*(1+tp_g)/((tp_r+0.01)-tp_g)/(1+(tp_r+0.01))^6)+tp_wC*MAX(0,Val!D8*(1-IF(tp_roe<=tp_g,0.8,MIN(tp_g/tp_roe,0.8)))/(1+(tp_r+0.01))^1+Val!D9*(1-IF(tp_roe<=tp_g,0.8,MIN(tp_g/tp_roe,0.8)))/(1+(tp_r+0.01))^2+Val!D10*(1-IF(tp_roe<=tp_g,0.8,MIN(tp_g/tp_roe,0.8)))/(1+(tp_r+0.01))^3+Val!D11*(1-IF(tp_roe<=tp_g,0.8,MIN(tp_g/tp_roe,0.8)))/(1+(tp_r+0.01))^4+Val!D12*(1-IF(tp_roe<=tp_g,0.8,MIN(tp_g/tp_roe,0.8)))/(1+(tp_r+0.01))^5+Val!D13*(1-IF(tp_roe<=tp_g,0.8,MIN(tp_g/tp_roe,0.8)))/(1+(tp_r+0.01))^6+Val!D13*(1-IF(tp_roe<=tp_g,0.8,MIN(tp_g/tp_roe,0.8)))*(1+tp_g)/((tp_r+0.01)-tp_g)/(1+(tp_r+0.01))^6))*(1+(tp_r+0.01)) -> 91.086757 | D26: =Val!B35 -> 159.62649 | E26: =tp_w_dcf*C26+(1-tp_w_dcf)*D26 -> 125.35662 | F26: =E26/E$25-1 -> -0.053807252
A27: 折現率 −1pt | B27: r 9% | C27: =(tp_wA*MAX(0,Val!B8*(1-IF(tp_roe<=tp_g,0.8,MIN(tp_g/tp_roe,0.8)))/(1+(tp_r-0.01))^1+Val!B9*(1-IF(tp_roe<=tp_g,0.8,MIN(tp_g/tp_roe,0.8)))/(1+(tp_r-0.01))^2+Val!B10*(1-IF(tp_roe<=tp_g,0.8,MIN(tp_g/tp_roe,0.8)))/(1+(tp_r-0.01))^3+Val!B11*(1-IF(tp_roe<=tp_g,0.8,MIN(tp_g/tp_roe,0.8)))/(1+(tp_r-0.01))^4+Val!B12*(1-IF(tp_roe<=tp_g,0.8,MIN(tp_g/tp_roe,0.8)))/(1+(tp_r-0.01))^5+Val!B13*(1-IF(tp_roe<=tp_g,0.8,MIN(tp_g/tp_roe,0.8)))/(1+(tp_r-0.01))^6+Val!B13*(1-IF(tp_roe<=tp_g,0.8,MIN(tp_g/tp_roe,0.8)))*(1+tp_g)/((tp_r-0.01)-tp_g)/(1+(tp_r-0.01))^6)+tp_wB*MAX(0,Val!C8*(1-IF(tp_roe<=tp_g,0.8,MIN(tp_g/tp_roe,0.8)))/(1+(tp_r-0.01))^1+Val!C9*(1-IF(tp_roe<=tp_g,0.8,MIN(tp_g/tp_roe,0.8)))/(1+(tp_r-0.01))^2+Val!C10*(1-IF(tp_roe<=tp_g,0.8,MIN(tp_g/tp_roe,0.8)))/(1+(tp_r-0.01))^3+Val!C11*(1-IF(tp_roe<=tp_g,0.8,MIN(tp_g/tp_roe,0.8)))/(1+(tp_r-0.01))^4+Val!C12*(1-IF(tp_roe<=tp_g,0.8,MIN(tp_g/tp_roe,0.8)))/(1+(tp_r-0.01))^5+Val!C13*(1-IF(tp_roe<=tp_g,0.8,MIN(tp_g/tp_roe,0.8)))/(1+(tp_r-0.01))^6+Val!C13*(1-IF(tp_roe<=tp_g,0.8,MIN(tp_g/tp_roe,0.8)))*(1+tp_g)/((tp_r-0.01)-tp_g)/(1+(tp_r-0.01))^6)+tp_wC*MAX(0,Val!D8*(1-IF(tp_roe<=tp_g,0.8,MIN(tp_g/tp_roe,0.8)))/(1+(tp_r-0.01))^1+Val!D9*(1-IF(tp_roe<=tp_g,0.8,MIN(tp_g/tp_roe,0.8)))/(1+(tp_r-0.01))^2+Val!D10*(1-IF(tp_roe<=tp_g,0.8,MIN(tp_g/tp_roe,0.8)))/(1+(tp_r-0.01))^3+Val!D11*(1-IF(tp_roe<=tp_g,0.8,MIN(tp_g/tp_roe,0.8)))/(1+(tp_r-0.01))^4+Val!D12*(1-IF(tp_roe<=tp_g,0.8,MIN(tp_g/tp_roe,0.8)))/(1+(tp_r-0.01))^5+Val!D13*(1-IF(tp_roe<=tp_g,0.8,MIN(tp_g/tp_roe,0.8)))/(1+(tp_r-0.01))^6+Val!D13*(1-IF(tp_roe<=tp_g,0.8,MIN(tp_g/tp_roe,0.8)))*(1+tp_g)/((tp_r-0.01)-tp_g)/(1+(tp_r-0.01))^6))*(1+(tp_r-0.01)) -> 125.30317 | D27: =Val!B35 -> 159.62649 | E27: =tp_w_dcf*C27+(1-tp_w_dcf)*D27 -> 142.46483 | F27: =E27/E$25-1 -> 0.075325621
A28: 長期成長 +1pt | B28: g 5% | C28: =(tp_wA*MAX(0,Val!B8*(1-IF(tp_roe<=(tp_g+0.01),0.8,MIN((tp_g+0.01)/tp_roe,0.8)))/(1+tp_r)^1+Val!B9*(1-IF(tp_roe<=(tp_g+0.01),0.8,MIN((tp_g+0.01)/tp_roe,0.8)))/(1+tp_r)^2+Val!B10*(1-IF(tp_roe<=(tp_g+0.01),0.8,MIN((tp_g+0.01)/tp_roe,0.8)))/(1+tp_r)^3+Val!B11*(1-IF(tp_roe<=(tp_g+0.01),0.8,MIN((tp_g+0.01)/tp_roe,0.8)))/(1+tp_r)^4+Val!B12*(1-IF(tp_roe<=(tp_g+0.01),0.8,MIN((tp_g+0.01)/tp_roe,0.8)))/(1+tp_r)^5+Val!B13*(1-IF(tp_roe<=(tp_g+0.01),0.8,MIN((tp_g+0.01)/tp_roe,0.8)))/(1+tp_r)^6+Val!B13*(1-IF(tp_roe<=(tp_g+0.01),0.8,MIN((tp_g+0.01)/tp_roe,0.8)))*(1+(tp_g+0.01))/(tp_r-(tp_g+0.01))/(1+tp_r)^6)+tp_wB*MAX(0,Val!C8*(1-IF(tp_roe<=(tp_g+0.01),0.8,MIN((tp_g+0.01)/tp_roe,0.8)))/(1+tp_r)^1+Val!C9*(1-IF(tp_roe<=(tp_g+0.01),0.8,MIN((tp_g+0.01)/tp_roe,0.8)))/(1+tp_r)^2+Val!C10*(1-IF(tp_roe<=(tp_g+0.01),0.8,MIN((tp_g+0.01)/tp_roe,0.8)))/(1+tp_r)^3+Val!C11*(1-IF(tp_roe<=(tp_g+0.01),0.8,MIN((tp_g+0.01)/tp_roe,0.8)))/(1+tp_r)^4+Val!C12*(1-IF(tp_roe<=(tp_g+0.01),0.8,MIN((tp_g+0.01)/tp_roe,0.8)))/(1+tp_r)^5+Val!C13*(1-IF(tp_roe<=(tp_g+0.01),0.8,MIN((tp_g+0.01)/tp_roe,0.8)))/(1+tp_r)^6+Val!C13*(1-IF(tp_roe<=(tp_g+0.01),0.8,MIN((tp_g+0.01)/tp_roe,0.8)))*(1+(tp_g+0.01))/(tp_r-(tp_g+0.01))/(1+tp_r)^6)+tp_wC*MAX(0,Val!D8*(1-IF(tp_roe<=(tp_g+0.01),0.8,MIN((tp_g+0.01)/tp_roe,0.8)))/(1+tp_r)^1+Val!D9*(1-IF(tp_roe<=(tp_g+0.01),0.8,MIN((tp_g+0.01)/tp_roe,0.8)))/(1+tp_r)^2+Val!D10*(1-IF(tp_roe<=(tp_g+0.01),0.8,MIN((tp_g+0.01)/tp_roe,0.8)))/(1+tp_r)^3+Val!D11*(1-IF(tp_roe<=(tp_g+0.01),0.8,MIN((tp_g+0.01)/tp_roe,0.8)))/(1+tp_r)^4+Val!D12*(1-IF(tp_roe<=(tp_g+0.01),0.8,MIN((tp_g+0.01)/tp_roe,0.8)))/(1+tp_r)^5+Val!D13*(1-IF(tp_roe<=(tp_g+0.01),0.8,MIN((tp_g+0.01)/tp_roe,0.8)))/(1+tp_r)^6+Val!D13*(1-IF(tp_roe<=(tp_g+0.01),0.8,MIN((tp_g+0.01)/tp_roe,0.8)))*(1+(tp_g+0.01))/(tp_r-(tp_g+0.01))/(1+tp_r)^6))*(1+tp_r) -> 116.16817 | D28: =Val!B35 -> 159.62649 | E28: =tp_w_dcf*C28+(1-tp_w_dcf)*D28 -> 137.89733 | F28: =E28/E$25-1 -> 0.0408501
A29: 長期成長 −1pt | B29: g 3% | C29: =(tp_wA*MAX(0,Val!B8*(1-IF(tp_roe<=(tp_g-0.01),0.8,MIN((tp_g-0.01)/tp_roe,0.8)))/(1+tp_r)^1+Val!B9*(1-IF(tp_roe<=(tp_g-0.01),0.8,MIN((tp_g-0.01)/tp_roe,0.8)))/(1+tp_r)^2+Val!B10*(1-IF(tp_roe<=(tp_g-0.01),0.8,MIN((tp_g-0.01)/tp_roe,0.8)))/(1+tp_r)^3+Val!B11*(1-IF(tp_roe<=(tp_g-0.01),0.8,MIN((tp_g-0.01)/tp_roe,0.8)))/(1+tp_r)^4+Val!B12*(1-IF(tp_roe<=(tp_g-0.01),0.8,MIN((tp_g-0.01)/tp_roe,0.8)))/(1+tp_r)^5+Val!B13*(1-IF(tp_roe<=(tp_g-0.01),0.8,MIN((tp_g-0.01)/tp_roe,0.8)))/(1+tp_r)^6+Val!B13*(1-IF(tp_roe<=(tp_g-0.01),0.8,MIN((tp_g-0.01)/tp_roe,0.8)))*(1+(tp_g-0.01))/(tp_r-(tp_g-0.01))/(1+tp_r)^6)+tp_wB*MAX(0,Val!C8*(1-IF(tp_roe<=(tp_g-0.01),0.8,MIN((tp_g-0.01)/tp_roe,0.8)))/(1+tp_r)^1+Val!C9*(1-IF(tp_roe<=(tp_g-0.01),0.8,MIN((tp_g-0.01)/tp_roe,0.8)))/(1+tp_r)^2+Val!C10*(1-IF(tp_roe<=(tp_g-0.01),0.8,MIN((tp_g-0.01)/tp_roe,0.8)))/(1+tp_r)^3+Val!C11*(1-IF(tp_roe<=(tp_g-0.01),0.8,MIN((tp_g-0.01)/tp_roe,0.8)))/(1+tp_r)^4+Val!C12*(1-IF(tp_roe<=(tp_g-0.01),0.8,MIN((tp_g-0.01)/tp_roe,0.8)))/(1+tp_r)^5+Val!C13*(1-IF(tp_roe<=(tp_g-0.01),0.8,MIN((tp_g-0.01)/tp_roe,0.8)))/(1+tp_r)^6+Val!C13*(1-IF(tp_roe<=(tp_g-0.01),0.8,MIN((tp_g-0.01)/tp_roe,0.8)))*(1+(tp_g-0.01))/(tp_r-(tp_g-0.01))/(1+tp_r)^6)+tp_wC*MAX(0,Val!D8*(1-IF(tp_roe<=(tp_g-0.01),0.8,MIN((tp_g-0.01)/tp_roe,0.8)))/(1+tp_r)^1+Val!D9*(1-IF(tp_roe<=(tp_g-0.01),0.8,MIN((tp_g-0.01)/tp_roe,0.8)))/(1+tp_r)^2+Val!D10*(1-IF(tp_roe<=(tp_g-0.01),0.8,MIN((tp_g-0.01)/tp_roe,0.8)))/(1+tp_r)^3+Val!D11*(1-IF(tp_roe<=(tp_g-0.01),0.8,MIN((tp_g-0.01)/tp_roe,0.8)))/(1+tp_r)^4+Val!D12*(1-IF(tp_roe<=(tp_g-0.01),0.8,MIN((tp_g-0.01)/tp_roe,0.8)))/(1+tp_r)^5+Val!D13*(1-IF(tp_roe<=(tp_g-0.01),0.8,MIN((tp_g-0.01)/tp_roe,0.8)))/(1+tp_r)^6+Val!D13*(1-IF(tp_roe<=(tp_g-0.01),0.8,MIN((tp_g-0.01)/tp_roe,0.8)))*(1+(tp_g-0.01))/(tp_r-(tp_g-0.01))/(1+tp_r)^6))*(1+tp_r) -> 97.92166 | D29: =Val!B35 -> 159.62649 | E29: =tp_w_dcf*C29+(1-tp_w_dcf)*D29 -> 128.77408 | F29: =E29/E$25-1 -> -0.028012301
A30: DCF 權重 0.3 | B30: Comparable 0.7 | C30: =(tp_wA*MAX(0,Val!B8*(1-IF(tp_roe<=tp_g,0.8,MIN(tp_g/tp_roe,0.8)))/(1+tp_r)^1+Val!B9*(1-IF(tp_roe<=tp_g,0.8,MIN(tp_g/tp_roe,0.8)))/(1+tp_r)^2+Val!B10*(1-IF(tp_roe<=tp_g,0.8,MIN(tp_g/tp_roe,0.8)))/(1+tp_r)^3+Val!B11*(1-IF(tp_roe<=tp_g,0.8,MIN(tp_g/tp_roe,0.8)))/(1+tp_r)^4+Val!B12*(1-IF(tp_roe<=tp_g,0.8,MIN(tp_g/tp_roe,0.8)))/(1+tp_r)^5+Val!B13*(1-IF(tp_roe<=tp_g,0.8,MIN(tp_g/tp_roe,0.8)))/(1+tp_r)^6+Val!B13*(1-IF(tp_roe<=tp_g,0.8,MIN(tp_g/tp_roe,0.8)))*(1+tp_g)/(tp_r-tp_g)/(1+tp_r)^6)+tp_wB*MAX(0,Val!C8*(1-IF(tp_roe<=tp_g,0.8,MIN(tp_g/tp_roe,0.8)))/(1+tp_r)^1+Val!C9*(1-IF(tp_roe<=tp_g,0.8,MIN(tp_g/tp_roe,0.8)))/(1+tp_r)^2+Val!C10*(1-IF(tp_roe<=tp_g,0.8,MIN(tp_g/tp_roe,0.8)))/(1+tp_r)^3+Val!C11*(1-IF(tp_roe<=tp_g,0.8,MIN(tp_g/tp_roe,0.8)))/(1+tp_r)^4+Val!C12*(1-IF(tp_roe<=tp_g,0.8,MIN(tp_g/tp_roe,0.8)))/(1+tp_r)^5+Val!C13*(1-IF(tp_roe<=tp_g,0.8,MIN(tp_g/tp_roe,0.8)))/(1+tp_r)^6+Val!C13*(1-IF(tp_roe<=tp_g,0.8,MIN(tp_g/tp_roe,0.8)))*(1+tp_g)/(tp_r-tp_g)/(1+tp_r)^6)+tp_wC*MAX(0,Val!D8*(1-IF(tp_roe<=tp_g,0.8,MIN(tp_g/tp_roe,0.8)))/(1+tp_r)^1+Val!D9*(1-IF(tp_roe<=tp_g,0.8,MIN(tp_g/tp_roe,0.8)))/(1+tp_r)^2+Val!D10*(1-IF(tp_roe<=tp_g,0.8,MIN(tp_g/tp_roe,0.8)))/(1+tp_r)^3+Val!D11*(1-IF(tp_roe<=tp_g,0.8,MIN(tp_g/tp_roe,0.8)))/(1+tp_r)^4+Val!D12*(1-IF(tp_roe<=tp_g,0.8,MIN(tp_g/tp_roe,0.8)))/(1+tp_r)^5+Val!D13*(1-IF(tp_roe<=tp_g,0.8,MIN(tp_g/tp_roe,0.8)))/(1+tp_r)^6+Val!D13*(1-IF(tp_roe<=tp_g,0.8,MIN(tp_g/tp_roe,0.8)))*(1+tp_g)/(tp_r-tp_g)/(1+tp_r)^6))*(1+tp_r) -> 105.3441 | D30: =Val!B35 -> 159.62649 | E30: =0.3*C30+(1-0.3)*D30 -> 143.34177 | F30: =E30/E$25-1 -> 0.081944784
A31: DCF 權重 0.7 | B31: Comparable 0.3 | C31: =(tp_wA*MAX(0,Val!B8*(1-IF(tp_roe<=tp_g,0.8,MIN(tp_g/tp_roe,0.8)))/(1+tp_r)^1+Val!B9*(1-IF(tp_roe<=tp_g,0.8,MIN(tp_g/tp_roe,0.8)))/(1+tp_r)^2+Val!B10*(1-IF(tp_roe<=tp_g,0.8,MIN(tp_g/tp_roe,0.8)))/(1+tp_r)^3+Val!B11*(1-IF(tp_roe<=tp_g,0.8,MIN(tp_g/tp_roe,0.8)))/(1+tp_r)^4+Val!B12*(1-IF(tp_roe<=tp_g,0.8,MIN(tp_g/tp_roe,0.8)))/(1+tp_r)^5+Val!B13*(1-IF(tp_roe<=tp_g,0.8,MIN(tp_g/tp_roe,0.8)))/(1+tp_r)^6+Val!B13*(1-IF(tp_roe<=tp_g,0.8,MIN(tp_g/tp_roe,0.8)))*(1+tp_g)/(tp_r-tp_g)/(1+tp_r)^6)+tp_wB*MAX(0,Val!C8*(1-IF(tp_roe<=tp_g,0.8,MIN(tp_g/tp_roe,0.8)))/(1+tp_r)^1+Val!C9*(1-IF(tp_roe<=tp_g,0.8,MIN(tp_g/tp_roe,0.8)))/(1+tp_r)^2+Val!C10*(1-IF(tp_roe<=tp_g,0.8,MIN(tp_g/tp_roe,0.8)))/(1+tp_r)^3+Val!C11*(1-IF(tp_roe<=tp_g,0.8,MIN(tp_g/tp_roe,0.8)))/(1+tp_r)^4+Val!C12*(1-IF(tp_roe<=tp_g,0.8,MIN(tp_g/tp_roe,0.8)))/(1+tp_r)^5+Val!C13*(1-IF(tp_roe<=tp_g,0.8,MIN(tp_g/tp_roe,0.8)))/(1+tp_r)^6+Val!C13*(1-IF(tp_roe<=tp_g,0.8,MIN(tp_g/tp_roe,0.8)))*(1+tp_g)/(tp_r-tp_g)/(1+tp_r)^6)+tp_wC*MAX(0,Val!D8*(1-IF(tp_roe<=tp_g,0.8,MIN(tp_g/tp_roe,0.8)))/(1+tp_r)^1+Val!D9*(1-IF(tp_roe<=tp_g,0.8,MIN(tp_g/tp_roe,0.8)))/(1+tp_r)^2+Val!D10*(1-IF(tp_roe<=tp_g,0.8,MIN(tp_g/tp_roe,0.8)))/(1+tp_r)^3+Val!D11*(1-IF(tp_roe<=tp_g,0.8,MIN(tp_g/tp_roe,0.8)))/(1+tp_r)^4+Val!D12*(1-IF(tp_roe<=tp_g,0.8,MIN(tp_g/tp_roe,0.8)))/(1+tp_r)^5+Val!D13*(1-IF(tp_roe<=tp_g,0.8,MIN(tp_g/tp_roe,0.8)))/(1+tp_r)^6+Val!D13*(1-IF(tp_roe<=tp_g,0.8,MIN(tp_g/tp_roe,0.8)))*(1+tp_g)/(tp_r-tp_g)/(1+tp_r)^6))*(1+tp_r) -> 105.3441 | D31: =Val!B35 -> 159.62649 | E31: =0.7*C31+(1-0.7)*D31 -> 121.62881 | F31: =E31/E$25-1 -> -0.081944784
A40: 案例區塊：Scorpio X 份額 低（情境 A）
A41: 項目 | B41: 單位 | C41: FY2025A | D41: FY2026（錨點） | E41: FY2027 | F41: FY2028 | G41: FY2029 | H41: 說明
A42: A. Scorpio X（D 欄＝FY2026 校準年；E–G＝FY2027–FY2029；市場為日曆年＝會計年度）
A43: 非 NVIDIA scale-up 交換晶片市場 × 情境顆數係數 | B43: US$B | D43: =msx_26 -> 2.025 | E43: =msx_27 -> 7.701 | F43: =msx_28*um28_A -> 9.468 | G43: =msx_29*um29_A -> 10.8882 | H43: AMD、Trainium、其他 ASIC 顆數 × 每顆 scale-up 交換晶片內容（網通模型）；CY2028 起乘顆數係數
A44: Astera Scorpio X 有效份額（FY2026 校準）＝ Scorpio X 營收 ÷ 市場 | B44: % | D44: =a26_x/D43 -> 0.18765432 | H44: Derived
A45: Scorpio X 有效份額相對值（÷ FY2026） | B45: x | D45: =1 -> 1 | E45: =XLO_27 -> 0.7 | F45: =XLO_28 -> 0.6 | G45: =XLO_29 -> 0.5
A46: Scorpio X 有效份額 | B46: % | D46: =$D$44*D45 -> 0.18765432 | E46: =$D$44*E45 -> 0.13135802 | F46: =$D$44*F45 -> 0.11259259 | G46: =$D$44*G45 -> 0.09382716
A47: Scorpio X 營收 | B47: US$B | C47: =a25_x -> 0 | D47: =a26_x -> 0.38 | E47: =E43*E46 -> 1.0115881 | F47: =F43*F46 -> 1.0660267 | G47: =G43*G46 -> 1.0216089
A48: B. PCIe 與訊號調節（Aries、Scorpio P、Taurus、Leo）
A49: AI 加速器顆數 × 情境顆數係數 | B49: 百萬顆 | D49: =u_26 -> 15.2 | E49: =u_27 -> 23.7 | F49: =u_28*um28_A -> 26.5 | G49: =u_29*um29_A -> 30.15
A50: PCIe／CXL／AEC 可服務市場＝顆數 × 每顆內容（c_pcie） | B50: US$B | D50: =D49*c_pcie/1000 -> 3.8 | E50: =E49*c_pcie/1000 -> 5.925 | F50: =F49*c_pcie/1000 -> 6.625 | G50: =G49*c_pcie/1000 -> 7.5375 | H50: c_pcie 只影響份額顯示，校準時抵銷
A51: Astera PCIe 等有效份額（FY2026 校準）＝ 營收 ÷ 可服務市場 | B51: % | D51: =a26_p/D50 -> 0.395595
...

Sheet Sources
A1: 來源（公司原文＝SEC 8-K 新聞稿與 10-K）
A2: 公司：2Q26 實績、3Q26 指引（8-K 附件 99.1；含 1Q26、1H 比較欄與資產負債表） | B2: https://www.sec.gov/Archives/edgar/data/0001736297/000173629726000033/q226exhibit991.htm
A3: 公司：2Q26 新聞稿（IR 網站） | B3: https://ir.asteralabs.com/news-releases/news-release-details/astera-labs-reports-second-quarter-2026-financial-results
A4: 公司：4Q25 與 FY2025 實績、1Q26 指引、2030 年商用 scale-up 交換市場 200 億美元（8-K 附件 99.1） | B4: https://www.sec.gov/Archives/edgar/data/1736297/000173629726000005/q425exhibit991.htm
A5: 公司：FY2025 10-K（客戶集中、競爭者、股數） | B5: https://www.sec.gov/Archives/edgar/data/1736297/000173629726000010/alab-20251231.htm
A6: 二手：2Q26 法說摘要（Scorpio 3Q26 成為最大產品線、X 超過 P、逾 10 家客戶、長期毛利率 70%、Taurus 2030 年逾 40 億美元） | B6: https://www.marketbeat.com/instant-alerts/astera-labs-q2-earnings-call-highlights-2026-08-04/
A7: 二手：2Q26 分析（Futurum；毛利率下滑原因、客戶集中） | B7: https://futurumgroup.com/insights/astera-labs-q2-fy-2026-earnings-pull-scorpio-switch-leadership-forward/
A8: 二手：1Q26 法說逐字稿（每顆加速器內容逾 1,000 美元、Scorpio 1Q26 約 20% 為分析師引述） | B8: https://www.fool.com/earnings/call-transcripts/2026/05/05/astera-labs-alab-q1-2026-earnings-transcript/
A9: 二手：TIKR（2026-03；Scorpio 逾 FY2025 營收 15%、Amazon 認股權證） | B9: https://www.tikr.com/blog/astera-labs-what-a-224-bull-case-looks-like
A10: 共識：Yahoo Finance 分析師預估（2026-10-23 頁面） | B10: https://finance.yahoo.com/quote/ALAB/analysis/
A11: 共識：StockAnalysis 預估與目標價（資料 2026-10-16） | B11: https://stockanalysis.com/stocks/alab/forecast/
A12: 共識：MarketScreener 年度預估（FY2028 營收、GAAP EPS） | B12: https://uk.marketscreener.com/quote/stock/ASTERA-LABS-INC-167508773/finances/
A13: 共識：Tickflow（目標價第二來源；頁面數字前後不一致） | B13: https://www.tickflow.io/stock/ALAB/forecast
... A18: 同業前瞻 P/E：StockAnalysis statistics 頁（CRDO、MRVL、AVGO、RMBS、MTSI；2026-10-23） | B18: https://stockanalysis.com/stocks/crdo/statistics/
A19: 市場層：markets/network、tsmc 成品（本 repo，唯讀）
A20: 待補（人工）：3Q26 財報；產品線營收拆分（Aries、Taurus、Leo、Scorpio P／X）；客戶名稱第一手出處；每顆加速器 PCIe 內容第一手來源；FY2028 non-GAAP 共識；前瞻 P/E 歷史（Bloomberg） | B20: 未找到
A21: SemiAnalysis | B21: 未使用
