Workbook

Sheet README
A1: Siliconomics v0.2 — AI 半導體產業基準庫（20261027）
A2: 用途：AI 半導體各子產業的『唯一事實』——加速器顆數、HBM 與記憶體價格、網通內容、CoWoS、載板、伺服器組裝、電源散熱、設備等行業變數只有一個值；各公司模型只讀本庫 Interface 的 SIF_ 名稱。
A3: 與 Tokenomics 的分工：每 GW 硬體量、機架價、每 GW 資本支出、NonNV 比例、產業年度部署路徑（R4）權威在 Tokenomics／算力收支，本庫只在 TK_In 頁鏡像（綠字、不得修改）；晶片產業資訊（HBM 單價與容量、每顆內容、網通內容、份額、出貨顆數、ASIC 規格、晶圓與設備）權威在本庫（《情境卡產生規則》第 13 條）。
A4: v0.1 範圍：(1) Tokenomics v21.7 鏡像（22 個名稱）與下游舊快照差異；(2) 加速器顆數層、記憶體價格路徑、HBM 市場（由 markets/memory/market.py 逐字搬入，數值不變）；(3) 跨模型衝突登錄；(4) Interface、Checks、Decisions。網通、CoWoS、載板、組裝電源散熱、設備依規劃書分段併入。
A5: v0.2：In 頁 Assumed 列全部補上區間、缺來源列補來源；新增 M5 節 2029 平台別顆數成長（單一來源，取代台積電、網通模型的寫死值與 NAND 模型的合計年增）與 Units 頁；Interface 新增 SIF_UnitsPlat_*、SIF_UnitsGrowth29。
A6: 讀法：Scen（情境定義）→ In（藍字輸入）→ Path／Mkt（推導）→ Interface（下游取數）→ Checks（SGOV_Errors 須為 0）。
A7: 顏色：藍字＝輸入（本活頁簿擁有）；黑字＝公式；綠字＝跨頁或外部連結；淡黃底＝關鍵輸出；亮黃底＝待 Andy 決定或未定。
A8: 標記：Verified／Interested-party／Analogy／Assumed／Derived；Analogy 與 Assumed 一律給區間（v0.1 搬入列尚有缺區間者，見 Checks G3）。
A9: Excel 優先：要改輸入，直接改 In 頁藍字；builder 重建時讀回（--base）。公式頁不要手改（重建時會被覆寫）。
A10: 取數規則（下游）：只取 SIF_ 具名範圍（含 SIF_TK_* 鏡像）；不得連結 In、Mkt 等內部頁；以 tools/export_snapshot.py 匯成版本固定快照，版本號寫入公司模型。
A11: 版本命名：YYYYMMDD_Siliconomics_vX.Y.xlsx；model/CURRENT 記錄現行檔名。只改證據或標記為修補版；輸入值或公式改變為次版；Interface 名稱刪除或定義改變為主版（v1.0 前只新增名稱以次版處理）。

Sheet Scen
A1: Scen — 行業情境定義（A＝順利、B＝平平、C＝不如預期）。各公司模型的 A／B／C 一律讀同字母行業情境（Andy 2026-10-25 13:13）
A3: 情境 | B3: 名稱 | C3: 定義（顆數與部署） | D3: 記憶體價格路徑 | E3: 2028 顆數 ÷ 基準 | F3: 2029 顆數 ÷ 基準 | G3: 2030–2032
A4: A | B4: 順利 | C4: 基準顆數（市場層 2026–2028 預測）；部署順利、新技術導入快 | D4: 2027–28 高檔持平、2029 緩降（BofA、TrendForce 型） | E4: =um28_A -> 1 | F4: =um29_A -> 1 | G4: 未定：待算力收支 R4 產業部署路徑（預計 10-31 後）；各公司模型目前以收斂法自推
A5: B | B5: 平平 | C5: AI 資本支出消化：2028 顆數約為基準 0.8、2029 約 0.85 | D5: 2027 Q2 見頂、2028 回落約一半、2029 溫和回升（Citi、Bernstein 型） | E5: =um28_B -> 0.8 | F5: =um29_B -> 0.85 | G5: 未定：待算力收支 R4 產業部署路徑（預計 10-31 後）；各公司模型目前以收斂法自推
A6: C | B6: 不如預期 | C6: 明顯下修：2028、2029 顆數約為基準 0.6 | D6: 2028 回到 2025 年價格水準、2029 自谷底回升（完整循環） | E6: =um28_C -> 0.6 | F6: =um29_C -> 0.6 | G6: 未定：待算力收支 R4 產業部署路徑（預計 10-31 後）；各公司模型目前以收斂法自推
A9: 說明
A10: 情境係數只定義 2028–29（Assumed，無外部預測可校準；B、C 區間 ±0.1，見 In 頁 M2b）。R4 上線後，2026–2030 的部署 GW 三情境改讀算力收支（權威在算力收支，第 13 條），本頁的係數改為由部署路徑推導。

Sheet In
A1: In — 產業輸入（藍字＝輸入，由本活頁簿擁有；要改值直接改本頁，builder 重建時讀回）。每列具名範圍＝鍵（指向 E 欄），另有 _lo／_hi（D、F 欄）
A2: 標記：Verified／Interested-party（寫明是誰）／Analogy／Assumed（給低／高區間）／Derived（寫明換算）。v0.1 內容由 markets/memory/market.py 逐字搬入（數值、標記、來源文字不變）
A4: 鍵 | B4: 項目 | C4: 單位 | D4: 低 | E4: 基準 | F4: 高 | G4: 標記 | H4: 來源／說明 | I4: Interface 名稱
A5: M1. 記憶體價格路徑（季增，共用市場層 markets/memory）
A6: cq_1 | B6: 一般 DRAM 合約價季增 2025Q2 | C6: % | E6: -0.025 | G6: Interested-party | H6: TrendForce 合約價：2Q25 0~−5%、3Q25 +10~15%、4Q25 實際 +45~50%、1Q26 實際約 +93~98%、2Q26 +58~63%、3Q26 +13~18%（MS 實際約 +15%）、4Q26 +10~15% | I6: SIF_cq_1
A7: cq_2 | B7: 一般 DRAM 合約價季增 2025Q3 | C7: % | E7: 0.125 | G7: Interested-party | H7: 同上 | I7: SIF_cq_2
A8: cq_3 | B8: 一般 DRAM 合約價季增 2025Q4 | C8: % | E8: 0.475 | G8: Interested-party | H8: 同上 | I8: SIF_cq_3
A9: cq_4 | B9: 一般 DRAM 合約價季增 2026Q1 | C9: % | E9: 0.95 | G9: Interested-party | H9: 同上 | I9: SIF_cq_4
A10: cq_5 | B10: 一般 DRAM 合約價季增 2026Q2 | C10: % | E10: 0.605 | G10: Interested-party | H10: 同上 | I10: SIF_cq_5
A11: cq_6 | B11: 一般 DRAM 合約價季增 2026Q3 | C11: % | E11: 0.155 | G11: Interested-party | H11: 同上 | I11: SIF_cq_6
A12: cq_7 | B12: 一般 DRAM 合約價季增 2026Q4 | C12: % | E12: 0.125 | G12: Interested-party | H12: 同上 | I12: SIF_cq_7
A13: cqA_8 | B13: 一般 DRAM 合約價季增 2027Q1（A） | C13: % | E13: 0.03 | G13: Interested-party | H13: BofA：2027 持平略降、2027 均價仍高於 2026；2028 溫和修正（年均約 −10%）；2029 Assumed 緩降 | I13: SIF_cqA_8
A14: cqA_9 | B14: 一般 DRAM 合約價季增 2027Q2（A） | C14: % | E14: 0 | G14: Interested-party | H14: 同上 | I14: SIF_cqA_9
A15: cqA_10 | B15: 一般 DRAM 合約價季增 2027Q3（A） | C15: % | E15: -0.02 | G15: Interested-party | H15: 同上 | I15: SIF_cqA_10
A16: cqA_11 | B16: 一般 DRAM 合約價季增 2027Q4（A） | C16: % | E16: -0.03 | G16: Interested-party | H16: 同上 | I16: SIF_cqA_11
A17: cqA_12 | B17: 一般 DRAM 合約價季增 2028Q1（A） | C17: % | E17: -0.03 | G17: Interested-party | H17: 同上 | I17: SIF_cqA_12
... A36: cqB_19 | B36: 一般 DRAM 合約價季增 2029Q4（B） | C36: % | E36: 0.03 | G36: Interested-party | H36: 同上 | I36: SIF_cqB_19
A37: cqC_8 | B37: 一般 DRAM 合約價季增 2027Q1（C） | C37: % | D37: 0 | E37: 0.05 | F37: 0.1 | G37: Assumed | H37: Assumed：2028 年底回到約 2025Q4 水準（自高點約 −79%），比照 2019、2023 年谷底；2029 自谷底回升。區間（v0.2）：2027 各季 ±5pt、2028–29 各季 ±10pt，表示路徑形狀的不確定（Assumed），不是另一個情境 | I37: SIF_cqC_8
A38: cqC_9 | B38: 一般 DRAM 合約價季增 2027Q2（C） | C38: % | D38: -0.03 | E38: 0.02 | F38: 0.07 | G38: Assumed | H38: 同上 | I38: SIF_cqC_9
A39: cqC_10 | B39: 一般 DRAM 合約價季增 2027Q3（C） | C39: % | D39: -0.13 | E39: -0.08 | F39: -0.03 | G39: Assumed | H39: 同上 | I39: SIF_cqC_10
A40: cqC_11 | B40: 一般 DRAM 合約價季增 2027Q4（C） | C40: % | D40: -0.2 | E40: -0.15 | F40: -0.1 | G40: Assumed | H40: 同上 | I40: SIF_cqC_11
A41: cqC_12 | B41: 一般 DRAM 合約價季增 2028Q1（C） | C41: % | D41: -0.45 | E41: -0.35 | F41: -0.25 | G41: Assumed | H41: 同上 | I41: SIF_cqC_12
A42: cqC_13 | B42: 一般 DRAM 合約價季增 2028Q2（C） | C42: % | D42: -0.4 | E42: -0.3 | F42: -0.2 | G42: Assumed | H42: 同上 | I42: SIF_cqC_13
A43: cqC_14 | B43: 一般 DRAM 合約價季增 2028Q3（C） | C43: % | D43: -0.35 | E43: -0.25 | F43: -0.15 | G43: Assumed | H43: 同上 | I43: SIF_cqC_14
A44: cqC_15 | B44: 一般 DRAM 合約價季增 2028Q4（C） | C44: % | D44: -0.3 | E44: -0.2 | F44: -0.1 | G44: Assumed | H44: 同上 | I44: SIF_cqC_15
A45: cqC_16 | B45: 一般 DRAM 合約價季增 2029Q1（C） | C45: % | D45: -0.1 | E45: 0 | F45: 0.1 | G45: Assumed | H45: 同上 | I45: SIF_cqC_16
A46: cqC_17 | B46: 一般 DRAM 合約價季增 2029Q2（C） | C46: % | D46: -0.05 | E46: 0.05 | F46: 0.15 | G46: Assumed | H46: 同上 | I46: SIF_cqC_17
A47: cqC_18 | B47: 一般 DRAM 合約價季增 2029Q3（C） | C47: % | D47: -0.02 | E47: 0.08 | F47: 0.18 | G47: Assumed | H47: 同上 | I47: SIF_cqC_18
A48: cqC_19 | B48: 一般 DRAM 合約價季增 2029Q4（C） | C48: % | D48: 0 | E48: 0.1 | F48: 0.2 | G48: Assumed | H48: 同上 | I48: SIF_cqC_19
A49: nq_1 | B49: NAND 合約價季增 2025Q2 | C49: % | E49: 0 | G49: Interested-party | H49: TrendForce：1Q26 +85~90%、2Q26 +70~75%、3Q26 +10~15%（MS 實際約 +20%）、4Q26 +15~20%；2025Q2–Q4 為 Assumed | I49: SIF_nq_1
A50: nq_2 | B50: NAND 合約價季增 2025Q3 | C50: % | E50: 0.05 | G50: Interested-party | H50: 同上 | I50: SIF_nq_2
A51: nq_3 | B51: NAND 合約價季增 2025Q4 | C51: % | E51: 0.3 | G51: Interested-party | H51: 同上 | I51: SIF_nq_3
A52: nq_4 | B52: NAND 合約價季增 2026Q1 | C52: % | E52: 0.875 | G52: Interested-party | H52: 同上 | I52: SIF_nq_4
A53: nq_5 | B53: NAND 合約價季增 2026Q2 | C53: % | E53: 0.725 | G53: Interested-party | H53: 同上 | I53: SIF_nq_5
A54: nq_6 | B54: NAND 合約價季增 2026Q3 | C54: % | E54: 0.15 | G54: Interested-party | H54: 同上 | I54: SIF_nq_6
A55: nq_7 | B55: NAND 合約價季增 2026Q4 | C55: % | E55: 0.175 | G55: Interested-party | H55: 同上 | I55: SIF_nq_7
A56: nqA_8 | B56: NAND 合約價季增 2027Q1（A） | C56: % | E56: 0.03 | G56: Interested-party | H56: TrendForce：2027 下半年供需平衡、價格面臨下修壓力 | I56: SIF_nqA_8
A57: nqA_9 | B57: NAND 合約價季增 2027Q2（A） | C57: % | E57: 0 | G57: Interested-party | H57: 同上 | I57: SIF_nqA_9
A58: nqA_10 | B58: NAND 合約價季增 2027Q3（A） | C58: % | E58: -0.05 | G58: Interested-party | H58: 同上 | I58: SIF_nqA_10
A59: nqA_11 | B59: NAND 合約價季增 2027Q4（A） | C59: % | E59: -0.07 | G59: Interested-party | H59: 同上 | I59: SIF_nqA_11
...

Sheet Units
A1: Units — 加速器平台別顆數（百萬顆；情境 A 基準）。2026–2028＝In 頁 M2；2029＝2028 ×（1＋In 頁 M5 平台別成長率）。情境 B、C 再乘 Scen 頁係數（2028–29）
A3: 平台 | B3: 鍵 | C3: 2026 | D3: 2027 | E3: 2028 | F3: 2029 | G3: 2029 成長
A4: NVIDIA Blackwell（B200／B300） | B4: bw | C4: =u_bw_26 -> 5.4 | D4: =u_bw_27 -> 2.4 | E4: =u_bw_28 -> 0.5 | F4: =E4*(1+g29_bw) -> 0.25 | G4: =g29_bw -> -0.5
A5: NVIDIA Rubin | B5: rb | C5: =u_rb_26 -> 1.7 | D5: =u_rb_27 -> 7 | E5: =u_rb_28 -> 7 | F5: =E5*(1+g29_rb) -> 8.05 | G5: =g29_rb -> 0.15
A6: NVIDIA Rubin Ultra | B6: ru | C6: =u_ru_26 -> 0 | D6: =u_ru_27 -> 0.3 | E6: =u_ru_28 -> 2 | F6: =E6*(1+g29_ru) -> 2.3 | G6: =g29_ru -> 0.15
A7: NVIDIA Hopper（H200 等） | B7: hp | C7: =u_hp_26 -> 0.5 | D7: =u_hp_27 -> 0 | E7: =u_hp_28 -> 0 | F7: =E7*(1+g29_hp) -> 0 | G7: =g29_hp -> 0
A8: AMD Instinct | B8: amd | C8: =u_amd_26 -> 0.75 | D8: =u_amd_27 -> 1.5 | E8: =u_amd_28 -> 2 | F8: =E8*(1+g29_amd) -> 2.3 | G8: =g29_amd -> 0.15
A9: Google TPU | B9: tpu | C9: =u_tpu_26 -> 3.85 | D9: =u_tpu_27 -> 5.5 | E9: =u_tpu_28 -> 7 | F9: =E9*(1+g29_tpu) -> 8.05 | G9: =g29_tpu -> 0.15
A10: AWS Trainium | B10: trn | C10: =u_trn_26 -> 2 | D10: =u_trn_27 -> 2.5 | E10: =u_trn_28 -> 3 | F10: =E10*(1+g29_trn) -> 3.45 | G10: =g29_trn -> 0.15
A11: 其他 ASIC（MTIA、Maia、Ascend 等） | B11: oth | C11: =u_oth_26 -> 1 | D11: =u_oth_27 -> 4.5 | E11: =u_oth_28 -> 5 | F11: =E11*(1+g29_oth) -> 5.75 | G11: =g29_oth -> 0.15
A12: 合計（基準＝情境 A，未乘係數） | C12: =SUM(C4:C11) -> 15.2 | D12: =SUM(D4:D11) -> 23.7 | E12: =SUM(E4:E11) -> 26.5 | F12: =SUM(F4:F11) -> 30.15 | G12: =F12/E12-1 -> 0.13773585
A13: 合計（情境 A） | C13: =C12 -> 15.2 | D13: =D12 -> 23.7 | E13: =E12*um28_A -> 26.5 | F13: =F12*um29_A -> 30.15
A14: 合計（情境 B） | C14: =C12 -> 15.2 | D14: =D12 -> 23.7 | E14: =E12*um28_B -> 21.2 | F14: =F12*um29_B -> 25.6275
A15: 合計（情境 C） | C15: =C12 -> 15.2 | D15: =D12 -> 23.7 | E15: =E12*um28_C -> 15.9 | F15: =F12*um29_C -> 18.09

Sheet Path
A1: Path — 記憶體合約價指數（2025Q1＝1；季增來自 In 頁 M1）。共用市場層：所有記憶體公司用同一條路徑，再依各自會計年度取平均
A3: 路徑 | B3: 情境 | C3: 2025Q1 | D3: 2025Q2 | E3: 2025Q3 | F3: 2025Q4 | G3: 2026Q1 | H3: 2026Q2 | I3: 2026Q3 | J3: 2026Q4 | K3: 2027Q1 | L3: 2027Q2 | M3: 2027Q3 | N3: 2027Q4 | O3: 2028Q1 | P3: 2028Q2 | Q3: 2028Q3 | R3: 2028Q4 | S3: 2029Q1 | T3: 2029Q2 | U3: 2029Q3 | V3: 2029Q4
A4: 一般 DRAM | B4: A | C4: 1 | D4: =C4*(1+cq_1) -> 0.975 | E4: =D4*(1+cq_2) -> 1.096875 | F4: =E4*(1+cq_3) -> 1.6178906 | G4: =F4*(1+cq_4) -> 3.1548867 | H4: =G4*(1+cq_5) -> 5.0635932 | I4: =H4*(1+cq_6) -> 5.8484501 | J4: =I4*(1+cq_7) -> 6.5795064 | K4: =J4*(1+cqA_8) -> 6.7768916 | L4: =K4*(1+cqA_9) -> 6.7768916 | M4: =L4*(1+cqA_10) -> 6.6413538 | N4: =M4*(1+cqA_11) -> 6.4421131 | O4: =N4*(1+cqA_12) -> 6.2488497 | P4: =O4*(1+cqA_13) -> 6.0613843 | Q4: =P4*(1+cqA_14) -> 5.9401566 | R4: =Q4*(1+cqA_15) -> 5.8213534 | S4: =R4*(1+cqA_16) -> 5.6467128 | T4: =S4*(1+cqA_17) -> 5.4773114 | U4: =T4*(1+cqA_18) -> 5.3677652 | V4: =U4*(1+cqA_19) -> 5.2604099
A5: 一般 DRAM | B5: B | C5: 1 | D5: =C5*(1+cq_1) -> 0.975 | E5: =D5*(1+cq_2) -> 1.096875 | F5: =E5*(1+cq_3) -> 1.6178906 | G5: =F5*(1+cq_4) -> 3.1548867 | H5: =G5*(1+cq_5) -> 5.0635932 | I5: =H5*(1+cq_6) -> 5.8484501 | J5: =I5*(1+cq_7) -> 6.5795064 | K5: =J5*(1+cqB_8) -> 6.9084817 | L5: =K5*(1+cqB_9) -> 7.0466513 | M5: =L5*(1+cqB_10) -> 6.4829192 | N5: =M5*(1+cqB_11) -> 5.5104814 | O5: =N5*(1+cqB_12) -> 4.132861 | P5: =O5*(1+cqB_13) -> 3.5129319 | Q5: =P5*(1+cqB_14) -> 3.1616387 | R5: =Q5*(1+cqB_15) -> 3.0035567 | S5: =R5*(1+cqB_16) -> 3.1537346 | T5: =S5*(1+cqB_17) -> 3.3114213 | U5: =T5*(1+cqB_18) -> 3.4107639 | V5: =U5*(1+cqB_19) -> 3.5130869
A6: 一般 DRAM | B6: C | C6: 1 | D6: =C6*(1+cq_1) -> 0.975 | E6: =D6*(1+cq_2) -> 1.096875 | F6: =E6*(1+cq_3) -> 1.6178906 | G6: =F6*(1+cq_4) -> 3.1548867 | H6: =G6*(1+cq_5) -> 5.0635932 | I6: =H6*(1+cq_6) -> 5.8484501 | J6: =I6*(1+cq_7) -> 6.5795064 | K6: =J6*(1+cqC_8) -> 6.9084817 | L6: =K6*(1+cqC_9) -> 7.0466513 | M6: =L6*(1+cqC_10) -> 6.4829192 | N6: =M6*(1+cqC_11) -> 5.5104814 | O6: =N6*(1+cqC_12) -> 3.5818129 | P6: =O6*(1+cqC_13) -> 2.507269 | Q6: =P6*(1+cqC_14) -> 1.8804518 | R6: =Q6*(1+cqC_15) -> 1.5043614 | S6: =R6*(1+cqC_16) -> 1.5043614 | T6: =S6*(1+cqC_17) -> 1.5795795 | U6: =T6*(1+cqC_18) -> 1.7059458 | V6: =U6*(1+cqC_19) -> 1.8765404
A8: NAND | B8: A | C8: 1 | D8: =C8*(1+nq_1) -> 1 | E8: =D8*(1+nq_2) -> 1.05 | F8: =E8*(1+nq_3) -> 1.365 | G8: =F8*(1+nq_4) -> 2.559375 | H8: =G8*(1+nq_5) -> 4.4149219 | I8: =H8*(1+nq_6) -> 5.0771602 | J8: =I8*(1+nq_7) -> 5.9656632 | K8: =J8*(1+nqA_8) -> 6.1446331 | L8: =K8*(1+nqA_9) -> 6.1446331 | M8: =L8*(1+nqA_10) -> 5.8374014 | N8: =M8*(1+nqA_11) -> 5.4287833 | O8: =N8*(1+nqA_12) -> 5.1573442 | P8: =O8*(1+nqA_13) -> 4.899477 | Q8: =P8*(1+nqA_14) -> 4.6545031 | R8: =Q8*(1+nqA_15) -> 4.4217779 | S8: =R8*(1+nqA_16) -> 4.2891246 | T8: =S8*(1+nqA_17) -> 4.1604509 | U8: =T8*(1+nqA_18) -> 4.0356373 | V8: =U8*(1+nqA_19) -> 3.9145682
A9: NAND | B9: B | C9: 1 | D9: =C9*(1+nq_1) -> 1 | E9: =D9*(1+nq_2) -> 1.05 | F9: =E9*(1+nq_3) -> 1.365 | G9: =F9*(1+nq_4) -> 2.559375 | H9: =G9*(1+nq_5) -> 4.4149219 | I9: =H9*(1+nq_6) -> 5.0771602 | J9: =I9*(1+nq_7) -> 5.9656632 | K9: =J9*(1+nqB_8) -> 6.2639463 | L9: =K9*(1+nqB_9) -> 6.3892253 | M9: =L9*(1+nqB_10) -> 5.7503027 | N9: =M9*(1+nqB_11) -> 4.6002422 | O9: =N9*(1+nqB_12) -> 3.2201695 | P9: =O9*(1+nqB_13) -> 2.4151272 | Q9: =P9*(1+nqB_14) -> 1.9321017 | R9: =Q9*(1+nqB_15) -> 1.7388915 | S9: =R9*(1+nqB_16) -> 1.8258361 | T9: =S9*(1+nqB_17) -> 1.9171279 | U9: =T9*(1+nqB_18) -> 1.9746418 | V9: =U9*(1+nqB_19) -> 2.033881
A10: NAND | B10: C | C10: 1 | D10: =C10*(1+nq_1) -> 1 | E10: =D10*(1+nq_2) -> 1.05 | F10: =E10*(1+nq_3) -> 1.365 | G10: =F10*(1+nq_4) -> 2.559375 | H10: =G10*(1+nq_5) -> 4.4149219 | I10: =H10*(1+nq_6) -> 5.0771602 | J10: =I10*(1+nq_7) -> 5.9656632 | K10: =J10*(1+nqC_8) -> 6.2639463 | L10: =K10*(1+nqC_9) -> 6.3892253 | M10: =L10*(1+nqC_10) -> 5.7503027 | N10: =M10*(1+nqC_11) -> 4.6002422 | O10: =N10*(1+nqC_12) -> 2.9901574 | P10: =O10*(1+nqC_13) -> 1.9436023 | Q10: =P10*(1+nqC_14) -> 1.4577017 | R10: =Q10*(1+nqC_15) -> 1.1661614 | S10: =R10*(1+nqC_16) -> 1.1661614 | T10: =S10*(1+nqC_17) -> 1.2244695 | U10: =T10*(1+nqC_18) -> 1.322427 | V10: =U10*(1+nqC_19) -> 1.4546697
A12: 年均指數
A13: 路徑 | B13: 情境 | C13: 2025 | D13: 2026 | E13: 2027 | F13: 2028 | G13: 2029 | H13: 2026÷2025 | I13: 2027÷2026 | J13: 2028÷2027 | K13: 2029÷2028
A14: 一般 DRAM | B14: A | C14: =AVERAGE(C4:F4) -> 1.1724414 | D14: =AVERAGE(G4:J4) -> 5.1616091 | E14: =AVERAGE(K4:N4) -> 6.6593125 | F14: =AVERAGE(O4:R4) -> 6.017936 | G14: =AVERAGE(S4:V4) -> 5.4380499 | H14: =D14/C14-1 -> 3.4024453 | I14: =E14/D14-1 -> 0.29016211 | J14: =F14/E14-1 -> -0.096312722 | K14: =G14/F14-1 -> -0.09635964
A15: 一般 DRAM | B15: B | C15: =AVERAGE(C5:F5) -> 1.1724414 | D15: =AVERAGE(G5:J5) -> 5.1616091 | E15: =AVERAGE(K5:N5) -> 6.4871334 | F15: =AVERAGE(O5:R5) -> 3.4527471 | G15: =AVERAGE(S5:V5) -> 3.3472517 | H15: =D15/C15-1 -> 3.4024453 | I15: =E15/D15-1 -> 0.25680447 | J15: =F15/E15-1 -> -0.46775458 | K15: =G15/F15-1 -> -0.030554048
A16: 一般 DRAM | B16: C | C16: =AVERAGE(C6:F6) -> 1.1724414 | D16: =AVERAGE(G6:J6) -> 5.1616091 | E16: =AVERAGE(K6:N6) -> 6.4871334 | F16: =AVERAGE(O6:R6) -> 2.3684738 | G16: =AVERAGE(S6:V6) -> 1.6666068 | H16: =D16/C16-1 -> 3.4024453 | I16: =E16/D16-1 -> 0.25680447 | J16: =F16/E16-1 -> -0.63489671 | K16: =G16/F16-1 -> -0.29633724
A17: NAND | B17: A | C17: =AVERAGE(C8:F8) -> 1.10375 | D17: =AVERAGE(G8:J8) -> 4.5042801 | E17: =AVERAGE(K8:N8) -> 5.8888627 | F17: =AVERAGE(O8:R8) -> 4.7832755 | G17: =AVERAGE(S8:V8) -> 4.0999453 | H17: =D17/C17-1 -> 3.0808879 | I17: =E17/D17-1 -> 0.30739267 | J17: =F17/E17-1 -> -0.18774205 | K17: =G17/F17-1 -> -0.14285823
A18: NAND | B18: B | C18: =AVERAGE(C9:F9) -> 1.10375 | D18: =AVERAGE(G9:J9) -> 4.5042801 | E18: =AVERAGE(K9:N9) -> 5.7509291 | F18: =AVERAGE(O9:R9) -> 2.3265725 | G18: =AVERAGE(S9:V9) -> 1.9378717 | H18: =D18/C18-1 -> 3.0808879 | I18: =E18/D18-1 -> 0.27676989 | J18: =F18/E18-1 -> -0.59544407 | K18: =G18/F18-1 -> -0.16707013
A19: NAND | B19: C | C19: =AVERAGE(C10:F10) -> 1.10375 | D19: =AVERAGE(G10:J10) -> 4.5042801 | E19: =AVERAGE(K10:N10) -> 5.7509291 | F19: =AVERAGE(O10:R10) -> 1.8894057 | G19: =AVERAGE(S10:V10) -> 1.2919319 | H19: =D19/C19-1 -> 3.0808879 | I19: =E19/D19-1 -> 0.27676989 | J19: =F19/E19-1 -> -0.67146079 | K19: =G19/F19-1 -> -0.31622315

Sheet Mkt
A1: Mkt — 加速器數量層（最小版）與 HBM 市場（日曆年）。需求＝顆數 × GB × 情境顆數係數（2028–29）；供給三情境相同；出貨＝MIN(需求, 供給)；市場＝出貨 × 單價（單價依情境）
A2: 公式由 markets/memory/market.py write() 產生（與各記憶體公司模型的 Mkt 頁同一份）；輸入讀本活頁簿 In 頁
A3: 項目 | B3: 單位 | C3: 2025 | D3: 2026 | E3: 2027 | F3: 2028 | G3: 2029 | H3: 說明
A4: 需求：加速器裝載的 HBM（PB）
A5: NVIDIA Blackwell（B200／B300） | B5: PB | D5: =u_bw_26*g_bw_26 -> 1404 | E5: =u_bw_27*g_bw_27 -> 672 | F5: =u_bw_28*g_bw_28 -> 144
A6: NVIDIA Rubin | B6: PB | D6: =u_rb_26*g_rb_26 -> 489.6 | E6: =u_rb_27*g_rb_27 -> 2016 | F6: =u_rb_28*g_rb_28 -> 2016
A7: NVIDIA Rubin Ultra | B7: PB | D7: =u_ru_26*g_ru_26 -> 0 | E7: =u_ru_27*g_ru_27 -> 307.2 | F7: =u_ru_28*g_ru_28 -> 2048
A8: NVIDIA Hopper（H200 等） | B8: PB | D8: =u_hp_26*g_hp_26 -> 70.5 | E8: =u_hp_27*g_hp_27 -> 0 | F8: =u_hp_28*g_hp_28 -> 0
A9: AMD Instinct | B9: PB | D9: =u_amd_26*g_amd_26 -> 216 | E9: =u_amd_27*g_amd_27 -> 540 | F9: =u_amd_28*g_amd_28 -> 864
A10: Google TPU | B10: PB | D10: =u_tpu_26*g_tpu_26 -> 739.2 | E10: =u_tpu_27*g_tpu_27 -> 1375 | F10: =u_tpu_28*g_tpu_28 -> 2016
A11: AWS Trainium | B11: PB | D11: =u_trn_26*g_trn_26 -> 220 | E11: =u_trn_27*g_trn_27 -> 360 | F11: =u_trn_28*g_trn_28 -> 600
A12: 其他 ASIC（MTIA、Maia、Ascend 等） | B12: PB | D12: =u_oth_26*g_oth_26 -> 150 | E12: =u_oth_27*g_oth_27 -> 900 | F12: =u_oth_28*g_oth_28 -> 1250
A13: 需求合計（裝載） | B13: EB | D13: =SUM(D5:D12)/1000 -> 3.2893 | E13: =SUM(E5:E12)/1000 -> 6.1702 | F13: =SUM(F5:F12)/1000 -> 8.938 | G13: =F13*(1+hbm_dem29) -> 11.6194
A14: 需求 × 出貨係數（基準＝情境 A） | B14: EB | D14: =D13*hbm_gross -> 3.782695 | E14: =E13*hbm_gross -> 7.09573 | F14: =F13*hbm_gross -> 10.2787 | G14: =G13*hbm_gross -> 13.36231
A15: 加速器顆數合計 | B15: 百萬顆 | D15: =u_bw_26+u_rb_26+u_ru_26+u_hp_26+u_amd_26+u_tpu_26+u_trn_26+u_oth_26 -> 15.2 | E15: =u_bw_27+u_rb_27+u_ru_27+u_hp_27+u_amd_27+u_tpu_27+u_trn_27+u_oth_27 -> 23.7 | F15: =u_bw_28+u_rb_28+u_ru_28+u_hp_28+u_amd_28+u_tpu_28+u_trn_28+u_oth_28 -> 26.5 | H15: JPMorgan 2027：GPU 10.9M、ASIC 12.5M；情境 A 基準
A16: 每顆平均 HBM | B16: GB | D16: =D13*1000/D15 -> 216.40132 | E16: =E13*1000/E15 -> 260.34599 | F16: =F13*1000/F15 -> 337.28302
A17: 供給（三情境相同） | B17: EB | C17: =D17/(1+hbm_g26) -> 2.2251147 | D17: =D14 -> 3.782695 | E17: =D17*(1+hbm_sup27) -> 5.8631772 | F17: =E17*(1+hbm_sup28) -> 8.501607 | G17: =F17*(1+hbm_sup29) -> 11.477169 | H17: 2026 供給＝需求出貨（年中已成交）；供給不隨需求情境變（產能 2027 前已訂定）
A18: 顆數係數（A；2028–29 ÷ 基準，與台積電、Advantest 同一套） | B18: x | D18: 1 | E18: 1 | F18: =um28_A -> 1 | G18: =um29_A -> 1 | H18: 2026–27 無情境差異
A19: 顆數係數（B；2028–29 ÷ 基準，與台積電、Advantest 同一套） | B19: x | D19: 1 | E19: 1 | F19: =um28_B -> 0.8 | G19: =um29_B -> 0.85 | H19: 2026–27 無情境差異
A20: 顆數係數（C；2028–29 ÷ 基準，與台積電、Advantest 同一套） | B20: x | D20: 1 | E20: 1 | F20: =um28_C -> 0.6 | G20: =um29_C -> 0.6 | H20: 2026–27 無情境差異
A21: 需求 × 出貨係數（A） | B21: EB | D21: =D14*D18 -> 3.782695 | E21: =E14*E18 -> 7.09573 | F21: =F14*F18 -> 10.2787 | G21: =G14*G18 -> 13.36231
A22: 需求 × 出貨係數（B） | B22: EB | D22: =D14*D19 -> 3.782695 | E22: =E14*E19 -> 7.09573 | F22: =F14*F19 -> 8.22296 | G22: =G14*G19 -> 11.357964
A23: 需求 × 出貨係數（C） | B23: EB | D23: =D14*D20 -> 3.782695 | E23: =E14*E20 -> 7.09573 | F23: =F14*F20 -> 6.16722 | G23: =G14*G20 -> 8.017386
A24: 出貨＝MIN(需求, 供給)（A） | B24: EB | C24: =C17 -> 2.2251147 | D24: =MIN(D21,D17) -> 3.782695 | E24: =MIN(E21,E17) -> 5.8631772 | F24: =MIN(F21,F17) -> 8.501607 | G24: =MIN(G21,G17) -> 11.477169 | H24: 需求低於供給時出貨＝需求（閒置產能）
A25: 出貨＝MIN(需求, 供給)（B） | B25: EB | C25: =C17 -> 2.2251147 | D25: =MIN(D22,D17) -> 3.782695 | E25: =MIN(E22,E17) -> 5.8631772 | F25: =MIN(F22,F17) -> 8.22296 | G25: =MIN(G22,G17) -> 11.357964
A26: 出貨＝MIN(需求, 供給)（C） | B26: EB | C26: =C17 -> 2.2251147 | D26: =MIN(D23,D17) -> 3.782695 | E26: =MIN(E23,E17) -> 5.8631772 | F26: =MIN(F23,F17) -> 6.16722 | G26: =MIN(G23,G17) -> 8.017386
A27: 需求 − 供給（A；>0＝短缺） | B27: EB | D27: =D21-D17 -> 0 | E27: =E21-E17 -> 1.2325527 | F27: =F21-F17 -> 1.777093 | G27: =G21-G17 -> 1.8851405
A28: 需求 − 供給（B；>0＝短缺） | B28: EB | D28: =D22-D17 -> 0 | E28: =E22-E17 -> 1.2325527 | F28: =F22-F17 -> -0.27864701 | G28: =G22-G17 -> -0.11920597
A29: 需求 − 供給（C；>0＝短缺） | B29: EB | D29: =D23-D17 -> 0 | E29: =E23-E17 -> 1.2325527 | F29: =F23-F17 -> -2.334387 | G29: =G23-G17 -> -3.4597835
A30: HBM 單價（A） | B30: $/GB | C30: =hbm_mkt25/C24 -> 15.729526 | D30: =hbm_p26 -> 14.6 | E30: =D30*(1+hbm_p27) -> 26.28 | F30: =E30*(1+hbm_p28_A) -> 28.908 | G30: =F30*(1+hbm_p29_A) -> 27.4626
A31: HBM 單價（B） | B31: $/GB | C31: =hbm_mkt25/C24 -> 15.729526 | D31: =hbm_p26 -> 14.6 | E31: =D31*(1+hbm_p27) -> 26.28 | F31: =E31*(1+hbm_p28_B) -> 19.71 | G31: =F31*(1+hbm_p29_B) -> 19.71
A32: HBM 單價（C） | B32: $/GB | C32: =hbm_mkt25/C24 -> 15.729526 | D32: =hbm_p26 -> 14.6 | E32: =D32*(1+hbm_p27) -> 26.28 | F32: =E32*(1+hbm_p28_C) -> 15.768 | G32: =F32*(1+hbm_p29_C) -> 16.5564
A33: HBM 市場（A） | B33: $B | C33: =C24*C30 -> 35 | D33: =D24*D30 -> 55.227347 | E33: =E24*E30 -> 154.0843 | F33: =F24*F30 -> 245.76446 | G33: =G24*G30 -> 315.19291
A34: HBM 市場（B） | B34: $B | C34: =C25*C31 -> 35 | D34: =D25*D31 -> 55.227347 | E34: =E25*E31 -> 154.0843 | F34: =F25*F31 -> 162.07454 | G34: =G25*G31 -> 223.86546
A35: HBM 市場（C） | B35: $B | C35: =C26*C32 -> 35 | D35: =D26*D32 -> 55.227347 | E35: =E26*E32 -> 154.0843 | F35: =F26*F32 -> 97.244725 | G35: =G26*G32 -> 132.73905
A37: 對帳（樣板驗收 2）
A38: 由下而上：NVIDIA 裝載 HBM × 單價（2026） | B38: $B | D38: =(D5+D6+D7+D8)/1000*hbm_p26 -> 28.67586
A39: 由上而下：NVIDIA 資料中心營收 × 每顆 HBM ÷ 每顆 NVIDIA 內容（2026） | B39: $B | D39: =nv_dc26*nv_hbm/nv_content -> 38.972897 | H39: 橋接表 v0.2；與顆數預測獨立
A40: 差距 | B40: % | D40: =D38/D39-1 -> -0.26421021
A41: 由營收推得 NVIDIA 顆數 vs 顆數預測 | B41: 百萬顆 | D41: =nv_dc26/nv_content -> 8.7383178 | E41: =u_bw_26+u_rb_26+u_hp_26 -> 7.6 | H41: D＝營收推得；E＝顆數預測（2026）
...

Sheet TK_In
A1: TK_In — Tokenomics 取數（只讀鏡像；權威在算力收支）：20261025_Tokenomics_v21.7.xlsx（v21.7，commit 91d541f，擷取 2026-10-27）。綠字＝外部連結值，不得在本頁修改；Tokenomics 升版時以 tools/tokenomics/import_tokenomics.py 重抽快照再重建
A2: 右側 J–L 欄：company-models 下游目前讀的舊版快照（markets/chip_bridge v20.1）；M 欄＝與現行 TK 不同的格數（>0 表示下游用的值已過時）
A4: 名稱（TK） | B4: 世代／項目 | C4: 本庫名稱 | D4: 低 | E4: 基準 | F4: 高 | G4: 單位 | H4: TK 位置 | I4: 取用者 | J4: 舊快照 低 | K4: 舊快照 基準 | L4: 舊快照 高 | M4: 差異格數
A5: IF_RacksPerGW | B5: Hopper H100 | C5: TK_RacksPerGW_H100 | D5: 22439 | E5: 22439 | F5: 22439 | G5: 架 | H5: Interface!C6:Q6 | I5: chip_bridge、network（經橋接表） | J5: 22439 | K5: 22439 | L5: 22439 | M5: =(ABS(D5-J5)>0.000000001)+(ABS(E5-K5)>0.000000001)+(ABS(F5-L5)>0.000000001) -> 0
A6: IF_RacksPerGW | B6: GB200 NVL72 | C6: TK_RacksPerGW_GB200 | D6: 6969 | E6: 6969 | F6: 6969 | G6: 架 | H6: Interface!C6:Q6 | I6: chip_bridge、network（經橋接表） | J6: 6969 | K6: 6969 | L6: 6969 | M6: =(ABS(D6-J6)>0.000000001)+(ABS(E6-K6)>0.000000001)+(ABS(F6-L6)>0.000000001) -> 0
A7: IF_RacksPerGW | B7: GB300 NVL72 | C7: TK_RacksPerGW_GB300 | D7: 6764 | E7: 6764 | F7: 6764 | G7: 架 | H7: Interface!C6:Q6 | I7: chip_bridge、network（經橋接表） | J7: 6764 | K7: 6764 | L7: 6764 | M7: =(ABS(D7-J7)>0.000000001)+(ABS(E7-K7)>0.000000001)+(ABS(F7-L7)>0.000000001) -> 0
A8: IF_RacksPerGW | B8: VR200 NVL72 | C8: TK_RacksPerGW_VR200 | D8: 4052 | E8: 4052 | F8: 4052 | G8: 架 | H8: Interface!C6:Q6 | I8: chip_bridge、network（經橋接表） | J8: 4052 | K8: 4052 | L8: 4052 | M8: =(ABS(D8-J8)>0.000000001)+(ABS(E8-K8)>0.000000001)+(ABS(F8-L8)>0.000000001) -> 0
A9: IF_RacksPerGW | B9: Rubin Ultra（MGX NVL 單架，72 GPU） | C9: TK_RacksPerGW_RU | D9: 2705 | E9: 2705 | F9: 2705 | G9: 架 | H9: Interface!C6:Q6 | I9: chip_bridge、network（經橋接表） | J9: 2705 | K9: 2705 | L9: 2705 | M9: =(ABS(D9-J9)>0.000000001)+(ABS(E9-K9)>0.000000001)+(ABS(F9-L9)>0.000000001) -> 0
A10: IF_GPUsPerGW | B10: Hopper H100 | C10: TK_GPUsPerGW_H100 | D10: 718048 | E10: 718048 | F10: 718048 | G10: 顆 | H10: Interface!C7:Q7 | I10: chip_bridge | J10: 718048 | K10: 718048 | L10: 718048 | M10: =(ABS(D10-J10)>0.000000001)+(ABS(E10-K10)>0.000000001)+(ABS(F10-L10)>0.000000001) -> 0
A11: IF_GPUsPerGW | B11: GB200 NVL72 | C11: TK_GPUsPerGW_GB200 | D11: 501768 | E11: 501768 | F11: 501768 | G11: 顆 | H11: Interface!C7:Q7 | I11: chip_bridge | J11: 501768 | K11: 501768 | L11: 501768 | M11: =(ABS(D11-J11)>0.000000001)+(ABS(E11-K11)>0.000000001)+(ABS(F11-L11)>0.000000001) -> 0
A12: IF_GPUsPerGW | B12: GB300 NVL72 | C12: TK_GPUsPerGW_GB300 | D12: 487008 | E12: 487008 | F12: 487008 | G12: 顆 | H12: Interface!C7:Q7 | I12: chip_bridge | J12: 487008 | K12: 487008 | L12: 487008 | M12: =(ABS(D12-J12)>0.000000001)+(ABS(E12-K12)>0.000000001)+(ABS(F12-L12)>0.000000001) -> 0
A13: IF_GPUsPerGW | B13: VR200 NVL72 | C13: TK_GPUsPerGW_VR200 | D13: 291744 | E13: 291744 | F13: 291744 | G13: 顆 | H13: Interface!C7:Q7 | I13: chip_bridge | J13: 291744 | K13: 291744 | L13: 291744 | M13: =(ABS(D13-J13)>0.000000001)+(ABS(E13-K13)>0.000000001)+(ABS(F13-L13)>0.000000001) -> 0
A14: IF_GPUsPerGW | B14: Rubin Ultra（MGX NVL 單架，72 GPU） | C14: TK_GPUsPerGW_RU | D14: 194760 | E14: 194760 | F14: 194760 | G14: 顆 | H14: Interface!C7:Q7 | I14: chip_bridge | J14: 194760 | K14: 194760 | L14: 194760 | M14: =(ABS(D14-J14)>0.000000001)+(ABS(E14-K14)>0.000000001)+(ABS(F14-L14)>0.000000001) -> 0
A15: IF_CapexIT | B15: Hopper H100 | C15: TK_CapexIT_H100 | D15: 21.420269 | E15: 27.510214 | F15: 34.120743 | G15: $B | H15: Interface!C9:Q9 | I15: chip_bridge、network、delta、quanta 等（部署 GW 換算） | J15: 21.420269 | K15: 27.510214 | L15: 34.120743 | M15: =(ABS(D15-J15)>0.000000001)+(ABS(E15-K15)>0.000000001)+(ABS(F15-L15)>0.000000001) -> 0
A16: IF_CapexIT | B16: GB200 NVL72 | C16: TK_CapexIT_GB200 | D16: 20.63939 | E16: 24.015174 | F16: 27.650204 | G16: $B | H16: Interface!C9:Q9 | I16: chip_bridge、network、delta、quanta 等（部署 GW 換算） | J16: 20.63939 | K16: 24.015174 | L16: 27.650204 | M16: =(ABS(D16-J16)>0.000000001)+(ABS(E16-K16)>0.000000001)+(ABS(F16-L16)>0.000000001) -> 0
... A29: IF_CapexTotal | B29: Rubin Ultra（MGX NVL 單架，72 GPU） | C29: TK_CapexTotal_RU | D29: 46.057578 | E29: 62.75578 | F29: 81.667558 | G29: $B | H29: Interface!C11:Q11 | I29: chip_bridge | J29: 46.057578 | K29: 62.75578 | L29: 81.667558 | M29: =(ABS(D29-J29)>0.000000001)+(ABS(E29-K29)>0.000000001)+(ABS(F29-L29)>0.000000001) -> 0
A30: IF_RackPrice | B30: Hopper H100 | C30: TK_RackPrice_H100 | D30: 0.9 | E30: 1.1 | F30: 1.3 | G30: $M/架 | H30: Interface!C364:Q364 | I30: chip_bridge（目前抄錄值，改接排入中）
A31: IF_RackPrice | B31: GB200 NVL72 | C31: TK_RackPrice_GB200 | D31: 2.8 | E31: 3.1 | F31: 3.4 | G31: $M/架 | H31: Interface!C364:Q364 | I31: chip_bridge（目前抄錄值，改接排入中）
A32: IF_RackPrice | B32: GB300 NVL72 | C32: TK_RackPrice_GB300 | D32: 4 | E32: 4.3 | F32: 5 | G32: $M/架 | H32: Interface!C364:Q364 | I32: chip_bridge（目前抄錄值，改接排入中）
A33: IF_RackPrice | B33: VR200 NVL72 | C33: TK_RackPrice_VR200 | D33: 7.5 | E33: 8.4 | F33: 9.1 | G33: $M/架 | H33: Interface!C364:Q364 | I33: chip_bridge（目前抄錄值，改接排入中）
A34: IF_RackPrice | B34: Rubin Ultra（MGX NVL 單架，72 GPU） | C34: TK_RackPrice_RU | D34: 12.6 | E34: 16.8 | F34: 21 | G34: $M/架 | H34: Interface!C364:Q364 | I34: chip_bridge（目前抄錄值，改接排入中）
A35: IF_ScaleOutShare | B35: Hopper H100 | C35: TK_ScaleOutShare_H100 | D35: 0.05 | E35: 0.1 | F35: 0.15 | G35: 比例（÷ 機架價） | H35: Interface!C365:Q365 | I35: chip_bridge（目前抄錄值）
A36: IF_ScaleOutShare | B36: GB200 NVL72 | C36: TK_ScaleOutShare_GB200 | D36: 0.05 | E36: 0.1 | F36: 0.15 | G36: 比例（÷ 機架價） | H36: Interface!C365:Q365 | I36: chip_bridge（目前抄錄值）
A37: IF_ScaleOutShare | B37: GB300 NVL72 | C37: TK_ScaleOutShare_GB300 | D37: 0.05 | E37: 0.1 | F37: 0.15 | G37: 比例（÷ 機架價） | H37: Interface!C365:Q365 | I37: chip_bridge（目前抄錄值）
A38: IF_ScaleOutShare | B38: VR200 NVL72 | C38: TK_ScaleOutShare_VR200 | D38: 0.05 | E38: 0.1 | F38: 0.15 | G38: 比例（÷ 機架價） | H38: Interface!C365:Q365 | I38: chip_bridge（目前抄錄值）
A39: IF_ScaleOutShare | B39: Rubin Ultra（MGX NVL 單架，72 GPU） | C39: TK_ScaleOutShare_RU | D39: 0.05 | E39: 0.1 | F39: 0.15 | G39: 比例（÷ 機架價） | H39: Interface!C365:Q365 | I39: chip_bridge（目前抄錄值）
A40: IF_StoragePerGPU | B40: Hopper H100 | C40: TK_StoragePerGPU_H100 | D40: 300 | E40: 500 | F40: 800 | G40: $/GPU | H40: Interface!C366:Q366 | I40: chip_bridge（目前抄錄值）
A41: IF_StoragePerGPU | B41: GB200 NVL72 | C41: TK_StoragePerGPU_GB200 | D41: 300 | E41: 500 | F41: 800 | G41: $/GPU | H41: Interface!C366:Q366 | I41: chip_bridge（目前抄錄值）
... A58: IF_NonNV_Hold_Maia | B58: Microsoft Maia 200：持有成本比（每 GW 持有成本 ÷ VR200）（NonNV 第 11 列 E:G；同層級、同 SLO；Assumed；C＝低、D＝基準、E＝高） | C58: TK_NonNV_Hold_Maia | D58: 0.4 | E58: 0.5 | F58: 0.6 | G58: 比（÷ VR200） | H58: Interface!C382:E382 | I58: avgo、mrvl、amd 等（目前各自假設，待改接）
A60: 下游舊快照與現行 TK 不同的格數 | M60: =SUM(M5:M58) -> 2

Sheet Conflicts
A1: Conflicts — 跨模型衝突登錄：同一個行業變數在兩個以上公司模型有不同值。本庫的任務是讓每個變數只有一個值；建議值為 Claude 預設（判斷類，Andy 可改），在對應子產業併入本庫的版本生效，生效前各公司模型維持現值
A3: ID | B3: 子產業 | C3: 變數 | D3: 單位 | E3: 模型甲（位置） | F3: 甲值 | G3: 模型乙（位置） | H3: 乙值 | I3: 性質 | J3: 建議單一值與理由 | K3: 生效版本 | L3: 狀態 | M3: 來源
A4: CF01 | B4: 載板 | C4: 南電 2027–29 資本支出（新廠是否已核准） | D4: NT$億 | E4: nanya_pcb In!I104（待董事會決議） | F4: 140／180／120 | G4: 工商時報 2026-08-07：董事會已通過高階載板新廠 | H4: 新廠 468 | I4: 過時（公司變數） | J4: 屬公司變數，不入本庫；南電模型下次改版更新為已核准，資本支出依新廠時程重排 | K4: 南電下版 | L4: 待併入 | M4: 算力收支 2026-10-25 A1
A5: CF02 | B5: 載板 | C5: 欣興 2026 資本支出 | D5: NT$億 | E5: unimicron In!E99 | F5: 537 | G5: ibiden In!H52（同業對照） | H5: 340 | I5: 過時 | J5: 以欣興模型 537（較新）為準；Ibiden 對照列下版改讀欣興成品 | K5: v0.4 | L5: 待併入 | M5: 算力收支 2026-10-25 A2
A6: CF03 | B6: 載板 | C6: ABF 供需缺口 2026／27／28 | D6: % | E6: unimicron In!E131（永豐） | F6: 8／27／35 | G6: ibiden 模型與比對 I9 | H6: —／約 21／逾 40 | I6: 行業變數（兩來源） | J6: 本庫設單一路徑：基準取兩來源中點（2027 約 24%、2028 約 37%），低／高為兩來源；Ibiden、欣興、南電、景碩、味之素改讀 | K6: v0.4 | L6: 待併入 | M6: 算力收支 2026-10-25 A3
A7: CF04 | B7: 散熱 | C7: 液冷份額合計（健策是否已納入雙鴻） | D7: % | E7: jentech README、Units!G18 | F7: 未含雙鴻 | G7: auras（2026 約 15.9%） | H7: 15.9 | I7: 份額表不完整 | J7: 本庫建液冷份額表（奇鋐、雙鴻、台達電、其他），合計＝100%；各公司讀自己的列 | K7: v0.5 | L7: 待併入 | M7: 算力收支 2026-10-25 A4
A8: CF05 | B8: 運算 | C8: AMD README 結果表過時 | D8: — | E8: amd/README.md（v0.2） | F8: FY2028 EPS A 10.44 | G8: amd xlsx v0.2.1 PL!F17 | H8: 11.39 | I8: 文件過時（非數值） | J8: README 依 xlsx 重產（工程類，下次改版） | K8: AMD 下版 | L8: 待併入 | M8: 算力收支 2026-10-25 B5
A9: CF06 | B9: 設備 | C9: Hanmi README 與敏感度頁情境 C 定義 | D9: — | E9: hanmi README（v0.2）、Sens!B33 | F9: 3,380／2,835／1,465；C＝高值 | G9: hanmi xlsx v0.2.1 | H9: 3,098 三情境；C＝低值 | I9: 文件過時、標籤相反 | J9: README 重產、Sens!B33 標籤更正（工程類）；混合鍵合滲透率移入本庫 v0.6 | K9: Hanmi 下版／v0.6 | L9: 待併入 | M9: 算力收支 2026-10-25 B6
A10: CF07 | B10: 設備 | C10: BESI README『跨模型注意』過時 | D10: — | E10: besi README | F10: Hanmi A 不含混合鍵合 | G10: hanmi v0.2.1、besi In!I35 | H10: 已同向（A＝高值） | I10: 文件過時 | J10: README 更正（工程類） | K10: BESI 下版 | L10: 待併入 | M10: 算力收支 2026-10-25 B7
A11: CF08 | B11: 設備 | C11: Lam Research 遠期本益比文字 | D11: x | E11: lrcx/README.md | F11: 約 24 | G11: lrcx xlsx README!A2 | H11: 約 25 | I11: 文件不一致 | J11: 以 xlsx 為準（工程類） | K11: Lam 下版 | L11: 待併入 | M11: 算力收支 2026-10-25 B8
A12: CF09 | B12: 伺服器組裝 | C12: 緯穎 2026 AI 占營收、AI 有效份額、AI 營收 | D12: %／US$B | E12: wistron In!E52 | F12: 55%；3.92%；24.85 | G12: wiwynn In!E44 | H12: 48%；3.45%；21.88 | I12: 行業變數（組裝份額表） | J12: 本庫建 AI 伺服器組裝份額表（鴻海、廣達、緯穎、緯創、美超微、戴爾、其他），以緯穎模型（公司自身錨點，較直接）為準；緯創改讀 | K12: v0.5 | L12: 待併入 | M12: 算力收支 2026-10-25 C9
A13: CF10 | B13: 伺服器組裝 | C13: 2026 商用 GPU 系統市場 | D13: US$B | E13: dell Units!C8（AMD 按 VR200 計價） | F13: 638.2 | G13: smci Units!C8（按 GB300） | H13: 595.5 | I13: 口徑（每顆計價世代） | J13: 本庫只留一個系統市場（每顆計價依各平台實際世代，AMD 依 TK NonNV 持有比換算），戴爾、美超微、廣達、鴻海同讀 | K13: v0.5 | L13: 待併入 | M13: 算力收支 2026-10-25 C10
A14: CF11 | B14: 電源 | C14: 台達電 AI 電源市占 | D14: % | E14: delta In!E67（凱基 2025-07） | F14: 約 70 | G14: liteon In!E75（凱基 2025-09） | H14: 60–65 | I14: 行業變數（份額表） | J14: 本庫建 AI 電源份額表（台達電、光寶、其他），基準採較新的凱基 2025-09：台達電 62.5%（60–65），兩家改讀；台達電 EPS 會下修 | K14: v0.5 | L14: 待 Andy | M14: 算力收支 2026-10-25 C11
... A25: CF22 | B25: 部署 | C25: 2026 部署 GW | D25: GW | E25: network／delta／quanta 等（AI IT capex ÷ 每 GW IT capex） | F25: 23.40 | G25: amkr | H25: 24.25 | I25: 行業變數（兩算法） | J25: 本庫設單一部署 GW 路徑（R4 上線前以 network 算法為準），各模型改讀 | K25: v0.2 | L25: 待併入 | M25: Siliconomics 盤點 2026-10-27

Sheet Interface
A1: Interface — 下游唯一連結點（各公司模型與市場層只讀本頁 SIF_ 具名範圍，經 tools/export_snapshot.py 匯成版本固定快照）。A 節＝輸入（純量，含低／高）；B 節＝推導（年度）；C 節＝Tokenomics 鏡像（SIF_TK_*，值＝TK_In）
A2: 版本：Siliconomics v0.2（20261027）；Tokenomics v21.7
A4: 名稱 | B4: 項目 | C4: 單位 | D4: 低 | E4: 基準 | F4: 高 | G4: 標記 | H4: 來源位置
A5: A. 輸入（純量）
A6: SIF_cq_1 | B6: 一般 DRAM 合約價季增 2025Q2 | C6: % | E6: =In!E6 -> -0.025 | G6: =In!G6 -> Interested-party | H6: In!E6
A7: SIF_cq_2 | B7: 一般 DRAM 合約價季增 2025Q3 | C7: % | E7: =In!E7 -> 0.125 | G7: =In!G7 -> Interested-party | H7: In!E7
A8: SIF_cq_3 | B8: 一般 DRAM 合約價季增 2025Q4 | C8: % | E8: =In!E8 -> 0.475 | G8: =In!G8 -> Interested-party | H8: In!E8
A9: SIF_cq_4 | B9: 一般 DRAM 合約價季增 2026Q1 | C9: % | E9: =In!E9 -> 0.95 | G9: =In!G9 -> Interested-party | H9: In!E9
A10: SIF_cq_5 | B10: 一般 DRAM 合約價季增 2026Q2 | C10: % | E10: =In!E10 -> 0.605 | G10: =In!G10 -> Interested-party | H10: In!E10
A11: SIF_cq_6 | B11: 一般 DRAM 合約價季增 2026Q3 | C11: % | E11: =In!E11 -> 0.155 | G11: =In!G11 -> Interested-party | H11: In!E11
A12: SIF_cq_7 | B12: 一般 DRAM 合約價季增 2026Q4 | C12: % | E12: =In!E12 -> 0.125 | G12: =In!G12 -> Interested-party | H12: In!E12
A13: SIF_cqA_8 | B13: 一般 DRAM 合約價季增 2027Q1（A） | C13: % | E13: =In!E13 -> 0.03 | G13: =In!G13 -> Interested-party | H13: In!E13
A14: SIF_cqA_9 | B14: 一般 DRAM 合約價季增 2027Q2（A） | C14: % | E14: =In!E14 -> 0 | G14: =In!G14 -> Interested-party | H14: In!E14
A15: SIF_cqA_10 | B15: 一般 DRAM 合約價季增 2027Q3（A） | C15: % | E15: =In!E15 -> -0.02 | G15: =In!G15 -> Interested-party | H15: In!E15
A16: SIF_cqA_11 | B16: 一般 DRAM 合約價季增 2027Q4（A） | C16: % | E16: =In!E16 -> -0.03 | G16: =In!G16 -> Interested-party | H16: In!E16
A17: SIF_cqA_12 | B17: 一般 DRAM 合約價季增 2028Q1（A） | C17: % | E17: =In!E17 -> -0.03 | G17: =In!G17 -> Interested-party | H17: In!E17
... A36: SIF_cqB_19 | B36: 一般 DRAM 合約價季增 2029Q4（B） | C36: % | E36: =In!E36 -> 0.03 | G36: =In!G36 -> Interested-party | H36: In!E36
A37: SIF_cqC_8 | B37: 一般 DRAM 合約價季增 2027Q1（C） | C37: % | D37: =In!D37 -> 0 | E37: =In!E37 -> 0.05 | F37: =In!F37 -> 0.1 | G37: =In!G37 -> Assumed | H37: In!E37
A38: SIF_cqC_9 | B38: 一般 DRAM 合約價季增 2027Q2（C） | C38: % | D38: =In!D38 -> -0.03 | E38: =In!E38 -> 0.02 | F38: =In!F38 -> 0.07 | G38: =In!G38 -> Assumed | H38: In!E38
A39: SIF_cqC_10 | B39: 一般 DRAM 合約價季增 2027Q3（C） | C39: % | D39: =In!D39 -> -0.13 | E39: =In!E39 -> -0.08 | F39: =In!F39 -> -0.03 | G39: =In!G39 -> Assumed | H39: In!E39
A40: SIF_cqC_11 | B40: 一般 DRAM 合約價季增 2027Q4（C） | C40: % | D40: =In!D40 -> -0.2 | E40: =In!E40 -> -0.15 | F40: =In!F40 -> -0.1 | G40: =In!G40 -> Assumed | H40: In!E40
A41: SIF_cqC_12 | B41: 一般 DRAM 合約價季增 2028Q1（C） | C41: % | D41: =In!D41 -> -0.45 | E41: =In!E41 -> -0.35 | F41: =In!F41 -> -0.25 | G41: =In!G41 -> Assumed | H41: In!E41
A42: SIF_cqC_13 | B42: 一般 DRAM 合約價季增 2028Q2（C） | C42: % | D42: =In!D42 -> -0.4 | E42: =In!E42 -> -0.3 | F42: =In!F42 -> -0.2 | G42: =In!G42 -> Assumed | H42: In!E42
A43: SIF_cqC_14 | B43: 一般 DRAM 合約價季增 2028Q3（C） | C43: % | D43: =In!D43 -> -0.35 | E43: =In!E43 -> -0.25 | F43: =In!F43 -> -0.15 | G43: =In!G43 -> Assumed | H43: In!E43
A44: SIF_cqC_15 | B44: 一般 DRAM 合約價季增 2028Q4（C） | C44: % | D44: =In!D44 -> -0.3 | E44: =In!E44 -> -0.2 | F44: =In!F44 -> -0.1 | G44: =In!G44 -> Assumed | H44: In!E44
A45: SIF_cqC_16 | B45: 一般 DRAM 合約價季增 2029Q1（C） | C45: % | D45: =In!D45 -> -0.1 | E45: =In!E45 -> 0 | F45: =In!F45 -> 0.1 | G45: =In!G45 -> Assumed | H45: In!E45
A46: SIF_cqC_17 | B46: 一般 DRAM 合約價季增 2029Q2（C） | C46: % | D46: =In!D46 -> -0.05 | E46: =In!E46 -> 0.05 | F46: =In!F46 -> 0.15 | G46: =In!G46 -> Assumed | H46: In!E46
A47: SIF_cqC_18 | B47: 一般 DRAM 合約價季增 2029Q3（C） | C47: % | D47: =In!D47 -> -0.02 | E47: =In!E47 -> 0.08 | F47: =In!F47 -> 0.18 | G47: =In!G47 -> Assumed | H47: In!E47
A48: SIF_cqC_19 | B48: 一般 DRAM 合約價季增 2029Q4（C） | C48: % | D48: =In!D48 -> 0 | E48: =In!E48 -> 0.1 | F48: =In!F48 -> 0.2 | G48: =In!G48 -> Assumed | H48: In!E48
A49: SIF_nq_1 | B49: NAND 合約價季增 2025Q2 | C49: % | E49: =In!E49 -> 0 | G49: =In!G49 -> Interested-party | H49: In!E49
A50: SIF_nq_2 | B50: NAND 合約價季增 2025Q3 | C50: % | E50: =In!E50 -> 0.05 | G50: =In!G50 -> Interested-party | H50: In!E50
A51: SIF_nq_3 | B51: NAND 合約價季增 2025Q4 | C51: % | E51: =In!E51 -> 0.3 | G51: =In!G51 -> Interested-party | H51: In!E51
A52: SIF_nq_4 | B52: NAND 合約價季增 2026Q1 | C52: % | E52: =In!E52 -> 0.875 | G52: =In!G52 -> Interested-party | H52: In!E52
A53: SIF_nq_5 | B53: NAND 合約價季增 2026Q2 | C53: % | E53: =In!E53 -> 0.725 | G53: =In!G53 -> Interested-party | H53: In!E53
A54: SIF_nq_6 | B54: NAND 合約價季增 2026Q3 | C54: % | E54: =In!E54 -> 0.15 | G54: =In!G54 -> Interested-party | H54: In!E54
A55: SIF_nq_7 | B55: NAND 合約價季增 2026Q4 | C55: % | E55: =In!E55 -> 0.175 | G55: =In!G55 -> Interested-party | H55: In!E55
A56: SIF_nqA_8 | B56: NAND 合約價季增 2027Q1（A） | C56: % | E56: =In!E56 -> 0.03 | G56: =In!G56 -> Interested-party | H56: In!E56
A57: SIF_nqA_9 | B57: NAND 合約價季增 2027Q2（A） | C57: % | E57: =In!E57 -> 0 | G57: =In!G57 -> Interested-party | H57: In!E57
A58: SIF_nqA_10 | B58: NAND 合約價季增 2027Q3（A） | C58: % | E58: =In!E58 -> -0.05 | G58: =In!G58 -> Interested-party | H58: In!E58
A59: SIF_nqA_11 | B59: NAND 合約價季增 2027Q4（A） | C59: % | E59: =In!E59 -> -0.07 | G59: =In!G59 -> Interested-party | H59: In!E59
...

Sheet Checks
A1: Checks — 交叉檢查與治理（ERROR 計入 SGOV_Errors，須為 0；WARN 計入 SGOV_Warn，列為待補）
A3: ID | B3: 項目 | C3: 本庫值 | D3: 參照值 | E3: 差 | F3: 判讀 | G3: 性質 | H3: 說明
A4: K1-A2025 | B4: HBM 市場（A） 2025：本庫 vs SK 海力士模型成品 | C4: =Mkt!C33 -> 35 | D4: 35 | E4: =IF(ISNUMBER(D4),C4-D4,"") -> 0 | F4: =IF(NOT(ISNUMBER(D4)),"WARN",IF(ABS(E4)<0.000000001,"OK","ERROR")) -> OK | G4: 驗證（搬移忠實度） | H4: skhynix/dist/20261025_SK海力士模型_v0.5.1.xlsx
A5: K1-A2026 | B5: HBM 市場（A） 2026：本庫 vs SK 海力士模型成品 | C5: =Mkt!D33 -> 55.227347 | D5: 55.227347 | E5: =IF(ISNUMBER(D5),C5-D5,"") -> 0 | F5: =IF(NOT(ISNUMBER(D5)),"WARN",IF(ABS(E5)<0.000000001,"OK","ERROR")) -> OK | G5: 驗證（搬移忠實度） | H5: skhynix/dist/20261025_SK海力士模型_v0.5.1.xlsx
A6: K1-A2027 | B6: HBM 市場（A） 2027：本庫 vs SK 海力士模型成品 | C6: =Mkt!E33 -> 154.0843 | D6: 154.0843 | E6: =IF(ISNUMBER(D6),C6-D6,"") -> 0 | F6: =IF(NOT(ISNUMBER(D6)),"WARN",IF(ABS(E6)<0.000000001,"OK","ERROR")) -> OK | G6: 驗證（搬移忠實度） | H6: skhynix/dist/20261025_SK海力士模型_v0.5.1.xlsx
A7: K1-A2028 | B7: HBM 市場（A） 2028：本庫 vs SK 海力士模型成品 | C7: =Mkt!F33 -> 245.76446 | D7: 245.76446 | E7: =IF(ISNUMBER(D7),C7-D7,"") -> 0 | F7: =IF(NOT(ISNUMBER(D7)),"WARN",IF(ABS(E7)<0.000000001,"OK","ERROR")) -> OK | G7: 驗證（搬移忠實度） | H7: skhynix/dist/20261025_SK海力士模型_v0.5.1.xlsx
A8: K1-A2029 | B8: HBM 市場（A） 2029：本庫 vs SK 海力士模型成品 | C8: =Mkt!G33 -> 315.19291 | D8: 315.19291 | E8: =IF(ISNUMBER(D8),C8-D8,"") -> 0 | F8: =IF(NOT(ISNUMBER(D8)),"WARN",IF(ABS(E8)<0.000000001,"OK","ERROR")) -> OK | G8: 驗證（搬移忠實度） | H8: skhynix/dist/20261025_SK海力士模型_v0.5.1.xlsx
A9: K1-B2025 | B9: HBM 市場（B） 2025：本庫 vs SK 海力士模型成品 | C9: =Mkt!C34 -> 35 | D9: 35 | E9: =IF(ISNUMBER(D9),C9-D9,"") -> 0 | F9: =IF(NOT(ISNUMBER(D9)),"WARN",IF(ABS(E9)<0.000000001,"OK","ERROR")) -> OK | G9: 驗證（搬移忠實度） | H9: skhynix/dist/20261025_SK海力士模型_v0.5.1.xlsx
A10: K1-B2026 | B10: HBM 市場（B） 2026：本庫 vs SK 海力士模型成品 | C10: =Mkt!D34 -> 55.227347 | D10: 55.227347 | E10: =IF(ISNUMBER(D10),C10-D10,"") -> 0 | F10: =IF(NOT(ISNUMBER(D10)),"WARN",IF(ABS(E10)<0.000000001,"OK","ERROR")) -> OK | G10: 驗證（搬移忠實度） | H10: skhynix/dist/20261025_SK海力士模型_v0.5.1.xlsx
A11: K1-B2027 | B11: HBM 市場（B） 2027：本庫 vs SK 海力士模型成品 | C11: =Mkt!E34 -> 154.0843 | D11: 154.0843 | E11: =IF(ISNUMBER(D11),C11-D11,"") -> 0 | F11: =IF(NOT(ISNUMBER(D11)),"WARN",IF(ABS(E11)<0.000000001,"OK","ERROR")) -> OK | G11: 驗證（搬移忠實度） | H11: skhynix/dist/20261025_SK海力士模型_v0.5.1.xlsx
A12: K1-B2028 | B12: HBM 市場（B） 2028：本庫 vs SK 海力士模型成品 | C12: =Mkt!F34 -> 162.07454 | D12: 162.07454 | E12: =IF(ISNUMBER(D12),C12-D12,"") -> 0 | F12: =IF(NOT(ISNUMBER(D12)),"WARN",IF(ABS(E12)<0.000000001,"OK","ERROR")) -> OK | G12: 驗證（搬移忠實度） | H12: skhynix/dist/20261025_SK海力士模型_v0.5.1.xlsx
A13: K1-B2029 | B13: HBM 市場（B） 2029：本庫 vs SK 海力士模型成品 | C13: =Mkt!G34 -> 223.86546 | D13: 223.86546 | E13: =IF(ISNUMBER(D13),C13-D13,"") -> 0 | F13: =IF(NOT(ISNUMBER(D13)),"WARN",IF(ABS(E13)<0.000000001,"OK","ERROR")) -> OK | G13: 驗證（搬移忠實度） | H13: skhynix/dist/20261025_SK海力士模型_v0.5.1.xlsx
A14: K1-C2025 | B14: HBM 市場（C） 2025：本庫 vs SK 海力士模型成品 | C14: =Mkt!C35 -> 35 | D14: 35 | E14: =IF(ISNUMBER(D14),C14-D14,"") -> 0 | F14: =IF(NOT(ISNUMBER(D14)),"WARN",IF(ABS(E14)<0.000000001,"OK","ERROR")) -> OK | G14: 驗證（搬移忠實度） | H14: skhynix/dist/20261025_SK海力士模型_v0.5.1.xlsx
A15: K1-C2026 | B15: HBM 市場（C） 2026：本庫 vs SK 海力士模型成品 | C15: =Mkt!D35 -> 55.227347 | D15: 55.227347 | E15: =IF(ISNUMBER(D15),C15-D15,"") -> 0 | F15: =IF(NOT(ISNUMBER(D15)),"WARN",IF(ABS(E15)<0.000000001,"OK","ERROR")) -> OK | G15: 驗證（搬移忠實度） | H15: skhynix/dist/20261025_SK海力士模型_v0.5.1.xlsx
A16: K1-C2027 | B16: HBM 市場（C） 2027：本庫 vs SK 海力士模型成品 | C16: =Mkt!E35 -> 154.0843 | D16: 154.0843 | E16: =IF(ISNUMBER(D16),C16-D16,"") -> 0 | F16: =IF(NOT(ISNUMBER(D16)),"WARN",IF(ABS(E16)<0.000000001,"OK","ERROR")) -> OK | G16: 驗證（搬移忠實度） | H16: skhynix/dist/20261025_SK海力士模型_v0.5.1.xlsx
A17: K1-C2028 | B17: HBM 市場（C） 2028：本庫 vs SK 海力士模型成品 | C17: =Mkt!F35 -> 97.244725 | D17: 97.244725 | E17: =IF(ISNUMBER(D17),C17-D17,"") -> 0 | F17: =IF(NOT(ISNUMBER(D17)),"WARN",IF(ABS(E17)<0.000000001,"OK","ERROR")) -> OK | G17: 驗證（搬移忠實度） | H17: skhynix/dist/20261025_SK海力士模型_v0.5.1.xlsx
A18: K1-C2029 | B18: HBM 市場（C） 2029：本庫 vs SK 海力士模型成品 | C18: =Mkt!G35 -> 132.73905 | D18: 132.73905 | E18: =IF(ISNUMBER(D18),C18-D18,"") -> 0 | F18: =IF(NOT(ISNUMBER(D18)),"WARN",IF(ABS(E18)<0.000000001,"OK","ERROR")) -> OK | G18: 驗證（搬移忠實度） | H18: skhynix/dist/20261025_SK海力士模型_v0.5.1.xlsx
A19: K2-A28 | B19: 情境 A 2028 顆數係數：A＝1；B、C 在區間內 | C19: =um28_A -> 1 | F19: =IF(ABS(C19-1)<0.000000001,"OK","ERROR") -> OK | G19: 驗證
A20: K2-A29 | B20: 情境 A 2029 顆數係數：A＝1；B、C 在區間內 | C20: =um29_A -> 1 | F20: =IF(ABS(C20-1)<0.000000001,"OK","ERROR") -> OK | G20: 驗證
A21: K2-B28 | B21: 情境 B 2028 顆數係數：A＝1；B、C 在區間內 | C21: =um28_B -> 0.8 | D21: =um28_B_lo&"–"&um28_B_hi -> 0.7–0.9 | F21: =IF(AND(C21>=um28_B_lo,C21<=um28_B_hi),"OK","ERROR") -> OK | G21: 驗證
A22: K2-B29 | B22: 情境 B 2029 顆數係數：A＝1；B、C 在區間內 | C22: =um29_B -> 0.85 | D22: =um29_B_lo&"–"&um29_B_hi -> 0.75–0.95 | F22: =IF(AND(C22>=um29_B_lo,C22<=um29_B_hi),"OK","ERROR") -> OK | G22: 驗證
A23: K2-C28 | B23: 情境 C 2028 顆數係數：A＝1；B、C 在區間內 | C23: =um28_C -> 0.6 | D23: =um28_C_lo&"–"&um28_C_hi -> 0.5–0.7 | F23: =IF(AND(C23>=um28_C_lo,C23<=um28_C_hi),"OK","ERROR") -> OK | G23: 驗證
A24: K2-C29 | B24: 情境 C 2029 顆數係數：A＝1；B、C 在區間內 | C24: =um29_C -> 0.6 | D24: =um29_C_lo&"–"&um29_C_hi -> 0.5–0.7 | F24: =IF(AND(C24>=um29_C_lo,C24<=um29_C_hi),"OK","ERROR") -> OK | G24: 驗證
A25: K2-ord28 | B25: 2028 顆數係數 A ≥ B ≥ C | F25: =IF(AND(um28_A>=um28_B,um28_B>=um28_C),"OK","ERROR") -> OK | G25: 驗證
A26: K2-ord29 | B26: 2029 顆數係數 A ≥ B ≥ C | F26: =IF(AND(um29_A>=um29_B,um29_B>=um29_C),"OK","ERROR") -> OK | G26: 驗證
A27: K3 | B27: 下游（chip_bridge 等）讀的 Tokenomics 快照與現行 TK 不同的格數 | C27: =TK_In!$M$60 -> 2 | F27: =IF(C27=0,"OK","WARN") -> WARN | G27: 治理（TK 一致） | H27: WARN＝下游仍用舊版 TK；本庫已用現行版；差異明細見 TK_In 頁 M 欄
A28: K4-2026 | B28: 2026 平台別顆數合計（Units）＝ HBM 市場頁顆數合計（Mkt） | C28: =Units!C12 -> 15.2 | D28: =Mkt!D15 -> 15.2 | E28: =C28-D28 -> 0 | F28: =IF(ABS(E28)<0.000000001,"OK","ERROR") -> OK | G28: 恆等式（結構）
A29: K4-2027 | B29: 2027 平台別顆數合計（Units）＝ HBM 市場頁顆數合計（Mkt） | C29: =Units!D12 -> 23.7 | D29: =Mkt!E15 -> 23.7 | E29: =C29-D29 -> 0 | F29: =IF(ABS(E29)<0.000000001,"OK","ERROR") -> OK | G29: 恆等式（結構）
A30: K4-2028 | B30: 2028 平台別顆數合計（Units）＝ HBM 市場頁顆數合計（Mkt） | C30: =Units!E12 -> 26.5 | D30: =Mkt!F15 -> 26.5 | E30: =C30-D30 -> 0 | F30: =IF(ABS(E30)<0.000000001,"OK","ERROR") -> OK | G30: 恆等式（結構）
A31: K5-bw | B31: 2029 成長率在區間內：NVIDIA Blackwell（B200／B300） | C31: =g29_bw -> -0.5 | D31: =g29_bw_lo&"–"&g29_bw_hi -> -0.7–-0.3 | F31: =IF(AND(C31>=g29_bw_lo,C31<=g29_bw_hi),"OK","ERROR") -> OK | G31: 驗證
A32: K5-rb | B32: 2029 成長率在區間內：NVIDIA Rubin | C32: =g29_rb -> 0.15 | D32: =g29_rb_lo&"–"&g29_rb_hi -> 0.05–0.25 | F32: =IF(AND(C32>=g29_rb_lo,C32<=g29_rb_hi),"OK","ERROR") -> OK | G32: 驗證
A33: K5-ru | B33: 2029 成長率在區間內：NVIDIA Rubin Ultra | C33: =g29_ru -> 0.15 | D33: =g29_ru_lo&"–"&g29_ru_hi -> 0.05–0.25 | F33: =IF(AND(C33>=g29_ru_lo,C33<=g29_ru_hi),"OK","ERROR") -> OK | G33: 驗證
A34: K5-hp | B34: 2029 成長率在區間內：NVIDIA Hopper（H200 等） | C34: =g29_hp -> 0 | D34: =g29_hp_lo&"–"&g29_hp_hi -> 0–0 | F34: =IF(AND(C34>=g29_hp_lo,C34<=g29_hp_hi),"OK","ERROR") -> OK | G34: 驗證
A35: K5-amd | B35: 2029 成長率在區間內：AMD Instinct | C35: =g29_amd -> 0.15 | D35: =g29_amd_lo&"–"&g29_amd_hi -> 0.05–0.25 | F35: =IF(AND(C35>=g29_amd_lo,C35<=g29_amd_hi),"OK","ERROR") -> OK | G35: 驗證
A36: K5-tpu | B36: 2029 成長率在區間內：Google TPU | C36: =g29_tpu -> 0.15 | D36: =g29_tpu_lo&"–"&g29_tpu_hi -> 0.05–0.25 | F36: =IF(AND(C36>=g29_tpu_lo,C36<=g29_tpu_hi),"OK","ERROR") -> OK | G36: 驗證
A37: K5-trn | B37: 2029 成長率在區間內：AWS Trainium | C37: =g29_trn -> 0.15 | D37: =g29_trn_lo&"–"&g29_trn_hi -> 0.05–0.25 | F37: =IF(AND(C37>=g29_trn_lo,C37<=g29_trn_hi),"OK","ERROR") -> OK | G37: 驗證
A38: K5-oth | B38: 2029 成長率在區間內：其他 ASIC（MTIA、Maia、Ascend 等） | C38: =g29_oth -> 0.15 | D38: =g29_oth_lo&"–"&g29_oth_hi -> 0.05–0.25 | F38: =IF(AND(C38>=g29_oth_lo,C38<=g29_oth_hi),"OK","ERROR") -> OK | G38: 驗證
A39: G1 | B39: In 頁輸入列缺標記 | C39: =SUMPRODUCT((In!A5:A190<>"")*(In!E5:E190<>"")*(In!G5:G190="")) -> 0 | F39: =IF(C39=0,"OK","ERROR") -> OK | G39: 治理
A40: G2 | B40: In 頁輸入列缺來源 | C40: =SUMPRODUCT((In!A5:A190<>"")*(In!E5:E190<>"")*(In!H5:H190="")) -> 0 | F40: =IF(C40=0,"OK","ERROR") -> OK | G40: 治理 | H40: v0.2 起應為 0
A41: G3 | B41: 標記含 Assumed／Analogy 但未給低／高區間的輸入列（Tokenomics 規則：一律給區間） | C41: =SUMPRODUCT((In!A5:A190<>"")*(In!E5:E190<>"")*(ISNUMBER(SEARCH("Assumed",In!G5:G190))+ISNUMBER(SEARCH("Analogy",In!G5:G190))>0)*((In!D5:D190="")+(In!F5:F190="")>0)) -> 0 | F41: =IF(C41=0,"OK","ERROR") -> OK | G41: 治理 | H41: v0.2 起應為 0（建置時 0 列）
...

Sheet Decisions
A1: Decisions — 決策登錄（Excel 擁有）。判斷類由 Andy 決定；Claude 依預設執行者標『預設、可撤回』
A3: 決策 ID | B3: 類別 | C3: 項目 | D3: 決議 | E3: 日期 | F3: Andy 原話／依據 | G3: 狀態
A4: S1 | B4: 範圍 | C4: 建立產業基準庫 | D4: 本專案建立自己的產業事實庫 Excel，規格比照 Tokenomics（Excel 唯一事實來源、builder 只產生公式頁、輸入由 Excel 擁有、Interface 具名範圍為下游唯一連結點、Checks、Decisions、證據登錄、版本固定快照）；與 TK 相關數據與 TK 一致；為各公司模型的基準事實來源 | E4: 2026-10-25 13:26；2026-10-27 07:59 | F4: 請開始規畫並建置AI半導體的次產業(唯一事實)excel(名稱另取較貼切的)，他的規格如同算力收支專案中的Tokenomics，與TK相關數據要與TK一致，只是負責領域不同，是相關個股模型的基準事實來源。 | G4: 生效
A5: S2 | B5: 命名 | C5: 名稱 | D5: Siliconomics（中文：AI 半導體產業基準庫），與 Tokenomics 對稱：一個管 token 的經濟，一個管矽的經濟。檔名 YYYYMMDD_Siliconomics_vX.Y.xlsx；下游名稱前綴 SIF_（Interface）、SGOV_（治理計數）；Tokenomics 鏡像為 TK_<名稱>_<世代>／SIF_TK_* | E5: 2026-10-27 | F5: 名稱另取較貼切的 | G5: 預設、可撤回
A6: S3 | B6: 工程 | C6: 位置 | D6: repo company-models 的 siliconomics/ 資料夾（model、builder、tools、data、docs），不另開 repo：下游 38 個建檔程式在同一 repo，可直接讀快照、CI 同一條；Tokenomics 是另一 repo 是因為服務跨專案 | E6: 2026-10-27 | F6: （工程類，Claude 決定） | G6: 生效
A7: S4 | B7: 範圍 | C7: 行業變數與公司變數的界線 | D7: 行業變數（本庫）＝跨公司共用或加總受限的量：加速器顆數與每顆內容、各市場規模與價格路徑、技術替代滲透率（CPO、銅轉光、液冷、混合鍵合）、同一市場各供應商份額表（合計 ≤ 100%）、供需缺口、情境 A／B／C 定義。公司變數（各公司模型）＝會計年度錨點、毛利率與費用、資本支出、股數、估值參數、公司特有的份額相對值 | E7: 2026-10-27 | F7: 依據 Andy 2026-10-25 13:13：個股 A／B／C 一律讀同字母行業情境（技術替代屬行業變數） | G7: 預設、可撤回
A8: S5 | B8: 工程 | C8: 下游改接方式 | D8: markets/memory/market.py 改為只讀 Siliconomics 快照（保留原 Python 名稱），38 個下游建檔程式不需修改；驗收＝全部 58 個 CI 目標重建後與 dist 逐格相同。其他市場層與公司模型依子產業分段改接 | E8: 2026-10-27 | F8: （工程類，Claude 決定） | G8: 生效
A9: S6 | B9: 範圍 | C9: 預測期間 | D9: v0.1 維持現有市場層的 2025–2029；2030–2032 的行業路徑不在 v0.1 自訂（目前各公司以收斂法自推），待算力收支 R4 三情境部署路徑（CY2026–2030）上線後由部署路徑推導並延伸到 2032 | E9: 2026-10-27 | F9: 依據 Andy 2026-10-25：預估延長到 FY2032；R4 回執：預計 10-31 後動工 | G9: 預設、可撤回
A10: S7 | B10: 治理 | C10: 衝突處理 | D10: 跨模型同一變數不同值者登錄於 Conflicts 頁；每項給建議單一值（判斷類標待 Andy），在該子產業併入本庫的版本生效；生效前各公司模型維持現值，不另做局部修補 | E10: 2026-10-27 | F10: （工程類流程；個別建議值屬判斷類） | G10: 生效
A11: S8 | B11: 範圍 | C11: v0.2 範圍 | D11: v0.2 只做：(1) In 頁 Assumed 列全部補區間、缺來源列補來源（區間為 Claude 預設，標 Assumed；C 情境季價區間 2027 ±5pt、2028–29 ±10pt）；(2) 2029 平台別顆數成長改為本庫單一來源（CF18）。ASIC 每顆規格、部署 GW、TPU 份額表（CF13、CF14、CF19、CF22）延到 v0.3（運算層一起做），網通與橋接表順延為 v0.4 | E11: 2026-10-27 | F11: （工程類分段；區間值屬判斷類預設） | G11: 預設、可撤回
A12: S9 | B12: 治理 | C12: G2、G3 升為 ERROR | D12: v0.2 起 In 頁缺來源、Assumed／Analogy 缺區間計入 SGOV_Errors（比照 Tokenomics：Analogy 與 Assumed 一律給區間） | E12: 2026-10-27 | F12: （工程類） | G12: 生效
A13: S10 | B13: 工程 | C13: 記憶體公司模型 In 頁不加新節 | D13: market.py 的 inputs() 只重播 M1–M3、ref_inputs() 只重播 M4；M5 起的新節（2029 平台別成長）不寫進記憶體公司模型，由需要的模型經 market.G29、G_U29 取用，避免既有儲存格位移 | E13: 2026-10-27 | F13: （工程類） | G13: 生效

Sheet DB_Evidence
A1: DB_Evidence — 證據登錄（所有比對過的新資訊，含不採納者）；先與本庫現值比對，再判定採納／部分採納／不採納／待查
A3: ID | B3: 日期 | C3: 主張（摘要） | D3: 來源 | E3: 標記 | F3: 對應鍵 | G3: 本庫當時值 | H3: 新資訊值 | I3: 判定 | J3: 處理版本 | K3: 立場 | L3: 備註
A4: （v0.1 尚無；跨模型衝突先登錄於 Conflicts 頁，判定後再轉入本頁）
