Workbook

Sheet README
A1: Siliconomics v0.10 — AI 半導體產業基準庫（20261031）
A2: 用途：AI 半導體各子產業的『唯一事實』——加速器顆數、HBM 與記憶體價格、網通內容、CoWoS、載板、伺服器組裝、電源散熱、設備等行業變數只有一個值；各公司模型只讀本庫 Interface 的 SIF_ 名稱。
A3: 與 Tokenomics 的分工：每 GW 硬體量、機架價、每 GW 資本支出、NonNV 比例、產業年度部署路徑（R4）權威在 Tokenomics／算力收支，本庫只在 TK_In 頁鏡像（綠字、不得修改）；晶片產業資訊（HBM 單價與容量、每顆內容、網通內容、份額、出貨顆數、ASIC 規格、晶圓與設備）權威在本庫（《情境卡產生規則》第 13 條）。
A4: v0.1 範圍：(1) Tokenomics v21.7 鏡像（22 個名稱）與下游舊快照差異；(2) 加速器顆數層、記憶體價格路徑、HBM 市場（由 markets/memory/market.py 逐字搬入，數值不變）；(3) 跨模型衝突登錄；(4) Interface、Checks、Decisions。網通、CoWoS、載板、組裝電源散熱、設備依規劃書分段併入。
A5: v0.2：In 頁 Assumed 列全部補上區間、缺來源列補來源；新增 M5 節 2029 平台別顆數成長（單一來源，取代台積電、網通模型的寫死值與 NAND 模型的合計年增）與 Units 頁；Interface 新增 SIF_UnitsPlat_*、SIF_UnitsGrowth29。
A6: v0.3：新增 M6 節（加速器每顆售價、ASIC 核心價、HBM 代購比例；原在 nvidia、avgo 模型）與 M7 節（ASIC 設計服務份額；原在 avgo、mrvl、mediatek、alchip 模型）、ShareTbl 頁（同一平台份額加總 ≤ 100%）；In 頁新增 J 欄第二來源。
A7: v0.10：NAND 季價 2026Q3 改用公司實現平均售價 +25%（原合約價 +15%；Kioxia、SK 海力士實績 mid-20%），2026Q4 改為兩季累計不變的餘額 +8.1%（原 +17.5%）；2027 起價格水準不變。決策 S30。
A8: v0.9：CY2026 SoC 測試機市場 ts_mk_soc26 由 11.0 改為 11.5（Advantest 2026-10-28 稱約 115 億美元；Advantest＋泰瑞達 CY2026 SoC 營收合計約 113 億美元已高於舊值）；每加權顆測試支出與 CY2027 起 SoC 市場隨之上升。決策 S29。
A9: v0.8.4：來源複核後修正標記與來源文字：DRAM／NAND 情境季價路徑 2027–28 改標 Derived、2029 改標 Assumed（區間＝情境 A、B）；Advantest 測試機市場來源改為 2026-07-29 原文；輸入值不變。
A10: v0.8.3：衝突登錄清理（CF02、CF05–08、CF16 結案；CF01 移到南電分部重建）；無新增輸入。
A11: v0.8.2：新增 M26（共用匯率：新台幣 32.0、人民幣 6.72、韓元 1,420；台、陸、韓 21 個模型改讀；日圓為公司財測前提，不共用）。
A12: v0.8.1：新增 M25（AI 伺服器組裝：廣達、鴻海、緯創本體、緯穎 FY2026 有效份額快照與 2027–29 份額相對值、緯穎 ASIC 比重；原在 quanta、foxconn、wistron、wiwynn）、ShareTbl 的組裝份額表（含緯穎 ASIC 傾斜係數）、Checks K6-asm、Interface SIF_AsmShareSum、SIF_AsmWyTilt、SIF_AsmShare_wy；CF23 登錄（緯創模型的緯穎份額路徑與緯穎模型不同）。
... A28: 版本命名：YYYYMMDD_Siliconomics_vX.Y.xlsx；model/CURRENT 記錄現行檔名。只改證據或標記為修補版；輸入值或公式改變為次版；Interface 名稱刪除或定義改變為主版（v1.0 前只新增名稱以次版處理）。

Sheet Scen
A1: Scen — 行業情境定義（A＝順利、B＝平平、C＝不如預期）。各公司模型的 A／B／C 一律讀同字母行業情境（Andy 2026-10-25 13:13）
A3: 情境 | B3: 名稱 | C3: 定義（顆數與部署） | D3: 記憶體價格路徑 | E3: 2028 顆數 ÷ 基準 | F3: 2029 顆數 ÷ 基準 | G3: 2030–2032
A4: A | B4: 順利 | C4: 基準顆數（市場層 2026–2028 預測）；部署順利、新技術導入快 | D4: 2027–28 高檔持平、2029 緩降（BofA、TrendForce 型） | E4: =um28_A -> 1 | F4: =um29_A -> 1 | G4: 未定：待算力收支 R4 產業部署路徑（預計 10-31 後）；各公司模型目前以收斂法自推
A5: B | B5: 平平 | C5: AI 資本支出消化：2028 顆數約為基準 0.8、2029 約 0.85 | D5: 2027 Q2 見頂、2028 回落約一半、2029 溫和回升（Citi、Bernstein 型） | E5: =um28_B -> 0.8 | F5: =um29_B -> 0.85 | G5: 未定：待算力收支 R4 產業部署路徑（預計 10-31 後）；各公司模型目前以收斂法自推
A6: C | B6: 不如預期 | C6: 明顯下修：2028、2029 顆數約為基準 0.6 | D6: 2028 回到 2025 年價格水準、2029 自谷底回升（完整循環） | E6: =um28_C -> 0.6 | F6: =um29_C -> 0.6 | G6: 未定：待算力收支 R4 產業部署路徑（預計 10-31 後）；各公司模型目前以收斂法自推
A9: 說明
A10: 情境係數只定義 2028–29（Assumed，無外部預測可校準；B、C 區間 ±0.1，見 In 頁 M2b）。R4 上線後，2026–2030 的部署 GW 三情境改讀算力收支（權威在算力收支，第 13 條），本頁的係數改為由部署路徑推導。

Sheet In
A1: In — 產業輸入（藍字＝輸入，由本活頁簿擁有；要改值直接改本頁，builder 重建時讀回）。每列具名範圍＝鍵（指向 E 欄），另有 _lo／_hi（D、F 欄）
A2: 標記：Verified／Interested-party（寫明是誰）／Analogy／Assumed（給低／高區間）／Derived（寫明換算）。v0.1 內容由 markets/memory/market.py 逐字搬入（數值、標記、來源文字不變）
A4: 鍵 | B4: 項目 | C4: 單位 | D4: 低 | E4: 基準 | F4: 高 | G4: 標記 | H4: 來源／說明 | I4: Interface 名稱 | J4: 第二來源／說明
A5: M1. 記憶體價格路徑（季增，共用市場層 markets/memory）
A6: cq_1 | B6: 一般 DRAM 合約價季增 2025Q2 | C6: % | E6: -0.025 | G6: Interested-party | H6: TrendForce 合約價：2Q25 0~−5%、3Q25 +10~15%、4Q25 實際 +45~50%、1Q26 實際約 +93~98%、2Q26 +58~63%、3Q26 +13~18%（MS 實際約 +15%）、4Q26 +10~15% | I6: SIF_cq_1
A7: cq_2 | B7: 一般 DRAM 合約價季增 2025Q3 | C7: % | E7: 0.125 | G7: Interested-party | H7: 同上 | I7: SIF_cq_2
A8: cq_3 | B8: 一般 DRAM 合約價季增 2025Q4 | C8: % | E8: 0.475 | G8: Interested-party | H8: 同上 | I8: SIF_cq_3
A9: cq_4 | B9: 一般 DRAM 合約價季增 2026Q1 | C9: % | E9: 0.95 | G9: Interested-party | H9: 同上 | I9: SIF_cq_4
A10: cq_5 | B10: 一般 DRAM 合約價季增 2026Q2 | C10: % | E10: 0.605 | G10: Interested-party | H10: 同上 | I10: SIF_cq_5
A11: cq_6 | B11: 一般 DRAM 合約價季增 2026Q3 | C11: % | E11: 0.155 | G11: Interested-party | H11: 同上 | I11: SIF_cq_6
A12: cq_7 | B12: 一般 DRAM 合約價季增 2026Q4 | C12: % | E12: 0.125 | G12: Interested-party | H12: 同上 | I12: SIF_cq_7
A13: cqA_8 | B13: 一般 DRAM 合約價季增 2027Q1（A） | C13: % | E13: 0.03 | G13: Derived | H13: 本庫情境路徑，依據：BofA：2027 持平略降、2027 均價仍高於 2026；2028 溫和修正（年均約 −10%）；2029 Assumed 緩降（2026-10-28 來源複核：來源無逐季數字，逐季值為本庫拆分） | I13: SIF_cqA_8
A14: cqA_9 | B14: 一般 DRAM 合約價季增 2027Q2（A） | C14: % | E14: 0 | G14: Derived | H14: 同上 | I14: SIF_cqA_9
A15: cqA_10 | B15: 一般 DRAM 合約價季增 2027Q3（A） | C15: % | E15: -0.02 | G15: Derived | H15: 同上 | I15: SIF_cqA_10
A16: cqA_11 | B16: 一般 DRAM 合約價季增 2027Q4（A） | C16: % | E16: -0.03 | G16: Derived | H16: 同上 | I16: SIF_cqA_11
A17: cqA_12 | B17: 一般 DRAM 合約價季增 2028Q1（A） | C17: % | E17: -0.03 | G17: Derived | H17: 同上 | I17: SIF_cqA_12
... A20: cqA_15 | B20: 一般 DRAM 合約價季增 2028Q4（A） | C20: % | E20: -0.02 | G20: Derived | H20: 同上 | I20: SIF_cqA_15
A21: cqA_16 | B21: 一般 DRAM 合約價季增 2029Q1（A） | C21: % | D21: -0.03 | E21: -0.03 | F21: 0.05 | G21: Assumed | H21: 2029 為本庫外推：標示來源只涵蓋到 2028（2026-10-28 來源複核）；區間＝情境 A、B 同季值 | I21: SIF_cqA_16
A22: cqA_17 | B22: 一般 DRAM 合約價季增 2029Q2（A） | C22: % | D22: -0.03 | E22: -0.03 | F22: 0.05 | G22: Assumed | H22: 同上 | I22: SIF_cqA_17
A23: cqA_18 | B23: 一般 DRAM 合約價季增 2029Q3（A） | C23: % | D23: -0.02 | E23: -0.02 | F23: 0.03 | G23: Assumed | H23: 同上 | I23: SIF_cqA_18
A24: cqA_19 | B24: 一般 DRAM 合約價季增 2029Q4（A） | C24: % | D24: -0.02 | E24: -0.02 | F24: 0.03 | G24: Assumed | H24: 同上 | I24: SIF_cqA_19
A25: cqB_8 | B25: 一般 DRAM 合約價季增 2027Q1（B） | C25: % | E25: 0.05 | G25: Derived | H25: 本庫情境路徑，依據：Citi：2027 Q2 見頂；Bernstein：2028 DRAM $/GB −52.9%（本路徑 2028 年均約 −47%）；2029 Assumed 溫和回升（2026-10-28 來源複核：來源無逐季數字，逐季值為本庫拆分） | I25: SIF_cqB_8
A26: cqB_9 | B26: 一般 DRAM 合約價季增 2027Q2（B） | C26: % | E26: 0.02 | G26: Derived | H26: 同上 | I26: SIF_cqB_9
A27: cqB_10 | B27: 一般 DRAM 合約價季增 2027Q3（B） | C27: % | E27: -0.08 | G27: Derived | H27: 同上 | I27: SIF_cqB_10
A28: cqB_11 | B28: 一般 DRAM 合約價季增 2027Q4（B） | C28: % | E28: -0.15 | G28: Derived | H28: 同上 | I28: SIF_cqB_11
A29: cqB_12 | B29: 一般 DRAM 合約價季增 2028Q1（B） | C29: % | E29: -0.25 | G29: Derived | H29: 同上 | I29: SIF_cqB_12
A30: cqB_13 | B30: 一般 DRAM 合約價季增 2028Q2（B） | C30: % | E30: -0.15 | G30: Derived | H30: 同上 | I30: SIF_cqB_13
A31: cqB_14 | B31: 一般 DRAM 合約價季增 2028Q3（B） | C31: % | E31: -0.1 | G31: Derived | H31: 同上 | I31: SIF_cqB_14
A32: cqB_15 | B32: 一般 DRAM 合約價季增 2028Q4（B） | C32: % | E32: -0.05 | G32: Derived | H32: 同上 | I32: SIF_cqB_15
A33: cqB_16 | B33: 一般 DRAM 合約價季增 2029Q1（B） | C33: % | D33: -0.03 | E33: 0.05 | F33: 0.05 | G33: Assumed | H33: 2029 為本庫外推：標示來源只涵蓋到 2028（2026-10-28 來源複核）；區間＝情境 A、B 同季值 | I33: SIF_cqB_16
A34: cqB_17 | B34: 一般 DRAM 合約價季增 2029Q2（B） | C34: % | D34: -0.03 | E34: 0.05 | F34: 0.05 | G34: Assumed | H34: 同上 | I34: SIF_cqB_17
A35: cqB_18 | B35: 一般 DRAM 合約價季增 2029Q3（B） | C35: % | D35: -0.02 | E35: 0.03 | F35: 0.03 | G35: Assumed | H35: 同上 | I35: SIF_cqB_18
A36: cqB_19 | B36: 一般 DRAM 合約價季增 2029Q4（B） | C36: % | D36: -0.02 | E36: 0.03 | F36: 0.03 | G36: Assumed | H36: 同上 | I36: SIF_cqB_19
A37: cqC_8 | B37: 一般 DRAM 合約價季增 2027Q1（C） | C37: % | D37: 0 | E37: 0.05 | F37: 0.1 | G37: Assumed | H37: Assumed：2028 年底回到約 2025Q4 水準（自高點約 −79%），比照 2019、2023 年谷底；2029 自谷底回升。區間（v0.2）：2027 各季 ±5pt、2028–29 各季 ±10pt，表示路徑形狀的不確定（Assumed），不是另一個情境 | I37: SIF_cqC_8
A38: cqC_9 | B38: 一般 DRAM 合約價季增 2027Q2（C） | C38: % | D38: -0.03 | E38: 0.02 | F38: 0.07 | G38: Assumed | H38: 同上 | I38: SIF_cqC_9
A39: cqC_10 | B39: 一般 DRAM 合約價季增 2027Q3（C） | C39: % | D39: -0.13 | E39: -0.08 | F39: -0.03 | G39: Assumed | H39: 同上 | I39: SIF_cqC_10
A40: cqC_11 | B40: 一般 DRAM 合約價季增 2027Q4（C） | C40: % | D40: -0.2 | E40: -0.15 | F40: -0.1 | G40: Assumed | H40: 同上 | I40: SIF_cqC_11
A41: cqC_12 | B41: 一般 DRAM 合約價季增 2028Q1（C） | C41: % | D41: -0.45 | E41: -0.35 | F41: -0.25 | G41: Assumed | H41: 同上 | I41: SIF_cqC_12
A42: cqC_13 | B42: 一般 DRAM 合約價季增 2028Q2（C） | C42: % | D42: -0.4 | E42: -0.3 | F42: -0.2 | G42: Assumed | H42: 同上 | I42: SIF_cqC_13
A43: cqC_14 | B43: 一般 DRAM 合約價季增 2028Q3（C） | C43: % | D43: -0.35 | E43: -0.25 | F43: -0.15 | G43: Assumed | H43: 同上 | I43: SIF_cqC_14
...

Sheet Units
A1: Units — 加速器平台別顆數（百萬顆；情境 A 基準）。2026–2028＝In 頁 M2；2029＝2028 ×（1＋In 頁 M5 平台別成長率）。情境 B、C 再乘 Scen 頁係數（2028–29）
A3: 平台 | B3: 鍵 | C3: 2026 | D3: 2027 | E3: 2028 | F3: 2029 | G3: 2029 成長
A4: NVIDIA Blackwell（B200／B300） | B4: bw | C4: =u_bw_26 -> 5.4 | D4: =u_bw_27 -> 2.4 | E4: =u_bw_28 -> 0.5 | F4: =E4*(1+g29_bw) -> 0.25 | G4: =g29_bw -> -0.5
A5: NVIDIA Rubin | B5: rb | C5: =u_rb_26 -> 1.7 | D5: =u_rb_27 -> 7 | E5: =u_rb_28 -> 7 | F5: =E5*(1+g29_rb) -> 8.05 | G5: =g29_rb -> 0.15
A6: NVIDIA Rubin Ultra | B6: ru | C6: =u_ru_26 -> 0 | D6: =u_ru_27 -> 0.3 | E6: =u_ru_28 -> 2 | F6: =E6*(1+g29_ru) -> 2.3 | G6: =g29_ru -> 0.15
A7: NVIDIA Hopper（H200 等） | B7: hp | C7: =u_hp_26 -> 0.5 | D7: =u_hp_27 -> 0 | E7: =u_hp_28 -> 0 | F7: =E7*(1+g29_hp) -> 0 | G7: =g29_hp -> 0
A8: AMD Instinct | B8: amd | C8: =u_amd_26 -> 0.75 | D8: =u_amd_27 -> 1.5 | E8: =u_amd_28 -> 2 | F8: =E8*(1+g29_amd) -> 2.3 | G8: =g29_amd -> 0.15
A9: Google TPU | B9: tpu | C9: =u_tpu_26 -> 3.85 | D9: =u_tpu_27 -> 5.5 | E9: =u_tpu_28 -> 7 | F9: =E9*(1+g29_tpu) -> 8.05 | G9: =g29_tpu -> 0.15
A10: AWS Trainium | B10: trn | C10: =u_trn_26 -> 2 | D10: =u_trn_27 -> 2.5 | E10: =u_trn_28 -> 3 | F10: =E10*(1+g29_trn) -> 3.45 | G10: =g29_trn -> 0.15
A11: 其他 ASIC（MTIA、Maia、Ascend 等） | B11: oth | C11: =u_oth_26 -> 1 | D11: =u_oth_27 -> 4.5 | E11: =u_oth_28 -> 5 | F11: =E11*(1+g29_oth) -> 5.75 | G11: =g29_oth -> 0.15
A12: 合計（基準＝情境 A，未乘係數） | C12: =SUM(C4:C11) -> 15.2 | D12: =SUM(D4:D11) -> 23.7 | E12: =SUM(E4:E11) -> 26.5 | F12: =SUM(F4:F11) -> 30.15 | G12: =F12/E12-1 -> 0.13773585
A13: 合計（情境 A） | C13: =C12 -> 15.2 | D13: =D12 -> 23.7 | E13: =E12*um28_A -> 26.5 | F13: =F12*um29_A -> 30.15
A14: 合計（情境 B） | C14: =C12 -> 15.2 | D14: =D12 -> 23.7 | E14: =E12*um28_B -> 21.2 | F14: =F12*um29_B -> 25.6275
A15: 合計（情境 C） | C15: =C12 -> 15.2 | D15: =D12 -> 23.7 | E15: =E12*um28_C -> 15.9 | F15: =F12*um29_C -> 18.09

Sheet ShareTbl
A1: ShareTbl — ASIC 設計服務顆數份額表（基準值；In 頁 M7）。同一平台各設計夥伴份額加總須 ≤ 100%，餘額＝客戶自行設計或未建模的夥伴。Trainium 的世芯份額隨情境（公司特有：A 最有利、C 最不利），三情境各列一次
A3: 平台 | B3: 夥伴 | C3: 鍵（2026／2027／2028） | D3: 2026 | E3: 2027 | F3: 2028 | G3: 說明
A4: Google TPU | B4: Broadcom | C4: sh_tpu_26／sh_tpu_27／sh_tpu_28 | D4: =sh_tpu_26 -> 0.9 | E4: =sh_tpu_27 -> 0.8 | F4: =sh_tpu_28 -> 0.75
A5: Google TPU | B5: Marvell | C5: msh_tpu_26／msh_tpu_27／msh_tpu_28 | D5: =msh_tpu_26 -> 0 | E5: =msh_tpu_27 -> 0 | F5: =msh_tpu_28 -> 0.05
A6: Google TPU | B6: 聯發科 | C6: mtk_tpu_26／mtk_tpu_27／mtk_tpu_28 | D6: =mtk_tpu_26 -> 0.05 | E6: =mtk_tpu_27 -> 0.15 | F6: =mtk_tpu_28 -> 0.18
A7: Google TPU | B7: 合計 | D7: =SUM(D4:D6) -> 0.95 | E7: =SUM(E4:E6) -> 0.95 | F7: =SUM(F4:F6) -> 0.98
A8: Google TPU | B8: 餘額（客戶自行設計或未建模） | D8: =1-D7 -> 0.05 | E8: =1-E7 -> 0.05 | F8: =1-F7 -> 0.02
A10: 其他 ASIC（MTIA、Maia、OpenAI 等） | B10: Broadcom | C10: sh_oth_26／sh_oth_27／sh_oth_28 | D10: =sh_oth_26 -> 0.35 | E10: =sh_oth_27 -> 0.55 | F10: =sh_oth_28 -> 0.55
A11: 其他 ASIC（MTIA、Maia、OpenAI 等） | B11: Marvell | C11: msh_oth_26／msh_oth_27／msh_oth_28 | D11: =msh_oth_26 -> 0.05 | E11: =msh_oth_27 -> 0.06 | F11: =msh_oth_28 -> 0.15
A12: 其他 ASIC（MTIA、Maia、OpenAI 等） | B12: 聯發科 | C12: mtk_oth_26／mtk_oth_27／mtk_oth_28 | D12: =mtk_oth_26 -> 0 | E12: =mtk_oth_27 -> 0 | F12: =mtk_oth_28 -> 0
A13: 其他 ASIC（MTIA、Maia、OpenAI 等） | B13: 合計 | D13: =SUM(D10:D12) -> 0.4 | E13: =SUM(E10:E12) -> 0.61 | F13: =SUM(F10:F12) -> 0.7
A14: 其他 ASIC（MTIA、Maia、OpenAI 等） | B14: 餘額（客戶自行設計或未建模） | D14: =1-D13 -> 0.6 | E14: =1-E13 -> 0.39 | F14: =1-F13 -> 0.3
A16: AWS Trainium（情境 A） | B16: Marvell | C16: msh_trn_26／msh_trn_27／msh_trn_28 | D16: =msh_trn_26 -> 0.1 | E16: =msh_trn_27 -> 0.1 | F16: =msh_trn_28 -> 0.08
A17: AWS Trainium（情境 A） | B17: 世芯 | C17: al_trn_26／al27_A／al28_A | D17: =al_trn_26 -> 0.3 | E17: =al27_A -> 0.55 | F17: =al28_A -> 0.55
A18: AWS Trainium（情境 A） | B18: 合計 | D18: =SUM(D16:D17) -> 0.4 | E18: =SUM(E16:E17) -> 0.65 | F18: =SUM(F16:F17) -> 0.63
A19: AWS Trainium（情境 A） | B19: 餘額（客戶自行設計或未建模） | D19: =1-D18 -> 0.6 | E19: =1-E18 -> 0.35 | F19: =1-F18 -> 0.37
A21: AWS Trainium（情境 B） | B21: Marvell | C21: msh_trn_26／msh_trn_27／msh_trn_28 | D21: =msh_trn_26 -> 0.1 | E21: =msh_trn_27 -> 0.1 | F21: =msh_trn_28 -> 0.08
A22: AWS Trainium（情境 B） | B22: 世芯 | C22: al_trn_26／al27_B／al28_B | D22: =al_trn_26 -> 0.3 | E22: =al27_B -> 0.5 | F22: =al28_B -> 0.45
A23: AWS Trainium（情境 B） | B23: 合計 | D23: =SUM(D21:D22) -> 0.4 | E23: =SUM(E21:E22) -> 0.6 | F23: =SUM(F21:F22) -> 0.53
A24: AWS Trainium（情境 B） | B24: 餘額（客戶自行設計或未建模） | D24: =1-D23 -> 0.6 | E24: =1-E23 -> 0.4 | F24: =1-F23 -> 0.47
A26: AWS Trainium（情境 C） | B26: Marvell | C26: msh_trn_26／msh_trn_27／msh_trn_28 | D26: =msh_trn_26 -> 0.1 | E26: =msh_trn_27 -> 0.1 | F26: =msh_trn_28 -> 0.08
A27: AWS Trainium（情境 C） | B27: 世芯 | C27: al_trn_26／al27_C／al28_C | D27: =al_trn_26 -> 0.3 | E27: =al27_C -> 0.4 | F27: =al28_C -> 0.35
A28: AWS Trainium（情境 C） | B28: 合計 | D28: =SUM(D26:D27) -> 0.4 | E28: =SUM(E26:E27) -> 0.5 | F28: =SUM(F26:F27) -> 0.43
A29: AWS Trainium（情境 C） | B29: 餘額（客戶自行設計或未建模） | D29: =1-D28 -> 0.6 | E29: =1-E28 -> 0.5 | F29: =1-F28 -> 0.57
A31: CPO 光學金額份額（欄 D–F＝2027／2028／2029；Fabrinet 為代工，與模組廠重疊，不計入合計）
A32: CPO 光學 | B32: Lumentum | C32: cposh_lite_27／28／29 | D32: =cposh_lite_27 -> 0.25 | E32: =cposh_lite_28 -> 0.25 | F32: =cposh_lite_29 -> 0.2
A33: CPO 光學 | B33: Coherent | C33: cposh_cohr_27／28／29 | D33: =cposh_cohr_27 -> 0.1 | E33: =cposh_cohr_28 -> 0.15 | F33: =cposh_cohr_29 -> 0.2
A34: CPO 光學 | B34: 中際旭創 | C34: cposh_innolight_27／28／29 | D34: =cposh_innolight_27 -> 0.1 | E34: =cposh_innolight_28 -> 0.15 | F34: =cposh_innolight_29 -> 0.2
A35: CPO 光學 | B35: 新易盛 | C35: cposh_eoptolink_27／28／29 | D35: =cposh_eoptolink_27 -> 0.05 | E35: =cposh_eoptolink_28 -> 0.1 | F35: =cposh_eoptolink_29 -> 0.15
A36: CPO 光學 | B36: 合計（模組與雷射廠） | D36: =SUM(D32:D35) -> 0.5 | E36: =SUM(E32:E35) -> 0.65 | F36: =SUM(F32:F35) -> 0.75
A37: CPO 光學 | B37: 餘額（NVIDIA、Broadcom 交換器端自製光引擎與其他，未建模） | D37: =1-D36 -> 0.5 | E37: =1-E36 -> 0.35 | F37: =1-F36 -> 0.25
A38: CPO 光學 | B38: Fabrinet（代工；參考，不計入） | C38: cposh_fabrinet_27／28／29 | D38: =cposh_fabrinet_27 -> 0.05 | E38: =cposh_fabrinet_28 -> 0.1 | F38: =cposh_fabrinet_29 -> 0.15
A40: 加速器 ABF 載板份額（欄 D–G＝2026／2027／2028／2029；NVIDIA 為顆數份額，非 NVIDIA 為金額份額）
A41: NVIDIA 加速器 | B41: Ibiden | C41: abf_ibsh26 × abf_ibrel | D41: =abf_ibsh26*1 -> 0.7 | E41: =abf_ibsh26*abf_ibrel_27 -> 0.665 | F41: =abf_ibsh26*abf_ibrel_28 -> 0.616 | G41: =abf_ibsh26*abf_ibrel_29 -> 0.595
A42: NVIDIA 加速器 | B42: 欣興 | C42: abf_un_nv_26／27／28／29 | D42: =abf_un_nv_26 -> 0.25 | E42: =abf_un_nv_27 -> 0.27 | F42: =abf_un_nv_28 -> 0.29 | G42: =abf_un_nv_29 -> 0.3
A43: NVIDIA 加速器 | B43: 南電 | C43: abf_np_nv_26／27／28／29 | D43: =abf_np_nv_26 -> 0.02 | E43: =abf_np_nv_27 -> 0.03 | F43: =abf_np_nv_28 -> 0.04 | G43: =abf_np_nv_29 -> 0.04
A44: NVIDIA 加速器 | B44: 景碩 | C44: abf_ks_nv_26／27／28／29 | D44: =abf_ks_nv_26 -> 0.02 | E44: =abf_ks_nv_27 -> 0.03 | F44: =abf_ks_nv_28 -> 0.05 | G44: =abf_ks_nv_29 -> 0.06
A45: NVIDIA 加速器 | B45: 合計 | D45: =SUM(D41:D44) -> 0.99 | E45: =SUM(E41:E44) -> 0.995 | F45: =SUM(F41:F44) -> 0.996 | G45: =SUM(G41:G44) -> 0.995
A46: NVIDIA 加速器 | B46: 餘額（三星電機、AT&S、Shinko 等，未建模） | D46: =1-D45 -> 0.01 | E46: =1-E45 -> 0.005 | F46: =1-F45 -> 0.004 | G46: =1-G45 -> 0.005
A48: 非 NVIDIA 加速器 | B48: Ibiden | C48: abf_wot_ib × abf_ibrel ÷ abf_vot | D48: =abf_wot_ib*1/abf_vot -> 0.5 | E48: =abf_wot_ib*abf_ibrel_27/abf_vot -> 0.475 | F48: =abf_wot_ib*abf_ibrel_28/abf_vot -> 0.44 | G48: =abf_wot_ib*abf_ibrel_29/abf_vot -> 0.425
...

Sheet Deploy
A1: Deploy — AI IT 資本支出＝Σ 平台顆數（Units 頁）× 每顆 IT capex（In 頁 M9）× 情境顆數係數；部署 GW＝AI IT 資本支出 ÷ 每 GW IT 資本支出（Tokenomics IF_CapexIT；2026 依 vr26 混合 GB300 與 VR200，2027 起 VR200）。公式與 markets/network、各公司模型相同；R4 產業部署路徑上線後改讀算力收支
A3: 項目 | B3: 情境 | C3: 2026 | D3: 2027 | E3: 2028 | F3: 2029
A4: AI IT 資本支出（基準，未乘係數） | C4: =Units!C4*it_GB+Units!C5*it_VR+Units!C6*it_RU+Units!C7*it_HP+Units!C8*it_AMD8+Units!C9*it_TPU+Units!C10*it_TRN+Units!C11*it_ASIC -> 781.87292 | D4: =Units!D4*it_GB+Units!D5*it_VR+Units!D6*it_RU+Units!D7*it_HP+Units!D8*it_AMDR+Units!D9*it_TPU+Units!D10*it_TRN+Units!D11*it_ASIC -> 1565.35 | E4: =Units!E4*it_GB+Units!E5*it_VR+Units!E6*it_RU+Units!E7*it_HP+Units!E8*it_AMDR+Units!E9*it_TPU+Units!E10*it_TRN+Units!E11*it_ASIC -> 1984.2639 | F4: =Units!F4*it_GB+Units!F5*it_VR+Units!F6*it_RU+Units!F7*it_HP+Units!F8*it_AMDR+Units!F9*it_TPU+Units!F10*it_TRN+Units!F11*it_ASIC -> 2260.3903
A5: AI IT 資本支出 × 情境顆數係數 | B5: A | C5: =C4 -> 781.87292 | D5: =D4 -> 1565.35 | E5: =E4*um28_A -> 1984.2639 | F5: =F4*um29_A -> 2260.3903
A6: AI IT 資本支出 × 情境顆數係數 | B6: B | C6: =C4 -> 781.87292 | D6: =D4 -> 1565.35 | E6: =E4*um28_B -> 1587.4111 | F6: =F4*um29_B -> 1921.3317
A7: AI IT 資本支出 × 情境顆數係數 | B7: C | C7: =C4 -> 781.87292 | D7: =D4 -> 1565.35 | E7: =E4*um28_C -> 1190.5583 | F7: =F4*um29_C -> 1356.2342
A8: 每 GW IT 資本支出（$B／GW） | C8: =TK_CapexIT_GB300*(1-vr26)+TK_CapexIT_VR200*vr26 -> 33.414032 | D8: =TK_CapexIT_VR200 -> 37.586352 | E8: =TK_CapexIT_VR200 -> 37.586352 | F8: =TK_CapexIT_VR200 -> 37.586352
A9: 部署 GW（IT 電力） | B9: A | C9: =C5/C8 -> 23.399538 | D9: =D5/D8 -> 41.646766 | E9: =E5/E8 -> 52.792138 | F9: =F5/F8 -> 60.138592
A10: 部署 GW（IT 電力） | B10: B | C10: =C6/C8 -> 23.399538 | D10: =D6/D8 -> 41.646766 | E10: =E6/E8 -> 42.233711 | F10: =F6/F8 -> 51.117803
A11: 部署 GW（IT 電力） | B11: C | C11: =C7/C8 -> 23.399538 | D11: =D7/D8 -> 41.646766 | E11: =E7/E8 -> 31.675283 | F11: =F7/F8 -> 36.083155

Sheet ABF
A1: ABF — 載板供需表。需求（面積 × 層數口徑，2026＝1）＝加速器（顆數 ×（NVIDIA 1、非 NVIDIA v_ot）×（1＋g_asp）^t）、其他 AI（AI IT 資本支出成長 ^ 彈性）、非 AI（年增 g_nai），以 2026 金額權重加總；供給＝各載板廠產能指數 × 2026 營收權重，再與味之素 ABF 膜可出貨量上限取小；缺口＝（1＋2026 外部缺口）× 需求 ÷ 有效供給 − 1。價格溢價不計入（只量）
A3: 項目 | B3: 情境 | C3: 2026 | D3: 2027 | E3: 2028 | F3: 2029 | G3: 說明
A4: A. 需求
A5: 2026 ABF 載板產值（US$B） | C5: =abfm_25*(1+abfm_g26) -> 10.1904 | G5: TPCA 2025 × 2026 年增
A6: 2026 權重：加速器 | C6: =abf_ai26*abf_accsh26 -> 0.288
A7: 2026 權重：其他 AI（交換器、CPU、網通） | C7: =abf_ai26*(1-abf_accsh26) -> 0.162
A8: 2026 權重：非 AI | C8: =1-abf_ai26 -> 0.55
A9: 加速器有效顆數（NVIDIA ＋ 非 NVIDIA × v_ot；百萬顆） | B9: A | C9: =(Units!C4+Units!C5+Units!C6+Units!C7+abf_vot*(Units!C8+Units!C9+Units!C10+Units!C11)) -> 13.68 | D9: =(Units!D4+Units!D5+Units!D6+Units!D7+abf_vot*(Units!D8+Units!D9+Units!D10+Units!D11)) -> 20.9 | E9: =(Units!E4+Units!E5+Units!E6+Units!E7+abf_vot*(Units!E8+Units!E9+Units!E10+Units!E11))*um28_A -> 23.1 | F9: =(Units!F4+Units!F5+Units!F6+Units!F7+abf_vot*(Units!F8+Units!F9+Units!F10+Units!F11))*um29_A -> 26.24
A10: 加速器有效顆數（NVIDIA ＋ 非 NVIDIA × v_ot；百萬顆） | B10: B | C10: =(Units!C4+Units!C5+Units!C6+Units!C7+abf_vot*(Units!C8+Units!C9+Units!C10+Units!C11)) -> 13.68 | D10: =(Units!D4+Units!D5+Units!D6+Units!D7+abf_vot*(Units!D8+Units!D9+Units!D10+Units!D11)) -> 20.9 | E10: =(Units!E4+Units!E5+Units!E6+Units!E7+abf_vot*(Units!E8+Units!E9+Units!E10+Units!E11))*um28_B -> 18.48 | F10: =(Units!F4+Units!F5+Units!F6+Units!F7+abf_vot*(Units!F8+Units!F9+Units!F10+Units!F11))*um29_B -> 22.304
A11: 加速器有效顆數（NVIDIA ＋ 非 NVIDIA × v_ot；百萬顆） | B11: C | C11: =(Units!C4+Units!C5+Units!C6+Units!C7+abf_vot*(Units!C8+Units!C9+Units!C10+Units!C11)) -> 13.68 | D11: =(Units!D4+Units!D5+Units!D6+Units!D7+abf_vot*(Units!D8+Units!D9+Units!D10+Units!D11)) -> 20.9 | E11: =(Units!E4+Units!E5+Units!E6+Units!E7+abf_vot*(Units!E8+Units!E9+Units!E10+Units!E11))*um28_C -> 13.86 | F11: =(Units!F4+Units!F5+Units!F6+Units!F7+abf_vot*(Units!F8+Units!F9+Units!F10+Units!F11))*um29_C -> 15.744
A12: 需求指數：加速器（× 面積層數） | B12: A | C12: =C9/$C9*(1+abf_gasp)^0 -> 1 | D12: =D9/$C9*(1+abf_gasp)^1 -> 1.8027778 | E12: =E9/$C9*(1+abf_gasp)^2 -> 2.3512018 | F12: =F9/$C9*(1+abf_gasp)^3 -> 3.1515468
A13: 需求指數：加速器（× 面積層數） | B13: B | C13: =C10/$C10*(1+abf_gasp)^0 -> 1 | D13: =D10/$C10*(1+abf_gasp)^1 -> 1.8027778 | E13: =E10/$C10*(1+abf_gasp)^2 -> 1.8809614 | F13: =F10/$C10*(1+abf_gasp)^3 -> 2.6788147
A14: 需求指數：加速器（× 面積層數） | B14: C | C14: =C11/$C11*(1+abf_gasp)^0 -> 1 | D14: =D11/$C11*(1+abf_gasp)^1 -> 1.8027778 | E14: =E11/$C11*(1+abf_gasp)^2 -> 1.4107211 | F14: =F11/$C11*(1+abf_gasp)^3 -> 1.8909281
A15: 需求指數：其他 AI（AI IT 資本支出成長 ^ 彈性） | B15: A | C15: =(Deploy!C5/Deploy!$C5)^abf_oai_el -> 1 | D15: =(Deploy!D5/Deploy!$C5)^abf_oai_el -> 1.4149388 | E15: =(Deploy!E5/Deploy!$C5)^abf_oai_el -> 1.5930582 | F15: =(Deploy!F5/Deploy!$C5)^abf_oai_el -> 1.7002925
A16: 需求指數：其他 AI（AI IT 資本支出成長 ^ 彈性） | B16: B | C16: =(Deploy!C6/Deploy!$C6)^abf_oai_el -> 1 | D16: =(Deploy!D6/Deploy!$C6)^abf_oai_el -> 1.4149388 | E16: =(Deploy!E6/Deploy!$C6)^abf_oai_el -> 1.4248745 | F16: =(Deploy!F6/Deploy!$C6)^abf_oai_el -> 1.5675922
A17: 需求指數：其他 AI（AI IT 資本支出成長 ^ 彈性） | B17: C | C17: =(Deploy!C7/Deploy!$C7)^abf_oai_el -> 1 | D17: =(Deploy!D7/Deploy!$C7)^abf_oai_el -> 1.4149388 | E17: =(Deploy!E7/Deploy!$C7)^abf_oai_el -> 1.2339775 | F17: =(Deploy!F7/Deploy!$C7)^abf_oai_el -> 1.3170409
A18: 需求指數：非 AI | C18: =(1+abf_gnai)^0 -> 1 | D18: =(1+abf_gnai)^1 -> 1.03 | E18: =(1+abf_gnai)^2 -> 1.0609 | F18: =(1+abf_gnai)^3 -> 1.092727
A19: 需求指數合計（2026＝1） | B19: A | C19: =$C$6*C12+$C$7*C15+$C$8*C18 -> 1 | D19: =$C$6*D12+$C$7*D15+$C$8*D18 -> 1.3149201 | E19: =$C$6*E12+$C$7*E15+$C$8*E18 -> 1.5187165 | F19: =$C$6*F12+$C$7*F15+$C$8*F18 -> 1.7840927
A20: 需求指數合計（2026＝1） | B20: B | C20: =$C$6*C13+$C$7*C16+$C$8*C18 -> 1 | D20: =$C$6*D13+$C$7*D16+$C$8*D18 -> 1.3149201 | E20: =$C$6*E13+$C$7*E16+$C$8*E18 -> 1.3560416 | F20: =$C$6*F13+$C$7*F16+$C$8*F18 -> 1.6264484
A21: 需求指數合計（2026＝1） | B21: C | C21: =$C$6*C14+$C$7*C17+$C$8*C18 -> 1 | D21: =$C$6*D14+$C$7*D17+$C$8*D18 -> 1.3149201 | E21: =$C$6*E14+$C$7*E17+$C$8*E18 -> 1.189687 | F21: =$C$6*F14+$C$7*F17+$C$8*F18 -> 1.3589478
A23: B. 供給
A24: 2026 供給權重：Ibiden | C24: =abfrev_ib26/$C$5 -> 0.20607631
A25: 2026 供給權重：欣興 | C25: =abfrev_un26/$C$5 -> 0.30126393
A26: 2026 供給權重：南電 | C26: =abfrev_np26/$C$5 -> 0.10401947
A27: 2026 供給權重：景碩 | C27: =abfrev_ks26/$C$5 -> 0.068692102
A28: 2026 供給權重：其他（三星電機、AT&S、Shinko、臻鼎等） | C28: =1-C24-C25-C26-C27 -> 0.31994819
A29: 產能指數：Ibiden | C29: =1 -> 1 | D29: =abfcap_ib_27 -> 1.25 | E29: =abfcap_ib_28 -> 1.55 | F29: =abfcap_ib_29 -> 1.8
A30: 產能指數：欣興 | C30: =1 -> 1 | D30: =abfcap_un_27 -> 1.35 | E30: =abfcap_un_28 -> 1.7 | F30: =abfcap_un_29 -> 2
A31: 產能指數：南電 | C31: =1 -> 1 | D31: =abfcap_np_27 -> 1.2 | E31: =abfcap_np_28 -> 1.35 | F31: =abfcap_np_29 -> 1.6
A32: 產能指數：景碩 | C32: =1 -> 1 | D32: =abfcap_ks_27 -> 1.2 | E32: =abfcap_ks_28 -> 1.5 | F32: =abfcap_ks_29 -> 1.85
A33: 產能指數：其他 | C33: =1 -> 1 | D33: =abfcap_oth_27 -> 1.15 | E33: =abfcap_oth_28 -> 1.3 | F33: =abfcap_oth_29 -> 1.45
A34: 載板產能指數（加權） | C34: =$C$24*C29+$C$25*C30+$C$26*C31+$C$27*C32+$C$28*C33 -> 1 | D34: =$C$24*D29+$C$25*D30+$C$26*D31+$C$27*D32+$C$28*D33 -> 1.239496 | E34: =$C$24*E29+$C$25*E30+$C$26*E31+$C$27*E32+$C$28*E33 -> 1.490964 | F34: =$C$24*F29+$C$25*F30+$C$26*F31+$C$27*F32+$C$28*F33 -> 1.7309016
A35: 味之素 ABF 膜可出貨量上限（2026＝1） | C35: =1 -> 1 | D35: =abffilm_27 -> 1.3 | E35: =abffilm_28 -> 1.55 | F35: =abffilm_29 -> 1.8
A36: 有效供給指數（取小） | C36: =MIN(C34,C35) -> 1 | D36: =MIN(D34,D35) -> 1.239496 | E36: =MIN(E34,E35) -> 1.490964 | F36: =MIN(F34,F35) -> 1.7309016 | G36: 膜上限低於載板產能時，膜為瓶頸
A38: C. 缺口（缺口 ÷ 供給；2026 以外部缺口校準）
A39: ABF 供需缺口 | B39: A | C39: =(1+abf_gap_26)*C19/C36-1 -> 0.09 | D39: =(1+abf_gap_26)*D19/D36-1 -> 0.15632716 | E39: =(1+abf_gap_26)*E19/E36-1 -> 0.11028902 | F39: =(1+abf_gap_26)*F19/F36-1 -> 0.12349599
A40: ABF 供需缺口 | B40: B | C40: =(1+abf_gap_26)*C20/C36-1 -> 0.09 | D40: =(1+abf_gap_26)*D20/D36-1 -> 0.15632716 | E40: =(1+abf_gap_26)*E20/E36-1 -> -0.0086378653 | F40: =(1+abf_gap_26)*F20/F36-1 -> 0.024222728
A41: ABF 供需缺口 | B41: C | C41: =(1+abf_gap_26)*C21/C36-1 -> 0.09 | D41: =(1+abf_gap_26)*D21/D36-1 -> 0.15632716 | E41: =(1+abf_gap_26)*E21/E36-1 -> -0.13025478 | F41: =(1+abf_gap_26)*F21/F36-1 -> -0.14423037
A42: 對照：外部缺口（In 頁 abf_gap_*；兩來源中點） | C42: =abf_gap_26 -> 0.09 | D42: =abf_gap_27 -> 0.24 | E42: =abf_gap_28 -> 0.37
A43: 對照：外部缺口低／高 | C43: =TEXT(abf_gap_26_lo,"0%")&"–"&TEXT(abf_gap_26_hi,"0%") -> 8%–10% | D43: =TEXT(abf_gap_27_lo,"0%")&"–"&TEXT(abf_gap_27_hi,"0%") -> 21%–27% | E43: =TEXT(abf_gap_28_lo,"0%")&"–"&TEXT(abf_gap_28_hi,"0%") -> 29%–42%

Sheet PGW
A1: PGW — 每 GW AI 高速 PCB 與 CCL 金額（US$M／GW，不含價格指數）＝ 2026 元件金額 × 2027–29 指數；市場＝每 GW × 部署 GW（Deploy 頁）。PCB 口徑權威原在勝宏模型、CCL 口徑原在台光電模型；兩者口徑不同，不可相加
A3: 項目 | B3: 情境 | C3: 2026 | D3: 2027 | E3: 2028 | F3: 2029 | G3: 說明
A4: 每 GW PCB
A5: 每 GW PCB：加速器卡／運算板 | C5: =pcb_cmp_26 -> 280 | D5: =pcb_cmp_26*pcb_cmpx_27 -> 420 | E5: =pcb_cmp_26*pcb_cmpx_28 -> 462 | F5: =pcb_cmp_26*pcb_cmpx_29 -> 504
A6: 每 GW PCB：交換器板 | C6: =pcb_sw_26 -> 120 | D6: =pcb_sw_26*pcb_swx_27 -> 162 | E6: =pcb_sw_26*pcb_swx_28 -> 180 | F6: =pcb_sw_26*pcb_swx_29 -> 198
A7: 每 GW PCB：中板／背板／其他 | C7: =pcb_mid_26 -> 50 | D7: =pcb_mid_26*pcb_midx_27 -> 100 | E7: =pcb_mid_26*pcb_midx_28 -> 150 | F7: =pcb_mid_26*pcb_midx_29 -> 175
A8: 每 GW PCB 合計（US$M／GW） | C8: =SUM(C5:C7) -> 450 | D8: =SUM(D5:D7) -> 682 | E8: =SUM(E5:E7) -> 792 | F8: =SUM(F5:F7) -> 877
A9: AI 高速 PCB 市場（不含價格指數；US$B） | B9: A | C9: =C8*Deploy!C9/1000 -> 10.529792 | D9: =D8*Deploy!D9/1000 -> 28.403094 | E9: =E8*Deploy!E9/1000 -> 41.811373 | F9: =F8*Deploy!F9/1000 -> 52.741545
A10: AI 高速 PCB 市場（不含價格指數；US$B） | B10: B | C10: =C8*Deploy!C10/1000 -> 10.529792 | D10: =D8*Deploy!D10/1000 -> 28.403094 | E10: =E8*Deploy!E10/1000 -> 33.449099 | F10: =F8*Deploy!F10/1000 -> 44.830313
A11: AI 高速 PCB 市場（不含價格指數；US$B） | B11: C | C11: =C8*Deploy!C11/1000 -> 10.529792 | D11: =D8*Deploy!D11/1000 -> 28.403094 | E11: =E8*Deploy!E11/1000 -> 25.086824 | F11: =F8*Deploy!F11/1000 -> 31.644927
A13: 每 GW CCL
A14: 每 GW CCL：加速器／運算板 | C14: =ccl_cmp_26 -> 190 | D14: =ccl_cmp_26*ccl_cmpx_27 -> 275.5 | E14: =ccl_cmp_26*ccl_cmpx_28 -> 304 | F14: =ccl_cmp_26*ccl_cmpx_29 -> 323
A15: 每 GW CCL：交換器板 | C15: =ccl_sw_26 -> 90 | D15: =ccl_sw_26*ccl_swx_27 -> 126 | E15: =ccl_sw_26*ccl_swx_28 -> 144 | F15: =ccl_sw_26*ccl_swx_29 -> 157.5
A16: 每 GW CCL：UBB／中板／背板 | C16: =ccl_ubb_26 -> 70 | D16: =ccl_ubb_26*ccl_ubbx_27 -> 126 | E16: =ccl_ubb_26*ccl_ubbx_28 -> 161 | F16: =ccl_ubb_26*ccl_ubbx_29 -> 182
A17: 每 GW CCL 合計（US$M／GW） | C17: =SUM(C14:C16) -> 350 | D17: =SUM(D14:D16) -> 527.5 | E17: =SUM(E14:E16) -> 609 | F17: =SUM(F14:F16) -> 662.5
A18: AI 高速 CCL 市場（不含價格指數；US$B） | B18: A | C18: =C17*Deploy!C9/1000 -> 8.1898383 | D18: =D17*Deploy!D9/1000 -> 21.968669 | E18: =E17*Deploy!E9/1000 -> 32.150412 | F18: =F17*Deploy!F9/1000 -> 39.841817
A19: AI 高速 CCL 市場（不含價格指數；US$B） | B19: B | C19: =C17*Deploy!C10/1000 -> 8.1898383 | D19: =D17*Deploy!D10/1000 -> 21.968669 | E19: =E17*Deploy!E10/1000 -> 25.72033 | F19: =F17*Deploy!F10/1000 -> 33.865544
A20: AI 高速 CCL 市場（不含價格指數；US$B） | B20: C | C20: =C17*Deploy!C11/1000 -> 8.1898383 | D20: =D17*Deploy!D11/1000 -> 21.968669 | E20: =E17*Deploy!E11/1000 -> 19.290247 | F20: =F17*Deploy!F11/1000 -> 23.90509
A22: 每 GW PCB ÷ 每 GW CCL | C22: =C8/C17 -> 1.2857143 | D22: =D8/D17 -> 1.292891 | E22: =E8/E17 -> 1.3004926 | F22: =F8/F17 -> 1.3237736

Sheet Rack
A1: Rack — 機架層市場（2026–2029；情境 A／B／C）：(1) AI 伺服器組裝市場（ODM 價）＝部署 GW × 每 GW 架數（Tokenomics）× ODM 每櫃價格；(2) 商用 GPU 系統市場（OEM／整櫃售價，含 GPU）＝商用 GPU 顆數 × 每顆系統價值（Tokenomics 機架價 ÷ 每架 GPU 數）；(3) AI 電源市場＝部署 GW × 每 kW 電源內容。2026 部署依 vr26 混合 GB300 與 VR200，2027 起 VR200（ASIC 機架假設每 GW 價值相同）
A3: 項目 | B3: 情境 | C3: 2026 | D3: 2027 | E3: 2028 | F3: 2029 | G3: 說明
A4: A. AI 伺服器組裝市場（ODM 價；quanta、foxconn、wistron、wiwynn 同讀）
A5: 每 GW ODM 整櫃價值（US$B／GW） | C5: =(TK_RacksPerGW_GB300*asm_odm_gb*(1-vr26)+TK_RacksPerGW_VR200*asm_odm_vr*vr26)/1000 -> 27.1209 | D5: =TK_RacksPerGW_VR200*asm_odm_vr/1000 -> 27.351 | E5: =TK_RacksPerGW_VR200*asm_odm_vr/1000 -> 27.351 | F5: =TK_RacksPerGW_VR200*asm_odm_vr/1000 -> 27.351 | G5: Tokenomics 每 GW 架數 × ODM 每櫃價格（In 頁 M18）
A6: AI 伺服器組裝市場（US$B） | B6: A | C6: =Deploy!C9*C5 -> 634.61653 | D6: =Deploy!D9*D5 -> 1139.0807 | E6: =Deploy!E9*E5 -> 1443.9178 | F6: =Deploy!F9*F5 -> 1644.8506
A7: AI 伺服器組裝市場（US$B） | B7: B | C7: =Deploy!C10*C5 -> 634.61653 | D7: =Deploy!D10*D5 -> 1139.0807 | E7: =Deploy!E10*E5 -> 1155.1342 | F7: =Deploy!F10*F5 -> 1398.123
A8: AI 伺服器組裝市場（US$B） | B8: C | C8: =Deploy!C11*C5 -> 634.61653 | D8: =Deploy!D11*D5 -> 1139.0807 | E8: =Deploy!E11*E5 -> 866.35066 | F8: =Deploy!F11*F5 -> 986.91037
A10: B. 商用 GPU 系統市場（OEM／整櫃售價；dell、smci 同讀；CF10）
A11: 每顆系統價值：GB300 世代（US$K／顆） | C11: =TK_RackPrice_GB300/(TK_GPUsPerGW_GB300/TK_RacksPerGW_GB300)*1000 -> 59.722222 | D11: =TK_RackPrice_GB300/(TK_GPUsPerGW_GB300/TK_RacksPerGW_GB300)*1000 -> 59.722222 | E11: =TK_RackPrice_GB300/(TK_GPUsPerGW_GB300/TK_RacksPerGW_GB300)*1000 -> 59.722222 | F11: =TK_RackPrice_GB300/(TK_GPUsPerGW_GB300/TK_RacksPerGW_GB300)*1000 -> 59.722222 | G11: Tokenomics 機架價 ÷ 每架 GPU 數；HGX 八卡與 AMD MI355 以同值近似（Analogy）
A12: 每顆系統價值：Rubin 世代（US$K／顆） | C12: =TK_RackPrice_VR200/(TK_GPUsPerGW_VR200/TK_RacksPerGW_VR200)*1000 -> 116.66667 | D12: =TK_RackPrice_VR200/(TK_GPUsPerGW_VR200/TK_RacksPerGW_VR200)*1000 -> 116.66667 | E12: =TK_RackPrice_VR200/(TK_GPUsPerGW_VR200/TK_RacksPerGW_VR200)*1000 -> 116.66667 | F12: =TK_RackPrice_VR200/(TK_GPUsPerGW_VR200/TK_RacksPerGW_VR200)*1000 -> 116.66667 | G12: Rubin Ultra 與 AMD MI450 整櫃以 VR200 同值近似（Analogy）
A13: GB300 世代商用 GPU 顆數（Blackwell＋Hopper；2026 另含 AMD MI355；百萬顆，情境 A） | C13: =Units!C4+Units!C7+Units!C8 -> 6.65 | D13: =Units!D4+Units!D7 -> 2.4 | E13: =Units!E4+Units!E7 -> 0.5 | F13: =Units!F4+Units!F7 -> 0.25 | G13: 世代分組依 AMD 實際產品：2026 MI355（八卡，GB300 世代）、2027 起 MI450 Helios 整櫃（Rubin 世代）
A14: Rubin 世代商用 GPU 顆數（Rubin＋Rubin Ultra；2027 起另含 AMD MI450；百萬顆，情境 A） | C14: =Units!C5+Units!C6 -> 1.7 | D14: =Units!D5+Units!D6+Units!D8 -> 8.8 | E14: =Units!E5+Units!E6+Units!E8 -> 11 | F14: =Units!F5+Units!F6+Units!F8 -> 12.65
A15: 商用 GPU 系統市場（US$B） | B15: A | C15: =(C13*C11+C14*C12) -> 595.48611 | D15: =(D13*D11+D14*D12) -> 1170 | E15: =(E13*E11+E14*E12)*um28_A -> 1313.1944 | F15: =(F13*F11+F14*F12)*um29_A -> 1490.7639
A16: 商用 GPU 系統市場（US$B） | B16: B | C16: =(C13*C11+C14*C12) -> 595.48611 | D16: =(D13*D11+D14*D12) -> 1170 | E16: =(E13*E11+E14*E12)*um28_B -> 1050.5556 | F16: =(F13*F11+F14*F12)*um29_B -> 1267.1493
A17: 商用 GPU 系統市場（US$B） | B17: C | C17: =(C13*C11+C14*C12) -> 595.48611 | D17: =(D13*D11+D14*D12) -> 1170 | E17: =(E13*E11+E14*E12)*um28_C -> 787.91667 | F17: =(F13*F11+F14*F12)*um29_C -> 894.45833
A19: C. AI 電源市場（delta、liteon 同讀）
A20: AI 電源每 kW 內容（US$/kW） | C20: =pwr_pkw_26 -> 450 | D20: =pwr_pkw_27 -> 600 | E20: =pwr_pkw_28 -> 680 | F20: =pwr_pkw_29 -> 720 | G20: 機架電源櫃、PSU、BBU、HVDC 電源櫃（In 頁 M17）
A21: AI 電源市場（US$B） | B21: A | C21: =Deploy!C9*C20/1000 -> 10.529792 | D21: =Deploy!D9*D20/1000 -> 24.988059 | E21: =Deploy!E9*E20/1000 -> 35.898654 | F21: =Deploy!F9*F20/1000 -> 43.299786
A22: AI 電源市場（US$B） | B22: B | C22: =Deploy!C10*C20/1000 -> 10.529792 | D22: =Deploy!D10*D20/1000 -> 24.988059 | E22: =Deploy!E10*E20/1000 -> 28.718923 | F22: =Deploy!F10*F20/1000 -> 36.804818
A23: AI 電源市場（US$B） | B23: C | C23: =Deploy!C11*C20/1000 -> 10.529792 | D23: =Deploy!D11*D20/1000 -> 24.988059 | E23: =Deploy!E11*E20/1000 -> 21.539192 | F23: =Deploy!F11*F20/1000 -> 25.979872
A24: 對照：UBS 全球 AI 伺服器電源市場（US$B；口徑未找到） | C24: =pwr_ubs_26 -> 17.7 | D24: =pwr_ubs_27 -> 38.2
A25: 本庫情境 A ÷ UBS | C25: =C21/C24 -> 0.59490351 | D25: =D21/D24 -> 0.65413768 | G25: UBS 高出約五到七成：口徑（是否含 BBU、HVDC、非 AI）未找到，只作對照
A27: D. AI 液冷市場（機架內液冷＋分歧管；avc、auras、jentech 同讀；不含 CDU、Liquid-to-Air 等機架外冷卻）
A28: 每 GW 液冷內容（US$M／GW） | C28: =((1-vr26)*TK_RacksPerGW_GB300*(lc_cool_gb+lc_mani)+vr26*TK_RacksPerGW_VR200*(lc_cool_vr+lc_mani))/1000 -> 350.7208 | D28: =TK_RacksPerGW_VR200*(lc_cool_vr+lc_mani)*lc_adj_27/1000 -> 326.5912 | E28: =TK_RacksPerGW_VR200*(lc_cool_vr+lc_mani)*lc_adj_28/1000 -> 351.7136 | F28: =TK_RacksPerGW_VR200*(lc_cool_vr+lc_mani)*lc_adj_29/1000 -> 351.7136 | G28: 每架機架內液冷（Morgan Stanley BOM）＋分歧管，× 每 GW 架數；2027 起 × 內容調整（Rubin 全液冷、ASIC 液冷）
A29: 液冷滲透率（部署 GW 中液冷占比） | B29: A | C29: =lc_pen_26 -> 0.55 | D29: =lc_pen_27_hi -> 0.85 | E29: =lc_pen_28_hi -> 0.95 | F29: =lc_pen_29_hi -> 0.95
A30: 液冷滲透率（部署 GW 中液冷占比） | B30: B | C30: =lc_pen_26 -> 0.55 | D30: =lc_pen_27 -> 0.75 | E30: =lc_pen_28 -> 0.85 | F30: =lc_pen_29 -> 0.9
A31: 液冷滲透率（部署 GW 中液冷占比） | B31: C | C31: =lc_pen_26 -> 0.55 | D31: =lc_pen_27_lo -> 0.6 | E31: =lc_pen_28_lo -> 0.7 | F31: =lc_pen_29_lo -> 0.75
A32: AI 液冷市場（US$B） | B32: A | C32: =Deploy!C9*C29*C28/1000 -> 4.5136876 | D32: =Deploy!D9*D29*D28/1000 -> 11.561247 | E32: =Deploy!E9*E29*E28/1000 -> 17.639327 | F32: =Deploy!F9*F29*F28/1000 -> 20.093983
A33: AI 液冷市場（US$B） | B33: B | C33: =Deploy!C10*C30*C28/1000 -> 4.5136876 | D33: =Deploy!D10*D30*D28/1000 -> 10.2011 | E33: =Deploy!E10*E30*E28/1000 -> 12.626045 | F33: =Deploy!F10*F30*F28/1000 -> 16.180944
A34: AI 液冷市場（US$B） | B34: C | C34: =Deploy!C11*C31*C28/1000 -> 4.5136876 | D34: =Deploy!D11*D31*D28/1000 -> 8.1608803 | E34: =Deploy!E11*E31*E28/1000 -> 7.7984394 | F34: =Deploy!F11*F31*F28/1000 -> 9.5182023
A35: 對照：TrendForce AI 晶片液冷滲透率（顆數口徑） | C35: =lc_tf_26 -> 0.53 | D35: =lc_tf_27 -> 0.6 | G35: 以 GW 計高於顆數計（液冷晶片功耗較高）

Sheet Equip
A1: Equip — (1) SEMI 設備分項路徑（2026 新聞稿值；2025 由年增回推；2027、2028 年增連乘，測試與封裝 2027 為 2026、2028 的幾何內插；2029 × (1＋g29)）；(2) SoC 測試機市場三情境＝AI（加速器顆數 × 每顆測試時間係數 × 每加權顆支出，以 CY2026 公司市場校準）＋非 AI；(3) 測試 ÷ WFE（CF15）。記憶體測試機市場依 DRAM 設備支出（公司資本支出推導，markets/equipment），留在 advantest 模型
A3: 項目 | B3: 情境 | C3: 2025 | D3: 2026 | E3: 2027 | F3: 2028 | G3: 2029 | H3: 說明
A4: A. SEMI 設備分項（US$B；SEMI 為設備商協會，Interested-party）
A5: SEMI DRAM 設備 | C5: =eq_s_dram_26/(1+eq_g_dram_26) -> 27.913669 | D5: =eq_s_dram_26 -> 38.8 | E5: =D5*(1+eq_g_dram_27) -> 49.4312 | F5: =E5*(1+eq_g_dram_28) -> 56.84588 | G5: =F5*(1+eq_g29) -> 61.39355
A6: SEMI NAND 設備 | C6: =eq_s_nand_26/(1+eq_g_nand_26) -> 10.635042 | D6: =eq_s_nand_26 -> 13.9 | E6: =D6*(1+eq_g_nand_27) -> 18.2229 | F6: =E6*(1+eq_g_nand_28) -> 20.86522 | G6: =F6*(1+eq_g29) -> 22.534438
A7: SEMI 代工與邏輯設備 | C7: =eq_s_fd_26/(1+eq_g_fd_26) -> 65.601346 | D7: =eq_s_fd_26 -> 78 | E7: =D7*(1+eq_g_fd_27) -> 92.118 | F7: =E7*(1+eq_g_fd_28) -> 104.64605 | G7: =F7*(1+eq_g29) -> 113.01773
A8: SEMI 晶圓前段設備（WFE） | C8: =eq_s_wfe_26/(1+eq_g_wfe_26) -> 116.89683 | D8: =eq_s_wfe_26 -> 143.9 | E8: =D8*(1+eq_g_wfe_27) -> 175.2702 | F8: =E8*(1+eq_g_wfe_28) -> 199.9833 | G8: =F8*(1+eq_g29) -> 215.98196
A9: SEMI 測試設備 | C9: =eq_s_test_26/(1+eq_g_test_26) -> 11.679389 | D9: =eq_s_test_26 -> 15.3 | E9: =SQRT(eq_s_test_26*eq_s_test_28) -> 17.839282 | F9: =eq_s_test_28 -> 20.8 | G9: =F9*(1+eq_g29) -> 22.464 | H9: 2027 幾何內插（Derived；SEMI 年中預測未給 2027）
A10: SEMI 組裝與封裝設備 | C10: =eq_s_pkg_26/(1+eq_g_pkg_26) -> 6.1131387 | D10: =eq_s_pkg_26 -> 6.7 | E10: =SQRT(eq_s_pkg_26*eq_s_pkg_28) -> 7.5907839 | F10: =eq_s_pkg_28 -> 8.6 | G10: =F10*(1+eq_g29) -> 9.288 | H10: 2027 幾何內插（Derived；SEMI 年中預測未給 2027）
A11: SEMI 設備合計（WFE＋測試＋封裝） | C11: =C8+C9+C10 -> 134.68936 | D11: =D8+D9+D10 -> 165.9 | E11: =E8+E9+E10 -> 200.70027 | F11: =F8+F9+F10 -> 229.3833 | G11: =G8+G9+G10 -> 247.73396
A13: B. SoC 測試機市場（日曆年，US$B）
A14: 測試時間加權顆數（百萬顆） | B14: A | D14: =(Units!C4*ts_tt_bw+Units!C5*ts_tt_rb+Units!C6*ts_tt_ru+Units!C7*ts_tt_hp+Units!C8*ts_tt_amd+Units!C9*ts_tt_tpu+Units!C10*ts_tt_trn+Units!C11*ts_tt_oth) -> 14.885 | E14: =(Units!D4*ts_tt_bw+Units!D5*ts_tt_rb+Units!D6*ts_tt_ru+Units!D7*ts_tt_hp+Units!D8*ts_tt_amd+Units!D9*ts_tt_tpu+Units!D10*ts_tt_trn+Units!D11*ts_tt_oth) -> 24.31 | F14: =(Units!E4*ts_tt_bw+Units!E5*ts_tt_rb+Units!E6*ts_tt_ru+Units!E7*ts_tt_hp+Units!E8*ts_tt_amd+Units!E9*ts_tt_tpu+Units!E10*ts_tt_trn+Units!E11*ts_tt_oth)*um28_A -> 28.1 | G14: =(Units!F4*ts_tt_bw+Units!F5*ts_tt_rb+Units!F6*ts_tt_ru+Units!F7*ts_tt_hp+Units!F8*ts_tt_amd+Units!F9*ts_tt_tpu+Units!F10*ts_tt_trn+Units!F11*ts_tt_oth)*um29_A -> 31.99
A15: 測試時間加權顆數（百萬顆） | B15: B | D15: =(Units!C4*ts_tt_bw+Units!C5*ts_tt_rb+Units!C6*ts_tt_ru+Units!C7*ts_tt_hp+Units!C8*ts_tt_amd+Units!C9*ts_tt_tpu+Units!C10*ts_tt_trn+Units!C11*ts_tt_oth) -> 14.885 | E15: =(Units!D4*ts_tt_bw+Units!D5*ts_tt_rb+Units!D6*ts_tt_ru+Units!D7*ts_tt_hp+Units!D8*ts_tt_amd+Units!D9*ts_tt_tpu+Units!D10*ts_tt_trn+Units!D11*ts_tt_oth) -> 24.31 | F15: =(Units!E4*ts_tt_bw+Units!E5*ts_tt_rb+Units!E6*ts_tt_ru+Units!E7*ts_tt_hp+Units!E8*ts_tt_amd+Units!E9*ts_tt_tpu+Units!E10*ts_tt_trn+Units!E11*ts_tt_oth)*um28_B -> 22.48 | G15: =(Units!F4*ts_tt_bw+Units!F5*ts_tt_rb+Units!F6*ts_tt_ru+Units!F7*ts_tt_hp+Units!F8*ts_tt_amd+Units!F9*ts_tt_tpu+Units!F10*ts_tt_trn+Units!F11*ts_tt_oth)*um29_B -> 27.1915
A16: 測試時間加權顆數（百萬顆） | B16: C | D16: =(Units!C4*ts_tt_bw+Units!C5*ts_tt_rb+Units!C6*ts_tt_ru+Units!C7*ts_tt_hp+Units!C8*ts_tt_amd+Units!C9*ts_tt_tpu+Units!C10*ts_tt_trn+Units!C11*ts_tt_oth) -> 14.885 | E16: =(Units!D4*ts_tt_bw+Units!D5*ts_tt_rb+Units!D6*ts_tt_ru+Units!D7*ts_tt_hp+Units!D8*ts_tt_amd+Units!D9*ts_tt_tpu+Units!D10*ts_tt_trn+Units!D11*ts_tt_oth) -> 24.31 | F16: =(Units!E4*ts_tt_bw+Units!E5*ts_tt_rb+Units!E6*ts_tt_ru+Units!E7*ts_tt_hp+Units!E8*ts_tt_amd+Units!E9*ts_tt_tpu+Units!E10*ts_tt_trn+Units!E11*ts_tt_oth)*um28_C -> 16.86 | G16: =(Units!F4*ts_tt_bw+Units!F5*ts_tt_rb+Units!F6*ts_tt_ru+Units!F7*ts_tt_hp+Units!F8*ts_tt_amd+Units!F9*ts_tt_tpu+Units!F10*ts_tt_trn+Units!F11*ts_tt_oth)*um29_C -> 19.194
A17: 每加權顆測試支出（以 CY2026 校準；US$B／百萬顆） | D17: =(ts_mk_soc26-ts_nonai26)/D14 -> 0.48370843 | H17: （公司 CY2026 SoC 市場 − 非 AI）÷ 加權顆數；平行測試效率提升基準為 0
A18: 非 AI SoC 測試機市場 | D18: =ts_nonai26*(1+ts_g_nonai)^0 -> 4.3 | E18: =ts_nonai26*(1+ts_g_nonai)^1 -> 4.472 | F18: =ts_nonai26*(1+ts_g_nonai)^2 -> 4.65088 | G18: =ts_nonai26*(1+ts_g_nonai)^3 -> 4.8369152
A19: SoC 測試機市場 | B19: A | C19: =ts_mk_soc25 -> 6.9 | D19: =$D$17*D14+D18 -> 11.5 | E19: =$D$17*E14+E18 -> 16.230952 | F19: =$D$17*F14+F18 -> 18.243087 | G19: =$D$17*G14+G18 -> 20.310748
A20: SoC 測試機市場 | B20: B | C20: =ts_mk_soc25 -> 6.9 | D20: =$D$17*D15+D18 -> 11.5 | E20: =$D$17*E15+E18 -> 16.230952 | F20: =$D$17*F15+F18 -> 15.524646 | G20: =$D$17*G15+G18 -> 17.989673
A21: SoC 測試機市場 | B21: C | C21: =ts_mk_soc25 -> 6.9 | D21: =$D$17*D16+D18 -> 11.5 | E21: =$D$17*E16+E18 -> 16.230952 | F21: =$D$17*F16+F18 -> 12.806204 | G21: =$D$17*G16+G18 -> 14.121215
A23: C. 測試 ÷ WFE（CF15；泰瑞達長期 7–9% 是其 ATE 口徑，SEMI 測試設備另含探針台、分選機等）
A24: SEMI 測試設備 ÷ SEMI WFE | C24: =C9/C8 -> 0.099911941 | D24: =D9/D8 -> 0.10632384 | E24: =E9/E8 -> 0.10178161 | F24: =F9/F8 -> 0.10400869 | G24: =G9/G8 -> 0.10400869
A25: SoC 測試機市場（情境 A）÷ SEMI WFE | C25: =C19/C8 -> 0.059026407 | D25: =D19/D8 -> 0.079916609 | E25: =E19/E8 -> 0.092605314 | F25: =F19/F8 -> 0.091223053 | G25: =G19/G8 -> 0.094039093
A26: 對照：泰瑞達測試 ÷ WFE 長期區間 | D26: =TEXT(ts_tw_lo,"0%")&"–"&TEXT(ts_tw_hi,"0%") -> 7%–9%
A28: D. 混合鍵合占 HBM 工序比例（行業技術情境：CY2028 起 A 高、B 基準、C 低；disco、hanmi、besi 同讀）
A29: 混合鍵合占 HBM 工序比例 | B29: A | C29: =hbm_hbp_25 -> 0 | D29: =hbm_hbp_26 -> 0 | E29: =hbm_hbp_27 -> 0 | F29: =hbm_hbp_28_hi -> 0.15 | G29: =hbm_hbp_29_hi -> 0.3
A30: 混合鍵合占 HBM 工序比例 | B30: B | C30: =hbm_hbp_25 -> 0 | D30: =hbm_hbp_26 -> 0 | E30: =hbm_hbp_27 -> 0 | F30: =hbm_hbp_28 -> 0.05 | G30: =hbm_hbp_29 -> 0.15
A31: 混合鍵合占 HBM 工序比例 | B31: C | C31: =hbm_hbp_25 -> 0 | D31: =hbm_hbp_26 -> 0 | E31: =hbm_hbp_27 -> 0 | F31: =hbm_hbp_28_lo -> 0 | G31: =hbm_hbp_29_lo -> 0.05
A32: HBM 平均堆疊層數（基準） | C32: =hbm_stk_25 -> 10 | D32: =hbm_stk_26 -> 12 | E32: =hbm_stk_27 -> 12.5 | F32: =hbm_stk_28 -> 14 | G32: =hbm_stk_29 -> 15

Sheet Path
A1: Path — 記憶體合約價指數（2025Q1＝1；季增來自 In 頁 M1）。共用市場層：所有記憶體公司用同一條路徑，再依各自會計年度取平均
A3: 路徑 | B3: 情境 | C3: 2025Q1 | D3: 2025Q2 | E3: 2025Q3 | F3: 2025Q4 | G3: 2026Q1 | H3: 2026Q2 | I3: 2026Q3 | J3: 2026Q4 | K3: 2027Q1 | L3: 2027Q2 | M3: 2027Q3 | N3: 2027Q4 | O3: 2028Q1 | P3: 2028Q2 | Q3: 2028Q3 | R3: 2028Q4 | S3: 2029Q1 | T3: 2029Q2 | U3: 2029Q3 | V3: 2029Q4
A4: 一般 DRAM | B4: A | C4: 1 | D4: =C4*(1+cq_1) -> 0.975 | E4: =D4*(1+cq_2) -> 1.096875 | F4: =E4*(1+cq_3) -> 1.6178906 | G4: =F4*(1+cq_4) -> 3.1548867 | H4: =G4*(1+cq_5) -> 5.0635932 | I4: =H4*(1+cq_6) -> 5.8484501 | J4: =I4*(1+cq_7) -> 6.5795064 | K4: =J4*(1+cqA_8) -> 6.7768916 | L4: =K4*(1+cqA_9) -> 6.7768916 | M4: =L4*(1+cqA_10) -> 6.6413538 | N4: =M4*(1+cqA_11) -> 6.4421131 | O4: =N4*(1+cqA_12) -> 6.2488497 | P4: =O4*(1+cqA_13) -> 6.0613843 | Q4: =P4*(1+cqA_14) -> 5.9401566 | R4: =Q4*(1+cqA_15) -> 5.8213534 | S4: =R4*(1+cqA_16) -> 5.6467128 | T4: =S4*(1+cqA_17) -> 5.4773114 | U4: =T4*(1+cqA_18) -> 5.3677652 | V4: =U4*(1+cqA_19) -> 5.2604099
A5: 一般 DRAM | B5: B | C5: 1 | D5: =C5*(1+cq_1) -> 0.975 | E5: =D5*(1+cq_2) -> 1.096875 | F5: =E5*(1+cq_3) -> 1.6178906 | G5: =F5*(1+cq_4) -> 3.1548867 | H5: =G5*(1+cq_5) -> 5.0635932 | I5: =H5*(1+cq_6) -> 5.8484501 | J5: =I5*(1+cq_7) -> 6.5795064 | K5: =J5*(1+cqB_8) -> 6.9084817 | L5: =K5*(1+cqB_9) -> 7.0466513 | M5: =L5*(1+cqB_10) -> 6.4829192 | N5: =M5*(1+cqB_11) -> 5.5104814 | O5: =N5*(1+cqB_12) -> 4.132861 | P5: =O5*(1+cqB_13) -> 3.5129319 | Q5: =P5*(1+cqB_14) -> 3.1616387 | R5: =Q5*(1+cqB_15) -> 3.0035567 | S5: =R5*(1+cqB_16) -> 3.1537346 | T5: =S5*(1+cqB_17) -> 3.3114213 | U5: =T5*(1+cqB_18) -> 3.4107639 | V5: =U5*(1+cqB_19) -> 3.5130869
A6: 一般 DRAM | B6: C | C6: 1 | D6: =C6*(1+cq_1) -> 0.975 | E6: =D6*(1+cq_2) -> 1.096875 | F6: =E6*(1+cq_3) -> 1.6178906 | G6: =F6*(1+cq_4) -> 3.1548867 | H6: =G6*(1+cq_5) -> 5.0635932 | I6: =H6*(1+cq_6) -> 5.8484501 | J6: =I6*(1+cq_7) -> 6.5795064 | K6: =J6*(1+cqC_8) -> 6.9084817 | L6: =K6*(1+cqC_9) -> 7.0466513 | M6: =L6*(1+cqC_10) -> 6.4829192 | N6: =M6*(1+cqC_11) -> 5.5104814 | O6: =N6*(1+cqC_12) -> 3.5818129 | P6: =O6*(1+cqC_13) -> 2.507269 | Q6: =P6*(1+cqC_14) -> 1.8804518 | R6: =Q6*(1+cqC_15) -> 1.5043614 | S6: =R6*(1+cqC_16) -> 1.5043614 | T6: =S6*(1+cqC_17) -> 1.5795795 | U6: =T6*(1+cqC_18) -> 1.7059458 | V6: =U6*(1+cqC_19) -> 1.8765404
A8: NAND | B8: A | C8: 1 | D8: =C8*(1+nq_1) -> 1 | E8: =D8*(1+nq_2) -> 1.05 | F8: =E8*(1+nq_3) -> 1.365 | G8: =F8*(1+nq_4) -> 2.559375 | H8: =G8*(1+nq_5) -> 4.4149219 | I8: =H8*(1+nq_6) -> 5.5186523 | J8: =I8*(1+nq_7) -> 5.9656632 | K8: =J8*(1+nqA_8) -> 6.1446331 | L8: =K8*(1+nqA_9) -> 6.1446331 | M8: =L8*(1+nqA_10) -> 5.8374014 | N8: =M8*(1+nqA_11) -> 5.4287833 | O8: =N8*(1+nqA_12) -> 5.1573442 | P8: =O8*(1+nqA_13) -> 4.899477 | Q8: =P8*(1+nqA_14) -> 4.6545031 | R8: =Q8*(1+nqA_15) -> 4.4217779 | S8: =R8*(1+nqA_16) -> 4.2891246 | T8: =S8*(1+nqA_17) -> 4.1604509 | U8: =T8*(1+nqA_18) -> 4.0356373 | V8: =U8*(1+nqA_19) -> 3.9145682
A9: NAND | B9: B | C9: 1 | D9: =C9*(1+nq_1) -> 1 | E9: =D9*(1+nq_2) -> 1.05 | F9: =E9*(1+nq_3) -> 1.365 | G9: =F9*(1+nq_4) -> 2.559375 | H9: =G9*(1+nq_5) -> 4.4149219 | I9: =H9*(1+nq_6) -> 5.5186523 | J9: =I9*(1+nq_7) -> 5.9656632 | K9: =J9*(1+nqB_8) -> 6.2639463 | L9: =K9*(1+nqB_9) -> 6.3892253 | M9: =L9*(1+nqB_10) -> 5.7503027 | N9: =M9*(1+nqB_11) -> 4.6002422 | O9: =N9*(1+nqB_12) -> 3.2201695 | P9: =O9*(1+nqB_13) -> 2.4151272 | Q9: =P9*(1+nqB_14) -> 1.9321017 | R9: =Q9*(1+nqB_15) -> 1.7388915 | S9: =R9*(1+nqB_16) -> 1.8258361 | T9: =S9*(1+nqB_17) -> 1.9171279 | U9: =T9*(1+nqB_18) -> 1.9746418 | V9: =U9*(1+nqB_19) -> 2.033881
A10: NAND | B10: C | C10: 1 | D10: =C10*(1+nq_1) -> 1 | E10: =D10*(1+nq_2) -> 1.05 | F10: =E10*(1+nq_3) -> 1.365 | G10: =F10*(1+nq_4) -> 2.559375 | H10: =G10*(1+nq_5) -> 4.4149219 | I10: =H10*(1+nq_6) -> 5.5186523 | J10: =I10*(1+nq_7) -> 5.9656632 | K10: =J10*(1+nqC_8) -> 6.2639463 | L10: =K10*(1+nqC_9) -> 6.3892253 | M10: =L10*(1+nqC_10) -> 5.7503027 | N10: =M10*(1+nqC_11) -> 4.6002422 | O10: =N10*(1+nqC_12) -> 2.9901574 | P10: =O10*(1+nqC_13) -> 1.9436023 | Q10: =P10*(1+nqC_14) -> 1.4577017 | R10: =Q10*(1+nqC_15) -> 1.1661614 | S10: =R10*(1+nqC_16) -> 1.1661614 | T10: =S10*(1+nqC_17) -> 1.2244695 | U10: =T10*(1+nqC_18) -> 1.322427 | V10: =U10*(1+nqC_19) -> 1.4546697
A12: 年均指數
A13: 路徑 | B13: 情境 | C13: 2025 | D13: 2026 | E13: 2027 | F13: 2028 | G13: 2029 | H13: 2026÷2025 | I13: 2027÷2026 | J13: 2028÷2027 | K13: 2029÷2028
A14: 一般 DRAM | B14: A | C14: =AVERAGE(C4:F4) -> 1.1724414 | D14: =AVERAGE(G4:J4) -> 5.1616091 | E14: =AVERAGE(K4:N4) -> 6.6593125 | F14: =AVERAGE(O4:R4) -> 6.017936 | G14: =AVERAGE(S4:V4) -> 5.4380499 | H14: =D14/C14-1 -> 3.4024453 | I14: =E14/D14-1 -> 0.29016211 | J14: =F14/E14-1 -> -0.096312722 | K14: =G14/F14-1 -> -0.09635964
A15: 一般 DRAM | B15: B | C15: =AVERAGE(C5:F5) -> 1.1724414 | D15: =AVERAGE(G5:J5) -> 5.1616091 | E15: =AVERAGE(K5:N5) -> 6.4871334 | F15: =AVERAGE(O5:R5) -> 3.4527471 | G15: =AVERAGE(S5:V5) -> 3.3472517 | H15: =D15/C15-1 -> 3.4024453 | I15: =E15/D15-1 -> 0.25680447 | J15: =F15/E15-1 -> -0.46775458 | K15: =G15/F15-1 -> -0.030554048
A16: 一般 DRAM | B16: C | C16: =AVERAGE(C6:F6) -> 1.1724414 | D16: =AVERAGE(G6:J6) -> 5.1616091 | E16: =AVERAGE(K6:N6) -> 6.4871334 | F16: =AVERAGE(O6:R6) -> 2.3684738 | G16: =AVERAGE(S6:V6) -> 1.6666068 | H16: =D16/C16-1 -> 3.4024453 | I16: =E16/D16-1 -> 0.25680447 | J16: =F16/E16-1 -> -0.63489671 | K16: =G16/F16-1 -> -0.29633724
A17: NAND | B17: A | C17: =AVERAGE(C8:F8) -> 1.10375 | D17: =AVERAGE(G8:J8) -> 4.6146531 | E17: =AVERAGE(K8:N8) -> 5.8888627 | F17: =AVERAGE(O8:R8) -> 4.7832755 | G17: =AVERAGE(S8:V8) -> 4.0999453 | H17: =D17/C17-1 -> 3.1808862 | I17: =E17/D17-1 -> 0.27612252 | J17: =F17/E17-1 -> -0.18774205 | K17: =G17/F17-1 -> -0.14285823
A18: NAND | B18: B | C18: =AVERAGE(C9:F9) -> 1.10375 | D18: =AVERAGE(G9:J9) -> 4.6146531 | E18: =AVERAGE(K9:N9) -> 5.7509291 | F18: =AVERAGE(O9:R9) -> 2.3265725 | G18: =AVERAGE(S9:V9) -> 1.9378717 | H18: =D18/C18-1 -> 3.1808862 | I18: =E18/D18-1 -> 0.24623217 | J18: =F18/E18-1 -> -0.59544407 | K18: =G18/F18-1 -> -0.16707013
A19: NAND | B19: C | C19: =AVERAGE(C10:F10) -> 1.10375 | D19: =AVERAGE(G10:J10) -> 4.6146531 | E19: =AVERAGE(K10:N10) -> 5.7509291 | F19: =AVERAGE(O10:R10) -> 1.8894057 | G19: =AVERAGE(S10:V10) -> 1.2919319 | H19: =D19/C19-1 -> 3.1808862 | I19: =E19/D19-1 -> 0.24623217 | J19: =F19/E19-1 -> -0.67146079 | K19: =G19/F19-1 -> -0.31622315

Sheet Mkt
A1: Mkt — 加速器數量層（最小版）與 HBM 市場（日曆年）。需求＝顆數 × GB × 情境顆數係數（2028–29）；供給三情境相同；出貨＝MIN(需求, 供給)；市場＝出貨 × 單價（單價依情境）
A2: 公式由 markets/memory/market.py write() 產生（與各記憶體公司模型的 Mkt 頁同一份）；輸入讀本活頁簿 In 頁
A3: 項目 | B3: 單位 | C3: 2025 | D3: 2026 | E3: 2027 | F3: 2028 | G3: 2029 | H3: 說明
A4: 需求：加速器裝載的 HBM（PB）
A5: NVIDIA Blackwell（B200／B300） | B5: PB | D5: =u_bw_26*g_bw_26 -> 1404 | E5: =u_bw_27*g_bw_27 -> 672 | F5: =u_bw_28*g_bw_28 -> 144
A6: NVIDIA Rubin | B6: PB | D6: =u_rb_26*g_rb_26 -> 489.6 | E6: =u_rb_27*g_rb_27 -> 2016 | F6: =u_rb_28*g_rb_28 -> 2016
A7: NVIDIA Rubin Ultra | B7: PB | D7: =u_ru_26*g_ru_26 -> 0 | E7: =u_ru_27*g_ru_27 -> 307.2 | F7: =u_ru_28*g_ru_28 -> 2048
A8: NVIDIA Hopper（H200 等） | B8: PB | D8: =u_hp_26*g_hp_26 -> 70.5 | E8: =u_hp_27*g_hp_27 -> 0 | F8: =u_hp_28*g_hp_28 -> 0
A9: AMD Instinct | B9: PB | D9: =u_amd_26*g_amd_26 -> 216 | E9: =u_amd_27*g_amd_27 -> 540 | F9: =u_amd_28*g_amd_28 -> 864
A10: Google TPU | B10: PB | D10: =u_tpu_26*g_tpu_26 -> 739.2 | E10: =u_tpu_27*g_tpu_27 -> 1375 | F10: =u_tpu_28*g_tpu_28 -> 2016
A11: AWS Trainium | B11: PB | D11: =u_trn_26*g_trn_26 -> 220 | E11: =u_trn_27*g_trn_27 -> 360 | F11: =u_trn_28*g_trn_28 -> 600
A12: 其他 ASIC（MTIA、Maia、Ascend 等） | B12: PB | D12: =u_oth_26*g_oth_26 -> 150 | E12: =u_oth_27*g_oth_27 -> 900 | F12: =u_oth_28*g_oth_28 -> 1250
A13: 需求合計（裝載） | B13: EB | D13: =SUM(D5:D12)/1000 -> 3.2893 | E13: =SUM(E5:E12)/1000 -> 6.1702 | F13: =SUM(F5:F12)/1000 -> 8.938 | G13: =F13*(1+hbm_dem29) -> 11.6194
A14: 需求 × 出貨係數（基準＝情境 A） | B14: EB | D14: =D13*hbm_gross -> 3.782695 | E14: =E13*hbm_gross -> 7.09573 | F14: =F13*hbm_gross -> 10.2787 | G14: =G13*hbm_gross -> 13.36231
A15: 加速器顆數合計 | B15: 百萬顆 | D15: =u_bw_26+u_rb_26+u_ru_26+u_hp_26+u_amd_26+u_tpu_26+u_trn_26+u_oth_26 -> 15.2 | E15: =u_bw_27+u_rb_27+u_ru_27+u_hp_27+u_amd_27+u_tpu_27+u_trn_27+u_oth_27 -> 23.7 | F15: =u_bw_28+u_rb_28+u_ru_28+u_hp_28+u_amd_28+u_tpu_28+u_trn_28+u_oth_28 -> 26.5 | H15: JPMorgan 2027：GPU 10.9M、ASIC 12.5M；情境 A 基準
A16: 每顆平均 HBM | B16: GB | D16: =D13*1000/D15 -> 216.40132 | E16: =E13*1000/E15 -> 260.34599 | F16: =F13*1000/F15 -> 337.28302
A17: 供給（三情境相同） | B17: EB | C17: =D17/(1+hbm_g26) -> 2.2251147 | D17: =D14 -> 3.782695 | E17: =D17*(1+hbm_sup27) -> 5.8631772 | F17: =E17*(1+hbm_sup28) -> 8.501607 | G17: =F17*(1+hbm_sup29) -> 11.477169 | H17: 2026 供給＝需求出貨（年中已成交）；供給不隨需求情境變（產能 2027 前已訂定）
A18: 顆數係數（A；2028–29 ÷ 基準，與台積電、Advantest 同一套） | B18: x | D18: 1 | E18: 1 | F18: =um28_A -> 1 | G18: =um29_A -> 1 | H18: 2026–27 無情境差異
A19: 顆數係數（B；2028–29 ÷ 基準，與台積電、Advantest 同一套） | B19: x | D19: 1 | E19: 1 | F19: =um28_B -> 0.8 | G19: =um29_B -> 0.85 | H19: 2026–27 無情境差異
A20: 顆數係數（C；2028–29 ÷ 基準，與台積電、Advantest 同一套） | B20: x | D20: 1 | E20: 1 | F20: =um28_C -> 0.6 | G20: =um29_C -> 0.6 | H20: 2026–27 無情境差異
A21: 需求 × 出貨係數（A） | B21: EB | D21: =D14*D18 -> 3.782695 | E21: =E14*E18 -> 7.09573 | F21: =F14*F18 -> 10.2787 | G21: =G14*G18 -> 13.36231
A22: 需求 × 出貨係數（B） | B22: EB | D22: =D14*D19 -> 3.782695 | E22: =E14*E19 -> 7.09573 | F22: =F14*F19 -> 8.22296 | G22: =G14*G19 -> 11.357964
A23: 需求 × 出貨係數（C） | B23: EB | D23: =D14*D20 -> 3.782695 | E23: =E14*E20 -> 7.09573 | F23: =F14*F20 -> 6.16722 | G23: =G14*G20 -> 8.017386
A24: 出貨＝MIN(需求, 供給)（A） | B24: EB | C24: =C17 -> 2.2251147 | D24: =MIN(D21,D17) -> 3.782695 | E24: =MIN(E21,E17) -> 5.8631772 | F24: =MIN(F21,F17) -> 8.501607 | G24: =MIN(G21,G17) -> 11.477169 | H24: 需求低於供給時出貨＝需求（閒置產能）
A25: 出貨＝MIN(需求, 供給)（B） | B25: EB | C25: =C17 -> 2.2251147 | D25: =MIN(D22,D17) -> 3.782695 | E25: =MIN(E22,E17) -> 5.8631772 | F25: =MIN(F22,F17) -> 8.22296 | G25: =MIN(G22,G17) -> 11.357964
A26: 出貨＝MIN(需求, 供給)（C） | B26: EB | C26: =C17 -> 2.2251147 | D26: =MIN(D23,D17) -> 3.782695 | E26: =MIN(E23,E17) -> 5.8631772 | F26: =MIN(F23,F17) -> 6.16722 | G26: =MIN(G23,G17) -> 8.017386
A27: 需求 − 供給（A；>0＝短缺） | B27: EB | D27: =D21-D17 -> 0 | E27: =E21-E17 -> 1.2325527 | F27: =F21-F17 -> 1.777093 | G27: =G21-G17 -> 1.8851405
A28: 需求 − 供給（B；>0＝短缺） | B28: EB | D28: =D22-D17 -> 0 | E28: =E22-E17 -> 1.2325527 | F28: =F22-F17 -> -0.27864701 | G28: =G22-G17 -> -0.11920597
A29: 需求 − 供給（C；>0＝短缺） | B29: EB | D29: =D23-D17 -> 0 | E29: =E23-E17 -> 1.2325527 | F29: =F23-F17 -> -2.334387 | G29: =G23-G17 -> -3.4597835
A30: HBM 單價（A） | B30: $/GB | C30: =hbm_mkt25/C24 -> 15.729526 | D30: =hbm_p26 -> 14.6 | E30: =D30*(1+hbm_p27) -> 26.28 | F30: =E30*(1+hbm_p28_A) -> 28.908 | G30: =F30*(1+hbm_p29_A) -> 27.4626
A31: HBM 單價（B） | B31: $/GB | C31: =hbm_mkt25/C24 -> 15.729526 | D31: =hbm_p26 -> 14.6 | E31: =D31*(1+hbm_p27) -> 26.28 | F31: =E31*(1+hbm_p28_B) -> 19.71 | G31: =F31*(1+hbm_p29_B) -> 19.71
A32: HBM 單價（C） | B32: $/GB | C32: =hbm_mkt25/C24 -> 15.729526 | D32: =hbm_p26 -> 14.6 | E32: =D32*(1+hbm_p27) -> 26.28 | F32: =E32*(1+hbm_p28_C) -> 15.768 | G32: =F32*(1+hbm_p29_C) -> 16.5564
A33: HBM 市場（A） | B33: $B | C33: =C24*C30 -> 35 | D33: =D24*D30 -> 55.227347 | E33: =E24*E30 -> 154.0843 | F33: =F24*F30 -> 245.76446 | G33: =G24*G30 -> 315.19291
A34: HBM 市場（B） | B34: $B | C34: =C25*C31 -> 35 | D34: =D25*D31 -> 55.227347 | E34: =E25*E31 -> 154.0843 | F34: =F25*F31 -> 162.07454 | G34: =G25*G31 -> 223.86546
A35: HBM 市場（C） | B35: $B | C35: =C26*C32 -> 35 | D35: =D26*D32 -> 55.227347 | E35: =E26*E32 -> 154.0843 | F35: =F26*F32 -> 97.244725 | G35: =G26*G32 -> 132.73905
A37: 對帳（樣板驗收 2）
A38: 由下而上：NVIDIA 裝載 HBM × 單價（2026） | B38: $B | D38: =(D5+D6+D7+D8)/1000*hbm_p26 -> 28.67586
A39: 由上而下：NVIDIA 資料中心營收 × 每顆 HBM ÷ 每顆 NVIDIA 內容（2026） | B39: $B | D39: =nv_dc26*nv_hbm/nv_content -> 38.972897 | H39: 橋接表 v0.2；與顆數預測獨立
A40: 差距 | B40: % | D40: =D38/D39-1 -> -0.26421021
A41: 由營收推得 NVIDIA 顆數 vs 顆數預測 | B41: 百萬顆 | D41: =nv_dc26/nv_content -> 8.7383178 | E41: =u_bw_26+u_rb_26+u_hp_26 -> 7.6 | H41: D＝營收推得；E＝顆數預測（2026）
...

Sheet TK_In
A1: TK_In — Tokenomics 取數（只讀鏡像；權威在算力收支）：20261025_Tokenomics_v21.7.xlsx（v21.7，commit 91d541f，擷取 2026-10-27）。綠字＝外部連結值，不得在本頁修改；Tokenomics 升版時以 tools/tokenomics/import_tokenomics.py 重抽快照再重建
A2: 右側 J–L 欄：company-models 下游目前讀的舊版快照（markets/chip_bridge v20.1）；M 欄＝與現行 TK 不同的格數（>0 表示下游用的值已過時）
A4: 名稱（TK） | B4: 世代／項目 | C4: 本庫名稱 | D4: 低 | E4: 基準 | F4: 高 | G4: 單位 | H4: TK 位置 | I4: 取用者 | J4: 舊快照 低 | K4: 舊快照 基準 | L4: 舊快照 高 | M4: 差異格數
A5: IF_RacksPerGW | B5: Hopper H100 | C5: TK_RacksPerGW_H100 | D5: 22439 | E5: 22439 | F5: 22439 | G5: 架 | H5: Interface!C6:Q6 | I5: chip_bridge、network（經橋接表） | J5: 22439 | K5: 22439 | L5: 22439 | M5: =(ABS(D5-J5)>0.000000001)+(ABS(E5-K5)>0.000000001)+(ABS(F5-L5)>0.000000001) -> 0
A6: IF_RacksPerGW | B6: GB200 NVL72 | C6: TK_RacksPerGW_GB200 | D6: 6969 | E6: 6969 | F6: 6969 | G6: 架 | H6: Interface!C6:Q6 | I6: chip_bridge、network（經橋接表） | J6: 6969 | K6: 6969 | L6: 6969 | M6: =(ABS(D6-J6)>0.000000001)+(ABS(E6-K6)>0.000000001)+(ABS(F6-L6)>0.000000001) -> 0
A7: IF_RacksPerGW | B7: GB300 NVL72 | C7: TK_RacksPerGW_GB300 | D7: 6764 | E7: 6764 | F7: 6764 | G7: 架 | H7: Interface!C6:Q6 | I7: chip_bridge、network（經橋接表） | J7: 6764 | K7: 6764 | L7: 6764 | M7: =(ABS(D7-J7)>0.000000001)+(ABS(E7-K7)>0.000000001)+(ABS(F7-L7)>0.000000001) -> 0
A8: IF_RacksPerGW | B8: VR200 NVL72 | C8: TK_RacksPerGW_VR200 | D8: 4052 | E8: 4052 | F8: 4052 | G8: 架 | H8: Interface!C6:Q6 | I8: chip_bridge、network（經橋接表） | J8: 4052 | K8: 4052 | L8: 4052 | M8: =(ABS(D8-J8)>0.000000001)+(ABS(E8-K8)>0.000000001)+(ABS(F8-L8)>0.000000001) -> 0
A9: IF_RacksPerGW | B9: Rubin Ultra（MGX NVL 單架，72 GPU） | C9: TK_RacksPerGW_RU | D9: 2705 | E9: 2705 | F9: 2705 | G9: 架 | H9: Interface!C6:Q6 | I9: chip_bridge、network（經橋接表） | J9: 2705 | K9: 2705 | L9: 2705 | M9: =(ABS(D9-J9)>0.000000001)+(ABS(E9-K9)>0.000000001)+(ABS(F9-L9)>0.000000001) -> 0
A10: IF_GPUsPerGW | B10: Hopper H100 | C10: TK_GPUsPerGW_H100 | D10: 718048 | E10: 718048 | F10: 718048 | G10: 顆 | H10: Interface!C7:Q7 | I10: chip_bridge | J10: 718048 | K10: 718048 | L10: 718048 | M10: =(ABS(D10-J10)>0.000000001)+(ABS(E10-K10)>0.000000001)+(ABS(F10-L10)>0.000000001) -> 0
A11: IF_GPUsPerGW | B11: GB200 NVL72 | C11: TK_GPUsPerGW_GB200 | D11: 501768 | E11: 501768 | F11: 501768 | G11: 顆 | H11: Interface!C7:Q7 | I11: chip_bridge | J11: 501768 | K11: 501768 | L11: 501768 | M11: =(ABS(D11-J11)>0.000000001)+(ABS(E11-K11)>0.000000001)+(ABS(F11-L11)>0.000000001) -> 0
A12: IF_GPUsPerGW | B12: GB300 NVL72 | C12: TK_GPUsPerGW_GB300 | D12: 487008 | E12: 487008 | F12: 487008 | G12: 顆 | H12: Interface!C7:Q7 | I12: chip_bridge | J12: 487008 | K12: 487008 | L12: 487008 | M12: =(ABS(D12-J12)>0.000000001)+(ABS(E12-K12)>0.000000001)+(ABS(F12-L12)>0.000000001) -> 0
A13: IF_GPUsPerGW | B13: VR200 NVL72 | C13: TK_GPUsPerGW_VR200 | D13: 291744 | E13: 291744 | F13: 291744 | G13: 顆 | H13: Interface!C7:Q7 | I13: chip_bridge | J13: 291744 | K13: 291744 | L13: 291744 | M13: =(ABS(D13-J13)>0.000000001)+(ABS(E13-K13)>0.000000001)+(ABS(F13-L13)>0.000000001) -> 0
A14: IF_GPUsPerGW | B14: Rubin Ultra（MGX NVL 單架，72 GPU） | C14: TK_GPUsPerGW_RU | D14: 194760 | E14: 194760 | F14: 194760 | G14: 顆 | H14: Interface!C7:Q7 | I14: chip_bridge | J14: 194760 | K14: 194760 | L14: 194760 | M14: =(ABS(D14-J14)>0.000000001)+(ABS(E14-K14)>0.000000001)+(ABS(F14-L14)>0.000000001) -> 0
A15: IF_CapexIT | B15: Hopper H100 | C15: TK_CapexIT_H100 | D15: 21.420269 | E15: 27.510214 | F15: 34.120743 | G15: $B | H15: Interface!C9:Q9 | I15: chip_bridge、network、delta、quanta 等（部署 GW 換算） | J15: 21.420269 | K15: 27.510214 | L15: 34.120743 | M15: =(ABS(D15-J15)>0.000000001)+(ABS(E15-K15)>0.000000001)+(ABS(F15-L15)>0.000000001) -> 0
A16: IF_CapexIT | B16: GB200 NVL72 | C16: TK_CapexIT_GB200 | D16: 20.63939 | E16: 24.015174 | F16: 27.650204 | G16: $B | H16: Interface!C9:Q9 | I16: chip_bridge、network、delta、quanta 等（部署 GW 換算） | J16: 20.63939 | K16: 24.015174 | L16: 27.650204 | M16: =(ABS(D16-J16)>0.000000001)+(ABS(E16-K16)>0.000000001)+(ABS(F16-L16)>0.000000001) -> 0
... A44: IF_StoragePerGPU | B44: Rubin Ultra（MGX NVL 單架，72 GPU） | C44: TK_StoragePerGPU_RU | D44: 300 | E44: 500 | F44: 800 | G44: $/GPU | H44: Interface!C366:Q366 | I44: chip_bridge（目前抄錄值） | J44: 300 | K44: 500 | L44: 800 | M44: =(ABS(D44-J44)>0.000000001)+(ABS(E44-K44)>0.000000001)+(ABS(F44-L44)>0.000000001) -> 0
A45: IF_NonNV_Out_AMD | B45: AMD MI455X（Helios）：產出比（每 GW 產出 ÷ VR200）（NonNV 第 5 列 B:D；同層級、同 SLO；Assumed；C＝低、D＝基準、E＝高） | C45: TK_NonNV_Out_AMD | D45: 0.7 | E45: 0.8 | F45: 1.15 | G45: 比（÷ VR200） | H45: Interface!C369:E369 | I45: avgo、mrvl、amd 等（目前各自假設，待改接）
A46: IF_NonNV_Out_TPU | B46: Google TPU v7 Ironwood：產出比（每 GW 產出 ÷ VR200）（NonNV 第 6 列 B:D；同層級、同 SLO；Assumed；C＝低、D＝基準、E＝高） | C46: TK_NonNV_Out_TPU | D46: 0.6 | E46: 0.8 | F46: 1.1 | G46: 比（÷ VR200） | H46: Interface!C370:E370 | I46: avgo、mrvl、amd 等（目前各自假設，待改接）
A47: IF_NonNV_Out_Trn | B47: AWS Trainium3：產出比（每 GW 產出 ÷ VR200）（NonNV 第 7 列 B:D；同層級、同 SLO；Assumed；C＝低、D＝基準、E＝高） | C47: TK_NonNV_Out_Trn | D47: 0.3 | E47: 0.5 | F47: 0.8 | G47: 比（÷ VR200） | H47: Interface!C371:E371 | I47: avgo、mrvl、amd 等（目前各自假設，待改接）
A48: IF_NonNV_Out_CS | B48: Cerebras WSE-3：產出比（每 GW 產出 ÷ VR200）（NonNV 第 8 列 B:D；同層級、同 SLO；Assumed；C＝低、D＝基準、E＝高） | C48: TK_NonNV_Out_CS | D48: 0.2 | E48: 0.4 | F48: 0.8 | G48: 比（÷ VR200） | H48: Interface!C372:E372 | I48: avgo、mrvl、amd 等（目前各自假設，待改接）
A49: IF_NonNV_Out_OAI | B49: OpenAI／Broadcom 客製：產出比（每 GW 產出 ÷ VR200）（NonNV 第 9 列 B:D；同層級、同 SLO；Assumed；C＝低、D＝基準、E＝高） | C49: TK_NonNV_Out_OAI | D49: 0.4 | E49: 0.6 | F49: 0.9 | G49: 比（÷ VR200） | H49: Interface!C373:E373 | I49: avgo、mrvl、amd 等（目前各自假設，待改接）
A50: IF_NonNV_Out_Ascend | B50: 華為昇騰 910C（CloudMatrix 384）：產出比（每 GW 產出 ÷ VR200）（NonNV 第 10 列 B:D；同層級、同 SLO；Assumed；C＝低、D＝基準、E＝高） | C50: TK_NonNV_Out_Ascend | D50: 0.05 | E50: 0.08 | F50: 0.15 | G50: 比（÷ VR200） | H50: Interface!C379:E379 | I50: avgo、mrvl、amd 等（目前各自假設，待改接）
A51: IF_NonNV_Out_Maia | B51: Microsoft Maia 200：產出比（每 GW 產出 ÷ VR200）（NonNV 第 11 列 B:D；同層級、同 SLO；Assumed；C＝低、D＝基準、E＝高） | C51: TK_NonNV_Out_Maia | D51: 0.25 | E51: 0.55 | F51: 0.75 | G51: 比（÷ VR200） | H51: Interface!C380:E380 | I51: avgo、mrvl、amd 等（目前各自假設，待改接）
A52: IF_NonNV_Hold_AMD | B52: AMD MI455X（Helios）：持有成本比（每 GW 持有成本 ÷ VR200）（NonNV 第 5 列 E:G；同層級、同 SLO；Assumed；C＝低、D＝基準、E＝高） | C52: TK_NonNV_Hold_AMD | D52: 0.67 | E52: 0.85 | F52: 1.12 | G52: 比（÷ VR200） | H52: Interface!C374:E374 | I52: avgo、mrvl、amd 等（目前各自假設，待改接）
A53: IF_NonNV_Hold_TPU | B53: Google TPU v7 Ironwood：持有成本比（每 GW 持有成本 ÷ VR200）（NonNV 第 6 列 E:G；同層級、同 SLO；Assumed；C＝低、D＝基準、E＝高） | C53: TK_NonNV_Hold_TPU | D53: 0.65 | E53: 0.7 | F53: 0.9 | G53: 比（÷ VR200） | H53: Interface!C375:E375 | I53: avgo、mrvl、amd 等（目前各自假設，待改接）
A54: IF_NonNV_Hold_Trn | B54: AWS Trainium3：持有成本比（每 GW 持有成本 ÷ VR200）（NonNV 第 7 列 E:G；同層級、同 SLO；Assumed；C＝低、D＝基準、E＝高） | C54: TK_NonNV_Hold_Trn | D54: 0.45 | E54: 0.61 | F54: 0.7 | G54: 比（÷ VR200） | H54: Interface!C376:E376 | I54: avgo、mrvl、amd 等（目前各自假設，待改接）
A55: IF_NonNV_Hold_CS | B55: Cerebras WSE-3：持有成本比（每 GW 持有成本 ÷ VR200）（NonNV 第 8 列 E:G；同層級、同 SLO；Assumed；C＝低、D＝基準、E＝高） | C55: TK_NonNV_Hold_CS | D55: 0.8 | E55: 1 | F55: 1.2 | G55: 比（÷ VR200） | H55: Interface!C377:E377 | I55: avgo、mrvl、amd 等（目前各自假設，待改接）
A56: IF_NonNV_Hold_OAI | B56: OpenAI／Broadcom 客製：持有成本比（每 GW 持有成本 ÷ VR200）（NonNV 第 9 列 E:G；同層級、同 SLO；Assumed；C＝低、D＝基準、E＝高） | C56: TK_NonNV_Hold_OAI | D56: 0.7 | E56: 0.8 | F56: 1 | G56: 比（÷ VR200） | H56: Interface!C378:E378 | I56: avgo、mrvl、amd 等（目前各自假設，待改接）
... A58: IF_NonNV_Hold_Maia | B58: Microsoft Maia 200：持有成本比（每 GW 持有成本 ÷ VR200）（NonNV 第 11 列 E:G；同層級、同 SLO；Assumed；C＝低、D＝基準、E＝高） | C58: TK_NonNV_Hold_Maia | D58: 0.4 | E58: 0.5 | F58: 0.6 | G58: 比（÷ VR200） | H58: Interface!C382:E382 | I58: avgo、mrvl、amd 等（目前各自假設，待改接）
A60: 下游舊快照與現行 TK 不同的格數 | M60: =SUM(M5:M58) -> 0

Sheet Conflicts
A1: Conflicts — 跨模型衝突登錄：同一個行業變數在兩個以上公司模型有不同值。本庫的任務是讓每個變數只有一個值；建議值為 Claude 預設（判斷類，Andy 可改），在對應子產業併入本庫的版本生效，生效前各公司模型維持現值
A3: ID | B3: 子產業 | C3: 變數 | D3: 單位 | E3: 模型甲（位置） | F3: 甲值 | G3: 模型乙（位置） | H3: 乙值 | I3: 性質 | J3: 建議單一值與理由 | K3: 生效版本 | L3: 狀態 | M3: 來源
A4: CF01 | B4: 載板 | C4: 南電 2027–29 資本支出（新廠是否已核准） | D4: NT$億 | E4: nanya_pcb In!I104（待董事會決議） | F4: 140／180／120 | G4: 工商時報 2026-08-07：董事會已通過高階載板新廠 | H4: 新廠 468 | I4: 過時（公司變數） | J4: 屬公司變數，不入本庫；南電模型下次改版更新為已核准，資本支出依新廠時程重排 | K4: 南電下版 | L4: 移到南電分部重建（部分符合 25 檔，預計 11-07）：屬公司變數，新廠 468 億的時程排入南電資本支出；本庫不收 | M4: 算力收支 2026-10-25 A1
A5: CF02 | B5: 載板 | C5: 欣興 2026 資本支出 | D5: NT$億 | E5: unimicron In!E99 | F5: 537 | G5: ibiden In!H52（同業對照） | H5: 340 | I5: 過時 | J5: 以欣興模型 537（較新）為準；Ibiden 對照列下版改讀欣興成品 | K5: v0.4 | L5: 已併入 v0.8.3（Ibiden 份額相對值 abf_ibrel_28 的來源文字改以欣興 537 億為準；數值不變） | M5: 算力收支 2026-10-25 A2
A6: CF03 | B6: 載板 | C6: ABF 供需缺口 2026／27／28 | D6: % | E6: unimicron In!E131（永豐） | F6: 8／27／35 | G6: ibiden 模型與比對 I9 | H6: —／約 21／逾 40 | I6: 行業變數（兩來源） | J6: 本庫設單一路徑：基準取兩來源中點（2027 約 24%、2028 約 37%），低／高為兩來源；Ibiden、欣興、南電、景碩、味之素改讀 | K6: v0.4 | L6: 待 Andy（各載板與膜模型的滿足率是否改讀本庫缺口；預設不改）：v0.5.1 ABF 供需表已建（ABF 頁）：本庫推導缺口情境 A 2027／28／29＝15.6／11.0／12.3%（外部 24／37%、各公司自算 1.6–14.1%）；味之素膜上限取低值時為 24.6／27.3／34.1%。待 Andy：各載板與膜模型是否改讀本庫缺口（會改變 EPS）；未改前各公司仍用自身滿足率 | M6: 算力收支 2026-10-25 A3
