Workbook

Sheet README
A1: 聯電（2303.TW；ADR UMC）個股模型 v0.1（AI 半導體 Project：代工層，成熟製程晶圓代工；樣板 guc/、營收結構參考 tsmc/） 2026-10-31
A2: 版本：v0.1（初版）。營收＝成熟製程晶圓（產能 × 稼動率 × 美元售價 × 匯率）＋AI 相關（先進封裝矽中介層、矽光子）＋Intel 12 奈米合作。滾入 3Q26 實績（2026-10-28 財報）與 4Q26 指引。本版未做先驗。
A3: 模型命題：聯電的獲利由成熟製程（22／28 奈米以上）的稼動率與價格循環決定。3Q26 稼動率回到 92%、毛利率 34.0%，公司估 2027 年平均售價年增約一成；AI 帶動的周邊（先進封裝矽中介層、矽光子，以及 OLED 驅動 IC、Wi-Fi 7、車用雷達等 22／28 奈米需求）與 Intel 12 奈米合作是增量，中國成熟製程擴產是價格的下行風險。
A4: 核心問題：稼動率與美元售價回升能走多遠（情境 A 稼動率 95%、售價 +10%），AI 相關與 Intel 合作在 FY2029 能補多少（模型情境 A 約 10 億＋5 億美元，不到營收一成）；現價約 20 倍前瞻 P/E，比聯電自己 10 年 Bloomberg 前瞻 P/E 中位數 15.2 倍高多少。
A6: 會計年度＝日曆年，FY(t)＝CY(t)，不平移。FY2025A 實績、FY2026 錨點（1Q–3Q26 實績＋4Q26 指引）、FY2027–FY2029 驅動因子推導、FY2030–FY2032 收斂法。金額：十億新台幣；EPS：新台幣（基本）；口徑：歸屬母公司淨利（TIFRS）。晶圓：千片 12 吋約當。
A8: 驅動因子 → 推導量（行業變數讀 Siliconomics；成熟製程稼動率與售價為公司層級，待併入 Siliconomics）
A9: 成熟製程晶圓：產能（FY2026 由各季出貨 ÷ 稼動率推得約 5,230 千片；FY2027–29 年增 4%／7%／7%，新加坡 P4 與台南新廠）× 稼動率（A／B／C：FY2027 95%／90%／82%、FY2028 94%／87%／76%、FY2029 93%／88%／80%）× 美元售價（FY2026 約 1,878 美元；FY2027 +10%／+5%／0、FY2028 +3%／0／−6%、FY2029 +2%／0／−3%）× 匯率 32（Siliconomics fx_twd）。
A10: 新業務：AI 相關 FY2026 3 億美元（公司）、FY2027 +60%／+40%／+20%、之後年增 45% 再乘 Siliconomics 同字母顆數係數（um28、um29）；Intel 12 奈米 FY2028 2.5／1.2／0 億美元、FY2029 5／3／0.8 億美元；新業務邊際貢獻率 45%（Assumed）。
A11: 成本：銷貨成本內折舊（FY2026 約 562 億元＝9M26 折舊年化 × 0.9；年增 12%／10%／8%）＋每片現金成本（FY2026 殘差，年增 2%）；營業費用彈性 0.5、年增下限 3%；營業外每年 40 億元（不外推 2Q26 一次性約 302 億元）、稅率 15%、股數 124.5 億股。
A12: 校準：FY2026 ＝ 1Q–3Q26 實績（公司 6-K）＋4Q26 公司指引（出貨 +2%、售價持穩、毛利率 34%、稼動率 92%）。成熟製程售價與每片現金成本以 FY2026 校準；不用券商數字（只在 Recon 對帳）。
A13: 估值：Val 第 0 節目標價＝0.5 × DCF 目標價（股東現金流＝EPS ×（1 − g／ROE），FY2027–32 明確期＋永續，r 10%、g 4%，三情境權重 0.3／0.5／0.2，情境價值負值取 0）＋0.5 × Comparable 目標價（台積電、格芯、中芯港股、高塔、世界先進前瞻 P/E 中位數 × 12 個月後前瞻 EPS，再乘相對倍數調整係數；不含 A 股）；另列 Comparable 單獨目標價、市場共識目標價與差距拆解。十年 P/E 規則值 × FY2027 EPS 保留為參考（不是目標價）。本版未做先驗，無 Andy 合理 P/E 對照。
A14: 預估期間：FY2027–FY2029 由驅動因子推導；FY2030 起為收斂法，非驅動因子推導（營收年增由 FY2029 線性收斂到 fade_g、淨利率收斂到 fade_m，FY2032 達到；PL 頁灰底）。十年平均淨利率未找到，B、C 依工作單以 FY2029 × 0.8 代替。
... A21: 公司特有：稼動率 FY2027 95%／90%／82%、FY2028 94%／87%／76%、FY2029 93%／88%／80%；售價 FY2027 +10%／+5%／0、FY2028 +3%／0／−6%、FY2029 +2%／0／−3%（C＝中國成熟製程擴產的價格壓力）；AI 相關 FY2027 +60%／+40%／+20%；Intel 12 奈米 FY2028 2.5／1.2／0、FY2029 5／3／0.8 億美元。
A23: ="投資建議："&Val!B135&"（依上檔空間固定規則）" -> 投資建議：放空（依上檔空間固定規則）
A24: ="重點觀察 1：目標價 NT$"&TEXT(Val!$B$39,"#,##0.00")&"（DCF "&TEXT(Val!$B$24,"#,##0.00")&"、Comparable（相對倍數調整後）"&TEXT(tp_comp_adj,"#,##0.00")&"；DCF 權重 "&TEXT(tp_w_dcf,"0%")&"），比現價 "&TEXT(px,"#,##0.00")&"（2026-10-22）"&IF(Val!$B$42>=0,"高 "&TEXT(Val!$B$42,"0.0%"),"低 "&TEXT(-Val!$B$42,"0.0%"))&"，級距 "&Val!$B$134&"、投資建議 "&Val!$B$135&"。相對倍數調整係數 "&TEXT(rm_factor,"0.00")&"（本公司 10 年前瞻倍數中位數 ÷ 同業的中位數，夾在 0.5–2.0；Val 第 0.5 節），調整前加權上檔空間 "&TEXT((tp_w_dcf*Val!$B$24+(1-tp_w_dcf)*Val!$B$35)/px-1,"+0.0%;−0.0%")&"；Comparable 單獨（市場主流同業法、未調整）為 "&TEXT(Val!$B$43,"+0.0%;−0.0%")&"。" -> 重點觀察 1：目標價 NT$76.40（DCF 82.47、Comparable（相對倍數調整後）70.34；DCF 權重 50%），比現價 125.50（2026-10-22）低 39.1%，級距 −25%～−50%、投資建議 放空。相對倍數調整係數 0.50（本公司 10 年前瞻倍數中位數 ÷ 同業的中位數，夾在 0.5–2.0；Val 第 0.5 節），調整前加權上檔空間 −11.1%；Comparable 單獨（市場主流同業法、未調整）為 +12.1%。
A25: 重點觀察 2：下檔主因有二：(1) 相對倍數調整係數 0.5——聯電 10 年 Bloomberg 前瞻 P/E 中位數 15.2 倍，只有台積電與中芯（港股）中位數的中位數 32.3 倍的 0.47（觸及下限 0.5；格芯、高塔、世界先進資料不足未納入），Comparable 因此由 140.7 減半為 70.3；若不調整，加權目標價約 111.6（−11%，中立）。(2) DCF 82.5 偏低：ROE 近三年平均 13.9%、再投資率 29%，情境 B 的 FY2027–29 EPS 只有 5.95／5.85／6.53（FY2026 的 7.36 含 2Q26 一次性投資收益約 2.0 元）。EPS 因素與倍數因素都只有 −3%，與市場共識的差距不在獲利預估，而在相對倍數調整與 DCF。
A26: 重點觀察 3：稼動率與售價是承重變數：3Q26 稼動率 92%、4Q26 指引低 90% 區間，公司估 2027 年平均售價年增約一成（情境 A 照用、B 取 +5%、C 持平）；售價 ±3% 使加權目標價 ±10.2%、匯率 30.5 使 −16.5%，AI 相關營收 ±30% 只有 ±2.9%。下一個檢驗點是 2027-01 下旬的 4Q26 法說（2027 年售價、折舊與資本支出指引；日期未公告）與 Intel 12 奈米 2027 年試產進度。
A28: 相對倍數調整（tools/relative_multiple.py；Val 第 0.5 節）已含在加權目標價：Comparable（相對倍數調整後）＝同業前瞻倍數中位數 × 本公司 10 年相對同業的倍數比（Bloomberg 前瞻倍數）。「Comparable 目標價（市場主流同業法）」維持不調整。重點觀察的數字以本版重算值撰寫（第 1 點第一句為公式）。
A30: v0.1（2026-10-31）：依個股模型原則第 8 節調整 In 頁呈現（數值不變）。In 頁 D／F 欄名改「敏感度低」「敏感度高」（只用於 Sens 頁、不進目標價）；In 頁最後新增「情境驅動對照」一節，把上方各情境專屬輸入三情境並排（只引用上方各列，純展示）；HTML 驅動因子一節分「情境驅動」與「單一參數」兩張表。

Sheet In
A1: In — 輸入（藍字；基準欄 E，低 D、高 F）。金額：十億新台幣（NT$B）；晶圓：千片（12 吋約當）；售價：美元／片；匯率：新台幣／美元。公司財報與法說為 Interested-party（公司說法）或 Verified（財報數字）；券商、資料商、媒體為 Interested-party。【v0.1】基準欄 E 進主模型；D／F＝敏感度低／高，只用於 Sens 頁（一次動一個參數）、不進目標價；情境 A／B／C 的驅動見本頁最後一節「情境驅動對照」。
A2: 標記：Verified／Interested-party／Analogy／Assumed／Derived；Analogy、Assumed 以情境或 Sens 區間呈現，不當點估計。行業變數讀 Siliconomics v0.10（siliconomics/data/siliconomics_snapshot_v0.10.json）；成熟製程稼動率與售價屬公司層級，說明欄標「待併入 Siliconomics」。SemiAnalysis 未使用
A3: 鍵 | B3: 項目 | C3: 單位 | D3: 敏感度低 | E3: 基準 | F3: 敏感度高 | G3: 標記 | H3: 來源1 | I3: 來源2／說明
A4: A. 行業變數（Siliconomics v0.10（siliconomics/data/siliconomics_snapshot_v0.10.json）；A／B／C 讀同字母上游，不自訂行業路徑）
A5: fx | B5: 匯率（FY2027 起；美元售價換算） | C5: NT$/US$ | D5: 30.5 | E5: 32 | F5: 33 | G5: Assumed | H5: Siliconomics v0.10（siliconomics/data/siliconomics_snapshot_v0.10.json）｜fx_twd | I5: Siliconomics 共用匯率（2026–2029）；與台積電、聯發科等台股模型同值
A6: um28_A | B6: 情境 A：CY2028 AI 加速器顆數 ÷ 基準 | C6: x | E6: 1 | G6: Derived | H6: Siliconomics v0.10（siliconomics/data/siliconomics_snapshot_v0.10.json）｜um28_A | I6: AI 相關營收 CY2028–29 依同字母顆數係數縮放（行業情境；A＝基準）
A7: um29_A | B7: 情境 A：CY2029 AI 加速器顆數 ÷ 基準 | C7: x | E7: 1 | G7: Derived | H7: Siliconomics v0.10（siliconomics/data/siliconomics_snapshot_v0.10.json）｜um29_A | I7: 同上
A8: um28_B | B8: 情境 B：CY2028 AI 加速器顆數 ÷ 基準 | C8: x | E8: 0.8 | G8: Assumed | H8: Siliconomics v0.10（siliconomics/data/siliconomics_snapshot_v0.10.json）｜um28_B | I8: 同上
A9: um29_B | B9: 情境 B：CY2029 AI 加速器顆數 ÷ 基準 | C9: x | E9: 0.85 | G9: Assumed | H9: Siliconomics v0.10（siliconomics/data/siliconomics_snapshot_v0.10.json）｜um29_B | I9: 同上
A10: um28_C | B10: 情境 C：CY2028 AI 加速器顆數 ÷ 基準 | C10: x | E10: 0.6 | G10: Assumed | H10: Siliconomics v0.10（siliconomics/data/siliconomics_snapshot_v0.10.json）｜um28_C | I10: 同上
A11: um29_C | B11: 情境 C：CY2029 AI 加速器顆數 ÷ 基準 | C11: x | E11: 0.6 | G11: Assumed | H11: Siliconomics v0.10（siliconomics/data/siliconomics_snapshot_v0.10.json）｜um29_C | I11: 同上
A12: B. 產能與稼動率（12 吋約當；公司層級，待併入 Siliconomics：Siliconomics 尚無成熟製程稼動率）
A13: cap_26 | B13: FY2026 產能（12 吋約當，千片／年） | C13: 千片 | E13: =Q!G7 -> 5230.4685 | G13: Derived | H13: Q 頁：各季出貨 ÷ 稼動率（1Q–3Q26 實績、4Q26 指引） | I13: 公司未揭露產能；以出貨與稼動率推得（Derived）
A14: capg27 | B14: FY2027 產能年增 | C14: % | E14: 0.04 | G14: Assumed | H14: 公司：董事會核准新加坡 P4、台南新廠擴產預算約 1,487 億元（2026-07-29）與約 1,028 億元（2026-10-28；6-K） | I14: 三情境相同（產能為公司已核准的擴產；待併入 Siliconomics）
A15: capg28 | B15: FY2028 產能年增 | C15: % | E15: 0.07 | G15: Assumed | H15: 同上；Fab12i P3 量產時程：未找到 | I15: 三情境相同（產能為公司已核准的擴產；待併入 Siliconomics）
A16: capg29 | B16: FY2029 產能年增 | C16: % | E16: 0.07 | G16: Assumed | H16: 同上 | I16: 三情境相同（產能為公司已核准的擴產；待併入 Siliconomics）
A17: cap_adj | B17: 產能係數（Sens 用；FY2027 起各年同乘） | C17: x | D17: 0.95 | E17: 1 | F17: 1.05 | G17: Assumed | H17: 無 | I17: ±5%：擴產時程提前或延後
A18: ut27_A | B18: FY2027 平均稼動率（情境 A） | C18: % | E18: 0.95 | G18: Assumed | H18: 公司：3Q26 稼動率 92%、4Q26 指引低 90% 區間（6-K）；1Q26 79%、2Q26 85% | I18: A 最有利、C 最不利（C＝中國成熟製程擴產的價格與份額壓力）；待併入 Siliconomics
A19: ut27_B | B19: FY2027 平均稼動率（情境 B） | C19: % | E19: 0.9 | G19: Assumed | H19: 同上 | I19: 待併入 Siliconomics
A20: ut27_C | B20: FY2027 平均稼動率（情境 C） | C20: % | E20: 0.82 | G20: Assumed | H20: 同上 | I20: 待併入 Siliconomics
A21: ut28_A | B21: FY2028 平均稼動率（情境 A） | C21: % | E21: 0.94 | G21: Assumed | H21: 同上 | I21: A 最有利、C 最不利（C＝中國成熟製程擴產的價格與份額壓力）；待併入 Siliconomics
A22: ut28_B | B22: FY2028 平均稼動率（情境 B） | C22: % | E22: 0.87 | G22: Assumed | H22: 同上 | I22: 待併入 Siliconomics
A23: ut28_C | B23: FY2028 平均稼動率（情境 C） | C23: % | E23: 0.76 | G23: Assumed | H23: 同上 | I23: 待併入 Siliconomics
A24: ut29_A | B24: FY2029 平均稼動率（情境 A） | C24: % | E24: 0.93 | G24: Assumed | H24: 同上 | I24: A 最有利、C 最不利（C＝中國成熟製程擴產的價格與份額壓力）；待併入 Siliconomics
A25: ut29_B | B25: FY2029 平均稼動率（情境 B） | C25: % | E25: 0.88 | G25: Assumed | H25: 同上 | I25: 待併入 Siliconomics
A26: ut29_C | B26: FY2029 平均稼動率（情境 C） | C26: % | E26: 0.8 | G26: Assumed | H26: 同上 | I26: 待併入 Siliconomics
A27: ut_adj | B27: 稼動率調整（Sens 用；FY2027 起各年加減，上限 98%） | C27: pt | D27: -0.03 | E27: 0 | F27: 0.03 | G27: Assumed | H27: 無 | I27: ±3 個百分點
A28: C. 平均售價（美元，每片 12 吋約當；公司層級，待併入 Siliconomics：Siliconomics 尚無成熟製程價格）
A29: asp_26 | B29: FY2026 平均售價（成熟製程晶圓；美元／片） | C29: US$/片 | E29: =(a26_rev-ai_26*fx_26)/a26_ship/fx_26*1000000 -> 1878.1749 | G29: Derived | H29: （FY2026 營收 − AI 相關）÷ 出貨 ÷ 匯率 | I29: 校準年；FY2027 起依情境年增
A30: asp27_A | B30: FY2027 平均售價年增（美元；情境 A） | C30: % | E30: 0.1 | G30: Assumed | H30: 優分析 2026-10-28（3Q26 法說轉述）：公司估 2027 年平均售價年增約一成（22 奈米份額與產品組合）；摩根士丹利：8 吋代工 2027 年漲價 | I30: A＝漲價延續；C＝中國成熟製程擴產造成價格壓力；待併入 Siliconomics
A31: asp27_B | B31: FY2027 平均售價年增（美元；情境 B） | C31: % | E31: 0.05 | G31: Assumed | H31: 同上 | I31: 待併入 Siliconomics
A32: asp27_C | B32: FY2027 平均售價年增（美元；情境 C） | C32: % | E32: 0 | G32: Assumed | H32: 同上 | I32: 待併入 Siliconomics
A33: asp28_A | B33: FY2028 平均售價年增（美元；情境 A） | C33: % | E33: 0.03 | G33: Assumed | H33: 同上 | I33: A＝漲價延續；C＝中國成熟製程擴產造成價格壓力；待併入 Siliconomics
A34: asp28_B | B34: FY2028 平均售價年增（美元；情境 B） | C34: % | E34: 0 | G34: Assumed | H34: 同上 | I34: 待併入 Siliconomics
A35: asp28_C | B35: FY2028 平均售價年增（美元；情境 C） | C35: % | E35: -0.06 | G35: Assumed | H35: 同上 | I35: 待併入 Siliconomics
A36: asp29_A | B36: FY2029 平均售價年增（美元；情境 A） | C36: % | E36: 0.02 | G36: Assumed | H36: 同上 | I36: A＝漲價延續；C＝中國成熟製程擴產造成價格壓力；待併入 Siliconomics
A37: asp29_B | B37: FY2029 平均售價年增（美元；情境 B） | C37: % | E37: 0 | G37: Assumed | H37: 同上 | I37: 待併入 Siliconomics
A38: asp29_C | B38: FY2029 平均售價年增（美元；情境 C） | C38: % | E38: -0.03 | G38: Assumed | H38: 同上 | I38: 待併入 Siliconomics
A39: asp_adj | B39: 售價水準調整（Sens 用；FY2027 起各年同乘 1＋x） | C39: % | D39: -0.03 | E39: 0 | F39: 0.03 | G39: Assumed | H39: 無 | I39: ±3%
A40: D. 新業務：AI 相關（先進封裝矽中介層、矽光子）與 Intel 12 奈米合作（美元營收；毛利以邊際貢獻率計）
...

Sheet Q
A1: Q — 實績與 FY2026 錨點（十億新台幣；EPS 為新台幣、基本；股數為十億股；晶圓為千片 12 吋約當）。藍字＝輸入（公司 6-K、stockanalysis）；黑字＝公式
A2: FY2026 錨點＝1Q、2Q、3Q26 實績（3Q26 財報 2026-10-28 公布；季值＝累計 − 上半年）＋4Q26 公司指引（出貨低個位數成長、售價持穩、毛利率與上季相當、稼動率低 90%）
A3: 項目 | B3: FY2025A | C3: 1Q26（實績） | D3: 2Q26（實績） | E3: 3Q26（實績） | F3: 4Q26（模型） | G3: FY2026 錨點 | H3: 標記 | I3: 來源1 | J3: 來源2／說明
A4: 營收 | B4: 237.553 | C4: 61.038 | D4: =129.771-C4 -> 68.733 | E4: =204.01-129.771 -> 74.239 | F4: =E4*(1+q4_ship)*(1+q4_asp) -> 75.72378 | G4: =SUM(C4:F4) -> 279.73378 | H4: Verified／Interested-party（4Q 指引） | I4: 公司 6-K：FY2025 與 4Q25（2026-01-28）、1Q26、2Q26（2026-07-29）、3Q26（2026-10-28）；FY2025 損益：stockanalysis 財報頁 | J4: 1H26 1,297.71 億、9M26 2,040.10 億（6-K）；4Q26＝3Q26 ×（1＋出貨季增）×（1＋售價變動）
A5: 晶圓出貨（千片，12 吋約當） | C5: =D5/(1+0.106) -> 1011.1752 | D5: =E5/(1+0.073) -> 1118.3597 | E5: 1200 | F5: =E5*(1+q4_ship) -> 1224 | G5: =SUM(C5:F5) -> 4553.5349 | H5: Interested-party／Derived | I5: 公司：3Q26 出貨超過 120 萬片 12 吋約當（創新高，季增 7.3%）；2Q26 季增 10.6%；1Q26 季增 2.7% | J5: 3Q26 取下限 1,200 千片；前兩季以季增率回推（Derived）
A6: 稼動率 | C6: 0.79 | D6: 0.85 | E6: 0.92 | F6: =q4_ut -> 0.92 | G6: =G5/G7 -> 0.87057878 | H6: Verified | I6: 公司 6-K：1Q26 79%、2Q26 85%、3Q26 92% | J6: FY2026 欄＝出貨合計 ÷ 產能合計
A7: 產能（千片，12 吋約當） | C7: =C5/C6 -> 1279.9686 | D7: =D5/D6 -> 1315.7173 | E7: =E5/E6 -> 1304.3478 | F7: =F5/F6 -> 1330.4348 | G7: =SUM(C7:F7) -> 5230.4685 | H7: Derived | I7: 出貨 ÷ 稼動率 | J7: 公司未揭露產能
A8: 平均售價（全部營收 ÷ 出貨；美元／片） | C8: =C4/C5/fx_26*1000000 -> 1910.2351 | D8: =D4/D5/fx_26*1000000 -> 1944.8974 | E8: =E4/E5/fx_26*1000000 -> 1957.7795 | F8: =F4/F5/fx_26*1000000 -> 1957.7795 | G8: =G4/G5/fx_26*1000000 -> 1944.0577 | H8: Derived | I8: 營收 ÷ 出貨 ÷ 匯率 | J8: 含 AI 相關營收；模型的成熟製程售價另扣 AI 相關（In 頁 asp_26）
A9: 毛利 | B9: 68.906 | C9: 17.818 | D9: =40.141-C9 -> 22.323 | E9: =65.346-40.141 -> 25.205 | F9: =F4*q4_gm -> 25.746085 | G9: =SUM(C9:F9) -> 91.092085 | H9: Verified／Interested-party（4Q 指引） | I9: 公司 6-K：FY2025 與 4Q25（2026-01-28）、1Q26、2Q26（2026-07-29）、3Q26（2026-10-28）；FY2025 損益：stockanalysis 財報頁 | J9: 1H26 毛利 401.41 億、9M26 653.46 億（6-K）
A10: 毛利率 | B10: =B9/B4 -> 0.2900658 | C10: =C9/C4 -> 0.29191651 | D10: =D9/D4 -> 0.32477849 | E10: =E9/E4 -> 0.33951158 | F10: =F9/F4 -> 0.34 | G10: =G9/G4 -> 0.32563849 | H10: Derived | I10: — | J10: 公司：1Q26 29.2%、2Q26 32.5%、3Q26 34.0%
A11: 營業費用 | B11: =B9-B12 -> 25.056 | C11: =C9-C12 -> 6.542 | D11: =D9-D12 -> 7.373 | E11: =E9-E12 -> 6.562 | F11: =q4_opx -> 6.75886 | G11: =SUM(C11:F11) -> 27.23586 | H11: Derived／Assumed | I11: 公司 6-K：FY2025 與 4Q25（2026-01-28）、1Q26、2Q26（2026-07-29）、3Q26（2026-10-28）；FY2025 損益：stockanalysis 財報頁 | J11: 毛利 − 營業利益
A12: 營業利益 | B12: 43.85 | C12: 11.276 | D12: =26.226-C12 -> 14.95 | E12: =44.869-26.226 -> 18.643 | F12: =F9-F11 -> 18.987225 | G12: =SUM(C12:F12) -> 63.856225 | H12: Verified／Derived | I12: 公司 6-K：FY2025 與 4Q25（2026-01-28）、1Q26、2Q26（2026-07-29）、3Q26（2026-10-28）；FY2025 損益：stockanalysis 財報頁 | J12: 1H26 262.26 億、9M26 448.69 億（6-K）
A13: 營業外淨額 | B13: =B14-B12 -> 5.805 | C13: =C14-C12 -> 5.368 | D13: =D14-D12 -> 30.236 | E13: =E14-E12 -> 1.268 | F13: =q4_nonop -> 1.5 | G13: =SUM(C13:F13) -> 38.372 | H13: Derived／Assumed | I13: 公司 6-K：FY2025 與 4Q25（2026-01-28）、1Q26、2Q26（2026-07-29）、3Q26（2026-10-28）；FY2025 損益：stockanalysis 財報頁 | J13: 稅前 − 營業利益；2Q26 含投資與股利收益約 302 億（優分析）
A14: 稅前利益 | B14: 49.655 | C14: 16.644 | D14: =61.83-C14 -> 45.186 | E14: =81.741-61.83 -> 19.911 | F14: =F12+F13 -> 20.487225 | G14: =SUM(C14:F14) -> 102.22823 | H14: Verified／Derived | I14: 公司 6-K：FY2025 與 4Q25（2026-01-28）、1Q26、2Q26（2026-07-29）、3Q26（2026-10-28）；FY2025 損益：stockanalysis 財報頁 | J14: FY2025 由 stockanalysis 稅前淨利率推得；1H26 618.30 億、9M26 817.41 億（6-K）
A15: 所得稅 | B15: =B14-B17-B18 -> 7.939 | C15: =C14-C17-C18 -> 0.527 | D15: =D14-D17-D18 -> 2.962 | E15: =E14-E17-E18 -> 3.522 | F15: =F14*q4_tax -> 3.4828283 | G15: =SUM(C15:F15) -> 10.493828 | H15: Derived／Assumed | I15: 公司 6-K：FY2025 與 4Q25（2026-01-28）、1Q26、2Q26（2026-07-29）、3Q26（2026-10-28）；FY2025 損益：stockanalysis 財報頁 | J15: 稅前 −（歸屬母公司淨利＋非控制權益）
A16: 有效稅率 | B16: =B15/B14 -> 0.15988319 | C16: =C15/C14 -> 0.031663062 | D16: =D15/D14 -> 0.065551277 | E16: =E15/E14 -> 0.17688715 | F16: =F15/F14 -> 0.17 | G16: =G15/G14 -> 0.10265099 | H16: Derived | I16: — | J16: —
A17: 歸屬母公司淨利 | B17: 41.716 | C17: 16.171 | D17: =58.431-C17 -> 42.26 | E17: =74.865-58.431 -> 16.434 | F17: =F14-F15-F18 -> 17.004397 | G17: =SUM(C17:F17) -> 91.869397 | H17: Verified／Derived | I17: 公司 6-K：FY2025 與 4Q25（2026-01-28）、1Q26、2Q26（2026-07-29）、3Q26（2026-10-28）；FY2025 損益：stockanalysis 財報頁 | J17: 1H26 584.31 億、9M26 748.65 億（6-K）
A18: 非控制權益 | B18: 0 | C18: =16.117-C17 -> -0.054 | D18: =(58.341-16.117)-D17 -> -0.036 | E18: =(74.73-58.341)-E17 -> -0.045 | F18: 0 | G18: =SUM(C18:F18) -> -0.135 | H18: Derived／Assumed | I18: 公司 6-K：FY2025 與 4Q25（2026-01-28）、1Q26、2Q26（2026-07-29）、3Q26（2026-10-28）；FY2025 損益：stockanalysis 財報頁 | J18: 本期淨利（含非控制權益）− 歸屬母公司；1H26 本期淨利 583.41 億、9M26 747.30 億；FY2025 未找到，取 0
A19: 加權股數（十億股） | B19: =41.716/3.34 -> 12.48982 | C19: =16.171/1.29 -> 12.535659 | D19: =42.26/3.39 -> 12.466077 | E19: =16.434/1.32 -> 12.45 | F19: =q_sh -> 12.45 | G19: =AVERAGE(C19:F19) -> 12.475434 | H19: Derived | I19: 淨利 ÷ EPS（公司） | J19: —
A20: EPS（基本） | B20: =B17/B19 -> 3.34 | C20: =C17/C19 -> 1.29 | D20: =D17/D19 -> 3.39 | E20: =E17/E19 -> 1.32 | F20: =F17/F19 -> 1.365815 | G20: =G17/G19 -> 7.3640242 | H20: Derived | I20: 淨利 ÷ 股數 | J20: —
A21: 公司揭露 EPS | B21: 3.34 | C21: 1.29 | D21: 3.39 | E21: 1.32 | H21: Verified | I21: 公司 6-K：FY2025 3.34（stockanalysis 3.31）、1Q26 1.29、2Q26 3.39、3Q26 1.32 | J21: 9M26 6.00
A23: FY2026 錨點的檢查（參考；校準未使用券商數字）
A24: FY2026 營收年增 | B24: =G4/B4-1 -> 0.17756366
A25: 3Q26 營收季增（公司 8.0%） | B25: =E4/D4-1 -> 0.080107081
A26: FY2026 毛利率 | B26: =G10 -> 0.32563849
A27: FY2026 營業利益率 | B27: =G12/G4 -> 0.22827499
A28: 檢查：9M26 EPS 自算 − 公司 6.00（應約為 0） | B28: =SUM(C20:E20)-6 -> 0
A29: 檢查：9M26 營收 自算 − 公司 204.01（應約為 0） | B29: =SUM(C4:E4)-204.01 -> 0
A30: FY2026 EPS 不含 2Q26 一次性業外（業外以 3Q26 水準代入，稅率 17%；參考） | B30: =G20-(D13-E13)*(1-0.17)/G19 -> 5.4367614
A34: 官方報告分部與製程別（最近完整年度＋最近四季 4Q25–3Q26；分部原則第 3 條）
A35: 項目 | B35: FY2025A | C35: 4Q25 | D35: 1Q26 | E35: 2Q26 | F35: 3Q26 | G35: 最近四季合計 | H35: 標記 | I35: 來源1 | J35: 來源2／說明
A36: 晶圓代工營收（單一主要部門） | B36: 237.553 | C36: 61.81 | D36: =C4 -> 61.038 | E36: =D4 -> 68.733 | F36: =E4 -> 74.239 | G36: =SUM(C36:F36) -> 265.82 | H36: Verified | I36: 公司 6-K 各季合併營收；20-F 部門資訊以晶圓製造為主要部門 | J36: 其他部門金額：未找到（本模型併入晶圓代工）
A37: 22／28 奈米 | C37: =C36*0.36 -> 22.2516 | D37: =D36*0.34 -> 20.75292 | E37: =E36*0.37 -> 25.43121 | F37: =F36*0.35 -> 25.98365 | G37: =SUM(C37:F37) -> 94.41938 | H37: Verified | I37: 公司 6-K：22／28 奈米占營收 4Q25 36%、1Q26 34%、2Q26 37%、3Q26 35% | J37: FY2025 全年比重：未找到
A38: 其他製程（14 奈米與 40 奈米以上） | C38: =C36-C37 -> 39.5584 | D38: =D36-D37 -> 40.28508 | E38: =E36-E37 -> 43.30179 | F38: =F36-F37 -> 48.25535 | G38: =G36-G37 -> 171.40062 | H38: Derived | I38: 差額 | J38: 40 奈米以上各製程比重：未找到
A39: 檢查：分部合計 − 合併營收 | B39: =B36-B4 -> 0 | C39: =C36-61.81 -> 0 | D39: =D36-C4 -> 0 | E39: =E36-D4 -> 0 | F39: =F36-E4 -> 0 | H39: Derived | I39: — | J39: 應為 0
A40: 檢查：子列合計 − 分部 | C40: =C37+C38-C36 -> 0 | D40: =D37+D38-D36 -> 0 | E40: =E37+E38-E36 -> 0 | F40: =F37+F38-F36 -> 0 | G40: =G37+G38-G36 -> 0 | H40: Derived | I40: — | J40: 應為 0

Sheet Units
A1: Units — 聯電成熟製程晶圓（千片 12 吋約當）、稼動率、售價與新業務（三情境）。產能 FY2026 由出貨 ÷ 稼動率推得；AI 相關營收 FY2028–29 乘 Siliconomics 同字母顆數係數
A3: 項目 | B3: 單位 | C3: FY2026 | D3: FY2027 | E3: FY2028 | F3: FY2029 | G3: 說明
A4: 1. 成熟製程晶圓：三情境稼動率、出貨與售價
A5: 稼動率（情境 A） | B5: % | C5: =PL!D64 -> 0.87057878 | D5: =PL!E64 -> 0.95 | E5: =PL!F64 -> 0.94 | F5: =PL!G64 -> 0.93 | G5: PL 頁各情境推導區塊
A6: 稼動率（情境 B） | B6: % | C6: =PL!D103 -> 0.87057878 | D6: =PL!E103 -> 0.9 | E6: =PL!F103 -> 0.87 | F6: =PL!G103 -> 0.88 | G6: 同上
A7: 稼動率（情境 C） | B7: % | C7: =PL!D142 -> 0.87057878 | D7: =PL!E142 -> 0.82 | E7: =PL!F142 -> 0.76 | F7: =PL!G142 -> 0.8 | G7: 同上
A8: 晶圓出貨（情境 A） | B8: 千片 | C8: =PL!D65 -> 4553.5349 | D8: =PL!E65 -> 5167.7029 | E8: =PL!F65 -> 5471.2374 | F8: =PL!G65 -> 5791.9451 | G8: PL 頁各情境推導區塊
A9: 晶圓出貨（情境 B） | B9: 千片 | C9: =PL!D104 -> 4553.5349 | D9: =PL!E104 -> 4895.7185 | E9: =PL!F104 -> 5063.8049 | F9: =PL!G104 -> 5480.5502 | G9: 同上
A10: 晶圓出貨（情境 C） | B10: 千片 | C10: =PL!D143 -> 4553.5349 | D10: =PL!E143 -> 4460.5436 | E10: =PL!F143 -> 4423.5537 | F10: =PL!G143 -> 4982.3184 | G10: 同上
A11: 平均售價（美元）（情境 A） | B11: US$/片 | C11: =PL!D66 -> 1878.1749 | D11: =PL!E66 -> 2065.9924 | E11: =PL!F66 -> 2127.9721 | F11: =PL!G66 -> 2170.5316 | G11: PL 頁各情境推導區塊
A12: 平均售價（美元）（情境 B） | B12: US$/片 | C12: =PL!D105 -> 1878.1749 | D12: =PL!E105 -> 1972.0836 | E12: =PL!F105 -> 1972.0836 | F12: =PL!G105 -> 1972.0836 | G12: 同上
A13: 平均售價（美元）（情境 C） | B13: US$/片 | C13: =PL!D144 -> 1878.1749 | D13: =PL!E144 -> 1878.1749 | E13: =PL!F144 -> 1765.4844 | F13: =PL!G144 -> 1712.5198 | G13: 同上
A14: 晶圓營收（情境 A） | B14: NT$B | C14: =PL!D69 -> 270.25378 | D14: =PL!E69 -> 341.64591 | E14: =PL!F69 -> 372.5645 | F14: =PL!G69 -> 402.29119 | G14: PL 頁各情境推導區塊
A15: 晶圓營收（情境 B） | B15: NT$B | C15: =PL!D108 -> 270.25378 | D15: =PL!E108 -> 308.95252 | E15: =PL!F108 -> 319.55989 | F15: =PL!G108 -> 345.8593 | G15: 同上
A16: 晶圓營收（情境 C） | B16: NT$B | C16: =PL!D147 -> 270.25378 | D16: =PL!E147 -> 268.08579 | E16: =PL!F147 -> 249.91088 | F16: =PL!G147 -> 273.03421 | G16: 同上
A18: 2. 新業務：AI 相關與 Intel 12 奈米（三情境）
A19: AI 相關營收（美元）（情境 A） | B19: US$B | C19: =PL!D71 -> 0.3 | D19: =PL!E71 -> 0.48 | E19: =PL!F71 -> 0.696 | F19: =PL!G71 -> 1.0092 | G19: PL 頁各情境推導區塊
A20: AI 相關營收（美元）（情境 B） | B20: US$B | C20: =PL!D110 -> 0.3 | D20: =PL!E110 -> 0.42 | E20: =PL!F110 -> 0.4872 | F20: =PL!G110 -> 0.7505925 | G20: 同上
A21: AI 相關營收（美元）（情境 C） | B21: US$B | C21: =PL!D149 -> 0.3 | D21: =PL!E149 -> 0.36 | E21: =PL!F149 -> 0.3132 | F21: =PL!G149 -> 0.45414 | G21: 同上
A22: AI 相關 ÷ 營收（情境 A） | B22: % | C22: =PL!D76 -> 0.033889364 | D22: =PL!E76 -> 0.043024498 | E22: =PL!F76 -> 0.055287939 | F22: =PL!G76 -> 0.071672066 | G22: PL 頁各情境推導區塊
A23: AI 相關 ÷ 營收（情境 B） | B23: % | C23: =PL!D115 -> 0.033889364 | D23: =PL!E115 -> 0.041688312 | E23: =PL!F115 -> 0.045990698 | F23: =PL!G115 -> 0.063294693 | G23: 同上
A24: AI 相關 ÷ 營收（情境 C） | B24: % | C24: =PL!D154 -> 0.033889364 | D24: =PL!E154 -> 0.041200864 | E24: =PL!F154 -> 0.038557587 | F24: =PL!G154 -> 0.050090118 | G24: 同上
A25: Intel 12 奈米營收（美元）（情境 A） | B25: US$B | C25: =PL!D73 -> 0 | D25: =PL!E73 -> 0 | E25: =PL!F73 -> 0.25 | F25: =PL!G73 -> 0.5 | G25: PL 頁各情境推導區塊
A26: Intel 12 奈米營收（美元）（情境 B） | B26: US$B | C26: =PL!D112 -> 0 | D26: =PL!E112 -> 0 | E26: =PL!F112 -> 0.12 | F26: =PL!G112 -> 0.3 | G26: 同上
A27: Intel 12 奈米營收（美元）（情境 C） | B27: US$B | C27: =PL!D151 -> 0 | D27: =PL!E151 -> 0 | E27: =PL!F151 -> 0 | F27: =PL!G151 -> 0.08 | G27: 同上
A29: 3. 校準值（只用 FY2026 已發生的實績與錨點；不用共識、不用 FY2027 起的目標）
A30: FY2026 平均售價（美元／片） | C30: =PL!D66 -> 1878.1749 | G30: 晶圓營收 ÷ 出貨 ÷ 匯率
A31: FY2026 每片現金成本（NT$K） | C31: =PL!D80 -> 27.946573 | G31: 讓 FY2026 毛利等於錨點
A32: FY2026 銷貨成本內折舊（NT$B） | C32: =PL!D79 -> 56.172 | G32: 全公司折舊 × da_sh
A34: 讀法：聯電 EPS 主要由稼動率與美元售價決定；AI 相關（先進封裝矽中介層、矽光子）與 Intel 12 奈米在 FY2029 合計仍低於營收一成，影響在情境 A 的上緣。

Sheet PL
A1: PL — 聯電損益（十億新台幣；EPS 新台幣、基本；歸屬母公司）。FY2025A 實績、FY2026 錨點（三情境相同），FY2027–FY2029 由驅動因子推導，FY2030–FY2032 為收斂法。FY(t)＝CY(t)。三情境各一個完整推導區塊（本頁下方），頂端為摘要
A2: 灰底＝FY2030–FY2032 收斂法（上游顆數只到 CY2029）：營收年增線性收斂到 fade_g、淨利率線性收斂到 fade_m（In 頁 I 節），非驅動因子推導
A3: 情境／項目 | B3: 單位 | C3: FY2025A | D3: FY2026（錨點） | E3: FY2027 | F3: FY2028 | G3: FY2029 | H3: FY2030（收斂） | I3: FY2031（收斂） | J3: FY2032（收斂） | K3: 說明
A4: 情境 A
A5: 營收 | B5: NT$B | C5: =C75 -> 237.553 | D5: =D75 -> 279.73378 | E5: =E75 -> 357.00591 | F5: =F75 -> 402.8365 | G5: =G75 -> 450.58559 | H5: =H75 -> 495.20322 | I5: =I75 -> 534.57719 | J5: =J75 -> 566.65182
A6: 營收年增 | B6: % | D6: =D77 -> 0.17756366 | E6: =E77 -> 0.27623453 | F6: =F77 -> 0.12837489 | G6: =G77 -> 0.11853217 | H6: =H77 -> 0.099021445 | I6: =I77 -> 0.079510722 | J6: =J77 -> 0.06
A7: 成熟製程晶圓營收（不含 AI 相關、Intel 12 奈米） | B7: NT$B | D7: =D69 -> 270.25378 | E7: =E69 -> 341.64591 | F7: =F69 -> 372.5645 | G7: =G69 -> 402.29119
A8: AI 相關營收 | B8: NT$B | D8: =D72 -> 9.48 | E8: =E72 -> 15.36 | F8: =F72 -> 22.272 | G8: =G72 -> 32.2944
A9: Intel 12 奈米營收 | B9: NT$B | D9: =D74 -> 0 | E9: =E74 -> 0 | F9: =F74 -> 8 | G9: =G74 -> 16
A10: 稼動率 | B10: % | D10: =D64 -> 0.87057878 | E10: =E64 -> 0.95 | F10: =F64 -> 0.94 | G10: =G64 -> 0.93
A11: 平均售價（美元） | B11: US$/片 | D11: =D66 -> 1878.1749 | E11: =E66 -> 2065.9924 | F11: =F66 -> 2127.9721 | G11: =G66 -> 2170.5316
A12: 毛利率 | B12: % | C12: =C84 -> 0.2900658 | D12: =D84 -> 0.32563849 | E12: =E84 -> 0.387493 | F12: =F84 -> 0.3919789 | G12: =G84 -> 0.39395624
A13: 營業利益率 | B13: % | C13: =C87 -> 0.18459039 | D13: =D87 -> 0.22827499 | E13: =E87 -> 0.30066642 | F13: =F87 -> 0.31009144 | G13: =G87 -> 0.31640763
A14: 歸屬母公司淨利 | B14: NT$B | C14: =C92 -> 41.716 | D14: =D92 -> 91.869397 | E14: =E92 -> 94.638736 | F14: =F92 -> 109.57873 | G14: =G92 -> 124.58341 | H14: =H92 -> 136.91984 | I14: =I92 -> 147.80643 | J14: =J92 -> 156.67482
A15: 淨利率 | B15: % | C15: =C96 -> 0.17560713 | D15: =D96 -> 0.32841724 | E15: =E96 -> 0.26509011 | F15: =F96 -> 0.27201787 | G15: =G96 -> 0.27649222 | H15: =H96 -> 0.27649222 | I15: =I96 -> 0.27649222 | J15: =J96 -> 0.27649222
A16: EPS | B16: NT$ | C16: =C94 -> 3.34 | D16: =D94 -> 7.3640242 | E16: =E94 -> 7.6015049 | F16: =F94 -> 8.8015043 | G16: =G94 -> 10.0067 | H16: =H94 -> 10.997577 | I16: =I94 -> 11.872003 | J16: =J94 -> 12.584323
A17: EPS 年增 | B17: % | D17: =D95 -> 1.2047977 | E17: =E95 -> 0.032248772 | F17: =F95 -> 0.15786339 | G17: =G95 -> 0.13693061 | H17: =H95 -> 0.099021445 | I17: =I95 -> 0.079510722 | J17: =J95 -> 0.06
A19: 情境 B
A20: 營收 | B20: NT$B | C20: =C114 -> 237.553 | D20: =D114 -> 279.73378 | E20: =E114 -> 322.39252 | F20: =F114 -> 338.99029 | G20: =G114 -> 379.47826 | H20: =H114 -> 414.75379 | I20: =I114 -> 442.32621 | J20: =J114 -> 460.01925
A21: 營收年增 | B21: % | D21: =D116 -> 0.17756366 | E21: =E116 -> 0.15249764 | F21: =F116 -> 0.051483111 | G21: =G116 -> 0.11943697 | H21: =H116 -> 0.092957977 | I21: =I116 -> 0.066478989 | J21: =J116 -> 0.04
A22: 成熟製程晶圓營收（不含 AI 相關、Intel 12 奈米） | B22: NT$B | D22: =D108 -> 270.25378 | E22: =E108 -> 308.95252 | F22: =F108 -> 319.55989 | G22: =G108 -> 345.8593
A23: AI 相關營收 | B23: NT$B | D23: =D111 -> 9.48 | E23: =E111 -> 13.44 | F23: =F111 -> 15.5904 | G23: =G111 -> 24.01896
A24: Intel 12 奈米營收 | B24: NT$B | D24: =D113 -> 0 | E24: =E113 -> 0 | F24: =F113 -> 3.84 | G24: =G113 -> 9.6
A25: 稼動率 | B25: % | D25: =D103 -> 0.87057878 | E25: =E103 -> 0.9 | F25: =F103 -> 0.87 | G25: =G103 -> 0.88
A26: 平均售價（美元） | B26: US$/片 | D26: =D105 -> 1878.1749 | E26: =E105 -> 1972.0836 | F26: =F105 -> 1972.0836 | G26: =G105 -> 1972.0836
A27: 毛利率 | B27: % | C27: =C123 -> 0.2900658 | D27: =D123 -> 0.32563849 | E27: =E123 -> 0.34905573 | F27: =F123 -> 0.32999892 | G27: =G123 -> 0.32600088
A28: 營業利益率 | B28: % | C28: =C126 -> 0.18459039 | D28: =D126 -> 0.22827499 | E28: =E126 -> 0.25813376 | F28: =F126 -> 0.2409346 | G28: =G126 -> 0.24168787
A29: 歸屬母公司淨利 | B29: NT$B | C29: =C131 -> 41.716 | D29: =D131 -> 91.869397 | E29: =E131 -> 74.137334 | F29: =F131 -> 72.823316 | G29: =G131 -> 81.357997 | H29: =H131 -> 85.956843 | I29: =I131 -> 88.510092 | J29: =J131 -> 88.762978
A30: 淨利率 | B30: % | C30: =C135 -> 0.17560713 | D30: =D135 -> 0.32841724 | E30: =E135 -> 0.22995984 | F30: =F135 -> 0.2148242 | G30: =G135 -> 0.21439436 | H30: =H135 -> 0.20724788 | I30: =I135 -> 0.2001014 | J30: =J135 -> 0.19295492
A31: EPS | B31: NT$ | C31: =C133 -> 3.34 | D31: =D133 -> 7.3640242 | E31: =E133 -> 5.9548059 | F31: =F133 -> 5.8492624 | G31: =G133 -> 6.5347789 | H31: =H133 -> 6.9041641 | I31: =I133 -> 7.1092444 | J31: =J133 -> 7.1295565
A32: EPS 年增 | B32: % | D32: =D134 -> 1.2047977 | E32: =E134 -> -0.19136524 | F32: =F134 -> -0.0177241 | G32: =G134 -> 0.11719709 | H32: =H134 -> 0.056526045 | I32: =I134 -> 0.029703851 | J32: =J134 -> 0.0028571429
A34: 情境 C
A35: 營收 | B35: NT$B | C35: =C153 -> 237.553 | D35: =D153 -> 279.73378 | E35: =E153 -> 279.60579 | F35: =F153 -> 259.93328 | G35: =G153 -> 290.12669 | H35: =H153 -> 314.52795 | I35: =I153 -> 330.90001 | J35: =J153 -> 337.51801
A36: 營收年增 | B36: % | D36: =D155 -> 0.17756366 | E36: =E155 -> -0.00045755998 | F36: =F155 -> -0.070358017 | G36: =G155 -> 0.11615832 | H36: =H155 -> 0.084105547 | I36: =I155 -> 0.052052773 | J36: =J155 -> 0.02
A37: 成熟製程晶圓營收（不含 AI 相關、Intel 12 奈米） | B37: NT$B | D37: =D147 -> 270.25378 | E37: =E147 -> 268.08579 | F37: =F147 -> 249.91088 | G37: =G147 -> 273.03421
A38: AI 相關營收 | B38: NT$B | D38: =D150 -> 9.48 | E38: =E150 -> 11.52 | F38: =F150 -> 10.0224 | G38: =G150 -> 14.53248
A39: Intel 12 奈米營收 | B39: NT$B | D39: =D152 -> 0 | E39: =E152 -> 0 | F39: =F152 -> 0 | G39: =G152 -> 2.56
A40: 稼動率 | B40: % | D40: =D142 -> 0.87057878 | E40: =E142 -> 0.82 | F40: =F142 -> 0.76 | G40: =G142 -> 0.8
A41: 平均售價（美元） | B41: US$/片 | D41: =D144 -> 1878.1749 | E41: =E144 -> 1878.1749 | F41: =F144 -> 1765.4844 | G41: =G144 -> 1712.5198
A42: 毛利率 | B42: % | C42: =C162 -> 0.2900658 | D42: =D162 -> 0.32563849 | E42: =E162 -> 0.2975872 | F42: =F162 -> 0.21774631 | G42: =G162 -> 0.20068599
...

Sheet Val
A1: Val — P/E 估值（新台幣）。結論用「現價 ÷ FY2027、FY2028 EPS（模型）」；目標價＝DCF 與 Comparable 加權（第 0 節）；十年 P/E 規則值（第 3 節，年底落後 P/E）只作參考
A2: 循環位置：聯電不是設備股，不套設備市場見頂年；以本模型營收最高的會計年度為見頂年（比照創意、聯發科；FY(t)＝CY(t)）。營收到 FY2029 仍在增加時，見頂年未知，判為中段
A4: 0. 目標價
A5: 0.1 DCF（股東權益現金流，FY2027–FY2032 明確期＋FY2032 後永續）
A6: 項目 | B6: A（順利） | C6: B（平平） | D6: C（不如預期） | E6: 說明
A7: 情境 EPS（FY2027–FY2032） | E7: PL 頁各情境；FY2030 起為收斂法
A8: FY2027 | B8: =PL!E16 -> 7.6015049 | C8: =PL!E31 -> 5.9548059 | D8: =PL!E46 -> 4.0386378
A9: FY2028 | B9: =PL!F16 -> 8.8015043 | C9: =PL!F31 -> 5.8492624 | D9: =PL!F46 -> 2.1645976
A10: FY2029 | B10: =PL!G16 -> 10.0067 | C10: =PL!G31 -> 6.5347789 | D10: =PL!G46 -> 2.1609573
A11: FY2030 | B11: =PL!H16 -> 10.997577 | C11: =PL!H31 -> 6.9041641 | D11: =PL!H46 -> 2.1865254
A12: FY2031 | B12: =PL!I16 -> 11.872003 | C12: =PL!I31 -> 7.1092444 | D12: =PL!I46 -> 2.1360301
A13: FY2032 | B13: =PL!J16 -> 12.584323 | C13: =PL!J31 -> 7.1295565 | D13: =PL!J46 -> 2.0111545
A14: 股東現金流＝EPS ×（1 − tp_g ÷ tp_roe）
A15: 再投資率（tp_g ÷ tp_roe，上限 0.8） | B15: =MIN(tp_g/tp_roe,0.8) -> 0.28749401 | E15: ROE 為近三年平均（In 頁 tp_roe）
A16: FY2027 | B16: =B8*(1-$B$15) -> 5.4161178 | C16: =C8*(1-$B$15) -> 4.2428349 | D16: =D8*(1-$B$15) -> 2.8775537
A17: FY2028 | B17: =B9*(1-$B$15) -> 6.2711245 | C17: =C9*(1-$B$15) -> 4.1676345 | D17: =D9*(1-$B$15) -> 1.5422887
A18: FY2029 | B18: =B10*(1-$B$15) -> 7.1298334 | C18: =C10*(1-$B$15) -> 4.6560691 | D18: =D10*(1-$B$15) -> 1.539695
A19: FY2030 | B19: =B11*(1-$B$15) -> 7.8358398 | C19: =C11*(1-$B$15) -> 4.9192583 | D19: =D11*(1-$B$15) -> 1.5579125
A20: FY2031 | B20: =B12*(1-$B$15) -> 8.4588731 | C20: =C12*(1-$B$15) -> 5.0653792 | D20: =D12*(1-$B$15) -> 1.5219343
A21: FY2032 | B21: =B13*(1-$B$15) -> 8.9664055 | C21: =C13*(1-$B$15) -> 5.0798517 | D21: =D13*(1-$B$15) -> 1.4329596
A22: DCF 情境每股價值（折現率 tp_r） | B22: =MAX(0,SUMPRODUCT(B16:B21,1/(1+tp_r)^{1;2;3;4;5;6})+B21*(1+tp_g)/(tp_r-tp_g)/(1+tp_r)^6) -> 118.85806 | C22: =MAX(0,SUMPRODUCT(C16:C21,1/(1+tp_r)^{1;2;3;4;5;6})+C21*(1+tp_g)/(tp_r-tp_g)/(1+tp_r)^6) -> 69.874548 | D22: =MAX(0,SUMPRODUCT(D16:D21,1/(1+tp_r)^{1;2;3;4;5;6})+D21*(1+tp_g)/(tp_r-tp_g)/(1+tp_r)^6) -> 21.885702 | E22: Σ 明確期現金流 ÷ (1＋r)^t ＋ 永續價值 ÷ (1＋r)^6；永續價值＝FY2032 現金流 ×(1＋g)÷(r−g)；基準日 2026 年底；負值取 0
A23: DCF 情境價值推到 12 個月後（×(1＋tp_r)） | B23: =B22*(1+tp_r) -> 130.74386 | C23: =C22*(1+tp_r) -> 76.862003 | D23: =D22*(1+tp_r) -> 24.074272
A24: DCF 目標價（情境加權） | B24: =tp_wA*B23+tp_wB*C23+tp_wC*D23 -> 82.469015 | E24: Σ 權重 × 情境價值 ×(1＋r)；權重見 In 頁
A26: 0.2 Comparable（市場主流同業前瞻 P/E）
A27: 同業與前瞻 P/E | B27: 代號 | C27: 前瞻 12 月 P/E | D27: 日期 | E27: 來源 | F27: 標記
A28: 台積電（TSMC） | B28: 2330.TW | C28: 16.81 | D28: 2026-10-22 | E28: stockanalysis.com forward PE（分析師共識；價格日期如左） | F28: Interested-party
A29: 格芯（GlobalFoundries） | B29: GFS | C29: 20.04 | D29: 2026-10-22 | E29: stockanalysis.com forward PE（抄自台積電模型 Val 頁同業表） | F29: Interested-party
A30: 中芯國際（SMIC，港股） | B30: 0981.HK | C30: 37.14 | D30: 2026-10-16 | E30: stockanalysis.com forward PE（抄自台積電模型 Val 頁同業表） | F30: Interested-party
A31: 高塔半導體（Tower） | B31: TSEM | C31: 34.63 | D31: 2026-10-26 | E31: stockanalysis.com forward PE（分析師共識；價格日期如左） | F31: Interested-party
A32: 世界先進（VIS） | B32: 5347.TWO | C32: 23.41 | D32: 2026-09-11 | E32: stockanalysis.com forward PE（價格日期如左；10 月值未取得） | F32: Interested-party
A33: 同業前瞻 P/E 中位數 | B33: =MEDIAN(C28:C32) -> 23.41 | E33: 晶圓代工同業（台積電、格芯、中芯港股、高塔、世界先進）；不含 A 股（非 A 股公司，Andy 2026-10-25 11:53）；華虹（1347.HK）前瞻 P/E 133.5 倍且資料日 2026-08-07，未列
A34: 12 個月後的前瞻 EPS（情境加權） | B34: =tp_wA*(2/12*B8+10/12*B9)+tp_wB*(2/12*C8+10/12*C9)+tp_wC*(2/12*D8+10/12*D9) -> 6.0092653 | E34: 約 2027-10 時的未來 12 月 EPS ≈ 2／12 × FY2027＋10／12 × FY2028（會計年度＝日曆年）
A35: Comparable 目標價 | B35: =B33*B34 -> 140.6769 | E35: 同業中位數 × 前瞻 EPS
A37: 0.3 結論
A38: 項目 | B38: 數值 | E38: 說明
A39: 目標價（DCF 與 Comparable 加權） | B39: =tp_w_dcf*B24+(1-tp_w_dcf)*tp_comp_adj -> 76.403733 | E39: tp_w_dcf × DCF＋（1 − tp_w_dcf）× Comparable（相對倍數調整後，見第 0.5 節）
A40: Comparable 目標價（市場主流同業法） | B40: =B35 -> 140.6769
A41: 市場共識目標價 | B41: =cons_tp -> 140.69 | E41: stockanalysis：25 位分析師平均 140.69（2026-10-08 擷取；中位數 135、區間 41–258）
A42: 上檔空間：加權目標價 | B42: =B39/px-1 -> -0.39120532 | E42: 現價＝In 頁 px（2026-10-22 收盤）
A43: 上檔空間：Comparable 目標價 | B43: =B40/px-1 -> 0.12093148
...

Sheet Recon
A1: Recon — 本模型 vs 公司說法、共識、券商。只作事後對照，不為對上數字而調參數。券商與資料商數字為 Interested-party，不用於校準
A3: 項目 | B3: 對照值 | C3: 模型 A | D3: 差距 A | E3: 模型 B | F3: 差距 B | G3: 模型 C | H3: 差距 C | I3: 對照來源 | J3: 說明
A4: A. FY2026 錨點 vs 共識與券商
A5: FY2026 營收 vs 共識 | B5: =cons_rev26 -> 283.2 | C5: =PL!D75 -> 279.73378 | D5: =C5/B5-1 -> -0.012239477 | E5: =PL!D114 -> 279.73378 | F5: =E5/B5-1 -> -0.012239477 | G5: =PL!D153 -> 279.73378 | H5: =G5/B5-1 -> -0.012239477 | I5: stockanalysis（21 位；2026-10-08） | J5: 共識資料日早於 3Q26 財報
A6: FY2026 EPS vs 共識 | B6: =cons_eps26 -> 7.02 | C6: =PL!D94 -> 7.3640242 | D6: =C6/B6-1 -> 0.049006293 | E6: =PL!D133 -> 7.3640242 | F6: =E6/B6-1 -> 0.049006293 | G6: =PL!D172 -> 7.3640242 | H6: =G6/B6-1 -> 0.049006293 | I6: stockanalysis（2026-10-08） | J6: 共識區間 4.55–8.15；模型含 2Q26 一次性業外（約 2.0 元）
A7: FY2026 EPS vs 美系外資中點 | B7: =us_eps26 -> 7.57 | C7: =PL!D94 -> 7.3640242 | D7: =C7/B7-1 -> -0.027209487 | E7: =PL!D133 -> 7.3640242 | F7: =E7/B7-1 -> -0.027209487 | G7: =PL!D172 -> 7.3640242 | H7: =G7/B7-1 -> -0.027209487 | I7: 旺得富 2026-10-17 | J7: 7.46–7.68
A8: 4Q26 毛利率 vs 公司指引（百分點） | B8: =q4_gm -> 0.34 | C8: =Q!F10 -> 0.34 | D8: =C8-B8 -> 0 | E8: =Q!F10 -> 0.34 | F8: =E8-B8 -> 0 | G8: =Q!F10 -> 0.34 | H8: =G8-B8 -> 0 | I8: 公司 6-K（2026-10-28） | J8: 三欄同值（FY2026 錨點）
A9: B. FY2027–29 vs 公司說法與券商（校準未使用）
A10: FY2027 平均售價年增 vs 公司約一成（百分點） | B10: =co_asp27 -> 0.1 | C10: =PL!E67 -> 0.1 | D10: =C10-B10 -> 0 | E10: =PL!E106 -> 0.05 | F10: =E10-B10 -> -0.05 | G10: =PL!E145 -> 0 | H10: =G10-B10 -> -0.1 | I10: 優分析 2026-10-28（法說） | J10: A＝公司說法；B、C 低於公司
A11: FY2027 EPS vs 本土投顧 | B11: =loc_eps27 -> 9.2 | C11: =PL!E94 -> 7.6015049 | D11: =C11/B11-1 -> -0.17374947 | E11: =PL!E133 -> 5.9548059 | F11: =E11/B11-1 -> -0.35273848 | G11: =PL!E172 -> 4.0386378 | H11: =G11/B11-1 -> -0.56101763 | I11: 旺得富 2026-10-17 | J11: FY2027 共識：未找到
A12: FY2029 AI 相關營收 vs 公司目標（US$B） | B12: =co_ai29 -> 1 | C12: =PL!G71 -> 1.0092 | D12: =C12/B12-1 -> 0.0092 | E12: =PL!G110 -> 0.7505925 | F12: =E12/B12-1 -> -0.2494075 | G12: =PL!G149 -> 0.45414 | H12: =G12/B12-1 -> -0.54586 | I12: 科技新報 2026-10-06（大摩轉述） | J12: B、C 乘同字母顆數係數
A13: 共識前瞻 12 月 EPS vs 模型（情境加權 2／12 × FY2027＋10／12 × FY2028） | B13: =cons_feps -> 6.206726 | C13: =Val!B34 -> 6.0092653 | D13: =C13/B13-1 -> -0.031813986 | E13: =Val!B34 -> 6.0092653 | F13: =E13/B13-1 -> -0.031813986 | G13: =Val!B34 -> 6.0092653 | H13: =G13/B13-1 -> -0.031813986 | I13: stockanalysis 前瞻 P/E 推得 | J13: 三欄同值（情境加權）
A14: 預留
A15: 成熟製程稼動率與價格的行業層（Siliconomics）尚未建立：上線後以本模型稼動率、售價情境對照行業路徑 | J15: 預留列：本版無數值

Sheet Sens
A1: Sens — 一次動一個輸入（In 頁敏感度低／高值），三情境都在本頁下方逐案重算（FY2026 恆等於錨點，每片現金成本在每個案例內重算），表內為情境加權後的 DCF、Comparable（相對倍數調整後）與加權目標價；另列 FY2027、FY2028 情境 A 的 EPS
A2: 相對基準＝案例加權目標價 ÷ 基準加權目標價 − 1。目標價參數（tp_r、tp_g、tp_w_dcf）三案只改 DCF 參數，PL 收斂法的 fade_g 不隨 tp_g 變動
A3: 案例 | B3: 設定 | C3: 鍵 | D3: FY2027 EPS（A） | E3: FY2028 EPS（A） | F3: FY2028 EPS 相對基準（A） | G3: DCF 目標價 | H3: Comparable（調整後）目標價 | I3: 加權目標價 | J3: 相對基準
A4: 基準（三情境加權） | B4: PL 頁三個推導區塊 | C4: — | D4: =PL!E94 -> 7.6015049 | E4: =PL!F94 -> 8.8015043 | F4: =E4/E$4-1 -> 0 | G4: =(tp_wA*MAX(0,PL!E94*(1-MIN(tp_g/tp_roe,0.8))/(1+tp_r)^1+PL!F94*(1-MIN(tp_g/tp_roe,0.8))/(1+tp_r)^2+PL!G94*(1-MIN(tp_g/tp_roe,0.8))/(1+tp_r)^3+PL!H94*(1-MIN(tp_g/tp_roe,0.8))/(1+tp_r)^4+PL!I94*(1-MIN(tp_g/tp_roe,0.8))/(1+tp_r)^5+PL!J94*(1-MIN(tp_g/tp_roe,0.8))/(1+tp_r)^6+PL!J94*(1-MIN(tp_g/tp_roe,0.8))*(1+tp_g)/(tp_r-tp_g)/(1+tp_r)^6)+tp_wB*MAX(0,PL!E133*(1-MIN(tp_g/tp_roe,0.8))/(1+tp_r)^1+PL!F133*(1-MIN(tp_g/tp_roe,0.8))/(1+tp_r)^2+PL!G133*(1-MIN(tp_g/tp_roe,0.8))/(1+tp_r)^3+PL!H133*(1-MIN(tp_g/tp_roe,0.8))/(1+tp_r)^4+PL!I133*(1-MIN(tp_g/tp_roe,0.8))/(1+tp_r)^5+PL!J133*(1-MIN(tp_g/tp_roe,0.8))/(1+tp_r)^6+PL!J133*(1-MIN(tp_g/tp_roe,0.8))*(1+tp_g)/(tp_r-tp_g)/(1+tp_r)^6)+tp_wC*MAX(0,PL!E172*(1-MIN(tp_g/tp_roe,0.8))/(1+tp_r)^1+PL!F172*(1-MIN(tp_g/tp_roe,0.8))/(1+tp_r)^2+PL!G172*(1-MIN(tp_g/tp_roe,0.8))/(1+tp_r)^3+PL!H172*(1-MIN(tp_g/tp_roe,0.8))/(1+tp_r)^4+PL!I172*(1-MIN(tp_g/tp_roe,0.8))/(1+tp_r)^5+PL!J172*(1-MIN(tp_g/tp_roe,0.8))/(1+tp_r)^6+PL!J172*(1-MIN(tp_g/tp_roe,0.8))*(1+tp_g)/(tp_r-tp_g)/(1+tp_r)^6))*(1+tp_r) -> 82.469015 | H4: =Val!$B$33*(tp_wA*(2/12*PL!E94+10/12*PL!F94)+tp_wB*(2/12*PL!E133+10/12*PL!F133)+tp_wC*(2/12*PL!E172+10/12*PL!F172))*rm_factor -> 70.338451 | I4: =tp_w_dcf*G4+(1-tp_w_dcf)*H4 -> 76.403733 | J4: =I4/I$4-1 -> 0
A5: 匯率：低 | B5: =TEXT(fx_lo,"0.0")&"（基準 "&TEXT(fx,"0.0")&"）" -> 30.5（基準 32.0） | C5: fx | D5: =E72 -> 6.5416348 | E5: =F72 -> 7.6247802 | F5: =E5/E$4-1 -> -0.13369579 | G5: =(tp_wA*MAX(0,E72*(1-MIN(tp_g/tp_roe,0.8))/(1+tp_r)^1+F72*(1-MIN(tp_g/tp_roe,0.8))/(1+tp_r)^2+G72*(1-MIN(tp_g/tp_roe,0.8))/(1+tp_r)^3+H72*(1-MIN(tp_g/tp_roe,0.8))/(1+tp_r)^4+I72*(1-MIN(tp_g/tp_roe,0.8))/(1+tp_r)^5+J72*(1-MIN(tp_g/tp_roe,0.8))/(1+tp_r)^6+J72*(1-MIN(tp_g/tp_roe,0.8))*(1+tp_g)/(tp_r-tp_g)/(1+tp_r)^6)+tp_wB*MAX(0,E111*(1-MIN(tp_g/tp_roe,0.8))/(1+tp_r)^1+F111*(1-MIN(tp_g/tp_roe,0.8))/(1+tp_r)^2+G111*(1-MIN(tp_g/tp_roe,0.8))/(1+tp_r)^3+H111*(1-MIN(tp_g/tp_roe,0.8))/(1+tp_r)^4+I111*(1-MIN(tp_g/tp_roe,0.8))/(1+tp_r)^5+J111*(1-MIN(tp_g/tp_roe,0.8))/(1+tp_r)^6+J111*(1-MIN(tp_g/tp_roe,0.8))*(1+tp_g)/(tp_r-tp_g)/(1+tp_r)^6)+tp_wC*MAX(0,E150*(1-MIN(tp_g/tp_roe,0.8))/(1+tp_r)^1+F150*(1-MIN(tp_g/tp_roe,0.8))/(1+tp_r)^2+G150*(1-MIN(tp_g/tp_roe,0.8))/(1+tp_r)^3+H150*(1-MIN(tp_g/tp_roe,0.8))/(1+tp_r)^4+I150*(1-MIN(tp_g/tp_roe,0.8))/(1+tp_r)^5+J150*(1-MIN(tp_g/tp_roe,0.8))/(1+tp_r)^6+J150*(1-MIN(tp_g/tp_roe,0.8))*(1+tp_g)/(tp_r-tp_g)/(1+tp_r)^6))*(1+tp_r) -> 69.035674 | H5: =Val!$B$33*(tp_wA*(2/12*E72+10/12*F72)+tp_wB*(2/12*E111+10/12*F111)+tp_wC*(2/12*E150+10/12*F150))*rm_factor -> 58.538924 | I5: =tp_w_dcf*G5+(1-tp_w_dcf)*H5 -> 63.787299 | J5: =I5/I$4-1 -> -0.1651285
A6: 匯率：高 | B6: =TEXT(fx_hi,"0.0")&"（基準 "&TEXT(fx,"0.0")&"）" -> 33.0（基準 32.0） | C6: fx | D6: =E189 -> 8.308085 | E6: =F189 -> 9.585987 | F6: =E6/E$4-1 -> 0.08913053 | G6: =(tp_wA*MAX(0,E189*(1-MIN(tp_g/tp_roe,0.8))/(1+tp_r)^1+F189*(1-MIN(tp_g/tp_roe,0.8))/(1+tp_r)^2+G189*(1-MIN(tp_g/tp_roe,0.8))/(1+tp_r)^3+H189*(1-MIN(tp_g/tp_roe,0.8))/(1+tp_r)^4+I189*(1-MIN(tp_g/tp_roe,0.8))/(1+tp_r)^5+J189*(1-MIN(tp_g/tp_roe,0.8))/(1+tp_r)^6+J189*(1-MIN(tp_g/tp_roe,0.8))*(1+tp_g)/(tp_r-tp_g)/(1+tp_r)^6)+tp_wB*MAX(0,E228*(1-MIN(tp_g/tp_roe,0.8))/(1+tp_r)^1+F228*(1-MIN(tp_g/tp_roe,0.8))/(1+tp_r)^2+G228*(1-MIN(tp_g/tp_roe,0.8))/(1+tp_r)^3+H228*(1-MIN(tp_g/tp_roe,0.8))/(1+tp_r)^4+I228*(1-MIN(tp_g/tp_roe,0.8))/(1+tp_r)^5+J228*(1-MIN(tp_g/tp_roe,0.8))/(1+tp_r)^6+J228*(1-MIN(tp_g/tp_roe,0.8))*(1+tp_g)/(tp_r-tp_g)/(1+tp_r)^6)+tp_wC*MAX(0,E267*(1-MIN(tp_g/tp_roe,0.8))/(1+tp_r)^1+F267*(1-MIN(tp_g/tp_roe,0.8))/(1+tp_r)^2+G267*(1-MIN(tp_g/tp_roe,0.8))/(1+tp_r)^3+H267*(1-MIN(tp_g/tp_roe,0.8))/(1+tp_r)^4+I267*(1-MIN(tp_g/tp_roe,0.8))/(1+tp_r)^5+J267*(1-MIN(tp_g/tp_roe,0.8))/(1+tp_r)^6+J267*(1-MIN(tp_g/tp_roe,0.8))*(1+tp_g)/(tp_r-tp_g)/(1+tp_r)^6))*(1+tp_r) -> 91.424576 | H6: =Val!$B$33*(tp_wA*(2/12*E189+10/12*F189)+tp_wB*(2/12*E228+10/12*F228)+tp_wC*(2/12*E267+10/12*F267))*rm_factor -> 78.204801 | I6: =tp_w_dcf*G6+(1-tp_w_dcf)*H6 -> 84.814689 | J6: =I6/I$4-1 -> 0.11008567
A7: 產能係數：低 | B7: =TEXT(cap_adj_lo,"0.00")&"（基準 "&TEXT(cap_adj,"0.00")&"）" -> 0.95（基準 1.00） | C7: cap_adj | D7: =E306 -> 6.994878 | E7: =F306 -> 8.1312004 | F7: =E7/E$4-1 -> -0.076157878 | G7: =(tp_wA*MAX(0,E306*(1-MIN(tp_g/tp_roe,0.8))/(1+tp_r)^1+F306*(1-MIN(tp_g/tp_roe,0.8))/(1+tp_r)^2+G306*(1-MIN(tp_g/tp_roe,0.8))/(1+tp_r)^3+H306*(1-MIN(tp_g/tp_roe,0.8))/(1+tp_r)^4+I306*(1-MIN(tp_g/tp_roe,0.8))/(1+tp_r)^5+J306*(1-MIN(tp_g/tp_roe,0.8))/(1+tp_r)^6+J306*(1-MIN(tp_g/tp_roe,0.8))*(1+tp_g)/(tp_r-tp_g)/(1+tp_r)^6)+tp_wB*MAX(0,E345*(1-MIN(tp_g/tp_roe,0.8))/(1+tp_r)^1+F345*(1-MIN(tp_g/tp_roe,0.8))/(1+tp_r)^2+G345*(1-MIN(tp_g/tp_roe,0.8))/(1+tp_r)^3+H345*(1-MIN(tp_g/tp_roe,0.8))/(1+tp_r)^4+I345*(1-MIN(tp_g/tp_roe,0.8))/(1+tp_r)^5+J345*(1-MIN(tp_g/tp_roe,0.8))/(1+tp_r)^6+J345*(1-MIN(tp_g/tp_roe,0.8))*(1+tp_g)/(tp_r-tp_g)/(1+tp_r)^6)+tp_wC*MAX(0,E384*(1-MIN(tp_g/tp_roe,0.8))/(1+tp_r)^1+F384*(1-MIN(tp_g/tp_roe,0.8))/(1+tp_r)^2+G384*(1-MIN(tp_g/tp_roe,0.8))/(1+tp_r)^3+H384*(1-MIN(tp_g/tp_roe,0.8))/(1+tp_r)^4+I384*(1-MIN(tp_g/tp_roe,0.8))/(1+tp_r)^5+J384*(1-MIN(tp_g/tp_roe,0.8))/(1+tp_r)^6+J384*(1-MIN(tp_g/tp_roe,0.8))*(1+tp_g)/(tp_r-tp_g)/(1+tp_r)^6))*(1+tp_r) -> 75.428388 | H7: =Val!$B$33*(tp_wA*(2/12*E306+10/12*F306)+tp_wB*(2/12*E345+10/12*F345)+tp_wC*(2/12*E384+10/12*F384))*rm_factor -> 63.901419 | I7: =tp_w_dcf*G7+(1-tp_w_dcf)*H7 -> 69.664903 | J7: =I7/I$4-1 -> -0.088200263
A8: 產能係數：高 | B8: =TEXT(cap_adj_hi,"0.00")&"（基準 "&TEXT(cap_adj,"0.00")&"）" -> 1.05（基準 1.00） | C8: cap_adj | D8: =E423 -> 8.2081319 | E8: =F423 -> 9.4717274 | F8: =E8/E$4-1 -> 0.076148697 | G8: =(tp_wA*MAX(0,E423*(1-MIN(tp_g/tp_roe,0.8))/(1+tp_r)^1+F423*(1-MIN(tp_g/tp_roe,0.8))/(1+tp_r)^2+G423*(1-MIN(tp_g/tp_roe,0.8))/(1+tp_r)^3+H423*(1-MIN(tp_g/tp_roe,0.8))/(1+tp_r)^4+I423*(1-MIN(tp_g/tp_roe,0.8))/(1+tp_r)^5+J423*(1-MIN(tp_g/tp_roe,0.8))/(1+tp_r)^6+J423*(1-MIN(tp_g/tp_roe,0.8))*(1+tp_g)/(tp_r-tp_g)/(1+tp_r)^6)+tp_wB*MAX(0,E462*(1-MIN(tp_g/tp_roe,0.8))/(1+tp_r)^1+F462*(1-MIN(tp_g/tp_roe,0.8))/(1+tp_r)^2+G462*(1-MIN(tp_g/tp_roe,0.8))/(1+tp_r)^3+H462*(1-MIN(tp_g/tp_roe,0.8))/(1+tp_r)^4+I462*(1-MIN(tp_g/tp_roe,0.8))/(1+tp_r)^5+J462*(1-MIN(tp_g/tp_roe,0.8))/(1+tp_r)^6+J462*(1-MIN(tp_g/tp_roe,0.8))*(1+tp_g)/(tp_r-tp_g)/(1+tp_r)^6)+tp_wC*MAX(0,E501*(1-MIN(tp_g/tp_roe,0.8))/(1+tp_r)^1+F501*(1-MIN(tp_g/tp_roe,0.8))/(1+tp_r)^2+G501*(1-MIN(tp_g/tp_roe,0.8))/(1+tp_r)^3+H501*(1-MIN(tp_g/tp_roe,0.8))/(1+tp_r)^4+I501*(1-MIN(tp_g/tp_roe,0.8))/(1+tp_r)^5+J501*(1-MIN(tp_g/tp_roe,0.8))/(1+tp_r)^6+J501*(1-MIN(tp_g/tp_roe,0.8))*(1+tp_g)/(tp_r-tp_g)/(1+tp_r)^6))*(1+tp_r) -> 89.500269 | H8: =Val!$B$33*(tp_wA*(2/12*E423+10/12*F423)+tp_wB*(2/12*E462+10/12*F462)+tp_wC*(2/12*E501+10/12*F501))*rm_factor -> 76.775246 | I8: =tp_w_dcf*G8+(1-tp_w_dcf)*H8 -> 83.137757 | J8: =I8/I$4-1 -> 0.088137376
A9: 稼動率調整：低 | B9: =TEXT(ut_adj_lo,"0.0%")&"（基準 "&TEXT(ut_adj,"0.0%")&"）" -> -3.0%（基準 0.0%） | C9: ut_adj | D9: =E540 -> 7.2183721 | E9: =F540 -> 8.3736441 | F9: =E9/E$4-1 -> -0.048612159 | G9: =(tp_wA*MAX(0,E540*(1-MIN(tp_g/tp_roe,0.8))/(1+tp_r)^1+F540*(1-MIN(tp_g/tp_roe,0.8))/(1+tp_r)^2+G540*(1-MIN(tp_g/tp_roe,0.8))/(1+tp_r)^3+H540*(1-MIN(tp_g/tp_roe,0.8))/(1+tp_r)^4+I540*(1-MIN(tp_g/tp_roe,0.8))/(1+tp_r)^5+J540*(1-MIN(tp_g/tp_roe,0.8))/(1+tp_r)^6+J540*(1-MIN(tp_g/tp_roe,0.8))*(1+tp_g)/(tp_r-tp_g)/(1+tp_r)^6)+tp_wB*MAX(0,E579*(1-MIN(tp_g/tp_roe,0.8))/(1+tp_r)^1+F579*(1-MIN(tp_g/tp_roe,0.8))/(1+tp_r)^2+G579*(1-MIN(tp_g/tp_roe,0.8))/(1+tp_r)^3+H579*(1-MIN(tp_g/tp_roe,0.8))/(1+tp_r)^4+I579*(1-MIN(tp_g/tp_roe,0.8))/(1+tp_r)^5+J579*(1-MIN(tp_g/tp_roe,0.8))/(1+tp_r)^6+J579*(1-MIN(tp_g/tp_roe,0.8))*(1+tp_g)/(tp_r-tp_g)/(1+tp_r)^6)+tp_wC*MAX(0,E618*(1-MIN(tp_g/tp_roe,0.8))/(1+tp_r)^1+F618*(1-MIN(tp_g/tp_roe,0.8))/(1+tp_r)^2+G618*(1-MIN(tp_g/tp_roe,0.8))/(1+tp_r)^3+H618*(1-MIN(tp_g/tp_roe,0.8))/(1+tp_r)^4+I618*(1-MIN(tp_g/tp_roe,0.8))/(1+tp_r)^5+J618*(1-MIN(tp_g/tp_roe,0.8))/(1+tp_r)^6+J618*(1-MIN(tp_g/tp_roe,0.8))*(1+tp_g)/(tp_r-tp_g)/(1+tp_r)^6))*(1+tp_r) -> 77.710611 | H9: =Val!$B$33*(tp_wA*(2/12*E540+10/12*F540)+tp_wB*(2/12*E579+10/12*F579)+tp_wC*(2/12*E618+10/12*F618))*rm_factor -> 65.937818 | I9: =tp_w_dcf*G9+(1-tp_w_dcf)*H9 -> 71.824214 | J9: =I9/I$4-1 -> -0.059938413
A10: 稼動率調整：高 | B10: =TEXT(ut_adj_hi,"0.0%")&"（基準 "&TEXT(ut_adj,"0.0%")&"）" -> 3.0%（基準 0.0%） | C10: ut_adj | D10: =E657 -> 7.9846377 | E10: =F657 -> 9.2293421 | F10: =E10/E$4-1 -> 0.048609622 | G10: =(tp_wA*MAX(0,E657*(1-MIN(tp_g/tp_roe,0.8))/(1+tp_r)^1+F657*(1-MIN(tp_g/tp_roe,0.8))/(1+tp_r)^2+G657*(1-MIN(tp_g/tp_roe,0.8))/(1+tp_r)^3+H657*(1-MIN(tp_g/tp_roe,0.8))/(1+tp_r)^4+I657*(1-MIN(tp_g/tp_roe,0.8))/(1+tp_r)^5+J657*(1-MIN(tp_g/tp_roe,0.8))/(1+tp_r)^6+J657*(1-MIN(tp_g/tp_roe,0.8))*(1+tp_g)/(tp_r-tp_g)/(1+tp_r)^6)+tp_wB*MAX(0,E696*(1-MIN(tp_g/tp_roe,0.8))/(1+tp_r)^1+F696*(1-MIN(tp_g/tp_roe,0.8))/(1+tp_r)^2+G696*(1-MIN(tp_g/tp_roe,0.8))/(1+tp_r)^3+H696*(1-MIN(tp_g/tp_roe,0.8))/(1+tp_r)^4+I696*(1-MIN(tp_g/tp_roe,0.8))/(1+tp_r)^5+J696*(1-MIN(tp_g/tp_roe,0.8))/(1+tp_r)^6+J696*(1-MIN(tp_g/tp_roe,0.8))*(1+tp_g)/(tp_r-tp_g)/(1+tp_r)^6)+tp_wC*MAX(0,E735*(1-MIN(tp_g/tp_roe,0.8))/(1+tp_r)^1+F735*(1-MIN(tp_g/tp_roe,0.8))/(1+tp_r)^2+G735*(1-MIN(tp_g/tp_roe,0.8))/(1+tp_r)^3+H735*(1-MIN(tp_g/tp_roe,0.8))/(1+tp_r)^4+I735*(1-MIN(tp_g/tp_roe,0.8))/(1+tp_r)^5+J735*(1-MIN(tp_g/tp_roe,0.8))/(1+tp_r)^6+J735*(1-MIN(tp_g/tp_roe,0.8))*(1+tp_g)/(tp_r-tp_g)/(1+tp_r)^6))*(1+tp_r) -> 87.220934 | H10: =Val!$B$33*(tp_wA*(2/12*E657+10/12*F657)+tp_wB*(2/12*E696+10/12*F696)+tp_wC*(2/12*E735+10/12*F735))*rm_factor -> 74.739018 | I10: =tp_w_dcf*G10+(1-tp_w_dcf)*H10 -> 80.979976 | J10: =I10/I$4-1 -> 0.059895545
A11: 售價水準調整：低 | B11: =TEXT(asp_adj_lo,"0.0%")&"（基準 "&TEXT(asp_adj,"0.0%")&"）" -> -3.0%（基準 0.0%） | C11: asp_adj | D11: =E774 -> 6.9358136 | E11: =F774 -> 8.0735067 | F11: =E11/E$4-1 -> -0.082712854 | G11: =(tp_wA*MAX(0,E774*(1-MIN(tp_g/tp_roe,0.8))/(1+tp_r)^1+F774*(1-MIN(tp_g/tp_roe,0.8))/(1+tp_r)^2+G774*(1-MIN(tp_g/tp_roe,0.8))/(1+tp_r)^3+H774*(1-MIN(tp_g/tp_roe,0.8))/(1+tp_r)^4+I774*(1-MIN(tp_g/tp_roe,0.8))/(1+tp_r)^5+J774*(1-MIN(tp_g/tp_roe,0.8))/(1+tp_r)^6+J774*(1-MIN(tp_g/tp_roe,0.8))*(1+tp_g)/(tp_r-tp_g)/(1+tp_r)^6)+tp_wB*MAX(0,E813*(1-MIN(tp_g/tp_roe,0.8))/(1+tp_r)^1+F813*(1-MIN(tp_g/tp_roe,0.8))/(1+tp_r)^2+G813*(1-MIN(tp_g/tp_roe,0.8))/(1+tp_r)^3+H813*(1-MIN(tp_g/tp_roe,0.8))/(1+tp_r)^4+I813*(1-MIN(tp_g/tp_roe,0.8))/(1+tp_r)^5+J813*(1-MIN(tp_g/tp_roe,0.8))/(1+tp_r)^6+J813*(1-MIN(tp_g/tp_roe,0.8))*(1+tp_g)/(tp_r-tp_g)/(1+tp_r)^6)+tp_wC*MAX(0,E852*(1-MIN(tp_g/tp_roe,0.8))/(1+tp_r)^1+F852*(1-MIN(tp_g/tp_roe,0.8))/(1+tp_r)^2+G852*(1-MIN(tp_g/tp_roe,0.8))/(1+tp_r)^3+H852*(1-MIN(tp_g/tp_roe,0.8))/(1+tp_r)^4+I852*(1-MIN(tp_g/tp_roe,0.8))/(1+tp_r)^5+J852*(1-MIN(tp_g/tp_roe,0.8))/(1+tp_r)^6+J852*(1-MIN(tp_g/tp_roe,0.8))*(1+tp_g)/(tp_r-tp_g)/(1+tp_r)^6))*(1+tp_r) -> 74.27469 | H11: =Val!$B$33*(tp_wA*(2/12*E774+10/12*F774)+tp_wB*(2/12*E813+10/12*F813)+tp_wC*(2/12*E852+10/12*F852))*rm_factor -> 62.981159 | I11: =tp_w_dcf*G11+(1-tp_w_dcf)*H11 -> 68.627925 | J11: =I11/I$4-1 -> -0.10177262
A12: 售價水準調整：高 | B12: =TEXT(asp_adj_hi,"0.0%")&"（基準 "&TEXT(asp_adj,"0.0%")&"）" -> 3.0%（基準 0.0%） | C12: asp_adj | D12: =E891 -> 8.2671962 | E12: =F891 -> 9.5294728 | F12: =E12/E$4-1 -> 0.082709554 | G12: =(tp_wA*MAX(0,E891*(1-MIN(tp_g/tp_roe,0.8))/(1+tp_r)^1+F891*(1-MIN(tp_g/tp_roe,0.8))/(1+tp_r)^2+G891*(1-MIN(tp_g/tp_roe,0.8))/(1+tp_r)^3+H891*(1-MIN(tp_g/tp_roe,0.8))/(1+tp_r)^4+I891*(1-MIN(tp_g/tp_roe,0.8))/(1+tp_r)^5+J891*(1-MIN(tp_g/tp_roe,0.8))/(1+tp_r)^6+J891*(1-MIN(tp_g/tp_roe,0.8))*(1+tp_g)/(tp_r-tp_g)/(1+tp_r)^6)+tp_wB*MAX(0,E930*(1-MIN(tp_g/tp_roe,0.8))/(1+tp_r)^1+F930*(1-MIN(tp_g/tp_roe,0.8))/(1+tp_r)^2+G930*(1-MIN(tp_g/tp_roe,0.8))/(1+tp_r)^3+H930*(1-MIN(tp_g/tp_roe,0.8))/(1+tp_r)^4+I930*(1-MIN(tp_g/tp_roe,0.8))/(1+tp_r)^5+J930*(1-MIN(tp_g/tp_roe,0.8))/(1+tp_r)^6+J930*(1-MIN(tp_g/tp_roe,0.8))*(1+tp_g)/(tp_r-tp_g)/(1+tp_r)^6)+tp_wC*MAX(0,E969*(1-MIN(tp_g/tp_roe,0.8))/(1+tp_r)^1+F969*(1-MIN(tp_g/tp_roe,0.8))/(1+tp_r)^2+G969*(1-MIN(tp_g/tp_roe,0.8))/(1+tp_r)^3+H969*(1-MIN(tp_g/tp_roe,0.8))/(1+tp_r)^4+I969*(1-MIN(tp_g/tp_roe,0.8))/(1+tp_r)^5+J969*(1-MIN(tp_g/tp_roe,0.8))/(1+tp_r)^6+J969*(1-MIN(tp_g/tp_roe,0.8))*(1+tp_g)/(tp_r-tp_g)/(1+tp_r)^6))*(1+tp_r) -> 90.653855 | H12: =Val!$B$33*(tp_wA*(2/12*E891+10/12*F891)+tp_wB*(2/12*E930+10/12*F930)+tp_wC*(2/12*E969+10/12*F969))*rm_factor -> 77.695657 | I12: =tp_w_dcf*G12+(1-tp_w_dcf)*H12 -> 84.174756 | J12: =I12/I$4-1 -> 0.10171
A13: 折舊年增調整：低 | B13: =TEXT(dag_adj_lo,"0.0%")&"（基準 "&TEXT(dag_adj,"0.0%")&"）" -> -5.0%（基準 0.0%） | C13: dag_adj | D13: =E1008 -> 7.7932567 | E13: =F1008 -> 9.2176057 | F13: =E13/E$4-1 -> 0.047276171 | G13: =(tp_wA*MAX(0,E1008*(1-MIN(tp_g/tp_roe,0.8))/(1+tp_r)^1+F1008*(1-MIN(tp_g/tp_roe,0.8))/(1+tp_r)^2+G1008*(1-MIN(tp_g/tp_roe,0.8))/(1+tp_r)^3+H1008*(1-MIN(tp_g/tp_roe,0.8))/(1+tp_r)^4+I1008*(1-MIN(tp_g/tp_roe,0.8))/(1+tp_r)^5+J1008*(1-MIN(tp_g/tp_roe,0.8))/(1+tp_r)^6+J1008*(1-MIN(tp_g/tp_roe,0.8))*(1+tp_g)/(tp_r-tp_g)/(1+tp_r)^6)+tp_wB*MAX(0,E1047*(1-MIN(tp_g/tp_roe,0.8))/(1+tp_r)^1+F1047*(1-MIN(tp_g/tp_roe,0.8))/(1+tp_r)^2+G1047*(1-MIN(tp_g/tp_roe,0.8))/(1+tp_r)^3+H1047*(1-MIN(tp_g/tp_roe,0.8))/(1+tp_r)^4+I1047*(1-MIN(tp_g/tp_roe,0.8))/(1+tp_r)^5+J1047*(1-MIN(tp_g/tp_roe,0.8))/(1+tp_r)^6+J1047*(1-MIN(tp_g/tp_roe,0.8))*(1+tp_g)/(tp_r-tp_g)/(1+tp_r)^6)+tp_wC*MAX(0,E1086*(1-MIN(tp_g/tp_roe,0.8))/(1+tp_r)^1+F1086*(1-MIN(tp_g/tp_roe,0.8))/(1+tp_r)^2+G1086*(1-MIN(tp_g/tp_roe,0.8))/(1+tp_r)^3+H1086*(1-MIN(tp_g/tp_roe,0.8))/(1+tp_r)^4+I1086*(1-MIN(tp_g/tp_roe,0.8))/(1+tp_r)^5+J1086*(1-MIN(tp_g/tp_roe,0.8))/(1+tp_r)^6+J1086*(1-MIN(tp_g/tp_roe,0.8))*(1+tp_g)/(tp_r-tp_g)/(1+tp_r)^6))*(1+tp_r) -> 89.978721 | H13: =Val!$B$33*(tp_wA*(2/12*E1008+10/12*F1008)+tp_wB*(2/12*E1047+10/12*F1047)+tp_wC*(2/12*E1086+10/12*F1086))*rm_factor -> 74.771249 | I13: =tp_w_dcf*G13+(1-tp_w_dcf)*H13 -> 82.374985 | J13: =I13/I$4-1 -> 0.078153929
A14: 折舊年增調整：高 | B14: =TEXT(dag_adj_hi,"0.0%")&"（基準 "&TEXT(dag_adj,"0.0%")&"）" -> 5.0%（基準 0.0%） | C14: dag_adj | D14: =E1125 -> 7.4097531 | E14: =F1125 -> 8.3662277 | F14: =E14/E$4-1 -> -0.049454796 | G14: =(tp_wA*MAX(0,E1125*(1-MIN(tp_g/tp_roe,0.8))/(1+tp_r)^1+F1125*(1-MIN(tp_g/tp_roe,0.8))/(1+tp_r)^2+G1125*(1-MIN(tp_g/tp_roe,0.8))/(1+tp_r)^3+H1125*(1-MIN(tp_g/tp_roe,0.8))/(1+tp_r)^4+I1125*(1-MIN(tp_g/tp_roe,0.8))/(1+tp_r)^5+J1125*(1-MIN(tp_g/tp_roe,0.8))/(1+tp_r)^6+J1125*(1-MIN(tp_g/tp_roe,0.8))*(1+tp_g)/(tp_r-tp_g)/(1+tp_r)^6)+tp_wB*MAX(0,E1164*(1-MIN(tp_g/tp_roe,0.8))/(1+tp_r)^1+F1164*(1-MIN(tp_g/tp_roe,0.8))/(1+tp_r)^2+G1164*(1-MIN(tp_g/tp_roe,0.8))/(1+tp_r)^3+H1164*(1-MIN(tp_g/tp_roe,0.8))/(1+tp_r)^4+I1164*(1-MIN(tp_g/tp_roe,0.8))/(1+tp_r)^5+J1164*(1-MIN(tp_g/tp_roe,0.8))/(1+tp_r)^6+J1164*(1-MIN(tp_g/tp_roe,0.8))*(1+tp_g)/(tp_r-tp_g)/(1+tp_r)^6)+tp_wC*MAX(0,E1203*(1-MIN(tp_g/tp_roe,0.8))/(1+tp_r)^1+F1203*(1-MIN(tp_g/tp_roe,0.8))/(1+tp_r)^2+G1203*(1-MIN(tp_g/tp_roe,0.8))/(1+tp_r)^3+H1203*(1-MIN(tp_g/tp_roe,0.8))/(1+tp_r)^4+I1203*(1-MIN(tp_g/tp_roe,0.8))/(1+tp_r)^5+J1203*(1-MIN(tp_g/tp_roe,0.8))/(1+tp_r)^6+J1203*(1-MIN(tp_g/tp_roe,0.8))*(1+tp_g)/(tp_r-tp_g)/(1+tp_r)^6))*(1+tp_r) -> 74.27077 | H14: =Val!$B$33*(tp_wA*(2/12*E1125+10/12*F1125)+tp_wB*(2/12*E1164+10/12*F1164)+tp_wC*(2/12*E1203+10/12*F1203))*rm_factor -> 65.718614 | I14: =tp_w_dcf*G14+(1-tp_w_dcf)*H14 -> 69.994692 | J14: =I14/I$4-1 -> -0.083883871
A15: 每片現金成本年增：低 | B15: =TEXT(cc_g_lo,"0.0%")&"（基準 "&TEXT(cc_g,"0.0%")&"）" -> 0.0%（基準 2.0%） | C15: cc_g | D15: =E1242 -> 7.7987043 | E15: =F1242 -> 9.2232445 | F15: =E15/E$4-1 -> 0.047916838 | G15: =(tp_wA*MAX(0,E1242*(1-MIN(tp_g/tp_roe,0.8))/(1+tp_r)^1+F1242*(1-MIN(tp_g/tp_roe,0.8))/(1+tp_r)^2+G1242*(1-MIN(tp_g/tp_roe,0.8))/(1+tp_r)^3+H1242*(1-MIN(tp_g/tp_roe,0.8))/(1+tp_r)^4+I1242*(1-MIN(tp_g/tp_roe,0.8))/(1+tp_r)^5+J1242*(1-MIN(tp_g/tp_roe,0.8))/(1+tp_r)^6+J1242*(1-MIN(tp_g/tp_roe,0.8))*(1+tp_g)/(tp_r-tp_g)/(1+tp_r)^6)+tp_wB*MAX(0,E1281*(1-MIN(tp_g/tp_roe,0.8))/(1+tp_r)^1+F1281*(1-MIN(tp_g/tp_roe,0.8))/(1+tp_r)^2+G1281*(1-MIN(tp_g/tp_roe,0.8))/(1+tp_r)^3+H1281*(1-MIN(tp_g/tp_roe,0.8))/(1+tp_r)^4+I1281*(1-MIN(tp_g/tp_roe,0.8))/(1+tp_r)^5+J1281*(1-MIN(tp_g/tp_roe,0.8))/(1+tp_r)^6+J1281*(1-MIN(tp_g/tp_roe,0.8))*(1+tp_g)/(tp_r-tp_g)/(1+tp_r)^6)+tp_wC*MAX(0,E1320*(1-MIN(tp_g/tp_roe,0.8))/(1+tp_r)^1+F1320*(1-MIN(tp_g/tp_roe,0.8))/(1+tp_r)^2+G1320*(1-MIN(tp_g/tp_roe,0.8))/(1+tp_r)^3+H1320*(1-MIN(tp_g/tp_roe,0.8))/(1+tp_r)^4+I1320*(1-MIN(tp_g/tp_roe,0.8))/(1+tp_r)^5+J1320*(1-MIN(tp_g/tp_roe,0.8))/(1+tp_r)^6+J1320*(1-MIN(tp_g/tp_roe,0.8))*(1+tp_g)/(tp_r-tp_g)/(1+tp_r)^6))*(1+tp_r) -> 89.717156 | H15: =Val!$B$33*(tp_wA*(2/12*E1242+10/12*F1242)+tp_wB*(2/12*E1281+10/12*F1281)+tp_wC*(2/12*E1320+10/12*F1320))*rm_factor -> 74.505509 | I15: =tp_w_dcf*G15+(1-tp_w_dcf)*H15 -> 82.111332 | J15: =I15/I$4-1 -> 0.074703151
A16: 每片現金成本年增：高 | B16: =TEXT(cc_g_hi,"0.0%")&"（基準 "&TEXT(cc_g,"0.0%")&"）" -> 4.0%（基準 2.0%） | C16: cc_g | D16: =E1359 -> 7.4043055 | E16: =F1359 -> 8.3714127 | F16: =E16/E$4-1 -> -0.048865687 | G16: =(tp_wA*MAX(0,E1359*(1-MIN(tp_g/tp_roe,0.8))/(1+tp_r)^1+F1359*(1-MIN(tp_g/tp_roe,0.8))/(1+tp_r)^2+G1359*(1-MIN(tp_g/tp_roe,0.8))/(1+tp_r)^3+H1359*(1-MIN(tp_g/tp_roe,0.8))/(1+tp_r)^4+I1359*(1-MIN(tp_g/tp_roe,0.8))/(1+tp_r)^5+J1359*(1-MIN(tp_g/tp_roe,0.8))/(1+tp_r)^6+J1359*(1-MIN(tp_g/tp_roe,0.8))*(1+tp_g)/(tp_r-tp_g)/(1+tp_r)^6)+tp_wB*MAX(0,E1398*(1-MIN(tp_g/tp_roe,0.8))/(1+tp_r)^1+F1398*(1-MIN(tp_g/tp_roe,0.8))/(1+tp_r)^2+G1398*(1-MIN(tp_g/tp_roe,0.8))/(1+tp_r)^3+H1398*(1-MIN(tp_g/tp_roe,0.8))/(1+tp_r)^4+I1398*(1-MIN(tp_g/tp_roe,0.8))/(1+tp_r)^5+J1398*(1-MIN(tp_g/tp_roe,0.8))/(1+tp_r)^6+J1398*(1-MIN(tp_g/tp_roe,0.8))*(1+tp_g)/(tp_r-tp_g)/(1+tp_r)^6)+tp_wC*MAX(0,E1437*(1-MIN(tp_g/tp_roe,0.8))/(1+tp_r)^1+F1437*(1-MIN(tp_g/tp_roe,0.8))/(1+tp_r)^2+G1437*(1-MIN(tp_g/tp_roe,0.8))/(1+tp_r)^3+H1437*(1-MIN(tp_g/tp_roe,0.8))/(1+tp_r)^4+I1437*(1-MIN(tp_g/tp_roe,0.8))/(1+tp_r)^5+J1437*(1-MIN(tp_g/tp_roe,0.8))/(1+tp_r)^6+J1437*(1-MIN(tp_g/tp_roe,0.8))*(1+tp_g)/(tp_r-tp_g)/(1+tp_r)^6))*(1+tp_r) -> 74.941403 | H16: =Val!$B$33*(tp_wA*(2/12*E1359+10/12*F1359)+tp_wB*(2/12*E1398+10/12*F1398)+tp_wC*(2/12*E1437+10/12*F1437))*rm_factor -> 66.096085 | I16: =tp_w_dcf*G16+(1-tp_w_dcf)*H16 -> 70.518744 | J16: =I16/I$4-1 -> -0.07702488
A17: 營業費用彈性：低 | B17: =TEXT(phi_lo,"0.00")&"（基準 "&TEXT(phi,"0.00")&"）" -> 0.30（基準 0.50） | C17: phi | D17: =E1476 -> 7.7042352 | E17: =F1476 -> 8.962527 | F17: =E17/E$4-1 -> 0.01829491 | G17: =(tp_wA*MAX(0,E1476*(1-MIN(tp_g/tp_roe,0.8))/(1+tp_r)^1+F1476*(1-MIN(tp_g/tp_roe,0.8))/(1+tp_r)^2+G1476*(1-MIN(tp_g/tp_roe,0.8))/(1+tp_r)^3+H1476*(1-MIN(tp_g/tp_roe,0.8))/(1+tp_r)^4+I1476*(1-MIN(tp_g/tp_roe,0.8))/(1+tp_r)^5+J1476*(1-MIN(tp_g/tp_roe,0.8))/(1+tp_r)^6+J1476*(1-MIN(tp_g/tp_roe,0.8))*(1+tp_g)/(tp_r-tp_g)/(1+tp_r)^6)+tp_wB*MAX(0,E1515*(1-MIN(tp_g/tp_roe,0.8))/(1+tp_r)^1+F1515*(1-MIN(tp_g/tp_roe,0.8))/(1+tp_r)^2+G1515*(1-MIN(tp_g/tp_roe,0.8))/(1+tp_r)^3+H1515*(1-MIN(tp_g/tp_roe,0.8))/(1+tp_r)^4+I1515*(1-MIN(tp_g/tp_roe,0.8))/(1+tp_r)^5+J1515*(1-MIN(tp_g/tp_roe,0.8))/(1+tp_r)^6+J1515*(1-MIN(tp_g/tp_roe,0.8))*(1+tp_g)/(tp_r-tp_g)/(1+tp_r)^6)+tp_wC*MAX(0,E1554*(1-MIN(tp_g/tp_roe,0.8))/(1+tp_r)^1+F1554*(1-MIN(tp_g/tp_roe,0.8))/(1+tp_r)^2+G1554*(1-MIN(tp_g/tp_roe,0.8))/(1+tp_r)^3+H1554*(1-MIN(tp_g/tp_roe,0.8))/(1+tp_r)^4+I1554*(1-MIN(tp_g/tp_roe,0.8))/(1+tp_r)^5+J1554*(1-MIN(tp_g/tp_roe,0.8))/(1+tp_r)^6+J1554*(1-MIN(tp_g/tp_roe,0.8))*(1+tp_g)/(tp_r-tp_g)/(1+tp_r)^6))*(1+tp_r) -> 84.01283 | H17: =Val!$B$33*(tp_wA*(2/12*E1476+10/12*F1476)+tp_wB*(2/12*E1515+10/12*F1515)+tp_wC*(2/12*E1554+10/12*F1554))*rm_factor -> 71.209978 | I17: =tp_w_dcf*G17+(1-tp_w_dcf)*H17 -> 77.611404 | J17: =I17/I$4-1 -> 0.015806443
A18: 營業費用彈性：高 | B18: =TEXT(phi_hi,"0.00")&"（基準 "&TEXT(phi,"0.00")&"）" -> 0.80（基準 0.50） | C18: phi | D18: =E1593 -> 7.4474094 | E18: =F1593 -> 8.5500792 | F18: =E18/E$4-1 -> -0.028566149 | G18: =(tp_wA*MAX(0,E1593*(1-MIN(tp_g/tp_roe,0.8))/(1+tp_r)^1+F1593*(1-MIN(tp_g/tp_roe,0.8))/(1+tp_r)^2+G1593*(1-MIN(tp_g/tp_roe,0.8))/(1+tp_r)^3+H1593*(1-MIN(tp_g/tp_roe,0.8))/(1+tp_r)^4+I1593*(1-MIN(tp_g/tp_roe,0.8))/(1+tp_r)^5+J1593*(1-MIN(tp_g/tp_roe,0.8))/(1+tp_r)^6+J1593*(1-MIN(tp_g/tp_roe,0.8))*(1+tp_g)/(tp_r-tp_g)/(1+tp_r)^6)+tp_wB*MAX(0,E1632*(1-MIN(tp_g/tp_roe,0.8))/(1+tp_r)^1+F1632*(1-MIN(tp_g/tp_roe,0.8))/(1+tp_r)^2+G1632*(1-MIN(tp_g/tp_roe,0.8))/(1+tp_r)^3+H1632*(1-MIN(tp_g/tp_roe,0.8))/(1+tp_r)^4+I1632*(1-MIN(tp_g/tp_roe,0.8))/(1+tp_r)^5+J1632*(1-MIN(tp_g/tp_roe,0.8))/(1+tp_r)^6+J1632*(1-MIN(tp_g/tp_roe,0.8))*(1+tp_g)/(tp_r-tp_g)/(1+tp_r)^6)+tp_wC*MAX(0,E1671*(1-MIN(tp_g/tp_roe,0.8))/(1+tp_r)^1+F1671*(1-MIN(tp_g/tp_roe,0.8))/(1+tp_r)^2+G1671*(1-MIN(tp_g/tp_roe,0.8))/(1+tp_r)^3+H1671*(1-MIN(tp_g/tp_roe,0.8))/(1+tp_r)^4+I1671*(1-MIN(tp_g/tp_roe,0.8))/(1+tp_r)^5+J1671*(1-MIN(tp_g/tp_roe,0.8))/(1+tp_r)^6+J1671*(1-MIN(tp_g/tp_roe,0.8))*(1+tp_g)/(tp_r-tp_g)/(1+tp_r)^6))*(1+tp_r) -> 79.891422 | H18: =Val!$B$33*(tp_wA*(2/12*E1593+10/12*F1593)+tp_wB*(2/12*E1632+10/12*F1632)+tp_wC*(2/12*E1671+10/12*F1671))*rm_factor -> 68.888391 | I18: =tp_w_dcf*G18+(1-tp_w_dcf)*H18 -> 74.389907 | J18: =I18/I$4-1 -> -0.026357693
A19: 營業外淨額：低 | B19: =TEXT(nonop_f_lo,"0.0")&"（基準 "&TEXT(nonop_f,"0.0")&"）" -> 2.0（基準 4.0） | C19: nonop_f | D19: =E1710 -> 7.4649587 | E19: =F1710 -> 8.6649581 | F19: =E19/E$4-1 -> -0.01551396 | G19: =(tp_wA*MAX(0,E1710*(1-MIN(tp_g/tp_roe,0.8))/(1+tp_r)^1+F1710*(1-MIN(tp_g/tp_roe,0.8))/(1+tp_r)^2+G1710*(1-MIN(tp_g/tp_roe,0.8))/(1+tp_r)^3+H1710*(1-MIN(tp_g/tp_roe,0.8))/(1+tp_r)^4+I1710*(1-MIN(tp_g/tp_roe,0.8))/(1+tp_r)^5+J1710*(1-MIN(tp_g/tp_roe,0.8))/(1+tp_r)^6+J1710*(1-MIN(tp_g/tp_roe,0.8))*(1+tp_g)/(tp_r-tp_g)/(1+tp_r)^6)+tp_wB*MAX(0,E1749*(1-MIN(tp_g/tp_roe,0.8))/(1+tp_r)^1+F1749*(1-MIN(tp_g/tp_roe,0.8))/(1+tp_r)^2+G1749*(1-MIN(tp_g/tp_roe,0.8))/(1+tp_r)^3+H1749*(1-MIN(tp_g/tp_roe,0.8))/(1+tp_r)^4+I1749*(1-MIN(tp_g/tp_roe,0.8))/(1+tp_r)^5+J1749*(1-MIN(tp_g/tp_roe,0.8))/(1+tp_r)^6+J1749*(1-MIN(tp_g/tp_roe,0.8))*(1+tp_g)/(tp_r-tp_g)/(1+tp_r)^6)+tp_wC*MAX(0,E1788*(1-MIN(tp_g/tp_roe,0.8))/(1+tp_r)^1+F1788*(1-MIN(tp_g/tp_roe,0.8))/(1+tp_r)^2+G1788*(1-MIN(tp_g/tp_roe,0.8))/(1+tp_r)^3+H1788*(1-MIN(tp_g/tp_roe,0.8))/(1+tp_r)^4+I1788*(1-MIN(tp_g/tp_roe,0.8))/(1+tp_r)^5+J1788*(1-MIN(tp_g/tp_roe,0.8))/(1+tp_r)^6+J1788*(1-MIN(tp_g/tp_roe,0.8))*(1+tp_g)/(tp_r-tp_g)/(1+tp_r)^6))*(1+tp_r) -> 80.824298 | H19: =Val!$B$33*(tp_wA*(2/12*E1710+10/12*F1710)+tp_wB*(2/12*E1749+10/12*F1749)+tp_wC*(2/12*E1788+10/12*F1788))*rm_factor -> 68.740177 | I19: =tp_w_dcf*G19+(1-tp_w_dcf)*H19 -> 74.782238 | J19: =I19/I$4-1 -> -0.021222718
A20: 營業外淨額：高 | B20: =TEXT(nonop_f_hi,"0.0")&"（基準 "&TEXT(nonop_f,"0.0")&"）" -> 8.0（基準 4.0） | C20: nonop_f | D20: =E1827 -> 7.8745973 | E20: =F1827 -> 9.0745966 | F20: =E20/E$4-1 -> 0.03102792 | G20: =(tp_wA*MAX(0,E1827*(1-MIN(tp_g/tp_roe,0.8))/(1+tp_r)^1+F1827*(1-MIN(tp_g/tp_roe,0.8))/(1+tp_r)^2+G1827*(1-MIN(tp_g/tp_roe,0.8))/(1+tp_r)^3+H1827*(1-MIN(tp_g/tp_roe,0.8))/(1+tp_r)^4+I1827*(1-MIN(tp_g/tp_roe,0.8))/(1+tp_r)^5+J1827*(1-MIN(tp_g/tp_roe,0.8))/(1+tp_r)^6+J1827*(1-MIN(tp_g/tp_roe,0.8))*(1+tp_g)/(tp_r-tp_g)/(1+tp_r)^6)+tp_wB*MAX(0,E1866*(1-MIN(tp_g/tp_roe,0.8))/(1+tp_r)^1+F1866*(1-MIN(tp_g/tp_roe,0.8))/(1+tp_r)^2+G1866*(1-MIN(tp_g/tp_roe,0.8))/(1+tp_r)^3+H1866*(1-MIN(tp_g/tp_roe,0.8))/(1+tp_r)^4+I1866*(1-MIN(tp_g/tp_roe,0.8))/(1+tp_r)^5+J1866*(1-MIN(tp_g/tp_roe,0.8))/(1+tp_r)^6+J1866*(1-MIN(tp_g/tp_roe,0.8))*(1+tp_g)/(tp_r-tp_g)/(1+tp_r)^6)+tp_wC*MAX(0,E1905*(1-MIN(tp_g/tp_roe,0.8))/(1+tp_r)^1+F1905*(1-MIN(tp_g/tp_roe,0.8))/(1+tp_r)^2+G1905*(1-MIN(tp_g/tp_roe,0.8))/(1+tp_r)^3+H1905*(1-MIN(tp_g/tp_roe,0.8))/(1+tp_r)^4+I1905*(1-MIN(tp_g/tp_roe,0.8))/(1+tp_r)^5+J1905*(1-MIN(tp_g/tp_roe,0.8))/(1+tp_r)^6+J1905*(1-MIN(tp_g/tp_roe,0.8))*(1+tp_g)/(tp_r-tp_g)/(1+tp_r)^6))*(1+tp_r) -> 85.758448 | H20: =Val!$B$33*(tp_wA*(2/12*E1827+10/12*F1827)+tp_wB*(2/12*E1866+10/12*F1866)+tp_wC*(2/12*E1905+10/12*F1905))*rm_factor -> 73.534997 | I20: =tp_w_dcf*G20+(1-tp_w_dcf)*H20 -> 79.646723 | J20: =I20/I$4-1 -> 0.042445436
A21: 稅率：低 | B21: =TEXT(tax_lo,"0%")&"（基準 "&TEXT(tax,"0%")&"）" -> 12%（基準 15%） | C21: tax | D21: =E1944 -> 7.8697933 | E21: =F1944 -> 9.1121456 | F21: =E21/E$4-1 -> 0.035294118 | G21: =(tp_wA*MAX(0,E1944*(1-MIN(tp_g/tp_roe,0.8))/(1+tp_r)^1+F1944*(1-MIN(tp_g/tp_roe,0.8))/(1+tp_r)^2+G1944*(1-MIN(tp_g/tp_roe,0.8))/(1+tp_r)^3+H1944*(1-MIN(tp_g/tp_roe,0.8))/(1+tp_r)^4+I1944*(1-MIN(tp_g/tp_roe,0.8))/(1+tp_r)^5+J1944*(1-MIN(tp_g/tp_roe,0.8))/(1+tp_r)^6+J1944*(1-MIN(tp_g/tp_roe,0.8))*(1+tp_g)/(tp_r-tp_g)/(1+tp_r)^6)+tp_wB*MAX(0,E1983*(1-MIN(tp_g/tp_roe,0.8))/(1+tp_r)^1+F1983*(1-MIN(tp_g/tp_roe,0.8))/(1+tp_r)^2+G1983*(1-MIN(tp_g/tp_roe,0.8))/(1+tp_r)^3+H1983*(1-MIN(tp_g/tp_roe,0.8))/(1+tp_r)^4+I1983*(1-MIN(tp_g/tp_roe,0.8))/(1+tp_r)^5+J1983*(1-MIN(tp_g/tp_roe,0.8))/(1+tp_r)^6+J1983*(1-MIN(tp_g/tp_roe,0.8))*(1+tp_g)/(tp_r-tp_g)/(1+tp_r)^6)+tp_wC*MAX(0,E2022*(1-MIN(tp_g/tp_roe,0.8))/(1+tp_r)^1+F2022*(1-MIN(tp_g/tp_roe,0.8))/(1+tp_r)^2+G2022*(1-MIN(tp_g/tp_roe,0.8))/(1+tp_r)^3+H2022*(1-MIN(tp_g/tp_roe,0.8))/(1+tp_r)^4+I2022*(1-MIN(tp_g/tp_roe,0.8))/(1+tp_r)^5+J2022*(1-MIN(tp_g/tp_roe,0.8))/(1+tp_r)^6+J2022*(1-MIN(tp_g/tp_roe,0.8))*(1+tp_g)/(tp_r-tp_g)/(1+tp_r)^6))*(1+tp_r) -> 85.379686 | H21: =Val!$B$33*(tp_wA*(2/12*E1944+10/12*F1944)+tp_wB*(2/12*E1983+10/12*F1983)+tp_wC*(2/12*E2022+10/12*F2022))*rm_factor -> 72.820984 | I21: =tp_w_dcf*G21+(1-tp_w_dcf)*H21 -> 79.100335 | J21: =I21/I$4-1 -> 0.035294118
