Workbook

Sheet README
A1: 美光 收支與估值模型 v0.3.1（記憶體樣板 v0.3） 2026-10-23
A2: 模型命題：美光的盈餘由一般 DRAM 與 NAND 的合約價循環決定，HBM 份額約與其 DRAM 份額相當（約兩成）；股價取決於循環見頂的年度與見頂時累積的淨值，以及「超額現金 100% 回饋」把淨值轉成買回的速度。
A4: 驅動因子 → 推導量
A5: Path（共用市場層）：一般 DRAM、NAND 合約價季增 → 季度指數（情境 A／B／C）；各公司依會計年度取平均，算年均價變動
A6: Mkt（共用市場層）：加速器顆數 × 每顆 GB × 情境顆數係數（2028–29，與台積電、Advantest 同一套）→ 需求位元；MIN(需求, 供給（三情境相同）) → 出貨；× 單價（依情境）→ HBM 市場（日曆年）
A7: Q：最後實績季 × 公司指引 × TrendForce 季價 → 基準年剩餘季度
A8: Y：前一年 × (1＋位元) × 價格指數比 → 一般 DRAM、NAND；Σ 各季 HBM 市場 × 市占 → HBM；成本量 × (1 − 年降)＋折舊 → 營業利益 → 淨利 → 權益 → 每股淨值
A9: Val：每股淨值 × P/B（主）、EPS × P/E（對照）
A10: Sens：各收入線同幅變動對營業利益的影響
A11: 非記憶體事業（只有三星）：營收與營業利益為輸入，不建模
A12: Recon：與共識、公司指引事後對照
A14: 情境：A＝2027–28 高檔持平、2029 緩降（BofA、TrendForce 型）；B＝2027 Q2 見頂、2028 回落約一半、2029 溫和回升（Citi、Bernstein 型）；C＝2028 回到 2025 年價格水準、2029 自谷底回升（完整循環）
... A23: 已知簡化：會計年度與日曆季對齊差約 1 個月；HBM 營收美光未揭露（由市場 × 市占推得）；FQ4-26 為 14 週。

Sheet In
A1: In — 輸入（藍字＝基準值；低／高供敏感度）。每列具名範圍＝鍵（指向 E 欄）。單位：十億美元
A3: 鍵 | B3: 項目 | C3: 單位 | D3: 低 | E3: 基準 | F3: 高 | G3: 標記 | H3: 來源／說明
A4: A. 股價
A5: px | B5: 股價（2026-10-07 收盤） | C5: USD | E5: 1088 | G5: Interested-party | H5: StockAnalysis、MarketBeat
A6: fx | B6: （美元公司不使用匯率） | C6: — | E6: 1 | G6: Verified
A7: B. 季度推估用（美光基準年 FY26 全為實績，以下不使用，保留樣板欄位）
A8: costdn_q | B8: 單位成本季降 | C8: % | E8: 0.03 | G8: Assumed | H8: 不使用
A9: opex_fix_q | B9: 營業費用固定部分（每季） | C9: 十億美元 | E9: 1.25 | G9: Assumed | H9: 不使用
A10: nonop_q | B10: 每季業外淨收益 | C10: 十億美元 | E10: 0.6 | G10: Assumed | H10: 不使用
A11: C. 年度驅動（公司別）
A12: cb_1 | B12: 一般 DRAM 位元成長 FY27 | C12: % | D12: 0.06 | E12: 0.12 | F12: 0.18 | G12: Verified／Derived | H12: 美光：產業 DRAM 位元 CY27 低 20% 段（含 HBM）；HBM 吃掉部分晶圓
A13: cb_2 | B13: 一般 DRAM 位元成長 FY28 | C13: % | D13: 0.1 | E13: 0.15 | F13: 0.2 | G13: Verified／Derived | H13: 同上
A14: nb_1 | B14: NAND 位元成長 FY27 | C14: % | D14: 0.12 | E14: 0.18 | F14: 0.25 | G14: Verified | H14: 美光：產業 CY27 中 20% 段；美光供給低於產業
A15: nb_2 | B15: NAND 位元成長 FY28 | C15: % | D15: 0.15 | E15: 0.2 | F15: 0.25 | G15: Verified | H15: 同上
A16: sh25 | B16: HBM 營收市占 2025 | C16: % | D16: 0.18 | E16: 0.21 | F16: 0.22 | G16: Interested-party | H16: Counterpoint 3Q25 21%；美光：與 DRAM 市占相當
A17: sh26 | B17: HBM 營收市占 2026 | C17: % | D17: 0.17 | E17: 0.19 | F17: 0.21 | G17: Interested-party | H17: Counterpoint Q1 21%、Q2 18%
A18: sh27 | B18: HBM 營收市占 2027 | C18: % | D18: 0.17 | E18: 0.2 | F18: 0.23 | G18: Interested-party | H18: UBS 2027 位元 20%
A19: sh28 | B19: HBM 營收市占 2028 | C19: % | D19: 0.17 | E19: 0.2 | F19: 0.23 | G19: Assumed
A20: other_y | B20: 其他營收（每年） | C20: 十億美元 | E20: 0.7 | G20: Derived | H20: FY26 營收 − DRAM − NAND
A21: w_c | B21: 成本權重：一般 DRAM | C21: % | E21: 0.5 | G21: Assumed
A22: w_h | B22: 成本權重：HBM | C22: % | E22: 0.22 | G22: Assumed | H22: HBM 3:1 晶圓（美光）
A23: w_n | B23: 成本權重：NAND | C23: % | E23: 0.28 | G23: Assumed | H23: NAND 約 24% 營收、毛利較低
A24: costdn_y | B24: 單位成本年降 | C24: % | D24: 0.05 | E24: 0.1 | F24: 0.15 | G24: Assumed
A25: da_life | B25: 新增資本支出轉為折舊的年數 | C25: 年 | D25: 4 | E25: 5 | F25: 6 | G25: Assumed
A26: da_cogs | B26: 折舊計入營業成本比例 | C26: % | E26: 0.9 | G26: Assumed
A27: opex_fix_y | B27: 營業費用固定部分（年，基準年） | C27: 十億美元 | E27: 5 | G27: Derived | H27: FY26 營業費用 7.6（GAAP）；FY27 指引約 +2.5（研發、獎金）
A28: opex_var | B28: 營業費用變動率 | C28: % 營收 | D28: 0.01 | E28: 0.015 | F28: 0.03 | G28: Derived | H28: 使 FY27 營業費用約 9.3–10（指引口徑）
A29: opex_g | B29: 營業費用固定部分年增 | C29: % | E29: 0.15 | G29: Derived | H29: 研發擴張
A30: tax | B30: 有效稅率 | C30: % | D30: 0.14 | E30: 0.155 | F30: 0.18 | G30: Verified | H30: FY26 14.8%；FY27 指引約 15.5%
A31: rf | B31: 淨現金收益率 | C31: % | E31: 0.04 | G31: Assumed | H31: 美元利率
A32: cap_0 | B32: 資本支出 FY26（淨） | C32: 十億美元 | E32: 27.367 | G32: Verified | H32: FY26 8-K（毛 30.7）
A33: cap_1 | B33: 資本支出 FY27 | C33: 十億美元 | D33: 50 | E33: 55 | F33: 65 | G33: Derived | H33: FQ1 約 11.5、上半年約 25、下半年更高（書面說明）
A34: cap_2 | B34: 資本支出 FY28 | C34: 十億美元 | D34: 50 | E34: 60 | F34: 75 | G34: Assumed
A35: cb_3 | B35: 一般 DRAM 位元成長 FY29 | C35: % | D35: 0.1 | E35: 0.15 | F35: 0.2 | G35: Assumed
A36: nb_3 | B36: NAND 位元成長 FY29 | C36: % | D36: 0.15 | E36: 0.2 | F36: 0.25 | G36: Assumed
A37: sh29 | B37: HBM 營收市占 2029 | C37: % | D37: 0.17 | E37: 0.2 | F37: 0.23 | G37: Assumed
A38: cap_3 | B38: 資本支出 FY29 | C38: 十億美元 | D38: 50 | E38: 60 | F38: 75 | G38: Assumed
A39: dps_3 | B39: 每股股利 FY29 | C39: USD | E39: 0.85 | G39: Assumed
A40: nm_op_q | B40: 非記憶體事業每季營業利益（基準年推估季） | C40: — | E40: 0 | G40: Verified | H40: 純記憶體公司，無
A41: nm_rev_0 | B41: 非記憶體事業營收 第 0 年 | C41: — | E41: 0 | G41: Verified | H41: 無
...

Sheet Path
A1: Path — 記憶體合約價指數（2025Q1＝1；季增來自 In 頁 M1）。共用市場層：所有記憶體公司用同一條路徑，再依各自會計年度取平均
A3: 路徑 | B3: 情境 | C3: 2025Q1 | D3: 2025Q2 | E3: 2025Q3 | F3: 2025Q4 | G3: 2026Q1 | H3: 2026Q2 | I3: 2026Q3 | J3: 2026Q4 | K3: 2027Q1 | L3: 2027Q2 | M3: 2027Q3 | N3: 2027Q4 | O3: 2028Q1 | P3: 2028Q2 | Q3: 2028Q3 | R3: 2028Q4 | S3: 2029Q1 | T3: 2029Q2 | U3: 2029Q3 | V3: 2029Q4
A4: 一般 DRAM | B4: A | C4: 1 | D4: =C4*(1+cq_1) -> 0.975 | E4: =D4*(1+cq_2) -> 1.096875 | F4: =E4*(1+cq_3) -> 1.6178906 | G4: =F4*(1+cq_4) -> 3.1548867 | H4: =G4*(1+cq_5) -> 5.0635932 | I4: =H4*(1+cq_6) -> 5.8484501 | J4: =I4*(1+cq_7) -> 6.5795064 | K4: =J4*(1+cqA_8) -> 6.7768916 | L4: =K4*(1+cqA_9) -> 6.7768916 | M4: =L4*(1+cqA_10) -> 6.6413538 | N4: =M4*(1+cqA_11) -> 6.4421131 | O4: =N4*(1+cqA_12) -> 6.2488497 | P4: =O4*(1+cqA_13) -> 6.0613843 | Q4: =P4*(1+cqA_14) -> 5.9401566 | R4: =Q4*(1+cqA_15) -> 5.8213534 | S4: =R4*(1+cqA_16) -> 5.6467128 | T4: =S4*(1+cqA_17) -> 5.4773114 | U4: =T4*(1+cqA_18) -> 5.3677652 | V4: =U4*(1+cqA_19) -> 5.2604099
A5: 一般 DRAM | B5: B | C5: 1 | D5: =C5*(1+cq_1) -> 0.975 | E5: =D5*(1+cq_2) -> 1.096875 | F5: =E5*(1+cq_3) -> 1.6178906 | G5: =F5*(1+cq_4) -> 3.1548867 | H5: =G5*(1+cq_5) -> 5.0635932 | I5: =H5*(1+cq_6) -> 5.8484501 | J5: =I5*(1+cq_7) -> 6.5795064 | K5: =J5*(1+cqB_8) -> 6.9084817 | L5: =K5*(1+cqB_9) -> 7.0466513 | M5: =L5*(1+cqB_10) -> 6.4829192 | N5: =M5*(1+cqB_11) -> 5.5104814 | O5: =N5*(1+cqB_12) -> 4.132861 | P5: =O5*(1+cqB_13) -> 3.5129319 | Q5: =P5*(1+cqB_14) -> 3.1616387 | R5: =Q5*(1+cqB_15) -> 3.0035567 | S5: =R5*(1+cqB_16) -> 3.1537346 | T5: =S5*(1+cqB_17) -> 3.3114213 | U5: =T5*(1+cqB_18) -> 3.4107639 | V5: =U5*(1+cqB_19) -> 3.5130869
A6: 一般 DRAM | B6: C | C6: 1 | D6: =C6*(1+cq_1) -> 0.975 | E6: =D6*(1+cq_2) -> 1.096875 | F6: =E6*(1+cq_3) -> 1.6178906 | G6: =F6*(1+cq_4) -> 3.1548867 | H6: =G6*(1+cq_5) -> 5.0635932 | I6: =H6*(1+cq_6) -> 5.8484501 | J6: =I6*(1+cq_7) -> 6.5795064 | K6: =J6*(1+cqC_8) -> 6.9084817 | L6: =K6*(1+cqC_9) -> 7.0466513 | M6: =L6*(1+cqC_10) -> 6.4829192 | N6: =M6*(1+cqC_11) -> 5.5104814 | O6: =N6*(1+cqC_12) -> 3.5818129 | P6: =O6*(1+cqC_13) -> 2.507269 | Q6: =P6*(1+cqC_14) -> 1.8804518 | R6: =Q6*(1+cqC_15) -> 1.5043614 | S6: =R6*(1+cqC_16) -> 1.5043614 | T6: =S6*(1+cqC_17) -> 1.5795795 | U6: =T6*(1+cqC_18) -> 1.7059458 | V6: =U6*(1+cqC_19) -> 1.8765404
A8: NAND | B8: A | C8: 1 | D8: =C8*(1+nq_1) -> 1 | E8: =D8*(1+nq_2) -> 1.05 | F8: =E8*(1+nq_3) -> 1.365 | G8: =F8*(1+nq_4) -> 2.559375 | H8: =G8*(1+nq_5) -> 4.4149219 | I8: =H8*(1+nq_6) -> 5.0771602 | J8: =I8*(1+nq_7) -> 5.9656632 | K8: =J8*(1+nqA_8) -> 6.1446331 | L8: =K8*(1+nqA_9) -> 6.1446331 | M8: =L8*(1+nqA_10) -> 5.8374014 | N8: =M8*(1+nqA_11) -> 5.4287833 | O8: =N8*(1+nqA_12) -> 5.1573442 | P8: =O8*(1+nqA_13) -> 4.899477 | Q8: =P8*(1+nqA_14) -> 4.6545031 | R8: =Q8*(1+nqA_15) -> 4.4217779 | S8: =R8*(1+nqA_16) -> 4.2891246 | T8: =S8*(1+nqA_17) -> 4.1604509 | U8: =T8*(1+nqA_18) -> 4.0356373 | V8: =U8*(1+nqA_19) -> 3.9145682
A9: NAND | B9: B | C9: 1 | D9: =C9*(1+nq_1) -> 1 | E9: =D9*(1+nq_2) -> 1.05 | F9: =E9*(1+nq_3) -> 1.365 | G9: =F9*(1+nq_4) -> 2.559375 | H9: =G9*(1+nq_5) -> 4.4149219 | I9: =H9*(1+nq_6) -> 5.0771602 | J9: =I9*(1+nq_7) -> 5.9656632 | K9: =J9*(1+nqB_8) -> 6.2639463 | L9: =K9*(1+nqB_9) -> 6.3892253 | M9: =L9*(1+nqB_10) -> 5.7503027 | N9: =M9*(1+nqB_11) -> 4.6002422 | O9: =N9*(1+nqB_12) -> 3.2201695 | P9: =O9*(1+nqB_13) -> 2.4151272 | Q9: =P9*(1+nqB_14) -> 1.9321017 | R9: =Q9*(1+nqB_15) -> 1.7388915 | S9: =R9*(1+nqB_16) -> 1.8258361 | T9: =S9*(1+nqB_17) -> 1.9171279 | U9: =T9*(1+nqB_18) -> 1.9746418 | V9: =U9*(1+nqB_19) -> 2.033881
A10: NAND | B10: C | C10: 1 | D10: =C10*(1+nq_1) -> 1 | E10: =D10*(1+nq_2) -> 1.05 | F10: =E10*(1+nq_3) -> 1.365 | G10: =F10*(1+nq_4) -> 2.559375 | H10: =G10*(1+nq_5) -> 4.4149219 | I10: =H10*(1+nq_6) -> 5.0771602 | J10: =I10*(1+nq_7) -> 5.9656632 | K10: =J10*(1+nqC_8) -> 6.2639463 | L10: =K10*(1+nqC_9) -> 6.3892253 | M10: =L10*(1+nqC_10) -> 5.7503027 | N10: =M10*(1+nqC_11) -> 4.6002422 | O10: =N10*(1+nqC_12) -> 2.9901574 | P10: =O10*(1+nqC_13) -> 1.9436023 | Q10: =P10*(1+nqC_14) -> 1.4577017 | R10: =Q10*(1+nqC_15) -> 1.1661614 | S10: =R10*(1+nqC_16) -> 1.1661614 | T10: =S10*(1+nqC_17) -> 1.2244695 | U10: =T10*(1+nqC_18) -> 1.322427 | V10: =U10*(1+nqC_19) -> 1.4546697
A12: 年均指數
A13: 路徑 | B13: 情境 | C13: 2025 | D13: 2026 | E13: 2027 | F13: 2028 | G13: 2029 | H13: 2026÷2025 | I13: 2027÷2026 | J13: 2028÷2027 | K13: 2029÷2028
A14: 一般 DRAM | B14: A | C14: =AVERAGE(C4:F4) -> 1.1724414 | D14: =AVERAGE(G4:J4) -> 5.1616091 | E14: =AVERAGE(K4:N4) -> 6.6593125 | F14: =AVERAGE(O4:R4) -> 6.017936 | G14: =AVERAGE(S4:V4) -> 5.4380499 | H14: =D14/C14-1 -> 3.4024453 | I14: =E14/D14-1 -> 0.29016211 | J14: =F14/E14-1 -> -0.096312722 | K14: =G14/F14-1 -> -0.09635964
A15: 一般 DRAM | B15: B | C15: =AVERAGE(C5:F5) -> 1.1724414 | D15: =AVERAGE(G5:J5) -> 5.1616091 | E15: =AVERAGE(K5:N5) -> 6.4871334 | F15: =AVERAGE(O5:R5) -> 3.4527471 | G15: =AVERAGE(S5:V5) -> 3.3472517 | H15: =D15/C15-1 -> 3.4024453 | I15: =E15/D15-1 -> 0.25680447 | J15: =F15/E15-1 -> -0.46775458 | K15: =G15/F15-1 -> -0.030554048
A16: 一般 DRAM | B16: C | C16: =AVERAGE(C6:F6) -> 1.1724414 | D16: =AVERAGE(G6:J6) -> 5.1616091 | E16: =AVERAGE(K6:N6) -> 6.4871334 | F16: =AVERAGE(O6:R6) -> 2.3684738 | G16: =AVERAGE(S6:V6) -> 1.6666068 | H16: =D16/C16-1 -> 3.4024453 | I16: =E16/D16-1 -> 0.25680447 | J16: =F16/E16-1 -> -0.63489671 | K16: =G16/F16-1 -> -0.29633724
A17: NAND | B17: A | C17: =AVERAGE(C8:F8) -> 1.10375 | D17: =AVERAGE(G8:J8) -> 4.5042801 | E17: =AVERAGE(K8:N8) -> 5.8888627 | F17: =AVERAGE(O8:R8) -> 4.7832755 | G17: =AVERAGE(S8:V8) -> 4.0999453 | H17: =D17/C17-1 -> 3.0808879 | I17: =E17/D17-1 -> 0.30739267 | J17: =F17/E17-1 -> -0.18774205 | K17: =G17/F17-1 -> -0.14285823
A18: NAND | B18: B | C18: =AVERAGE(C9:F9) -> 1.10375 | D18: =AVERAGE(G9:J9) -> 4.5042801 | E18: =AVERAGE(K9:N9) -> 5.7509291 | F18: =AVERAGE(O9:R9) -> 2.3265725 | G18: =AVERAGE(S9:V9) -> 1.9378717 | H18: =D18/C18-1 -> 3.0808879 | I18: =E18/D18-1 -> 0.27676989 | J18: =F18/E18-1 -> -0.59544407 | K18: =G18/F18-1 -> -0.16707013
A19: NAND | B19: C | C19: =AVERAGE(C10:F10) -> 1.10375 | D19: =AVERAGE(G10:J10) -> 4.5042801 | E19: =AVERAGE(K10:N10) -> 5.7509291 | F19: =AVERAGE(O10:R10) -> 1.8894057 | G19: =AVERAGE(S10:V10) -> 1.2919319 | H19: =D19/C19-1 -> 3.0808879 | I19: =E19/D19-1 -> 0.27676989 | J19: =F19/E19-1 -> -0.67146079 | K19: =G19/F19-1 -> -0.31622315

Sheet Mkt
A1: Mkt — 加速器數量層（最小版）與 HBM 市場（日曆年）。需求＝顆數 × GB × 情境顆數係數（2028–29）；供給三情境相同；出貨＝MIN(需求, 供給)；市場＝出貨 × 單價（單價依情境）
A3: 項目 | B3: 單位 | C3: 2025 | D3: 2026 | E3: 2027 | F3: 2028 | G3: 2029 | H3: 說明
A4: 需求：加速器裝載的 HBM（PB）
A5: NVIDIA Blackwell（B200／B300） | B5: PB | D5: =u_bw_26*g_bw_26 -> 1404 | E5: =u_bw_27*g_bw_27 -> 672 | F5: =u_bw_28*g_bw_28 -> 144
A6: NVIDIA Rubin | B6: PB | D6: =u_rb_26*g_rb_26 -> 489.6 | E6: =u_rb_27*g_rb_27 -> 2016 | F6: =u_rb_28*g_rb_28 -> 2016
A7: NVIDIA Rubin Ultra | B7: PB | D7: =u_ru_26*g_ru_26 -> 0 | E7: =u_ru_27*g_ru_27 -> 307.2 | F7: =u_ru_28*g_ru_28 -> 2048
A8: NVIDIA Hopper（H200 等） | B8: PB | D8: =u_hp_26*g_hp_26 -> 70.5 | E8: =u_hp_27*g_hp_27 -> 0 | F8: =u_hp_28*g_hp_28 -> 0
A9: AMD Instinct | B9: PB | D9: =u_amd_26*g_amd_26 -> 216 | E9: =u_amd_27*g_amd_27 -> 540 | F9: =u_amd_28*g_amd_28 -> 864
A10: Google TPU | B10: PB | D10: =u_tpu_26*g_tpu_26 -> 739.2 | E10: =u_tpu_27*g_tpu_27 -> 1375 | F10: =u_tpu_28*g_tpu_28 -> 2016
A11: AWS Trainium | B11: PB | D11: =u_trn_26*g_trn_26 -> 220 | E11: =u_trn_27*g_trn_27 -> 360 | F11: =u_trn_28*g_trn_28 -> 600
A12: 其他 ASIC（MTIA、Maia、Ascend 等） | B12: PB | D12: =u_oth_26*g_oth_26 -> 150 | E12: =u_oth_27*g_oth_27 -> 900 | F12: =u_oth_28*g_oth_28 -> 1250
A13: 需求合計（裝載） | B13: EB | D13: =SUM(D5:D12)/1000 -> 3.2893 | E13: =SUM(E5:E12)/1000 -> 6.1702 | F13: =SUM(F5:F12)/1000 -> 8.938 | G13: =F13*(1+hbm_dem29) -> 11.6194
A14: 需求 × 出貨係數（基準＝情境 A） | B14: EB | D14: =D13*hbm_gross -> 3.782695 | E14: =E13*hbm_gross -> 7.09573 | F14: =F13*hbm_gross -> 10.2787 | G14: =G13*hbm_gross -> 13.36231
A15: 加速器顆數合計 | B15: 百萬顆 | D15: =u_bw_26+u_rb_26+u_ru_26+u_hp_26+u_amd_26+u_tpu_26+u_trn_26+u_oth_26 -> 15.2 | E15: =u_bw_27+u_rb_27+u_ru_27+u_hp_27+u_amd_27+u_tpu_27+u_trn_27+u_oth_27 -> 23.7 | F15: =u_bw_28+u_rb_28+u_ru_28+u_hp_28+u_amd_28+u_tpu_28+u_trn_28+u_oth_28 -> 26.5 | H15: JPMorgan 2027：GPU 10.9M、ASIC 12.5M；情境 A 基準
A16: 每顆平均 HBM | B16: GB | D16: =D13*1000/D15 -> 216.40132 | E16: =E13*1000/E15 -> 260.34599 | F16: =F13*1000/F15 -> 337.28302
A17: 供給（三情境相同） | B17: EB | C17: =D17/(1+hbm_g26) -> 2.2251147 | D17: =D14 -> 3.782695 | E17: =D17*(1+hbm_sup27) -> 5.8631772 | F17: =E17*(1+hbm_sup28) -> 8.501607 | G17: =F17*(1+hbm_sup29) -> 11.477169 | H17: 2026 供給＝需求出貨（年中已成交）；供給不隨需求情境變（產能 2027 前已訂定）
A18: 顆數係數（A；2028–29 ÷ 基準，與台積電、Advantest 同一套） | B18: x | D18: 1 | E18: 1 | F18: =um28_A -> 1 | G18: =um29_A -> 1 | H18: 2026–27 無情境差異
A19: 顆數係數（B；2028–29 ÷ 基準，與台積電、Advantest 同一套） | B19: x | D19: 1 | E19: 1 | F19: =um28_B -> 0.8 | G19: =um29_B -> 0.85 | H19: 2026–27 無情境差異
A20: 顆數係數（C；2028–29 ÷ 基準，與台積電、Advantest 同一套） | B20: x | D20: 1 | E20: 1 | F20: =um28_C -> 0.6 | G20: =um29_C -> 0.6 | H20: 2026–27 無情境差異
A21: 需求 × 出貨係數（A） | B21: EB | D21: =D14*D18 -> 3.782695 | E21: =E14*E18 -> 7.09573 | F21: =F14*F18 -> 10.2787 | G21: =G14*G18 -> 13.36231
A22: 需求 × 出貨係數（B） | B22: EB | D22: =D14*D19 -> 3.782695 | E22: =E14*E19 -> 7.09573 | F22: =F14*F19 -> 8.22296 | G22: =G14*G19 -> 11.357964
A23: 需求 × 出貨係數（C） | B23: EB | D23: =D14*D20 -> 3.782695 | E23: =E14*E20 -> 7.09573 | F23: =F14*F20 -> 6.16722 | G23: =G14*G20 -> 8.017386
A24: 出貨＝MIN(需求, 供給)（A） | B24: EB | C24: =C17 -> 2.2251147 | D24: =MIN(D21,D17) -> 3.782695 | E24: =MIN(E21,E17) -> 5.8631772 | F24: =MIN(F21,F17) -> 8.501607 | G24: =MIN(G21,G17) -> 11.477169 | H24: 需求低於供給時出貨＝需求（閒置產能）
A25: 出貨＝MIN(需求, 供給)（B） | B25: EB | C25: =C17 -> 2.2251147 | D25: =MIN(D22,D17) -> 3.782695 | E25: =MIN(E22,E17) -> 5.8631772 | F25: =MIN(F22,F17) -> 8.22296 | G25: =MIN(G22,G17) -> 11.357964
A26: 出貨＝MIN(需求, 供給)（C） | B26: EB | C26: =C17 -> 2.2251147 | D26: =MIN(D23,D17) -> 3.782695 | E26: =MIN(E23,E17) -> 5.8631772 | F26: =MIN(F23,F17) -> 6.16722 | G26: =MIN(G23,G17) -> 8.017386
A27: 需求 − 供給（A；>0＝短缺） | B27: EB | D27: =D21-D17 -> 0 | E27: =E21-E17 -> 1.2325527 | F27: =F21-F17 -> 1.777093 | G27: =G21-G17 -> 1.8851405
A28: 需求 − 供給（B；>0＝短缺） | B28: EB | D28: =D22-D17 -> 0 | E28: =E22-E17 -> 1.2325527 | F28: =F22-F17 -> -0.27864701 | G28: =G22-G17 -> -0.11920597
A29: 需求 − 供給（C；>0＝短缺） | B29: EB | D29: =D23-D17 -> 0 | E29: =E23-E17 -> 1.2325527 | F29: =F23-F17 -> -2.334387 | G29: =G23-G17 -> -3.4597835
A30: HBM 單價（A） | B30: $/GB | C30: =hbm_mkt25/C24 -> 15.729526 | D30: =hbm_p26 -> 14.6 | E30: =D30*(1+hbm_p27) -> 26.28 | F30: =E30*(1+hbm_p28_A) -> 28.908 | G30: =F30*(1+hbm_p29_A) -> 27.4626
A31: HBM 單價（B） | B31: $/GB | C31: =hbm_mkt25/C24 -> 15.729526 | D31: =hbm_p26 -> 14.6 | E31: =D31*(1+hbm_p27) -> 26.28 | F31: =E31*(1+hbm_p28_B) -> 19.71 | G31: =F31*(1+hbm_p29_B) -> 19.71
A32: HBM 單價（C） | B32: $/GB | C32: =hbm_mkt25/C24 -> 15.729526 | D32: =hbm_p26 -> 14.6 | E32: =D32*(1+hbm_p27) -> 26.28 | F32: =E32*(1+hbm_p28_C) -> 15.768 | G32: =F32*(1+hbm_p29_C) -> 16.5564
A33: HBM 市場（A） | B33: $B | C33: =C24*C30 -> 35 | D33: =D24*D30 -> 55.227347 | E33: =E24*E30 -> 154.0843 | F33: =F24*F30 -> 245.76446 | G33: =G24*G30 -> 315.19291
A34: HBM 市場（B） | B34: $B | C34: =C25*C31 -> 35 | D34: =D25*D31 -> 55.227347 | E34: =E25*E31 -> 154.0843 | F34: =F25*F31 -> 162.07454 | G34: =G25*G31 -> 223.86546
A35: HBM 市場（C） | B35: $B | C35: =C26*C32 -> 35 | D35: =D26*D32 -> 55.227347 | E35: =E26*E32 -> 154.0843 | F35: =F26*F32 -> 97.244725 | G35: =G26*G32 -> 132.73905
A37: 對帳（樣板驗收 2）
A38: 由下而上：NVIDIA 裝載 HBM × 單價（2026） | B38: $B | D38: =(D5+D6+D7+D8)/1000*hbm_p26 -> 28.67586
A39: 由上而下：NVIDIA 資料中心營收 × 每顆 HBM ÷ 每顆 NVIDIA 內容（2026） | B39: $B | D39: =nv_dc26*nv_hbm/nv_content -> 38.972897 | H39: 橋接表 v0.2；與顆數預測獨立
A40: 差距 | B40: % | D40: =D38/D39-1 -> -0.26421021
A41: 由營收推得 NVIDIA 顆數 vs 顆數預測 | B41: 百萬顆 | D41: =nv_dc26/nv_content -> 8.7383178 | E41: =u_bw_26+u_rb_26+u_hp_26 -> 7.6 | H41: D＝營收推得；E＝顆數預測（2026）
A42: 已發布：SK 海力士自估 2026／BofA 2026／BofA 2027 | B42: $B | D42: =pub26_lo -> 54.6 | E42: =pub26_hi -> 77.4 | F42: =pub27 -> 152.8
...

Sheet Q
A1: Q — 季度損益（十億美元）。實績：SEC 8-K 財報新聞稿、10-Q、10-K、CFO 書面說明；推估季：實績 × 公司指引 × TrendForce 價格
A3: 項目 | B3: FQ1-25 | C3: FQ2-25 | D3: FQ3-25 | E3: FQ4-25 | F3: FQ1-26 | G3: FQ2-26 | H3: FQ3-26 | I3: FQ4-26 | J3: FY2026 合計
A4: 記憶體營收 | B4: 8.709 | C4: 8.053 | D4: 9.301 | E4: 11.315 | F4: 13.643 | G4: 23.86 | H4: 41.456 | I4: 54.229 | J4: =SUM(F4:I4) -> 133.188
A5: DRAM（含 HBM） | B5: 6.4 | C5: 6.123 | D5: 7.071 | E5: 8.984 | F5: 10.812 | G5: 18.768 | H5: 31.328 | I5: 39.8 | J5: =SUM(F5:I5) -> 100.708
A6: NAND | B6: 2.241 | C6: 1.855 | D6: 2.155 | E6: 2.252 | F6: 2.743 | G6: 4.997 | H6: 9.943 | I6: 14.1 | J6: =SUM(F6:I6) -> 31.783
A7: 其他 | B7: =B4-B5-B6 -> 0.068 | C7: =C4-C5-C6 -> 0.075 | D7: =D4-D5-D6 -> 0.075 | E7: =E4-E5-E6 -> 0.079 | F7: =F4-F5-F6 -> 0.088 | G7: =G4-G5-G6 -> 0.095 | H7: =H4-H5-H6 -> 0.185 | I7: =I4-I5-I6 -> 0.329 | J7: =SUM(F7:I7) -> 0.697
A8: 營業成本 | B8: =B4*(1-0.384) -> 5.364744 | C8: =C4*(1-0.368) -> 5.089496 | D8: =D4*(1-0.377) -> 5.794523 | E8: =E4*(1-0.447) -> 6.257195 | F8: =F4*(1-0.56) -> 6.00292 | G8: =G4*(1-0.744) -> 6.10816 | H8: =H4*(1-0.846) -> 6.384224 | I8: =I4*(1-0.868) -> 7.158228 | J8: =SUM(F8:I8) -> 25.653532
A9: 營業費用 | B9: =B4-B8-B10 -> 1.170256 | C9: =C4-C8-C10 -> 1.190504 | D9: =D4-D8-D10 -> 1.337477 | E9: =E4-E8-E10 -> 1.403805 | F9: =F4-F8-F10 -> 1.50408 | G9: =G4-G8-G10 -> 1.61684 | H9: =H4-H8-H10 -> 1.753776 | I9: =I4-I8-I10 -> 3.319772 | J9: =SUM(F9:I9) -> 8.194468
A10: 記憶體營業利益 | B10: 2.174 | C10: 1.773 | D10: 2.169 | E10: 3.654 | F10: 6.136 | G10: 16.135 | H10: 33.318 | I10: 43.751 | J10: =SUM(F10:I10) -> 99.34
A11: 記憶體營業利益率 | B11: =IF(B4=0,"",B10/B4) -> 0.24962682 | C11: =IF(C4=0,"",C10/C4) -> 0.2201664 | D11: =IF(D4=0,"",D10/D4) -> 0.23320073 | E11: =IF(E4=0,"",E10/E4) -> 0.32293416 | F11: =IF(F4=0,"",F10/F4) -> 0.44975445 | G11: =IF(G4=0,"",G10/G4) -> 0.67623638 | H11: =IF(H4=0,"",H10/H4) -> 0.80369548 | I11: =IF(I4=0,"",I10/I4) -> 0.80678235 | J11: =J10/J4 -> 0.74586299
A12: 淨利（合併，含非記憶體事業） | B12: 1.87 | C12: 1.583 | D12: 1.885 | E12: 3.201 | F12: 5.24 | G12: 13.785 | H12: 28.243 | I12: 37.701 | J12: =SUM(F12:I12) -> 84.969
A13: 折舊攤銷 | B13: 2.03 | C13: 2.079 | D13: 2.094 | E13: 2.149 | F13: 2.212 | G13: 2.286 | H13: 2.364 | I13: 2.641 | J13: =SUM(F13:I13) -> 9.503
A14: DRAM 位元指數（最後實績季＝1） | I14: 1
A15: NAND 位元指數 | I15: 1
A18: 營業成本＝營收 × (1 − GAAP 毛利率)；FQ4-26 為 14 週，DRAM／NAND 依書面說明 73%／26%（10-K 未出）

Sheet Y
A1: Y — 年度（十億美元；股數百萬股）。情境 A：2027–28 高檔持平、2029 緩降（BofA、TrendForce 型）；B：2027 Q2 見頂、2028 回落約一半、2029 溫和回升（Citi、Bernstein 型）；C：2028 回到 2025 年價格水準、2029 自谷底回升（完整循環）
A3: 項目 | B3: FY2025 實績 | C3: FY2026（基準） | D3: FY2027 A | E3: FY2028 A | F3: FY2029 A | G3: FY2027 B | H3: FY2028 B | I3: FY2029 B | J3: FY2027 C | K3: FY2028 C | L3: FY2029 C | M3: 說明
A4: 記憶體營收 | B4: =SUM(Q!B4:E4) -> 37.378 | C4: =Q!J4 -> 133.188 | D4: =D5+D6+D7+D8 -> 267.76573 | E4: =E5+E6+E7+E8 -> 297.34867 | F4: =F5+F6+F7+F8 -> 308.91055 | G4: =G5+G6+G7+G8 -> 270.11798 | H4: =H5+H6+H7+H8 -> 195.47076 | I4: =I5+I6+I7+I8 -> 251.83093 | J4: =J5+J6+J7+J8 -> 270.11798 | K4: =K5+K6+K7+K8 -> 160.59477 | L4: =L5+L6+L7+L8 -> 156.0311
A5: 一般 DRAM | C5: =Q!J5-C6 -> 91.000603 | D5: =C5*(1+cb_1)*(AVERAGE(Path!J4:M4)/AVERAGE(Path!F4:I4)) -> 173.98285 | E5: =D5*(1+cb_2)*(AVERAGE(Path!N4:Q4)/AVERAGE(Path!J4:M4)) -> 184.52096 | F5: =D5*(1+cb_3)*(AVERAGE(Path!R4:U4)/AVERAGE(Path!N4:Q4)) -> 180.80061 | G5: =C5*(1+cb_1)*(AVERAGE(Path!J5:M5)/AVERAGE(Path!F5:I5)) -> 175.56132 | H5: =G5*(1+cb_2)*(AVERAGE(Path!N5:Q5)/AVERAGE(Path!J5:M5)) -> 121.93972 | I5: =G5*(1+cb_3)*(AVERAGE(Path!R5:U5)/AVERAGE(Path!N5:Q5)) -> 159.35301 | J5: =C5*(1+cb_1)*(AVERAGE(Path!J6:M6)/AVERAGE(Path!F6:I6)) -> 175.56132 | K5: =J5*(1+cb_2)*(AVERAGE(Path!N6:Q6)/AVERAGE(Path!J6:M6)) -> 100.73281 | L5: =J5*(1+cb_3)*(AVERAGE(Path!R6:U6)/AVERAGE(Path!N6:Q6)) -> 94.271445 | M5: 前一年 × (1＋位元) × 會計年度價格指數平均比（Path）
A6: HBM | C6: =(Mkt!C33/4*sh25+Mkt!D33/4*sh26+Mkt!D33/4*sh26+Mkt!D33/4*sh26)*1 -> 9.7073969 | D6: =(Mkt!D33/4*sh26+Mkt!E33/4*sh27+Mkt!E33/4*sh27+Mkt!E33/4*sh27)*1 -> 25.735944 | E6: =(Mkt!E33/4*sh27+Mkt!F33/4*sh28+Mkt!F33/4*sh28+Mkt!F33/4*sh28)*1 -> 44.568883 | F6: =(Mkt!F33/4*sh28+Mkt!G33/4*sh29+Mkt!G33/4*sh29+Mkt!G33/4*sh29)*1 -> 59.56716 | G6: =(Mkt!D34/4*sh26+Mkt!E34/4*sh27+Mkt!E34/4*sh27+Mkt!E34/4*sh27)*1 -> 25.735944 | H6: =(Mkt!E34/4*sh27+Mkt!F34/4*sh28+Mkt!F34/4*sh28+Mkt!F34/4*sh28)*1 -> 32.015396 | I6: =(Mkt!F34/4*sh28+Mkt!G34/4*sh29+Mkt!G34/4*sh29+Mkt!G34/4*sh29)*1 -> 41.683546 | J6: =(Mkt!D35/4*sh26+Mkt!E35/4*sh27+Mkt!E35/4*sh27+Mkt!E35/4*sh27)*1 -> 25.735944 | K6: =(Mkt!E35/4*sh27+Mkt!F35/4*sh28+Mkt!F35/4*sh28+Mkt!F35/4*sh28)*1 -> 22.290924 | L6: =(Mkt!F35/4*sh28+Mkt!G35/4*sh29+Mkt!G35/4*sh29+Mkt!G35/4*sh29)*1 -> 24.773094 | M6: Σ 會計年度各季：HBM 市場 ÷ 4 × 市占 × 匯率（Mkt）
A7: NAND | C7: =Q!J6 -> 31.783 | D7: =C7*(1+nb_1)*(AVERAGE(Path!J8:M8)/AVERAGE(Path!F8:I8)) -> 67.34694 | E7: =D7*(1+nb_2)*(AVERAGE(Path!N8:Q8)/AVERAGE(Path!J8:M8)) -> 67.558824 | F7: =D7*(1+nb_3)*(AVERAGE(Path!R8:U8)/AVERAGE(Path!N8:Q8)) -> 67.842781 | G7: =C7*(1+nb_1)*(AVERAGE(Path!J9:M9)/AVERAGE(Path!F9:I9)) -> 68.120717 | H7: =G7*(1+nb_2)*(AVERAGE(Path!N9:Q9)/AVERAGE(Path!J9:M9)) -> 40.815646 | I7: =G7*(1+nb_3)*(AVERAGE(Path!R9:U9)/AVERAGE(Path!N9:Q9)) -> 50.094374 | J7: =C7*(1+nb_1)*(AVERAGE(Path!J10:M10)/AVERAGE(Path!F10:I10)) -> 68.120717 | K7: =J7*(1+nb_2)*(AVERAGE(Path!N10:Q10)/AVERAGE(Path!J10:M10)) -> 36.871033 | L7: =J7*(1+nb_3)*(AVERAGE(Path!R10:U10)/AVERAGE(Path!N10:Q10)) -> 36.286558
A8: 其他 | C8: =Q!J7 -> 0.697 | D8: =other_y -> 0.7 | E8: =other_y -> 0.7 | F8: =other_y -> 0.7 | G8: =other_y -> 0.7 | H8: =other_y -> 0.7 | I8: =other_y -> 0.7 | J8: =other_y -> 0.7 | K8: =other_y -> 0.7 | L8: =other_y -> 0.7
A9: HBM ÷ 營收 | C9: =C6/C4 -> 0.072884922 | D9: =D6/D4 -> 0.096113658 | E9: =E6/E4 -> 0.14988762 | F9: =F6/F4 -> 0.1928298 | G9: =G6/G4 -> 0.095276677 | H9: =H6/H4 -> 0.16378611 | I9: =I6/I4 -> 0.16552195 | J9: =J6/J4 -> 0.095276677 | ... L9: =L6/L4 -> 0.15877023
A10: 折舊攤銷 | B10: =SUM(Q!B13:E13) -> 8.352 | C10: =Q!J13 -> 9.503 | D10: =C10+(C21-C10)/da_life -> 13.0758 | E10: =D10+(D21-D10)/da_life -> 21.46064 | F10: =D10+(D21-D10)/da_life -> 21.46064 | G10: =C10+(C21-C10)/da_life -> 13.0758 | H10: =G10+(G21-G10)/da_life -> 21.46064 | I10: =G10+(G21-G10)/da_life -> 21.46064 | J10: =C10+(C21-C10)/da_life -> 13.0758 | K10: =J10+(J21-J10)/da_life -> 21.46064 | L10: =J10+(J21-J10)/da_life -> 21.46064
A11: 成本量指數（÷ 前一年） | D11: =w_c*(1+cb_1)+w_h*D31/C31+w_n*(1+nb_1) -> 1.2456841 | E11: =w_c*(1+cb_2)+w_h*E31/D31+w_n*(1+nb_2) -> 1.2367768 | F11: =w_c*(1+cb_3)+w_h*F31/D31+w_n*(1+nb_3) -> 1.3568879 | G11: =w_c*(1+cb_1)+w_h*G31/C31+w_n*(1+nb_1) -> 1.2456841 | H11: =w_c*(1+cb_2)+w_h*H31/G31+w_n*(1+nb_2) -> 1.228095 | I11: =w_c*(1+cb_3)+w_h*I31/G31+w_n*(1+nb_3) -> 1.3502799 | J11: =w_c*(1+cb_1)+w_h*J31/C31+w_n*(1+nb_1) -> 1.2456841 | K11: =w_c*(1+cb_2)+w_h*K31/J31+w_n*(1+nb_2) -> 1.1640445 | L11: =w_c*(1+cb_3)+w_h*L31/J31+w_n*(1+nb_3) -> 1.2248476
A12: 營業成本 | C12: =Q!J8 -> 25.653532 | D12: =(C12-da_cogs*C10)*D11*(1-costdn_y)+da_cogs*D10 -> 30.940232 | E12: =(D12-da_cogs*D10)*E11*(1-costdn_y)+da_cogs*E10 -> 40.654925 | F12: =(D12-da_cogs*D10)*F11*(1-costdn_y)+da_cogs*F10 -> 42.72742 | G12: =(C12-da_cogs*C10)*G11*(1-costdn_y)+da_cogs*G10 -> 30.940232 | H12: =(G12-da_cogs*G10)*H11*(1-costdn_y)+da_cogs*H10 -> 40.505123 | I12: =(G12-da_cogs*G10)*I11*(1-costdn_y)+da_cogs*I10 -> 42.6134 | J12: =(C12-da_cogs*C10)*J11*(1-costdn_y)+da_cogs*J10 -> 30.940232 | K12: =(J12-da_cogs*J10)*K11*(1-costdn_y)+da_cogs*K10 -> 39.399943 | L12: =(J12-da_cogs*J10)*L11*(1-costdn_y)+da_cogs*L10 -> 40.44909 | M12: 現金成本 × 量 × (1 − 年降)＋折舊
A13: 營業費用 | C13: =Q!J9 -> 8.194468 | D13: =opex_fix_y*(1+opex_g)^1+opex_var*D4 -> 9.7664859 | E13: =opex_fix_y*(1+opex_g)^2+opex_var*E4 -> 11.07273 | F13: =opex_fix_y*(1+opex_g)^3+opex_var*F4 -> 12.238033 | G13: =opex_fix_y*(1+opex_g)^1+opex_var*G4 -> 9.8017697 | H13: =opex_fix_y*(1+opex_g)^2+opex_var*H4 -> 9.5445614 | I13: =opex_fix_y*(1+opex_g)^3+opex_var*I4 -> 11.381839 | J13: =opex_fix_y*(1+opex_g)^1+opex_var*J4 -> 9.8017697 | K13: =opex_fix_y*(1+opex_g)^2+opex_var*K4 -> 9.0214215 | L13: =opex_fix_y*(1+opex_g)^3+opex_var*L4 -> 9.9448415
A14: 記憶體營業利益 | B14: =SUM(Q!B10:E10) -> 9.77 | C14: =Q!J10 -> 99.34 | D14: =D4-D12-D13 -> 227.05901 | E14: =E4-E12-E13 -> 245.62101 | F14: =F4-F12-F13 -> 253.9451 | G14: =G4-G12-G13 -> 229.37598 | H14: =H4-H12-H13 -> 145.42108 | I14: =I4-I12-I13 -> 197.83569 | J14: =J4-J12-J13 -> 229.37598 | K14: =K4-K12-K13 -> 112.1734 | L14: =L4-L12-L13 -> 105.63717
A15: 記憶體營業利益率 | B15: =B14/B4 -> 0.2613837 | C15: =C14/C4 -> 0.74586299 | D15: =D14/D4 -> 0.84797637 | E15: =E14/E4 -> 0.82603704 | F15: =F14/F4 -> 0.82206676 | G15: =G14/G4 -> 0.84916961 | H15: =H14/H4 -> 0.74395309 | I15: =I14/I4 -> 0.78558933 | ... L15: =L14/L4 -> 0.67702636
A16: 非記憶體事業營收 | C16: =nm_rev_0 -> 0 | D16: =nm_rev_1 -> 0 | E16: =nm_rev_2 -> 0 | F16: =nm_rev_3 -> 0 | G16: =nm_rev_1 -> 0 | H16: =nm_rev_2 -> 0 | I16: =nm_rev_3 -> 0 | J16: =nm_rev_1 -> 0 | K16: =nm_rev_2 -> 0 | L16: =nm_rev_3 -> 0
A17: 非記憶體事業營業利益 | C17: =nm_op_0 -> 0 | D17: =nm_op_1 -> 0 | E17: =nm_op_2 -> 0 | F17: =nm_op_3 -> 0 | G17: =nm_op_1 -> 0 | H17: =nm_op_2 -> 0 | I17: =nm_op_3 -> 0 | J17: =nm_op_1 -> 0 | K17: =nm_op_2 -> 0 | L17: =nm_op_3 -> 0
A18: 合併營收 | C18: =C4+C16 -> 133.188 | D18: =D4+D16 -> 267.76573 | E18: =E4+E16 -> 297.34867 | F18: =F4+F16 -> 308.91055 | G18: =G4+G16 -> 270.11798 | H18: =H4+H16 -> 195.47076 | I18: =I4+I16 -> 251.83093 | J18: =J4+J16 -> 270.11798 | ... L18: =L4+L16 -> 156.0311
A19: 合併營業利益 | C19: =C14+C17 -> 99.34 | D19: =D14+D17 -> 227.05901 | E19: =E14+E17 -> 245.62101 | F19: =F14+F17 -> 253.9451 | G19: =G14+G17 -> 229.37598 | H19: =H14+H17 -> 145.42108 | I19: =I14+I17 -> 197.83569 | J19: =J14+J17 -> 229.37598 | ... L19: =L14+L17 -> 105.63717
A20: 淨利（合併） | B20: =SUM(Q!B12:E12) -> 8.539 | C20: =Q!J12 -> 84.969 | D20: =(D19+rf*C26)*(1-tax) -> 194.1734 | E20: =(E19+rf*D26)*(1-tax) -> 210.8875 | F20: =(F19+rf*D26)*(1-tax) -> 217.92135 | G20: =(G19+rf*C26)*(1-tax) -> 196.13124 | H20: =(H19+rf*G26)*(1-tax) -> 126.23179 | I20: =(I19+rf*G26)*(1-tax) -> 170.52214 | J20: =(J19+rf*C26)*(1-tax) -> 196.13124 | K20: =(K19+rf*J26)*(1-tax) -> 98.137506 | L20: =(L19+rf*J26)*(1-tax) -> 92.614385 | M20: （營業利益＋淨現金 × 收益率）× (1 − 稅率)
A21: 資本支出 | C21: =cap_0 -> 27.367 | D21: =cap_1 -> 55 | E21: =cap_2 -> 60 | F21: =cap_3 -> 60 | G21: =cap_1 -> 55 | H21: =cap_2 -> 60 | I21: =cap_3 -> 60 | J21: =cap_1 -> 55 | K21: =cap_2 -> 60 | L21: =cap_3 -> 60
A22: 自由現金流（淨利＋折舊 − 資本支出） | C22: =C20+C10-C21 -> 67.105 | D22: =D20+D10-D21 -> 152.2492 | E22: =E20+E10-E21 -> 172.34814 | F22: =F20+F10-F21 -> 179.38199 | G22: =G20+G10-G21 -> 154.20704 | H22: =H20+H10-H21 -> 87.692429 | I22: =I20+I10-I21 -> 131.98278 | J22: =J20+J10-J21 -> 154.20704 | ... L22: =L20+L10-L21 -> 54.075025
A23: 股利 | C23: =div_0 -> 0 | D23: =dps_1*C27/1000 -> 0.67764 | E23: =dps_2*D27/1000 -> 0.73301392 | F23: =dps_3*D27/1000 -> 0.86536365 | G23: =dps_1*C27/1000 -> 0.67764 | H23: =dps_2*G27/1000 -> 0.73197742 | I23: =dps_3*G27/1000 -> 0.86414 | J23: =dps_1*C27/1000 -> 0.67764 | K23: =dps_2*J27/1000 -> 0.73197742 | L23: =dps_3*J27/1000 -> 0.86414
A24: 買回 | C24: =bb_0 -> 0 | D24: =MAX(0,payout*D22-D23) -> 121.12172 | E24: =MAX(0,payout*E22-E23) -> 137.1455 | F24: =MAX(0,payout*F22-F23) -> 142.64023 | G24: =MAX(0,payout*G22-G23) -> 122.68799 | H24: =MAX(0,payout*H22-H23) -> 69.421966 | I24: =MAX(0,payout*I22-I23) -> 104.72209 | J24: =MAX(0,payout*J22-J23) -> 122.68799 | K24: =MAX(0,payout*K22-K23) -> 46.946539 | L24: =MAX(0,payout*L22-L23) -> 42.39588 | M24: 回饋比例 × FCF − 股利
A25: 期末權益 | C25: =eq_last+(0)+extra_eq-C24-C23 -> 138.378 | D25: =C25+D20-D23-D24 -> 210.75204 | E25: =D25+E20-E23-E24 -> 283.76103 | F25: =D25+F20-F23-F24 -> 285.1678 | G25: =C25+G20-G23-G24 -> 211.14361 | H25: =G25+H20-H23-H24 -> 267.22145 | I25: =G25+I20-I23-I24 -> 276.07952 | J25: =C25+J20-J23-J24 -> 211.14361 | K25: =J25+K20-K23-K24 -> 261.6026 | L25: =J25+L20-L23-L24 -> 260.49797
A26: 期末淨現金 | C26: =nc_last+(0)+(0)-capex_rem+extra_eq-C24-C23 -> 68.3 | D26: =C26+D22-D23-D24 -> 98.749841 | E26: =D26+E22-E23-E24 -> 133.21947 | F26: =D26+F22-F23-F24 -> 134.62624 | G26: =C26+G22-G23-G24 -> 99.141409 | H26: =G26+H22-H23-H24 -> 116.67989 | I26: =G26+I22-I23-I24 -> 125.53796 | J26: =C26+J22-J23-J24 -> 99.141409 | K26: =J26+K22-K23-K24 -> 111.06104 | L26: =J26+L22-L23-L24 -> 109.95641
A27: 期末流通股數 | C27: =sh_last+extra_sh-bb_sh_0 -> 1129.4 | D27: =C27-D24/bb_px*1000 -> 1018.0749 | E27: =D27-E24/bb_px*1000 -> 892.02204 | F27: =D27-F24/bb_px*1000 -> 886.97173 | G27: =C27-G24/bb_px*1000 -> 1016.6353 | H27: =G27-H24/bb_px*1000 -> 952.82835 | I27: =G27-I24/bb_px*1000 -> 920.38338 | J27: =C27-J24/bb_px*1000 -> 1016.6353 | K27: =J27-K24/bb_px*1000 -> 973.48591 | L27: =J27-L24/bb_px*1000 -> 977.6685
A28: 每股淨值 BVPS | C28: =C25/C27*1000 -> 122.52346 | D28: =D25/D27*1000 -> 207.01035 | E28: =E25/E27*1000 -> 318.10989 | F28: =F25/F27*1000 -> 321.5072 | G28: =G25/G27*1000 -> 207.68865 | H28: =H25/H27*1000 -> 280.45078 | I28: =I25/I27*1000 -> 299.96144 | J28: =J25/J27*1000 -> 207.68865 | ... L28: =L25/L27*1000 -> 266.44816
A29: 每股盈餘 EPS（期末股數） | C29: =C20/C27*1000 -> 75.233752 | D29: =D20/D27*1000 -> 190.72605 | E29: =E20/E27*1000 -> 236.41512 | F29: =F20/F27*1000 -> 245.69143 | G29: =G20/G27*1000 -> 192.92193 | H29: =H20/H27*1000 -> 132.48114 | I29: =I20/I27*1000 -> 185.27295 | J29: =J20/J27*1000 -> 192.92193 | ... L29: =L20/L27*1000 -> 94.729845
A30: ROE（期末權益） | C30: =C20/C25 -> 0.61403547 | D30: =D20/D25 -> 0.92133582 | E30: =E20/E25 -> 0.74318697 | F30: =F20/F25 -> 0.76418639 | G30: =G20/G25 -> 0.92889974 | H30: =H20/H25 -> 0.47238643 | I30: =I20/I25 -> 0.61765588 | J30: =J20/J25 -> 0.92889974 | ... L30: =L20/L25 -> 0.35552824
A31: HBM 出貨位元（EB，公司） | C31: =(Mkt!C24/4*sh25+Mkt!D24/4*sh26+Mkt!D24/4*sh26+Mkt!D24/4*sh26) -> 0.65585256 | D31: =(Mkt!D24/4*sh26+Mkt!E24/4*sh27+Mkt!E24/4*sh27+Mkt!E24/4*sh27) -> 1.0591546 | E31: =(Mkt!E24/4*sh27+Mkt!F24/4*sh28+Mkt!F24/4*sh28+Mkt!F24/4*sh28) -> 1.5683999 | F31: =(Mkt!F24/4*sh28+Mkt!G24/4*sh29+Mkt!G24/4*sh29+Mkt!G24/4*sh29) -> 2.1466558 | G31: =(Mkt!D25/4*sh26+Mkt!E25/4*sh27+Mkt!E25/4*sh27+Mkt!E25/4*sh27) -> 1.0591546 | H31: =(Mkt!E25/4*sh27+Mkt!F25/4*sh28+Mkt!F25/4*sh28+Mkt!F25/4*sh28) -> 1.5266029 | I31: =(Mkt!F25/4*sh28+Mkt!G25/4*sh29+Mkt!G25/4*sh29+Mkt!G25/4*sh29) -> 2.1148425 | J31: =(Mkt!D26/4*sh26+Mkt!E26/4*sh27+Mkt!E26/4*sh27+Mkt!E26/4*sh27) -> 1.0591546 | K31: =(Mkt!E26/4*sh27+Mkt!F26/4*sh28+Mkt!F26/4*sh28+Mkt!F26/4*sh28) -> 1.2182419 | L31: =(Mkt!F26/4*sh28+Mkt!G26/4*sh29+Mkt!G26/4*sh29+Mkt!G26/4*sh29) -> 1.5109689

Sheet Val
A1: Val — 估值（P/B 主、P/E 對照）。隱含股價 ÷ 目前股價 − 1
A3: 方法 | B3: 倍數 | C3: 基準 | D3: 情境 | E3: 每股基準 | F3: 隱含股價 | G3: 相對目前
A4: P/B 1.0x（谷底） | B4: =pb_1 -> 1 | C4: FY2026 期末 BVPS | D4: 共用 | E4: =Y!C28 -> 122.52346 | F4: =B4*E4 -> 122.52346 | G4: =F4/px-1 -> -0.88738652
A5: P/B 歷史中位 1.4x | B5: =pb_2 -> 1.4 | C5: FY2026 期末 BVPS | D5: 共用 | E5: =Y!C28 -> 122.52346 | F5: =B5*E5 -> 171.53285 | G5: =F5/px-1 -> -0.84234113
A6: P/B 前高 3.0x | B6: =pb_3 -> 3 | C6: FY2026 期末 BVPS | D6: 共用 | E6: =Y!C28 -> 122.52346 | F6: =B6*E6 -> 367.57039 | G6: =F6/px-1 -> -0.66215957
A7: P/B 1.0x（谷底） | B7: =pb_1 -> 1 | C7: FY2027 期末 BVPS | D7: A | E7: =Y!D28 -> 207.01035 | F7: =B7*E7 -> 207.01035 | G7: =F7/px-1 -> -0.80973313
A8: P/B 歷史中位 1.4x | B8: =pb_2 -> 1.4 | C8: FY2027 期末 BVPS | D8: A | E8: =Y!D28 -> 207.01035 | F8: =B8*E8 -> 289.81449 | G8: =F8/px-1 -> -0.73362638
A9: P/B 前高 3.0x | B9: =pb_3 -> 3 | C9: FY2027 期末 BVPS | D9: A | E9: =Y!D28 -> 207.01035 | F9: =B9*E9 -> 621.03106 | G9: =F9/px-1 -> -0.4291994
A10: P/B 1.0x（谷底） | B10: =pb_1 -> 1 | C10: FY2027 期末 BVPS | D10: B | E10: =Y!G28 -> 207.68865 | F10: =B10*E10 -> 207.68865 | G10: =F10/px-1 -> -0.8091097
A11: P/B 歷史中位 1.4x | B11: =pb_2 -> 1.4 | C11: FY2027 期末 BVPS | D11: B | E11: =Y!G28 -> 207.68865 | F11: =B11*E11 -> 290.7641 | G11: =F11/px-1 -> -0.73275358
A12: P/B 前高 3.0x | B12: =pb_3 -> 3 | C12: FY2027 期末 BVPS | D12: B | E12: =Y!G28 -> 207.68865 | F12: =B12*E12 -> 623.06594 | G12: =F12/px-1 -> -0.4273291
A13: P/B 1.0x（谷底） | B13: =pb_1 -> 1 | C13: FY2027 期末 BVPS | D13: C | E13: =Y!J28 -> 207.68865 | F13: =B13*E13 -> 207.68865 | G13: =F13/px-1 -> -0.8091097
A14: P/B 歷史中位 1.4x | B14: =pb_2 -> 1.4 | C14: FY2027 期末 BVPS | D14: C | E14: =Y!J28 -> 207.68865 | F14: =B14*E14 -> 290.7641 | G14: =F14/px-1 -> -0.73275358
A15: P/B 前高 3.0x | B15: =pb_3 -> 3 | C15: FY2027 期末 BVPS | D15: C | E15: =Y!J28 -> 207.68865 | F15: =B15*E15 -> 623.06594 | G15: =F15/px-1 -> -0.4273291
A16: P/B 1.0x（谷底） | B16: =pb_1 -> 1 | C16: FY2028 期末 BVPS | D16: A | E16: =Y!E28 -> 318.10989 | F16: =B16*E16 -> 318.10989 | G16: =F16/px-1 -> -0.70761959
A17: P/B 歷史中位 1.4x | B17: =pb_2 -> 1.4 | C17: FY2028 期末 BVPS | D17: A | E17: =Y!E28 -> 318.10989 | F17: =B17*E17 -> 445.35384 | G17: =F17/px-1 -> -0.59066743
A18: P/B 前高 3.0x | B18: =pb_3 -> 3 | C18: FY2028 期末 BVPS | D18: A | E18: =Y!E28 -> 318.10989 | F18: =B18*E18 -> 954.32966 | G18: =F18/px-1 -> -0.12285877
A19: P/B 1.0x（谷底） | B19: =pb_1 -> 1 | C19: FY2028 期末 BVPS | D19: B | E19: =Y!H28 -> 280.45078 | F19: =B19*E19 -> 280.45078 | G19: =F19/px-1 -> -0.74223274
A20: P/B 歷史中位 1.4x | B20: =pb_2 -> 1.4 | C20: FY2028 期末 BVPS | D20: B | E20: =Y!H28 -> 280.45078 | F20: =B20*E20 -> 392.63109 | G20: =F20/px-1 -> -0.63912583
A21: P/B 前高 3.0x | B21: =pb_3 -> 3 | C21: FY2028 期末 BVPS | D21: B | E21: =Y!H28 -> 280.45078 | F21: =B21*E21 -> 841.35235 | G21: =F21/px-1 -> -0.22669821
A22: P/B 1.0x（谷底） | B22: =pb_1 -> 1 | C22: FY2028 期末 BVPS | D22: C | E22: =Y!K28 -> 268.72767 | F22: =B22*E22 -> 268.72767 | G22: =F22/px-1 -> -0.75300766
A23: P/B 歷史中位 1.4x | B23: =pb_2 -> 1.4 | C23: FY2028 期末 BVPS | D23: C | E23: =Y!K28 -> 268.72767 | F23: =B23*E23 -> 376.21874 | G23: =F23/px-1 -> -0.65421072
A24: P/B 前高 3.0x | B24: =pb_3 -> 3 | C24: FY2028 期末 BVPS | D24: C | E24: =Y!K28 -> 268.72767 | F24: =B24*E24 -> 806.183 | G24: =F24/px-1 -> -0.25902297
A25: P/B 1.0x（谷底） | B25: =pb_1 -> 1 | C25: FY2029 期末 BVPS | D25: A | E25: =Y!F28 -> 321.5072 | F25: =B25*E25 -> 321.5072 | G25: =F25/px-1 -> -0.70449706
A26: P/B 歷史中位 1.4x | B26: =pb_2 -> 1.4 | C26: FY2029 期末 BVPS | D26: A | E26: =Y!F28 -> 321.5072 | F26: =B26*E26 -> 450.11008 | G26: =F26/px-1 -> -0.58629588
A27: P/B 前高 3.0x | B27: =pb_3 -> 3 | C27: FY2029 期末 BVPS | D27: A | E27: =Y!F28 -> 321.5072 | F27: =B27*E27 -> 964.5216 | G27: =F27/px-1 -> -0.11349117
A28: P/B 1.0x（谷底） | B28: =pb_1 -> 1 | C28: FY2029 期末 BVPS | D28: B | E28: =Y!I28 -> 299.96144 | F28: =B28*E28 -> 299.96144 | G28: =F28/px-1 -> -0.72430015
A29: P/B 歷史中位 1.4x | B29: =pb_2 -> 1.4 | C29: FY2029 期末 BVPS | D29: B | E29: =Y!I28 -> 299.96144 | F29: =B29*E29 -> 419.94602 | G29: =F29/px-1 -> -0.61402021
A30: P/B 前高 3.0x | B30: =pb_3 -> 3 | C30: FY2029 期末 BVPS | D30: B | E30: =Y!I28 -> 299.96144 | F30: =B30*E30 -> 899.88432 | G30: =F30/px-1 -> -0.17290044
A31: P/B 1.0x（谷底） | B31: =pb_1 -> 1 | C31: FY2029 期末 BVPS | D31: C | E31: =Y!L28 -> 266.44816 | F31: =B31*E31 -> 266.44816 | G31: =F31/px-1 -> -0.75510279
A32: P/B 歷史中位 1.4x | B32: =pb_2 -> 1.4 | C32: FY2029 期末 BVPS | D32: C | E32: =Y!L28 -> 266.44816 | F32: =B32*E32 -> 373.02743 | G32: =F32/px-1 -> -0.65714391
A33: P/B 前高 3.0x | B33: =pb_3 -> 3 | C33: FY2029 期末 BVPS | D33: C | E33: =Y!L28 -> 266.44816 | F33: =B33*E33 -> 799.34448 | G33: =F33/px-1 -> -0.26530838
A34: P/E 4x | B34: =pe_1 -> 4 | C34: FY2027 EPS | D34: A | E34: =Y!D29 -> 190.72605 | F34: =B34*E34 -> 762.90421 | G34: =F34/px-1 -> -0.29880127
A35: P/E 8x | B35: =pe_2 -> 8 | C35: FY2027 EPS | D35: A | E35: =Y!D29 -> 190.72605 | F35: =B35*E35 -> 1525.8084 | G35: =F35/px-1 -> 0.40239745
A36: P/E 12x | B36: =pe_3 -> 12 | C36: FY2027 EPS | D36: A | E36: =Y!D29 -> 190.72605 | F36: =B36*E36 -> 2288.7126 | G36: =F36/px-1 -> 1.1035962
A37: P/E 4x | B37: =pe_1 -> 4 | C37: FY2027 EPS | D37: B | E37: =Y!G29 -> 192.92193 | F37: =B37*E37 -> 771.68772 | G37: =F37/px-1 -> -0.2907282
A38: P/E 8x | B38: =pe_2 -> 8 | C38: FY2027 EPS | D38: B | E38: =Y!G29 -> 192.92193 | F38: =B38*E38 -> 1543.3754 | G38: =F38/px-1 -> 0.4185436
A39: P/E 12x | B39: =pe_3 -> 12 | C39: FY2027 EPS | D39: B | E39: =Y!G29 -> 192.92193 | F39: =B39*E39 -> 2315.0631 | G39: =F39/px-1 -> 1.1278154
A40: P/E 4x | B40: =pe_1 -> 4 | C40: FY2027 EPS | D40: C | E40: =Y!J29 -> 192.92193 | F40: =B40*E40 -> 771.68772 | G40: =F40/px-1 -> -0.2907282
A41: P/E 8x | B41: =pe_2 -> 8 | C41: FY2027 EPS | D41: C | E41: =Y!J29 -> 192.92193 | F41: =B41*E41 -> 1543.3754 | G41: =F41/px-1 -> 0.4185436
...

Sheet Sens
A1: Sens — 一次只動一個價格或份額輸入；Δ營業利益＝Δ營收 × (1 − 營業費用變動率)（成本只隨量變動，所以這是精確值，不是近似）
A3: 欄 | B3: 輸入變動 | C3: Δ營收 | D3: 營業利益 | E3: 相對基準
A4: FY2027 A | B4: 基準 | D4: =Y!D14 -> 227.05901
A5: FY2027 A | B5: 一般 DRAM 收入 −20% | C5: =-0.2*Y!D5 -> -34.796569 | D5: =D4+C5*(1-opex_var) -> 192.78439 | E5: =D5/D4-1 -> -0.15095028
A6: FY2027 A | B6: 一般 DRAM 收入 +20% | C6: =0.2*Y!D5 -> 34.796569 | D6: =D4+C6*(1-opex_var) -> 261.33363 | E6: =D6/D4-1 -> 0.15095028
A7: FY2027 A | B7: HBM 收入 −30%（價格或份額） | C7: =-0.3*Y!D6 -> -7.7207831 | D7: =D4+C7*(1-opex_var) -> 219.45404 | E7: =D7/D4-1 -> -0.033493369
A8: FY2027 A | B8: HBM 收入 +30% | C8: =0.3*Y!D6 -> 7.7207831 | D8: =D4+C8*(1-opex_var) -> 234.66398 | E8: =D8/D4-1 -> 0.033493369
A9: FY2027 A | B9: NAND 收入 −30% | C9: =-0.3*Y!D7 -> -20.204082 | D9: =D4+C9*(1-opex_var) -> 207.15799 | E9: =D9/D4-1 -> -0.08764691
A10: FY2027 A | B10: NAND 收入 +30% | C10: =0.3*Y!D7 -> 20.204082 | D10: =D4+C10*(1-opex_var) -> 246.96003 | E10: =D10/D4-1 -> 0.08764691
A12: FY2028 B | B12: 基準 | D12: =Y!H14 -> 145.42108
A13: FY2028 B | B13: 一般 DRAM 收入 −20% | C13: =-0.2*Y!H5 -> -24.387944 | D13: =D12+C13*(1-opex_var) -> 121.39895 | E13: =D13/D12-1 -> -0.16519012
A14: FY2028 B | B14: 一般 DRAM 收入 +20% | C14: =0.2*Y!H5 -> 24.387944 | D14: =D12+C14*(1-opex_var) -> 169.4432 | E14: =D14/D12-1 -> 0.16519012
A15: FY2028 B | B15: HBM 收入 −30%（價格或份額） | C15: =-0.3*Y!H6 -> -9.6046188 | D15: =D12+C15*(1-opex_var) -> 135.96053 | E15: =D15/D12-1 -> -0.065056248
A16: FY2028 B | B16: HBM 收入 +30% | C16: =0.3*Y!H6 -> 9.6046188 | D16: =D12+C16*(1-opex_var) -> 154.88163 | E16: =D16/D12-1 -> 0.065056248
A17: FY2028 B | B17: NAND 收入 −30% | C17: =-0.3*Y!H7 -> -12.244694 | D17: =D12+C17*(1-opex_var) -> 133.36005 | E17: =D17/D12-1 -> -0.082938619
A18: FY2028 B | B18: NAND 收入 +30% | C18: =0.3*Y!H7 -> 12.244694 | D18: =D12+C18*(1-opex_var) -> 157.4821 | E18: =D18/D12-1 -> 0.082938619
A20: FY2028 C | B20: 基準 | D20: =Y!K14 -> 112.1734
A21: FY2028 C | B21: 一般 DRAM 收入 −20% | C21: =-0.2*Y!K5 -> -20.146562 | D21: =D20+C21*(1-opex_var) -> 92.32904 | E21: =D21/D20-1 -> -0.17690792
A22: FY2028 C | B22: 一般 DRAM 收入 +20% | C22: =0.2*Y!K5 -> 20.146562 | D22: =D20+C22*(1-opex_var) -> 132.01777 | E22: =D22/D20-1 -> 0.17690792
A23: FY2028 C | B23: HBM 收入 −30%（價格或份額） | C23: =-0.3*Y!K6 -> -6.6872771 | D23: =D20+C23*(1-opex_var) -> 105.58644 | E23: =D23/D20-1 -> -0.058721299
A24: FY2028 C | B24: HBM 收入 +30% | C24: =0.3*Y!K6 -> 6.6872771 | D24: =D20+C24*(1-opex_var) -> 118.76037 | E24: =D24/D20-1 -> 0.058721299
A25: FY2028 C | B25: NAND 收入 −30% | C25: =-0.3*Y!K7 -> -11.06131 | D25: =D20+C25*(1-opex_var) -> 101.27801 | E25: =D25/D20-1 -> -0.09712989
A26: FY2028 C | B26: NAND 收入 +30% | C26: =0.3*Y!K7 -> 11.06131 | D26: =D20+C26*(1-opex_var) -> 123.06879 | E26: =D26/D20-1 -> 0.09712989
A28: FY2029 C | B28: 基準 | D28: =Y!L14 -> 105.63717
A29: FY2029 C | B29: 一般 DRAM 收入 −20% | C29: =-0.2*Y!L5 -> -18.854289 | D29: =D28+C29*(1-opex_var) -> 87.065691 | E29: =D29/D28-1 -> -0.17580436
A30: FY2029 C | B30: 一般 DRAM 收入 +20% | C30: =0.2*Y!L5 -> 18.854289 | D30: =D28+C30*(1-opex_var) -> 124.20864 | E30: =D30/D28-1 -> 0.17580436
A31: FY2029 C | B31: HBM 收入 −30%（價格或份額） | C31: =-0.3*Y!L6 -> -7.4319281 | D31: =D28+C31*(1-opex_var) -> 98.316717 | E31: =D31/D28-1 -> -0.069298046
A32: FY2029 C | B32: HBM 收入 +30% | C32: =0.3*Y!L6 -> 7.4319281 | D32: =D28+C32*(1-opex_var) -> 112.95762 | E32: =D32/D28-1 -> 0.069298046
A33: FY2029 C | B33: NAND 收入 −30% | C33: =-0.3*Y!L7 -> -10.885968 | D33: =D28+C33*(1-opex_var) -> 94.914488 | E33: =D33/D28-1 -> -0.10150479
A34: FY2029 C | B34: NAND 收入 +30% | C34: =0.3*Y!L7 -> 10.885968 | D34: =D28+C34*(1-opex_var) -> 116.35984 | E34: =D34/D28-1 -> 0.10150479
A36: 讀法：哪一條收入線的同幅變動對營業利益影響最大，就是該年度的主要驅動。價格路徑本身的情境差異見 Y 頁 A／B／C 欄。

Sheet Recon
A1: Recon — 本模型（正向推導）vs 共識或公司指引（只作事後對照，不用來回推參數）；十億美元
A3: 項目 | B3: 本模型 | C3: 對照值 | D3: 差距 | E3: 對照來源
A4: FY26 營收（實績核對） | B4: =Y!C4 -> 133.188 | C4: 133.188 | D4: =B4/C4-1 -> 0 | E4: FQ4-26 8-K
A5: FY27 營收（A）vs 共識 | B5: =Y!D4 -> 267.76573 | C5: 275 | D5: =B5/C5-1 -> -0.026306439 | E5: Yahoo／LSEG（39 位分析師）2026-10-07
A6: FY27 淨利（A）vs 共識（EPS 176.15 × 約 1.15B 股） | B6: =Y!D20 -> 194.1734 | C6: 202.6 | D6: =B6/C6-1 -> -0.041592276 | E6: Yahoo／LSEG [Derived]
A7: FY28 營收（A）vs 共識 | B7: =Y!E4 -> 297.34867 | C7: 319.1 | D7: =B7/C7-1 -> -0.068164629 | E7: Yahoo／LSEG
A8: FY28 淨利（A）vs 共識（EPS 206.33 × 1.15B） | B8: =Y!E20 -> 210.8875 | C8: 237.3 | D8: =B8/C8-1 -> -0.11130426 | E8: Yahoo／LSEG [Derived]
A9: FY27 平均每季營收（A）vs FQ1-27 指引 | B9: =Y!D4/4 -> 66.941432 | C9: 61.5 | D9: =B9/C9-1 -> 0.088478575 | E9: 公司指引 ±1.5；管理層：FQ1 毛利率為 FY27 低點

Sheet Feedback
A1: Feedback — 回饋算力收支
A3: 每顆加速器 HBM 金額（GB300，2026 價） | B3: =nv_hbm -> 4.46 | C3: $K
A4: 全市場每顆加速器平均 HBM 2026／2027 | B4: =TEXT(Mkt!D16,"0")&" ／ "&TEXT(Mkt!E16,"0") -> 216 ／ 260 | C4: GB
A5: HBM 市場 2026／2027（A） | B5: =TEXT(Mkt!D33,"0")&" ／ "&TEXT(Mkt!E33,"0") -> 55 ／ 154 | C5: $B
A6: 2027 HBM 需求缺口（三情境相同） | B6: =Mkt!E27 -> 1.2325527 | C6: EB
A7: 美光 HBM 毛利率 | B7: 無法由公開資料分離 | C7: —

Sheet Sources
A1: 來源
A2: FQ4 FY26 財報新聞稿（2026-09-30） | B2: https://www.sec.gov/Archives/edgar/data/723125/000072312526000018/a2026q4ex991-pressrelease.htm
A3: FQ4 FY26 書面說明 | B3: https://s25.q4cdn.com/621799436/files/doc_financials/2026/q4/Q4-FY26-Prepared-Remarks.pdf
A4: FQ4 FY26 法說逐字稿 | B4: https://www.investing.com/news/transcripts/earnings-call-transcript-micron-tops-q4-2026-estimates-as-demand-stays-hot-93CH-4925992
A5: FQ3 FY26 新聞稿 | B5: https://www.sec.gov/Archives/edgar/data/723125/000072312526000013/a2026q3ex991-pressrelease.htm
A6: FQ2 FY26 新聞稿 | B6: https://www.sec.gov/Archives/edgar/data/723125/000072312526000004/a2026q2ex991-pressrelease.htm
A7: FQ1 FY26 新聞稿 | B7: https://www.sec.gov/Archives/edgar/data/723125/000072312525000044/a2026q1ex991-pressrelease.htm
A8: 10-Q FQ3 FY26 | B8: https://www.sec.gov/Archives/edgar/data/723125/000072312526000015/mu-20260528.htm
A9: 10-K FY25 | B9: https://www.sec.gov/Archives/edgar/data/723125/000072312525000028/mu-20250828.htm
A10: Yahoo Finance 共識 | B10: https://finance.yahoo.com/quote/MU/analysis/
A11: Macrotrends P/B | B11: https://www.macrotrends.net/stocks/charts/MU/micron-technology/price-book
A12: markets/memory/market.py（共用市場層） | B12: 本 repo
A13: markets/chip_bridge v0.2 | B13: 本 repo
