Workbook

Sheet README
A1: TOWA（6315.T）收支與估值模型 v0.1.1（AI 半導體 Project 步驟 5：設備與材料） 2026-10-25
A2: 模型命題：TOWA 握有封膠設備約 2/3 市占，但營收只有約兩成來自 AI（HBM 與 CoWoS 封膠），FY2025 營益率僅 12.7%；問題是 HBM 堆疊與 2.5D 封裝的封膠增量，能否在 FY2027 以後延續並把營益率拉回 16% 以上，撐住約 21 倍的指引本益比？
A3: 註：21 倍＝現價 ¥1,968（2026-10-23）÷ 公司 FY2026 指引 EPS ¥93.30；÷ FY2025 EPS ¥61.22 為 32.1 倍（Val 第 5 節）。
A5: 驅動因子 → 推導量（因果方向：左邊決定右邊）
A6: PL 區塊｜HBM 出貨位元（skhynix 成品，同字母情境）÷（晶粒容量 × 層數）→ HBM 堆疊數 → 下一年增量＋汰換 → 新機需求 × kH（以 FY2025 AI 錨點校準）→ HBM 封膠營收
A7: PL 區塊｜CoWoS 片數（台積電成品；B、C × 同字母顆數係數）→ 下一年增量＋汰換 → 新機需求 × kL → 2.5D 封膠營收
A8: PL 區塊｜SEMI 組裝與封裝設備 ×（情境 s 非 AI 設備 ÷ 情境 A 非 AI 設備）（markets/equipment）→ 非 AI 封膠設備與模具；設備總額 → 切割與雷射；新事業、醫療以自身歷史年增
A9: PL（D 節）｜FY2026 錨點＝公司全年指引（營收 640、營業利益 102.4、淨利 70.0 億）×（1＋g_anc）；各組成同比例縮放，FY2027 起 AI 兩項回到驅動推導、非 AI 以錨定水準（情境 A 的 sc）為基期
A10: PL（E 節）｜營業利益＝FY2026 錨點＋（Hist 迴歸增量營益率＋情境調整）×（營收 − FY2026 營收）；淨利＝營業利益 × 0.684（公司指引比例）
A11: Val｜第 0 節目標價（DCF 與 Comparable 各半）；第 1–6 節十年 P/E、循環位置（設備股共用規則：見頂年度 A 2029、B 2028、C 2027 → FY2027：A 中段、B 中段、C 見頂）、規則值與目前倍數
A13: 會計年度：4 月到隔年 3 月（FY2025＝2025-04～2026-03，公司「2026年3月期」）。日曆年轉會計年度：FY(t)＝3/4 × CY(t)＋1/4 × CY(t+1)。金額為日圓，未建匯率。
A14: 情境：A＝順利、B＝平平、C＝不如預期，各讀同字母的上游情境（HBM 位元、顆數係數、設備市場）；公司特有變數（AI 封膠市占流失、增量營益率調整）A 最有利、C 最不利。FY2030 起為收斂法，非驅動因子推導。
... A18: v0.1.1（2026-10-25）：補上檔空間級距、投資建議、重點觀察（數值不變）。Val 頁最後新增「上檔空間級距」「投資建議」兩列（依「上檔空間：加權目標價」固定規則）；README 頁最後新增投資建議與重點觀察三點。
A19: ="投資建議："&Val!B125&"（依上檔空間固定規則）" -> 投資建議：放空（依上檔空間固定規則）
A20: ="重點觀察 1：目標價 ¥"&TEXT(Val!$B$39,"#,##0")&"（DCF "&TEXT(Val!$B$24,"#,##0")&"、Comparable（相對倍數調整後）"&TEXT(tp_comp_adj,"#,##0")&"；DCF 權重 "&TEXT(tp_w_dcf,"0%")&"），比現價 "&TEXT(px,"#,##0")&"（2026-10-23）"&IF(Val!$B$42>=0,"高 "&TEXT(Val!$B$42,"0.0%"),"低 "&TEXT(-Val!$B$42,"0.0%"))&"，級距 "&Val!$B$124&"、投資建議 "&Val!$B$125&"。相對倍數調整係數 "&TEXT(rm_factor,"0.00")&"（本公司 10 年前瞻倍數中位數 ÷ 同業的中位數，夾在 0.5–2.0；Val 第 0.5 節），調整前加權上檔空間 "&TEXT((tp_w_dcf*Val!$B$24+(1-tp_w_dcf)*Val!$B$35)/px-1,"+0.0%;−0.0%")&"；Comparable 單獨（市場主流同業法、未調整）為 "&TEXT(Val!$B$43,"+0.0%;−0.0%")&"。"&"以下為 2026-10-29 相對倍數調整前撰寫的說明，其中數字為調整前：DCF 只有現價的 0.52 倍：ROE 近三年平均 10.9% 只略高於折現率 10%，再投資率 36.7%，股東現金流只有 EPS 的六成多。" -> 重點觀察 1：目標價 ¥1,382（DCF 1,015、Comparable（相對倍數調整後）1,748；DCF 權重 50%），比現價 1,968（2026-10-23）低 29.8%，級距 −25%～−50%、投資建議 放空。相對倍數調整係數 0.72（本公司 10 年前瞻倍數中位數 ÷ 同業的中位數，夾在 0.5–2.0；Val 第 0.5 節），調整前加權上檔空間 −12.3%；Comparable 單獨（市場主流同業法、未調整）為 +23.8%。以下為 2026-10-29 相對倍數調整前撰寫的說明，其中數字為調整前：DCF 只有現價的 0.52 倍：ROE 近三年平均 10.9% 只略高於折現率 10%，再投資率 36.7%，股東現金流只有 EPS 的六成多。
A21: 重點觀察 2：本模型 12 個月後前瞻 EPS 94.4 比共識前瞻 EPS 116.0 低 18.6%；共識目標價 3,300 隱含 28.5 倍，同業中位數 25.8 倍（倍數因素 +10.2%）。情境 B、C 的 FY2027 EPS 比 A 低 12.5%、22.6%（AI 封膠市占流失 3pt／8pt 與上游下修）。
A22: 重點觀察 3：FY2027 EPS 對堆疊層數（低值 → +8.9%）、淨利 ÷ 營業利益（0.65／0.72 → −4.9%／+5.3%）與 FY2026 錨點（−5%／+8% → −3.5%／+5.7%）最敏感。下一個檢驗事件是第二季財報（預計 2026-11 上旬，日期未確認），FY2026 錨點將改為上半年實績加下半年指引。
A24: 2026-10-29：加權目標價中的 Comparable 改用相對倍數調整後的值（Val 第 0.5 節：同業前瞻倍數中位數 × 本公司 10 年相對同業的倍數比，Bloomberg 前瞻倍數；Andy 2026-10-27「照建議做」、10-29 資料取回）。「Comparable 目標價（市場主流同業法）」維持不調整。重點觀察 1 的第一句已改為公式；重點觀察 2、3 與其他說明中的目標價與上檔空間數字為調整前撰寫，以 Val 頁為準。
A26: v0.2.1（2026-10-30）：依個股模型原則第 8 節調整 In 頁呈現（數值不變）。In 頁 D／F 欄名改「敏感度低」「敏感度高」（只用於 Sens 頁、不進目標價）；In 頁最後新增「情境驅動對照」一節，把上方各情境專屬輸入三情境並排（只引用上方各列，純展示）；HTML 驅動因子一節分「情境驅動」與「單一參數」兩張表。

Sheet In
A1: In — 輸入（藍字；基準欄 E，低 D、高 F）。金額：十億日圓（¥B）；HBM 位元：EB；CoWoS：千片；設備市場：十億美元。每個輸入附標記與來源；找不到者寫「未找到」，公司未揭露者寫「公司不揭露」。【v0.2.1】基準欄 E 進主模型；D／F＝敏感度低／高，只用於 Sens 頁（一次動一個參數）、不進目標價；情境 A／B／C 的驅動見本頁最後一節「情境驅動對照」。
A2: 標記：Verified（公司文件、交易所資料）／Interested-party（寫明是誰、立場）／Analogy（寫明對照與差異）／Assumed（一律給低／高區間）／Derived（寫明換算）。SemiAnalysis 未使用。公司原文（JPX 決算短信 iXBRL、towajapan.co.jp 說明資料 PDF）以網頁擷取工具讀取；圖表數字擷取錯位處未採用，待人工複核
A3: 鍵 | B3: 項目 | C3: 單位 | D3: 敏感度低 | E3: 基準 | F3: 敏感度高 | G3: 標記 | H3: 來源1 | I3: 來源2／說明
A4: A. FY2025 實績（2025-04～2026-03）與事業別營收（校準錨）
A5: a25_rev | B5: 營收 FY2025 | C5: ¥B | E5: 54.365 | G5: Verified | H5: 公司 2026年3月期 決算短信（2026-04-22 登錄，JPX iXBRL 081220260422508001）：54,365 百萬日圓（+1.7%） | I5: 松井證券 決算情報（finance.matsui.co.jp/stock/6315/settlement）：54,365
A6: a25_gp | B6: 毛利 FY2025 | C6: ¥B | E6: 18.372 | G6: Verified | H6: kabutore 財務分析（轉載公司損益表）：売上総利益 18,371,561 千日圓（毛利率 33.8%） | I6: edinetdb（2026-10-24 讀取）：毛利率 33.8%。決算短信摘要頁未列毛利
A7: a25_oi | B7: 營業利益 FY2025 | C7: ¥B | E7: 6.917 | G7: Verified | H7: 公司 2026年3月期 決算短信（2026-04-22 登錄，JPX iXBRL 081220260422508001）：6,917（−22.1%；營益率 12.7%） | I7: 松井證券 決算情報（finance.matsui.co.jp/stock/6315/settlement）：6,917
A8: a25_ni | B8: 淨利（歸屬母公司）FY2025 | C8: ¥B | E8: 4.593 | G8: Verified | H8: 公司 2026年3月期 決算短信（2026-04-22 登錄，JPX iXBRL 081220260422508001）：4,593（−43.4%） | I8: 松井證券 決算情報（finance.matsui.co.jp/stock/6315/settlement）：4,593
A9: a25_eps | B9: 基本 EPS FY2025 | C9: ¥ | E9: 61.22 | G9: Verified | H9: 公司 2026年3月期 決算短信（2026-04-22 登錄，JPX iXBRL 081220260422508001）：61.22 | I9: 松井證券 決算情報（finance.matsui.co.jp/stock/6315/settlement）：61.22
A10: seg_semi | B10: 半導體事業營收 FY2025 | C10: ¥B | E10: 40.39 | G10: Verified | H10: 公司 2026年3月期 決算說明資料（2026-05，2025FY_end_presentation.pdf）：403.9 億日圓（+2.2%） | I10: tousaiblog（2026-05-12）：403.9
A11: seg_mold | B11: 其中：封膠設備與模具（モールディング装置・金型） | C11: ¥B | E11: 36.46 | G11: Verified | H11: 公司 2026年3月期 決算說明資料（2026-05，2025FY_end_presentation.pdf）：364.6 億日圓（擷取文字；版面待複核） | I11: 第二來源：未找到。設備與模具未分開揭露（公司不揭露）
A12: seg_osemi | B12: 其中：其他半導體（切割 singulation 等） | C12: ¥B | E12: =seg_semi-seg_mold -> 3.93 | G12: Derived | H12: 403.9 − 364.6 ＝ 39.3 | I12: 公司：記憶體投資使切割設備大增（tousaiblog 摘要，無金額）
A13: seg_new | B13: 新事業營收 FY2025（含 TSS：售後、翻新、二手機、零件） | C13: ¥B | E13: 9.47 | G13: Verified | H13: 公司 2026年3月期 決算說明資料（2026-05，2025FY_end_presentation.pdf）：94.7 億日圓（+0.6%） | I13: tousaiblog：94.7
A14: seg_med | B14: 醫療器材事業營收 FY2025（BANDIC，精密塑膠成形品） | C14: ¥B | E14: 2.48 | G14: Verified | H14: 公司 2026年3月期 決算說明資料（2026-05，2025FY_end_presentation.pdf）：24.8 億日圓（+9.9%） | I14: tousaiblog：24.8
A15: seg_las | B15: 雷射事業營收 FY2025 | C15: ¥B | E15: 2 | G15: Verified | H15: 公司 2026年3月期 決算說明資料（2026-05，2025FY_end_presentation.pdf）：20.0 億日圓（−11.0%） | I15: tousaiblog：20.0
A16: seg_adj | B16: 事業合計與營收的差額（取整與調整） | C16: ¥B | E16: =a25_rev-seg_semi-seg_new-seg_med-seg_las -> 0.025 | G16: Derived | H16: 營收 − 四事業合計 | I16: FY2025 以後設為 0
A17: ord_25 | B17: 受注高 FY2025 | C17: ¥B | E17: 59.56 | G17: Verified | H17: 公司 2026年3月期 決算說明資料（2026-05，2025FY_end_presentation.pdf）：595.6 億日圓（+25.6%，史上第二高） | I17: tousaiblog：595.6
A18: bl_25 | B18: 受注殘高 2026-03 末 | C18: ¥B | E18: 30.14 | G18: Verified | H18: 公司 2026年3月期 決算說明資料（2026-05，2025FY_end_presentation.pdf）：301.4 億日圓 | I18: 2025-09 末 267.4（公司 2026年3月期 第2四半期 決算說明會資料（2025-11-07））
A19: sh | B19: TOWA 封膠設備全球市占（2024 年，TechInsights） | C19: % | D19: 0.6 | E19: 0.648 | F19: 0.7 | G19: Interested-party | H19: 公司 2026年3月期 第2四半期 決算說明會資料（2025-11-07） 第 14 頁、公司 2026年3月期 決算說明資料（2026-05，2025FY_end_presentation.pdf）：TechInsights 數據，世界市占 No.1；圓餅最大塊 64.8%（標籤 A–D 未明示哪塊是公司） | I19: 本專案候選表：市占約 2/3（markets/invest_map universe，非獨立來源）。只透過「市占流失」進入模型；FY2025 水準已含在校準中
A20: B. AI 錨點（校準用；公司不揭露 AI 或 HBM 金額）
A21: ai_25 | B21: FY2025 AI 相關封膠設備與模具營收（HBM＋CoWoS 等 2.5D／晶圓級） | C21: ¥B | D21: 7 | E21: 10 | F21: 13 | G21: Assumed | H21: 公司不揭露。推估：說明資料圓餅「移轉成形 59%／壓縮成形 41%」（標籤對應未確認）× 封膠 36.5 ≈ 壓縮成形 15.0；AI（HBM、AI 加速器、先進封裝）約占壓縮成形三分之二 → 約 10.0（約占營收 18%） | I21: 第二來源：未找到。公司說法（Interested-party）：壓縮成形占比上升改善組合；AI／資料中心帶動第二季後的接單。低／高 ±30%
A22: w_hbm | B22: AI 相關中 HBM 比重 FY2025（其餘為 CoWoS 等 2.5D／晶圓級封膠） | C22: % | D22: 0.35 | E22: 0.5 | F22: 0.65 | G22: Assumed | H22: 公司 2026年3月期 第2四半期 決算說明會資料（2025-11-07）：HBM 封膠設備（含同業）累計約 30 台，數年內需再增 30–45 台；已取得 HBM4 客戶認證 | I22: 比重未找到；取一半。HBM 與 CoWoS 的成長形狀不同，Sens 列 35%／65%
A23: C. HBM 封膠需求（skhynix 成品 Mkt 頁，情境 A／B／C 各一列；唯讀）
A24: hsA_25 | B24: HBM 出貨位元 2025（EB；A） | C24: EB | E24: 2.2251147 | G24: Derived | H24: skhynix/dist/20261030_SK海力士個股模型_v0.6.1.xlsx｜Mkt!C24:G24 | I24: markets/memory：出貨＝MIN(需求 × 情境顆數係數, 供給)；2028–29 隨同字母情境
A25: hsA_26 | B25: HBM 出貨位元 2026（EB；A） | C25: EB | E25: 3.782695 | G25: Derived | H25: skhynix/dist/20261030_SK海力士個股模型_v0.6.1.xlsx｜Mkt!C24:G24 | I25: 同上
A26: hsA_27 | B26: HBM 出貨位元 2027（EB；A） | C26: EB | E26: 5.8631772 | G26: Derived | H26: skhynix/dist/20261030_SK海力士個股模型_v0.6.1.xlsx｜Mkt!C24:G24 | I26: 同上
A27: hsA_28 | B27: HBM 出貨位元 2028（EB；A） | C27: EB | E27: 8.501607 | G27: Derived | H27: skhynix/dist/20261030_SK海力士個股模型_v0.6.1.xlsx｜Mkt!C24:G24 | I27: 同上
A28: hsA_29 | B28: HBM 出貨位元 2029（EB；A） | C28: EB | E28: 11.477169 | G28: Derived | H28: skhynix/dist/20261030_SK海力士個股模型_v0.6.1.xlsx｜Mkt!C24:G24 | I28: 同上
A29: hsB_25 | B29: HBM 出貨位元 2025（EB；B） | C29: EB | E29: 2.2251147 | G29: Derived | H29: skhynix/dist/20261030_SK海力士個股模型_v0.6.1.xlsx｜Mkt!C25:G25 | I29: markets/memory：出貨＝MIN(需求 × 情境顆數係數, 供給)；2028–29 隨同字母情境
A30: hsB_26 | B30: HBM 出貨位元 2026（EB；B） | C30: EB | E30: 3.782695 | G30: Derived | H30: skhynix/dist/20261030_SK海力士個股模型_v0.6.1.xlsx｜Mkt!C25:G25 | I30: 同上
A31: hsB_27 | B31: HBM 出貨位元 2027（EB；B） | C31: EB | E31: 5.8631772 | G31: Derived | H31: skhynix/dist/20261030_SK海力士個股模型_v0.6.1.xlsx｜Mkt!C25:G25 | I31: 同上
A32: hsB_28 | B32: HBM 出貨位元 2028（EB；B） | C32: EB | E32: 8.22296 | G32: Derived | H32: skhynix/dist/20261030_SK海力士個股模型_v0.6.1.xlsx｜Mkt!C25:G25 | I32: 同上
A33: hsB_29 | B33: HBM 出貨位元 2029（EB；B） | C33: EB | E33: 11.357964 | G33: Derived | H33: skhynix/dist/20261030_SK海力士個股模型_v0.6.1.xlsx｜Mkt!C25:G25 | I33: 同上
A34: hsC_25 | B34: HBM 出貨位元 2025（EB；C） | C34: EB | E34: 2.2251147 | G34: Derived | H34: skhynix/dist/20261030_SK海力士個股模型_v0.6.1.xlsx｜Mkt!C26:G26 | I34: markets/memory：出貨＝MIN(需求 × 情境顆數係數, 供給)；2028–29 隨同字母情境
A35: hsC_26 | B35: HBM 出貨位元 2026（EB；C） | C35: EB | E35: 3.782695 | G35: Derived | H35: skhynix/dist/20261030_SK海力士個股模型_v0.6.1.xlsx｜Mkt!C26:G26 | I35: 同上
... A38: hsC_29 | B38: HBM 出貨位元 2029（EB；C） | C38: EB | E38: 8.017386 | G38: Derived | H38: skhynix/dist/20261030_SK海力士個股模型_v0.6.1.xlsx｜Mkt!C26:G26 | I38: 同上
A39: den_25 | B39: DRAM 核心晶粒容量（組合平均）2025 | C39: Gb／顆 | D39: 22 | E39: 24 | F39: 24 | G39: Assumed | H39: 沿用 disco/ 的假設（JEDEC HBM4：24Gb 或 32Gb 晶粒，TrendForce 2025-04-28） | I39: 組合比例未找到
A40: den_26 | B40: DRAM 核心晶粒容量（組合平均）2026 | C40: Gb／顆 | D40: 24 | E40: 24 | F40: 26 | G40: Assumed | H40: 沿用 disco/ 的假設（JEDEC HBM4：24Gb 或 32Gb 晶粒，TrendForce 2025-04-28） | I40: 同上
A41: den_27 | B41: DRAM 核心晶粒容量（組合平均）2027 | C41: Gb／顆 | D41: 24 | E41: 26 | F41: 28 | G41: Assumed | H41: 沿用 disco/ 的假設（JEDEC HBM4：24Gb 或 32Gb 晶粒，TrendForce 2025-04-28） | I41: 同上
A42: den_28 | B42: DRAM 核心晶粒容量（組合平均）2028 | C42: Gb／顆 | D42: 24 | E42: 28 | F42: 32 | G42: Assumed | H42: 沿用 disco/ 的假設（JEDEC HBM4：24Gb 或 32Gb 晶粒，TrendForce 2025-04-28） | I42: 同上
...

Sheet Q
A1: Q — 季度實績（十億日圓；EPS 為日圓）。會計年度 4–3 月。來源1：松井證券季度表（百萬日圓）；來源2：公司決算短信與說明資料
A3: 項目 | B3: FY25 Q1 | C3: FY25 Q2 | D3: FY25 Q3 | E3: FY25 Q4 | F3: FY2025 | G3: FY26 Q1 | H3: FY26 上半（公司指引） | I3: FY2026（公司指引） | J3: 標記 | K3: 來源1 | L3: 來源2／說明
A4: 營收 | B4: 8.08 | C4: 15.369 | D4: 13.481 | E4: 17.435 | F4: =SUM(B4:E4) -> 54.365 | G4: 16.183 | H4: =h1g_rev -> 32 | I4: =g26_rev -> 64 | J4: Verified／Interested-party（指引） | K4: 松井：8,080／15,369／13,481／17,435；FY26 Q1 16,183 | L4: 公司：上半 234.4 億（說明資料 2025-11-07）＝8.08＋15.37
A5: 營業利益 | B5: -0.581 | C5: 3.074 | D5: 1.192 | E5: 3.232 | F5: =SUM(B5:E5) -> 6.917 | G5: 2.212 | H5: =h1g_oi -> 5.12 | I5: =g26_oi -> 10.24 | J5: Verified／Interested-party（指引） | K5: 松井：−581／3,074／1,192／3,232；2,212 | L5: 公司：上半 24.9 億
A6: 淨利 | B6: -0.528 | C6: 2.377 | D6: 0.778 | E6: 1.966 | F6: =SUM(B6:E6) -> 4.593 | G6: 1.657 | H6: 3.5 | I6: =g26_ni -> 7 | J6: Verified／Interested-party（指引） | K6: 松井：−528／2,377／778／1,966；1,657 | L6: 上半指引 3,500（決算短信）
A7: EPS（基本） | B7: -7.05 | C7: 31.7 | D7: 10.37 | E7: 26.2 | F7: =SUM(B7:E7) -> 61.22 | G7: 22.09 | H7: 46.65 | I7: =g26_eps -> 93.3 | J7: Verified／Interested-party（指引） | K7: 松井 | L7: 上半指引 46.65
A8: 受注高 | B8: 10.43 | C8: 14.61 | F8: =ord_25 -> 59.56 | J8: Verified／Interested-party（指引） | K8: 說明資料 2025-11-07：上半 250.3、第二季 146.1（第一季＝差額 104.3，Derived） | L8: FY2025 全年 595.6 → 下半 345.3（Derived）；FY2026 計畫每季 150–170
A9: 營業利益率 | B9: =B5/B4 -> -0.071905941 | C9: =C5/C4 -> 0.20001301 | D9: =D5/D4 -> 0.08842074 | E9: =E5/E4 -> 0.18537425 | F9: =F5/F4 -> 0.12723259 | G9: =G5/G4 -> 0.13668665 | H9: =H5/H4 -> 0.16 | I9: =I5/I4 -> 0.16
A10: 檢查：FY2025 四季合計 − 年度（營收、營業利益、淨利；應約為 0） | B10: =F4-a25_rev -> 0 | C10: =F5-a25_oi -> 0 | D10: =F6-a25_ni -> 0
A11: FY2026 第一季占全年指引（營收／營業利益） | B11: =G4/I4 -> 0.25285937 | C11: =G5/I5 -> 0.21601562
A13: 第二季（2026-07～09）財報尚未公布（去年為 11-07 公布）；本版 FY2026 錨定公司全年指引。FY2025 第一季虧損、第三季因記憶體量產投資延後而下修（公司第三季說明資料）

Sheet Hist
A1: Hist — 年度實績（十億日圓；EPS 為日圓）。來源：公司決算短信（JPX）、四半期報告書（EDINET）、松井證券（FY2021 起）、the-shashi（轉載有價證券報告書）。用途：增量營益率迴歸、十年平均淨利率、10 年 P/E 的 EPS
A2: 股票分割：2024-10-01 一股分三股（基準日 2024-09-30；tipranks 轉載公司公告；Yahoo Finance 分割紀錄 2024-09-27）。FY2023（2024年3月期）以前公司公布的 EPS 除以 3；FY2021–FY2023 的松井、kabutan 數字已調整
A5: 會計年度 | B5: 營收 | C5: 毛利 | D5: 銷管費 | E5: 營業利益 | F5: 淨利 | G5: EPS（公司公布） | H5: 淨利率 | I5: 分割係數 | J5: EPS（分割調整後） | K5: 營業利益率 | L5: 來源1 | M5: 來源2
A6: FY2016（2017-03） | B6: 27.632 | E6: 3.831 | F6: 3.867 | G6: 154.64 | H6: =F6/B6 -> 0.13994644 | I6: 3 | J6: =G6/I6 -> 51.546667 | K6: =E6/B6 -> 0.1386436 | L6: 決算短信 2018-05-10（前期欄） | M6: the-shashi：38.3／38.7
A7: FY2017（2018-03） | B7: 31.01 | E7: 3.682 | F7: 3.026 | G7: 121.02 | H7: =F7/B7 -> 0.097581425 | I7: 3 | J7: =G7/I7 -> 40.34 | K7: =E7/B7 -> 0.11873589 | L7: 決算短信 2018-05-10（JPX 140120180422416748） | M7: 決算短信 2019-05（前期欄）同值
A8: FY2018（2019-03） | B8: 28.272 | C8: 6.986 | D8: =C8-E8 -> 6.049 | E8: 0.937 | F8: 0.877 | G8: 35.09 | H8: =F8/B8 -> 0.031020091 | I8: 3 | J8: =G8/I8 -> 11.696667 | K8: =E8/B8 -> 0.033142332 | L8: 決算短信 2019-05（JPX 140120190511422405） | M8: 決算短信 2020-05-07（前期欄，毛利 6,986）
A9: FY2019（2020-03） | B9: 25.255 | C9: 6.588 | D9: =C9-E9 -> 5.776 | E9: 0.812 | F9: 0.368 | G9: 14.75 | H9: =F9/B9 -> 0.014571372 | I9: 3 | J9: =G9/I9 -> 4.9166667 | K9: =E9/B9 -> 0.032152049 | L9: 決算短信 2020-05-07（JPX 140120200507404921） | M9: the-shashi：8.1／3.7
A10: FY2020（2021-03） | B10: 29.707 | E10: 3.62 | F10: 2.663 | G10: 106.49 | H10: =F10/B10 -> 0.089642172 | I10: 3 | J10: =G10/I10 -> 35.496667 | K10: =E10/B10 -> 0.1218568 | L10: 四半期報告書 第44期第3四半期（EDINET S100NDD0，前期通期欄：營收 29,707、淨利 2,663、EPS 106.49） | M10: 營業利益：the-shashi 36.2 億（單一來源；營收以外未見第二來源）
A11: FY2021（2022-03） | B11: 50.666 | E11: 11.505 | F11: 8.129 | G11: 108.36 | H11: =F11/B11 -> 0.1604429 | I11: 1 | J11: =G11/I11 -> 108.36 | K11: =E11/B11 -> 0.22707536 | L11: 松井證券 決算情報（finance.matsui.co.jp/stock/6315/settlement）（分割調整後） | M11: the-shashi：115／81.3
A12: FY2022（2023-03） | B12: 53.822 | E12: 10.037 | F12: 7.346 | G12: 97.9 | H12: =F12/B12 -> 0.13648694 | I12: 1 | J12: =G12/I12 -> 97.9 | K12: =E12/B12 -> 0.18648508 | L12: 松井證券 決算情報（finance.matsui.co.jp/stock/6315/settlement） | M12: kabutan：同值
A13: FY2023（2024-03） | B13: 50.471 | E13: 8.661 | F13: 6.444 | G13: 85.9 | H13: =F13/B13 -> 0.12767728 | I13: 1 | J13: =G13/I13 -> 85.9 | K13: =E13/B13 -> 0.1716035 | L13: 松井證券 決算情報（finance.matsui.co.jp/stock/6315/settlement） | M13: kabutan：同值
A14: FY2024（2025-03） | B14: 53.479 | E14: 8.88 | F14: 8.121 | G14: 108.28 | H14: =F14/B14 -> 0.151854 | I14: 1 | J14: =G14/I14 -> 108.28 | K14: =E14/B14 -> 0.16604649 | L14: 公司 2026年3月期 決算短信（2026-04-22 登錄，JPX iXBRL 081220260422508001）（前期欄） | M14: 松井證券 決算情報（finance.matsui.co.jp/stock/6315/settlement）
A15: FY2025（2026-03） | B15: 54.365 | C15: 18.372 | D15: =C15-E15 -> 11.455 | E15: 6.917 | F15: 4.593 | G15: 61.22 | H15: =F15/B15 -> 0.084484503 | I15: 1 | J15: =G15/I15 -> 61.22 | K15: =E15/B15 -> 0.12723259 | L15: 公司 2026年3月期 決算短信（2026-04-22 登錄，JPX iXBRL 081220260422508001） | M15: 松井證券 決算情報（finance.matsui.co.jp/stock/6315/settlement）
A17: 檢查：FY2025 列 − In 頁 a25_*（應為 0） | B17: =ABS(B15-a25_rev)+ABS(C15-a25_gp)+ABS(E15-a25_oi)+ABS(F15-a25_ni)+ABS(G15-a25_eps) -> 0
A19: 迴歸與統計
A20: 營業利益 ＝ 截距 ＋ 斜率 × 營收：斜率（增量營益率） | B20: =SLOPE(E6:E15,B6:B15) -> 0.26952113
A21: 截距 ¥B | B21: =INTERCEPT(E6:E15,B6:B15) -> -5.018754
A22: R² | B22: =RSQ(E6:E15,B6:B15) -> 0.82909389
A23: FY2025 營業利益：迴歸值 − 實績（¥B） | B23: =INTERCEPT(E6:E15,B6:B15)+SLOPE(E6:E15,B6:B15)*B15-E15 -> 2.716762
A24: 十年平均淨利率 | B24: =AVERAGE(H6:H15) -> 0.10337071
A25: 十年平均營業利益率 | B25: =AVERAGE(K6:K15) -> 0.13229737
A26: FY2021–FY2025 平均營業利益率（AI 前後的高營收期） | B26: =AVERAGE(K11:K15) -> 0.1756886
A27: 毛利率 FY2018／FY2019／FY2025（其餘年度未找到） | B27: =C8/B8 -> 0.2470996 | C27: =C9/B9 -> 0.26085924 | D27: =C15/B15 -> 0.33793801

Sheet PL
A1: PL — TOWA 損益（¥B；FY2025 實績；FY2026 錨定公司全年指引；FY2027–FY2029 驅動推導；FY2030–FY2032 收斂法見底部）。頂端為摘要，下方為三情境各一個完整推導區塊
A3: 情境／項目 | B3: 單位 | C3: FY2025A | D3: FY2026 | E3: FY2027 | F3: FY2028 | G3: FY2029 | H3: 說明
A4: 情境 A（順利）
A5: 營收 | B5: ¥B | C5: =C101 -> 54.365 | D5: =D101 -> 64 | E5: =E101 -> 66.938645 | F5: =F101 -> 71.971111 | G5: =G101 -> 74.976624
A6: 半導體製造裝置事業 | B6: ¥B | C6: =C100 -> 40.39 | D6: =D100 -> 48.821956 | E6: =E100 -> 50.866189 | F6: =F100 -> 55.167886 | G6: =G100 -> 57.574955
A7: AI 封膠（HBM＋2.5D） | B7: ¥B | C7: =C99 -> 10 | D7: =D99 -> 13.824744 | E7: =E99 -> 10.886268 | F7: =F99 -> 10.512298 | G7: =G99 -> 9.8050901
A8: 非 AI 封膠設備與模具 | B8: ¥B | C8: =C94 -> 26.46 | D8: =D94 -> 29.81967 | E8: =E94 -> 33.78428 | F8: =F94 -> 37.78559 | G8: =G94 -> 40.508375
A9: 其他半導體（切割等） | B9: ¥B | C9: =C95 -> 3.93 | D9: =D95 -> 5.1775411 | E9: =E95 -> 6.1956409 | F9: =F95 -> 6.869999 | G9: =G95 -> 7.2614905
A10: 新事業（TSS 等） | B10: ¥B | C10: =C96 -> 9.47 | D10: =D96 -> 9.9400633 | E10: =E96 -> 10.238265 | F10: =F96 -> 10.545413 | G10: =G96 -> 10.861776
A11: 醫療器材 | B11: ¥B | C11: =C97 -> 2.48 | D11: =D97 -> 2.6031 | E11: =E97 -> 2.681193 | F11: =F97 -> 2.7616288 | G11: =G97 -> 2.8444776
A12: 雷射 | B12: ¥B | C12: =C98 -> 2 | D12: =D98 -> 2.634881 | E12: =E98 -> 3.1529979 | F12: =F98 -> 3.4961827 | G12: =G98 -> 3.695415
A13: AI 封膠占營收 | B13: % | C13: =C103 -> 0.18394187 | D13: =D103 -> 0.21601163 | E13: =E103 -> 0.16263054 | F13: =F103 -> 0.14606274 | G13: =G103 -> 0.1307753
A14: 營業利益 | B14: ¥B | C14: =C104 -> 6.917 | D14: =D104 -> 10.24 | E14: =E104 -> 11.120186 | F14: =F104 -> 12.627516 | G14: =G104 -> 13.527731
A15: 營業利益率 | B15: % | C15: =C105 -> 0.12723259 | D15: =D105 -> 0.16 | E15: =E105 -> 0.16612506 | F15: =F105 -> 0.17545257 | G15: =G105 -> 0.18042598
A16: 淨利 | B16: ¥B | C16: =C106 -> 4.593 | D16: =D106 -> 7 | E16: =E106 -> 7.6016898 | F16: =F106 -> 8.6320911 | G16: =G106 -> 9.2474721
A17: EPS | B17: ¥ | C17: =C107 -> 61.22 | D17: =D107 -> 93.296149 | E17: =E107 -> 101.31548 | F17: =F107 -> 115.04869 | G17: =G107 -> 123.25051
A18: 對照：營收（只用驅動，無錨點） | B18: ¥B | C18: =C84 -> 54.365 | D18: =D84 -> 62.802659 | E18: =E84 -> 65.889991 | F18: =F84 -> 70.821311 | G18: =G84 -> 73.757365
A20: 情境 B（平平）
A21: 營收 | B21: ¥B | C21: =C152 -> 54.365 | D21: =D152 -> 64 | E21: =E152 -> 62.111502 | F21: =F152 -> 65.41661 | G21: =G152 -> 63.249191
A22: 半導體製造裝置事業 | B22: ¥B | C22: =C151 -> 40.39 | D22: =D151 -> 48.496668 | E22: =E151 -> 46.136373 | F22: =F151 -> 49.092093 | G22: =G151 -> 46.603764
A23: AI 封膠（HBM＋2.5D） | B23: ¥B | C23: =C150 -> 10 | D23: =D150 -> 12.749415 | E23: =E150 -> 7.3185286 | F23: =F150 -> 10.340214 | G23: =G150 -> 8.6246979
A24: 非 AI 封膠設備與模具 | B24: ¥B | C24: =C145 -> 26.46 | D24: =D145 -> 30.458749 | E24: =E145 -> 32.813451 | F24: =F145 -> 32.822541 | G24: =G145 -> 32.203591
A25: 其他半導體（切割等） | B25: ¥B | C25: =C146 -> 3.93 | D25: =D146 -> 5.2885034 | E25: =E146 -> 6.004393 | F25: =F146 -> 5.9293381 | G25: =G146 -> 5.7754755
A26: 新事業（TSS 等） | B26: ¥B | C26: =C147 -> 9.47 | D26: =D147 -> 10.153093 | E26: =E147 -> 10.238265 | F26: =F147 -> 10.545413 | G26: =G147 -> 10.861776
A27: 醫療器材 | B27: ¥B | C27: =C148 -> 2.48 | D27: =D148 -> 2.6588882 | E27: =E148 -> 2.681193 | F27: =F148 -> 2.7616288 | G27: =G148 -> 2.8444776
A28: 雷射 | B28: ¥B | C28: =C149 -> 2 | D28: =D149 -> 2.6913503 | E28: =E149 -> 3.0556707 | F28: =F149 -> 3.0174748 | G28: =G149 -> 2.9391733
A29: AI 封膠占營收 | B29: % | C29: =C154 -> 0.18394187 | D29: =D154 -> 0.19920961 | E29: =E154 -> 0.11782888 | F29: =F154 -> 0.15806711 | G29: =G154 -> 0.1363606
A30: 營業利益 | B30: ¥B | C30: =C155 -> 6.917 | D30: =D155 -> 10.24 | E30: =E155 -> 9.7310098 | F30: =F155 -> 10.621806 | G30: =G155 -> 10.037641
A31: 營業利益率 | B31: % | C31: =C156 -> 0.12723259 | D31: =D156 -> 0.16 | E31: =E156 -> 0.15667001 | F31: =F156 -> 0.1623717 | G31: =G156 -> 0.15869991
A32: 淨利 | B32: ¥B | C32: =C157 -> 4.593 | D32: =D157 -> 7 | E32: =E157 -> 6.6520575 | F32: =F157 -> 7.2610004 | G32: =G157 -> 6.8616687
A33: EPS | B33: ¥ | C33: =C158 -> 61.22 | D33: =D158 -> 93.296149 | E33: =E158 -> 88.658764 | F33: =F158 -> 96.774768 | G33: =G158 -> 91.452467
A34: 對照：營收（只用驅動，無錨點） | B34: ¥B | C34: =C135 -> 54.365 | D34: =D135 -> 61.484946 | E34: =E135 -> 61.08641 | F34: =F135 -> 64.386215 | G34: =G135 -> 62.227251
A36: 情境 C（不如預期）
A37: 營收 | B37: ¥B | C37: =C203 -> 54.365 | D37: =D203 -> 64 | E37: =E203 -> 56.582631 | F37: =F203 -> 53.025347 | G37: =G203 -> 53.759182
A38: 半導體製造裝置事業 | B38: ¥B | C38: =C202 -> 40.39 | D38: =D202 -> 48.258545 | E38: =E202 -> 40.760286 | F38: =F202 -> 37.273769 | G38: =G202 -> 37.577835
A39: AI 封膠（HBM＋2.5D） | B39: ¥B | C39: =C201 -> 10 | D39: =D201 -> 11.962234 | E39: =E201 -> 3.9007301 | F39: =F201 -> 5.8774213 | G39: =G201 -> 5.5954636
A40: 非 AI 封膠設備與模具 | B40: ¥B | C40: =C196 -> 26.46 | D40: =D196 -> 30.926579 | E40: =E196 -> 31.155382 | F40: =F196 -> 26.592833 | G40: =G196 -> 27.118814
A41: 其他半導體（切割等） | B41: ¥B | C41: =C197 -> 3.93 | D41: =D197 -> 5.3697319 | E41: =E197 -> 5.7041733 | F41: =F197 -> 4.8035144 | G41: =G197 -> 4.8635583
A42: 新事業（TSS 等） | B42: ¥B | C42: =C198 -> 9.47 | D42: =D198 -> 10.309039 | E42: =E198 -> 10.238265 | F42: =F198 -> 10.545413 | G42: =G198 -> 10.861776
A43: 醫療器材 | B43: ¥B | C43: =C199 -> 2.48 | D43: =D199 -> 2.6997273 | E43: =E199 -> 2.681193 | F43: =F199 -> 2.7616288 | G43: =G199 -> 2.8444776
...

Sheet Val
A1: Val — 估值。第 0 節為目標價（DCF 與 Comparable 加權）；第 1–6 節為十年 P/E、循環位置規則值（設備股共用規則：見頂年 25 分位、中段中位數、谷底 75 分位）與目前倍數
A2: P/E 定義（自算）：日曆年底收盤價 ÷ 「當期會計年度」公司公布的基本 EPS（例：2025-12 對 FY2025＝2026年3月期）。價格與 EPS 皆以 2024-10-01 一股分三股調整
A4: 0. 目標價
A5: 0.1 DCF（股東權益現金流，FY2027–FY2032 明確期＋FY2032 後永續）
A6: 項目 | B6: A（順利） | C6: B（平平） | D6: C（不如預期） | E6: 說明
A7: 情境 EPS（FY2027–FY2032） | E7: PL 頁延伸區塊；FY2030 起為收斂法
A8: FY2027 | B8: =PL!E221 -> 101.31548 | C8: =PL!E228 -> 88.658764 | D8: =PL!E235 -> 78.461067
A9: FY2028 | B9: =PL!F221 -> 115.04869 | C9: =PL!F228 -> 96.774768 | D9: =PL!F235 -> 71.346333
A10: FY2029 | B10: =PL!G221 -> 123.25051 | C10: =PL!G228 -> 91.452467 | D10: =PL!G235 -> 72.814037
A11: FY2030 | B11: =PL!H221 -> 129.14681 | C11: =PL!H228 -> 89.939366 | D11: =PL!H235 -> 74.395039
A12: FY2031 | B12: =PL!I221 -> 136.1104 | C12: =PL!I228 -> 90.62088 | D12: =PL!I235 -> 76.161548
A13: FY2032 | B13: =PL!J221 -> 144.27703 | C13: =PL!J228 -> 93.493211 | D13: =PL!J235 -> 78.124788
A14: 股東現金流＝EPS ×（1 − tp_g ÷ tp_roe） | E14: 模型無折舊與資本支出項目，故不用（淨利＋折舊－資本支出）；TOWA 資本支出 FY2025 41.9 億、FY2026 計畫 55.0 億（約營收 9%、指引淨利的約八成），高於再投資率 36.7%，此式可能高估現金流
A15: 再投資率（tp_g ÷ tp_roe，上限 0.8） | B15: =MIN(tp_g/tp_roe,0.8) -> 0.36742192 | E15: ROE 為近三年平均（In 頁 tp_roe）
A16: FY2027 | B16: =B8*(1-$B$15) -> 64.089953 | C16: =C8*(1-$B$15) -> 56.083591 | D16: =D8*(1-$B$15) -> 49.632751
A17: FY2028 | B17: =B9*(1-$B$15) -> 72.777282 | C17: =C9*(1-$B$15) -> 61.217597 | D17: =D9*(1-$B$15) -> 45.132126
A18: FY2029 | B18: =B10*(1-$B$15) -> 77.965568 | C18: =C10*(1-$B$15) -> 57.850826 | D18: =D10*(1-$B$15) -> 46.060564
A19: FY2030 | B19: =B11*(1-$B$15) -> 81.69544 | C19: =C11*(1-$B$15) -> 56.893671 | D19: =D11*(1-$B$15) -> 47.060671
A20: FY2031 | B20: =B12*(1-$B$15) -> 86.100458 | C20: =C12*(1-$B$15) -> 57.324782 | D20: =D12*(1-$B$15) -> 48.178125
A21: FY2032 | B21: =B13*(1-$B$15) -> 91.266485 | C21: =C13*(1-$B$15) -> 59.141756 | D21: =D13*(1-$B$15) -> 49.420028
A22: DCF 情境每股價值（折現率 tp_r） | B22: =MAX(0,SUMPRODUCT(B16:B21,1/(1+tp_r)^{1;2;3;4;5;6})+B21*(1+tp_g)/(tp_r-tp_g)/(1+tp_r)^6) -> 1230.7359 | C22: =MAX(0,SUMPRODUCT(C16:C21,1/(1+tp_r)^{1;2;3;4;5;6})+C21*(1+tp_g)/(tp_r-tp_g)/(1+tp_r)^6) -> 831.53526 | D22: =MAX(0,SUMPRODUCT(D16:D21,1/(1+tp_r)^{1;2;3;4;5;6})+D21*(1+tp_g)/(tp_r-tp_g)/(1+tp_r)^6) -> 690.51633 | E22: Σ 明確期現金流 ÷ (1＋r)^t ＋ 永續價值 ÷ (1＋r)^6；永續價值＝FY2032 現金流 ×(1＋g)÷(r−g)；基準日 2026 年底，t＝1 對 FY2027；負值取 0（股東有限責任）；會計年度 4–3 月，FY2027 仍以 t＝1 折現（略高估）
A23: DCF 情境價值推到 12 個月後（×(1＋tp_r)） | B23: =B22*(1+tp_r) -> 1353.8095 | C23: =C22*(1+tp_r) -> 914.68879 | D23: =D22*(1+tp_r) -> 759.56796
A24: DCF 目標價（情境加權） | B24: =tp_wA*B23+tp_wB*C23+tp_wC*D23 -> 1015.4008 | E24: Σ 權重 × 情境價值 ×(1＋r)；權重見 In 頁 tp_wA／tp_wB／tp_wC
A26: 0.2 Comparable（市場主流同業前瞻 P/E）
A27: 同業與前瞻 P/E | B27: 代號 | C27: 前瞻 12 月 P/E | D27: 日期 | E27: 來源 | F27: 標記
A28: Disco | B28: 6146.T | C28: 26.01 | D28: 2026-10-23 | E28: stockanalysis.com statistics：Forward PE（分析師共識；價格日期如左；本 repo hanmi／disco 同值） | F28: Interested-party
A29: 東京精密（Accretech） | B29: 7729.T | C29: 21.86 | D29: 2026-09-29 | E29: stockanalysis.com statistics：Forward PE（分析師共識；價格日期如左；本 repo hanmi／disco 同值） | F29: Interested-party
A30: ASMPT（封膠與鍵合競爭者） | B30: 0522.HK | C30: 30.26 | D30: 2026-09-23 | E30: stockanalysis.com statistics：Forward PE（分析師共識；價格日期如左；本 repo hanmi／disco 同值） | F30: Interested-party
A31: BE Semiconductor（BESI） | B31: BESI.AS | C31: 25.82 | D31: 2026-10-23 | E31: stockanalysis.com statistics：Forward PE（分析師共識；價格日期如左；本 repo hanmi／disco 同值） | F31: Interested-party
A32: Kulicke & Soffa | B32: KLIC | C32: 12.61 | D32: 2026-10-23 | E32: stockanalysis.com statistics：Forward PE（分析師共識；價格日期如左；本 repo hanmi／disco 同值） | F32: Interested-party
A33: 同業前瞻 P/E 中位數 | B33: =MEDIAN(C28:C32) -> 25.82 | E33: 後段設備同業：日本 Disco、東京精密；封裝設備 ASMPT（封膠直接競爭者）、BESI、Kulicke & Soffa。同業名單不含中國 A 股
A34: 12 個月後的前瞻 EPS（情境加權） | B34: =tp_wA*(5/12*B8+7/12*B9)+tp_wB*(5/12*C8+7/12*C9)+tp_wC*(5/12*D8+7/12*D9) -> 94.356668 | E34: 約 2027-10 時的未來 12 月（2027-11～2028-10）≈ 5／12 × FY2027（2027-04～2028-03）＋7／12 × FY2028（會計年度 4–3 月，依月份調整）
A35: Comparable 目標價 | B35: =B33*B34 -> 2436.2892 | E35: 同業中位數 × 上列 EPS
A37: 0.3 結論
A38: 項目 | B38: 數值 | E38: 說明
A39: 目標價（DCF 與 Comparable 加權） | B39: =tp_w_dcf*B24+(1-tp_w_dcf)*tp_comp_adj -> 1381.6029 | E39: tp_w_dcf × DCF 目標價＋（1 − tp_w_dcf）× Comparable 目標價；tp_w_dcf 見 In 頁
A40: Comparable 目標價（市場主流同業法） | B40: =B35 -> 2436.2892 | E40: 引用 0.2
A41: 市場共識目標價 | B41: =cons_tp -> 3300 | E41: stockanalysis：6 位分析師平均 ¥3,300（中位數 3,300；區間 2,600–4,000），2026-09-17 更新
A42: 上檔空間：加權目標價 | B42: =B39/px-1 -> -0.29796602 | E42: 現價＝In 頁 px（2026-10-23 收盤）
A43: 上檔空間：Comparable 目標價 | B43: =B40/px-1 -> 0.23795181
...

Sheet Recon
A1: Recon — FY2026 錨定公司全年指引（A 節為恆等式）；A2 節列只用驅動推導的結果；B 節共識只作參考，未用於校準或錨點。差距＝模型 ÷ 對照 − 1
A3: 項目 | B3: 對照值 | C3: 模型 A | D3: 差距 A | E3: 模型 B | F3: 差距 B | G3: 模型 C | H3: 差距 C | I3: 對照來源 | J3: 說明
A4: A. FY2026 錨點（公司指引）：差距為 0 是恆等式，不是獨立檢驗
A5: FY2026 營收 vs 公司指引 | B5: =g26_rev -> 64 | C5: =PL!D5 -> 64 | D5: =C5/B5-1 -> 0 | E5: =PL!D21 -> 64 | F5: =E5/B5-1 -> 0 | G5: =PL!D37 -> 64 | H5: =G5/B5-1 -> 0 | I5: 決算短信 2026-08-06（640.0 億） | J5: g_anc＝0
A6: FY2026 營業利益 vs 公司指引 | B6: =g26_oi -> 10.24 | C6: =PL!D14 -> 10.24 | D6: =C6/B6-1 -> 0 | E6: =PL!D30 -> 10.24 | F6: =E6/B6-1 -> 0 | G6: =PL!D46 -> 10.24 | H6: =G6/B6-1 -> 0 | I6: 同上（102.4 億）
A7: FY2026 EPS vs 公司指引 | B7: =g26_eps -> 93.3 | C7: =PL!D17 -> 93.296149 | D7: =C7/B7-1 -> -4.1273096e-05 | E7: =PL!D33 -> 93.296149 | F7: =E7/B7-1 -> -4.1273096e-05 | G7: =PL!D49 -> 93.296149 | H7: =G7/B7-1 -> -4.1273096e-05 | I7: 同上（93.30） | J7: 股數差異造成的小差
A8: FY2026 營收 vs 第一季 × 4 | B8: =q1_rev*4 -> 64.732 | C8: =PL!D5 -> 64 | D8: =C8/B8-1 -> -0.011308163 | E8: =PL!D21 -> 64 | F8: =E8/B8-1 -> -0.011308163 | G8: =PL!D37 -> 64 | H8: =G8/B8-1 -> -0.011308163 | I8: 第一季 16.2（實績） | J8: 第一季占全年指引 25.3%；第二季起計畫每季接單 150–170 億
A9: FY2026 營業利益率 vs 第一季（百分點） | B9: =q1_oi/q1_rev -> 0.13668665 | C9: =PL!D15 -> 0.16 | D9: =C9-B9 -> 0.023313354 | E9: =PL!D31 -> 0.16 | F9: =E9-B9 -> 0.023313354 | G9: =PL!D47 -> 0.16 | H9: =G9-B9 -> 0.023313354 | I9: 第一季 13.7% | J9: 指引隱含第二至四季營益率約 16.8%
A10: FY2026 半導體＋雷射營收 vs 公司事業計畫（484.3＋32.5） | B10: =g26_semi+g26_las -> 51.68 | C10: =PL!D99+PL!D94+PL!D95+PL!D98 -> 51.456837 | D10: =C10/B10-1 -> -0.0043181746 | E10: =PL!D150+PL!D145+PL!D146+PL!D149 -> 51.188018 | F10: =E10/B10-1 -> -0.0095197673 | G10: =PL!D201+PL!D196+PL!D197+PL!D200 -> 50.991233 | H10: =G10/B10-1 -> -0.013327526 | I10: 決算說明資料 2026-05 | J10: 事業組成經錨點同比例縮放（sc），組成比例來自驅動推導
A11: A2. 只用驅動推導時的 FY2026（對照；說明錨點改變了多少）
A12: 驅動推導營收 vs 錨點營收 | B12: =PL!D86 -> 64 | C12: =PL!D84 -> 62.802659 | D12: =C12/B12-1 -> -0.01870846 | E12: =PL!D135 -> 61.484946 | F12: =E12/B12-1 -> -0.039297713 | G12: =PL!D186 -> 60.554857 | H12: =G12/B12-1 -> -0.053830358 | I12: PL 區塊 C、D 節 | J12: 負＝驅動推導低於公司指引
A13: 驅動推導 雷射 vs 公司計畫 32.5 | B13: =g26_las -> 3.25 | C13: =PL!D83 -> 2.5855864 | D13: =C13/B13-1 -> -0.20443496 | E13: =PL!D134 -> 2.5855864 | F13: =E13/B13-1 -> -0.20443496 | G13: =PL!D185 -> 2.5855864 | H13: =G13/B13-1 -> -0.20443496 | I13: 公司計畫 +61.9%（雷射新機） | J13: 本模型雷射隨設備總額，低估公司計畫
A14: B. FY2026 vs 共識（參考）
A15: 營收 vs 共識（stockanalysis 2026-09-17，6 位） | B15: =cons_rev26 -> 69.3 | C15: =PL!D5 -> 64 | D15: =C15/B15-1 -> -0.076479076 | E15: =PL!D21 -> 64 | F15: =E15/B15-1 -> -0.076479076 | G15: =PL!D37 -> 64 | H15: =G15/B15-1 -> -0.076479076 | I15: stockanalysis（69.3；區間 65.3–74.3） | J15: 共識高於公司指引 8%
A16: 營業利益 vs 共識 | B16: =cons_oi26 -> 12.25 | C16: =PL!D14 -> 10.24 | D16: =C16/B16-1 -> -0.16408163 | E16: =PL!D30 -> 10.24 | F16: =E16/B16-1 -> -0.16408163 | G16: =PL!D46 -> 10.24 | H16: =G16/B16-1 -> -0.16408163 | I16: stockanalysis（12.25）
A17: 淨利 vs 共識 | B17: =cons_ni26 -> 8.7 | C17: =PL!D16 -> 7 | D17: =C17/B17-1 -> -0.1954023 | E17: =PL!D32 -> 7 | F17: =E17/B17-1 -> -0.1954023 | G17: =PL!D48 -> 7 | H17: =G17/B17-1 -> -0.1954023 | I17: stockanalysis（8.70）
A18: EPS vs 共識（淨利 ÷ 股數） | B18: =cons_feps -> 115.95379 | C18: =PL!D17 -> 93.296149 | D18: =C18/B18-1 -> -0.1954023 | E18: =PL!D33 -> 93.296149 | F18: =E18/B18-1 -> -0.1954023 | G18: =PL!D49 -> 93.296149 | H18: =G18/B18-1 -> -0.1954023 | I18: Derived（約 116） | J18: 差距約 −20%，未超過 30%：本模型 FY2026 採公司指引
A19: C. 結構檢查
A20: FY2025 AI 封膠占營收（校準結果；命題的「約兩成」） | C20: =PL!C13 -> 0.18394187
A21: FY2027 AI 封膠占營收（A／B／C） | C21: =PL!E13 -> 0.16263054 | E21: =PL!E29 -> 0.11782888 | G21: =PL!E45 -> 0.068938648
A22: FY2025 受注高 ÷ 營收（book-to-bill） | C22: =ord_25/a25_rev -> 1.0955578 | J22: 1.10：接單領先營收，支持 FY2026 指引
A23: FY2026 錨點營收 ÷（期初受注殘高＋計畫接單下限 4 × 150 億） | C23: =PL!D5/(bl_25+4*15) -> 0.71000666 | J23: 營收不超過可出貨量（＜1 表示指引可由殘高與接單支撐）

Sheet Sens
A1: Sens — 一次動一個輸入（情境 A）：對 FY2027、FY2028 營收與 EPS 的影響。每個案例是一個完整推導區塊（本頁下方，與 PL 同一引擎；校準會跟著重算）
A3: 案例 | B3: 設定 | C3: FY2027 營收 ¥B | D3: FY2027 EPS ¥ | E3: 相對基準 | F3: FY2028 營收 ¥B | G3: FY2028 EPS ¥ | H3: 相對基準 | I3: FY2027 AI 占營收 | J3: FY2026 EPS ¥ | K3: 相對基準
A4: 基準（情境 A） | B4: PL 區塊 A | C4: =PL!E101 -> 66.938645 | D4: =PL!E107 -> 101.31548 | E4: =D4/D$4-1 -> 0 | F4: =PL!F101 -> 71.971111 | G4: =PL!F107 -> 115.04869 | H4: =G4/G$4-1 -> 0 | I4: =PL!E103 -> 0.16263054 | J4: =PL!D107 -> 93.296149 | K4: =J4/J$4-1 -> 0
A5: AI 錨點 7.0（−30%） | B5: ai_25 低 | C5: =E111 -> 68.229073 | D5: =E117 -> 104.83696 | E5: =D5/D$4-1 -> 0.03475756 | F5: =F111 -> 73.898429 | G5: =F117 -> 120.3082 | H5: =G5/G$4-1 -> 0.045715442 | I5: =E113 -> 0.11168828 | J5: =D117 -> 93.296149 | K5: =J5/J$4-1 -> 0
A6: AI 錨點 13.0（+30%） | B6: ai_25 高 | C6: =E171 -> 65.756064 | D6: =E177 -> 98.088311 | E6: =D6/D$4-1 -> -0.031852702 | F6: =F171 -> 70.16406 | G6: =F177 -> 110.11739 | H6: =G6/G$4-1 -> -0.042862745 | I6: =E173 -> 0.21522195 | J6: =D177 -> 93.296149 | K6: =J6/J$4-1 -> 0
A7: HBM 比重 35% | B7: w_hbm 低 | C7: =E231 -> 66.456889 | D7: =E237 -> 100.00081 | E7: =D7/D$4-1 -> -0.012976051 | F7: =F231 -> 71.224913 | G7: =F237 -> 113.01238 | H7: =G7/G$4-1 -> -0.017699599 | I7: =E233 -> 0.16397462 | J7: =D237 -> 93.296149 | K7: =J7/J$4-1 -> 0
A8: HBM 比重 65% | B8: w_hbm 高 | C8: =E291 -> 67.429218 | D8: =E297 -> 102.65422 | E8: =D8/D$4-1 -> 0.013213556 | F8: =F291 -> 72.726977 | G8: =F297 -> 117.11139 | H8: =G8/G$4-1 -> 0.017928928 | I8: =E293 -> 0.16128458 | J8: =D297 -> 93.296149 | K8: =J8/J$4-1 -> 0
A9: 汰換／升級比例 5% | B9: dlt 低 | C9: =E351 -> 66.126044 | D9: =E357 -> 99.097958 | E9: =D9/D$4-1 -> -0.021887326 | F9: =F351 -> 70.76066 | G9: =F357 -> 111.74547 | H9: =G9/G$4-1 -> -0.028711546 | I9: =E353 -> 0.14976539 | J9: =D357 -> 93.296149 | K9: =J9/J$4-1 -> 0
A10: 汰換／升級比例 15% | B10: dlt 高 | C10: =E411 -> 67.639495 | D10: =E417 -> 103.22805 | E10: =D10/D$4-1 -> 0.018877336 | F10: =F411 -> 73.013581 | G10: =F417 -> 117.89351 | H10: =G10/G$4-1 -> 0.024727094 | I10: =E413 -> 0.17341346 | J10: =D417 -> 93.296149 | K10: =J10/J$4-1 -> 0
A11: 晶粒容量 低 | B11: den 低欄 | C11: =E471 -> 67.354251 | D11: =E477 -> 102.44964 | E11: =D11/D$4-1 -> 0.011194306 | F11: =F471 -> 71.056409 | G11: =F477 -> 112.55254 | H11: =G11/G$4-1 -> -0.021696478 | I11: =E473 -> 0.19269253 | J11: =D477 -> 93.296149 | K11: =J11/J$4-1 -> 0
A12: 晶粒容量 高 | B12: den 高欄 | C12: =E531 -> 66.570549 | D12: =E537 -> 100.31098 | E12: =D12/D$4-1 -> -0.0099146303 | F12: =F531 -> 73.359129 | G12: =F537 -> 118.83649 | H12: =G12/G$4-1 -> 0.03292341 | I12: =E533 -> 0.16305868 | J12: =D537 -> 93.296149 | K12: =J12/J$4-1 -> 0
A13: 堆疊層數 低（同位元更多堆疊） | B13: stk 低欄 | C13: =E591 -> 70.250487 | D13: =E597 -> 110.35324 | E13: =D13/D$4-1 -> 0.089204138 | F13: =F591 -> 75.009262 | G13: =F597 -> 123.33957 | H13: =G13/G$4-1 -> 0.072064091 | I13: =E593 -> 0.19616999 | J13: =D597 -> 93.296149 | K13: =J13/J$4-1 -> 0
A14: 堆疊層數 高 | B14: stk 高欄 | C14: =E651 -> 67.851675 | D14: =E657 -> 103.80707 | E14: =D14/D$4-1 -> 0.024592383 | F14: =F651 -> 73.988996 | G14: =F657 -> 120.55535 | H14: =G14/G$4-1 -> 0.047863664 | I14: =E653 -> 0.14592429 | J14: =D657 -> 93.296149 | K14: =J14/J$4-1 -> 0
A15: CY2030–31 需求年增 0% | B15: g_tail 低 | C15: =E711 -> 66.938645 | D15: =E717 -> 101.31548 | E15: =D15/D$4-1 -> 0 | F15: =F711 -> 70.775368 | G15: =F717 -> 111.7856 | H15: =G15/G$4-1 -> -0.02836268 | I15: =E713 -> 0.16263054 | J15: =D717 -> 93.296149 | K15: =J15/J$4-1 -> 0
A16: CY2030–31 需求年增 20% | B16: g_tail 高 | C16: =E771 -> 66.938645 | D16: =E777 -> 101.31548 | E16: =D16/D$4-1 -> 0 | F16: =F771 -> 73.166854 | G16: =F777 -> 118.31178 | H16: =G16/G$4-1 -> 0.02836268 | I16: =E773 -> 0.16263054 | J16: =D777 -> 93.296149 | K16: =J16/J$4-1 -> 0
A17: CoWoS 2025 600 千片 | B17: cw_25 低 | C17: =E831 -> 67.03834 | D17: =E837 -> 101.58754 | E17: =D17/D$4-1 -> 0.0026852909 | F17: =F831 -> 72.152928 | G17: =F837 -> 115.54486 | H17: =G17/G$4-1 -> 0.0043126578 | I17: =E833 -> 0.1568954 | J17: =D837 -> 93.296149 | K17: =J17/J$4-1 -> 0
A18: CY2030 封裝設備年增 0% | B18: g_pk_tail 低 | C18: =E891 -> 66.938645 | D18: =E897 -> 101.31548 | E18: =D18/D$4-1 -> 0 | F18: =F891 -> 71.971111 | G18: =F897 -> 115.04869 | H18: =G18/G$4-1 -> 0 | I18: =E893 -> 0.16263054 | J18: =D897 -> 93.296149 | K18: =J18/J$4-1 -> 0
A19: CY2030 封裝設備年增 10% | B19: g_pk_tail 高 | C19: =E951 -> 66.938645 | D19: =E957 -> 101.31548 | E19: =D19/D$4-1 -> 0 | F19: =F951 -> 71.971111 | G19: =F957 -> 115.04869 | H19: =G19/G$4-1 -> 0 | I19: =E953 -> 0.16263054 | J19: =D957 -> 93.296149 | K19: =J19/J$4-1 -> 0
A20: 新事業年增 0% | B20: g_tss 低 | C20: =E1011 -> 66.602972 | D20: =E1017 -> 100.39946 | E20: =D20/D$4-1 -> -0.0090413193 | F20: =F1011 -> 71.351462 | G20: =F1017 -> 113.35772 | H20: =G20/G$4-1 -> -0.014697888 | I20: =E1013 -> 0.16345019 | J20: =D1017 -> 93.296149 | K20: =J20/J$4-1 -> 0
A21: 新事業年增 6% | B21: g_tss 高 | C21: =E1071 -> 67.288587 | D21: =E1077 -> 102.27045 | E21: =D21/D$4-1 -> 0.0094256661 | F21: =F1071 -> 72.638613 | G21: =F1077 -> 116.87026 | H21: =G21/G$4-1 -> 0.015832964 | I21: =E1073 -> 0.16178476 | J21: =D1077 -> 93.296149 | K21: =J21/J$4-1 -> 0
A22: AI 封膠市占流失 8pt（C 的值） | B22: shl_C | C22: =E1131 -> 66.642864 | D22: =E1137 -> 100.50832 | E22: =D22/D$4-1 -> -0.0079668329 | F22: =F1131 -> 71.410248 | G22: =F1137 -> 113.51814 | H22: =G22/G$4-1 -> -0.013303519 | I22: =E1133 -> 0.15326887 | J22: =D1137 -> 93.296149 | K22: =J22/J$4-1 -> 0
A23: AI 封膠市占流失 12pt | B23: shl_C 高 | C23: =E1191 -> 66.496873 | D23: =E1197 -> 100.10992 | E23: =D23/D$4-1 -> -0.011899069 | F23: =F1191 -> 71.131899 | G23: =F1197 -> 112.75855 | H23: =G23/G$4-1 -> -0.01990586 | I23: =E1193 -> 0.14855255 | J23: =D1197 -> 93.296149 | K23: =J23/J$4-1 -> 0
A24: 增量營益率 −5pt | B24: im 低 | C24: =E1251 -> 66.938645 | D24: =E1257 -> 99.976791 | E24: =D24/D$4-1 -> -0.013213109 | F24: =F1251 -> 71.971111 | G24: =F1257 -> 111.41747 | H24: =G24/G$4-1 -> -0.031562466 | I24: =E1253 -> 0.16263054 | J24: =D1257 -> 93.296149 | K24: =J24/J$4-1 -> 0
A25: 增量營益率 +5pt | B25: im 高 | C25: =E1311 -> 66.938645 | D25: =E1317 -> 102.65418 | E25: =D25/D$4-1 -> 0.013213109 | F25: =F1311 -> 71.971111 | G25: =F1317 -> 118.67991 | H25: =G25/G$4-1 -> 0.031562466 | I25: =E1313 -> 0.16263054 | J25: =D1317 -> 93.296149 | K25: =J25/J$4-1 -> 0
A26: 增量營益率調整取 C 的 −5pt | B26: ima_C | C26: =E1371 -> 66.938645 | D26: =E1377 -> 99.173575 | E26: =D26/D$4-1 -> -0.021140974 | F26: =F1371 -> 71.971111 | G26: =F1377 -> 109.23874 | H26: =G26/G$4-1 -> -0.050499945 | I26: =E1373 -> 0.16263054 | J26: =D1377 -> 93.296149 | K26: =J26/J$4-1 -> 0
A27: 淨利÷營業利益 0.65 | B27: nioi 低 | C27: =E1431 -> 66.938645 | D27: =E1437 -> 96.336551 | E27: =D27/D$4-1 -> -0.049142857 | F27: =F1431 -> 71.971111 | G27: =F1437 -> 109.39487 | H27: =G27/G$4-1 -> -0.049142857 | I27: =E1433 -> 0.16263054 | J27: =D1437 -> 93.296149 | K27: =J27/J$4-1 -> 0
A28: 淨利÷營業利益 0.72 | B28: nioi 高 | C28: =E1491 -> 66.938645 | D28: =E1497 -> 106.71126 | E28: =D28/D$4-1 -> 0.053257143 | F28: =F1491 -> 71.971111 | G28: =F1497 -> 121.17586 | H28: =G28/G$4-1 -> 0.053257143 | I28: =E1493 -> 0.16263054 | J28: =D1497 -> 93.296149 | K28: =J28/J$4-1 -> 0
A29: FY2026 錨點 −5% | B29: g_anc 低 | C29: =E1551 -> 64.136026 | D29: =E1557 -> 97.735098 | E29: =D29/D$4-1 -> -0.035338972 | F29: =F1551 -> 68.89817 | G29: =F1557 -> 110.73062 | H29: =G29/G$4-1 -> -0.037532563 | I29: =E1553 -> 0.16973718 | J29: =D1557 -> 88.631342 | K29: =J29/J$4-1 -> -0.05
A30: FY2026 錨點 +8% | B30: g_anc 高 | C30: =E1611 -> 71.422835 | D30: =E1617 -> 107.0441 | E30: =D30/D$4-1 -> 0.056542355 | F30: =F1611 -> 76.887816 | G30: =F1617 -> 121.95761 | H30: =G30/G$4-1 -> 0.060052101 | I30: =E1613 -> 0.15241999 | J30: =D1617 -> 100.75984 | K30: =J30/J$4-1 -> 0.08
A31: 錨點差額不延續到 FY2027 | B31: 非 AI 基期回到驅動推導 | C31: =E1671 -> 65.889991 | D31: =E1677 -> 98.453788 | E31: =D31/D$4-1 -> -0.028245383 | F31: =F1671 -> 70.821311 | G31: =F1677 -> 111.91098 | H31: =G31/G$4-1 -> -0.027272926 | I31: =E1673 -> 0.16521884 | J31: =D1677 -> 93.296149 | K31: =J31/J$4-1 -> 0
A32: 情境 B | B32: 上游 B；市占流失 3pt；增量營益率＝迴歸 | C32: =PL!E152 -> 62.111502 | D32: =PL!E158 -> 88.658764 | E32: =D32/D$4-1 -> -0.12492384 | F32: =PL!F152 -> 65.41661 | G32: =PL!F158 -> 96.774768 | H32: =G32/G$4-1 -> -0.15883645 | I32: =PL!E154 -> 0.11782888 | J32: =PL!D158 -> 93.296149 | K32: =J32/J$4-1 -> 0
A33: 情境 C | B33: 上游 C；市占流失 8pt；增量營益率 −5pt | C33: =PL!E203 -> 56.582631 | D33: =PL!E209 -> 78.461067 | E33: =D33/D$4-1 -> -0.22557674 | F33: =PL!F203 -> 53.025347 | G33: =PL!F209 -> 71.346333 | H33: =G33/G$4-1 -> -0.37985968 | I33: =PL!E205 -> 0.068938648 | J33: =PL!D209 -> 93.296149 | K33: =J33/J$4-1 -> 0
A35: 讀法：校準在 FY2025 進行，所以改變 AI 錨點、HBM 比重、汰換比例等參數時，FY2025 仍等於實績，只改變之後的路徑形狀；FY2026 錨定公司指引，只受 g_anc 影響。
A70: 案例區塊：AI 錨點 7.0（−30%）（情境 A）
A71: 項目 | B71: 單位 | C71: CY2025／FY2025 | D71: CY2026／FY2026 | E71: CY2027／FY2027 | F71: CY2028／FY2028 | G71: CY2029／FY2029 | H71: CY2030 | I71: CY2031 | J71: 說明
A72: A. 日曆年（C＝CY2025 … I＝CY2031）
A73: HBM 出貨位元（同字母情境） | B73: EB | C73: =hsA_25 -> 2.2251147 | D73: =hsA_26 -> 3.782695 | E73: =hsA_27 -> 5.8631772 | F73: =hsA_28 -> 8.501607 | G73: =hsA_29 -> 11.477169 | J73: skhynix 成品 Mkt 頁
A74: DRAM 晶粒容量 | B74: Gb | C74: =den_25 -> 24 | D74: =den_26 -> 24 | E74: =den_27 -> 26 | F74: =den_28 -> 28 | G74: =den_29 -> 30
A75: 平均堆疊層數 | B75: 層 | C75: =stk_25 -> 10 | D75: =stk_26 -> 12 | E75: =stk_27 -> 12.5 | F75: =stk_28 -> 14 | G75: =stk_29 -> 15
A76: HBM 堆疊數（每個堆疊封膠一次） | B76: 十億個 | C76: =C73*8/(C74*C75) -> 0.07417049 | D76: =D73*8/(D74*D75) -> 0.10507486 | E76: =E73*8/(E74*E75) -> 0.14432436 | F76: =F73*8/(F74*F75) -> 0.17350218 | G76: =G73*8/(G74*G75) -> 0.20403857 | H76: =G76*(1+g_tail) -> 0.22444243 | I76: =H76*(1+g_tail) -> 0.24688667 | J76: EB × 8 ÷（晶粒容量 × 層數）；CY2030–31 以 g_tail 外推
...

Sheet Sources
A1: 來源（公司原文以網頁擷取工具讀取；說明資料圖表擷取錯位處未採用；版面與頁碼待人工複核）
A2: 公司：2026年3月期 決算短信（JPX iXBRL，2026-04-22 登錄） | B2: https://www2.jpx.co.jp/disc/63150/081220260422508001_tse-acedjpsm-63150-20260422508001-ixbrl.htm
A3: 公司：2027年3月期 第1四半期 決算短信（2026-08-06） | B3: https://www2.jpx.co.jp/disc/63150/081220260702586673_tse-qcedjpsm-63150-20260702586673-ixbrl.htm
A4: 公司：2026年3月期 決算說明資料（2026-05） | B4: https://www.towajapan.co.jp/jp/wp-content/uploads/sites/2/2026/05/2025FY_end_presentation.pdf
A5: 公司：2026年3月期 第2四半期 決算說明會資料（2025-11-07；HBM 台數、TechInsights 市占） | B5: https://www.towajapan.co.jp/jp/wp-content/uploads/sites/2/2025/11/2026_secondquarter_presentation.pdf
A6: 公司：2026年3月期 第3四半期 決算說明資料（記憶體量產投資延後） | B6: https://www.towajapan.co.jp/jp/wp-content/uploads/sites/2/2026/02/2026_thirdquarter_presentation.pdf
A7: 公司：歷年決算短信（2018-05-10、2019-05、2020-05-07） | B7: https://www2.jpx.co.jp/disc/63150/140120200507404921.pdf
A8: EDINET：四半期報告書 第44期第3四半期（FY2020 通期數字） | B8: https://disclosure2dl.edinet-fsa.go.jp/searchdocument/pdf/S100NDD0.pdf
A9: 松井證券：決算情報（年度、季度） | B9: https://finance.matsui.co.jp/stock/6315/settlement/index
A10: kabutan：業績（分割調整 EPS）、日足、年足 | B10: https://s.kabutan.jp/stocks/6315/historical_prices/daily/
A11: kabutore：現在株價、財務分析（毛利） | B11: https://www.kabutore.biz/genzaikabuka/6315.html
A12: the-shashi：配當與 EPS、營業利益歷史、股票分割 | B12: https://the-shashi.com/tse/6315/financials/profit/
A13: tipranks：股票分割公告（三分割，2024-10-01） | B13: https://www.tipranks.com/news/company-announcements/towa-corporation-announces-stock-split-and-dividend-revision
... A19: 36Kr／半導體產業縱橫：CoWoS 2025 67 萬片（2025-12-04） | B19: https://eu.36kr.com/en/p/3580962946874242
A20: 市場層與其他模型：skhynix、tsmc、markets/equipment 成品；markets/memory/market.py（本 repo）
A21: 無法開啟：irbank（權限逾時）、limo.media、kabutan 股價頁（桌面版）；kabuyoho 分析師頁（速率限制）
A22: SemiAnalysis | B22: 未使用
