Workbook

Sheet README
A1: SK 海力士 收支與估值模型 v0.4（記憶體樣板 v0.3） 2026-10-23
A2: 模型命題：SK 海力士的盈餘由兩條價格線決定——每季議價的一般 DRAM 與年約鎖價的 HBM；股價取決於這個循環在哪一年見頂，以及見頂時累積了多少淨值。
A4: 驅動因子 → 推導量
A5: Path（共用市場層）：一般 DRAM、NAND 合約價季增 → 季度指數（情境 A／B／C）；各公司依會計年度取平均，算年均價變動
A6: Mkt（共用市場層）：加速器顆數 × 每顆 GB × 情境顆數係數（2028–29，與台積電、Advantest 同一套）→ 需求位元；MIN(需求, 供給（三情境相同）) → 出貨；× 單價（依情境）→ HBM 市場（日曆年）
A7: Q：最後實績季 × 公司指引 × TrendForce 季價 → 基準年剩餘季度
A8: Y：前一年 × (1＋位元) × 價格指數比 → 一般 DRAM、NAND；Σ 各季 HBM 市場 × 市占 → HBM；成本量 × (1 − 年降)＋折舊 → 營業利益 → 淨利 → 權益 → 每股淨值
A9: Val：每股淨值 × P/B（主）、EPS × P/E（對照）
A10: Sens：各收入線同幅變動對營業利益的影響
A11: 非記憶體事業（只有三星）：營收與營業利益為輸入，不建模
A12: Recon：與共識、公司指引事後對照
A14: 情境：A＝2027–28 高檔持平、2029 緩降（BofA、TrendForce 型）；B＝2027 Q2 見頂、2028 回落約一半、2029 溫和回升（Citi、Bernstein 型）；C＝2028 回到 2025 年價格水準、2029 自谷底回升（完整循環）
... A22: 已知簡化：營運資金未計；股數用期末；HBM 毛利率無法由公開資料分離。

Sheet In
A1: In — 輸入（藍字＝基準值；低／高供敏感度）。每列具名範圍＝鍵（指向 E 欄）。單位：兆韓元
A3: 鍵 | B3: 項目 | C3: 單位 | D3: 低 | E3: 基準 | F3: 高 | G3: 標記 | H3: 來源／說明
A4: A. 匯率、股價
A5: fx | B5: 美元兌韓元（2026–2028 平均） | C5: KRW/USD | D5: 1350 | E5: 1420 | F5: 1500 | G5: Derived | H5: Q2 2026 營收 79.32 兆 ≈ US$55.2B → 約 1,437
A6: px | B6: 股價（2026-10-07 收盤） | C6: KRW | E6: 1723000 | G6: Verified | H6: Investing.com；10-02 為 1,841,000
A7: B. 基準年剩餘季度（公司指引＋TrendForce）
A8: q3_db | B8: Q3 DRAM 位元季增 | C8: % | D8: 0.08 | E8: 0.1 | F8: 0.12 | G8: Verified | H8: 公司 Q2 法說：約 +10%
A9: q3_dp | B9: Q3 DRAM 混合 ASP 季增 | C9: % | D9: 0.08 | E9: 0.12 | F9: 0.16 | G9: Derived | H9: TrendForce 一般 DRAM +13–18%；HBM 年約鎖價拉低混合值
A10: q3_nb | B10: Q3 NAND 位元季增 | C10: % | D10: 0 | E10: 0.02 | F10: 0.04 | G10: Verified | H10: 公司：低個位數
A11: q3_np | B11: Q3 NAND ASP 季增 | C11: % | D11: 0.1 | E11: 0.125 | F11: 0.2 | G11: Interested-party | H11: TrendForce +10–15%；MS 實際約 +20%
A12: q4_db | B12: Q4 DRAM 位元季增 | C12: % | D12: 0 | E12: 0.05 | F12: 0.08 | G12: Assumed | H12: 公司：下半年位元成長優於上半年
A13: q4_dp | B13: Q4 DRAM 混合 ASP 季增 | C13: % | D13: 0.05 | E13: 0.1 | F13: 0.15 | G13: Derived | H13: TrendForce +10–15%；BofA 約 +8%
A14: q4_nb | B14: Q4 NAND 位元季增 | C14: % | D14: 0 | E14: 0.05 | F14: 0.08 | G14: Assumed
A15: q4_np | B15: Q4 NAND ASP 季增 | C15: % | D15: 0.1 | E15: 0.175 | F15: 0.2 | G15: Interested-party | H15: TrendForce +15–20%
A16: da_q3 | B16: Q3 折舊攤銷 | C16: 兆韓元 | E16: 4.3 | G16: Assumed | H16: Q1 3.726、Q2 4.028 延伸
A17: da_q4 | B17: Q4 折舊攤銷 | C17: 兆韓元 | E17: 4.6 | G17: Assumed
A18: costdn_q | B18: 單位成本季降 | C18: % | D18: 0.01 | E18: 0.03 | F18: 0.05 | G18: Assumed
A19: opex_fix_q | B19: 營業費用固定部分（每季） | C19: 兆韓元 | E19: 1.5 | G19: Derived | H19: Q1、Q2 2026 營業費用 3.97、5.24 對營收迴歸
A20: nonop_q | B20: 下半年每季業外淨收益 | C20: 兆韓元 | D20: 0.5 | E20: 1 | F20: 2 | G20: Assumed | H20: 淨現金 × 約 2%
A21: C. 年度驅動（公司別）
A22: cb_1 | B22: 一般 DRAM 位元成長 第 1 年 | C22: % | D22: 0.05 | E22: 0.1 | F22: 0.15 | G22: Derived | H22: BofA DRAM 供給 +19%；HBM 晶圓占比 22%→30% 吃掉增量
A23: cb_2 | B23: 一般 DRAM 位元成長 第 2 年 | C23: % | D23: 0.1 | E23: 0.15 | F23: 0.19 | G23: Interested-party | H23: BofA 2028 供給 +19%
A24: nb_1 | B24: NAND 位元成長 第 1 年 | C24: % | D24: 0.15 | E24: 0.2 | F24: 0.25 | G24: Verified | H24: Micron：產業 2027 中 20% 段
A25: nb_2 | B25: NAND 位元成長 第 2 年 | C25: % | D25: 0.15 | E25: 0.2 | F25: 0.25 | G25: Verified | H25: 同上
A26: sh25 | B26: HBM 營收市占 2025 | C26: % | D26: 0.55 | E26: 0.58 | F26: 0.62 | G26: Interested-party | H26: Counterpoint 3Q25 57%；出貨 62%
A27: sh26 | B27: HBM 營收市占 2026 | C27: % | D27: 0.48 | E27: 0.52 | F27: 0.56 | G27: Interested-party | H27: Counterpoint Q1 58%、Q2 50%；IDC Q1 56.4%
A28: sh27 | B28: HBM 營收市占 2027 | C28: % | D28: 0.38 | E28: 0.42 | F28: 0.48 | G28: Interested-party | H28: UBS 2027 位元：SK 39%、三星 41%、美光 20%
A29: sh28 | B29: HBM 營收市占 2028 | C29: % | D29: 0.35 | E29: 0.4 | F29: 0.45 | G29: Assumed
A30: other_y | B30: 其他營收（每年） | C30: 兆韓元 | E30: 1.6 | G30: Verified
A31: w_c | B31: 成本權重：一般 DRAM | C31: % | E31: 0.45 | G31: Assumed
A32: w_h | B32: 成本權重：HBM | C32: % | E32: 0.3 | G32: Assumed | H32: HBM 每位元耗晶圓約 DDR5 的 3 倍（Micron）
A33: w_n | B33: 成本權重：NAND | C33: % | E33: 0.25 | G33: Assumed
A34: costdn_y | B34: 單位成本年降 | C34: % | D34: 0.05 | E34: 0.1 | F34: 0.15 | G34: Assumed
A35: da_life | B35: 新增資本支出轉為折舊的年數 | C35: 年 | D35: 4 | E35: 5 | F35: 6 | G35: Assumed
A36: da_cogs | B36: 折舊計入營業成本比例 | C36: % | E36: 0.9 | G36: Assumed
A37: opex_fix_y | B37: 營業費用固定部分（年，基準年） | C37: 兆韓元 | E37: 6 | G37: Derived | H37: ＝每季 1.5 × 4
A38: opex_var | B38: 營業費用變動率 | C38: % 營收 | D38: 0.04 | E38: 0.047 | F38: 0.06 | G38: Derived | H38: 同上迴歸
A39: opex_g | B39: 營業費用固定部分年增 | C39: % | E39: 0.1 | G39: Assumed
A40: tax | B40: 有效稅率 | C40: % | D40: 0.2 | E40: 0.23 | F40: 0.25 | G40: Verified | H40: Q1 21.8%、Q2 23.5%
A41: rf | B41: 淨現金收益率 | C41: % | E41: 0.02 | G41: Assumed
...

Sheet Path
A1: Path — 記憶體合約價指數（2025Q1＝1；季增來自 In 頁 M1）。共用市場層：所有記憶體公司用同一條路徑，再依各自會計年度取平均
A3: 路徑 | B3: 情境 | C3: 2025Q1 | D3: 2025Q2 | E3: 2025Q3 | F3: 2025Q4 | G3: 2026Q1 | H3: 2026Q2 | I3: 2026Q3 | J3: 2026Q4 | K3: 2027Q1 | L3: 2027Q2 | M3: 2027Q3 | N3: 2027Q4 | O3: 2028Q1 | P3: 2028Q2 | Q3: 2028Q3 | R3: 2028Q4 | S3: 2029Q1 | T3: 2029Q2 | U3: 2029Q3 | V3: 2029Q4
A4: 一般 DRAM | B4: A | C4: 1 | D4: =C4*(1+cq_1) -> 0.975 | E4: =D4*(1+cq_2) -> 1.096875 | F4: =E4*(1+cq_3) -> 1.6178906 | G4: =F4*(1+cq_4) -> 3.1548867 | H4: =G4*(1+cq_5) -> 5.0635932 | I4: =H4*(1+cq_6) -> 5.8484501 | J4: =I4*(1+cq_7) -> 6.5795064 | K4: =J4*(1+cqA_8) -> 6.7768916 | L4: =K4*(1+cqA_9) -> 6.7768916 | M4: =L4*(1+cqA_10) -> 6.6413538 | N4: =M4*(1+cqA_11) -> 6.4421131 | O4: =N4*(1+cqA_12) -> 6.2488497 | P4: =O4*(1+cqA_13) -> 6.0613843 | Q4: =P4*(1+cqA_14) -> 5.9401566 | R4: =Q4*(1+cqA_15) -> 5.8213534 | S4: =R4*(1+cqA_16) -> 5.6467128 | T4: =S4*(1+cqA_17) -> 5.4773114 | U4: =T4*(1+cqA_18) -> 5.3677652 | V4: =U4*(1+cqA_19) -> 5.2604099
A5: 一般 DRAM | B5: B | C5: 1 | D5: =C5*(1+cq_1) -> 0.975 | E5: =D5*(1+cq_2) -> 1.096875 | F5: =E5*(1+cq_3) -> 1.6178906 | G5: =F5*(1+cq_4) -> 3.1548867 | H5: =G5*(1+cq_5) -> 5.0635932 | I5: =H5*(1+cq_6) -> 5.8484501 | J5: =I5*(1+cq_7) -> 6.5795064 | K5: =J5*(1+cqB_8) -> 6.9084817 | L5: =K5*(1+cqB_9) -> 7.0466513 | M5: =L5*(1+cqB_10) -> 6.4829192 | N5: =M5*(1+cqB_11) -> 5.5104814 | O5: =N5*(1+cqB_12) -> 4.132861 | P5: =O5*(1+cqB_13) -> 3.5129319 | Q5: =P5*(1+cqB_14) -> 3.1616387 | R5: =Q5*(1+cqB_15) -> 3.0035567 | S5: =R5*(1+cqB_16) -> 3.1537346 | T5: =S5*(1+cqB_17) -> 3.3114213 | U5: =T5*(1+cqB_18) -> 3.4107639 | V5: =U5*(1+cqB_19) -> 3.5130869
A6: 一般 DRAM | B6: C | C6: 1 | D6: =C6*(1+cq_1) -> 0.975 | E6: =D6*(1+cq_2) -> 1.096875 | F6: =E6*(1+cq_3) -> 1.6178906 | G6: =F6*(1+cq_4) -> 3.1548867 | H6: =G6*(1+cq_5) -> 5.0635932 | I6: =H6*(1+cq_6) -> 5.8484501 | J6: =I6*(1+cq_7) -> 6.5795064 | K6: =J6*(1+cqC_8) -> 6.9084817 | L6: =K6*(1+cqC_9) -> 7.0466513 | M6: =L6*(1+cqC_10) -> 6.4829192 | N6: =M6*(1+cqC_11) -> 5.5104814 | O6: =N6*(1+cqC_12) -> 3.5818129 | P6: =O6*(1+cqC_13) -> 2.507269 | Q6: =P6*(1+cqC_14) -> 1.8804518 | R6: =Q6*(1+cqC_15) -> 1.5043614 | S6: =R6*(1+cqC_16) -> 1.5043614 | T6: =S6*(1+cqC_17) -> 1.5795795 | U6: =T6*(1+cqC_18) -> 1.7059458 | V6: =U6*(1+cqC_19) -> 1.8765404
A8: NAND | B8: A | C8: 1 | D8: =C8*(1+nq_1) -> 1 | E8: =D8*(1+nq_2) -> 1.05 | F8: =E8*(1+nq_3) -> 1.365 | G8: =F8*(1+nq_4) -> 2.559375 | H8: =G8*(1+nq_5) -> 4.4149219 | I8: =H8*(1+nq_6) -> 5.0771602 | J8: =I8*(1+nq_7) -> 5.9656632 | K8: =J8*(1+nqA_8) -> 6.1446331 | L8: =K8*(1+nqA_9) -> 6.1446331 | M8: =L8*(1+nqA_10) -> 5.8374014 | N8: =M8*(1+nqA_11) -> 5.4287833 | O8: =N8*(1+nqA_12) -> 5.1573442 | P8: =O8*(1+nqA_13) -> 4.899477 | Q8: =P8*(1+nqA_14) -> 4.6545031 | R8: =Q8*(1+nqA_15) -> 4.4217779 | S8: =R8*(1+nqA_16) -> 4.2891246 | T8: =S8*(1+nqA_17) -> 4.1604509 | U8: =T8*(1+nqA_18) -> 4.0356373 | V8: =U8*(1+nqA_19) -> 3.9145682
A9: NAND | B9: B | C9: 1 | D9: =C9*(1+nq_1) -> 1 | E9: =D9*(1+nq_2) -> 1.05 | F9: =E9*(1+nq_3) -> 1.365 | G9: =F9*(1+nq_4) -> 2.559375 | H9: =G9*(1+nq_5) -> 4.4149219 | I9: =H9*(1+nq_6) -> 5.0771602 | J9: =I9*(1+nq_7) -> 5.9656632 | K9: =J9*(1+nqB_8) -> 6.2639463 | L9: =K9*(1+nqB_9) -> 6.3892253 | M9: =L9*(1+nqB_10) -> 5.7503027 | N9: =M9*(1+nqB_11) -> 4.6002422 | O9: =N9*(1+nqB_12) -> 3.2201695 | P9: =O9*(1+nqB_13) -> 2.4151272 | Q9: =P9*(1+nqB_14) -> 1.9321017 | R9: =Q9*(1+nqB_15) -> 1.7388915 | S9: =R9*(1+nqB_16) -> 1.8258361 | T9: =S9*(1+nqB_17) -> 1.9171279 | U9: =T9*(1+nqB_18) -> 1.9746418 | V9: =U9*(1+nqB_19) -> 2.033881
A10: NAND | B10: C | C10: 1 | D10: =C10*(1+nq_1) -> 1 | E10: =D10*(1+nq_2) -> 1.05 | F10: =E10*(1+nq_3) -> 1.365 | G10: =F10*(1+nq_4) -> 2.559375 | H10: =G10*(1+nq_5) -> 4.4149219 | I10: =H10*(1+nq_6) -> 5.0771602 | J10: =I10*(1+nq_7) -> 5.9656632 | K10: =J10*(1+nqC_8) -> 6.2639463 | L10: =K10*(1+nqC_9) -> 6.3892253 | M10: =L10*(1+nqC_10) -> 5.7503027 | N10: =M10*(1+nqC_11) -> 4.6002422 | O10: =N10*(1+nqC_12) -> 2.9901574 | P10: =O10*(1+nqC_13) -> 1.9436023 | Q10: =P10*(1+nqC_14) -> 1.4577017 | R10: =Q10*(1+nqC_15) -> 1.1661614 | S10: =R10*(1+nqC_16) -> 1.1661614 | T10: =S10*(1+nqC_17) -> 1.2244695 | U10: =T10*(1+nqC_18) -> 1.322427 | V10: =U10*(1+nqC_19) -> 1.4546697
A12: 年均指數
A13: 路徑 | B13: 情境 | C13: 2025 | D13: 2026 | E13: 2027 | F13: 2028 | G13: 2029 | H13: 2026÷2025 | I13: 2027÷2026 | J13: 2028÷2027 | K13: 2029÷2028
A14: 一般 DRAM | B14: A | C14: =AVERAGE(C4:F4) -> 1.1724414 | D14: =AVERAGE(G4:J4) -> 5.1616091 | E14: =AVERAGE(K4:N4) -> 6.6593125 | F14: =AVERAGE(O4:R4) -> 6.017936 | G14: =AVERAGE(S4:V4) -> 5.4380499 | H14: =D14/C14-1 -> 3.4024453 | I14: =E14/D14-1 -> 0.29016211 | J14: =F14/E14-1 -> -0.096312722 | K14: =G14/F14-1 -> -0.09635964
A15: 一般 DRAM | B15: B | C15: =AVERAGE(C5:F5) -> 1.1724414 | D15: =AVERAGE(G5:J5) -> 5.1616091 | E15: =AVERAGE(K5:N5) -> 6.4871334 | F15: =AVERAGE(O5:R5) -> 3.4527471 | G15: =AVERAGE(S5:V5) -> 3.3472517 | H15: =D15/C15-1 -> 3.4024453 | I15: =E15/D15-1 -> 0.25680447 | J15: =F15/E15-1 -> -0.46775458 | K15: =G15/F15-1 -> -0.030554048
A16: 一般 DRAM | B16: C | C16: =AVERAGE(C6:F6) -> 1.1724414 | D16: =AVERAGE(G6:J6) -> 5.1616091 | E16: =AVERAGE(K6:N6) -> 6.4871334 | F16: =AVERAGE(O6:R6) -> 2.3684738 | G16: =AVERAGE(S6:V6) -> 1.6666068 | H16: =D16/C16-1 -> 3.4024453 | I16: =E16/D16-1 -> 0.25680447 | J16: =F16/E16-1 -> -0.63489671 | K16: =G16/F16-1 -> -0.29633724
A17: NAND | B17: A | C17: =AVERAGE(C8:F8) -> 1.10375 | D17: =AVERAGE(G8:J8) -> 4.5042801 | E17: =AVERAGE(K8:N8) -> 5.8888627 | F17: =AVERAGE(O8:R8) -> 4.7832755 | G17: =AVERAGE(S8:V8) -> 4.0999453 | H17: =D17/C17-1 -> 3.0808879 | I17: =E17/D17-1 -> 0.30739267 | J17: =F17/E17-1 -> -0.18774205 | K17: =G17/F17-1 -> -0.14285823
A18: NAND | B18: B | C18: =AVERAGE(C9:F9) -> 1.10375 | D18: =AVERAGE(G9:J9) -> 4.5042801 | E18: =AVERAGE(K9:N9) -> 5.7509291 | F18: =AVERAGE(O9:R9) -> 2.3265725 | G18: =AVERAGE(S9:V9) -> 1.9378717 | H18: =D18/C18-1 -> 3.0808879 | I18: =E18/D18-1 -> 0.27676989 | J18: =F18/E18-1 -> -0.59544407 | K18: =G18/F18-1 -> -0.16707013
A19: NAND | B19: C | C19: =AVERAGE(C10:F10) -> 1.10375 | D19: =AVERAGE(G10:J10) -> 4.5042801 | E19: =AVERAGE(K10:N10) -> 5.7509291 | F19: =AVERAGE(O10:R10) -> 1.8894057 | G19: =AVERAGE(S10:V10) -> 1.2919319 | H19: =D19/C19-1 -> 3.0808879 | I19: =E19/D19-1 -> 0.27676989 | J19: =F19/E19-1 -> -0.67146079 | K19: =G19/F19-1 -> -0.31622315

Sheet Mkt
A1: Mkt — 加速器數量層（最小版）與 HBM 市場（日曆年）。需求＝顆數 × GB × 情境顆數係數（2028–29）；供給三情境相同；出貨＝MIN(需求, 供給)；市場＝出貨 × 單價（單價依情境）
A3: 項目 | B3: 單位 | C3: 2025 | D3: 2026 | E3: 2027 | F3: 2028 | G3: 2029 | H3: 說明
A4: 需求：加速器裝載的 HBM（PB）
A5: NVIDIA Blackwell（B200／B300） | B5: PB | D5: =u_bw_26*g_bw_26 -> 1404 | E5: =u_bw_27*g_bw_27 -> 672 | F5: =u_bw_28*g_bw_28 -> 144
A6: NVIDIA Rubin | B6: PB | D6: =u_rb_26*g_rb_26 -> 489.6 | E6: =u_rb_27*g_rb_27 -> 2016 | F6: =u_rb_28*g_rb_28 -> 2016
A7: NVIDIA Rubin Ultra | B7: PB | D7: =u_ru_26*g_ru_26 -> 0 | E7: =u_ru_27*g_ru_27 -> 307.2 | F7: =u_ru_28*g_ru_28 -> 2048
A8: NVIDIA Hopper（H200 等） | B8: PB | D8: =u_hp_26*g_hp_26 -> 70.5 | E8: =u_hp_27*g_hp_27 -> 0 | F8: =u_hp_28*g_hp_28 -> 0
A9: AMD Instinct | B9: PB | D9: =u_amd_26*g_amd_26 -> 216 | E9: =u_amd_27*g_amd_27 -> 540 | F9: =u_amd_28*g_amd_28 -> 864
A10: Google TPU | B10: PB | D10: =u_tpu_26*g_tpu_26 -> 739.2 | E10: =u_tpu_27*g_tpu_27 -> 1375 | F10: =u_tpu_28*g_tpu_28 -> 2016
A11: AWS Trainium | B11: PB | D11: =u_trn_26*g_trn_26 -> 220 | E11: =u_trn_27*g_trn_27 -> 360 | F11: =u_trn_28*g_trn_28 -> 600
A12: 其他 ASIC（MTIA、Maia、Ascend 等） | B12: PB | D12: =u_oth_26*g_oth_26 -> 150 | E12: =u_oth_27*g_oth_27 -> 900 | F12: =u_oth_28*g_oth_28 -> 1250
A13: 需求合計（裝載） | B13: EB | D13: =SUM(D5:D12)/1000 -> 3.2893 | E13: =SUM(E5:E12)/1000 -> 6.1702 | F13: =SUM(F5:F12)/1000 -> 8.938 | G13: =F13*(1+hbm_dem29) -> 11.6194
A14: 需求 × 出貨係數（基準＝情境 A） | B14: EB | D14: =D13*hbm_gross -> 3.782695 | E14: =E13*hbm_gross -> 7.09573 | F14: =F13*hbm_gross -> 10.2787 | G14: =G13*hbm_gross -> 13.36231
A15: 加速器顆數合計 | B15: 百萬顆 | D15: =u_bw_26+u_rb_26+u_ru_26+u_hp_26+u_amd_26+u_tpu_26+u_trn_26+u_oth_26 -> 15.2 | E15: =u_bw_27+u_rb_27+u_ru_27+u_hp_27+u_amd_27+u_tpu_27+u_trn_27+u_oth_27 -> 23.7 | F15: =u_bw_28+u_rb_28+u_ru_28+u_hp_28+u_amd_28+u_tpu_28+u_trn_28+u_oth_28 -> 26.5 | H15: JPMorgan 2027：GPU 10.9M、ASIC 12.5M；情境 A 基準
A16: 每顆平均 HBM | B16: GB | D16: =D13*1000/D15 -> 216.40132 | E16: =E13*1000/E15 -> 260.34599 | F16: =F13*1000/F15 -> 337.28302
A17: 供給（三情境相同） | B17: EB | C17: =D17/(1+hbm_g26) -> 2.2251147 | D17: =D14 -> 3.782695 | E17: =D17*(1+hbm_sup27) -> 5.8631772 | F17: =E17*(1+hbm_sup28) -> 8.501607 | G17: =F17*(1+hbm_sup29) -> 11.477169 | H17: 2026 供給＝需求出貨（年中已成交）；供給不隨需求情境變（產能 2027 前已訂定）
A18: 顆數係數（A；2028–29 ÷ 基準，與台積電、Advantest 同一套） | B18: x | D18: 1 | E18: 1 | F18: =um28_A -> 1 | G18: =um29_A -> 1 | H18: 2026–27 無情境差異
A19: 顆數係數（B；2028–29 ÷ 基準，與台積電、Advantest 同一套） | B19: x | D19: 1 | E19: 1 | F19: =um28_B -> 0.8 | G19: =um29_B -> 0.85 | H19: 2026–27 無情境差異
A20: 顆數係數（C；2028–29 ÷ 基準，與台積電、Advantest 同一套） | B20: x | D20: 1 | E20: 1 | F20: =um28_C -> 0.6 | G20: =um29_C -> 0.6 | H20: 2026–27 無情境差異
A21: 需求 × 出貨係數（A） | B21: EB | D21: =D14*D18 -> 3.782695 | E21: =E14*E18 -> 7.09573 | F21: =F14*F18 -> 10.2787 | G21: =G14*G18 -> 13.36231
A22: 需求 × 出貨係數（B） | B22: EB | D22: =D14*D19 -> 3.782695 | E22: =E14*E19 -> 7.09573 | F22: =F14*F19 -> 8.22296 | G22: =G14*G19 -> 11.357964
A23: 需求 × 出貨係數（C） | B23: EB | D23: =D14*D20 -> 3.782695 | E23: =E14*E20 -> 7.09573 | F23: =F14*F20 -> 6.16722 | G23: =G14*G20 -> 8.017386
A24: 出貨＝MIN(需求, 供給)（A） | B24: EB | C24: =C17 -> 2.2251147 | D24: =MIN(D21,D17) -> 3.782695 | E24: =MIN(E21,E17) -> 5.8631772 | F24: =MIN(F21,F17) -> 8.501607 | G24: =MIN(G21,G17) -> 11.477169 | H24: 需求低於供給時出貨＝需求（閒置產能）
A25: 出貨＝MIN(需求, 供給)（B） | B25: EB | C25: =C17 -> 2.2251147 | D25: =MIN(D22,D17) -> 3.782695 | E25: =MIN(E22,E17) -> 5.8631772 | F25: =MIN(F22,F17) -> 8.22296 | G25: =MIN(G22,G17) -> 11.357964
A26: 出貨＝MIN(需求, 供給)（C） | B26: EB | C26: =C17 -> 2.2251147 | D26: =MIN(D23,D17) -> 3.782695 | E26: =MIN(E23,E17) -> 5.8631772 | F26: =MIN(F23,F17) -> 6.16722 | G26: =MIN(G23,G17) -> 8.017386
A27: 需求 − 供給（A；>0＝短缺） | B27: EB | D27: =D21-D17 -> 0 | E27: =E21-E17 -> 1.2325527 | F27: =F21-F17 -> 1.777093 | G27: =G21-G17 -> 1.8851405
A28: 需求 − 供給（B；>0＝短缺） | B28: EB | D28: =D22-D17 -> 0 | E28: =E22-E17 -> 1.2325527 | F28: =F22-F17 -> -0.27864701 | G28: =G22-G17 -> -0.11920597
A29: 需求 − 供給（C；>0＝短缺） | B29: EB | D29: =D23-D17 -> 0 | E29: =E23-E17 -> 1.2325527 | F29: =F23-F17 -> -2.334387 | G29: =G23-G17 -> -3.4597835
A30: HBM 單價（A） | B30: $/GB | C30: =hbm_mkt25/C24 -> 15.729526 | D30: =hbm_p26 -> 14.6 | E30: =D30*(1+hbm_p27) -> 26.28 | F30: =E30*(1+hbm_p28_A) -> 28.908 | G30: =F30*(1+hbm_p29_A) -> 27.4626
A31: HBM 單價（B） | B31: $/GB | C31: =hbm_mkt25/C24 -> 15.729526 | D31: =hbm_p26 -> 14.6 | E31: =D31*(1+hbm_p27) -> 26.28 | F31: =E31*(1+hbm_p28_B) -> 19.71 | G31: =F31*(1+hbm_p29_B) -> 19.71
A32: HBM 單價（C） | B32: $/GB | C32: =hbm_mkt25/C24 -> 15.729526 | D32: =hbm_p26 -> 14.6 | E32: =D32*(1+hbm_p27) -> 26.28 | F32: =E32*(1+hbm_p28_C) -> 15.768 | G32: =F32*(1+hbm_p29_C) -> 16.5564
A33: HBM 市場（A） | B33: $B | C33: =C24*C30 -> 35 | D33: =D24*D30 -> 55.227347 | E33: =E24*E30 -> 154.0843 | F33: =F24*F30 -> 245.76446 | G33: =G24*G30 -> 315.19291
A34: HBM 市場（B） | B34: $B | C34: =C25*C31 -> 35 | D34: =D25*D31 -> 55.227347 | E34: =E25*E31 -> 154.0843 | F34: =F25*F31 -> 162.07454 | G34: =G25*G31 -> 223.86546
A35: HBM 市場（C） | B35: $B | C35: =C26*C32 -> 35 | D35: =D26*D32 -> 55.227347 | E35: =E26*E32 -> 154.0843 | F35: =F26*F32 -> 97.244725 | G35: =G26*G32 -> 132.73905
A37: 對帳（樣板驗收 2）
A38: 由下而上：NVIDIA 裝載 HBM × 單價（2026） | B38: $B | D38: =(D5+D6+D7+D8)/1000*hbm_p26 -> 28.67586
A39: 由上而下：NVIDIA 資料中心營收 × 每顆 HBM ÷ 每顆 NVIDIA 內容（2026） | B39: $B | D39: =nv_dc26*nv_hbm/nv_content -> 38.972897 | H39: 橋接表 v0.2；與顆數預測獨立
A40: 差距 | B40: % | D40: =D38/D39-1 -> -0.26421021
A41: 由營收推得 NVIDIA 顆數 vs 顆數預測 | B41: 百萬顆 | D41: =nv_dc26/nv_content -> 8.7383178 | E41: =u_bw_26+u_rb_26+u_hp_26 -> 7.6 | H41: D＝營收推得；E＝顆數預測（2026）
A42: 已發布：SK 海力士自估 2026／BofA 2026／BofA 2027 | B42: $B | D42: =pub26_lo -> 54.6 | E42: =pub26_hi -> 77.4 | F42: =pub27 -> 152.8
...

Sheet Q
A1: Q — 季度損益（兆韓元）。實績：SEC 424B4（2026-07）、6-K 半年報（2026-08-18）、公司公告；推估季：實績 × 公司指引 × TrendForce 價格
A3: 項目 | B3: 2025Q1 | C3: 2025Q2 | D3: 2025Q3 | E3: 2025Q4 | F3: 2026Q1 | G3: 2026Q2 | H3: 2026Q3E | I3: 2026Q4E | J3: 2026 合計
A4: 記憶體營收 | B4: 17.639 | C4: 22.232 | D4: 24.449 | E4: 32.827 | F4: 52.576 | G4: 79.319 | H4: =H5+H6+H7 -> 96.311345 | I4: =I5+I6+I7 -> 113.11289 | J4: =SUM(F4:I4) -> 341.31923
A5: DRAM（含 HBM） | F5: =F4*0.773 -> 40.641248 | G5: =G4*0.73 -> 57.90287 | H5: =G5*(1+q3_db)*(1+q3_dp) -> 71.336336 | I5: =H5*(1+q4_db)*(1+q4_dp) -> 82.393468 | J5: =SUM(F5:I5) -> 252.27392
A6: NAND | F6: =F4*0.22 -> 11.56672 | G6: =G4*0.27 -> 21.41613 | H6: =G6*(1+q3_nb)*(1+q3_np) -> 24.575009 | I6: =H6*(1+q4_nb)*(1+q4_np) -> 30.319418 | J6: =SUM(F6:I6) -> 87.877277
A7: 其他 | F7: =F4-F5-F6 -> 0.368032 | G7: =G4-G5-G6 -> 0 | H7: =other_y/4 -> 0.4 | I7: =other_y/4 -> 0.4 | J7: =SUM(F7:I7) -> 1.168032
A8: 營業成本 | F8: =F4*(1-0.79) -> 11.04096 | G8: =G4*(1-0.83) -> 13.48423 | H8: =(G8-da_cogs*G13)*((w_c+w_h)*H14/G14+w_n*H15/G15)*(1-costdn_q)+da_cogs*da_q3 -> 14.19832 | I8: =(H8-da_cogs*H13)*((w_c+w_h)*I14/H14+w_n*I15/H15)*(1-costdn_q)+da_cogs*da_q4 -> 14.659394 | J8: =SUM(F8:I8) -> 53.382904
A9: 營業費用 | F9: =F4-F8-F10 -> 3.92504 | G9: =G4-G8-G10 -> 5.29177 | H9: =opex_fix_q+opex_var*H4 -> 6.0266332 | I9: =opex_fix_q+opex_var*I4 -> 6.8163056 | J9: =SUM(F9:I9) -> 22.059749
A10: 記憶體營業利益 | B10: 7.441 | C10: 9.213 | D10: 11.383 | E10: 19.17 | F10: 37.61 | G10: 60.543 | H10: =H4-H8-H9 -> 76.086392 | I10: =I4-I8-I9 -> 91.637186 | J10: =SUM(F10:I10) -> 265.87658
A11: 記憶體營業利益率 | B11: =IF(B4=0,"",B10/B4) -> 0.42184931 | C11: =IF(C4=0,"",C10/C4) -> 0.41440266 | D11: =IF(D4=0,"",D10/D4) -> 0.46558141 | E11: =IF(E4=0,"",E10/E4) -> 0.58397051 | F11: =IF(F4=0,"",F10/F4) -> 0.7153454 | G11: =IF(G4=0,"",G10/G4) -> 0.76328496 | H11: =IF(H4=0,"",H10/H4) -> 0.79000446 | I11: =IF(I4=0,"",I10/I4) -> 0.81013923 | J11: =J10/J4 -> 0.77896747
A12: 淨利（合併，含非記憶體事業） | B12: 8.108 | C12: 6.996 | D12: 12.598 | E12: 15.246 | F12: 40.346 | G12: 93.923 | H12: =(H10+nonop_q+nm_op_q)*(1-tax) -> 59.356522 | I12: =(I10+nonop_q+nm_op_q)*(1-tax) -> 71.330633 | J12: =SUM(F12:I12) -> 264.95616
A13: 折舊攤銷 | B13: 3.334 | C13: 3.443 | D13: 3.556 | E13: 3.557 | F13: 3.726 | G13: 4.028 | H13: =da_q3 -> 4.3 | I13: =da_q4 -> 4.6 | J13: =SUM(F13:I13) -> 16.654
A14: DRAM 位元指數（最後實績季＝1） | G14: 1 | H14: =G14*(1+q3_db) -> 1.1 | I14: =H14*(1+q4_db) -> 1.155
A15: NAND 位元指數 | G15: 1 | H15: =G15*(1+q3_nb) -> 1.02 | I15: =H15*(1+q4_nb) -> 1.071
A18: 2026Q1 DRAM 77.3%、NAND 22%、毛利率約 79%；Q2 DRAM 73%、NAND 27%、毛利率 83%（公司簡報）。2025 季度拆分未取得。2025Q3、Q4 折舊為合計 7.113 平均分配 [Derived]

Sheet Y
A1: Y — 年度（兆韓元；股數百萬股）。情境 A：2027–28 高檔持平、2029 緩降（BofA、TrendForce 型）；B：2027 Q2 見頂、2028 回落約一半、2029 溫和回升（Citi、Bernstein 型）；C：2028 回到 2025 年價格水準、2029 自谷底回升（完整循環）
A3: 項目 | B3: 2025 實績 | C3: 2026（基準） | D3: 2027 A | E3: 2028 A | F3: 2029 A | G3: 2027 B | H3: 2028 B | I3: 2029 B | J3: 2027 C | K3: 2028 C | L3: 2029 C | M3: 說明
A4: 記憶體營收 | B4: =SUM(Q!B4:E4) -> 97.147 | C4: =Q!J4 -> 341.31923 | D4: =D5+D6+D7+D8 -> 531.51177 | E4: =E5+E6+E7+E8 -> 587.50127 | F4: =F5+F6+F7+F8 -> 634.3461 | G4: =G5+G6+G7+G8 -> 520.52208 | H4: =H5+H6+H7+H8 -> 337.98618 | I4: =I5+I6+I7+I8 -> 589.30104 | J4: =J5+J6+J7+J8 -> 520.52208 | K4: =K5+K6+K7+K8 -> 232.6803 | L4: =L5+L6+L7+L8 -> 424.0747
A5: 一般 DRAM | C5: =Q!J5-C6 -> 211.49405 | D5: =C5*(1+cb_1)*(AVERAGE(Path!K4:N4)/AVERAGE(Path!G4:J4)) -> 300.14777 | E5: =D5*(1+cb_2)*(AVERAGE(Path!O4:R4)/AVERAGE(Path!K4:N4)) -> 311.92568 | F5: =D5*(1+cb_3)*(AVERAGE(Path!S4:V4)/AVERAGE(Path!O4:R4)) -> 311.90948 | G5: =C5*(1+cb_1)*(AVERAGE(Path!K5:N5)/AVERAGE(Path!G5:J5)) -> 292.38733 | H5: =G5*(1+cb_2)*(AVERAGE(Path!O5:R5)/AVERAGE(Path!K5:N5)) -> 178.96509 | I5: =G5*(1+cb_3)*(AVERAGE(Path!S5:V5)/AVERAGE(Path!O5:R5)) -> 325.97177 | J5: =C5*(1+cb_1)*(AVERAGE(Path!K6:N6)/AVERAGE(Path!G6:J6)) -> 292.38733 | K5: =J5*(1+cb_2)*(AVERAGE(Path!O6:R6)/AVERAGE(Path!K6:N6)) -> 122.76431 | L5: =J5*(1+cb_3)*(AVERAGE(Path!S6:V6)/AVERAGE(Path!O6:R6)) -> 236.60339 | M5: 前一年 × (1＋位元) × 會計年度價格指數平均比（Path）
A6: HBM | C6: =(Mkt!D33/4*sh26+Mkt!D33/4*sh26+Mkt!D33/4*sh26+Mkt!D33/4*sh26)*fx/1000 -> 40.779873 | D6: =(Mkt!E33/4*sh27+Mkt!E33/4*sh27+Mkt!E33/4*sh27+Mkt!E33/4*sh27)*fx/1000 -> 91.895875 | E6: =(Mkt!F33/4*sh28+Mkt!F33/4*sh28+Mkt!F33/4*sh28+Mkt!F33/4*sh28)*fx/1000 -> 139.59421 | F6: =(Mkt!G33/4*sh29+Mkt!G33/4*sh29+Mkt!G33/4*sh29+Mkt!G33/4*sh29)*fx/1000 -> 179.02958 | G6: =(Mkt!E34/4*sh27+Mkt!E34/4*sh27+Mkt!E34/4*sh27+Mkt!E34/4*sh27)*fx/1000 -> 91.895875 | H6: =(Mkt!F34/4*sh28+Mkt!F34/4*sh28+Mkt!F34/4*sh28+Mkt!F34/4*sh28)*fx/1000 -> 92.05834 | I6: =(Mkt!G34/4*sh29+Mkt!G34/4*sh29+Mkt!G34/4*sh29+Mkt!G34/4*sh29)*fx/1000 -> 127.15558 | J6: =(Mkt!E35/4*sh27+Mkt!E35/4*sh27+Mkt!E35/4*sh27+Mkt!E35/4*sh27)*fx/1000 -> 91.895875 | K6: =(Mkt!F35/4*sh28+Mkt!F35/4*sh28+Mkt!F35/4*sh28+Mkt!F35/4*sh28)*fx/1000 -> 55.235004 | L6: =(Mkt!G35/4*sh29+Mkt!G35/4*sh29+Mkt!G35/4*sh29+Mkt!G35/4*sh29)*fx/1000 -> 75.39578 | M6: Σ 會計年度各季：HBM 市場 ÷ 4 × 市占 × 匯率（Mkt）
A7: NAND | C7: =Q!J6 -> 87.877277 | D7: =C7*(1+nb_1)*(AVERAGE(Path!K8:N8)/AVERAGE(Path!G8:J8)) -> 137.86813 | E7: =D7*(1+nb_2)*(AVERAGE(Path!O8:R8)/AVERAGE(Path!K8:N8)) -> 134.38138 | F7: =D7*(1+nb_3)*(AVERAGE(Path!S8:V8)/AVERAGE(Path!O8:R8)) -> 141.80704 | G7: =C7*(1+nb_1)*(AVERAGE(Path!K9:N9)/AVERAGE(Path!G9:J9)) -> 134.63887 | H7: =G7*(1+nb_2)*(AVERAGE(Path!O9:R9)/AVERAGE(Path!K9:N9)) -> 65.362745 | I7: =G7*(1+nb_3)*(AVERAGE(Path!S9:V9)/AVERAGE(Path!O9:R9)) -> 134.57369 | J7: =C7*(1+nb_1)*(AVERAGE(Path!K10:N10)/AVERAGE(Path!G10:J10)) -> 134.63887 | K7: =J7*(1+nb_2)*(AVERAGE(Path!O10:R10)/AVERAGE(Path!K10:N10)) -> 53.080979 | L7: =J7*(1+nb_3)*(AVERAGE(Path!S10:V10)/AVERAGE(Path!O10:R10)) -> 110.47553
A8: 其他 | C8: =Q!J7 -> 1.168032 | D8: =other_y -> 1.6 | E8: =other_y -> 1.6 | F8: =other_y -> 1.6 | G8: =other_y -> 1.6 | H8: =other_y -> 1.6 | I8: =other_y -> 1.6 | J8: =other_y -> 1.6 | K8: =other_y -> 1.6 | L8: =other_y -> 1.6
A9: HBM ÷ 營收 | C9: =C6/C4 -> 0.11947722 | D9: =D6/D4 -> 0.17289528 | E9: =E6/E4 -> 0.23760665 | F9: =F6/F4 -> 0.28222697 | G9: =G6/G4 -> 0.17654559 | H9: =H6/H4 -> 0.27237309 | I9: =I6/I4 -> 0.21577356 | J9: =J6/J4 -> 0.17654559 | ... L9: =L6/L4 -> 0.17778891
A10: 折舊攤銷 | B10: =SUM(Q!B13:E13) -> 13.89 | C10: =Q!J13 -> 16.654 | D10: =C10+(C21-C10)/da_life -> 23.0632 | E10: =D10+(D21-D10)/da_life -> 30.91056 | F10: =D10+(D21-D10)/da_life -> 30.91056 | G10: =C10+(C21-C10)/da_life -> 23.0632 | H10: =G10+(G21-G10)/da_life -> 30.91056 | I10: =G10+(G21-G10)/da_life -> 30.91056 | J10: =C10+(C21-C10)/da_life -> 23.0632 | K10: =J10+(J21-J10)/da_life -> 30.91056 | L10: =J10+(J21-J10)/da_life -> 30.91056
A11: 成本量指數（÷ 前一年） | D11: =w_c*(1+cb_1)+w_h*D31/C31+w_n*(1+nb_1) -> 1.1705769 | E11: =w_c*(1+cb_2)+w_h*E31/D31+w_n*(1+nb_2) -> 1.2317857 | F11: =w_c*(1+cb_3)+w_h*F31/D31+w_n*(1+nb_3) -> 1.3767857 | G11: =w_c*(1+cb_1)+w_h*G31/C31+w_n*(1+nb_1) -> 1.1705769 | H11: =w_c*(1+cb_2)+w_h*H31/G31+w_n*(1+nb_2) -> 1.2182072 | I11: =w_c*(1+cb_3)+w_h*I31/G31+w_n*(1+nb_3) -> 1.3709768 | J11: =w_c*(1+cb_1)+w_h*J31/C31+w_n*(1+nb_1) -> 1.1705769 | K11: =w_c*(1+cb_2)+w_h*K31/J31+w_n*(1+nb_2) -> 1.1180304 | L11: =w_c*(1+cb_3)+w_h*L31/J31+w_n*(1+nb_3) -> 1.2081895
A12: 營業成本 | C12: =Q!J8 -> 53.382904 | D12: =(C12-da_cogs*C10)*D11*(1-costdn_y)+da_cogs*D10 -> 61.206017 | E12: =(D12-da_cogs*D10)*E11*(1-costdn_y)+da_cogs*E10 -> 72.661706 | F12: =(D12-da_cogs*D10)*F11*(1-costdn_y)+da_cogs*F10 -> 77.940319 | G12: =(C12-da_cogs*C10)*G11*(1-costdn_y)+da_cogs*G10 -> 61.206017 | H12: =(G12-da_cogs*G10)*H11*(1-costdn_y)+da_cogs*H10 -> 72.16739 | I12: =(G12-da_cogs*G10)*I11*(1-costdn_y)+da_cogs*I10 -> 77.728849 | J12: =(C12-da_cogs*C10)*J11*(1-costdn_y)+da_cogs*J10 -> 61.206017 | K12: =(J12-da_cogs*J10)*K11*(1-costdn_y)+da_cogs*K10 -> 68.520532 | L12: =(J12-da_cogs*J10)*L11*(1-costdn_y)+da_cogs*L10 -> 71.802704 | M12: 現金成本 × 量 × (1 − 年降)＋折舊
A13: 營業費用 | C13: =Q!J9 -> 22.059749 | D13: =opex_fix_y*(1+opex_g)^1+opex_var*D4 -> 31.581053 | E13: =opex_fix_y*(1+opex_g)^2+opex_var*E4 -> 34.87256 | F13: =opex_fix_y*(1+opex_g)^3+opex_var*F4 -> 37.800267 | G13: =opex_fix_y*(1+opex_g)^1+opex_var*G4 -> 31.064538 | H13: =opex_fix_y*(1+opex_g)^2+opex_var*H4 -> 23.14535 | I13: =opex_fix_y*(1+opex_g)^3+opex_var*I4 -> 35.683149 | J13: =opex_fix_y*(1+opex_g)^1+opex_var*J4 -> 31.064538 | K13: =opex_fix_y*(1+opex_g)^2+opex_var*K4 -> 18.195974 | L13: =opex_fix_y*(1+opex_g)^3+opex_var*L4 -> 27.917511
A14: 記憶體營業利益 | B14: =SUM(Q!B10:E10) -> 47.207 | C14: =Q!J10 -> 265.87658 | D14: =D4-D12-D13 -> 438.7247 | E14: =E4-E12-E13 -> 479.967 | F14: =F4-F12-F13 -> 518.60551 | G14: =G4-G12-G13 -> 428.25153 | H14: =H4-H12-H13 -> 242.67344 | I14: =I4-I12-I13 -> 475.88904 | J14: =J4-J12-J13 -> 428.25153 | K14: =K4-K12-K13 -> 145.96379 | L14: =L4-L12-L13 -> 324.35449
A15: 記憶體營業利益率 | B15: =B14/B4 -> 0.48593369 | C15: =C14/C4 -> 0.77896747 | D15: =D14/D4 -> 0.82542801 | E15: =E14/E4 -> 0.81696335 | F15: =F14/F4 -> 0.81754347 | G15: =G14/G4 -> 0.8227346 | H15: =H14/H4 -> 0.71799811 | I15: =I14/I4 -> 0.80754828 | ... L15: =L14/L4 -> 0.76485224
A16: 非記憶體事業營收 | C16: =nm_rev_0 -> 0 | D16: =nm_rev_1 -> 0 | E16: =nm_rev_2 -> 0 | F16: =nm_rev_3 -> 0 | G16: =nm_rev_1 -> 0 | H16: =nm_rev_2 -> 0 | I16: =nm_rev_3 -> 0 | J16: =nm_rev_1 -> 0 | K16: =nm_rev_2 -> 0 | L16: =nm_rev_3 -> 0
A17: 非記憶體事業營業利益 | C17: =nm_op_0 -> 0 | D17: =nm_op_1 -> 0 | E17: =nm_op_2 -> 0 | F17: =nm_op_3 -> 0 | G17: =nm_op_1 -> 0 | H17: =nm_op_2 -> 0 | I17: =nm_op_3 -> 0 | J17: =nm_op_1 -> 0 | K17: =nm_op_2 -> 0 | L17: =nm_op_3 -> 0
A18: 合併營收 | C18: =C4+C16 -> 341.31923 | D18: =D4+D16 -> 531.51177 | E18: =E4+E16 -> 587.50127 | F18: =F4+F16 -> 634.3461 | G18: =G4+G16 -> 520.52208 | H18: =H4+H16 -> 337.98618 | I18: =I4+I16 -> 589.30104 | J18: =J4+J16 -> 520.52208 | ... L18: =L4+L16 -> 424.0747
A19: 合併營業利益 | C19: =C14+C17 -> 265.87658 | D19: =D14+D17 -> 438.7247 | E19: =E14+E17 -> 479.967 | F19: =F14+F17 -> 518.60551 | G19: =G14+G17 -> 428.25153 | H19: =H14+H17 -> 242.67344 | I19: =I14+I17 -> 475.88904 | J19: =J14+J17 -> 428.25153 | ... L19: =L14+L17 -> 324.35449
A20: 淨利（合併） | B20: =SUM(Q!B12:E12) -> 42.948 | C20: =Q!J12 -> 264.95616 | D20: =(D19+rf*C26)*(1-tax) -> 340.58459 | E20: =(E19+rf*D26)*(1-tax) -> 374.66154 | F20: =(F19+rf*D26)*(1-tax) -> 404.41319 | G20: =(G19+rf*C26)*(1-tax) -> 332.52024 | H20: =(H19+rf*G26)*(1-tax) -> 191.8834 | I20: =(I19+rf*G26)*(1-tax) -> 371.45941 | J20: =(J19+rf*C26)*(1-tax) -> 332.52024 | K20: =(K19+rf*J26)*(1-tax) -> 117.41697 | L20: =(L19+rf*J26)*(1-tax) -> 254.7778 | M20: （營業利益＋淨現金 × 收益率）× (1 − 稅率)
A21: 資本支出 | C21: =cap_0 -> 48.7 | D21: =cap_1 -> 62.3 | E21: =cap_2 -> 71.2 | F21: =cap_3 -> 75 | G21: =cap_1 -> 62.3 | H21: =cap_2 -> 71.2 | I21: =cap_3 -> 75 | J21: =cap_1 -> 62.3 | K21: =cap_2 -> 71.2 | L21: =cap_3 -> 75
A22: 自由現金流（淨利＋折舊 − 資本支出） | C22: =C20+C10-C21 -> 232.91016 | D22: =D20+D10-D21 -> 301.34779 | E22: =E20+E10-E21 -> 334.3721 | F22: =F20+F10-F21 -> 360.32375 | G22: =G20+G10-G21 -> 293.28344 | H22: =H20+H10-H21 -> 151.59396 | I22: =I20+I10-I21 -> 327.36997 | J22: =J20+J10-J21 -> 293.28344 | ... L22: =L20+L10-L21 -> 210.68836
A23: 股利 | C23: =div_0 -> 0.54 | D23: =dps_1*C27/1000000 -> 3.2004764 | E23: =dps_2*D27/1000000 -> 3.250204 | F23: =dps_3*D27/1000000 -> 3.5913857 | G23: =dps_1*C27/1000000 -> 3.2004764 | H23: =dps_2*G27/1000000 -> 3.2624878 | I23: =dps_3*G27/1000000 -> 3.6049589 | J23: =dps_1*C27/1000000 -> 3.2004764 | K23: =dps_2*J27/1000000 -> 3.2624878 | L23: =dps_3*J27/1000000 -> 3.6049589
A24: 買回 | C24: =bb_0 -> 40 | D24: =MAX(0,payout*D22-D23) -> 147.47342 | E24: =MAX(0,payout*E22-E23) -> 163.93584 | F24: =MAX(0,payout*F22-F23) -> 176.57049 | G24: =MAX(0,payout*G22-G23) -> 143.44124 | H24: =MAX(0,payout*H22-H23) -> 72.53449 | I24: =MAX(0,payout*I22-I23) -> 160.08003 | J24: =MAX(0,payout*J22-J23) -> 143.44124 | K24: =MAX(0,payout*K22-K23) -> 35.301276 | L24: =MAX(0,payout*L22-L23) -> 101.73922 | M24: 回饋比例 × FCF − 股利
A25: 期末權益 | C25: =eq_last+(Q!H12+Q!I12)+extra_eq-C24-C23 -> 393.24016 | D25: =C25+D20-D23-D24 -> 583.15085 | E25: =D25+E20-E23-E24 -> 790.62634 | F25: =D25+F20-F23-F24 -> 807.40216 | G25: =C25+G20-G23-G24 -> 579.11868 | H25: =G25+H20-H23-H24 -> 695.20509 | I25: =G25+I20-I23-I24 -> 786.8931 | J25: =C25+J20-J23-J24 -> 579.11868 | K25: =J25+K20-K23-K24 -> 657.97188 | L25: =J25+L20-L23-L24 -> 728.5523
A26: 期末淨現金 | C26: =nc_last+(Q!H12+Q!I12)+(Q!H13+Q!I13)-capex_rem+extra_eq-C24-C23 -> 179.64716 | D26: =C26+D22-D23-D24 -> 330.32105 | E26: =D26+E22-E23-E24 -> 497.5071 | F26: =D26+F22-F23-F24 -> 510.48292 | G26: =C26+G22-G23-G24 -> 326.28888 | H26: =G26+H22-H23-H24 -> 402.08585 | I26: =G26+I22-I23-I24 -> 489.97386 | J26: =C26+J22-J23-J24 -> 326.28888 | K26: =J26+K22-K23-K24 -> 364.85264 | L26: =J26+L22-L23-L24 -> 431.63306
A27: 期末流通股數 | C27: =sh_last+extra_sh-bb_sh_0 -> 704.7955 | D27: =C27-D24/bb_px*1000000 -> 619.20443 | E27: =D27-E24/bb_px*1000000 -> 524.05884 | F27: =D27-F24/bb_px*1000000 -> 516.72591 | G27: =C27-G24/bb_px*1000000 -> 621.54463 | H27: =G27-H24/bb_px*1000000 -> 579.44684 | I27: =G27-I24/bb_px*1000000 -> 528.6369 | J27: =C27-J24/bb_px*1000000 -> 621.54463 | K27: =J27-K24/bb_px*1000000 -> 601.05637 | L27: =J27-L24/bb_px*1000000 -> 562.49691
A28: 每股淨值 BVPS | C28: =C25/C27*1000000 -> 557949.3 | D28: =D25/D27*1000000 -> 941774.35 | E28: =E25/E27*1000000 -> 1508659.5 | F28: =F25/F27*1000000 -> 1562534.7 | G28: =G25/G27*1000000 -> 931741.09 | H28: =H25/H27*1000000 -> 1199773.7 | I28: =I25/I27*1000000 -> 1488532.3 | J28: =J25/J27*1000000 -> 931741.09 | ... L28: =L25/L27*1000000 -> 1295211.2
A29: 每股盈餘 EPS（期末股數） | C29: =C20/C27*1000000 -> 375933.38 | D29: =D20/D27*1000000 -> 550035.78 | E29: =E20/E27*1000000 -> 714922.65 | F29: =F20/F27*1000000 -> 782645.47 | G29: =G20/G27*1000000 -> 534990.13 | H29: =H20/H27*1000000 -> 331149.26 | I29: =I20/I27*1000000 -> 702674.02 | J29: =J20/J27*1000000 -> 534990.13 | ... L29: =L20/L27*1000000 -> 452940.81
A30: ROE（期末權益） | C30: =C20/C25 -> 0.67377696 | D30: =D20/D25 -> 0.584042 | E30: =E20/E25 -> 0.4738794 | F30: =F20/F25 -> 0.50088197 | G30: =G20/G25 -> 0.57418325 | H30: =H20/H25 -> 0.27600977 | I30: =I20/I25 -> 0.47205829 | J30: =J20/J25 -> 0.57418325 | ... L30: =L20/L25 -> 0.34970421
A31: HBM 出貨位元（EB，公司） | C31: =(Mkt!D24/4*sh26+Mkt!D24/4*sh26+Mkt!D24/4*sh26+Mkt!D24/4*sh26) -> 1.9670014 | D31: =(Mkt!E24/4*sh27+Mkt!E24/4*sh27+Mkt!E24/4*sh27+Mkt!E24/4*sh27) -> 2.4625344 | E31: =(Mkt!F24/4*sh28+Mkt!F24/4*sh28+Mkt!F24/4*sh28+Mkt!F24/4*sh28) -> 3.4006428 | F31: =(Mkt!G24/4*sh29+Mkt!G24/4*sh29+Mkt!G24/4*sh29+Mkt!G24/4*sh29) -> 4.5908678 | G31: =(Mkt!E25/4*sh27+Mkt!E25/4*sh27+Mkt!E25/4*sh27+Mkt!E25/4*sh27) -> 2.4625344 | H31: =(Mkt!F25/4*sh28+Mkt!F25/4*sh28+Mkt!F25/4*sh28+Mkt!F25/4*sh28) -> 3.289184 | I31: =(Mkt!G25/4*sh29+Mkt!G25/4*sh29+Mkt!G25/4*sh29+Mkt!G25/4*sh29) -> 4.5431854 | J31: =(Mkt!E26/4*sh27+Mkt!E26/4*sh27+Mkt!E26/4*sh27+Mkt!E26/4*sh27) -> 2.4625344 | K31: =(Mkt!F26/4*sh28+Mkt!F26/4*sh28+Mkt!F26/4*sh28+Mkt!F26/4*sh28) -> 2.466888 | L31: =(Mkt!G26/4*sh29+Mkt!G26/4*sh29+Mkt!G26/4*sh29+Mkt!G26/4*sh29) -> 3.2069544

Sheet Val
A1: Val — 估值（P/B 主、P/E 對照）。隱含股價 ÷ 目前股價 − 1
A3: 方法 | B3: 倍數 | C3: 基準 | D3: 情境 | E3: 每股基準 | F3: 隱含股價 | G3: 相對目前
A4: P/B 1.0x | B4: =pb_1 -> 1 | C4: 2026 期末 BVPS | D4: 共用 | E4: =Y!C28 -> 557949.3 | F4: =B4*E4 -> 557949.3 | G4: =F4/px-1 -> -0.67617568
A5: P/B 歷史中位 1.6x | B5: =pb_2 -> 1.6 | C5: 2026 期末 BVPS | D5: 共用 | E5: =Y!C28 -> 557949.3 | F5: =B5*E5 -> 892718.88 | G5: =F5/px-1 -> -0.48188109
A6: P/B 券商遠期 3.3x | B6: =pb_3 -> 3.3 | C6: 2026 期末 BVPS | D6: 共用 | E6: =Y!C28 -> 557949.3 | F6: =B6*E6 -> 1841232.7 | G6: =F6/px-1 -> 0.068620248
A7: P/B 1.0x | B7: =pb_1 -> 1 | C7: 2027 期末 BVPS | D7: A | E7: =Y!D28 -> 941774.35 | F7: =B7*E7 -> 941774.35 | G7: =F7/px-1 -> -0.45341013
A8: P/B 歷史中位 1.6x | B8: =pb_2 -> 1.6 | C8: 2027 期末 BVPS | D8: A | E8: =Y!D28 -> 941774.35 | F8: =B8*E8 -> 1506839 | G8: =F8/px-1 -> -0.1254562
A9: P/B 券商遠期 3.3x | B9: =pb_3 -> 3.3 | C9: 2027 期末 BVPS | D9: A | E9: =Y!D28 -> 941774.35 | F9: =B9*E9 -> 3107855.4 | G9: =F9/px-1 -> 0.80374658
A10: P/B 1.0x | B10: =pb_1 -> 1 | C10: 2027 期末 BVPS | D10: B | E10: =Y!G28 -> 931741.09 | F10: =B10*E10 -> 931741.09 | G10: =F10/px-1 -> -0.45923326
A11: P/B 歷史中位 1.6x | B11: =pb_2 -> 1.6 | C11: 2027 期末 BVPS | D11: B | E11: =Y!G28 -> 931741.09 | F11: =B11*E11 -> 1490785.8 | G11: =F11/px-1 -> -0.13477322
A12: P/B 券商遠期 3.3x | B12: =pb_3 -> 3.3 | C12: 2027 期末 BVPS | D12: B | E12: =Y!G28 -> 931741.09 | F12: =B12*E12 -> 3074745.6 | G12: =F12/px-1 -> 0.78453024
A13: P/B 1.0x | B13: =pb_1 -> 1 | C13: 2027 期末 BVPS | D13: C | E13: =Y!J28 -> 931741.09 | F13: =B13*E13 -> 931741.09 | G13: =F13/px-1 -> -0.45923326
A14: P/B 歷史中位 1.6x | B14: =pb_2 -> 1.6 | C14: 2027 期末 BVPS | D14: C | E14: =Y!J28 -> 931741.09 | F14: =B14*E14 -> 1490785.8 | G14: =F14/px-1 -> -0.13477322
A15: P/B 券商遠期 3.3x | B15: =pb_3 -> 3.3 | C15: 2027 期末 BVPS | D15: C | E15: =Y!J28 -> 931741.09 | F15: =B15*E15 -> 3074745.6 | G15: =F15/px-1 -> 0.78453024
A16: P/B 1.0x | B16: =pb_1 -> 1 | C16: 2028 期末 BVPS | D16: A | E16: =Y!E28 -> 1508659.5 | F16: =B16*E16 -> 1508659.5 | G16: =F16/px-1 -> -0.12439961
A17: P/B 歷史中位 1.6x | B17: =pb_2 -> 1.6 | C17: 2028 期末 BVPS | D17: A | E17: =Y!E28 -> 1508659.5 | F17: =B17*E17 -> 2413855.2 | G17: =F17/px-1 -> 0.40096063
A18: P/B 券商遠期 3.3x | B18: =pb_3 -> 3.3 | C18: 2028 期末 BVPS | D18: A | E18: =Y!E28 -> 1508659.5 | F18: =B18*E18 -> 4978576.3 | G18: =F18/px-1 -> 1.8894813
A19: P/B 1.0x | B19: =pb_1 -> 1 | C19: 2028 期末 BVPS | D19: B | E19: =Y!H28 -> 1199773.7 | F19: =B19*E19 -> 1199773.7 | G19: =F19/px-1 -> -0.30367167
A20: P/B 歷史中位 1.6x | B20: =pb_2 -> 1.6 | C20: 2028 期末 BVPS | D20: B | E20: =Y!H28 -> 1199773.7 | F20: =B20*E20 -> 1919637.9 | G20: =F20/px-1 -> 0.11412533
A21: P/B 券商遠期 3.3x | B21: =pb_3 -> 3.3 | C21: 2028 期末 BVPS | D21: B | E21: =Y!H28 -> 1199773.7 | F21: =B21*E21 -> 3959253.3 | G21: =F21/px-1 -> 1.2978835
A22: P/B 1.0x | B22: =pb_1 -> 1 | C22: 2028 期末 BVPS | D22: C | E22: =Y!K28 -> 1094692.5 | F22: =B22*E22 -> 1094692.5 | G22: =F22/px-1 -> -0.36465904
A23: P/B 歷史中位 1.6x | B23: =pb_2 -> 1.6 | C23: 2028 期末 BVPS | D23: C | E23: =Y!K28 -> 1094692.5 | F23: =B23*E23 -> 1751507.9 | G23: =F23/px-1 -> 0.016545529
A24: P/B 券商遠期 3.3x | B24: =pb_3 -> 3.3 | C24: 2028 期末 BVPS | D24: C | E24: =Y!K28 -> 1094692.5 | F24: =B24*E24 -> 3612485.1 | G24: =F24/px-1 -> 1.0966252
A25: P/B 1.0x | B25: =pb_1 -> 1 | C25: 2029 期末 BVPS | D25: A | E25: =Y!F28 -> 1562534.7 | F25: =B25*E25 -> 1562534.7 | G25: =F25/px-1 -> -0.093131339
A26: P/B 歷史中位 1.6x | B26: =pb_2 -> 1.6 | C26: 2029 期末 BVPS | D26: A | E26: =Y!F28 -> 1562534.7 | F26: =B26*E26 -> 2500055.5 | G26: =F26/px-1 -> 0.45098986
A27: P/B 券商遠期 3.3x | B27: =pb_3 -> 3.3 | C27: 2029 期末 BVPS | D27: A | E27: =Y!F28 -> 1562534.7 | F27: =B27*E27 -> 5156364.5 | G27: =F27/px-1 -> 1.9926666
A28: P/B 1.0x | B28: =pb_1 -> 1 | C28: 2029 期末 BVPS | D28: B | E28: =Y!I28 -> 1488532.3 | F28: =B28*E28 -> 1488532.3 | G28: =F28/px-1 -> -0.13608107
A29: P/B 歷史中位 1.6x | B29: =pb_2 -> 1.6 | C29: 2029 期末 BVPS | D29: B | E29: =Y!I28 -> 1488532.3 | F29: =B29*E29 -> 2381651.7 | G29: =F29/px-1 -> 0.38227028
A30: P/B 券商遠期 3.3x | B30: =pb_3 -> 3.3 | C30: 2029 期末 BVPS | D30: B | E30: =Y!I28 -> 1488532.3 | F30: =B30*E30 -> 4912156.6 | G30: =F30/px-1 -> 1.8509325
A31: P/B 1.0x | B31: =pb_1 -> 1 | C31: 2029 期末 BVPS | D31: C | E31: =Y!L28 -> 1295211.2 | F31: =B31*E31 -> 1295211.2 | G31: =F31/px-1 -> -0.24828137
A32: P/B 歷史中位 1.6x | B32: =pb_2 -> 1.6 | C32: 2029 期末 BVPS | D32: C | E32: =Y!L28 -> 1295211.2 | F32: =B32*E32 -> 2072337.9 | G32: =F32/px-1 -> 0.20274981
A33: P/B 券商遠期 3.3x | B33: =pb_3 -> 3.3 | C33: 2029 期末 BVPS | D33: C | E33: =Y!L28 -> 1295211.2 | F33: =B33*E33 -> 4274197 | G33: =F33/px-1 -> 1.4806715
A34: P/E 4x | B34: =pe_1 -> 4 | C34: 2027 EPS | D34: A | E34: =Y!D29 -> 550035.78 | F34: =B34*E34 -> 2200143.1 | G34: =F34/px-1 -> 0.27692577
A35: P/E 8x | B35: =pe_2 -> 8 | C35: 2027 EPS | D35: A | E35: =Y!D29 -> 550035.78 | F35: =B35*E35 -> 4400286.2 | G35: =F35/px-1 -> 1.5538515
A36: P/E 12x | B36: =pe_3 -> 12 | C36: 2027 EPS | D36: A | E36: =Y!D29 -> 550035.78 | F36: =B36*E36 -> 6600429.3 | G36: =F36/px-1 -> 2.8307773
A37: P/E 4x | B37: =pe_1 -> 4 | C37: 2027 EPS | D37: B | E37: =Y!G29 -> 534990.13 | F37: =B37*E37 -> 2139960.5 | G37: =F37/px-1 -> 0.24199681
A38: P/E 8x | B38: =pe_2 -> 8 | C38: 2027 EPS | D38: B | E38: =Y!G29 -> 534990.13 | F38: =B38*E38 -> 4279921 | G38: =F38/px-1 -> 1.4839936
A39: P/E 12x | B39: =pe_3 -> 12 | C39: 2027 EPS | D39: B | E39: =Y!G29 -> 534990.13 | F39: =B39*E39 -> 6419881.5 | G39: =F39/px-1 -> 2.7259904
A40: P/E 4x | B40: =pe_1 -> 4 | C40: 2027 EPS | D40: C | E40: =Y!J29 -> 534990.13 | F40: =B40*E40 -> 2139960.5 | G40: =F40/px-1 -> 0.24199681
A41: P/E 8x | B41: =pe_2 -> 8 | C41: 2027 EPS | D41: C | E41: =Y!J29 -> 534990.13 | F41: =B41*E41 -> 4279921 | G41: =F41/px-1 -> 1.4839936
...

Sheet Sens
A1: Sens — 一次只動一個價格或份額輸入；Δ營業利益＝Δ營收 × (1 − 營業費用變動率)（成本只隨量變動，所以這是精確值，不是近似）
A3: 欄 | B3: 輸入變動 | C3: Δ營收 | D3: 營業利益 | E3: 相對基準
A4: 2027 A | B4: 基準 | D4: =Y!D14 -> 438.7247
A5: 2027 A | B5: 一般 DRAM 收入 −20% | C5: =-0.2*Y!D5 -> -60.029554 | D5: =D4+C5*(1-opex_var) -> 381.51654 | E5: =D5/D4-1 -> -0.1303965
A6: 2027 A | B6: 一般 DRAM 收入 +20% | C6: =0.2*Y!D5 -> 60.029554 | D6: =D4+C6*(1-opex_var) -> 495.93287 | E6: =D6/D4-1 -> 0.1303965
A7: 2027 A | B7: HBM 收入 −30%（價格或份額） | C7: =-0.3*Y!D6 -> -27.568763 | D7: =D4+C7*(1-opex_var) -> 412.45167 | E7: =D7/D4-1 -> -0.059885004
A8: 2027 A | B8: HBM 收入 +30% | C8: =0.3*Y!D6 -> 27.568763 | D8: =D4+C8*(1-opex_var) -> 464.99773 | E8: =D8/D4-1 -> 0.059885004
A9: 2027 A | B9: NAND 收入 −30% | C9: =-0.3*Y!D7 -> -41.360439 | D9: =D4+C9*(1-opex_var) -> 399.30821 | E9: =D9/D4-1 -> -0.089843352
A10: 2027 A | B10: NAND 收入 +30% | C10: =0.3*Y!D7 -> 41.360439 | D10: =D4+C10*(1-opex_var) -> 478.1412 | E10: =D10/D4-1 -> 0.089843352
A12: 2028 B | B12: 基準 | D12: =Y!H14 -> 242.67344
A13: 2028 B | B13: 一般 DRAM 收入 −20% | C13: =-0.2*Y!H5 -> -35.793019 | D13: =D12+C13*(1-opex_var) -> 208.56269 | E13: =D13/D12-1 -> -0.14056234
A14: 2028 B | B14: 一般 DRAM 收入 +20% | C14: =0.2*Y!H5 -> 35.793019 | D14: =D12+C14*(1-opex_var) -> 276.78418 | E14: =D14/D12-1 -> 0.14056234
A15: 2028 B | B15: HBM 收入 −30%（價格或份額） | C15: =-0.3*Y!H6 -> -27.617502 | D15: =D12+C15*(1-opex_var) -> 216.35396 | E15: =D15/D12-1 -> -0.10845637
A16: 2028 B | B16: HBM 收入 +30% | C16: =0.3*Y!H6 -> 27.617502 | D16: =D12+C16*(1-opex_var) -> 268.99292 | E16: =D16/D12-1 -> 0.10845637
A17: 2028 B | B17: NAND 收入 −30% | C17: =-0.3*Y!H7 -> -19.608824 | D17: =D12+C17*(1-opex_var) -> 223.98623 | E17: =D17/D12-1 -> -0.07700558
A18: 2028 B | B18: NAND 收入 +30% | C18: =0.3*Y!H7 -> 19.608824 | D18: =D12+C18*(1-opex_var) -> 261.36065 | E18: =D18/D12-1 -> 0.07700558
A20: 2028 C | B20: 基準 | D20: =Y!K14 -> 145.96379
A21: 2028 C | B21: 一般 DRAM 收入 −20% | C21: =-0.2*Y!K5 -> -24.552863 | D21: =D20+C21*(1-opex_var) -> 122.56491 | E21: =D21/D20-1 -> -0.16030605
A22: 2028 C | B22: 一般 DRAM 收入 +20% | C22: =0.2*Y!K5 -> 24.552863 | D22: =D20+C22*(1-opex_var) -> 169.36267 | E22: =D22/D20-1 -> 0.16030605
A23: 2028 C | B23: HBM 收入 −30%（價格或份額） | C23: =-0.3*Y!K6 -> -16.570501 | D23: =D20+C23*(1-opex_var) -> 130.1721 | E23: =D23/D20-1 -> -0.10818907
A24: 2028 C | B24: HBM 收入 +30% | C24: =0.3*Y!K6 -> 16.570501 | D24: =D20+C24*(1-opex_var) -> 161.75548 | E24: =D24/D20-1 -> 0.10818907
A25: 2028 C | B25: NAND 收入 −30% | C25: =-0.3*Y!K7 -> -15.924294 | D25: =D20+C25*(1-opex_var) -> 130.78794 | E25: =D25/D20-1 -> -0.10396998
A26: 2028 C | B26: NAND 收入 +30% | C26: =0.3*Y!K7 -> 15.924294 | D26: =D20+C26*(1-opex_var) -> 161.13964 | E26: =D26/D20-1 -> 0.10396998
A28: 2029 C | B28: 基準 | D28: =Y!L14 -> 324.35449
A29: 2029 C | B29: 一般 DRAM 收入 −20% | C29: =-0.2*Y!L5 -> -47.320678 | D29: =D28+C29*(1-opex_var) -> 279.25788 | E29: =D29/D28-1 -> -0.13903494
A30: 2029 C | B30: 一般 DRAM 收入 +20% | C30: =0.2*Y!L5 -> 47.320678 | D30: =D28+C30*(1-opex_var) -> 369.45109 | E30: =D30/D28-1 -> 0.13903494
A31: 2029 C | B31: HBM 收入 −30%（價格或份額） | C31: =-0.3*Y!L6 -> -22.618734 | D31: =D28+C31*(1-opex_var) -> 302.79883 | E31: =D31/D28-1 -> -0.066457084
A32: 2029 C | B32: HBM 收入 +30% | C32: =0.3*Y!L6 -> 22.618734 | D32: =D28+C32*(1-opex_var) -> 345.91014 | E32: =D32/D28-1 -> 0.066457084
A33: 2029 C | B33: NAND 收入 −30% | C33: =-0.3*Y!L7 -> -33.14266 | D33: =D28+C33*(1-opex_var) -> 292.76953 | E33: =D33/D28-1 -> -0.097377888
A34: 2029 C | B34: NAND 收入 +30% | C34: =0.3*Y!L7 -> 33.14266 | D34: =D28+C34*(1-opex_var) -> 355.93944 | E34: =D34/D28-1 -> 0.097377888
A36: 讀法：哪一條收入線的同幅變動對營業利益影響最大，就是該年度的主要驅動。價格路徑本身的情境差異見 Y 頁 A／B／C 欄。

Sheet Recon
A1: Recon — 本模型（正向推導）vs 共識或公司指引（只作事後對照，不用來回推參數）；兆韓元
A3: 項目 | B3: 本模型 | C3: 對照值 | D3: 差距 | E3: 對照來源
A4: 2026E 營收 vs 共識 | B4: =Y!C4 -> 341.31923 | C4: 344.2 | D4: =B4/C4-1 -> -0.008369464 | E4: MarketScreener 2026-10-02
A5: 2026E 營業利益 vs 共識 | B5: =Y!C14 -> 265.87658 | C5: 266.1 | D5: =B5/C5-1 -> -0.00083961641 | E5: MarketScreener；FnGuide 265.2
A6: 2026E 淨利 vs 共識 | B6: =Y!C20 -> 264.95616 | C6: 256.3 | D6: =B6/C6-1 -> 0.033773528 | E6: MarketScreener
A7: 2026E HBM 營收 vs BofA | B7: =Y!C6 -> 40.779873 | C7: 45.7 | D7: =B7/C7-1 -> -0.10766142 | E7: BofA 2026-09-13；CLSA 49.4
A8: 2027E 營收（A）vs 共識 | B8: =Y!D4 -> 531.51177 | C8: 531.3 | D8: =B8/C8-1 -> 0.00039859647 | E8: MarketScreener
A9: 2027E 營業利益（A）vs 共識 | B9: =Y!D14 -> 438.7247 | C9: 417.2 | D9: =B9/C9-1 -> 0.05159325 | E9: MarketScreener；FnGuide 391.8（08-14）
A10: 2027E 淨利（A）vs 共識 | B10: =Y!D20 -> 340.58459 | C10: 336.2 | D10: =B10/C10-1 -> 0.013041606 | E10: MarketScreener
A11: 2028E 營業利益（A）vs 共識 | B11: =Y!E14 -> 479.967 | C11: 454 | D11: =B11/C11-1 -> 0.057196044 | E11: MarketScreener；FnGuide 399.1
A12: 2026Q3E 營收 vs 共識 | B12: =Q!H4 -> 96.311345 | C12: 94.1 | D12: =B12/C12-1 -> 0.023499947 | E12: FnGuide 2026-09-25
A13: 2026Q3E 營業利益 vs 共識 | B13: =Q!H10 -> 76.086392 | C13: 76.1 | D13: =B13/C13-1 -> -0.00017881772 | E13: FnGuide 74.1–78.1

Sheet Feedback
A1: Feedback — 回饋算力收支
A3: 每顆加速器 HBM 金額（GB300，2026 價） | B3: =nv_hbm -> 4.46 | C3: $K
A4: 全市場每顆加速器平均 HBM 2026／2027 | B4: =TEXT(Mkt!D16,"0")&" ／ "&TEXT(Mkt!E16,"0") -> 216 ／ 260 | C4: GB
A5: HBM 市場 2026／2027（A） | B5: =TEXT(Mkt!D33,"0")&" ／ "&TEXT(Mkt!E33,"0") -> 55 ／ 154 | C5: $B
A6: 2027 HBM 需求缺口（三情境相同） | B6: =Mkt!E27 -> 1.2325527 | C6: EB
A7: SK 海力士 HBM 毛利率 | B7: 無法由公開資料分離 | C7: —

Sheet Sources
A1: 來源
A2: SK hynix 424B4（2026-07） | B2: https://www.sec.gov/Archives/edgar/data/2120882/000119312526299963/d32785d424b4.htm
A3: SK hynix 6-K 半年報（2026-08-18） | B3: https://www.sec.gov/Archives/edgar/data/2120882/000119312526354777/d147827d6k.htm
A4: Q2 2026 法說逐字稿 | B4: https://ng.investing.com/news/transcripts/earnings-call-transcript-sk-hynix-posts-record-q2-2026-results-as-shares-fall-93CH-2622277
A5: MarketScreener 共識 | B5: https://www.marketscreener.com/quote/stock/SK-HYNIX-INC-6494929/finances/
A6: Herald Business：FnGuide、目標價 | B6: https://biz.heraldcorp.com/article/10841314
A7: BofA HBM（Economy Tribune） | B7: https://www.economytribune.co.kr/news/articleView.html?idxno=3903874
A8: 40 兆買回（Korea Herald） | B8: https://www.koreaherald.com/article/10845792
A9: UBS 2027 HBM 市占（Korea Herald） | B9: https://www.koreaherald.com/article/10828143
A10: companiesmarketcap P/B | B10: https://companiesmarketcap.com/sk-hynix/pb-ratio/
A11: TrendForce 4Q26 價格 | B11: https://www.trendforce.com/presscenter/news/20260930-13258.html
A12: Citi 2027 見頂 | B12: https://www.tipranks.com/news/memory-prices-will-peak-next-year-warns-citi-as-it-cuts-micron-mu-price-target-by-18
A13: Bernstein 2028 | B13: https://www.notebookcheck.net/DRAM-crisis-Analysts-expect-drastic-price-drop-in-2028.1337992.0.html
... A15: markets/chip_bridge v0.2 | B15: 本 repo
