Workbook

Sheet README
A1: SK 海力士 收支與估值模型 v0.6.1（記憶體樣板 v0.4.1） 2026-10-29
A2: 模型命題：SK 海力士的盈餘由兩條價格線決定——每季議價的一般 DRAM 與年約鎖價的 HBM；股價取決於這個循環在哪一年見頂，以及見頂時累積了多少淨值。
A4: 驅動因子 → 推導量
A5: Path（共用市場層）：一般 DRAM、NAND 合約價季增 → 季度指數（情境 A／B／C）；各公司依會計年度取平均，算年均價變動
A6: Mkt（共用市場層）：加速器顆數 × 每顆 GB × 情境顆數係數（2028–29，與台積電、Advantest 同一套）→ 需求位元；MIN(需求, 供給（三情境相同）) → 出貨；× 單價（依情境）→ HBM 市場（日曆年）
A7: Q：最後實績季 × 公司指引 × TrendForce 季價 → 基準年剩餘季度
A8: Y：前一年 × (1＋位元) × 價格指數比 → 一般 DRAM、NAND；Σ 各季 HBM 市場 × 市占 → HBM；成本量 × (1 − 年降)＋折舊 → 營業利益 → 淨利 → 權益 → 每股淨值
A9: Val：第 0 節目標價＝DCF（股東現金流，FY2027–FY2032 明確期＋永續）與 Comparable（同業前瞻 P/B × 前瞻每股淨值）加權；另有每股淨值 × P/B（主）、EPS × P/E（對照）與十年倍數規則值
A10: Sens：各收入線同幅變動對營業利益的影響
A11: 非記憶體事業（只有三星）：營收與營業利益為輸入，不建模
A12: Recon：與共識、公司指引事後對照
A14: 情境：A＝2027–28 高檔持平、2029 緩降（BofA、TrendForce 型）；B＝2027 Q2 見頂、2028 回落約一半、2029 溫和回升（Citi、Bernstein 型）；C＝2028 回到 2025 年價格水準、2029 自谷底回升（完整循環）（目標價對應：A＝順利、B＝平平、C＝不如預期；2030–2032 為收斂法）
... A27: v0.6（2026-10-29）：滾入 2026Q3 實績（營收 104.616、營業利益 83.334、淨利 39.776 兆；業外淨損 32.6 兆＝匯兌損失 11.6＋投資資產評價損失 22.9−其他淨收益 1.9）；4Q DRAM 位元季增改為公司指引中 20% 段（原 5%）、NAND 中個位數；資產負債錨點移到 9-30（淨現金 98.7 兆為公司數字；權益、股數為推估，假設 40 兆買回於 3Q 執行完畢）；4Q 股東回饋改為 10-28 決議的買回 20 兆與 3Q 每股 20,000 韓元股利；2027 每股股利改為 FY2026 年度股利下限 22,050 韓元（6-K：全年現金股利 30 兆以上）。結果：2027 EPS（A）550,036 → 617,759（+12.3%）、加權目標價 3,087,845 → 3,408,692（+10.4%）。3Q 資產負債表待季報後校正。
A28: ="投資建議："&Val!B185&"（依上檔空間固定規則）" -> 投資建議：強力買進（依上檔空間固定規則）
A29: ="重點觀察 1：目標價 ₩"&TEXT(Val!$B$161,"#,##0")&"（DCF "&TEXT(Val!$B$146,"#,##0")&"、Comparable（相對倍數調整後）"&TEXT(tp_comp_adj,"#,##0")&"；DCF 權重 "&TEXT(tp_w_dcf,"0%")&"），比現價 "&TEXT(px,"#,##0")&"（2026-10-23）"&IF(Val!$B$164>=0,"高 "&TEXT(Val!$B$164,"0.0%"),"低 "&TEXT(-Val!$B$164,"0.0%"))&"，級距 "&Val!$B$184&"、投資建議 "&Val!$B$185&"。相對倍數調整係數 "&TEXT(rm_factor,"0.00")&"（本公司 10 年前瞻倍數中位數 ÷ 同業的中位數，夾在 0.5–2.0；Val 第 0.5 節），調整前加權上檔空間 "&TEXT((tp_w_dcf*Val!$B$146+(1-tp_w_dcf)*Val!$B$156)/px-1,"+0.0%;−0.0%")&"；Comparable 單獨（市場主流同業法、未調整）為 "&TEXT(Val!$B$165,"+0.0%;−0.0%")&"。"&"以下為 2026-10-29 相對倍數調整前撰寫的說明，其中數字為調整前：v0.6 滾入 3Q26 實績與 4Q 指引（DRAM 位元季增中 20% 段）後，2026 年第四季營收由 113.1 升到 140.7 兆，2027 起各年營收隨第四季基期上移約 9–10%；FY2026 年度股利（2027 支付）依公司「全年現金股利 30 兆以上」改為每股 22,050 韓元後，同樣的股東回饋總額中買"&"回減少、股數多約 1.2%，加權目標價合計 +10.4%。上檔空間仍主要來自倍數：現價隱含約 1.0 倍前瞻 P/B，同業中位數 1.94 倍。" -> 重點觀察 1：目標價 ₩3,362,856（DCF 4,288,814、Comparable（相對倍數調整後）2,436,897；DCF 權重 50%），比現價 1,277,000（2026-10-23）高 163.3%，級距 大於 50%、投資建議 強力買進。相對倍數調整係數 0.96（本公司 10 年前瞻倍數中位數 ÷ 同業的中位數，夾在 0.5–2.0；Val 第 0.5 節），調整前加權上檔空間 +166.9%；Comparable 單獨（市場主流同業法、未調整）為 +98.0%。以下為 2026-10-29 相對倍數調整前撰寫的說明，其中數字為調整前：v0.6 滾入 3Q26 實績與 4Q 指引（DRAM 位元季增中 20% 段）後，2026 年第四季營收由 113.1 升到 140.7 兆，2027 起各年營收隨第四季基期上移約 9–10%；FY2026 年度股利（2027 支付）依公司「全年現金股利 30 兆以上」改為每股 22,050 韓元後，同樣的股東回饋總額中買回減少、股數多約 1.2%，加權目標價合計 +10.4%。上檔空間仍主要來自倍數：現價隱含約 1.0 倍前瞻 P/B，同業中位數 1.94 倍。
A30: 重點觀察 2：情境分歧集中在 2028 年後：EPS 2028 A 818,444、B 375,667、C 222,213；DCF 情境價值（推到 12 個月後）A 7,641,482、B 3,401,631、C 1,477,771，C 情境為現價 1.16 倍。2026 年淨利 264 兆幾乎不變：3Q 業外淨損 32.6 兆（匯兌損失 11.6、投資資產評價損失 22.9、其他淨收益 1.9）抵銷了 4Q 上調。
A31: 重點觀察 3：2027 A 營業利益對一般 DRAM 收入最敏感（±20% → ±13.7%），NAND ±30% → ±8.3%、HBM ±30% → ±5.4%。待校正：3Q 資產負債表（權益、股數為推估，假設 40 兆買回於 3Q 執行完畢）於季報公布後更新；下一個檢驗事件是 4Q26 財報（2027-01 下旬）的 DRAM 位元與 HBM4 占比。
A33: 2026-10-29：加權目標價中的 Comparable 改用相對倍數調整後的值（Val 第 0.5 節：同業前瞻倍數中位數 × 本公司 10 年相對同業的倍數比，Bloomberg 前瞻倍數；Andy 2026-10-27「照建議做」、10-29 資料取回）。「Comparable 目標價（市場主流同業法）」維持不調整。重點觀察 1 的第一句已改為公式；重點觀察 2、3 與其他說明中的目標價與上檔空間數字為調整前撰寫，以 Val 頁為準。
A35: v0.6.1（2026-10-30）：依個股模型原則第 8 節調整 In 頁呈現（數值不變）。In 頁 D／F 欄名改「敏感度低」「敏感度高」（只用於 Sens 頁、不進目標價）；In 頁最後新增「情境驅動對照」一節，把上方各情境專屬輸入三情境並排（只引用上方各列，純展示）；HTML 驅動因子一節分「情境驅動」與「單一參數」兩張表。

Sheet In
A1: In — 輸入（藍字＝基準值；低／高供敏感度）。每列具名範圍＝鍵（指向 E 欄）。單位：兆韓元。【v0.6.1】基準欄 E 進主模型；D／F＝敏感度低／高，只用於 Sens 頁（一次動一個參數）、不進目標價；情境 A／B／C 的驅動見本頁最後一節「情境驅動對照」。
A3: 鍵 | B3: 項目 | C3: 單位 | D3: 敏感度低 | E3: 基準 | F3: 敏感度高 | G3: 標記 | H3: 來源／說明
A4: A. 匯率、股價
A5: fx | B5: 美元兌韓元（2026–2028 平均） | C5: KRW/USD | D5: 1350 | E5: 1420 | F5: 1500 | G5: Derived | H5: Q2 2026 營收 79.32 兆 ≈ US$55.2B → 約 1,437
A6: px | B6: 股價（2026-10-23 收盤） | C6: KRW | E6: 1277000 | G6: Verified | H6: markets/invest_map/data/prices.csv（tradersunion、digrin；Yonhap 當日 +4.4%）；MarketScreener 2026-10-23 收盤同（v0.4.2 為 10-07 收盤 1,723,000）
A7: B. 基準年剩餘季度（公司指引＋TrendForce）
A8: q4_db | B8: Q4 DRAM 位元季增 | C8: % | D8: 0.2 | E8: 0.25 | F8: 0.28 | G8: Interested-party | H8: 公司 3Q26 法說（2026-10-28）：4Q DRAM 位元季增中 20% 段（1z 製程、HBM4 放量）
A9: q4_dp | B9: Q4 DRAM 混合 ASP 季增 | C9: % | D9: 0.05 | E9: 0.1 | F9: 0.15 | G9: Derived | H9: TrendForce +10–15%；BofA 約 +8%
A10: q4_nb | B10: Q4 NAND 位元季增 | C10: % | D10: 0.03 | E10: 0.05 | F10: 0.07 | G10: Interested-party | H10: 公司 3Q26 法說：4Q NAND 位元季增中個位數
A11: q4_np | B11: Q4 NAND ASP 季增 | C11: % | D11: 0.1 | E11: 0.175 | F11: 0.2 | G11: Interested-party | H11: TrendForce +15–20%
A12: da_q4 | B12: Q4 折舊攤銷 | C12: 兆韓元 | E12: 4.6 | G12: Assumed
A13: costdn_q | B13: 單位成本季降 | C13: % | D13: 0.01 | E13: 0.03 | F13: 0.05 | G13: Assumed
A14: opex_fix_q | B14: 營業費用固定部分（每季） | C14: 兆韓元 | E14: 1.5 | G14: Derived | H14: Q1、Q2 2026 營業費用 3.97、5.24 對營收迴歸
A15: nonop_q | B15: 下半年每季業外淨收益 | C15: 兆韓元 | D15: 0.5 | E15: 1 | F15: 2 | G15: Assumed | H15: 淨現金 × 約 2%
A16: C. 年度驅動（公司別）
A17: cb_1 | B17: 一般 DRAM 位元成長 第 1 年 | C17: % | D17: 0.05 | E17: 0.1 | F17: 0.15 | G17: Derived | H17: BofA DRAM 供給 +19%；HBM 晶圓占比 22%→30% 吃掉增量
A18: cb_2 | B18: 一般 DRAM 位元成長 第 2 年 | C18: % | D18: 0.1 | E18: 0.15 | F18: 0.19 | G18: Interested-party | H18: BofA 2028 供給 +19%
A19: nb_1 | B19: NAND 位元成長 第 1 年 | C19: % | D19: 0.15 | E19: 0.2 | F19: 0.25 | G19: Derived | H19: 美光 FQ4-26 法說：產業 2027、2028 皆中 20% 段；本模型取低於產業（SK 海力士優先高價值產品，3Q26 NAND 位元季減）。2026-10-28 來源複核：原標 Verified 不當
A20: nb_2 | B20: NAND 位元成長 第 2 年 | C20: % | D20: 0.15 | E20: 0.2 | F20: 0.25 | G20: Derived | H20: 同上
A21: sh25 | B21: HBM 營收市占 2025 | C21: % | D21: 0.55 | E21: 0.58 | F21: 0.62 | G21: Interested-party | H21: Counterpoint 3Q25 57%；出貨 62%
A22: sh26 | B22: HBM 營收市占 2026 | C22: % | D22: 0.48 | E22: 0.52 | F22: 0.56 | G22: Interested-party | H22: Counterpoint Q1 58%、Q2 50%；IDC Q1 56.4%
A23: sh27 | B23: HBM 營收市占 2027 | C23: % | D23: 0.38 | E23: 0.42 | F23: 0.48 | G23: Interested-party | H23: UBS 2027 位元：SK 39%、三星 41%、美光 20%
A24: sh28 | B24: HBM 營收市占 2028 | C24: % | D24: 0.35 | E24: 0.4 | F24: 0.45 | G24: Assumed
A25: other_y | B25: 其他營收（每年） | C25: 兆韓元 | E25: 1.6 | G25: Verified
A26: w_c | B26: 成本權重：一般 DRAM | C26: % | E26: 0.45 | G26: Assumed
A27: w_h | B27: 成本權重：HBM | C27: % | E27: 0.3 | G27: Assumed | H27: HBM 每位元耗晶圓約 DDR5 的 3 倍（Micron）
A28: w_n | B28: 成本權重：NAND | C28: % | E28: 0.25 | G28: Assumed
A29: costdn_y | B29: 單位成本年降 | C29: % | D29: 0.05 | E29: 0.1 | F29: 0.15 | G29: Assumed
A30: da_life | B30: 新增資本支出轉為折舊的年數 | C30: 年 | D30: 4 | E30: 5 | F30: 6 | G30: Assumed
A31: da_cogs | B31: 折舊計入營業成本比例 | C31: % | E31: 0.9 | G31: Assumed
A32: opex_fix_y | B32: 營業費用固定部分（年，基準年） | C32: 兆韓元 | E32: 6 | G32: Derived | H32: ＝每季 1.5 × 4
A33: opex_var | B33: 營業費用變動率 | C33: % 營收 | D33: 0.04 | E33: 0.047 | F33: 0.06 | G33: Derived | H33: 同上迴歸
A34: opex_g | B34: 營業費用固定部分年增 | C34: % | E34: 0.1 | G34: Assumed
A35: tax | B35: 有效稅率 | C35: % | D35: 0.2 | E35: 0.23 | F35: 0.25 | G35: Verified | H35: Q1 21.8%、Q2 23.5%
A36: rf | B36: 淨現金收益率 | C36: % | E36: 0.02 | G36: Assumed
A37: cap_0 | B37: 資本支出 基準年 2026 | C37: 兆韓元 | D37: 45 | E37: 48.7 | F37: 50 | G37: Verified／Interested-party | H37: 指引「40 兆後段」；共識 48.7
A38: cap_1 | B38: 資本支出 2027 | C38: 兆韓元 | D38: 55 | E38: 62.3 | F38: 75 | G38: Interested-party | H38: MarketScreener 共識 62.3
A39: cap_2 | B39: 資本支出 2028 | C39: 兆韓元 | D39: 60 | E39: 71.2 | F39: 85 | G39: Interested-party | H39: MarketScreener 共識 71.2
A40: cb_3 | B40: 一般 DRAM 位元成長 第 3 年（2029） | C40: % | D40: 0.1 | E40: 0.15 | F40: 0.2 | G40: Assumed | H40: 龍仁一廠 2027 起投產
A41: nb_3 | B41: NAND 位元成長 第 3 年 | C41: % | D41: 0.15 | E41: 0.2 | F41: 0.25 | G41: Assumed
...

Sheet Path
A1: Path — 記憶體合約價指數（2025Q1＝1；季增來自 In 頁 M1）。共用市場層：所有記憶體公司用同一條路徑，再依各自會計年度取平均
A3: 路徑 | B3: 情境 | C3: 2025Q1 | D3: 2025Q2 | E3: 2025Q3 | F3: 2025Q4 | G3: 2026Q1 | H3: 2026Q2 | I3: 2026Q3 | J3: 2026Q4 | K3: 2027Q1 | L3: 2027Q2 | M3: 2027Q3 | N3: 2027Q4 | O3: 2028Q1 | P3: 2028Q2 | Q3: 2028Q3 | R3: 2028Q4 | S3: 2029Q1 | T3: 2029Q2 | U3: 2029Q3 | V3: 2029Q4
A4: 一般 DRAM | B4: A | C4: 1 | D4: =C4*(1+cq_1) -> 0.975 | E4: =D4*(1+cq_2) -> 1.096875 | F4: =E4*(1+cq_3) -> 1.6178906 | G4: =F4*(1+cq_4) -> 3.1548867 | H4: =G4*(1+cq_5) -> 5.0635932 | I4: =H4*(1+cq_6) -> 5.8484501 | J4: =I4*(1+cq_7) -> 6.5795064 | K4: =J4*(1+cqA_8) -> 6.7768916 | L4: =K4*(1+cqA_9) -> 6.7768916 | M4: =L4*(1+cqA_10) -> 6.6413538 | N4: =M4*(1+cqA_11) -> 6.4421131 | O4: =N4*(1+cqA_12) -> 6.2488497 | P4: =O4*(1+cqA_13) -> 6.0613843 | Q4: =P4*(1+cqA_14) -> 5.9401566 | R4: =Q4*(1+cqA_15) -> 5.8213534 | S4: =R4*(1+cqA_16) -> 5.6467128 | T4: =S4*(1+cqA_17) -> 5.4773114 | U4: =T4*(1+cqA_18) -> 5.3677652 | V4: =U4*(1+cqA_19) -> 5.2604099
A5: 一般 DRAM | B5: B | C5: 1 | D5: =C5*(1+cq_1) -> 0.975 | E5: =D5*(1+cq_2) -> 1.096875 | F5: =E5*(1+cq_3) -> 1.6178906 | G5: =F5*(1+cq_4) -> 3.1548867 | H5: =G5*(1+cq_5) -> 5.0635932 | I5: =H5*(1+cq_6) -> 5.8484501 | J5: =I5*(1+cq_7) -> 6.5795064 | K5: =J5*(1+cqB_8) -> 6.9084817 | L5: =K5*(1+cqB_9) -> 7.0466513 | M5: =L5*(1+cqB_10) -> 6.4829192 | N5: =M5*(1+cqB_11) -> 5.5104814 | O5: =N5*(1+cqB_12) -> 4.132861 | P5: =O5*(1+cqB_13) -> 3.5129319 | Q5: =P5*(1+cqB_14) -> 3.1616387 | R5: =Q5*(1+cqB_15) -> 3.0035567 | S5: =R5*(1+cqB_16) -> 3.1537346 | T5: =S5*(1+cqB_17) -> 3.3114213 | U5: =T5*(1+cqB_18) -> 3.4107639 | V5: =U5*(1+cqB_19) -> 3.5130869
A6: 一般 DRAM | B6: C | C6: 1 | D6: =C6*(1+cq_1) -> 0.975 | E6: =D6*(1+cq_2) -> 1.096875 | F6: =E6*(1+cq_3) -> 1.6178906 | G6: =F6*(1+cq_4) -> 3.1548867 | H6: =G6*(1+cq_5) -> 5.0635932 | I6: =H6*(1+cq_6) -> 5.8484501 | J6: =I6*(1+cq_7) -> 6.5795064 | K6: =J6*(1+cqC_8) -> 6.9084817 | L6: =K6*(1+cqC_9) -> 7.0466513 | M6: =L6*(1+cqC_10) -> 6.4829192 | N6: =M6*(1+cqC_11) -> 5.5104814 | O6: =N6*(1+cqC_12) -> 3.5818129 | P6: =O6*(1+cqC_13) -> 2.507269 | Q6: =P6*(1+cqC_14) -> 1.8804518 | R6: =Q6*(1+cqC_15) -> 1.5043614 | S6: =R6*(1+cqC_16) -> 1.5043614 | T6: =S6*(1+cqC_17) -> 1.5795795 | U6: =T6*(1+cqC_18) -> 1.7059458 | V6: =U6*(1+cqC_19) -> 1.8765404
A8: NAND | B8: A | C8: 1 | D8: =C8*(1+nq_1) -> 1 | E8: =D8*(1+nq_2) -> 1.05 | F8: =E8*(1+nq_3) -> 1.365 | G8: =F8*(1+nq_4) -> 2.559375 | H8: =G8*(1+nq_5) -> 4.4149219 | I8: =H8*(1+nq_6) -> 5.0771602 | J8: =I8*(1+nq_7) -> 5.9656632 | K8: =J8*(1+nqA_8) -> 6.1446331 | L8: =K8*(1+nqA_9) -> 6.1446331 | M8: =L8*(1+nqA_10) -> 5.8374014 | N8: =M8*(1+nqA_11) -> 5.4287833 | O8: =N8*(1+nqA_12) -> 5.1573442 | P8: =O8*(1+nqA_13) -> 4.899477 | Q8: =P8*(1+nqA_14) -> 4.6545031 | R8: =Q8*(1+nqA_15) -> 4.4217779 | S8: =R8*(1+nqA_16) -> 4.2891246 | T8: =S8*(1+nqA_17) -> 4.1604509 | U8: =T8*(1+nqA_18) -> 4.0356373 | V8: =U8*(1+nqA_19) -> 3.9145682
A9: NAND | B9: B | C9: 1 | D9: =C9*(1+nq_1) -> 1 | E9: =D9*(1+nq_2) -> 1.05 | F9: =E9*(1+nq_3) -> 1.365 | G9: =F9*(1+nq_4) -> 2.559375 | H9: =G9*(1+nq_5) -> 4.4149219 | I9: =H9*(1+nq_6) -> 5.0771602 | J9: =I9*(1+nq_7) -> 5.9656632 | K9: =J9*(1+nqB_8) -> 6.2639463 | L9: =K9*(1+nqB_9) -> 6.3892253 | M9: =L9*(1+nqB_10) -> 5.7503027 | N9: =M9*(1+nqB_11) -> 4.6002422 | O9: =N9*(1+nqB_12) -> 3.2201695 | P9: =O9*(1+nqB_13) -> 2.4151272 | Q9: =P9*(1+nqB_14) -> 1.9321017 | R9: =Q9*(1+nqB_15) -> 1.7388915 | S9: =R9*(1+nqB_16) -> 1.8258361 | T9: =S9*(1+nqB_17) -> 1.9171279 | U9: =T9*(1+nqB_18) -> 1.9746418 | V9: =U9*(1+nqB_19) -> 2.033881
A10: NAND | B10: C | C10: 1 | D10: =C10*(1+nq_1) -> 1 | E10: =D10*(1+nq_2) -> 1.05 | F10: =E10*(1+nq_3) -> 1.365 | G10: =F10*(1+nq_4) -> 2.559375 | H10: =G10*(1+nq_5) -> 4.4149219 | I10: =H10*(1+nq_6) -> 5.0771602 | J10: =I10*(1+nq_7) -> 5.9656632 | K10: =J10*(1+nqC_8) -> 6.2639463 | L10: =K10*(1+nqC_9) -> 6.3892253 | M10: =L10*(1+nqC_10) -> 5.7503027 | N10: =M10*(1+nqC_11) -> 4.6002422 | O10: =N10*(1+nqC_12) -> 2.9901574 | P10: =O10*(1+nqC_13) -> 1.9436023 | Q10: =P10*(1+nqC_14) -> 1.4577017 | R10: =Q10*(1+nqC_15) -> 1.1661614 | S10: =R10*(1+nqC_16) -> 1.1661614 | T10: =S10*(1+nqC_17) -> 1.2244695 | U10: =T10*(1+nqC_18) -> 1.322427 | V10: =U10*(1+nqC_19) -> 1.4546697
A12: 年均指數
A13: 路徑 | B13: 情境 | C13: 2025 | D13: 2026 | E13: 2027 | F13: 2028 | G13: 2029 | H13: 2026÷2025 | I13: 2027÷2026 | J13: 2028÷2027 | K13: 2029÷2028
A14: 一般 DRAM | B14: A | C14: =AVERAGE(C4:F4) -> 1.1724414 | D14: =AVERAGE(G4:J4) -> 5.1616091 | E14: =AVERAGE(K4:N4) -> 6.6593125 | F14: =AVERAGE(O4:R4) -> 6.017936 | G14: =AVERAGE(S4:V4) -> 5.4380499 | H14: =D14/C14-1 -> 3.4024453 | I14: =E14/D14-1 -> 0.29016211 | J14: =F14/E14-1 -> -0.096312722 | K14: =G14/F14-1 -> -0.09635964
A15: 一般 DRAM | B15: B | C15: =AVERAGE(C5:F5) -> 1.1724414 | D15: =AVERAGE(G5:J5) -> 5.1616091 | E15: =AVERAGE(K5:N5) -> 6.4871334 | F15: =AVERAGE(O5:R5) -> 3.4527471 | G15: =AVERAGE(S5:V5) -> 3.3472517 | H15: =D15/C15-1 -> 3.4024453 | I15: =E15/D15-1 -> 0.25680447 | J15: =F15/E15-1 -> -0.46775458 | K15: =G15/F15-1 -> -0.030554048
A16: 一般 DRAM | B16: C | C16: =AVERAGE(C6:F6) -> 1.1724414 | D16: =AVERAGE(G6:J6) -> 5.1616091 | E16: =AVERAGE(K6:N6) -> 6.4871334 | F16: =AVERAGE(O6:R6) -> 2.3684738 | G16: =AVERAGE(S6:V6) -> 1.6666068 | H16: =D16/C16-1 -> 3.4024453 | I16: =E16/D16-1 -> 0.25680447 | J16: =F16/E16-1 -> -0.63489671 | K16: =G16/F16-1 -> -0.29633724
A17: NAND | B17: A | C17: =AVERAGE(C8:F8) -> 1.10375 | D17: =AVERAGE(G8:J8) -> 4.5042801 | E17: =AVERAGE(K8:N8) -> 5.8888627 | F17: =AVERAGE(O8:R8) -> 4.7832755 | G17: =AVERAGE(S8:V8) -> 4.0999453 | H17: =D17/C17-1 -> 3.0808879 | I17: =E17/D17-1 -> 0.30739267 | J17: =F17/E17-1 -> -0.18774205 | K17: =G17/F17-1 -> -0.14285823
A18: NAND | B18: B | C18: =AVERAGE(C9:F9) -> 1.10375 | D18: =AVERAGE(G9:J9) -> 4.5042801 | E18: =AVERAGE(K9:N9) -> 5.7509291 | F18: =AVERAGE(O9:R9) -> 2.3265725 | G18: =AVERAGE(S9:V9) -> 1.9378717 | H18: =D18/C18-1 -> 3.0808879 | I18: =E18/D18-1 -> 0.27676989 | J18: =F18/E18-1 -> -0.59544407 | K18: =G18/F18-1 -> -0.16707013
A19: NAND | B19: C | C19: =AVERAGE(C10:F10) -> 1.10375 | D19: =AVERAGE(G10:J10) -> 4.5042801 | E19: =AVERAGE(K10:N10) -> 5.7509291 | F19: =AVERAGE(O10:R10) -> 1.8894057 | G19: =AVERAGE(S10:V10) -> 1.2919319 | H19: =D19/C19-1 -> 3.0808879 | I19: =E19/D19-1 -> 0.27676989 | J19: =F19/E19-1 -> -0.67146079 | K19: =G19/F19-1 -> -0.31622315

Sheet Mkt
A1: Mkt — 加速器數量層（最小版）與 HBM 市場（日曆年）。需求＝顆數 × GB × 情境顆數係數（2028–29）；供給三情境相同；出貨＝MIN(需求, 供給)；市場＝出貨 × 單價（單價依情境）
A3: 項目 | B3: 單位 | C3: 2025 | D3: 2026 | E3: 2027 | F3: 2028 | G3: 2029 | H3: 說明
A4: 需求：加速器裝載的 HBM（PB）
A5: NVIDIA Blackwell（B200／B300） | B5: PB | D5: =u_bw_26*g_bw_26 -> 1404 | E5: =u_bw_27*g_bw_27 -> 672 | F5: =u_bw_28*g_bw_28 -> 144
A6: NVIDIA Rubin | B6: PB | D6: =u_rb_26*g_rb_26 -> 489.6 | E6: =u_rb_27*g_rb_27 -> 2016 | F6: =u_rb_28*g_rb_28 -> 2016
A7: NVIDIA Rubin Ultra | B7: PB | D7: =u_ru_26*g_ru_26 -> 0 | E7: =u_ru_27*g_ru_27 -> 307.2 | F7: =u_ru_28*g_ru_28 -> 2048
A8: NVIDIA Hopper（H200 等） | B8: PB | D8: =u_hp_26*g_hp_26 -> 70.5 | E8: =u_hp_27*g_hp_27 -> 0 | F8: =u_hp_28*g_hp_28 -> 0
A9: AMD Instinct | B9: PB | D9: =u_amd_26*g_amd_26 -> 216 | E9: =u_amd_27*g_amd_27 -> 540 | F9: =u_amd_28*g_amd_28 -> 864
A10: Google TPU | B10: PB | D10: =u_tpu_26*g_tpu_26 -> 739.2 | E10: =u_tpu_27*g_tpu_27 -> 1375 | F10: =u_tpu_28*g_tpu_28 -> 2016
A11: AWS Trainium | B11: PB | D11: =u_trn_26*g_trn_26 -> 220 | E11: =u_trn_27*g_trn_27 -> 360 | F11: =u_trn_28*g_trn_28 -> 600
A12: 其他 ASIC（MTIA、Maia、Ascend 等） | B12: PB | D12: =u_oth_26*g_oth_26 -> 150 | E12: =u_oth_27*g_oth_27 -> 900 | F12: =u_oth_28*g_oth_28 -> 1250
A13: 需求合計（裝載） | B13: EB | D13: =SUM(D5:D12)/1000 -> 3.2893 | E13: =SUM(E5:E12)/1000 -> 6.1702 | F13: =SUM(F5:F12)/1000 -> 8.938 | G13: =F13*(1+hbm_dem29) -> 11.6194
A14: 需求 × 出貨係數（基準＝情境 A） | B14: EB | D14: =D13*hbm_gross -> 3.782695 | E14: =E13*hbm_gross -> 7.09573 | F14: =F13*hbm_gross -> 10.2787 | G14: =G13*hbm_gross -> 13.36231
A15: 加速器顆數合計 | B15: 百萬顆 | D15: =u_bw_26+u_rb_26+u_ru_26+u_hp_26+u_amd_26+u_tpu_26+u_trn_26+u_oth_26 -> 15.2 | E15: =u_bw_27+u_rb_27+u_ru_27+u_hp_27+u_amd_27+u_tpu_27+u_trn_27+u_oth_27 -> 23.7 | F15: =u_bw_28+u_rb_28+u_ru_28+u_hp_28+u_amd_28+u_tpu_28+u_trn_28+u_oth_28 -> 26.5 | H15: JPMorgan 2027：GPU 10.9M、ASIC 12.5M；情境 A 基準
A16: 每顆平均 HBM | B16: GB | D16: =D13*1000/D15 -> 216.40132 | E16: =E13*1000/E15 -> 260.34599 | F16: =F13*1000/F15 -> 337.28302
A17: 供給（三情境相同） | B17: EB | C17: =D17/(1+hbm_g26) -> 2.2251147 | D17: =D14 -> 3.782695 | E17: =D17*(1+hbm_sup27) -> 5.8631772 | F17: =E17*(1+hbm_sup28) -> 8.501607 | G17: =F17*(1+hbm_sup29) -> 11.477169 | H17: 2026 供給＝需求出貨（年中已成交）；供給不隨需求情境變（產能 2027 前已訂定）
A18: 顆數係數（A；2028–29 ÷ 基準，與台積電、Advantest 同一套） | B18: x | D18: 1 | E18: 1 | F18: =um28_A -> 1 | G18: =um29_A -> 1 | H18: 2026–27 無情境差異
A19: 顆數係數（B；2028–29 ÷ 基準，與台積電、Advantest 同一套） | B19: x | D19: 1 | E19: 1 | F19: =um28_B -> 0.8 | G19: =um29_B -> 0.85 | H19: 2026–27 無情境差異
A20: 顆數係數（C；2028–29 ÷ 基準，與台積電、Advantest 同一套） | B20: x | D20: 1 | E20: 1 | F20: =um28_C -> 0.6 | G20: =um29_C -> 0.6 | H20: 2026–27 無情境差異
A21: 需求 × 出貨係數（A） | B21: EB | D21: =D14*D18 -> 3.782695 | E21: =E14*E18 -> 7.09573 | F21: =F14*F18 -> 10.2787 | G21: =G14*G18 -> 13.36231
A22: 需求 × 出貨係數（B） | B22: EB | D22: =D14*D19 -> 3.782695 | E22: =E14*E19 -> 7.09573 | F22: =F14*F19 -> 8.22296 | G22: =G14*G19 -> 11.357964
A23: 需求 × 出貨係數（C） | B23: EB | D23: =D14*D20 -> 3.782695 | E23: =E14*E20 -> 7.09573 | F23: =F14*F20 -> 6.16722 | G23: =G14*G20 -> 8.017386
A24: 出貨＝MIN(需求, 供給)（A） | B24: EB | C24: =C17 -> 2.2251147 | D24: =MIN(D21,D17) -> 3.782695 | E24: =MIN(E21,E17) -> 5.8631772 | F24: =MIN(F21,F17) -> 8.501607 | G24: =MIN(G21,G17) -> 11.477169 | H24: 需求低於供給時出貨＝需求（閒置產能）
A25: 出貨＝MIN(需求, 供給)（B） | B25: EB | C25: =C17 -> 2.2251147 | D25: =MIN(D22,D17) -> 3.782695 | E25: =MIN(E22,E17) -> 5.8631772 | F25: =MIN(F22,F17) -> 8.22296 | G25: =MIN(G22,G17) -> 11.357964
A26: 出貨＝MIN(需求, 供給)（C） | B26: EB | C26: =C17 -> 2.2251147 | D26: =MIN(D23,D17) -> 3.782695 | E26: =MIN(E23,E17) -> 5.8631772 | F26: =MIN(F23,F17) -> 6.16722 | G26: =MIN(G23,G17) -> 8.017386
A27: 需求 − 供給（A；>0＝短缺） | B27: EB | D27: =D21-D17 -> 0 | E27: =E21-E17 -> 1.2325527 | F27: =F21-F17 -> 1.777093 | G27: =G21-G17 -> 1.8851405
A28: 需求 − 供給（B；>0＝短缺） | B28: EB | D28: =D22-D17 -> 0 | E28: =E22-E17 -> 1.2325527 | F28: =F22-F17 -> -0.27864701 | G28: =G22-G17 -> -0.11920597
A29: 需求 − 供給（C；>0＝短缺） | B29: EB | D29: =D23-D17 -> 0 | E29: =E23-E17 -> 1.2325527 | F29: =F23-F17 -> -2.334387 | G29: =G23-G17 -> -3.4597835
A30: HBM 單價（A） | B30: $/GB | C30: =hbm_mkt25/C24 -> 15.729526 | D30: =hbm_p26 -> 14.6 | E30: =D30*(1+hbm_p27) -> 26.28 | F30: =E30*(1+hbm_p28_A) -> 28.908 | G30: =F30*(1+hbm_p29_A) -> 27.4626
A31: HBM 單價（B） | B31: $/GB | C31: =hbm_mkt25/C24 -> 15.729526 | D31: =hbm_p26 -> 14.6 | E31: =D31*(1+hbm_p27) -> 26.28 | F31: =E31*(1+hbm_p28_B) -> 19.71 | G31: =F31*(1+hbm_p29_B) -> 19.71
A32: HBM 單價（C） | B32: $/GB | C32: =hbm_mkt25/C24 -> 15.729526 | D32: =hbm_p26 -> 14.6 | E32: =D32*(1+hbm_p27) -> 26.28 | F32: =E32*(1+hbm_p28_C) -> 15.768 | G32: =F32*(1+hbm_p29_C) -> 16.5564
A33: HBM 市場（A） | B33: $B | C33: =C24*C30 -> 35 | D33: =D24*D30 -> 55.227347 | E33: =E24*E30 -> 154.0843 | F33: =F24*F30 -> 245.76446 | G33: =G24*G30 -> 315.19291
A34: HBM 市場（B） | B34: $B | C34: =C25*C31 -> 35 | D34: =D25*D31 -> 55.227347 | E34: =E25*E31 -> 154.0843 | F34: =F25*F31 -> 162.07454 | G34: =G25*G31 -> 223.86546
A35: HBM 市場（C） | B35: $B | C35: =C26*C32 -> 35 | D35: =D26*D32 -> 55.227347 | E35: =E26*E32 -> 154.0843 | F35: =F26*F32 -> 97.244725 | G35: =G26*G32 -> 132.73905
A37: 對帳（樣板驗收 2）
A38: 由下而上：NVIDIA 裝載 HBM × 單價（2026） | B38: $B | D38: =(D5+D6+D7+D8)/1000*hbm_p26 -> 28.67586
A39: 由上而下：NVIDIA 資料中心營收 × 每顆 HBM ÷ 每顆 NVIDIA 內容（2026） | B39: $B | D39: =nv_dc26*nv_hbm/nv_content -> 38.972897 | H39: 橋接表 v0.2；與顆數預測獨立
A40: 差距 | B40: % | D40: =D38/D39-1 -> -0.26421021
A41: 由營收推得 NVIDIA 顆數 vs 顆數預測 | B41: 百萬顆 | D41: =nv_dc26/nv_content -> 8.7383178 | E41: =u_bw_26+u_rb_26+u_hp_26 -> 7.6 | H41: D＝營收推得；E＝顆數預測（2026）
A42: 已發布：SK 海力士自估 2026／BofA 2026／BofA 2027 | B42: $B | D42: =pub26_lo -> 54.6 | E42: =pub26_hi -> 77.4 | F42: =pub27 -> 152.8
...

Sheet Q
A1: Q — 季度損益（兆韓元）。實績：SEC 424B4（2026-07）、6-K 半年報（2026-08-18）、3Q26 財報新聞稿與法說（2026-10-28）、公司公告；推估季：實績 × 公司指引 × TrendForce 價格
A3: 項目 | B3: 2025Q1 | C3: 2025Q2 | D3: 2025Q3 | E3: 2025Q4 | F3: 2026Q1 | G3: 2026Q2 | H3: 2026Q3 | I3: 2026Q4E | J3: 2026 合計
A4: 記憶體營收 | B4: 17.639 | C4: 22.232 | D4: 24.449 | E4: 32.827 | F4: 52.576 | G4: 79.319 | H4: 104.616 | I4: =I5+I6+I7 -> 140.65619 | J4: =SUM(F4:I4) -> 377.16719
A5: DRAM（含 HBM） | F5: =F4*0.773 -> 40.641248 | G5: =G4*0.73 -> 57.90287 | H5: =H4*0.757 -> 79.194312 | I5: =H5*(1+q4_db)*(1+q4_dp) -> 108.89218 | J5: =SUM(F5:I5) -> 286.63061
A6: NAND | F6: =F4*0.22 -> 11.56672 | G6: =G4*0.27 -> 21.41613 | H6: =H4*0.243 -> 25.421688 | I6: =H6*(1+q4_nb)*(1+q4_np) -> 31.364008 | J6: =SUM(F6:I6) -> 89.768546
A7: 其他 | F7: =F4-F5-F6 -> 0.368032 | G7: =G4-G5-G6 -> 0 | H7: =H4-H5-H6 -> 0 | I7: =other_y/4 -> 0.4 | J7: =SUM(F7:I7) -> 0.768032
A8: 營業成本 | F8: =F4*(1-0.79) -> 11.04096 | G8: =G4*(1-0.83) -> 13.48423 | H8: =H4*(1-0.858) -> 14.855472 | I8: =(H8-da_cogs*H13)*((w_c+w_h)*I14/H14+w_n*I15/H15)*(1-costdn_q)+da_cogs*da_q4 -> 16.822329 | J8: =SUM(F8:I8) -> 56.202991
A9: 營業費用 | F9: =F4-F8-F10 -> 3.92504 | G9: =G4-G8-G10 -> 5.29177 | H9: =H4-H8-H10 -> 6.426528 | I9: =opex_fix_q+opex_var*I4 -> 8.1108408 | J9: =SUM(F9:I9) -> 23.754179
A10: 記憶體營業利益 | B10: 7.441 | C10: 9.213 | D10: 11.383 | E10: 19.17 | F10: 37.61 | G10: 60.543 | H10: 83.334 | I10: =I4-I8-I9 -> 115.72302 | J10: =SUM(F10:I10) -> 297.21002
A11: 記憶體營業利益率 | B11: =IF(B4=0,"",B10/B4) -> 0.42184931 | C11: =IF(C4=0,"",C10/C4) -> 0.41440266 | D11: =IF(D4=0,"",D10/D4) -> 0.46558141 | E11: =IF(E4=0,"",E10/E4) -> 0.58397051 | F11: =IF(F4=0,"",F10/F4) -> 0.7153454 | G11: =IF(G4=0,"",G10/G4) -> 0.76328496 | H11: =IF(H4=0,"",H10/H4) -> 0.79657031 | I11: =IF(I4=0,"",I10/I4) -> 0.82273677 | J11: =J10/J4 -> 0.78800603
A12: 淨利（合併，含非記憶體事業） | B12: 8.108 | C12: 6.996 | D12: 12.598 | E12: 15.246 | F12: 40.346 | G12: 93.923 | H12: 39.776 | I12: =(I10+nonop_q+nm_op_q)*(1-tax) -> 89.876723 | J12: =SUM(F12:I12) -> 263.92172
A13: 折舊攤銷 | B13: 3.334 | C13: 3.443 | D13: 3.556 | E13: 3.557 | F13: 3.726 | G13: 4.028 | H13: 4.4 | I13: =da_q4 -> 4.6 | J13: =SUM(F13:I13) -> 16.754
A14: DRAM 位元指數（最後實績季＝1） | H14: 1 | I14: =H14*(1+q4_db) -> 1.25
A15: NAND 位元指數 | H15: 1 | I15: =H15*(1+q4_nb) -> 1.05
A18: 2026Q3 實績：營收 104.616、營業利益 83.334、淨利 39.776 兆（業外淨損 32.6 兆：匯兌損失 11.6、投資資產評價損失 22.9、其他淨收益 1.9）；DRAM 75.7%／NAND 24.3% 與毛利率 85.8% 為推估 [Derived：Q2 結構 × 法說位元與 ASP 季增（DRAM +10%／高 20% 段、NAND 小幅季減／中 20% 段）後依實際營收縮放；毛利＝營業利益＋營業費用迴歸值]；折舊 4.4＝EBITDA 87.7 − 營業利益。2026Q1 DRAM 77.3%、NAND 22%、毛利率約 79%；Q2 DRAM 73%、NAND 27%、毛利率 83%（公司簡報）。2025 季度拆分未取得。2025Q3、Q4 折舊為合計 7.113 平均分配 [Derived]

Sheet Y
A1: Y — 年度（兆韓元；股數百萬股）。情境 A：2027–28 高檔持平、2029 緩降（BofA、TrendForce 型）；B：2027 Q2 見頂、2028 回落約一半、2029 溫和回升（Citi、Bernstein 型）；C：2028 回到 2025 年價格水準、2029 自谷底回升（完整循環）
A2: 灰底＝2030–2032 收斂法（上游市場層只到 2029）：合併營收年增由 2029 線性收斂到 fade_g、淨利率收斂到 fade_m（In 頁目標價參數），股數固定；非驅動因子推導，只算營收、淨利、EPS
A3: 項目 | B3: 2025 實績 | C3: 2026（基準） | D3: 2027 A | E3: 2028 A | F3: 2029 A | G3: 2027 B | H3: 2028 B | I3: 2029 B | J3: 2027 C | K3: 2028 C | L3: 2029 C | M3: 2030 A 收斂 | N3: 2031 A 收斂 | O3: 2032 A 收斂 | P3: 2030 B 收斂 | Q3: 2031 B 收斂 | R3: 2032 B 收斂 | S3: 2030 C 收斂 | T3: 2031 C 收斂 | U3: 2032 C 收斂 | V3: 說明
A4: 記憶體營收 | B4: =SUM(Q!B4:E4) -> 97.147 | C4: =Q!J4 -> 377.16719 | D4: =D5+D6+D7+D8 -> 583.2372 | E4: =E5+E6+E7+E8 -> 641.06494 | F4: =F5+F6+F7+F8 -> 698.63112 | G4: =G5+G6+G7+G8 -> 570.91734 | H4: =H5+H6+H7+H8 -> 368.46533 | I4: =I5+I6+I7+I8 -> 427.42603 | J4: =J5+J6+J7+J8 -> 570.91734 | K4: =K5+K6+K7+K8 -> 253.76545 | L4: =L5+L6+L7+L8 -> 236.96811
A5: 一般 DRAM | C5: =Q!J5-C6 -> 245.85074 | D5: =C5*(1+cb_1)*(AVERAGE(Path!K4:N4)/AVERAGE(Path!G4:J4)) -> 348.90604 | E5: =D5*(1+cb_2)*(AVERAGE(Path!O4:R4)/AVERAGE(Path!K4:N4)) -> 362.59724 | F5: =E5*(1+cb_3)*(AVERAGE(Path!S4:V4)/AVERAGE(Path!O4:R4)) -> 376.80612 | G5: =C5*(1+cb_1)*(AVERAGE(Path!K5:N5)/AVERAGE(Path!G5:J5)) -> 339.88494 | H5: =G5*(1+cb_2)*(AVERAGE(Path!O5:R5)/AVERAGE(Path!K5:N5)) -> 208.03753 | I5: =H5*(1+cb_3)*(AVERAGE(Path!S5:V5)/AVERAGE(Path!O5:R5)) -> 231.93331 | J5: =C5*(1+cb_1)*(AVERAGE(Path!K6:N6)/AVERAGE(Path!G6:J6)) -> 339.88494 | K5: =J5*(1+cb_2)*(AVERAGE(Path!O6:R6)/AVERAGE(Path!K6:N6)) -> 142.70708 | L5: =K5*(1+cb_3)*(AVERAGE(Path!S6:V6)/AVERAGE(Path!O6:R6)) -> 115.4803 | V5: 前一年 × (1＋位元) × 會計年度價格指數平均比（Path）
A6: HBM | C6: =(Mkt!D33/4*sh26+Mkt!D33/4*sh26+Mkt!D33/4*sh26+Mkt!D33/4*sh26)*fx/1000 -> 40.779873 | D6: =(Mkt!E33/4*sh27+Mkt!E33/4*sh27+Mkt!E33/4*sh27+Mkt!E33/4*sh27)*fx/1000 -> 91.895875 | E6: =(Mkt!F33/4*sh28+Mkt!F33/4*sh28+Mkt!F33/4*sh28+Mkt!F33/4*sh28)*fx/1000 -> 139.59421 | F6: =(Mkt!G33/4*sh29+Mkt!G33/4*sh29+Mkt!G33/4*sh29+Mkt!G33/4*sh29)*fx/1000 -> 179.02958 | G6: =(Mkt!E34/4*sh27+Mkt!E34/4*sh27+Mkt!E34/4*sh27+Mkt!E34/4*sh27)*fx/1000 -> 91.895875 | H6: =(Mkt!F34/4*sh28+Mkt!F34/4*sh28+Mkt!F34/4*sh28+Mkt!F34/4*sh28)*fx/1000 -> 92.05834 | I6: =(Mkt!G34/4*sh29+Mkt!G34/4*sh29+Mkt!G34/4*sh29+Mkt!G34/4*sh29)*fx/1000 -> 127.15558 | J6: =(Mkt!E35/4*sh27+Mkt!E35/4*sh27+Mkt!E35/4*sh27+Mkt!E35/4*sh27)*fx/1000 -> 91.895875 | K6: =(Mkt!F35/4*sh28+Mkt!F35/4*sh28+Mkt!F35/4*sh28+Mkt!F35/4*sh28)*fx/1000 -> 55.235004 | L6: =(Mkt!G35/4*sh29+Mkt!G35/4*sh29+Mkt!G35/4*sh29+Mkt!G35/4*sh29)*fx/1000 -> 75.39578 | V6: Σ 會計年度各季：HBM 市場 ÷ 4 × 市占 × 匯率（Mkt）
A7: NAND | C7: =Q!J6 -> 89.768546 | D7: =C7*(1+nb_1)*(AVERAGE(Path!K8:N8)/AVERAGE(Path!G8:J8)) -> 140.83529 | E7: =D7*(1+nb_2)*(AVERAGE(Path!O8:R8)/AVERAGE(Path!K8:N8)) -> 137.2735 | F7: =E7*(1+nb_3)*(AVERAGE(Path!S8:V8)/AVERAGE(Path!O8:R8)) -> 141.19542 | G7: =C7*(1+nb_1)*(AVERAGE(Path!K9:N9)/AVERAGE(Path!G9:J9)) -> 137.53653 | H7: =G7*(1+nb_2)*(AVERAGE(Path!O9:R9)/AVERAGE(Path!K9:N9)) -> 66.769463 | I7: =H7*(1+nb_3)*(AVERAGE(Path!S9:V9)/AVERAGE(Path!O9:R9)) -> 66.737136 | J7: =C7*(1+nb_1)*(AVERAGE(Path!K10:N10)/AVERAGE(Path!G10:J10)) -> 137.53653 | K7: =J7*(1+nb_2)*(AVERAGE(Path!O10:R10)/AVERAGE(Path!K10:N10)) -> 54.223372 | L7: =K7*(1+nb_3)*(AVERAGE(Path!S10:V10)/AVERAGE(Path!O10:R10)) -> 44.492024
A8: 其他 | C8: =Q!J7 -> 0.768032 | D8: =other_y -> 1.6 | E8: =other_y -> 1.6 | F8: =other_y -> 1.6 | G8: =other_y -> 1.6 | H8: =other_y -> 1.6 | I8: =other_y -> 1.6 | J8: =other_y -> 1.6 | K8: =other_y -> 1.6 | L8: =other_y -> 1.6
A9: HBM ÷ 營收 | C9: =C6/C4 -> 0.10812148 | D9: =D6/D4 -> 0.15756175 | E9: =E6/E4 -> 0.21775362 | F9: =F6/F4 -> 0.25625766 | G9: =G6/G4 -> 0.16096179 | H9: =H6/H4 -> 0.24984261 | I9: =I6/I4 -> 0.29749143 | J9: =J6/J4 -> 0.16096179 | ... L9: =L6/L4 -> 0.31816847
A10: 折舊攤銷 | B10: =SUM(Q!B13:E13) -> 13.89 | C10: =Q!J13 -> 16.754 | D10: =C10+(C21-C10)/da_life -> 23.1432 | E10: =D10+(D21-D10)/da_life -> 30.97456 | F10: =E10+(E21-E10)/da_life -> 39.019648 | G10: =C10+(C21-C10)/da_life -> 23.1432 | H10: =G10+(G21-G10)/da_life -> 30.97456 | I10: =H10+(H21-H10)/da_life -> 39.019648 | J10: =C10+(C21-C10)/da_life -> 23.1432 | K10: =J10+(J21-J10)/da_life -> 30.97456 | L10: =K10+(K21-K10)/da_life -> 39.019648
A11: 成本量指數（÷ 前一年） | D11: =w_c*(1+cb_1)+w_h*D31/C31+w_n*(1+nb_1) -> 1.1705769 | E11: =w_c*(1+cb_2)+w_h*E31/D31+w_n*(1+nb_2) -> 1.2317857 | F11: =w_c*(1+cb_3)+w_h*F31/E31+w_n*(1+nb_3) -> 1.2225 | G11: =w_c*(1+cb_1)+w_h*G31/C31+w_n*(1+nb_1) -> 1.1705769 | H11: =w_c*(1+cb_2)+w_h*H31/G31+w_n*(1+nb_2) -> 1.2182072 | I11: =w_c*(1+cb_3)+w_h*I31/H31+w_n*(1+nb_3) -> 1.231875 | J11: =w_c*(1+cb_1)+w_h*J31/C31+w_n*(1+nb_1) -> 1.1705769 | K11: =w_c*(1+cb_2)+w_h*K31/J31+w_n*(1+nb_2) -> 1.1180304 | L11: =w_c*(1+cb_3)+w_h*L31/K31+w_n*(1+nb_3) -> 1.2075
A12: 營業成本 | C12: =Q!J8 -> 56.202991 | D12: =(C12-da_cogs*C10)*D11*(1-costdn_y)+da_cogs*D10 -> 64.154217 | E12: =(D12-da_cogs*D10)*E11*(1-costdn_y)+da_cogs*E10 -> 75.907882 | F12: =(E12-da_cogs*E10)*F11*(1-costdn_y)+da_cogs*F10 -> 87.963547 | G12: =(C12-da_cogs*C10)*G11*(1-costdn_y)+da_cogs*G10 -> 64.154217 | H12: =(G12-da_cogs*G10)*H11*(1-costdn_y)+da_cogs*H10 -> 75.378417 | I12: =(H12-da_cogs*H10)*I11*(1-costdn_y)+da_cogs*I10 -> 87.781795 | J12: =(C12-da_cogs*C10)*J11*(1-costdn_y)+da_cogs*J10 -> 64.154217 | K12: =(J12-da_cogs*J10)*K11*(1-costdn_y)+da_cogs*K10 -> 71.472243 | L12: =(K12-da_cogs*K10)*L11*(1-costdn_y)+da_cogs*L10 -> 82.4947 | V12: 現金成本 × 量 × (1 − 年降)＋折舊
A13: 營業費用 | C13: =Q!J9 -> 23.754179 | D13: =opex_fix_y*(1+opex_g)^1+opex_var*D4 -> 34.012148 | E13: =opex_fix_y*(1+opex_g)^2+opex_var*E4 -> 37.390052 | F13: =opex_fix_y*(1+opex_g)^3+opex_var*F4 -> 40.821662 | G13: =opex_fix_y*(1+opex_g)^1+opex_var*G4 -> 33.433115 | H13: =opex_fix_y*(1+opex_g)^2+opex_var*H4 -> 24.577871 | I13: =opex_fix_y*(1+opex_g)^3+opex_var*I4 -> 28.075024 | J13: =opex_fix_y*(1+opex_g)^1+opex_var*J4 -> 33.433115 | K13: =opex_fix_y*(1+opex_g)^2+opex_var*K4 -> 19.186976 | L13: =opex_fix_y*(1+opex_g)^3+opex_var*L4 -> 19.123501
A14: 記憶體營業利益 | B14: =SUM(Q!B10:E10) -> 47.207 | C14: =Q!J10 -> 297.21002 | D14: =D4-D12-D13 -> 485.07083 | E14: =E4-E12-E13 -> 527.76701 | F14: =F4-F12-F13 -> 569.84591 | G14: =G4-G12-G13 -> 473.33001 | H14: =H4-H12-H13 -> 268.50905 | I14: =I4-I12-I13 -> 311.56921 | J14: =J4-J12-J13 -> 473.33001 | K14: =K4-K12-K13 -> 163.10623 | L14: =L4-L12-L13 -> 135.34991
A15: 記憶體營業利益率 | B15: =B14/B4 -> 0.48593369 | C15: =C14/C4 -> 0.78800603 | D15: =D14/D4 -> 0.83168706 | E15: =E14/E4 -> 0.82326606 | F15: =F14/F4 -> 0.81566064 | G15: =G14/G4 -> 0.82906924 | H15: =H14/H4 -> 0.72872268 | I15: =I14/I4 -> 0.728943 | ... L15: =L14/L4 -> 0.57117351
A16: 非記憶體事業營收 | C16: =nm_rev_0 -> 0 | D16: =nm_rev_1 -> 0 | E16: =nm_rev_2 -> 0 | F16: =nm_rev_3 -> 0 | G16: =nm_rev_1 -> 0 | H16: =nm_rev_2 -> 0 | I16: =nm_rev_3 -> 0 | J16: =nm_rev_1 -> 0 | K16: =nm_rev_2 -> 0 | L16: =nm_rev_3 -> 0
A17: 非記憶體事業營業利益 | C17: =nm_op_0 -> 0 | D17: =nm_op_1 -> 0 | E17: =nm_op_2 -> 0 | F17: =nm_op_3 -> 0 | G17: =nm_op_1 -> 0 | H17: =nm_op_2 -> 0 | I17: =nm_op_3 -> 0 | J17: =nm_op_1 -> 0 | K17: =nm_op_2 -> 0 | L17: =nm_op_3 -> 0
A18: 合併營收 | C18: =C4+C16 -> 377.16719 | D18: =D4+D16 -> 583.2372 | E18: =E4+E16 -> 641.06494 | F18: =F4+F16 -> 698.63112 | G18: =G4+G16 -> 570.91734 | H18: =H4+H16 -> 368.46533 | I18: =I4+I16 -> 427.42603 | J18: =J4+J16 -> 570.91734 | ... L18: =L4+L16 -> 236.96811 | M18: =F18*(1+M32) -> 754.42739 | N18: =M18*(1+N32) -> 807.18644 | O18: =N18*(1+O32) -> 855.61763 | P18: =I18*(1+P32) -> 478.72198 | Q18: =P18*(1+Q32) -> 517.02245 | R18: =Q18*(1+R32) -> 537.70335 | S18: =L18*(1+S32) -> 228.0909 | T18: =S18*(1+T32) -> 226.09949 | U18: =T18*(1+U32) -> 230.62148 | V18: 2030 起為收斂法：合併營收年增由 2029 線性收斂到 fade_g、淨利率收斂到 fade_m（2032 達到），非驅動因子推導
A19: 合併營業利益 | C19: =C14+C17 -> 297.21002 | D19: =D14+D17 -> 485.07083 | E19: =E14+E17 -> 527.76701 | F19: =F14+F17 -> 569.84591 | G19: =G14+G17 -> 473.33001 | H19: =H14+H17 -> 268.50905 | I19: =I14+I17 -> 311.56921 | J19: =J14+J17 -> 473.33001 | ... L19: =L14+L17 -> 135.34991
A20: 淨利（合併） | B20: =SUM(Q!B12:E12) -> 42.948 | C20: =Q!J12 -> 263.92172 | D20: =(D19+rf*C26)*(1-tax) -> 375.72955 | E20: =(E19+rf*D26)*(1-tax) -> 411.19721 | F20: =(F19+rf*E26)*(1-tax) -> 446.45444 | G20: =(G19+rf*C26)*(1-tax) -> 366.68911 | H20: =(H19+rf*G26)*(1-tax) -> 211.49897 | I20: =(I19+rf*H26)*(1-tax) -> 245.9741 | J20: =(J19+rf*C26)*(1-tax) -> 366.68911 | K20: =(K19+rf*J26)*(1-tax) -> 130.3388 | L20: =(L19+rf*K26)*(1-tax) -> 109.6603 | M20: =M18*M33 -> 377.82508 | N20: =N18*N33 -> 292.66889 | O20: =O18*O33 -> 191.95585 | P20: =P18*P33 -> 213.4959 | Q20: =Q18*Q33 -> 163.61872 | R20: =R18*R33 -> 100.52709 | S20: =S18*S33 -> 81.739651 | T20: =T18*T33 -> 57.421299 | U20: =U18*U33 -> 34.492932 | V20: （營業利益＋淨現金 × 收益率）× (1 − 稅率)
A21: 資本支出 | C21: =cap_0 -> 48.7 | D21: =cap_1 -> 62.3 | E21: =cap_2 -> 71.2 | F21: =cap_3 -> 75 | G21: =cap_1 -> 62.3 | H21: =cap_2 -> 71.2 | I21: =cap_3 -> 75 | J21: =cap_1 -> 62.3 | K21: =cap_2 -> 71.2 | L21: =cap_3 -> 75
A22: 自由現金流（淨利＋折舊 − 資本支出） | C22: =C20+C10-C21 -> 231.97572 | D22: =D20+D10-D21 -> 336.57275 | E22: =E20+E10-E21 -> 370.97177 | F22: =F20+F10-F21 -> 410.47409 | G22: =G20+G10-G21 -> 327.53231 | H22: =H20+H10-H21 -> 171.27353 | I22: =I20+I10-I21 -> 209.99375 | J22: =J20+J10-J21 -> 327.53231 | ... L22: =L20+L10-L21 -> 73.679952
A23: 股利 | C23: =div_0 -> 14.09591 | D23: =dps_1*C27/1000000 -> 15.36807 | E23: =dps_2*D27/1000000 -> 3.1925124 | F23: =dps_3*E27/1000000 -> 2.9139981 | G23: =dps_1*C27/1000000 -> 15.36807 | H23: =dps_2*G27/1000000 -> 3.206283 | I23: =dps_3*H27/1000000 -> 3.2653748 | J23: =dps_1*C27/1000000 -> 15.36807 | K23: =dps_2*J27/1000000 -> 3.206283 | L23: =dps_3*K27/1000000 -> 3.4019764
A24: 買回 | C24: =bb_0 -> 20 | D24: =MAX(0,payout*D22-D23) -> 152.9183 | E24: =MAX(0,payout*E22-E23) -> 182.29337 | F24: =MAX(0,payout*F22-F23) -> 202.32305 | G24: =MAX(0,payout*G22-G23) -> 148.39809 | H24: =MAX(0,payout*H22-H23) -> 82.430482 | I24: =MAX(0,payout*I22-I23) -> 101.7315 | J24: =MAX(0,payout*J22-J23) -> 148.39809 | K24: =MAX(0,payout*K22-K23) -> 41.850398 | L24: =MAX(0,payout*L22-L23) -> 33.437999 | V24: 回饋比例 × FCF − 股利
A25: 期末權益 | C25: =eq_last+(Q!I12)+extra_eq-C24-C23 -> 358.37981 | D25: =C25+D20-D23-D24 -> 565.82299 | E25: =D25+E20-E23-E24 -> 791.53431 | F25: =E25+F20-F23-F24 -> 1032.7517 | G25: =C25+G20-G23-G24 -> 561.30277 | H25: =G25+H20-H23-H24 -> 687.16497 | I25: =H25+I20-I23-I24 -> 828.1422 | J25: =C25+J20-J23-J24 -> 561.30277 | K25: =J25+K20-K23-K24 -> 646.58489 | L25: =K25+L20-L23-L24 -> 719.40522
A26: 期末淨現金 | C26: =nc_last+(Q!I12)+(Q!I13)-capex_rem+extra_eq-C24-C23 -> 144.48081 | D26: =C26+D22-D23-D24 -> 312.76719 | E26: =D26+E22-E23-E24 -> 498.25307 | F26: =E26+F22-F23-F24 -> 703.49012 | G26: =C26+G22-G23-G24 -> 308.24697 | H26: =G26+H22-H23-H24 -> 393.88373 | I26: =H26+I22-I23-I24 -> 498.88061 | J26: =C26+J22-J23-J24 -> 308.24697 | K26: =J26+K22-K23-K24 -> 353.30365 | L26: =K26+L22-L23-L24 -> 390.14363
A27: 期末流通股數 | C27: =sh_last+extra_sh-bb_sh_0 -> 696.96465 | D27: =C27-D24/bb_px*1000000 -> 608.21346 | E27: =D27-E24/bb_px*1000000 -> 502.41347 | F27: =E27-F24/bb_px*1000000 -> 384.9886 | G27: =C27-G24/bb_px*1000000 -> 610.83691 | H27: =G27-H24/bb_px*1000000 -> 562.99566 | I27: =H27-I24/bb_px*1000000 -> 503.95242 | J27: =C27-J24/bb_px*1000000 -> 610.83691 | K27: =J27-K24/bb_px*1000000 -> 586.54765 | L27: =K27-L24/bb_px*1000000 -> 567.1408 | M27: =F27 -> 384.9886 | N27: =M27 -> 384.9886 | O27: =N27 -> 384.9886 | P27: =I27 -> 503.95242 | Q27: =P27 -> 503.95242 | R27: =Q27 -> 503.95242 | S27: =L27 -> 567.1408 | T27: =S27 -> 567.1408 | U27: =T27 -> 567.1408
A28: 每股淨值 BVPS | C28: =C25/C27*1000000 -> 514200.85 | D28: =D25/D27*1000000 -> 930303.3 | E28: =E25/E27*1000000 -> 1575464 | F28: =F25/F27*1000000 -> 2682551.4 | G28: =G25/G27*1000000 -> 918907.74 | H28: =H25/H27*1000000 -> 1220551.1 | I28: =I25/I27*1000000 -> 1643294.4 | J28: =J25/J27*1000000 -> 918907.74 | ... L28: =L25/L27*1000000 -> 1268477.3
A29: 每股盈餘 EPS（期末股數） | C29: =C20/C27*1000000 -> 378673.04 | D29: =D20/D27*1000000 -> 617759.34 | E29: =E20/E27*1000000 -> 818443.84 | F29: =F20/F27*1000000 -> 1159656.3 | G29: =G20/G27*1000000 -> 600306.08 | H29: =H20/H27*1000000 -> 375667.14 | I29: =I20/I27*1000000 -> 488089.94 | J29: =J20/J27*1000000 -> 600306.08 | ... U29: =U20/U27*1000000 -> 60818.992
A30: ROE（期末權益） | C30: =C20/C25 -> 0.73643022 | D30: =D20/D25 -> 0.6640408 | E30: =E20/E25 -> 0.51949386 | F30: =F20/F25 -> 0.43229601 | G30: =G20/G25 -> 0.65328221 | H30: =H20/H25 -> 0.30778485 | I30: =I20/I25 -> 0.29701916 | J30: =J20/J25 -> 0.65328221 | ... L30: =L20/L25 -> 0.1524319
A31: HBM 出貨位元（EB，公司） | C31: =(Mkt!D24/4*sh26+Mkt!D24/4*sh26+Mkt!D24/4*sh26+Mkt!D24/4*sh26) -> 1.9670014 | D31: =(Mkt!E24/4*sh27+Mkt!E24/4*sh27+Mkt!E24/4*sh27+Mkt!E24/4*sh27) -> 2.4625344 | E31: =(Mkt!F24/4*sh28+Mkt!F24/4*sh28+Mkt!F24/4*sh28+Mkt!F24/4*sh28) -> 3.4006428 | F31: =(Mkt!G24/4*sh29+Mkt!G24/4*sh29+Mkt!G24/4*sh29+Mkt!G24/4*sh29) -> 4.5908678 | G31: =(Mkt!E25/4*sh27+Mkt!E25/4*sh27+Mkt!E25/4*sh27+Mkt!E25/4*sh27) -> 2.4625344 | H31: =(Mkt!F25/4*sh28+Mkt!F25/4*sh28+Mkt!F25/4*sh28+Mkt!F25/4*sh28) -> 3.289184 | I31: =(Mkt!G25/4*sh29+Mkt!G25/4*sh29+Mkt!G25/4*sh29+Mkt!G25/4*sh29) -> 4.5431854 | J31: =(Mkt!E26/4*sh27+Mkt!E26/4*sh27+Mkt!E26/4*sh27+Mkt!E26/4*sh27) -> 2.4625344 | K31: =(Mkt!F26/4*sh28+Mkt!F26/4*sh28+Mkt!F26/4*sh28+Mkt!F26/4*sh28) -> 2.466888 | L31: =(Mkt!G26/4*sh29+Mkt!G26/4*sh29+Mkt!G26/4*sh29+Mkt!G26/4*sh29) -> 3.2069544
A32: 合併營收年增 | D32: =D18/C18-1 -> 0.54636251 | E32: =E18/D18-1 -> 0.099149621 | F32: =F18/E18-1 -> 0.089797721 | G32: =G18/C18-1 -> 0.51369833 | H32: =H18/G18-1 -> -0.35460826 | I32: =I18/H18-1 -> 0.16001695 | J32: =J18/C18-1 -> 0.51369833 | K32: =K18/J18-1 -> -0.5555128 | L32: =L18/K18-1 -> -0.0661924 | M32: =$F32+(fade_gA-$F32)*1/3 -> 0.079865147 | N32: =$F32+(fade_gA-$F32)*2/3 -> 0.069932574 | O32: =$F32+(fade_gA-$F32)*3/3 -> 0.06 | P32: =$I32+(fade_gB-$I32)*1/3 -> 0.1200113 | Q32: =$I32+(fade_gB-$I32)*2/3 -> 0.080005649 | R32: =$I32+(fade_gB-$I32)*3/3 -> 0.04 | S32: =$L32+(fade_gC-$L32)*1/3 -> -0.0374616 | T32: =$L32+(fade_gC-$L32)*2/3 -> -0.0087307999 | U32: =$L32+(fade_gC-$L32)*3/3 -> 0.02
A33: 淨利率（淨利 ÷ 合併營收） | C33: =C20/C18 -> 0.69974731 | D33: =D20/D18 -> 0.64421396 | E33: =E20/E18 -> 0.64142832 | F33: =F20/F18 -> 0.63904174 | G33: =G20/G18 -> 0.64228056 | H33: =H20/H18 -> 0.57399964 | I33: =I20/I18 -> 0.57547759 | J33: =J20/J18 -> 0.64228056 | ... L33: =L20/L18 -> 0.46276398 | M33: =$F33+(fade_mA-$F33)*1/3 -> 0.5008104 | N33: =$F33+(fade_mA-$F33)*2/3 -> 0.36257905 | O33: =$F33+(fade_mA-$F33)*3/3 -> 0.2243477 | P33: =$I33+(fade_mB-$I33)*1/3 -> 0.44597053 | Q33: =$I33+(fade_mB-$I33)*2/3 -> 0.31646348 | R33: =$I33+(fade_mB-$I33)*3/3 -> 0.18695642 | S33: =$L33+(fade_mC-$L33)*1/3 -> 0.35836436 | T33: =$L33+(fade_mC-$L33)*2/3 -> 0.25396475 | U33: =$L33+(fade_mC-$L33)*3/3 -> 0.14956513

Sheet Val
A1: Val — 估值（P/B 主、P/E 對照）。隱含股價 ÷ 目前股價 − 1
A3: 方法 | B3: 倍數 | C3: 基準 | D3: 情境 | E3: 每股基準 | F3: 隱含股價 | G3: 相對目前
A4: P/B 1.0x | B4: =pb_1 -> 1 | C4: 2026 期末 BVPS | D4: 共用 | E4: =Y!C28 -> 514200.85 | F4: =B4*E4 -> 514200.85 | G4: =F4/px-1 -> -0.59733685
A5: P/B 歷史中位 1.6x | B5: =pb_2 -> 1.6 | C5: 2026 期末 BVPS | D5: 共用 | E5: =Y!C28 -> 514200.85 | F5: =B5*E5 -> 822721.36 | G5: =F5/px-1 -> -0.35573895
A6: P/B 券商遠期 3.3x | B6: =pb_3 -> 3.3 | C6: 2026 期末 BVPS | D6: 共用 | E6: =Y!C28 -> 514200.85 | F6: =B6*E6 -> 1696862.8 | G6: =F6/px-1 -> 0.32878841
A7: P/B 1.0x | B7: =pb_1 -> 1 | C7: 2027 期末 BVPS | D7: A | E7: =Y!D28 -> 930303.3 | F7: =B7*E7 -> 930303.3 | G7: =F7/px-1 -> -0.27149311
A8: P/B 歷史中位 1.6x | B8: =pb_2 -> 1.6 | C8: 2027 期末 BVPS | D8: A | E8: =Y!D28 -> 930303.3 | F8: =B8*E8 -> 1488485.3 | G8: =F8/px-1 -> 0.16561103
A9: P/B 券商遠期 3.3x | B9: =pb_3 -> 3.3 | C9: 2027 期末 BVPS | D9: A | E9: =Y!D28 -> 930303.3 | F9: =B9*E9 -> 3070000.9 | G9: =F9/px-1 -> 1.4040727
A10: P/B 1.0x | B10: =pb_1 -> 1 | C10: 2027 期末 BVPS | D10: B | E10: =Y!G28 -> 918907.74 | F10: =B10*E10 -> 918907.74 | G10: =F10/px-1 -> -0.2804168
A11: P/B 歷史中位 1.6x | B11: =pb_2 -> 1.6 | C11: 2027 期末 BVPS | D11: B | E11: =Y!G28 -> 918907.74 | F11: =B11*E11 -> 1470252.4 | G11: =F11/px-1 -> 0.15133312
A12: P/B 券商遠期 3.3x | B12: =pb_3 -> 3.3 | C12: 2027 期末 BVPS | D12: B | E12: =Y!G28 -> 918907.74 | F12: =B12*E12 -> 3032395.6 | G12: =F12/px-1 -> 1.3746246
A13: P/B 1.0x | B13: =pb_1 -> 1 | C13: 2027 期末 BVPS | D13: C | E13: =Y!J28 -> 918907.74 | F13: =B13*E13 -> 918907.74 | G13: =F13/px-1 -> -0.2804168
A14: P/B 歷史中位 1.6x | B14: =pb_2 -> 1.6 | C14: 2027 期末 BVPS | D14: C | E14: =Y!J28 -> 918907.74 | F14: =B14*E14 -> 1470252.4 | G14: =F14/px-1 -> 0.15133312
A15: P/B 券商遠期 3.3x | B15: =pb_3 -> 3.3 | C15: 2027 期末 BVPS | D15: C | E15: =Y!J28 -> 918907.74 | F15: =B15*E15 -> 3032395.6 | G15: =F15/px-1 -> 1.3746246
A16: P/B 1.0x | B16: =pb_1 -> 1 | C16: 2028 期末 BVPS | D16: A | E16: =Y!E28 -> 1575464 | F16: =B16*E16 -> 1575464 | G16: =F16/px-1 -> 0.23372275
A17: P/B 歷史中位 1.6x | B17: =pb_2 -> 1.6 | C17: 2028 期末 BVPS | D17: A | E17: =Y!E28 -> 1575464 | F17: =B17*E17 -> 2520742.3 | G17: =F17/px-1 -> 0.9739564
A18: P/B 券商遠期 3.3x | B18: =pb_3 -> 3.3 | C18: 2028 期末 BVPS | D18: A | E18: =Y!E28 -> 1575464 | F18: =B18*E18 -> 5199031 | G18: =F18/px-1 -> 3.0712851
A19: P/B 1.0x | B19: =pb_1 -> 1 | C19: 2028 期末 BVPS | D19: B | E19: =Y!H28 -> 1220551.1 | F19: =B19*E19 -> 1220551.1 | G19: =F19/px-1 -> -0.044204302
A20: P/B 歷史中位 1.6x | B20: =pb_2 -> 1.6 | C20: 2028 期末 BVPS | D20: B | E20: =Y!H28 -> 1220551.1 | F20: =B20*E20 -> 1952881.8 | G20: =F20/px-1 -> 0.52927312
A21: P/B 券商遠期 3.3x | B21: =pb_3 -> 3.3 | C21: 2028 期末 BVPS | D21: B | E21: =Y!H28 -> 1220551.1 | F21: =B21*E21 -> 4027818.7 | G21: =F21/px-1 -> 2.1541258
A22: P/B 1.0x | B22: =pb_1 -> 1 | C22: 2028 期末 BVPS | D22: C | E22: =Y!K28 -> 1102357 | F22: =B22*E22 -> 1102357 | G22: =F22/px-1 -> -0.1367604
A23: P/B 歷史中位 1.6x | B23: =pb_2 -> 1.6 | C23: 2028 期末 BVPS | D23: C | E23: =Y!K28 -> 1102357 | F23: =B23*E23 -> 1763771.1 | G23: =F23/px-1 -> 0.38118336
A24: P/B 券商遠期 3.3x | B24: =pb_3 -> 3.3 | C24: 2028 期末 BVPS | D24: C | E24: =Y!K28 -> 1102357 | F24: =B24*E24 -> 3637778 | G24: =F24/px-1 -> 1.8486907
A25: P/B 1.0x | B25: =pb_1 -> 1 | C25: 2029 期末 BVPS | D25: A | E25: =Y!F28 -> 2682551.4 | F25: =B25*E25 -> 2682551.4 | G25: =F25/px-1 -> 1.1006667
A26: P/B 歷史中位 1.6x | B26: =pb_2 -> 1.6 | C26: 2029 期末 BVPS | D26: A | E26: =Y!F28 -> 2682551.4 | F26: =B26*E26 -> 4292082.2 | G26: =F26/px-1 -> 2.3610667
A27: P/B 券商遠期 3.3x | B27: =pb_3 -> 3.3 | C27: 2029 期末 BVPS | D27: A | E27: =Y!F28 -> 2682551.4 | F27: =B27*E27 -> 8852419.6 | G27: =F27/px-1 -> 5.9322001
A28: P/B 1.0x | B28: =pb_1 -> 1 | C28: 2029 期末 BVPS | D28: B | E28: =Y!I28 -> 1643294.4 | F28: =B28*E28 -> 1643294.4 | G28: =F28/px-1 -> 0.2868398
A29: P/B 歷史中位 1.6x | B29: =pb_2 -> 1.6 | C29: 2029 期末 BVPS | D29: B | E29: =Y!I28 -> 1643294.4 | F29: =B29*E29 -> 2629271.1 | G29: =F29/px-1 -> 1.0589437
A30: P/B 券商遠期 3.3x | B30: =pb_3 -> 3.3 | C30: 2029 期末 BVPS | D30: B | E30: =Y!I28 -> 1643294.4 | F30: =B30*E30 -> 5422871.6 | G30: =F30/px-1 -> 3.2465713
A31: P/B 1.0x | B31: =pb_1 -> 1 | C31: 2029 期末 BVPS | D31: C | E31: =Y!L28 -> 1268477.3 | F31: =B31*E31 -> 1268477.3 | G31: =F31/px-1 -> -0.0066740247
A32: P/B 歷史中位 1.6x | B32: =pb_2 -> 1.6 | C32: 2029 期末 BVPS | D32: C | E32: =Y!L28 -> 1268477.3 | F32: =B32*E32 -> 2029563.6 | G32: =F32/px-1 -> 0.58932156
A33: P/B 券商遠期 3.3x | B33: =pb_3 -> 3.3 | C33: 2029 期末 BVPS | D33: C | E33: =Y!L28 -> 1268477.3 | F33: =B33*E33 -> 4185975 | G33: =F33/px-1 -> 2.2779757
A34: P/E 4x | B34: =pe_1 -> 4 | C34: 2027 EPS | D34: A | E34: =Y!D29 -> 617759.34 | F34: =B34*E34 -> 2471037.4 | G34: =F34/px-1 -> 0.93503318
A35: P/E 8x | B35: =pe_2 -> 8 | C35: 2027 EPS | D35: A | E35: =Y!D29 -> 617759.34 | F35: =B35*E35 -> 4942074.8 | G35: =F35/px-1 -> 2.8700664
A36: P/E 12x | B36: =pe_3 -> 12 | C36: 2027 EPS | D36: A | E36: =Y!D29 -> 617759.34 | F36: =B36*E36 -> 7413112.1 | G36: =F36/px-1 -> 4.8050995
A37: P/E 4x | B37: =pe_1 -> 4 | C37: 2027 EPS | D37: B | E37: =Y!G29 -> 600306.08 | F37: =B37*E37 -> 2401224.3 | G37: =F37/px-1 -> 0.8803636
A38: P/E 8x | B38: =pe_2 -> 8 | C38: 2027 EPS | D38: B | E38: =Y!G29 -> 600306.08 | F38: =B38*E38 -> 4802448.6 | G38: =F38/px-1 -> 2.7607272
A39: P/E 12x | B39: =pe_3 -> 12 | C39: 2027 EPS | D39: B | E39: =Y!G29 -> 600306.08 | F39: =B39*E39 -> 7203672.9 | G39: =F39/px-1 -> 4.6410908
A40: P/E 4x | B40: =pe_1 -> 4 | C40: 2027 EPS | D40: C | E40: =Y!J29 -> 600306.08 | F40: =B40*E40 -> 2401224.3 | G40: =F40/px-1 -> 0.8803636
A41: P/E 8x | B41: =pe_2 -> 8 | C41: 2027 EPS | D41: C | E41: =Y!J29 -> 600306.08 | F41: =B41*E41 -> 4802448.6 | G41: =F41/px-1 -> 2.7607272
...

Sheet Sens
A1: Sens — 一次只動一個價格或份額輸入；Δ營業利益＝Δ營收 × (1 − 營業費用變動率)（成本只隨量變動，所以這是精確值，不是近似）
A3: 欄 | B3: 輸入變動 | C3: Δ營收 | D3: 營業利益 | E3: 相對基準
A4: 2027 A | B4: 基準 | D4: =Y!D14 -> 485.07083
A5: 2027 A | B5: 一般 DRAM 收入 −20% | C5: =-0.2*Y!D5 -> -69.781207 | D5: =D4+C5*(1-opex_var) -> 418.56934 | E5: =D5/D4-1 -> -0.13709645
A6: 2027 A | B6: 一般 DRAM 收入 +20% | C6: =0.2*Y!D5 -> 69.781207 | D6: =D4+C6*(1-opex_var) -> 551.57232 | E6: =D6/D4-1 -> 0.13709645
A7: 2027 A | B7: HBM 收入 −30%（價格或份額） | C7: =-0.3*Y!D6 -> -27.568763 | D7: =D4+C7*(1-opex_var) -> 458.7978 | E7: =D7/D4-1 -> -0.054163287
A8: 2027 A | B8: HBM 收入 +30% | C8: =0.3*Y!D6 -> 27.568763 | D8: =D4+C8*(1-opex_var) -> 511.34386 | E8: =D8/D4-1 -> 0.054163287
A9: 2027 A | B9: NAND 收入 −30% | C9: =-0.3*Y!D7 -> -42.250586 | D9: =D4+C9*(1-opex_var) -> 444.80602 | E9: =D9/D4-1 -> -0.0830081
A10: 2027 A | B10: NAND 收入 +30% | C10: =0.3*Y!D7 -> 42.250586 | D10: =D4+C10*(1-opex_var) -> 525.33564 | E10: =D10/D4-1 -> 0.0830081
A12: 2028 B | B12: 基準 | D12: =Y!H14 -> 268.50905
A13: 2028 B | B13: 一般 DRAM 收入 −20% | C13: =-0.2*Y!H5 -> -41.607506 | D13: =D12+C13*(1-opex_var) -> 228.85709 | E13: =D13/D12-1 -> -0.14767455
A14: 2028 B | B14: 一般 DRAM 收入 +20% | C14: =0.2*Y!H5 -> 41.607506 | D14: =D12+C14*(1-opex_var) -> 308.161 | E14: =D14/D12-1 -> 0.14767455
A15: 2028 B | B15: HBM 收入 −30%（價格或份額） | C15: =-0.3*Y!H6 -> -27.617502 | D15: =D12+C15*(1-opex_var) -> 242.18957 | E15: =D15/D12-1 -> -0.098020829
A16: 2028 B | B16: HBM 收入 +30% | C16: =0.3*Y!H6 -> 27.617502 | D16: =D12+C16*(1-opex_var) -> 294.82853 | E16: =D16/D12-1 -> 0.098020829
A17: 2028 B | B17: NAND 收入 −30% | C17: =-0.3*Y!H7 -> -20.030839 | D17: =D12+C17*(1-opex_var) -> 249.41966 | E17: =D17/D12-1 -> -0.071094027
A18: 2028 B | B18: NAND 收入 +30% | C18: =0.3*Y!H7 -> 20.030839 | D18: =D12+C18*(1-opex_var) -> 287.59844 | E18: =D18/D12-1 -> 0.071094027
A20: 2028 C | B20: 基準 | D20: =Y!K14 -> 163.10623
A21: 2028 C | B21: 一般 DRAM 收入 −20% | C21: =-0.2*Y!K5 -> -28.541415 | D21: =D20+C21*(1-opex_var) -> 135.90626 | E21: =D21/D20-1 -> -0.16676229
A22: 2028 C | B22: 一般 DRAM 收入 +20% | C22: =0.2*Y!K5 -> 28.541415 | D22: =D20+C22*(1-opex_var) -> 190.3062 | E22: =D22/D20-1 -> 0.16676229
A23: 2028 C | B23: HBM 收入 −30%（價格或份額） | C23: =-0.3*Y!K6 -> -16.570501 | D23: =D20+C23*(1-opex_var) -> 147.31454 | E23: =D23/D20-1 -> -0.096818419
A24: 2028 C | B24: HBM 收入 +30% | C24: =0.3*Y!K6 -> 16.570501 | D24: =D20+C24*(1-opex_var) -> 178.89792 | E24: =D24/D20-1 -> 0.096818419
A25: 2028 C | B25: NAND 收入 −30% | C25: =-0.3*Y!K7 -> -16.267012 | D25: =D20+C25*(1-opex_var) -> 147.60377 | E25: =D25/D20-1 -> -0.095045185
A26: 2028 C | B26: NAND 收入 +30% | C26: =0.3*Y!K7 -> 16.267012 | D26: =D20+C26*(1-opex_var) -> 178.60869 | E26: =D26/D20-1 -> 0.095045185
A28: 2029 C | B28: 基準 | D28: =Y!L14 -> 135.34991
A29: 2029 C | B29: 一般 DRAM 收入 −20% | C29: =-0.2*Y!L5 -> -23.096061 | D29: =D28+C29*(1-opex_var) -> 113.33936 | E29: =D29/D28-1 -> -0.16261959
A30: 2029 C | B30: 一般 DRAM 收入 +20% | C30: =0.2*Y!L5 -> 23.096061 | D30: =D28+C30*(1-opex_var) -> 157.36045 | E30: =D30/D28-1 -> 0.16261959
A31: 2029 C | B31: HBM 收入 −30%（價格或份額） | C31: =-0.3*Y!L6 -> -22.618734 | D31: =D28+C31*(1-opex_var) -> 113.79425 | E31: =D31/D28-1 -> -0.15925873
A32: 2029 C | B32: HBM 收入 +30% | C32: =0.3*Y!L6 -> 22.618734 | D32: =D28+C32*(1-opex_var) -> 156.90556 | E32: =D32/D28-1 -> 0.15925873
A33: 2029 C | B33: NAND 收入 −30% | C33: =-0.3*Y!L7 -> -13.347607 | D33: =D28+C33*(1-opex_var) -> 122.62964 | E33: =D33/D28-1 -> -0.093980632
A34: 2029 C | B34: NAND 收入 +30% | C34: =0.3*Y!L7 -> 13.347607 | D34: =D28+C34*(1-opex_var) -> 148.07018 | E34: =D34/D28-1 -> 0.093980632
A36: 讀法：哪一條收入線的同幅變動對營業利益影響最大，就是該年度的主要驅動。價格路徑本身的情境差異見 Y 頁 A／B／C 欄。
A38: 目標價參數（只改 DCF 參數；Y 頁收斂法的 fade_g 不隨 tp_g 變動）
A39: 案例 | B39: 設定 | C39: DCF 目標價 | D39: Comparable 目標價（相對倍數調整後） | E39: 加權目標價 | F39: 相對基準
A40: 基準 | B40: r 10%、g 4%、DCF 權重 0.5 | C40: =(tp_wA*(Val!B138/(1+tp_r)^1+Val!B139/(1+tp_r)^2+Val!B140/(1+tp_r)^3+Val!B133*(1-MIN(tp_g/tp_roe,0.8))/(1+tp_r)^4+Val!B134*(1-MIN(tp_g/tp_roe,0.8))/(1+tp_r)^5+Val!B135*(1-MIN(tp_g/tp_roe,0.8))/(1+tp_r)^6+Val!B135*(1-MIN(tp_g/tp_roe,0.8))*(1+tp_g)/(tp_r-tp_g)/(1+tp_r)^6)+tp_wB*(Val!C138/(1+tp_r)^1+Val!C139/(1+tp_r)^2+Val!C140/(1+tp_r)^3+Val!C133*(1-MIN(tp_g/tp_roe,0.8))/(1+tp_r)^4+Val!C134*(1-MIN(tp_g/tp_roe,0.8))/(1+tp_r)^5+Val!C135*(1-MIN(tp_g/tp_roe,0.8))/(1+tp_r)^6+Val!C135*(1-MIN(tp_g/tp_roe,0.8))*(1+tp_g)/(tp_r-tp_g)/(1+tp_r)^6)+tp_wC*(Val!D138/(1+tp_r)^1+Val!D139/(1+tp_r)^2+Val!D140/(1+tp_r)^3+Val!D133*(1-MIN(tp_g/tp_roe,0.8))/(1+tp_r)^4+Val!D134*(1-MIN(tp_g/tp_roe,0.8))/(1+tp_r)^5+Val!D135*(1-MIN(tp_g/tp_roe,0.8))/(1+tp_r)^6+Val!D135*(1-MIN(tp_g/tp_roe,0.8))*(1+tp_g)/(tp_r-tp_g)/(1+tp_r)^6))*(1+tp_r) -> 4288814.4 | D40: =tp_comp_adj -> 2436897.4 | E40: =tp_w_dcf*C40+(1-tp_w_dcf)*D40 -> 3362855.9 | F40: =E40/E$40-1 -> 0
A41: 折現率 +1pt | B41: r 11% | C41: =(tp_wA*(Val!B138/(1+(tp_r+0.01))^1+Val!B139/(1+(tp_r+0.01))^2+Val!B140/(1+(tp_r+0.01))^3+Val!B133*(1-MIN(tp_g/tp_roe,0.8))/(1+(tp_r+0.01))^4+Val!B134*(1-MIN(tp_g/tp_roe,0.8))/(1+(tp_r+0.01))^5+Val!B135*(1-MIN(tp_g/tp_roe,0.8))/(1+(tp_r+0.01))^6+Val!B135*(1-MIN(tp_g/tp_roe,0.8))*(1+tp_g)/((tp_r+0.01)-tp_g)/(1+(tp_r+0.01))^6)+tp_wB*(Val!C138/(1+(tp_r+0.01))^1+Val!C139/(1+(tp_r+0.01))^2+Val!C140/(1+(tp_r+0.01))^3+Val!C133*(1-MIN(tp_g/tp_roe,0.8))/(1+(tp_r+0.01))^4+Val!C134*(1-MIN(tp_g/tp_roe,0.8))/(1+(tp_r+0.01))^5+Val!C135*(1-MIN(tp_g/tp_roe,0.8))/(1+(tp_r+0.01))^6+Val!C135*(1-MIN(tp_g/tp_roe,0.8))*(1+tp_g)/((tp_r+0.01)-tp_g)/(1+(tp_r+0.01))^6)+tp_wC*(Val!D138/(1+(tp_r+0.01))^1+Val!D139/(1+(tp_r+0.01))^2+Val!D140/(1+(tp_r+0.01))^3+Val!D133*(1-MIN(tp_g/tp_roe,0.8))/(1+(tp_r+0.01))^4+Val!D134*(1-MIN(tp_g/tp_roe,0.8))/(1+(tp_r+0.01))^5+Val!D135*(1-MIN(tp_g/tp_roe,0.8))/(1+(tp_r+0.01))^6+Val!D135*(1-MIN(tp_g/tp_roe,0.8))*(1+tp_g)/((tp_r+0.01)-tp_g)/(1+(tp_r+0.01))^6))*(1+(tp_r+0.01)) -> 3848740.7 | D41: =tp_comp_adj -> 2436897.4 | E41: =tp_w_dcf*C41+(1-tp_w_dcf)*D41 -> 3142819.1 | F41: =E41/E$40-1 -> -0.065431531
A42: 折現率 −1pt | B42: r 9% | C42: =(tp_wA*(Val!B138/(1+(tp_r-0.01))^1+Val!B139/(1+(tp_r-0.01))^2+Val!B140/(1+(tp_r-0.01))^3+Val!B133*(1-MIN(tp_g/tp_roe,0.8))/(1+(tp_r-0.01))^4+Val!B134*(1-MIN(tp_g/tp_roe,0.8))/(1+(tp_r-0.01))^5+Val!B135*(1-MIN(tp_g/tp_roe,0.8))/(1+(tp_r-0.01))^6+Val!B135*(1-MIN(tp_g/tp_roe,0.8))*(1+tp_g)/((tp_r-0.01)-tp_g)/(1+(tp_r-0.01))^6)+tp_wB*(Val!C138/(1+(tp_r-0.01))^1+Val!C139/(1+(tp_r-0.01))^2+Val!C140/(1+(tp_r-0.01))^3+Val!C133*(1-MIN(tp_g/tp_roe,0.8))/(1+(tp_r-0.01))^4+Val!C134*(1-MIN(tp_g/tp_roe,0.8))/(1+(tp_r-0.01))^5+Val!C135*(1-MIN(tp_g/tp_roe,0.8))/(1+(tp_r-0.01))^6+Val!C135*(1-MIN(tp_g/tp_roe,0.8))*(1+tp_g)/((tp_r-0.01)-tp_g)/(1+(tp_r-0.01))^6)+tp_wC*(Val!D138/(1+(tp_r-0.01))^1+Val!D139/(1+(tp_r-0.01))^2+Val!D140/(1+(tp_r-0.01))^3+Val!D133*(1-MIN(tp_g/tp_roe,0.8))/(1+(tp_r-0.01))^4+Val!D134*(1-MIN(tp_g/tp_roe,0.8))/(1+(tp_r-0.01))^5+Val!D135*(1-MIN(tp_g/tp_roe,0.8))/(1+(tp_r-0.01))^6+Val!D135*(1-MIN(tp_g/tp_roe,0.8))*(1+tp_g)/((tp_r-0.01)-tp_g)/(1+(tp_r-0.01))^6))*(1+(tp_r-0.01)) -> 4899375 | D42: =tp_comp_adj -> 2436897.4 | E42: =tp_w_dcf*C42+(1-tp_w_dcf)*D42 -> 3668136.2 | F42: =E42/E$40-1 -> 0.090780079
A43: 長期成長 +1pt | B43: g 5% | C43: =(tp_wA*(Val!B138/(1+tp_r)^1+Val!B139/(1+tp_r)^2+Val!B140/(1+tp_r)^3+Val!B133*(1-MIN((tp_g+0.01)/tp_roe,0.8))/(1+tp_r)^4+Val!B134*(1-MIN((tp_g+0.01)/tp_roe,0.8))/(1+tp_r)^5+Val!B135*(1-MIN((tp_g+0.01)/tp_roe,0.8))/(1+tp_r)^6+Val!B135*(1-MIN((tp_g+0.01)/tp_roe,0.8))*(1+(tp_g+0.01))/(tp_r-(tp_g+0.01))/(1+tp_r)^6)+tp_wB*(Val!C138/(1+tp_r)^1+Val!C139/(1+tp_r)^2+Val!C140/(1+tp_r)^3+Val!C133*(1-MIN((tp_g+0.01)/tp_roe,0.8))/(1+tp_r)^4+Val!C134*(1-MIN((tp_g+0.01)/tp_roe,0.8))/(1+tp_r)^5+Val!C135*(1-MIN((tp_g+0.01)/tp_roe,0.8))/(1+tp_r)^6+Val!C135*(1-MIN((tp_g+0.01)/tp_roe,0.8))*(1+(tp_g+0.01))/(tp_r-(tp_g+0.01))/(1+tp_r)^6)+tp_wC*(Val!D138/(1+tp_r)^1+Val!D139/(1+tp_r)^2+Val!D140/(1+tp_r)^3+Val!D133*(1-MIN((tp_g+0.01)/tp_roe,0.8))/(1+tp_r)^4+Val!D134*(1-MIN((tp_g+0.01)/tp_roe,0.8))/(1+tp_r)^5+Val!D135*(1-MIN((tp_g+0.01)/tp_roe,0.8))/(1+tp_r)^6+Val!D135*(1-MIN((tp_g+0.01)/tp_roe,0.8))*(1+(tp_g+0.01))/(tp_r-(tp_g+0.01))/(1+tp_r)^6))*(1+tp_r) -> 4549899.9 | D43: =tp_comp_adj -> 2436897.4 | E43: =tp_w_dcf*C43+(1-tp_w_dcf)*D43 -> 3493398.7 | F43: =E43/E$40-1 -> 0.038819026
A44: 長期成長 −1pt | B44: g 3% | C44: =(tp_wA*(Val!B138/(1+tp_r)^1+Val!B139/(1+tp_r)^2+Val!B140/(1+tp_r)^3+Val!B133*(1-MIN((tp_g-0.01)/tp_roe,0.8))/(1+tp_r)^4+Val!B134*(1-MIN((tp_g-0.01)/tp_roe,0.8))/(1+tp_r)^5+Val!B135*(1-MIN((tp_g-0.01)/tp_roe,0.8))/(1+tp_r)^6+Val!B135*(1-MIN((tp_g-0.01)/tp_roe,0.8))*(1+(tp_g-0.01))/(tp_r-(tp_g-0.01))/(1+tp_r)^6)+tp_wB*(Val!C138/(1+tp_r)^1+Val!C139/(1+tp_r)^2+Val!C140/(1+tp_r)^3+Val!C133*(1-MIN((tp_g-0.01)/tp_roe,0.8))/(1+tp_r)^4+Val!C134*(1-MIN((tp_g-0.01)/tp_roe,0.8))/(1+tp_r)^5+Val!C135*(1-MIN((tp_g-0.01)/tp_roe,0.8))/(1+tp_r)^6+Val!C135*(1-MIN((tp_g-0.01)/tp_roe,0.8))*(1+(tp_g-0.01))/(tp_r-(tp_g-0.01))/(1+tp_r)^6)+tp_wC*(Val!D138/(1+tp_r)^1+Val!D139/(1+tp_r)^2+Val!D140/(1+tp_r)^3+Val!D133*(1-MIN((tp_g-0.01)/tp_roe,0.8))/(1+tp_r)^4+Val!D134*(1-MIN((tp_g-0.01)/tp_roe,0.8))/(1+tp_r)^5+Val!D135*(1-MIN((tp_g-0.01)/tp_roe,0.8))/(1+tp_r)^6+Val!D135*(1-MIN((tp_g-0.01)/tp_roe,0.8))*(1+(tp_g-0.01))/(tp_r-(tp_g-0.01))/(1+tp_r)^6))*(1+tp_r) -> 4112146.4 | D44: =tp_comp_adj -> 2436897.4 | E44: =tp_w_dcf*C44+(1-tp_w_dcf)*D44 -> 3274521.9 | F44: =E44/E$40-1 -> -0.026267552
A45: DCF 權重 0.3 | B45: Comparable 0.7 | C45: =(tp_wA*(Val!B138/(1+tp_r)^1+Val!B139/(1+tp_r)^2+Val!B140/(1+tp_r)^3+Val!B133*(1-MIN(tp_g/tp_roe,0.8))/(1+tp_r)^4+Val!B134*(1-MIN(tp_g/tp_roe,0.8))/(1+tp_r)^5+Val!B135*(1-MIN(tp_g/tp_roe,0.8))/(1+tp_r)^6+Val!B135*(1-MIN(tp_g/tp_roe,0.8))*(1+tp_g)/(tp_r-tp_g)/(1+tp_r)^6)+tp_wB*(Val!C138/(1+tp_r)^1+Val!C139/(1+tp_r)^2+Val!C140/(1+tp_r)^3+Val!C133*(1-MIN(tp_g/tp_roe,0.8))/(1+tp_r)^4+Val!C134*(1-MIN(tp_g/tp_roe,0.8))/(1+tp_r)^5+Val!C135*(1-MIN(tp_g/tp_roe,0.8))/(1+tp_r)^6+Val!C135*(1-MIN(tp_g/tp_roe,0.8))*(1+tp_g)/(tp_r-tp_g)/(1+tp_r)^6)+tp_wC*(Val!D138/(1+tp_r)^1+Val!D139/(1+tp_r)^2+Val!D140/(1+tp_r)^3+Val!D133*(1-MIN(tp_g/tp_roe,0.8))/(1+tp_r)^4+Val!D134*(1-MIN(tp_g/tp_roe,0.8))/(1+tp_r)^5+Val!D135*(1-MIN(tp_g/tp_roe,0.8))/(1+tp_r)^6+Val!D135*(1-MIN(tp_g/tp_roe,0.8))*(1+tp_g)/(tp_r-tp_g)/(1+tp_r)^6))*(1+tp_r) -> 4288814.4 | D45: =tp_comp_adj -> 2436897.4 | E45: =0.3*C45+(1-0.3)*D45 -> 2992472.5 | F45: =E45/E$40-1 -> -0.11013953
A46: DCF 權重 0.7 | B46: Comparable 0.3 | C46: =(tp_wA*(Val!B138/(1+tp_r)^1+Val!B139/(1+tp_r)^2+Val!B140/(1+tp_r)^3+Val!B133*(1-MIN(tp_g/tp_roe,0.8))/(1+tp_r)^4+Val!B134*(1-MIN(tp_g/tp_roe,0.8))/(1+tp_r)^5+Val!B135*(1-MIN(tp_g/tp_roe,0.8))/(1+tp_r)^6+Val!B135*(1-MIN(tp_g/tp_roe,0.8))*(1+tp_g)/(tp_r-tp_g)/(1+tp_r)^6)+tp_wB*(Val!C138/(1+tp_r)^1+Val!C139/(1+tp_r)^2+Val!C140/(1+tp_r)^3+Val!C133*(1-MIN(tp_g/tp_roe,0.8))/(1+tp_r)^4+Val!C134*(1-MIN(tp_g/tp_roe,0.8))/(1+tp_r)^5+Val!C135*(1-MIN(tp_g/tp_roe,0.8))/(1+tp_r)^6+Val!C135*(1-MIN(tp_g/tp_roe,0.8))*(1+tp_g)/(tp_r-tp_g)/(1+tp_r)^6)+tp_wC*(Val!D138/(1+tp_r)^1+Val!D139/(1+tp_r)^2+Val!D140/(1+tp_r)^3+Val!D133*(1-MIN(tp_g/tp_roe,0.8))/(1+tp_r)^4+Val!D134*(1-MIN(tp_g/tp_roe,0.8))/(1+tp_r)^5+Val!D135*(1-MIN(tp_g/tp_roe,0.8))/(1+tp_r)^6+Val!D135*(1-MIN(tp_g/tp_roe,0.8))*(1+tp_g)/(tp_r-tp_g)/(1+tp_r)^6))*(1+tp_r) -> 4288814.4 | D46: =tp_comp_adj -> 2436897.4 | E46: =0.7*C46+(1-0.7)*D46 -> 3733239.3 | F46: =E46/E$40-1 -> 0.11013953
...

Sheet Recon
A1: Recon — 本模型（正向推導）vs 共識或公司指引（只作事後對照，不用來回推參數）；兆韓元
A3: 項目 | B3: 本模型 | C3: 對照值 | D3: 差距 | E3: 對照來源
A4: 2026E 營收 vs 共識 | B4: =Y!C4 -> 377.16719 | C4: 344.2 | D4: =B4/C4-1 -> 0.095779159 | E4: MarketScreener 2026-10-02
A5: 2026E 營業利益 vs 共識 | B5: =Y!C14 -> 297.21002 | C5: 266.1 | D5: =B5/C5-1 -> 0.116911 | E5: MarketScreener；FnGuide 265.2
A6: 2026E 淨利 vs 共識 | B6: =Y!C20 -> 263.92172 | C6: 256.3 | D6: =B6/C6-1 -> 0.029737505 | E6: MarketScreener
A7: 2026E HBM 營收 vs BofA | B7: =Y!C6 -> 40.779873 | C7: 45.7 | D7: =B7/C7-1 -> -0.10766142 | E7: BofA 2026-09-13；CLSA 49.4
A8: 2027E 營收（A）vs 共識 | B8: =Y!D4 -> 583.2372 | C8: 531.3 | D8: =B8/C8-1 -> 0.097754936 | E8: MarketScreener
A9: 2027E 營業利益（A）vs 共識 | B9: =Y!D14 -> 485.07083 | C9: 417.2 | D9: =B9/C9-1 -> 0.16268176 | E9: MarketScreener；FnGuide 391.8（08-14）
A10: 2027E 淨利（A）vs 共識 | B10: =Y!D20 -> 375.72955 | C10: 336.2 | D10: =B10/C10-1 -> 0.11757747 | E10: MarketScreener
A11: 2028E 營業利益（A）vs 共識 | B11: =Y!E14 -> 527.76701 | C11: 454 | D11: =B11/C11-1 -> 0.1624824 | E11: MarketScreener；FnGuide 399.1
A12: 2026Q3 營收（實績）vs 事前共識 | B12: =Q!H4 -> 104.616 | C12: 94.1 | D12: =B12/C12-1 -> 0.11175345 | E12: FnGuide 2026-09-25
A13: 2026Q3 營業利益（實績）vs 事前共識 | B13: =Q!H10 -> 83.334 | C13: 76.1 | D13: =B13/C13-1 -> 0.095059133 | E13: FnGuide 74.1–78.1
A14: 2027E EPS（A）vs 共識（第 0 節差距拆解用） | B14: =Y!D29 -> 617759.34 | C14: =cons_eps27 -> 475721 | D14: =B14/C14-1 -> 0.29857489 | E14: MarketScreener 預估頁（2026-10-25 擷取；頁面為 10-23 收盤）
A15: 2028E EPS（A）vs 共識（第 0 節差距拆解用） | B15: =Y!E29 -> 818443.84 | C15: =cons_eps28 -> 537981 | D15: =B15/C15-1 -> 0.52132481 | E15: MarketScreener 預估頁（2026-10-25 擷取；頁面為 10-23 收盤）
A16: 2028E 年底每股淨值（A）vs 共識 | B16: =Y!E28 -> 1575464 | C16: =cons_bvps28 -> 1398106 | D16: =B16/C16-1 -> 0.12685587 | E16: MarketScreener 預估頁（2026-10-25 擷取；頁面為 10-23 收盤）

Sheet Feedback
A1: Feedback — 回饋算力收支
A3: 每顆加速器 HBM 金額（GB300，2026 價） | B3: =nv_hbm -> 4.46 | C3: $K
A4: 全市場每顆加速器平均 HBM 2026／2027 | B4: =TEXT(Mkt!D16,"0")&" ／ "&TEXT(Mkt!E16,"0") -> 216 ／ 260 | C4: GB
A5: HBM 市場 2026／2027（A） | B5: =TEXT(Mkt!D33,"0")&" ／ "&TEXT(Mkt!E33,"0") -> 55 ／ 154 | C5: $B
A6: 2027 HBM 需求缺口（三情境相同） | B6: =Mkt!E27 -> 1.2325527 | C6: EB
A7: SK 海力士 HBM 毛利率 | B7: 無法由公開資料分離 | C7: —

Sheet Sources
A1: 來源
A2: SK hynix 424B4（2026-07） | B2: https://www.sec.gov/Archives/edgar/data/2120882/000119312526299963/d32785d424b4.htm
A3: SK hynix 6-K 半年報（2026-08-18） | B3: https://www.sec.gov/Archives/edgar/data/2120882/000119312526354777/d147827d6k.htm
A4: Q2 2026 法說逐字稿 | B4: https://ng.investing.com/news/transcripts/earnings-call-transcript-sk-hynix-posts-record-q2-2026-results-as-shares-fall-93CH-2622277
A5: MarketScreener 共識 | B5: https://www.marketscreener.com/quote/stock/SK-HYNIX-INC-6494929/finances/
A6: Herald Business：FnGuide、目標價 | B6: https://biz.heraldcorp.com/article/10841314
A7: BofA HBM（Economy Tribune） | B7: https://www.economytribune.co.kr/news/articleView.html?idxno=3903874
A8: 40 兆買回（Korea Herald） | B8: https://www.koreaherald.com/article/10845792
A9: SK hynix 6-K 3Q26 股東回饋（2026-10-28） | B9: https://www.sec.gov/Archives/edgar/data/0002120882/000119312526435008/d236990d6k.htm
A10: UBS 2027 HBM 市占（Korea Herald） | B10: https://www.koreaherald.com/article/10828143
A11: companiesmarketcap P/B | B11: https://companiesmarketcap.com/sk-hynix/pb-ratio/
A12: TrendForce 4Q26 價格 | B12: https://www.trendforce.com/presscenter/news/20260930-13258.html
A13: Citi 2027 見頂 | B13: https://www.tipranks.com/news/memory-prices-will-peak-next-year-warns-citi-as-it-cuts-micron-mu-price-target-by-18
... A16: markets/chip_bridge v0.2 | B16: 本 repo
