Workbook

Sheet README
A1: SK 海力士收支與估值模型 v0.1（AI 半導體樣板第一家） 2026-10-08
A2: 模型命題：SK 海力士的盈餘由兩條價格線決定——每季議價的一般 DRAM 與年約鎖價的 HBM；股價取決於這個循環在哪一年見頂，以及見頂時累積了多少淨值。
A4: 驅動因子 → 推導量（頁：輸入 → 推導 → 因果方向）
A5: Mkt：加速器顆數 × 每顆 GB → HBM 需求位元；供給成長 → 出貨位元＝MIN(需求, 供給)；× 單價 → HBM 市場；× 市占 → SK 海力士 HBM 營收。需求 > 供給 → 價格上漲（缺口列）
A6: Q：2026H1 實績（SEC 6-K）× 公司 Q3 指引 × TrendForce 季價 → 2026H2 營收與成本；成本隨位元量增、每季單位成本降
A7: Y：一般 DRAM 2026 × (1＋位元) × (1＋年均價變動)；NAND 同；HBM 取自 Mkt → 營收；成本量指數 × (1 − 年降)＋折舊 → 營業利益 → 淨利 → 權益（減股利、買回）→ 每股淨值
A8: Val：每股淨值 × P/B（主）、EPS × P/E（對照）→ 隱含股價 vs 目前股價
A9: Sens：一次動一個輸入 → 2027E 營業利益
A10: Recon：本模型 vs 共識（事後對照；參數不由共識回推）
A12: 情境：A＝2027–28 高檔持平（BofA、TrendForce 型）；B＝2027 見頂、2028 一般 DRAM −50%、NAND −65%（Bernstein 型）。2026 兩情境相同。
A13: 取數：markets/chip_bridge v0.1（每顆 GPU HBM 金額、NVIDIA 內容，取 Tokenomics v5.27）。SemiAnalysis 未使用。
A14: 標記：Verified 公開一手；Interested-party 有利害關係；Analogy 類比；Assumed 無實證；Derived 推導。Assumed／Analogy 皆有低／高區間（In 頁）。
... A19: 1 取數註明版本：✓（Tokenomics v5.27 經橋接表 v0.1） 2 HBM 由上而下 vs 由下而上對帳：見 Mkt 對帳列 3 回饋摘要：Feedback 頁 4 命題＋驅動對照＋Excel：本頁 5 兩個使用端結論：另記（不放公開 repo） 6 審閱＋模型後先驗：待 7 複製測試（美光）：待

Sheet In
A1: In — 輸入（藍字＝基準值；低／高供敏感度）。每列有具名範圍＝鍵（指向基準欄 E）
A3: 鍵 | B3: 項目 | C3: 單位 | D3: 低 | E3: 基準 | F3: 高 | G3: 標記 | H3: 來源／說明
A4: A. 匯率與市場價格
A5: fx | B5: 美元兌韓元（2026–2028 平均） | C5: KRW/USD | D5: 1350 | E5: 1420 | F5: 1500 | G5: Derived | H5: Q2 2026 營收 79.32 兆韓元 ≈ US$55.2B → 約 1,437；7 月 ADS 定價匯率 1,538（S1）
A6: px | B6: 股價（2026-10-07 收盤） | C6: KRW | E6: 1723000 | G6: Verified | H6: Investing.com 歷史價格；10-02 為 1,841,000（StockAnalysis、MarketScreener）
A7: B. 加速器數量層（百萬顆，封裝）與每顆 HBM（GB）— HBM 需求端
A8: u_bw_26 | B8: NVIDIA Blackwell（B200／B300） 顆數 2026 | C8: 百萬顆 | E8: 5.4 | G8: Interested-party | H8: 顆數：Morgan Stanley 2026-07（2026 5.4M）；AC Research 2027 約 2.4M 淨新增；2028 Assumed。GB：B200 186、B300 288 的組合 [Derived]
A9: u_bw_27 | B9: NVIDIA Blackwell（B200／B300） 顆數 2027 | C9: 百萬顆 | E9: 2.4 | G9: Interested-party | H9: 同上
A10: u_bw_28 | B10: NVIDIA Blackwell（B200／B300） 顆數 2028 | C10: 百萬顆 | E10: 0.5 | G10: Interested-party | H10: 同上
A11: g_bw_26 | B11: NVIDIA Blackwell（B200／B300） 每顆 HBM 2026 | C11: GB | E11: 260 | G11: Interested-party | H11: 同上
A12: g_bw_27 | B12: NVIDIA Blackwell（B200／B300） 每顆 HBM 2027 | C12: GB | E12: 280 | G12: Interested-party | H12: 同上
A13: g_bw_28 | B13: NVIDIA Blackwell（B200／B300） 每顆 HBM 2028 | C13: GB | E13: 288 | G13: Interested-party | H13: 同上
A14: u_rb_26 | B14: NVIDIA Rubin 顆數 2026 | C14: 百萬顆 | E14: 1.7 | G14: Interested-party | H14: 2026：TrendForce 2026 組合 Rubin 22% × NVIDIA 約 7.6M [Derived]；2027：Morgan Stanley 約 7.0M（約 9 萬架 NVL72）；2028 Assumed 持平。GB：NVIDIA 規格 288
A15: u_rb_27 | B15: NVIDIA Rubin 顆數 2027 | C15: 百萬顆 | E15: 7 | G15: Interested-party | H15: 同上
A16: u_rb_28 | B16: NVIDIA Rubin 顆數 2028 | C16: 百萬顆 | E16: 7 | G16: Interested-party | H16: 同上
A17: g_rb_26 | B17: NVIDIA Rubin 每顆 HBM 2026 | C17: GB | E17: 288 | G17: Interested-party | H17: 同上
A18: g_rb_27 | B18: NVIDIA Rubin 每顆 HBM 2027 | C18: GB | E18: 288 | G18: Interested-party | H18: 同上
A19: g_rb_28 | B19: NVIDIA Rubin 每顆 HBM 2028 | C19: GB | E19: 288 | G19: Interested-party | H19: 同上
... A55: g_oth_28 | B55: 其他 ASIC（MTIA、Maia、Ascend 等） 每顆 HBM 2028 | C55: GB | E55: 250 | G55: Derived／Assumed | H55: 同上
A56: C. HBM 市場（供給、價格、份額）
A57: hbm_gross | B57: 出貨位元 ÷ 加速器裝載位元（封裝良率損失、庫存、通路） | C57: x | D57: 1 | E57: 1.15 | F57: 1.3 | G57: Assumed | H57: Epoch：CoWoS-L 良率 65–95%；另含庫存與未列入的買方
A58: hbm_sup27 | B58: 2027 HBM 位元供給成長 | C58: % | D58: 0.5 | E58: 0.55 | F58: 0.63 | G58: Interested-party | H58: TrendForce 2027 位元需求 +50–60%（供給受晶圓與 TSV 產能限制）；JPMorgan 2026–28 CAGR 63%
A59: hbm_sup28 | B59: 2028 HBM 位元供給成長 | C59: % | D59: 0.3 | E59: 0.45 | F59: 0.63 | G59: Assumed | H59: JPMorgan CAGR 63% 為上限；新廠 2028 才貢獻（TrendForce）
A60: hbm_p26 | B60: HBM 混合單價 2026 | C60: $/GB | D60: 12.5 | E60: 14.6 | F60: 16 | G60: Interested-party | H60: BofA $14.6/GB（2026-08）；DigiTimes HBM3E $12–12.8、HBM4 約 $16
A61: hbm_p27_A | B61: HBM 單價 2027 變動（情境 A） | C61: % | D61: 0.38 | E61: 0.8 | F61: 1.21 | G61: Interested-party | H61: BofA +38%、JPM +54%、UBS +76–79%、TrendForce +121%；取中間
A62: hbm_p27_B | B62: HBM 單價 2027 變動（情境 B） | C62: % | D62: 0.38 | E62: 0.8 | F62: 1.21 | G62: Interested-party | H62: 2027 年約已在議價，兩情境相同
A63: hbm_p28_A | B63: HBM 單價 2028 變動（情境 A） | C63: % | D63: 0 | E63: 0.1 | F63: 0.25 | G63: Interested-party | H63: JPMorgan 2028 +25%（上限）；BofA 2028 溫和修正
A64: hbm_p28_B | B64: HBM 單價 2028 變動（情境 B） | C64: % | D64: -0.4 | E64: -0.25 | F64: -0.1 | G64: Assumed | H64: 2027 見頂、2028 一般 DRAM 大跌時，HBM 年約重議跟著下修
A65: sh26 | B65: SK 海力士 HBM 營收市占 2026 | C65: % | D65: 0.48 | E65: 0.52 | F65: 0.56 | G65: Interested-party | H65: Counterpoint Q1 58%、Q2 50%；IDC Q1 56.4%；UBS 位元 48%
A66: sh27 | B66: SK 海力士 HBM 營收市占 2027 | C66: % | D66: 0.38 | E66: 0.42 | F66: 0.48 | G66: Interested-party | H66: UBS 2027 位元：SK 39%、三星 41%、美光 20%；JPM：三星＋美光 59%
A67: sh28 | B67: SK 海力士 HBM 營收市占 2028 | C67: % | D67: 0.35 | E67: 0.4 | F67: 0.45 | G67: Assumed | H67: 延續 2027
A68: nv_dc26 | B68: NVIDIA 資料中心營收 2026（約 FY27） | C68: $B | D68: 340 | E68: 374 | F68: 400 | G68: Verified／Assumed | H68: FY27 Q1 75.2、Q2 89.0（8-K）；Q3 指引總營收 108（資料中心取 100）；Q4 Assumed 110
... A70: nv_hbm | B70: 每顆 GPU HBM 金額（GB300 橋接表） | C70: $K | D70: 3.5 | E70: 4.46 | F70: 4.9 | G70: Derived | H70: markets/chip_bridge v0.1（288GB × $15.5/GB）
A71: pub26_lo | B71: 已發布 2026 HBM 市場（低） | C71: $B | E71: 54.6 | G71: Interested-party | H71: SK 海力士自估（Motley Fool／글로벌이코노믹 2026-09）
A72: pub26_hi | B72: 已發布 2026 HBM 市場（高） | C72: $B | E72: 77.4 | G72: Interested-party | H72: BofA 2026-08-07；CLSA 推算約 69
A73: pub27 | B73: 已發布 2027 HBM 市場 | C73: $B | E73: 152.8 | G73: Interested-party | H73: BofA；JPMorgan 2027–28 為 160–282
A74: D. SK 海力士 2026 下半年（實績錨定＋公司指引＋TrendForce 價格）
A75: q3_db | B75: Q3 DRAM 位元季增 | C75: % | D75: 0.08 | E75: 0.1 | F75: 0.12 | G75: Verified | H75: 公司 Q2 法說：約 +10%
A76: q3_dp | B76: Q3 DRAM 混合 ASP 季增 | C76: % | D76: 0.08 | E76: 0.12 | F76: 0.16 | G76: Derived | H76: TrendForce 一般 DRAM +13–18%；HBM 年約鎖價拉低混合值
A77: q3_nb | B77: Q3 NAND 位元季增 | C77: % | D77: 0 | E77: 0.02 | F77: 0.04 | G77: Verified | H77: 公司：低個位數
...

Sheet Mkt
A1: Mkt — 加速器數量層（最小版）與 HBM 市場：需求（顆數 × GB）、供給（位元成長）、價格 → 市場規模；並與由上而下、已發布數字對帳
A3: 項目 | B3: 單位 | C3: 2026 | D3: 2027 | E3: 2028 | F3: 說明
A4: 需求：加速器裝載的 HBM（PB）
A5: NVIDIA Blackwell（B200／B300） | B5: PB | C5: =u_bw_26*g_bw_26 -> 1404 | D5: =u_bw_27*g_bw_27 -> 672 | E5: =u_bw_28*g_bw_28 -> 144
A6: NVIDIA Rubin | B6: PB | C6: =u_rb_26*g_rb_26 -> 489.6 | D6: =u_rb_27*g_rb_27 -> 2016 | E6: =u_rb_28*g_rb_28 -> 2016
A7: NVIDIA Rubin Ultra | B7: PB | C7: =u_ru_26*g_ru_26 -> 0 | D7: =u_ru_27*g_ru_27 -> 307.2 | E7: =u_ru_28*g_ru_28 -> 2048
A8: NVIDIA Hopper（H200 等） | B8: PB | C8: =u_hp_26*g_hp_26 -> 70.5 | D8: =u_hp_27*g_hp_27 -> 0 | E8: =u_hp_28*g_hp_28 -> 0
A9: AMD Instinct | B9: PB | C9: =u_amd_26*g_amd_26 -> 216 | D9: =u_amd_27*g_amd_27 -> 540 | E9: =u_amd_28*g_amd_28 -> 864
A10: Google TPU | B10: PB | C10: =u_tpu_26*g_tpu_26 -> 739.2 | D10: =u_tpu_27*g_tpu_27 -> 1375 | E10: =u_tpu_28*g_tpu_28 -> 2016
A11: AWS Trainium | B11: PB | C11: =u_trn_26*g_trn_26 -> 220 | D11: =u_trn_27*g_trn_27 -> 360 | E11: =u_trn_28*g_trn_28 -> 600
A12: 其他 ASIC（MTIA、Maia、Ascend 等） | B12: PB | C12: =u_oth_26*g_oth_26 -> 150 | D12: =u_oth_27*g_oth_27 -> 900 | E12: =u_oth_28*g_oth_28 -> 1250
A13: 需求合計（加速器裝載） | B13: EB | C13: =SUM(C5:C12)/1000 -> 3.2893 | D13: =SUM(D5:D12)/1000 -> 6.1702 | E13: =SUM(E5:E12)/1000 -> 8.938 | F13: 1 EB＝1,000 PB
A14: 需求合計 × 出貨／裝載係數 | B14: EB | C14: =C13*hbm_gross -> 3.782695 | D14: =D13*hbm_gross -> 7.09573 | E14: =E13*hbm_gross -> 10.2787
A15: 需求年增 | B15: % | D15: =D14/C14-1 -> 0.87583984 | E15: =E14/D14-1 -> 0.44857541
A16: 加速器顆數合計 | B16: 百萬顆 | C16: =u_bw_26+u_rb_26+u_ru_26+u_hp_26+u_amd_26+u_tpu_26+u_trn_26+u_oth_26 -> 15.2 | D16: =u_bw_27+u_rb_27+u_ru_27+u_hp_27+u_amd_27+u_tpu_27+u_trn_27+u_oth_27 -> 23.7 | E16: =u_bw_28+u_rb_28+u_ru_28+u_hp_28+u_amd_28+u_tpu_28+u_trn_28+u_oth_28 -> 26.5
A17: 其中 GPU（NVIDIA＋AMD） | B17: 百萬顆 | C17: =u_bw_26+u_rb_26+u_ru_26+u_hp_26+u_amd_26 -> 8.35 | D17: =u_bw_27+u_rb_27+u_ru_27+u_hp_27+u_amd_27 -> 11.2 | E17: =u_bw_28+u_rb_28+u_ru_28+u_hp_28+u_amd_28 -> 11.5 | F17: JPMorgan 2027：GPU 10.9M、ASIC 12.5M
A18: 每顆平均 HBM | B18: GB | C18: =C13*1000/C16 -> 216.40132 | D18: =D13*1000/D16 -> 260.34599 | E18: =E13*1000/E16 -> 337.28302
A20: 供給與出貨（位元）
A21: 供給（2026＝需求出貨；之後依供給成長） | B21: EB | C21: =C14 -> 3.782695 | D21: =C14*(1+hbm_sup27) -> 5.8631772 | E21: =D21*(1+hbm_sup28) -> 8.501607
A22: 出貨＝MIN(需求, 供給) | B22: EB | C22: =MIN(C14,C21) -> 3.782695 | D22: =MIN(D14,D21) -> 5.8631772 | E22: =MIN(E14,E21) -> 8.501607
A23: 需求 − 供給（缺口＞0＝短缺，支撐價格） | B23: EB | C23: =C14-C21 -> 0 | D23: =D14-D21 -> 1.2325527 | E23: =E14-E21 -> 1.777093
A25: 價格與市場規模
A26: HBM 單價（情境 A） | B26: $/GB | C26: =hbm_p26 -> 14.6 | D26: =C26*(1+hbm_p27_A) -> 26.28 | E26: =D26*(1+hbm_p28_A) -> 28.908
A27: HBM 單價（情境 B） | B27: $/GB | C27: =hbm_p26 -> 14.6 | D27: =C27*(1+hbm_p27_B) -> 26.28 | E27: =D27*(1+hbm_p28_B) -> 19.71
A28: HBM 市場（情境 A） | B28: $B | C28: =C22*C26 -> 55.227347 | D28: =D22*D26 -> 154.0843 | E28: =E22*E26 -> 245.76446 | F28: EB × $/GB ＝ $B
A29: HBM 市場（情境 B） | B29: $B | C29: =C22*C27 -> 55.227347 | D29: =D22*D27 -> 154.0843 | E29: =E22*E27 -> 167.56667
A30: SK 海力士 HBM 市占 | B30: % | C30: =sh26 -> 0.52 | D30: =sh27 -> 0.42 | E30: =sh28 -> 0.4
A31: SK 海力士 HBM 營收（A） | B31: 兆韓元 | C31: =C28*C30*fx/1000 -> 40.779873 | D31: =D28*D30*fx/1000 -> 91.895875 | E31: =E28*E30*fx/1000 -> 139.59421
A32: SK 海力士 HBM 營收（B） | B32: 兆韓元 | C32: =C29*C30*fx/1000 -> 40.779873 | D32: =D29*D30*fx/1000 -> 91.895875 | E32: =E29*E30*fx/1000 -> 95.177871
A33: SK 海力士 HBM 位元成長 | B33: % | D33: =D22*D30/(C22*C30)-1 -> 0.25192308 | E33: =E22*E30/(D22*D30)-1 -> 0.38095238
A35: 對帳（驗收標準 2）
A36: 由下而上：NVIDIA 裝載 HBM × 單價 | B36: $B | C36: =(C5+C6+C7+C8)/1000*hbm_p26 -> 28.67586 | F36: 2026；未乘出貨係數
A37: 由上而下：NVIDIA 資料中心營收 × (每顆 HBM ÷ 每顆 NVIDIA 內容) | B37: $B | C37: =nv_dc26*nv_hbm/nv_content -> 32.326357 | F37: 營收、HBM 金額取自橋接表；與顆數預測獨立
A38: 差距（由下而上 ÷ 由上而下 − 1） | B38: % | C38: =C36/C37-1 -> -0.11292632
A39: 由營收推得的 NVIDIA 顆數 | B39: 百萬顆 | C39: =nv_dc26/nv_content -> 7.248062
A40: 對照：顆數預測（Blackwell＋Rubin＋Hopper） | B40: 百萬顆 | C40: =u_bw_26+u_rb_26+u_hp_26 -> 7.6
A41: 已發布 HBM 市場（低／高） | B41: $B | C41: =pub26_lo -> 54.6 | D41: =pub27 -> 152.8 | F41: 2026：SK 海力士自估 54.6；高 77.4（BofA）。2027：BofA 152.8
A42: 本模型 ÷ 已發布（A） | B42: % | C42: =C28/C41-1 -> 0.011489872 | D42: =D28/D41-1 -> 0.0084050925
A43: 本模型 ÷ 已發布高值（2026） | B43: % | C43: =C28/pub26_hi-1 -> -0.28646839

Sheet Q
A1: Q — 季度損益（2025Q1–2026Q2 實績，SEC 424B4／6-K 與公司公告；2026Q3–Q4 由實績 × 公司指引 × TrendForce 價格推估）；兆韓元
A3: 項目 | B3: 2025Q1 | C3: 2025Q2 | D3: 2025Q3 | E3: 2025Q4 | F3: 2026Q1 | G3: 2026Q2 | H3: 2026Q3E | I3: 2026Q4E | J3: 2026 合計
A4: 營收 | B4: 17.639 | C4: 22.232 | D4: 24.449 | E4: 32.827 | F4: 52.576 | G4: 79.319 | H4: =H5+H6+H7 -> 96.311345 | I4: =I5+I6+I7 -> 113.11289 | J4: =SUM(F4:I4) -> 341.31923
A5: DRAM | F5: =F4*0.773 -> 40.641248 | G5: =G4*0.73 -> 57.90287 | H5: =G5*(1+q3_db)*(1+q3_dp) -> 71.336336 | I5: =H5*(1+q4_db)*(1+q4_dp) -> 82.393468 | J5: =SUM(F5:I5) -> 252.27392
A6: NAND | F6: =F4*0.22 -> 11.56672 | G6: =G4*0.27 -> 21.41613 | H6: =G6*(1+q3_nb)*(1+q3_np) -> 24.575009 | I6: =H6*(1+q4_nb)*(1+q4_np) -> 30.319418 | J6: =SUM(F6:I6) -> 87.877277
A7: 其他 | F7: =F4-F5-F6 -> 0.368032 | G7: =G4-G5-G6 -> 0 | H7: =other_y/4 -> 0.4 | I7: =other_y/4 -> 0.4 | J7: =SUM(F7:I7) -> 1.168032
A8: 營業成本 | F8: =F4*(1-0.79) -> 11.04096 | G8: =G4*(1-0.83) -> 13.48423 | H8: =(G8-da_cogs*G13)*((w_c+w_h)*H14/G14+w_n*H15/G15)*(1-costdn_q)+da_cogs*da_q3 -> 14.19832 | I8: =(H8-da_cogs*H13)*((w_c+w_h)*I14/H14+w_n*I15/H15)*(1-costdn_q)+da_cogs*da_q4 -> 14.659394 | J8: =SUM(F8:I8) -> 53.382904
A9: 營業費用 | F9: =F4-F8-F10 -> 3.92504 | G9: =G4-G8-G10 -> 5.29177 | H9: =opex_fix+opex_var*H4 -> 6.0266332 | I9: =opex_fix+opex_var*I4 -> 6.8163056 | J9: =SUM(F9:I9) -> 22.059749
A10: 營業利益 | B10: 7.441 | C10: 9.213 | D10: 11.383 | E10: 19.17 | F10: 37.61 | G10: 60.543 | H10: =H4-H8-H9 -> 76.086392 | I10: =I4-I8-I9 -> 91.637186 | J10: =SUM(F10:I10) -> 265.87658
A11: 營業利益率 | B11: =B10/B4 -> 0.42184931 | C11: =C10/C4 -> 0.41440266 | D11: =D10/D4 -> 0.46558141 | E11: =E10/E4 -> 0.58397051 | F11: =F10/F4 -> 0.7153454 | G11: =G10/G4 -> 0.76328496 | H11: =H10/H4 -> 0.79000446 | I11: =I10/I4 -> 0.81013923 | J11: =J10/J4 -> 0.77896747
A12: 淨利 | B12: 8.108 | C12: 6.996 | D12: 12.598 | E12: 15.246 | F12: 40.346 | G12: 93.923 | H12: =(H10+nonop_q)*(1-tax) -> 59.356522 | I12: =(I10+nonop_q)*(1-tax) -> 71.330633 | J12: =SUM(F12:I12) -> 264.95616
A13: 折舊攤銷 | B13: 3.334 | C13: 3.443 | D13: 3.556 | E13: 3.557 | F13: 3.726 | G13: 4.028 | H13: =da_q3 -> 4.3 | I13: =da_q4 -> 4.6 | J13: =SUM(F13:I13) -> 16.654
A14: DRAM 位元指數（2026Q2＝1） | G14: 1 | H14: =G14*(1+q3_db) -> 1.1 | I14: =H14*(1+q4_db) -> 1.155
A15: NAND 位元指數 | G15: 1 | H15: =G15*(1+q3_nb) -> 1.02 | I15: =H15*(1+q4_nb) -> 1.071
A18: 註：2025 季度 DRAM／NAND 拆分、Q2–Q4 2025 資本支出未找到；2025Q3、Q4 折舊為合計 7.113 平均分配 [Derived]。2026Q1 毛利率約 79%、Q2 83% 為公司簡報數；營業費用＝營收 − 營業成本 − 營業利益 [Derived]

Sheet Y
A1: Y — 年度損益、資本支出、淨值與股數（兆韓元；股數百萬股）。情境 A：2027–28 高檔持平（市場共識型）；情境 B：2027 見頂、2028 價格大幅回落
A3: 項目 | B3: 2025A | C3: 2026E | D3: 2027E A | E3: 2028E A | F3: 2027E B | G3: 2028E B | H3: 說明
A4: 營收 | B4: =SUM(Q!B4:E4) -> 97.147 | C4: =Q!J4 -> 341.31923 | D4: =D5+D6+D7+D8 -> 535.12997 | E4: =E5+E6+E7+E8 -> 587.84568 | F4: =F5+F6+F7+F8 -> 516.11611 | G4: =G5+G6+G7+G8 -> 319.35304
A5: 一般 DRAM | B5: =74.9-28.1 -> 46.8 | C5: =Q!J5-C6 -> 211.49405 | D5: =C5*(1+cb27)*(1+cp27_A) -> 302.43649 | E5: =D5*(1+cb28)*(1+cp28_A) -> 313.02177 | F5: =C5*(1+cb27)*(1+cp27_B) -> 290.80432 | G5: =F5*(1+cb28)*(1+cp28_B) -> 167.21248 | H5: 2025：DRAM 74.9（FY25 77.1%）− HBM 28.1（BofA）
A6: HBM | B6: =28.1 -> 28.1 | C6: =Mkt!C31 -> 40.779873 | D6: =Mkt!D31 -> 91.895875 | E6: =Mkt!E31 -> 139.59421 | F6: =Mkt!D32 -> 91.895875 | G6: =Mkt!E32 -> 95.177871 | H6: 2026 起＝HBM 市場 × 市占（Mkt）；BofA 2026E 45.7、CLSA 49.4
A7: NAND | B7: =20.69 -> 20.69 | C7: =Q!J6 -> 87.877277 | D7: =C7*(1+nb27)*(1+np27_A) -> 139.19761 | E7: =D7*(1+nb28)*(1+np28_A) -> 133.6297 | F7: =C7*(1+nb27)*(1+np27_B) -> 131.81592 | G7: =F7*(1+nb28)*(1+np28_B) -> 55.362684 | H7: FY25 NAND 21.3%
A8: 其他 | B8: =B4-74.9-20.69 -> 1.557 | C8: =Q!J7 -> 1.168032 | D8: =other_y -> 1.6 | E8: =other_y -> 1.6 | F8: =other_y -> 1.6 | G8: =other_y -> 1.6
A9: HBM ÷ 營收 | B9: =B6/B4 -> 0.28925237 | C9: =C6/C4 -> 0.11947722 | D9: =D6/D4 -> 0.17172627 | E9: =E6/E4 -> 0.23746744 | F9: =F6/F4 -> 0.17805272 | G9: =G6/G4 -> 0.2980334
A10: 折舊攤銷 | B10: =SUM(Q!B13:E13) -> 13.89 | C10: =Q!J13 -> 16.654 | D10: =C10+(C17-C10)/da_life -> 23.0632 | E10: =D10+(D17-D10)/da_life -> 30.91056 | F10: =C10+(C17-C10)/da_life -> 23.0632 | G10: =F10+(F17-F10)/da_life -> 30.91056 | H10: 2027 起：D&A_t－1＋(capex_t－1 − D&A_t－1) ÷ 年數
A11: 成本量指數年增 | D11: =w_c*(1+cb27)+w_h*(1+Mkt!D33)+w_n*(1+nb27) -> 1.1705769 | E11: =w_c*(1+cb28)+w_h*(1+Mkt!E33)+w_n*(1+nb28) -> 1.2317857 | F11: =w_c*(1+cb27)+w_h*(1+Mkt!D33)+w_n*(1+nb27) -> 1.1705769 | G11: =w_c*(1+cb28)+w_h*(1+Mkt!E33)+w_n*(1+nb28) -> 1.2317857 | H11: HBM 位元依 SK 海力士 HBM 位元成長
A12: 營業成本 | B12: =B4*0.37 -> 35.94439 | C12: =Q!J8 -> 53.382904 | D12: =(C12-da_cogs*C10)*D11*(1-costdn_y)+da_cogs*D10 -> 61.206017 | E12: =(D12-da_cogs*D10)*E11*(1-costdn_y)+da_cogs*E10 -> 72.661706 | F12: =(C12-da_cogs*C10)*F11*(1-costdn_y)+da_cogs*F10 -> 61.206017 | G12: =(F12-da_cogs*F10)*G11*(1-costdn_y)+da_cogs*G10 -> 72.661706 | H12: 現金成本 × 量 × (1 − 年降)＋折舊
A13: 營業費用 | B13: =B4-B12-B14 -> 13.99561 | C13: =Q!J9 -> 22.059749 | D13: =opex_fix*4*(1+opex_g)+opex_var*D4 -> 31.751109 | E13: =opex_fix*4*(1+opex_g)^2+opex_var*E4 -> 34.888747 | F13: =opex_fix*4*(1+opex_g)+opex_var*F4 -> 30.857457 | G13: =opex_fix*4*(1+opex_g)^2+opex_var*G4 -> 22.269593
A14: 營業利益 | B14: =SUM(Q!B10:E10) -> 47.207 | C14: =Q!J10 -> 265.87658 | D14: =D4-D12-D13 -> 442.17285 | E14: =E4-E12-E13 -> 480.29523 | F14: =F4-F12-F13 -> 424.05263 | G14: =G4-G12-G13 -> 224.42174
A15: 營業利益率 | B15: =B14/B4 -> 0.48593369 | C15: =C14/C4 -> 0.77896747 | D15: =D14/D4 -> 0.82629056 | E15: =E14/E4 -> 0.81704305 | F15: =F14/F4 -> 0.82162255 | G15: =G14/G4 -> 0.7027387
A16: 淨利 | B16: =SUM(Q!B12:E12) -> 42.948 | C16: =Q!J12 -> 264.95616 | D16: =(D14+rf*C22)*(1-tax) -> 343.23935 | E16: =(E14+rf*D22)*(1-tax) -> 374.9344 | F16: =(F14+rf*C22)*(1-tax) -> 329.28679 | G16: =(G14+rf*F22)*(1-tax) -> 177.80438 | H16: 2026 含 H1 Kioxia 相關一次性收益約 63 兆（業外）
A17: 資本支出 | B17: =27.519 -> 27.519 | C17: =cap26 -> 48.7 | D17: =cap27 -> 62.3 | E17: =cap28 -> 71.2 | F17: =cap27 -> 62.3 | G17: =cap28 -> 71.2
A18: 自由現金流（淨利＋折舊 − 資本支出） | B18: =B16+B10-B17 -> 29.319 | C18: =C16+C10-C17 -> 232.91016 | D18: =D16+D10-D17 -> 304.00255 | E18: =E16+E10-E17 -> 334.64496 | F18: =F16+F10-F17 -> 290.04999 | G18: =G16+G10-G17 -> 137.51494 | H18: 未計營運資金變動
A19: 股利 | C19: =div26_h2 -> 0.54 | D19: =dps27*C23/1000000 -> 3.2004764 | E19: =dps28*D23/1000000 -> 3.2461603 | F19: =dps27*C23/1000000 -> 3.2004764 | G19: =dps28*F23/1000000 -> 3.267413 | H19: 2026 只列下半年（上半年已在 6 月底權益中）
A20: 買回 | C20: =bb26 -> 40 | D20: =MAX(0,payout*D18-D19) -> 148.8008 | E20: =MAX(0,payout*E18-E19) -> 164.07632 | F20: =MAX(0,payout*F18-F19) -> 141.82452 | G20: =MAX(0,payout*G18-G19) -> 65.490058
A21: 期末權益 | C21: =eq_h1+(Q!H12+Q!I12)+ads_kw-C20-C19 -> 393.24016 | D21: =C21+D16-D19-D20 -> 584.47823 | E21: =D21+E16-E19-E20 -> 792.09015 | F21: =C21+F16-F19-F20 -> 577.50195 | G21: =F21+G16-G19-G20 -> 686.54886 | H21: 2026：6 月底權益＋下半年淨利＋ADS − 買回 − 股利
A22: 期末淨現金 | C22: =nc_h1+(Q!H12+Q!I12)+(Q!H13+Q!I13)-C17*0.6+ads_kw-C20-C19 -> 179.62716 | D22: =C22+D18-D19-D20 -> 331.62843 | E22: =D22+E18-E19-E20 -> 498.95091 | F22: =C22+F18-F19-F20 -> 324.65215 | G22: =F22+G18-G19-G20 -> 393.40962 | H22: 2026 下半年資本支出取全年約 60%（上半年實付 18.3）
A23: 期末流通股數 | C23: =sh_h1+ads_sh-bb26_sh -> 704.7955 | D23: =C23-D20/bb_px*1000000 -> 618.43404 | E23: =D23-E20/bb_px*1000000 -> 523.20692 | F23: =C23-F20/bb_px*1000000 -> 622.48295 | G23: =F23-G20/bb_px*1000000 -> 584.47363
A24: 每股淨值 BVPS | C24: =C21/C23*1000000 -> 557949.3 | D24: =D21/D23*1000000 -> 945093.89 | E24: =E21/E23*1000000 -> 1513913.7 | F24: =F21/F23*1000000 -> 927739.38 | G24: =G21/G23*1000000 -> 1174644.7
A25: 每股盈餘 EPS（期末股數） | C25: =C16/C23*1000000 -> 375933.38 | D25: =D16/D23*1000000 -> 555013.68 | E25: =E16/E23*1000000 -> 716608.26 | F25: =F16/F23*1000000 -> 528989.24 | G25: =G16/G23*1000000 -> 304212.84
A26: ROE（期末權益） | C26: =C16/C21 -> 0.67377696 | D26: =D16/D21 -> 0.58725771 | E26: =E16/E21 -> 0.47334814 | F26: =F16/F21 -> 0.57019165 | G26: =G16/G21 -> 0.25898285
A30: 2025A 營業成本與營業費用的拆分未取得一手數字；B12 以 37% 營收示意（只影響 2025 欄顯示，不影響 2026 以後）

Sheet Val
A1: Val — 估值（P/B 為主、P/E 對照）。隱含股價 ÷ 目前股價 − 1
A3: 方法 | B3: 倍數 | C3: 淨值／盈餘基準 | D3: 情境 | E3: 每股基準（韓元） | F3: 隱含股價 | G3: 相對目前
A4: P/B 1.0x | B4: =pb_1 -> 1 | C4: 2026 年底 BVPS | D4: 共用 | E4: =Y!C24 -> 557949.3 | F4: =B4*E4 -> 557949.3 | G4: =F4/px-1 -> -0.67617568
A5: P/B 歷史中位 1.6x | B5: =pb_2 -> 1.6 | C5: 2026 年底 BVPS | D5: 共用 | E5: =Y!C24 -> 557949.3 | F5: =B5*E5 -> 892718.88 | G5: =F5/px-1 -> -0.48188109
A6: P/B 券商遠期 3.3x | B6: =pb_3 -> 3.3 | C6: 2026 年底 BVPS | D6: 共用 | E6: =Y!C24 -> 557949.3 | F6: =B6*E6 -> 1841232.7 | G6: =F6/px-1 -> 0.068620248
A7: P/B 1.0x | B7: =pb_1 -> 1 | C7: 2027 年底 BVPS | D7: A | E7: =Y!D24 -> 945093.89 | F7: =B7*E7 -> 945093.89 | G7: =F7/px-1 -> -0.45148352
A8: P/B 歷史中位 1.6x | B8: =pb_2 -> 1.6 | C8: 2027 年底 BVPS | D8: A | E8: =Y!D24 -> 945093.89 | F8: =B8*E8 -> 1512150.2 | G8: =F8/px-1 -> -0.12237364
A9: P/B 券商遠期 3.3x | B9: =pb_3 -> 3.3 | C9: 2027 年底 BVPS | D9: A | E9: =Y!D24 -> 945093.89 | F9: =B9*E9 -> 3118809.8 | G9: =F9/px-1 -> 0.81010437
A10: P/B 1.0x | B10: =pb_1 -> 1 | C10: 2027 年底 BVPS | D10: B | E10: =Y!F24 -> 927739.38 | F10: =B10*E10 -> 927739.38 | G10: =F10/px-1 -> -0.46155579
A11: P/B 歷史中位 1.6x | B11: =pb_2 -> 1.6 | C11: 2027 年底 BVPS | D11: B | E11: =Y!F24 -> 927739.38 | F11: =B11*E11 -> 1484383 | G11: =F11/px-1 -> -0.13848926
A12: P/B 券商遠期 3.3x | B12: =pb_3 -> 3.3 | C12: 2027 年底 BVPS | D12: B | E12: =Y!F24 -> 927739.38 | F12: =B12*E12 -> 3061539.9 | G12: =F12/px-1 -> 0.7768659
A13: P/B 1.0x | B13: =pb_1 -> 1 | C13: 2028 年底 BVPS | D13: A | E13: =Y!E24 -> 1513913.7 | F13: =B13*E13 -> 1513913.7 | G13: =F13/px-1 -> -0.12135012
A14: P/B 歷史中位 1.6x | B14: =pb_2 -> 1.6 | C14: 2028 年底 BVPS | D14: A | E14: =Y!E24 -> 1513913.7 | F14: =B14*E14 -> 2422262 | G14: =F14/px-1 -> 0.40583981
A15: P/B 券商遠期 3.3x | B15: =pb_3 -> 3.3 | C15: 2028 年底 BVPS | D15: A | E15: =Y!E24 -> 1513913.7 | F15: =B15*E15 -> 4995915.4 | G15: =F15/px-1 -> 1.8995446
A16: P/B 1.0x | B16: =pb_1 -> 1 | C16: 2028 年底 BVPS | D16: B | E16: =Y!G24 -> 1174644.7 | F16: =B16*E16 -> 1174644.7 | G16: =F16/px-1 -> -0.31825612
A17: P/B 歷史中位 1.6x | B17: =pb_2 -> 1.6 | C17: 2028 年底 BVPS | D17: B | E17: =Y!G24 -> 1174644.7 | F17: =B17*E17 -> 1879431.5 | G17: =F17/px-1 -> 0.090790206
A18: P/B 券商遠期 3.3x | B18: =pb_3 -> 3.3 | C18: 2028 年底 BVPS | D18: B | E18: =Y!G24 -> 1174644.7 | F18: =B18*E18 -> 3876327.5 | G18: =F18/px-1 -> 1.2497548
A19: P/E 4x | B19: =pe_1 -> 4 | C19: 2027 EPS | D19: A | E19: =Y!D25 -> 555013.68 | F19: =B19*E19 -> 2220054.7 | G19: =F19/px-1 -> 0.28848213
A20: P/E 8x | B20: =pe_2 -> 8 | C20: 2027 EPS | D20: A | E20: =Y!D25 -> 555013.68 | F20: =B20*E20 -> 4440109.4 | G20: =F20/px-1 -> 1.5769643
A21: P/E 12x | B21: =pe_3 -> 12 | C21: 2027 EPS | D21: A | E21: =Y!D25 -> 555013.68 | F21: =B21*E21 -> 6660164.1 | G21: =F21/px-1 -> 2.8654464
A22: P/E 4x | B22: =pe_1 -> 4 | C22: 2027 EPS | D22: B | E22: =Y!F25 -> 528989.24 | F22: =B22*E22 -> 2115957 | G22: =F22/px-1 -> 0.22806556
A23: P/E 8x | B23: =pe_2 -> 8 | C23: 2027 EPS | D23: B | E23: =Y!F25 -> 528989.24 | F23: =B23*E23 -> 4231913.9 | G23: =F23/px-1 -> 1.4561311
A24: P/E 12x | B24: =pe_3 -> 12 | C24: 2027 EPS | D24: B | E24: =Y!F25 -> 528989.24 | F24: =B24*E24 -> 6347870.9 | G24: =F24/px-1 -> 2.6841967
A25: P/E 4x | B25: =pe_1 -> 4 | C25: 2028 EPS | D25: A | E25: =Y!E25 -> 716608.26 | F25: =B25*E25 -> 2866433 | G25: =F25/px-1 -> 0.66362916
A26: P/E 8x | B26: =pe_2 -> 8 | C26: 2028 EPS | D26: A | E26: =Y!E25 -> 716608.26 | F26: =B26*E26 -> 5732866.1 | G26: =F26/px-1 -> 2.3272583
A27: P/E 12x | B27: =pe_3 -> 12 | C27: 2028 EPS | D27: A | E27: =Y!E25 -> 716608.26 | F27: =B27*E27 -> 8599299.1 | G27: =F27/px-1 -> 3.9908875
A28: P/E 4x | B28: =pe_1 -> 4 | C28: 2028 EPS | D28: B | E28: =Y!G25 -> 304212.84 | F28: =B28*E28 -> 1216851.3 | G28: =F28/px-1 -> -0.2937601
A29: P/E 8x | B29: =pe_2 -> 8 | C29: 2028 EPS | D29: B | E29: =Y!G25 -> 304212.84 | F29: =B29*E29 -> 2433702.7 | G29: =F29/px-1 -> 0.41247979
A30: P/E 12x | B30: =pe_3 -> 12 | C30: 2028 EPS | D30: B | E30: =Y!G25 -> 304212.84 | F30: =B30*E30 -> 3650554 | G30: =F30/px-1 -> 1.1187197
A32: 讀法：循環股在盈餘高峰時 P/E 低、P/B 高；若 2028 盈餘回落（情境 B），市場通常在 2027 就以 2028 的淨值與盈餘定價。

Sheet Sens
A1: Sens — 一次只動一個輸入（其餘＝基準）。輸出：2027E 營業利益（情境 A）、2028E 營業利益（情境 B）
A3: 輸入 | B3: 設定 | C3: 2027E 營業利益 A | D3: 相對基準 | E3: 說明
A4: 基準 | B4: — | C4: =((Y!C5*(1+cb27)*(1+cp27_A))+(MIN(Mkt!D14,Mkt!C14*(1+hbm_sup27))*hbm_p26*(1+hbm_p27_A)*sh27*fx/1000)+(Y!C7*(1+nb27)*(1+np27_A))+other_y)-((Y!C12-da_cogs*Y!C10)*Y!D11*(1-costdn_y)+da_cogs*Y!D10)-(opex_fix*4*(1+opex_g)+opex_var*((Y!C5*(1+cb27)*(1+cp27_A))+(MIN(Mkt!D14,Mkt!C14*(1+hbm_sup27))*hbm_p26*(1+hbm_p27_A)*sh27*fx/1000)+(Y!C7*(1+nb27)*(1+np27_A))+other_y)) -> 442.17285 | D4: =C4/C$4-1 -> 0
A5: 一般 DRAM 2027 價 +15% | B5: cp27_A→cp27_A_lo | C5: =((Y!C5*(1+cb27)*(1+cp27_A_lo))+(MIN(Mkt!D14,Mkt!C14*(1+hbm_sup27))*hbm_p26*(1+hbm_p27_A)*sh27*fx/1000)+(Y!C7*(1+nb27)*(1+np27_A))+other_y)-((Y!C12-da_cogs*Y!C10)*Y!D11*(1-costdn_y)+da_cogs*Y!D10)-(opex_fix*4*(1+opex_g)+opex_var*((Y!C5*(1+cb27)*(1+cp27_A_lo))+(MIN(Mkt!D14,Mkt!C14*(1+hbm_sup27))*hbm_p26*(1+hbm_p27_A)*sh27*fx/1000)+(Y!C7*(1+nb27)*(1+np27_A))+other_y)) -> 408.91646 | D5: =C5/C$4-1 -> -0.075211271
A6: 一般 DRAM 2027 價 +45% | B6: cp27_A→cp27_A_hi | C6: =((Y!C5*(1+cb27)*(1+cp27_A_hi))+(MIN(Mkt!D14,Mkt!C14*(1+hbm_sup27))*hbm_p26*(1+hbm_p27_A)*sh27*fx/1000)+(Y!C7*(1+nb27)*(1+np27_A))+other_y)-((Y!C12-da_cogs*Y!C10)*Y!D11*(1-costdn_y)+da_cogs*Y!D10)-(opex_fix*4*(1+opex_g)+opex_var*((Y!C5*(1+cb27)*(1+cp27_A_hi))+(MIN(Mkt!D14,Mkt!C14*(1+hbm_sup27))*hbm_p26*(1+hbm_p27_A)*sh27*fx/1000)+(Y!C7*(1+nb27)*(1+np27_A))+other_y)) -> 475.42923 | D6: =C6/C$4-1 -> 0.075211271
A7: HBM 2027 價 +38%（BofA） | B7: hbm_p27_A→hbm_p27_A_lo | C7: =((Y!C5*(1+cb27)*(1+cp27_A))+(MIN(Mkt!D14,Mkt!C14*(1+hbm_sup27))*hbm_p26*(1+hbm_p27_A_lo)*sh27*fx/1000)+(Y!C7*(1+nb27)*(1+np27_A))+other_y)-((Y!C12-da_cogs*Y!C10)*Y!D11*(1-costdn_y)+da_cogs*Y!D10)-(opex_fix*4*(1+opex_g)+opex_var*((Y!C5*(1+cb27)*(1+cp27_A))+(MIN(Mkt!D14,Mkt!C14*(1+hbm_sup27))*hbm_p26*(1+hbm_p27_A_lo)*sh27*fx/1000)+(Y!C7*(1+nb27)*(1+np27_A))+other_y)) -> 421.73827 | D7: =C7/C$4-1 -> -0.046214008
A8: HBM 2027 價 +121%（TrendForce） | B8: hbm_p27_A→hbm_p27_A_hi | C8: =((Y!C5*(1+cb27)*(1+cp27_A))+(MIN(Mkt!D14,Mkt!C14*(1+hbm_sup27))*hbm_p26*(1+hbm_p27_A_hi)*sh27*fx/1000)+(Y!C7*(1+nb27)*(1+np27_A))+other_y)-((Y!C12-da_cogs*Y!C10)*Y!D11*(1-costdn_y)+da_cogs*Y!D10)-(opex_fix*4*(1+opex_g)+opex_var*((Y!C5*(1+cb27)*(1+cp27_A))+(MIN(Mkt!D14,Mkt!C14*(1+hbm_sup27))*hbm_p26*(1+hbm_p27_A_hi)*sh27*fx/1000)+(Y!C7*(1+nb27)*(1+np27_A))+other_y)) -> 462.12089 | D8: =C8/C$4-1 -> 0.045113675
A9: SK HBM 市占 2027 38% | B9: sh27→sh27_lo | C9: =((Y!C5*(1+cb27)*(1+cp27_A))+(MIN(Mkt!D14,Mkt!C14*(1+hbm_sup27))*hbm_p26*(1+hbm_p27_A)*sh27_lo*fx/1000)+(Y!C7*(1+nb27)*(1+np27_A))+other_y)-((Y!C12-da_cogs*Y!C10)*Y!D11*(1-costdn_y)+da_cogs*Y!D10)-(opex_fix*4*(1+opex_g)+opex_var*((Y!C5*(1+cb27)*(1+cp27_A))+(MIN(Mkt!D14,Mkt!C14*(1+hbm_sup27))*hbm_p26*(1+hbm_p27_A)*sh27_lo*fx/1000)+(Y!C7*(1+nb27)*(1+np27_A))+other_y)) -> 433.8322 | D9: =C9/C$4-1 -> -0.01886286
A10: SK HBM 市占 2027 48% | B10: sh27→sh27_hi | C10: =((Y!C5*(1+cb27)*(1+cp27_A))+(MIN(Mkt!D14,Mkt!C14*(1+hbm_sup27))*hbm_p26*(1+hbm_p27_A)*sh27_hi*fx/1000)+(Y!C7*(1+nb27)*(1+np27_A))+other_y)-((Y!C12-da_cogs*Y!C10)*Y!D11*(1-costdn_y)+da_cogs*Y!D10)-(opex_fix*4*(1+opex_g)+opex_var*((Y!C5*(1+cb27)*(1+cp27_A))+(MIN(Mkt!D14,Mkt!C14*(1+hbm_sup27))*hbm_p26*(1+hbm_p27_A)*sh27_hi*fx/1000)+(Y!C7*(1+nb27)*(1+np27_A))+other_y)) -> 454.68381 | D10: =C10/C$4-1 -> 0.028294291
A11: HBM 2027 供給 +50% | B11: hbm_sup27→hbm_sup27_lo | C11: =((Y!C5*(1+cb27)*(1+cp27_A))+(MIN(Mkt!D14,Mkt!C14*(1+hbm_sup27_lo))*hbm_p26*(1+hbm_p27_A)*sh27*fx/1000)+(Y!C7*(1+nb27)*(1+np27_A))+other_y)-((Y!C12-da_cogs*Y!C10)*Y!D11*(1-costdn_y)+da_cogs*Y!D10)-(opex_fix*4*(1+opex_g)+opex_var*((Y!C5*(1+cb27)*(1+cp27_A))+(MIN(Mkt!D14,Mkt!C14*(1+hbm_sup27_lo))*hbm_p26*(1+hbm_p27_A)*sh27*fx/1000)+(Y!C7*(1+nb27)*(1+np27_A))+other_y)) -> 439.34779 | D11: =C11/C$4-1 -> -0.0063890334
A12: HBM 2027 供給 +63% | B12: hbm_sup27→hbm_sup27_hi | C12: =((Y!C5*(1+cb27)*(1+cp27_A))+(MIN(Mkt!D14,Mkt!C14*(1+hbm_sup27_hi))*hbm_p26*(1+hbm_p27_A)*sh27*fx/1000)+(Y!C7*(1+nb27)*(1+np27_A))+other_y)-((Y!C12-da_cogs*Y!C10)*Y!D11*(1-costdn_y)+da_cogs*Y!D10)-(opex_fix*4*(1+opex_g)+opex_var*((Y!C5*(1+cb27)*(1+cp27_A))+(MIN(Mkt!D14,Mkt!C14*(1+hbm_sup27_hi))*hbm_p26*(1+hbm_p27_A)*sh27*fx/1000)+(Y!C7*(1+nb27)*(1+np27_A))+other_y)) -> 446.69294 | D12: =C12/C$4-1 -> 0.010222453
A13: 一般 DRAM 位元 +5% | B13: cb27→cb27_lo | C13: =((Y!C5*(1+cb27_lo)*(1+cp27_A))+(MIN(Mkt!D14,Mkt!C14*(1+hbm_sup27))*hbm_p26*(1+hbm_p27_A)*sh27*fx/1000)+(Y!C7*(1+nb27)*(1+np27_A))+other_y)-((Y!C12-da_cogs*Y!C10)*Y!D11*(1-costdn_y)+da_cogs*Y!D10)-(opex_fix*4*(1+opex_g)+opex_var*((Y!C5*(1+cb27_lo)*(1+cp27_A))+(MIN(Mkt!D14,Mkt!C14*(1+hbm_sup27))*hbm_p26*(1+hbm_p27_A)*sh27*fx/1000)+(Y!C7*(1+nb27)*(1+np27_A))+other_y)) -> 429.07185 | D13: =C13/C$4-1 -> -0.029628682
A14: 一般 DRAM 位元 +15% | B14: cb27→cb27_hi | C14: =((Y!C5*(1+cb27_hi)*(1+cp27_A))+(MIN(Mkt!D14,Mkt!C14*(1+hbm_sup27))*hbm_p26*(1+hbm_p27_A)*sh27*fx/1000)+(Y!C7*(1+nb27)*(1+np27_A))+other_y)-((Y!C12-da_cogs*Y!C10)*Y!D11*(1-costdn_y)+da_cogs*Y!D10)-(opex_fix*4*(1+opex_g)+opex_var*((Y!C5*(1+cb27_hi)*(1+cp27_A))+(MIN(Mkt!D14,Mkt!C14*(1+hbm_sup27))*hbm_p26*(1+hbm_p27_A)*sh27*fx/1000)+(Y!C7*(1+nb27)*(1+np27_A))+other_y)) -> 455.27384 | D14: =C14/C$4-1 -> 0.029628682
A15: NAND 2027 價 +15% | B15: np27_A→np27_A_lo | C15: =((Y!C5*(1+cb27)*(1+cp27_A))+(MIN(Mkt!D14,Mkt!C14*(1+hbm_sup27))*hbm_p26*(1+hbm_p27_A)*sh27*fx/1000)+(Y!C7*(1+nb27)*(1+np27_A_lo))+other_y)-((Y!C12-da_cogs*Y!C10)*Y!D11*(1-costdn_y)+da_cogs*Y!D10)-(opex_fix*4*(1+opex_g)+opex_var*((Y!C5*(1+cb27)*(1+cp27_A))+(MIN(Mkt!D14,Mkt!C14*(1+hbm_sup27))*hbm_p26*(1+hbm_p27_A)*sh27*fx/1000)+(Y!C7*(1+nb27)*(1+np27_A_lo))+other_y)) -> 425.08845 | D15: =C15/C$4-1 -> -0.038637373
A16: NAND 2027 價 +45% | B16: np27_A→np27_A_hi | C16: =((Y!C5*(1+cb27)*(1+cp27_A))+(MIN(Mkt!D14,Mkt!C14*(1+hbm_sup27))*hbm_p26*(1+hbm_p27_A)*sh27*fx/1000)+(Y!C7*(1+nb27)*(1+np27_A_hi))+other_y)-((Y!C12-da_cogs*Y!C10)*Y!D11*(1-costdn_y)+da_cogs*Y!D10)-(opex_fix*4*(1+opex_g)+opex_var*((Y!C5*(1+cb27)*(1+cp27_A))+(MIN(Mkt!D14,Mkt!C14*(1+hbm_sup27))*hbm_p26*(1+hbm_p27_A)*sh27*fx/1000)+(Y!C7*(1+nb27)*(1+np27_A_hi))+other_y)) -> 455.23738 | D16: =C16/C$4-1 -> 0.029546226
A17: 匯率 1,350 | B17: fx→fx_lo | C17: =((Y!C5*(1+cb27)*(1+cp27_A))+(MIN(Mkt!D14,Mkt!C14*(1+hbm_sup27))*hbm_p26*(1+hbm_p27_A)*sh27*fx_lo/1000)+(Y!C7*(1+nb27)*(1+np27_A))+other_y)-((Y!C12-da_cogs*Y!C10)*Y!D11*(1-costdn_y)+da_cogs*Y!D10)-(opex_fix*4*(1+opex_g)+opex_var*((Y!C5*(1+cb27)*(1+cp27_A))+(MIN(Mkt!D14,Mkt!C14*(1+hbm_sup27))*hbm_p26*(1+hbm_p27_A)*sh27*fx_lo/1000)+(Y!C7*(1+nb27)*(1+np27_A))+other_y)) -> 437.85568 | D17: =C17/C$4-1 -> -0.0097635229 | E17: 只影響 HBM（美元計價）
A18: 匯率 1,500 | B18: fx→fx_hi | C18: =((Y!C5*(1+cb27)*(1+cp27_A))+(MIN(Mkt!D14,Mkt!C14*(1+hbm_sup27))*hbm_p26*(1+hbm_p27_A)*sh27*fx_hi/1000)+(Y!C7*(1+nb27)*(1+np27_A))+other_y)-((Y!C12-da_cogs*Y!C10)*Y!D11*(1-costdn_y)+da_cogs*Y!D10)-(opex_fix*4*(1+opex_g)+opex_var*((Y!C5*(1+cb27)*(1+cp27_A))+(MIN(Mkt!D14,Mkt!C14*(1+hbm_sup27))*hbm_p26*(1+hbm_p27_A)*sh27*fx_hi/1000)+(Y!C7*(1+nb27)*(1+np27_A))+other_y)) -> 447.10675 | D18: =C18/C$4-1 -> 0.011158312
A19: 單位成本年降 5% | B19: costdn_y→costdn_y_lo | C19: =((Y!C5*(1+cb27)*(1+cp27_A))+(MIN(Mkt!D14,Mkt!C14*(1+hbm_sup27))*hbm_p26*(1+hbm_p27_A)*sh27*fx/1000)+(Y!C7*(1+nb27)*(1+np27_A))+other_y)-((Y!C12-da_cogs*Y!C10)*Y!D11*(1-costdn_y_lo)+da_cogs*Y!D10)-(opex_fix*4*(1+opex_g)+opex_var*((Y!C5*(1+cb27)*(1+cp27_A))+(MIN(Mkt!D14,Mkt!C14*(1+hbm_sup27))*hbm_p26*(1+hbm_p27_A)*sh27*fx/1000)+(Y!C7*(1+nb27)*(1+np27_A))+other_y)) -> 439.92567 | D19: =C19/C$4-1 -> -0.0050821173
A20: 單位成本年降 15% | B20: costdn_y→costdn_y_hi | C20: =((Y!C5*(1+cb27)*(1+cp27_A))+(MIN(Mkt!D14,Mkt!C14*(1+hbm_sup27))*hbm_p26*(1+hbm_p27_A)*sh27*fx/1000)+(Y!C7*(1+nb27)*(1+np27_A))+other_y)-((Y!C12-da_cogs*Y!C10)*Y!D11*(1-costdn_y_hi)+da_cogs*Y!D10)-(opex_fix*4*(1+opex_g)+opex_var*((Y!C5*(1+cb27)*(1+cp27_A))+(MIN(Mkt!D14,Mkt!C14*(1+hbm_sup27))*hbm_p26*(1+hbm_p27_A)*sh27*fx/1000)+(Y!C7*(1+nb27)*(1+np27_A))+other_y)) -> 444.42002 | D20: =C20/C$4-1 -> 0.0050821173
A22: 核對：基準列應等於 Y!D14 | C22: =C4-Y!D14 -> 0
A24: 2028E 營業利益（情境 B）
A25: 基準 | B25: — | C25: =((Y!F5*(1+cb28)*(1+cp28_B))+(Mkt!E22*Mkt!D27*(1+hbm_p28_B)*sh28*fx/1000)+(Y!F7*(1+nb28)*(1+np28_B))+other_y)-Y!G12-(opex_fix*4*(1+opex_g)^2+opex_var*((Y!F5*(1+cb28)*(1+cp28_B))+(Mkt!E22*Mkt!D27*(1+hbm_p28_B)*sh28*fx/1000)+(Y!F7*(1+nb28)*(1+np28_B))+other_y)) -> 224.42174 | D25: =C25/C$25-1 -> 0
A26: 一般 DRAM 2028 價 −60% | B26: cp28_B→cp28_B_lo | C26: =((Y!F5*(1+cb28)*(1+cp28_B_lo))+(Mkt!E22*Mkt!D27*(1+hbm_p28_B)*sh28*fx/1000)+(Y!F7*(1+nb28)*(1+np28_B))+other_y)-Y!G12-(opex_fix*4*(1+opex_g)^2+opex_var*((Y!F5*(1+cb28)*(1+cp28_B_lo))+(Mkt!E22*Mkt!D27*(1+hbm_p28_B)*sh28*fx/1000)+(Y!F7*(1+nb28)*(1+np28_B))+other_y)) -> 192.55104 | D26: =C26/C$25-1 -> -0.14201253
A27: 一般 DRAM 2028 價 −30% | B27: cp28_B→cp28_B_hi | C27: =((Y!F5*(1+cb28)*(1+cp28_B_hi))+(Mkt!E22*Mkt!D27*(1+hbm_p28_B)*sh28*fx/1000)+(Y!F7*(1+nb28)*(1+np28_B))+other_y)-Y!G12-(opex_fix*4*(1+opex_g)^2+opex_var*((Y!F5*(1+cb28)*(1+cp28_B_hi))+(Mkt!E22*Mkt!D27*(1+hbm_p28_B)*sh28*fx/1000)+(Y!F7*(1+nb28)*(1+np28_B))+other_y)) -> 288.16314 | D27: =C27/C$25-1 -> 0.28402506
A28: NAND 2028 價 −70% | B28: np28_B→np28_B_lo | C28: =((Y!F5*(1+cb28)*(1+cp28_B))+(Mkt!E22*Mkt!D27*(1+hbm_p28_B)*sh28*fx/1000)+(Y!F7*(1+nb28)*(1+np28_B_lo))+other_y)-Y!G12-(opex_fix*4*(1+opex_g)^2+opex_var*((Y!F5*(1+cb28)*(1+cp28_B))+(Mkt!E22*Mkt!D27*(1+hbm_p28_B)*sh28*fx/1000)+(Y!F7*(1+nb28)*(1+np28_B_lo))+other_y)) -> 216.8845 | D28: =C28/C$25-1 -> -0.033585133
A29: NAND 2028 價 −40% | B29: np28_B→np28_B_hi | C29: =((Y!F5*(1+cb28)*(1+cp28_B))+(Mkt!E22*Mkt!D27*(1+hbm_p28_B)*sh28*fx/1000)+(Y!F7*(1+nb28)*(1+np28_B_hi))+other_y)-Y!G12-(opex_fix*4*(1+opex_g)^2+opex_var*((Y!F5*(1+cb28)*(1+cp28_B))+(Mkt!E22*Mkt!D27*(1+hbm_p28_B)*sh28*fx/1000)+(Y!F7*(1+nb28)*(1+np28_B_hi))+other_y)) -> 262.10791 | D29: =C29/C$25-1 -> 0.16792567
A30: HBM 2028 價 −40% | B30: hbm_p28_B→hbm_p28_B_lo | C30: =((Y!F5*(1+cb28)*(1+cp28_B))+(Mkt!E22*Mkt!D27*(1+hbm_p28_B_lo)*sh28*fx/1000)+(Y!F7*(1+nb28)*(1+np28_B))+other_y)-Y!G12-(opex_fix*4*(1+opex_g)^2+opex_var*((Y!F5*(1+cb28)*(1+cp28_B))+(Mkt!E22*Mkt!D27*(1+hbm_p28_B_lo)*sh28*fx/1000)+(Y!F7*(1+nb28)*(1+np28_B))+other_y)) -> 206.28084 | D30: =C30/C$25-1 -> -0.08083398
A31: HBM 2028 價 −10% | B31: hbm_p28_B→hbm_p28_B_hi | C31: =((Y!F5*(1+cb28)*(1+cp28_B))+(Mkt!E22*Mkt!D27*(1+hbm_p28_B_hi)*sh28*fx/1000)+(Y!F7*(1+nb28)*(1+np28_B))+other_y)-Y!G12-(opex_fix*4*(1+opex_g)^2+opex_var*((Y!F5*(1+cb28)*(1+cp28_B))+(Mkt!E22*Mkt!D27*(1+hbm_p28_B_hi)*sh28*fx/1000)+(Y!F7*(1+nb28)*(1+np28_B))+other_y)) -> 242.56264 | D31: =C31/C$25-1 -> 0.08083398
A32: 一般 DRAM −60%、NAND −70%、HBM −40%（同時） | B32: cp28_B→cp28_B_lo, np28_B→np28_B_lo, hbm_p28_B→hbm_p28_B_lo | C32: =((Y!F5*(1+cb28)*(1+cp28_B_lo))+(Mkt!E22*Mkt!D27*(1+hbm_p28_B_lo)*sh28*fx/1000)+(Y!F7*(1+nb28)*(1+np28_B_lo))+other_y)-Y!G12-(opex_fix*4*(1+opex_g)^2+opex_var*((Y!F5*(1+cb28)*(1+cp28_B_lo))+(Mkt!E22*Mkt!D27*(1+hbm_p28_B_lo)*sh28*fx/1000)+(Y!F7*(1+nb28)*(1+np28_B_lo))+other_y)) -> 166.8729 | D32: =C32/C$25-1 -> -0.25643164
A34: 核對：基準列應等於 Y!G14 | C34: =C25-Y!G14 -> 0
A35: 讀法：情境 B 的 2028 價格（2027 均價 × 0.5）仍約為 2025 年均價的 2.7 倍；若回到 2025 年水準（類似 2023 年谷底），需要約 −80%，不在本表範圍

Sheet Recon
A1: Recon — 模型（由驅動因子正向推導）vs 市場共識（只作事後對照，不用來回推參數）；兆韓元
A3: 項目 | B3: 本模型 2026E | C3: 共識 2026E | D3: 本模型 2027E A | E3: 本模型 2027E B | F3: 共識 2027E | G3: 共識來源
A4: 營收 | B4: =Y!C4 -> 341.31923 | C4: 344.2 | D4: =Y!D4 -> 535.12997 | E4: =Y!F4 -> 516.11611 | F4: 531.3 | G4: MarketScreener 2026-10-02
A5: 營業利益 | B5: =Y!C14 -> 265.87658 | C5: 266.1 | D5: =Y!D14 -> 442.17285 | E5: =Y!F14 -> 424.05263 | F5: 417.2 | G5: MarketScreener；FnGuide 2027 391.8（08-14）
A6: 淨利 | B6: =Y!C16 -> 264.95616 | C6: 256.3 | D6: =Y!D16 -> 343.23935 | E6: =Y!F16 -> 329.28679 | F6: 336.2 | G6: MarketScreener
A7: HBM 營收 | B7: =Y!C6 -> 40.779873 | C7: 45.7 | D7: =Y!D6 -> 91.895875 | E7: =Y!F6 -> 91.895875 | G7: BofA 2026-09-13（2026E）
A9: 2026Q3E 營收：本模型 vs 共識 94.1（FnGuide，2026-09-25） | B9: =Q!H4 -> 96.311345 | C9: 94.1
A10: 2026Q3E 營業利益：本模型 vs 共識 74.1–78.1 | B10: =Q!H10 -> 76.086392 | C10: 76.1

Sheet Feedback
A1: Feedback — 回饋算力收支的摘要數字
A3: 每顆加速器 HBM 金額（GB300，2026 價） | B3: =nv_hbm -> 4.46 | C3: $K | D3: markets/chip_bridge v0.1
A4: 全市場每顆加速器平均 HBM 容量 2026／2027 | B4: =TEXT(Mkt!C18,"0")&" ／ "&TEXT(Mkt!D18,"0") -> 216 ／ 260 | C4: GB | D4: Mkt
A5: HBM 市場 2026／2027（情境 A） | B5: =TEXT(Mkt!C28,"0")&" ／ "&TEXT(Mkt!D28,"0") -> 55 ／ 154 | C5: $B | D5: Mkt
A6: SK 海力士 HBM 毛利率 | B6: 無法由公開資料分離 | C6: — | D6: 公司不揭露；TrendForce、三星、Micron 皆指出 2026 年一般 DRAM 毛利高於 HBM，Bloter 報導差距約 40 個百分點（單一來源）
A7: 2027 HBM 需求缺口（需求 − 供給） | B7: =Mkt!D23 -> 1.2325527 | C7: EB | D7: 加速器顆數預測隱含的位元需求高於供給成長；顆數預測可能偏高或價格會上漲

Sheet Sources
A1: 來源
A2: S1 SK hynix 424B4 招股書（2026-07） | B2: https://www.sec.gov/Archives/edgar/data/2120882/000119312526299963/d32785d424b4.htm
A3: S2 SK hynix 6-K 半年報（2026-08-18） | B3: https://www.sec.gov/Archives/edgar/data/2120882/000119312526354777/d147827d6k.htm
A4: Q2 2026 簡報（Investing.com） | B4: https://www.investing.com/news/company-news/sk-hynix-q2-2026-slides-record-revenue-76-operating-margin-93CH-4818489
A5: Q2 2026 法說逐字稿（Investing.com） | B5: https://ng.investing.com/news/transcripts/earnings-call-transcript-sk-hynix-posts-record-q2-2026-results-as-shares-fall-93CH-2622277
A6: 40 兆買回（Korea Herald 2026-08-19） | B6: https://www.koreaherald.com/article/10845792
A7: MarketScreener 共識（2026-10-02） | B7: https://www.marketscreener.com/quote/stock/SK-HYNIX-INC-6494929/finances/
A8: Herald Business：FnGuide 共識、目標價（2026-08-14） | B8: https://biz.heraldcorp.com/article/10841314
A9: BofA HBM 估計（Economy Tribune 2026-09-13） | B9: https://www.economytribune.co.kr/news/articleView.html?idxno=3903874
A10: Bloter（CLSA，2026-09-15） | B10: https://www.bloter.net/news/articleView.html?idxno=673654
A11: Counterpoint HBM 2Q26（SamMobile） | B11: https://www.sammobile.com/?p=16676368
A12: UBS 2027 HBM 市占（Korea Herald） | B12: https://www.koreaherald.com/article/10828143
A13: TrendForce 4Q26 價格（2026-09-30） | B13: https://www.trendforce.com/presscenter/news/20260930-13258.html
... A31: markets/chip_bridge v0.1（本 repo） | B31: markets/chip_bridge/dist/20261008_晶片內容橋接表_v0.1.xlsx
