Workbook

Sheet README
A1: SK 海力士 收支與估值模型 v0.2（記憶體樣板 v0.2） 2026-10-08
A2: 模型命題：SK 海力士的盈餘由兩條價格線決定——每季議價的一般 DRAM 與年約鎖價的 HBM；股價取決於這個循環在哪一年見頂，以及見頂時累積了多少淨值。
A4: 驅動因子 → 推導量
A5: Path（共用市場層）：一般 DRAM、NAND 合約價季增 → 季度指數（情境 A／B／C）；各公司依會計年度取平均，算年均價變動
A6: Mkt（共用市場層）：加速器顆數 × 每顆 GB → 需求位元；MIN(需求, 供給) → 出貨；× 單價 → HBM 市場（日曆年）
A7: Q：最後實績季 × 公司指引 × TrendForce 季價 → 基準年剩餘季度
A8: Y：前一年 × (1＋位元) × 價格指數比 → 一般 DRAM、NAND；Σ 各季 HBM 市場 × 市占 → HBM；成本量 × (1 − 年降)＋折舊 → 營業利益 → 淨利 → 權益 → 每股淨值
A9: Val：每股淨值 × P/B（主）、EPS × P/E（對照）
A10: Sens：各收入線同幅變動對營業利益的影響
A11: Recon：與共識、公司指引事後對照
A13: 情境：A＝2027–28 高檔持平（BofA、TrendForce 型）；B＝2027 Q2 見頂、2028 回落約一半（Citi、Bernstein 型）；C＝2028 回到 2025 年價格水準（完整谷底；歷史循環型）
A14: 幣別單位：兆韓元；會計年度：日曆年（K-IFRS 合併）
... A18: 已知簡化：營運資金未計；股數用期末；HBM 毛利率無法由公開資料分離。

Sheet In
A1: In — 輸入（藍字＝基準值；低／高供敏感度）。每列具名範圍＝鍵（指向 E 欄）。單位：兆韓元
A3: 鍵 | B3: 項目 | C3: 單位 | D3: 低 | E3: 基準 | F3: 高 | G3: 標記 | H3: 來源／說明
A4: A. 匯率、股價
A5: fx | B5: 美元兌韓元（2026–2028 平均） | C5: KRW/USD | D5: 1350 | E5: 1420 | F5: 1500 | G5: Derived | H5: Q2 2026 營收 79.32 兆 ≈ US$55.2B → 約 1,437
A6: px | B6: 股價（2026-10-07 收盤） | C6: KRW | E6: 1723000 | G6: Verified | H6: Investing.com；10-02 為 1,841,000
A7: B. 基準年剩餘季度（公司指引＋TrendForce）
A8: q3_db | B8: Q3 DRAM 位元季增 | C8: % | D8: 0.08 | E8: 0.1 | F8: 0.12 | G8: Verified | H8: 公司 Q2 法說：約 +10%
A9: q3_dp | B9: Q3 DRAM 混合 ASP 季增 | C9: % | D9: 0.08 | E9: 0.12 | F9: 0.16 | G9: Derived | H9: TrendForce 一般 DRAM +13–18%；HBM 年約鎖價拉低混合值
A10: q3_nb | B10: Q3 NAND 位元季增 | C10: % | D10: 0 | E10: 0.02 | F10: 0.04 | G10: Verified | H10: 公司：低個位數
A11: q3_np | B11: Q3 NAND ASP 季增 | C11: % | D11: 0.1 | E11: 0.125 | F11: 0.2 | G11: Interested-party | H11: TrendForce +10–15%；MS 實際約 +20%
A12: q4_db | B12: Q4 DRAM 位元季增 | C12: % | D12: 0 | E12: 0.05 | F12: 0.08 | G12: Assumed | H12: 公司：下半年位元成長優於上半年
A13: q4_dp | B13: Q4 DRAM 混合 ASP 季增 | C13: % | D13: 0.05 | E13: 0.1 | F13: 0.15 | G13: Derived | H13: TrendForce +10–15%；BofA 約 +8%
A14: q4_nb | B14: Q4 NAND 位元季增 | C14: % | D14: 0 | E14: 0.05 | F14: 0.08 | G14: Assumed
A15: q4_np | B15: Q4 NAND ASP 季增 | C15: % | D15: 0.1 | E15: 0.175 | F15: 0.2 | G15: Interested-party | H15: TrendForce +15–20%
A16: da_q3 | B16: Q3 折舊攤銷 | C16: 兆韓元 | E16: 4.3 | G16: Assumed | H16: Q1 3.726、Q2 4.028 延伸
A17: da_q4 | B17: Q4 折舊攤銷 | C17: 兆韓元 | E17: 4.6 | G17: Assumed
A18: costdn_q | B18: 單位成本季降 | C18: % | D18: 0.01 | E18: 0.03 | F18: 0.05 | G18: Assumed
A19: opex_fix_q | B19: 營業費用固定部分（每季） | C19: 兆韓元 | E19: 1.5 | G19: Derived | H19: Q1、Q2 2026 營業費用 3.97、5.24 對營收迴歸
A20: nonop_q | B20: 下半年每季業外淨收益 | C20: 兆韓元 | D20: 0.5 | E20: 1 | F20: 2 | G20: Assumed | H20: 淨現金 × 約 2%
A21: C. 年度驅動（公司別）
A22: cb_1 | B22: 一般 DRAM 位元成長 第 1 年 | C22: % | D22: 0.05 | E22: 0.1 | F22: 0.15 | G22: Derived | H22: BofA DRAM 供給 +19%；HBM 晶圓占比 22%→30% 吃掉增量
A23: cb_2 | B23: 一般 DRAM 位元成長 第 2 年 | C23: % | D23: 0.1 | E23: 0.15 | F23: 0.19 | G23: Interested-party | H23: BofA 2028 供給 +19%
A24: nb_1 | B24: NAND 位元成長 第 1 年 | C24: % | D24: 0.15 | E24: 0.2 | F24: 0.25 | G24: Verified | H24: Micron：產業 2027 中 20% 段
A25: nb_2 | B25: NAND 位元成長 第 2 年 | C25: % | D25: 0.15 | E25: 0.2 | F25: 0.25 | G25: Verified | H25: 同上
A26: sh25 | B26: HBM 營收市占 2025 | C26: % | D26: 0.55 | E26: 0.58 | F26: 0.62 | G26: Interested-party | H26: Counterpoint 3Q25 57%；出貨 62%
A27: sh26 | B27: HBM 營收市占 2026 | C27: % | D27: 0.48 | E27: 0.52 | F27: 0.56 | G27: Interested-party | H27: Counterpoint Q1 58%、Q2 50%；IDC Q1 56.4%
A28: sh27 | B28: HBM 營收市占 2027 | C28: % | D28: 0.38 | E28: 0.42 | F28: 0.48 | G28: Interested-party | H28: UBS 2027 位元：SK 39%、三星 41%、美光 20%
A29: sh28 | B29: HBM 營收市占 2028 | C29: % | D29: 0.35 | E29: 0.4 | F29: 0.45 | G29: Assumed
A30: other_y | B30: 其他營收（每年） | C30: 兆韓元 | E30: 1.6 | G30: Verified
A31: w_c | B31: 成本權重：一般 DRAM | C31: % | E31: 0.45 | G31: Assumed
A32: w_h | B32: 成本權重：HBM | C32: % | E32: 0.3 | G32: Assumed | H32: HBM 每位元耗晶圓約 DDR5 的 3 倍（Micron）
A33: w_n | B33: 成本權重：NAND | C33: % | E33: 0.25 | G33: Assumed
A34: costdn_y | B34: 單位成本年降 | C34: % | D34: 0.05 | E34: 0.1 | F34: 0.15 | G34: Assumed
A35: da_life | B35: 新增資本支出轉為折舊的年數 | C35: 年 | D35: 4 | E35: 5 | F35: 6 | G35: Assumed
A36: da_cogs | B36: 折舊計入營業成本比例 | C36: % | E36: 0.9 | G36: Assumed
A37: opex_fix_y | B37: 營業費用固定部分（年，基準年） | C37: 兆韓元 | E37: 6 | G37: Derived | H37: ＝每季 1.5 × 4
A38: opex_var | B38: 營業費用變動率 | C38: % 營收 | D38: 0.04 | E38: 0.047 | F38: 0.06 | G38: Derived | H38: 同上迴歸
A39: opex_g | B39: 營業費用固定部分年增 | C39: % | E39: 0.1 | G39: Assumed
A40: tax | B40: 有效稅率 | C40: % | D40: 0.2 | E40: 0.23 | F40: 0.25 | G40: Verified | H40: Q1 21.8%、Q2 23.5%
A41: rf | B41: 淨現金收益率 | C41: % | E41: 0.02 | G41: Assumed
...

Sheet Path
A1: Path — 記憶體合約價指數（2025Q1＝1；季增來自 In 頁 M1）。共用市場層：所有記憶體公司用同一條路徑，再依各自會計年度取平均
A3: 路徑 | B3: 情境 | C3: 2025Q1 | D3: 2025Q2 | E3: 2025Q3 | F3: 2025Q4 | G3: 2026Q1 | H3: 2026Q2 | I3: 2026Q3 | J3: 2026Q4 | K3: 2027Q1 | L3: 2027Q2 | M3: 2027Q3 | N3: 2027Q4 | O3: 2028Q1 | P3: 2028Q2 | Q3: 2028Q3 | R3: 2028Q4
A4: 一般 DRAM | B4: A | C4: 1 | D4: =C4*(1+cq_1) -> 0.975 | E4: =D4*(1+cq_2) -> 1.096875 | F4: =E4*(1+cq_3) -> 1.6178906 | G4: =F4*(1+cq_4) -> 3.1548867 | H4: =G4*(1+cq_5) -> 5.0635932 | I4: =H4*(1+cq_6) -> 5.8484501 | J4: =I4*(1+cq_7) -> 6.5795064 | K4: =J4*(1+cqA_8) -> 6.7768916 | L4: =K4*(1+cqA_9) -> 6.7768916 | M4: =L4*(1+cqA_10) -> 6.6413538 | N4: =M4*(1+cqA_11) -> 6.4421131 | O4: =N4*(1+cqA_12) -> 6.2488497 | P4: =O4*(1+cqA_13) -> 6.0613843 | Q4: =P4*(1+cqA_14) -> 5.9401566 | R4: =Q4*(1+cqA_15) -> 5.8213534
A5: 一般 DRAM | B5: B | C5: 1 | D5: =C5*(1+cq_1) -> 0.975 | E5: =D5*(1+cq_2) -> 1.096875 | F5: =E5*(1+cq_3) -> 1.6178906 | G5: =F5*(1+cq_4) -> 3.1548867 | H5: =G5*(1+cq_5) -> 5.0635932 | I5: =H5*(1+cq_6) -> 5.8484501 | J5: =I5*(1+cq_7) -> 6.5795064 | K5: =J5*(1+cqB_8) -> 6.9084817 | L5: =K5*(1+cqB_9) -> 7.0466513 | M5: =L5*(1+cqB_10) -> 6.4829192 | N5: =M5*(1+cqB_11) -> 5.5104814 | O5: =N5*(1+cqB_12) -> 4.132861 | P5: =O5*(1+cqB_13) -> 3.5129319 | Q5: =P5*(1+cqB_14) -> 3.1616387 | R5: =Q5*(1+cqB_15) -> 3.0035567
A6: 一般 DRAM | B6: C | C6: 1 | D6: =C6*(1+cq_1) -> 0.975 | E6: =D6*(1+cq_2) -> 1.096875 | F6: =E6*(1+cq_3) -> 1.6178906 | G6: =F6*(1+cq_4) -> 3.1548867 | H6: =G6*(1+cq_5) -> 5.0635932 | I6: =H6*(1+cq_6) -> 5.8484501 | J6: =I6*(1+cq_7) -> 6.5795064 | K6: =J6*(1+cqC_8) -> 6.9084817 | L6: =K6*(1+cqC_9) -> 7.0466513 | M6: =L6*(1+cqC_10) -> 6.4829192 | N6: =M6*(1+cqC_11) -> 5.5104814 | O6: =N6*(1+cqC_12) -> 3.5818129 | P6: =O6*(1+cqC_13) -> 2.507269 | Q6: =P6*(1+cqC_14) -> 1.8804518 | R6: =Q6*(1+cqC_15) -> 1.5043614
A8: NAND | B8: A | C8: 1 | D8: =C8*(1+nq_1) -> 1 | E8: =D8*(1+nq_2) -> 1.05 | F8: =E8*(1+nq_3) -> 1.365 | G8: =F8*(1+nq_4) -> 2.559375 | H8: =G8*(1+nq_5) -> 4.4149219 | I8: =H8*(1+nq_6) -> 5.0771602 | J8: =I8*(1+nq_7) -> 5.9656632 | K8: =J8*(1+nqA_8) -> 6.1446331 | L8: =K8*(1+nqA_9) -> 6.1446331 | M8: =L8*(1+nqA_10) -> 5.8374014 | N8: =M8*(1+nqA_11) -> 5.4287833 | O8: =N8*(1+nqA_12) -> 5.1573442 | P8: =O8*(1+nqA_13) -> 4.899477 | Q8: =P8*(1+nqA_14) -> 4.6545031 | R8: =Q8*(1+nqA_15) -> 4.4217779
A9: NAND | B9: B | C9: 1 | D9: =C9*(1+nq_1) -> 1 | E9: =D9*(1+nq_2) -> 1.05 | F9: =E9*(1+nq_3) -> 1.365 | G9: =F9*(1+nq_4) -> 2.559375 | H9: =G9*(1+nq_5) -> 4.4149219 | I9: =H9*(1+nq_6) -> 5.0771602 | J9: =I9*(1+nq_7) -> 5.9656632 | K9: =J9*(1+nqB_8) -> 6.2639463 | L9: =K9*(1+nqB_9) -> 6.3892253 | M9: =L9*(1+nqB_10) -> 5.7503027 | N9: =M9*(1+nqB_11) -> 4.6002422 | O9: =N9*(1+nqB_12) -> 3.2201695 | P9: =O9*(1+nqB_13) -> 2.4151272 | Q9: =P9*(1+nqB_14) -> 1.9321017 | R9: =Q9*(1+nqB_15) -> 1.7388915
A10: NAND | B10: C | C10: 1 | D10: =C10*(1+nq_1) -> 1 | E10: =D10*(1+nq_2) -> 1.05 | F10: =E10*(1+nq_3) -> 1.365 | G10: =F10*(1+nq_4) -> 2.559375 | H10: =G10*(1+nq_5) -> 4.4149219 | I10: =H10*(1+nq_6) -> 5.0771602 | J10: =I10*(1+nq_7) -> 5.9656632 | K10: =J10*(1+nqC_8) -> 6.2639463 | L10: =K10*(1+nqC_9) -> 6.3892253 | M10: =L10*(1+nqC_10) -> 5.7503027 | N10: =M10*(1+nqC_11) -> 4.6002422 | O10: =N10*(1+nqC_12) -> 2.9901574 | P10: =O10*(1+nqC_13) -> 1.9436023 | Q10: =P10*(1+nqC_14) -> 1.4577017 | R10: =Q10*(1+nqC_15) -> 1.1661614
A12: 年均指數
A13: 路徑 | B13: 情境 | C13: 2025 | D13: 2026 | E13: 2027 | F13: 2028 | G13: 2026÷2025 | H13: 2027÷2026 | I13: 2028÷2027
A14: 一般 DRAM | B14: A | C14: =AVERAGE(C4:F4) -> 1.1724414 | D14: =AVERAGE(G4:J4) -> 5.1616091 | E14: =AVERAGE(K4:N4) -> 6.6593125 | F14: =AVERAGE(O4:R4) -> 6.017936 | G14: =D14/C14-1 -> 3.4024453 | H14: =E14/D14-1 -> 0.29016211 | I14: =F14/E14-1 -> -0.096312722
A15: 一般 DRAM | B15: B | C15: =AVERAGE(C5:F5) -> 1.1724414 | D15: =AVERAGE(G5:J5) -> 5.1616091 | E15: =AVERAGE(K5:N5) -> 6.4871334 | F15: =AVERAGE(O5:R5) -> 3.4527471 | G15: =D15/C15-1 -> 3.4024453 | H15: =E15/D15-1 -> 0.25680447 | I15: =F15/E15-1 -> -0.46775458
A16: 一般 DRAM | B16: C | C16: =AVERAGE(C6:F6) -> 1.1724414 | D16: =AVERAGE(G6:J6) -> 5.1616091 | E16: =AVERAGE(K6:N6) -> 6.4871334 | F16: =AVERAGE(O6:R6) -> 2.3684738 | G16: =D16/C16-1 -> 3.4024453 | H16: =E16/D16-1 -> 0.25680447 | I16: =F16/E16-1 -> -0.63489671
A17: NAND | B17: A | C17: =AVERAGE(C8:F8) -> 1.10375 | D17: =AVERAGE(G8:J8) -> 4.5042801 | E17: =AVERAGE(K8:N8) -> 5.8888627 | F17: =AVERAGE(O8:R8) -> 4.7832755 | G17: =D17/C17-1 -> 3.0808879 | H17: =E17/D17-1 -> 0.30739267 | I17: =F17/E17-1 -> -0.18774205
A18: NAND | B18: B | C18: =AVERAGE(C9:F9) -> 1.10375 | D18: =AVERAGE(G9:J9) -> 4.5042801 | E18: =AVERAGE(K9:N9) -> 5.7509291 | F18: =AVERAGE(O9:R9) -> 2.3265725 | G18: =D18/C18-1 -> 3.0808879 | H18: =E18/D18-1 -> 0.27676989 | I18: =F18/E18-1 -> -0.59544407
A19: NAND | B19: C | C19: =AVERAGE(C10:F10) -> 1.10375 | D19: =AVERAGE(G10:J10) -> 4.5042801 | E19: =AVERAGE(K10:N10) -> 5.7509291 | F19: =AVERAGE(O10:R10) -> 1.8894057 | G19: =D19/C19-1 -> 3.0808879 | H19: =E19/D19-1 -> 0.27676989 | I19: =F19/E19-1 -> -0.67146079

Sheet Mkt
A1: Mkt — 加速器數量層（最小版）與 HBM 市場（日曆年）。需求＝顆數 × GB；出貨＝MIN(需求, 供給)；市場＝出貨 × 單價
A3: 項目 | B3: 單位 | C3: 2025 | D3: 2026 | E3: 2027 | F3: 2028 | G3: 說明
A4: 需求：加速器裝載的 HBM（PB）
A5: NVIDIA Blackwell（B200／B300） | B5: PB | D5: =u_bw_26*g_bw_26 -> 1404 | E5: =u_bw_27*g_bw_27 -> 672 | F5: =u_bw_28*g_bw_28 -> 144
A6: NVIDIA Rubin | B6: PB | D6: =u_rb_26*g_rb_26 -> 489.6 | E6: =u_rb_27*g_rb_27 -> 2016 | F6: =u_rb_28*g_rb_28 -> 2016
A7: NVIDIA Rubin Ultra | B7: PB | D7: =u_ru_26*g_ru_26 -> 0 | E7: =u_ru_27*g_ru_27 -> 307.2 | F7: =u_ru_28*g_ru_28 -> 2048
A8: NVIDIA Hopper（H200 等） | B8: PB | D8: =u_hp_26*g_hp_26 -> 70.5 | E8: =u_hp_27*g_hp_27 -> 0 | F8: =u_hp_28*g_hp_28 -> 0
A9: AMD Instinct | B9: PB | D9: =u_amd_26*g_amd_26 -> 216 | E9: =u_amd_27*g_amd_27 -> 540 | F9: =u_amd_28*g_amd_28 -> 864
A10: Google TPU | B10: PB | D10: =u_tpu_26*g_tpu_26 -> 739.2 | E10: =u_tpu_27*g_tpu_27 -> 1375 | F10: =u_tpu_28*g_tpu_28 -> 2016
A11: AWS Trainium | B11: PB | D11: =u_trn_26*g_trn_26 -> 220 | E11: =u_trn_27*g_trn_27 -> 360 | F11: =u_trn_28*g_trn_28 -> 600
A12: 其他 ASIC（MTIA、Maia、Ascend 等） | B12: PB | D12: =u_oth_26*g_oth_26 -> 150 | E12: =u_oth_27*g_oth_27 -> 900 | F12: =u_oth_28*g_oth_28 -> 1250
A13: 需求合計（裝載） | B13: EB | D13: =SUM(D5:D12)/1000 -> 3.2893 | E13: =SUM(E5:E12)/1000 -> 6.1702 | F13: =SUM(F5:F12)/1000 -> 8.938
A14: 需求 × 出貨係數 | B14: EB | D14: =D13*hbm_gross -> 3.782695 | E14: =E13*hbm_gross -> 7.09573 | F14: =F13*hbm_gross -> 10.2787
A15: 加速器顆數合計 | B15: 百萬顆 | D15: =u_bw_26+u_rb_26+u_ru_26+u_hp_26+u_amd_26+u_tpu_26+u_trn_26+u_oth_26 -> 15.2 | E15: =u_bw_27+u_rb_27+u_ru_27+u_hp_27+u_amd_27+u_tpu_27+u_trn_27+u_oth_27 -> 23.7 | F15: =u_bw_28+u_rb_28+u_ru_28+u_hp_28+u_amd_28+u_tpu_28+u_trn_28+u_oth_28 -> 26.5 | G15: JPMorgan 2027：GPU 10.9M、ASIC 12.5M
A16: 每顆平均 HBM | B16: GB | D16: =D13*1000/D15 -> 216.40132 | E16: =E13*1000/E15 -> 260.34599 | F16: =F13*1000/F15 -> 337.28302
A17: 供給 | B17: EB | C17: =D17/(1+hbm_g26) -> 2.2251147 | D17: =D14 -> 3.782695 | E17: =D17*(1+hbm_sup27) -> 5.8631772 | F17: =E17*(1+hbm_sup28) -> 8.501607 | G17: 2026 供給＝需求出貨（年中已成交）
A18: 出貨＝MIN(需求, 供給) | B18: EB | C18: =C17 -> 2.2251147 | D18: =MIN(D14,D17) -> 3.782695 | E18: =MIN(E14,E17) -> 5.8631772 | F18: =MIN(F14,F17) -> 8.501607
A19: 需求 − 供給（>0＝短缺） | B19: EB | D19: =D14-D17 -> 0 | E19: =E14-E17 -> 1.2325527 | F19: =F14-F17 -> 1.777093
A20: HBM 單價（A） | B20: $/GB | C20: =hbm_mkt25/C18 -> 15.729526 | D20: =hbm_p26 -> 14.6 | E20: =D20*(1+hbm_p27) -> 26.28 | F20: =E20*(1+hbm_p28_A) -> 28.908
A21: HBM 單價（B） | B21: $/GB | C21: =hbm_mkt25/C18 -> 15.729526 | D21: =hbm_p26 -> 14.6 | E21: =D21*(1+hbm_p27) -> 26.28 | F21: =E21*(1+hbm_p28_B) -> 19.71
A22: HBM 單價（C） | B22: $/GB | C22: =hbm_mkt25/C18 -> 15.729526 | D22: =hbm_p26 -> 14.6 | E22: =D22*(1+hbm_p27) -> 26.28 | F22: =E22*(1+hbm_p28_C) -> 15.768
A23: HBM 市場（A） | B23: $B | C23: =C18*C20 -> 35 | D23: =D18*D20 -> 55.227347 | E23: =E18*E20 -> 154.0843 | F23: =F18*F20 -> 245.76446
A24: HBM 市場（B） | B24: $B | C24: =C18*C21 -> 35 | D24: =D18*D21 -> 55.227347 | E24: =E18*E21 -> 154.0843 | F24: =F18*F21 -> 167.56667
A25: HBM 市場（C） | B25: $B | C25: =C18*C22 -> 35 | D25: =D18*D22 -> 55.227347 | E25: =E18*E22 -> 154.0843 | F25: =F18*F22 -> 134.05334
A27: 對帳（樣板驗收 2）
A28: 由下而上：NVIDIA 裝載 HBM × 單價（2026） | B28: $B | D28: =(D5+D6+D7+D8)/1000*hbm_p26 -> 28.67586
A29: 由上而下：NVIDIA 資料中心營收 × 每顆 HBM ÷ 每顆 NVIDIA 內容（2026） | B29: $B | D29: =nv_dc26*nv_hbm/nv_content -> 32.326357 | G29: 橋接表 v0.1；與顆數預測獨立
A30: 差距 | B30: % | D30: =D28/D29-1 -> -0.11292632
A31: 由營收推得 NVIDIA 顆數 vs 顆數預測 | B31: 百萬顆 | D31: =nv_dc26/nv_content -> 7.248062 | E31: =u_bw_26+u_rb_26+u_hp_26 -> 7.6 | G31: D＝營收推得；E＝顆數預測（2026）
A32: 已發布：SK 海力士自估 2026／BofA 2026／BofA 2027 | B32: $B | D32: =pub26_lo -> 54.6 | E32: =pub26_hi -> 77.4 | F32: =pub27 -> 152.8
A33: 本模型 2026 ÷ SK 海力士自估、2027 ÷ BofA | B33: % | D33: =D23/pub26_lo-1 -> 0.011489872 | F33: =E23/pub27-1 -> 0.0084050925

Sheet Q
A1: Q — 季度損益（兆韓元）。實績：SEC 424B4（2026-07）、6-K 半年報（2026-08-18）、公司公告；推估季：實績 × 公司指引 × TrendForce 價格
A3: 項目 | B3: 2025Q1 | C3: 2025Q2 | D3: 2025Q3 | E3: 2025Q4 | F3: 2026Q1 | G3: 2026Q2 | H3: 2026Q3E | I3: 2026Q4E | J3: 2026 合計
A4: 營收 | B4: 17.639 | C4: 22.232 | D4: 24.449 | E4: 32.827 | F4: 52.576 | G4: 79.319 | H4: =H5+H6+H7 -> 96.311345 | I4: =I5+I6+I7 -> 113.11289 | J4: =SUM(F4:I4) -> 341.31923
A5: DRAM（含 HBM） | F5: =F4*0.773 -> 40.641248 | G5: =G4*0.73 -> 57.90287 | H5: =G5*(1+q3_db)*(1+q3_dp) -> 71.336336 | I5: =H5*(1+q4_db)*(1+q4_dp) -> 82.393468 | J5: =SUM(F5:I5) -> 252.27392
A6: NAND | F6: =F4*0.22 -> 11.56672 | G6: =G4*0.27 -> 21.41613 | H6: =G6*(1+q3_nb)*(1+q3_np) -> 24.575009 | I6: =H6*(1+q4_nb)*(1+q4_np) -> 30.319418 | J6: =SUM(F6:I6) -> 87.877277
A7: 其他 | F7: =F4-F5-F6 -> 0.368032 | G7: =G4-G5-G6 -> 0 | H7: =other_y/4 -> 0.4 | I7: =other_y/4 -> 0.4 | J7: =SUM(F7:I7) -> 1.168032
A8: 營業成本 | F8: =F4*(1-0.79) -> 11.04096 | G8: =G4*(1-0.83) -> 13.48423 | H8: =(G8-da_cogs*G13)*((w_c+w_h)*H14/G14+w_n*H15/G15)*(1-costdn_q)+da_cogs*da_q3 -> 14.19832 | I8: =(H8-da_cogs*H13)*((w_c+w_h)*I14/H14+w_n*I15/H15)*(1-costdn_q)+da_cogs*da_q4 -> 14.659394 | J8: =SUM(F8:I8) -> 53.382904
A9: 營業費用 | F9: =F4-F8-F10 -> 3.92504 | G9: =G4-G8-G10 -> 5.29177 | H9: =opex_fix_q+opex_var*H4 -> 6.0266332 | I9: =opex_fix_q+opex_var*I4 -> 6.8163056 | J9: =SUM(F9:I9) -> 22.059749
A10: 營業利益 | B10: 7.441 | C10: 9.213 | D10: 11.383 | E10: 19.17 | F10: 37.61 | G10: 60.543 | H10: =H4-H8-H9 -> 76.086392 | I10: =I4-I8-I9 -> 91.637186 | J10: =SUM(F10:I10) -> 265.87658
A11: 營業利益率 | B11: =IF(B4=0,"",B10/B4) -> 0.42184931 | C11: =IF(C4=0,"",C10/C4) -> 0.41440266 | D11: =IF(D4=0,"",D10/D4) -> 0.46558141 | E11: =IF(E4=0,"",E10/E4) -> 0.58397051 | F11: =IF(F4=0,"",F10/F4) -> 0.7153454 | G11: =IF(G4=0,"",G10/G4) -> 0.76328496 | H11: =IF(H4=0,"",H10/H4) -> 0.79000446 | I11: =IF(I4=0,"",I10/I4) -> 0.81013923 | J11: =J10/J4 -> 0.77896747
A12: 淨利 | B12: 8.108 | C12: 6.996 | D12: 12.598 | E12: 15.246 | F12: 40.346 | G12: 93.923 | H12: =(H10+nonop_q)*(1-tax) -> 59.356522 | I12: =(I10+nonop_q)*(1-tax) -> 71.330633 | J12: =SUM(F12:I12) -> 264.95616
A13: 折舊攤銷 | B13: 3.334 | C13: 3.443 | D13: 3.556 | E13: 3.557 | F13: 3.726 | G13: 4.028 | H13: =da_q3 -> 4.3 | I13: =da_q4 -> 4.6 | J13: =SUM(F13:I13) -> 16.654
A14: DRAM 位元指數（最後實績季＝1） | G14: 1 | H14: =G14*(1+q3_db) -> 1.1 | I14: =H14*(1+q4_db) -> 1.155
A15: NAND 位元指數 | G15: 1 | H15: =G15*(1+q3_nb) -> 1.02 | I15: =H15*(1+q4_nb) -> 1.071
A18: 2026Q1 DRAM 77.3%、NAND 22%、毛利率約 79%；Q2 DRAM 73%、NAND 27%、毛利率 83%（公司簡報）。2025 季度拆分未取得。2025Q3、Q4 折舊為合計 7.113 平均分配 [Derived]

Sheet Y
A1: Y — 年度（兆韓元；股數百萬股）。情境 A：2027–28 高檔持平（BofA、TrendForce 型）；B：2027 Q2 見頂、2028 回落約一半（Citi、Bernstein 型）；C：2028 回到 2025 年價格水準（完整谷底；歷史循環型）
A3: 項目 | B3: 2025 實績 | C3: 2026（基準） | D3: 2027 A | E3: 2028 A | F3: 2027 B | G3: 2028 B | H3: 2027 C | I3: 2028 C | J3: 說明
A4: 營收 | B4: =SUM(Q!B4:E4) -> 97.147 | C4: =Q!J4 -> 341.31923 | D4: =D5+D6+D7+D8 -> 531.51177 | E4: =E5+E6+E7+E8 -> 587.50127 | F4: =F5+F6+F7+F8 -> 520.52208 | G4: =G5+G6+G7+G8 -> 341.10571 | H4: =H5+H6+H7+H8 -> 520.52208 | I4: =I5+I6+I7+I8 -> 253.58759
A5: 一般 DRAM | C5: =Q!J5-C6 -> 211.49405 | D5: =C5*(1+cb_1)*(AVERAGE(Path!K4:N4)/AVERAGE(Path!G4:J4)) -> 300.14777 | E5: =D5*(1+cb_2)*(AVERAGE(Path!O4:R4)/AVERAGE(Path!K4:N4)) -> 311.92568 | F5: =C5*(1+cb_1)*(AVERAGE(Path!K5:N5)/AVERAGE(Path!G5:J5)) -> 292.38733 | G5: =F5*(1+cb_2)*(AVERAGE(Path!O5:R5)/AVERAGE(Path!K5:N5)) -> 178.96509 | H5: =C5*(1+cb_1)*(AVERAGE(Path!K6:N6)/AVERAGE(Path!G6:J6)) -> 292.38733 | I5: =H5*(1+cb_2)*(AVERAGE(Path!O6:R6)/AVERAGE(Path!K6:N6)) -> 122.76431 | J5: 前一年 × (1＋位元) × 會計年度價格指數平均比（Path）
A6: HBM | C6: =(Mkt!D23/4*sh26+Mkt!D23/4*sh26+Mkt!D23/4*sh26+Mkt!D23/4*sh26)*fx/1000 -> 40.779873 | D6: =(Mkt!E23/4*sh27+Mkt!E23/4*sh27+Mkt!E23/4*sh27+Mkt!E23/4*sh27)*fx/1000 -> 91.895875 | E6: =(Mkt!F23/4*sh28+Mkt!F23/4*sh28+Mkt!F23/4*sh28+Mkt!F23/4*sh28)*fx/1000 -> 139.59421 | F6: =(Mkt!E24/4*sh27+Mkt!E24/4*sh27+Mkt!E24/4*sh27+Mkt!E24/4*sh27)*fx/1000 -> 91.895875 | G6: =(Mkt!F24/4*sh28+Mkt!F24/4*sh28+Mkt!F24/4*sh28+Mkt!F24/4*sh28)*fx/1000 -> 95.177871 | H6: =(Mkt!E25/4*sh27+Mkt!E25/4*sh27+Mkt!E25/4*sh27+Mkt!E25/4*sh27)*fx/1000 -> 91.895875 | I6: =(Mkt!F25/4*sh28+Mkt!F25/4*sh28+Mkt!F25/4*sh28+Mkt!F25/4*sh28)*fx/1000 -> 76.142297 | J6: Σ 會計年度各季：HBM 市場 ÷ 4 × 市占 × 匯率（Mkt）
A7: NAND | C7: =Q!J6 -> 87.877277 | D7: =C7*(1+nb_1)*(AVERAGE(Path!K8:N8)/AVERAGE(Path!G8:J8)) -> 137.86813 | E7: =D7*(1+nb_2)*(AVERAGE(Path!O8:R8)/AVERAGE(Path!K8:N8)) -> 134.38138 | F7: =C7*(1+nb_1)*(AVERAGE(Path!K9:N9)/AVERAGE(Path!G9:J9)) -> 134.63887 | G7: =F7*(1+nb_2)*(AVERAGE(Path!O9:R9)/AVERAGE(Path!K9:N9)) -> 65.362745 | H7: =C7*(1+nb_1)*(AVERAGE(Path!K10:N10)/AVERAGE(Path!G10:J10)) -> 134.63887 | I7: =H7*(1+nb_2)*(AVERAGE(Path!O10:R10)/AVERAGE(Path!K10:N10)) -> 53.080979
A8: 其他 | C8: =Q!J7 -> 1.168032 | D8: =other_y -> 1.6 | E8: =other_y -> 1.6 | F8: =other_y -> 1.6 | G8: =other_y -> 1.6 | H8: =other_y -> 1.6 | I8: =other_y -> 1.6
A9: HBM ÷ 營收 | C9: =C6/C4 -> 0.11947722 | D9: =D6/D4 -> 0.17289528 | E9: =E6/E4 -> 0.23760665 | F9: =F6/F4 -> 0.17654559 | G9: =G6/G4 -> 0.27902749 | H9: =H6/H4 -> 0.17654559 | I9: =I6/I4 -> 0.30026034
A10: 折舊攤銷 | B10: =SUM(Q!B13:E13) -> 13.89 | C10: =Q!J13 -> 16.654 | D10: =C10+(C17-C10)/da_life -> 23.0632 | E10: =D10+(D17-D10)/da_life -> 30.91056 | F10: =C10+(C17-C10)/da_life -> 23.0632 | G10: =F10+(F17-F10)/da_life -> 30.91056 | H10: =C10+(C17-C10)/da_life -> 23.0632 | I10: =H10+(H17-H10)/da_life -> 30.91056
A11: 成本量指數（÷ 前一年） | D11: =w_c*(1+cb_1)+w_h*D27/C27+w_n*(1+nb_1) -> 1.1705769 | E11: =w_c*(1+cb_2)+w_h*E27/D27+w_n*(1+nb_2) -> 1.2317857 | F11: =w_c*(1+cb_1)+w_h*F27/C27+w_n*(1+nb_1) -> 1.1705769 | G11: =w_c*(1+cb_2)+w_h*G27/F27+w_n*(1+nb_2) -> 1.2317857 | H11: =w_c*(1+cb_1)+w_h*H27/C27+w_n*(1+nb_1) -> 1.1705769 | I11: =w_c*(1+cb_2)+w_h*I27/H27+w_n*(1+nb_2) -> 1.2317857
A12: 營業成本 | C12: =Q!J8 -> 53.382904 | D12: =(C12-da_cogs*C10)*D11*(1-costdn_y)+da_cogs*D10 -> 61.206017 | E12: =(D12-da_cogs*D10)*E11*(1-costdn_y)+da_cogs*E10 -> 72.661706 | F12: =(C12-da_cogs*C10)*F11*(1-costdn_y)+da_cogs*F10 -> 61.206017 | G12: =(F12-da_cogs*F10)*G11*(1-costdn_y)+da_cogs*G10 -> 72.661706 | H12: =(C12-da_cogs*C10)*H11*(1-costdn_y)+da_cogs*H10 -> 61.206017 | I12: =(H12-da_cogs*H10)*I11*(1-costdn_y)+da_cogs*I10 -> 72.661706 | J12: 現金成本 × 量 × (1 − 年降)＋折舊
A13: 營業費用 | C13: =Q!J9 -> 22.059749 | D13: =opex_fix_y*(1+opex_g)^1+opex_var*D4 -> 31.581053 | E13: =opex_fix_y*(1+opex_g)^2+opex_var*E4 -> 34.87256 | F13: =opex_fix_y*(1+opex_g)^1+opex_var*F4 -> 31.064538 | G13: =opex_fix_y*(1+opex_g)^2+opex_var*G4 -> 23.291968 | H13: =opex_fix_y*(1+opex_g)^1+opex_var*H4 -> 31.064538 | I13: =opex_fix_y*(1+opex_g)^2+opex_var*I4 -> 19.178617
A14: 營業利益 | B14: =SUM(Q!B10:E10) -> 47.207 | C14: =Q!J10 -> 265.87658 | D14: =D4-D12-D13 -> 438.7247 | E14: =E4-E12-E13 -> 479.967 | F14: =F4-F12-F13 -> 428.25153 | G14: =G4-G12-G13 -> 245.15203 | H14: =H4-H12-H13 -> 428.25153 | I14: =I4-I12-I13 -> 161.74727
A15: 營業利益率 | B15: =B14/B4 -> 0.48593369 | C15: =C14/C4 -> 0.77896747 | D15: =D14/D4 -> 0.82542801 | E15: =E14/E4 -> 0.81696335 | F15: =F14/F4 -> 0.8227346 | G15: =G14/G4 -> 0.71869813 | H15: =H14/H4 -> 0.8227346 | I15: =I14/I4 -> 0.63783589
A16: 淨利 | B16: =SUM(Q!B12:E12) -> 42.948 | C16: =Q!J12 -> 264.95616 | D16: =(D14+rf*C22)*(1-tax) -> 340.58459 | E16: =(E14+rf*D22)*(1-tax) -> 374.66154 | F16: =(F14+rf*C22)*(1-tax) -> 332.52024 | G16: =(G14+rf*F22)*(1-tax) -> 193.79192 | H16: =(H14+rf*C22)*(1-tax) -> 332.52024 | I16: =(I14+rf*H22)*(1-tax) -> 129.57024 | J16: （營業利益＋淨現金 × 收益率）× (1 − 稅率)
A17: 資本支出 | C17: =cap_0 -> 48.7 | D17: =cap_1 -> 62.3 | E17: =cap_2 -> 71.2 | F17: =cap_1 -> 62.3 | G17: =cap_2 -> 71.2 | H17: =cap_1 -> 62.3 | I17: =cap_2 -> 71.2
A18: 自由現金流（淨利＋折舊 − 資本支出） | C18: =C16+C10-C17 -> 232.91016 | D18: =D16+D10-D17 -> 301.34779 | E18: =E16+E10-E17 -> 334.3721 | F18: =F16+F10-F17 -> 293.28344 | G18: =G16+G10-G17 -> 153.50248 | H18: =H16+H10-H17 -> 293.28344 | I18: =I16+I10-I17 -> 89.280804
A19: 股利 | C19: =div_0 -> 0.54 | D19: =dps_1*C23/1000000 -> 3.2004764 | E19: =dps_2*D23/1000000 -> 3.250204 | F19: =dps_1*C23/1000000 -> 3.2004764 | G19: =dps_2*F23/1000000 -> 3.2624878 | H19: =dps_1*C23/1000000 -> 3.2004764 | I19: =dps_2*H23/1000000 -> 3.2624878
A20: 買回 | C20: =bb_0 -> 40 | D20: =MAX(0,payout*D18-D19) -> 147.47342 | E20: =MAX(0,payout*E18-E19) -> 163.93584 | F20: =MAX(0,payout*F18-F19) -> 143.44124 | G20: =MAX(0,payout*G18-G19) -> 73.48875 | H20: =MAX(0,payout*H18-H19) -> 143.44124 | I20: =MAX(0,payout*I18-I19) -> 41.377914 | J20: 回饋比例 × FCF − 股利
A21: 期末權益 | C21: =eq_last+(Q!H12+Q!I12)+extra_eq-C20-C19 -> 393.24016 | D21: =C21+D16-D19-D20 -> 583.15085 | E21: =D21+E16-E19-E20 -> 790.62634 | F21: =C21+F16-F19-F20 -> 579.11868 | G21: =F21+G16-G19-G20 -> 696.15935 | H21: =C21+H16-H19-H20 -> 579.11868 | I21: =H21+I16-I19-I20 -> 664.04852
A22: 期末淨現金 | C22: =nc_last+(Q!H12+Q!I12)+(Q!H13+Q!I13)-capex_rem+extra_eq-C20-C19 -> 179.64716 | D22: =C22+D18-D19-D20 -> 330.32105 | E22: =D22+E18-E19-E20 -> 497.5071 | F22: =C22+F18-F19-F20 -> 326.28888 | G22: =F22+G18-G19-G20 -> 403.04011 | H22: =C22+H18-H19-H20 -> 326.28888 | I22: =H22+I18-I19-I20 -> 370.92928
A23: 期末流通股數 | C23: =sh_last+extra_sh-bb_sh_0 -> 704.7955 | D23: =C23-D20/bb_px*1000000 -> 619.20443 | E23: =D23-E20/bb_px*1000000 -> 524.05884 | F23: =C23-F20/bb_px*1000000 -> 621.54463 | G23: =F23-G20/bb_px*1000000 -> 578.89301 | H23: =C23-H20/bb_px*1000000 -> 621.54463 | I23: =H23-I20/bb_px*1000000 -> 597.52959
A24: 每股淨值 BVPS | C24: =C21/C23*1000000 -> 557949.3 | D24: =D21/D23*1000000 -> 941774.35 | E24: =E21/E23*1000000 -> 1508659.5 | F24: =F21/F23*1000000 -> 931741.09 | G24: =G21/G23*1000000 -> 1202570 | H24: =H21/H23*1000000 -> 931741.09 | I24: =I21/I23*1000000 -> 1111323.2
A25: 每股盈餘 EPS（期末股數） | C25: =C16/C23*1000000 -> 375933.38 | D25: =D16/D23*1000000 -> 550035.78 | E25: =E16/E23*1000000 -> 714922.65 | F25: =F16/F23*1000000 -> 534990.13 | G25: =G16/G23*1000000 -> 334762.92 | H25: =H16/H23*1000000 -> 534990.13 | I25: =I16/I23*1000000 -> 216843.23
A26: ROE（期末權益） | C26: =C16/C21 -> 0.67377696 | D26: =D16/D21 -> 0.584042 | E26: =E16/E21 -> 0.4738794 | F26: =F16/F21 -> 0.57418325 | G26: =G16/G21 -> 0.27837292 | H26: =H16/H21 -> 0.57418325 | I26: =I16/I21 -> 0.19512165
A27: HBM 出貨位元（EB，公司） | C27: =(Mkt!D18/4*sh26+Mkt!D18/4*sh26+Mkt!D18/4*sh26+Mkt!D18/4*sh26) -> 1.9670014 | D27: =(Mkt!E18/4*sh27+Mkt!E18/4*sh27+Mkt!E18/4*sh27+Mkt!E18/4*sh27) -> 2.4625344 | E27: =(Mkt!F18/4*sh28+Mkt!F18/4*sh28+Mkt!F18/4*sh28+Mkt!F18/4*sh28) -> 3.4006428 | F27: =(Mkt!E18/4*sh27+Mkt!E18/4*sh27+Mkt!E18/4*sh27+Mkt!E18/4*sh27) -> 2.4625344 | G27: =(Mkt!F18/4*sh28+Mkt!F18/4*sh28+Mkt!F18/4*sh28+Mkt!F18/4*sh28) -> 3.4006428 | H27: =(Mkt!E18/4*sh27+Mkt!E18/4*sh27+Mkt!E18/4*sh27+Mkt!E18/4*sh27) -> 2.4625344 | I27: =(Mkt!F18/4*sh28+Mkt!F18/4*sh28+Mkt!F18/4*sh28+Mkt!F18/4*sh28) -> 3.4006428

Sheet Val
A1: Val — 估值（P/B 主、P/E 對照）。隱含股價 ÷ 目前股價 − 1
A3: 方法 | B3: 倍數 | C3: 基準 | D3: 情境 | E3: 每股基準 | F3: 隱含股價 | G3: 相對目前
A4: P/B 1.0x | B4: =pb_1 -> 1 | C4: 2026 期末 BVPS | D4: 共用 | E4: =Y!C24 -> 557949.3 | F4: =B4*E4 -> 557949.3 | G4: =F4/px-1 -> -0.67617568
A5: P/B 歷史中位 1.6x | B5: =pb_2 -> 1.6 | C5: 2026 期末 BVPS | D5: 共用 | E5: =Y!C24 -> 557949.3 | F5: =B5*E5 -> 892718.88 | G5: =F5/px-1 -> -0.48188109
A6: P/B 券商遠期 3.3x | B6: =pb_3 -> 3.3 | C6: 2026 期末 BVPS | D6: 共用 | E6: =Y!C24 -> 557949.3 | F6: =B6*E6 -> 1841232.7 | G6: =F6/px-1 -> 0.068620248
A7: P/B 1.0x | B7: =pb_1 -> 1 | C7: 2027 期末 BVPS | D7: A | E7: =Y!D24 -> 941774.35 | F7: =B7*E7 -> 941774.35 | G7: =F7/px-1 -> -0.45341013
A8: P/B 歷史中位 1.6x | B8: =pb_2 -> 1.6 | C8: 2027 期末 BVPS | D8: A | E8: =Y!D24 -> 941774.35 | F8: =B8*E8 -> 1506839 | G8: =F8/px-1 -> -0.1254562
A9: P/B 券商遠期 3.3x | B9: =pb_3 -> 3.3 | C9: 2027 期末 BVPS | D9: A | E9: =Y!D24 -> 941774.35 | F9: =B9*E9 -> 3107855.4 | G9: =F9/px-1 -> 0.80374658
A10: P/B 1.0x | B10: =pb_1 -> 1 | C10: 2027 期末 BVPS | D10: B | E10: =Y!F24 -> 931741.09 | F10: =B10*E10 -> 931741.09 | G10: =F10/px-1 -> -0.45923326
A11: P/B 歷史中位 1.6x | B11: =pb_2 -> 1.6 | C11: 2027 期末 BVPS | D11: B | E11: =Y!F24 -> 931741.09 | F11: =B11*E11 -> 1490785.8 | G11: =F11/px-1 -> -0.13477322
A12: P/B 券商遠期 3.3x | B12: =pb_3 -> 3.3 | C12: 2027 期末 BVPS | D12: B | E12: =Y!F24 -> 931741.09 | F12: =B12*E12 -> 3074745.6 | G12: =F12/px-1 -> 0.78453024
A13: P/B 1.0x | B13: =pb_1 -> 1 | C13: 2027 期末 BVPS | D13: C | E13: =Y!H24 -> 931741.09 | F13: =B13*E13 -> 931741.09 | G13: =F13/px-1 -> -0.45923326
A14: P/B 歷史中位 1.6x | B14: =pb_2 -> 1.6 | C14: 2027 期末 BVPS | D14: C | E14: =Y!H24 -> 931741.09 | F14: =B14*E14 -> 1490785.8 | G14: =F14/px-1 -> -0.13477322
A15: P/B 券商遠期 3.3x | B15: =pb_3 -> 3.3 | C15: 2027 期末 BVPS | D15: C | E15: =Y!H24 -> 931741.09 | F15: =B15*E15 -> 3074745.6 | G15: =F15/px-1 -> 0.78453024
A16: P/B 1.0x | B16: =pb_1 -> 1 | C16: 2028 期末 BVPS | D16: A | E16: =Y!E24 -> 1508659.5 | F16: =B16*E16 -> 1508659.5 | G16: =F16/px-1 -> -0.12439961
A17: P/B 歷史中位 1.6x | B17: =pb_2 -> 1.6 | C17: 2028 期末 BVPS | D17: A | E17: =Y!E24 -> 1508659.5 | F17: =B17*E17 -> 2413855.2 | G17: =F17/px-1 -> 0.40096063
A18: P/B 券商遠期 3.3x | B18: =pb_3 -> 3.3 | C18: 2028 期末 BVPS | D18: A | E18: =Y!E24 -> 1508659.5 | F18: =B18*E18 -> 4978576.3 | G18: =F18/px-1 -> 1.8894813
A19: P/B 1.0x | B19: =pb_1 -> 1 | C19: 2028 期末 BVPS | D19: B | E19: =Y!G24 -> 1202570 | F19: =B19*E19 -> 1202570 | G19: =F19/px-1 -> -0.30204876
A20: P/B 歷史中位 1.6x | B20: =pb_2 -> 1.6 | C20: 2028 期末 BVPS | D20: B | E20: =Y!G24 -> 1202570 | F20: =B20*E20 -> 1924112 | G20: =F20/px-1 -> 0.11672198
A21: P/B 券商遠期 3.3x | B21: =pb_3 -> 3.3 | C21: 2028 期末 BVPS | D21: B | E21: =Y!G24 -> 1202570 | F21: =B21*E21 -> 3968480.9 | G21: =F21/px-1 -> 1.3032391
A22: P/B 1.0x | B22: =pb_1 -> 1 | C22: 2028 期末 BVPS | D22: C | E22: =Y!I24 -> 1111323.2 | F22: =B22*E22 -> 1111323.2 | G22: =F22/px-1 -> -0.35500683
A23: P/B 歷史中位 1.6x | B23: =pb_2 -> 1.6 | C23: 2028 期末 BVPS | D23: C | E23: =Y!I24 -> 1111323.2 | F23: =B23*E23 -> 1778117.2 | G23: =F23/px-1 -> 0.031989073
A24: P/B 券商遠期 3.3x | B24: =pb_3 -> 3.3 | C24: 2028 期末 BVPS | D24: C | E24: =Y!I24 -> 1111323.2 | F24: =B24*E24 -> 3667366.7 | G24: =F24/px-1 -> 1.1284775
A25: P/E 4x | B25: =pe_1 -> 4 | C25: 2027 EPS | D25: A | E25: =Y!D25 -> 550035.78 | F25: =B25*E25 -> 2200143.1 | G25: =F25/px-1 -> 0.27692577
A26: P/E 8x | B26: =pe_2 -> 8 | C26: 2027 EPS | D26: A | E26: =Y!D25 -> 550035.78 | F26: =B26*E26 -> 4400286.2 | G26: =F26/px-1 -> 1.5538515
A27: P/E 12x | B27: =pe_3 -> 12 | C27: 2027 EPS | D27: A | E27: =Y!D25 -> 550035.78 | F27: =B27*E27 -> 6600429.3 | G27: =F27/px-1 -> 2.8307773
A28: P/E 4x | B28: =pe_1 -> 4 | C28: 2027 EPS | D28: B | E28: =Y!F25 -> 534990.13 | F28: =B28*E28 -> 2139960.5 | G28: =F28/px-1 -> 0.24199681
A29: P/E 8x | B29: =pe_2 -> 8 | C29: 2027 EPS | D29: B | E29: =Y!F25 -> 534990.13 | F29: =B29*E29 -> 4279921 | G29: =F29/px-1 -> 1.4839936
A30: P/E 12x | B30: =pe_3 -> 12 | C30: 2027 EPS | D30: B | E30: =Y!F25 -> 534990.13 | F30: =B30*E30 -> 6419881.5 | G30: =F30/px-1 -> 2.7259904
A31: P/E 4x | B31: =pe_1 -> 4 | C31: 2027 EPS | D31: C | E31: =Y!H25 -> 534990.13 | F31: =B31*E31 -> 2139960.5 | G31: =F31/px-1 -> 0.24199681
A32: P/E 8x | B32: =pe_2 -> 8 | C32: 2027 EPS | D32: C | E32: =Y!H25 -> 534990.13 | F32: =B32*E32 -> 4279921 | G32: =F32/px-1 -> 1.4839936
A33: P/E 12x | B33: =pe_3 -> 12 | C33: 2027 EPS | D33: C | E33: =Y!H25 -> 534990.13 | F33: =B33*E33 -> 6419881.5 | G33: =F33/px-1 -> 2.7259904
A34: P/E 4x | B34: =pe_1 -> 4 | C34: 2028 EPS | D34: A | E34: =Y!E25 -> 714922.65 | F34: =B34*E34 -> 2859690.6 | G34: =F34/px-1 -> 0.65971597
A35: P/E 8x | B35: =pe_2 -> 8 | C35: 2028 EPS | D35: A | E35: =Y!E25 -> 714922.65 | F35: =B35*E35 -> 5719381.2 | G35: =F35/px-1 -> 2.3194319
A36: P/E 12x | B36: =pe_3 -> 12 | C36: 2028 EPS | D36: A | E36: =Y!E25 -> 714922.65 | F36: =B36*E36 -> 8579071.8 | G36: =F36/px-1 -> 3.9791479
A37: P/E 4x | B37: =pe_1 -> 4 | C37: 2028 EPS | D37: B | E37: =Y!G25 -> 334762.92 | F37: =B37*E37 -> 1339051.7 | G37: =F37/px-1 -> -0.22283709
A38: P/E 8x | B38: =pe_2 -> 8 | C38: 2028 EPS | D38: B | E38: =Y!G25 -> 334762.92 | F38: =B38*E38 -> 2678103.4 | G38: =F38/px-1 -> 0.55432582
A39: P/E 12x | B39: =pe_3 -> 12 | C39: 2028 EPS | D39: B | E39: =Y!G25 -> 334762.92 | F39: =B39*E39 -> 4017155.1 | G39: =F39/px-1 -> 1.3314887
A40: P/E 4x | B40: =pe_1 -> 4 | C40: 2028 EPS | D40: C | E40: =Y!I25 -> 216843.23 | F40: =B40*E40 -> 867372.9 | G40: =F40/px-1 -> -0.49659147
A41: P/E 8x | B41: =pe_2 -> 8 | C41: 2028 EPS | D41: C | E41: =Y!I25 -> 216843.23 | F41: =B41*E41 -> 1734745.8 | G41: =F41/px-1 -> 0.006817068
...

Sheet Sens
A1: Sens — 一次只動一個價格或份額輸入；Δ營業利益＝Δ營收 × (1 − 營業費用變動率)（成本只隨量變動，所以這是精確值，不是近似）
A3: 欄 | B3: 輸入變動 | C3: Δ營收 | D3: 營業利益 | E3: 相對基準
A4: 2027 A | B4: 基準 | D4: =Y!D14 -> 438.7247
A5: 2027 A | B5: 一般 DRAM 收入 −20% | C5: =-0.2*Y!D5 -> -60.029554 | D5: =D4+C5*(1-opex_var) -> 381.51654 | E5: =D5/D4-1 -> -0.1303965
A6: 2027 A | B6: 一般 DRAM 收入 +20% | C6: =0.2*Y!D5 -> 60.029554 | D6: =D4+C6*(1-opex_var) -> 495.93287 | E6: =D6/D4-1 -> 0.1303965
A7: 2027 A | B7: HBM 收入 −30%（價格或份額） | C7: =-0.3*Y!D6 -> -27.568763 | D7: =D4+C7*(1-opex_var) -> 412.45167 | E7: =D7/D4-1 -> -0.059885004
A8: 2027 A | B8: HBM 收入 +30% | C8: =0.3*Y!D6 -> 27.568763 | D8: =D4+C8*(1-opex_var) -> 464.99773 | E8: =D8/D4-1 -> 0.059885004
A9: 2027 A | B9: NAND 收入 −30% | C9: =-0.3*Y!D7 -> -41.360439 | D9: =D4+C9*(1-opex_var) -> 399.30821 | E9: =D9/D4-1 -> -0.089843352
A10: 2027 A | B10: NAND 收入 +30% | C10: =0.3*Y!D7 -> 41.360439 | D10: =D4+C10*(1-opex_var) -> 478.1412 | E10: =D10/D4-1 -> 0.089843352
A12: 2028 B | B12: 基準 | D12: =Y!G14 -> 245.15203
A13: 2028 B | B13: 一般 DRAM 收入 −20% | C13: =-0.2*Y!G5 -> -35.793019 | D13: =D12+C13*(1-opex_var) -> 211.04129 | E13: =D13/D12-1 -> -0.13914119
A14: 2028 B | B14: 一般 DRAM 收入 +20% | C14: =0.2*Y!G5 -> 35.793019 | D14: =D12+C14*(1-opex_var) -> 279.26278 | E14: =D14/D12-1 -> 0.13914119
A15: 2028 B | B15: HBM 收入 −30%（價格或份額） | C15: =-0.3*Y!G6 -> -28.553361 | D15: =D12+C15*(1-opex_var) -> 217.94068 | E15: =D15/D12-1 -> -0.11099787
A16: 2028 B | B16: HBM 收入 +30% | C16: =0.3*Y!G6 -> 28.553361 | D16: =D12+C16*(1-opex_var) -> 272.36339 | E16: =D16/D12-1 -> 0.11099787
A17: 2028 B | B17: NAND 收入 −30% | C17: =-0.3*Y!G7 -> -19.608824 | D17: =D12+C17*(1-opex_var) -> 226.46483 | E17: =D17/D12-1 -> -0.076227019
A18: 2028 B | B18: NAND 收入 +30% | C18: =0.3*Y!G7 -> 19.608824 | D18: =D12+C18*(1-opex_var) -> 263.83924 | E18: =D18/D12-1 -> 0.076227019
A20: 2028 C | B20: 基準 | D20: =Y!I14 -> 161.74727
A21: 2028 C | B21: 一般 DRAM 收入 −20% | C21: =-0.2*Y!I5 -> -24.552863 | D21: =D20+C21*(1-opex_var) -> 138.34839 | E21: =D21/D20-1 -> -0.14466321
A22: 2028 C | B22: 一般 DRAM 收入 +20% | C22: =0.2*Y!I5 -> 24.552863 | D22: =D20+C22*(1-opex_var) -> 185.14615 | E22: =D22/D20-1 -> 0.14466321
A23: 2028 C | B23: HBM 收入 −30%（價格或份額） | C23: =-0.3*Y!I6 -> -22.842689 | D23: =D20+C23*(1-opex_var) -> 139.97818 | E23: =D23/D20-1 -> -0.13458702
A24: 2028 C | B24: HBM 收入 +30% | C24: =0.3*Y!I6 -> 22.842689 | D24: =D20+C24*(1-opex_var) -> 183.51635 | E24: =D24/D20-1 -> 0.13458702
A25: 2028 C | B25: NAND 收入 −30% | C25: =-0.3*Y!I7 -> -15.924294 | D25: =D20+C25*(1-opex_var) -> 146.57142 | E25: =D25/D20-1 -> -0.093824472
A26: 2028 C | B26: NAND 收入 +30% | C26: =0.3*Y!I7 -> 15.924294 | D26: =D20+C26*(1-opex_var) -> 176.92312 | E26: =D26/D20-1 -> 0.093824472
A28: 讀法：哪一條收入線的同幅變動對營業利益影響最大，就是該年度的主要驅動。價格路徑本身的情境差異見 Y 頁 A／B／C 欄。

Sheet Recon
A1: Recon — 本模型（正向推導）vs 共識或公司指引（只作事後對照，不用來回推參數）；兆韓元
A3: 項目 | B3: 本模型 | C3: 對照值 | D3: 差距 | E3: 對照來源
A4: 2026E 營收 vs 共識 | B4: =Y!C4 -> 341.31923 | C4: 344.2 | D4: =B4/C4-1 -> -0.008369464 | E4: MarketScreener 2026-10-02
A5: 2026E 營業利益 vs 共識 | B5: =Y!C14 -> 265.87658 | C5: 266.1 | D5: =B5/C5-1 -> -0.00083961641 | E5: MarketScreener；FnGuide 265.2
A6: 2026E 淨利 vs 共識 | B6: =Y!C16 -> 264.95616 | C6: 256.3 | D6: =B6/C6-1 -> 0.033773528 | E6: MarketScreener
A7: 2026E HBM 營收 vs BofA | B7: =Y!C6 -> 40.779873 | C7: 45.7 | D7: =B7/C7-1 -> -0.10766142 | E7: BofA 2026-09-13；CLSA 49.4
A8: 2027E 營收（A）vs 共識 | B8: =Y!D4 -> 531.51177 | C8: 531.3 | D8: =B8/C8-1 -> 0.00039859647 | E8: MarketScreener
A9: 2027E 營業利益（A）vs 共識 | B9: =Y!D14 -> 438.7247 | C9: 417.2 | D9: =B9/C9-1 -> 0.05159325 | E9: MarketScreener；FnGuide 391.8（08-14）
A10: 2027E 淨利（A）vs 共識 | B10: =Y!D16 -> 340.58459 | C10: 336.2 | D10: =B10/C10-1 -> 0.013041606 | E10: MarketScreener
A11: 2028E 營業利益（A）vs 共識 | B11: =Y!E14 -> 479.967 | C11: 454 | D11: =B11/C11-1 -> 0.057196044 | E11: MarketScreener；FnGuide 399.1
A12: 2026Q3E 營收 vs 共識 | B12: =Q!H4 -> 96.311345 | C12: 94.1 | D12: =B12/C12-1 -> 0.023499947 | E12: FnGuide 2026-09-25
A13: 2026Q3E 營業利益 vs 共識 | B13: =Q!H10 -> 76.086392 | C13: 76.1 | D13: =B13/C13-1 -> -0.00017881772 | E13: FnGuide 74.1–78.1

Sheet Feedback
A1: Feedback — 回饋算力收支
A3: 每顆加速器 HBM 金額（GB300，2026 價） | B3: =nv_hbm -> 4.46 | C3: $K
A4: 全市場每顆加速器平均 HBM 2026／2027 | B4: =TEXT(Mkt!D16,"0")&" ／ "&TEXT(Mkt!E16,"0") -> 216 ／ 260 | C4: GB
A5: HBM 市場 2026／2027（A） | B5: =TEXT(Mkt!D23,"0")&" ／ "&TEXT(Mkt!E23,"0") -> 55 ／ 154 | C5: $B
A6: 2027 HBM 需求缺口 | B6: =Mkt!E19 -> 1.2325527 | C6: EB
A7: SK 海力士 HBM 毛利率 | B7: 無法由公開資料分離 | C7: —

Sheet Sources
A1: 來源
A2: SK hynix 424B4（2026-07） | B2: https://www.sec.gov/Archives/edgar/data/2120882/000119312526299963/d32785d424b4.htm
A3: SK hynix 6-K 半年報（2026-08-18） | B3: https://www.sec.gov/Archives/edgar/data/2120882/000119312526354777/d147827d6k.htm
A4: Q2 2026 法說逐字稿 | B4: https://ng.investing.com/news/transcripts/earnings-call-transcript-sk-hynix-posts-record-q2-2026-results-as-shares-fall-93CH-2622277
A5: MarketScreener 共識 | B5: https://www.marketscreener.com/quote/stock/SK-HYNIX-INC-6494929/finances/
A6: Herald Business：FnGuide、目標價 | B6: https://biz.heraldcorp.com/article/10841314
A7: BofA HBM（Economy Tribune） | B7: https://www.economytribune.co.kr/news/articleView.html?idxno=3903874
A8: 40 兆買回（Korea Herald） | B8: https://www.koreaherald.com/article/10845792
A9: UBS 2027 HBM 市占（Korea Herald） | B9: https://www.koreaherald.com/article/10828143
A10: companiesmarketcap P/B | B10: https://companiesmarketcap.com/sk-hynix/pb-ratio/
A11: TrendForce 4Q26 價格 | B11: https://www.trendforce.com/presscenter/news/20260930-13258.html
A12: Citi 2027 見頂 | B12: https://www.tipranks.com/news/memory-prices-will-peak-next-year-warns-citi-as-it-cuts-micron-mu-price-target-by-18
A13: Bernstein 2028 | B13: https://www.notebookcheck.net/DRAM-crisis-Analysts-expect-drastic-price-drop-in-2028.1337992.0.html
... A15: markets/chip_bridge v0.1 | B15: 本 repo
