Workbook

Sheet In
A1: In — R4 Wattonomics 側歸因的輸入。藍字＝輸入：取自 20261031_Wattonomics_v0.1.7.xlsx（Wattonomics v0.1.7）與 20261031_R4對帳橋接_Siliconomics側_r1.xlsx（Siliconomics 側 r1）；低／高為敏感度。標記沿用專案規則。
A3: 鍵 | B3: 項目 | C3: 單位 | D3: 低 | E3: 基準 | F3: 高 | G3: 標記 | H3: 來源
A4: A. Siliconomics 側 R4 橋接 r1（情境 A；Bridge 頁值）
A5: s_b1_2026 | B5: Siliconomics 部署 GW（成本等值；出貨年） 2026 | C5: GW | E5: 23.399538 | G5: Derived | H5: 20261031_R4對帳橋接_Siliconomics側_r1.xlsx Bridge!E4
A6: s_b1_2027 | B6: Siliconomics 部署 GW（成本等值；出貨年） 2027 | C6: GW | E6: 41.646766 | G6: Derived | H6: 20261031_R4對帳橋接_Siliconomics側_r1.xlsx Bridge!F4
A7: s_b1_2028 | B7: Siliconomics 部署 GW（成本等值；出貨年） 2028 | C7: GW | E7: 52.792138 | G7: Derived | H7: 20261031_R4對帳橋接_Siliconomics側_r1.xlsx Bridge!G4
A8: s_b1_2029 | B8: Siliconomics 部署 GW（成本等值；出貨年） 2029 | C8: GW | E8: 60.138592 | G8: Derived | H8: 20261031_R4對帳橋接_Siliconomics側_r1.xlsx Bridge!H4
A9: s_b2_2026 | B9: ① 成本等值 → 實體 2026 | C9: GW | E9: 1.6302797 | G9: Derived | H9: 20261031_R4對帳橋接_Siliconomics側_r1.xlsx Bridge!E7
A10: s_b2_2027 | B10: ① 成本等值 → 實體 2027 | C10: GW | E10: 4.6089461 | G10: Derived | H10: 20261031_R4對帳橋接_Siliconomics側_r1.xlsx Bridge!F7
A11: s_b2_2028 | B11: ① 成本等值 → 實體 2028 | C11: GW | E11: 5.6065384 | G11: Derived | H11: 20261031_R4對帳橋接_Siliconomics側_r1.xlsx Bridge!G7
A12: s_b2_2029 | B12: ① 成本等值 → 實體 2029 | C12: GW | E12: 6.4475192 | G12: Derived | H12: 20261031_R4對帳橋接_Siliconomics側_r1.xlsx Bridge!H7
A13: s_b3_2025 | B13: 實體出貨 GW 2025 | C13: GW | E13: 16.136572 | G13: Derived | H13: 20261031_R4對帳橋接_Siliconomics側_r1.xlsx Bridge!D8
A14: s_b3_2026 | B14: 實體出貨 GW 2026 | C14: GW | E14: 25.029818 | G14: Derived | H14: 20261031_R4對帳橋接_Siliconomics側_r1.xlsx Bridge!E8
A15: s_b3_2027 | B15: 實體出貨 GW 2027 | C15: GW | E15: 46.255712 | G15: Derived | H15: 20261031_R4對帳橋接_Siliconomics側_r1.xlsx Bridge!F8
A16: s_b3_2028 | B16: 實體出貨 GW 2028 | C16: GW | E16: 58.398677 | G16: Derived | H16: 20261031_R4對帳橋接_Siliconomics側_r1.xlsx Bridge!G8
... A41: s_b10_2029 | B41: ⑥ 殘差（r1） 2029 | C41: GW | E41: 33.25885 | G41: Derived | H41: 20261031_R4對帳橋接_Siliconomics側_r1.xlsx Bridge!H17
A42: lag | B42: 出貨到上線的平均延遲（年） | C42: 年 | D42: 0.25 | E42: 0.375 | F42: 0.5 | G42: Assumed | H42: 20261031_R4對帳橋接_Siliconomics側_r1.xlsx In!D52:F52（與 Siliconomics 側同參數，對稱套用）
A43: inv_k | B43: 已出貨未上線庫存 ÷ 年出貨（庫存增加＝k × 出貨年增量） | C43: x | D43: 0.05 | E43: 0.1 | F43: 0.2 | G43: Assumed | H43: 20261031_R4對帳橋接_Siliconomics側_r1.xlsx In!D58:F58（與 Siliconomics 側同參數，對稱套用）
A44: retire | B44: 汰換率（舊加速器下線釋出的電力 ÷ 前一年年底在役 IT GW） | C44: % | D44: 0 | E44: 0.02 | F44: 0.05 | G44: Assumed | H44: 20261031_R4對帳橋接_Siliconomics側_r1.xlsx In!D59:F59（與 Siliconomics 側同參數，對稱套用）
A45: s_cap_oth_2026 | B45: Siliconomics 其他 ASIC（MTIA、Maia、昇騰等）AI IT capex 2026 | C45: $B | E45: 20 | G45: Derived | H45: 20261031_R4對帳橋接_Siliconomics側_r1.xlsx In!E33
A46: pgw_vr | B46: VR200 每 IT GW IT capex | C46: $B/GW | D46: 31.997023 | E46: 37.586352 | F46: 42.637575 | G46: Derived | H46: 20261031_R4對帳橋接_Siliconomics側_r1.xlsx In!E46；原出處：Tokenomics v21.7 IF_CapexIT（TK_In 鏡像）
A47: hold_oth | B47: 持有成本比 其他 ASIC ÷ VR200（Maia、昇騰、OpenAI 客製三者簡單平均） | C47: x | D47: 0.517 | E47: 0.617 | F47: 0.767 | G47: Assumed | H47: 20261031_R4對帳橋接_Siliconomics側_r1.xlsx In!E50；原出處：Tokenomics v21.7 IF_NonNV_Hold_Maia 0.5、_Ascend 0.55、_OAI 0.8；MTIA 無 TK 值，組合權重未知故取簡單平均
A48: nv_dc_25 | B48: NVIDIA 資料中心營收 FY2026（約 CY2025） | C48: $B | E48: 193.7 | G48: Verified | H48: 20261031_R4對帳橋接_Siliconomics側_r1.xlsx In!E53；原出處：NVIDIA 8-K：FY26 Q1–Q4 39.1／41.1／51.2／62.3（nvidia/build_nvidia.py Q 頁）
A49: nv_dc_26 | B49: NVIDIA 資料中心營收 FY2027 錨點（約 CY2026） | C49: $B | E49: 375.46 | G49: Verified／Assumed | H49: 20261031_R4對帳橋接_Siliconomics側_r1.xlsx In!E54；原出處：Q1、Q2 實績 75.2／89.0（8-K）＋Q3 指引中點＋Q4 假設（NVIDIA 個股模型 v0.2.3）
A50: nvc_gb_tk | B50: Tokenomics 隱含 NVIDIA 內容 每 IT GW（GB300） | C50: $B/GW | E50: 20.84 | G50: Derived | H50: 20261031_R4對帳橋接_Siliconomics側_r1.xlsx In!E61；原出處：TK IF_GPUsPerGW GB300 487,008 × 每顆 NVIDIA 內容 42.8 千美元（Siliconomics nv_content）
A51: nvc_gb_jh | B51: 黃仁勳說法：NVIDIA 每 GW 內容（Grace Blackwell） | C51: $B/GW | E51: 25 | G51: Interested-party | H51: 20261031_R4對帳橋接_Siliconomics側_r1.xlsx In!E62；原出處：247wallst 2026-09-24 轉述：Hopper 約 18、Grace Blackwell 約 25、Vera Rubin 約 40（十億美元／GW）；Bg2 Pod 2026-10-15「18 → 20 some → 40 plus」。GW 口徑（IT 或廠區）未說明
A52: B. Wattonomics 市場層（20261031_Wattonomics_v0.1.7.xlsx；需求 A、D0）
A53: wt_new_2025 | B53: Wattonomics 年新增 IT GW（主路徑）2025 | C53: GW | E53: 9.0491243 | G53: Derived | H53: 20261031_Wattonomics_v0.1.7.xlsx Deploy!F19
A54: wt_new_2026 | B54: Wattonomics 年新增 IT GW（主路徑）2026 | C54: GW | E54: 12.515371 | G54: Derived | H54: 20261031_Wattonomics_v0.1.7.xlsx Deploy!G19
A55: wt_new_2027 | B55: Wattonomics 年新增 IT GW（主路徑）2027 | C55: GW | E55: 23.962254 | G55: Derived | H55: 20261031_Wattonomics_v0.1.7.xlsx Deploy!H19
A56: wt_new_2028 | B56: Wattonomics 年新增 IT GW（主路徑）2028 | C56: GW | E56: 26.923293 | G56: Derived | H56: 20261031_Wattonomics_v0.1.7.xlsx Deploy!I19
A57: wt_new_2029 | B57: Wattonomics 年新增 IT GW（主路徑）2029 | C57: GW | E57: 27.663468 | G57: Derived | H57: 20261031_Wattonomics_v0.1.7.xlsx Deploy!J19
A58: wt_ye_2025 | B58: Wattonomics 年底上線 IT GW（主路徑）2025 | C58: GW | E58: 25.337143 | G58: Derived | H58: 20261031_Wattonomics_v0.1.7.xlsx Deploy!F13
A59: wt_ye_2026 | B59: Wattonomics 年底上線 IT GW（主路徑）2026 | C59: GW | E59: 37.852515 | G59: Derived | H59: 20261031_Wattonomics_v0.1.7.xlsx Deploy!G13
A60: wt_ye_2027 | B60: Wattonomics 年底上線 IT GW（主路徑）2027 | C60: GW | E60: 61.814769 | G60: Derived | H60: 20261031_Wattonomics_v0.1.7.xlsx Deploy!H13
A61: wt_ye_2028 | B61: Wattonomics 年底上線 IT GW（主路徑）2028 | C61: GW | E61: 88.738062 | G61: Derived | H61: 20261031_Wattonomics_v0.1.7.xlsx Deploy!I13
A62: wt_ye_2029 | B62: Wattonomics 年底上線 IT GW（主路徑）2029 | C62: GW | E62: 116.40153 | G62: Derived | H62: 20261031_Wattonomics_v0.1.7.xlsx Deploy!J13
A63: nnv_mkt_2026 | B63: 市場新增 GW 非 NVIDIA 占比 2026 | C63: % | E63: 0.23821007 | G63: Derived | H63: 20261031_Wattonomics_v0.1.7.xlsx Players!G12
A64: nnv_mkt_2027 | B64: 市場新增 GW 非 NVIDIA 占比 2027 | C64: % | E64: 0.27310186 | G64: Derived | H64: 20261031_Wattonomics_v0.1.7.xlsx Players!H12
... A71: oth_ye_2025 | B71: Wattonomics「其他（主權、企業、學研）」2025 年底 IT GW（之後持平） | C71: GW | E71: 1 | G71: Derived | H71: 20261031_Wattonomics_v0.1.7.xlsx Players!F296（2026 起無園區列，年新增＝0）
...

Sheet Calc
A1: Calc — 甲2 重算（與 Wattonomics CapexGW 同式）：當年資金＝IT 占比 × AI_t ＋ 廠房占比 ×（w1·AI_t−1 ＋ w2·AI_t−2）；CapexGW 在 t−1、t−2 缺值時留空，本頁改為：缺 t−2 用 t−1、兩者皆缺用當年（只影響 2024–2026 與無前期值的玩家，屬近似）；GW_付款年＝資金 ÷（IT＋廠房）；資金缺值時以站點年新增代入（同 CapexGW「缺值以甲代入」）。上線年＝(1−lag)·GW_t ＋ lag·GW_t−1 − inv_k·(GW_t − GW_t−1)（與 Siliconomics ②③ 同參數）。
A3: ■ 情況：基準
A4: 鍵 | B4: 項目 | C4: 2024 | D4: 2025 | E4: 2026 | F4: 2027 | G4: 2028 | H4: 2029
A5: base_ai2_msft | B5: Microsoft 曆年 AI 資本支出（In Y2） | D5: =IF(ISNUMBER(ai2_msft_2024),ai2_msft_2024,"") -> 46.3369 | E5: =IF(ISNUMBER(ai2_msft_2025),ai2_msft_2025,"") -> 76.712075 | F5: =IF(ISNUMBER(ai2_msft_2026),ai2_msft_2026,"") -> 131.22938 | G5: =IF(ISNUMBER(ai2_msft_2027),ai2_msft_2027,"") -> 174.08595 | H5: =IF(ISNUMBER(ai2_msft_2028),ai2_msft_2028,"") -> 198.883 | I5: =IF(ISNUMBER(ai2_msft_2029),ai2_msft_2029,"") -> 224.1719
A6: base_x2_msft | B6: Microsoft 甲2 年新增 IT GW（付款年；缺值以站點代入） | D6: =IF(ISNUMBER(D5),(pit_msft_2024/(pit_msft_2024+pfac_msft_2024)*D5+pfac_msft_2024/(pit_msft_2024+pfac_msft_2024)*IF(AND(ISNUMBER(""),ISNUMBER("")),wb1*""+wb2*"",IF(ISNUMBER(""),"",D5)))/(pit_msft_2024+pfac_msft_2024),site_msft_2024) -> 1.26622 | E6: =IF(ISNUMBER(E5),(pit_msft_2025/(pit_msft_2025+pfac_msft_2025)*E5+pfac_msft_2025/(pit_msft_2025+pfac_msft_2025)*IF(AND(ISNUMBER(D5),ISNUMBER("")),wb1*D5+wb2*"",IF(ISNUMBER(D5),D5,E5)))/(pit_msft_2025+pfac_msft_2025),site_msft_2025) -> 1.8941339 | F6: =IF(ISNUMBER(F5),(pit_msft_2026/(pit_msft_2026+pfac_msft_2026)*F5+pfac_msft_2026/(pit_msft_2026+pfac_msft_2026)*IF(AND(ISNUMBER(E5),ISNUMBER(D5)),wb1*E5+wb2*D5,IF(ISNUMBER(E5),E5,F5)))/(pit_msft_2026+pfac_msft_2026),site_msft_2026) -> 2.7328098 | G6: =IF(ISNUMBER(G5),(pit_msft_2027/(pit_msft_2027+pfac_msft_2027)*G5+pfac_msft_2027/(pit_msft_2027+pfac_msft_2027)*IF(AND(ISNUMBER(F5),ISNUMBER(E5)),wb1*F5+wb2*E5,IF(ISNUMBER(F5),F5,G5)))/(pit_msft_2027+pfac_msft_2027),site_msft_2027) -> 3.5644758 | H6: =IF(ISNUMBER(H5),(pit_msft_2028/(pit_msft_2028+pfac_msft_2028)*H5+pfac_msft_2028/(pit_msft_2028+pfac_msft_2028)*IF(AND(ISNUMBER(G5),ISNUMBER(F5)),wb1*G5+wb2*F5,IF(ISNUMBER(G5),G5,H5)))/(pit_msft_2028+pfac_msft_2028),site_msft_2028) -> 4.0659788 | I6: =IF(ISNUMBER(I5),(pit_msft_2029/(pit_msft_2029+pfac_msft_2029)*I5+pfac_msft_2029/(pit_msft_2029+pfac_msft_2029)*IF(AND(ISNUMBER(H5),ISNUMBER(G5)),wb1*H5+wb2*G5,IF(ISNUMBER(H5),H5,I5)))/(pit_msft_2029+pfac_msft_2029),site_msft_2029) -> 4.664421
A7: base_on2_msft | B7: Microsoft 甲2 年新增 IT GW（上線年） | E7: =(1-lag)*E6+lag*D6-inv_k*(E6-D6) -> 1.5958748 | F7: =(1-lag)*F6+lag*E6-inv_k*(F6-E6) -> 2.3344388 | G7: =(1-lag)*G6+lag*F6-inv_k*(G6-F6) -> 3.1694344 | H7: =(1-lag)*H6+lag*G6-inv_k*(H6-G6) -> 3.8277648 | I7: =(1-lag)*I6+lag*H6-inv_k*(I6-H6) -> 4.3801609
A8: base_ai9_msft | B8: Microsoft 曆年 AI 資本支出（Y9 個股模型 v0.3） | D8: ="" | E8: =(6/12*cap2_msft_2025+6/12*gcap_msft_2026)*ai_sh -> 89.186675 | F8: =(6/12*gcap_msft_2026+6/12*gcap_msft_2027)*ai_sh -> 148.5375 | G8: =(6/12*gcap_msft_2027+6/12*gcap_msft_2028)*ai_sh -> 185.93958 | H8: =(6/12*gcap_msft_2028+6/12*gcap_msft_2029)*ai_sh -> 202.79786 | I8: =(6/12*gcap_msft_2029+6/12*gcap_msft_2030)*ai_sh -> 197.61173
A9: base_x9_msft | B9: Microsoft 甲2 年新增 IT GW（付款年；缺值以站點代入） | D9: =IF(ISNUMBER(D8),(pit_msft_2024/(pit_msft_2024+pfac_msft_2024)*D8+pfac_msft_2024/(pit_msft_2024+pfac_msft_2024)*IF(AND(ISNUMBER(""),ISNUMBER("")),wb1*""+wb2*"",IF(ISNUMBER(""),"",D8)))/(pit_msft_2024+pfac_msft_2024),site_msft_2024) -> 0 | E9: =IF(ISNUMBER(E8),(pit_msft_2025/(pit_msft_2025+pfac_msft_2025)*E8+pfac_msft_2025/(pit_msft_2025+pfac_msft_2025)*IF(AND(ISNUMBER(D8),ISNUMBER("")),wb1*D8+wb2*"",IF(ISNUMBER(D8),D8,E8)))/(pit_msft_2025+pfac_msft_2025),site_msft_2025) -> 2.5157644 | F9: =IF(ISNUMBER(F8),(pit_msft_2026/(pit_msft_2026+pfac_msft_2026)*F8+pfac_msft_2026/(pit_msft_2026+pfac_msft_2026)*IF(AND(ISNUMBER(E8),ISNUMBER(D8)),wb1*E8+wb2*D8,IF(ISNUMBER(E8),E8,F8)))/(pit_msft_2026+pfac_msft_2026),site_msft_2026) -> 3.2224502 | G9: =IF(ISNUMBER(G8),(pit_msft_2027/(pit_msft_2027+pfac_msft_2027)*G8+pfac_msft_2027/(pit_msft_2027+pfac_msft_2027)*IF(AND(ISNUMBER(F8),ISNUMBER(E8)),wb1*F8+wb2*E8,IF(ISNUMBER(F8),F8,G8)))/(pit_msft_2027+pfac_msft_2027),site_msft_2027) -> 3.8514435 | H9: =IF(ISNUMBER(H8),(pit_msft_2028/(pit_msft_2028+pfac_msft_2028)*H8+pfac_msft_2028/(pit_msft_2028+pfac_msft_2028)*IF(AND(ISNUMBER(G8),ISNUMBER(F8)),wb1*G8+wb2*F8,IF(ISNUMBER(G8),G8,H8)))/(pit_msft_2028+pfac_msft_2028),site_msft_2028) -> 4.2054206 | I9: =IF(ISNUMBER(I8),(pit_msft_2029/(pit_msft_2029+pfac_msft_2029)*I8+pfac_msft_2029/(pit_msft_2029+pfac_msft_2029)*IF(AND(ISNUMBER(H8),ISNUMBER(G8)),wb1*H8+wb2*G8,IF(ISNUMBER(H8),H8,I8)))/(pit_msft_2029+pfac_msft_2029),site_msft_2029) -> 4.2658892
A10: base_on9_msft | B10: Microsoft 甲2 年新增 IT GW（上線年） | E10: =(1-lag)*E9+lag*D9-inv_k*(E9-D9) -> 1.3207763 | F10: =(1-lag)*F9+lag*E9-inv_k*(F9-E9) -> 2.8867744 | G10: =(1-lag)*G9+lag*F9-inv_k*(G9-F9) -> 3.5526716 | H10: =(1-lag)*H9+lag*G9-inv_k*(H9-G9) -> 4.0372815 | I10: =(1-lag)*I9+lag*H9-inv_k*(I9-H9) -> 4.2371666
A11: base_site_msft | B11: Microsoft 甲（站點）年新增 | D11: =site_msft_2024 -> 0 | E11: =site_msft_2025 -> 2.13527 | F11: =site_msft_2026 -> 0.770955 | G11: =site_msft_2027 -> 1.04 | H11: =site_msft_2028 -> 1.67 | I11: =site_msft_2029 -> 0.144
A12: base_ai2_googl | B12: Alphabet 曆年 AI 資本支出（In Y2） | D12: =IF(ISNUMBER(ai2_googl_2024),ai2_googl_2024,"") | E12: =IF(ISNUMBER(ai2_googl_2025),ai2_googl_2025,"") -> 77.72995 | F12: =IF(ISNUMBER(ai2_googl_2026),ai2_googl_2026,"") -> 170 | G12: =IF(ISNUMBER(ai2_googl_2027),ai2_googl_2027,"") -> 255.83215 | H12: =IF(ISNUMBER(ai2_googl_2028),ai2_googl_2028,"") -> 288.53335 | I12: =IF(ISNUMBER(ai2_googl_2029),ai2_googl_2029,"") -> 317.38668
A13: base_x2_googl | B13: Alphabet 甲2 年新增 IT GW（付款年；缺值以站點代入） | D13: =IF(ISNUMBER(D12),(pit_googl_2024/(pit_googl_2024+pfac_googl_2024)*D12+pfac_googl_2024/(pit_googl_2024+pfac_googl_2024)*IF(AND(ISNUMBER(""),ISNUMBER("")),wb1*""+wb2*"",IF(ISNUMBER(""),"",D12)))/(pit_googl_2024+pfac_googl_2024),site_googl_2024) -> 1.3298083 | E13: =IF(ISNUMBER(E12),(pit_googl_2025/(pit_googl_2025+pfac_googl_2025)*E12+pfac_googl_2025/(pit_googl_2025+pfac_googl_2025)*IF(AND(ISNUMBER(D12),ISNUMBER("")),wb1*D12+wb2*"",IF(ISNUMBER(D12),D12,E12)))/(pit_googl_2025+pfac_googl_2025),site_googl_2025) -> 2.156538 | F13: =IF(ISNUMBER(F12),(pit_googl_2026/(pit_googl_2026+pfac_googl_2026)*F12+pfac_googl_2026/(pit_googl_2026+pfac_googl_2026)*IF(AND(ISNUMBER(E12),ISNUMBER(D12)),wb1*E12+wb2*D12,IF(ISNUMBER(E12),E12,F12)))/(pit_googl_2026+pfac_googl_2026),site_googl_2026) -> 3.8577751 | G13: =IF(ISNUMBER(G12),(pit_googl_2027/(pit_googl_2027+pfac_googl_2027)*G12+pfac_googl_2027/(pit_googl_2027+pfac_googl_2027)*IF(AND(ISNUMBER(F12),ISNUMBER(E12)),wb1*F12+wb2*E12,IF(ISNUMBER(F12),F12,G12)))/(pit_googl_2027+pfac_googl_2027),site_googl_2027) -> 5.6976857 | H13: =IF(ISNUMBER(H12),(pit_googl_2028/(pit_googl_2028+pfac_googl_2028)*H12+pfac_googl_2028/(pit_googl_2028+pfac_googl_2028)*IF(AND(ISNUMBER(G12),ISNUMBER(F12)),wb1*G12+wb2*F12,IF(ISNUMBER(G12),G12,H12)))/(pit_googl_2028+pfac_googl_2028),site_googl_2028) -> 6.7768241 | I13: =IF(ISNUMBER(I12),(pit_googl_2029/(pit_googl_2029+pfac_googl_2029)*I12+pfac_googl_2029/(pit_googl_2029+pfac_googl_2029)*IF(AND(ISNUMBER(H12),ISNUMBER(G12)),wb1*H12+wb2*G12,IF(ISNUMBER(H12),H12,I12)))/(pit_googl_2029+pfac_googl_2029),site_googl_2029) -> 7.6892959
A14: base_on2_googl | B14: Alphabet 甲2 年新增 IT GW（上線年） | E14: =(1-lag)*E13+lag*D13-inv_k*(E13-D13) -> 1.7638414 | F14: =(1-lag)*F13+lag*E13-inv_k*(F13-E13) -> 3.0496875 | G14: =(1-lag)*G13+lag*F13-inv_k*(G13-F13) -> 4.8237282 | H14: =(1-lag)*H13+lag*G13-inv_k*(H13-G13) -> 6.2642334 | I14: =(1-lag)*I13+lag*H13-inv_k*(I13-H13) -> 7.2558718
A15: base_ai9_googl | B15: Alphabet 曆年 AI 資本支出（Y9 個股模型 v0.3） | D15: =gcap_googl_2024*ai_sh -> 44.65475 | E15: =gcap_googl_2025*ai_sh -> 77.72995 | F15: =gcap_googl_2026*ai_sh -> 170 | G15: =gcap_googl_2027*ai_sh -> 246.81037 | H15: =gcap_googl_2028*ai_sh -> 269.78901 | I15: =gcap_googl_2029*ai_sh -> 248.67674
A16: base_x9_googl | B16: Alphabet 甲2 年新增 IT GW（付款年；缺值以站點代入） | D16: =IF(ISNUMBER(D15),(pit_googl_2024/(pit_googl_2024+pfac_googl_2024)*D15+pfac_googl_2024/(pit_googl_2024+pfac_googl_2024)*IF(AND(ISNUMBER(""),ISNUMBER("")),wb1*""+wb2*"",IF(ISNUMBER(""),"",D15)))/(pit_googl_2024+pfac_googl_2024),site_googl_2024) -> 1.2262858 | E16: =IF(ISNUMBER(E15),(pit_googl_2025/(pit_googl_2025+pfac_googl_2025)*E15+pfac_googl_2025/(pit_googl_2025+pfac_googl_2025)*IF(AND(ISNUMBER(D15),ISNUMBER("")),wb1*D15+wb2*"",IF(ISNUMBER(D15),D15,E15)))/(pit_googl_2025+pfac_googl_2025),site_googl_2025) -> 1.9068409 | F16: =IF(ISNUMBER(F15),(pit_googl_2026/(pit_googl_2026+pfac_googl_2026)*F15+pfac_googl_2026/(pit_googl_2026+pfac_googl_2026)*IF(AND(ISNUMBER(E15),ISNUMBER(D15)),wb1*E15+wb2*D15,IF(ISNUMBER(E15),E15,F15)))/(pit_googl_2026+pfac_googl_2026),site_googl_2026) -> 3.7446941 | G16: =IF(ISNUMBER(G15),(pit_googl_2027/(pit_googl_2027+pfac_googl_2027)*G15+pfac_googl_2027/(pit_googl_2027+pfac_googl_2027)*IF(AND(ISNUMBER(F15),ISNUMBER(E15)),wb1*F15+wb2*E15,IF(ISNUMBER(F15),F15,G15)))/(pit_googl_2027+pfac_googl_2027),site_googl_2027) -> 5.5247971 | H16: =IF(ISNUMBER(H15),(pit_googl_2028/(pit_googl_2028+pfac_googl_2028)*H15+pfac_googl_2028/(pit_googl_2028+pfac_googl_2028)*IF(AND(ISNUMBER(G15),ISNUMBER(F15)),wb1*G15+wb2*F15,IF(ISNUMBER(G15),G15,H15)))/(pit_googl_2028+pfac_googl_2028),site_googl_2028) -> 6.3942025 | I16: =IF(ISNUMBER(I15),(pit_googl_2029/(pit_googl_2029+pfac_googl_2029)*I15+pfac_googl_2029/(pit_googl_2029+pfac_googl_2029)*IF(AND(ISNUMBER(H15),ISNUMBER(G15)),wb1*H15+wb2*G15,IF(ISNUMBER(H15),H15,I15)))/(pit_googl_2029+pfac_googl_2029),site_googl_2029) -> 6.303142
A17: base_on9_googl | B17: Alphabet 甲2 年新增 IT GW（上線年） | E17: =(1-lag)*E16+lag*D16-inv_k*(E16-D16) -> 1.5835772 | F17: =(1-lag)*F16+lag*E16-inv_k*(F16-E16) -> 2.8717138 | G17: =(1-lag)*G16+lag*F16-inv_k*(G16-F16) -> 4.6792482 | H17: =(1-lag)*H16+lag*G16-inv_k*(H16-G16) -> 5.9812349 | I17: =(1-lag)*I16+lag*H16-inv_k*(I16-H16) -> 6.3463957
A18: base_site_googl | B18: Alphabet 甲（站點）年新增 | D18: =site_googl_2024 -> 1.3298083 | E18: =site_googl_2025 -> 2.4096133 | F18: =site_googl_2026 -> 1.2926791 | G18: =site_googl_2027 -> 1.626 | H18: =site_googl_2028 -> 0.83333333 | I18: =site_googl_2029 -> 0
A19: base_ai2_amzn | B19: Amazon 曆年 AI 資本支出（In Y2） | D19: =IF(ISNUMBER(ai2_amzn_2024),ai2_amzn_2024,"") | E19: =IF(ISNUMBER(ai2_amzn_2025),ai2_amzn_2025,"") -> 87.2576 | F19: =IF(ISNUMBER(ai2_amzn_2026),ai2_amzn_2026,"") -> 149.6 | G19: =IF(ISNUMBER(ai2_amzn_2027),ai2_amzn_2027,"") -> 187.04284 | H19: =IF(ISNUMBER(ai2_amzn_2028),ai2_amzn_2028,"") -> 199.19036 | I19: =IF(ISNUMBER(ai2_amzn_2029),ai2_amzn_2029,"") -> 219.1094
A20: base_x2_amzn | B20: Amazon 甲2 年新增 IT GW（付款年；缺值以站點代入） | D20: =IF(ISNUMBER(D19),(pit_amzn_2024/(pit_amzn_2024+pfac_amzn_2024)*D19+pfac_amzn_2024/(pit_amzn_2024+pfac_amzn_2024)*IF(AND(ISNUMBER(""),ISNUMBER("")),wb1*""+wb2*"",IF(ISNUMBER(""),"",D19)))/(pit_amzn_2024+pfac_amzn_2024),site_amzn_2024) -> 0 | E20: =IF(ISNUMBER(E19),(pit_amzn_2025/(pit_amzn_2025+pfac_amzn_2025)*E19+pfac_amzn_2025/(pit_amzn_2025+pfac_amzn_2025)*IF(AND(ISNUMBER(D19),ISNUMBER("")),wb1*D19+wb2*"",IF(ISNUMBER(D19),D19,E19)))/(pit_amzn_2025+pfac_amzn_2025),site_amzn_2025) -> 2.6200438 | F20: =IF(ISNUMBER(F19),(pit_amzn_2026/(pit_amzn_2026+pfac_amzn_2026)*F19+pfac_amzn_2026/(pit_amzn_2026+pfac_amzn_2026)*IF(AND(ISNUMBER(E19),ISNUMBER(D19)),wb1*E19+wb2*D19,IF(ISNUMBER(E19),E19,F19)))/(pit_amzn_2026+pfac_amzn_2026),site_amzn_2026) -> 3.7283069 | G20: =IF(ISNUMBER(G19),(pit_amzn_2027/(pit_amzn_2027+pfac_amzn_2027)*G19+pfac_amzn_2027/(pit_amzn_2027+pfac_amzn_2027)*IF(AND(ISNUMBER(F19),ISNUMBER(E19)),wb1*F19+wb2*E19,IF(ISNUMBER(F19),F19,G19)))/(pit_amzn_2027+pfac_amzn_2027),site_amzn_2027) -> 4.5449655 | H20: =IF(ISNUMBER(H19),(pit_amzn_2028/(pit_amzn_2028+pfac_amzn_2028)*H19+pfac_amzn_2028/(pit_amzn_2028+pfac_amzn_2028)*IF(AND(ISNUMBER(G19),ISNUMBER(F19)),wb1*G19+wb2*F19,IF(ISNUMBER(G19),G19,H19)))/(pit_amzn_2028+pfac_amzn_2028),site_amzn_2028) -> 4.9962382 | I20: =IF(ISNUMBER(I19),(pit_amzn_2029/(pit_amzn_2029+pfac_amzn_2029)*I19+pfac_amzn_2029/(pit_amzn_2029+pfac_amzn_2029)*IF(AND(ISNUMBER(H19),ISNUMBER(G19)),wb1*H19+wb2*G19,IF(ISNUMBER(H19),H19,I19)))/(pit_amzn_2029+pfac_amzn_2029),site_amzn_2029) -> 5.5465088
A21: base_on2_amzn | B21: Amazon 甲2 年新增 IT GW（上線年） | E21: =(1-lag)*E20+lag*D20-inv_k*(E20-D20) -> 1.375523 | F21: =(1-lag)*F20+lag*E20-inv_k*(F20-E20) -> 3.2018819 | G21: =(1-lag)*G20+lag*F20-inv_k*(G20-F20) -> 4.1570526 | H21: =(1-lag)*H20+lag*G20-inv_k*(H20-G20) -> 4.7818837 | I21: =(1-lag)*I20+lag*H20-inv_k*(I20-H20) -> 5.2851303
A22: base_ai9_amzn | B22: Amazon 曆年 AI 資本支出（Y9 個股模型 v0.3） | D22: =gcap_amzn_2024*ai_amzn -> 52.80744 | E22: =gcap_amzn_2025*ai_amzn -> 87.2576 | F22: =gcap_amzn_2026*ai_amzn -> 149.6 | G22: =gcap_amzn_2027*ai_amzn -> 172.09446 | H22: =gcap_amzn_2028*ai_amzn -> 181.54067 | I22: =gcap_amzn_2029*ai_amzn -> 189.31601
A23: base_x9_amzn | B23: Amazon 甲2 年新增 IT GW（付款年；缺值以站點代入） | D23: =IF(ISNUMBER(D22),(pit_amzn_2024/(pit_amzn_2024+pfac_amzn_2024)*D22+pfac_amzn_2024/(pit_amzn_2024+pfac_amzn_2024)*IF(AND(ISNUMBER(""),ISNUMBER("")),wb1*""+wb2*"",IF(ISNUMBER(""),"",D22)))/(pit_amzn_2024+pfac_amzn_2024),site_amzn_2024) -> 1.5623853 | E23: =IF(ISNUMBER(E22),(pit_amzn_2025/(pit_amzn_2025+pfac_amzn_2025)*E22+pfac_amzn_2025/(pit_amzn_2025+pfac_amzn_2025)*IF(AND(ISNUMBER(D22),ISNUMBER("")),wb1*D22+wb2*"",IF(ISNUMBER(D22),D22,E22)))/(pit_amzn_2025+pfac_amzn_2025),site_amzn_2025) -> 2.3293428 | F23: =IF(ISNUMBER(F22),(pit_amzn_2026/(pit_amzn_2026+pfac_amzn_2026)*F22+pfac_amzn_2026/(pit_amzn_2026+pfac_amzn_2026)*IF(AND(ISNUMBER(E22),ISNUMBER(D22)),wb1*E22+wb2*D22,IF(ISNUMBER(E22),E22,F22)))/(pit_amzn_2026+pfac_amzn_2026),site_amzn_2026) -> 3.6021489 | G23: =IF(ISNUMBER(G22),(pit_amzn_2027/(pit_amzn_2027+pfac_amzn_2027)*G22+pfac_amzn_2027/(pit_amzn_2027+pfac_amzn_2027)*IF(AND(ISNUMBER(F22),ISNUMBER(E22)),wb1*F22+wb2*E22,IF(ISNUMBER(F22),F22,G22)))/(pit_amzn_2027+pfac_amzn_2027),site_amzn_2027) -> 4.2451551 | H23: =IF(ISNUMBER(H22),(pit_amzn_2028/(pit_amzn_2028+pfac_amzn_2028)*H22+pfac_amzn_2028/(pit_amzn_2028+pfac_amzn_2028)*IF(AND(ISNUMBER(G22),ISNUMBER(F22)),wb1*G22+wb2*F22,IF(ISNUMBER(G22),G22,H22)))/(pit_amzn_2028+pfac_amzn_2028),site_amzn_2028) -> 4.6008577 | I23: =IF(ISNUMBER(I22),(pit_amzn_2029/(pit_amzn_2029+pfac_amzn_2029)*I22+pfac_amzn_2029/(pit_amzn_2029+pfac_amzn_2029)*IF(AND(ISNUMBER(H22),ISNUMBER(G22)),wb1*H22+wb2*G22,IF(ISNUMBER(H22),H22,I22)))/(pit_amzn_2029+pfac_amzn_2029),site_amzn_2029) -> 4.8556703
A24: base_on9_amzn | B24: Amazon 甲2 年新增 IT GW（上線年） | E24: =(1-lag)*E23+lag*D23-inv_k*(E23-D23) -> 1.965038 | F24: =(1-lag)*F23+lag*E23-inv_k*(F23-E23) -> 2.997566 | G24: =(1-lag)*G23+lag*F23-inv_k*(G23-F23) -> 3.9397271 | H24: =(1-lag)*H23+lag*G23-inv_k*(H23-G23) -> 4.4318989 | I24: =(1-lag)*I23+lag*H23-inv_k*(I23-H23) -> 4.7346343
A25: base_site_amzn | B25: Amazon 甲（站點）年新增 | D25: =site_amzn_2024 -> 0 | E25: =site_amzn_2025 -> 1.389716 | F25: =site_amzn_2026 -> 0.527 | G25: =site_amzn_2027 -> 0.364 | H25: =site_amzn_2028 -> 1.744 | I25: =site_amzn_2029 -> 0.062
A26: base_ai2_meta | B26: Meta 曆年 AI 資本支出（In Y2） | D26: =IF(ISNUMBER(ai2_meta_2024),ai2_meta_2024,"") | E26: =IF(ISNUMBER(ai2_meta_2025),ai2_meta_2025,"") | F26: =IF(ISNUMBER(ai2_meta_2026),ai2_meta_2026,"") -> 119 | G26: =IF(ISNUMBER(ai2_meta_2027),ai2_meta_2027,"") -> 130.9 | H26: =IF(ISNUMBER(ai2_meta_2028),ai2_meta_2028,"") -> 143.99 | I26: =IF(ISNUMBER(ai2_meta_2029),ai2_meta_2029,"") -> 158.389
A27: base_x2_meta | B27: Meta 甲2 年新增 IT GW（付款年；缺值以站點代入） | D27: =IF(ISNUMBER(D26),(pit_meta_2024/(pit_meta_2024+pfac_meta_2024)*D26+pfac_meta_2024/(pit_meta_2024+pfac_meta_2024)*IF(AND(ISNUMBER(""),ISNUMBER("")),wb1*""+wb2*"",IF(ISNUMBER(""),"",D26)))/(pit_meta_2024+pfac_meta_2024),site_meta_2024) -> 0 | E27: =IF(ISNUMBER(E26),(pit_meta_2025/(pit_meta_2025+pfac_meta_2025)*E26+pfac_meta_2025/(pit_meta_2025+pfac_meta_2025)*IF(AND(ISNUMBER(D26),ISNUMBER("")),wb1*D26+wb2*"",IF(ISNUMBER(D26),D26,E26)))/(pit_meta_2025+pfac_meta_2025),site_meta_2025) -> 1.50812 | F27: =IF(ISNUMBER(F26),(pit_meta_2026/(pit_meta_2026+pfac_meta_2026)*F26+pfac_meta_2026/(pit_meta_2026+pfac_meta_2026)*IF(AND(ISNUMBER(E26),ISNUMBER(D26)),wb1*E26+wb2*D26,IF(ISNUMBER(E26),E26,F26)))/(pit_meta_2026+pfac_meta_2026),site_meta_2026) -> 2.627965 | G27: =IF(ISNUMBER(G26),(pit_meta_2027/(pit_meta_2027+pfac_meta_2027)*G26+pfac_meta_2027/(pit_meta_2027+pfac_meta_2027)*IF(AND(ISNUMBER(F26),ISNUMBER(E26)),wb1*F26+wb2*E26,IF(ISNUMBER(F26),F26,G26)))/(pit_meta_2027+pfac_meta_2027),site_meta_2027) -> 2.6245119 | H27: =IF(ISNUMBER(H26),(pit_meta_2028/(pit_meta_2028+pfac_meta_2028)*H26+pfac_meta_2028/(pit_meta_2028+pfac_meta_2028)*IF(AND(ISNUMBER(G26),ISNUMBER(F26)),wb1*G26+wb2*F26,IF(ISNUMBER(G26),G26,H26)))/(pit_meta_2028+pfac_meta_2028),site_meta_2028) -> 2.736412 | I27: =IF(ISNUMBER(I26),(pit_meta_2029/(pit_meta_2029+pfac_meta_2029)*I26+pfac_meta_2029/(pit_meta_2029+pfac_meta_2029)*IF(AND(ISNUMBER(H26),ISNUMBER(G26)),wb1*H26+wb2*G26,IF(ISNUMBER(H26),H26,I26)))/(pit_meta_2029+pfac_meta_2029),site_meta_2029) -> 3.0117483
A28: base_on2_meta | B28: Meta 甲2 年新增 IT GW（上線年） | E28: =(1-lag)*E27+lag*D27-inv_k*(E27-D27) -> 0.791763 | F28: =(1-lag)*F27+lag*E27-inv_k*(F27-E27) -> 2.0960386 | G28: =(1-lag)*G27+lag*F27-inv_k*(G27-F27) -> 2.6261521 | H28: =(1-lag)*H27+lag*G27-inv_k*(H27-G27) -> 2.6832595 | I28: =(1-lag)*I27+lag*H27-inv_k*(I27-H27) -> 2.8809635
A29: base_ai9_meta | B29: Meta 曆年 AI 資本支出（Y9 個股模型 v0.3） | D29: =gcap_meta_2024*ai_sh -> 33.34125 | E29: =gcap_meta_2025*ai_sh -> 61.38275 | F29: =gcap_meta_2026*ai_sh -> 119 | G29: =gcap_meta_2027*ai_sh -> 174.85 | H29: =gcap_meta_2028*ai_sh -> 186.39077 | I29: =gcap_meta_2029*ai_sh -> 165.57988
A30: base_x9_meta | B30: Meta 甲2 年新增 IT GW（付款年；缺值以站點代入） | D30: =IF(ISNUMBER(D29),(pit_meta_2024/(pit_meta_2024+pfac_meta_2024)*D29+pfac_meta_2024/(pit_meta_2024+pfac_meta_2024)*IF(AND(ISNUMBER(""),ISNUMBER("")),wb1*""+wb2*"",IF(ISNUMBER(""),"",D29)))/(pit_meta_2024+pfac_meta_2024),site_meta_2024) -> 0.81749374 | E30: =IF(ISNUMBER(E29),(pit_meta_2025/(pit_meta_2025+pfac_meta_2025)*E29+pfac_meta_2025/(pit_meta_2025+pfac_meta_2025)*IF(AND(ISNUMBER(D29),ISNUMBER("")),wb1*D29+wb2*"",IF(ISNUMBER(D29),D29,E29)))/(pit_meta_2025+pfac_meta_2025),site_meta_2025) -> 1.3304462 | F30: =IF(ISNUMBER(F29),(pit_meta_2026/(pit_meta_2026+pfac_meta_2026)*F29+pfac_meta_2026/(pit_meta_2026+pfac_meta_2026)*IF(AND(ISNUMBER(E29),ISNUMBER(D29)),wb1*E29+wb2*D29,IF(ISNUMBER(E29),E29,F29)))/(pit_meta_2026+pfac_meta_2026),site_meta_2026) -> 2.2011268 | G30: =IF(ISNUMBER(G29),(pit_meta_2027/(pit_meta_2027+pfac_meta_2027)*G29+pfac_meta_2027/(pit_meta_2027+pfac_meta_2027)*IF(AND(ISNUMBER(F29),ISNUMBER(E29)),wb1*F29+wb2*E29,IF(ISNUMBER(F29),F29,G29)))/(pit_meta_2027+pfac_meta_2027),site_meta_2027) -> 3.1540614 | H30: =IF(ISNUMBER(H29),(pit_meta_2028/(pit_meta_2028+pfac_meta_2028)*H29+pfac_meta_2028/(pit_meta_2028+pfac_meta_2028)*IF(AND(ISNUMBER(G29),ISNUMBER(F29)),wb1*G29+wb2*F29,IF(ISNUMBER(G29),G29,H29)))/(pit_meta_2028+pfac_meta_2028),site_meta_2028) -> 3.4728281 | I30: =IF(ISNUMBER(I29),(pit_meta_2029/(pit_meta_2029+pfac_meta_2029)*I29+pfac_meta_2029/(pit_meta_2029+pfac_meta_2029)*IF(AND(ISNUMBER(H29),ISNUMBER(G29)),wb1*H29+wb2*G29,IF(ISNUMBER(H29),H29,I29)))/(pit_meta_2029+pfac_meta_2029),site_meta_2029) -> 3.3215234
A31: base_on9_meta | B31: Meta 甲2 年新增 IT GW（上線年） | E31: =(1-lag)*E30+lag*D30-inv_k*(E30-D30) -> 1.0867938 | F31: =(1-lag)*F30+lag*E30-inv_k*(F30-E30) -> 1.7875535 | G31: =(1-lag)*G30+lag*F30-inv_k*(G30-F30) -> 2.7014175 | H31: =(1-lag)*H30+lag*G30-inv_k*(H30-G30) -> 3.3214139 | I31: =(1-lag)*I30+lag*H30-inv_k*(I30-H30) -> 3.3933931
A32: base_site_meta | B32: Meta 甲（站點）年新增 | D32: =site_meta_2024 -> 0 | E32: =site_meta_2025 -> 1.50812 | F32: =site_meta_2026 -> 0.676 | G32: =site_meta_2027 -> 0.615 | H32: =site_meta_2028 -> 2.9943333 | I32: =site_meta_2029 -> 0.968
A33: base_ai2_orcl | B33: Oracle 曆年 AI 資本支出（In Y2） | D33: =IF(ISNUMBER(ai2_orcl_2024),ai2_orcl_2024,"") | E33: =IF(ISNUMBER(ai2_orcl_2025),ai2_orcl_2025,"") -> 35.113217 | F33: =IF(ISNUMBER(ai2_orcl_2026),ai2_orcl_2026,"") -> 65.578563 | G33: =IF(ISNUMBER(ai2_orcl_2027),ai2_orcl_2027,"") -> 82.820742 | H33: =IF(ISNUMBER(ai2_orcl_2028),ai2_orcl_2028,"") -> 77.827842 | I33: =IF(ISNUMBER(ai2_orcl_2029),ai2_orcl_2029,"") -> 76.327847
A34: base_x2_orcl | B34: Oracle 甲2 年新增 IT GW（付款年；缺值以站點代入） | D34: =IF(ISNUMBER(D33),(pit_orcl_2024/(pit_orcl_2024+pfac_orcl_2024)*D33+pfac_orcl_2024/(pit_orcl_2024+pfac_orcl_2024)*IF(AND(ISNUMBER(""),ISNUMBER("")),wb1*""+wb2*"",IF(ISNUMBER(""),"",D33)))/(pit_orcl_2024+pfac_orcl_2024),site_orcl_2024) -> 0 | E34: =IF(ISNUMBER(E33),(pit_orcl_2025/(pit_orcl_2025+pfac_orcl_2025)*E33+pfac_orcl_2025/(pit_orcl_2025+pfac_orcl_2025)*IF(AND(ISNUMBER(D33),ISNUMBER("")),wb1*D33+wb2*"",IF(ISNUMBER(D33),D33,E33)))/(pit_orcl_2025+pfac_orcl_2025),site_orcl_2025) -> 0.88577642 | F34: =IF(ISNUMBER(F33),(pit_orcl_2026/(pit_orcl_2026+pfac_orcl_2026)*F33+pfac_orcl_2026/(pit_orcl_2026+pfac_orcl_2026)*IF(AND(ISNUMBER(E33),ISNUMBER(D33)),wb1*E33+wb2*D33,IF(ISNUMBER(E33),E33,F33)))/(pit_orcl_2026+pfac_orcl_2026),site_orcl_2026) -> 1.2666993 | G34: =IF(ISNUMBER(G33),(pit_orcl_2027/(pit_orcl_2027+pfac_orcl_2027)*G33+pfac_orcl_2027/(pit_orcl_2027+pfac_orcl_2027)*IF(AND(ISNUMBER(F33),ISNUMBER(E33)),wb1*F33+wb2*E33,IF(ISNUMBER(F33),F33,G33)))/(pit_orcl_2027+pfac_orcl_2027),site_orcl_2027) -> 1.5329692 | H34: =IF(ISNUMBER(H33),(pit_orcl_2028/(pit_orcl_2028+pfac_orcl_2028)*H33+pfac_orcl_2028/(pit_orcl_2028+pfac_orcl_2028)*IF(AND(ISNUMBER(G33),ISNUMBER(F33)),wb1*G33+wb2*F33,IF(ISNUMBER(G33),G33,H33)))/(pit_orcl_2028+pfac_orcl_2028),site_orcl_2028) -> 1.5102479 | I34: =IF(ISNUMBER(I33),(pit_orcl_2029/(pit_orcl_2029+pfac_orcl_2029)*I33+pfac_orcl_2029/(pit_orcl_2029+pfac_orcl_2029)*IF(AND(ISNUMBER(H33),ISNUMBER(G33)),wb1*H33+wb2*G33,IF(ISNUMBER(H33),H33,I33)))/(pit_orcl_2029+pfac_orcl_2029),site_orcl_2029) -> 1.5173735
A35: base_on2_orcl | B35: Oracle 甲2 年新增 IT GW（上線年） | E35: =(1-lag)*E34+lag*D34-inv_k*(E34-D34) -> 0.46503262 | F35: =(1-lag)*F34+lag*E34-inv_k*(F34-E34) -> 1.0857609 | G35: =(1-lag)*G34+lag*F34-inv_k*(G34-F34) -> 1.406491 | H35: =(1-lag)*H34+lag*G34-inv_k*(H34-G34) -> 1.5210405 | I35: =(1-lag)*I34+lag*H34-inv_k*(I34-H34) -> 1.5139888
A36: base_ai9_orcl | B36: Oracle 曆年 AI 資本支出（Y9 個股模型 v0.3） | D36: ="" | E36: =(5/12*cap2_orcl_2025+7/12*gcap_orcl_2026)*ai_sh -> 35.113217 | F36: =(5/12*gcap_orcl_2026+7/12*gcap_orcl_2027)*ai_sh -> 65.578563 | G36: =(5/12*gcap_orcl_2027+7/12*gcap_orcl_2028)*ai_sh -> 75.59919 | H36: =(5/12*gcap_orcl_2028+7/12*gcap_orcl_2029)*ai_sh -> 49.443549 | I36: =(5/12*gcap_orcl_2029+7/12*gcap_orcl_2030)*ai_sh -> 23.382754
A37: base_x9_orcl | B37: Oracle 甲2 年新增 IT GW（付款年；缺值以站點代入） | D37: =IF(ISNUMBER(D36),(pit_orcl_2024/(pit_orcl_2024+pfac_orcl_2024)*D36+pfac_orcl_2024/(pit_orcl_2024+pfac_orcl_2024)*IF(AND(ISNUMBER(""),ISNUMBER("")),wb1*""+wb2*"",IF(ISNUMBER(""),"",D36)))/(pit_orcl_2024+pfac_orcl_2024),site_orcl_2024) -> 0 | E37: =IF(ISNUMBER(E36),(pit_orcl_2025/(pit_orcl_2025+pfac_orcl_2025)*E36+pfac_orcl_2025/(pit_orcl_2025+pfac_orcl_2025)*IF(AND(ISNUMBER(D36),ISNUMBER("")),wb1*D36+wb2*"",IF(ISNUMBER(D36),D36,E36)))/(pit_orcl_2025+pfac_orcl_2025),site_orcl_2025) -> 0.88577642 | F37: =IF(ISNUMBER(F36),(pit_orcl_2026/(pit_orcl_2026+pfac_orcl_2026)*F36+pfac_orcl_2026/(pit_orcl_2026+pfac_orcl_2026)*IF(AND(ISNUMBER(E36),ISNUMBER(D36)),wb1*E36+wb2*D36,IF(ISNUMBER(E36),E36,F36)))/(pit_orcl_2026+pfac_orcl_2026),site_orcl_2026) -> 1.2666993 | G37: =IF(ISNUMBER(G36),(pit_orcl_2027/(pit_orcl_2027+pfac_orcl_2027)*G36+pfac_orcl_2027/(pit_orcl_2027+pfac_orcl_2027)*IF(AND(ISNUMBER(F36),ISNUMBER(E36)),wb1*F36+wb2*E36,IF(ISNUMBER(F36),F36,G36)))/(pit_orcl_2027+pfac_orcl_2027),site_orcl_2027) -> 1.4217508 | H37: =IF(ISNUMBER(H36),(pit_orcl_2028/(pit_orcl_2028+pfac_orcl_2028)*H36+pfac_orcl_2028/(pit_orcl_2028+pfac_orcl_2028)*IF(AND(ISNUMBER(G36),ISNUMBER(F36)),wb1*G36+wb2*F36,IF(ISNUMBER(G36),G36,H36)))/(pit_orcl_2028+pfac_orcl_2028),site_orcl_2028) -> 1.0692345 | I37: =IF(ISNUMBER(I36),(pit_orcl_2029/(pit_orcl_2029+pfac_orcl_2029)*I36+pfac_orcl_2029/(pit_orcl_2029+pfac_orcl_2029)*IF(AND(ISNUMBER(H36),ISNUMBER(G36)),wb1*H36+wb2*G36,IF(ISNUMBER(H36),H36,I36)))/(pit_orcl_2029+pfac_orcl_2029),site_orcl_2029) -> 0.64246955
A38: base_on9_orcl | B38: Oracle 甲2 年新增 IT GW（上線年） | E38: =(1-lag)*E37+lag*D37-inv_k*(E37-D37) -> 0.46503262 | F38: =(1-lag)*F37+lag*E37-inv_k*(F37-E37) -> 1.0857609 | G38: =(1-lag)*G37+lag*F37-inv_k*(G37-F37) -> 1.3481014 | H38: =(1-lag)*H37+lag*G37-inv_k*(H37-G37) -> 1.2366798 | I38: =(1-lag)*I37+lag*H37-inv_k*(I37-H37) -> 0.84518292
A39: base_site_orcl | B39: Oracle 甲（站點）年新增 | D39: =site_orcl_2024 -> 0 | E39: =site_orcl_2025 -> 0.816405 | F39: =site_orcl_2026 -> 1.54613 | G39: =site_orcl_2027 -> 0.94416667 | H39: =site_orcl_2028 -> 4.9116667 | I39: =site_orcl_2029 -> 0
A40: base_ai2_crwv | B40: CoreWeave 曆年 AI 資本支出（In Y2） | D40: =IF(ISNUMBER(ai2_crwv_2024),ai2_crwv_2024,"") | E40: =IF(ISNUMBER(ai2_crwv_2025),ai2_crwv_2025,"") | F40: =IF(ISNUMBER(ai2_crwv_2026),ai2_crwv_2026,"") -> 31.45 | G40: =IF(ISNUMBER(ai2_crwv_2027),ai2_crwv_2027,"") -> 39.5046 | H40: =IF(ISNUMBER(ai2_crwv_2028),ai2_crwv_2028,"") -> 42.60965 | I40: =IF(ISNUMBER(ai2_crwv_2029),ai2_crwv_2029,"") -> 46.870615
A41: base_x2_crwv | B41: CoreWeave 甲2 年新增 IT GW（付款年；缺值以站點代入） | D41: =IF(ISNUMBER(D40),(pit_crwv_2024/(pit_crwv_2024+pfac_crwv_2024)*D40+pfac_crwv_2024/(pit_crwv_2024+pfac_crwv_2024)*IF(AND(ISNUMBER(""),ISNUMBER("")),wb1*""+wb2*"",IF(ISNUMBER(""),"",D40)))/(pit_crwv_2024+pfac_crwv_2024),site_crwv_2024) -> 0.29 | E41: =IF(ISNUMBER(E40),(pit_crwv_2025/(pit_crwv_2025+pfac_crwv_2025)*E40+pfac_crwv_2025/(pit_crwv_2025+pfac_crwv_2025)*IF(AND(ISNUMBER(D40),ISNUMBER("")),wb1*D40+wb2*"",IF(ISNUMBER(D40),D40,E40)))/(pit_crwv_2025+pfac_crwv_2025),site_crwv_2025) -> 0.49 | F41: =IF(ISNUMBER(F40),(pit_crwv_2026/(pit_crwv_2026+pfac_crwv_2026)*F40+pfac_crwv_2026/(pit_crwv_2026+pfac_crwv_2026)*IF(AND(ISNUMBER(E40),ISNUMBER(D40)),wb1*E40+wb2*D40,IF(ISNUMBER(E40),E40,F40)))/(pit_crwv_2026+pfac_crwv_2026),site_crwv_2026) -> 0.68244896 | G41: =IF(ISNUMBER(G40),(pit_crwv_2027/(pit_crwv_2027+pfac_crwv_2027)*G40+pfac_crwv_2027/(pit_crwv_2027+pfac_crwv_2027)*IF(AND(ISNUMBER(F40),ISNUMBER(E40)),wb1*F40+wb2*E40,IF(ISNUMBER(F40),F40,G40)))/(pit_crwv_2027+pfac_crwv_2027),site_crwv_2027) -> 0.73522262 | H41: =IF(ISNUMBER(H40),(pit_crwv_2028/(pit_crwv_2028+pfac_crwv_2028)*H40+pfac_crwv_2028/(pit_crwv_2028+pfac_crwv_2028)*IF(AND(ISNUMBER(G40),ISNUMBER(F40)),wb1*G40+wb2*F40,IF(ISNUMBER(G40),G40,H40)))/(pit_crwv_2028+pfac_crwv_2028),site_crwv_2028) -> 0.75804229 | I41: =IF(ISNUMBER(I40),(pit_crwv_2029/(pit_crwv_2029+pfac_crwv_2029)*I40+pfac_crwv_2029/(pit_crwv_2029+pfac_crwv_2029)*IF(AND(ISNUMBER(H40),ISNUMBER(G40)),wb1*H40+wb2*G40,IF(ISNUMBER(H40),H40,I40)))/(pit_crwv_2029+pfac_crwv_2029),site_crwv_2029) -> 0.8426751
...

Sheet Bridge
A1: Bridge — Wattonomics 側歸因：Siliconomics 推得上線 GW（r1）vs Wattonomics 主路徑（v0.1.7，A、D0），逐項列 Wattonomics 側可量化的差距。正值＝Wattonomics 應加的 GW。
A3: 列 | B3: 項目 | C3: 說明 | D3: 2026 | E3: 2027 | F3: 2028 | G3: 2029 | H3: 標記
A4: 一、起點
A5: s8 | B5: Siliconomics 推得淨新增上線 IT GW（r1） | C5: Siliconomics Bridge b8（已扣 ②③④） | D5: =s_b8_2026 -> 20.298783 | E5: =s_b8_2027 -> 35.416362 | F5: =s_b8_2028 -> 51.394473 | G5: =s_b8_2029 -> 60.922318 | H5: Derived
A6: w0 | B6: Wattonomics 主路徑年新增 IT GW（v0.1.7，A、D0） | C6: Deploy 第 19 列 | D6: =wt_new_2026 -> 12.515371 | E6: =wt_new_2027 -> 23.962254 | F6: =wt_new_2028 -> 26.923293 | G6: =wt_new_2029 -> 27.663468 | H6: Derived
A7: r0 | B7: 殘差 r1（Siliconomics 側交來） | C7: s8 − w0 | D7: =D5-D6 -> 7.7834116 | E7: =E5-E6 -> 11.454108 | F7: =F5-F6 -> 24.47118 | G7: =G5-G6 -> 33.25885
A9: 二、Wattonomics 側逐項（Compare 第 1–4 點＋覆蓋）
A10: d1 | B10: 【覆蓋】2026 七家改甲2（付款年，In Y2 讀法）＝AI半導體 10-31 觀察 2 的量 | C10: Σ七家 甲2（付款年）− Σ七家 站點；2027 起主路徑已是甲2 → 0 | D10: =Calc!$F$66-Calc!$F$70 -> 8.6747647 | E10: =0 -> 0 | F10: =0 -> 0 | G10: =0 -> 0 | H10: Derived
A11: d2 | B11: 【第 1 點 出貨年 vs 上線年】七家甲2 付款年 → 上線年（Wattonomics 自己的口徑修正） | C11: 甲2 的 IT 資本支出以付款年當上線年；以 Siliconomics ②③ 同參數平移：Σ上線年 − Σ付款年（In Y2） | D11: =Calc!$F$67-Calc!$F$66 -> -2.6474426 | E11: =Calc!$G$67-Calc!$G$66 -> -1.8422786 | F11: =Calc!$H$67-Calc!$H$66 -> -1.0934827 | G11: =Calc!$I$67-Calc!$I$66 -> -1.1893373 | H11: Derived／Assumed
A12: d3 | B12: 【覆蓋】七家資本支出改讀個股模型 v0.3（v0.1.8 規劃） | C12: Σ上線年（Y9）− Σ上線年（In Y2） | D12: =Calc!$F$69-Calc!$F$67 -> -0.13641276 | E12: =Calc!$G$69-Calc!$G$67 -> 0.053095503 | F12: =Calc!$H$69-Calc!$H$67 -> -0.26957827 | G12: =Calc!$I$69-Calc!$I$67 -> -2.1766344 | H12: Derived
A13: d4 | B13: 【覆蓋】非七家：xAI、OpenAI 自建、Anthropic 自建改讀個股模型資本支出 | C13: Σ模型推得（上線年）− Σ站點；每 GW 用 NVIDIA 世代加權成本（OpenAI 含客製晶片 → 偏低估 GW） | D13: =Calc!$F$72-Calc!$F$73 -> 0.9724714 | E13: =Calc!$G$72-Calc!$G$73 -> 1.7323233 | F13: =Calc!$H$72-Calc!$H$73 -> 2.1574543 | G13: =Calc!$I$72-Calc!$I$73 -> 2.2563632 | H13: Derived
A14: d5 | B14: 【覆蓋】「其他（企業、學研）」2026 起持平 → 改隨市場成長 | C14: 其他_t−1 ×（主路徑年底 t ÷ 年底 t−1 − 1），逐年累積 | D14: =oth_ye_2025*(wt_ye_2026/wt_ye_2025-1) -> 0.49395353 | E14: =(oth_ye_2025+SUM($D$14:D14))*(wt_ye_2027/wt_ye_2026-1) -> 0.94573621 | F14: =(oth_ye_2025+SUM($D$14:E14))*(wt_ye_2028/wt_ye_2027-1) -> 1.0626017 | G14: =(oth_ye_2025+SUM($D$14:F14))*(wt_ye_2029/wt_ye_2028-1) -> 1.0918148 | H14: Analogy
A15: d6 | B15: 【第 3 點 成本等值 vs 實體】Wattonomics 側 | C15: Wattonomics 甲2 已用 NonNV 持有比換算實體 GW（與 Siliconomics ① 同法），無需調整 | D15: =0 -> 0 | E15: =0 -> 0 | F15: =0 -> 0 | G15: =0 -> 0 | H15: —
A16: d7 | B16: 【第 4 點 中國】Wattonomics 中國年新增（揭露，不調整） | C16: Rystad 容量 × AI 占比；見下方「中國」節 | D16: =cn_add_2026 -> 3.3333333 | E16: =cn_add_2027 -> 1.9895045 | F16: =cn_add_2028 -> 2.2812141 | G16: =cn_add_2029 -> 2.6125213 | H16: Derived
A17: wadj | B17: Wattonomics 調整後年新增 IT GW | C17: w0 + d1 + d2 + d3 + d4 + d5（d7 不加） | D17: =D6+D10+D11+D12+D13+D14 -> 19.872706 | E17: =E6+E10+E11+E12+E13+E14 -> 24.85113 | F17: =F6+F10+F11+F12+F13+F14 -> 28.780288 | G17: =G6+G10+G11+G12+G13+G14 -> 27.645674 | H17: Derived
A19: 三、比較口徑對齊（兩邊都不改模型）
A20: e1 | B20: 【第 1 點附帶】汰換：Wattonomics 不建模汰換（主路徑實為毛額）→ 加回 Siliconomics ④ | C20: −④；兩邊改以毛額比較 | D20: =-s_b6_2026 -> 0.50674287 | E20: =-s_b6_2027 -> 0.7570503 | F20: =-s_b6_2028 -> 1.2362954 | G20: =-s_b6_2029 -> 1.7747612 | H20: Assumed
A21: sg | B21: Siliconomics 推得上線 IT GW（毛額，與 Wattonomics 同口徑） | C21: s8 + e1 | D21: =D5+D20 -> 20.805526 | E21: =E5+E20 -> 36.173412 | F21: =F5+F20 -> 52.630768 | G21: =G5+G20 -> 62.69708 | H21: Derived
A23: 四、殘差與判讀
A24: rf | B24: 殘差（調整後） | C24: sg − wadj | D24: =D21-D17 -> 0.9328202 | E24: =E21-E17 -> 11.322282 | F24: =F21-F17 -> 23.850481 | G24: =G21-G17 -> 35.051405
A25: ra | B25: 比值：Wattonomics 調整後 ÷ Siliconomics（毛額） | D25: =D17/D21 -> 0.95516479 | E25: =E17/E21 -> 0.68699989 | F25: =F17/F21 -> 0.54683389 | G25: =G17/G21 -> 0.44094038
A26: rb | B26: 比值：Wattonomics v0.1.7 ÷ Siliconomics（毛額） | D26: =D6/D21 -> 0.60154074 | E26: =E6/E21 -> 0.66242725 | F26: =F6/F21 -> 0.51155044 | G26: =G6/G21 -> 0.44122419
A27: lb | B27: 容許帶判定（調整後） | C27: |1 − 比值| ≤ tolband → 帶內 | D27: =IF(ABS(1-D25)<=tolband,"帶內",IF(D25<1,"帶外（Wattonomics 偏低）","帶外（Wattonomics 偏高）")) -> 帶內 | E27: =IF(ABS(1-E25)<=tolband,"帶內",IF(E25<1,"帶外（Wattonomics 偏低）","帶外（Wattonomics 偏高）")) -> 帶外（Wattonomics 偏低） | F27: =IF(ABS(1-F25)<=tolband,"帶內",IF(F25<1,"帶外（Wattonomics 偏低）","帶外（Wattonomics 偏高）")) -> 帶外（Wattonomics 偏低） | G27: =IF(ABS(1-G25)<=tolband,"帶內",IF(G25<1,"帶外（Wattonomics 偏低）","帶外（Wattonomics 偏高）")) -> 帶外（Wattonomics 偏低）
A28: km | B28: 七家上線 GW 需放大倍數（其餘不變，使殘差歸零） | C28: (sg −（wadj − 七家上線年 Y9））÷ 七家上線年 Y9 | D28: =(D21-(D17-Calc!$F$69))/Calc!$F$69 -> 1.0750237 | E28: =(E21-(E17-Calc!$G$69))/Calc!$G$69 -> 1.654209 | F28: =(F21-(F17-Calc!$H$69))/Calc!$H$69 -> 2.1904397 | G28: =(G21-(G17-Calc!$I$69))/Calc!$I$69 -> 2.7068294 | H28: Derived
A30: 五、敏感度（一次動一個輸入；殘差＝sg − wadj）
A31: 情況 | D31: 2026 | E31: 2027 | F31: 2028 | G31: 2029
A32: base | B32: 基準 | D32: =D21-(wt_new_2026+(Calc!$F$66-Calc!$F$70)+(Calc!$F$67-Calc!$F$66)+(Calc!$F$69-Calc!$F$67)+(Calc!$F$72-Calc!$F$73)+D14) -> 0.9328202 | E32: =E21-(wt_new_2027+0+(Calc!$G$67-Calc!$G$66)+(Calc!$G$69-Calc!$G$67)+(Calc!$G$72-Calc!$G$73)+E14) -> 11.322282 | F32: =F21-(wt_new_2028+0+(Calc!$H$67-Calc!$H$66)+(Calc!$H$69-Calc!$H$67)+(Calc!$H$72-Calc!$H$73)+F14) -> 23.850481 | G32: =G21-(wt_new_2029+0+(Calc!$I$67-Calc!$I$66)+(Calc!$I$69-Calc!$I$67)+(Calc!$I$72-Calc!$I$73)+G14) -> 35.051405
A33: ailo | B33: AI 占比 低 | D33: =D21-(wt_new_2026+(Calc!$F$138-Calc!$F$142)+(Calc!$F$139-Calc!$F$138)+(Calc!$F$141-Calc!$F$139)+(Calc!$F$144-Calc!$F$145)+D14) -> 2.368223 | E33: =E21-(wt_new_2027+0+(Calc!$G$139-Calc!$G$138)+(Calc!$G$141-Calc!$G$139)+(Calc!$G$144-Calc!$G$145)+E14) -> 11.11179 | F33: =F21-(wt_new_2028+0+(Calc!$H$139-Calc!$H$138)+(Calc!$H$141-Calc!$H$139)+(Calc!$H$144-Calc!$H$145)+F14) -> 23.69012 | G33: =G21-(wt_new_2029+0+(Calc!$I$139-Calc!$I$138)+(Calc!$I$141-Calc!$I$139)+(Calc!$I$144-Calc!$I$145)+G14) -> 34.655409
A34: aihi | B34: AI 占比 高 | D34: =D21-(wt_new_2026+(Calc!$F$210-Calc!$F$214)+(Calc!$F$211-Calc!$F$210)+(Calc!$F$213-Calc!$F$211)+(Calc!$F$216-Calc!$F$217)+D14) -> -0.45850071 | E34: =E21-(wt_new_2027+0+(Calc!$G$211-Calc!$G$210)+(Calc!$G$213-Calc!$G$211)+(Calc!$G$216-Calc!$G$217)+E14) -> 11.523873 | F34: =F21-(wt_new_2028+0+(Calc!$H$211-Calc!$H$210)+(Calc!$H$213-Calc!$H$211)+(Calc!$H$216-Calc!$H$217)+F14) -> 24.002542 | G34: =G21-(wt_new_2029+0+(Calc!$I$211-Calc!$I$210)+(Calc!$I$213-Calc!$I$211)+(Calc!$I$216-Calc!$I$217)+G14) -> 35.435463
A35: lblo | B35: lag_bldg 低（12 月） | D35: =D21-(wt_new_2026+(Calc!$F$282-Calc!$F$286)+(Calc!$F$283-Calc!$F$282)+(Calc!$F$285-Calc!$F$283)+(Calc!$F$288-Calc!$F$289)+D14) -> 0.76336162 | E35: =E21-(wt_new_2027+0+(Calc!$G$283-Calc!$G$282)+(Calc!$G$285-Calc!$G$283)+(Calc!$G$288-Calc!$G$289)+E14) -> 11.472812 | F35: =F21-(wt_new_2028+0+(Calc!$H$283-Calc!$H$282)+(Calc!$H$285-Calc!$H$283)+(Calc!$H$288-Calc!$H$289)+F14) -> 23.629036 | G35: =G21-(wt_new_2029+0+(Calc!$I$283-Calc!$I$282)+(Calc!$I$285-Calc!$I$283)+(Calc!$I$288-Calc!$I$289)+G14) -> 34.87533
A36: lbhi | B36: lag_bldg 高（24 月） | D36: =D21-(wt_new_2026+(Calc!$F$354-Calc!$F$358)+(Calc!$F$355-Calc!$F$354)+(Calc!$F$357-Calc!$F$355)+(Calc!$F$360-Calc!$F$361)+D14) -> 1.1022788 | E36: =E21-(wt_new_2027+0+(Calc!$G$355-Calc!$G$354)+(Calc!$G$357-Calc!$G$355)+(Calc!$G$360-Calc!$G$361)+E14) -> 11.171751 | F36: =F21-(wt_new_2028+0+(Calc!$H$355-Calc!$H$354)+(Calc!$H$357-Calc!$H$355)+(Calc!$H$360-Calc!$H$361)+F14) -> 24.071925 | G36: =G21-(wt_new_2029+0+(Calc!$I$355-Calc!$I$354)+(Calc!$I$357-Calc!$I$355)+(Calc!$I$360-Calc!$I$361)+G14) -> 35.227481
A37: lglo | B37: 上線延遲 低（3 個月） | C37: Siliconomics 側同參數時，s8 亦隨之變（以 r1 的 ②③ 比例近似重算） | D37: =(s_b8_2026-s_b4_2026-s_b5_2026-(lag_lo+inv_k)*(s_b3_2026-s_b3_2025)-s_b6_2026)-(wt_new_2026+(Calc!$F$426-Calc!$F$430)+(Calc!$F$427-Calc!$F$426)+(Calc!$F$429-Calc!$F$427)+(Calc!$F$432-Calc!$F$433)+D14) -> 1.3360229 | E37: =(s_b8_2027-s_b4_2027-s_b5_2027-(lag_lo+inv_k)*(s_b3_2027-s_b3_2026)-s_b6_2027)-(wt_new_2027+0+(Calc!$G$427-Calc!$G$426)+(Calc!$G$429-Calc!$G$427)+(Calc!$G$432-Calc!$G$433)+E14) -> 13.352261 | F37: =(s_b8_2028-s_b4_2028-s_b5_2028-(lag_lo+inv_k)*(s_b3_2028-s_b3_2027)-s_b6_2028)-(wt_new_2028+0+(Calc!$H$427-Calc!$H$426)+(Calc!$H$429-Calc!$H$427)+(Calc!$H$432-Calc!$H$433)+F14) -> 25.148603 | G37: =(s_b8_2029-s_b4_2029-s_b5_2029-(lag_lo+inv_k)*(s_b3_2029-s_b3_2028)-s_b6_2029)-(wt_new_2029+0+(Calc!$I$427-Calc!$I$426)+(Calc!$I$429-Calc!$I$427)+(Calc!$I$432-Calc!$I$433)+G14) -> 36.153686
A38: lghi | B38: 上線延遲 高（6 個月） | C38: Siliconomics 側同參數時，s8 亦隨之變（以 r1 的 ②③ 比例近似重算） | D38: =(s_b8_2026-s_b4_2026-s_b5_2026-(lag_hi+inv_k)*(s_b3_2026-s_b3_2025)-s_b6_2026)-(wt_new_2026+(Calc!$F$498-Calc!$F$502)+(Calc!$F$499-Calc!$F$498)+(Calc!$F$501-Calc!$F$499)+(Calc!$F$504-Calc!$F$505)+D14) -> 0.52961749 | E38: =(s_b8_2027-s_b4_2027-s_b5_2027-(lag_hi+inv_k)*(s_b3_2027-s_b3_2026)-s_b6_2027)-(wt_new_2027+0+(Calc!$G$499-Calc!$G$498)+(Calc!$G$501-Calc!$G$499)+(Calc!$G$504-Calc!$G$505)+E14) -> 9.2923031 | F38: =(s_b8_2028-s_b4_2028-s_b5_2028-(lag_hi+inv_k)*(s_b3_2028-s_b3_2027)-s_b6_2028)-(wt_new_2028+0+(Calc!$H$499-Calc!$H$498)+(Calc!$H$501-Calc!$H$499)+(Calc!$H$504-Calc!$H$505)+F14) -> 22.552358 | G38: =(s_b8_2029-s_b4_2029-s_b5_2029-(lag_hi+inv_k)*(s_b3_2029-s_b3_2028)-s_b6_2029)-(wt_new_2029+0+(Calc!$I$499-Calc!$I$498)+(Calc!$I$501-Calc!$I$499)+(Calc!$I$504-Calc!$I$505)+G14) -> 33.949125
A39: ivlo | B39: 庫存 低 | C39: Siliconomics 側同參數時，s8 亦隨之變（以 r1 的 ②③ 比例近似重算） | D39: =(s_b8_2026-s_b4_2026-s_b5_2026-(lag+inv_k_lo)*(s_b3_2026-s_b3_2025)-s_b6_2026)-(wt_new_2026+(Calc!$F$570-Calc!$F$574)+(Calc!$F$571-Calc!$F$570)+(Calc!$F$573-Calc!$F$571)+(Calc!$F$576-Calc!$F$577)+D14) -> 1.0941013 | E39: =(s_b8_2027-s_b4_2027-s_b5_2027-(lag+inv_k_lo)*(s_b3_2027-s_b3_2026)-s_b6_2027)-(wt_new_2027+0+(Calc!$G$571-Calc!$G$570)+(Calc!$G$573-Calc!$G$571)+(Calc!$G$576-Calc!$G$577)+E14) -> 12.134273 | F39: =(s_b8_2028-s_b4_2028-s_b5_2028-(lag+inv_k_lo)*(s_b3_2028-s_b3_2027)-s_b6_2028)-(wt_new_2028+0+(Calc!$H$571-Calc!$H$570)+(Calc!$H$573-Calc!$H$571)+(Calc!$H$576-Calc!$H$577)+F14) -> 24.36973 | G39: =(s_b8_2029-s_b4_2029-s_b5_2029-(lag+inv_k_lo)*(s_b3_2029-s_b3_2028)-s_b6_2029)-(wt_new_2029+0+(Calc!$I$571-Calc!$I$570)+(Calc!$I$573-Calc!$I$571)+(Calc!$I$576-Calc!$I$577)+G14) -> 35.492318
A40: ivhi | B40: 庫存 高 | C40: Siliconomics 側同參數時，s8 亦隨之變（以 r1 的 ②③ 比例近似重算） | D40: =(s_b8_2026-s_b4_2026-s_b5_2026-(lag+inv_k_hi)*(s_b3_2026-s_b3_2025)-s_b6_2026)-(wt_new_2026+(Calc!$F$642-Calc!$F$646)+(Calc!$F$643-Calc!$F$642)+(Calc!$F$645-Calc!$F$643)+(Calc!$F$648-Calc!$F$649)+D14) -> 0.61025803 | E40: =(s_b8_2027-s_b4_2027-s_b5_2027-(lag+inv_k_hi)*(s_b3_2027-s_b3_2026)-s_b6_2027)-(wt_new_2027+0+(Calc!$G$643-Calc!$G$642)+(Calc!$G$645-Calc!$G$643)+(Calc!$G$648-Calc!$G$649)+E14) -> 9.6982989 | F40: =(s_b8_2028-s_b4_2028-s_b5_2028-(lag+inv_k_hi)*(s_b3_2028-s_b3_2027)-s_b6_2028)-(wt_new_2028+0+(Calc!$H$643-Calc!$H$642)+(Calc!$H$645-Calc!$H$643)+(Calc!$H$648-Calc!$H$649)+F14) -> 22.811982 | G40: =(s_b8_2029-s_b4_2029-s_b5_2029-(lag+inv_k_hi)*(s_b3_2029-s_b3_2028)-s_b6_2029)-(wt_new_2029+0+(Calc!$I$643-Calc!$I$642)+(Calc!$I$645-Calc!$I$643)+(Calc!$I$648-Calc!$I$649)+G14) -> 34.169581
B41: 只做 d1（不平移、不改讀 v0.3、不補非七家） | D41: =D21-(D6+D10) -> -0.38461024 | E41: =E21-(E6+E10) -> 12.211158 | F41: =F21-(F6+F10) -> 25.707476 | G41: =G21-(G6+G10) -> 35.033612
B42: d1＋d2（改甲2 並平移；仍讀 In Y2） | D42: =D21-(D6+D10+D11) -> 2.2628324 | E42: =E21-(E6+E10+E11) -> 14.053437 | F42: =F21-(F6+F10+F11) -> 26.800958 | G42: =G21-(G6+G10+G11) -> 36.222949
B43: 不含 d4、d5（只動七家） | D43: =D21-(D6+D10+D11+D12) -> 2.3992451 | E43: =E21-(E6+E10+E11+E12) -> 14.000341 | F43: =F21-(F6+F10+F11+F12) -> 27.070537 | G43: =G21-(G6+G10+G11+G12) -> 38.399583
A45: 六、NVIDIA 營收對照（2026；只作佐證）
A46: n1 | B46: NVIDIA 出貨 GW 2026（TK 每 GW 內容 20.8） | C46: nv_dc_26 ÷ nvc_gb_tk | D46: =nv_dc_26/nvc_gb_tk -> 18.016315 | H46: Derived
...
