Workbook

Sheet README
A1: 日月光投控（3711.TW；ADR ASX）個股模型 v0.1（AI 半導體 Project：封測次產業） 2026-10-31
A2: 版本：v0.1（2026-10-31：初版）。全球最大封測代工（OSAT）；封測（ATM：封裝、測試、材料）約占營收六成五、EMS（環旭）約三成五。樣板 amkr/；行業變數讀 Siliconomics 快照 v0.10（20261031_Siliconomics_v0.10.xlsx）。
A3: 模型命題：封測（ATM）＝主流封測＋LEAP 先進封裝；LEAP＝AI 加速器顆數（Siliconomics）× 委外與份額相對值 × 每顆內容（隨封裝面積）＋全流程（CoWoS full process）＋CPO（Siliconomics 同字母滲透率）。公司稱 LEAP 2026 逾 US$4B、2027 翻倍；全流程 2026 約 US$0.3B → 2027 逾 US$1B；CPO 2027 逾 US$0.5B（Interested-party）。EMS 用簡單成長率。
A4: 核心問題：LEAP 占封測營收升到三成以上後，前瞻 P/E 應停在歷史中位（約 12.6 倍）與 2026 窗口（約 24.1 倍）之間的哪裡；資本支出約占營收 42% 的報酬能否撐住毛利率與 EPS。
A6: 會計年度＝日曆年，FY(t)＝CY(t)。預測期 FY2027–FY2029（三年）由驅動因子推導，FY2030–32 為收斂法。金額：十億新台幣；EPS：新台幣（基本）。口徑：歸屬母公司淨利（IFRS）。現價 668.00（2026-10-30 收盤）；其他模型仍用 10-22／10-23 收盤。
A8: 驅動因子 → 推導量（全部唯讀上游，不修改）
A9: LEAP：Siliconomics 加速器顆數 × 情境係數（2028–29）× 委外與份額相對值（Assumed，情境專屬）× 每顆 LEAP 核心內容（FY2026 以公司「逾 US$4B」校準，之後 × 封裝面積指數 ^ 0.5）＋全流程（FY2027 依情境，之後隨顆數 × 1.3）＋CPO（公司 2027 逾 US$0.5B × Siliconomics 同字母 CPO 滲透率 ÷ 情境 A 2027）。
A10: 主流封測：FY2027 +15%（公司稱與 2026 相近，逾 20%；本模型保守）、FY2028–29 +7%（Assumed；行業變數待併入 Siliconomics）。EMS：FY2027 +10%、之後 +5%，毛利率 8.5%。
A11: 毛利：封測毛利＝FY2026 錨點＋現金流通率 50% × 封測營收增量 − 折舊增量；折舊＝前一年 × (1 − 1／8)＋前一年資本支出 ÷ 8；資本支出 FY2026 US$11.5B、FY2027 US$13.0B、之後營收 × 30%。營業費用彈性 0.6；營業外每年 −5；稅率 17%。
A12: 校準：FY2026 ＝ 1Q–3Q26 實績＋4Q26 依公司指引（ATM 季增 12%、ATM 毛利率 +1.5pt、EMS 持平）。不用券商數字（只在 Recon 對帳）。
A13: 估值：Val 第 0 節目標價＝0.5 × DCF 目標價（股東現金流＝EPS ×（1 − g／ROE），FY2027–32 明確期＋永續，r 10%、g 4%，三情境權重 0.3／0.5／0.2）＋0.5 × Comparable 目標價（Amkor、力成、京元電、矽格、南茂前瞻 P/E 中位數 × 12 個月後前瞻 EPS × 相對倍數調整係數）。十年 P/E 規則值保留為參考。本版未做先驗，無 Andy 合理 P/E 對照。
A14: 預估期間：FY2027–FY2029 由驅動因子推導；FY2030 起為收斂法，非驅動因子推導（營收年增由 FY2029 線性收斂到 fade_g、淨利率收斂到 fade_m，FY2032 達到；PL 頁灰底）。
... A17: 已知限制：(1) LEAP 季度與分項金額公司未揭露，FY2026 以全年說法校準、季度拆分用 BofA 占比；(2) 委外與份額相對值是 Assumed；(3) 主流封測與 EMS 只用成長率；(4) 折舊全數歸封測、混合年限 8 年；(5) DCF 未扣資本支出高峰（偏高估）但 ROE 用低谷年（偏低估）；(6) 賣方共識未找到，以 BofA 單一券商對照；(7) 十年 P/E 只有一個來源；(8) 下次更新：4Q26 財報（2027-02 上旬）。
A19: ="投資建議："&Val!B50&"（依上檔空間固定規則）" -> 投資建議：中立（依上檔空間固定規則）
A20: ="重點觀察 1：目標價 NT$"&TEXT(Val!$B$39,"0.00")&"（DCF "&TEXT(Val!$B$24,"0.00")&"、Comparable（相對倍數調整後）"&TEXT(tp_comp_adj,"0.00")&"；DCF 權重 "&TEXT(tp_w_dcf,"0%")&"），比現價 "&TEXT(px,"0.00")&"（2026-10-30）"&IF(Val!$B$42>=0,"高 "&TEXT(Val!$B$42,"0.0%"),"低 "&TEXT(-Val!$B$42,"0.0%"))&"，級距 "&Val!$B$49&"、投資建議 "&Val!$B$50&"。相對倍數調整係數 "&TEXT(rm_factor,"0.00")&"（本公司 10 年前瞻倍數中位數 ÷ 同業的中位數，夾在 0.5–2.0；Val 第 0.5 節），調整前加權上檔空間 "&TEXT((tp_w_dcf*Val!$B$24+(1-tp_w_dcf)*Val!$B$35)/px-1,"+0.0%;−0.0%")&"；Comparable 單獨（市場主流同業法、未調整）為 "&TEXT(Val!$B$43,"+0.0%;−0.0%")&"。" -> 重點觀察 1：目標價 NT$503.84（DCF 336.54、Comparable（相對倍數調整後）671.15；DCF 權重 50%），比現價 668.00（2026-10-30）低 24.6%，級距 0%～−25%、投資建議 中立。相對倍數調整係數 1.12（本公司 10 年前瞻倍數中位數 ÷ 同業的中位數，夾在 0.5–2.0；Val 第 0.5 節），調整前加權上檔空間 −29.9%；Comparable 單獨（市場主流同業法、未調整）為 −10.2%。
A21: 重點觀察 2：核心問題一（LEAP 三成以上後的倍數）：LEAP 占封測營收 FY2026 22.8% → FY2027 35.9%／33.9%／31.8%（A／B／C），現價 ÷ FY2027 EPS 21.6／23.0／24.6 倍，已接近 Bloomberg 2026 窗口前瞻 P/E 24.1 倍、約為十年中位 12.6 倍的兩倍；Comparable 等於 22.1 倍 × 相對倍數係數 1.12＝24.7 倍，若倍數回到十年中位，Comparable 目標價約減半。與 BofA 目標價 900 的差距主要在 EPS（本模型 12 個月後前瞻 EPS 27.2 比 BofA 同口徑 47.2 低 42%），倍數因素只 −14%。
A22: 重點觀察 3：核心問題二（資本支出約占營收四成的報酬）：FY2026 資本支出 US$11.5B（營收 42%）、FY2027 假設 US$13.0B，折舊由 FY2026 NT$97B 升到 FY2028 NT$166B（+71%），營業利益增量 ÷ FY2026 起累計資本支出在 FY2028 只有 12.4%／8.4%／4.7%（A／B／C），股東自由現金流到 FY2029 都為負。加權上檔空間 −24.6% 距放空門檻僅 0.4 個百分點（現金流通率 40% 或折舊年限 6 年即跨線）；下一個檢驗點是 4Q26 財報（2027-02 上旬）的封測毛利率能否達指引 31.6–32.6%。
A24: 相對倍數調整（Val 第 0.5 節）：加權目標價中的 Comparable 使用相對倍數調整後的值（同業前瞻 P/E 中位數 × 本公司 10 年相對同業的前瞻 P/E 比，Bloomberg；Andy 2026-10-27「照建議做」）；「Comparable 目標價（市場主流同業法）」不調整。重點觀察 1 的第一句為公式，其餘重點觀察的數字以調整後撰寫。
A26: v0.1（2026-10-31）：依個股模型原則第 8 節調整 In 頁呈現（數值不變）。In 頁 D／F 欄名改「敏感度低」「敏感度高」（只用於 Sens 頁、不進目標價）；In 頁最後新增「情境驅動對照」一節，把上方各情境專屬輸入三情境並排（只引用上方各列，純展示）；HTML 驅動因子一節分「情境驅動」與「單一參數」兩張表。

Sheet In
A1: In — 輸入（藍字；基準欄 E，低 D、高 F）。金額：十億新台幣（NT$B），LEAP 與資本支出為十億美元（US$B）；顆數：百萬顆；比例：%。每個輸入附兩個來源（找不到者寫「未找到」）；公司原文算一個。【v0.1】基準欄 E 進主模型；D／F＝敏感度低／高，只用於 Sens 頁（一次動一個參數）、不進目標價；情境 A／B／C 的驅動見本頁最後一節「情境驅動對照」。
A2: 標記：Verified／Interested-party／Analogy／Assumed／Derived；Analogy、Assumed 給低／高區間（放 Sens），情境專屬列不給區間。SemiAnalysis 未使用。公司原文＝SEC 6-K（季度新聞稿與簡報）；法說內容經 Motley Fool 逐字稿；公司指引與說法為 Interested-party；券商與媒體為 Interested-party
A3: 鍵 | B3: 項目 | C3: 單位 | D3: 敏感度低 | E3: 基準 | F3: 敏感度高 | G3: 標記 | H3: 來源1 | I3: 來源2／說明
A4: A. AI 加速器顆數、情境係數與封裝面積（讀 Siliconomics 快照 v0.10（20261031_Siliconomics_v0.10.xlsx）；唯讀，不自行重估）
A5: units_26 | B5: AI 加速器顆數 2026（情境 A 基準） | C5: 百萬顆 | E5: 15.2 | G5: Derived | H5: Siliconomics SIF_UnitsPlat_Total_A（八類加速器合計） | I5: NVIDIA、AMD、Google TPU、AWS Trainium、其他 ASIC 合計；與台積電、Amkor、京元電模型同一份
A6: units_27 | B6: AI 加速器顆數 2027（情境 A 基準） | C6: 百萬顆 | E6: 23.7 | G6: Derived | H6: 同上 | I6: 同上
A7: units_28 | B7: AI 加速器顆數 2028（情境 A 基準） | C7: 百萬顆 | E7: 26.5 | G7: Derived | H7: 同上 | I7: 同上
A8: units_29 | B8: AI 加速器顆數 2029（情境 A 基準） | C8: 百萬顆 | E8: 30.15 | G8: Derived | H8: 同上 | I8: 同上
A9: um28_A | B9: 情境 A：2028 顆數 ÷ 基準 | C9: x | E9: 1 | G9: Assumed | H9: Siliconomics um28_A（同字母行業情境） | I9: A＝基準；B＝AI 資本支出消化；C＝明顯下修（與台積電、Amkor、NVIDIA 模型相同）
A10: um29_A | B10: 情境 A：2029 顆數 ÷ 基準 | C10: x | E10: 1 | G10: Assumed | H10: Siliconomics um29_A（同字母行業情境） | I10: 同上
A11: um28_B | B11: 情境 B：2028 顆數 ÷ 基準 | C11: x | E11: 0.8 | G11: Assumed | H11: Siliconomics um28_B（同字母行業情境） | I11: 同上
A12: um29_B | B12: 情境 B：2029 顆數 ÷ 基準 | C12: x | E12: 0.85 | G12: Assumed | H12: Siliconomics um29_B（同字母行業情境） | I12: 同上
A13: um28_C | B13: 情境 C：2028 顆數 ÷ 基準 | C13: x | E13: 0.6 | G13: Assumed | H13: Siliconomics um28_C（同字母行業情境） | I13: 同上
A14: um29_C | B14: 情境 C：2029 顆數 ÷ 基準 | C14: x | E14: 0.6 | G14: Assumed | H14: Siliconomics um29_C（同字母行業情境） | I14: 同上
A15: ar_26 | B15: 封裝面積指數 2026（加速器用 CoWoS 片數 ÷ 顆數，2026＝1） | C15: x | E15: 1 | G15: Derived | H15: Siliconomics 平台別顆數 SIF_UnitsPlat_* ÷ 每片封裝數 cw_pp_*（Blackwell→GB、Rubin→VR、Rubin Ultra→RU、AMD 2026 MI3xx→AMD8／之後→AMDR、TPU 2026→TPU7／之後→TPU8） | I15: 平台對應為本模型假設；每片封裝數下降＝單顆封裝面積變大（Rubin、Rubin Ultra）
A16: ar_27 | B16: 封裝面積指數 2027（加速器用 CoWoS 片數 ÷ 顆數，2026＝1） | C16: x | E16: 1.278156 | G16: Derived | H16: 同上 | I16: 同上
... A30: cpo_C_29 | B30: 情境 C：CPO 占 scale-out 光學金額 2029 | C30: % | E30: 0.05 | G30: Assumed | H30: Siliconomics cpo_C_29（技術替代屬行業情境，同字母） | I30: 同上
A31: fx | B31: 匯率：新台幣 ÷ 美元（2027 起換算 LEAP 與資本支出） | C31: NT$/US$ | D31: 30.5 | E31: 32 | F31: 33 | G31: Assumed | H31: Siliconomics fx_twd（v0.10） | I31: 公司 4Q26 指引假設 31.9（3Q26 新聞稿）
A32: B. 封測（ATM）：LEAP 先進封裝＝顆數 × 委外／份額相對值 × 每顆內容（隨封裝面積）＋全流程（CoWoS full process）＋CPO；主流封測另依成長率
A33: leap25 | B33: LEAP 營收 FY2025 | C33: US$B | E33: 1.6 | G33: Interested-party | H33: 公司 4Q25 新聞稿與簡報（SEC 6-K）：LEAP 2025 年 US$1.6B（占 ATM 13%）、2024 年 US$0.6B（公司 4Q25 簡報） | I33: 2026 年初目標 US$3.2B（同上）
A34: fx25 | B34: FY2025 平均匯率（LEAP 換算新台幣用） | C34: NT$/US$ | E34: 31 | G34: Assumed | H34: 公司：2025 年 ATM 美元營收年增 23%、新台幣年增 20%（4Q25 簡報）；4Q25 指引假設 30.9 | I34: 只影響 FY2025 LEAP／主流拆分
A35: leap26 | B35: LEAP 營收 FY2026（公司：逾 US$4B） | C35: US$B | E35: 4 | G35: Interested-party | H35: 3Q26 法說逐字稿（Motley Fool）：LEAP 2026 由 US$3.7B 上調到 over US$4 billion（3Q26 法說） | I35: 2Q26 法說報導（數位時代）：2Q26 法說時為逾 US$3.5B
A36: lsh_1h | B36: LEAP ÷ ATM 營收 1H26 | C36: % | E36: 0.18 | G36: Interested-party | H36: BofA 報告摘要（科技新報 2026-10-14）：BofA 估 1H26 18%、3Q26 22%、全年約 30%（券商） | I36: 公司未揭露季度 LEAP；只影響 Q 頁季度拆分
A37: lsh_3q | B37: LEAP ÷ ATM 營收 3Q26 | C37: % | E37: 0.22 | G37: Interested-party | H37: 同上（BofA 2026-10-14） | I37: 4Q26＝全年 US$4.0B 減前三季（Derived）
A38: fp26 | B38: 全流程（CoWoS full process）營收 FY2026（含在 LEAP） | C38: US$B | E38: 0.3 | G38: Interested-party | H38: 3Q26 法說逐字稿（Motley Fool）：full process 2026 約 US$300M、on track（3Q26 法說） | I38: 2Q26 法說報導（數位時代）：2Q26 法說同（約 3 億美元）
A39: fp27_A | B39: 情境 A：全流程營收 FY2027 | C39: US$B | E39: 1.2 | G39: Assumed | H39: 3Q26 法說逐字稿（Motley Fool）：full process 2027 over US$1 billion（保守；3Q26 法說） | I39: 公司稱逾 US$1B 為保守數字；取高於公司說法
A40: fp27_B | B40: 情境 B：全流程營收 FY2027 | C40: US$B | E40: 1 | G40: Interested-party | H40: 同上 | I40: 公司說法下緣（逾 US$1B）
A41: fp27_C | B41: 情境 C：全流程營收 FY2027 | C41: US$B | E41: 0.7 | G41: Assumed | H41: 同上 | I41: 全流程導入延後、台積電自製比例維持
A42: fp_g | B42: 全流程 FY2028–29：每年隨顆數成長外再加的滲透成長 | C42: % | D42: 0.1 | E42: 0.3 | F42: 0.5 | G42: Assumed | H42: 台積電 CoWoS 2027 需求接近產能（Siliconomics cw_capend27 200 千片／月）；全流程擴大由 OSAT 補充 | I42: 量化資料：未找到
A43: cpo27 | B43: CPO 營收 FY2027（情境 A 滲透率下；含在 LEAP） | C43: US$B | D43: 0.3 | E43: 0.5 | F43: 0.8 | G43: Interested-party | H43: 3Q26 法說逐字稿（Motley Fool）：CPO 2027 over US$0.5 billion，含在 LEAP；4Q26 量產（3Q26 法說） | I43: 2Q26 法說報導（數位時代）：2Q26 時稱 2026 年底小量（媒體）
A44: rel27_A | B44: 情境 A：日月光委外與份額相對值 2027（2026＝1） | C44: x | E44: 1.1 | G44: Assumed | H44: 台積電 CoWoS 吃緊、委外補充（Siliconomics cw_osat 10%）；日月光直接專案擴大（AMD Venice 等；BofA 2026-10-14） | I44: A＝委外擴大、份額上升；B＝小幅上升（公司 LEAP 翻倍的中性路徑）；C＝台積電自製與 Amkor 分食
A45: rel28_A | B45: 情境 A：日月光委外與份額相對值 2028（2026＝1） | C45: x | E45: 1.15 | G45: Assumed | H45: 同上 | I45: 同上
A46: rel29_A | B46: 情境 A：日月光委外與份額相對值 2029（2026＝1） | C46: x | E46: 1.2 | G46: Assumed | H46: 同上 | I46: 同上
A47: rel27_B | B47: 情境 B：日月光委外與份額相對值 2027（2026＝1） | C47: x | E47: 1.05 | G47: Assumed | H47: 同上 | I47: 同上
A48: rel28_B | B48: 情境 B：日月光委外與份額相對值 2028（2026＝1） | C48: x | E48: 1.08 | G48: Assumed | H48: 同上 | I48: 同上
A49: rel29_B | B49: 情境 B：日月光委外與份額相對值 2029（2026＝1） | C49: x | E49: 1.1 | G49: Assumed | H49: 同上 | I49: 同上
A50: rel27_C | B50: 情境 C：日月光委外與份額相對值 2027（2026＝1） | C50: x | E50: 1 | G50: Assumed | H50: 同上 | I50: 同上
A51: rel28_C | B51: 情境 C：日月光委外與份額相對值 2028（2026＝1） | C51: x | E51: 0.95 | G51: Assumed | H51: 同上 | I51: 同上
A52: rel29_C | B52: 情境 C：日月光委外與份額相對值 2029（2026＝1） | C52: x | E52: 0.92 | G52: Assumed | H52: 同上 | I52: 同上
A53: el | B53: 每顆 LEAP 內容對封裝面積的彈性 | C53: x | D53: 0.3 | E53: 0.5 | F53: 1 | G53: Assumed | H53: 封裝面積大 → oS、測試時間與良率成本上升；後段金額不與面積等比例（與 Amkor 模型同值） | I53: 第二來源：未找到
...

Sheet Q
A1: Q — 實績與 FY2026 錨點（十億新台幣；EPS 為新台幣、基本；股數為百萬股）。藍字＝輸入（SEC 6-K 公司新聞稿與簡報，原單位百萬元 ÷ 1,000）；黑字＝公式。分部營收取分部表（含部門間交易），差額列「沖銷及其他」
A2: v0.1（2026-10-31）：FY2026 錨點＝1Q、2Q、3Q26 實績（3Q26：2026-10-29 新聞稿）＋4Q26 依公司指引（ATM 季增 12%、ATM 毛利率 +1.5pt、EMS 持平；合併營收季增約 7%，指引 6–8%）
A3: 項目 | B3: FY2025A | C3: 1Q26（實績） | D3: 2Q26（實績） | E3: 3Q26（實績） | F3: 4Q26（模型） | G3: FY2026 錨點 | H3: 標記 | I3: 來源1（公司） | J3: 來源2／說明
A4: 營收 | B4: 645.388 | C4: 173.662 | D4: 191.064 | E4: 244.161 | F4: =F5+F8+F9 -> 262.28035 | G4: =SUM(C4:F4) -> 871.16735 | H4: Verified | I4: FY2025：4Q25 新聞稿（SEC 6-K 2026-02-05）；1Q、2Q26：2Q26 新聞稿（6-K 2026-07-30）；3Q26：6-K 2026-10-29 | J4: 9M26 608.887（公司月營收）＝三季合計
A5: 封測（ATM；分部表） | B5: 389.228 | C5: 112.434 | D5: 126.148 | E5: 151.485 | F5: =E5*(1+q4_atm) -> 169.6632 | G5: =SUM(C5:F5) -> 559.7302 | H5: Verified／Interested-party（4Q） | I5: FY2025：4Q25 新聞稿（SEC 6-K 2026-02-05）；1Q、2Q26：2Q26 新聞稿（6-K 2026-07-30）；3Q26：6-K 2026-10-29 | J5: ATM＝封裝、測試、材料；合併表口徑 FY2025 385.3、3Q26 150.6（含沖銷）
A6: LEAP 先進封裝（命題子列） | B6: =leap25*fx25 -> 49.6 | C6: =C5*lsh_1h -> 20.23812 | D6: =D5*lsh_1h -> 22.70664 | E6: =E5*lsh_3q -> 33.3267 | F6: =leap26*31.9-SUM(C6:E6) -> 51.32854 | G6: =SUM(C6:F6) -> 127.6 | H6: Interested-party／Derived | I6: FY2025：4Q25 新聞稿（SEC 6-K 2026-02-05）；1Q、2Q26：2Q26 新聞稿（6-K 2026-07-30）；3Q26：6-K 2026-10-29 | J6: FY2025 US$1.6B；1H26、3Q26 依 BofA 占比；4Q26＝全年 US$4.0B × 31.9 − 前三季（Derived）
A7: 主流封測（ATM − LEAP） | B7: =B5-B6 -> 339.628 | C7: =C5-C6 -> 92.19588 | D7: =D5-D6 -> 103.44136 | E7: =E5-E6 -> 118.1583 | F7: =F5-F6 -> 118.33466 | G7: =SUM(C7:F7) -> 432.1302 | H7: Derived | I7: — | J7: —
A8: EMS（環旭；分部表） | B8: 259.079 | C8: 61.875 | D8: 65.789 | E8: 93.469 | F8: =E8*(1+q4_ems) -> 93.469 | G8: =SUM(C8:F8) -> 314.602 | H8: Verified／Interested-party（4Q） | I8: FY2025：4Q25 新聞稿（SEC 6-K 2026-02-05）；1Q、2Q26：2Q26 新聞稿（6-K 2026-07-30）；3Q26：6-K 2026-10-29 | J8: 1Q26 簡報另一頁 61.361（口徑不同）；取分部頁
A9: 沖銷及其他（合併 − 分部合計） | B9: =B4-B5-B8 -> -2.919 | C9: =C4-C5-C8 -> -0.647 | D9: =D4-D5-D8 -> -0.873 | E9: =E4-E5-E8 -> -0.793 | F9: =E9/(E5+E8)*(F5+F8) -> -0.85184906 | G9: =SUM(C9:F9) -> -3.1648491 | H9: Derived | I9: — | J9: 4Q26 依 3Q26 比例
A10: 封測毛利 | B10: 91.38 | C10: 29.198 | D10: 34.487 | E10: 46.412 | F10: =F5*F11 -> 54.526388 | G10: =SUM(C10:F10) -> 164.62339 | H10: Verified | I10: FY2025：4Q25 新聞稿（SEC 6-K 2026-02-05）；1Q、2Q26：2Q26 新聞稿（6-K 2026-07-30）；3Q26：6-K 2026-10-29 | J10: —
A11: 封測毛利率 | B11: =B10/B5 -> 0.23477242 | C11: =C10/C5 -> 0.25969013 | D11: =D10/D5 -> 0.27338523 | E11: =E10/E5 -> 0.30638017 | F11: =E11+q4_atmgm -> 0.32138017 | G11: =G10/G5 -> 0.29411203 | H11: Derived | I11: — | J11: 公司：FY2025 23.5%、3Q26 30.6%
A12: EMS 毛利 | B12: 23.695 | C12: 5.862 | D12: 5.873 | E12: 7.793 | F12: =F8*q4_emsgm -> 7.47752 | G12: =SUM(C12:F12) -> 27.00552 | H12: Verified | I12: FY2025：4Q25 新聞稿（SEC 6-K 2026-02-05）；1Q、2Q26：2Q26 新聞稿（6-K 2026-07-30）；3Q26：6-K 2026-10-29 | J12: —
A13: 沖銷及其他毛利（合併毛利 − 分部毛利） | B13: =B14-B10-B12 -> -0.882 | C13: =C14-C10-C12 -> -0.242 | D13: =D14-D10-D12 -> -0.213 | E13: =E14-E10-E12 -> -0.238 | F13: =E13/E9*F9 -> -0.25566214 | G13: =SUM(C13:F13) -> -0.94866214 | H13: Derived | I13: — | J13: —
A14: 毛利 | B14: 114.193 | C14: 34.818 | D14: 40.147 | E14: 53.967 | F14: =F10+F12+F13 -> 61.748246 | G14: =SUM(C14:F14) -> 190.68025 | H14: Verified | I14: FY2025：4Q25 新聞稿（SEC 6-K 2026-02-05）；1Q、2Q26：2Q26 新聞稿（6-K 2026-07-30）；3Q26：6-K 2026-10-29 | J14: —
A15: 毛利率 | B15: =B14/B4 -> 0.17693697 | C15: =C14/C4 -> 0.20049291 | D15: =D14/D4 -> 0.21012331 | E15: =E14/E4 -> 0.22103039 | F15: =F14/F4 -> 0.23542841 | G15: =G14/G4 -> 0.21887901 | H15: Derived | I15: — | J15: 公司：FY2025 17.7%、3Q26 22.1%
A16: 營業費用（毛利 − 營業利益） | B16: =B14-B17 -> 63.437 | C16: =C14-C17 -> 17.325 | D16: =D14-D17 -> 19.017 | E16: =E14-E17 -> 20.825 | F16: =E16*(1+q4_opx) -> 22.491 | G16: =SUM(C16:F16) -> 79.658 | H16: Derived | I16: — | J16: —
A17: 營業利益 | B17: 50.756 | C17: 17.493 | D17: 21.13 | E17: 33.142 | F17: =F14-F16 -> 39.257246 | G17: =SUM(C17:F17) -> 111.02225 | H17: Verified | I17: FY2025：4Q25 新聞稿（SEC 6-K 2026-02-05）；1Q、2Q26：2Q26 新聞稿（6-K 2026-07-30）；3Q26：6-K 2026-10-29 | J17: —
A18: 營業外淨額 | B18: 0.545 | C18: 0.668 | D18: 4.566 | E18: =E19-E17 -> -0.432 | F18: =q4_nonop -> -0.5 | G18: =SUM(C18:F18) -> 4.302 | H18: Verified／Derived | I18: FY2025：4Q25 新聞稿（SEC 6-K 2026-02-05）；1Q、2Q26：2Q26 新聞稿（6-K 2026-07-30）；3Q26：6-K 2026-10-29 | J18: 2Q26 含投資評價利益 4.2、匯兌避險 1.5（風傳媒）
A19: 稅前利益 | B19: 51.301 | C19: 18.161 | D19: 25.696 | E19: 32.71 | F19: =F17+F18 -> 38.757246 | G19: =SUM(C19:F19) -> 115.32425 | H19: Verified | I19: FY2025：4Q25 新聞稿（SEC 6-K 2026-02-05）；1Q、2Q26：2Q26 新聞稿（6-K 2026-07-30）；3Q26：6-K 2026-10-29 | J19: —
A20: 所得稅 | B20: 9.461 | C20: 3.629 | D20: 4.171 | E20: 4.831 | F20: =F19*q4_tax -> 6.5887318 | G20: =SUM(C20:F20) -> 19.219732 | H20: Verified | I20: FY2025：4Q25 新聞稿（SEC 6-K 2026-02-05）；1Q、2Q26：2Q26 新聞稿（6-K 2026-07-30）；3Q26：6-K 2026-10-29 | J20: —
A21: 非控制權益 | B21: 1.182 | C21: 0.4 | D21: 0.46 | E21: 0.883 | F21: =q4_nci -> 0.8 | G21: =SUM(C21:F21) -> 2.543 | H21: Verified | I21: FY2025：4Q25 新聞稿（SEC 6-K 2026-02-05）；1Q、2Q26：2Q26 新聞稿（6-K 2026-07-30）；3Q26：6-K 2026-10-29 | J21: —
A22: 歸屬母公司淨利 | B22: 40.658 | C22: 14.132 | D22: 21.065 | E22: 26.996 | F22: =F19-F20-F21 -> 31.368514 | G22: =SUM(C22:F22) -> 93.561514 | H22: Verified | I22: FY2025：4Q25 新聞稿（SEC 6-K 2026-02-05）；1Q、2Q26：2Q26 新聞稿（6-K 2026-07-30）；3Q26：6-K 2026-10-29 | J22: —
A23: 基本股數（百萬股） | B23: =B22/B25*1000 -> 4339.1676 | C23: =C22/C25*1000 -> 4375.2322 | D23: =D22/D25*1000 -> 4388.5417 | E23: =E22/E25*1000 -> 4403.9152 | F23: =E23 -> 4403.9152 | G23: =AVERAGE(C23:F23) -> 4392.9011 | H23: Derived | I23: 淨利 ÷ 公司揭露基本 EPS | J23: —
A24: EPS（基本） | B24: =B22/B23*1000 -> 9.37 | C24: =C22/C23*1000 -> 3.23 | D24: =D22/D23*1000 -> 4.8 | E24: =E22/E23*1000 -> 6.13 | F24: =F22/F23*1000 -> 7.1228697 | G24: =SUM(C24:F24) -> 21.28287 | H24: Derived | I24: 淨利 ÷ 股數；FY2026＝四季加總 | J24: —
A25: 公司揭露 EPS（基本） | B25: 9.37 | C25: 3.23 | D25: 4.8 | E25: 6.13 | H25: Verified | I25: FY2025：4Q25 新聞稿（SEC 6-K 2026-02-05）；1Q、2Q26：2Q26 新聞稿（6-K 2026-07-30）；3Q26：6-K 2026-10-29 | J25: 稀釋 EPS：FY2025 8.89、3Q26 5.84（可轉債）
A26: 折舊攤提（EBITDA − 營業利益） | B26: =126.011-B17 -> 75.255 | C26: =38.147-C17 -> 20.654 | D26: =45.779-D17 -> 24.649 | E26: =57.963-E17 -> 24.821 | F26: =q4_da -> 27 | G26: =SUM(C26:F26) -> 97.124 | H26: Derived | I26: FY2025：4Q25 新聞稿（SEC 6-K 2026-02-05）；1Q、2Q26：2Q26 新聞稿（6-K 2026-07-30）；3Q26：6-K 2026-10-29 | J26: EBITDA：FY2025 126.0、1Q26 38.1、2Q26 45.8、3Q26 58.0（公司簡報）
A27: 資本支出（US$B） | B27: =capex25 -> 5.5 | G27: =capex26 -> 11.5 | H27: Interested-party | I27: FY2025：4Q25 新聞稿（SEC 6-K 2026-02-05）；1Q、2Q26：2Q26 新聞稿（6-K 2026-07-30）；3Q26：6-K 2026-10-29 | J27: 公司：2026 前三季 US$8.0B；全年 US$11.5B
A28: 資本支出 ÷ 營收 | B28: =B27*fx25/B4 -> 0.26418217 | G28: =G27*31.9/G4 -> 0.42110164 | H28: Derived | I28: — | J28: FY2026 以 31.9 換算
A29: LEAP ÷ 封測營收 | B29: =B6/B5 -> 0.12743174 | C29: =C6/C5 -> 0.18 | D29: =D6/D5 -> 0.18 | E29: =E6/E5 -> 0.22 | F29: =F6/F5 -> 0.30253196 | G29: =G6/G5 -> 0.22796697 | H29: Derived | I29: — | J29: —
A31: FY2026 錨點的檢查（參考；校準未使用券商數字）
A32: FY2026 營收年增 | B32: =G4/B4-1 -> 0.34983506
A33: FY2026 封測年增（公司 2Q26：逾 35%） | B33: =G5/B5-1 -> 0.43805225
A34: FY2026 主流封測年增（公司：逾 20%） | B34: =G7/B7-1 -> 0.27236329
A35: 封測現金毛利增量 ÷ 封測營收增量（In 頁 ft 的對照；折舊增量全數歸封測） | B35: =((G10+G26)-(B10+B26))/(G5-B5) -> 0.55783672
A36: 營業費用彈性（In 頁 phi 的對照） | B36: =(G16/B16-1)/(G4/B4-1) -> 0.73092304
A37: 4Q26 合併營收季增（指引 6–8%） | B37: =F4/E4-1 -> 0.074210668
A38: 4Q26 合併毛利率（指引 23–24%） | B38: =F15 -> 0.23542841
A39: 4Q26 合併營業利益率（指引 14.5–15.5%） | B39: =F17/F4 -> 0.14967666
A40: FY2025 分部毛利 + 沖銷 − 合併毛利（應為 0） | B40: =B10+B12+B13-B14 -> 0
A41: 3Q26 EPS 自算 − 公司 6.13（應約 0） | B41: =E24-E25 -> 0
...

Sheet Units
A1: Units — AI 加速器顆數（Siliconomics）→ 日月光 LEAP 先進封裝營收（情境 A）。部署 GW 讀 Siliconomics SIF_DeployGW_A，只作 Recon
A3: 項目 | B3: 單位 | C3: CY2026 | D3: CY2027 | E3: CY2028 | F3: CY2029 | G3: 說明
A4: AI 加速器顆數（情境 A） | B4: 百萬顆 | C4: =PL!D73 -> 15.2 | D4: =PL!E73 -> 23.7 | E4: =PL!F73 -> 26.5 | F4: =PL!G73 -> 30.15 | G4: Siliconomics（台積電、Amkor、京元電模型同一份）
A5: 封裝面積指數（2026＝1） | B5: x | C5: =PL!D74 -> 1 | D5: =PL!E74 -> 1.278156 | E5: =PL!F74 -> 1.428615 | F5: =PL!G74 -> 1.431796 | G5: Siliconomics 平台顆數 ÷ CoWoS 每片封裝數
A6: 委外與份額相對值 | B6: x | C6: =PL!D75 -> 1 | D6: =PL!E75 -> 1.1 | E6: =PL!F75 -> 1.15 | F6: =PL!G75 -> 1.2 | G6: Assumed（情境 A）
A7: 每顆 LEAP 核心內容 | B7: US$／顆 | C7: =PL!D76 -> 236.84211 | D7: =PL!E76 -> 267.76317 | E7: =PL!F76 -> 283.08478 | F7: =PL!G76 -> 283.39976 | G7: FY2026 校準；之後隨封裝面積
A8: LEAP 核心 | B8: US$B | C8: =PL!D77 -> 3.6 | D8: =PL!E77 -> 6.9805859 | E8: =PL!F77 -> 8.6270086 | F8: =PL!G77 -> 10.253403 | G8: 顆數 × 相對值 × 每顆內容
A9: 全流程 | B9: US$B | C9: =PL!D78 -> 0.3 | D9: =PL!E78 -> 1.2 | E9: =PL!F78 -> 1.7443038 | F9: =PL!G78 -> 2.5799241 | G9: 公司 2026 約 0.3、2027 逾 1.0
A10: CPO | B10: US$B | C10: =PL!D79 -> 0.1 | D10: =PL!E79 -> 0.5 | E10: =PL!F79 -> 1.1181435 | F10: =PL!G79 -> 2.035443 | G10: 公司 2027 逾 0.5；Siliconomics 滲透率
A11: LEAP 合計 | B11: US$B | C11: =PL!D80 -> 4 | D11: =PL!E80 -> 8.6805859 | E11: =PL!F80 -> 11.489456 | F11: =PL!G80 -> 14.868771 | G11: 公司：2026 逾 4.0、2027 翻倍
A12: 每顆加速器的日月光 LEAP 營收 | B12: US$／顆 | C12: =PL!D80/PL!D73*1000 -> 263.15789 | D12: =PL!E80/PL!E73*1000 -> 366.26945 | E12: =PL!F80/PL!F73*1000 -> 433.56437 | F12: =PL!G80/PL!G73*1000 -> 493.15989 | G12: 含全流程與 CPO
A13: 部署 GW（Siliconomics SIF_DeployGW_A） | B13: GW | C13: 23.399538 | D13: 41.646766 | E13: 52.792138 | F13: 60.138592 | G13: Siliconomics 推導值（唯讀）
A14: 每 GW 的日月光 LEAP 營收 | B14: US$B／GW | C14: =C11/C13 -> 0.17094355 | D14: =D11/D13 -> 0.20843361 | E14: =E11/E13 -> 0.21763574 | F14: =F11/F13 -> 0.24724175 | G14: 對照 Amkor 投資人日：OSAT 先進封裝可服務市場約 US$0.5B／GW
A16: 讀法：LEAP FY2026 以公司「逾 US$4B」校準，不是公司揭露的拆分；委外與份額相對值是 Assumed，只有相對變化影響 FY2027 起的營收。每顆內容隨封裝面積上升（彈性 0.5），全流程與 CPO 另計；CPO 依 Siliconomics 同字母滲透率縮放。

Sheet PL
A1: PL — 日月光投控損益（十億新台幣；EPS 新台幣、基本；歸屬母公司）。FY2025A 實績、FY2026 錨點（1Q–3Q26 實績＋4Q26 依指引；三情境相同），FY2027 起為模型。FY(t)＝CY(t)。三情境各一個完整推導區塊（本頁下方），頂端為摘要
A2: 灰底＝FY2030–FY2032 收斂法（上游只到 2029）：營收年增線性收斂到 fade_g、淨利率線性收斂到 fade_m（In 頁 I 節），非驅動因子推導
A3: 情境／項目 | B3: 單位 | C3: FY2025A | D3: FY2026（錨點） | E3: FY2027 | F3: FY2028 | G3: FY2029 | H3: FY2030（收斂） | I3: FY2031（收斂） | J3: FY2032（收斂） | K3: 說明
A4: 情境 A
A5: 營收 | B5: NT$B | C5: =C88 -> 645.388 | D5: =D88 -> 871.16735 | E5: =E88 -> 1116.7337 | F5: =F88 -> 1258.1932 | G5: =G88 -> 1421.1292 | H5: =H88 -> 1572.2425 | I5: =I88 -> 1703.0007 | J5: =J88 -> 1805.1807
A6: 營收年增 | B6: % | D6: =D89 -> 0.34983506 | E6: =E89 -> 0.28188197 | F6: =F89 -> 0.12667256 | G6: =G89 -> 0.12949994 | H6: =H89 -> 0.10633329 | I6: =I89 -> 0.083166646 | J6: =J89 -> 0.06
A7: 封測（ATM） | B7: NT$B | C7: =C85 -> 389.228 | D7: =D85 -> 559.7302 | E7: =E85 -> 774.72848 | F7: =F85 -> 899.3988 | G7: =G85 -> 1044.7584
A8: LEAP 先進封裝 | B8: NT$B | C8: =C83 -> 49.6 | D8: =D83 -> 127.6 | E8: =E83 -> 277.77875 | F8: =F83 -> 367.66259 | G8: =G83 -> 475.80066
A9: LEAP ÷ 封測營收 | B9: % | C9: =C90 -> 0.12743174 | D9: =D90 -> 0.22796697 | E9: =E90 -> 0.35854981 | F9: =F90 -> 0.40878706 | G9: =G90 -> 0.45541692
A10: EMS | B10: NT$B | C10: =C86 -> 259.079 | D10: =D86 -> 314.602 | E10: =E86 -> 346.0622 | F10: =F86 -> 363.36531 | G10: =G86 -> 381.53358
A11: 封測毛利率 | B11: % | C11: =C98 -> 0.23477242 | D11: =D98 -> 0.29411203 | E11: =E98 -> 0.30772946 | F11: =F98 -> 0.29474901 | G11: =G98 -> 0.29806418
A12: 毛利率 | B12: % | C12: =C102 -> 0.17693697 | D12: =D102 -> 0.21887901 | E12: =E102 -> 0.2387373 | F12: =F102 -> 0.23415548 | G12: =G102 -> 0.24085627
A13: 營業利益率 | B13: % | C13: =C105 -> 0.078644164 | D13: =D105 -> 0.12744078 | E13: =E105 -> 0.15534187 | F13: =F105 -> 0.15451053 | G13: =G105 -> 0.16486391
A14: 資本支出 ÷ 營收 | B14: % | C14: =C95 -> 0.26418217 | D14: =D95 -> 0.42110164 | E14: =E95 -> 0.37251495 | F14: =F95 -> 0.3 | G14: =G95 -> 0.3
A15: 歸屬母公司淨利 | B15: NT$B | C15: =C110 -> 40.658 | D15: =D110 -> 93.561514 | E15: =E110 -> 136.83466 | F15: =F110 -> 154.2054 | G15: =G110 -> 187.31312 | H15: =H110 -> 207.23074 | I15: =I110 -> 224.46542 | J15: =J110 -> 237.93335
A16: 淨利率 | B16: % | C16: =C114 -> 0.062997763 | D16: =D114 -> 0.10739787 | E16: =E114 -> 0.12253115 | F16: =F114 -> 0.12256099 | G16: =G114 -> 0.13180583 | H16: =H114 -> 0.13180583 | I16: =I114 -> 0.13180583 | J16: =J114 -> 0.13180583
A17: EPS | B17: NT$ | C17: =C112 -> 9.37 | D17: =D112 -> 21.28287 | E17: =E112 -> 30.994073 | F17: =F112 -> 34.754901 | G17: =G112 -> 42.006702 | H17: =H112 -> 46.242202 | I17: =I112 -> 49.838817 | J17: =J112 -> 52.566314
A18: EPS 年增 | B18: % | D18: =D113 -> 1.2713842 | E18: =E113 -> 0.45629199 | F18: =F113 -> 0.12134023 | G18: =G113 -> 0.20865551 | H18: =H113 -> 0.10082915 | I18: =I113 -> 0.077777757 | J18: =J113 -> 0.054726368
A20: 情境 B
A21: 營收 | B21: NT$B | C21: =C137 -> 645.388 | D21: =D137 -> 871.16735 | E21: =E137 -> 1093.8632 | F21: =F137 -> 1149.8566 | G21: =G137 -> 1287.6254 | H21: =H137 -> 1407.644 | I21: =I137 -> 1501.3996 | J21: =J137 -> 1561.4556
A22: 營收年增 | B22: % | D22: =D138 -> 0.34983506 | E22: =E138 -> 0.25562927 | F22: =F138 -> 0.051188617 | G22: =G138 -> 0.11981389 | H22: =H138 -> 0.093209263 | I22: =I138 -> 0.066604631 | J22: =J138 -> 0.04
A23: 封測（ATM） | B23: NT$B | C23: =C134 -> 389.228 | D23: =D134 -> 559.7302 | E23: =E134 -> 751.7749 | F23: =F134 -> 790.66855 | G23: =G134 -> 910.76958
A24: LEAP 先進封裝 | B24: NT$B | C24: =C132 -> 49.6 | D24: =D132 -> 127.6 | E24: =E132 -> 254.82517 | F24: =F132 -> 258.93234 | G24: =G132 -> 341.81183
A25: LEAP ÷ 封測營收 | B25: % | C25: =C139 -> 0.12743174 | D25: =D139 -> 0.22796697 | E25: =E139 -> 0.33896472 | F25: =F139 -> 0.32748532 | G25: =G139 -> 0.37530001
A26: EMS | B26: NT$B | C26: =C135 -> 259.079 | D26: =D135 -> 314.602 | E26: =E135 -> 346.0622 | F26: =F135 -> 363.36531 | G26: =G135 -> 381.53358
A27: 封測毛利率 | B27: % | C27: =C147 -> 0.23477242 | D27: =D147 -> 0.29411203 | E27: =E147 -> 0.30185896 | F27: =F147 -> 0.26652354 | G27: =G147 -> 0.27281683
A28: 毛利率 | B28: % | C28: =C151 -> 0.17693697 | D28: =D151 -> 0.21887901 | E28: =E151 -> 0.23325961 | F28: =F151 -> 0.20903972 | G28: =G151 -> 0.21706738
A29: 營業利益率 | B29: % | C29: =C154 -> 0.078644164 | D29: =D154 -> 0.12744078 | E29: =E154 -> 0.14926762 | F29: =F154 -> 0.12668375 | G29: =G154 -> 0.13823607
A30: 資本支出 ÷ 營收 | B30: % | C30: =C144 -> 0.26418217 | D30: =D144 -> 0.42110164 | E30: =E144 -> 0.38030349 | F30: =F144 -> 0.3 | G30: =G144 -> 0.3
A31: 歸屬母公司淨利 | B31: NT$B | C31: =C159 -> 40.658 | D31: =D159 -> 93.561514 | E31: =E159 -> 128.37104 | F31: =F159 -> 113.75456 | G31: =G159 -> 140.5869 | H31: =H159 -> 148.56787 | I31: =I159 -> 152.99893 | J31: =J159 -> 153.43607
A32: 淨利率 | B32: % | C32: =C163 -> 0.062997763 | D32: =D163 -> 0.10739787 | E32: =E163 -> 0.11735566 | F32: =F163 -> 0.098929349 | G32: =G163 -> 0.10918308 | H32: =H163 -> 0.10554364 | I32: =I163 -> 0.10190421 | J32: =J163 -> 0.09826477
A33: EPS | B33: NT$ | C33: =C161 -> 9.37 | D33: =D161 -> 21.28287 | E33: =E161 -> 29.076998 | F33: =F161 -> 25.638067 | G33: =G161 -> 31.527915 | H33: =H161 -> 33.151962 | I33: =I161 -> 33.97087 | J33: =J161 -> 33.898437
A34: EPS 年增 | B34: % | D34: =D162 -> 1.2713842 | E34: =E162 -> 0.36621603 | F34: =F162 -> -0.11826981 | G34: =G162 -> 0.22973058 | H34: =H162 -> 0.051511397 | I34: =I162 -> 0.024701653 | J34: =J162 -> -0.0021321962
A36: 情境 C
A37: 營收 | B37: NT$B | C37: =C186 -> 645.388 | D37: =D186 -> 871.16735 | E37: =E186 -> 1070.9927 | F37: =F186 -> 1054.0807 | G37: =G186 -> 1138.3936 | H37: =H186 -> 1206.6874 | I37: =I186 -> 1254.9497 | J37: =J186 -> 1280.0487
A38: 營收年增 | B38: % | D38: =D187 -> 0.34983506 | E38: =E187 -> 0.22937657 | F38: =F187 -> -0.01579095 | G38: =G187 -> 0.079987082 | H38: =H187 -> 0.059991388 | I38: =I187 -> 0.039995694 | J38: =J187 -> 0.02
A39: 封測（ATM） | B39: NT$B | C39: =C183 -> 389.228 | D39: =D183 -> 559.7302 | E39: =E183 -> 728.82132 | F39: =F183 -> 694.54478 | G39: =G183 -> 760.99565
A40: LEAP 先進封裝 | B40: NT$B | C40: =C181 -> 49.6 | D40: =D181 -> 127.6 | E40: =E181 -> 231.87159 | F40: =F181 -> 162.80857 | G40: =G181 -> 192.03791
A41: LEAP ÷ 封測營收 | B41: % | C41: =C188 -> 0.12743174 | D41: =D188 -> 0.22796697 | E41: =E188 -> 0.318146 | F41: =F188 -> 0.23441047 | G41: =G188 -> 0.25235086
A42: EMS | B42: NT$B | C42: =C184 -> 259.079 | D42: =D184 -> 314.602 | E42: =E184 -> 346.0622 | F42: =F184 -> 363.36531 | G42: =G184 -> 381.53358
...

Sheet Val
A1: Val — P/E 估值（新台幣）。結論用「現價 ÷ FY2027、FY2028 EPS（模型）」；目標價＝DCF 與 Comparable 加權（第 0 節）；十年 P/E 規則值（第 3 節，年底落後 P/E）只作參考
A2: 循環位置：日月光不是設備股，不套設備市場見頂年；以本模型封測（ATM）營收最高的會計年度為見頂年（Andy 前一串定案；FY(t)＝CY(t)）。封測營收到 FY2029 仍在增加時，見頂年未知，判為中段
A4: 0. 目標價
A5: 0.1 DCF（股東權益現金流，FY2027–FY2032 明確期＋FY2032 後永續）
A6: 項目 | B6: A（順利） | C6: B（平平） | D6: C（不如預期） | E6: 說明
A7: 情境 EPS（FY2027–FY2032） | E7: PL 頁各情境；FY2030 起為收斂法
A8: FY2027 | B8: =PL!E17 -> 30.994073 | C8: =PL!E33 -> 29.076998 | D8: =PL!E49 -> 27.159923
A9: FY2028 | B9: =PL!F17 -> 34.754901 | C9: =PL!F33 -> 25.638067 | D9: =PL!F49 -> 17.590034
A10: FY2029 | B10: =PL!G17 -> 42.006702 | C10: =PL!G33 -> 31.527915 | D10: =PL!G49 -> 19.671479
A11: FY2030 | B11: =PL!H17 -> 46.242202 | C11: =PL!H33 -> 33.151962 | D11: =PL!H49 -> 19.364669
A12: FY2031 | B12: =PL!I17 -> 49.838817 | C12: =PL!I33 -> 33.97087 | D12: =PL!I49 -> 18.607622
A13: FY2032 | B13: =PL!J17 -> 52.566314 | C13: =PL!J33 -> 33.898437 | D13: =PL!J49 -> 17.432628
A14: 股東現金流＝EPS ×（1 − tp_g ÷ tp_roe）
A15: 再投資率（tp_g ÷ tp_roe，上限 0.8） | B15: =MIN(tp_g/tp_roe,0.8) -> 0.37974684 | E15: ROE 為近三年平均（In 頁 tp_roe）
A16: FY2027 | B16: =B8*(1-$B$15) -> 19.224172 | C16: =C8*(1-$B$15) -> 18.0351 | D16: =D8*(1-$B$15) -> 16.846028
A17: FY2028 | B17: =B9*(1-$B$15) -> 21.556837 | C17: =C9*(1-$B$15) -> 15.902092 | D17: =D9*(1-$B$15) -> 10.910274
A18: FY2029 | B18: =B10*(1-$B$15) -> 26.05479 | C18: =C10*(1-$B$15) -> 19.555289 | D18: =D10*(1-$B$15) -> 12.201297
A19: FY2030 | B19: =B11*(1-$B$15) -> 28.681872 | C19: =C11*(1-$B$15) -> 20.562609 | D19: =D11*(1-$B$15) -> 12.010997
A20: FY2031 | B20: =B12*(1-$B$15) -> 30.912684 | C20: =C12*(1-$B$15) -> 21.07054 | D20: =D12*(1-$B$15) -> 11.541436
A21: FY2032 | B21: =B13*(1-$B$15) -> 32.604423 | C21: =C13*(1-$B$15) -> 21.025613 | D21: =D13*(1-$B$15) -> 10.812643
A22: DCF 情境每股價值（折現率 tp_r） | B22: =MAX(0,SUMPRODUCT(B16:B21,1/(1+tp_r)^{1;2;3;4;5;6})+B21*(1+tp_g)/(tp_r-tp_g)/(1+tp_r)^6) -> 431.06491 | C22: =MAX(0,SUMPRODUCT(C16:C21,1/(1+tp_r)^{1;2;3;4;5;6})+C21*(1+tp_g)/(tp_r-tp_g)/(1+tp_r)^6) -> 288.94516 | D22: =MAX(0,SUMPRODUCT(D16:D21,1/(1+tp_r)^{1;2;3;4;5;6})+D21*(1+tp_g)/(tp_r-tp_g)/(1+tp_r)^6) -> 160.76501 | E22: Σ 明確期現金流 ÷ (1＋r)^t ＋ 永續價值 ÷ (1＋r)^6；永續價值＝FY2032 現金流 ×(1＋g)÷(r−g)；基準日 2026 年底；下限 0
A23: DCF 情境價值推到 12 個月後（×(1＋tp_r)） | B23: =B22*(1+tp_r) -> 474.1714 | C23: =C22*(1+tp_r) -> 317.83968 | D23: =D22*(1+tp_r) -> 176.84151
A24: DCF 目標價（情境加權） | B24: =tp_wA*B23+tp_wB*C23+tp_wC*D23 -> 336.53956 | E24: Σ 權重 × 情境價值 ×(1＋r)；權重見 In 頁
A26: 0.2 Comparable（市場主流同業前瞻 P/E）
A27: 同業與前瞻 P/E | B27: 代號 | C27: 前瞻 12 月 P/E | D27: 日期 | E27: 來源 | F27: 標記
A28: Amkor Technology（艾克爾） | B28: AMKR | C28: 14.02 | D28: 2026-10-23 | E28: stockanalysis.com forward PE（分析師共識；價格日期如左；與 Amkor、京元電模型同一組數字） | F28: Interested-party
A29: 力成（Powertech） | B29: 6239.TW | C29: 20.6 | D29: 2026-10-02 | E29: stockanalysis.com forward PE（分析師共識；價格日期如左；與 Amkor、京元電模型同一組數字） | F29: Interested-party
A30: 京元電子（KYEC） | B30: 2449.TW | C30: 26.13 | D30: 2026-10-06 | E30: stockanalysis.com forward PE（分析師共識；價格日期如左；與 Amkor、京元電模型同一組數字） | F30: Interested-party
A31: 矽格（Sigurd） | B31: 6257.TW | C31: 23.3 | D31: 2026-10-02 | E31: stockanalysis.com forward PE（分析師共識；價格日期如左；與 Amkor、京元電模型同一組數字） | F31: Interested-party
A32: 南茂（ChipMOS） | B32: 8150.TW | C32: 22.08 | D32: 2026-10-08 | E32: stockanalysis.com forward PE（分析師共識；價格日期如左；與 Amkor、京元電模型同一組數字） | F32: Interested-party
A33: 同業前瞻 P/E 中位數 | B33: =MEDIAN(C28:C32) -> 22.08 | E33: 台美封測同業：Amkor、力成、京元電、矽格、南茂（不放 A 股：長電、通富）
A34: 12 個月後的前瞻 EPS（情境加權） | B34: =tp_wA*(2/12*B8+10/12*B9)+tp_wB*(2/12*C8+10/12*C9)+tp_wC*(2/12*D8+10/12*D9) -> 27.181043 | E34: 約 2027-10 時的未來 12 月 EPS ≈ 2／12 × FY2027＋10／12 × FY2028（會計年度＝日曆年）
A35: Comparable 目標價 | B35: =B33*B34 -> 600.15743 | E35: 同業中位數 × 前瞻 EPS
A37: 0.3 結論
A38: 項目 | B38: 數值 | E38: 說明
A39: 目標價（DCF 與 Comparable 加權） | B39: =tp_w_dcf*B24+(1-tp_w_dcf)*tp_comp_adj -> 503.84483 | E39: tp_w_dcf × DCF＋（1 − tp_w_dcf）× Comparable（相對倍數調整後，Val 第 0.5 節）；tp_w_dcf 見 In 頁
A40: Comparable 目標價（市場主流同業法） | B40: =B35 -> 600.15743
A41: 市場共識目標價 | B41: =cons_tp -> 900 | E41: 賣方平均：未找到；以 BofA 900（2026-10-14，單一券商）代替
A42: 上檔空間：加權目標價 | B42: =B39/px-1 -> -0.24574127 | E42: 現價＝In 頁 px（2026-10-30 收盤）
A43: 上檔空間：Comparable 目標價 | B43: =B40/px-1 -> -0.10156074
...

Sheet Recon
A1: Recon — 本模型 vs 公司指引、公司說法、券商預估與市場口徑。只作事後對照，不為對上數字而調參數。賣方共識未找到，以 BofA（2026-10-14，單一券商，3Q26 財報前）對照
A3: 項目 | B3: 對照值 | C3: 模型 A | D3: 差距 A | E3: 模型 B | F3: 差距 B | G3: 模型 C | H3: 差距 C | I3: 對照來源 | J3: 說明
A4: A. 4Q26 模型 vs 公司指引（錨點用指引中點，非獨立檢驗）
A5: 4Q26 合併營收季增 vs 指引中點 7%（百分點） | B5: =(g4_rev_lo+g4_rev_hi)/2 -> 0.07 | C5: =Q!F4/Q!E4-1 -> 0.074210668 | D5: =C5-B5 -> 0.0042106681 | E5: =Q!F4/Q!E4-1 -> 0.074210668 | F5: =E5-B5 -> 0.0042106681 | G5: =Q!F4/Q!E4-1 -> 0.074210668 | H5: =G5-B5 -> 0.0042106681 | I5: 3Q26 新聞稿：6–8%
A6: 4Q26 合併毛利率 vs 指引中點 23.5%（百分點） | B6: =(g4_gm_lo+g4_gm_hi)/2 -> 0.235 | C6: =Q!F15 -> 0.23542841 | D6: =C6-B6 -> 0.00042840948 | E6: =Q!F15 -> 0.23542841 | F6: =E6-B6 -> 0.00042840948 | G6: =Q!F15 -> 0.23542841 | H6: =G6-B6 -> 0.00042840948 | I6: 3Q26 新聞稿：23–24%
A7: 4Q26 合併營業利益率 vs 指引中點 15%（百分點） | B7: =(g4_om_lo+g4_om_hi)/2 -> 0.15 | C7: =Q!F17/Q!F4 -> 0.14967666 | D7: =C7-B7 -> -0.00032334401 | E7: =Q!F17/Q!F4 -> 0.14967666 | F7: =E7-B7 -> -0.00032334401 | G7: =Q!F17/Q!F4 -> 0.14967666 | H7: =G7-B7 -> -0.00032334401 | I7: 3Q26 新聞稿：14.5–15.5% | J7: 營業費用季增 8% 校準
A8: B. 公司說法（3Q26 法說 2026-10-29）
A9: FY2027 LEAP ÷ FY2026（公司：翻倍） | B9: 2 | C9: =PL!E80/PL!D80 -> 2.1701465 | D9: =C9/B9-1 -> 0.085073237 | E9: =PL!E129/PL!D129 -> 1.9908216 | F9: =E9/B9-1 -> -0.0045891827 | G9: =PL!E178/PL!D178 -> 1.8114968 | H9: =G9/B9-1 -> -0.094251603 | I9: 3Q26 法說：expecting … to double our LEAP revenue | J9: 情境 A 高於翻倍、B 約翻倍
A10: FY2027 全流程（公司：逾 US$1B） | B10: 1 | C10: =PL!E78 -> 1.2 | D10: =C10/B10-1 -> 0.2 | E10: =PL!E127 -> 1 | F10: =E10/B10-1 -> 0 | G10: =PL!E176 -> 0.7 | H10: =G10/B10-1 -> -0.3 | I10: 3Q26 法說：over US$1 billion（保守）
A11: FY2027 CPO（公司：逾 US$0.5B） | B11: =cpo27 -> 0.5 | C11: =PL!E79 -> 0.5 | D11: =C11/B11-1 -> 0 | E11: =PL!E128 -> 0.3 | F11: =E11/B11-1 -> -0.4 | G11: =PL!E177 -> 0.2 | H11: =G11/B11-1 -> -0.6 | I11: 3Q26 法說：over US$0.5 billion | J11: B、C 依 Siliconomics 較低滲透率
A12: FY2027 主流封測年增 vs 公司「與 2026 相近」（FY2026 實測，百分點） | B12: =Q!G7/Q!B7-1 -> 0.27236329 | C12: =PL!E84/PL!D84-1 -> 0.15 | D12: =C12-B12 -> -0.12236329 | E12: =PL!E133/PL!D133-1 -> 0.15 | F12: =E12-B12 -> -0.12236329 | G12: =PL!E182/PL!D182-1 -> 0.15 | H12: =G12-B12 -> -0.12236329 | I12: 3Q26 法說：general market 2027 similar（逾 20%） | J12: 本模型取 15%（偏保守）
A13: FY2027 資本支出 vs FY2026 US$11.5B（公司：更大） | B13: =capex26 -> 11.5 | C13: =PL!E93 -> 13 | D13: =C13/B13-1 -> 0.13043478 | E13: =PL!E142 -> 13 | F13: =E13/B13-1 -> 0.13043478 | G13: =PL!E191 -> 13 | H13: =G13/B13-1 -> 0.13043478 | I13: 3Q26 法說：even larger than this year
A14: C. 券商（BofA 2026-10-14；3Q26 財報前、單一來源）
A15: FY2026 EPS vs BofA | B15: =bofa_eps26 -> 19.64 | C15: =PL!D112 -> 21.28287 | D15: =C15/B15-1 -> 0.083649172 | E15: =PL!D161 -> 21.28287 | F15: =E15/B15-1 -> 0.083649172 | G15: =PL!D210 -> 21.28287 | H15: =G15/B15-1 -> 0.083649172 | I15: BofA | J15: 錨點含 3Q26 實績（BofA 為財報前）
A16: FY2027 EPS vs BofA | B16: =bofa_eps27 -> 34.26 | C16: =PL!E112 -> 30.994073 | D16: =C16/B16-1 -> -0.095327706 | E16: =PL!E161 -> 29.076998 | F16: =E16/B16-1 -> -0.15128436 | G16: =PL!E210 -> 27.159923 | H16: =G16/B16-1 -> -0.20724101 | I16: BofA
A17: FY2028 EPS vs BofA | B17: =bofa_eps28 -> 49.78 | C17: =PL!F112 -> 34.754901 | D17: =C17/B17-1 -> -0.30183004 | E17: =PL!F161 -> 25.638067 | F17: =E17/B17-1 -> -0.48497254 | G17: =PL!F210 -> 17.590034 | H17: =G17/B17-1 -> -0.64664457 | I17: BofA | J17: 差距超過 30% 時 README 說明
A18: FY2028 封測毛利率 vs BofA 約 30%（百分點） | B18: =bofa_gm28 -> 0.3 | C18: =PL!F98 -> 0.29474901 | D18: =C18-B18 -> -0.0052509895 | E18: =PL!F147 -> 0.26652354 | F18: =E18-B18 -> -0.033476458 | G18: =PL!F196 -> 0.23421081 | H18: =G18-B18 -> -0.065789189 | I18: BofA
A19: D. LEAP 的市場口徑
A20: FY2026 每 GW 的日月光 LEAP 營收（US$B／GW） | C20: =Units!C14 -> 0.17094355 | E20: =Units!C14 -> 0.17094355 | G20: =Units!C14 -> 0.17094355 | I20: Siliconomics 部署 GW | J20: 對照 Amkor 投資人日：OSAT 先進封裝 US$0.5B／GW（全體 OSAT）
A21: FY2027 每 GW 的日月光 LEAP 營收（US$B／GW） | C21: =Units!D14 -> 0.20843361 | E21: =Units!D14 -> 0.20843361 | G21: =Units!D14 -> 0.20843361 | I21: 同上 | J21: 情境 A
A22: FY2028 LEAP ÷ 封測營收（核心問題：三成以上） | B22: 0.3 | C22: =PL!F90 -> 0.40878706 | D22: =C22-B22 -> 0.10878706 | E22: =PL!F139 -> 0.32748532 | F22: =E22-B22 -> 0.027485316 | G22: =PL!F188 -> 0.23441047 | H22: =G22-B22 -> -0.065589532 | I22: 核心問題門檻

Sheet Sens
A1: Sens — 一次動一個輸入（三情境同時重算，再依情境權重求 DCF 與 Comparable 目標價）：對 FY2027、FY2028 EPS（情境 B）與加權目標價的影響。每個案例的三情境推導區塊在本頁下方
A2: 註：情境專屬列（委外相對值、全流程 FY2027、CPO 滲透率、顆數係數）不給敏感度區間，差異見情境 B、C；Comparable 欄已乘相對倍數調整係數（rm_factor），與加權目標價同口徑。
A3: 案例 | B3: 鍵 | C3: 設定 | D3: FY2027 EPS（B） | E3: FY2028 EPS（B） | F3: FY2028 EPS（B）相對基準 | G3: DCF 目標價 | H3: Comparable 目標價 | I3: 加權目標價 | J3: 加權目標價相對基準
A4: 基準 | B4: — | C4: PL 三情境 | D4: =PL!E161 -> 29.076998 | E4: =PL!F161 -> 25.638067 | F4: =E4/E$4-1 -> 0 | G4: =(tp_wA*MAX(0,PL!E112*(1-MIN(tp_g/tp_roe,0.8))/(1+tp_r)^1+PL!F112*(1-MIN(tp_g/tp_roe,0.8))/(1+tp_r)^2+PL!G112*(1-MIN(tp_g/tp_roe,0.8))/(1+tp_r)^3+PL!H112*(1-MIN(tp_g/tp_roe,0.8))/(1+tp_r)^4+PL!I112*(1-MIN(tp_g/tp_roe,0.8))/(1+tp_r)^5+PL!J112*(1-MIN(tp_g/tp_roe,0.8))/(1+tp_r)^6+PL!J112*(1-MIN(tp_g/tp_roe,0.8))*(1+tp_g)/(tp_r-tp_g)/(1+tp_r)^6)+tp_wB*MAX(0,PL!E161*(1-MIN(tp_g/tp_roe,0.8))/(1+tp_r)^1+PL!F161*(1-MIN(tp_g/tp_roe,0.8))/(1+tp_r)^2+PL!G161*(1-MIN(tp_g/tp_roe,0.8))/(1+tp_r)^3+PL!H161*(1-MIN(tp_g/tp_roe,0.8))/(1+tp_r)^4+PL!I161*(1-MIN(tp_g/tp_roe,0.8))/(1+tp_r)^5+PL!J161*(1-MIN(tp_g/tp_roe,0.8))/(1+tp_r)^6+PL!J161*(1-MIN(tp_g/tp_roe,0.8))*(1+tp_g)/(tp_r-tp_g)/(1+tp_r)^6)+tp_wC*MAX(0,PL!E210*(1-MIN(tp_g/tp_roe,0.8))/(1+tp_r)^1+PL!F210*(1-MIN(tp_g/tp_roe,0.8))/(1+tp_r)^2+PL!G210*(1-MIN(tp_g/tp_roe,0.8))/(1+tp_r)^3+PL!H210*(1-MIN(tp_g/tp_roe,0.8))/(1+tp_r)^4+PL!I210*(1-MIN(tp_g/tp_roe,0.8))/(1+tp_r)^5+PL!J210*(1-MIN(tp_g/tp_roe,0.8))/(1+tp_r)^6+PL!J210*(1-MIN(tp_g/tp_roe,0.8))*(1+tp_g)/(tp_r-tp_g)/(1+tp_r)^6))*(1+tp_r) -> 336.53956 | H4: =Val!$B$33*(tp_wA*(2/12*PL!E112+10/12*PL!F112)+tp_wB*(2/12*PL!E161+10/12*PL!F161)+tp_wC*(2/12*PL!E210+10/12*PL!F210))*rm_factor -> 671.1501 | I4: =tp_w_dcf*G4+(1-tp_w_dcf)*H4 -> 503.84483 | J4: =I4/I$4-1 -> 0
A5: AI 部署 ×0.8 | B5: mf | C5: FY2027 起顆數 ×0.8（三情境） | D5: =E211 -> 25.5153 | E5: =F211 -> 22.184187 | F5: =E5/E$4-1 -> -0.13471687 | G5: =(tp_wA*MAX(0,E162*(1-MIN(tp_g/tp_roe,0.8))/(1+tp_r)^1+F162*(1-MIN(tp_g/tp_roe,0.8))/(1+tp_r)^2+G162*(1-MIN(tp_g/tp_roe,0.8))/(1+tp_r)^3+H162*(1-MIN(tp_g/tp_roe,0.8))/(1+tp_r)^4+I162*(1-MIN(tp_g/tp_roe,0.8))/(1+tp_r)^5+J162*(1-MIN(tp_g/tp_roe,0.8))/(1+tp_r)^6+J162*(1-MIN(tp_g/tp_roe,0.8))*(1+tp_g)/(tp_r-tp_g)/(1+tp_r)^6)+tp_wB*MAX(0,E211*(1-MIN(tp_g/tp_roe,0.8))/(1+tp_r)^1+F211*(1-MIN(tp_g/tp_roe,0.8))/(1+tp_r)^2+G211*(1-MIN(tp_g/tp_roe,0.8))/(1+tp_r)^3+H211*(1-MIN(tp_g/tp_roe,0.8))/(1+tp_r)^4+I211*(1-MIN(tp_g/tp_roe,0.8))/(1+tp_r)^5+J211*(1-MIN(tp_g/tp_roe,0.8))/(1+tp_r)^6+J211*(1-MIN(tp_g/tp_roe,0.8))*(1+tp_g)/(tp_r-tp_g)/(1+tp_r)^6)+tp_wC*MAX(0,E260*(1-MIN(tp_g/tp_roe,0.8))/(1+tp_r)^1+F260*(1-MIN(tp_g/tp_roe,0.8))/(1+tp_r)^2+G260*(1-MIN(tp_g/tp_roe,0.8))/(1+tp_r)^3+H260*(1-MIN(tp_g/tp_roe,0.8))/(1+tp_r)^4+I260*(1-MIN(tp_g/tp_roe,0.8))/(1+tp_r)^5+J260*(1-MIN(tp_g/tp_roe,0.8))/(1+tp_r)^6+J260*(1-MIN(tp_g/tp_roe,0.8))*(1+tp_g)/(tp_r-tp_g)/(1+tp_r)^6))*(1+tp_r) -> 316.36624 | H5: =Val!$B$33*(tp_wA*(2/12*E162+10/12*F162)+tp_wB*(2/12*E211+10/12*F211)+tp_wC*(2/12*E260+10/12*F260))*rm_factor -> 583.08261 | I5: =tp_w_dcf*G5+(1-tp_w_dcf)*H5 -> 449.72442 | J5: =I5/I$4-1 -> -0.10741483
A6: AI 部署 ×1.2 | B6: mf | C6: ×1.2 | D6: =E358 -> 32.638696 | E6: =F358 -> 29.091099 | F6: =E6/E$4-1 -> 0.13468378 | G6: =(tp_wA*MAX(0,E309*(1-MIN(tp_g/tp_roe,0.8))/(1+tp_r)^1+F309*(1-MIN(tp_g/tp_roe,0.8))/(1+tp_r)^2+G309*(1-MIN(tp_g/tp_roe,0.8))/(1+tp_r)^3+H309*(1-MIN(tp_g/tp_roe,0.8))/(1+tp_r)^4+I309*(1-MIN(tp_g/tp_roe,0.8))/(1+tp_r)^5+J309*(1-MIN(tp_g/tp_roe,0.8))/(1+tp_r)^6+J309*(1-MIN(tp_g/tp_roe,0.8))*(1+tp_g)/(tp_r-tp_g)/(1+tp_r)^6)+tp_wB*MAX(0,E358*(1-MIN(tp_g/tp_roe,0.8))/(1+tp_r)^1+F358*(1-MIN(tp_g/tp_roe,0.8))/(1+tp_r)^2+G358*(1-MIN(tp_g/tp_roe,0.8))/(1+tp_r)^3+H358*(1-MIN(tp_g/tp_roe,0.8))/(1+tp_r)^4+I358*(1-MIN(tp_g/tp_roe,0.8))/(1+tp_r)^5+J358*(1-MIN(tp_g/tp_roe,0.8))/(1+tp_r)^6+J358*(1-MIN(tp_g/tp_roe,0.8))*(1+tp_g)/(tp_r-tp_g)/(1+tp_r)^6)+tp_wC*MAX(0,E407*(1-MIN(tp_g/tp_roe,0.8))/(1+tp_r)^1+F407*(1-MIN(tp_g/tp_roe,0.8))/(1+tp_r)^2+G407*(1-MIN(tp_g/tp_roe,0.8))/(1+tp_r)^3+H407*(1-MIN(tp_g/tp_roe,0.8))/(1+tp_r)^4+I407*(1-MIN(tp_g/tp_roe,0.8))/(1+tp_r)^5+J407*(1-MIN(tp_g/tp_roe,0.8))/(1+tp_r)^6+J407*(1-MIN(tp_g/tp_roe,0.8))*(1+tp_g)/(tp_r-tp_g)/(1+tp_r)^6))*(1+tp_r) -> 356.72446 | H6: =Val!$B$33*(tp_wA*(2/12*E309+10/12*F309)+tp_wB*(2/12*E358+10/12*F358)+tp_wC*(2/12*E407+10/12*F407))*rm_factor -> 759.20347 | I6: =tp_w_dcf*G6+(1-tp_w_dcf)*H6 -> 557.96397 | J6: =I6/I$4-1 -> 0.10741231
A7: LEAP 每顆內容彈性 0.3 | B7: el | C7: 封裝面積帶動較少 | D7: =E505 -> 28.223997 | E7: =F505 -> 24.446253 | F7: =E7/E$4-1 -> -0.046486096 | G7: =(tp_wA*MAX(0,E456*(1-MIN(tp_g/tp_roe,0.8))/(1+tp_r)^1+F456*(1-MIN(tp_g/tp_roe,0.8))/(1+tp_r)^2+G456*(1-MIN(tp_g/tp_roe,0.8))/(1+tp_r)^3+H456*(1-MIN(tp_g/tp_roe,0.8))/(1+tp_r)^4+I456*(1-MIN(tp_g/tp_roe,0.8))/(1+tp_r)^5+J456*(1-MIN(tp_g/tp_roe,0.8))/(1+tp_r)^6+J456*(1-MIN(tp_g/tp_roe,0.8))*(1+tp_g)/(tp_r-tp_g)/(1+tp_r)^6)+tp_wB*MAX(0,E505*(1-MIN(tp_g/tp_roe,0.8))/(1+tp_r)^1+F505*(1-MIN(tp_g/tp_roe,0.8))/(1+tp_r)^2+G505*(1-MIN(tp_g/tp_roe,0.8))/(1+tp_r)^3+H505*(1-MIN(tp_g/tp_roe,0.8))/(1+tp_r)^4+I505*(1-MIN(tp_g/tp_roe,0.8))/(1+tp_r)^5+J505*(1-MIN(tp_g/tp_roe,0.8))/(1+tp_r)^6+J505*(1-MIN(tp_g/tp_roe,0.8))*(1+tp_g)/(tp_r-tp_g)/(1+tp_r)^6)+tp_wC*MAX(0,E554*(1-MIN(tp_g/tp_roe,0.8))/(1+tp_r)^1+F554*(1-MIN(tp_g/tp_roe,0.8))/(1+tp_r)^2+G554*(1-MIN(tp_g/tp_roe,0.8))/(1+tp_r)^3+H554*(1-MIN(tp_g/tp_roe,0.8))/(1+tp_r)^4+I554*(1-MIN(tp_g/tp_roe,0.8))/(1+tp_r)^5+J554*(1-MIN(tp_g/tp_roe,0.8))/(1+tp_r)^6+J554*(1-MIN(tp_g/tp_roe,0.8))*(1+tp_g)/(tp_r-tp_g)/(1+tp_r)^6))*(1+tp_r) -> 329.76448 | H7: =Val!$B$33*(tp_wA*(2/12*E456+10/12*F456)+tp_wB*(2/12*E505+10/12*F505)+tp_wC*(2/12*E554+10/12*F554))*rm_factor -> 642.31926 | I7: =tp_w_dcf*G7+(1-tp_w_dcf)*H7 -> 486.04187 | J7: =I7/I$4-1 -> -0.035334209
A8: LEAP 每顆內容彈性 1.0 | B8: el | C8: 與面積等比例 | D8: =E652 -> 31.401996 | E8: =F652 -> 29.019524 | F8: =E8/E$4-1 -> 0.13189204 | G8: =(tp_wA*MAX(0,E603*(1-MIN(tp_g/tp_roe,0.8))/(1+tp_r)^1+F603*(1-MIN(tp_g/tp_roe,0.8))/(1+tp_r)^2+G603*(1-MIN(tp_g/tp_roe,0.8))/(1+tp_r)^3+H603*(1-MIN(tp_g/tp_roe,0.8))/(1+tp_r)^4+I603*(1-MIN(tp_g/tp_roe,0.8))/(1+tp_r)^5+J603*(1-MIN(tp_g/tp_roe,0.8))/(1+tp_r)^6+J603*(1-MIN(tp_g/tp_roe,0.8))*(1+tp_g)/(tp_r-tp_g)/(1+tp_r)^6)+tp_wB*MAX(0,E652*(1-MIN(tp_g/tp_roe,0.8))/(1+tp_r)^1+F652*(1-MIN(tp_g/tp_roe,0.8))/(1+tp_r)^2+G652*(1-MIN(tp_g/tp_roe,0.8))/(1+tp_r)^3+H652*(1-MIN(tp_g/tp_roe,0.8))/(1+tp_r)^4+I652*(1-MIN(tp_g/tp_roe,0.8))/(1+tp_r)^5+J652*(1-MIN(tp_g/tp_roe,0.8))/(1+tp_r)^6+J652*(1-MIN(tp_g/tp_roe,0.8))*(1+tp_g)/(tp_r-tp_g)/(1+tp_r)^6)+tp_wC*MAX(0,E701*(1-MIN(tp_g/tp_roe,0.8))/(1+tp_r)^1+F701*(1-MIN(tp_g/tp_roe,0.8))/(1+tp_r)^2+G701*(1-MIN(tp_g/tp_roe,0.8))/(1+tp_r)^3+H701*(1-MIN(tp_g/tp_roe,0.8))/(1+tp_r)^4+I701*(1-MIN(tp_g/tp_roe,0.8))/(1+tp_r)^5+J701*(1-MIN(tp_g/tp_roe,0.8))/(1+tp_r)^6+J701*(1-MIN(tp_g/tp_roe,0.8))*(1+tp_g)/(tp_r-tp_g)/(1+tp_r)^6))*(1+tp_r) -> 355.7263 | H8: =Val!$B$33*(tp_wA*(2/12*E603+10/12*F603)+tp_wB*(2/12*E652+10/12*F652)+tp_wC*(2/12*E701+10/12*F701))*rm_factor -> 752.55663 | I8: =tp_w_dcf*G8+(1-tp_w_dcf)*H8 -> 554.14147 | J8: =I8/I$4-1 -> 0.099825654
A9: 全流程滲透成長 10% | B9: fp_g | C9: 基準 30% | D9: =E799 -> 29.076998 | E9: =F799 -> 25.157537 | F9: =E9/E$4-1 -> -0.018742821 | G9: =(tp_wA*MAX(0,E750*(1-MIN(tp_g/tp_roe,0.8))/(1+tp_r)^1+F750*(1-MIN(tp_g/tp_roe,0.8))/(1+tp_r)^2+G750*(1-MIN(tp_g/tp_roe,0.8))/(1+tp_r)^3+H750*(1-MIN(tp_g/tp_roe,0.8))/(1+tp_r)^4+I750*(1-MIN(tp_g/tp_roe,0.8))/(1+tp_r)^5+J750*(1-MIN(tp_g/tp_roe,0.8))/(1+tp_r)^6+J750*(1-MIN(tp_g/tp_roe,0.8))*(1+tp_g)/(tp_r-tp_g)/(1+tp_r)^6)+tp_wB*MAX(0,E799*(1-MIN(tp_g/tp_roe,0.8))/(1+tp_r)^1+F799*(1-MIN(tp_g/tp_roe,0.8))/(1+tp_r)^2+G799*(1-MIN(tp_g/tp_roe,0.8))/(1+tp_r)^3+H799*(1-MIN(tp_g/tp_roe,0.8))/(1+tp_r)^4+I799*(1-MIN(tp_g/tp_roe,0.8))/(1+tp_r)^5+J799*(1-MIN(tp_g/tp_roe,0.8))/(1+tp_r)^6+J799*(1-MIN(tp_g/tp_roe,0.8))*(1+tp_g)/(tp_r-tp_g)/(1+tp_r)^6)+tp_wC*MAX(0,E848*(1-MIN(tp_g/tp_roe,0.8))/(1+tp_r)^1+F848*(1-MIN(tp_g/tp_roe,0.8))/(1+tp_r)^2+G848*(1-MIN(tp_g/tp_roe,0.8))/(1+tp_r)^3+H848*(1-MIN(tp_g/tp_roe,0.8))/(1+tp_r)^4+I848*(1-MIN(tp_g/tp_roe,0.8))/(1+tp_r)^5+J848*(1-MIN(tp_g/tp_roe,0.8))/(1+tp_r)^6+J848*(1-MIN(tp_g/tp_roe,0.8))*(1+tp_g)/(tp_r-tp_g)/(1+tp_r)^6))*(1+tp_r) -> 328.72162 | H9: =Val!$B$33*(tp_wA*(2/12*E750+10/12*F750)+tp_wB*(2/12*E799+10/12*F799)+tp_wC*(2/12*E848+10/12*F848))*rm_factor -> 660.71596 | I9: =tp_w_dcf*G9+(1-tp_w_dcf)*H9 -> 494.71879 | J9: =I9/I$4-1 -> -0.01811279
A10: 全流程滲透成長 50% | B10: fp_g | D10: =E946 -> 29.076998 | E10: =F946 -> 26.118597 | F10: =E10/E$4-1 -> 0.018742821 | G10: =(tp_wA*MAX(0,E897*(1-MIN(tp_g/tp_roe,0.8))/(1+tp_r)^1+F897*(1-MIN(tp_g/tp_roe,0.8))/(1+tp_r)^2+G897*(1-MIN(tp_g/tp_roe,0.8))/(1+tp_r)^3+H897*(1-MIN(tp_g/tp_roe,0.8))/(1+tp_r)^4+I897*(1-MIN(tp_g/tp_roe,0.8))/(1+tp_r)^5+J897*(1-MIN(tp_g/tp_roe,0.8))/(1+tp_r)^6+J897*(1-MIN(tp_g/tp_roe,0.8))*(1+tp_g)/(tp_r-tp_g)/(1+tp_r)^6)+tp_wB*MAX(0,E946*(1-MIN(tp_g/tp_roe,0.8))/(1+tp_r)^1+F946*(1-MIN(tp_g/tp_roe,0.8))/(1+tp_r)^2+G946*(1-MIN(tp_g/tp_roe,0.8))/(1+tp_r)^3+H946*(1-MIN(tp_g/tp_roe,0.8))/(1+tp_r)^4+I946*(1-MIN(tp_g/tp_roe,0.8))/(1+tp_r)^5+J946*(1-MIN(tp_g/tp_roe,0.8))/(1+tp_r)^6+J946*(1-MIN(tp_g/tp_roe,0.8))*(1+tp_g)/(tp_r-tp_g)/(1+tp_r)^6)+tp_wC*MAX(0,E995*(1-MIN(tp_g/tp_roe,0.8))/(1+tp_r)^1+F995*(1-MIN(tp_g/tp_roe,0.8))/(1+tp_r)^2+G995*(1-MIN(tp_g/tp_roe,0.8))/(1+tp_r)^3+H995*(1-MIN(tp_g/tp_roe,0.8))/(1+tp_r)^4+I995*(1-MIN(tp_g/tp_roe,0.8))/(1+tp_r)^5+J995*(1-MIN(tp_g/tp_roe,0.8))/(1+tp_r)^6+J995*(1-MIN(tp_g/tp_roe,0.8))*(1+tp_g)/(tp_r-tp_g)/(1+tp_r)^6))*(1+tp_r) -> 345.96739 | H10: =Val!$B$33*(tp_wA*(2/12*E897+10/12*F897)+tp_wB*(2/12*E946+10/12*F946)+tp_wC*(2/12*E995+10/12*F995))*rm_factor -> 681.58423 | I10: =tp_w_dcf*G10+(1-tp_w_dcf)*H10 -> 513.77581 | J10: =I10/I$4-1 -> 0.019710395
A11: CPO 2027 US$0.3B | B11: cpo27 | C11: 基準 0.5（公司逾 0.5） | D11: =E1093 -> 28.954155 | E11: =F1093 -> 25.351961 | F11: =E11/E$4-1 -> -0.011159437 | G11: =(tp_wA*MAX(0,E1044*(1-MIN(tp_g/tp_roe,0.8))/(1+tp_r)^1+F1044*(1-MIN(tp_g/tp_roe,0.8))/(1+tp_r)^2+G1044*(1-MIN(tp_g/tp_roe,0.8))/(1+tp_r)^3+H1044*(1-MIN(tp_g/tp_roe,0.8))/(1+tp_r)^4+I1044*(1-MIN(tp_g/tp_roe,0.8))/(1+tp_r)^5+J1044*(1-MIN(tp_g/tp_roe,0.8))/(1+tp_r)^6+J1044*(1-MIN(tp_g/tp_roe,0.8))*(1+tp_g)/(tp_r-tp_g)/(1+tp_r)^6)+tp_wB*MAX(0,E1093*(1-MIN(tp_g/tp_roe,0.8))/(1+tp_r)^1+F1093*(1-MIN(tp_g/tp_roe,0.8))/(1+tp_r)^2+G1093*(1-MIN(tp_g/tp_roe,0.8))/(1+tp_r)^3+H1093*(1-MIN(tp_g/tp_roe,0.8))/(1+tp_r)^4+I1093*(1-MIN(tp_g/tp_roe,0.8))/(1+tp_r)^5+J1093*(1-MIN(tp_g/tp_roe,0.8))/(1+tp_r)^6+J1093*(1-MIN(tp_g/tp_roe,0.8))*(1+tp_g)/(tp_r-tp_g)/(1+tp_r)^6)+tp_wC*MAX(0,E1142*(1-MIN(tp_g/tp_roe,0.8))/(1+tp_r)^1+F1142*(1-MIN(tp_g/tp_roe,0.8))/(1+tp_r)^2+G1142*(1-MIN(tp_g/tp_roe,0.8))/(1+tp_r)^3+H1142*(1-MIN(tp_g/tp_roe,0.8))/(1+tp_r)^4+I1142*(1-MIN(tp_g/tp_roe,0.8))/(1+tp_r)^5+J1142*(1-MIN(tp_g/tp_roe,0.8))/(1+tp_r)^6+J1142*(1-MIN(tp_g/tp_roe,0.8))*(1+tp_g)/(tp_r-tp_g)/(1+tp_r)^6))*(1+tp_r) -> 331.15807 | H11: =Val!$B$33*(tp_wA*(2/12*E1044+10/12*F1044)+tp_wB*(2/12*E1093+10/12*F1093)+tp_wC*(2/12*E1142+10/12*F1142))*rm_factor -> 661.34695 | I11: =tp_w_dcf*G11+(1-tp_w_dcf)*H11 -> 496.25251 | J11: =I11/I$4-1 -> -0.015068771
A12: CPO 2027 US$0.8B | B12: cpo27 | D12: =E1240 -> 29.261263 | E12: =F1240 -> 26.067257 | F12: =E12/E$4-1 -> 0.016740351 | G12: =(tp_wA*MAX(0,E1191*(1-MIN(tp_g/tp_roe,0.8))/(1+tp_r)^1+F1191*(1-MIN(tp_g/tp_roe,0.8))/(1+tp_r)^2+G1191*(1-MIN(tp_g/tp_roe,0.8))/(1+tp_r)^3+H1191*(1-MIN(tp_g/tp_roe,0.8))/(1+tp_r)^4+I1191*(1-MIN(tp_g/tp_roe,0.8))/(1+tp_r)^5+J1191*(1-MIN(tp_g/tp_roe,0.8))/(1+tp_r)^6+J1191*(1-MIN(tp_g/tp_roe,0.8))*(1+tp_g)/(tp_r-tp_g)/(1+tp_r)^6)+tp_wB*MAX(0,E1240*(1-MIN(tp_g/tp_roe,0.8))/(1+tp_r)^1+F1240*(1-MIN(tp_g/tp_roe,0.8))/(1+tp_r)^2+G1240*(1-MIN(tp_g/tp_roe,0.8))/(1+tp_r)^3+H1240*(1-MIN(tp_g/tp_roe,0.8))/(1+tp_r)^4+I1240*(1-MIN(tp_g/tp_roe,0.8))/(1+tp_r)^5+J1240*(1-MIN(tp_g/tp_roe,0.8))/(1+tp_r)^6+J1240*(1-MIN(tp_g/tp_roe,0.8))*(1+tp_g)/(tp_r-tp_g)/(1+tp_r)^6)+tp_wC*MAX(0,E1289*(1-MIN(tp_g/tp_roe,0.8))/(1+tp_r)^1+F1289*(1-MIN(tp_g/tp_roe,0.8))/(1+tp_r)^2+G1289*(1-MIN(tp_g/tp_roe,0.8))/(1+tp_r)^3+H1289*(1-MIN(tp_g/tp_roe,0.8))/(1+tp_r)^4+I1289*(1-MIN(tp_g/tp_roe,0.8))/(1+tp_r)^5+J1289*(1-MIN(tp_g/tp_roe,0.8))/(1+tp_r)^6+J1289*(1-MIN(tp_g/tp_roe,0.8))*(1+tp_g)/(tp_r-tp_g)/(1+tp_r)^6))*(1+tp_r) -> 344.65137 | H12: =Val!$B$33*(tp_wA*(2/12*E1191+10/12*F1191)+tp_wB*(2/12*E1240+10/12*F1240)+tp_wC*(2/12*E1289+10/12*F1289))*rm_factor -> 685.85691 | I12: =tp_w_dcf*G12+(1-tp_w_dcf)*H12 -> 515.25414 | J12: =I12/I$4-1 -> 0.022644497
A13: 主流封測 FY2027 +5% | B13: g_ms27 | C13: 基準 +15%（公司：與 2026 相近，逾 20%） | D13: =E1387 -> 25.467862 | E13: =F1387 -> 21.785888 | F13: =E13/E$4-1 -> -0.15025233 | G13: =(tp_wA*MAX(0,E1338*(1-MIN(tp_g/tp_roe,0.8))/(1+tp_r)^1+F1338*(1-MIN(tp_g/tp_roe,0.8))/(1+tp_r)^2+G1338*(1-MIN(tp_g/tp_roe,0.8))/(1+tp_r)^3+H1338*(1-MIN(tp_g/tp_roe,0.8))/(1+tp_r)^4+I1338*(1-MIN(tp_g/tp_roe,0.8))/(1+tp_r)^5+J1338*(1-MIN(tp_g/tp_roe,0.8))/(1+tp_r)^6+J1338*(1-MIN(tp_g/tp_roe,0.8))*(1+tp_g)/(tp_r-tp_g)/(1+tp_r)^6)+tp_wB*MAX(0,E1387*(1-MIN(tp_g/tp_roe,0.8))/(1+tp_r)^1+F1387*(1-MIN(tp_g/tp_roe,0.8))/(1+tp_r)^2+G1387*(1-MIN(tp_g/tp_roe,0.8))/(1+tp_r)^3+H1387*(1-MIN(tp_g/tp_roe,0.8))/(1+tp_r)^4+I1387*(1-MIN(tp_g/tp_roe,0.8))/(1+tp_r)^5+J1387*(1-MIN(tp_g/tp_roe,0.8))/(1+tp_r)^6+J1387*(1-MIN(tp_g/tp_roe,0.8))*(1+tp_g)/(tp_r-tp_g)/(1+tp_r)^6)+tp_wC*MAX(0,E1436*(1-MIN(tp_g/tp_roe,0.8))/(1+tp_r)^1+F1436*(1-MIN(tp_g/tp_roe,0.8))/(1+tp_r)^2+G1436*(1-MIN(tp_g/tp_roe,0.8))/(1+tp_r)^3+H1436*(1-MIN(tp_g/tp_roe,0.8))/(1+tp_r)^4+I1436*(1-MIN(tp_g/tp_roe,0.8))/(1+tp_r)^5+J1436*(1-MIN(tp_g/tp_roe,0.8))/(1+tp_r)^6+J1436*(1-MIN(tp_g/tp_roe,0.8))*(1+tp_g)/(tp_r-tp_g)/(1+tp_r)^6))*(1+tp_r) -> 318.71198 | H13: =Val!$B$33*(tp_wA*(2/12*E1338+10/12*F1338)+tp_wB*(2/12*E1387+10/12*F1387)+tp_wC*(2/12*E1436+10/12*F1436))*rm_factor -> 577.00723 | I13: =tp_w_dcf*G13+(1-tp_w_dcf)*H13 -> 447.85961 | J13: =I13/I$4-1 -> -0.111116
A14: 主流封測 FY2027 +22% | B14: g_ms27 | D14: =E1534 -> 31.603393 | E14: =F1534 -> 28.334718 | F14: =E14/E$4-1 -> 0.10518153 | G14: =(tp_wA*MAX(0,E1485*(1-MIN(tp_g/tp_roe,0.8))/(1+tp_r)^1+F1485*(1-MIN(tp_g/tp_roe,0.8))/(1+tp_r)^2+G1485*(1-MIN(tp_g/tp_roe,0.8))/(1+tp_r)^3+H1485*(1-MIN(tp_g/tp_roe,0.8))/(1+tp_r)^4+I1485*(1-MIN(tp_g/tp_roe,0.8))/(1+tp_r)^5+J1485*(1-MIN(tp_g/tp_roe,0.8))/(1+tp_r)^6+J1485*(1-MIN(tp_g/tp_roe,0.8))*(1+tp_g)/(tp_r-tp_g)/(1+tp_r)^6)+tp_wB*MAX(0,E1534*(1-MIN(tp_g/tp_roe,0.8))/(1+tp_r)^1+F1534*(1-MIN(tp_g/tp_roe,0.8))/(1+tp_r)^2+G1534*(1-MIN(tp_g/tp_roe,0.8))/(1+tp_r)^3+H1534*(1-MIN(tp_g/tp_roe,0.8))/(1+tp_r)^4+I1534*(1-MIN(tp_g/tp_roe,0.8))/(1+tp_r)^5+J1534*(1-MIN(tp_g/tp_roe,0.8))/(1+tp_r)^6+J1534*(1-MIN(tp_g/tp_roe,0.8))*(1+tp_g)/(tp_r-tp_g)/(1+tp_r)^6)+tp_wC*MAX(0,E1583*(1-MIN(tp_g/tp_roe,0.8))/(1+tp_r)^1+F1583*(1-MIN(tp_g/tp_roe,0.8))/(1+tp_r)^2+G1583*(1-MIN(tp_g/tp_roe,0.8))/(1+tp_r)^3+H1583*(1-MIN(tp_g/tp_roe,0.8))/(1+tp_r)^4+I1583*(1-MIN(tp_g/tp_roe,0.8))/(1+tp_r)^5+J1583*(1-MIN(tp_g/tp_roe,0.8))/(1+tp_r)^6+J1583*(1-MIN(tp_g/tp_roe,0.8))*(1+tp_g)/(tp_r-tp_g)/(1+tp_r)^6))*(1+tp_r) -> 349.01812 | H14: =Val!$B$33*(tp_wA*(2/12*E1485+10/12*F1485)+tp_wB*(2/12*E1534+10/12*F1534)+tp_wC*(2/12*E1583+10/12*F1583))*rm_factor -> 737.05161 | I14: =tp_w_dcf*G14+(1-tp_w_dcf)*H14 -> 543.03487 | J14: =I14/I$4-1 -> 0.077781957
A15: 主流封測 FY2028–29 +2% | B15: g_msL | C15: 基準 +7% | D15: =E1681 -> 29.076998 | E15: =F1681 -> 23.552447 | F15: =E15/E$4-1 -> -0.081348574 | G15: =(tp_wA*MAX(0,E1632*(1-MIN(tp_g/tp_roe,0.8))/(1+tp_r)^1+F1632*(1-MIN(tp_g/tp_roe,0.8))/(1+tp_r)^2+G1632*(1-MIN(tp_g/tp_roe,0.8))/(1+tp_r)^3+H1632*(1-MIN(tp_g/tp_roe,0.8))/(1+tp_r)^4+I1632*(1-MIN(tp_g/tp_roe,0.8))/(1+tp_r)^5+J1632*(1-MIN(tp_g/tp_roe,0.8))/(1+tp_r)^6+J1632*(1-MIN(tp_g/tp_roe,0.8))*(1+tp_g)/(tp_r-tp_g)/(1+tp_r)^6)+tp_wB*MAX(0,E1681*(1-MIN(tp_g/tp_roe,0.8))/(1+tp_r)^1+F1681*(1-MIN(tp_g/tp_roe,0.8))/(1+tp_r)^2+G1681*(1-MIN(tp_g/tp_roe,0.8))/(1+tp_r)^3+H1681*(1-MIN(tp_g/tp_roe,0.8))/(1+tp_r)^4+I1681*(1-MIN(tp_g/tp_roe,0.8))/(1+tp_r)^5+J1681*(1-MIN(tp_g/tp_roe,0.8))/(1+tp_r)^6+J1681*(1-MIN(tp_g/tp_roe,0.8))*(1+tp_g)/(tp_r-tp_g)/(1+tp_r)^6)+tp_wC*MAX(0,E1730*(1-MIN(tp_g/tp_roe,0.8))/(1+tp_r)^1+F1730*(1-MIN(tp_g/tp_roe,0.8))/(1+tp_r)^2+G1730*(1-MIN(tp_g/tp_roe,0.8))/(1+tp_r)^3+H1730*(1-MIN(tp_g/tp_roe,0.8))/(1+tp_r)^4+I1730*(1-MIN(tp_g/tp_roe,0.8))/(1+tp_r)^5+J1730*(1-MIN(tp_g/tp_roe,0.8))/(1+tp_r)^6+J1730*(1-MIN(tp_g/tp_roe,0.8))*(1+tp_g)/(tp_r-tp_g)/(1+tp_r)^6))*(1+tp_r) -> 315.45315 | H15: =Val!$B$33*(tp_wA*(2/12*E1632+10/12*F1632)+tp_wB*(2/12*E1681+10/12*F1681)+tp_wC*(2/12*E1730+10/12*F1730))*rm_factor -> 628.23214 | I15: =tp_w_dcf*G15+(1-tp_w_dcf)*H15 -> 471.84264 | J15: =I15/I$4-1 -> -0.063515951
A16: 主流封測 FY2028–29 +12% | B16: g_msL | D16: =E1828 -> 29.076998 | E16: =F1828 -> 27.723687 | F16: =E16/E$4-1 -> 0.081348574 | G16: =(tp_wA*MAX(0,E1779*(1-MIN(tp_g/tp_roe,0.8))/(1+tp_r)^1+F1779*(1-MIN(tp_g/tp_roe,0.8))/(1+tp_r)^2+G1779*(1-MIN(tp_g/tp_roe,0.8))/(1+tp_r)^3+H1779*(1-MIN(tp_g/tp_roe,0.8))/(1+tp_r)^4+I1779*(1-MIN(tp_g/tp_roe,0.8))/(1+tp_r)^5+J1779*(1-MIN(tp_g/tp_roe,0.8))/(1+tp_r)^6+J1779*(1-MIN(tp_g/tp_roe,0.8))*(1+tp_g)/(tp_r-tp_g)/(1+tp_r)^6)+tp_wB*MAX(0,E1828*(1-MIN(tp_g/tp_roe,0.8))/(1+tp_r)^1+F1828*(1-MIN(tp_g/tp_roe,0.8))/(1+tp_r)^2+G1828*(1-MIN(tp_g/tp_roe,0.8))/(1+tp_r)^3+H1828*(1-MIN(tp_g/tp_roe,0.8))/(1+tp_r)^4+I1828*(1-MIN(tp_g/tp_roe,0.8))/(1+tp_r)^5+J1828*(1-MIN(tp_g/tp_roe,0.8))/(1+tp_r)^6+J1828*(1-MIN(tp_g/tp_roe,0.8))*(1+tp_g)/(tp_r-tp_g)/(1+tp_r)^6)+tp_wC*MAX(0,E1877*(1-MIN(tp_g/tp_roe,0.8))/(1+tp_r)^1+F1877*(1-MIN(tp_g/tp_roe,0.8))/(1+tp_r)^2+G1877*(1-MIN(tp_g/tp_roe,0.8))/(1+tp_r)^3+H1877*(1-MIN(tp_g/tp_roe,0.8))/(1+tp_r)^4+I1877*(1-MIN(tp_g/tp_roe,0.8))/(1+tp_r)^5+J1877*(1-MIN(tp_g/tp_roe,0.8))/(1+tp_r)^6+J1877*(1-MIN(tp_g/tp_roe,0.8))*(1+tp_g)/(tp_r-tp_g)/(1+tp_r)^6))*(1+tp_r) -> 359.19432 | H16: =Val!$B$33*(tp_wA*(2/12*E1779+10/12*F1779)+tp_wB*(2/12*E1828+10/12*F1828)+tp_wC*(2/12*E1877+10/12*F1877))*rm_factor -> 714.06806 | I16: =tp_w_dcf*G16+(1-tp_w_dcf)*H16 -> 536.63119 | J16: =I16/I$4-1 -> 0.065072334
A17: EMS FY2027 0% | B17: g_ems27 | C17: 基準 +10% | D17: =E1975 -> 28.903993 | E17: =F1975 -> 25.450756 | F17: =E17/E$4-1 -> -0.0073059537 | G17: =(tp_wA*MAX(0,E1926*(1-MIN(tp_g/tp_roe,0.8))/(1+tp_r)^1+F1926*(1-MIN(tp_g/tp_roe,0.8))/(1+tp_r)^2+G1926*(1-MIN(tp_g/tp_roe,0.8))/(1+tp_r)^3+H1926*(1-MIN(tp_g/tp_roe,0.8))/(1+tp_r)^4+I1926*(1-MIN(tp_g/tp_roe,0.8))/(1+tp_r)^5+J1926*(1-MIN(tp_g/tp_roe,0.8))/(1+tp_r)^6+J1926*(1-MIN(tp_g/tp_roe,0.8))*(1+tp_g)/(tp_r-tp_g)/(1+tp_r)^6)+tp_wB*MAX(0,E1975*(1-MIN(tp_g/tp_roe,0.8))/(1+tp_r)^1+F1975*(1-MIN(tp_g/tp_roe,0.8))/(1+tp_r)^2+G1975*(1-MIN(tp_g/tp_roe,0.8))/(1+tp_r)^3+H1975*(1-MIN(tp_g/tp_roe,0.8))/(1+tp_r)^4+I1975*(1-MIN(tp_g/tp_roe,0.8))/(1+tp_r)^5+J1975*(1-MIN(tp_g/tp_roe,0.8))/(1+tp_r)^6+J1975*(1-MIN(tp_g/tp_roe,0.8))*(1+tp_g)/(tp_r-tp_g)/(1+tp_r)^6)+tp_wC*MAX(0,E2024*(1-MIN(tp_g/tp_roe,0.8))/(1+tp_r)^1+F2024*(1-MIN(tp_g/tp_roe,0.8))/(1+tp_r)^2+G2024*(1-MIN(tp_g/tp_roe,0.8))/(1+tp_r)^3+H2024*(1-MIN(tp_g/tp_roe,0.8))/(1+tp_r)^4+I2024*(1-MIN(tp_g/tp_roe,0.8))/(1+tp_r)^5+J2024*(1-MIN(tp_g/tp_roe,0.8))/(1+tp_r)^6+J2024*(1-MIN(tp_g/tp_roe,0.8))*(1+tp_g)/(tp_r-tp_g)/(1+tp_r)^6))*(1+tp_r) -> 329.79039 | H17: =Val!$B$33*(tp_wA*(2/12*E1926+10/12*F1926)+tp_wB*(2/12*E1975+10/12*F1975)+tp_wC*(2/12*E2024+10/12*F2024))*rm_factor -> 666.56553 | I17: =tp_w_dcf*G17+(1-tp_w_dcf)*H17 -> 498.17796 | J17: =I17/I$4-1 -> -0.011247246
A18: EMS FY2027 +15% | B18: g_ems27 | D18: =E2122 -> 29.1635 | E18: =F2122 -> 25.73172 | F18: =E18/E$4-1 -> 0.0036528732 | G18: =(tp_wA*MAX(0,E2073*(1-MIN(tp_g/tp_roe,0.8))/(1+tp_r)^1+F2073*(1-MIN(tp_g/tp_roe,0.8))/(1+tp_r)^2+G2073*(1-MIN(tp_g/tp_roe,0.8))/(1+tp_r)^3+H2073*(1-MIN(tp_g/tp_roe,0.8))/(1+tp_r)^4+I2073*(1-MIN(tp_g/tp_roe,0.8))/(1+tp_r)^5+J2073*(1-MIN(tp_g/tp_roe,0.8))/(1+tp_r)^6+J2073*(1-MIN(tp_g/tp_roe,0.8))*(1+tp_g)/(tp_r-tp_g)/(1+tp_r)^6)+tp_wB*MAX(0,E2122*(1-MIN(tp_g/tp_roe,0.8))/(1+tp_r)^1+F2122*(1-MIN(tp_g/tp_roe,0.8))/(1+tp_r)^2+G2122*(1-MIN(tp_g/tp_roe,0.8))/(1+tp_r)^3+H2122*(1-MIN(tp_g/tp_roe,0.8))/(1+tp_r)^4+I2122*(1-MIN(tp_g/tp_roe,0.8))/(1+tp_r)^5+J2122*(1-MIN(tp_g/tp_roe,0.8))/(1+tp_r)^6+J2122*(1-MIN(tp_g/tp_roe,0.8))*(1+tp_g)/(tp_r-tp_g)/(1+tp_r)^6)+tp_wC*MAX(0,E2171*(1-MIN(tp_g/tp_roe,0.8))/(1+tp_r)^1+F2171*(1-MIN(tp_g/tp_roe,0.8))/(1+tp_r)^2+G2171*(1-MIN(tp_g/tp_roe,0.8))/(1+tp_r)^3+H2171*(1-MIN(tp_g/tp_roe,0.8))/(1+tp_r)^4+I2171*(1-MIN(tp_g/tp_roe,0.8))/(1+tp_r)^5+J2171*(1-MIN(tp_g/tp_roe,0.8))/(1+tp_r)^6+J2171*(1-MIN(tp_g/tp_roe,0.8))*(1+tp_g)/(tp_r-tp_g)/(1+tp_r)^6))*(1+tp_r) -> 339.91522 | H18: =Val!$B$33*(tp_wA*(2/12*E2073+10/12*F2073)+tp_wB*(2/12*E2122+10/12*F2122)+tp_wC*(2/12*E2171+10/12*F2171))*rm_factor -> 673.44197 | I18: =tp_w_dcf*G18+(1-tp_w_dcf)*H18 -> 506.6786 | J18: =I18/I$4-1 -> 0.0056242885
A19: EMS FY2028–29 0% | B19: g_emsL | C19: 基準 +5% | D19: =E2269 -> 29.076998 | E19: =F2269 -> 25.528979 | F19: =E19/E$4-1 -> -0.004254924 | G19: =(tp_wA*MAX(0,E2220*(1-MIN(tp_g/tp_roe,0.8))/(1+tp_r)^1+F2220*(1-MIN(tp_g/tp_roe,0.8))/(1+tp_r)^2+G2220*(1-MIN(tp_g/tp_roe,0.8))/(1+tp_r)^3+H2220*(1-MIN(tp_g/tp_roe,0.8))/(1+tp_r)^4+I2220*(1-MIN(tp_g/tp_roe,0.8))/(1+tp_r)^5+J2220*(1-MIN(tp_g/tp_roe,0.8))/(1+tp_r)^6+J2220*(1-MIN(tp_g/tp_roe,0.8))*(1+tp_g)/(tp_r-tp_g)/(1+tp_r)^6)+tp_wB*MAX(0,E2269*(1-MIN(tp_g/tp_roe,0.8))/(1+tp_r)^1+F2269*(1-MIN(tp_g/tp_roe,0.8))/(1+tp_r)^2+G2269*(1-MIN(tp_g/tp_roe,0.8))/(1+tp_r)^3+H2269*(1-MIN(tp_g/tp_roe,0.8))/(1+tp_r)^4+I2269*(1-MIN(tp_g/tp_roe,0.8))/(1+tp_r)^5+J2269*(1-MIN(tp_g/tp_roe,0.8))/(1+tp_r)^6+J2269*(1-MIN(tp_g/tp_roe,0.8))*(1+tp_g)/(tp_r-tp_g)/(1+tp_r)^6)+tp_wC*MAX(0,E2318*(1-MIN(tp_g/tp_roe,0.8))/(1+tp_r)^1+F2318*(1-MIN(tp_g/tp_roe,0.8))/(1+tp_r)^2+G2318*(1-MIN(tp_g/tp_roe,0.8))/(1+tp_r)^3+H2318*(1-MIN(tp_g/tp_roe,0.8))/(1+tp_r)^4+I2318*(1-MIN(tp_g/tp_roe,0.8))/(1+tp_r)^5+J2318*(1-MIN(tp_g/tp_roe,0.8))/(1+tp_r)^6+J2318*(1-MIN(tp_g/tp_roe,0.8))*(1+tp_g)/(tp_r-tp_g)/(1+tp_r)^6))*(1+tp_r) -> 325.68723 | H19: =Val!$B$33*(tp_wA*(2/12*E2220+10/12*F2220)+tp_wB*(2/12*E2269+10/12*F2269)+tp_wC*(2/12*E2318+10/12*F2318))*rm_factor -> 668.90327 | I19: =tp_w_dcf*G19+(1-tp_w_dcf)*H19 -> 497.29525 | J19: =I19/I$4-1 -> -0.012999202
A20: EMS FY2028–29 +8% | B20: g_emsL | D20: =E2416 -> 29.076998 | E20: =F2416 -> 25.70352 | F20: =E20/E$4-1 -> 0.0025529544 | G20: =(tp_wA*MAX(0,E2367*(1-MIN(tp_g/tp_roe,0.8))/(1+tp_r)^1+F2367*(1-MIN(tp_g/tp_roe,0.8))/(1+tp_r)^2+G2367*(1-MIN(tp_g/tp_roe,0.8))/(1+tp_r)^3+H2367*(1-MIN(tp_g/tp_roe,0.8))/(1+tp_r)^4+I2367*(1-MIN(tp_g/tp_roe,0.8))/(1+tp_r)^5+J2367*(1-MIN(tp_g/tp_roe,0.8))/(1+tp_r)^6+J2367*(1-MIN(tp_g/tp_roe,0.8))*(1+tp_g)/(tp_r-tp_g)/(1+tp_r)^6)+tp_wB*MAX(0,E2416*(1-MIN(tp_g/tp_roe,0.8))/(1+tp_r)^1+F2416*(1-MIN(tp_g/tp_roe,0.8))/(1+tp_r)^2+G2416*(1-MIN(tp_g/tp_roe,0.8))/(1+tp_r)^3+H2416*(1-MIN(tp_g/tp_roe,0.8))/(1+tp_r)^4+I2416*(1-MIN(tp_g/tp_roe,0.8))/(1+tp_r)^5+J2416*(1-MIN(tp_g/tp_roe,0.8))/(1+tp_r)^6+J2416*(1-MIN(tp_g/tp_roe,0.8))*(1+tp_g)/(tp_r-tp_g)/(1+tp_r)^6)+tp_wC*MAX(0,E2465*(1-MIN(tp_g/tp_roe,0.8))/(1+tp_r)^1+F2465*(1-MIN(tp_g/tp_roe,0.8))/(1+tp_r)^2+G2465*(1-MIN(tp_g/tp_roe,0.8))/(1+tp_r)^3+H2465*(1-MIN(tp_g/tp_roe,0.8))/(1+tp_r)^4+I2465*(1-MIN(tp_g/tp_roe,0.8))/(1+tp_r)^5+J2465*(1-MIN(tp_g/tp_roe,0.8))/(1+tp_r)^6+J2465*(1-MIN(tp_g/tp_roe,0.8))*(1+tp_g)/(tp_r-tp_g)/(1+tp_r)^6))*(1+tp_r) -> 343.45741 | H20: =Val!$B$33*(tp_wA*(2/12*E2367+10/12*F2367)+tp_wB*(2/12*E2416+10/12*F2416)+tp_wC*(2/12*E2465+10/12*F2465))*rm_factor -> 672.49819 | I20: =tp_w_dcf*G20+(1-tp_w_dcf)*H20 -> 507.9778 | J20: =I20/I$4-1 -> 0.0082028676
A21: EMS 毛利率 7.5% | B21: ems_gm | C21: 基準 8.5% | D21: =E2563 -> 28.426397 | E21: =F2563 -> 24.958334 | F21: =E21/E$4-1 -> -0.026512625 | G21: =(tp_wA*MAX(0,E2514*(1-MIN(tp_g/tp_roe,0.8))/(1+tp_r)^1+F2514*(1-MIN(tp_g/tp_roe,0.8))/(1+tp_r)^2+G2514*(1-MIN(tp_g/tp_roe,0.8))/(1+tp_r)^3+H2514*(1-MIN(tp_g/tp_roe,0.8))/(1+tp_r)^4+I2514*(1-MIN(tp_g/tp_roe,0.8))/(1+tp_r)^5+J2514*(1-MIN(tp_g/tp_roe,0.8))/(1+tp_r)^6+J2514*(1-MIN(tp_g/tp_roe,0.8))*(1+tp_g)/(tp_r-tp_g)/(1+tp_r)^6)+tp_wB*MAX(0,E2563*(1-MIN(tp_g/tp_roe,0.8))/(1+tp_r)^1+F2563*(1-MIN(tp_g/tp_roe,0.8))/(1+tp_r)^2+G2563*(1-MIN(tp_g/tp_roe,0.8))/(1+tp_r)^3+H2563*(1-MIN(tp_g/tp_roe,0.8))/(1+tp_r)^4+I2563*(1-MIN(tp_g/tp_roe,0.8))/(1+tp_r)^5+J2563*(1-MIN(tp_g/tp_roe,0.8))/(1+tp_r)^6+J2563*(1-MIN(tp_g/tp_roe,0.8))*(1+tp_g)/(tp_r-tp_g)/(1+tp_r)^6)+tp_wC*MAX(0,E2612*(1-MIN(tp_g/tp_roe,0.8))/(1+tp_r)^1+F2612*(1-MIN(tp_g/tp_roe,0.8))/(1+tp_r)^2+G2612*(1-MIN(tp_g/tp_roe,0.8))/(1+tp_r)^3+H2612*(1-MIN(tp_g/tp_roe,0.8))/(1+tp_r)^4+I2612*(1-MIN(tp_g/tp_roe,0.8))/(1+tp_r)^5+J2612*(1-MIN(tp_g/tp_roe,0.8))/(1+tp_r)^6+J2612*(1-MIN(tp_g/tp_roe,0.8))*(1+tp_g)/(tp_r-tp_g)/(1+tp_r)^6))*(1+tp_r) -> 335.03384 | H21: =Val!$B$33*(tp_wA*(2/12*E2514+10/12*F2514)+tp_wB*(2/12*E2563+10/12*F2563)+tp_wC*(2/12*E2612+10/12*F2612))*rm_factor -> 654.48613 | I21: =tp_w_dcf*G21+(1-tp_w_dcf)*H21 -> 494.75998 | J21: =I21/I$4-1 -> -0.018031036
