Workbook

Sheet README
A1: Meta（META）個股模型 v0.1.1（2026-10-30）— 命題模組＋官方營收分部 → 損益表（完整 10-Q、法說與 follow-up call 補資料缺口）
A3: 命題：Meta 的 AI 資本支出（2026 指引 1,350–1,450 億美元，含融資租賃本金）能否由廣告現金流支撐，且自用算力（GPU＋自研 MTIA）是否帶來足以回本的廣告變現提升。
A4: 核心問題：FY2028 AI 增量營業利益（讀法 2：自用 AI 影子效益＝自用在役 MW × Tokenomics 每 MW 持有成本）能否覆蓋 AI 資本支出的資金成本；收支關卡＝FY2026–FY2030 自由現金流扣股利合計。
A5: ="投資建議："&Val!B14&"（加權目標價 US$"&TEXT(Val!B8,"0.00")&"，上檔空間 "&TEXT(Val!B11,"+0.0%;-0.0%")&"；現價 "&TEXT(px,"0.00")&"，2026-10-28 收盤；每股為 Class C 股票股利前口徑）" -> 投資建議：買進（加權目標價 US$844.10，上檔空間 +37.8%；現價 612.49，2026-10-28 收盤；每股為 Class C 股票股利前口徑）
A6: ="重點觀察 1：目標價 "&TEXT(Val!B8,"0")&"＝DCF "&TEXT(Val!B6,"0")&"、分部加總 "&TEXT(Val!B7,"0")&" 各半；情境 A／B／C 為 "&TEXT(Val!B17,"0")&"／"&TEXT(Val!C17,"0")&"／"&TEXT(Val!D17,"0")&"；讀法 1 目標價 "&TEXT(Val!B21,"0")&"。市場共識目標價 "&TEXT(cons_tp,"0")&"。" -> 重點觀察 1：目標價 844＝DCF 793、分部加總 896 各半；情境 A／B／C 為 933／844／755；讀法 1 目標價 429。市場共識目標價 833。
A7: ="重點觀察 2：FY2028 自用 AI 影子效益（B）"&TEXT(Thesis!I113,"0.0")&"，對自用 AI 增量成本（營運＋新增 AI 折舊）"&TEXT(Thesis!I108,"0.0")&"；FY2028 Advertising A／B／C 為 "&TEXT(PL!I12,"0")&"／"&TEXT(PL!I59,"0")&"／"&TEXT(PL!I106,"0")&"，合併營業利益率（財報口徑，B）由 FY2025 "&TEXT(PL!D84,"0.0%")&" 變為 FY2028 "&TEXT(PL!I84,"0.0%")&"。" -> 重點觀察 2：FY2028 自用 AI 影子效益（B）107.9，對自用 AI 增量成本（營運＋新增 AI 折舊）70.9；FY2028 Advertising A／B／C 為 381／362／344，合併營業利益率（財報口徑，B）由 FY2025 41.4% 變為 FY2028 24.5%。
A8: ="重點觀察 3：收支關卡（FY2026–2030 自由現金流扣股利合計）A／B／C＝"&TEXT(CF!B6,"0.0")&"／"&TEXT(CF!C6,"0.0")&"／"&TEXT(CF!D6,"0.0")&"；B 情境 "&CF!C9&"。FY2027 資本支出（B）"&TEXT(CF!H54,"0")&"，自用 AI MW 由評價日 "&TEXT(mw_tot0,"#,##0")&" 增至 FY2028 年底 "&TEXT(Thesis!I81,"#,##0")&"。" -> 重點觀察 3：收支關卡（FY2026–2030 自由現金流扣股利合計）A／B／C＝-19.6／15.0／49.0；B 情境 需要舉債。FY2027 資本支出（B）206，自用 AI MW 由評價日 5,038 增至 FY2028 年底 14,678。
A10: 驅動 → 推導對照表（每頁輸入、推導量、因果方向）
A11: 頁 | B11: 輸入（In 頁鍵） | C11: 推導量 | D11: 因果方向
A12: Thesis | B12: capex_g、cx27_A／B／C、cx_na、selfb、a28、cip_0、cip_ai、Tokenomics IF_CapexIT／Facility／OpexGW／HoldEcon | C12: 自用 AI MW、AI 資本支出、新增 AI 折舊、自用 AI 增量營運成本、影子效益 | D12: 資本支出 → MW（C10）→ 折舊與營運成本 → FoA 營業利益；MW → 影子效益（讀法 2）
A13: Seg | B13: 近四季年增（Q 頁）、gl_impr、gl_price、pA／pC、gl_other、gl_rl、conv_n | C13: Advertising（曝光 × 價格）、Other revenue、FoA、RL、合併營收；非 AI 資本支出與折舊 | D13: 近四季年增 → 長期值；Advertising＝B 路徑 ×(1＋價格情境調整)
A14: PL | B14: m_foa（Q 頁）、inc_m、rl_loss26／27／32、rl_da_sh、tax、一次性項目 | C14: 分部 EBITDA、分部營業利益、合併營業利益、EPS（財報／排除一次性／評價口徑） | D14: 分部營收 → EBITDA − 折舊 → 營業利益 → 業外、稅 → EPS
A15: CF | B15: sbc_r、wc_k、ag_pay、dps、bb_t、min_cash、mcps、fwd_cash | C15: 自由現金流、股利、回購、新債、淨現金、收支關卡 | D15: 淨利＋折舊 − 協議付款 − 資本支出 → 自由現金流 → 股利 → 回購／舉債
A16: Val | B16: rf、beta、erp、kd_sp、g_tv、ronic_sp、同業倍數、ads_mode、rl_mode、tp_w*、w_dcf | C16: DCF、分部加總、目標價、上檔空間、投資建議 | D16: 無槓桿 FCF 折現＋分部 EBITDA × 倍數 → 情境加權 → 50／50
A17: Sens | B17: In 頁敏感度低／高 | C17: 加權目標價變動 | D17: 一次改一個輸入、整本重算
A19: 本版要點（v0.1.1）
A20: 架構同 v0.1（Alphabet v0.3.2 範本）：命題（自用 AI MW）＋官方分部 → 損益表 → 現金流 → DCF 50%＋分部加總 50%；情境 25／50／25；讀法 2 主值。v0.1.1 以完整 10-Q（106 頁，入庫）、法說與 follow-up call 逐字稿（不入庫）補資料缺口。
A21: 更正（完整 10-Q）：多州檢察長協議費用前三季合計 11.89（v0.1 只計 Q3 的 9.89）→ 其他法律應計類債 9.99 → 7.99。協議 12.7 原文只寫十年分年支付、未載各年金額 → 維持等額（H3）；前高後低（第一年約 4.04，由流動／非流動應計推論）只進 Sens。
A22: 小修：強制轉換特別股改用淨額 12.46（424B5 承銷折扣）；DCF 的遠期出售現金以 ke 自 FY2027 期中折現；分部加總補扣 FY2028–FY2029 特別股股利。
A23: 資料缺口：10-Q 未單獨揭露融資租賃負債（使用權資產 11.70）→ 基準 0、Sens 上限 11.70；未載伺服器耐用年限 → 維持 6 年；買回授權剩餘 25.03（2026 年未買回）。
A24: 法說與 follow-up call：2027 資本支出未量化（Q4 法說才給）、RL 2027 虧損約 15（已在模型）、未提 MTIA；自建為主、以第三方雲端補近期容量、自建／租用比例未揭露 → 只寫 Recon，不填數值（H2）。
A26: 工作表：README → In → Q → Thesis → Seg → PL → CF → Val → Recon → Sens → Sources。藍字＝輸入、黑字＝公式；黃底＝判斷題。建置：bash meta/make_v01.sh
A27: 數字標記：Verified（公司正式財報或申報文件）／Interested-party（公司指引、賣方、第三方網站）／Analogy／Assumed（給區間）／Derived（換算）。每股數字為 Class C 股票股利（2027-01 下旬，1:1）前的口徑。

Sheet In
A1: In — 輸入（藍字；基準欄 E 進主模型；D／F＝敏感度低／高，只用於 Sens 頁、不進目標價；情境 A／B／C 的驅動見本頁最後一節「情境驅動對照」）。金額 US$B；每股 US$（Class C 股票股利前口徑）；股數十億股；MW＝IT MW。標記：Verified／Interested-party／Analogy／Assumed／Derived（Analogy、Assumed 一律給低／高區間）
A2: 事實總帳：data/meta_facts_2026q3.json（facts_2026q3.py 兩讀核對，648 筆；v0.1.1 加完整 10-Q、424B5、follow-up call）；Tokenomics v21.7 快照（data/tokenomics_snapshot_v21.7.json）；共識 data/consensus_meta_20261030.json；同業 data/peers_ads_20261030.json（五家 2026-10-07 基準＋GOOGL）。評價日 2026-09-30，目標時點 2027-10-30。黃底＝判斷題（Andy 可改）
A3: 鍵 | B3: 項目 | C3: 單位 | D3: 敏感度低 | E3: 基準 | F3: 敏感度高 | G3: 標記 | H3: 來源 | I3: 說明
A4: A. 現價、股數與資產負債（評價日 2026-09-30）
A5: px | B5: 現價（2026-10-28 收盤；10-29 收盤只找到一個來源） | C5: US$ | E5: 612.49 | G5: Verified | H5: StockScan https://stockscan.io/stocks/META/price-history（10-28 −1.24%）；Digrin、TipRanks（10-27 620.19 − 7.70）相符（consensus_meta_20261030.json priceReference） | I5: 工作單 M8：10-29 收盤需兩個來源一致；2026-10-30 再查只有 ChartRow「as of close, Oct 29, 2026」624.55（+1.97%）一個來源（https://chartrow.com/quote/meta），故用 10-28。只影響上檔空間與評等
A6: px_val | B6: 評價日股價（2026-09-30 收盤；WACC 權益權重用） | C6: US$ | E6: 725.18 | G6: Verified | H6: TipRanks 歷史股價 https://www.tipranks.com/stocks/meta/historical-prices（2026-10-30 讀取：9/29 738.79、9/30 725.18）；StockScan 9/30 −1.84%（738.79 × 0.9816＝725.20，相符）
A7: sh_out | B7: 流通股數（2026-10-16，10-Q 封面 Class A＋B） | C7: 十億股 | E7: 2.556241 | G7: Verified | H7: 10-Q 封面兩類相加（2026-10-29；事實總帳 sh.out.20261016）
A8: sh_dil_q3 | B8: 2026Q3 稀釋加權股數 | C8: 十億股 | E8: 2.573 | G8: Verified | H8: Meta 2026Q3 財報新聞稿（8-K 附件 99.1）表格（2026-10-21；事實總帳 is.sh_d.2026q3）
A9: sh_basic_q3 | B9: 2026Q3 基本加權股數 | C9: 十億股 | E9: 2.552 | G9: Verified | H9: Meta 2026Q3 財報新聞稿（8-K 附件 99.1）表格（2026-10-21；事實總帳 is.sh_b.2026q3） | I9: 期末稀釋股數＝Q3 稀釋加權＋(流通股 − Q3 基本加權)
A10: cash_0 | B10: 現金＋有價證券（2026-09-30） | C10: US$B | E10: 82.449 | G10: Verified | H10: 新聞稿資產負債表：現金 11.222＋有價證券 71.227（事實總帳 bs.cash／bs.mktsec.20260930）
A11: cash_ye25 | B11: 現金＋有價證券（2025-12-31） | C11: US$B | E11: 81.592 | G11: Verified | H11: 新聞稿資產負債表 35.873＋45.719
A12: debt_0 | B12: 票據面額（2026-09-30） | C12: US$B | E12: 84 | G12: Verified | H12: Meta 10-Q 2026Q3 長期債務附註（2026-10-29；事實總帳 debt.face.20260930） | I12: 帳面 83.669＝流動 2.747＋非流動 80.922
A13: debt_ye25 | B13: 長期債務帳面（2025-12-31，非流動） | C13: US$B | E13: 58.744 | G13: Verified | H13: Meta 2025Q4 財報新聞稿（8-K 附件 99.1）資產負債表（2026-01-28；事實總帳 bs.ltd.20251231） | I13: 只作 CF 頁期初顯示；9M26 期末直接取 debt_0
A14: fin_lease | B14: 融資租賃負債（類債） | C14: US$B | E14: 0 | F14: 11.704 | G14: Assumed | H14: 完整 10-Q 未單獨揭露融資租賃負債（資產負債表無此科目；附註 8 其他流動 13.993／非流動 5.041 未拆）；融資租賃使用權資產 11.704（Meta 10-Q 2026Q3（完整 PDF 第 19 頁；mag/extract/docs/2026Q3/meta_2026Q3_10-Q.pdf）（2026-10-29；事實總帳 fl.rou.20260930）） | I14: 基準 0：Meta 融資租賃多為預付，本金支付已含在資本支出（公司口徑，收支關卡與 MAG 一致扣本金）；高＝使用權資產 11.704 當上限（只進 Sens）。仍為資料缺口（10-K 租賃附註）
A15: legal_oth | B15: 其他法律相關應計（類債）＝法律應計 19.881 − 協議費用前三季合計 11.89 | C15: US$B | D15: 0 | E15: 7.991 | G15: Derived | H15: Meta 10-Q 2026Q3（2026-10-29；事實總帳 legal.accrual.20260930）；協議費用 Meta 10-Q 2026Q3（完整 PDF 第 47 頁；mag/extract/docs/2026Q3/meta_2026Q3_10-Q.pdf）（2026-10-29；事實總帳 legal.agCharge.ytd9m2026） | I15: 比照 Alphabet 應計罰款（類債）；低＝0（不扣）。v0.1.1 更正：v0.1 只扣 Q3 的 9.89（得 9.991），完整 10-Q 載協議費用前三季合計 11.89（Q3 以前已認列約 2.00），協議應計已由 ag_y1／ag_rest 現金付款計入
A16: mcps | B16: 6.50% 強制轉換特別股募得現金淨額（2026-10-29 交割，評價日後；毛額 12.5 − 承銷折扣 0.0416） | C16: US$B | E16: 12.458375 | G16: Verified | H16: 424B5 封面推算（2026-10-27；事實總帳 eq.mcps.net）；Meta 424B5（Series A 存託股）封面（2026-10-27；事實總帳 eq.mcps.uwDisc） | I16: v0.1.1：改用淨額（v0.1 用毛額 12.5）；發行費用未揭露、不扣；超額配售（約 1.8）未知是否行使，不計
A17: conv_sh | B17: 強制轉換特別股 2029-08 轉換股數（上限） | C17: 十億股 | D17: 0.017025 | E17: 0.02 | F17: 0.02 | G17: Derived | H17: FWP：每股特別股（1,000 美元）轉 1.3620–1.6000 股 Class A；12.5B ÷ 1,000 × 1.6＝20.0M 股（上限） | I17: 取稀釋最大（保守）；轉換前股利照付
A18: pref_2H | B18: 強制轉換特別股股利 Q4 26E | C18: US$B | E18: 0 | G18: Assumed | H18: 6.50% × 12.5B＝0.8125／年；首次付息推定 2027-02，2029-08 轉換前最後一期（FY2029 約三季）
A19: pref_27 | B19: 強制轉換特別股股利 FY2027E | C19: US$B | E19: 0.8125 | G19: Assumed
A20: pref_28 | B20: 強制轉換特別股股利 FY2028E | C20: US$B | E20: 0.8125 | G20: Assumed
A21: pref_29 | B21: 強制轉換特別股股利 FY2029E | C21: US$B | E21: 0.609 | G21: Assumed
A22: fwd_on | B22: Class A 遠期出售於 FY2027 交割（1＝計入；0＝不計） | C22: x | D22: 0 | E22: 1 | G22: Assumed | H22: Meta FWP 定價條款（2026-10-26；事實總帳 eq.fwd.shares）：40M 股、初始遠期價 622.91875、2027-11-19 前由公司選擇交割 | I22: 交割前公司不收款；目標時點 2027-10-30 前推定已交割（判斷）
A23: fwd_sh | B23: 遠期出售股數 | C23: 十億股 | E23: 0.04 | G23: Verified | H23: Meta FWP 定價條款（2026-10-26；事實總帳 eq.fwd.shares）
A24: fwd_cash | B24: 遠期出售淨額（初始遠期價 622.91875 × 40M 股） | C24: US$B | E24: 24.9168 | G24: Derived | H24: Meta FWP 定價條款（2026-10-26；事實總帳 eq.fwd.shares） | I24: 超額配售 6M 股不計
A25: B. 折現率與目標價規則（同 Alphabet v0.3.2）
A26: rf | B26: 無風險利率（10 年美債，2026-10-27） | C26: % | E26: 0.0499 | G26: Verified | H26: 美國財政部每日殖利率曲線（10 Yr）2026-10-27 4.99%（Alphabet v0.3.1 In 頁 rf，2026-10-29 讀取） | I26: 本次重讀財政部網頁被擋（權限逾時），沿用同一讀值
A27: beta_cr | B27: 原始 β：ChartRow（期間未載） | C27: x | E27: 1.24 | G27: Interested-party | H27: https://chartrow.com/quote/meta（2026-10-30 讀取，as of close Oct 29, 2026）
A28: beta_cd | B28: 原始 β：CoinDataFlow「Beta (5Y Monthly)」 | C28: x | E28: 1.185 | G28: Interested-party | H28: https://coindataflow.com/en/stock/META（Updated 2026-10-30 00:37 UTC） | I28: StockAnalysis 統計頁讀取被擋（權限逾時）
A29: blume_a | B29: Blume 調整係數 | C29: x | E29: 0.67 | G29: Derived | H29: Blume（1971）；同 Alphabet
A30: beta | B30: β（Blume 調整後兩個來源的中位數） | C30: x | D30: 1.124 | E30: =MEDIAN(blume_a*beta_cr+1-blume_a,blume_a*beta_cd+1-blume_a) -> 1.142375 | F30: 1.1608 | G30: Derived | H30: 同 Alphabet 修正一 F4 | I30: 低／高＝兩個來源各自的調整值
A31: erp | B31: 股權風險溢酬 | C31: % | D31: 0.04 | E31: 0.05 | F31: 0.06 | G31: Assumed | H31: 同 Alphabet（MAG v0.2.2 val.erp）
A32: kd_sp | B32: 約 10 年期 AA− 公司債利差 | C32: % | D32: 0.004 | E32: 0.007 | F32: 0.01 | G32: Assumed | H32: 判斷：Meta 評等 AA−／Aa3 級（未入事實總帳）；10 年期利差約 50–100bp
A33: kd | B33: 稅前債務成本＝rf＋利差 | C33: % | E33: =rf+kd_sp -> 0.0569 | G33: Derived | H33: 同 Alphabet
A34: wacc_adj | B34: WACC 調整（Sens 格：±1pt） | C34: % | D34: -0.01 | E34: 0 | F34: 0.01 | G34: Assumed | H34: 同 Alphabet
A35: g_tv | B35: 永續成長率（FY2032 後） | C35: % | D35: 0.02 | E35: 0.03 | F35: 0.04 | G35: Assumed | H35: 同 Alphabet
A36: ronic_sp | B36: 永續期 RONIC 相對 WACC 的差 | C36: % | E36: 0 | F36: 0.05 | G36: Assumed | H36: 同 Alphabet 修正一 F5：RONIC＝WACC | I36: Sens：WACC＋5pt
A37: mid | B37: 期中慣例：年度現金流距年初 | C37: 年 | E37: 0.5 | G37: Derived | H37: 同 Alphabet
A38: t_val | B38: 評價日（2026-09-30）的年份小數 | C38: 年 | E38: 2026.75 | G38: Derived | H38: 同 Alphabet
A39: t_q4 | B39: Q4 26 現金流折現年數（期中） | C39: 年 | E39: 0.125 | G39: Derived | H39: 2026-10-01～12-31 中點
A40: tp_wA | B40: 情境權重 A | C40: % | E40: 0.25 | G40: Assumed | H40: 同 Alphabet（A 25%／B 50%／C 25%）
...

Sheet Q
A1: Q — 實績（US$B；EPS 美元；股數十億股）。資料取自 data/meta_facts_2026q3.json（四季財報新聞稿兩讀核對：SEC 8-K 附件 99.1 與 IR 網站 PDF；比較欄取自後一季新聞稿）[Verified]
A2: 核對列（實績必須為 0）：Advertising＋Other revenue＝Family of Apps、分部合計＝合併營收、分部營業利益合計＝合併營業利益、營收 − 成本費用＝營業利益、FCF＝營運現金 − 資本支出（含租賃本金）；FY2025 四季合計對年報取超出四捨五入容差（0.002）的部分
A3: 項目 | B3: 2024Q4 | C3: 2025Q1 | D3: 2025Q2 | E3: 2025Q3 | F3: 2025Q4 | G3: 2026Q1 | H3: 2026Q2 | I3: 2026Q3 | J3: FY2024 | K3: FY2025 | L3: 9M26 | M3: 近四季 TTM | N3: 前四季 | O3: 標記 | P3: 來源
A4: 營收（官方分部與子列）
A5: Advertising | B5: 46.783 | C5: 41.392 | D5: 46.563 | E5: 50.082 | F5: 58.137 | G5: 55.024 | H5: 59.363 | I5: 63.061 | J5: 160.633 | K5: 196.175 | L5: =G5+H5+I5 -> 177.448 | M5: =SUM(F5:I5) -> 235.585 | N5: =SUM(B5:E5) -> 184.82 | O5: Verified | P5: Meta 各季財報新聞稿（8-K 附件 99.1；事實總帳 data/meta_facts_2026q3.json）
A6: Other revenue | B6: 0.519 | C6: 0.51 | D6: 0.583 | E6: 0.69 | F6: 0.801 | G6: 0.885 | H6: 1.007 | I6: 1.097 | J6: 1.722 | K6: 2.584 | L6: =G6+H6+I6 -> 2.989 | M6: =SUM(F6:I6) -> 3.79 | N6: =SUM(B6:E6) -> 2.302 | O6: Verified | P6: Meta 各季財報新聞稿（8-K 附件 99.1；事實總帳 data/meta_facts_2026q3.json）
A7: Family of Apps（分部） | B7: 47.302 | C7: 41.902 | D7: 47.146 | E7: 50.772 | F7: 58.938 | G7: 55.909 | H7: 60.37 | I7: 64.158 | J7: 162.355 | K7: 198.759 | L7: =G7+H7+I7 -> 180.437 | M7: =SUM(F7:I7) -> 239.375 | N7: =SUM(B7:E7) -> 187.122 | O7: Verified | P7: Meta 各季財報新聞稿（8-K 附件 99.1；事實總帳 data/meta_facts_2026q3.json）
A8: 檢查：Advertising＋Other revenue－Family of Apps | B8: =B5+B6-B7 -> 0 | C8: =C5+C6-C7 -> 0 | D8: =D5+D6-D7 -> 0 | E8: =E5+E6-E7 -> 0 | F8: =F5+F6-F7 -> 0 | G8: =G5+G6-G7 -> 0 | H8: =H5+H6-H7 -> 0 | I8: =I5+I6-I7 -> 0 | ... K8: =K5+K6-K7 -> 0 | L8: =G8+H8+I8 -> 0 | M8: =SUM(F8:I8) -> 0 | N8: =SUM(B8:E8) -> 0 | O8: — | P8: —
A9: Reality Labs（分部） | B9: 1.083 | C9: 0.412 | D9: 0.37 | E9: 0.47 | F9: 0.955 | G9: 0.402 | H9: 0.431 | I9: 0.443 | J9: 2.146 | K9: 2.207 | L9: =G9+H9+I9 -> 1.276 | M9: =SUM(F9:I9) -> 2.231 | N9: =SUM(B9:E9) -> 2.335 | O9: Verified | P9: Meta 各季財報新聞稿（8-K 附件 99.1；事實總帳 data/meta_facts_2026q3.json）
A10: 合併營收 | B10: 48.385 | C10: 42.314 | D10: 47.516 | E10: 51.242 | F10: 59.893 | G10: 56.311 | H10: 60.801 | I10: 64.601 | J10: 164.501 | K10: 200.966 | L10: =G10+H10+I10 -> 181.713 | M10: =SUM(F10:I10) -> 241.606 | N10: =SUM(B10:E10) -> 189.457 | O10: Verified | P10: Meta 各季財報新聞稿（8-K 附件 99.1；事實總帳 data/meta_facts_2026q3.json）
A11: 檢查：分部合計－合併營收 | B11: =B7+B9-B10 -> 0 | C11: =C7+C9-C10 -> 0 | D11: =D7+D9-D10 -> 0 | E11: =E7+E9-E10 -> 0 | F11: =F7+F9-F10 -> 0 | G11: =G7+G9-G10 -> 0 | H11: =H7+H9-H10 -> 0 | I11: =I7+I9-I10 -> 0 | ... K11: =K7+K9-K10 -> 0 | L11: =G11+H11+I11 -> 0 | M11: =SUM(F11:I11) -> 0 | N11: =SUM(B11:E11) -> 0 | O11: — | P11: —
A13: 分部營業利益
A14: Family of Apps 營業利益 | B14: 28.332 | C14: 21.765 | D14: 24.971 | E14: 24.967 | F14: 30.766 | G14: 26.9 | H14: 23.394 | I14: 17.117 | J14: 87.109 | K14: 102.469 | L14: =G14+H14+I14 -> 67.411 | M14: =SUM(F14:I14) -> 98.177 | N14: =SUM(B14:E14) -> 100.035 | O14: Verified | P14: Meta 各季財報新聞稿（8-K 附件 99.1；事實總帳 data/meta_facts_2026q3.json）
A15: Reality Labs 營業損益 | B15: -4.967 | C15: -4.21 | D15: -4.53 | E15: -4.432 | F15: -6.021 | G15: -4.028 | H15: -4.619 | I15: -4.129 | J15: -17.729 | K15: -19.193 | L15: =G15+H15+I15 -> -12.776 | M15: =SUM(F15:I15) -> -18.797 | N15: =SUM(B15:E15) -> -18.139 | O15: Verified | P15: Meta 各季財報新聞稿（8-K 附件 99.1；事實總帳 data/meta_facts_2026q3.json）
A16: 合併營業利益 | B16: 23.365 | C16: 17.555 | D16: 20.441 | E16: 20.535 | F16: 24.745 | G16: 22.872 | H16: 18.775 | I16: 12.988 | J16: 69.38 | K16: 83.276 | L16: =G16+H16+I16 -> 54.635 | M16: =SUM(F16:I16) -> 79.38 | N16: =SUM(B16:E16) -> 81.896 | O16: Verified | P16: Meta 各季財報新聞稿（8-K 附件 99.1；事實總帳 data/meta_facts_2026q3.json）
A17: 檢查：分部營業利益合計－合併營業利益 | B17: =B14+B15-B16 -> 0 | C17: =C14+C15-C16 -> 0 | D17: =D14+D15-D16 -> 0 | E17: =E14+E15-E16 -> 0 | F17: =F14+F15-F16 -> 0 | G17: =G14+G15-G16 -> 0 | H17: =H14+H15-H16 -> 0 | I17: =I14+I15-I16 -> 0 | ... K17: =K14+K15-K16 -> 0 | L17: =G17+H17+I17 -> 0 | M17: =SUM(F17:I17) -> 0 | N17: =SUM(B17:E17) -> 0 | O17: — | P17: —
A19: 合併損益
A20: 營業成本 | B20: 8.839 | C20: 7.572 | D20: 8.491 | E20: 9.206 | F20: 10.905 | G20: 10.218 | H20: 11.33 | I20: 13.369 | J20: 30.161 | K20: 36.175 | L20: =G20+H20+I20 -> 34.917 | M20: =SUM(F20:I20) -> 45.822 | N20: =SUM(B20:E20) -> 34.108 | O20: Verified | P20: Meta 各季財報新聞稿（8-K 附件 99.1；事實總帳 data/meta_facts_2026q3.json）
A21: 研發費用 | B21: 12.18 | C21: 12.15 | D21: 12.942 | E21: 15.144 | F21: 17.136 | G21: 17.699 | H21: 21.656 | I21: 20.054 | J21: 43.873 | K21: 57.372 | L21: =G21+H21+I21 -> 59.409 | M21: =SUM(F21:I21) -> 76.545 | N21: =SUM(B21:E21) -> 52.416 | O21: Verified | P21: Meta 各季財報新聞稿（8-K 附件 99.1；事實總帳 data/meta_facts_2026q3.json）
A22: 行銷費用 | B22: 3.24 | C22: 2.757 | D22: 2.979 | E22: 2.845 | F22: 3.41 | G22: 2.908 | H22: 3.431 | I22: 3.333 | J22: 11.347 | K22: 11.991 | L22: =G22+H22+I22 -> 9.672 | M22: =SUM(F22:I22) -> 13.082 | N22: =SUM(B22:E22) -> 11.821 | O22: Verified | P22: Meta 各季財報新聞稿（8-K 附件 99.1；事實總帳 data/meta_facts_2026q3.json）
A23: 管理費用（含法律費用） | B23: 0.761 | C23: 2.28 | D23: 2.663 | E23: 3.512 | F23: 3.697 | G23: 2.614 | H23: 5.609 | I23: 14.857 | J23: 9.74 | K23: 12.152 | L23: =G23+H23+I23 -> 23.08 | M23: =SUM(F23:I23) -> 26.777 | N23: =SUM(B23:E23) -> 9.216 | O23: Verified | P23: Meta 各季財報新聞稿（8-K 附件 99.1；事實總帳 data/meta_facts_2026q3.json）
A24: 檢查：營收 − 成本費用 − 營業利益 | B24: =B10-B20-B21-B22-B23-B16 -> 0 | C24: =C10-C20-C21-C22-C23-C16 -> 0 | D24: =D10-D20-D21-D22-D23-D16 -> 0 | E24: =E10-E20-E21-E22-E23-E16 -> 0 | F24: =F10-F20-F21-F22-F23-F16 -> 0 | G24: =G10-G20-G21-G22-G23-G16 -> 0 | H24: =H10-H20-H21-H22-H23-H16 -> 0 | I24: =I10-I20-I21-I22-I23-I16 -> 0 | ... K24: =K10-K20-K21-K22-K23-K16 -> 0 | L24: =G24+H24+I24 -> 0 | M24: =SUM(F24:I24) -> 0 | N24: =SUM(B24:E24) -> 0 | O24: — | P24: —
A25: 利息與其他收益淨額 | B25: 0.188 | C25: 0.827 | D25: 0.093 | E25: 1.128 | F25: 0.609 | G25: -1.12 | H25: -0.019 | I25: 0.013 | J25: 1.283 | K25: 2.656 | L25: =G25+H25+I25 -> -1.126 | M25: =SUM(F25:I25) -> -0.517 | N25: =SUM(B25:E25) -> 2.236 | O25: Verified | P25: Meta 各季財報新聞稿（8-K 附件 99.1；事實總帳 data/meta_facts_2026q3.json）
A26: 稅前利益 | B26: 23.553 | C26: 18.382 | D26: 20.534 | E26: 21.663 | F26: 25.354 | G26: 21.752 | H26: 18.756 | I26: 13.001 | J26: 70.663 | K26: 85.932 | L26: =G26+H26+I26 -> 53.509 | M26: =SUM(F26:I26) -> 78.863 | N26: =SUM(B26:E26) -> 84.132 | O26: Verified | P26: Meta 各季財報新聞稿（8-K 附件 99.1；事實總帳 data/meta_facts_2026q3.json）
A27: 檢查：營業利益＋業外 − 稅前利益 | B27: =B16+B25-B26 -> 0 | C27: =C16+C25-C26 -> 0 | D27: =D16+D25-D26 -> 0 | E27: =E16+E25-E26 -> 0 | F27: =F16+F25-F26 -> 0 | G27: =G16+G25-G26 -> 0 | H27: =H16+H25-H26 -> 0 | I27: =I16+I25-I26 -> 0 | ... K27: =K16+K25-K26 -> 0 | L27: =G27+H27+I27 -> 0 | M27: =SUM(F27:I27) -> 0 | N27: =SUM(B27:E27) -> 0 | O27: — | P27: —
A28: 所得稅（負值＝利益） | B28: 2.715 | C28: 1.738 | D28: 2.197 | E28: 18.954 | F28: 2.586 | G28: -5.021 | H28: 2.908 | I28: 3.141 | J28: 8.303 | K28: 25.474 | L28: =G28+H28+I28 -> 1.028 | M28: =SUM(F28:I28) -> 3.614 | N28: =SUM(B28:E28) -> 25.604 | O28: Verified | P28: Meta 各季財報新聞稿（8-K 附件 99.1；事實總帳 data/meta_facts_2026q3.json）
A29: 淨利 | B29: 20.838 | C29: 16.644 | D29: 18.337 | E29: 2.709 | F29: 22.768 | G29: 26.773 | H29: 15.848 | I29: 9.86 | J29: 62.36 | K29: 60.458 | L29: =G29+H29+I29 -> 52.481 | M29: =SUM(F29:I29) -> 75.249 | N29: =SUM(B29:E29) -> 58.528 | O29: Verified | P29: Meta 各季財報新聞稿（8-K 附件 99.1；事實總帳 data/meta_facts_2026q3.json）
A30: 檢查：稅前 − 所得稅 − 淨利 | B30: =B26-B28-B29 -> 0 | C30: =C26-C28-C29 -> 0 | D30: =D26-D28-D29 -> 0 | E30: =E26-E28-E29 -> 0 | F30: =F26-F28-F29 -> 0 | G30: =G26-G28-G29 -> 0 | H30: =H26-H28-H29 -> 0 | I30: =I26-I28-I29 -> 0 | ... K30: =K26-K28-K29 -> 0 | L30: =G30+H30+I30 -> 0 | M30: =SUM(F30:I30) -> 0 | N30: =SUM(B30:E30) -> 0 | O30: — | P30: —
A31: 稀釋加權股數（十億股） | B31: 2.599 | C31: 2.59 | D31: 2.57 | E31: 2.572 | F31: 2.565 | G31: 2.564 | H31: 2.566 | I31: 2.573 | J31: 2.614 | K31: 2.574 | L31: =2.568 -> 2.568 | O31: Verified | P31: Meta 各季財報新聞稿（8-K 附件 99.1；事實總帳 data/meta_facts_2026q3.json）
A32: EPS（GAAP 稀釋，美元） | B32: 8.02 | C32: 6.43 | D32: 7.14 | E32: 1.05 | F32: 8.88 | G32: 10.44 | H32: 6.18 | I32: 3.83 | J32: 23.86 | K32: 23.49 | L32: =20.44 -> 20.44 | M32: =SUM(F32:I32) -> 29.33 | N32: =SUM(B32:E32) -> 22.64 | O32: Verified | P32: Meta 各季財報新聞稿（8-K 附件 99.1；事實總帳 data/meta_facts_2026q3.json）
A34: 現金流與股東回饋
A35: 折舊與攤銷 | B35: 4.46 | C35: 3.9 | D35: 4.342 | E35: 4.963 | F35: 5.411 | G35: 5.999 | H35: 6.356 | I35: 7.154 | J35: 15.498 | K35: 18.616 | L35: =G35+H35+I35 -> 19.509 | M35: =SUM(F35:I35) -> 24.92 | N35: =SUM(B35:E35) -> 17.665 | O35: Verified | P35: Meta 各季財報新聞稿（8-K 附件 99.1；事實總帳 data/meta_facts_2026q3.json）
A36: 股權報酬（SBC） | B36: 4.262 | C36: 4.147 | D36: 4.834 | E36: 5.555 | F36: 5.89 | G36: 6.032 | H36: 7.658 | I36: 7.363 | J36: 16.69 | K36: 20.427 | L36: =G36+H36+I36 -> 21.053 | M36: =SUM(F36:I36) -> 26.943 | N36: =SUM(B36:E36) -> 18.798 | O36: Verified | P36: Meta 各季財報新聞稿（8-K 附件 99.1；事實總帳 data/meta_facts_2026q3.json）
A37: 營運現金流 | B37: 27.988 | C37: 24.026 | D37: 25.561 | E37: 29.999 | F37: 36.214 | G37: 32.226 | H37: 31.862 | I37: 32.786 | J37: 91.328 | K37: 115.8 | L37: =G37+H37+I37 -> 96.874 | M37: =SUM(F37:I37) -> 133.088 | N37: =SUM(B37:E37) -> 107.574 | O37: Verified | P37: Meta 各季財報新聞稿（8-K 附件 99.1；事實總帳 data/meta_facts_2026q3.json）
A38: 購置不動產與設備 | B38: 14.425 | C38: 12.941 | D38: 16.538 | E38: 18.829 | F38: 21.383 | G38: 18.997 | H38: 30.116 | I38: 33.942 | J38: 37.256 | K38: 69.691 | L38: =G38+H38+I38 -> 83.055 | M38: =SUM(F38:I38) -> 104.438 | N38: =SUM(B38:E38) -> 62.733 | O38: Verified | P38: Meta 各季財報新聞稿（8-K 附件 99.1；事實總帳 data/meta_facts_2026q3.json）
A39: 融資租賃本金支付 | B39: 0.411 | C39: 0.751 | D39: 0.474 | E39: 0.545 | F39: 0.754 | G39: 0.843 | H39: 0.962 | I39: 0.964 | J39: 1.969 | K39: 2.524 | L39: =G39+H39+I39 -> 2.769 | M39: =SUM(F39:I39) -> 3.523 | N39: =SUM(B39:E39) -> 2.181 | O39: Verified | P39: Meta 各季財報新聞稿（8-K 附件 99.1；事實總帳 data/meta_facts_2026q3.json）
A40: 資本支出（含融資租賃本金；公司口徑） | B40: =B38+B39 -> 14.836 | C40: =C38+C39 -> 13.692 | D40: =D38+D39 -> 17.012 | E40: =E38+E39 -> 19.374 | F40: =F38+F39 -> 22.137 | G40: =G38+G39 -> 19.84 | H40: =H38+H39 -> 31.078 | I40: =I38+I39 -> 34.906 | ... K40: =K38+K39 -> 72.215 | L40: =G40+H40+I40 -> 85.824 | M40: =SUM(F40:I40) -> 107.961 | N40: =SUM(B40:E40) -> 64.914 | O40: Derived | P40: Meta 各季財報新聞稿（8-K 附件 99.1；事實總帳 data/meta_facts_2026q3.json）
A41: 自由現金流（公司定義） | B41: 13.152 | C41: 10.334 | D41: 8.549 | E41: 10.625 | F41: 14.077 | G41: 12.386 | H41: 0.784 | I41: -2.12 | J41: 52.103 | K41: 43.585 | L41: =G41+H41+I41 -> 11.05 | M41: =SUM(F41:I41) -> 25.127 | N41: =SUM(B41:E41) -> 42.66 | O41: Verified | P41: Meta 各季財報新聞稿（8-K 附件 99.1；事實總帳 data/meta_facts_2026q3.json）
A42: 檢查：營運現金流 − 資本支出（含租賃本金）− 自由現金流 | B42: =B37-B40-B41 -> 0 | C42: =C37-C40-C41 -> 0 | D42: =D37-D40-D41 -> 0 | E42: =E37-E40-E41 -> 0 | F42: =F37-F40-F41 -> 0 | G42: =G37-G40-G41 -> 0 | H42: =H37-H40-H41 -> 0 | I42: =I37-I40-I41 -> 0 | ... K42: =K37-K40-K41 -> 0 | L42: =G42+H42+I42 -> 0 | M42: =SUM(F42:I42) -> 0 | N42: =SUM(B42:E42) -> 0 | O42: — | P42: —
A43: 買回 | B43: 0 | C43: 12.754 | D43: 10.167 | E43: 3.327 | F43: 0 | G43: 0 | H43: 0 | I43: 0 | J43: 30.125 | K43: 26.248 | L43: =G43+H43+I43 -> 0 | M43: =SUM(F43:I43) -> 0 | N43: =SUM(B43:E43) -> 26.248 | O43: Verified | P43: Meta 各季財報新聞稿（8-K 附件 99.1；事實總帳 data/meta_facts_2026q3.json）
...

Sheet Thesis
A1: Thesis — 命題模組：Meta 的 AI 算力全部自用。資本支出（指引與 M6）÷ Tokenomics 每 MW 資本支出 → 自用 AI MW（同 Alphabet C10）；MW → 新增 AI 折舊、自用 AI 增量營運成本（相對評價日在役機隊）→ FoA 營業利益；讀法 2：自用增量 MW × IF_HoldEcon（k＝1）＝影子效益（只進評價口徑）
A2: 期初機隊：FY2023（Assumed）、FY2024、FY2025、2026 年 9M 的 AI 資本支出（資本支出 − 營收 × cx_na）各以當年錨世代的每 MW 資本支出（IT＋自建比例 × 機房）換算；在建工程對應的 MW 於 Q4 26 轉入在役。MTIA 無揭露 → 全部按 GPU 世代（M4，不套 NonNV）。不計尚未起租租賃與第三方雲端（M4；Recon、Sens）→ 可能低估自用算力
A4: A. 期初機隊（單一數值，C 欄；三情境共用）
A5: 項目 | B5: 單位 | C5: 數值 | N5: 說明
A6: 每 MW 資本支出：H100 錨（IT＋自建比例 × 機房） | B6: US$m/MW | C6: =cit_h+selfb*cfac -> 38.279714
A7: 每 MW 資本支出：GB200 錨 | B7: US$m/MW | C7: =cit_b2+selfb*cfac -> 34.784674
A8: 每 MW 資本支出：GB300 錨 | B8: US$m/MW | C8: =cit_b3+selfb*cfac -> 43.006724
A9: 每 MW 資本支出：2026 新增組合 | B9: US$m/MW | C9: =am_26*cit_b3+(1-am_26)*cit_vr+selfb*cfac -> 43.006724
A10: 每 MW 資本支出：2027 新增組合 | B10: US$m/MW | C10: =am_27*cit_b3+(1-am_27)*cit_vr+selfb*cfac -> 45.681288
A11: 每 MW 資本支出：2028 起新增組合 | B11: US$m/MW | C11: =(1-am_28)*cit_b3+am_28*cit_vr+selfb*cfac -> 48.355852
A12: FY2024 AI 資本支出（資本支出 − 營收 × cx_na） | B12: US$B | C12: =cx_24-Q!J10*cx_na -> 32.64496
A13: FY2025 AI 資本支出 | B13: US$B | C13: =cx_25-Q!K10*cx_na -> 64.17636
A14: 2026 年 9M AI 資本支出 | B14: US$B | C14: =capex_9m-Q!L10*cx_na -> 78.55548
A15: 2026 年 9M AI 占資本支出 | B15: % | C15: =aicx_9m/capex_9m -> 0.915309 | N15: 對照 cip_ai
A16: 2023 年底以前 AI MW（FY2023 × AI 比例 ÷ H100 錨） | B16: MW | C16: =cx_23*ai_23/pmw_h*1000 -> 513.84919 | N16: 只用於 FY2029 汰換
A17: FY2024 新增 AI MW（H100 錨） | B17: MW | C17: =aicx_24/pmw_h*1000 -> 852.80052
A18: FY2025 新增 AI MW（GB200 錨） | B18: MW | C18: =aicx_25/pmw_b2*1000 -> 1844.9608
A19: 2026 年 9M 新增 AI MW（GB300 錨） | B19: MW | C19: =aicx_9m/pmw_b3*1000 -> 1826.586
A20: 評價日 AI MW（支出口徑，含在建） | B20: MW | C20: =mw_pre24+mw_24+mw_25+mw_9m -> 5038.1965 | N20: Wattonomics 對照：本值為資本支出換算，非實際上線 MW
A21: 在建工程對應 MW（cip_0 × cip_ai ÷ GB300 錨） | B21: MW | C21: =cip_0*cip_ai/pmw_b3*1000 -> 1872.942 | N21: Q4 26 轉入在役
A22: 評價日在役 MW：H100 錨 | B22: MW | C22: =mw_pre24+mw_24 -> 1366.6497
A23: 評價日在役 MW：GB200 錨（在建工程超過 9M 新增的部分自此扣） | B23: MW | C23: =mw_25-MAX(0,mw_cip-mw_9m) -> 1798.6048
A24: 評價日在役 MW：GB300 錨 | B24: MW | C24: =MAX(0,mw_9m-mw_cip) -> 0
A25: 評價日在役 AI MW（基準機隊；其成本已在 FoA 利益率內） | B25: MW | C25: =base_h+base_b2+base_b3 -> 3165.2545
A26: 基準機隊每 MW IT 年折舊（IF_DeprIT 加權） | B26: US$m/MW-年 | C26: =(base_h*dpi_h+base_b2*dpi_b2+base_b3*dpi_b3)/base_tot -> 4.2540357
A27: 基準機隊每 MW 持有成本（IF_HoldEcon 加權） | B27: US$m/MW-年 | C27: =(base_h*he_h+base_b2*he_b2+base_b3*he_b3)/base_tot -> 9.2059271
A28: 基準機隊每 MW 營運費用（IF_OpexGW 加權） | B28: US$m/MW-年 | C28: =(base_h*opx_h+base_b2*opx_b2+base_b3*opx_b3)/base_tot -> 1.8435076
A30: 情境 A（AI 提高每則廣告價格）
A31: 項目 | B31: 單位 | C31: FY2024A | D31: FY2025A | E31: 9M26A | F31: Q4 26E | G31: FY2026E | H31: FY2027E | I31: FY2028E | J31: FY2029E | K31: FY2030E | L31: FY2031E | M31: FY2032E | N31: 說明
A32: B. 自用 AI 容量（MW；期末）
A33: 自用 AI MW 新增（Q4 26、FY2027 由資本支出反推；FY2028＝FY2027 × a28；FY2029 起收斂） | B33: MW | F33: =(capex_g-capex_9m-Seg!F22)/pmw_26*1000 -> 1188.7101 | G33: =F33 -> 1188.7101 | H33: =(cx27_A-Seg!H22)/pmw_27*1000 -> 4894.3519 | I33: =H33*a28 -> 4894.3519 | J33: =$I$33+(g_tv*I38-$I$33)*MIN(1,(2029-2028)/conv_mw) -> 3790.881 | K33: =$I$33+(g_tv*J38-$I$33)*MIN(1,(2030-2028)/conv_mw) -> 2744.2733 | L33: =$I$33+(g_tv*K38-$I$33)*MIN(1,(2031-2028)/conv_mw) -> 1730.9802 | M33: =$I$33+(g_tv*L38-$I$33)*MIN(1,(2032-2028)/conv_mw) -> 728.45235 | N33: C10：Q4 26＝(2026 指引中點 − 9M 實績 − Q4 非 AI) ÷ 每 MW 資本支出；FY2027＝(情境 FY2027 資本支出 − 非 AI) ÷ 每 MW（汰換 0）
A34: 期末 MW：H100 錨 | B34: MW | E34: =mw_pre24+mw_24 -> 1366.6497 | F34: =E34+F33*0 -> 1366.6497 | G34: =F34 -> 1366.6497 | H34: =F34+H33*0 -> 1366.6497 | I34: =H34+I33*0 -> 1366.6497 | J34: =I34+J33*0 -> 1366.6497 | K34: =J34+K33*0 -> 1366.6497 | L34: =K34+L33*0 -> 1366.6497 | M34: =L34+M33*0 -> 1366.6497
A35: 期末 MW：GB200 錨 | B35: MW | E35: =mw_25 -> 1844.9608 | F35: =E35+F33*0 -> 1844.9608 | G35: =F35 -> 1844.9608 | H35: =F35+H33*0 -> 1844.9608 | I35: =H35+I33*0 -> 1844.9608 | J35: =I35+J33*0 -> 1844.9608 | K35: =J35+K33*0 -> 1844.9608 | L35: =K35+L33*0 -> 1844.9608 | M35: =L35+M33*0 -> 1844.9608
A36: 期末 MW：GB300 錨 | B36: MW | E36: =mw_9m -> 1826.586 | F36: =E36+F33*am_26 -> 3015.2961 | G36: =F36 -> 3015.2961 | H36: =F36+H33*am_27 -> 5462.472 | I36: =H36+I33*(1-am_28) -> 5462.472 | J36: =I36+J33*(1-am_28) -> 5462.472 | K36: =J36+K33*(1-am_28) -> 5462.472 | L36: =K36+L33*(1-am_28) -> 5462.472 | M36: =L36+M33*(1-am_28) -> 5462.472
A37: 期末 MW：VR200 錨 | B37: MW | E37: 0 | F37: =E37+F33*(1-am_26) -> 0 | G37: =F37 -> 0 | H37: =F37+H33*(1-am_27) -> 2447.176 | I37: =H37+I33*am_28 -> 7341.5279 | J37: =I37+J33*am_28 -> 11132.409 | K37: =J37+K33*am_28 -> 13876.682 | L37: =K37+L33*am_28 -> 15607.662 | M37: =L37+M33*am_28 -> 16336.115
A38: 期末自用 AI MW（在役；9M26 欄為支出口徑含在建） | B38: MW | E38: =E34+E35+E36+E37 -> 5038.1965 | F38: =F34+F35+F36+F37 -> 6226.9066 | G38: =G34+G35+G36+G37 -> 6226.9066 | H38: =H34+H35+H36+H37 -> 11121.258 | I38: =I34+I35+I36+I37 -> 16015.61 | J38: =J34+J35+J36+J37 -> 19806.491 | K38: =K34+K35+K36+K37 -> 22550.765 | L38: =L34+L35+L36+L37 -> 24281.745 | M38: =M34+M35+M36+M37 -> 25010.197
A39: 平均在役 MW：H100 錨 | B39: MW | F39: =(base_h+F34)/2 -> 1366.6497 | H39: =(F34+H34)/2 -> 1366.6497 | I39: =(H34+I34)/2 -> 1366.6497 | J39: =(I34+J34)/2 -> 1366.6497 | K39: =(J34+K34)/2 -> 1366.6497 | L39: =(K34+L34)/2 -> 1366.6497 | M39: =(L34+M34)/2 -> 1366.6497 | N39: Q4 26：期初＝評價日在役（不含在建），期末含在建轉入
A40: 平均在役 MW：GB200 錨 | B40: MW | F40: =(base_b2+F35)/2 -> 1821.7828 | H40: =(F35+H35)/2 -> 1844.9608 | I40: =(H35+I35)/2 -> 1844.9608 | J40: =(I35+J35)/2 -> 1844.9608 | K40: =(J35+K35)/2 -> 1844.9608 | L40: =(K35+L35)/2 -> 1844.9608 | M40: =(L35+M35)/2 -> 1844.9608
A41: 平均在役 MW：GB300 錨 | B41: MW | F41: =(base_b3+F36)/2 -> 1507.648 | H41: =(F36+H36)/2 -> 4238.884 | I41: =(H36+I36)/2 -> 5462.472 | J41: =(I36+J36)/2 -> 5462.472 | K41: =(J36+K36)/2 -> 5462.472 | L41: =(K36+L36)/2 -> 5462.472 | M41: =(L36+M36)/2 -> 5462.472
A42: 平均在役 MW：VR200 錨 | B42: MW | F42: =(0+F37)/2 -> 0 | H42: =(F37+H37)/2 -> 1223.588 | I42: =(H37+I37)/2 -> 4894.3519 | J42: =(I37+J37)/2 -> 9236.9684 | K42: =(J37+K37)/2 -> 12504.546 | L42: =(K37+L37)/2 -> 14742.172 | M42: =(L37+M37)/2 -> 15971.889
...

Sheet Seg
A1: Seg — 營收分部層：官方分部 Family of Apps（子列 Advertising、Other revenue）、Reality Labs。命題模組：Advertising＝廣告曝光數 × 每則廣告平均價格；情境差異只在每則價格（A：AI 提升／B：近四季成長收斂／C：提升消退）
A2: 成長路徑：Q4 26 年增＝近四季年增（Q 頁），之後線性收斂到長期值（conv_n 年，FY2030 到達）。曝光與價格各自收斂；價格情境＝B 路徑 ×(1＋情境調整)，調整自 FY2026 的 0 線性到 FY2030 的 In 頁值。非 AI 資本支出＝營收 × cx_na
A4: 情境 A（AI 提高每則廣告價格）
A5: 項目 | B5: 單位 | C5: FY2024A | D5: FY2025A | E5: 9M26A | F5: Q4 26E | G5: FY2026E | H5: FY2027E | I5: FY2028E | J5: FY2029E | K5: FY2030E | L5: FY2031E | M5: FY2032E | N5: 說明
A6: 廣告曝光數年增（B 路徑） | B6: % | F6: =g0_impr -> 0.1525 | H6: =g0_impr+(gl_impr-g0_impr)*MIN(1,(2027-2026)/conv_n) -> 0.126875 | I6: =g0_impr+(gl_impr-g0_impr)*MIN(1,(2028-2026)/conv_n) -> 0.10125 | J6: =g0_impr+(gl_impr-g0_impr)*MIN(1,(2029-2026)/conv_n) -> 0.075625 | K6: =g0_impr+(gl_impr-g0_impr)*MIN(1,(2030-2026)/conv_n) -> 0.05 | L6: =g0_impr+(gl_impr-g0_impr)*MIN(1,(2031-2026)/conv_n) -> 0.05 | M6: =g0_impr+(gl_impr-g0_impr)*MIN(1,(2032-2026)/conv_n) -> 0.05 | N6: Q4 26＝近四季平均（Q 頁），FY2030 收斂到 gl_impr
A7: 每則廣告價格年增（B 路徑） | B7: % | F7: =g0_price -> 0.10600664 | H7: =g0_price+(gl_price-g0_price)*MIN(1,(2027-2026)/conv_n) -> 0.087004981 | I7: =g0_price+(gl_price-g0_price)*MIN(1,(2028-2026)/conv_n) -> 0.068003321 | J7: =g0_price+(gl_price-g0_price)*MIN(1,(2029-2026)/conv_n) -> 0.04900166 | K7: =g0_price+(gl_price-g0_price)*MIN(1,(2030-2026)/conv_n) -> 0.03 | L7: =g0_price+(gl_price-g0_price)*MIN(1,(2031-2026)/conv_n) -> 0.03 | M7: =g0_price+(gl_price-g0_price)*MIN(1,(2032-2026)/conv_n) -> 0.03 | N7: Q4 26＝由近四季廣告金額年增反推，FY2030 收斂到 gl_price
A8: Advertising：B 路徑（曝光 × 價格） | B8: US$B | C8: =Q!J5 -> 160.633 | D8: =Q!K5 -> 196.175 | E8: =Q!L5 -> 177.448 | F8: =Q!F5*(1+F6)*(1+F7) -> 74.105644 | G8: =E8+F8 -> 251.55364 | H8: =G8*(1+H6)*(1+H7) -> 308.13277 | I8: =H8*(1+I6)*(1+I7) -> 362.40687 | J8: =I8*(1+J6)*(1+J7) -> 408.91541 | K8: =J8*(1+K6)*(1+K7) -> 442.24202 | L8: =K8*(1+L6)*(1+L7) -> 478.28474 | M8: =L8*(1+M6)*(1+M7) -> 517.26495 | N8: Q4 26＝2025Q4 × (1＋曝光年增) × (1＋價格年增)；年度＝前一年 × 同式
A9: 情境爬坡（FY2026 0 → FY2030 1） | B9: x | F9: 0 | H9: =MIN(1,(2027-2026)/conv_n) -> 0.25 | I9: =MIN(1,(2028-2026)/conv_n) -> 0.5 | J9: =MIN(1,(2029-2026)/conv_n) -> 0.75 | K9: =MIN(1,(2030-2026)/conv_n) -> 1 | L9: =MIN(1,(2031-2026)/conv_n) -> 1 | M9: =MIN(1,(2032-2026)/conv_n) -> 1
A10: 每則價格情境調整（相對 B 路徑） | B10: % | F10: =pA*F9 -> 0 | H10: =pA*H9 -> 0.025 | I10: =pA*I9 -> 0.05 | J10: =pA*J9 -> 0.075 | K10: =pA*K9 -> 0.1 | L10: =pA*L9 -> 0.1 | M10: =pA*M9 -> 0.1 | N10: In 頁 pA
A11: Advertising | B11: US$B | C11: =C8 -> 160.633 | D11: =D8 -> 196.175 | E11: =E8 -> 177.448 | F11: =F8*(1+F10) -> 74.105644 | G11: =E11+F11 -> 251.55364 | H11: =H8*(1+H10) -> 315.83609 | I11: =I8*(1+I10) -> 380.52721 | J11: =J8*(1+J10) -> 439.58407 | K11: =K8*(1+K10) -> 486.46622 | L11: =L8*(1+L10) -> 526.11322 | M11: =M8*(1+M10) -> 568.99144
A12: Advertising 年增 | B12: % | D12: =D11/C11-1 -> 0.22126213 | G12: =G11/D11-1 -> 0.28229206 | H12: =H11/G11-1 -> 0.25554171 | I12: =I11/H11-1 -> 0.20482497 | J12: =J11/I11-1 -> 0.15519747 | K12: =K11/J11-1 -> 0.10665116 | L12: =L11/K11-1 -> 0.0815 | M12: =M11/L11-1 -> 0.0815
A13: Other revenue 年增 | B13: % | F13: =g0_other -> 0.64639444 | H13: =g0_other+(gl_other-g0_other)*MIN(1,(2027-2026)/conv_n) -> 0.52229583 | I13: =g0_other+(gl_other-g0_other)*MIN(1,(2028-2026)/conv_n) -> 0.39819722 | J13: =g0_other+(gl_other-g0_other)*MIN(1,(2029-2026)/conv_n) -> 0.27409861 | K13: =g0_other+(gl_other-g0_other)*MIN(1,(2030-2026)/conv_n) -> 0.15 | L13: =g0_other+(gl_other-g0_other)*MIN(1,(2031-2026)/conv_n) -> 0.15 | M13: =g0_other+(gl_other-g0_other)*MIN(1,(2032-2026)/conv_n) -> 0.15 | N13: 三情境相同
A14: Other revenue | B14: US$B | C14: =Q!J6 -> 1.722 | D14: =Q!K6 -> 2.584 | E14: =Q!L6 -> 2.989 | F14: =Q!F6*(1+F13) -> 1.3187619 | G14: =E14+F14 -> 4.3077619 | H14: =G14*(1+H13) -> 6.557688 | I14: =H14*(1+I13) -> 9.1689412 | J14: =I14*(1+J13) -> 11.682135 | K14: =J14*(1+K13) -> 13.434456 | L14: =K14*(1+L13) -> 15.449624 | M14: =L14*(1+M13) -> 17.767067
A15: Family of Apps | B15: US$B | C15: =Q!J7 -> 162.355 | D15: =Q!K7 -> 198.759 | E15: =Q!L7 -> 180.437 | F15: =F11+F14 -> 75.424406 | G15: =E15+F15 -> 255.86141 | H15: =H11+H14 -> 322.39378 | I15: =I11+I14 -> 389.69615 | J15: =J11+J14 -> 451.2662 | K15: =K11+K14 -> 499.90068 | L15: =L11+L14 -> 541.56284 | M15: =M11+M14 -> 586.75851
A16: Reality Labs 營收年增 | B16: % | F16: =g0_rl -> -0.044539615 | H16: =g0_rl+(gl_rl-g0_rl)*MIN(1,(2027-2026)/conv_n) -> -0.020904711 | I16: =g0_rl+(gl_rl-g0_rl)*MIN(1,(2028-2026)/conv_n) -> 0.0027301927 | J16: =g0_rl+(gl_rl-g0_rl)*MIN(1,(2029-2026)/conv_n) -> 0.026365096 | K16: =g0_rl+(gl_rl-g0_rl)*MIN(1,(2030-2026)/conv_n) -> 0.05 | L16: =g0_rl+(gl_rl-g0_rl)*MIN(1,(2031-2026)/conv_n) -> 0.05 | M16: =g0_rl+(gl_rl-g0_rl)*MIN(1,(2032-2026)/conv_n) -> 0.05 | N16: 三情境相同
A17: Reality Labs | B17: US$B | C17: =Q!J9 -> 2.146 | D17: =Q!K9 -> 2.207 | E17: =Q!L9 -> 1.276 | F17: =Q!F9*(1+F16) -> 0.91246467 | G17: =E17+F17 -> 2.1884647 | H17: =G17*(1+H16) -> 2.1427154 | I17: =H17*(1+I16) -> 2.1485655 | J17: =I17*(1+J16) -> 2.2052126 | K17: =J17*(1+K16) -> 2.3154732 | L17: =K17*(1+L16) -> 2.4312469 | M17: =L17*(1+M16) -> 2.5528092
A18: 合併營收 | B18: US$B | C18: =Q!J10 -> 164.501 | D18: =Q!K10 -> 200.966 | E18: =Q!L10 -> 181.713 | F18: =F15+F17 -> 76.336871 | G18: =E18+F18 -> 258.04987 | H18: =H15+H17 -> 324.5365 | I18: =I15+I17 -> 391.84471 | J18: =J15+J17 -> 453.47142 | K18: =K15+K17 -> 502.21615 | L18: =L15+L17 -> 543.99409 | M18: =M15+M17 -> 589.31132
A19: 檢查：Advertising＋Other revenue－Family of Apps | B19: US$B | C19: =C11+C14-C15 -> 0 | D19: =D11+D14-D15 -> 0 | E19: =E11+E14-E15 -> 0 | F19: =F11+F14-F15 -> 0 | G19: =G11+G14-G15 -> 0 | H19: =H11+H14-H15 -> 0 | I19: =I11+I14-I15 -> 0 | J19: =J11+J14-J15 -> 0 | ... M19: =M11+M14-M15 -> 0
A20: 檢查：分部合計－合併營收 | B20: US$B | C20: =C15+C17-C18 -> 0 | D20: =D15+D17-D18 -> 0 | E20: =E15+E17-E18 -> 0 | F20: =F15+F17-F18 -> 0 | G20: =G15+G17-G18 -> 0 | H20: =H15+H17-H18 -> 0 | I20: =I15+I17-I18 -> 0 | J20: =J15+J17-J18 -> 0 | ... M20: =M15+M17-M18 -> 0
A21: 檢查：實績欄合併營收 − Q 頁（FY2024、FY2025、9M26） | B21: US$B | C21: =C18-Q!J10 -> 0 | D21: =D18-Q!K10 -> 0 | E21: =E18-Q!L10 -> 0
A22: 非 AI 資本支出（營收 × cx_na） | B22: US$B | F22: =F18*cx_na -> 3.0534748 | G22: =F22 -> 3.0534748 | H22: =H18*cx_na -> 12.98146 | I22: =I18*cx_na -> 15.673789 | J22: =J18*cx_na -> 18.138857 | K22: =K18*cx_na -> 20.088646 | L22: =L18*cx_na -> 21.759763 | M22: =M18*cx_na -> 23.572453
A23: 新增非 AI 折舊（年限 life_na） | B23: US$B | F23: =$F$22/life_na*IF((0)<0,0,IF((0)=0,phi_q4,IF((0)<life_na,1,IF((0)=life_na,1-phi_q4,0)))) -> 0.038168435 | G23: =F23 -> 0.038168435 | H23: =$F$22/life_na*IF((1)<0,0,IF((1)=0,phi_q4,IF((1)<life_na,1,IF((1)=life_na,1-phi_q4,0))))+$H$22/life_na*IF((0)<0,0,IF((0)=0,phi_0,IF((0)<life_na,1,IF((0)=life_na,1-phi_0,0)))) -> 0.62988398 | I23: =$F$22/life_na*IF((2)<0,0,IF((2)=0,phi_q4,IF((2)<life_na,1,IF((2)=life_na,1-phi_q4,0))))+$H$22/life_na*IF((1)<0,0,IF((1)=0,phi_0,IF((1)<life_na,1,IF((1)=life_na,1-phi_0,0))))+$I$22/life_na*IF((0)<0,0,IF((0)=0,phi_0,IF((0)<life_na,1,IF((0)=life_na,1-phi_0,0)))) -> 1.9953382 | J23: =$F$22/life_na*IF((3)<0,0,IF((3)=0,phi_q4,IF((3)<life_na,1,IF((3)=life_na,1-phi_q4,0))))+$H$22/life_na*IF((2)<0,0,IF((2)=0,phi_0,IF((2)<life_na,1,IF((2)=life_na,1-phi_0,0))))+$I$22/life_na*IF((1)<0,0,IF((1)=0,phi_0,IF((1)<life_na,1,IF((1)=life_na,1-phi_0,0))))+$J$22/life_na*IF((0)<0,0,IF((0)=0,phi_0,IF((0)<life_na,1,IF((0)=life_na,1-phi_0,0)))) -> 3.6243437 | K23: =$F$22/life_na*IF((4)<0,0,IF((4)=0,phi_q4,IF((4)<life_na,1,IF((4)=life_na,1-phi_q4,0))))+$H$22/life_na*IF((3)<0,0,IF((3)=0,phi_0,IF((3)<life_na,1,IF((3)=life_na,1-phi_0,0))))+$I$22/life_na*IF((2)<0,0,IF((2)=0,phi_0,IF((2)<life_na,1,IF((2)=life_na,1-phi_0,0))))+$J$22/life_na*IF((1)<0,0,IF((1)=0,phi_0,IF((1)<life_na,1,IF((1)=life_na,1-phi_0,0))))+$K$22/life_na*IF((0)<0,0,IF((0)=0,phi_0,IF((0)<life_na,1,IF((0)=life_na,1-phi_0,0)))) -> 5.4869741 | L23: =$F$22/life_na*IF((5)<0,0,IF((5)=0,phi_q4,IF((5)<life_na,1,IF((5)=life_na,1-phi_q4,0))))+$H$22/life_na*IF((4)<0,0,IF((4)=0,phi_0,IF((4)<life_na,1,IF((4)=life_na,1-phi_0,0))))+$I$22/life_na*IF((3)<0,0,IF((3)=0,phi_0,IF((3)<life_na,1,IF((3)=life_na,1-phi_0,0))))+$J$22/life_na*IF((2)<0,0,IF((2)=0,phi_0,IF((2)<life_na,1,IF((2)=life_na,1-phi_0,0))))+$K$22/life_na*IF((1)<0,0,IF((1)=0,phi_0,IF((1)<life_na,1,IF((1)=life_na,1-phi_0,0))))+$L$22/life_na*IF((0)<0,0,IF((0)=0,phi_0,IF((0)<life_na,1,IF((0)=life_na,1-phi_0,0)))) -> 7.5376167 | M23: =$F$22/life_na*IF((6)<0,0,IF((6)=0,phi_q4,IF((6)<life_na,1,IF((6)=life_na,1-phi_q4,0))))+$H$22/life_na*IF((5)<0,0,IF((5)=0,phi_0,IF((5)<life_na,1,IF((5)=life_na,1-phi_0,0))))+$I$22/life_na*IF((4)<0,0,IF((4)=0,phi_0,IF((4)<life_na,1,IF((4)=life_na,1-phi_0,0))))+$J$22/life_na*IF((3)<0,0,IF((3)=0,phi_0,IF((3)<life_na,1,IF((3)=life_na,1-phi_0,0))))+$K$22/life_na*IF((2)<0,0,IF((2)=0,phi_0,IF((2)<life_na,1,IF((2)=life_na,1-phi_0,0))))+$L$22/life_na*IF((1)<0,0,IF((1)=0,phi_0,IF((1)<life_na,1,IF((1)=life_na,1-phi_0,0))))+$M$22/life_na*IF((0)<0,0,IF((0)=0,phi_0,IF((0)<life_na,1,IF((0)=life_na,1-phi_0,0)))) -> 9.7589102
A25: 情境 B（近四季成長收斂；基準）
A26: 項目 | B26: 單位 | C26: FY2024A | D26: FY2025A | E26: 9M26A | F26: Q4 26E | G26: FY2026E | H26: FY2027E | I26: FY2028E | J26: FY2029E | K26: FY2030E | L26: FY2031E | M26: FY2032E | N26: 說明
A27: 廣告曝光數年增（B 路徑） | B27: % | F27: =g0_impr -> 0.1525 | H27: =g0_impr+(gl_impr-g0_impr)*MIN(1,(2027-2026)/conv_n) -> 0.126875 | I27: =g0_impr+(gl_impr-g0_impr)*MIN(1,(2028-2026)/conv_n) -> 0.10125 | J27: =g0_impr+(gl_impr-g0_impr)*MIN(1,(2029-2026)/conv_n) -> 0.075625 | K27: =g0_impr+(gl_impr-g0_impr)*MIN(1,(2030-2026)/conv_n) -> 0.05 | L27: =g0_impr+(gl_impr-g0_impr)*MIN(1,(2031-2026)/conv_n) -> 0.05 | M27: =g0_impr+(gl_impr-g0_impr)*MIN(1,(2032-2026)/conv_n) -> 0.05 | N27: Q4 26＝近四季平均（Q 頁），FY2030 收斂到 gl_impr
A28: 每則廣告價格年增（B 路徑） | B28: % | F28: =g0_price -> 0.10600664 | H28: =g0_price+(gl_price-g0_price)*MIN(1,(2027-2026)/conv_n) -> 0.087004981 | I28: =g0_price+(gl_price-g0_price)*MIN(1,(2028-2026)/conv_n) -> 0.068003321 | J28: =g0_price+(gl_price-g0_price)*MIN(1,(2029-2026)/conv_n) -> 0.04900166 | K28: =g0_price+(gl_price-g0_price)*MIN(1,(2030-2026)/conv_n) -> 0.03 | L28: =g0_price+(gl_price-g0_price)*MIN(1,(2031-2026)/conv_n) -> 0.03 | M28: =g0_price+(gl_price-g0_price)*MIN(1,(2032-2026)/conv_n) -> 0.03 | N28: Q4 26＝由近四季廣告金額年增反推，FY2030 收斂到 gl_price
A29: Advertising：B 路徑（曝光 × 價格） | B29: US$B | C29: =Q!J5 -> 160.633 | D29: =Q!K5 -> 196.175 | E29: =Q!L5 -> 177.448 | F29: =Q!F5*(1+F27)*(1+F28) -> 74.105644 | G29: =E29+F29 -> 251.55364 | H29: =G29*(1+H27)*(1+H28) -> 308.13277 | I29: =H29*(1+I27)*(1+I28) -> 362.40687 | J29: =I29*(1+J27)*(1+J28) -> 408.91541 | K29: =J29*(1+K27)*(1+K28) -> 442.24202 | L29: =K29*(1+L27)*(1+L28) -> 478.28474 | M29: =L29*(1+M27)*(1+M28) -> 517.26495 | N29: Q4 26＝2025Q4 × (1＋曝光年增) × (1＋價格年增)；年度＝前一年 × 同式
A30: 情境爬坡（FY2026 0 → FY2030 1） | B30: x | F30: 0 | H30: =MIN(1,(2027-2026)/conv_n) -> 0.25 | I30: =MIN(1,(2028-2026)/conv_n) -> 0.5 | J30: =MIN(1,(2029-2026)/conv_n) -> 0.75 | K30: =MIN(1,(2030-2026)/conv_n) -> 1 | L30: =MIN(1,(2031-2026)/conv_n) -> 1 | M30: =MIN(1,(2032-2026)/conv_n) -> 1
A31: 每則價格情境調整（相對 B 路徑） | B31: % | F31: =0*F30 -> 0 | H31: =0*H30 -> 0 | I31: =0*I30 -> 0 | J31: =0*J30 -> 0 | K31: =0*K30 -> 0 | L31: =0*L30 -> 0 | M31: =0*M30 -> 0 | N31: 基準不另調整
A32: Advertising | B32: US$B | C32: =C29 -> 160.633 | D32: =D29 -> 196.175 | E32: =E29 -> 177.448 | F32: =F29*(1+F31) -> 74.105644 | G32: =E32+F32 -> 251.55364 | H32: =H29*(1+H31) -> 308.13277 | I32: =I29*(1+I31) -> 362.40687 | J32: =J29*(1+J31) -> 408.91541 | K32: =K29*(1+K31) -> 442.24202 | L32: =L29*(1+L31) -> 478.28474 | M32: =M29*(1+M31) -> 517.26495
A33: Advertising 年增 | B33: % | D33: =D32/C32-1 -> 0.22126213 | G33: =G32/D32-1 -> 0.28229206 | H33: =H32/G32-1 -> 0.22491874 | I33: =I32/H32-1 -> 0.17613866 | J33: =J32/I32-1 -> 0.12833241 | K33: =K32/J32-1 -> 0.0815 | L33: =L32/K32-1 -> 0.0815 | M33: =M32/L32-1 -> 0.0815
A34: Other revenue 年增 | B34: % | F34: =g0_other -> 0.64639444 | H34: =g0_other+(gl_other-g0_other)*MIN(1,(2027-2026)/conv_n) -> 0.52229583 | I34: =g0_other+(gl_other-g0_other)*MIN(1,(2028-2026)/conv_n) -> 0.39819722 | J34: =g0_other+(gl_other-g0_other)*MIN(1,(2029-2026)/conv_n) -> 0.27409861 | K34: =g0_other+(gl_other-g0_other)*MIN(1,(2030-2026)/conv_n) -> 0.15 | L34: =g0_other+(gl_other-g0_other)*MIN(1,(2031-2026)/conv_n) -> 0.15 | M34: =g0_other+(gl_other-g0_other)*MIN(1,(2032-2026)/conv_n) -> 0.15 | N34: 三情境相同
A35: Other revenue | B35: US$B | C35: =Q!J6 -> 1.722 | D35: =Q!K6 -> 2.584 | E35: =Q!L6 -> 2.989 | F35: =Q!F6*(1+F34) -> 1.3187619 | G35: =E35+F35 -> 4.3077619 | H35: =G35*(1+H34) -> 6.557688 | I35: =H35*(1+I34) -> 9.1689412 | J35: =I35*(1+J34) -> 11.682135 | K35: =J35*(1+K34) -> 13.434456 | L35: =K35*(1+L34) -> 15.449624 | M35: =L35*(1+M34) -> 17.767067
A36: Family of Apps | B36: US$B | C36: =Q!J7 -> 162.355 | D36: =Q!K7 -> 198.759 | E36: =Q!L7 -> 180.437 | F36: =F32+F35 -> 75.424406 | G36: =E36+F36 -> 255.86141 | H36: =H32+H35 -> 314.69046 | I36: =I32+I35 -> 371.57581 | J36: =J32+J35 -> 420.59755 | K36: =K32+K35 -> 455.67647 | L36: =L32+L35 -> 493.73437 | M36: =M32+M35 -> 535.03202
A37: Reality Labs 營收年增 | B37: % | F37: =g0_rl -> -0.044539615 | H37: =g0_rl+(gl_rl-g0_rl)*MIN(1,(2027-2026)/conv_n) -> -0.020904711 | I37: =g0_rl+(gl_rl-g0_rl)*MIN(1,(2028-2026)/conv_n) -> 0.0027301927 | J37: =g0_rl+(gl_rl-g0_rl)*MIN(1,(2029-2026)/conv_n) -> 0.026365096 | K37: =g0_rl+(gl_rl-g0_rl)*MIN(1,(2030-2026)/conv_n) -> 0.05 | L37: =g0_rl+(gl_rl-g0_rl)*MIN(1,(2031-2026)/conv_n) -> 0.05 | M37: =g0_rl+(gl_rl-g0_rl)*MIN(1,(2032-2026)/conv_n) -> 0.05 | N37: 三情境相同
A38: Reality Labs | B38: US$B | C38: =Q!J9 -> 2.146 | D38: =Q!K9 -> 2.207 | E38: =Q!L9 -> 1.276 | F38: =Q!F9*(1+F37) -> 0.91246467 | G38: =E38+F38 -> 2.1884647 | H38: =G38*(1+H37) -> 2.1427154 | I38: =H38*(1+I37) -> 2.1485655 | J38: =I38*(1+J37) -> 2.2052126 | K38: =J38*(1+K37) -> 2.3154732 | L38: =K38*(1+L37) -> 2.4312469 | M38: =L38*(1+M37) -> 2.5528092
A39: 合併營收 | B39: US$B | C39: =Q!J10 -> 164.501 | D39: =Q!K10 -> 200.966 | E39: =Q!L10 -> 181.713 | F39: =F36+F38 -> 76.336871 | G39: =E39+F39 -> 258.04987 | H39: =H36+H38 -> 316.83318 | I39: =I36+I38 -> 373.72437 | J39: =J36+J38 -> 422.80276 | K39: =K36+K38 -> 457.99195 | L39: =L36+L38 -> 496.16561 | M39: =M36+M38 -> 537.58483
A40: 檢查：Advertising＋Other revenue－Family of Apps | B40: US$B | C40: =C32+C35-C36 -> 0 | D40: =D32+D35-D36 -> 0 | E40: =E32+E35-E36 -> 0 | F40: =F32+F35-F36 -> 0 | G40: =G32+G35-G36 -> 0 | H40: =H32+H35-H36 -> 0 | I40: =I32+I35-I36 -> 0 | J40: =J32+J35-J36 -> 0 | ... M40: =M32+M35-M36 -> 0
A41: 檢查：分部合計－合併營收 | B41: US$B | C41: =C36+C38-C39 -> 0 | D41: =D36+D38-D39 -> 0 | E41: =E36+E38-E39 -> 0 | F41: =F36+F38-F39 -> 0 | G41: =G36+G38-G39 -> 0 | H41: =H36+H38-H39 -> 0 | I41: =I36+I38-I39 -> 0 | J41: =J36+J38-J39 -> 0 | ... M41: =M36+M38-M39 -> 0
A42: 檢查：實績欄合併營收 − Q 頁（FY2024、FY2025、9M26） | B42: US$B | C42: =C39-Q!J10 -> 0 | D42: =D39-Q!K10 -> 0 | E42: =E39-Q!L10 -> 0
...

Sheet PL
A1: PL — 分部營收 → 分部營業利益 → 合併營業利益 → 業外 → 稅 → 淨利 → EPS（三情境；US$B，EPS 美元）。實績欄（FY2024A、FY2025A、9M26A）取自 Q 頁；FY2026E＝9M 實績＋Q4 模型
A2: FoA EBITDA＝(FoA 營收 − 價格情境差額) × FoA EBITDA 率（9M26，排除一次性）＋差額 × inc_m − 自用 AI 增量營運成本與租金；FoA 折舊＝基礎折舊 ×(1 − RL 占比)＋新增 AI＋新增非 AI。RL 營業損益＝指引與法說路徑。財報口徑保留 2026 年一次性項目；評價口徑排除（M5 擴大）並加讀法 2 影子效益
A4: 分部對帳彙總（三情境 × 全部年度取絕對值最大者；實績欄同列）
A5: 項目 | B5: 單位 | C5: FY2024A | D5: FY2025A | E5: 9M26A | F5: Q4 26E | G5: FY2026E | H5: FY2027E | I5: FY2028E | J5: FY2029E | K5: FY2030E | L5: FY2031E | M5: FY2032E | N5: 說明
A6: 檢查：Advertising＋Other revenue－Family of Apps | B6: US$B | C6: =MAX(ABS(C18),ABS(C65),ABS(C112)) -> 0 | D6: =MAX(ABS(D18),ABS(D65),ABS(D112)) -> 0 | E6: =MAX(ABS(E18),ABS(E65),ABS(E112)) -> 0 | F6: =MAX(ABS(F18),ABS(F65),ABS(F112)) -> 0 | G6: =MAX(ABS(G18),ABS(G65),ABS(G112)) -> 0 | H6: =MAX(ABS(H18),ABS(H65),ABS(H112)) -> 0 | I6: =MAX(ABS(I18),ABS(I65),ABS(I112)) -> 0 | J6: =MAX(ABS(J18),ABS(J65),ABS(J112)) -> 0 | ... M6: =MAX(ABS(M18),ABS(M65),ABS(M112)) -> 0 | N6: 三情境各區塊同名核對列的最大絕對值；必須為 0（tools/segment_check 讀本列）
A7: 檢查：分部合計－合併營收 | B7: US$B | C7: =MAX(ABS(C19),ABS(C66),ABS(C113)) -> 0 | D7: =MAX(ABS(D19),ABS(D66),ABS(D113)) -> 0 | E7: =MAX(ABS(E19),ABS(E66),ABS(E113)) -> 0 | F7: =MAX(ABS(F19),ABS(F66),ABS(F113)) -> 0 | G7: =MAX(ABS(G19),ABS(G66),ABS(G113)) -> 0 | H7: =MAX(ABS(H19),ABS(H66),ABS(H113)) -> 0 | I7: =MAX(ABS(I19),ABS(I66),ABS(I113)) -> 0 | J7: =MAX(ABS(J19),ABS(J66),ABS(J113)) -> 0 | ... M7: =MAX(ABS(M19),ABS(M66),ABS(M113)) -> 0 | N7: 三情境各區塊同名核對列的最大絕對值；必須為 0（tools/segment_check 讀本列）
A8: 檢查：分部營業利益合計－合併營業利益 | B8: US$B | C8: =MAX(ABS(C32),ABS(C79),ABS(C126)) -> 0 | D8: =MAX(ABS(D32),ABS(D79),ABS(D126)) -> 0 | E8: =MAX(ABS(E32),ABS(E79),ABS(E126)) -> 0 | F8: =MAX(ABS(F32),ABS(F79),ABS(F126)) -> 0 | G8: =MAX(ABS(G32),ABS(G79),ABS(G126)) -> 0 | H8: =MAX(ABS(H32),ABS(H79),ABS(H126)) -> 0 | I8: =MAX(ABS(I32),ABS(I79),ABS(I126)) -> 0 | J8: =MAX(ABS(J32),ABS(J79),ABS(J126)) -> 0 | ... M8: =MAX(ABS(M32),ABS(M79),ABS(M126)) -> 0 | N8: 三情境各區塊同名核對列的最大絕對值；必須為 0（tools/segment_check 讀本列）
A10: 情境 A（AI 提高每則廣告價格）
A11: 項目 | B11: 單位 | C11: FY2024A | D11: FY2025A | E11: 9M26A | F11: Q4 26E | G11: FY2026E | H11: FY2027E | I11: FY2028E | J11: FY2029E | K11: FY2030E | L11: FY2031E | M11: FY2032E | N11: 說明
A12: Advertising | B12: US$B | C12: =Seg!C11 -> 160.633 | D12: =Seg!D11 -> 196.175 | E12: =Seg!E11 -> 177.448 | F12: =Seg!F11 -> 74.105644 | G12: =Seg!G11 -> 251.55364 | H12: =Seg!H11 -> 315.83609 | I12: =Seg!I11 -> 380.52721 | J12: =Seg!J11 -> 439.58407 | ... M12: =Seg!M11 -> 568.99144
A13: Other revenue | B13: US$B | C13: =Seg!C14 -> 1.722 | D13: =Seg!D14 -> 2.584 | E13: =Seg!E14 -> 2.989 | F13: =Seg!F14 -> 1.3187619 | G13: =Seg!G14 -> 4.3077619 | H13: =Seg!H14 -> 6.557688 | I13: =Seg!I14 -> 9.1689412 | J13: =Seg!J14 -> 11.682135 | ... M13: =Seg!M14 -> 17.767067
A14: Family of Apps | B14: US$B | C14: =Seg!C15 -> 162.355 | D14: =Seg!D15 -> 198.759 | E14: =Seg!E15 -> 180.437 | F14: =Seg!F15 -> 75.424406 | G14: =Seg!G15 -> 255.86141 | H14: =Seg!H15 -> 322.39378 | I14: =Seg!I15 -> 389.69615 | J14: =Seg!J15 -> 451.2662 | ... M14: =Seg!M15 -> 586.75851
A15: Reality Labs | B15: US$B | C15: =Seg!C17 -> 2.146 | D15: =Seg!D17 -> 2.207 | E15: =Seg!E17 -> 1.276 | F15: =Seg!F17 -> 0.91246467 | G15: =Seg!G17 -> 2.1884647 | H15: =Seg!H17 -> 2.1427154 | I15: =Seg!I17 -> 2.1485655 | J15: =Seg!J17 -> 2.2052126 | ... M15: =Seg!M17 -> 2.5528092
A16: 合併營收 | B16: US$B | C16: =Seg!C18 -> 164.501 | D16: =Seg!D18 -> 200.966 | E16: =Seg!E18 -> 181.713 | F16: =Seg!F18 -> 76.336871 | G16: =Seg!G18 -> 258.04987 | H16: =Seg!H18 -> 324.5365 | I16: =Seg!I18 -> 391.84471 | J16: =Seg!J18 -> 453.47142 | ... M16: =Seg!M18 -> 589.31132
A17: 合併營收年增 | B17: % | D17: =D16/C16-1 -> 0.22167038 | G17: =G16/D16-1 -> 0.2840474 | H17: =H16/G16-1 -> 0.25765029 | I17: =I16/H16-1 -> 0.207398 | J17: =J16/I16-1 -> 0.15727327 | K17: =K16/J16-1 -> 0.1074924 | L17: =L16/K16-1 -> 0.083187168 | M17: =M16/L16-1 -> 0.083304643
A18: 檢查：Advertising＋Other revenue－Family of Apps | B18: US$B | C18: =C12+C13-C14 -> 0 | D18: =D12+D13-D14 -> 0 | E18: =E12+E13-E14 -> 0 | F18: =F12+F13-F14 -> 0 | G18: =G12+G13-G14 -> 0 | H18: =H12+H13-H14 -> 0 | I18: =I12+I13-I14 -> 0 | J18: =J12+J13-J14 -> 0 | ... M18: =M12+M13-M14 -> 0
A19: 檢查：分部合計－合併營收 | B19: US$B | C19: =C14+C15-C16 -> 0 | D19: =D14+D15-D16 -> 0 | E19: =E14+E15-E16 -> 0 | F19: =F14+F15-F16 -> 0 | G19: =G14+G15-G16 -> 0 | H19: =H14+H15-H16 -> 0 | I19: =I14+I15-I16 -> 0 | J19: =J14+J15-J16 -> 0 | ... M19: =M14+M15-M16 -> 0
A20: 價格情境差額（相對 B 路徑） | B20: US$B | F20: =Seg!F11-Seg!F8 -> 0 | G20: =F20 -> 0 | H20: =Seg!H11-Seg!H8 -> 7.7033193 | I20: =Seg!I11-Seg!I8 -> 18.120343 | J20: =Seg!J11-Seg!J8 -> 30.668656 | K20: =Seg!K11-Seg!K8 -> 44.224202 | L20: =Seg!L11-Seg!L8 -> 47.828474 | M20: =Seg!M11-Seg!M8 -> 51.726495
A21: Family of Apps EBITDA（不含一次性） | B21: US$B | F21: =m_foa*(F14-F20)+inc_m*F20-Thesis!F63-Thesis!F64 -> 40.798461 | H21: =m_foa*(H14-H20)+inc_m*H20-Thesis!H63-Thesis!H64 -> 168.88164 | I21: =m_foa*(I14-I20)+inc_m*I20-Thesis!I63-Thesis!I64 -> 198.96732 | J21: =m_foa*(J14-J20)+inc_m*J20-Thesis!J63-Thesis!J64 -> 227.55142 | K21: =m_foa*(K14-K20)+inc_m*K20-Thesis!K63-Thesis!K64 -> 251.56025 | L21: =m_foa*(L14-L20)+inc_m*L20-Thesis!L63-Thesis!L64 -> 270.90801 | M21: =m_foa*(M14-M20)+inc_m*M20-Thesis!M63-Thesis!M64 -> 294.40049
A22: Family of Apps 折舊（基礎 ×(1 − RL 占比)＋新增 AI＋新增非 AI） | B22: US$B | F22: =Thesis!F68*(1-rl_da_sh)+Thesis!F61+Seg!F23 -> 9.0553129 | H22: =Thesis!H68*(1-rl_da_sh)+Thesis!H61+Seg!H23 -> 53.360319 | I22: =Thesis!I68*(1-rl_da_sh)+Thesis!I61+Seg!I23 -> 86.385116 | J22: =Thesis!J68*(1-rl_da_sh)+Thesis!J61+Seg!J23 -> 119.19948 | K22: =Thesis!K68*(1-rl_da_sh)+Thesis!K61+Seg!K23 -> 146.05922 | L22: =Thesis!L68*(1-rl_da_sh)+Thesis!L61+Seg!L23 -> 166.50029 | M22: =Thesis!M68*(1-rl_da_sh)+Thesis!M61+Seg!M23 -> 186.53747
A23: Family of Apps 營業利益 | B23: US$B | C23: =Q!J14 -> 87.109 | D23: =Q!K14 -> 102.469 | E23: =Q!L14 -> 67.411 | F23: =F21-F22 -> 31.743148 | G23: =E23+F23 -> 99.154148 | H23: =H21-H22 -> 115.52133 | I23: =I21-I22 -> 112.5822 | J23: =J21-J22 -> 108.35194 | K23: =K21-K22 -> 105.50103 | L23: =L21-L22 -> 104.40772 | M23: =M21-M22 -> 107.86302 | N23: 9M26 實績含一次性法律 12.29 與遣散 1.18（M5）
A24: Reality Labs 營業損益 | B24: US$B | C24: =Q!J15 -> -17.729 | D24: =Q!K15 -> -19.193 | E24: =Q!L15 -> -12.776 | F24: =-(rl_loss26+Q!L15) -> -5.724 | G24: =E24+F24 -> -18.5 | H24: =-rl_loss27 -> -15 | I24: =-(rl_loss27+(rl_loss32-rl_loss27)*(2028-2027)/5) -> -13 | J24: =-(rl_loss27+(rl_loss32-rl_loss27)*(2029-2027)/5) -> -11 | K24: =-(rl_loss27+(rl_loss32-rl_loss27)*(2030-2027)/5) -> -9 | L24: =-(rl_loss27+(rl_loss32-rl_loss27)*(2031-2027)/5) -> -7 | M24: =-(rl_loss27+(rl_loss32-rl_loss27)*(2032-2027)/5) -> -5 | N24: Q4 26＝2026 指引中點 − 9M 實績；FY2027 約 −15（法說）；之後線性到 FY2032 rl_loss32
A25: Reality Labs 折舊（基礎 × RL 占比） | B25: US$B | F25: =Thesis!F68*rl_da_sh -> 0.3577 | H25: =Thesis!H68*rl_da_sh -> 1.4308 | I25: =Thesis!I68*rl_da_sh -> 1.4308 | J25: =Thesis!J68*rl_da_sh -> 1.3761517 | K25: =Thesis!K68*rl_da_sh -> 1.2308073 | L25: =Thesis!L68*rl_da_sh -> 0.94389794 | M25: =Thesis!M68*rl_da_sh -> 0.74768472
A26: Reality Labs EBITDA | B26: US$B | F26: =F24+F25 -> -5.3663 | H26: =H24+H25 -> -13.5692 | I26: =I24+I25 -> -11.5692 | J26: =J24+J25 -> -9.6238483 | K26: =K24+K25 -> -7.7691927 | L26: =L24+L25 -> -6.0561021 | M26: =M24+M25 -> -4.2523153
A27: 分部營業利益合計 | B27: US$B | C27: =C23+C24 -> 69.38 | D27: =D23+D24 -> 83.276 | E27: =E23+E24 -> 54.635 | F27: =F23+F24 -> 26.019148 | G27: =G23+G24 -> 80.654148 | H27: =H23+H24 -> 100.52133 | I27: =I23+I24 -> 99.582202 | J27: =J23+J24 -> 97.351945 | ... M27: =M23+M24 -> 102.86302
A28: 合併 EBITDA（分部 EBITDA 合計） | B28: US$B | F28: =F21+F26 -> 35.432161 | H28: =H21+H26 -> 155.31244 | I28: =I21+I26 -> 187.39812 | J28: =J21+J26 -> 217.92757 | K28: =K21+K26 -> 243.79106 | L28: =L21+L26 -> 264.8519 | M28: =M21+M26 -> 290.14818
A29: 折舊與攤銷合計（基礎＋新增 AI＋新增非 AI） | B29: US$B | C29: =Q!J35 -> 15.498 | D29: =Q!K35 -> 18.616 | E29: =Q!L35 -> 19.509 | F29: =Thesis!F68+Thesis!F61+Seg!F23 -> 9.4130129 | G29: =E29+F29 -> 28.922013 | H29: =Thesis!H68+Thesis!H61+Seg!H23 -> 54.791119 | I29: =Thesis!I68+Thesis!I61+Seg!I23 -> 87.815916 | J29: =Thesis!J68+Thesis!J61+Seg!J23 -> 120.57563 | K29: =Thesis!K68+Thesis!K61+Seg!K23 -> 147.29003 | L29: =Thesis!L68+Thesis!L61+Seg!L23 -> 167.44418 | M29: =Thesis!M68+Thesis!M61+Seg!M23 -> 187.28516
A30: 其中：新增 AI 折舊 | B30: US$B | F30: =Thesis!F61 -> 2.2208445 | G30: =F30 -> 2.2208445 | H30: =Thesis!H61 -> 25.545235 | I30: =Thesis!I61 -> 57.204578 | J30: =Thesis!J61 -> 89.42825 | K30: =Thesis!K61 -> 117.18691 | L30: =Thesis!L61 -> 141.02861 | M30: =Thesis!M61 -> 162.57255
A31: 合併營業利益（財報口徑） | B31: US$B | C31: =Q!J16 -> 69.38 | D31: =Q!K16 -> 83.276 | E31: =Q!L16 -> 54.635 | F31: =F28-F29 -> 26.019148 | G31: =E31+F31 -> 80.654148 | H31: =H28-H29 -> 100.52133 | I31: =I28-I29 -> 99.582202 | J31: =J28-J29 -> 97.351945 | K31: =K28-K29 -> 96.50103 | L31: =L28-L29 -> 97.407719 | M31: =M28-M29 -> 102.86302 | N31: 預測期＝合併 EBITDA − 折舊合計（與分部合計獨立計算，下一列核對）
A32: 檢查：分部營業利益合計－合併營業利益 | B32: US$B | C32: =C27-C31 -> 0 | D32: =D27-D31 -> 0 | E32: =E27-E31 -> 0 | F32: =F27-F31 -> 0 | G32: =G27-G31 -> 0 | H32: =H27-H31 -> 0 | I32: =I27-I31 -> 0 | J32: =J27-J31 -> 0 | ... M32: =M27-M31 -> 0
A33: 一次性項目（營業利益內；負值＝費用） | B33: US$B | E33: =-ot_oi_9m -> -13.47 | F33: 0 | G33: =E33+F33 -> -13.47 | H33: 0 | I33: 0 | J33: 0 | K33: 0 | L33: 0 | M33: 0 | N33: Q2 法律 2.40＋遣散 1.18、Q3 法律 9.89（新聞稿）；預測期 0
A34: 營業利益（排除一次性） | B34: US$B | E34: =E31-E33 -> 68.105 | F34: =F31-F33 -> 26.019148 | G34: =G31-G33 -> 94.124148 | H34: =H31-H33 -> 100.52133 | I34: =I31-I33 -> 99.582202 | J34: =J31-J33 -> 97.351945 | K34: =K31-K33 -> 96.50103 | L34: =L31-L33 -> 97.407719 | M34: =M31-M33 -> 102.86302
A35: 自用 AI 影子效益（讀法 2；非財報營收） | B35: US$B | F35: =Thesis!F70 -> 4.1543738 | G35: =F35 -> 4.1543738 | H35: =Thesis!H70 -> 61.514412 | I35: =Thesis!I70 -> 119.71171 | J35: =Thesis!J70 -> 172.80224 | K35: =Thesis!K70 -> 212.74991 | L35: =Thesis!L70 -> 240.10595 | M35: =Thesis!M70 -> 255.13982
A36: 營業利益（評價口徑：排除一次性＋讀法 2 影子效益） | B36: US$B | E36: =E34 -> 68.105 | F36: =F34+(internal_ai_reading=2)*F35 -> 30.173522 | G36: =G34+(internal_ai_reading=2)*G35 -> 98.278522 | H36: =H34+(internal_ai_reading=2)*H35 -> 162.03574 | I36: =I34+(internal_ai_reading=2)*I35 -> 219.29391 | J36: =J34+(internal_ai_reading=2)*J35 -> 270.15419 | K36: =K34+(internal_ai_reading=2)*K35 -> 309.25094 | L36: =L34+(internal_ai_reading=2)*L35 -> 337.51367 | M36: =M34+(internal_ai_reading=2)*M35 -> 358.00284
A37: 營業利益率（財報口徑） | B37: % | C37: =C31/C16 -> 0.42176035 | D37: =D31/D16 -> 0.41437855 | E37: =E31/E16 -> 0.30066644 | F37: =F31/F16 -> 0.3408464 | G37: =G31/G16 -> 0.31255256 | H37: =H31/H16 -> 0.30973813 | I37: =I31/I16 -> 0.2541369 | J37: =J31/J16 -> 0.21468155 | ... M37: =M31/M16 -> 0.17454785
A38: 營業利益率（排除一次性） | B38: % | E38: =E34/E16 -> 0.37479432 | F38: =F34/F16 -> 0.3408464 | G38: =G34/G16 -> 0.36475177 | H38: =H34/H16 -> 0.30973813 | I38: =I34/I16 -> 0.2541369 | J38: =J34/J16 -> 0.21468155 | K38: =K34/K16 -> 0.19215039 | L38: =L34/L16 -> 0.17906025 | M38: =M34/M16 -> 0.17454785
A39: Family of Apps 營業利益率 | B39: % | C39: =C23/C14 -> 0.53653414 | D39: =D23/D14 -> 0.51554395 | E39: =E23/E14 -> 0.37359854 | F39: =F23/F14 -> 0.42086043 | G39: =G23/G14 -> 0.38753069 | H39: =H23/H14 -> 0.35832368 | I39: =I23/I14 -> 0.28889739 | J39: =J23/J14 -> 0.24010649 | ... M39: =M23/M14 -> 0.18382865
A40: 利息收入（期初現金 × r_cash） | B40: US$B | F40: =r_cash*CF!F31*0.25 -> 0.82449 | G40: =F40 -> 0.82449 | H40: =r_cash*CF!H31*1 -> 3.1597857 | I40: =r_cash*CF!I31*1 -> 1.6 | J40: =r_cash*CF!J31*1 -> 1.6 | K40: =r_cash*CF!K31*1 -> 2.3758941 | L40: =r_cash*CF!L31*1 -> 5.8770718 | M40: =r_cash*CF!M31*1 -> 10.901779
A41: 利息費用（期初債務 × r_debt） | B41: US$B | F41: =r_debt*CF!F38*0.25 -> 1.008 | G41: =F41 -> 1.008 | H41: =r_debt*CF!H38*1 -> 4.032 | I41: =r_debt*CF!I38*1 -> 4.3124875 | J41: =r_debt*CF!J38*1 -> 6.6074357 | K41: =r_debt*CF!K38*1 -> 6.6074357 | L41: =r_debt*CF!L38*1 -> 6.6074357 | M41: =r_debt*CF!M38*1 -> 6.6074357
A42: 業外收益合計 | B42: US$B | C42: =Q!J25 -> 1.283 | D42: =Q!K25 -> 2.656 | E42: =Q!L25 -> -1.126 | F42: =F40-F41 -> -0.18351 | G42: =E42+F42 -> -1.30951 | H42: =H40-H41 -> -0.87221434 | I42: =I40-I41 -> -2.7124875 | J42: =J40-J41 -> -5.0074357 | K42: =K40-K41 -> -4.2315416 | L42: =L40-L41 -> -0.73036387 | M42: =M40-M41 -> 4.2943436
...

Sheet CF
A1: CF — 現金流（US$B）。營運現金＝淨利＋折舊＋股權報酬＋營運資金 − 協議付款；資本支出（含融資租賃本金，公司口徑）＝AI（Thesis）＋非 AI（Seg）；自由現金流＝營運現金 − 資本支出。融資順序：現金 → 減少回購 → 新債（最低現金 40）
A2: 2026-10-29 強制轉換特別股 12.5（Q4 26 流入）；Class A 遠期出售 24.9 推定 FY2027 交割（fwd_on）；回購 2026 暫停、預設 FY2027 起 0；多州檢察長協議 12.7 分 10 年（10-Q 未載各年金額；FY2027 起每年 1.27 等額，第一年 ag_y1 前高後低只進 Sens）
A4: 收支關卡（地圖讀這兩列；模型期間 FY2026–FY2030，FY2026 含 9M 實績）
A5: 項目 | B5: 情境 A | C5: 情境 B | D5: 情境 C | E5: 說明
A6: 收支關卡：自由現金流扣股利（五年合計） | B6: =SUM(G27:K27) -> -19.56229 | C6: =SUM(G59:K59) -> 14.97977 | D6: =SUM(G91:K91) -> 49.007632 | E6: FY2026–FY2030 自由現金流（公司定義，已扣融資租賃本金與協議付款）− 普通股與特別股股利；FY2026 含 9M 實績。負值＝入不敷出
A7: 其中：五年新增舉債 | B7: =SUM(G35:K35) -> 56.40191 | C7: =SUM(G67:K67) -> 11.644114 | D7: =SUM(G99:K99) -> 0
A8: 其中：五年回購合計 | B8: =SUM(G34:K34) -> 0 | C8: =SUM(G66:K66) -> 0 | D8: =SUM(G98:K98) -> 0
A9: 是否需要舉債或停止回購 | B9: =IF(B7>0.001,"需要舉債"&IF(B8<4*bb_t-0.001,"且減少回購",""),IF(B8<4*bb_t-0.001,"不需舉債，但須減少回購","不需舉債，回購照目標")) -> 需要舉債 | C9: =IF(C7>0.001,"需要舉債"&IF(C8<4*bb_t-0.001,"且減少回購",""),IF(C8<4*bb_t-0.001,"不需舉債，但須減少回購","不需舉債，回購照目標")) -> 需要舉債 | D9: =IF(D7>0.001,"需要舉債"&IF(D8<4*bb_t-0.001,"且減少回購",""),IF(D8<4*bb_t-0.001,"不需舉債，但須減少回購","不需舉債，回購照目標")) -> 不需舉債，回購照目標 | E9: 依現金瀑布：現金 → 減少回購 → 新債（最低現金 40）；強制轉換特別股與遠期出售不計入關卡（融資）
A10: 檢查：收支關卡 − 首年起五年逐欄加總（FY2026＋…＋FY2030） | B10: =B6-(G27+H27+I27+J27+K27) -> 0 | C10: =C6-(G59+H59+I59+J59+K59) -> 0 | D10: =D6-(G91+H91+I91+J91+K91) -> 0
A11: 情境 A（AI 提高每則廣告價格）
A12: 項目 | B12: 單位 | C12: FY2024A | D12: FY2025A | E12: 9M26A | F12: Q4 26E | G12: FY2026E | H12: FY2027E | I12: FY2028E | J12: FY2029E | K12: FY2030E | L12: FY2031E | M12: FY2032E | N12: 說明
A13: 淨利 | B13: US$B | C13: =PL!C45 -> 62.36 | D13: =PL!D45 -> 60.458 | E13: =PL!E45 -> 52.481 | F13: =PL!F45 -> 21.701936 | G13: =PL!G45 -> 74.182936 | H13: =PL!H45 -> 83.705253 | I13: =PL!I45 -> 81.37056 | J13: =PL!J45 -> 77.569387 | ... M13: =PL!M45 -> 90.012187
A14: 折舊與攤銷 | B14: US$B | C14: =PL!C29 -> 15.498 | D14: =PL!D29 -> 18.616 | E14: =PL!E29 -> 19.509 | F14: =PL!F29 -> 9.4130129 | G14: =PL!G29 -> 28.922013 | H14: =PL!H29 -> 54.791119 | I14: =PL!I29 -> 87.815916 | J14: =PL!J29 -> 120.57563 | ... M14: =PL!M29 -> 187.28516
A15: 股權報酬（非現金） | B15: US$B | C15: =PL!C55 -> 16.69 | D15: =PL!D55 -> 20.427 | E15: =PL!E55 -> 21.053 | F15: =PL!F55 -> 8.5115611 | G15: =PL!G55 -> 29.564561 | H15: =PL!H55 -> 36.185819 | I15: =PL!I55 -> 43.690686 | J15: =PL!J55 -> 50.562063 | ... M15: =PL!M55 -> 65.708212
A16: 營運資金變動（流入＋） | B16: US$B | F16: 0 | G16: =F16 -> 0 | H16: =wc_k*(PL!H16-PL!G16) -> 0 | I16: =wc_k*(PL!I16-PL!H16) -> 0 | J16: =wc_k*(PL!J16-PL!I16) -> 0 | K16: =wc_k*(PL!K16-PL!J16) -> 0 | L16: =wc_k*(PL!L16-PL!K16) -> 0 | M16: =wc_k*(PL!M16-PL!L16) -> 0
A17: 多州檢察長協議付款（費用已於 2026Q2–Q3 認列 11.89） | B17: US$B | F17: 0 | G17: =F17 -> 0 | H17: =-ag_y1 -> -1.27 | I17: =-ag_rest -> -1.27 | J17: =-ag_rest -> -1.27 | K17: =-ag_rest -> -1.27 | L17: =-ag_rest -> -1.27 | M17: =-ag_rest -> -1.27 | N17: chat 端審查第 3 條：留在現金流與 DCF；FY2027＝ag_y1（基準等額 1.27），FY2028 起 ag_rest
A18: 其他非現金調整（實績差額：應計法律費用、遞延稅、營運資金等） | B18: US$B | C18: =Q!J37-C13-C14-C15 -> -3.22 | D18: =Q!K37-D13-D14-D15 -> 16.299 | E18: =Q!L37-E13-E14-E15 -> 3.831 | F18: 0 | G18: =E18+F18 -> 3.831 | H18: 0 | I18: 0 | J18: 0 | K18: 0 | L18: 0 | M18: 0
A19: 營運現金流 | B19: US$B | C19: =N(C13)+N(C14)+N(C15)+N(C16)+N(C17)+N(C18) -> 91.328 | D19: =N(D13)+N(D14)+N(D15)+N(D16)+N(D17)+N(D18) -> 115.8 | E19: =N(E13)+N(E14)+N(E15)+N(E16)+N(E17)+N(E18) -> 96.874 | F19: =N(F13)+N(F14)+N(F15)+N(F16)+N(F17)+N(F18) -> 39.62651 | G19: =N(G13)+N(G14)+N(G15)+N(G16)+N(G17)+N(G18) -> 136.50051 | H19: =N(H13)+N(H14)+N(H15)+N(H16)+N(H17)+N(H18) -> 173.41219 | I19: =N(I13)+N(I14)+N(I15)+N(I16)+N(I17)+N(I18) -> 211.60716 | J19: =N(J13)+N(J14)+N(J15)+N(J16)+N(J17)+N(J18) -> 247.43708 | ... M19: =N(M13)+N(M14)+N(M15)+N(M16)+N(M17)+N(M18) -> 341.73556
A20: 資本支出：AI（Thesis） | B20: US$B | F20: =Thesis!F50 -> 51.122525 | G20: =F20 -> 51.122525 | H20: =Thesis!H50 -> 223.5803 | I20: =Thesis!I50 -> 236.67056 | J20: =Thesis!J50 -> 202.625 | K20: =Thesis!K50 -> 164.75534 | L20: =Thesis!L50 -> 153.04837 | M20: =Thesis!M50 -> 148.55891
A21: 資本支出：非 AI（Seg） | B21: US$B | F21: =Seg!F22 -> 3.0534748 | G21: =F21 -> 3.0534748 | H21: =Seg!H22 -> 12.98146 | I21: =Seg!I22 -> 15.673789 | J21: =Seg!J22 -> 18.138857 | K21: =Seg!K22 -> 20.088646 | L21: =Seg!L22 -> 21.759763 | M21: =Seg!M22 -> 23.572453
A22: 資本支出合計（含融資租賃本金） | B22: US$B | C22: =Q!J40 -> 39.225 | D22: =Q!K40 -> 72.215 | E22: =Q!L40 -> 85.824 | F22: =F20+F21 -> 54.176 | G22: =E22+F22 -> 140 | H22: =H20+H21 -> 236.56176 | I22: =I20+I21 -> 252.34435 | J22: =J20+J21 -> 220.76386 | K22: =K20+K21 -> 184.84398 | L22: =L20+L21 -> 174.80813 | M22: =M20+M21 -> 172.13137
