Workbook

Sheet README
A1: 半導體設備市場模型 v0.1（AI 半導體 Project 步驟 5：設備與材料——設備部分） 2026-10-22
A2: 模型命題：設備需求＝為滿足記憶體、代工擴產所需的資本支出 × 設備占比；本模型回答核心問題 1——設備循環在 2027 還是 2028 見頂——並列出核心問題 2、3 的瓶頸表。公司份額與毛利留給公司層，v0.1 不做。
A4: 驅動因子 → 推導量
A5: In：公司資本支出（讀自 skhynix／micron／samsung／tsmc dist，不修改它們）、設備占資本支出比例（兩個來源給低／高）、SEMI 2026-07 分項、情境係數（Assumed）、AI 分類假設
A6: Mkt：2025 年用「SEMI 實績 − 已知廠」求其他廠基準（Derived）；2026 起記憶體＝三家資本支出 × 設備占比 ＋ 其他廠（基準 × 成長率，Assumed）；代工邏輯＝台積電 × 占比 ＋ 其他廠；測試與封裝＝SEMI；三情境 A／B／C；AI 增量占比；見頂年度
A7: Recon：對 SEMI、Lam、KLA、Morgan Stanley、Goldman Sachs 的差距；不為對上而調參。Sens：占比、匯率、2025 資本支出、其他廠成長率與基準、情境係數
A9: 結果摘要（v0.1 建置時；見 Mkt 摘要區）
A10: 設備總額（$B）：A 2025–2029＝134.7／181.6／222.7／250.3／262.6（2029 仍增，未在區間內見頂）；B＝134.7／181.6／222.7／222.7／211.6（見頂 2028，與 2027 同水準）；C＝134.7／181.6／222.7／178.2／178.2（見頂 2027）。
A11: 2026 年以後總額由下而上：三家記憶體與台積電的資本支出 × 設備占比，加「其他廠＝2025 基準 × 成長率（Assumed）」；其他前段維持 2025 年占比；測試與封裝為 SEMI 輸入。SEMI 2026 以後的 DRAM、NAND、代工邏輯、前段預測只用於對帳。
A12: AI 相關增量（先進邏輯＋DRAM／HBM＋先進封裝）占總增量（相對 2025 累計）：A 2026–2029＝64／64／62／61%；B 64／64／64／65%；C 64／64／72／72%。結論取決於情境係數（Assumed），不是預測。
A14: 限制
A15: (1) 2025 其他記憶體廠殘差近 0（＋0.05 $B）而非負值：三家資本支出 × 設備占比已幾乎填滿 SEMI 2025 記憶體總額；其他廠基準因此近 0，與其他廠實際存在矛盾。最可能原因：三星記憶體資本支出假設（DS 47.5 兆 × 75%）、資本支出與設備認列的時差、口徑差異。Sens 列出基準 ＋5／＋10／＋20 $B 的影響。
... A20: 瓶頸表（核心問題 2、3；v0.1 只做表，不入模）
A21: 瓶頸 | B21: 現況（v0.1 能找到的證據） | C21: 來源 | D21: 證據強度 | E21: 對本模型的含意
A22: 無塵室空間 | B22: 美光：FY27 資本支出『增量』一半以上為建築（FQ3 稿）、『增量』多數為建築且用於 2028 下半年後的無塵室（FQ4 法說）；KLA 稱客戶受廠房就緒度與廠房外殼限制，壓住 1H 出貨；SK 證券稱記憶體供給成長受無塵室限制至 2027；SK 海力士首座無塵室提前到 2027-02 | C22: Micron FQ3／FQ4 FY26 稿；Futurum（KLA FQ2 2026 摘要）；Cleanroom Technology（三星 P5） | D22: 強（美光一手）／中／弱 | E22: 解釋為何三家資本支出 × 設備占比可能超過 SEMI 記憶體總額；設備認列落後資本支出現金支出一至兩季，v0.1 未建模
A23: 長交期零組件 | B23: TrendForce：設備零組件（閥件管路、陶瓷、RF 電源、氣體箱）交期據報倍增、最長 40 個月；BigGo：日本關鍵零件最長 40 個月，沉積設備零組件由約 4 個月增至約 10 個月 | C23: TrendForce 2026-09-18；BigGo Finance | D23: 中（皆為「據報」）／弱；應用材料、Lam 的一手說法：未找到 | E23: 限制 2027–28 設備出貨上限，不改變需求面；若上限生效，情境 A 的 2028 可能偏高
A24: EUV | B24: ASML：2026 低 NA 產能約 65 台、2027 再增約 30%；2027、2028 需求超過供給（二手摘要）；各來源對 2027 台數不一致（56／80／約 85） | C24: ASML 2026 Q2 6-K；Pomegra、TechPowerUp、Tom's 類二手整理 | D24: 強（產能，一手）／弱（2027 台數與供不應求，二手） | E24: EUV 台數限制先進邏輯與 DRAM 的 2027–28 增量；v0.1 未建模
A25: 量測 | B25: KLA 稱 2026 先進封裝製程控制營收約 $1.1B；交期 18–24 個月僅見於社群貼文轉述 KLA 法說；「量測產能是瓶頸」本身的證據：未找到（搜尋 Onto、KLA 皆無交期或積壓一手數字） | C25: Zacks／TradingView；X（TheValueist）；Futurum | D25: 弱；瓶頸證據：未找到 | E25: 不影響 v0.1 數字；列為待查
A26: HBM 鍵合機 | B26: Hanmi 占 HBM TC 鍵合機營收 71.2%（TechInsights，2025 前三季）；SK 海力士 HBM4 約用 50 組 TC 鍵合機、約半數來自 ASMPT；預期約 100 台訂單（M15X 1b DRAM）；Hanmi 6 月接 SK 海力士約 15 台。供給短缺或交期：未找到 | C26: TrendForce 2025-12-12；The Elec；Techtimes 2026-06 | D26: 中（供應商集中度）；短缺：未找到 | E26: 鍵合機屬後段／封裝，v0.1 以 SEMI 金額為輸入，未建模
A28: 對帳差距說明
A29: 對帳差距 > 15% 的項目與可能原因（v0.1 建置時數值；未為對上而調參；2026 年以後總額由下而上，不由 SEMI 2026 以後預測決定）：
A30: (a) 2026 NAND +18.9%（模型 16.5 vs SEMI 13.9）：三家記憶體設備以 2025 年 SEMI DRAM／NAND 比例（72.4／27.6）拆分，而 SEMI 2026 的 NAND 占比降到 26.4%（資本支出轉向 DRAM／HBM）；其他 NAND 廠 2025 基準近 0，故 NAND 幾乎全來自三家。DRAM +11.8%、記憶體合計比 SEMI 高 7.2 $B，同一方向。
A31: (b) Goldman Sachs 2028 −21.4%（模型 A 220.9 vs 281）：GS 2027 年增約 +45%（150→218）、2028 +29%，分別高於 SEMI 的 +21.8%、+14.1%；GS 為最高的一組，可能納入不同口徑（KLA 口徑含先進封裝；廠務設備）、更激進的 DRAM／先進代工假設，且發布較晚（2026-08，SEMI 為 2026-07）。
A32: (c) 未超過 15% 的差距：2026 前段 159.6 比 SEMI 143.9 高 10.9%、比 Lam／KLA／GS 的 150 高 6.4%；2027 前段 197.3 比 SEMI 推得的 175.3 高 12.5%，落在 KLA 190（+3.8%）、Lam >200（−1.4%）、Morgan Stanley 202（−2.3%）、GS 218（−9.5%）之內；2028 前段 220.9 落在 Morgan Stanley 227 的 −2.7%。本模型高於 SEMI、低於其他來源，與「SEMI 7 月預測落後之後的上修」一致。B、C 在 2028 的差距是情境設計的結果。
A33: (d) 2025 殘差不是負值，而是近 0（DRAM＋NAND ＋0.05 $B）：三家資本支出 × 設備占比已幾乎填滿 SEMI 2025 記憶體總額，其他記憶體廠（長鑫、鎧俠、SanDisk、南亞、華邦、長江存儲）基準因此近 0，與它們確實有設備支出矛盾。最可能的原因：（1）三星記憶體資本支出假設（DS 47.5 兆 × 75%）；（2）資本支出（現金支出）與設備營收（出貨認列）的時差；（3）口徑，如 SEMI 與公司資本支出對建築、廠務的處理。Sens 列出其他記憶體廠基準 ＋5／＋10／＋20 $B 對 2027 總額的影響（＋3.5%／＋7.0%／＋14.0%）。
A35: 標記：Verified、Interested-party、Analogy、Assumed、Derived；Analogy 與 Assumed 給區間。SemiAnalysis 未使用。本檔不含任何個人投資部位或個人先驗。

Sheet In
A1: In — 輸入（藍字＝本模型輸入；綠字＝讀自其他模型 dist 成品，不在此修改；基準欄 E）。金額：十億美元（公司資本支出另標幣別）
A2: 每個數字附兩個來源（來源1、來源2）；找不到第二來源者寫「未找到」。SemiAnalysis 未使用。標記：Verified／Interested-party／Analogy／Assumed／Derived；Analogy、Assumed 給低／高區間。
A3: 鍵 | B3: 項目 | C3: 單位 | D3: 低 | E3: 基準 | F3: 高 | G3: 標記 | H3: 來源1 | I3: 來源2／備註
A4: A. 公司資本支出（2026–2029 讀自 dist 成品，三情境相同；2025 為本模型自行輸入——其他模型不含 2025——用於求「其他廠」2025 基準）
A5: fx | B5: 美元兌韓元（2025 亦沿用，Assumed） | C5: KRW/USD | D5: 1350 | E5: 1420 | F5: 1500 | G5: Derived | H5: 讀自 skhynix 模型 In!fx（Q2 2026 營收 79.32 兆 ≈ US$55.2B → 約 1,437） | I5: 三星模型 In!fx 同值（「同 SK 海力士」）；獨立匯率來源：本模型未另查
A6: cap_sk_26 | B6: SK 海力士資本支出 2026 | C6: 兆韓元 | E6: 48.7 | G6: Interested-party | H6: 20261022_SK海力士模型_v0.3.1.xlsx／Y!C21 | I6: 模型 In 標記：Verified／Interested-party｜指引「40 兆後段」；共識 48.7｜第二來源：未找到（模型只引共識）
A7: cap_sk_27 | B7: SK 海力士資本支出 2027 | C7: 兆韓元 | E7: 62.3 | G7: Interested-party | H7: 20261022_SK海力士模型_v0.3.1.xlsx／Y!D21 | I7: 模型 In 標記：Interested-party｜MarketScreener 共識 62.3｜第二來源：未找到（模型只引共識）
A8: cap_sk_28 | B8: SK 海力士資本支出 2028 | C8: 兆韓元 | E8: 71.2 | G8: Interested-party | H8: 20261022_SK海力士模型_v0.3.1.xlsx／Y!E21 | I8: 模型 In 標記：Interested-party｜MarketScreener 共識 71.2｜第二來源：未找到（模型只引共識）
A9: cap_sk_29 | B9: SK 海力士資本支出 2029 | C9: 兆韓元 | E9: 75 | G9: Assumed | H9: 20261022_SK海力士模型_v0.3.1.xlsx／Y!F21 | I9: 模型 In 標記：Assumed｜龍仁 2–6 期｜第二來源：未找到
A10: cap_mu_26 | B10: 美光資本支出 FY2026（淨；以 FY≈日曆年） | C10: $B | E10: 27.367 | G10: Verified | H10: 20261022_美光模型_v0.2.1.xlsx／Y!C21 | I10: 模型 In 標記：Verified｜FY26 8-K（毛 30.7）｜美光 FY 於 8–9 月結束，以日曆年近似，未調整（誤差方向：FY 比日曆年早約 4 個月）
A11: cap_mu_27 | B11: 美光資本支出 FY2027（淨；以 FY≈日曆年） | C11: $B | E11: 55 | G11: Derived | H11: 20261022_美光模型_v0.2.1.xlsx／Y!D21 | I11: 模型 In 標記：Derived｜FQ1 約 11.5、上半年約 25、下半年更高（書面說明）｜美光 FY 於 8–9 月結束，以日曆年近似，未調整（誤差方向：FY 比日曆年早約 4 個月）
A12: cap_mu_28 | B12: 美光資本支出 FY2028（淨；以 FY≈日曆年） | C12: $B | E12: 60 | G12: Assumed | H12: 20261022_美光模型_v0.2.1.xlsx／Y!E21 | I12: 模型 In 標記：Assumed｜None｜美光 FY 於 8–9 月結束，以日曆年近似，未調整（誤差方向：FY 比日曆年早約 4 個月）
A13: cap_mu_29 | B13: 美光資本支出 FY2029（淨；以 FY≈日曆年） | C13: $B | E13: 60 | G13: Assumed | H13: 20261022_美光模型_v0.2.1.xlsx／Y!F21 | I13: 模型 In 標記：Assumed｜None｜美光 FY 於 8–9 月結束，以日曆年近似，未調整（誤差方向：FY 比日曆年早約 4 個月）
A14: cap_ss_26 | B14: 三星記憶體資本支出 2026（只取記憶體） | C14: 兆韓元 | E14: 52.5 | G14: Derived／Assumed | H14: 20261022_三星電子模型_v0.1.1.xlsx／Y!C21 | I14: 口徑（三星模型 In）：Derived／Assumed｜全公司約 70（首爾經濟日報）× 記憶體約 75%（Assumed）；全公司×記憶體約 75% 為 Assumed；第二來源：未找到
A15: cap_ss_27 | B15: 三星記憶體資本支出 2027（只取記憶體） | C15: 兆韓元 | E15: 60 | G15: Assumed | H15: 20261022_三星電子模型_v0.1.1.xlsx／Y!D21 | I15: 口徑（三星模型 In）：Assumed｜P5 主體工程（>80 兆，多年）；全公司×記憶體約 75% 為 Assumed；第二來源：未找到
A16: cap_ss_28 | B16: 三星記憶體資本支出 2028（只取記憶體） | C16: 兆韓元 | E16: 66 | G16: Assumed | H16: 20261022_三星電子模型_v0.1.1.xlsx／Y!E21 | I16: 口徑（三星模型 In）：Assumed｜None；全公司×記憶體約 75% 為 Assumed；第二來源：未找到
A17: cap_ss_29 | B17: 三星記憶體資本支出 2029（只取記憶體） | C17: 兆韓元 | E17: 66 | G17: Assumed | H17: 20261022_三星電子模型_v0.1.1.xlsx／Y!F21 | I17: 口徑（三星模型 In）：Assumed｜None；全公司×記憶體約 75% 為 Assumed；第二來源：未找到
... A21: cap_ts_29 | B21: 台積電資本支出 2029 | C21: $B | E21: 95 | G21: Assumed | H21: 20261022_台積電模型_v0.2.xlsx／PL!E15 | I21: 模型 In 標記：Assumed｜None
A22: cap_sk_25 | B22: SK 海力士資本支出 2025 | C22: 兆韓元 | D22: 28 | E22: 30.2 | F22: 30.2 | G22: Interested-party | H22: Qz 2026-07-29（公司在 2Q26 法說稱 2026 預算相較 2025 的 30.2 兆韓元）https://qz.com/sk-hynix-q2-2026-earnings-record-profit-misses-estimates-072926 | I22: MLQ https://mlq.ai/news/sk-hynix-posts-record-605-trillion-won-operating-profit-raises-capacity-spending/ 同為 2Q26 法說摘要；另有產業估計約 28 兆（X：Jukan，低 28）。皆為搜尋摘要，未開啟原文
A23: cap_mu_25 | B23: 美光資本支出 FY2025（淨） | C23: $B | E23: 13.8 | G23: Verified | H23: 美光 FY25 8-K（淨 13.80）https://www.sec.gov/Archives/edgar/data/723125/000072312525000024/a2025q4ex991-pressrelease.htm | I23: 美光 FY25 10-K（毛 15.86、政府補助 2.01）https://www.sec.gov/Archives/edgar/data/723125/000072312525000028/mu-20250828.htm
A24: cap_ssds_25 | B24: 三星 DS（半導體）資本支出 2025 | C24: 兆韓元 | E24: 47.5 | G24: Verified | H24: 三星 IR：FY2025 CAPEX Results（DS 47.5、顯示 2.8、合計約 52.7）https://www.samsung.com/global/ir/reports-disclosures/public-disclosure-view.84547/ | I24: Korea Herald 合計 52.7 兆（https://koreaherald.com/article/10691933）；DS 47.5 另見 tech-insider（低權威）
A25: ss_mem | B25: 三星 DS 資本支出中記憶體占比（2025） | C25: % | D25: 0.65 | E25: 0.75 | F25: 0.85 | G25: Assumed | H25: 沿用三星模型 In（全公司 × 記憶體約 75%，Assumed）；三星不揭露記憶體分項 | I25: 未找到第二來源。此假設直接影響 2025 其他廠殘差
A26: cap_ts_25 | B26: 台積電資本支出 2025 | C26: $B | D26: 40 | E26: 40.9 | F26: 42 | G26: Interested-party | H26: Semiconductor Intelligence：台積電 2025 資本支出 40.9B https://www.semiconductorintelligence.com/capex-up-for-foundry-memory/ | I26: 台積電 3Q25 法說：全年指引 40–42B（https://www.fool.com/earnings/call-transcripts/2025/10/17/tsmc-tsm-q3-2025-earnings-call-transcript）
A27: B. 設備占資本支出比例：按公司分開（公司有揭露建築與設備比例者用公司揭露；未找到者用業界 58–70%，Analogy）
A28: sh_mu_25 | B28: 美光：FY25 設備占資本支出比例（建築基數的起點） | C28: % | D28: 0.58 | E28: 0.64 | F28: 0.7 | G28: Analogy | H28: SEMI 2025 WFE 116.9B（年中預測新聞稿）÷ Semiconductor Intelligence 2025 全球半導體資本支出 166B（https://www.semiconductorintelligence.com/capex-up-for-foundry-memory/）＝70.4% → 高 70% | I28: Rebound Capital（Substack）資本支出→晶圓前段設備轉換率約 58%（https://reboundcapital.substack.com/p/industry-deep-dive-semiconductor）→ 低 58%；基準取兩者中點 64%。業界合計值，未找到記憶體／代工分項。美光未揭露 FY25 建築／設備比例
A29: sh_mu_26 | B29: 美光：FY26 設備占資本支出比例 | C29: % | D29: 0.471 | E29: 0.521 | F29: 0.571 | G29: Derived | H29: FQ3 FY26 準備稿（https://s25.q4cdn.com/621799436/files/doc_financials/2026/q3/Q3-FY26-Prepared-Remarks.pdf）：「more than half the increase year over year in fiscal 2027 from construction capex as we pull in cleanroom capacity required to address long-term demand」（引自搜尋摘要，未能開啟全文）｜FQ4 FY26 法說（https://s25.q4cdn.com/621799436/files/doc_financials/2026/q4/Q4-FY26-Prepared-Remarks.pdf；逐字稿 https://www.fool.com/earnings/call-transcripts/2026/10/01/micron-mu-q4-2026-earnings-call-transcript/）：「A majority of the increase is for construction capex, most of which is to help accelerate clean room space availability in late calendar 2028 and beyond」「a meaningfully higher growth rate in construction CapEx as compared to equipment CapEx in fiscal 2027」（引自搜尋摘要）｜FY26 增量多數為無塵室建築（摘要轉述，非逐字） | I29: 注意：公司原文是「資本支出『增量』多數為建築」，不是「FY27 資本支出多數為建築」，故文稿本身不給出設備占比，只給出下限性的建築比例。推導：FY25 淨資本支出 13.80（8-K）× (1−64%) ＝建築基數；之後每年增量中建築占 c（c＝50%「多於一半」為上限情境，60%、70% 為 Assumed 區間）；FY26＝27.37、FY27＝55（美光模型）。FY28–FY29 無揭露，沿用 FY27。 引文為公司一手（Verified），比例為 Derived（FY25 基準 64% 為 Analogy、c 為 Assumed）
A30: sh_mu_27 | B30: 美光：FY27–FY29 設備占資本支出比例 | C30: % | D30: 0.385 | E30: 0.46 | F30: 0.535 | G30: Derived | H30: FQ3 FY26 準備稿（https://s25.q4cdn.com/621799436/files/doc_financials/2026/q3/Q3-FY26-Prepared-Remarks.pdf）：「more than half the increase year over year in fiscal 2027 from construction capex as we pull in cleanroom capacity required to address long-term demand」（引自搜尋摘要，未能開啟全文）；FQ4 FY26 法說（https://s25.q4cdn.com/621799436/files/doc_financials/2026/q4/Q4-FY26-Prepared-Remarks.pdf；逐字稿 https://www.fool.com/earnings/call-transcripts/2026/10/01/micron-mu-q4-2026-earnings-call-transcript/）：「A majority of the increase is for construction capex, most of which is to help accelerate clean room space availability in late calendar 2028 and beyond」「a meaningfully higher growth rate in construction CapEx as compared to equipment CapEx in fiscal 2027」（引自搜尋摘要） | I30: 注意：公司原文是「資本支出『增量』多數為建築」，不是「FY27 資本支出多數為建築」，故文稿本身不給出設備占比，只給出下限性的建築比例。推導：FY25 淨資本支出 13.80（8-K）× (1−64%) ＝建築基數；之後每年增量中建築占 c（c＝50%「多於一半」為上限情境，60%、70% 為 Assumed 區間）；FY26＝27.37、FY27＝55（美光模型）。FY28–FY29 無揭露，沿用 FY27。 高＝c 取 50%（「多於一半」）時的推導上限，約 53%。引文為公司一手（Verified），比例為 Derived
A31: sh_sk | B31: SK 海力士：設備占資本支出比例 | C31: % | D31: 0.58 | E31: 0.64 | F31: 0.7 | G31: Analogy | H31: SEMI 2025 WFE 116.9B（年中預測新聞稿）÷ Semiconductor Intelligence 2025 全球半導體資本支出 166B（https://www.semiconductorintelligence.com/capex-up-for-foundry-memory/）＝70.4% → 高 70% | I31: Rebound Capital（Substack）資本支出→晶圓前段設備轉換率約 58%（https://reboundcapital.substack.com/p/industry-deep-dive-semiconductor）→ 低 58%；基準取兩者中點 64%。業界合計值，未找到記憶體／代工分項。未找到公司揭露（定性：董事會 2026-02 核准 21.6 兆韓元完成龍仁第一晶圓廠結構工程與二至六期無塵室——TrendForce／UPI；無年度建築／設備比例）
A32: sh_ss | B32: 三星（記憶體）：設備占資本支出比例 | C32: % | D32: 0.58 | E32: 0.64 | F32: 0.7 | G32: Analogy | H32: SEMI 2025 WFE 116.9B（年中預測新聞稿）÷ Semiconductor Intelligence 2025 全球半導體資本支出 166B（https://www.semiconductorintelligence.com/capex-up-for-foundry-memory/）＝70.4% → 高 70% | I32: Rebound Capital（Substack）資本支出→晶圓前段設備轉換率約 58%（https://reboundcapital.substack.com/p/industry-deep-dive-semiconductor）→ 低 58%；基準取兩者中點 64%。業界合計值，未找到記憶體／代工分項。未找到公司揭露（P5 無塵室先行、設備發包另行；無建築／設備比例）；電子新聞稱「晶圓廠成本中設備 70–80%」為業界泛稱，非三星數字
A33: sh_fd | B33: 台積電（代工與邏輯）：設備占資本支出比例 | C33: % | D33: 0.58 | E33: 0.64 | F33: 0.7 | G33: Analogy | H33: SEMI 2025 WFE 116.9B（年中預測新聞稿）÷ Semiconductor Intelligence 2025 全球半導體資本支出 166B（https://www.semiconductorintelligence.com/capex-up-for-foundry-memory/）＝70.4% → 高 70% | I33: Rebound Capital（Substack）資本支出→晶圓前段設備轉換率約 58%（https://reboundcapital.substack.com/p/industry-deep-dive-semiconductor）→ 低 58%；基準取兩者中點 64%。業界合計值，未找到記憶體／代工分項。未找到公司揭露；台積電資本支出含先進封裝、光罩等（公司稱 10–20%），未另扣
A34: B2. 其他廠 2026 年以後成長率（Assumed；每個區塊合併成一個年成長率，套用 2026–2029。依據公司資本支出指引；不參照 SEMI 2026 以後預測）
A35: g_oth_dram | B35: 其他 DRAM 廠（長鑫、南亞、華邦等）設備成長率 | C35: %/年 | D35: 0.1 | E35: 0.18 | F35: 0.6 | G35: Assumed | H35: 長鑫：未揭露資本支出；研究估計月產能 360k／420k／500k 片（2026／27／28）→ +17%／+19%（https://faxiangongchang.com/en/reports/china-memory-chip-2026，弱）；南亞 2026 資本支出上限 NT$69.7B，2027 最高 NT$200B（約 4 倍，https://www.digitimes.com/news/a20260713PD211/nanya-technology-capex-capacity-2027.html）；華邦 2026 NT$42.1B（紀錄高，https://www.gate.com/news/detail/winbond-approves-507b-capex-expands-kaohsiung-fab-production-to-24000-23369791） | I35: 基準取長鑫產能成長（兩年平均約 18%，Analogy：產能成長代替資本支出）；低 10% 假設資本支出增速低於產能；高 60% 取南亞 2027 與鎧俠 FY26 的高增速。長鑫的資本支出指引：未找到；2025 年基準（華邦、南亞）：未找到
A36: g_oth_nand | B36: 其他 NAND 廠（鎧俠、SanDisk 合資、長江存儲等）設備成長率 | C36: %/年 | D36: 0 | E36: 0.18 | F36: 0.6 | G36: Assumed | H36: 鎧俠：FY25 ¥283.7B → FY26 ¥450B（+59%），FY26–28 年均約 ¥470B（https://www.trendforce.com/news/2026/06/03/news-kioxia-targets-%C2%A5470b-yearly-capex-in-fy26-28-up-66-from-fy25-reportedly-weighing-third-kitakami-fab-and-ma/）；SanDisk FY27 毛資本支出約營收 6%（含與鎧俠合資的分攤，與鎧俠重疊，不另加，https://www.fool.com/investing/2026/08/29/sandisk-and-kioxia-plan-to-invest-more-than-usd31-billion-in-japanese-memory-plants-about-60-of-what-they-have-spent-there-in-25-years/）；長江存儲：三廠 2026 底投產，金額未找到 | I36: 基準＝鎧俠 FY25→FY28 年複合 ((470/283.7)^(1/3)−1)≈18%（Derived，單一公司）；低 0% 為 FY27–28 持平；高 60% 為 FY26 單年增速。長江存儲資本支出指引：未找到
A37: g_oth_fd | B37: 其他代工與邏輯（中芯、Intel、三星晶圓代工、華虹、聯電、GlobalFoundries 等）設備成長率 | C37: %/年 | D37: 0 | E37: 0.08 | F37: 0.2 | G37: Assumed | H37: 中芯：2025 約 $8.1B、2026 約持平（https://www.trendforce.com/news/2026/03/30/news-smic-2026-action-plan-points-to-above-industry-growth-capex-held-in-line-with-2025/）；Intel：2026 提高到 >$20B（原約 $17–18B；2027「明顯更高」，https://www.gate.com/news/detail/intel-raises-2026-capex-guidance-to-over-20-billion-q2-earnings-beat-22949346） | I37: 基準＝中芯（0%）與 Intel（約 +11%，18→20）以 2025 金額加權約 +8%（Derived）；低 0%＝中芯持平；高 20% 假設 Intel 2027 大增。三星晶圓代工、華虹、聯電、GlobalFoundries 資本支出指引：未找到（三星僅有半導體合計）
A38: C. SEMI 2026-07 年中預測（Interested-party）。2025 為實績（由年增率回推），用於求其他廠基準；2026 以後的 SEMI 分項只用於對帳，不決定本模型總額（測試與封裝除外，v0.1 以 SEMI 為輸入）
A39: s_dram_26 | B39: SEMI DRAM 設備 2026 | C39: $B | E39: 38.8 | G39: Interested-party | H39: SEMI 2026-07-14 年中預測新聞稿 https://www.semi.org/en/semi-press-release/global-semiconductor-equipment-sales-forecast-to-reach-a-record-229-billion-dollars-in-2028-semi-reports | I39: 轉載：PR Newswire／Semiconductor Digest（同一原始發布，非獨立來源）；SEMI 為設備商協會，傾向樂觀（Interested-party）
A40: g_dram_26 | B40: SEMI DRAM 設備 2026 年增 | C40: % | E40: 0.39 | G40: Interested-party | H40: SEMI 2026-07-14 年中預測新聞稿 https://www.semi.org/en/semi-press-release/global-semiconductor-equipment-sales-forecast-to-reach-a-record-229-billion-dollars-in-2028-semi-reports | I40: 轉載：PR Newswire／Semiconductor Digest（同一原始發布，非獨立來源）；SEMI 為設備商協會，傾向樂觀（Interested-party）
A41: g_dram_27 | B41: SEMI DRAM 設備 2027 年增 | C41: % | E41: 0.274 | G41: Interested-party | H41: SEMI 2026-07-14 年中預測新聞稿 https://www.semi.org/en/semi-press-release/global-semiconductor-equipment-sales-forecast-to-reach-a-record-229-billion-dollars-in-2028-semi-reports（2027 前段 +21.8% 為使用者提供並經搜尋確認；其餘分項年增來自新聞稿摘要） | I41: 轉載：PR Newswire／Semiconductor Digest（同一原始發布，非獨立來源）；SEMI 為設備商協會，傾向樂觀（Interested-party）
A42: g_dram_28 | B42: SEMI DRAM 設備 2028 年增 | C42: % | E42: 0.15 | G42: Interested-party | H42: SEMI 2026-07-14 年中預測新聞稿 https://www.semi.org/en/semi-press-release/global-semiconductor-equipment-sales-forecast-to-reach-a-record-229-billion-dollars-in-2028-semi-reports | I42: 轉載：PR Newswire／Semiconductor Digest（同一原始發布，非獨立來源）；SEMI 為設備商協會，傾向樂觀（Interested-party）；DRAM 2028 推得 56.85 vs 報導 56.9、NAND 20.87 vs 20.8（捨入）
A43: s_nand_26 | B43: SEMI NAND 設備 2026 | C43: $B | E43: 13.9 | G43: Interested-party | H43: SEMI 2026-07-14 年中預測新聞稿 https://www.semi.org/en/semi-press-release/global-semiconductor-equipment-sales-forecast-to-reach-a-record-229-billion-dollars-in-2028-semi-reports | I43: 轉載：PR Newswire／Semiconductor Digest（同一原始發布，非獨立來源）；SEMI 為設備商協會，傾向樂觀（Interested-party）
...

Sheet Mkt
A1: Mkt — 半導體設備市場（十億美元）：由下而上（公司資本支出 × 設備占比）＋ 其他廠（2025 基準 × 成長率）＋ SEMI 後段；三情境
A2: 2025＝由下而上（三家＋台積電資本支出 × 設備占比）＋其他廠基準（SEMI 實績減已知廠）；2026 起其他廠＝基準 × 成長率（Assumed），總額由下而上，不由 SEMI 2026 以後預測決定。SEMI 2026 以後的分項只用於對帳。
A3: 項目 | B3: 單位 | C3: 2025 | D3: 2026 | E3: 2027 | F3: 2028 | G3: 2029 | H3: 說明
A4: 摘要（各情境設備總額、年增、AI 增量占比、見頂年度）
A5: 情境 A
A6: 設備總額 | B6: $B | C6: =C100 -> 134.68936 | D6: =D100 -> 181.58883 | E6: =E100 -> 222.69572 | F6: =F100 -> 250.26573 | G6: =G100 -> 262.6074
A7: 年增 | B7: % | D7: =D101 -> 0.3482047 | E7: =E101 -> 0.22637345 | F7: =F101 -> 0.12380128 | G7: =G101 -> 0.049314255
A8: 其中晶圓前段 | B8: $B | C8: =C98 -> 116.89683 | D8: =D98 -> 159.58883 | E8: =E98 -> 197.26565 | F8: =F98 -> 220.86573 | G8: =G98 -> 230.8554
A9: AI 相關設備 | B9: $B | C9: =C103 -> 67.002575 | D9: =D103 -> 97.069138 | E9: =E103 -> 122.85541 | F9: =F103 -> 139.13689 | G9: =G103 -> 144.92488
A10: AI 增量占總增量（相對 2025 累計） | B10: % | D10: =D105 -> 0.64108538 | E10: =E105 -> 0.63464549 | F10: =F105 -> 0.62412687 | G10: =G105 -> 0.60915802
A11: AI 增量占總增量（當年） | B11: % | D11: =D106 -> 0.64108538 | E11: =E106 -> 0.62729812 | F11: =F106 -> 0.59055033 | G11: =G106 -> 0.46897881
A12: 見頂年度 | C12: =C107 -> 2029
A13: 情境 B
A14: 設備總額 | B14: $B | C14: =C119 -> 134.68936 | D14: =D119 -> 181.58883 | E14: =E119 -> 222.69572 | F14: =F119 -> 222.69572 | G14: =G119 -> 211.56093
A15: 年增 | B15: % | D15: =D120 -> 0.3482047 | E15: =E120 -> 0.22637345 | F15: =F120 -> 0 | G15: =G120 -> -0.05
A16: 其中晶圓前段 | B16: $B | C16: =C117 -> 116.89683 | D16: =D117 -> 159.58883 | E16: =E117 -> 197.26565 | F16: =F117 -> 197.26565 | G16: =G117 -> 187.40237
A17: AI 相關設備 | B17: $B | C17: =C122 -> 67.002575 | D17: =D122 -> 97.069138 | E17: =E122 -> 122.85541 | F17: =F122 -> 122.85541 | G17: =G122 -> 116.71264
A18: AI 增量占總增量（相對 2025 累計） | B18: % | D18: =D124 -> 0.64108538 | E18: =E124 -> 0.63464549 | F18: =F124 -> 0.63464549 | G18: =G124 -> 0.64666386
A19: AI 增量占總增量（當年） | B19: % | D19: =D125 -> 0.64108538 | E19: =E125 -> 0.62729812 | F19: =F125 -> n/a | G19: =G125 -> 0.55167389
A20: 見頂年度 | C20: =C126 -> 2028
A21: 情境 C
A22: 設備總額 | B22: $B | C22: =C138 -> 134.68936 | D22: =D138 -> 181.58883 | E22: =E138 -> 222.69572 | F22: =F138 -> 178.15658 | G22: =G138 -> 178.15658
A23: 年增 | B23: % | D23: =D139 -> 0.3482047 | E23: =E139 -> 0.22637345 | F23: =F139 -> -0.2 | G23: =G139 -> 0
A24: 其中晶圓前段 | B24: $B | C24: =C136 -> 116.89683 | D24: =D136 -> 159.58883 | E24: =E136 -> 197.26565 | F24: =F136 -> 157.81252 | G24: =G136 -> 157.81252
A25: AI 相關設備 | B25: $B | C25: =C141 -> 67.002575 | D25: =D141 -> 97.069138 | E25: =E141 -> 122.85541 | F25: =F141 -> 98.284331 | G25: =G141 -> 98.284331
A26: AI 增量占總增量（相對 2025 累計） | B26: % | D26: =D143 -> 0.64108538 | E26: =E143 -> 0.63464549 | F26: =F143 -> 0.71966322 | G26: =G143 -> 0.71966322
A27: AI 增量占總增量（當年） | B27: % | D27: =D144 -> 0.64108538 | E27: =E144 -> 0.62729812 | F27: =F144 -> 0.55167389 | G27: =G144 -> n/a
A28: 見頂年度 | C28: =C145 -> 2027
A40: 1. SEMI 分項金額（A 路徑的天花板與「其他廠」推導基礎）
A41: SEMI DRAM 設備 | B41: $B | C41: =D41/(1+g_dram_26) -> 27.913669 | D41: =s_dram_26 -> 38.8 | E41: =D41*(1+g_dram_27) -> 49.4312 | F41: =E41*(1+g_dram_28) -> 56.84588 | G41: =F41*(1+g29) -> 61.39355 | H41: 2026 新聞稿值；2025 由年增回推；2027、2028 年增連乘；2029 為 g29（Assumed）
A42: SEMI NAND 設備 | B42: $B | C42: =D42/(1+g_nand_26) -> 10.635042 | D42: =s_nand_26 -> 13.9 | E42: =D42*(1+g_nand_27) -> 18.2229 | F42: =E42*(1+g_nand_28) -> 20.86522 | G42: =F42*(1+g29) -> 22.534438 | H42: 2026 新聞稿值；2025 由年增回推；2027、2028 年增連乘；2029 為 g29（Assumed）
A43: SEMI 代工與邏輯設備 | B43: $B | C43: =D43/(1+g_fd_26) -> 65.601346 | D43: =s_fd_26 -> 78 | E43: =D43*(1+g_fd_27) -> 92.118 | F43: =E43*(1+g_fd_28) -> 104.64605 | G43: =F43*(1+g29) -> 113.01773 | H43: 2026 新聞稿值；2025 由年增回推；2027、2028 年增連乘；2029 為 g29（Assumed）
A44: SEMI 晶圓前段設備（WFE） | B44: $B | C44: =D44/(1+g_wfe_26) -> 116.89683 | D44: =s_wfe_26 -> 143.9 | E44: =D44*(1+g_wfe_27) -> 175.2702 | F44: =E44*(1+g_wfe_28) -> 199.9833 | G44: =F44*(1+g29) -> 215.98196 | H44: 2026 新聞稿值；2025 由年增回推；2027、2028 年增連乘；2029 為 g29（Assumed）
A45: SEMI 測試設備 | B45: $B | C45: =D45/(1+g_test_26) -> 11.679389 | D45: =s_test_26 -> 15.3 | E45: =SQRT(D45*F45) -> 17.839282 | F45: =s_test_28 -> 20.8 | G45: =F45*(1+g29) -> 22.464 | H45: 2026、2028 新聞稿值；2027 幾何內插（Derived，未找到年中預測 2027 值）
A46: SEMI 組裝與封裝設備 | B46: $B | C46: =D46/(1+g_pkg_26) -> 6.1131387 | D46: =s_pkg_26 -> 6.7 | E46: =SQRT(D46*F46) -> 7.5907839 | F46: =s_pkg_28 -> 8.6 | G46: =F46*(1+g29) -> 9.288 | H46: 2026、2028 新聞稿值；2027 幾何內插（Derived，未找到年中預測 2027 值）
A47: SEMI 其他前段（WFE − 代工邏輯 − DRAM − NAND） | B47: $B | C47: =C44-C43-C41-C42 -> 12.746775 | D47: =D44-D43-D41-D42 -> 13.2 | E47: =E44-E43-E41-E42 -> 15.4981 | F47: =F44-F43-F41-F42 -> 17.62615 | G47: =G44-G43-G41-G42 -> 19.036242 | H47: Derived：類比、功率、光罩、廠務設備等；v0.1 不由下而上，沿用 SEMI 差額
A48: SEMI 設備合計（WFE＋測試＋封裝） | B48: $B | C48: =C44+C45+C46 -> 134.68936 | D48: =D44+D45+D46 -> 165.9 | E48: =E44+E45+E46 -> 200.70027 | F48: =F44+F45+F46 -> 229.3833 | G48: =G44+G45+G46 -> 247.73396 | H48: 2026 應＝165.9、2028 應＝229.5（捨入差見 Recon）
A49: 2025 年 SEMI DRAM ÷（DRAM＋NAND）（各年沿用，Assumed） | B49: % | C49: =C41/(C41+C42) -> 0.7241142 | D49: =$C49 -> 0.7241142 | E49: =$C49 -> 0.7241142 | F49: =$C49 -> 0.7241142 | G49: =$C49 -> 0.7241142 | H49: 把各廠記憶體設備拆成 DRAM（含 HBM）與 NAND：假設三家組合同 2025 年 SEMI 市場組合
A50: SEMI 其他前段占（記憶體＋代工邏輯）比例（2025；各年沿用，Assumed） | B50: % | C50: =C47/(C41+C42+C43) -> 0.12238856 | D50: =$C50 -> 0.12238856 | E50: =$C50 -> 0.12238856 | F50: =$C50 -> 0.12238856 | G50: =$C50 -> 0.12238856 | H50: 其他前段（類比、功率、光罩等）v0.1 維持 2025 年占比
A52: 2. 記憶體晶圓前段設備（2025：三家由下而上＋SEMI 殘差求其他廠基準；2026 起：其他廠＝基準 × 成長率）
...

Sheet Recon
A1: Recon — 本模型與外部來源對帳。不為對上來源而調整參數；差距 > 15% 的原因見 README。模型欄＝晶圓前段設備（除非另註）；來源口徑各異（SEMI WFE、分析師 WFE、KLA 含先進封裝）
A3: 項目 | B3: 年度 | C3: 來源 | D3: 來源值 | E3: 模型 A | F3: 差距 A | G3: 模型 B | H3: 差距 B | I3: 模型 C | J3: 差距 C | K3: A 差距 > 門檻 | L3: 口徑備註
A4: 設備合計 | B4: 2026 | C4: SEMI 2026-07 | D4: =s_tot_26 -> 165.9 | E4: =Mkt!D100 -> 181.58883 | F4: =E4/D4-1 -> 0.094567984 | G4: =Mkt!D119 -> 181.58883 | H4: =G4/D4-1 -> 0.094567984 | I4: =Mkt!D138 -> 181.58883 | J4: =I4/D4-1 -> 0.094567984 | K4: =IF(ABS(F4)>rc_thr,"超過門檻","") | L4: SEMI 公布 165.9
A5: 晶圓前段 | B5: 2026 | C5: SEMI 2026-07 | D5: =s_wfe_26 -> 143.9 | E5: =Mkt!D98 -> 159.58883 | F5: =E5/D5-1 -> 0.10902591 | G5: =Mkt!D117 -> 159.58883 | H5: =G5/D5-1 -> 0.10902591 | I5: =Mkt!D136 -> 159.58883 | J5: =I5/D5-1 -> 0.10902591 | K5: =IF(ABS(F5)>rc_thr,"超過門檻","")
A6: 代工與邏輯 | B6: 2026 | C6: SEMI 2026-07 | D6: =s_fd_26 -> 78 | E6: =Mkt!D91+Mkt!D92 -> 82.259373 | F6: =E6/D6-1 -> 0.05460735 | G6: =Mkt!D110+Mkt!D111 -> 82.259373 | H6: =G6/D6-1 -> 0.05460735 | I6: =Mkt!D129+Mkt!D130 -> 82.259373 | J6: =I6/D6-1 -> 0.05460735 | K6: =IF(ABS(F6)>rc_thr,"超過門檻","") | L6: 模型＝代工邏輯設備合計（台積電由下而上＋其他殘差）
A7: DRAM | B7: 2026 | C7: SEMI 2026-07 | D7: =s_dram_26 -> 38.8 | E7: =Mkt!D93 -> 43.394295 | F7: =E7/D7-1 -> 0.11840967 | G7: =Mkt!D112 -> 43.394295 | H7: =G7/D7-1 -> 0.11840967 | I7: =Mkt!D131 -> 43.394295 | J7: =I7/D7-1 -> 0.11840967 | K7: =IF(ABS(F7)>rc_thr,"超過門檻","") | L7: 模型記憶體設備 × SEMI DRAM 占比
A8: NAND | B8: 2026 | C8: SEMI 2026-07 | D8: =s_nand_26 -> 13.9 | E8: =Mkt!D94 -> 16.533124 | F8: =E8/D8-1 -> 0.18943339 | G8: =Mkt!D113 -> 16.533124 | H8: =G8/D8-1 -> 0.18943339 | I8: =Mkt!D132 -> 16.533124 | J8: =I8/D8-1 -> 0.18943339 | K8: =IF(ABS(F8)>rc_thr,"超過門檻","") -> 超過門檻
A9: 晶圓前段年增 | B9: 2027 | C9: SEMI 2026-07（+21.8%） | D9: =g_wfe_27 -> 0.218 | E9: =Mkt!E102 -> 0.23608685 | F9: =E9-D9 -> 0.018086851 | G9: =Mkt!E121 -> 0.23608685 | H9: =G9-D9 -> 0.018086851 | I9: =Mkt!E140 -> 0.23608685 | J9: =I9-D9 -> 0.018086851 | K9: =IF(ABS(F9)>0.05,"超過 5 個百分點","") | L9: 年增率之差以百分點計
A10: 晶圓前段 | B10: 2027 | C10: SEMI 2026-07（由 2026 值連乘年增） | D10: =Mkt!E44 -> 175.2702 | E10: =Mkt!E98 -> 197.26565 | F10: =E10/D10-1 -> 0.12549454 | G10: =Mkt!E117 -> 197.26565 | H10: =G10/D10-1 -> 0.12549454 | I10: =Mkt!E136 -> 197.26565 | J10: =I10/D10-1 -> 0.12549454 | K10: =IF(ABS(F10)>rc_thr,"超過門檻","") | L10: SEMI 2027 絕對金額為推得（143.9×1.218）
A11: 晶圓前段 | B11: 2028 | C11: SEMI 2026-07（連乘） | D11: =Mkt!F44 -> 199.9833 | E11: =Mkt!F98 -> 220.86573 | F11: =E11/D11-1 -> 0.10442089 | G11: =Mkt!F117 -> 197.26565 | H11: =G11/D11-1 -> -0.013589363 | I11: =Mkt!F136 -> 157.81252 | J11: =I11/D11-1 -> -0.21087149 | K11: =IF(ABS(F11)>rc_thr,"超過門檻","") | L11: 新聞稿稱「達 200B」
A12: 設備合計 | B12: 2028 | C12: SEMI 2026-07 | D12: =s_tot_28 -> 229.5 | E12: =Mkt!F100 -> 250.26573 | F12: =E12/D12-1 -> 0.090482497 | G12: =Mkt!F119 -> 222.69572 | H12: =G12/D12-1 -> -0.029648284 | I12: =Mkt!F138 -> 178.15658 | J12: =I12/D12-1 -> -0.22371863 | K12: =IF(ABS(F12)>rc_thr,"超過門檻","") | L12: 公布 229.5；分項加總 229.4
A13: 晶圓前段 | B13: 2026 | C13: Lam Research（低 150B） | D13: =rc_lam26 -> 150 | E13: =Mkt!D98 -> 159.58883 | F13: =E13/D13-1 -> 0.063925524 | G13: =Mkt!D117 -> 159.58883 | H13: =G13/D13-1 -> 0.063925524 | I13: =Mkt!D136 -> 159.58883 | J13: =I13/D13-1 -> 0.063925524 | K13: =IF(ABS(F13)>rc_thr,"超過門檻","") | L13: Lam 2026-10 法說另稱 mid-150
A14: 晶圓前段 | B14: 2026 | C14: KLA（低 150B；含先進封裝） | D14: =rc_kla26 -> 150 | E14: =Mkt!D98 -> 159.58883 | F14: =E14/D14-1 -> 0.063925524 | G14: =Mkt!D117 -> 159.58883 | H14: =G14/D14-1 -> 0.063925524 | I14: =Mkt!D136 -> 159.58883 | J14: =I14/D14-1 -> 0.063925524 | K14: =IF(ABS(F14)>rc_thr,"超過門檻","") | L14: KLA 口徑含先進封裝，2025 基準約 120 vs SEMI 116.9
A15: 晶圓前段 | B15: 2027 | C15: KLA 規劃（約 190B） | D15: =rc_kla27 -> 190 | E15: =Mkt!E98 -> 197.26565 | F15: =E15/D15-1 -> 0.038240277 | G15: =Mkt!E117 -> 197.26565 | H15: =G15/D15-1 -> 0.038240277 | I15: =Mkt!E136 -> 197.26565 | J15: =I15/D15-1 -> 0.038240277 | K15: =IF(ABS(F15)>rc_thr,"超過門檻","")
A16: 晶圓前段 | B16: 2027 | C16: Lam Research（>200B；額外對照） | D16: =rc_lam27 -> 200 | E16: =Mkt!E98 -> 197.26565 | F16: =E16/D16-1 -> -0.013671737 | G16: =Mkt!E117 -> 197.26565 | H16: =G16/D16-1 -> -0.013671737 | I16: =Mkt!E136 -> 197.26565 | J16: =I16/D16-1 -> -0.013671737 | K16: =IF(ABS(F16)>rc_thr,"超過門檻","") | L16: 取下限
A17: 晶圓前段 | B17: 2027 | C17: Morgan Stanley（itiger 二手轉述 https://www.itiger.com/news/2649678863） | D17: =rc_ms27 -> 202 | E17: =Mkt!E98 -> 197.26565 | F17: =E17/D17-1 -> -0.023437364 | G17: =Mkt!E117 -> 197.26565 | H17: =G17/D17-1 -> -0.023437364 | I17: =Mkt!E136 -> 197.26565 | J17: =I17/D17-1 -> -0.023437364 | K17: =IF(ABS(F17)>rc_thr,"超過門檻","") | L17: itiger 二手轉述（2026-07-06）：2027 由 191 上修到 202；連結見 In 頁
A18: 晶圓前段 | B18: 2028 | C18: Morgan Stanley（itiger 二手轉述 https://www.itiger.com/news/2649678863） | D18: =rc_ms28 -> 227 | E18: =Mkt!F98 -> 220.86573 | F18: =E18/D18-1 -> -0.027023202 | G18: =Mkt!F117 -> 197.26565 | H18: =G18/D18-1 -> -0.13098831 | I18: =Mkt!F136 -> 157.81252 | J18: =I18/D18-1 -> -0.30479065 | K18: =IF(ABS(F18)>rc_thr,"超過門檻","") | L18: itiger 二手轉述：2028 由 215 上修到 227
A19: 晶圓前段 | B19: 2026 | C19: Goldman Sachs | D19: =rc_gs26 -> 150 | E19: =Mkt!D98 -> 159.58883 | F19: =E19/D19-1 -> 0.063925524 | G19: =Mkt!D117 -> 159.58883 | H19: =G19/D19-1 -> 0.063925524 | I19: =Mkt!D136 -> 159.58883 | J19: =I19/D19-1 -> 0.063925524 | K19: =IF(ABS(F19)>rc_thr,"超過門檻","")
A20: 晶圓前段 | B20: 2027 | C20: Goldman Sachs | D20: =rc_gs27 -> 218 | E20: =Mkt!E98 -> 197.26565 | F20: =E20/D20-1 -> -0.095111686 | G20: =Mkt!E117 -> 197.26565 | H20: =G20/D20-1 -> -0.095111686 | I20: =Mkt!E136 -> 197.26565 | J20: =I20/D20-1 -> -0.095111686 | K20: =IF(ABS(F20)>rc_thr,"超過門檻","")
A21: 晶圓前段 | B21: 2028 | C21: Goldman Sachs | D21: =rc_gs28 -> 281 | E21: =Mkt!F98 -> 220.86573 | F21: =E21/D21-1 -> -0.21400095 | G21: =Mkt!F117 -> 197.26565 | H21: =G21/D21-1 -> -0.297987 | I21: =Mkt!F136 -> 157.81252 | J21: =I21/D21-1 -> -0.4383896 | K21: =IF(ABS(F21)>rc_thr,"超過門檻","") -> 超過門檻
A23: 核對：SEMI 2026 分項加總
A24: DRAM＋NAND＋代工邏輯＋其他前段 − WFE | D24: =Mkt!D41+Mkt!D42+Mkt!D43+Mkt!D47-Mkt!D44 -> 0
A25: 注意：2026 年以後 A 路徑的總額由下而上（其他廠＝2025 基準 × 成長率，Assumed），不由 SEMI 2026 以後預測決定（測試與封裝除外，v0.1 以 SEMI 為輸入），所以對 SEMI 與各來源的差距有意義。2025 年的其他廠基準由「SEMI 實績減已知廠」求得。

Sheet Sens
A1: Sens — 一次動一個輸入（低／高取 In 的區間）；輸出：情境 A 2027、2028、2029 設備總額（$B）。最後兩組列出「其他記憶體廠 2025 基準」若不為 0 對總額的影響（2025 殘差為負時基準取 0）
A3: 輸入 | B3: 2027 A | C3: 相對基準 | D3: 2028 A | E3: 相對基準 | F3: 2029 A | G3: 相對基準 | H3: 說明
A4: 基準 | B4: =((cap_sk_27*1000/fx*sh_sk+cap_mu_27*sh_mu_27+cap_ss_27*1000/fx*sh_ss)+(MAX(Mkt!$C$41-(cap_sk_25*1000/fx*sh_sk+cap_mu_25*sh_mu_25+cap_ssds_25*ss_mem*1000/fx*sh_ss)*Mkt!$C$49,0)+0*Mkt!$C$49)*(1+g_oth_dram)^2+(MAX(Mkt!$C$42-(cap_sk_25*1000/fx*sh_sk+cap_mu_25*sh_mu_25+cap_ssds_25*ss_mem*1000/fx*sh_ss)*(1-Mkt!$C$49),0)+0*(1-Mkt!$C$49))*(1+g_oth_nand)^2)+(cap_ts_27*sh_fd+MAX(Mkt!$C$43-cap_ts_25*sh_fd,0)*(1+g_oth_fd)^2)+Mkt!E50*(((cap_sk_27*1000/fx*sh_sk+cap_mu_27*sh_mu_27+cap_ss_27*1000/fx*sh_ss)+(MAX(Mkt!$C$41-(cap_sk_25*1000/fx*sh_sk+cap_mu_25*sh_mu_25+cap_ssds_25*ss_mem*1000/fx*sh_ss)*Mkt!$C$49,0)+0*Mkt!$C$49)*(1+g_oth_dram)^2+(MAX(Mkt!$C$42-(cap_sk_25*1000/fx*sh_sk+cap_mu_25*sh_mu_25+cap_ssds_25*ss_mem*1000/fx*sh_ss)*(1-Mkt!$C$49),0)+0*(1-Mkt!$C$49))*(1+g_oth_nand)^2)+(cap_ts_27*sh_fd+MAX(Mkt!$C$43-cap_ts_25*sh_fd,0)*(1+g_oth_fd)^2))+Mkt!E87+Mkt!E88 -> 222.69572 | C4: =B4/B$4-1 -> 0 | D4: =((cap_sk_28*1000/fx*sh_sk+cap_mu_28*sh_mu_27+cap_ss_28*1000/fx*sh_ss)+(MAX(Mkt!$C$41-(cap_sk_25*1000/fx*sh_sk+cap_mu_25*sh_mu_25+cap_ssds_25*ss_mem*1000/fx*sh_ss)*Mkt!$C$49,0)+0*Mkt!$C$49)*(1+g_oth_dram)^3+(MAX(Mkt!$C$42-(cap_sk_25*1000/fx*sh_sk+cap_mu_25*sh_mu_25+cap_ssds_25*ss_mem*1000/fx*sh_ss)*(1-Mkt!$C$49),0)+0*(1-Mkt!$C$49))*(1+g_oth_nand)^3)+(cap_ts_28*sh_fd+MAX(Mkt!$C$43-cap_ts_25*sh_fd,0)*(1+g_oth_fd)^3)+Mkt!F50*(((cap_sk_28*1000/fx*sh_sk+cap_mu_28*sh_mu_27+cap_ss_28*1000/fx*sh_ss)+(MAX(Mkt!$C$41-(cap_sk_25*1000/fx*sh_sk+cap_mu_25*sh_mu_25+cap_ssds_25*ss_mem*1000/fx*sh_ss)*Mkt!$C$49,0)+0*Mkt!$C$49)*(1+g_oth_dram)^3+(MAX(Mkt!$C$42-(cap_sk_25*1000/fx*sh_sk+cap_mu_25*sh_mu_25+cap_ssds_25*ss_mem*1000/fx*sh_ss)*(1-Mkt!$C$49),0)+0*(1-Mkt!$C$49))*(1+g_oth_nand)^3)+(cap_ts_28*sh_fd+MAX(Mkt!$C$43-cap_ts_25*sh_fd,0)*(1+g_oth_fd)^3))+Mkt!F87+Mkt!F88 -> 250.26573 | E4: =D4/D$4-1 -> 0 | F4: =((cap_sk_29*1000/fx*sh_sk+cap_mu_29*sh_mu_27+cap_ss_29*1000/fx*sh_ss)+(MAX(Mkt!$C$41-(cap_sk_25*1000/fx*sh_sk+cap_mu_25*sh_mu_25+cap_ssds_25*ss_mem*1000/fx*sh_ss)*Mkt!$C$49,0)+0*Mkt!$C$49)*(1+g_oth_dram)^4+(MAX(Mkt!$C$42-(cap_sk_25*1000/fx*sh_sk+cap_mu_25*sh_mu_25+cap_ssds_25*ss_mem*1000/fx*sh_ss)*(1-Mkt!$C$49),0)+0*(1-Mkt!$C$49))*(1+g_oth_nand)^4)+(cap_ts_29*sh_fd+MAX(Mkt!$C$43-cap_ts_25*sh_fd,0)*(1+g_oth_fd)^4)+Mkt!G50*(((cap_sk_29*1000/fx*sh_sk+cap_mu_29*sh_mu_27+cap_ss_29*1000/fx*sh_ss)+(MAX(Mkt!$C$41-(cap_sk_25*1000/fx*sh_sk+cap_mu_25*sh_mu_25+cap_ssds_25*ss_mem*1000/fx*sh_ss)*Mkt!$C$49,0)+0*Mkt!$C$49)*(1+g_oth_dram)^4+(MAX(Mkt!$C$42-(cap_sk_25*1000/fx*sh_sk+cap_mu_25*sh_mu_25+cap_ssds_25*ss_mem*1000/fx*sh_ss)*(1-Mkt!$C$49),0)+0*(1-Mkt!$C$49))*(1+g_oth_nand)^4)+(cap_ts_29*sh_fd+MAX(Mkt!$C$43-cap_ts_25*sh_fd,0)*(1+g_oth_fd)^4))+Mkt!G87+Mkt!G88 -> 262.6074 | G4: =F4/F$4-1 -> 0 | H4: 同 Mkt 情境 A（公式重算；核對列應為 0）
A5: SK 海力士設備占比 低（58%） | B5: =((cap_sk_27*1000/fx*sh_sk_lo+cap_mu_27*sh_mu_27+cap_ss_27*1000/fx*sh_ss)+(MAX(Mkt!$C$41-(cap_sk_25*1000/fx*sh_sk_lo+cap_mu_25*sh_mu_25+cap_ssds_25*ss_mem*1000/fx*sh_ss)*Mkt!$C$49,0)+0*Mkt!$C$49)*(1+g_oth_dram)^2+(MAX(Mkt!$C$42-(cap_sk_25*1000/fx*sh_sk_lo+cap_mu_25*sh_mu_25+cap_ssds_25*ss_mem*1000/fx*sh_ss)*(1-Mkt!$C$49),0)+0*(1-Mkt!$C$49))*(1+g_oth_nand)^2)+(cap_ts_27*sh_fd+MAX(Mkt!$C$43-cap_ts_25*sh_fd,0)*(1+g_oth_fd)^2)+Mkt!E50*(((cap_sk_27*1000/fx*sh_sk_lo+cap_mu_27*sh_mu_27+cap_ss_27*1000/fx*sh_ss)+(MAX(Mkt!$C$41-(cap_sk_25*1000/fx*sh_sk_lo+cap_mu_25*sh_mu_25+cap_ssds_25*ss_mem*1000/fx*sh_ss)*Mkt!$C$49,0)+0*Mkt!$C$49)*(1+g_oth_dram)^2+(MAX(Mkt!$C$42-(cap_sk_25*1000/fx*sh_sk_lo+cap_mu_25*sh_mu_25+cap_ssds_25*ss_mem*1000/fx*sh_ss)*(1-Mkt!$C$49),0)+0*(1-Mkt!$C$49))*(1+g_oth_nand)^2)+(cap_ts_27*sh_fd+MAX(Mkt!$C$43-cap_ts_25*sh_fd,0)*(1+g_oth_fd)^2))+Mkt!E87+Mkt!E88 -> 221.73539 | C5: =B5/B$4-1 -> -0.0043123003 | D5: =((cap_sk_28*1000/fx*sh_sk_lo+cap_mu_28*sh_mu_27+cap_ss_28*1000/fx*sh_ss)+(MAX(Mkt!$C$41-(cap_sk_25*1000/fx*sh_sk_lo+cap_mu_25*sh_mu_25+cap_ssds_25*ss_mem*1000/fx*sh_ss)*Mkt!$C$49,0)+0*Mkt!$C$49)*(1+g_oth_dram)^3+(MAX(Mkt!$C$42-(cap_sk_25*1000/fx*sh_sk_lo+cap_mu_25*sh_mu_25+cap_ssds_25*ss_mem*1000/fx*sh_ss)*(1-Mkt!$C$49),0)+0*(1-Mkt!$C$49))*(1+g_oth_nand)^3)+(cap_ts_28*sh_fd+MAX(Mkt!$C$43-cap_ts_25*sh_fd,0)*(1+g_oth_fd)^3)+Mkt!F50*(((cap_sk_28*1000/fx*sh_sk_lo+cap_mu_28*sh_mu_27+cap_ss_28*1000/fx*sh_ss)+(MAX(Mkt!$C$41-(cap_sk_25*1000/fx*sh_sk_lo+cap_mu_25*sh_mu_25+cap_ssds_25*ss_mem*1000/fx*sh_ss)*Mkt!$C$49,0)+0*Mkt!$C$49)*(1+g_oth_dram)^3+(MAX(Mkt!$C$42-(cap_sk_25*1000/fx*sh_sk_lo+cap_mu_25*sh_mu_25+cap_ssds_25*ss_mem*1000/fx*sh_ss)*(1-Mkt!$C$49),0)+0*(1-Mkt!$C$49))*(1+g_oth_nand)^3)+(cap_ts_28*sh_fd+MAX(Mkt!$C$43-cap_ts_25*sh_fd,0)*(1+g_oth_fd)^3))+Mkt!F87+Mkt!F88 -> 249.24228 | E5: =D5/D$4-1 -> -0.0040894501 | F5: =((cap_sk_29*1000/fx*sh_sk_lo+cap_mu_29*sh_mu_27+cap_ss_29*1000/fx*sh_ss)+(MAX(Mkt!$C$41-(cap_sk_25*1000/fx*sh_sk_lo+cap_mu_25*sh_mu_25+cap_ssds_25*ss_mem*1000/fx*sh_ss)*Mkt!$C$49,0)+0*Mkt!$C$49)*(1+g_oth_dram)^4+(MAX(Mkt!$C$42-(cap_sk_25*1000/fx*sh_sk_lo+cap_mu_25*sh_mu_25+cap_ssds_25*ss_mem*1000/fx*sh_ss)*(1-Mkt!$C$49),0)+0*(1-Mkt!$C$49))*(1+g_oth_nand)^4)+(cap_ts_29*sh_fd+MAX(Mkt!$C$43-cap_ts_25*sh_fd,0)*(1+g_oth_fd)^4)+Mkt!G50*(((cap_sk_29*1000/fx*sh_sk_lo+cap_mu_29*sh_mu_27+cap_ss_29*1000/fx*sh_ss)+(MAX(Mkt!$C$41-(cap_sk_25*1000/fx*sh_sk_lo+cap_mu_25*sh_mu_25+cap_ssds_25*ss_mem*1000/fx*sh_ss)*Mkt!$C$49,0)+0*Mkt!$C$49)*(1+g_oth_dram)^4+(MAX(Mkt!$C$42-(cap_sk_25*1000/fx*sh_sk_lo+cap_mu_25*sh_mu_25+cap_ssds_25*ss_mem*1000/fx*sh_ss)*(1-Mkt!$C$49),0)+0*(1-Mkt!$C$49))*(1+g_oth_nand)^4)+(cap_ts_29*sh_fd+MAX(Mkt!$C$43-cap_ts_25*sh_fd,0)*(1+g_oth_fd)^4))+Mkt!G87+Mkt!G88 -> 261.82731 | G5: =F5/F$4-1 -> -0.0029705464
A6: SK 海力士設備占比 高（70%） | B6: =((cap_sk_27*1000/fx*sh_sk_hi+cap_mu_27*sh_mu_27+cap_ss_27*1000/fx*sh_ss)+(MAX(Mkt!$C$41-(cap_sk_25*1000/fx*sh_sk_hi+cap_mu_25*sh_mu_25+cap_ssds_25*ss_mem*1000/fx*sh_ss)*Mkt!$C$49,0)+0*Mkt!$C$49)*(1+g_oth_dram)^2+(MAX(Mkt!$C$42-(cap_sk_25*1000/fx*sh_sk_hi+cap_mu_25*sh_mu_25+cap_ssds_25*ss_mem*1000/fx*sh_ss)*(1-Mkt!$C$49),0)+0*(1-Mkt!$C$49))*(1+g_oth_nand)^2)+(cap_ts_27*sh_fd+MAX(Mkt!$C$43-cap_ts_25*sh_fd,0)*(1+g_oth_fd)^2)+Mkt!E50*(((cap_sk_27*1000/fx*sh_sk_hi+cap_mu_27*sh_mu_27+cap_ss_27*1000/fx*sh_ss)+(MAX(Mkt!$C$41-(cap_sk_25*1000/fx*sh_sk_hi+cap_mu_25*sh_mu_25+cap_ssds_25*ss_mem*1000/fx*sh_ss)*Mkt!$C$49,0)+0*Mkt!$C$49)*(1+g_oth_dram)^2+(MAX(Mkt!$C$42-(cap_sk_25*1000/fx*sh_sk_hi+cap_mu_25*sh_mu_25+cap_ssds_25*ss_mem*1000/fx*sh_ss)*(1-Mkt!$C$49),0)+0*(1-Mkt!$C$49))*(1+g_oth_nand)^2)+(cap_ts_27*sh_fd+MAX(Mkt!$C$43-cap_ts_25*sh_fd,0)*(1+g_oth_fd)^2))+Mkt!E87+Mkt!E88 -> 225.57355 | C6: =B6/B$4-1 -> 0.012922685 | D6: =((cap_sk_28*1000/fx*sh_sk_hi+cap_mu_28*sh_mu_27+cap_ss_28*1000/fx*sh_ss)+(MAX(Mkt!$C$41-(cap_sk_25*1000/fx*sh_sk_hi+cap_mu_25*sh_mu_25+cap_ssds_25*ss_mem*1000/fx*sh_ss)*Mkt!$C$49,0)+0*Mkt!$C$49)*(1+g_oth_dram)^3+(MAX(Mkt!$C$42-(cap_sk_25*1000/fx*sh_sk_hi+cap_mu_25*sh_mu_25+cap_ssds_25*ss_mem*1000/fx*sh_ss)*(1-Mkt!$C$49),0)+0*(1-Mkt!$C$49))*(1+g_oth_nand)^3)+(cap_ts_28*sh_fd+MAX(Mkt!$C$43-cap_ts_25*sh_fd,0)*(1+g_oth_fd)^3)+Mkt!F50*(((cap_sk_28*1000/fx*sh_sk_hi+cap_mu_28*sh_mu_27+cap_ss_28*1000/fx*sh_ss)+(MAX(Mkt!$C$41-(cap_sk_25*1000/fx*sh_sk_hi+cap_mu_25*sh_mu_25+cap_ssds_25*ss_mem*1000/fx*sh_ss)*Mkt!$C$49,0)+0*Mkt!$C$49)*(1+g_oth_dram)^3+(MAX(Mkt!$C$42-(cap_sk_25*1000/fx*sh_sk_hi+cap_mu_25*sh_mu_25+cap_ssds_25*ss_mem*1000/fx*sh_ss)*(1-Mkt!$C$49),0)+0*(1-Mkt!$C$49))*(1+g_oth_nand)^3)+(cap_ts_28*sh_fd+MAX(Mkt!$C$43-cap_ts_25*sh_fd,0)*(1+g_oth_fd)^3))+Mkt!F87+Mkt!F88 -> 253.55183 | E6: =D6/D$4-1 -> 0.01313042 | F6: =((cap_sk_29*1000/fx*sh_sk_hi+cap_mu_29*sh_mu_27+cap_ss_29*1000/fx*sh_ss)+(MAX(Mkt!$C$41-(cap_sk_25*1000/fx*sh_sk_hi+cap_mu_25*sh_mu_25+cap_ssds_25*ss_mem*1000/fx*sh_ss)*Mkt!$C$49,0)+0*Mkt!$C$49)*(1+g_oth_dram)^4+(MAX(Mkt!$C$42-(cap_sk_25*1000/fx*sh_sk_hi+cap_mu_25*sh_mu_25+cap_ssds_25*ss_mem*1000/fx*sh_ss)*(1-Mkt!$C$49),0)+0*(1-Mkt!$C$49))*(1+g_oth_nand)^4)+(cap_ts_29*sh_fd+MAX(Mkt!$C$43-cap_ts_25*sh_fd,0)*(1+g_oth_fd)^4)+Mkt!G50*(((cap_sk_29*1000/fx*sh_sk_hi+cap_mu_29*sh_mu_27+cap_ss_29*1000/fx*sh_ss)+(MAX(Mkt!$C$41-(cap_sk_25*1000/fx*sh_sk_hi+cap_mu_25*sh_mu_25+cap_ssds_25*ss_mem*1000/fx*sh_ss)*Mkt!$C$49,0)+0*Mkt!$C$49)*(1+g_oth_dram)^4+(MAX(Mkt!$C$42-(cap_sk_25*1000/fx*sh_sk_hi+cap_mu_25*sh_mu_25+cap_ssds_25*ss_mem*1000/fx*sh_ss)*(1-Mkt!$C$49),0)+0*(1-Mkt!$C$49))*(1+g_oth_nand)^4)+(cap_ts_29*sh_fd+MAX(Mkt!$C$43-cap_ts_25*sh_fd,0)*(1+g_oth_fd)^4))+Mkt!G87+Mkt!G88 -> 266.05741 | G6: =F6/F$4-1 -> 0.013137514
A7: 三星設備占比 低 | B7: =((cap_sk_27*1000/fx*sh_sk+cap_mu_27*sh_mu_27+cap_ss_27*1000/fx*sh_ss_lo)+(MAX(Mkt!$C$41-(cap_sk_25*1000/fx*sh_sk+cap_mu_25*sh_mu_25+cap_ssds_25*ss_mem*1000/fx*sh_ss_lo)*Mkt!$C$49,0)+0*Mkt!$C$49)*(1+g_oth_dram)^2+(MAX(Mkt!$C$42-(cap_sk_25*1000/fx*sh_sk+cap_mu_25*sh_mu_25+cap_ssds_25*ss_mem*1000/fx*sh_ss_lo)*(1-Mkt!$C$49),0)+0*(1-Mkt!$C$49))*(1+g_oth_nand)^2)+(cap_ts_27*sh_fd+MAX(Mkt!$C$43-cap_ts_25*sh_fd,0)*(1+g_oth_fd)^2)+Mkt!E50*(((cap_sk_27*1000/fx*sh_sk+cap_mu_27*sh_mu_27+cap_ss_27*1000/fx*sh_ss_lo)+(MAX(Mkt!$C$41-(cap_sk_25*1000/fx*sh_sk+cap_mu_25*sh_mu_25+cap_ssds_25*ss_mem*1000/fx*sh_ss_lo)*Mkt!$C$49,0)+0*Mkt!$C$49)*(1+g_oth_dram)^2+(MAX(Mkt!$C$42-(cap_sk_25*1000/fx*sh_sk+cap_mu_25*sh_mu_25+cap_ssds_25*ss_mem*1000/fx*sh_ss_lo)*(1-Mkt!$C$49),0)+0*(1-Mkt!$C$49))*(1+g_oth_nand)^2)+(cap_ts_27*sh_fd+MAX(Mkt!$C$43-cap_ts_25*sh_fd,0)*(1+g_oth_fd)^2))+Mkt!E87+Mkt!E88 -> 222.2027 | C7: =B7/B$4-1 -> -0.0022138597 | D7: =((cap_sk_28*1000/fx*sh_sk+cap_mu_28*sh_mu_27+cap_ss_28*1000/fx*sh_ss_lo)+(MAX(Mkt!$C$41-(cap_sk_25*1000/fx*sh_sk+cap_mu_25*sh_mu_25+cap_ssds_25*ss_mem*1000/fx*sh_ss_lo)*Mkt!$C$49,0)+0*Mkt!$C$49)*(1+g_oth_dram)^3+(MAX(Mkt!$C$42-(cap_sk_25*1000/fx*sh_sk+cap_mu_25*sh_mu_25+cap_ssds_25*ss_mem*1000/fx*sh_ss_lo)*(1-Mkt!$C$49),0)+0*(1-Mkt!$C$49))*(1+g_oth_nand)^3)+(cap_ts_28*sh_fd+MAX(Mkt!$C$43-cap_ts_25*sh_fd,0)*(1+g_oth_fd)^3)+Mkt!F50*(((cap_sk_28*1000/fx*sh_sk+cap_mu_28*sh_mu_27+cap_ss_28*1000/fx*sh_ss_lo)+(MAX(Mkt!$C$41-(cap_sk_25*1000/fx*sh_sk+cap_mu_25*sh_mu_25+cap_ssds_25*ss_mem*1000/fx*sh_ss_lo)*Mkt!$C$49,0)+0*Mkt!$C$49)*(1+g_oth_dram)^3+(MAX(Mkt!$C$42-(cap_sk_25*1000/fx*sh_sk+cap_mu_25*sh_mu_25+cap_ssds_25*ss_mem*1000/fx*sh_ss_lo)*(1-Mkt!$C$49),0)+0*(1-Mkt!$C$49))*(1+g_oth_nand)^3)+(cap_ts_28*sh_fd+MAX(Mkt!$C$43-cap_ts_25*sh_fd,0)*(1+g_oth_fd)^3))+Mkt!F87+Mkt!F88 -> 249.91161 | E7: =D7/D$4-1 -> -0.0014149791 | F7: =((cap_sk_29*1000/fx*sh_sk+cap_mu_29*sh_mu_27+cap_ss_29*1000/fx*sh_ss_lo)+(MAX(Mkt!$C$41-(cap_sk_25*1000/fx*sh_sk+cap_mu_25*sh_mu_25+cap_ssds_25*ss_mem*1000/fx*sh_ss_lo)*Mkt!$C$49,0)+0*Mkt!$C$49)*(1+g_oth_dram)^4+(MAX(Mkt!$C$42-(cap_sk_25*1000/fx*sh_sk+cap_mu_25*sh_mu_25+cap_ssds_25*ss_mem*1000/fx*sh_ss_lo)*(1-Mkt!$C$49),0)+0*(1-Mkt!$C$49))*(1+g_oth_nand)^4)+(cap_ts_29*sh_fd+MAX(Mkt!$C$43-cap_ts_25*sh_fd,0)*(1+g_oth_fd)^4)+Mkt!G50*(((cap_sk_29*1000/fx*sh_sk+cap_mu_29*sh_mu_27+cap_ss_29*1000/fx*sh_ss_lo)+(MAX(Mkt!$C$41-(cap_sk_25*1000/fx*sh_sk+cap_mu_25*sh_mu_25+cap_ssds_25*ss_mem*1000/fx*sh_ss_lo)*Mkt!$C$49,0)+0*Mkt!$C$49)*(1+g_oth_dram)^4+(MAX(Mkt!$C$42-(cap_sk_25*1000/fx*sh_sk+cap_mu_25*sh_mu_25+cap_ssds_25*ss_mem*1000/fx*sh_ss_lo)*(1-Mkt!$C$49),0)+0*(1-Mkt!$C$49))*(1+g_oth_nand)^4)+(cap_ts_29*sh_fd+MAX(Mkt!$C$43-cap_ts_25*sh_fd,0)*(1+g_oth_fd)^4))+Mkt!G87+Mkt!G88 -> 262.75295 | G7: =F7/F$4-1 -> 0.00055423006
A8: 三星設備占比 高 | B8: =((cap_sk_27*1000/fx*sh_sk+cap_mu_27*sh_mu_27+cap_ss_27*1000/fx*sh_ss_hi)+(MAX(Mkt!$C$41-(cap_sk_25*1000/fx*sh_sk+cap_mu_25*sh_mu_25+cap_ssds_25*ss_mem*1000/fx*sh_ss_hi)*Mkt!$C$49,0)+0*Mkt!$C$49)*(1+g_oth_dram)^2+(MAX(Mkt!$C$42-(cap_sk_25*1000/fx*sh_sk+cap_mu_25*sh_mu_25+cap_ssds_25*ss_mem*1000/fx*sh_ss_hi)*(1-Mkt!$C$49),0)+0*(1-Mkt!$C$49))*(1+g_oth_nand)^2)+(cap_ts_27*sh_fd+MAX(Mkt!$C$43-cap_ts_25*sh_fd,0)*(1+g_oth_fd)^2)+Mkt!E50*(((cap_sk_27*1000/fx*sh_sk+cap_mu_27*sh_mu_27+cap_ss_27*1000/fx*sh_ss_hi)+(MAX(Mkt!$C$41-(cap_sk_25*1000/fx*sh_sk+cap_mu_25*sh_mu_25+cap_ssds_25*ss_mem*1000/fx*sh_ss_hi)*Mkt!$C$49,0)+0*Mkt!$C$49)*(1+g_oth_dram)^2+(MAX(Mkt!$C$42-(cap_sk_25*1000/fx*sh_sk+cap_mu_25*sh_mu_25+cap_ssds_25*ss_mem*1000/fx*sh_ss_hi)*(1-Mkt!$C$49),0)+0*(1-Mkt!$C$49))*(1+g_oth_nand)^2)+(cap_ts_27*sh_fd+MAX(Mkt!$C$43-cap_ts_25*sh_fd,0)*(1+g_oth_fd)^2))+Mkt!E87+Mkt!E88 -> 225.46447 | C8: =B8/B$4-1 -> 0.012432881 | D8: =((cap_sk_28*1000/fx*sh_sk+cap_mu_28*sh_mu_27+cap_ss_28*1000/fx*sh_ss_hi)+(MAX(Mkt!$C$41-(cap_sk_25*1000/fx*sh_sk+cap_mu_25*sh_mu_25+cap_ssds_25*ss_mem*1000/fx*sh_ss_hi)*Mkt!$C$49,0)+0*Mkt!$C$49)*(1+g_oth_dram)^3+(MAX(Mkt!$C$42-(cap_sk_25*1000/fx*sh_sk+cap_mu_25*sh_mu_25+cap_ssds_25*ss_mem*1000/fx*sh_ss_hi)*(1-Mkt!$C$49),0)+0*(1-Mkt!$C$49))*(1+g_oth_nand)^3)+(cap_ts_28*sh_fd+MAX(Mkt!$C$43-cap_ts_25*sh_fd,0)*(1+g_oth_fd)^3)+Mkt!F50*(((cap_sk_28*1000/fx*sh_sk+cap_mu_28*sh_mu_27+cap_ss_28*1000/fx*sh_ss_hi)+(MAX(Mkt!$C$41-(cap_sk_25*1000/fx*sh_sk+cap_mu_25*sh_mu_25+cap_ssds_25*ss_mem*1000/fx*sh_ss_hi)*Mkt!$C$49,0)+0*Mkt!$C$49)*(1+g_oth_dram)^3+(MAX(Mkt!$C$42-(cap_sk_25*1000/fx*sh_sk+cap_mu_25*sh_mu_25+cap_ssds_25*ss_mem*1000/fx*sh_ss_hi)*(1-Mkt!$C$49),0)+0*(1-Mkt!$C$49))*(1+g_oth_nand)^3)+(cap_ts_28*sh_fd+MAX(Mkt!$C$43-cap_ts_25*sh_fd,0)*(1+g_oth_fd)^3))+Mkt!F87+Mkt!F88 -> 253.30522 | E8: =D8/D$4-1 -> 0.01214503 | F8: =((cap_sk_29*1000/fx*sh_sk+cap_mu_29*sh_mu_27+cap_ss_29*1000/fx*sh_ss_hi)+(MAX(Mkt!$C$41-(cap_sk_25*1000/fx*sh_sk+cap_mu_25*sh_mu_25+cap_ssds_25*ss_mem*1000/fx*sh_ss_hi)*Mkt!$C$49,0)+0*Mkt!$C$49)*(1+g_oth_dram)^4+(MAX(Mkt!$C$42-(cap_sk_25*1000/fx*sh_sk+cap_mu_25*sh_mu_25+cap_ssds_25*ss_mem*1000/fx*sh_ss_hi)*(1-Mkt!$C$49),0)+0*(1-Mkt!$C$49))*(1+g_oth_nand)^4)+(cap_ts_29*sh_fd+MAX(Mkt!$C$43-cap_ts_25*sh_fd,0)*(1+g_oth_fd)^4)+Mkt!G50*(((cap_sk_29*1000/fx*sh_sk+cap_mu_29*sh_mu_27+cap_ss_29*1000/fx*sh_ss_hi)+(MAX(Mkt!$C$41-(cap_sk_25*1000/fx*sh_sk+cap_mu_25*sh_mu_25+cap_ssds_25*ss_mem*1000/fx*sh_ss_hi)*Mkt!$C$49,0)+0*Mkt!$C$49)*(1+g_oth_dram)^4+(MAX(Mkt!$C$42-(cap_sk_25*1000/fx*sh_sk+cap_mu_25*sh_mu_25+cap_ssds_25*ss_mem*1000/fx*sh_ss_hi)*(1-Mkt!$C$49),0)+0*(1-Mkt!$C$49))*(1+g_oth_nand)^4)+(cap_ts_29*sh_fd+MAX(Mkt!$C$43-cap_ts_25*sh_fd,0)*(1+g_oth_fd)^4))+Mkt!G87+Mkt!G88 -> 265.63059 | G8: =F8/F$4-1 -> 0.011512184
A9: 美光設備占比 低（FY25／26／27–29） | B9: =((cap_sk_27*1000/fx*sh_sk+cap_mu_27*sh_mu_27_lo+cap_ss_27*1000/fx*sh_ss)+(MAX(Mkt!$C$41-(cap_sk_25*1000/fx*sh_sk+cap_mu_25*sh_mu_25_lo+cap_ssds_25*ss_mem*1000/fx*sh_ss)*Mkt!$C$49,0)+0*Mkt!$C$49)*(1+g_oth_dram)^2+(MAX(Mkt!$C$42-(cap_sk_25*1000/fx*sh_sk+cap_mu_25*sh_mu_25_lo+cap_ssds_25*ss_mem*1000/fx*sh_ss)*(1-Mkt!$C$49),0)+0*(1-Mkt!$C$49))*(1+g_oth_nand)^2)+(cap_ts_27*sh_fd+MAX(Mkt!$C$43-cap_ts_25*sh_fd,0)*(1+g_oth_fd)^2)+Mkt!E50*(((cap_sk_27*1000/fx*sh_sk+cap_mu_27*sh_mu_27_lo+cap_ss_27*1000/fx*sh_ss)+(MAX(Mkt!$C$41-(cap_sk_25*1000/fx*sh_sk+cap_mu_25*sh_mu_25_lo+cap_ssds_25*ss_mem*1000/fx*sh_ss)*Mkt!$C$49,0)+0*Mkt!$C$49)*(1+g_oth_dram)^2+(MAX(Mkt!$C$42-(cap_sk_25*1000/fx*sh_sk+cap_mu_25*sh_mu_25_lo+cap_ssds_25*ss_mem*1000/fx*sh_ss)*(1-Mkt!$C$49),0)+0*(1-Mkt!$C$49))*(1+g_oth_nand)^2)+(cap_ts_27*sh_fd+MAX(Mkt!$C$43-cap_ts_25*sh_fd,0)*(1+g_oth_fd)^2))+Mkt!E87+Mkt!E88 -> 219.35988 | C9: =B9/B$4-1 -> -0.014979376 | D9: =((cap_sk_28*1000/fx*sh_sk+cap_mu_28*sh_mu_27_lo+cap_ss_28*1000/fx*sh_ss)+(MAX(Mkt!$C$41-(cap_sk_25*1000/fx*sh_sk+cap_mu_25*sh_mu_25_lo+cap_ssds_25*ss_mem*1000/fx*sh_ss)*Mkt!$C$49,0)+0*Mkt!$C$49)*(1+g_oth_dram)^3+(MAX(Mkt!$C$42-(cap_sk_25*1000/fx*sh_sk+cap_mu_25*sh_mu_25_lo+cap_ssds_25*ss_mem*1000/fx*sh_ss)*(1-Mkt!$C$49),0)+0*(1-Mkt!$C$49))*(1+g_oth_nand)^3)+(cap_ts_28*sh_fd+MAX(Mkt!$C$43-cap_ts_25*sh_fd,0)*(1+g_oth_fd)^3)+Mkt!F50*(((cap_sk_28*1000/fx*sh_sk+cap_mu_28*sh_mu_27_lo+cap_ss_28*1000/fx*sh_ss)+(MAX(Mkt!$C$41-(cap_sk_25*1000/fx*sh_sk+cap_mu_25*sh_mu_25_lo+cap_ssds_25*ss_mem*1000/fx*sh_ss)*Mkt!$C$49,0)+0*Mkt!$C$49)*(1+g_oth_dram)^3+(MAX(Mkt!$C$42-(cap_sk_25*1000/fx*sh_sk+cap_mu_25*sh_mu_25_lo+cap_ssds_25*ss_mem*1000/fx*sh_ss)*(1-Mkt!$C$49),0)+0*(1-Mkt!$C$49))*(1+g_oth_nand)^3)+(cap_ts_28*sh_fd+MAX(Mkt!$C$43-cap_ts_25*sh_fd,0)*(1+g_oth_fd)^3))+Mkt!F87+Mkt!F88 -> 246.74192 | E9: =D9/D$4-1 -> -0.014080301 | F9: =((cap_sk_29*1000/fx*sh_sk+cap_mu_29*sh_mu_27_lo+cap_ss_29*1000/fx*sh_ss)+(MAX(Mkt!$C$41-(cap_sk_25*1000/fx*sh_sk+cap_mu_25*sh_mu_25_lo+cap_ssds_25*ss_mem*1000/fx*sh_ss)*Mkt!$C$49,0)+0*Mkt!$C$49)*(1+g_oth_dram)^4+(MAX(Mkt!$C$42-(cap_sk_25*1000/fx*sh_sk+cap_mu_25*sh_mu_25_lo+cap_ssds_25*ss_mem*1000/fx*sh_ss)*(1-Mkt!$C$49),0)+0*(1-Mkt!$C$49))*(1+g_oth_nand)^4)+(cap_ts_29*sh_fd+MAX(Mkt!$C$43-cap_ts_25*sh_fd,0)*(1+g_oth_fd)^4)+Mkt!G50*(((cap_sk_29*1000/fx*sh_sk+cap_mu_29*sh_mu_27_lo+cap_ss_29*1000/fx*sh_ss)+(MAX(Mkt!$C$41-(cap_sk_25*1000/fx*sh_sk+cap_mu_25*sh_mu_25_lo+cap_ssds_25*ss_mem*1000/fx*sh_ss)*Mkt!$C$49,0)+0*Mkt!$C$49)*(1+g_oth_dram)^4+(MAX(Mkt!$C$42-(cap_sk_25*1000/fx*sh_sk+cap_mu_25*sh_mu_25_lo+cap_ssds_25*ss_mem*1000/fx*sh_ss)*(1-Mkt!$C$49),0)+0*(1-Mkt!$C$49))*(1+g_oth_nand)^4)+(cap_ts_29*sh_fd+MAX(Mkt!$C$43-cap_ts_25*sh_fd,0)*(1+g_oth_fd)^4))+Mkt!G87+Mkt!G88 -> 259.35843 | G9: =F9/F$4-1 -> -0.012371964
A10: 美光設備占比 高 | B10: =((cap_sk_27*1000/fx*sh_sk+cap_mu_27*sh_mu_27_hi+cap_ss_27*1000/fx*sh_ss)+(MAX(Mkt!$C$41-(cap_sk_25*1000/fx*sh_sk+cap_mu_25*sh_mu_25_hi+cap_ssds_25*ss_mem*1000/fx*sh_ss)*Mkt!$C$49,0)+0*Mkt!$C$49)*(1+g_oth_dram)^2+(MAX(Mkt!$C$42-(cap_sk_25*1000/fx*sh_sk+cap_mu_25*sh_mu_25_hi+cap_ssds_25*ss_mem*1000/fx*sh_ss)*(1-Mkt!$C$49),0)+0*(1-Mkt!$C$49))*(1+g_oth_nand)^2)+(cap_ts_27*sh_fd+MAX(Mkt!$C$43-cap_ts_25*sh_fd,0)*(1+g_oth_fd)^2)+Mkt!E50*(((cap_sk_27*1000/fx*sh_sk+cap_mu_27*sh_mu_27_hi+cap_ss_27*1000/fx*sh_ss)+(MAX(Mkt!$C$41-(cap_sk_25*1000/fx*sh_sk+cap_mu_25*sh_mu_25_hi+cap_ssds_25*ss_mem*1000/fx*sh_ss)*Mkt!$C$49,0)+0*Mkt!$C$49)*(1+g_oth_dram)^2+(MAX(Mkt!$C$42-(cap_sk_25*1000/fx*sh_sk+cap_mu_25*sh_mu_25_hi+cap_ssds_25*ss_mem*1000/fx*sh_ss)*(1-Mkt!$C$49),0)+0*(1-Mkt!$C$49))*(1+g_oth_nand)^2)+(cap_ts_27*sh_fd+MAX(Mkt!$C$43-cap_ts_25*sh_fd,0)*(1+g_oth_fd)^2))+Mkt!E87+Mkt!E88 -> 227.24883 | C10: =B10/B$4-1 -> 0.020445431 | D10: =((cap_sk_28*1000/fx*sh_sk+cap_mu_28*sh_mu_27_hi+cap_ss_28*1000/fx*sh_ss)+(MAX(Mkt!$C$41-(cap_sk_25*1000/fx*sh_sk+cap_mu_25*sh_mu_25_hi+cap_ssds_25*ss_mem*1000/fx*sh_ss)*Mkt!$C$49,0)+0*Mkt!$C$49)*(1+g_oth_dram)^3+(MAX(Mkt!$C$42-(cap_sk_25*1000/fx*sh_sk+cap_mu_25*sh_mu_25_hi+cap_ssds_25*ss_mem*1000/fx*sh_ss)*(1-Mkt!$C$49),0)+0*(1-Mkt!$C$49))*(1+g_oth_nand)^3)+(cap_ts_28*sh_fd+MAX(Mkt!$C$43-cap_ts_25*sh_fd,0)*(1+g_oth_fd)^3)+Mkt!F50*(((cap_sk_28*1000/fx*sh_sk+cap_mu_28*sh_mu_27_hi+cap_ss_28*1000/fx*sh_ss)+(MAX(Mkt!$C$41-(cap_sk_25*1000/fx*sh_sk+cap_mu_25*sh_mu_25_hi+cap_ssds_25*ss_mem*1000/fx*sh_ss)*Mkt!$C$49,0)+0*Mkt!$C$49)*(1+g_oth_dram)^3+(MAX(Mkt!$C$42-(cap_sk_25*1000/fx*sh_sk+cap_mu_25*sh_mu_25_hi+cap_ssds_25*ss_mem*1000/fx*sh_ss)*(1-Mkt!$C$49),0)+0*(1-Mkt!$C$49))*(1+g_oth_nand)^3)+(cap_ts_28*sh_fd+MAX(Mkt!$C$43-cap_ts_25*sh_fd,0)*(1+g_oth_fd)^3))+Mkt!F87+Mkt!F88 -> 255.22593 | E10: =D10/D$4-1 -> 0.019819701 | F10: =((cap_sk_29*1000/fx*sh_sk+cap_mu_29*sh_mu_27_hi+cap_ss_29*1000/fx*sh_ss)+(MAX(Mkt!$C$41-(cap_sk_25*1000/fx*sh_sk+cap_mu_25*sh_mu_25_hi+cap_ssds_25*ss_mem*1000/fx*sh_ss)*Mkt!$C$49,0)+0*Mkt!$C$49)*(1+g_oth_dram)^4+(MAX(Mkt!$C$42-(cap_sk_25*1000/fx*sh_sk+cap_mu_25*sh_mu_25_hi+cap_ssds_25*ss_mem*1000/fx*sh_ss)*(1-Mkt!$C$49),0)+0*(1-Mkt!$C$49))*(1+g_oth_nand)^4)+(cap_ts_29*sh_fd+MAX(Mkt!$C$43-cap_ts_25*sh_fd,0)*(1+g_oth_fd)^4)+Mkt!G50*(((cap_sk_29*1000/fx*sh_sk+cap_mu_29*sh_mu_27_hi+cap_ss_29*1000/fx*sh_ss)+(MAX(Mkt!$C$41-(cap_sk_25*1000/fx*sh_sk+cap_mu_25*sh_mu_25_hi+cap_ssds_25*ss_mem*1000/fx*sh_ss)*Mkt!$C$49,0)+0*Mkt!$C$49)*(1+g_oth_dram)^4+(MAX(Mkt!$C$42-(cap_sk_25*1000/fx*sh_sk+cap_mu_25*sh_mu_25_hi+cap_ssds_25*ss_mem*1000/fx*sh_ss)*(1-Mkt!$C$49),0)+0*(1-Mkt!$C$49))*(1+g_oth_nand)^4)+(cap_ts_29*sh_fd+MAX(Mkt!$C$43-cap_ts_25*sh_fd,0)*(1+g_oth_fd)^4))+Mkt!G87+Mkt!G88 -> 267.55129 | G10: =F10/F$4-1 -> 0.018826171
A11: 台積電設備占比 低 | B11: =((cap_sk_27*1000/fx*sh_sk+cap_mu_27*sh_mu_27+cap_ss_27*1000/fx*sh_ss)+(MAX(Mkt!$C$41-(cap_sk_25*1000/fx*sh_sk+cap_mu_25*sh_mu_25+cap_ssds_25*ss_mem*1000/fx*sh_ss)*Mkt!$C$49,0)+0*Mkt!$C$49)*(1+g_oth_dram)^2+(MAX(Mkt!$C$42-(cap_sk_25*1000/fx*sh_sk+cap_mu_25*sh_mu_25+cap_ssds_25*ss_mem*1000/fx*sh_ss)*(1-Mkt!$C$49),0)+0*(1-Mkt!$C$49))*(1+g_oth_nand)^2)+(cap_ts_27*sh_fd_lo+MAX(Mkt!$C$43-cap_ts_25*sh_fd_lo,0)*(1+g_oth_fd)^2)+Mkt!E50*(((cap_sk_27*1000/fx*sh_sk+cap_mu_27*sh_mu_27+cap_ss_27*1000/fx*sh_ss)+(MAX(Mkt!$C$41-(cap_sk_25*1000/fx*sh_sk+cap_mu_25*sh_mu_25+cap_ssds_25*ss_mem*1000/fx*sh_ss)*Mkt!$C$49,0)+0*Mkt!$C$49)*(1+g_oth_dram)^2+(MAX(Mkt!$C$42-(cap_sk_25*1000/fx*sh_sk+cap_mu_25*sh_mu_25+cap_ssds_25*ss_mem*1000/fx*sh_ss)*(1-Mkt!$C$49),0)+0*(1-Mkt!$C$49))*(1+g_oth_nand)^2)+(cap_ts_27*sh_fd_lo+MAX(Mkt!$C$43-cap_ts_25*sh_fd_lo,0)*(1+g_oth_fd)^2))+Mkt!E87+Mkt!E88 -> 220.72295 | C11: =B11/B$4-1 -> -0.008858595 | D11: =((cap_sk_28*1000/fx*sh_sk+cap_mu_28*sh_mu_27+cap_ss_28*1000/fx*sh_ss)+(MAX(Mkt!$C$41-(cap_sk_25*1000/fx*sh_sk+cap_mu_25*sh_mu_25+cap_ssds_25*ss_mem*1000/fx*sh_ss)*Mkt!$C$49,0)+0*Mkt!$C$49)*(1+g_oth_dram)^3+(MAX(Mkt!$C$42-(cap_sk_25*1000/fx*sh_sk+cap_mu_25*sh_mu_25+cap_ssds_25*ss_mem*1000/fx*sh_ss)*(1-Mkt!$C$49),0)+0*(1-Mkt!$C$49))*(1+g_oth_nand)^3)+(cap_ts_28*sh_fd_lo+MAX(Mkt!$C$43-cap_ts_25*sh_fd_lo,0)*(1+g_oth_fd)^3)+Mkt!F50*(((cap_sk_28*1000/fx*sh_sk+cap_mu_28*sh_mu_27+cap_ss_28*1000/fx*sh_ss)+(MAX(Mkt!$C$41-(cap_sk_25*1000/fx*sh_sk+cap_mu_25*sh_mu_25+cap_ssds_25*ss_mem*1000/fx*sh_ss)*Mkt!$C$49,0)+0*Mkt!$C$49)*(1+g_oth_dram)^3+(MAX(Mkt!$C$42-(cap_sk_25*1000/fx*sh_sk+cap_mu_25*sh_mu_25+cap_ssds_25*ss_mem*1000/fx*sh_ss)*(1-Mkt!$C$49),0)+0*(1-Mkt!$C$49))*(1+g_oth_nand)^3)+(cap_ts_28*sh_fd_lo+MAX(Mkt!$C$43-cap_ts_25*sh_fd_lo,0)*(1+g_oth_fd)^3))+Mkt!F87+Mkt!F88 -> 247.67451 | E11: =D11/D$4-1 -> -0.010353879 | F11: =((cap_sk_29*1000/fx*sh_sk+cap_mu_29*sh_mu_27+cap_ss_29*1000/fx*sh_ss)+(MAX(Mkt!$C$41-(cap_sk_25*1000/fx*sh_sk+cap_mu_25*sh_mu_25+cap_ssds_25*ss_mem*1000/fx*sh_ss)*Mkt!$C$49,0)+0*Mkt!$C$49)*(1+g_oth_dram)^4+(MAX(Mkt!$C$42-(cap_sk_25*1000/fx*sh_sk+cap_mu_25*sh_mu_25+cap_ssds_25*ss_mem*1000/fx*sh_ss)*(1-Mkt!$C$49),0)+0*(1-Mkt!$C$49))*(1+g_oth_nand)^4)+(cap_ts_29*sh_fd_lo+MAX(Mkt!$C$43-cap_ts_25*sh_fd_lo,0)*(1+g_oth_fd)^4)+Mkt!G50*(((cap_sk_29*1000/fx*sh_sk+cap_mu_29*sh_mu_27+cap_ss_29*1000/fx*sh_ss)+(MAX(Mkt!$C$41-(cap_sk_25*1000/fx*sh_sk+cap_mu_25*sh_mu_25+cap_ssds_25*ss_mem*1000/fx*sh_ss)*Mkt!$C$49,0)+0*Mkt!$C$49)*(1+g_oth_dram)^4+(MAX(Mkt!$C$42-(cap_sk_25*1000/fx*sh_sk+cap_mu_25*sh_mu_25+cap_ssds_25*ss_mem*1000/fx*sh_ss)*(1-Mkt!$C$49),0)+0*(1-Mkt!$C$49))*(1+g_oth_nand)^4)+(cap_ts_29*sh_fd_lo+MAX(Mkt!$C$43-cap_ts_25*sh_fd_lo,0)*(1+g_oth_fd)^4))+Mkt!G87+Mkt!G88 -> 259.95704 | G11: =F11/F$4-1 -> -0.010092494
A12: 台積電設備占比 高 | B12: =((cap_sk_27*1000/fx*sh_sk+cap_mu_27*sh_mu_27+cap_ss_27*1000/fx*sh_ss)+(MAX(Mkt!$C$41-(cap_sk_25*1000/fx*sh_sk+cap_mu_25*sh_mu_25+cap_ssds_25*ss_mem*1000/fx*sh_ss)*Mkt!$C$49,0)+0*Mkt!$C$49)*(1+g_oth_dram)^2+(MAX(Mkt!$C$42-(cap_sk_25*1000/fx*sh_sk+cap_mu_25*sh_mu_25+cap_ssds_25*ss_mem*1000/fx*sh_ss)*(1-Mkt!$C$49),0)+0*(1-Mkt!$C$49))*(1+g_oth_nand)^2)+(cap_ts_27*sh_fd_hi+MAX(Mkt!$C$43-cap_ts_25*sh_fd_hi,0)*(1+g_oth_fd)^2)+Mkt!E50*(((cap_sk_27*1000/fx*sh_sk+cap_mu_27*sh_mu_27+cap_ss_27*1000/fx*sh_ss)+(MAX(Mkt!$C$41-(cap_sk_25*1000/fx*sh_sk+cap_mu_25*sh_mu_25+cap_ssds_25*ss_mem*1000/fx*sh_ss)*Mkt!$C$49,0)+0*Mkt!$C$49)*(1+g_oth_dram)^2+(MAX(Mkt!$C$42-(cap_sk_25*1000/fx*sh_sk+cap_mu_25*sh_mu_25+cap_ssds_25*ss_mem*1000/fx*sh_ss)*(1-Mkt!$C$49),0)+0*(1-Mkt!$C$49))*(1+g_oth_nand)^2)+(cap_ts_27*sh_fd_hi+MAX(Mkt!$C$43-cap_ts_25*sh_fd_hi,0)*(1+g_oth_fd)^2))+Mkt!E87+Mkt!E88 -> 224.66849 | C12: =B12/B$4-1 -> 0.008858595 | D12: =((cap_sk_28*1000/fx*sh_sk+cap_mu_28*sh_mu_27+cap_ss_28*1000/fx*sh_ss)+(MAX(Mkt!$C$41-(cap_sk_25*1000/fx*sh_sk+cap_mu_25*sh_mu_25+cap_ssds_25*ss_mem*1000/fx*sh_ss)*Mkt!$C$49,0)+0*Mkt!$C$49)*(1+g_oth_dram)^3+(MAX(Mkt!$C$42-(cap_sk_25*1000/fx*sh_sk+cap_mu_25*sh_mu_25+cap_ssds_25*ss_mem*1000/fx*sh_ss)*(1-Mkt!$C$49),0)+0*(1-Mkt!$C$49))*(1+g_oth_nand)^3)+(cap_ts_28*sh_fd_hi+MAX(Mkt!$C$43-cap_ts_25*sh_fd_hi,0)*(1+g_oth_fd)^3)+Mkt!F50*(((cap_sk_28*1000/fx*sh_sk+cap_mu_28*sh_mu_27+cap_ss_28*1000/fx*sh_ss)+(MAX(Mkt!$C$41-(cap_sk_25*1000/fx*sh_sk+cap_mu_25*sh_mu_25+cap_ssds_25*ss_mem*1000/fx*sh_ss)*Mkt!$C$49,0)+0*Mkt!$C$49)*(1+g_oth_dram)^3+(MAX(Mkt!$C$42-(cap_sk_25*1000/fx*sh_sk+cap_mu_25*sh_mu_25+cap_ssds_25*ss_mem*1000/fx*sh_ss)*(1-Mkt!$C$49),0)+0*(1-Mkt!$C$49))*(1+g_oth_nand)^3)+(cap_ts_28*sh_fd_hi+MAX(Mkt!$C$43-cap_ts_25*sh_fd_hi,0)*(1+g_oth_fd)^3))+Mkt!F87+Mkt!F88 -> 252.85695 | E12: =D12/D$4-1 -> 0.010353879 | F12: =((cap_sk_29*1000/fx*sh_sk+cap_mu_29*sh_mu_27+cap_ss_29*1000/fx*sh_ss)+(MAX(Mkt!$C$41-(cap_sk_25*1000/fx*sh_sk+cap_mu_25*sh_mu_25+cap_ssds_25*ss_mem*1000/fx*sh_ss)*Mkt!$C$49,0)+0*Mkt!$C$49)*(1+g_oth_dram)^4+(MAX(Mkt!$C$42-(cap_sk_25*1000/fx*sh_sk+cap_mu_25*sh_mu_25+cap_ssds_25*ss_mem*1000/fx*sh_ss)*(1-Mkt!$C$49),0)+0*(1-Mkt!$C$49))*(1+g_oth_nand)^4)+(cap_ts_29*sh_fd_hi+MAX(Mkt!$C$43-cap_ts_25*sh_fd_hi,0)*(1+g_oth_fd)^4)+Mkt!G50*(((cap_sk_29*1000/fx*sh_sk+cap_mu_29*sh_mu_27+cap_ss_29*1000/fx*sh_ss)+(MAX(Mkt!$C$41-(cap_sk_25*1000/fx*sh_sk+cap_mu_25*sh_mu_25+cap_ssds_25*ss_mem*1000/fx*sh_ss)*Mkt!$C$49,0)+0*Mkt!$C$49)*(1+g_oth_dram)^4+(MAX(Mkt!$C$42-(cap_sk_25*1000/fx*sh_sk+cap_mu_25*sh_mu_25+cap_ssds_25*ss_mem*1000/fx*sh_ss)*(1-Mkt!$C$49),0)+0*(1-Mkt!$C$49))*(1+g_oth_nand)^4)+(cap_ts_29*sh_fd_hi+MAX(Mkt!$C$43-cap_ts_25*sh_fd_hi,0)*(1+g_oth_fd)^4))+Mkt!G87+Mkt!G88 -> 265.25776 | G12: =F12/F$4-1 -> 0.010092494
A13: 匯率 低（1,350） | B13: =((cap_sk_27*1000/fx_lo*sh_sk+cap_mu_27*sh_mu_27+cap_ss_27*1000/fx_lo*sh_ss)+(MAX(Mkt!$C$41-(cap_sk_25*1000/fx_lo*sh_sk+cap_mu_25*sh_mu_25+cap_ssds_25*ss_mem*1000/fx_lo*sh_ss)*Mkt!$C$49,0)+0*Mkt!$C$49)*(1+g_oth_dram)^2+(MAX(Mkt!$C$42-(cap_sk_25*1000/fx_lo*sh_sk+cap_mu_25*sh_mu_25+cap_ssds_25*ss_mem*1000/fx_lo*sh_ss)*(1-Mkt!$C$49),0)+0*(1-Mkt!$C$49))*(1+g_oth_nand)^2)+(cap_ts_27*sh_fd+MAX(Mkt!$C$43-cap_ts_25*sh_fd,0)*(1+g_oth_fd)^2)+Mkt!E50*(((cap_sk_27*1000/fx_lo*sh_sk+cap_mu_27*sh_mu_27+cap_ss_27*1000/fx_lo*sh_ss)+(MAX(Mkt!$C$41-(cap_sk_25*1000/fx_lo*sh_sk+cap_mu_25*sh_mu_25+cap_ssds_25*ss_mem*1000/fx_lo*sh_ss)*Mkt!$C$49,0)+0*Mkt!$C$49)*(1+g_oth_dram)^2+(MAX(Mkt!$C$42-(cap_sk_25*1000/fx_lo*sh_sk+cap_mu_25*sh_mu_25+cap_ssds_25*ss_mem*1000/fx_lo*sh_ss)*(1-Mkt!$C$49),0)+0*(1-Mkt!$C$49))*(1+g_oth_nand)^2)+(cap_ts_27*sh_fd+MAX(Mkt!$C$43-cap_ts_25*sh_fd,0)*(1+g_oth_fd)^2))+Mkt!E87+Mkt!E88 -> 225.82691 | C13: =B13/B$4-1 -> 0.014060407 | D13: =((cap_sk_28*1000/fx_lo*sh_sk+cap_mu_28*sh_mu_27+cap_ss_28*1000/fx_lo*sh_ss)+(MAX(Mkt!$C$41-(cap_sk_25*1000/fx_lo*sh_sk+cap_mu_25*sh_mu_25+cap_ssds_25*ss_mem*1000/fx_lo*sh_ss)*Mkt!$C$49,0)+0*Mkt!$C$49)*(1+g_oth_dram)^3+(MAX(Mkt!$C$42-(cap_sk_25*1000/fx_lo*sh_sk+cap_mu_25*sh_mu_25+cap_ssds_25*ss_mem*1000/fx_lo*sh_ss)*(1-Mkt!$C$49),0)+0*(1-Mkt!$C$49))*(1+g_oth_nand)^3)+(cap_ts_28*sh_fd+MAX(Mkt!$C$43-cap_ts_25*sh_fd,0)*(1+g_oth_fd)^3)+Mkt!F50*(((cap_sk_28*1000/fx_lo*sh_sk+cap_mu_28*sh_mu_27+cap_ss_28*1000/fx_lo*sh_ss)+(MAX(Mkt!$C$41-(cap_sk_25*1000/fx_lo*sh_sk+cap_mu_25*sh_mu_25+cap_ssds_25*ss_mem*1000/fx_lo*sh_ss)*Mkt!$C$49,0)+0*Mkt!$C$49)*(1+g_oth_dram)^3+(MAX(Mkt!$C$42-(cap_sk_25*1000/fx_lo*sh_sk+cap_mu_25*sh_mu_25+cap_ssds_25*ss_mem*1000/fx_lo*sh_ss)*(1-Mkt!$C$49),0)+0*(1-Mkt!$C$49))*(1+g_oth_nand)^3)+(cap_ts_28*sh_fd+MAX(Mkt!$C$43-cap_ts_25*sh_fd,0)*(1+g_oth_fd)^3))+Mkt!F87+Mkt!F88 -> 253.77394 | E13: =D13/D$4-1 -> 0.014017926 | F13: =((cap_sk_29*1000/fx_lo*sh_sk+cap_mu_29*sh_mu_27+cap_ss_29*1000/fx_lo*sh_ss)+(MAX(Mkt!$C$41-(cap_sk_25*1000/fx_lo*sh_sk+cap_mu_25*sh_mu_25+cap_ssds_25*ss_mem*1000/fx_lo*sh_ss)*Mkt!$C$49,0)+0*Mkt!$C$49)*(1+g_oth_dram)^4+(MAX(Mkt!$C$42-(cap_sk_25*1000/fx_lo*sh_sk+cap_mu_25*sh_mu_25+cap_ssds_25*ss_mem*1000/fx_lo*sh_ss)*(1-Mkt!$C$49),0)+0*(1-Mkt!$C$49))*(1+g_oth_nand)^4)+(cap_ts_29*sh_fd+MAX(Mkt!$C$43-cap_ts_25*sh_fd,0)*(1+g_oth_fd)^4)+Mkt!G50*(((cap_sk_29*1000/fx_lo*sh_sk+cap_mu_29*sh_mu_27+cap_ss_29*1000/fx_lo*sh_ss)+(MAX(Mkt!$C$41-(cap_sk_25*1000/fx_lo*sh_sk+cap_mu_25*sh_mu_25+cap_ssds_25*ss_mem*1000/fx_lo*sh_ss)*Mkt!$C$49,0)+0*Mkt!$C$49)*(1+g_oth_dram)^4+(MAX(Mkt!$C$42-(cap_sk_25*1000/fx_lo*sh_sk+cap_mu_25*sh_mu_25+cap_ssds_25*ss_mem*1000/fx_lo*sh_ss)*(1-Mkt!$C$49),0)+0*(1-Mkt!$C$49))*(1+g_oth_nand)^4)+(cap_ts_29*sh_fd+MAX(Mkt!$C$43-cap_ts_25*sh_fd,0)*(1+g_oth_fd)^4))+Mkt!G87+Mkt!G88 -> 266.19898 | G13: =F13/F$4-1 -> 0.013676616
A14: 匯率 高（1,500） | B14: =((cap_sk_27*1000/fx_hi*sh_sk+cap_mu_27*sh_mu_27+cap_ss_27*1000/fx_hi*sh_ss)+(MAX(Mkt!$C$41-(cap_sk_25*1000/fx_hi*sh_sk+cap_mu_25*sh_mu_25+cap_ssds_25*ss_mem*1000/fx_hi*sh_ss)*Mkt!$C$49,0)+0*Mkt!$C$49)*(1+g_oth_dram)^2+(MAX(Mkt!$C$42-(cap_sk_25*1000/fx_hi*sh_sk+cap_mu_25*sh_mu_25+cap_ssds_25*ss_mem*1000/fx_hi*sh_ss)*(1-Mkt!$C$49),0)+0*(1-Mkt!$C$49))*(1+g_oth_nand)^2)+(cap_ts_27*sh_fd+MAX(Mkt!$C$43-cap_ts_25*sh_fd,0)*(1+g_oth_fd)^2)+Mkt!E50*(((cap_sk_27*1000/fx_hi*sh_sk+cap_mu_27*sh_mu_27+cap_ss_27*1000/fx_hi*sh_ss)+(MAX(Mkt!$C$41-(cap_sk_25*1000/fx_hi*sh_sk+cap_mu_25*sh_mu_25+cap_ssds_25*ss_mem*1000/fx_hi*sh_ss)*Mkt!$C$49,0)+0*Mkt!$C$49)*(1+g_oth_dram)^2+(MAX(Mkt!$C$42-(cap_sk_25*1000/fx_hi*sh_sk+cap_mu_25*sh_mu_25+cap_ssds_25*ss_mem*1000/fx_hi*sh_ss)*(1-Mkt!$C$49),0)+0*(1-Mkt!$C$49))*(1+g_oth_nand)^2)+(cap_ts_27*sh_fd+MAX(Mkt!$C$43-cap_ts_25*sh_fd,0)*(1+g_oth_fd)^2))+Mkt!E87+Mkt!E88 -> 221.86893 | C14: =B14/B$4-1 -> -0.0037126599 | D14: =((cap_sk_28*1000/fx_hi*sh_sk+cap_mu_28*sh_mu_27+cap_ss_28*1000/fx_hi*sh_ss)+(MAX(Mkt!$C$41-(cap_sk_25*1000/fx_hi*sh_sk+cap_mu_25*sh_mu_25+cap_ssds_25*ss_mem*1000/fx_hi*sh_ss)*Mkt!$C$49,0)+0*Mkt!$C$49)*(1+g_oth_dram)^3+(MAX(Mkt!$C$42-(cap_sk_25*1000/fx_hi*sh_sk+cap_mu_25*sh_mu_25+cap_ssds_25*ss_mem*1000/fx_hi*sh_ss)*(1-Mkt!$C$49),0)+0*(1-Mkt!$C$49))*(1+g_oth_nand)^3)+(cap_ts_28*sh_fd+MAX(Mkt!$C$43-cap_ts_25*sh_fd,0)*(1+g_oth_fd)^3)+Mkt!F50*(((cap_sk_28*1000/fx_hi*sh_sk+cap_mu_28*sh_mu_27+cap_ss_28*1000/fx_hi*sh_ss)+(MAX(Mkt!$C$41-(cap_sk_25*1000/fx_hi*sh_sk+cap_mu_25*sh_mu_25+cap_ssds_25*ss_mem*1000/fx_hi*sh_ss)*Mkt!$C$49,0)+0*Mkt!$C$49)*(1+g_oth_dram)^3+(MAX(Mkt!$C$42-(cap_sk_25*1000/fx_hi*sh_sk+cap_mu_25*sh_mu_25+cap_ssds_25*ss_mem*1000/fx_hi*sh_ss)*(1-Mkt!$C$49),0)+0*(1-Mkt!$C$49))*(1+g_oth_nand)^3)+(cap_ts_28*sh_fd+MAX(Mkt!$C$43-cap_ts_25*sh_fd,0)*(1+g_oth_fd)^3))+Mkt!F87+Mkt!F88 -> 249.48205 | E14: =D14/D$4-1 -> -0.0031314086 | F14: =((cap_sk_29*1000/fx_hi*sh_sk+cap_mu_29*sh_mu_27+cap_ss_29*1000/fx_hi*sh_ss)+(MAX(Mkt!$C$41-(cap_sk_25*1000/fx_hi*sh_sk+cap_mu_25*sh_mu_25+cap_ssds_25*ss_mem*1000/fx_hi*sh_ss)*Mkt!$C$49,0)+0*Mkt!$C$49)*(1+g_oth_dram)^4+(MAX(Mkt!$C$42-(cap_sk_25*1000/fx_hi*sh_sk+cap_mu_25*sh_mu_25+cap_ssds_25*ss_mem*1000/fx_hi*sh_ss)*(1-Mkt!$C$49),0)+0*(1-Mkt!$C$49))*(1+g_oth_nand)^4)+(cap_ts_29*sh_fd+MAX(Mkt!$C$43-cap_ts_25*sh_fd,0)*(1+g_oth_fd)^4)+Mkt!G50*(((cap_sk_29*1000/fx_hi*sh_sk+cap_mu_29*sh_mu_27+cap_ss_29*1000/fx_hi*sh_ss)+(MAX(Mkt!$C$41-(cap_sk_25*1000/fx_hi*sh_sk+cap_mu_25*sh_mu_25+cap_ssds_25*ss_mem*1000/fx_hi*sh_ss)*Mkt!$C$49,0)+0*Mkt!$C$49)*(1+g_oth_dram)^4+(MAX(Mkt!$C$42-(cap_sk_25*1000/fx_hi*sh_sk+cap_mu_25*sh_mu_25+cap_ssds_25*ss_mem*1000/fx_hi*sh_ss)*(1-Mkt!$C$49),0)+0*(1-Mkt!$C$49))*(1+g_oth_nand)^4)+(cap_ts_29*sh_fd+MAX(Mkt!$C$43-cap_ts_25*sh_fd,0)*(1+g_oth_fd)^4))+Mkt!G87+Mkt!G88 -> 262.24642 | G14: =F14/F$4-1 -> -0.0013746155
