Workbook

Sheet README
A1: Arista Networks（ANET）收支與估值模型 v0.2（AI 半導體 Project：網通系統端樣板） 2026-10-25
A2: 版本：v0.1（初版）。Arista 在 AI 後端乙太網路交換器的份額在本模型 Units 頁建立，為本專案權威資料（規則第 13 條）。
A3: 模型命題：Arista 的 AI 營收＝AI 後端 scale-out 交換器市場（本專案網通模型）× 乙太網路占比 × Arista 份額（含前端與 scale-across 附掛）；非 AI（雲端前端、企業、園區）另依成長率推。股價約 37 倍前瞻 EPS：在 NVIDIA（Spectrum-X）與白牌夾擊下，Arista 的份額路徑能否支撐這個倍數？
A4: 核心問題：2027–28 年 Arista 在 AI 乙太網路的份額每掉一截，EPS 少多少；現價隱含的份額路徑合不合理。
A6: 會計年度＝日曆年，FY(t)＝CY(t)，不平移。預測期 FY2027–FY2029（三年）。口徑：公司 non-GAAP；十年 P/E 規則值用 GAAP 換算 EPS。
A8: 驅動因子 → 推導量（全部唯讀上游，不修改）
A9: AI 營收：markets/network 的 AI 後端 scale-out 交換器市場 × 情境顆數係數 × 乙太網路占比（Assumed）× Arista 有效份額（FY2026 以公司 AI 目標 3.5 校準）× 份額相對值（Assumed）。
A10: 非 AI 營收：FY2026 錨點（營收指引 − AI 目標）× Assumed 成長率。毛利率：AI 比非 AI 低 d_ai（Assumed），非 AI 毛利率為 FY2026 殘差（Derived）。營業費用：彈性 phi（Derived）。
A11: 校準：FY2026 ＝ 1Q–2Q 實績＋3Q 指引＋全年指引（營收 12.6、毛利率 63%、營業利益率 48.5%）。不用共識（只在 Recon 對帳）。
A12: 估值：現價 ÷ FY2027、FY2028 EPS；十年 GAAP P/E 規則值（兩個資料商來源）× FY2027 GAAP 換算 EPS；循環位置以本模型營收最高年判定（Arista 不套設備股見頂年）。
A13: 標記：Verified、Interested-party、Analogy、Assumed、Derived。SemiAnalysis 未使用。公司原文＝SEC EDGAR 8-K；法說內容只經二手轉述（標二手）。
A15: 已知限制：(1) 份額相對值與乙太網路占比皆為 Assumed，是 FY2028 EPS 最敏感的輸入（Sens）；(2) FY2026 AI 用公司目標「至少 3.5」，實際可能較高；(3) 網通模型 2027 年 scale-out 交換器 +90%，公司稱供給吃緊到 2028 年，模型未設供給上限（Sens 用市場 ×0.8）；(4) 2027 共識未找到，只有單一分析師；(5) 十年 P/E 含高成長期溢價；(6) R4 產業部署路徑未建（Recon 預留列）。
... A18: 情境對應（v0.2 延伸期）：A＝順利（基準顆數）、B＝平平（CY2028 ×0.8、CY2029 ×0.85）、C＝不如預期（CY2028–29 ×0.6）；FY2027 三情境相同，情境差從 FY2028 起。

Sheet In
A1: In — 輸入（藍字；基準欄 E，低 D、高 F）。金額：十億美元（US$B）；比例：%。每個輸入附兩個來源（找不到者寫「未找到」）；公司原文算一個
A2: 標記：Verified／Interested-party／Analogy／Assumed／Derived；Analogy、Assumed 給低／高區間。SemiAnalysis 未使用。公司原文＝Arista 8-K 新聞稿（SEC EDGAR）；公司的 AI 營收目標與全年指引為 Interested-party
A3: 鍵 | B3: 項目 | C3: 單位 | D3: 低 | E3: 基準 | F3: 高 | G3: 標記 | H3: 來源1 | I3: 來源2／說明
A4: A. AI 後端 scale-out 交換器市場（讀 markets/network 成品；情境 A 基準，B／C 依顆數係數縮放）
A5: mkt_26 | B5: AI 後端 scale-out 交換器市場 2026 | C5: US$B | E5: 32.0719 | G5: Derived | H5: markets/network/dist/20261023_AI網通市場模型_v0.2.2.xlsx｜Mkt!C7:F7 | I5: 加速器顆數 × 每顆 scale-out 交換器內容（不分乙太網路與 InfiniBand）；只含 AI 後端
A6: mkt_27 | B6: AI 後端 scale-out 交換器市場 2027 | C6: US$B | E6: 61.085 | G6: Derived | H6: markets/network/dist/20261023_AI網通市場模型_v0.2.2.xlsx｜Mkt!C7:F7 | I6: 同上
A7: mkt_28 | B7: AI 後端 scale-out 交換器市場 2028 | C7: US$B | E7: 69.005 | G7: Derived | H7: markets/network/dist/20261023_AI網通市場模型_v0.2.2.xlsx｜Mkt!C7:F7 | I7: 同上
A8: mkt_29 | B8: AI 後端 scale-out 交換器市場 2029 | C8: US$B | E8: 78.48215 | G8: Derived | H8: markets/network/dist/20261023_AI網通市場模型_v0.2.2.xlsx｜Mkt!C7:F7 | I8: 同上
A9: itc_26 | B9: AI IT 資本支出 2026 | C9: US$B | E9: 781.87292 | G9: Derived | H9: markets/network/dist/20261023_AI網通市場模型_v0.2.2.xlsx｜Mkt!C27:F27 | I9: Recon 用：Arista AI 營收 ÷ AI IT 資本支出
A10: itc_27 | B10: AI IT 資本支出 2027 | C10: US$B | E10: 1565.35 | G10: Derived | H10: markets/network/dist/20261023_AI網通市場模型_v0.2.2.xlsx｜Mkt!C27:F27 | I10: 同上
A11: itc_28 | B11: AI IT 資本支出 2028 | C11: US$B | E11: 1984.2639 | G11: Derived | H11: markets/network/dist/20261023_AI網通市場模型_v0.2.2.xlsx｜Mkt!C27:F27 | I11: 同上
A12: itc_29 | B12: AI IT 資本支出 2029 | C12: US$B | E12: 2260.3903 | G12: Derived | H12: markets/network/dist/20261023_AI網通市場模型_v0.2.2.xlsx｜Mkt!C27:F27 | I12: 同上
A13: um28_A | B13: 情境 A：2028 顆數 ÷ 基準 | C13: x | E13: 1 | G13: Assumed | H13: tsmc/dist/20261025_台積電模型_v0.3.xlsx｜In!E37 | I13: A＝基準；B＝AI 資本支出消化；C＝明顯下修（與台積電、NVIDIA、Broadcom 模型相同）
A14: um29_A | B14: 情境 A：2029 顆數 ÷ 基準 | C14: x | E14: 1 | G14: Assumed | H14: tsmc/dist/20261025_台積電模型_v0.3.xlsx｜In!E38 | I14: 同上
A15: um28_B | B15: 情境 B：2028 顆數 ÷ 基準 | C15: x | E15: 0.8 | G15: Assumed | H15: tsmc/dist/20261025_台積電模型_v0.3.xlsx｜In!E39 | I15: A＝基準；B＝AI 資本支出消化；C＝明顯下修（與台積電、NVIDIA、Broadcom 模型相同）
A16: um29_B | B16: 情境 B：2029 顆數 ÷ 基準 | C16: x | E16: 0.85 | G16: Assumed | H16: tsmc/dist/20261025_台積電模型_v0.3.xlsx｜In!E40 | I16: 同上
... A18: um29_C | B18: 情境 C：2029 顆數 ÷ 基準 | C18: x | E18: 0.6 | G18: Assumed | H18: tsmc/dist/20261025_台積電模型_v0.3.xlsx｜In!E42 | I18: 同上
A19: B. 乙太網路占比與 Arista 份額（本專案為權威：晶片商與網通廠份額，規則第 13 條）
A20: eth_26 | B20: 乙太網路 ÷ AI 後端交換器（金額）2026 | C20: % | D20: 0.7 | E20: 0.75 | F20: 0.8 | G20: Assumed | H20: Dell'Oro 2026-03-10：2025 年乙太網路占 AI 叢集交換器三分之二以上、為 InfiniBand 兩倍以上（Interested-party） | I20: IDC 2Q26：NVIDIA 資料中心乙太網路年增 181%（乙太網路取代 InfiniBand 的方向）
A21: eth_27 | B21: 乙太網路 ÷ AI 後端交換器 2027 | C21: % | D21: 0.72 | E21: 0.8 | F21: 0.88 | G21: Assumed | H21: 同上；2027 年無公開預測：未找到 | I21: 外推（Assumed）
A22: eth_28 | B22: 乙太網路 ÷ AI 後端交換器 2028 | C22: % | D22: 0.74 | E22: 0.83 | F22: 0.9 | G22: Assumed | H22: 同上 | I22: —
A23: eth_29 | B23: 乙太網路 ÷ AI 後端交換器 2029 | C23: % | D23: 0.75 | E23: 0.85 | F23: 0.92 | G23: Assumed | H23: 同上 | I23: —
A24: rel_27 | B24: Arista 份額 2027 ÷ 2026（相對值） | C24: x | D24: 0.8 | E24: 0.95 | F24: 1.05 | G24: Assumed | H24: IDC 2Q26：NVIDIA 20.4% 已超過 Arista 18.7%（資料中心乙太網路，全部速率；Interested-party） | I24: Dell'Oro 2025 AI 後端乙太網路：Celestica（白牌）與 NVIDIA 並列第一、合計約 50%，Arista 第三（Interested-party）
A25: rel_28 | B25: Arista 份額 2028 ÷ 2026 | C25: x | D25: 0.7 | E25: 0.9 | F25: 1.05 | G25: Assumed | H25: 同上 | I25: —
A26: rel_29 | B26: Arista 份額 2029 ÷ 2026 | C26: x | D26: 0.65 | E26: 0.88 | F26: 1.05 | G26: Assumed | H26: 同上 | I26: —
A27: C. 非 AI 營收（雲端前端、企業、園區、服務）
A28: g_nai27 | B28: 非 AI 營收年增 2027 | C28: % | D28: 0.03 | E28: 0.1 | F28: 0.15 | G28: Assumed | H28: 2026 錨點非 AI 約 9.1（營收指引 12.6 − AI 目標 3.5）；2025 約 7.4（9.0 − AI 約 1.63）→ 2026 約 +23%（Derived，含記憶體缺貨下的提前拉貨可能） | I28: 園區目標 2026 至少 1.25（公司，Interested-party）
A29: g_nai28 | B29: 非 AI 營收年增 2028 | C29: % | D29: 0.02 | E29: 0.08 | F29: 0.12 | G29: Assumed | H29: 同上 | I29: —
A30: g_nai29 | B30: 非 AI 營收年增 2029 | C30: % | D30: 0.02 | E30: 0.06 | F30: 0.1 | G30: Assumed | H30: 同上 | I30: —
A31: ai25 | B31: 2025 年 AI 營收（參考） | C31: US$B | D31: 1.5 | E31: 1.63 | F31: 1.8 | G31: Derived | H31: Next Platform 2026-02-13：以 2026 目標倒推約 1.63（公司稱超過 1.5 目標） | I31: 公司：2025 年 AI 目標 1.5 已超越（法說）
A32: D. 毛利率
A33: d_ai | B33: AI 營收毛利率低於非 AI 的幅度 | C33: pt | D33: 0.03 | E33: 0.06 | F33: 0.1 | G33: Assumed | H33: 公司：毛利率下滑來自雲端與 AI 大客戶占比（2Q26 毛利率較去年同期 −2.2 個百分點；法說，二手） | I33: 產品別毛利率未揭露：未找到
A34: E. FY2026 錨點（Q1–Q2 實績＋Q3 指引＋全年指引）
A35: fy_rev | B35: FY2026 營收指引 | C35: US$B | E35: 12.6 | G35: Interested-party | H35: 法說轉述：BigGo Finance 摘要（2026-08-04；二手）：約 $12.6B（8 月由 11.5 上修） | I35: StockAnalysis 共識 12.68（27 位）
A36: fy_gm | B36: FY2026 non-GAAP 毛利率指引（中點） | C36: % | D36: 0.62 | E36: 0.63 | F36: 0.64 | G36: Interested-party | H36: 法說轉述：BigGo Finance 摘要（2026-08-04；二手）：62–64% | I36: sec-api 彙整同值
A37: fy_oim | B37: FY2026 non-GAAP 營業利益率指引（中點） | C37: % | D37: 0.48 | E37: 0.485 | F37: 0.49 | G37: Interested-party | H37: 法說轉述：BigGo Finance 摘要（2026-08-04；二手）：48–49% | I37: sec-api 彙整同值
A38: q3_rev | B38: 3Q26 營收指引 | C38: US$B | E38: 3.3 | G38: Interested-party | H38: https://www.sec.gov/Archives/edgar/data/0001596532/000159653226000174/ex991q226-earningsrelease.htm：約 $3.3B | I38: BigGo（二手）同值
A39: q3_gm | B39: 3Q26 non-GAAP 毛利率指引 | C39: % | D39: 0.62 | E39: 0.63 | F39: 0.64 | G39: Interested-party | H39: 法說轉述：BigGo Finance 摘要（2026-08-04；二手）：約 63% | I39: 第二來源：未找到
A40: q3_oim | B40: 3Q26 non-GAAP 營業利益率指引（中點） | C40: % | D40: 0.48 | E40: 0.485 | F40: 0.49 | G40: Interested-party | H40: https://www.sec.gov/Archives/edgar/data/0001596532/000159653226000174/ex991q226-earningsrelease.htm：48–49% | I40: —
A41: q_oth | B41: 3Q、4Q26 non-GAAP 其他收益（每季） | C41: US$B | D41: 0.12 | E41: 0.13 | F41: 0.14 | G41: Derived | H41: 1Q26 0.1136、2Q26 0.1263（公司，GAAP 其他收益） | I41: 現金與有價證券 13.3（2026-06，公司）
...

Sheet Q
A1: Q — 實績（十億美元；EPS 為美元；股數為十億股）。口徑：公司 non-GAAP。藍字＝輸入；黑字＝公式。實績取自 Arista 8-K 新聞稿（SEC EDGAR、Business Wire）
A2: FY2026 錨點＝1Q26、2Q26 實績＋3Q26 指引＋4Q26（＝全年指引 − 前三季；毛利率、營業利益率同法）。1Q26＝上半年合計 − 2Q26。FY2025 non-GAAP 淨利與 EPS 為 2025 年度新聞稿原報值；公司 2026 年起改 non-GAAP 稅額方法並重編 2025 年各季，重編後的全年值：未找到
A3: 項目 | B3: FY2025A | C3: 1Q26 | D3: 2Q26 | E3: 3Q26（指引） | F3: 4Q26（全年指引 − 前三季） | G3: FY2026 錨點 | H3: 標記 | I3: 來源1（公司） | J3: 來源2／說明
A4: 營收 | B4: 9.0057 | C4: =5.7447-D4 -> 2.709 | D4: 3.0357 | E4: =q3_rev -> 3.3 | F4: =fy_rev-C4-D4-E4 -> 3.5553 | G4: =SUM(C4:F4) -> 12.6 | H4: Verified／Interested-party（3Q、4Q 指引） | I4: FY2025：https://www.businesswire.com/news/home/20260212962784/en/Arista-Networks-Inc.-Reports-Fourth-Quarter-and-Year-End-2025-Financial-Results；1Q26、2Q26：https://www.sec.gov/Archives/edgar/data/0001596532/000159653226000174/ex991q226-earningsrelease.htm（2Q26 與上半年合計） | J4: 1Q26＝上半年 − 2Q26；交叉：sec-api 彙整的 GAAP、non-GAAP 毛利率與營業利益率同值
A5: non-GAAP 毛利 | B5: 5.8154 | C5: =3.6155-D5 -> 1.6908 | D5: 1.9247 | E5: =E4*q3_gm -> 2.079 | F5: =fy_rev*fy_gm-C5-D5-E5 -> 2.2435 | G5: =SUM(C5:F5) -> 7.938 | H5: Verified／Interested-party | I5: FY2025：https://www.businesswire.com/news/home/20260212962784/en/Arista-Networks-Inc.-Reports-Fourth-Quarter-and-Year-End-2025-Financial-Results；1Q26、2Q26：https://www.sec.gov/Archives/edgar/data/0001596532/000159653226000174/ex991q226-earningsrelease.htm（2Q26 與上半年合計） | J5: 1Q26＝上半年 − 2Q26；交叉：sec-api 彙整的 GAAP、non-GAAP 毛利率與營業利益率同值
A6: 毛利率 | B6: =B5/B4 -> 0.64574658 | C6: =C5/C4 -> 0.62414175 | D6: =D5/D4 -> 0.63402181 | E6: =E5/E4 -> 0.63 | F6: =F5/F4 -> 0.63102973 | G6: =G5/G4 -> 0.63 | H6: Derived | I6: — | J6: FY2025 64.6%；FY2026 指引 62–64%
A7: non-GAAP 營業費用 | B7: =B5-B8 -> 1.4784 | C7: =C5-C8 -> 0.3968 | D7: =D5-D8 -> 0.411 | E7: =E5-E8 -> 0.4785 | F7: =F5-F8 -> 0.5407 | G7: =SUM(C7:F7) -> 1.827 | H7: Derived（毛利 − 營業利益） | I7: FY2025：https://www.businesswire.com/news/home/20260212962784/en/Arista-Networks-Inc.-Reports-Fourth-Quarter-and-Year-End-2025-Financial-Results；1Q26、2Q26：https://www.sec.gov/Archives/edgar/data/0001596532/000159653226000174/ex991q226-earningsrelease.htm（2Q26 與上半年合計） | J7: 1Q26＝上半年 − 2Q26；交叉：sec-api 彙整的 GAAP、non-GAAP 毛利率與營業利益率同值
A8: non-GAAP 營業利益 | B8: 4.337 | C8: =2.8077-D8 -> 1.294 | D8: 1.5137 | E8: =E4*q3_oim -> 1.6005 | F8: =fy_rev*fy_oim-C8-D8-E8 -> 1.7028 | G8: =SUM(C8:F8) -> 6.111 | H8: Verified／Interested-party | I8: FY2025：https://www.businesswire.com/news/home/20260212962784/en/Arista-Networks-Inc.-Reports-Fourth-Quarter-and-Year-End-2025-Financial-Results；1Q26、2Q26：https://www.sec.gov/Archives/edgar/data/0001596532/000159653226000174/ex991q226-earningsrelease.htm（2Q26 與上半年合計） | J8: 1Q26＝上半年 − 2Q26；交叉：sec-api 彙整的 GAAP、non-GAAP 毛利率與營業利益率同值
A9: 營業利益率 | B9: =B8/B4 -> 0.48158389 | C9: =C8/C4 -> 0.47766704 | D9: =D8/D4 -> 0.49863293 | E9: =E8/E4 -> 0.485 | F9: =F8/F4 -> 0.47894692 | G9: =G8/G4 -> 0.485 | H9: Derived | I9: — | J9: —
A10: 其他收益（GAAP，non-GAAP 沿用） | B10: 0.3936 | C10: =0.2399-D10 -> 0.1136 | D10: 0.1263 | E10: =q_oth -> 0.13 | F10: =q_oth -> 0.13 | G10: =SUM(C10:F10) -> 0.4999 | H10: Verified／Derived（3Q、4Q） | I10: FY2025：https://www.businesswire.com/news/home/20260212962784/en/Arista-Networks-Inc.-Reports-Fourth-Quarter-and-Year-End-2025-Financial-Results；1Q26、2Q26：https://www.sec.gov/Archives/edgar/data/0001596532/000159653226000174/ex991q226-earningsrelease.htm（2Q26 與上半年合計） | J10: 1Q26＝上半年 − 2Q26；交叉：sec-api 彙整的 GAAP、non-GAAP 毛利率與營業利益率同值
A11: 稅前利益 | B11: =B8+B10 -> 4.7306 | C11: =C8+C10 -> 1.4076 | D11: =D8+D10 -> 1.64 | E11: =E8+E10 -> 1.7305 | F11: =F8+F10 -> 1.8328 | G11: =SUM(C11:F11) -> 6.6109 | H11: Derived | I11: FY2025：https://www.businesswire.com/news/home/20260212962784/en/Arista-Networks-Inc.-Reports-Fourth-Quarter-and-Year-End-2025-Financial-Results；1Q26、2Q26：https://www.sec.gov/Archives/edgar/data/0001596532/000159653226000174/ex991q226-earningsrelease.htm（2Q26 與上半年合計） | J11: 1Q26＝上半年 − 2Q26；交叉：sec-api 彙整的 GAAP、non-GAAP 毛利率與營業利益率同值
A12: non-GAAP 淨利 | B12: 3.806 | C12: =2.4099-D12 -> 1.1082 | D12: 1.3017 | E12: =E11*(1-q_tx) -> 1.367095 | F12: =F11*(1-q_tx) -> 1.447912 | G12: =SUM(C12:F12) -> 5.224907 | H12: Verified／Derived（3Q、4Q） | I12: FY2025：https://www.businesswire.com/news/home/20260212962784/en/Arista-Networks-Inc.-Reports-Fourth-Quarter-and-Year-End-2025-Financial-Results；1Q26、2Q26：https://www.sec.gov/Archives/edgar/data/0001596532/000159653226000174/ex991q226-earningsrelease.htm（2Q26 與上半年合計） | J12: 1Q26＝上半年 − 2Q26；交叉：sec-api 彙整的 GAAP、non-GAAP 毛利率與營業利益率同值
A13: 有效稅率（推導） | B13: =1-B12/B11 -> 0.19545089 | C13: =1-C12/C11 -> 0.21270247 | D13: =1-D12/D11 -> 0.20628049 | E13: =1-E12/E11 -> 0.21 | F13: =1-F12/F11 -> 0.21 | G13: =1-G12/G11 -> 0.20965269 | H13: Derived | I13: — | J13: non-GAAP 稅額未直接揭露：1 − 淨利 ÷ 稅前
A14: 稀釋股數（十億股） | B14: 1.2757 | C14: =(1.2749*2-D14) -> 1.2738 | D14: 1.276 | E14: =q_sh -> 1.277 | F14: =q_sh -> 1.277 | G14: =AVERAGE(C14:F14) -> 1.27595 | H14: Verified／Derived | I14: FY2025：https://www.businesswire.com/news/home/20260212962784/en/Arista-Networks-Inc.-Reports-Fourth-Quarter-and-Year-End-2025-Financial-Results；1Q26、2Q26：https://www.sec.gov/Archives/edgar/data/0001596532/000159653226000174/ex991q226-earningsrelease.htm（2Q26 與上半年合計） | J14: 1Q26＝上半年加權 × 2 − 2Q26（近似）
A15: non-GAAP EPS | B15: =B12/B14 -> 2.9834601 | C15: =C12/C14 -> 0.86999529 | D15: =D12/D14 -> 1.0201411 | E15: =E12/E14 -> 1.0705521 | F15: =F12/F14 -> 1.1338387 | G15: =G12/G14 -> 4.0949152 | H15: Derived | I15: 淨利 ÷ 稀釋股數 | J15: —
A16: 公司揭露 non-GAAP EPS | B16: 2.98 | D16: 1.02 | H16: Verified | I16: FY2025：https://www.businesswire.com/news/home/20260212962784/en/Arista-Networks-Inc.-Reports-Fourth-Quarter-and-Year-End-2025-Financial-Results；1Q26、2Q26：https://www.sec.gov/Archives/edgar/data/0001596532/000159653226000174/ex991q226-earningsrelease.htm（2Q26 與上半年合計） | J16: 1Q26：1.89 − 1.02＝0.87；3Q26 指引 1.06–1.08
A17: AI 營收 | B17: =ai25 -> 1.63 | G17: =ai26 -> 3.5 | H17: Derived／Interested-party | I17: FY2025：In ai25；FY2026：公司目標「至少 3.5」 | J17: 各季 AI 營收未揭露：未找到
A18: 非 AI 營收（＝營收 − AI） | B18: =B4-B17 -> 7.3757 | G18: =G4-G17 -> 9.1 | H18: Derived | I18: — | J18: —
A19: AI ÷ 營收 | B19: =B17/B4 -> 0.18099648 | G19: =G17/G4 -> 0.27777778 | H19: Derived | I19: — | J19: Andy 先驗 A2：2026 年 50%
A21: FY2026 錨點與共識的距離（參考；校準未使用共識）
A22: FY2026 營收 ÷ 共識 − 1 | B22: =G4/cons_rev26-1 -> -0.0063091483
A23: FY2026 EPS ÷ 共識 − 1 | B23: =G15/cons_eps26-1 -> -0.0060885531
A24: FY2026 營收年增 | B24: =G4/B4-1 -> 0.39911389
A25: FY2026 營業費用年增 | B25: =G7/B7-1 -> 0.23579545
A26: 營業費用彈性（營業費用年增 ÷ 營收年增；In 頁 phi 的依據） | B26: =B25/B24 -> 0.59079741
A27: 3Q26 EPS（模型）vs 公司指引中點 1.07 | B27: =E15/1.07-1 -> 0.00051595811

Sheet Units
A1: Units — Arista 在 AI 後端乙太網路交換器的份額（本專案權威，規則第 13 條）。市場取自 markets/network（只含 AI 後端 scale-out 交換器，不分協定）
A3: 項目 | B3: 單位 | C3: CY2026 | D3: CY2027 | E3: CY2028 | F3: CY2029 | G3: 說明
A4: AI 後端 scale-out 交換器市場（情境 A） | B4: US$B | C4: =PL!D63 -> 32.0719 | D4: =PL!E63 -> 61.085 | E4: =PL!F63 -> 69.005 | F4: =PL!G63 -> 78.48215 | G4: markets/network Mkt 頁
A5: 乙太網路占比 | B5: % | C5: =PL!D64 -> 0.75 | D5: =PL!E64 -> 0.8 | E5: =PL!F64 -> 0.83 | F5: =PL!G64 -> 0.85 | G5: In 頁 B 節（Assumed）
A6: AI 後端乙太網路交換器市場 | B6: US$B | C6: =PL!D65 -> 24.053925 | D6: =PL!E65 -> 48.868 | E6: =PL!F65 -> 57.27415 | F6: =PL!G65 -> 66.709828
A7: InfiniBand 等其他協定（＝市場 − 乙太網路） | B7: US$B | C7: =PL!D63-PL!D65 -> 8.017975 | D7: =PL!E63-PL!E65 -> 12.217 | E7: =PL!F63-PL!F65 -> 11.73085 | F7: =PL!G63-PL!G65 -> 11.772322 | G7: 幾乎全為 NVIDIA
A8: Arista 有效份額（含前端與 scale-across） | B8: % | C8: =PL!D68 -> 0.1455064 | D8: =PL!E68 -> 0.13823108 | E8: =PL!F68 -> 0.13095576 | F8: =PL!G68 -> 0.12804563 | G8: FY2026 以公司 AI 目標校準
A9: Arista AI 營收（情境 A） | B9: US$B | C9: =PL!D69 -> 3.5 | D9: =PL!E69 -> 6.7550764 | E9: =PL!F69 -> 7.5003798 | F9: =PL!G69 -> 8.5419019
A10: 其他廠商（NVIDIA Spectrum-X、白牌、Cisco 等）＝ 乙太網路市場 − Arista | B10: US$B | C10: =PL!D65-PL!D69 -> 20.553925 | D10: =PL!E65-PL!E69 -> 42.112924 | E10: =PL!F65-PL!F69 -> 49.77377 | F10: =PL!G65-PL!G69 -> 58.167926 | G10: 上限：Arista AI 含前端，所以此列偏低
A11: Arista AI 營收 ÷ AI IT 資本支出 | B11: % | C11: =PL!D69/itc_26 -> 0.0044764308 | D11: =PL!E69/itc_27 -> 0.0043153776 | E11: =PL!F69/itc_28 -> 0.0037799306 | F11: =PL!G69/itc_29 -> 0.00377895 | G11: markets/network 的 AI IT 資本支出（加速器 × 每顆 IT capex）
A13: 讀法：FY2026 有效份額約 15%，與 Dell'Oro「Celestica＋NVIDIA 合計約 50%、Arista 第三」相容；本模型的份額路徑（相對值）是 Assumed，是最需要每季檢查的輸入。

Sheet PL
A1: PL — Arista 損益（US$B；non-GAAP）。FY2025A 實績、FY2026 錨點（1Q–2Q 實績＋3Q 指引＋全年指引），FY2027 起為模型。FY(t)＝CY(t)。三情境各一個完整推導區塊（本頁下方），頂端為摘要。FY2026–FY2027 三情境相同（顆數係數從 CY2028 開始）
A3: 情境／項目 | B3: 單位 | C3: FY2025A | D3: FY2026（錨點） | E3: FY2027 | F3: FY2028 | G3: FY2029 | H3: 說明
A4: 情境 A
A5: 營收 | B5: US$B | C5: =C72 -> 9.0057 | D5: =D72 -> 12.6 | E5: =E72 -> 16.765076 | F5: =F72 -> 18.31118 | G5: =G72 -> 20.00135
A6: 營收年增 | B6: % | D6: =D73 -> 0.39911389 | E6: =E73 -> 0.33056162 | F6: =F73 -> 0.092221675 | G6: =G73 -> 0.092302637
A7: AI 營收 | B7: US$B | C7: =C69 -> 1.63 | D7: =D69 -> 3.5 | E7: =E69 -> 6.7550764 | F7: =F69 -> 7.5003798 | G7: =G69 -> 8.5419019
A8: 非 AI 營收 | B8: US$B | C8: =C71 -> 7.3757 | D8: =D71 -> 9.1 | E8: =E71 -> 10.01 | F8: =F71 -> 10.8108 | G8: =G71 -> 11.459448
A9: AI ÷ 營收 | B9: % | C9: =C74 -> 0.18099648 | D9: =D74 -> 0.27777778 | E9: =E74 -> 0.40292548 | F9: =F74 -> 0.40960658 | G9: =G74 -> 0.42706627
A10: 毛利率 | B10: % | C10: =C78 -> 0.64574658 | D10: =D78 -> 0.63 | E10: =E78 -> 0.62249114 | F10: =F78 -> 0.62209027 | G10: =G78 -> 0.62104269
A11: 營業利益率 | B11: % | C11: =C82 -> 0.48158389 | D11: =D82 -> 0.485 | E11: =E82 -> 0.4937017 | F11: =F82 -> 0.49819428 | G11: =G82 -> 0.501858
A12: 淨利（non-GAAP） | B12: US$B | C12: =C85 -> 3.806 | D12: =D85 -> 5.224907 | E12: =E85 -> 6.9732878 | F12: =F85 -> 7.6412947 | G12: =G85 -> 8.3643916
A13: EPS（non-GAAP） | B13: US$ | C13: =C87 -> 2.9834601 | D13: =D87 -> 4.0949152 | E13: =E87 -> 5.4651733 | F13: =F87 -> 5.9887102 | G13: =G87 -> 6.5554227
A14: EPS 年增 | B14: % | D14: =D88 -> 0.37253896 | E14: =E88 -> 0.3346243 | F14: =F88 -> 0.095795113 | G14: =G88 -> 0.094630147
A16: 情境 B
A17: 營收 | B17: US$B | C17: =C103 -> 9.0057 | D17: =D103 -> 12.6 | E17: =E103 -> 16.765076 | F17: =F103 -> 16.811104 | G17: =G103 -> 18.720065
A18: 營收年增 | B18: % | D18: =D104 -> 0.39911389 | E18: =E104 -> 0.33056162 | F18: =F104 -> 0.0027454371 | G18: =G104 -> 0.11355357
A19: AI 營收 | B19: US$B | C19: =C100 -> 1.63 | D19: =D100 -> 3.5 | E19: =E100 -> 6.7550764 | F19: =F100 -> 6.0003038 | G19: =G100 -> 7.2606167
A20: 非 AI 營收 | B20: US$B | C20: =C102 -> 7.3757 | D20: =D102 -> 9.1 | E20: =E102 -> 10.01 | F20: =F102 -> 10.8108 | G20: =G102 -> 11.459448
A21: AI ÷ 營收 | B21: % | C21: =C105 -> 0.18099648 | D21: =D105 -> 0.27777778 | E21: =E105 -> 0.40292548 | F21: =F105 -> 0.35692503 | G21: =G105 -> 0.38785211
A22: 毛利率 | B22: % | C22: =C109 -> 0.64574658 | D22: =D109 -> 0.63 | E22: =E109 -> 0.62249114 | F22: =F109 -> 0.62525116 | G22: =G109 -> 0.62339554
A23: 營業利益率 | B23: % | C23: =C113 -> 0.48158389 | D23: =D113 -> 0.485 | E23: =E113 -> 0.4937017 | F23: =F113 -> 0.4966204 | G23: =G113 -> 0.50066742
A24: 淨利（non-GAAP） | B24: US$B | C24: =C116 -> 3.806 | D24: =D116 -> 5.224907 | E24: =E116 -> 6.9732878 | F24: =F116 -> 7.0300023 | G24: =G116 -> 7.838796
A25: EPS（non-GAAP） | B25: US$ | C25: =C118 -> 2.9834601 | D25: =D118 -> 4.0949152 | E25: =E118 -> 5.4651733 | F25: =F118 -> 5.5096221 | G25: =G118 -> 6.1434978
A26: EPS 年增 | B26: % | D26: =D119 -> 0.37253896 | E26: =E119 -> 0.3346243 | F26: =F119 -> 0.0081331023 | G26: =G119 -> 0.11504885
A28: 情境 C
A29: 營收 | B29: US$B | C29: =C134 -> 9.0057 | D29: =D134 -> 12.6 | E29: =E134 -> 16.765076 | F29: =F134 -> 15.311028 | G29: =G134 -> 16.584589
A30: 營收年增 | B30: % | D30: =D135 -> 0.39911389 | E30: =E135 -> 0.33056162 | F30: =F135 -> -0.0867308 | G30: =G135 -> 0.083179347
A31: AI 營收 | B31: US$B | C31: =C131 -> 1.63 | D31: =D131 -> 3.5 | E31: =E131 -> 6.7550764 | F31: =F131 -> 4.5002279 | G31: =G131 -> 5.1251412
A32: 非 AI 營收 | B32: US$B | C32: =C133 -> 7.3757 | D32: =D133 -> 9.1 | E32: =E133 -> 10.01 | F32: =F133 -> 10.8108 | G32: =G133 -> 11.459448
A33: AI ÷ 營收 | B33: % | C33: =C136 -> 0.18099648 | D33: =D136 -> 0.27777778 | E33: =E136 -> 0.40292548 | F33: =F136 -> 0.29392069 | G33: =G136 -> 0.30903034
A34: 毛利率 | B34: % | C34: =C140 -> 0.64574658 | D34: =D140 -> 0.63 | E34: =E140 -> 0.62249114 | F34: =F140 -> 0.62903143 | G34: =G140 -> 0.62812485
A35: 營業利益率 | B35: % | C35: =C144 -> 0.48158389 | D35: =D144 -> 0.485 | E35: =E144 -> 0.4937017 | F35: =F144 -> 0.48801118 | G35: =G144 -> 0.49197775
A36: 淨利（non-GAAP） | B36: US$B | C36: =C147 -> 3.806 | D36: =D147 -> 5.224907 | E36: =E147 -> 6.9732878 | F36: =F147 -> 6.3373427 | G36: =G147 -> 6.8803066
A37: EPS（non-GAAP） | B37: US$ | C37: =C149 -> 2.9834601 | D37: =D149 -> 4.0949152 | E37: =E149 -> 5.4651733 | F37: =F149 -> 4.9667642 | G37: =G149 -> 5.3923011
A38: EPS 年增 | B38: % | D38: =D150 -> 0.37253896 | E38: =E150 -> 0.3346243 | F38: =F150 -> -0.091197309 | G38: =G150 -> 0.085676892
A40: 核對（應為 0）：FY2026 模型營收 − 錨點；FY2026 模型 AI − 公司目標（校準恆等式）
A41: 情境 A：營收差（US$B） | D41: =D72-a26_rev -> 0
A42: 情境 A：AI 差（US$B） | D42: =D69-a26_ai -> 0
A43: 情境 A：毛利差（US$B） | D43: =D76*D71+(D76-d_ai)*D69-a26_gp -> 0
A60: 情境 A：基準（顆數係數 1.0）
...

Sheet Val
A1: Val — P/E 估值（美元）。結論用「現價 ÷ FY2027、FY2028 EPS（模型）」與十年 P/E 規則值。Arista 的 GAAP 與 non-GAAP 差距小（約 7%），十年 GAAP P/E 適用；規則值以 GAAP 換算 EPS（non-GAAP × g2n）計算
A2: 循環位置：Arista 不是設備股，不套設備市場見頂年；以本模型營收最高的會計年度為見頂年（比照 NVIDIA；FY(t)＝CY(t)，不平移）。營收到 FY2029 仍在增加時，見頂年未知，判為中段
A3: 0. 目標價（DCF 與 Comparable 加權；v0.2 新增，Andy 2026-10-25）
A4: 0.1 DCF（股東權益現金流，FY2027–FY2032 明確期＋FY2032 後永續）
A5: 項目 | B5: A | C5: B | D5: C | E5: 說明 | F5: 折現年數 t | G5: 期內占比（基準日後）
A6: 情境 EPS（FY2027–FY2032） | E6: 引用 PL 頁延伸表（上游結束後為收斂法）；三情境欄 B／C／D＝A／B／C
A7: FY2027 | B7: =PL!E162 -> 5.4651733 | C7: =PL!E171 -> 5.4651733 | D7: =PL!E180 -> 5.4651733 | F7: 1 | G7: 1
A8: FY2028 | B8: =PL!F162 -> 5.9887102 | C8: =PL!F171 -> 5.5096221 | D8: =PL!F180 -> 4.9667642 | F8: 2 | G8: 1
A9: FY2029 | B9: =PL!G162 -> 6.5554227 | C9: =PL!G171 -> 6.1434978 | D9: =PL!G180 -> 5.3923011 | F9: 3 | G9: 1
A10: FY2030 | B10: =PL!H162 -> 7.0899197 | C10: =PL!H171 -> 6.4674722 | D10: =PL!H180 -> 5.3454506 | F10: 4 | G10: 1
A11: FY2031 | B11: =PL!I162 -> 7.5916559 | C11: =PL!I171 -> 6.6473348 | D11: =PL!I180 -> 5.1674384 | F11: 5 | G11: 1
A12: FY2032 | B12: =PL!J162 -> 8.0471552 | C12: =PL!J171 -> 6.6663272 | D12: =PL!J180 -> 4.865342 | F12: 6 | G12: 1
A13: 股東現金流＝EPS ×（1 − tp_g ÷ tp_roe） | B13: =1-MIN(0.8,tp_g/tp_roe) -> 0.86018875 | E13: B 欄＝可發放比例（1 − 再投資率；再投資率＝tp_g ÷ tp_roe，上限 0.8）；下列六列＝EPS × 可發放比例 × 期內占比
A14: FY2027 股東現金流 | B14: =B7*$B$13*$G$7 -> 4.7010805 | C14: =C7*$B$13*$G$7 -> 4.7010805 | D14: =D7*$B$13*$G$7 -> 4.7010805
A15: FY2028 股東現金流 | B15: =B8*$B$13*$G$8 -> 5.1514211 | C15: =C8*$B$13*$G$8 -> 4.7393149 | D15: =D8*$B$13*$G$8 -> 4.2723546
A16: FY2029 股東現金流 | B16: =B9*$B$13*$G$9 -> 5.6389008 | C16: =C9*$B$13*$G$9 -> 5.2845676 | D16: =D9*$B$13*$G$9 -> 4.6383967
A17: FY2030 股東現金流 | B17: =B10*$B$13*$G$10 -> 6.0986691 | C17: =C10*$B$13*$G$10 -> 5.5632468 | D17: =D10*$B$13*$G$10 -> 4.5980964
A18: FY2031 股東現金流 | B18: =B11*$B$13*$G$11 -> 6.5302569 | C18: =C11*$B$13*$G$11 -> 5.7179626 | D18: =D11*$B$13*$G$11 -> 4.4449723
A19: FY2032 股東現金流 | B19: =B12*$B$13*$G$12 -> 6.9220724 | C19: =C12*$B$13*$G$12 -> 5.7342996 | D19: =D12*$B$13*$G$12 -> 4.1851124
A20: 永續價值（FY2032 年底；FY2032 現金流 ×(1＋tp_g) ÷ (tp_r − tp_g)） | B20: =B19*(1+tp_g)/(tp_r-tp_g) -> 119.98259 | C20: =C19*(1+tp_g)/(tp_r-tp_g) -> 99.394527 | D20: =D19*(1+tp_g)/(tp_r-tp_g) -> 72.541948
A21: DCF 情境每股價值（折現率 tp_r） | B21: =MAX(0,B14/(1+tp_r)^$F$7+B15/(1+tp_r)^$F$8+B16/(1+tp_r)^$F$9+B17/(1+tp_r)^$F$10+B18/(1+tp_r)^$F$11+B19/(1+tp_r)^$F$12+B20/(1+tp_r)^$F$12) -> 92.622293 | C21: =MAX(0,C14/(1+tp_r)^$F$7+C15/(1+tp_r)^$F$8+C16/(1+tp_r)^$F$9+C17/(1+tp_r)^$F$10+C18/(1+tp_r)^$F$11+C19/(1+tp_r)^$F$12+C20/(1+tp_r)^$F$12) -> 78.853532 | D21: =MAX(0,D14/(1+tp_r)^$F$7+D15/(1+tp_r)^$F$8+D16/(1+tp_r)^$F$9+D17/(1+tp_r)^$F$10+D18/(1+tp_r)^$F$11+D19/(1+tp_r)^$F$12+D20/(1+tp_r)^$F$12) -> 60.500443 | E21: 基準日 2026 年底；明確期現金流與永續價值依 F 欄年數折現；小於 0 時取 0（Andy 2026-10-25 12:22）
A22: 其中：永續價值現值占比 | B22: =B20/(1+tp_r)^$F$12/B21 -> 0.73121751 | C22: =C20/(1+tp_r)^$F$12/C21 -> 0.71151688 | D22: =D20/(1+tp_r)^$F$12/D21 -> 0.67682213
A23: DCF 目標價（情境加權） | B23: =(tp_wA*B21+tp_wB*C21+tp_wC*D21)*(1+tp_r) -> 87.244897 | E23: Σ 權重 × 情境價值 ×(1＋tp_r)：推到約 12 個月後
A25: 0.2 Comparable（市場主流同業前瞻 P/E）
A26: 同業與前瞻 P/E | B26: 代號 | C26: 前瞻 12 月 P/E | D26: 日期 | E26: 來源 | F26: 標記
A27: Cisco | B27: CSCO | C27: 20.7 | D27: 2026-10-23 | E27: stockanalysis.com 統計頁（Forward PE） | F27: Interested-party（資料商彙整賣方預估）
A28: Ciena | B28: CIEN | C28: 30.77 | D28: 2026-10-23 | E28: 同上 | F28: Interested-party（同上）
A29: Celestica | B29: CLS | C29: 16.65 | D29: 2026-10-23 | E29: 同上 | F29: Interested-party（同上）
A30: Hewlett Packard Enterprise（含 Juniper） | B30: HPE | C30: 12.19 | D30: 2026-10-23 | E30: 同上 | F30: Interested-party（同上）
A31: Credo | B31: CRDO | C31: 20.19 | D31: 2026-10-23 | E31: 同上 | F31: Interested-party（同上）
A32: 同業選擇 | E32: 券商常用的資料中心網通同業（交換器：Cisco、HPE＋Juniper；光傳輸：Ciena；白牌交換器 ODM：Celestica；AI 互連：Credo）；不含 A 股（Andy 11:53）。前瞻 P/E 口徑為資料商的未來 12 個月共識 EPS，各家 GAAP／non-GAAP 口徑不一
A33: 同業前瞻 P/E 中位數 | B33: =MEDIAN(C27:C31) -> 20.19
A34: 各情境 12 個月後的前瞻 EPS | B34: =2/12*PL!E162+10/12*PL!F162 -> 5.901454 | C34: =2/12*PL!E171+10/12*PL!F171 -> 5.5022139 | D34: =2/12*PL!E180+10/12*PL!F180 -> 5.0498324 | E34: 會計年度＝日曆年：約 12 個月後（2027-10 底）的未來 12 個月＝2027-11～2028-10（2/12 × FY2027＋10/12 × FY2028）
A35: 12 個月後的前瞻 EPS（情境加權） | B35: =tp_wA*B34+tp_wB*C34+tp_wC*D34 -> 5.5315096
A36: Comparable 目標價 | B36: =B33*B35 -> 111.68118 | E36: 同業前瞻 P/E 中位數 × 12 個月後的前瞻 EPS（情境加權）
A38: 0.3 結論
A39: 項目 | B39: 數值 | C39: 對照 | D39: 對照 | E39: 說明
A40: 目標價（DCF 與 Comparable 加權） | B40: =tp_w_dcf*B23+(1-tp_w_dcf)*B36 -> 99.463038 | E40: ="DCF 權重 "&TEXT(tp_w_dcf,"0%")&"、Comparable 權重 "&TEXT(1-tp_w_dcf,"0%")&"（In 頁 tp_w_dcf，Andy 可改）" -> DCF 權重 50%、Comparable 權重 50%（In 頁 tp_w_dcf，Andy 可改）
A41: Comparable 目標價（市場主流同業法） | B41: =B36 -> 111.68118
A42: 市場共識目標價 | B42: =cons_tp -> 243.59 | E42: stockanalysis.com：32 位分析師平均目標價（2026-10-23）；Interested-party
...

Sheet Recon
A1: Recon — 本模型 vs 公司指引、共識、研調份額。只作事後對照，不為對上數字而調參數。2027 年共識（StockAnalysis 付費）未找到，只有單一分析師與前瞻 P/E 隱含值
A3: 項目 | B3: 對照值 | C3: 模型 A | D3: 差距 A | E3: 模型 B | F3: 差距 B | G3: 模型 C | H3: 差距 C | I3: 對照來源 | J3: 說明
A4: A. 共識與分析師（校準未使用）
A5: FY2026 營收 vs 共識 | B5: =cons_rev26 -> 12.68 | C5: =PL!D72 -> 12.6 | D5: =C5/B5-1 -> -0.0063091483 | E5: =PL!D103 -> 12.6 | F5: =E5/B5-1 -> -0.0063091483 | G5: =PL!D134 -> 12.6 | H5: =G5/B5-1 -> -0.0063091483 | I5: StockAnalysis | J5: 錨點＝公司全年指引 12.6
A6: FY2026 EPS vs 共識 | B6: =cons_eps26 -> 4.12 | C6: =PL!D87 -> 4.0949152 | D6: =C6/B6-1 -> -0.0060885531 | E6: =PL!D118 -> 4.0949152 | F6: =E6/B6-1 -> -0.0060885531 | G6: =PL!D149 -> 4.0949152 | H6: =G6/B6-1 -> -0.0060885531 | I6: StockAnalysis | J6: 錨點（3Q、4Q 依指引與 In 頁假設）
A7: FY2027 EPS vs Erste Group（單一分析師） | B7: =erste_eps27 -> 4.79 | C7: =PL!E87 -> 5.4651733 | D7: =C7/B7-1 -> 0.14095475 | E7: =PL!E118 -> 5.4651733 | F7: =E7/B7-1 -> 0.14095475 | G7: =PL!E149 -> 5.4651733 | H7: =G7/B7-1 -> 0.14095475 | I7: MarketBeat | J7: 2027 共識：未找到（付費）
A8: FY2027 EPS vs 前瞻 P/E 隱含未來 12 月 EPS | B8: =px/pe_fwd_sa -> 4.6511063 | C8: =PL!E87 -> 5.4651733 | D8: =C8/B8-1 -> 0.17502652 | E8: =PL!E118 -> 5.4651733 | F8: =E8/B8-1 -> 0.17502652 | G8: =PL!E149 -> 5.4651733 | H8: =G8/B8-1 -> 0.17502652 | I8: StockAnalysis（推導） | J8: 未來 12 月 ≈ 4Q26＋¾ FY2027，口徑不同，只作量級比較
A9: FY2027 營收年增（模型） | C9: =PL!E73 -> 0.33056162 | E9: =PL!E104 -> 0.33056162 | G9: =PL!E135 -> 0.33056162 | I9: —
A10: B. 份額與市場（先驗比對的機制檢查）
A11: FY2026 Arista 有效份額 vs IDC 資料中心乙太網路份額（全部速率） | B11: =idc_anet -> 0.187 | C11: =PL!D66 -> 0.1455064 | D11: =C11-B11 -> -0.041493601 | E11: =PL!D97 -> 0.1455064 | F11: =E11-B11 -> -0.041493601 | G11: =PL!D128 -> 0.1455064 | H11: =G11-B11 -> -0.041493601 | I11: IDC 2Q26 | J11: 口徑不同：IDC 含前端與非 AI；本模型分母只含 AI 後端
A12: FY2026 Arista 有效份額 vs 1 − Celestica、NVIDIA 合計（上限） | B12: =1-dell_top2 -> 0.5 | C12: =PL!D66 -> 0.1455064 | D12: =C12-B12 -> -0.3544936 | E12: =PL!D97 -> 0.1455064 | F12: =E12-B12 -> -0.3544936 | G12: =PL!D128 -> 0.1455064 | H12: =G12-B12 -> -0.3544936 | I12: Dell'Oro 2025 | J12: Arista 第三，有效份額應低於上限
A13: FY2027 AI ÷ 營收 vs Andy 先驗（54%） | B13: 0.54 | C13: =PL!E74 -> 0.40292548 | D13: =C13-B13 -> -0.13707452 | E13: =PL!E105 -> 0.40292548 | F13: =E13-B13 -> -0.13707452 | G13: =PL!E136 -> 0.40292548 | H13: =G13-B13 -> -0.13707452 | I13: 先驗_Andy_Arista A2（Drive）
A14: FY2027 Arista AI 營收 ÷ AI IT 資本支出 | C14: =PL!E69/itc_27 -> 0.0043153776 | E14: =PL!E100/itc_27 -> 0.0043153776 | G14: =PL!E131/itc_27 -> 0.0043153776 | I14: markets/network | J14: Andy 先驗 A7：每 GW 4 億美元
A15: FY2028 Arista AI 營收 ÷ AI 後端乙太網路市場（有效份額） | C15: =PL!F68 -> 0.13095576 | E15: =PL!F99 -> 0.13095576 | G15: =PL!F130 -> 0.13095576 | I15: —
A16: C. 校準
A17: 非 AI 毛利率（Derived） | C17: =PL!D76 -> 0.64666667 | E17: =PL!D107 -> 0.64666667 | G17: =PL!D138 -> 0.64666667 | I17: FY2026 錨點 | J17: AI 毛利率＝此值 − d_ai
A18: FY2027 毛利率 vs FY2026（百分點） | B18: =a26_gp/a26_rev -> 0.63 | C18: =PL!E78 -> 0.62249114 | D18: =C18-B18 -> -0.0075088618 | E18: =PL!E109 -> 0.62249114 | F18: =E18-B18 -> -0.0075088618 | G18: =PL!E140 -> 0.62249114 | H18: =G18-B18 -> -0.0075088618 | I18: 錨點 | J18: AI 占比上升使毛利率下滑
A19: 3Q26 EPS（模型）vs 公司指引中點 1.07 | B19: 1.07 | C19: =Q!E15 -> 1.0705521 | D19: =C19/B19-1 -> 0.00051595811 | E19: =Q!E15 -> 1.0705521 | F19: =E19/B19-1 -> 0.00051595811 | G19: =Q!E15 -> 1.0705521 | H19: =G19/B19-1 -> 0.00051595811 | I19: 公司（2Q26 新聞稿）
A20: D. 預留
A21: R4 產業部署路徑（markets/deploy_path/，尚未建立）：上線後以 Arista AI 營收 ÷ 部署 GW 計算每 GW 營收，對照 Andy 先驗 A7 | J21: 預留列：本版無數值

Sheet Sens
A1: Sens — 一次動一個輸入（情境 A；有效份額、非 AI 毛利率在每個案例內依 FY2026 錨點重算，FY2026 恆等於錨點）：對 FY2027、FY2028 的營收、AI 營收、毛利率與 EPS 的影響。每個案例是一個完整推導區塊（本頁下方）
A3: 案例 | B3: 設定 | C3: FY2027 營收 | D3: FY2027 AI 營收 | E3: FY2027 毛利率 | F3: FY2027 EPS | G3: FY2027 EPS 相對基準 | H3: FY2028 營收 | I3: FY2028 AI 營收 | J3: FY2028 毛利率 | K3: FY2028 EPS | L3: FY2028 EPS 相對基準
A4: 基準（情境 A） | B4: PL 區塊 A | C4: =PL!E72 -> 16.765076 | D4: =PL!E69 -> 6.7550764 | E4: =PL!E78 -> 0.62249114 | F4: =PL!E87 -> 5.4651733 | G4: =F4/F$4-1 -> 0 | H4: =PL!F72 -> 18.31118 | I4: =PL!F69 -> 7.5003798 | J4: =PL!F78 -> 0.62209027 | K4: =PL!F87 -> 5.9887102 | L4: =K4/K$4-1 -> 0
A5: 份額流失（低） | B5: 份額相對值 2027 0.80、2028 0.70、2029 0.65（NVIDIA、白牌加速） | C5: =E52 -> 15.698485 | D5: =E49 -> 5.6884854 | E5: =E58 -> 0.62492513 | F5: =E67 -> 5.1304176 | G5: =F5/F$4-1 -> -0.061252524 | H5: =F52 -> 16.644429 | I5: =F49 -> 5.8336287 | J5: =F58 -> 0.62563754 | K5: =F67 -> 5.4612046 | L5: =K5/K$4-1 -> -0.088083335
A6: 份額持平（高） | B6: 份額相對值 1.05 | C6: =E83 -> 17.476137 | D6: =E80 -> 7.466137 | E6: =E89 -> 0.62103353 | F6: =E98 -> 5.6883437 | G6: =F6/F$4-1 -> 0.040835016 | H6: =F83 -> 19.561243 | I6: =F80 -> 8.7504431 | J6: =F89 -> 0.61982652 | K6: =F98 -> 6.3854418 | L6: =K6/K$4-1 -> 0.066246588
A7: 乙太網路占比 低 | B7: 2026 70% → 2029 75% | C7: =E114 -> 16.523824 | D7: =E111 -> 6.5138236 | E7: =E120 -> 0.62301419 | F7: =E129 -> 5.3894547 | G7: =F7/F$4-1 -> -0.013854737 | H7: =F114 -> 17.975535 | I7: =F111 -> 7.1647345 | J7: =F120 -> 0.62275171 | K7: =F129 -> 5.882491 | L7: =K7/K$4-1 -> -0.01773657
A8: 乙太網路占比 高 | B8: 2026 80% → 2029 92% | C8: =E145 -> 16.976172 | D8: =E142 -> 6.9661725 | E8: =E151 -> 0.62204567 | F8: =E160 -> 5.531427 | G8: =F8/F$4-1 -> 0.012122895 | H8: =F145 -> 18.435433 | I8: =F142 -> 7.6246331 | J8: =F151 -> 0.62185152 | K8: =F160 -> 6.0275314 | L8: =K8/K$4-1 -> 0.0064824029
A9: AI 市場 ×0.8 | B9: FY2027 起 scale-out 交換器市場 ×0.8（供給受限或內容不如預期） | C9: =E176 -> 15.414061 | D9: =E173 -> 5.4040611 | E9: =E182 -> 0.62563109 | F9: =E191 -> 5.0411494 | G9: =F9/F$4-1 -> -0.07758653 | H9: =F176 -> 16.811104 | I9: =F173 -> 6.0003038 | J9: =F182 -> 0.62525116 | K9: =F191 -> 5.5150351 | L9: =K9/K$4-1 -> -0.079094667
A10: AI 市場 ×1.2 | B10: ×1.2 | C10: =E207 -> 18.116092 | D10: =E204 -> 8.1060916 | E10: =E213 -> 0.61981951 | F10: =E222 -> 5.8891971 | G10: =F10/F$4-1 -> 0.07758653 | H10: =F207 -> 19.811256 | I10: =F204 -> 9.0004557 | J10: =F213 -> 0.61940805 | K10: =F222 -> 6.4624515 | L10: =K10/K$4-1 -> 0.079105735
A11: 非 AI 成長 低 | B11: 2027 +3%、2028–29 +2% | C11: =E238 -> 16.128076 | D11: =E235 -> 6.7550764 | E11: =E244 -> 0.62153629 | F11: =E253 -> 5.2415834 | G11: =F11/F$4-1 -> -0.040911759 | H11: =F238 -> 17.06084 | I11: =F235 -> 7.5003798 | J11: =F244 -> 0.62028914 | K11: =F253 -> 5.5458342 | L11: =K11/K$4-1 -> -0.073951803
A12: 非 AI 成長 高 | B12: 2027 +15%、2028 +12%、2029 +10% | C12: =E269 -> 17.220076 | D12: =E266 -> 6.7550764 | E12: =E275 -> 0.62312992 | F12: =E284 -> 5.6248803 | G12: =F12/F$4-1 -> 0.029222685 | H12: =F269 -> 19.22118 | I12: =F266 -> 7.5003798 | J12: =F275 -> 0.62325381 | K12: =F284 -> 6.3115189 | L12: =K12/K$4-1 -> 0.053902882
A13: AI 毛利率差距 3pt | B13: AI 毛利率只低 3 個百分點 | C13: =E300 -> 16.765076 | D13: =E297 -> 6.7550764 | E13: =E306 -> 0.62624557 | F13: =E315 -> 5.5041444 | G13: =F13/F$4-1 -> 0.0071308147 | H13: =F300 -> 18.31118 | I13: =F297 -> 7.5003798 | J13: =F306 -> 0.62604514 | K13: =F315 -> 6.0335477 | L13: =K13/K$4-1 -> 0.0074870035
A14: AI 毛利率差距 10pt | B14: 低 10 個百分點 | C14: =E331 -> 16.765076 | D14: =E328 -> 6.7550764 | E14: =E337 -> 0.61748523 | F14: =E346 -> 5.4132118 | G14: =F14/F$4-1 -> -0.009507753 | H14: =F331 -> 18.31118 | I14: =F328 -> 7.5003798 | J14: =F337 -> 0.61681712 | K14: =F346 -> 5.9289268 | L14: =K14/K$4-1 -> -0.0099826713
A15: 營業費用率 +2pt | B15: 營業費用額外 +2% × 營收 | C15: =E362 -> 16.765076 | D15: =E359 -> 6.7550764 | E15: =E368 -> 0.62249114 | F15: =E377 -> 5.2575725 | G15: =F15/F$4-1 -> -0.037986128 | H15: =F362 -> 18.31118 | I15: =F359 -> 7.5003798 | J15: =F368 -> 0.62209027 | K15: =F377 -> 5.7619641 | L15: =K15/K$4-1 -> -0.037862254
A16: 顆數情境 B | B16: CY2028 ×0.8、CY2029 ×0.85 | C16: =PL!E103 -> 16.765076 | D16: =PL!E100 -> 6.7550764 | E16: =PL!E109 -> 0.62249114 | F16: =PL!E118 -> 5.4651733 | G16: =F16/F$4-1 -> 0 | H16: =PL!F103 -> 16.811104 | I16: =PL!F100 -> 6.0003038 | J16: =PL!F109 -> 0.62525116 | K16: =PL!F118 -> 5.5096221 | L16: =K16/K$4-1 -> -0.079998541
A17: 顆數情境 C | B17: CY2028–29 ×0.6 | C17: =PL!E134 -> 16.765076 | D17: =PL!E131 -> 6.7550764 | E17: =PL!E140 -> 0.62249114 | F17: =PL!E149 -> 5.4651733 | G17: =F17/F$4-1 -> 0 | H17: =PL!F134 -> 15.311028 | I17: =PL!F131 -> 4.5002279 | J17: =PL!F140 -> 0.62903143 | K17: =PL!F149 -> 4.9667642 | L17: =K17/K$4-1 -> -0.17064542
A19: 讀法：FY2027 三情境相同；顆數情境 B、C 的差異從 FY2028 起。份額與乙太網路占比的案例中，FY2026 有效份額依新的乙太網路占比重算，所以 FY2026 恆等於錨點。
A21: 目標價參數敏感度（v0.2）：加權目標價（Val 第 0 節）一次動一個參數；PL 延伸期的收斂路徑不隨 tp_g 變動，tp_g 只改再投資率與永續成長
A22: 參數 | B22: 設定（低／高） | C22: 低：加權目標價 | D22: 低：相對基準 | E22: 高：加權目標價 | F22: 高：相對基準 | G22: 基準加權目標價
A23: tp_r ±1pt | B23: 折現率 −1pt／＋1pt | C23: =tp_w_dcf*(tp_wA*(MAX(0,Val!B7*Val!$G$7*(1-MIN(0.8,tp_g/tp_roe))/(1+(tp_r-0.01))^Val!$F$7+Val!B8*Val!$G$8*(1-MIN(0.8,tp_g/tp_roe))/(1+(tp_r-0.01))^Val!$F$8+Val!B9*Val!$G$9*(1-MIN(0.8,tp_g/tp_roe))/(1+(tp_r-0.01))^Val!$F$9+Val!B10*Val!$G$10*(1-MIN(0.8,tp_g/tp_roe))/(1+(tp_r-0.01))^Val!$F$10+Val!B11*Val!$G$11*(1-MIN(0.8,tp_g/tp_roe))/(1+(tp_r-0.01))^Val!$F$11+Val!B12*Val!$G$12*(1-MIN(0.8,tp_g/tp_roe))/(1+(tp_r-0.01))^Val!$F$12+Val!B12*(1-MIN(0.8,tp_g/tp_roe))*(1+tp_g)/((tp_r-0.01)-tp_g)/(1+(tp_r-0.01))^Val!$F$12))+tp_wB*(MAX(0,Val!C7*Val!$G$7*(1-MIN(0.8,tp_g/tp_roe))/(1+(tp_r-0.01))^Val!$F$7+Val!C8*Val!$G$8*(1-MIN(0.8,tp_g/tp_roe))/(1+(tp_r-0.01))^Val!$F$8+Val!C9*Val!$G$9*(1-MIN(0.8,tp_g/tp_roe))/(1+(tp_r-0.01))^Val!$F$9+Val!C10*Val!$G$10*(1-MIN(0.8,tp_g/tp_roe))/(1+(tp_r-0.01))^Val!$F$10+Val!C11*Val!$G$11*(1-MIN(0.8,tp_g/tp_roe))/(1+(tp_r-0.01))^Val!$F$11+Val!C12*Val!$G$12*(1-MIN(0.8,tp_g/tp_roe))/(1+(tp_r-0.01))^Val!$F$12+Val!C12*(1-MIN(0.8,tp_g/tp_roe))*(1+tp_g)/((tp_r-0.01)-tp_g)/(1+(tp_r-0.01))^Val!$F$12))+tp_wC*(MAX(0,Val!D7*Val!$G$7*(1-MIN(0.8,tp_g/tp_roe))/(1+(tp_r-0.01))^Val!$F$7+Val!D8*Val!$G$8*(1-MIN(0.8,tp_g/tp_roe))/(1+(tp_r-0.01))^Val!$F$8+Val!D9*Val!$G$9*(1-MIN(0.8,tp_g/tp_roe))/(1+(tp_r-0.01))^Val!$F$9+Val!D10*Val!$G$10*(1-MIN(0.8,tp_g/tp_roe))/(1+(tp_r-0.01))^Val!$F$10+Val!D11*Val!$G$11*(1-MIN(0.8,tp_g/tp_roe))/(1+(tp_r-0.01))^Val!$F$11+Val!D12*Val!$G$12*(1-MIN(0.8,tp_g/tp_roe))/(1+(tp_r-0.01))^Val!$F$12+Val!D12*(1-MIN(0.8,tp_g/tp_roe))*(1+tp_g)/((tp_r-0.01)-tp_g)/(1+(tp_r-0.01))^Val!$F$12)))*(1+(tp_r-0.01))+(1-tp_w_dcf)*Val!$B$36 -> 107.70283 | D23: =C23/G23-1 -> 0.082842754 | E23: =tp_w_dcf*(tp_wA*(MAX(0,Val!B7*Val!$G$7*(1-MIN(0.8,tp_g/tp_roe))/(1+(tp_r+0.01))^Val!$F$7+Val!B8*Val!$G$8*(1-MIN(0.8,tp_g/tp_roe))/(1+(tp_r+0.01))^Val!$F$8+Val!B9*Val!$G$9*(1-MIN(0.8,tp_g/tp_roe))/(1+(tp_r+0.01))^Val!$F$9+Val!B10*Val!$G$10*(1-MIN(0.8,tp_g/tp_roe))/(1+(tp_r+0.01))^Val!$F$10+Val!B11*Val!$G$11*(1-MIN(0.8,tp_g/tp_roe))/(1+(tp_r+0.01))^Val!$F$11+Val!B12*Val!$G$12*(1-MIN(0.8,tp_g/tp_roe))/(1+(tp_r+0.01))^Val!$F$12+Val!B12*(1-MIN(0.8,tp_g/tp_roe))*(1+tp_g)/((tp_r+0.01)-tp_g)/(1+(tp_r+0.01))^Val!$F$12))+tp_wB*(MAX(0,Val!C7*Val!$G$7*(1-MIN(0.8,tp_g/tp_roe))/(1+(tp_r+0.01))^Val!$F$7+Val!C8*Val!$G$8*(1-MIN(0.8,tp_g/tp_roe))/(1+(tp_r+0.01))^Val!$F$8+Val!C9*Val!$G$9*(1-MIN(0.8,tp_g/tp_roe))/(1+(tp_r+0.01))^Val!$F$9+Val!C10*Val!$G$10*(1-MIN(0.8,tp_g/tp_roe))/(1+(tp_r+0.01))^Val!$F$10+Val!C11*Val!$G$11*(1-MIN(0.8,tp_g/tp_roe))/(1+(tp_r+0.01))^Val!$F$11+Val!C12*Val!$G$12*(1-MIN(0.8,tp_g/tp_roe))/(1+(tp_r+0.01))^Val!$F$12+Val!C12*(1-MIN(0.8,tp_g/tp_roe))*(1+tp_g)/((tp_r+0.01)-tp_g)/(1+(tp_r+0.01))^Val!$F$12))+tp_wC*(MAX(0,Val!D7*Val!$G$7*(1-MIN(0.8,tp_g/tp_roe))/(1+(tp_r+0.01))^Val!$F$7+Val!D8*Val!$G$8*(1-MIN(0.8,tp_g/tp_roe))/(1+(tp_r+0.01))^Val!$F$8+Val!D9*Val!$G$9*(1-MIN(0.8,tp_g/tp_roe))/(1+(tp_r+0.01))^Val!$F$9+Val!D10*Val!$G$10*(1-MIN(0.8,tp_g/tp_roe))/(1+(tp_r+0.01))^Val!$F$10+Val!D11*Val!$G$11*(1-MIN(0.8,tp_g/tp_roe))/(1+(tp_r+0.01))^Val!$F$11+Val!D12*Val!$G$12*(1-MIN(0.8,tp_g/tp_roe))/(1+(tp_r+0.01))^Val!$F$12+Val!D12*(1-MIN(0.8,tp_g/tp_roe))*(1+tp_g)/((tp_r+0.01)-tp_g)/(1+(tp_r+0.01))^Val!$F$12)))*(1+(tp_r+0.01))+(1-tp_w_dcf)*Val!$B$36 -> 93.576482 | F23: =E23/G23-1 -> -0.059183358 | G23: =Val!$B$40 -> 99.463038
A24: tp_g ±1pt | B24: 長期成長 −1pt／＋1pt | C24: =tp_w_dcf*(tp_wA*(MAX(0,Val!B7*Val!$G$7*(1-MIN(0.8,(tp_g-0.01)/tp_roe))/(1+tp_r)^Val!$F$7+Val!B8*Val!$G$8*(1-MIN(0.8,(tp_g-0.01)/tp_roe))/(1+tp_r)^Val!$F$8+Val!B9*Val!$G$9*(1-MIN(0.8,(tp_g-0.01)/tp_roe))/(1+tp_r)^Val!$F$9+Val!B10*Val!$G$10*(1-MIN(0.8,(tp_g-0.01)/tp_roe))/(1+tp_r)^Val!$F$10+Val!B11*Val!$G$11*(1-MIN(0.8,(tp_g-0.01)/tp_roe))/(1+tp_r)^Val!$F$11+Val!B12*Val!$G$12*(1-MIN(0.8,(tp_g-0.01)/tp_roe))/(1+tp_r)^Val!$F$12+Val!B12*(1-MIN(0.8,(tp_g-0.01)/tp_roe))*(1+(tp_g-0.01))/(tp_r-(tp_g-0.01))/(1+tp_r)^Val!$F$12))+tp_wB*(MAX(0,Val!C7*Val!$G$7*(1-MIN(0.8,(tp_g-0.01)/tp_roe))/(1+tp_r)^Val!$F$7+Val!C8*Val!$G$8*(1-MIN(0.8,(tp_g-0.01)/tp_roe))/(1+tp_r)^Val!$F$8+Val!C9*Val!$G$9*(1-MIN(0.8,(tp_g-0.01)/tp_roe))/(1+tp_r)^Val!$F$9+Val!C10*Val!$G$10*(1-MIN(0.8,(tp_g-0.01)/tp_roe))/(1+tp_r)^Val!$F$10+Val!C11*Val!$G$11*(1-MIN(0.8,(tp_g-0.01)/tp_roe))/(1+tp_r)^Val!$F$11+Val!C12*Val!$G$12*(1-MIN(0.8,(tp_g-0.01)/tp_roe))/(1+tp_r)^Val!$F$12+Val!C12*(1-MIN(0.8,(tp_g-0.01)/tp_roe))*(1+(tp_g-0.01))/(tp_r-(tp_g-0.01))/(1+tp_r)^Val!$F$12))+tp_wC*(MAX(0,Val!D7*Val!$G$7*(1-MIN(0.8,(tp_g-0.01)/tp_roe))/(1+tp_r)^Val!$F$7+Val!D8*Val!$G$8*(1-MIN(0.8,(tp_g-0.01)/tp_roe))/(1+tp_r)^Val!$F$8+Val!D9*Val!$G$9*(1-MIN(0.8,(tp_g-0.01)/tp_roe))/(1+tp_r)^Val!$F$9+Val!D10*Val!$G$10*(1-MIN(0.8,(tp_g-0.01)/tp_roe))/(1+tp_r)^Val!$F$10+Val!D11*Val!$G$11*(1-MIN(0.8,(tp_g-0.01)/tp_roe))/(1+tp_r)^Val!$F$11+Val!D12*Val!$G$12*(1-MIN(0.8,(tp_g-0.01)/tp_roe))/(1+tp_r)^Val!$F$12+Val!D12*(1-MIN(0.8,(tp_g-0.01)/tp_roe))*(1+(tp_g-0.01))/(tp_r-(tp_g-0.01))/(1+tp_r)^Val!$F$12)))*(1+tp_r)+(1-tp_w_dcf)*Val!$B$36 -> 96.344162 | D24: =C24/G24-1 -> -0.031357132 | E24: =tp_w_dcf*(tp_wA*(MAX(0,Val!B7*Val!$G$7*(1-MIN(0.8,(tp_g+0.01)/tp_roe))/(1+tp_r)^Val!$F$7+Val!B8*Val!$G$8*(1-MIN(0.8,(tp_g+0.01)/tp_roe))/(1+tp_r)^Val!$F$8+Val!B9*Val!$G$9*(1-MIN(0.8,(tp_g+0.01)/tp_roe))/(1+tp_r)^Val!$F$9+Val!B10*Val!$G$10*(1-MIN(0.8,(tp_g+0.01)/tp_roe))/(1+tp_r)^Val!$F$10+Val!B11*Val!$G$11*(1-MIN(0.8,(tp_g+0.01)/tp_roe))/(1+tp_r)^Val!$F$11+Val!B12*Val!$G$12*(1-MIN(0.8,(tp_g+0.01)/tp_roe))/(1+tp_r)^Val!$F$12+Val!B12*(1-MIN(0.8,(tp_g+0.01)/tp_roe))*(1+(tp_g+0.01))/(tp_r-(tp_g+0.01))/(1+tp_r)^Val!$F$12))+tp_wB*(MAX(0,Val!C7*Val!$G$7*(1-MIN(0.8,(tp_g+0.01)/tp_roe))/(1+tp_r)^Val!$F$7+Val!C8*Val!$G$8*(1-MIN(0.8,(tp_g+0.01)/tp_roe))/(1+tp_r)^Val!$F$8+Val!C9*Val!$G$9*(1-MIN(0.8,(tp_g+0.01)/tp_roe))/(1+tp_r)^Val!$F$9+Val!C10*Val!$G$10*(1-MIN(0.8,(tp_g+0.01)/tp_roe))/(1+tp_r)^Val!$F$10+Val!C11*Val!$G$11*(1-MIN(0.8,(tp_g+0.01)/tp_roe))/(1+tp_r)^Val!$F$11+Val!C12*Val!$G$12*(1-MIN(0.8,(tp_g+0.01)/tp_roe))/(1+tp_r)^Val!$F$12+Val!C12*(1-MIN(0.8,(tp_g+0.01)/tp_roe))*(1+(tp_g+0.01))/(tp_r-(tp_g+0.01))/(1+tp_r)^Val!$F$12))+tp_wC*(MAX(0,Val!D7*Val!$G$7*(1-MIN(0.8,(tp_g+0.01)/tp_roe))/(1+tp_r)^Val!$F$7+Val!D8*Val!$G$8*(1-MIN(0.8,(tp_g+0.01)/tp_roe))/(1+tp_r)^Val!$F$8+Val!D9*Val!$G$9*(1-MIN(0.8,(tp_g+0.01)/tp_roe))/(1+tp_r)^Val!$F$9+Val!D10*Val!$G$10*(1-MIN(0.8,(tp_g+0.01)/tp_roe))/(1+tp_r)^Val!$F$10+Val!D11*Val!$G$11*(1-MIN(0.8,(tp_g+0.01)/tp_roe))/(1+tp_r)^Val!$F$11+Val!D12*Val!$G$12*(1-MIN(0.8,(tp_g+0.01)/tp_roe))/(1+tp_r)^Val!$F$12+Val!D12*(1-MIN(0.8,(tp_g+0.01)/tp_roe))*(1+(tp_g+0.01))/(tp_r-(tp_g+0.01))/(1+tp_r)^Val!$F$12)))*(1+tp_r)+(1-tp_w_dcf)*Val!$B$36 -> 104.00369 | F24: =E24/G24-1 -> 0.045651683 | G24: =Val!$B$40 -> 99.463038
A25: tp_w_dcf 0.3／0.7 | B25: DCF 權重 0.3／0.7 | C25: =0.3*(tp_wA*(MAX(0,Val!B7*Val!$G$7*(1-MIN(0.8,tp_g/tp_roe))/(1+tp_r)^Val!$F$7+Val!B8*Val!$G$8*(1-MIN(0.8,tp_g/tp_roe))/(1+tp_r)^Val!$F$8+Val!B9*Val!$G$9*(1-MIN(0.8,tp_g/tp_roe))/(1+tp_r)^Val!$F$9+Val!B10*Val!$G$10*(1-MIN(0.8,tp_g/tp_roe))/(1+tp_r)^Val!$F$10+Val!B11*Val!$G$11*(1-MIN(0.8,tp_g/tp_roe))/(1+tp_r)^Val!$F$11+Val!B12*Val!$G$12*(1-MIN(0.8,tp_g/tp_roe))/(1+tp_r)^Val!$F$12+Val!B12*(1-MIN(0.8,tp_g/tp_roe))*(1+tp_g)/(tp_r-tp_g)/(1+tp_r)^Val!$F$12))+tp_wB*(MAX(0,Val!C7*Val!$G$7*(1-MIN(0.8,tp_g/tp_roe))/(1+tp_r)^Val!$F$7+Val!C8*Val!$G$8*(1-MIN(0.8,tp_g/tp_roe))/(1+tp_r)^Val!$F$8+Val!C9*Val!$G$9*(1-MIN(0.8,tp_g/tp_roe))/(1+tp_r)^Val!$F$9+Val!C10*Val!$G$10*(1-MIN(0.8,tp_g/tp_roe))/(1+tp_r)^Val!$F$10+Val!C11*Val!$G$11*(1-MIN(0.8,tp_g/tp_roe))/(1+tp_r)^Val!$F$11+Val!C12*Val!$G$12*(1-MIN(0.8,tp_g/tp_roe))/(1+tp_r)^Val!$F$12+Val!C12*(1-MIN(0.8,tp_g/tp_roe))*(1+tp_g)/(tp_r-tp_g)/(1+tp_r)^Val!$F$12))+tp_wC*(MAX(0,Val!D7*Val!$G$7*(1-MIN(0.8,tp_g/tp_roe))/(1+tp_r)^Val!$F$7+Val!D8*Val!$G$8*(1-MIN(0.8,tp_g/tp_roe))/(1+tp_r)^Val!$F$8+Val!D9*Val!$G$9*(1-MIN(0.8,tp_g/tp_roe))/(1+tp_r)^Val!$F$9+Val!D10*Val!$G$10*(1-MIN(0.8,tp_g/tp_roe))/(1+tp_r)^Val!$F$10+Val!D11*Val!$G$11*(1-MIN(0.8,tp_g/tp_roe))/(1+tp_r)^Val!$F$11+Val!D12*Val!$G$12*(1-MIN(0.8,tp_g/tp_roe))/(1+tp_r)^Val!$F$12+Val!D12*(1-MIN(0.8,tp_g/tp_roe))*(1+tp_g)/(tp_r-tp_g)/(1+tp_r)^Val!$F$12)))*(1+tp_r)+(1-0.3)*Val!$B$36 -> 104.35029 | D25: =C25/G25-1 -> 0.04913641 | E25: =0.7*(tp_wA*(MAX(0,Val!B7*Val!$G$7*(1-MIN(0.8,tp_g/tp_roe))/(1+tp_r)^Val!$F$7+Val!B8*Val!$G$8*(1-MIN(0.8,tp_g/tp_roe))/(1+tp_r)^Val!$F$8+Val!B9*Val!$G$9*(1-MIN(0.8,tp_g/tp_roe))/(1+tp_r)^Val!$F$9+Val!B10*Val!$G$10*(1-MIN(0.8,tp_g/tp_roe))/(1+tp_r)^Val!$F$10+Val!B11*Val!$G$11*(1-MIN(0.8,tp_g/tp_roe))/(1+tp_r)^Val!$F$11+Val!B12*Val!$G$12*(1-MIN(0.8,tp_g/tp_roe))/(1+tp_r)^Val!$F$12+Val!B12*(1-MIN(0.8,tp_g/tp_roe))*(1+tp_g)/(tp_r-tp_g)/(1+tp_r)^Val!$F$12))+tp_wB*(MAX(0,Val!C7*Val!$G$7*(1-MIN(0.8,tp_g/tp_roe))/(1+tp_r)^Val!$F$7+Val!C8*Val!$G$8*(1-MIN(0.8,tp_g/tp_roe))/(1+tp_r)^Val!$F$8+Val!C9*Val!$G$9*(1-MIN(0.8,tp_g/tp_roe))/(1+tp_r)^Val!$F$9+Val!C10*Val!$G$10*(1-MIN(0.8,tp_g/tp_roe))/(1+tp_r)^Val!$F$10+Val!C11*Val!$G$11*(1-MIN(0.8,tp_g/tp_roe))/(1+tp_r)^Val!$F$11+Val!C12*Val!$G$12*(1-MIN(0.8,tp_g/tp_roe))/(1+tp_r)^Val!$F$12+Val!C12*(1-MIN(0.8,tp_g/tp_roe))*(1+tp_g)/(tp_r-tp_g)/(1+tp_r)^Val!$F$12))+tp_wC*(MAX(0,Val!D7*Val!$G$7*(1-MIN(0.8,tp_g/tp_roe))/(1+tp_r)^Val!$F$7+Val!D8*Val!$G$8*(1-MIN(0.8,tp_g/tp_roe))/(1+tp_r)^Val!$F$8+Val!D9*Val!$G$9*(1-MIN(0.8,tp_g/tp_roe))/(1+tp_r)^Val!$F$9+Val!D10*Val!$G$10*(1-MIN(0.8,tp_g/tp_roe))/(1+tp_r)^Val!$F$10+Val!D11*Val!$G$11*(1-MIN(0.8,tp_g/tp_roe))/(1+tp_r)^Val!$F$11+Val!D12*Val!$G$12*(1-MIN(0.8,tp_g/tp_roe))/(1+tp_r)^Val!$F$12+Val!D12*(1-MIN(0.8,tp_g/tp_roe))*(1+tp_g)/(tp_r-tp_g)/(1+tp_r)^Val!$F$12)))*(1+tp_r)+(1-0.7)*Val!$B$36 -> 94.575782 | F25: =E25/G25-1 -> -0.04913641 | G25: =Val!$B$40 -> 99.463038
A40: 案例區塊：份額流失（低）（情境 A）
A41: 項目 | B41: 單位 | C41: FY2025A | D41: FY2026（錨點） | E41: FY2027 | F41: FY2028 | G41: FY2029 | H41: 說明
A42: A. AI 營收（D 欄＝FY2026 校準年；E–G＝FY2027–FY2029）
A43: AI 後端 scale-out 交換器市場 × 情境顆數係數 | B43: US$B | D43: =mkt_26*1 -> 32.0719 | E43: =mkt_27*1*1 -> 61.085 | F43: =mkt_28*um28_A*1 -> 69.005 | G43: =mkt_29*um29_A*1 -> 78.48215
A44: 乙太網路占比 | B44: % | D44: =eth_26 -> 0.75 | E44: =eth_27 -> 0.8 | F44: =eth_28 -> 0.83 | G44: =eth_29 -> 0.85
A45: AI 後端乙太網路交換器市場 | B45: US$B | D45: =D43*D44 -> 24.053925 | E45: =E43*E44 -> 48.868 | F45: =F43*F44 -> 57.27415 | G45: =G43*G44 -> 66.709828
A46: Arista 有效份額（FY2026 校準）＝ AI 目標 ÷ 乙太網路市場 | B46: % | D46: =a26_ai/D45 -> 0.1455064 | H46: Derived：分子含前端與 scale-across，所以高於純後端份額；FY2027 起乘相對值
A47: 份額相對值（÷ FY2026） | B47: x | D47: =1 -> 1 | E47: =RLO_27 -> 0.8 | F47: =RLO_28 -> 0.7 | G47: =RLO_29 -> 0.65
A48: Arista 有效份額 | B48: % | D48: =$D$46*D47 -> 0.1455064 | E48: =$D$46*E47 -> 0.11640512 | F48: =$D$46*F47 -> 0.10185448 | G48: =$D$46*G47 -> 0.094579159
A49: AI 營收 | B49: US$B | C49: =a25_ai -> 1.63 | D49: =D45*D48 -> 3.5 | E49: =E45*E48 -> 5.6884854 | F49: =F45*F48 -> 5.8336287 | G49: =G45*G48 -> 6.3093594
A50: B. 非 AI 與合計
A51: 非 AI 營收 | B51: US$B | C51: =a25_nai -> 7.3757 | D51: =a26_nai -> 9.1 | E51: =D51*(1+g_nai27) -> 10.01 | F51: =E51*(1+g_nai28) -> 10.8108 | G51: =F51*(1+g_nai29) -> 11.459448
A52: 營收 | B52: US$B | C52: =a25_rev -> 9.0057 | D52: =D49+D51 -> 12.6 | E52: =E49+E51 -> 15.698485 | F52: =F49+F51 -> 16.644429 | G52: =G49+G51 -> 17.768807
A53: 營收年增 | B53: % | D53: =D52/C52-1 -> 0.39911389 | E53: =E52/D52-1 -> 0.24591154 | F53: =F52/E52-1 -> 0.060256983 | G53: =G52/F52-1 -> 0.067552855
A54: AI ÷ 營收 | B54: % | C54: =C49/C52 -> 0.18099648 | D54: =D49/D52 -> 0.27777778 | E54: =E49/E52 -> 0.36235887 | F54: =F49/F52 -> 0.35048537 | G54: =G49/G52 -> 0.35508063
A55: C. 損益
A56: 非 AI 毛利率 ＝ 錨點毛利率 ＋ 差距 × AI 占比（FY2026 校準） | B56: % | D56: =a26_gp/a26_rev+d_ai*D54 -> 0.64666667 | H56: Derived：讓 FY2026 毛利率等於錨點；AI 毛利率＝非 AI − 差距。FY2027 起毛利率隨 AI 占比變動
A57: 毛利 | B57: US$B | C57: =a25_gp -> 5.8154 | D57: =a26_gp -> 7.938 | E57: =$D$56*E51+($D$56-d_ai)*E49 -> 9.8103781 | F57: =$D$56*F51+($D$56-d_ai)*F49 -> 10.41338 | G57: =$D$56*G51+($D$56-d_ai)*G49 -> 11.111934
...

Sheet Sources
A1: 來源（公司原文＝Arista 8-K 新聞稿，已逐份抓取；法說內容只經二手轉述）
A2: 公司：2Q26 新聞稿（含上半年合計、3Q26 指引） | B2: https://www.sec.gov/Archives/edgar/data/0001596532/000159653226000174/ex991q226-earningsrelease.htm
A3: 公司：4Q25 與 FY2025 新聞稿 | B3: https://www.businesswire.com/news/home/20260212962784/en/Arista-Networks-Inc.-Reports-Fourth-Quarter-and-Year-End-2025-Financial-Results
A4: 二手：BigGo Finance 2Q26 法說摘要（全年指引 12.6、AI 至少 3.5、scale-across 約 1.2、毛利率與營業利益率指引） | B4: https://finance.biggo.com/news/US_ANET_2026-08-04
A5: 二手：sec-api 彙整（客戶集中、遞延收入、GAAP／non-GAAP 毛利率與營業利益率） | B5: https://sec-api.io/insights/arista-networks-anet-stock-analysis-q2-2026-ai-networking-revenue-deferred-revenue-customer-concentration-insider-sales-and-scenarios-to-fy2029
A6: 二手：Next Platform（2025 營收、2025 AI 約 1.63、微軟 26%、Meta 16%） | B6: https://www.nextplatform.com/2026/02/13/the-current-ai-networking-wave-will-be-a-tsunami-of-money-by-2027/
A7: 研調：IDC 2Q26 乙太網路交換器（NVIDIA 20.4%、Arista 18.7%、Cisco 18.2%） | B7: https://www.idc.com/resource-center/blog/ethernet-switch-market-surges-43-4-to-18-9b-in-2q26-as-ai-infrastructure-demand-drives-record-datacenter-spending/
A8: 研調：Dell'Oro 2025 AI 後端（乙太網路超過 InfiniBand 兩倍；Celestica、NVIDIA 並列第一，Arista 第三） | B8: https://www.delloro.com/news/ethernet-more-than-doubles-size-of-infiniband-as-the-leading-fabric-for-ai-scale-out-networks-in-2025/
A9: 二手：StockAnalysis 現價、前瞻 P/E、2026 共識 | B9: https://stockanalysis.com/stocks/anet/forecast/
A10: 二手：MarketBeat（Erste FY2027 EPS 4.79） | B10: https://www.marketbeat.com/instant-alerts/estimates-fy2027-eps-forecast-for-arista-networks-increased-by-analyst-2026-10-23/
A11: 資料商：companiesmarketcap 年底 P/E | B11: https://companiesmarketcap.com/arista-networks/pe-ratio/
A12: 資料商：Macrotrends 季度 P/E（至 2024-04） | B12: https://www.macrotrends.net/stocks/charts/ANET/arista-networks/pe-ratio
A13: 市場層：markets/network、tsmc 成品（本 repo，唯讀）
A14: 待補（人工）：2027 共識（付費）；各季 AI 營收；產品別毛利率；前瞻 P/E 十年歷史（Bloomberg）；重編後 FY2025 non-GAAP 淨利 | B14: 未找到
A15: SemiAnalysis | B15: 未使用
