Workbook

Sheet README
A1: Amazon（AMZN）個股模型 v0.3（命題模組＋官方營收分部 → 損益表） 2026-10-27
A2: 版本：v0.3（架構重建；取代 v0.2.2 的 CoreWeave 式收支引擎，舊引擎移至 legacy_v0.2/）。資料截至 2026Q2（10-Q 2026-07-31）；FY2026＝上半年實績＋下半年模型；2026Q3 財報 2026-10-29 公布後以 v0.3.1 滾入。
A3: 命題：AWS 的 AI 容量（Trainium＋NVIDIA）能否以高於資金成本的報酬變現，零售與廣告的現金流能否支應資本支出。
A4: 核心問題：FY2028 AWS 營業利益率與自由現金流（扣股利後）是否轉正並維持。
A5: ="投資建議："&Val!B24&"（加權目標價 US$"&TEXT(Val!B19,"0.00")&"，現價 US$"&TEXT(px,"0.00")&"〔2026-10-26〕，上檔空間 "&TEXT(Val!B21,"+0.0%;-0.0%")&"；依五級固定規則）" -> 投資建議：中立（加權目標價 US$215.58，現價 US$249.09〔2026-10-26〕，上檔空間 -13.5%；依五級固定規則）
A6: ="命題答案（情境 B）：FY2028 對外 AI ROIC "&TEXT(Thesis!$I$124,"0.0%")&"，低於 WACC "&TEXT(wacc,"0.0%")&"；打平所需機隊平均 k "&TEXT(Thesis!$I$126,"0.00")&"，模型 k "&TEXT(Thesis!$I$125,"0.00")&"。FY2028 AWS 營業利益率 "&TEXT(PL!$I$123,"0.0%")&"（FY2025 "&TEXT(PL!$D$123,"0.0%")&"）；FY2028 自由現金流扣股利 "&TEXT(CF!$I$60,"#,##0.0")&"；收支關卡（FY2026–FY2030 合計，情境加權）"&TEXT(CF!E6,"#,##0.0")&"。" -> 命題答案（情境 B）：FY2028 對外 AI ROIC 6.7%，低於 WACC 11.3%；打平所需機隊平均 k 1.20，模型 k 0.99。FY2028 AWS 營業利益率 34.1%（FY2025 35.4%）；FY2028 自由現金流扣股利 -15.0；收支關卡（FY2026–FY2030 合計，情境加權）50.1。
A7: ="重點觀察 1：目標價 US$"&TEXT(Val!B19,"0.00")&"＝DCF "&TEXT(Val!B17,"0.00")&"（永續價值占 EV "&TEXT(Val!C8,"0%")&"）與分部加總 "&TEXT(Val!B18,"0.00")&" 各半；DCF 低是因為 WACC "&TEXT(wacc,"0.0%")&" 下，2027–2029 的 AI 資本支出（情境 B FY2027 "&TEXT(CF!$H$55,"#,##0")&"）讓 FCFF 為負，而 AI 增量報酬低於資金成本。" -> 重點觀察 1：目標價 US$215.58＝DCF 149.60（永續價值占 EV 78%）與分部加總 281.56 各半；DCF 低是因為 WACC 11.3% 下，2027–2029 的 AI 資本支出（情境 B FY2027 273）讓 FCFF 為負，而 AI 增量報酬低於資金成本。
A8: ="重點觀察 2：分部加總中 AWS 其他（非 AI 雲端）占 "&TEXT(Val!$C$167/Val!$C$175,"0%")&"、廣告占 "&TEXT(Val!$C$161/Val!$C$175,"0%")&"；零售本業未來 12 個月 EBITDA（SBC 加回）僅 "&TEXT(Val!$C$162,"#,##0")&"，廣告利潤（m_ad 50%）幾乎是零售分部的全部利潤；AWS AI 以自身 DCF 計只值 "&TEXT(Val!$C$174,"#,##0")&"。" -> 重點觀察 2：分部加總中 AWS 其他（非 AI 雲端）占 46%、廣告占 18%；零售本業未來 12 個月 EBITDA（SBC 加回）僅 52，廣告利潤（m_ad 50%）幾乎是零售分部的全部利潤；AWS AI 以自身 DCF 計只值 143。
A9: ="重點觀察 3：三情境目標價 A "&TEXT(Val!B7,"0")&"／B "&TEXT(Val!C7,"0")&"／C "&TEXT(Val!D7,"0")&"；新產能 k 是最大的命題驅動（Sens：k_C "&TEXT(Sens!D5,"+0%;-0%")&"、k_A "&TEXT(Sens!D6,"+0%;-0%")&"），對外比例 ±20pt 為 "&TEXT(Sens!D7,"+0%;-0%")&"／"&TEXT(Sens!D8,"+0%;-0%")&"；市場共識目標價 "&TEXT(cons_tp,"0")&"。" -> 重點觀察 3：三情境目標價 A 270／B 204／C 184；新產能 k 是最大的命題驅動（Sens：k_C -10%、k_A +31%），對外比例 ±20pt 為 +3%／-2%；市場共識目標價 332。
A11: 驅動 → 推導對照表（每頁輸入、推導量、因果方向）
A12: In → Thesis：對外 AI MW（期初 2,080 MW、每年新增 pace）× Tokenomics IF_HoldEcon × k → AWS AI 營收；新增 MW ÷ 對外比例 ×（IT＋自建機房成本）→ AI 資本支出 → IT 6 年／機房 20 年折舊 → AWS AI 營業利益（對外）與自用 AI 成本（零售）。
A13: In → Seg：零售六條營收線（2H26＝2H25 ×（1＋2H25 年增）× 校準係數〔隱含 2026Q3＝指引中點〕，之後收斂到長期年增）→ 零售合計 × 北美比例 → North America／International；AWS＝AWS AI＋AWS 其他（殘差起算、收斂到 8%）。
A14: Seg、Thesis → PL：北美／國際營業利益＝廣告營收 × 50%＋零售本業營收 × 本業利益率（實績殘差＋每年改善）− 自用 AI 成本；AWS 營業利益＝AWS AI＋AWS 其他 × 近四季利益率 → 合併營業利益 → 利息（CF）、稅 17.4% → 淨利 → EPS。
A15: PL → CF：淨利＋分部折舊＋SBC＋其他 − 資本支出（AI＋AWS 其他 20%＋零售 5.9%）− 融資租賃本金 → 自由現金流；股利 0、回購 0；現金低於 50 即舉債 → 利息費用回到 PL。
A16: PL、CF → Val：DCF（FCFF、WACC、RONIC 永續）＋分部加總（廣告、零售本業、AWS 其他、AWS AI × 同業倍數）＋持股（Anthropic、OpenAI）→ 情境目標價 → 情境加權 → 上檔空間 → 投資建議。
A18: 工作表：README → In（輸入）→ Q（實績與核對）→ Thesis（命題模組）→ Seg（營收分部）→ PL → CF → Val → Recon（共識、指引、v0.2.2）→ Sens（敏感度）→ Sources。
A19: 標記：Verified、Interested-party、Analogy、Assumed、Derived。沿用 v0.2.2：k 規格（kspec.py）、C10 基準速度、對外比例、Tokenomics v21.4 快照、WACC 輸入、持股與同業倍數。SemiAnalysis 未使用。
A20: 已知限制：(1) 公司未揭露 AI 在役 MW、對外比例與 AI 營收，AWS AI／AWS 其他的歷史分拆為估計；(2) 分部共識未找到；(3) 同業倍數與 WACC 輸入沿用 2026-10-07；(4) 到期債務假設全數再融資；(5) 自用 AI 讀法 1 為主值（C16 待決）。

Sheet In
A1: In — 輸入（藍字；基準欄 E，低 D、高 F）。金額 US$bn、每股 US$、MW＝IT 關鍵電力 MW。每列一個鍵（定義名稱＝鍵）；Analogy、Assumed 一律給低／高區間
A2: 標記：Verified／Interested-party／Analogy／Assumed／Derived。「沿用 v0.2.2」＝v0.2.2 已核准的參數與證據（k 規格 kspec.py、C10 基準速度、對外比例、Tokenomics v21.4 快照），出處見 legacy_v0.2/ 與 docs/handoff。不以公司雲端營收、RPO、AI run-rate 反推 k 或每 MW 價格（共同規則第 4 節）；公司說法只作 Recon 驗證列。SemiAnalysis 未使用
A3: 鍵 | B3: 項目 | C3: 單位 | D3: 低 | E3: 基準 | F3: 高 | G3: 標記 | H3: 來源 | I3: 說明
A4: A. 價格、股數與共識目標價
A5: px | B5: AMZN 現價（2026-10-26 收盤） | C5: US$ | E5: 249.09 | G5: Verified | H5: S13；S14 | I5: 前收 248.00（10-23）；市值約 2.69T（Yahoo 盤中）
A6: sh_out | B6: 流通股數（2026-07-22，10-Q 封面） | C6: 十億股 | E6: 10.786314 | G6: Verified | H6: S02 | I6: 10,786,313,572 股
A7: sh_awd | B7: 未歸屬股份獎勵（2026-06-30） | C7: 十億股 | E7: 0.244 | G7: Verified | H7: S02 | I7: 244 百萬股
A8: sh_val | B8: 分部加總用稀釋股數＝流通股數＋未歸屬獎勵（倍數為 SBC 加回口徑，故計入稀釋） | C8: 十億股 | E8: =sh_out+sh_awd -> 11.030314 | G8: Derived | H8: 修正一（F2） | I8: DCF 視 SBC 為現金成本，改用流通股數 sh_out，不另計稀釋
A9: cons_tp | B9: 市場共識目標價（S&P Global，60 位平均） | C9: US$ | D9: 230 | E9: 332.24 | F9: 405 | G9: Interested-party | H9: S15 | I9: 中位數 330；Strong Buy 42、Buy 16、Hold 2（2026-10）；MarketBeat 2026-10-07 平均 322.86（獨立彙整）
A10: B. 折現率（CAPM；沿用 v0.2.2 輸入，現價更新）
A11: rf | B11: 無風險利率（10 年美債，2026-10-26） | C11: % | E11: 0.05 | G11: Verified | H11: S28 | I11: 美國財政部每日殖利率曲線：10-26 5.00%、10-23 5.00%、10-22 4.96%（v0.2.2 用 10-07 5.28%）
A12: beta_sa | B12: 原始 Beta：StockAnalysis 5 年月資料（Yahoo 同值，推測同源） | C12: x | E12: 1.46 | G12: Verified | H12: 沿用 v0.2.2（事實總帳 val.beta.sa）
A13: beta_gf | B13: 原始 Beta：GuruFocus 3 年 | C13: x | E13: 1.567 | G13: Verified | H13: 沿用 v0.2.2（事實總帳 val.beta.gurufocus） | I13: 不同資料商、不同期間（C13 獨立來源）
A14: beta | B14: Beta（Blume 調整 0.67 × 原始＋0.33，兩個獨立來源的中位數） | C14: x | D14: =MIN(0.67*beta_sa+0.33,0.67*beta_gf+0.33) -> 1.3082 | E14: =MEDIAN(0.67*beta_sa+0.33,0.67*beta_gf+0.33) -> 1.344045 | F14: =MAX(0.67*beta_sa+0.33,0.67*beta_gf+0.33) -> 1.37989 | G14: Derived | H14: 修正一（F4） | I14: v0.2.2 為原始平均 1.5135
A15: erp | B15: 股權風險溢酬 | C15: % | D15: 0.04 | E15: 0.05 | F15: 0.06 | G15: Assumed | H15: 沿用 v0.2.2（對照表預設 10）
A16: kd_new | B16: 新增借款利率（2026-07 新發 2066 票據有效利率；只用於利息費用） | C16: % | E16: 0.0633 | G16: Interested-party | H16: S02 | I16: 期後事項：固定票面 4.60%–6.25%、有效 4.67%–6.33%
A17: kd_spr | B17: AA 級公司債約 10 年期利差（相對 10 年美債） | C17: % | D17: 0.005 | E17: 0.0065 | F17: 0.01 | G17: Assumed | H17: 修正一（F4）：kd＝約 10 年期公司債殖利率 | I17: Amazon 各期票據的 10 年期殖利率：未找到（本輪網路搜尋額度用盡）
A18: kd | B18: 稅前債務成本（WACC 用）＝rf＋利差 | C18: % | E18: =rf+kd_spr -> 0.0565 | G18: Derived | H18: 修正一（F4）
A19: tax | B19: 稅率（2023–2025 有效稅率平均） | C19: % | D19: 0.135 | E19: =AVERAGE(Q!$C$40,Q!$D$40,Q!$E$40) -> 0.17358453 | F19: 0.23 | G19: Derived | H19: S01 | I19: 18.96%、13.50%、19.61%；沿用 v0.2.2（17.36%）；2026 上半年不含一次性項目 23%
A20: debt_q2 | B20: 債務面額（2026-06-30） | C20: US$bn | E20: 132.995 | G20: Verified | H20: S02 | I20: 附註 5
A21: fl_pv | B21: 融資租賃負債現值（2026-06-30） | C21: US$bn | E21: 13.451 | G21: Verified | H21: S02 | I21: 附註 4
A22: fin_obl | B22: 融資義務（financing obligations，2026-06-30） | C22: US$bn | E22: 11.07 | G22: Verified | H22: S02
A23: fin_debt | B23: 類債務（融資租賃＋融資義務；淨負債與 WACC 的 D 皆計入，模型期間持平） | C23: US$bn | E23: =fl_pv+fin_obl -> 24.521 | G23: Derived | H23: 修正一（F6、核對第 4 點）
A24: ke | B24: 股權成本＝rf＋β × ERP | C24: % | E24: =rf+beta*erp -> 0.11720225 | G24: Derived | H24: CAPM
A25: wacc | B25: WACC＝E/(D+E) × ke＋D/(D+E) × kd ×（1 − 稅率）；E＝現價 × 流通股數；D＝債務面額＋類債務 | C25: % | E25: =px*sh_out/(px*sh_out+debt_q2+fin_debt)*ke+(debt_q2+fin_debt)/(px*sh_out+debt_q2+fin_debt)*kd*(1-tax) -> 0.11329742 | G25: Derived | H25: 修正一（F4） | I25: v0.2.2 為 12.5%
A26: tg | B26: 永續成長率 g | C26: % | D26: 0.02 | E26: 0.03 | F26: 0.04 | G26: Assumed | H26: 工作單第 2 節（g 3%）
A27: ronic | B27: 永續期新投資報酬率（RONIC；預設＝WACC：永續成長不創造價值） | C27: % | E27: =wacc -> 0.11329742 | F27: =wacc+0.05 -> 0.16329742 | G27: Assumed | H27: 判斷（報告第 5 節；F5） | I27: 高值＝WACC＋5pt（Sens）
A28: w_dcf | B28: 目標價中 DCF 的權重；其餘為分部加總（SOTP） | C28: % | E28: 0.5 | G28: Assumed | H28: 工作單第 2 節（[判斷] 預設 DCF 50%＋分部加總 50%） | I28: Andy 可改
A29: w_A | B29: 情境權重 A（樂觀） | C29: % | E29: 0.25 | G29: Assumed | H29: 工作單第 2 節（[判斷] 預設 A 25%／B 50%／C 25%） | I29: 三者合計 100%
A30: w_B | B30: 情境權重 B（基準） | C30: % | E30: 0.5 | G30: Assumed | H30: 工作單第 2 節（[判斷] 預設 A 25%／B 50%／C 25%） | I30: 三者合計 100%
A31: w_C | B31: 情境權重 C（保守） | C31: % | E31: 0.25 | G31: Assumed | H31: 工作單第 2 節（[判斷] 預設 A 25%／B 50%／C 25%） | I31: 三者合計 100%
A32: tp_yf | B32: 目標價時點（2027-10-27）距評價基準日（2026-12-31）年數 | C32: 年 | E32: =(DATE(2027,10,27)-DATE(2026,12,31))/365 -> 0.82191781 | G32: Derived | H32: 目標價約 12 個月後 | I32: DCF 情境價值以 ke 推到目標價時點
A33: C. 命題模組：AWS AI（對外 AI 在役 MW × 每 MW 年收入；沿用 v0.2.2）
A34: mw_ye23 | B34: 對外 AI 在役 MW（2023 年底） | C34: MW | E34: 120 | G34: Assumed | H34: 沿用 v0.2.2（defaults.mwYearEnd） | I34: 公司未揭露 AI 在役 MW；只用於歷史分拆與折舊年份
A35: mw_ye24 | B35: 對外 AI 在役 MW（2024 年底） | C35: MW | E35: 360 | G35: Assumed | H35: 沿用 v0.2.2（defaults.mwYearEnd） | I35: 同上
A36: mw_ye25 | B36: 對外 AI 在役 MW（2025 年底） | C36: MW | D36: 1100 | E36: 1440 | F36: 1800 | G36: Assumed | H36: 沿用 v0.2.2（defaults.mwYearEnd） | I36: Trainium2 1.4M 顆 × 0.871 kW ≈ 1,220 MW-IT（事實總帳 chip.trn2.mwFromLanded）
A37: mw_open | B37: 對外 AI 在役 MW（期初 2026-06-30）＝在役 AI 2,600 × 對外 80% | C37: MW | D37: 1400 | E37: 2080 | F37: 2970 | G37: Derived | H37: S19；S20 | I37: Epoch 三站 1,422 MW（Trainium2）＋NVIDIA 推估；第三方估計，區間見事實總帳 mw.ai.ext.2026q2
A38: pace_A | B38: 情境 A：對外 AI MW 每年新增（公司「2027 年底容量為 2025 年兩倍」，以 MS 6＋8 GW 對照） | C38: MW/年 | E38: 3733 | G38: Derived | H38: 沿用 v0.2.2（scenarios.mwPath.pace.high）；S30 | I38: 每年 +7 GW × AI 占新增 80% ÷ PUE 1.2 × 對外 80%
A39: pace_B | B39: 情境 B：對外 AI MW 每年新增（2026 資本支出指引 220 隱含的建置量，C10） | C39: MW/年 | E39: 3634.3 | G39: Derived | H39: 沿用 v0.2.2（scripts/calib_pace.js 解出，C10） | I39: 這是把支出換成實體產能（物理換算），不是以營收反推單價
A40: pace_C | B40: 情境 C：對外 AI MW 每年新增（與 B 相同：資本支出照指引投入，下檔在變現） | C40: MW/年 | E40: =pace_B -> 3634.3 | G40: Assumed | H40: 判斷（報告第 5 節） | I40: v0.2.2 的保守情境為 Epoch 站點速度 720／年；本版改為變現不如預期
...

Sheet Q
A1: Q — 實績（US$bn；股數十億股）：FY2023–FY2025、最近 8 季（2024Q3–2026Q2）與半年合計。資料取自 data/amazon_facts_20261008.json（10-K、10-Q、財報新聞稿逐季補充表），藍字＝事實值、黑字＝加總或換算。2026Q3 財報 2026-10-29（美國時間）公布，本版未納入
A2: 核對列（綠底）：零售營收線合計＝北美＋國際、營收線合計＝合併營收、分部合計＝合併營收、分部營業利益合計＋未分攤＝合併營業利益；實績皆須為 0
A3: 項目 | B3: 單位 | C3: FY2023A | D3: FY2024A | E3: FY2025A | F3: 2024Q3 | G3: 2024Q4 | H3: 2025Q1 | I3: 2025Q2 | J3: 2025Q3 | K3: 2025Q4 | L3: 2026Q1 | M3: 2026Q2 | N3: 1H25 | O3: 2H25 | P3: 1H26 | Q3: 近四季（2025Q3–2026Q2） | R3: 標記 | S3: 來源
A4: 1. 官方報告分部營收（10-K 附註：North America、International、AWS）
A5: North America | B5: US$bn | C5: 352.828 | D5: 387.497 | E5: 426.305 | F5: 95.537 | G5: 115.586 | H5: 92.887 | I5: 100.068 | J5: 106.267 | K5: 127.083 | L5: 104.143 | M5: 116.177 | N5: =H5+I5 -> 192.955 | O5: =J5+K5 -> 233.35 | P5: =L5+M5 -> 220.32 | Q5: =J5+K5+L5+M5 -> 453.67 | R5: Verified／Interested-party | S5: S01（FY）；S04、S08（逐季補充表）
A6: International | B6: US$bn | C6: 131.2 | D6: 142.906 | E6: 161.894 | F6: 35.888 | G6: 43.42 | H6: 33.513 | I6: 36.761 | J6: 40.896 | K6: 50.724 | L6: 39.789 | M6: 42.197 | N6: =H6+I6 -> 70.274 | O6: =J6+K6 -> 91.62 | P6: =L6+M6 -> 81.986 | Q6: =J6+K6+L6+M6 -> 173.606 | R6: Verified／Interested-party | S6: S01（FY）；S04、S08（逐季補充表）
A7: AWS | B7: US$bn | C7: 90.757 | D7: 107.556 | E7: 128.725 | F7: 27.452 | G7: 28.786 | H7: 29.267 | I7: 30.873 | J7: 33.006 | K7: 35.579 | L7: 37.587 | M7: 42.232 | N7: =H7+I7 -> 60.14 | O7: =J7+K7 -> 68.585 | P7: =L7+M7 -> 79.819 | Q7: =J7+K7+L7+M7 -> 148.404 | R7: Verified／Interested-party | S7: S01（FY）；S04、S08（逐季補充表）
A8: 合併營收 | B8: US$bn | C8: 574.785 | D8: 637.959 | E8: 716.924 | F8: 158.877 | G8: 187.792 | H8: 155.667 | I8: 167.702 | J8: 180.169 | K8: 213.386 | L8: 181.519 | M8: 200.606 | N8: =H8+I8 -> 323.369 | O8: =J8+K8 -> 393.555 | P8: =L8+M8 -> 382.125 | Q8: =J8+K8+L8+M8 -> 775.68 | R8: Verified／Interested-party | S8: S01（FY）；S04、S08（逐季補充表）
A9: 2. 營收線（10-K 營收類別；零售各線＝北美＋國際，AWS 線＝AWS 分部）
A10: Online stores | B10: US$bn | C10: 231.872 | D10: 247.029 | E10: 269.287 | F10: 61.411 | G10: 75.556 | H10: 57.407 | I10: 61.485 | J10: 67.407 | K10: 82.988 | L10: 64.254 | M10: 70.432 | N10: =H10+I10 -> 118.892 | O10: =J10+K10 -> 150.395 | P10: =L10+M10 -> 134.686 | Q10: =J10+K10+L10+M10 -> 285.081 | R10: Verified／Interested-party | S10: S01（FY）；S04、S08（逐季補充表）
A11: Physical stores | B11: US$bn | C11: 20.03 | D11: 21.215 | E11: 22.561 | F11: 5.228 | G11: 5.579 | H11: 5.533 | I11: 5.595 | J11: 5.578 | K11: 5.855 | L11: 5.785 | M11: 5.794 | N11: =H11+I11 -> 11.128 | O11: =J11+K11 -> 11.433 | P11: =L11+M11 -> 11.579 | Q11: =J11+K11+L11+M11 -> 23.012 | R11: Verified／Interested-party | S11: S01（FY）；S04、S08（逐季補充表）
A12: Third-party seller services | B12: US$bn | C12: 140.053 | D12: 156.146 | E12: 172.162 | F12: 37.864 | G12: 47.485 | H12: 36.512 | I12: 40.348 | J12: 42.486 | K12: 52.816 | L12: 41.578 | M12: 46.78 | N12: =H12+I12 -> 76.86 | O12: =J12+K12 -> 95.302 | P12: =L12+M12 -> 88.358 | Q12: =J12+K12+L12+M12 -> 183.66 | R12: Verified／Interested-party | S12: S01（FY）；S04、S08（逐季補充表）
A13: Advertising services | B13: US$bn | C13: 46.906 | D13: 56.214 | E13: 68.635 | F13: 14.331 | G13: 17.288 | H13: 13.921 | I13: 15.694 | J13: 17.703 | K13: 21.317 | L13: 17.243 | M13: 19.809 | N13: =H13+I13 -> 29.615 | O13: =J13+K13 -> 39.02 | P13: =L13+M13 -> 37.052 | Q13: =J13+K13+L13+M13 -> 76.072 | R13: Verified／Interested-party | S13: S01（FY）；S04、S08（逐季補充表）
A14: Subscription services | B14: US$bn | C14: 40.209 | D14: 44.374 | E14: 49.619 | F14: 11.278 | G14: 11.508 | H14: 11.715 | I14: 12.208 | J14: 12.574 | K14: 13.122 | L14: 13.427 | M14: 13.73 | N14: =H14+I14 -> 23.923 | O14: =J14+K14 -> 25.696 | P14: =L14+M14 -> 27.157 | Q14: =J14+K14+L14+M14 -> 52.853 | R14: Verified／Interested-party | S14: S01（FY）；S04、S08（逐季補充表）
A15: Other | B15: US$bn | C15: 4.958 | D15: 5.425 | E15: 5.935 | F15: 1.313 | G15: 1.59 | H15: 1.312 | I15: 1.499 | J15: 1.415 | K15: 1.709 | L15: 1.645 | M15: 1.829 | N15: =H15+I15 -> 2.811 | O15: =J15+K15 -> 3.124 | P15: =L15+M15 -> 3.474 | Q15: =J15+K15+L15+M15 -> 6.598 | R15: Verified／Interested-party | S15: S01（FY）；S04、S08（逐季補充表）
A16: 零售營收線合計（不含 AWS） | B16: US$bn | C16: =C10+C11+C12+C13+C14+C15 -> 484.028 | D16: =D10+D11+D12+D13+D14+D15 -> 530.403 | E16: =E10+E11+E12+E13+E14+E15 -> 588.199 | F16: =F10+F11+F12+F13+F14+F15 -> 131.425 | G16: =G10+G11+G12+G13+G14+G15 -> 159.006 | H16: =H10+H11+H12+H13+H14+H15 -> 126.4 | I16: =I10+I11+I12+I13+I14+I15 -> 136.829 | J16: =J10+J11+J12+J13+J14+J15 -> 147.163 | ... Q16: =Q10+Q11+Q12+Q13+Q14+Q15 -> 627.276 | R16: Derived
A17: AWS（營收線） | B17: US$bn | C17: =C7 -> 90.757 | D17: =D7 -> 107.556 | E17: =E7 -> 128.725 | F17: =F7 -> 27.452 | G17: =G7 -> 28.786 | H17: =H7 -> 29.267 | I17: =I7 -> 30.873 | J17: =J7 -> 33.006 | ... Q17: =Q7 -> 148.404 | R17: Derived
A18: 檢查：零售營收線合計 − (North America＋International) | B18: US$bn | C18: =C16-(C5+C6) -> 0 | D18: =D16-(D5+D6) -> 0 | E18: =E16-(E5+E6) -> 0 | F18: =F16-(F5+F6) -> 0 | G18: =G16-(G5+G6) -> 0 | H18: =H16-(H5+H6) -> 0 | I18: =I16-(I5+I6) -> 0 | J18: =J16-(J5+J6) -> 0 | ... Q18: =Q16-(Q5+Q6) -> 0 | R18: Derived
A19: 檢查：營收線合計（含 AWS）− 合併營收 | B19: US$bn | C19: =C16+C17-C8 -> 0 | D19: =D16+D17-D8 -> 0 | E19: =E16+E17-E8 -> 0 | F19: =F16+F17-F8 -> 0 | G19: =G16+G17-G8 -> 0 | H19: =H16+H17-H8 -> 0 | I19: =I16+I17-I8 -> 0 | J19: =J16+J17-J8 -> 0 | ... Q19: =Q16+Q17-Q8 -> 0 | R19: Derived
A20: 檢查：分部合計 − 合併營收 | B20: US$bn | C20: =C5+C6+C7-C8 -> 0 | D20: =D5+D6+D7-D8 -> 0 | E20: =E5+E6+E7-E8 -> 0 | F20: =F5+F6+F7-F8 -> 0 | G20: =G5+G6+G7-G8 -> 0 | H20: =H5+H6+H7-H8 -> 0 | I20: =I5+I6+I7-I8 -> 0 | J20: =J5+J6+J7-J8 -> 0 | ... Q20: =Q5+Q6+Q7-Q8 -> 0 | R20: Derived
A21: 3. 分部營業利益
A22: North America 營業利益 | B22: US$bn | C22: 14.877 | D22: 24.967 | E22: 29.619 | F22: 5.663 | G22: 9.256 | H22: 5.841 | I22: 7.517 | J22: 4.789 | K22: 11.472 | L22: 8.267 | M22: 9.123 | N22: =H22+I22 -> 13.358 | O22: =J22+K22 -> 16.261 | P22: =L22+M22 -> 17.39 | Q22: =J22+K22+L22+M22 -> 33.651 | R22: Verified／Interested-party | S22: S01（FY）；S04、S08（逐季補充表）
A23: International 營業利益 | B23: US$bn | C23: -2.656 | D23: 3.792 | E23: 4.75 | F23: 1.301 | G23: 1.315 | H23: 1.017 | I23: 1.494 | J23: 1.199 | K23: 1.04 | L23: 1.424 | M23: 1.717 | N23: =H23+I23 -> 2.511 | O23: =J23+K23 -> 2.239 | P23: =L23+M23 -> 3.141 | Q23: =J23+K23+L23+M23 -> 5.38 | R23: Verified／Interested-party | S23: S01（FY）；S04、S08（逐季補充表）
A24: AWS 營業利益 | B24: US$bn | C24: 24.631 | D24: 39.834 | E24: 45.606 | F24: 10.447 | G24: 10.632 | H24: 11.547 | I24: 10.16 | J24: 11.434 | K24: 12.465 | L24: 14.161 | M24: 16.621 | N24: =H24+I24 -> 21.707 | O24: =J24+K24 -> 23.899 | P24: =L24+M24 -> 30.782 | Q24: =J24+K24+L24+M24 -> 54.681 | R24: Verified／Interested-party | S24: S01（FY）；S04、S08（逐季補充表）
A25: 合併營業利益 | B25: US$bn | C25: 36.852 | D25: 68.593 | E25: 79.975 | F25: 17.411 | G25: 21.203 | H25: 18.405 | I25: 19.171 | J25: 17.422 | K25: 24.977 | L25: 23.852 | M25: 27.461 | N25: =H25+I25 -> 37.576 | O25: =J25+K25 -> 42.399 | P25: =L25+M25 -> 51.313 | Q25: =J25+K25+L25+M25 -> 93.712 | R25: Verified／Interested-party | S25: S01（FY）；S04、S08（逐季補充表）
A26: 未分攤（合併 − 分部合計；Amazon 分部已含全部費用） | B26: US$bn | C26: =C25-(C22+C23+C24) -> 0 | D26: =D25-(D22+D23+D24) -> 0 | E26: =E25-(E22+E23+E24) -> 0 | F26: =F25-(F22+F23+F24) -> 0 | G26: =G25-(G22+G23+G24) -> 0 | H26: =H25-(H22+H23+H24) -> 0 | I26: =I25-(I22+I23+I24) -> 0 | J26: =J25-(J22+J23+J24) -> 0 | ... Q26: =Q25-(Q22+Q23+Q24) -> 0 | R26: Derived
A27: 檢查：分部營業利益合計＋未分攤 − 合併營業利益 | B27: US$bn | C27: =C22+C23+C24+C26-C25 -> 0 | D27: =D22+D23+D24+D26-D25 -> 0 | E27: =E22+E23+E24+E26-E25 -> 0 | F27: =F22+F23+F24+F26-F25 -> 0 | G27: =G22+G23+G24+G26-G25 -> 0 | H27: =H22+H23+H24+H26-H25 -> 0 | I27: =I22+I23+I24+I26-I25 -> 0 | J27: =J22+J23+J24+J26-J25 -> 0 | ... Q27: =Q22+Q23+Q24+Q26-Q25 -> 0 | R27: Derived
A28: 4. 分部折舊攤銷（不含影音內容與營業租賃資產攤銷；2024 季度 facts 未收；2025Q4＝全年 − 前三季）
A29: North America 折舊攤銷 | B29: US$bn | C29: 13.678 | D29: 14.285 | E29: 15.503 | H29: 3.53 | I29: 3.742 | J29: 4.001 | K29: =E29-H29-I29-J29 -> 4.23 | L29: 4.28 | M29: 4.5 | N29: =H29+I29 -> 7.272 | O29: =J29+K29 -> 8.231 | P29: =L29+M29 -> 8.78 | Q29: =J29+K29+L29+M29 -> 17.011 | R29: Verified | S29: S01；S02；S03
A30: International 折舊攤銷 | B30: US$bn | C30: 4.016 | D30: 4.462 | E30: 4.907 | H30: 1.136 | I30: 1.18 | J30: 1.276 | K30: =E30-H30-I30-J30 -> 1.315 | L30: 1.277 | M30: 1.293 | N30: =H30+I30 -> 2.316 | O30: =J30+K30 -> 2.591 | P30: =L30+M30 -> 2.57 | Q30: =J30+K30+L30+M30 -> 5.161 | R30: Verified | S30: S01；S02；S03
A31: AWS 折舊攤銷 | B31: US$bn | C31: 12.531 | D31: 13.32 | E31: 21.45 | H31: 4.39 | I31: 4.844 | J31: 5.648 | K31: =E31-H31-I31-J31 -> 6.568 | L31: 7.277 | M31: 8.076 | N31: =H31+I31 -> 9.234 | O31: =J31+K31 -> 12.216 | P31: =L31+M31 -> 15.353 | Q31: =J31+K31+L31+M31 -> 27.569 | R31: Verified | S31: S01；S02；S03
A32: 分部折舊攤銷合計 | B32: US$bn | C32: =IF(COUNT(C29:C31)=3,C29+C30+C31,"") -> 30.225 | D32: =IF(COUNT(D29:D31)=3,D29+D30+D31,"") -> 32.067 | E32: =IF(COUNT(E29:E31)=3,E29+E30+E31,"") -> 41.86 | F32: =IF(COUNT(F29:F31)=3,F29+F30+F31,"") | G32: =IF(COUNT(G29:G31)=3,G29+G30+G31,"") | H32: =IF(COUNT(H29:H31)=3,H29+H30+H31,"") -> 9.056 | I32: =IF(COUNT(I29:I31)=3,I29+I30+I31,"") -> 9.766 | J32: =IF(COUNT(J29:J31)=3,J29+J30+J31,"") -> 10.925 | ... Q32: =IF(COUNT(Q29:Q31)=3,Q29+Q30+Q31,"") -> 49.741 | R32: Derived
A33: 5. 損益（業外、稅、淨利）
A34: 利息費用 | B34: US$bn | C34: 3.182 | D34: 2.406 | E34: 2.274 | F34: 0.603 | G34: 0.57 | H34: 0.541 | I34: 0.516 | J34: 0.538 | K34: 0.679 | L34: 0.8 | M34: 1.314 | N34: =H34+I34 -> 1.057 | O34: =J34+K34 -> 1.217 | P34: =L34+M34 -> 2.114 | Q34: =J34+K34+L34+M34 -> 3.331 | R34: Verified | S34: S01；S04
A35: 利息收入（2026Q2） | B35: US$bn | M35: 1.295 | R35: Verified | S35: S02
A36: 稅前淨利 | B36: US$bn | C36: 37.557 | D36: 68.614 | E36: 97.311 | F36: 18.037 | G36: 22.349 | H36: 21.679 | I36: 20.857 | J36: 28.17 | K36: 26.605 | L36: 39.834 | M36: 80.857 | N36: =H36+I36 -> 42.536 | O36: =J36+K36 -> 54.775 | P36: =L36+M36 -> 120.691 | Q36: =J36+K36+L36+M36 -> 175.466 | R36: Verified | S36: S01；S04
A37: 所得稅 | B37: US$bn | C37: 7.12 | D37: 9.265 | E37: 19.087 | F37: 2.706 | G37: 2.325 | H37: 4.553 | I37: 2.678 | J37: 6.91 | K37: 4.946 | L37: 9.56 | M37: 18.199 | N37: =H37+I37 -> 7.231 | O37: =J37+K37 -> 11.856 | P37: =L37+M37 -> 27.759 | Q37: =J37+K37+L37+M37 -> 39.615 | R37: Verified | S37: S01；S04
A38: 淨利 | B38: US$bn | C38: 30.425 | D38: 59.248 | E38: 77.67 | F38: 15.328 | G38: 20.004 | H38: 17.127 | I38: 18.164 | J38: 21.187 | K38: 21.192 | L38: 30.255 | M38: 62.647 | N38: =H38+I38 -> 35.291 | O38: =J38+K38 -> 42.379 | P38: =L38+M38 -> 92.902 | Q38: =J38+K38+L38+M38 -> 135.281 | R38: Verified | S38: S01；S04
A39: 業外淨額（稅前 − 營業利益＋利息費用；含 Anthropic 等持股評價利益） | B39: US$bn | C39: =IF(AND(ISNUMBER(C36),ISNUMBER(C34)),C36-C25+C34,"") -> 3.887 | D39: =IF(AND(ISNUMBER(D36),ISNUMBER(D34)),D36-D25+D34,"") -> 2.427 | E39: =IF(AND(ISNUMBER(E36),ISNUMBER(E34)),E36-E25+E34,"") -> 19.61 | F39: =IF(AND(ISNUMBER(F36),ISNUMBER(F34)),F36-F25+F34,"") -> 1.229 | G39: =IF(AND(ISNUMBER(G36),ISNUMBER(G34)),G36-G25+G34,"") -> 1.716 | H39: =IF(AND(ISNUMBER(H36),ISNUMBER(H34)),H36-H25+H34,"") -> 3.815 | I39: =IF(AND(ISNUMBER(I36),ISNUMBER(I34)),I36-I25+I34,"") -> 2.202 | J39: =IF(AND(ISNUMBER(J36),ISNUMBER(J34)),J36-J25+J34,"") -> 11.286 | ... Q39: =IF(AND(ISNUMBER(Q36),ISNUMBER(Q34)),Q36-Q25+Q34,"") -> 85.085 | R39: Derived
A40: 有效稅率 | B40: US$bn | C40: =C37/C36 -> 0.18957851 | D40: =D37/D36 -> 0.13503075 | E40: =E37/E36 -> 0.19614432 | R40: Derived
...

Sheet Thesis
A1: Thesis — 命題模組：AWS AI＝對外 AI 在役 MW × 每 MW 年收入（Tokenomics v21.4 IF_HoldEcon × k；Trainium 以同期 NVIDIA 世代計價，C2）。AI 資本支出（含自用）→ IT 6 年／機房 20 年折舊（次年起提列）→ 對外部分進 AWS 營業利益、自用部分進北美／國際營業利益。三情境 A／B／C 依序排列
A2: 情境差異集中在命題驅動：A＝公司容量目標速度＋新產能 k 價格軸高；B＝資本支出指引隱含速度（C10）＋基準 k；C＝與 B 同速度（資本支出照指引）＋新產能 k 價格軸低。非 AI 業務三情境相同
A4: Thesis｜情境 A（樂觀）：命題模組 AWS AI＝對外 AI 在役 MW × 每 MW 年收入（Tokenomics 持有成本 × k）；AI 資本支出 → 折舊 → 分部營業利益
A5: 項目 | B5: 單位 | C5: FY2024A | D5: FY2025A | E5: 1H26A | F5: 2H26E | G5: FY2026E（1H 實績＋2H 模型） | H5: FY2027E | I5: FY2028E | J5: FY2029E | K5: FY2030E | L5: FY2031E | M5: FY2032E | N5: 1H25A | O5: 2H25A | P5: 說明 | R5: 2023 | S5: 2024 | T5: 2025 | U5: 2026 | V5: 2027 | W5: 2028 | X5: 2029 | Y5: 2030 | Z5: 2031 | AA5: 2032
A6: 1. 容量（對外 AI 在役 MW-IT；期末）
A7: 對外 AI MW 每年新增（2030–2032 線性收斂到 FY2029 年底 MW × g，F5） | B7: MW/年 | H7: =pace_A -> 3733 | I7: =pace_A -> 3733 | J7: =pace_A -> 3733 | K7: =pace_A+(Thesis!$J$8*tg-pace_A)*1/3 -> 2640.1217 | L7: =pace_A+(Thesis!$J$8*tg-pace_A)*2/3 -> 1547.2433 | M7: =pace_A+(Thesis!$J$8*tg-pace_A)*3/3 -> 454.365 | P7: 終值不落在建置高峰（共同修正 F5）
A8: 對外 AI 在役 MW（期末） | B8: MW | C8: =mw_ye24 -> 360 | D8: =mw_ye25 -> 1440 | E8: =mw_open -> 2080 | F8: =Thesis!$E$8+pace_A*0.5 -> 3946.5 | G8: =Thesis!$F$8 -> 3946.5 | H8: =Thesis!$G$8+Thesis!$H$7 -> 7679.5 | I8: =Thesis!$H$8+Thesis!$I$7 -> 11412.5 | J8: =Thesis!$I$8+Thesis!$J$7 -> 15145.5 | K8: =Thesis!$J$8+Thesis!$K$7 -> 17785.622 | L8: =Thesis!$K$8+Thesis!$L$7 -> 19332.865 | M8: =Thesis!$L$8+Thesis!$M$7 -> 19787.23 | N8: =(mw_ye24+mw_ye25)/2 -> 900 | O8: =mw_ye25 -> 1440 | P8: 期初 2026-06-30＝In 頁 mw_open；每年新增＝In 頁 pace（情境）；歷史年底值只用於分拆與折舊年份
A9: 對外 AI 平均在役 MW（期間） | B9: MW | C9: =(mw_ye23+mw_ye24)/2 -> 240 | D9: =(Thesis!$C$8+Thesis!$D$8)/2 -> 900 | E9: =(Thesis!$D$8+Thesis!$E$8)/2 -> 1760 | F9: =(Thesis!$E$8+Thesis!$F$8)/2 -> 3013.25 | G9: =(Thesis!$E$9+Thesis!$F$9)/2 -> 2386.625 | H9: =(Thesis!$G$8+Thesis!$H$8)/2 -> 5813 | I9: =(Thesis!$H$8+Thesis!$I$8)/2 -> 9546 | J9: =(Thesis!$I$8+Thesis!$J$8)/2 -> 13279 | K9: =(Thesis!$J$8+Thesis!$K$8)/2 -> 16465.561 | L9: =(Thesis!$K$8+Thesis!$L$8)/2 -> 18559.243 | M9: =(Thesis!$L$8+Thesis!$M$8)/2 -> 19560.048 | N9: =(Thesis!$C$8+Thesis!$N$8)/2 -> 630 | O9: =(Thesis!$N$8+Thesis!$O$8)/2 -> 1170
A10: 期間長度 | B10: 年 | C10: 1 | D10: 1 | E10: 0.5 | F10: 0.5 | G10: 1 | H10: 1 | I10: 1 | J10: 1 | K10: 1 | L10: 1 | M10: 1 | N10: 0.5 | O10: 0.5
A11: 新增對外 AI MW | B11: MW | C11: =Thesis!$C$8-mw_ye23 -> 240 | D11: =Thesis!$D$8-Thesis!$C$8 -> 1080 | E11: =Thesis!$E$8-Thesis!$D$8 -> 640 | F11: =Thesis!$F$8-Thesis!$E$8 -> 1866.5 | G11: =Thesis!$E$11+Thesis!$F$11 -> 2506.5 | H11: =Thesis!$H$8-Thesis!$G$8 -> 3733 | I11: =Thesis!$I$8-Thesis!$H$8 -> 3733 | J11: =Thesis!$J$8-Thesis!$I$8 -> 3733 | K11: =Thesis!$K$8-Thesis!$J$8 -> 2640.1217 | L11: =Thesis!$L$8-Thesis!$K$8 -> 1547.2433 | M11: =Thesis!$M$8-Thesis!$L$8 -> 454.365 | N11: =Thesis!$N$8-Thesis!$C$8 -> 540 | O11: =Thesis!$O$8-Thesis!$N$8 -> 540
A12: 新增 AI 總 MW（含自用＝對外 ÷ 對外比例） | B12: MW | C12: =Thesis!$C$11/ext_sh -> 300 | D12: =Thesis!$D$11/ext_sh -> 1350 | E12: =Thesis!$E$11/ext_sh -> 800 | F12: =Thesis!$F$11/ext_sh -> 2333.125 | G12: =Thesis!$G$11/ext_sh -> 3133.125 | H12: =Thesis!$H$11/ext_sh -> 4666.25 | I12: =Thesis!$I$11/ext_sh -> 4666.25 | J12: =Thesis!$J$11/ext_sh -> 4666.25 | K12: =Thesis!$K$11/ext_sh -> 3300.1521 | L12: =Thesis!$L$11/ext_sh -> 1934.0542 | M12: =Thesis!$M$11/ext_sh -> 567.95625 | N12: =Thesis!$N$11/ext_sh -> 675 | O12: =Thesis!$O$11/ext_sh -> 675 | P12: R–AA 欄：依年份（折舊與汰換用） | R12: =mw_ye23/ext_sh -> 150 | S12: =Thesis!$C$12 -> 300 | T12: =Thesis!$D$12 -> 1350 | U12: =Thesis!$G$12 -> 3133.125 | V12: =Thesis!$H$12 -> 4666.25 | W12: =Thesis!$I$12 -> 4666.25 | X12: =Thesis!$J$12 -> 4666.25 | Y12: =Thesis!$K$12 -> 3300.1521 | Z12: =Thesis!$L$12 -> 1934.0542 | AA12: =Thesis!$M$12 -> 567.95625
A13: 2. 新增產能的世代與單位經濟（Tokenomics v21.4 基準成本；自研晶片以同期 NVIDIA 世代計價，C2）
A14: NVIDIA 新增中 VR200 比例 | B14: % | F14: =na_vr26 -> 0 | G14: =na_vr26 -> 0 | H14: =na_vr27 -> 0.5 | I14: =na_vr28 -> 1 | J14: =na_vr28 -> 1 | K14: =na_vr28 -> 1 | L14: =na_vr28 -> 1 | M14: =na_vr28 -> 1
A15: 新增 MW 加權 IF_HoldEcon（含自研晶片係數） | B15: US$m/MW-年 | F15: =cust_sh*tk_he_gb300*cf_chip+(1-cust_sh)*((1-Thesis!$F$14)*tk_he_gb300+Thesis!$F$14*tk_he_vr200) -> 10.886411 | G15: =cust_sh*tk_he_gb300*cf_chip+(1-cust_sh)*((1-Thesis!$G$14)*tk_he_gb300+Thesis!$G$14*tk_he_vr200) -> 10.886411 | H15: =cust_sh*tk_he_gb300*cf_chip+(1-cust_sh)*((1-Thesis!$H$14)*tk_he_gb300+Thesis!$H$14*tk_he_vr200) -> 11.221176 | I15: =cust_sh*tk_he_gb300*cf_chip+(1-cust_sh)*((1-Thesis!$I$14)*tk_he_gb300+Thesis!$I$14*tk_he_vr200) -> 11.555941 | J15: =cust_sh*tk_he_gb300*cf_chip+(1-cust_sh)*((1-Thesis!$J$14)*tk_he_gb300+Thesis!$J$14*tk_he_vr200) -> 11.555941 | K15: =cust_sh*tk_he_gb300*cf_chip+(1-cust_sh)*((1-Thesis!$K$14)*tk_he_gb300+Thesis!$K$14*tk_he_vr200) -> 11.555941 | L15: =cust_sh*tk_he_gb300*cf_chip+(1-cust_sh)*((1-Thesis!$L$14)*tk_he_gb300+Thesis!$L$14*tk_he_vr200) -> 11.555941 | M15: =cust_sh*tk_he_gb300*cf_chip+(1-cust_sh)*((1-Thesis!$M$14)*tk_he_gb300+Thesis!$M$14*tk_he_vr200) -> 11.555941
A16: 新增 MW 加權營運費用（IF_OpexGW） | B16: US$m/MW-年 | F16: =cust_sh*tk_ox_gb300+(1-cust_sh)*((1-Thesis!$F$14)*tk_ox_gb300+Thesis!$F$14*tk_ox_vr200) -> 1.9826348 | G16: =cust_sh*tk_ox_gb300+(1-cust_sh)*((1-Thesis!$G$14)*tk_ox_gb300+Thesis!$G$14*tk_ox_vr200) -> 1.9826348 | H16: =cust_sh*tk_ox_gb300+(1-cust_sh)*((1-Thesis!$H$14)*tk_ox_gb300+Thesis!$H$14*tk_ox_vr200) -> 2.01035 | I16: =cust_sh*tk_ox_gb300+(1-cust_sh)*((1-Thesis!$I$14)*tk_ox_gb300+Thesis!$I$14*tk_ox_vr200) -> 2.0380652 | J16: =cust_sh*tk_ox_gb300+(1-cust_sh)*((1-Thesis!$J$14)*tk_ox_gb300+Thesis!$J$14*tk_ox_vr200) -> 2.0380652 | K16: =cust_sh*tk_ox_gb300+(1-cust_sh)*((1-Thesis!$K$14)*tk_ox_gb300+Thesis!$K$14*tk_ox_vr200) -> 2.0380652 | L16: =cust_sh*tk_ox_gb300+(1-cust_sh)*((1-Thesis!$L$14)*tk_ox_gb300+Thesis!$L$14*tk_ox_vr200) -> 2.0380652 | M16: =cust_sh*tk_ox_gb300+(1-cust_sh)*((1-Thesis!$M$14)*tk_ox_gb300+Thesis!$M$14*tk_ox_vr200) -> 2.0380652
A17: 新增 MW 加權 IT 資本支出（IF_CapexIT；含自研晶片資本支出係數） | B17: US$m/MW | F17: =cust_sh*tk_cx_gb300*cf_cx+(1-cust_sh)*((1-Thesis!$F$14)*tk_cx_gb300+Thesis!$F$14*tk_cx_vr200) -> 32.237224 | G17: =cust_sh*tk_cx_gb300*cf_cx+(1-cust_sh)*((1-Thesis!$G$14)*tk_cx_gb300+Thesis!$G$14*tk_cx_vr200) -> 32.237224 | H17: =cust_sh*tk_cx_gb300*cf_cx+(1-cust_sh)*((1-Thesis!$H$14)*tk_cx_gb300+Thesis!$H$14*tk_cx_vr200) -> 33.574506 | I17: =cust_sh*tk_cx_gb300*cf_cx+(1-cust_sh)*((1-Thesis!$I$14)*tk_cx_gb300+Thesis!$I$14*tk_cx_vr200) -> 34.911788 | J17: =cust_sh*tk_cx_gb300*cf_cx+(1-cust_sh)*((1-Thesis!$J$14)*tk_cx_gb300+Thesis!$J$14*tk_cx_vr200) -> 34.911788 | K17: =cust_sh*tk_cx_gb300*cf_cx+(1-cust_sh)*((1-Thesis!$K$14)*tk_cx_gb300+Thesis!$K$14*tk_cx_vr200) -> 34.911788 | L17: =cust_sh*tk_cx_gb300*cf_cx+(1-cust_sh)*((1-Thesis!$L$14)*tk_cx_gb300+Thesis!$L$14*tk_cx_vr200) -> 34.911788 | M17: =cust_sh*tk_cx_gb300*cf_cx+(1-cust_sh)*((1-Thesis!$M$14)*tk_cx_gb300+Thesis!$M$14*tk_cx_vr200) -> 34.911788
A18: 期初後新增對外 MW 累計（期末） | B18: MW | F18: =Thesis!$F$8-mw_open -> 1866.5 | G18: =Thesis!$F$18 -> 1866.5 | H18: =Thesis!$H$8-mw_open -> 5599.5 | I18: =Thesis!$I$8-mw_open -> 9332.5 | J18: =Thesis!$J$8-mw_open -> 13065.5 | K18: =Thesis!$K$8-mw_open -> 15705.622 | L18: =Thesis!$L$8-mw_open -> 17252.865 | M18: =Thesis!$M$8-mw_open -> 17707.23
A19: Σ 新增 MW × HoldEcon | B19: US$m | F19: =Thesis!$F$11*Thesis!$F$15 -> 20319.486 | G19: =Thesis!$F$19 -> 20319.486 | H19: =Thesis!$G$19+Thesis!$H$11*Thesis!$H$15 -> 62208.136 | I19: =Thesis!$H$19+Thesis!$I$11*Thesis!$I$15 -> 105346.46 | J19: =Thesis!$I$19+Thesis!$J$11*Thesis!$J$15 -> 148484.79 | K19: =Thesis!$J$19+Thesis!$K$11*Thesis!$K$15 -> 178993.88 | L19: =Thesis!$K$19+Thesis!$L$11*Thesis!$L$15 -> 196873.73 | M19: =Thesis!$L$19+Thesis!$M$11*Thesis!$M$15 -> 202124.35
A20: Σ 新增 MW × 營運費用 | B20: US$m | F20: =Thesis!$F$11*Thesis!$F$16 -> 3700.5879 | G20: =Thesis!$F$20 -> 3700.5879 | H20: =Thesis!$G$20+Thesis!$H$11*Thesis!$H$16 -> 11205.224 | I20: =Thesis!$H$20+Thesis!$I$11*Thesis!$I$16 -> 18813.322 | J20: =Thesis!$I$20+Thesis!$J$11*Thesis!$J$16 -> 26421.419 | K20: =Thesis!$J$20+Thesis!$K$11*Thesis!$K$16 -> 31802.159 | L20: =Thesis!$K$20+Thesis!$L$11*Thesis!$L$16 -> 34955.542 | M20: =Thesis!$L$20+Thesis!$M$11*Thesis!$M$16 -> 35881.567
A21: 新增機隊加權 HoldEcon | B21: US$m/MW-年 | F21: =IF(Thesis!$F$18>0,Thesis!$F$19/Thesis!$F$18,Thesis!$F$15) -> 10.886411 | G21: =IF(Thesis!$G$18>0,Thesis!$G$19/Thesis!$G$18,Thesis!$G$15) -> 10.886411 | H21: =IF(Thesis!$H$18>0,Thesis!$H$19/Thesis!$H$18,Thesis!$H$15) -> 11.109588 | I21: =IF(Thesis!$I$18>0,Thesis!$I$19/Thesis!$I$18,Thesis!$I$15) -> 11.288129 | J21: =IF(Thesis!$J$18>0,Thesis!$J$19/Thesis!$J$18,Thesis!$J$15) -> 11.364647 | K21: =IF(Thesis!$K$18>0,Thesis!$K$19/Thesis!$K$18,Thesis!$K$15) -> 11.396803 | L21: =IF(Thesis!$L$18>0,Thesis!$L$19/Thesis!$L$18,Thesis!$L$15) -> 11.411075 | M21: =IF(Thesis!$M$18>0,Thesis!$M$19/Thesis!$M$18,Thesis!$M$15) -> 11.414792
A22: 新增機隊加權營運費用 | B22: US$m/MW-年 | F22: =IF(Thesis!$F$18>0,Thesis!$F$20/Thesis!$F$18,Thesis!$F$16) -> 1.9826348 | G22: =IF(Thesis!$G$18>0,Thesis!$G$20/Thesis!$G$18,Thesis!$G$16) -> 1.9826348 | H22: =IF(Thesis!$H$18>0,Thesis!$H$20/Thesis!$H$18,Thesis!$H$16) -> 2.0011116 | I22: =IF(Thesis!$I$18>0,Thesis!$I$20/Thesis!$I$18,Thesis!$I$16) -> 2.015893 | J22: =IF(Thesis!$J$18>0,Thesis!$J$20/Thesis!$J$18,Thesis!$J$16) -> 2.0222279 | K22: =IF(Thesis!$K$18>0,Thesis!$K$20/Thesis!$K$18,Thesis!$K$16) -> 2.0248902 | L22: =IF(Thesis!$L$18>0,Thesis!$L$20/Thesis!$L$18,Thesis!$L$16) -> 2.0260717 | M22: =IF(Thesis!$M$18>0,Thesis!$M$20/Thesis!$M$18,Thesis!$M$16) -> 2.0263795
A23: 新增產能每 MW 年收入＝新增機隊 HoldEcon × 情境 k | B23: US$m/MW-年 | F23: =Thesis!$F$21*k_A -> 16.52921 | G23: =Thesis!$G$21*k_A -> 16.52921 | H23: =Thesis!$H$21*k_A -> 16.868067 | I23: =Thesis!$I$21*k_A -> 17.139152 | J23: =Thesis!$J$21*k_A -> 17.255332 | K23: =Thesis!$K$21*k_A -> 17.304156 | L23: =Thesis!$L$21*k_A -> 17.325825 | M23: =Thesis!$M$21*k_A -> 17.331469 | P23: 期初機隊 2,080 MW 三情境同用 rpm_open（k_B）；情境 k 只用於新產能
A24: 新增產能平均在役 MW（期間） | B24: MW | F24: =Thesis!$F$18/2 -> 933.25 | H24: =(Thesis!$G$18+Thesis!$H$18)/2 -> 3733 | I24: =(Thesis!$H$18+Thesis!$I$18)/2 -> 7466 | J24: =(Thesis!$I$18+Thesis!$J$18)/2 -> 11199 | K24: =(Thesis!$J$18+Thesis!$K$18)/2 -> 14385.561 | L24: =(Thesis!$K$18+Thesis!$L$18)/2 -> 16479.243 | M24: =(Thesis!$L$18+Thesis!$M$18)/2 -> 17480.048
A25: 3. AWS AI 損益（收入端不乘 IF_Util：MW-year 計價）
A26: AWS AI 營收（命題子列） | B26: US$bn | C26: =Thesis!$C$9*rpm_open*Thesis!$C$10/1000 -> 2.3210054 | D26: =Thesis!$D$9*rpm_open*Thesis!$D$10/1000 -> 8.7037701 | E26: =Thesis!$E$9*rpm_open*Thesis!$E$10/1000 -> 8.510353 | F26: =(mw_open*rpm_open+Thesis!$F$24*Thesis!$F$23)*Thesis!$F$10/1000 -> 17.770633 | G26: =Thesis!$E$26+Thesis!$F$26 -> 26.280986 | H26: =(mw_open*rpm_open+Thesis!$H$24*Thesis!$H$23)/1000 -> 83.083874 | I26: =(mw_open*rpm_open+Thesis!$I$24*Thesis!$I$23)/1000 -> 148.07629 | J26: =(mw_open*rpm_open+Thesis!$J$24*Thesis!$J$23)/1000 -> 213.35784 | K26: =(mw_open*rpm_open+Thesis!$K$24*Thesis!$K$23)/1000 -> 269.04538 | L26: =(mw_open*rpm_open+Thesis!$L$24*Thesis!$L$23)/1000 -> 305.63187 | M26: =(mw_open*rpm_open+Thesis!$M$24*Thesis!$M$23)/1000 -> 323.07029 | N26: =Thesis!$N$9*rpm_open*Thesis!$N$10/1000 -> 3.0463195 | O26: =Thesis!$O$9*rpm_open*Thesis!$O$10/1000 -> 5.6574506 | P26: 實績欄為分拆估計（期初 k，Derived），不是公司揭露值
A27: 全機隊每 MW 年收入 | B27: US$m/MW-年 | C27: =Thesis!$C$26*1000/(Thesis!$C$9*Thesis!$C$10) -> 9.6708557 | D27: =Thesis!$D$26*1000/(Thesis!$D$9*Thesis!$D$10) -> 9.6708557 | E27: =Thesis!$E$26*1000/(Thesis!$E$9*Thesis!$E$10) -> 9.6708557 | F27: =Thesis!$F$26*1000/(Thesis!$F$9*Thesis!$F$10) -> 11.794994 | G27: =Thesis!$G$26*1000/(Thesis!$G$9*Thesis!$G$10) -> 11.011778 | H27: =Thesis!$H$26*1000/(Thesis!$H$9*Thesis!$H$10) -> 14.29277 | I27: =Thesis!$I$26*1000/(Thesis!$I$9*Thesis!$I$10) -> 15.511868 | J27: =Thesis!$J$26*1000/(Thesis!$J$9*Thesis!$J$10) -> 16.067312 | K27: =Thesis!$K$26*1000/(Thesis!$K$9*Thesis!$K$10) -> 16.339885 | L27: =Thesis!$L$26*1000/(Thesis!$L$9*Thesis!$L$10) -> 16.467906 | M27: =Thesis!$M$26*1000/(Thesis!$M$9*Thesis!$M$10) -> 16.516846 | N27: =Thesis!$N$26*1000/(Thesis!$N$9*Thesis!$N$10) -> 9.6708557 | O27: =Thesis!$O$26*1000/(Thesis!$O$9*Thesis!$O$10) -> 9.6708557
A28: AI 營運成本（含自用 MW、租用機房租金 C22） | B28: US$bn | C28: =Thesis!$C$9/ext_sh*(ox_open+rent_mw)*Thesis!$C$10/1000 -> 0.64256921 | D28: =Thesis!$D$9/ext_sh*(ox_open+rent_mw)*Thesis!$D$10/1000 -> 2.4096345 | E28: =Thesis!$E$9/ext_sh*(ox_open+rent_mw)*Thesis!$E$10/1000 -> 2.3560871 | F28: =((mw_open*ox_open+Thesis!$F$24*Thesis!$F$22)/ext_sh+Thesis!$F$9/ext_sh*rent_mw)*Thesis!$F$10/1000 -> 4.0887038 | G28: =Thesis!$E$28+Thesis!$F$28 -> 6.4447909 | H28: =((mw_open*ox_open+Thesis!$H$24*Thesis!$H$22)/ext_sh+Thesis!$H$9/ext_sh*rent_mw)*Thesis!$H$10/1000 -> 16.089048 | I28: =((mw_open*ox_open+Thesis!$I$24*Thesis!$I$22)/ext_sh+Thesis!$I$9/ext_sh*rent_mw)*Thesis!$I$10/1000 -> 26.74711 | J28: =((mw_open*ox_open+Thesis!$J$24*Thesis!$J$22)/ext_sh+Thesis!$J$9/ext_sh*rent_mw)*Thesis!$J$10/1000 -> 37.42488 | K28: =((mw_open*ox_open+Thesis!$K$24*Thesis!$K$22)/ext_sh+Thesis!$K$9/ext_sh*rent_mw)*Thesis!$K$10/1000 -> 46.537036 | L28: =((mw_open*ox_open+Thesis!$L$24*Thesis!$L$22)/ext_sh+Thesis!$L$9/ext_sh*rent_mw)*Thesis!$L$10/1000 -> 52.523895 | M28: =((mw_open*ox_open+Thesis!$M$24*Thesis!$M$22)/ext_sh+Thesis!$M$9/ext_sh*rent_mw)*Thesis!$M$10/1000 -> 55.38225 | N28: =Thesis!$N$9/ext_sh*(ox_open+rent_mw)*Thesis!$N$10/1000 -> 0.84337209 | O28: =Thesis!$O$9/ext_sh*(ox_open+rent_mw)*Thesis!$O$10/1000 -> 1.5662625
A29: AWS 營收（實績，Q 頁） | B29: US$bn | C29: =Q!$D$7 -> 107.556 | D29: =Q!$E$7 -> 128.725 | E29: =Q!$P$7 -> 79.819 | N29: =Q!$N$7 -> 60.14 | O29: =Q!$O$7 -> 68.585
A30: AWS 其他營收（非 AI 雲端） | B30: US$bn | C30: =Thesis!$C$29-Thesis!$C$26 -> 105.23499 | D30: =Thesis!$D$29-Thesis!$D$26 -> 120.02123 | E30: =Thesis!$E$29-Thesis!$E$26 -> 71.308647 | F30: =Thesis!$O$30*(1+Thesis!$F$31) -> 71.7693 | G30: =Thesis!$E$30+Thesis!$F$30 -> 143.07795 | H30: =Thesis!$G$30*(1+Thesis!$H$31) -> 161.01708 | I30: =Thesis!$H$30*(1+Thesis!$I$31) -> 178.76976 | J30: =Thesis!$I$30*(1+Thesis!$J$31) -> 195.77554 | K30: =Thesis!$J$30*(1+Thesis!$K$31) -> 211.43758 | L30: =Thesis!$K$30*(1+Thesis!$L$31) -> 228.35259 | M30: =Thesis!$L$30*(1+Thesis!$M$31) -> 246.62079 | N30: =Thesis!$N$29-Thesis!$N$26 -> 57.09368 | O30: =Thesis!$O$29-Thesis!$O$26 -> 62.927549 | P30: 實績＝AWS 實績 − AWS AI 分拆估計（殘差，Derived）
A31: AWS 其他年增 | B31: % | D31: =Thesis!$D$30/Thesis!$C$30-1 -> 0.14050683 | E31: =Thesis!$E$30/Thesis!$N$30-1 -> 0.24897618 | F31: =Thesis!$D$31 -> 0.14050683 | G31: =Thesis!$G$30/Thesis!$D$30-1 -> 0.19210532 | H31: =Thesis!$F$31+(g_awso_lt-Thesis!$F$31)*1/4 -> 0.12538012 | I31: =Thesis!$F$31+(g_awso_lt-Thesis!$F$31)*2/4 -> 0.11025341 | J31: =Thesis!$F$31+(g_awso_lt-Thesis!$F$31)*3/4 -> 0.095126707 | K31: =Thesis!$F$31+(g_awso_lt-Thesis!$F$31)*4/4 -> 0.08 | L31: =g_awso_lt -> 0.08 | M31: =g_awso_lt -> 0.08 | P31: 起點＝FY2025 年增（D 欄，Derived）；1H26 年增（E 欄）受 AI 分拆低估影響偏高，只列不用；收斂到 g_awso_lt
A32: 4. AI 資本支出（現金）→ 折舊（IT 6 年、機房 20 年；次年起提列）
A33: 2H26 非 AI 資本支出（零售＋AWS 其他） | B33: US$bn | F33: =cx_rt*Seg!$F$20+cx_awso*Thesis!$F$30 -> 34.97345
A34: AI 資本支出中 IT 比例 | B34: % | C34: =tk_cx_h100/(tk_cx_h100+tk_fac*(1-colo_sh)) -> 0.73075646 | D34: =tk_cx_h100/(tk_cx_h100+tk_fac*(1-colo_sh)) -> 0.73075646 | E34: =Thesis!$F$34 -> 0.76079233 | F34: =Thesis!$F$17/(Thesis!$F$17+tk_fac*(1-colo_sh)) -> 0.76079233 | G34: =Thesis!$G$17/(Thesis!$G$17+tk_fac*(1-colo_sh)) -> 0.76079233 | H34: =Thesis!$H$17/(Thesis!$H$17+tk_fac*(1-colo_sh)) -> 0.76811067 | I34: =Thesis!$I$17/(Thesis!$I$17+tk_fac*(1-colo_sh)) -> 0.7749945 | J34: =Thesis!$J$17/(Thesis!$J$17+tk_fac*(1-colo_sh)) -> 0.7749945 | K34: =Thesis!$K$17/(Thesis!$K$17+tk_fac*(1-colo_sh)) -> 0.7749945 | L34: =Thesis!$L$17/(Thesis!$L$17+tk_fac*(1-colo_sh)) -> 0.7749945 | M34: =Thesis!$M$17/(Thesis!$M$17+tk_fac*(1-colo_sh)) -> 0.7749945
A35: AI 資本支出（現金，含自用） | B35: US$bn | C35: =Q!$D$46-cx_rt*Q!$D$16-cx_awso*Thesis!$C$30 -> 25.278105 | D35: =Q!$E$46-cx_rt*Q!$E$16-cx_awso*Thesis!$D$30 -> 69.568632 | E35: =Q!$P$46-cx_rt*Q!$P$16-cx_awso*Thesis!$E$30 -> 64.189921 | F35: =capex_g26-Q!$P$46-Thesis!$F$33 -> 88.71655 | G35: =Thesis!$E$35+Thesis!$F$35 -> 152.90647 | H35: =Thesis!$H$12*(Thesis!$H$17+tk_fac*(1-colo_sh))/1000+Thesis!$H$36 -> 203.96415 | I35: =Thesis!$I$12*(Thesis!$I$17+tk_fac*(1-colo_sh))/1000+Thesis!$I$36 -> 210.20424 | J35: =Thesis!$J$12*(Thesis!$J$17+tk_fac*(1-colo_sh))/1000+Thesis!$J$36 -> 215.44101 | K35: =Thesis!$K$12*(Thesis!$K$17+tk_fac*(1-colo_sh))/1000+Thesis!$K$36 -> 159.13809 | L35: =Thesis!$L$12*(Thesis!$L$17+tk_fac*(1-colo_sh))/1000+Thesis!$L$36 -> 134.25578 | M35: =Thesis!$M$12*(Thesis!$M$17+tk_fac*(1-colo_sh))/1000+Thesis!$M$36 -> 134.96817 | P35: 實績＝公司資本支出淨額 − 非 AI（零售 cx_rt、AWS 其他 cx_awso）；2H26＝指引 220 − 上半年 − 非 AI（修正三：FY2026 現金資本支出錨定指引；2H26 新增 MW 部分由上半年在建資本支出支應）；之後＝新增 MW ×（IT＋自建機房）＋汰換 | R35: =Q!$C$46-cx_rt*Q!$C$16-cx_awso*(Q!$C$7-mw_ye23/2*rpm_open/1000) -> 1.5042998 | S35: =Thesis!$C$35 -> 25.278105 | T35: =Thesis!$D$35 -> 69.568632 | U35: =Thesis!$G$35 -> 152.90647 | V35: =Thesis!$H$35 -> 203.96415 | W35: =Thesis!$I$35 -> 210.20424 | X35: =Thesis!$J$35 -> 215.44101 | Y35: =Thesis!$K$35 -> 159.13809 | Z35: =Thesis!$L$35 -> 134.25578 | AA35: =Thesis!$M$35 -> 134.96817
A36: IT 汰換（折舊年限前新增的總 MW × 當年 IT 每 MW） | B36: US$bn | H36: =SUMPRODUCT(--(Thesis!$R$5:$AA$5=2027-tk_life),Thesis!$R$12:$AA$12)*Thesis!$H$17/1000 -> 0 | I36: =SUMPRODUCT(--(Thesis!$R$5:$AA$5=2028-tk_life),Thesis!$R$12:$AA$12)*Thesis!$I$17/1000 -> 0 | J36: =SUMPRODUCT(--(Thesis!$R$5:$AA$5=2029-tk_life),Thesis!$R$12:$AA$12)*Thesis!$J$17/1000 -> 5.2367682 | K36: =SUMPRODUCT(--(Thesis!$R$5:$AA$5=2030-tk_life),Thesis!$R$12:$AA$12)*Thesis!$K$17/1000 -> 10.473536 | L36: =SUMPRODUCT(--(Thesis!$R$5:$AA$5=2031-tk_life),Thesis!$R$12:$AA$12)*Thesis!$L$17/1000 -> 47.130914 | M36: =SUMPRODUCT(--(Thesis!$R$5:$AA$5=2032-tk_life),Thesis!$R$12:$AA$12)*Thesis!$M$17/1000 -> 109.383
A37: AI 資本支出：折舊基礎（實績期以新增在役 MW × 每 MW 成本為上限） | B37: US$bn | C37: =MIN(Thesis!$C$35,Thesis!$C$12*(tk_cx_h100+tk_fac*(1-colo_sh))/1000) -> 11.293864 | D37: =MIN(Thesis!$D$35,Thesis!$D$12*(tk_cx_h100+tk_fac*(1-colo_sh))/1000) -> 50.822389 | E37: =MIN(Thesis!$E$35,Thesis!$E$12*(Thesis!$F$17+tk_fac*(1-colo_sh))/1000) -> 33.898579 | F37: =Thesis!$F$35 -> 88.71655 | G37: =Thesis!$E$37+Thesis!$F$37 -> 122.61513 | H37: =Thesis!$H$35 -> 203.96415 | I37: =Thesis!$I$35 -> 210.20424 | J37: =Thesis!$J$35 -> 215.44101 | K37: =Thesis!$K$35 -> 159.13809 | L37: =Thesis!$L$35 -> 134.25578 | M37: =Thesis!$M$35 -> 134.96817 | P37: 實績期以新增在役 MW × 每 MW 成本為上限；超出部分見下列在建（修正三：延後轉入在役後提列折舊） | R37: =MIN(Thesis!$R$35,Thesis!$R$12*(tk_cx_h100+tk_fac*(1-colo_sh))/1000) -> 1.5042998 | S37: =Thesis!$C$37 -> 11.293864 | T37: =Thesis!$D$37 -> 50.822389 | U37: =Thesis!$G$37 -> 122.61513 | V37: =Thesis!$H$37 -> 203.96415 | W37: =Thesis!$I$37 -> 210.20424 | X37: =Thesis!$J$37 -> 215.44101 | Y37: =Thesis!$K$37 -> 159.13809 | Z37: =Thesis!$L$37 -> 134.25578 | AA37: =Thesis!$M$37 -> 134.96817
A38: 在建（CIP）：實績期超出新增在役 MW 成本的 AI 資本支出 | B38: US$bn | C38: =Thesis!$C$35-Thesis!$C$37 -> 13.984241 | D38: =Thesis!$D$35-Thesis!$D$37 -> 18.746243 | E38: =Thesis!$E$35-Thesis!$E$37 -> 30.291341 | F38: =Thesis!$F$35-Thesis!$F$37 -> 0 | G38: =Thesis!$G$35-Thesis!$G$37 -> 30.291341 | H38: =Thesis!$H$35-Thesis!$H$37 -> 0 | I38: =Thesis!$I$35-Thesis!$I$37 -> 0 | J38: =Thesis!$J$35-Thesis!$J$37 -> 0 | K38: =Thesis!$K$35-Thesis!$K$37 -> 0 | L38: =Thesis!$L$35-Thesis!$L$37 -> 0 | M38: =Thesis!$M$35-Thesis!$M$37 -> 0 | P38: 修正三：視為在建，延後 cip_lag 年轉入在役後提列折舊（仍計入 AI 投入資本）；AWS 分部折舊 2024→2025→1H26 年化 13.3→21.5→30.7 支持此處理 | R38: =Thesis!$R$35-Thesis!$R$37 -> 0 | S38: =Thesis!$S$35-Thesis!$S$37 -> 13.984241 | T38: =Thesis!$T$35-Thesis!$T$37 -> 18.746243 | U38: =Thesis!$U$35-Thesis!$U$37 -> 30.291341 | V38: =Thesis!$V$35-Thesis!$V$37 -> 0 | W38: =Thesis!$W$35-Thesis!$W$37 -> 0 | X38: =Thesis!$X$35-Thesis!$X$37 -> 0 | Y38: =Thesis!$Y$35-Thesis!$Y$37 -> 0 | Z38: =Thesis!$Z$35-Thesis!$Z$37 -> 0 | AA38: =Thesis!$AA$35-Thesis!$AA$37 -> 0
A39: 在建中 IT 設備（依支出年份） | B39: US$bn | R39: =Thesis!$R$38*Thesis!$C$34 -> 0 | S39: =Thesis!$S$38*Thesis!$C$34 -> 10.219074 | T39: =Thesis!$T$38*Thesis!$C$34 -> 13.698938 | U39: =Thesis!$U$38*Thesis!$E$34 -> 23.04542 | V39: =Thesis!$V$38*Thesis!$E$34 -> 0 | W39: =Thesis!$W$38*Thesis!$E$34 -> 0 | X39: =Thesis!$X$38*Thesis!$E$34 -> 0 | Y39: =Thesis!$Y$38*Thesis!$E$34 -> 0 | Z39: =Thesis!$Z$38*Thesis!$E$34 -> 0 | AA39: =Thesis!$AA$38*Thesis!$E$34 -> 0
A40: 在建轉入在役：IT（依轉入年份） | B40: US$bn | R40: =SUMPRODUCT(--(Thesis!$R$5:$AA$5=2023-cip_lag),Thesis!$R$39:$AA$39) -> 0 | S40: =SUMPRODUCT(--(Thesis!$R$5:$AA$5=2024-cip_lag),Thesis!$R$39:$AA$39) -> 0 | T40: =SUMPRODUCT(--(Thesis!$R$5:$AA$5=2025-cip_lag),Thesis!$R$39:$AA$39) -> 10.219074 | U40: =SUMPRODUCT(--(Thesis!$R$5:$AA$5=2026-cip_lag),Thesis!$R$39:$AA$39) -> 13.698938 | V40: =SUMPRODUCT(--(Thesis!$R$5:$AA$5=2027-cip_lag),Thesis!$R$39:$AA$39) -> 23.04542 | W40: =SUMPRODUCT(--(Thesis!$R$5:$AA$5=2028-cip_lag),Thesis!$R$39:$AA$39) -> 0 | X40: =SUMPRODUCT(--(Thesis!$R$5:$AA$5=2029-cip_lag),Thesis!$R$39:$AA$39) -> 0 | Y40: =SUMPRODUCT(--(Thesis!$R$5:$AA$5=2030-cip_lag),Thesis!$R$39:$AA$39) -> 0 | Z40: =SUMPRODUCT(--(Thesis!$R$5:$AA$5=2031-cip_lag),Thesis!$R$39:$AA$39) -> 0 | AA40: =SUMPRODUCT(--(Thesis!$R$5:$AA$5=2032-cip_lag),Thesis!$R$39:$AA$39) -> 0
A41: 在建轉入在役：機房（依轉入年份） | B41: US$bn | R41: =SUMPRODUCT(--(Thesis!$R$5:$AA$5=2023-cip_lag),Thesis!$R$38:$AA$38)-Thesis!$R$40 -> 0 | S41: =SUMPRODUCT(--(Thesis!$R$5:$AA$5=2024-cip_lag),Thesis!$R$38:$AA$38)-Thesis!$S$40 -> 0 | T41: =SUMPRODUCT(--(Thesis!$R$5:$AA$5=2025-cip_lag),Thesis!$R$38:$AA$38)-Thesis!$T$40 -> 3.7651666 | U41: =SUMPRODUCT(--(Thesis!$R$5:$AA$5=2026-cip_lag),Thesis!$R$38:$AA$38)-Thesis!$U$40 -> 5.0473048 | V41: =SUMPRODUCT(--(Thesis!$R$5:$AA$5=2027-cip_lag),Thesis!$R$38:$AA$38)-Thesis!$V$40 -> 7.2459211 | W41: =SUMPRODUCT(--(Thesis!$R$5:$AA$5=2028-cip_lag),Thesis!$R$38:$AA$38)-Thesis!$W$40 -> 0 | X41: =SUMPRODUCT(--(Thesis!$R$5:$AA$5=2029-cip_lag),Thesis!$R$38:$AA$38)-Thesis!$X$40 -> 0 | Y41: =SUMPRODUCT(--(Thesis!$R$5:$AA$5=2030-cip_lag),Thesis!$R$38:$AA$38)-Thesis!$Y$40 -> 0 | Z41: =SUMPRODUCT(--(Thesis!$R$5:$AA$5=2031-cip_lag),Thesis!$R$38:$AA$38)-Thesis!$Z$40 -> 0 | AA41: =SUMPRODUCT(--(Thesis!$R$5:$AA$5=2032-cip_lag),Thesis!$R$38:$AA$38)-Thesis!$AA$40 -> 0
...

Sheet Seg
A1: Seg — 營收分部層：官方分部 North America、International、AWS；10-K 營收線 Online stores、Physical stores、Third-party seller services、Advertising services、Subscription services、Other（零售各線合計＝北美＋國際）與 AWS。AWS＝AWS AI（命題子列，Thesis）＋AWS 其他。核對列（綠底）每情境每年度皆須為 0
A4: Seg｜情境 A（樂觀）：營收分部層（官方分部 North America、International、AWS；10-K 營收線）
A5: 項目 | B5: 單位 | C5: FY2024A | D5: FY2025A | E5: 1H26A | F5: 2H26E | G5: FY2026E（1H 實績＋2H 模型） | H5: FY2027E | I5: FY2028E | J5: FY2029E | K5: FY2030E | L5: FY2031E | M5: FY2032E | N5: 1H25A | O5: 2H25A | P5: 說明 | R5: 2023 | S5: 2024 | T5: 2025 | U5: 2026 | V5: 2027 | W5: 2028 | X5: 2029 | Y5: 2030 | Z5: 2031 | AA5: 2032
A6: 1. 零售各營收線（2H26＝2H25 ×（1＋2H25 年增）× 校準係數；2027–2030 年增由 2H25 年增線性收斂到長期值；2031–2032＝長期值）
A7: Online stores | B7: US$bn | C7: =Q!$D$10 -> 247.029 | D7: =Q!$E$10 -> 269.287 | E7: =Q!$P$10 -> 134.686 | F7: =Seg!$O$7*(1+Seg!$F$8)*Seg!$F$19 -> 158.29388 | G7: =Seg!$E$7+Seg!$F$7 -> 292.97988 | H7: =Seg!$G$7*(1+Seg!$H$8) -> 318.18454 | I7: =Seg!$H$7*(1+Seg!$I$8) -> 341.73628 | J7: =Seg!$I$7*(1+Seg!$J$8) -> 362.92719 | K7: =Seg!$J$7*(1+Seg!$K$8) -> 381.07355 | L7: =Seg!$K$7*(1+Seg!$L$8) -> 400.12723 | M7: =Seg!$L$7*(1+Seg!$M$8) -> 420.13359 | N7: =Q!$N$10 -> 118.892 | O7: =Q!$O$10 -> 150.395 | P7: Q 頁實績；預測＝前期 ×（1＋年增）
A8: Online stores 年增 | B8: % | E8: =Seg!$E$7/Seg!$N$7-1 -> 0.13284325 | F8: =Seg!$O$7/(Q!$F$10+Q!$G$10)-1 -> 0.098038214 | G8: =Seg!$G$7/Seg!$D$7-1 -> 0.087983738 | H8: =Seg!$F$8+(g_os-Seg!$F$8)*1/4 -> 0.08602866 | I8: =Seg!$F$8+(g_os-Seg!$F$8)*2/4 -> 0.074019107 | J8: =Seg!$F$8+(g_os-Seg!$F$8)*3/4 -> 0.062009553 | K8: =Seg!$F$8+(g_os-Seg!$F$8)*4/4 -> 0.05 | L8: =g_os -> 0.05 | M8: =g_os -> 0.05 | P8: E＝1H26 對 1H25（含 Prime Day 移入 Q2）；F＝2H25 對 2H24（2H26 成長基準，Derived）；收斂到 In 頁 g_os
A9: Physical stores | B9: US$bn | C9: =Q!$D$11 -> 21.215 | D9: =Q!$E$11 -> 22.561 | E9: =Q!$P$11 -> 11.579 | F9: =Seg!$O$9*(1+Seg!$F$10)*Seg!$F$19 -> 11.593872 | G9: =Seg!$E$9+Seg!$F$9 -> 23.172872 | H9: =Seg!$G$9*(1+Seg!$H$10) -> 24.353393 | I9: =Seg!$H$9*(1+Seg!$I$10) -> 25.424034 | J9: =Seg!$I$9*(1+Seg!$J$10) -> 26.364249 | K9: =Seg!$J$9*(1+Seg!$K$10) -> 27.155177 | L9: =Seg!$K$9*(1+Seg!$L$10) -> 27.969832 | M9: =Seg!$L$9*(1+Seg!$M$10) -> 28.808927 | N9: =Q!$N$11 -> 11.128 | O9: =Q!$O$11 -> 11.433 | P9: Q 頁實績；預測＝前期 ×（1＋年增）
A10: Physical stores 年增 | B10: % | E10: =Seg!$E$9/Seg!$N$9-1 -> 0.040528397 | F10: =Seg!$O$9/(Q!$F$11+Q!$G$11)-1 -> 0.057925419 | G10: =Seg!$G$9/Seg!$D$9-1 -> 0.027120804 | H10: =Seg!$F$10+(g_ps-Seg!$F$10)*1/4 -> 0.050944064 | I10: =Seg!$F$10+(g_ps-Seg!$F$10)*2/4 -> 0.043962709 | J10: =Seg!$F$10+(g_ps-Seg!$F$10)*3/4 -> 0.036981355 | K10: =Seg!$F$10+(g_ps-Seg!$F$10)*4/4 -> 0.03 | L10: =g_ps -> 0.03 | M10: =g_ps -> 0.03 | P10: E＝1H26 對 1H25（含 Prime Day 移入 Q2）；F＝2H25 對 2H24（2H26 成長基準，Derived）；收斂到 In 頁 g_ps
A11: Third-party seller services | B11: US$bn | C11: =Q!$D$12 -> 156.146 | D11: =Q!$E$12 -> 172.162 | E11: =Q!$P$12 -> 88.358 | F11: =Seg!$O$11*(1+Seg!$F$12)*Seg!$F$19 -> 102.00439 | G11: =Seg!$E$11+Seg!$F$11 -> 190.36239 | H11: =Seg!$G$11*(1+Seg!$H$12) -> 210.34311 | I11: =Seg!$H$11*(1+Seg!$I$12) -> 229.96973 | J11: =Seg!$I$11*(1+Seg!$J$12) -> 248.74764 | K11: =Seg!$J$11*(1+Seg!$K$12) -> 266.15997 | L11: =Seg!$K$11*(1+Seg!$L$12) -> 284.79117 | M11: =Seg!$L$11*(1+Seg!$M$12) -> 304.72655 | N11: =Q!$N$12 -> 76.86 | O11: =Q!$O$12 -> 95.302 | P11: Q 頁實績；預測＝前期 ×（1＋年增）
A12: Third-party seller services 年增 | B12: % | E12: =Seg!$E$11/Seg!$N$11-1 -> 0.14959667 | F12: =Seg!$O$11/(Q!$F$12+Q!$G$12)-1 -> 0.11661531 | G12: =Seg!$G$11/Seg!$D$11-1 -> 0.10571664 | H12: =Seg!$F$12+(g_sp-Seg!$F$12)*1/4 -> 0.10496148 | I12: =Seg!$F$12+(g_sp-Seg!$F$12)*2/4 -> 0.093307654 | J12: =Seg!$F$12+(g_sp-Seg!$F$12)*3/4 -> 0.081653827 | K12: =Seg!$F$12+(g_sp-Seg!$F$12)*4/4 -> 0.07 | L12: =g_sp -> 0.07 | M12: =g_sp -> 0.07 | P12: E＝1H26 對 1H25（含 Prime Day 移入 Q2）；F＝2H25 對 2H24（2H26 成長基準，Derived）；收斂到 In 頁 g_sp
A13: Advertising services | B13: US$bn | C13: =Q!$D$13 -> 56.214 | D13: =Q!$E$13 -> 68.635 | E13: =Q!$P$13 -> 37.052 | F13: =Seg!$O$13*(1+Seg!$F$14)*Seg!$F$19 -> 46.157222 | G13: =Seg!$E$13+Seg!$F$13 -> 83.209222 | H13: =Seg!$G$13*(1+Seg!$H$14) -> 99.896922 | I13: =Seg!$H$13*(1+Seg!$I$14) -> 116.58311 | J13: =Seg!$I$13*(1+Seg!$J$14) -> 132.14894 | K13: =Seg!$J$13*(1+Seg!$K$14) -> 145.36384 | L13: =Seg!$K$13*(1+Seg!$L$14) -> 159.90022 | M13: =Seg!$L$13*(1+Seg!$M$14) -> 175.89024 | N13: =Q!$N$13 -> 29.615 | O13: =Q!$O$13 -> 39.02 | P13: Q 頁實績；預測＝前期 ×（1＋年增）
A14: Advertising services 年增 | B14: % | E14: =Seg!$E$13/Seg!$N$13-1 -> 0.25112274 | F14: =Seg!$O$13/(Q!$F$13+Q!$G$13)-1 -> 0.23406812 | G14: =Seg!$G$13/Seg!$D$13-1 -> 0.21234388 | H14: =Seg!$F$14+(g_ad-Seg!$F$14)*1/4 -> 0.20055109 | I14: =Seg!$F$14+(g_ad-Seg!$F$14)*2/4 -> 0.16703406 | J14: =Seg!$F$14+(g_ad-Seg!$F$14)*3/4 -> 0.13351703 | K14: =Seg!$F$14+(g_ad-Seg!$F$14)*4/4 -> 0.1 | L14: =g_ad -> 0.1 | M14: =g_ad -> 0.1 | P14: E＝1H26 對 1H25（含 Prime Day 移入 Q2）；F＝2H25 對 2H24（2H26 成長基準，Derived）；收斂到 In 頁 g_ad
A15: Subscription services | B15: US$bn | C15: =Q!$D$14 -> 44.374 | D15: =Q!$E$14 -> 49.619 | E15: =Q!$P$14 -> 27.157 | F15: =Seg!$O$15*(1+Seg!$F$16)*Seg!$F$19 -> 27.776417 | G15: =Seg!$E$15+Seg!$F$15 -> 54.933417 | H15: =Seg!$G$15*(1+Seg!$H$16) -> 61.156411 | I15: =Seg!$H$15*(1+Seg!$I$16) -> 67.202028 | J15: =Seg!$I$15*(1+Seg!$J$16) -> 72.875727 | K15: =Seg!$J$15*(1+Seg!$K$16) -> 77.977028 | L15: =Seg!$K$15*(1+Seg!$L$16) -> 83.43542 | M15: =Seg!$L$15*(1+Seg!$M$16) -> 89.2759 | N15: =Q!$N$14 -> 23.923 | O15: =Q!$O$14 -> 25.696 | P15: Q 頁實績；預測＝前期 ×（1＋年增）
A16: Subscription services 年增 | B16: % | E16: =Seg!$E$15/Seg!$N$15-1 -> 0.13518371 | F16: =Seg!$O$15/(Q!$F$14+Q!$G$14)-1 -> 0.12771 | G16: =Seg!$G$15/Seg!$D$15-1 -> 0.10710447 | H16: =Seg!$F$16+(g_sub-Seg!$F$16)*1/4 -> 0.1132825 | I16: =Seg!$F$16+(g_sub-Seg!$F$16)*2/4 -> 0.098854999 | J16: =Seg!$F$16+(g_sub-Seg!$F$16)*3/4 -> 0.084427499 | K16: =Seg!$F$16+(g_sub-Seg!$F$16)*4/4 -> 0.07 | L16: =g_sub -> 0.07 | M16: =g_sub -> 0.07 | P16: E＝1H26 對 1H25（含 Prime Day 移入 Q2）；F＝2H25 對 2H24（2H26 成長基準，Derived）；收斂到 In 頁 g_sub
A17: Other | B17: US$bn | C17: =Q!$D$15 -> 5.425 | D17: =Q!$E$15 -> 5.935 | E17: =Q!$P$15 -> 3.474 | F17: =Seg!$O$17*(1+Seg!$F$18)*Seg!$F$19 -> 3.2224655 | G17: =Seg!$E$17+Seg!$F$17 -> 6.6964655 | H17: =Seg!$G$17*(1+Seg!$H$18) -> 7.1625134 | I17: =Seg!$H$17*(1+Seg!$I$18) -> 7.6142107 | J17: =Seg!$I$17*(1+Seg!$J$18) -> 8.0446575 | K17: =Seg!$J$17*(1+Seg!$K$18) -> 8.4468904 | L17: =Seg!$K$17*(1+Seg!$L$18) -> 8.8692349 | M17: =Seg!$L$17*(1+Seg!$M$18) -> 9.3126967 | N17: =Q!$N$15 -> 2.811 | O17: =Q!$O$15 -> 3.124 | P17: Q 頁實績；預測＝前期 ×（1＋年增）
A18: Other 年增 | B18: % | E18: =Seg!$E$17/Seg!$N$17-1 -> 0.23585912 | F18: =Seg!$O$17/(Q!$F$15+Q!$G$15)-1 -> 0.076128143 | G18: =Seg!$G$17/Seg!$D$17-1 -> 0.12830084 | H18: =Seg!$F$18+(g_ot-Seg!$F$18)*1/4 -> 0.069596107 | I18: =Seg!$F$18+(g_ot-Seg!$F$18)*2/4 -> 0.063064072 | J18: =Seg!$F$18+(g_ot-Seg!$F$18)*3/4 -> 0.056532036 | K18: =Seg!$F$18+(g_ot-Seg!$F$18)*4/4 -> 0.05 | L18: =g_ot -> 0.05 | M18: =g_ot -> 0.05 | P18: E＝1H26 對 1H25（含 Prime Day 移入 Q2）；F＝2H25 對 2H24（2H26 成長基準，Derived）；收斂到 In 頁 g_ot
A19: 2H26 零售營收校準係數（使隱含 2026Q3 營收＝指引中點） | B19: x | F19: =(g26q3_mid*Q!$O$8/Q!$J$8-Thesis!$F$89-Thesis!$F$93)/(Seg!$O$7*(1+Seg!$F$8)+Seg!$O$9*(1+Seg!$F$10)+Seg!$O$11*(1+Seg!$F$12)+Seg!$O$13*(1+Seg!$F$14)+Seg!$O$15*(1+Seg!$F$16)+Seg!$O$17*(1+Seg!$F$18)) -> 0.95854667 | P19: 2H26 合併營收目標＝Q3 指引中點 ÷（2025Q3 占 2H25 比例）− 主頁情境 B 的 AWS 2H26；三情境與 Sens 共用同一係數（修正二），零售不隨 AI 分拆變動（Prime Day 時點已含在指引中）
A20: 零售營收線合計（＝North America＋International） | B20: US$bn | C20: =Seg!$C$7+Seg!$C$9+Seg!$C$11+Seg!$C$13+Seg!$C$15+Seg!$C$17 -> 530.403 | D20: =Seg!$D$7+Seg!$D$9+Seg!$D$11+Seg!$D$13+Seg!$D$15+Seg!$D$17 -> 588.199 | E20: =Seg!$E$7+Seg!$E$9+Seg!$E$11+Seg!$E$13+Seg!$E$15+Seg!$E$17 -> 302.306 | F20: =Seg!$F$7+Seg!$F$9+Seg!$F$11+Seg!$F$13+Seg!$F$15+Seg!$F$17 -> 349.04824 | G20: =Seg!$G$7+Seg!$G$9+Seg!$G$11+Seg!$G$13+Seg!$G$15+Seg!$G$17 -> 651.35424 | H20: =Seg!$H$7+Seg!$H$9+Seg!$H$11+Seg!$H$13+Seg!$H$15+Seg!$H$17 -> 721.09689 | I20: =Seg!$I$7+Seg!$I$9+Seg!$I$11+Seg!$I$13+Seg!$I$15+Seg!$I$17 -> 788.52939 | J20: =Seg!$J$7+Seg!$J$9+Seg!$J$11+Seg!$J$13+Seg!$J$15+Seg!$J$17 -> 851.10841 | K20: =Seg!$K$7+Seg!$K$9+Seg!$K$11+Seg!$K$13+Seg!$K$15+Seg!$K$17 -> 906.17646 | L20: =Seg!$L$7+Seg!$L$9+Seg!$L$11+Seg!$L$13+Seg!$L$15+Seg!$L$17 -> 965.09311 | M20: =Seg!$M$7+Seg!$M$9+Seg!$M$11+Seg!$M$13+Seg!$M$15+Seg!$M$17 -> 1028.1479 | N20: =Seg!$N$7+Seg!$N$9+Seg!$N$11+Seg!$N$13+Seg!$N$15+Seg!$N$17 -> 263.229 | O20: =Seg!$O$7+Seg!$O$9+Seg!$O$11+Seg!$O$13+Seg!$O$15+Seg!$O$17 -> 324.97
A21: 北美占零售營收比例（地區分攤） | B21: % | C21: =Q!$D$5/(Q!$D$5+Q!$D$6) -> 0.73057091 | D21: =Q!$E$5/(Q!$E$5+Q!$E$6) -> 0.72476322 | E21: =Q!$P$5/(Q!$P$5+Q!$P$6) -> 0.72879797 | F21: =Seg!$O$21 -> 0.71806628 | G21: =Seg!$G$22/Seg!$G$20 -> 0.72304707 | H21: =Seg!$G$21 -> 0.72304707 | I21: =Seg!$G$21 -> 0.72304707 | J21: =Seg!$G$21 -> 0.72304707 | K21: =Seg!$G$21 -> 0.72304707 | L21: =Seg!$G$21 -> 0.72304707 | M21: =Seg!$G$21 -> 0.72304707 | N21: =Q!$N$5/(Q!$N$5+Q!$N$6) -> 0.73303094 | O21: =Q!$O$5/(Q!$O$5+Q!$O$6) -> 0.71806628 | P21: 2H26＝2H25 比例；2027 起固定為 FY2026（Derived）；各營收線不分地區揭露，故以本列分攤
A22: North America | B22: US$bn | C22: =Q!$D$5 -> 387.497 | D22: =Q!$E$5 -> 426.305 | E22: =Q!$P$5 -> 220.32 | F22: =Seg!$F$20*Seg!$F$21 -> 250.63977 | G22: =Seg!$E$22+Seg!$F$22 -> 470.95977 | H22: =Seg!$H$20*Seg!$H$21 -> 521.38699 | I22: =Seg!$I$20*Seg!$I$21 -> 570.14386 | J22: =Seg!$J$20*Seg!$J$21 -> 615.39144 | K22: =Seg!$K$20*Seg!$K$21 -> 655.20823 | L22: =Seg!$L$20*Seg!$L$21 -> 697.80774 | M22: =Seg!$M$20*Seg!$M$21 -> 743.39933 | N22: =Q!$N$5 -> 192.955 | O22: =Q!$O$5 -> 233.35 | P22: 官方分部；預測＝零售營收線合計 × 北美比例
A23: International | B23: US$bn | C23: =Q!$D$6 -> 142.906 | D23: =Q!$E$6 -> 161.894 | E23: =Q!$P$6 -> 81.986 | F23: =Seg!$F$20*(1-Seg!$F$21) -> 98.408468 | G23: =Seg!$E$23+Seg!$F$23 -> 180.39447 | H23: =Seg!$H$20*(1-Seg!$H$21) -> 199.7099 | I23: =Seg!$I$20*(1-Seg!$I$21) -> 218.38553 | J23: =Seg!$J$20*(1-Seg!$J$21) -> 235.71697 | K23: =Seg!$K$20*(1-Seg!$K$21) -> 250.96823 | L23: =Seg!$L$20*(1-Seg!$L$21) -> 267.28537 | M23: =Seg!$M$20*(1-Seg!$M$21) -> 284.74858 | N23: =Q!$N$6 -> 70.274 | O23: =Q!$O$6 -> 91.62 | P23: 官方分部；預測＝零售營收線合計 ×（1 − 北美比例）
A24: 廣告營收歸北美（＝廣告 × 北美比例） | B24: US$bn | C24: =Seg!$C$13*Seg!$C$21 -> 41.068313 | D24: =Seg!$D$13*Seg!$D$21 -> 49.744123 | E24: =Seg!$E$13*Seg!$E$21 -> 27.003422 | F24: =Seg!$F$13*Seg!$F$21 -> 33.143945 | G24: =Seg!$G$13*Seg!$G$21 -> 60.164184 | H24: =Seg!$H$13*Seg!$H$21 -> 72.230177 | I24: =Seg!$I$13*Seg!$I$21 -> 84.295076 | J24: =Seg!$J$13*Seg!$J$21 -> 95.549905 | K24: =Seg!$K$13*Seg!$K$21 -> 105.1049 | L24: =Seg!$L$13*Seg!$L$21 -> 115.61538 | M24: =Seg!$M$13*Seg!$M$21 -> 127.17692 | N24: =Seg!$N$13*Seg!$N$21 -> 21.708711 | O24: =Seg!$O$13*Seg!$O$21 -> 28.018946 | P24: 廣告營收依零售營收的地區比例分攤（Assumed；公司未分地區揭露）
A25: 廣告營收歸國際 | B25: US$bn | C25: =Seg!$C$13-Seg!$C$24 -> 15.145687 | D25: =Seg!$D$13-Seg!$D$24 -> 18.890877 | E25: =Seg!$E$13-Seg!$E$24 -> 10.048578 | F25: =Seg!$F$13-Seg!$F$24 -> 13.013277 | G25: =Seg!$G$13-Seg!$G$24 -> 23.045038 | H25: =Seg!$H$13-Seg!$H$24 -> 27.666746 | I25: =Seg!$I$13-Seg!$I$24 -> 32.288035 | J25: =Seg!$J$13-Seg!$J$24 -> 36.599037 | K25: =Seg!$K$13-Seg!$K$24 -> 40.258941 | L25: =Seg!$L$13-Seg!$L$24 -> 44.284835 | M25: =Seg!$M$13-Seg!$M$24 -> 48.713318 | N25: =Seg!$N$13-Seg!$N$24 -> 7.9062889 | O25: =Seg!$O$13-Seg!$O$24 -> 11.001054
A26: 2. AWS（命題子列＋AWS 其他）與合併營收
A27: AWS AI（命題子列） | B27: US$bn | C27: =Thesis!$C$26 -> 2.3210054 | D27: =Thesis!$D$26 -> 8.7037701 | E27: =Thesis!$E$26 -> 8.510353 | F27: =Thesis!$F$26 -> 17.770633 | G27: =Thesis!$G$26 -> 26.280986 | H27: =Thesis!$H$26 -> 83.083874 | I27: =Thesis!$I$26 -> 148.07629 | J27: =Thesis!$J$26 -> 213.35784 | K27: =Thesis!$K$26 -> 269.04538 | L27: =Thesis!$L$26 -> 305.63187 | M27: =Thesis!$M$26 -> 323.07029 | N27: =Thesis!$N$26 -> 3.0463195 | O27: =Thesis!$O$26 -> 5.6574506 | P27: Thesis 頁
A28: AWS 其他 | B28: US$bn | C28: =Thesis!$C$30 -> 105.23499 | D28: =Thesis!$D$30 -> 120.02123 | E28: =Thesis!$E$30 -> 71.308647 | F28: =Thesis!$F$30 -> 71.7693 | G28: =Thesis!$G$30 -> 143.07795 | H28: =Thesis!$H$30 -> 161.01708 | I28: =Thesis!$I$30 -> 178.76976 | J28: =Thesis!$J$30 -> 195.77554 | K28: =Thesis!$K$30 -> 211.43758 | L28: =Thesis!$L$30 -> 228.35259 | M28: =Thesis!$M$30 -> 246.62079 | N28: =Thesis!$N$30 -> 57.09368 | O28: =Thesis!$O$30 -> 62.927549 | P28: Thesis 頁
A29: AWS | B29: US$bn | C29: =Q!$D$7 -> 107.556 | D29: =Q!$E$7 -> 128.725 | E29: =Q!$P$7 -> 79.819 | F29: =Seg!$F$27+Seg!$F$28 -> 89.539932 | G29: =Seg!$G$27+Seg!$G$28 -> 169.35893 | H29: =Seg!$H$27+Seg!$H$28 -> 244.10095 | I29: =Seg!$I$27+Seg!$I$28 -> 326.84605 | J29: =Seg!$J$27+Seg!$J$28 -> 409.13338 | K29: =Seg!$K$27+Seg!$K$28 -> 480.48296 | L29: =Seg!$L$27+Seg!$L$28 -> 533.98446 | M29: =Seg!$M$27+Seg!$M$28 -> 569.69108 | N29: =Q!$N$7 -> 60.14 | O29: =Q!$O$7 -> 68.585 | P29: 官方分部＝AWS 營收線
A30: 合併營收（實績＝公司揭露；預測＝營收線加總） | B30: US$bn | C30: =Q!$D$8 -> 637.959 | D30: =Q!$E$8 -> 716.924 | E30: =Q!$P$8 -> 382.125 | F30: =Seg!$F$20+Seg!$F$29 -> 438.58817 | G30: =Seg!$G$20+Seg!$G$29 -> 820.71317 | H30: =Seg!$H$20+Seg!$H$29 -> 965.19784 | I30: =Seg!$I$20+Seg!$I$29 -> 1115.3754 | J30: =Seg!$J$20+Seg!$J$29 -> 1260.2418 | K30: =Seg!$K$20+Seg!$K$29 -> 1386.6594 | L30: =Seg!$L$20+Seg!$L$29 -> 1499.0776 | M30: =Seg!$M$20+Seg!$M$29 -> 1597.839 | N30: =Q!$N$8 -> 323.369 | O30: =Q!$O$8 -> 393.555
A31: 檢查（情境 A）：零售營收線合計 − (North America＋International) | B31: US$bn | C31: =Seg!$C$20-(Seg!$C$22+Seg!$C$23) -> 0 | D31: =Seg!$D$20-(Seg!$D$22+Seg!$D$23) -> 0 | E31: =Seg!$E$20-(Seg!$E$22+Seg!$E$23) -> 0 | F31: =Seg!$F$20-(Seg!$F$22+Seg!$F$23) -> 0 | G31: =Seg!$G$20-(Seg!$G$22+Seg!$G$23) -> 0 | H31: =Seg!$H$20-(Seg!$H$22+Seg!$H$23) -> 0 | I31: =Seg!$I$20-(Seg!$I$22+Seg!$I$23) -> 0 | J31: =Seg!$J$20-(Seg!$J$22+Seg!$J$23) -> 0 | K31: =Seg!$K$20-(Seg!$K$22+Seg!$K$23) -> 0 | L31: =Seg!$L$20-(Seg!$L$22+Seg!$L$23) -> 0 | M31: =Seg!$M$20-(Seg!$M$22+Seg!$M$23) -> 0 | N31: =Seg!$N$20-(Seg!$N$22+Seg!$N$23) -> 0 | O31: =Seg!$O$20-(Seg!$O$22+Seg!$O$23) -> 0
A32: 檢查（情境 A）：AWS AI＋AWS 其他 − AWS | B32: US$bn | C32: =Seg!$C$27+Seg!$C$28-Seg!$C$29 -> 0 | D32: =Seg!$D$27+Seg!$D$28-Seg!$D$29 -> 0 | E32: =Seg!$E$27+Seg!$E$28-Seg!$E$29 -> 0 | F32: =Seg!$F$27+Seg!$F$28-Seg!$F$29 -> 0 | G32: =Seg!$G$27+Seg!$G$28-Seg!$G$29 -> 0 | H32: =Seg!$H$27+Seg!$H$28-Seg!$H$29 -> 0 | I32: =Seg!$I$27+Seg!$I$28-Seg!$I$29 -> 0 | J32: =Seg!$J$27+Seg!$J$28-Seg!$J$29 -> 0 | K32: =Seg!$K$27+Seg!$K$28-Seg!$K$29 -> 0 | L32: =Seg!$L$27+Seg!$L$28-Seg!$L$29 -> 0 | M32: =Seg!$M$27+Seg!$M$28-Seg!$M$29 -> 0 | N32: =Seg!$N$27+Seg!$N$28-Seg!$N$29 -> 0 | O32: =Seg!$O$27+Seg!$O$28-Seg!$O$29 -> 0
A33: 檢查（情境 A）：分部合計 − 合併營收 | B33: US$bn | C33: =Seg!$C$22+Seg!$C$23+Seg!$C$29-Seg!$C$30 -> 0 | D33: =Seg!$D$22+Seg!$D$23+Seg!$D$29-Seg!$D$30 -> 0 | E33: =Seg!$E$22+Seg!$E$23+Seg!$E$29-Seg!$E$30 -> 0 | F33: =Seg!$F$22+Seg!$F$23+Seg!$F$29-Seg!$F$30 -> 0 | G33: =Seg!$G$22+Seg!$G$23+Seg!$G$29-Seg!$G$30 -> 0 | H33: =Seg!$H$22+Seg!$H$23+Seg!$H$29-Seg!$H$30 -> 0 | I33: =Seg!$I$22+Seg!$I$23+Seg!$I$29-Seg!$I$30 -> 0 | J33: =Seg!$J$22+Seg!$J$23+Seg!$J$29-Seg!$J$30 -> 0 | K33: =Seg!$K$22+Seg!$K$23+Seg!$K$29-Seg!$K$30 -> 0 | L33: =Seg!$L$22+Seg!$L$23+Seg!$L$29-Seg!$L$30 -> 0 | M33: =Seg!$M$22+Seg!$M$23+Seg!$M$29-Seg!$M$30 -> 0 | N33: =Seg!$N$22+Seg!$N$23+Seg!$N$29-Seg!$N$30 -> 0 | O33: =Seg!$O$22+Seg!$O$23+Seg!$O$29-Seg!$O$30 -> 0
A34: 合併營收年增 | B34: % | G34: =Seg!$G$30/Seg!$D$30-1 -> 0.14477012 | H34: =Seg!$H$30/Seg!$G$30-1 -> 0.1760477 | I34: =Seg!$I$30/Seg!$H$30-1 -> 0.15559256 | J34: =Seg!$J$30/Seg!$I$30-1 -> 0.12988124 | K34: =Seg!$K$30/Seg!$J$30-1 -> 0.1003122 | L34: =Seg!$L$30/Seg!$K$30-1 -> 0.081071209 | M34: =Seg!$M$30/Seg!$L$30-1 -> 0.065881464
A35: AWS 占合併營收 | B35: % | C35: =Seg!$C$29/Seg!$C$30 -> 0.16859391 | D35: =Seg!$D$29/Seg!$D$30 -> 0.17955181 | E35: =Seg!$E$29/Seg!$E$30 -> 0.20888191 | F35: =Seg!$F$29/Seg!$F$30 -> 0.20415492 | G35: =Seg!$G$29/Seg!$G$30 -> 0.20635581 | H35: =Seg!$H$29/Seg!$H$30 -> 0.2529025 | I35: =Seg!$I$29/Seg!$I$30 -> 0.2930368 | J35: =Seg!$J$29/Seg!$J$30 -> 0.32464673 | K35: =Seg!$K$29/Seg!$K$30 -> 0.34650394 | L35: =Seg!$L$29/Seg!$L$30 -> 0.35620869 | M35: =Seg!$M$29/Seg!$M$30 -> 0.35653848 | N35: =Seg!$N$29/Seg!$N$30 -> 0.18597948 | O35: =Seg!$O$29/Seg!$O$30 -> 0.17427043
A36: AWS AI 占 AWS | B36: % | C36: =Seg!$C$27/Seg!$C$29 -> 0.021579506 | D36: =Seg!$D$27/Seg!$D$29 -> 0.067615227 | E36: =Seg!$E$27/Seg!$E$29 -> 0.10662064 | F36: =Seg!$F$27/Seg!$F$29 -> 0.198466 | G36: =Seg!$G$27/Seg!$G$29 -> 0.15517921 | H36: =Seg!$H$27/Seg!$H$29 -> 0.34036686 | I36: =Seg!$I$27/Seg!$I$29 -> 0.45304599 | J36: =Seg!$J$27/Seg!$J$29 -> 0.52148725 | K36: =Seg!$K$27/Seg!$K$29 -> 0.5599478 | L36: =Seg!$L$27/Seg!$L$29 -> 0.57236099 | M36: =Seg!$M$27/Seg!$M$29 -> 0.56709732 | N36: =Seg!$N$27/Seg!$N$29 -> 0.0506538 | O36: =Seg!$O$27/Seg!$O$29 -> 0.082488162
A39: Seg｜情境 B（基準）：營收分部層（官方分部 North America、International、AWS；10-K 營收線）
