Workbook

Sheet README
A1: Amazon（AMZN）個股模型 v0.3.1（命題模組＋官方營收分部 → 損益表；2026Q3 季度滾動） 2026-10-31
A2: 版本：v0.3.1（2026Q3 財報 2026-10-29 滾入；v0.3 為 2026-10-27）。資料截至 2026-09-30（2026Q3 新聞稿；10-Q 未取得，附註數字沿用 2026Q2）；FY2026＝9M 實績＋Q4 模型；Tokenomics v21.7（Trainium 改讀 IF_NonNV_Hold_Trn）。
A3: 命題：AWS 的 AI 容量（Trainium＋NVIDIA）能否以高於資金成本的報酬變現，零售與廣告的現金流能否支應資本支出。
A4: 核心問題：FY2028 AWS 營業利益率與自由現金流（扣股利後）是否轉正並維持。
A5: ="投資建議："&Val!B24&"（加權目標價 US$"&TEXT(Val!B19,"0.00")&"，現價 US$"&TEXT(px,"0.00")&"〔2026-10-30〕，上檔空間 "&TEXT(Val!B21,"+0.0%;-0.0%")&"；依五級固定規則）" -> 投資建議：中立（加權目標價 US$217.65，現價 US$240.35〔2026-10-30〕，上檔空間 -9.4%；依五級固定規則）
A6: ="命題答案（情境 B）：FY2028 對外 AI ROIC "&TEXT(Thesis!$I$130,"0.0%")&"，WACC "&TEXT(wacc,"0.0%")&"；打平所需機隊平均 k "&TEXT(Thesis!$I$132,"0.00")&"，模型 k "&TEXT(Thesis!$I$131,"0.00")&"。FY2028 AWS 營業利益率 "&TEXT(PL!$I$123,"0.0%")&"（FY2025 "&TEXT(PL!$D$123,"0.0%")&"）；FY2028 自由現金流扣股利 "&TEXT(CF!$I$59,"#,##0.0")&"；收支關卡（FY2026–FY2030 合計，情境加權）"&TEXT(CF!E6,"#,##0.0")&"。" -> 命題答案（情境 B）：FY2028 對外 AI ROIC 4.9%，WACC 11.2%；打平所需機隊平均 k 1.30，模型 k 0.99。FY2028 AWS 營業利益率 32.8%（FY2025 35.4%）；FY2028 自由現金流扣股利 0.6；收支關卡（FY2026–FY2030 合計，情境加權）118.8。
A7: ="重點觀察 1：目標價 US$"&TEXT(Val!B19,"0.00")&"＝DCF "&TEXT(Val!B17,"0.00")&"（永續價值占 EV "&TEXT(Val!C8,"0%")&"）與分部加總 "&TEXT(Val!B18,"0.00")&" 各半；DCF 低是因為 WACC "&TEXT(wacc,"0.0%")&" 下，2027–2029 的 AI 資本支出（情境 B FY2027 "&TEXT(CF!$H$54,"#,##0")&"）讓 FCFF 偏低，而 AI 增量報酬接近資金成本。" -> 重點觀察 1：目標價 US$217.65＝DCF 147.30（永續價值占 EV 77%）與分部加總 288.00 各半；DCF 低是因為 WACC 11.2% 下，2027–2029 的 AI 資本支出（情境 B FY2027 253）讓 FCFF 偏低，而 AI 增量報酬接近資金成本。
A8: ="重點觀察 2：分部加總中 AWS 其他（非 AI 雲端）占 "&TEXT(Val!$C$166/Val!$C$174,"0%")&"、廣告占 "&TEXT(Val!$C$160/Val!$C$174,"0%")&"；零售本業未來 12 個月 EBITDA（SBC 加回）"&TEXT(Val!$C$161,"#,##0")&"；AWS AI 以自身 DCF 計 "&TEXT(Val!$C$173,"#,##0")&"。" -> 重點觀察 2：分部加總中 AWS 其他（非 AI 雲端）占 47%、廣告占 17%；零售本業未來 12 個月 EBITDA（SBC 加回）58；AWS AI 以自身 DCF 計 58。
A9: ="重點觀察 3：三情境目標價 A "&TEXT(Val!B7,"0")&"／B "&TEXT(Val!C7,"0")&"／C "&TEXT(Val!D7,"0")&"（差異來自新產能 k 與 MW 速度，In 頁 J 節）；讀法 1 加權 "&TEXT(Val!B33,"0.00")&"；市場共識目標價 "&TEXT(cons_tp,"0")&"；v0.3 加權目標價 "&TEXT(v03_tp,"0.00")&"（拆解見 Recon D 節）。" -> 重點觀察 3：三情境目標價 A 263／B 208／C 191（差異來自新產能 k 與 MW 速度，In 頁 J 節）；讀法 1 加權 198.51；市場共識目標價 332；v0.3 加權目標價 215.58（拆解見 Recon D 節）。
A11: 驅動 → 推導對照表（每頁輸入、推導量、因果方向）
A12: In → Thesis：對外 AI MW（6/30 機隊 2,080 MW、評價日 9/30 加一季 C10 速度、之後每年新增 pace）× Tokenomics IF_HoldEcon × k → AWS AI 營收；新增 MW ÷ 對外比例 ×（IT＋自建機房成本）→ AI 資本支出 → IT 6 年／機房 20 年折舊 → AWS AI 營業利益（對外）與自用 AI 成本（零售）。
A13: In → Seg：零售六條營收線（Q4 26＝Q4 25 ×（1＋9M26 年增）× 校準係數〔Q4 合併營收＝指引中點〕，之後收斂到長期年增）→ 零售合計 × 北美比例 → North America／International；AWS＝AWS AI＋AWS 其他（殘差起算、收斂到 8%）。
A14: Seg、Thesis → PL：北美／國際營業利益＝廣告營收 × 50%＋零售本業營收 × 本業利益率（實績殘差＋每年改善）− 自用 AI 成本；AWS 營業利益＝AWS AI＋AWS 其他 × 近四季利益率 → 合併營業利益 → 利息（CF）、稅 17.4% → 淨利 → EPS。
A15: PL → CF：淨利＋分部折舊＋SBC＋其他 − 資本支出（AI＋AWS 其他 20%＋零售 5.9%）− 融資租賃本金 → 自由現金流；股利 0、回購 0；現金低於 50 即舉債 → 利息費用回到 PL。
A16: PL、CF → Val：DCF（FCFF、WACC、RONIC 永續）＋分部加總（廣告、零售本業、AWS 其他、AWS AI × 同業倍數）＋持股（Anthropic、OpenAI）→ 情境目標價 → 情境加權 → 上檔空間 → 投資建議。
A18: 工作表：README → In（輸入；J 節情境驅動對照）→ Q（實績與核對）→ Thesis（命題模組）→ Seg（營收分部）→ PL → CF → Val → Recon（共識、指引、v0.3 拆解）→ Sens（敏感度）→ Sources。
A19: 標記：Verified、Interested-party、Analogy、Assumed、Derived。沿用 v0.2.2：k 規格（kspec.py）、對外比例、WACC 輸入、持股與同業倍數。SemiAnalysis 未使用。In 頁 D／F＝敏感度低／高，只用於 Sens 頁；共識區間只作對照。
A20: 已知限制：(1) 公司未揭露 AI 在役 MW、對外比例與 AI 營收，AWS AI／AWS 其他的歷史分拆為估計；(2) 分部共識未找到，合併共識為財報前；(3) 同業倍數沿用 2026-10-07；(4) 到期債務假設全數再融資；(5) 10-Q 未取得：債務面額、在建、分部折舊、租賃為推導或沿用 2026Q2。

Sheet In
A1: In — 輸入（藍字；基準欄 E 進主模型；D／F＝敏感度低／高，只用於 Sens 頁〔一次動一個參數〕、不進目標價；情境 A／B／C 的驅動見本頁最後一節「J. 情境驅動對照」〔v0.3.1〕）。金額 US$bn、每股 US$、MW＝IT 關鍵電力 MW。每列一個鍵（定義名稱＝鍵）；Analogy、Assumed 一律給低／高區間
A2: 標記：Verified／Interested-party／Analogy／Assumed／Derived。「沿用 v0.2.2」＝v0.2.2 已核准的參數與證據（k 規格 kspec.py、對外比例），出處見 legacy_v0.2/ 與 docs/handoff。不以公司 AWS 營收、backlog、run-rate 反推 k 或每 MW 價格（共同規則第 4 節）；公司說法只作 Recon 驗證列。SemiAnalysis 未使用。資料截至 2026-09-30（2026Q3 新聞稿；10-Q 未取得）
A3: 鍵 | B3: 項目 | C3: 單位 | D3: 敏感度低 | E3: 基準 | F3: 敏感度高 | G3: 標記 | H3: 來源 | I3: 說明
A4: A. 價格、股數與共識目標價
A5: px | B5: AMZN 現價（2026-10-30 收盤） | C5: US$ | E5: 240.35 | G5: Verified | H5: S15；S16 | I5: 10-29 收盤 243.79（財報日，−4.3%）；只影響上檔空間與評等
A6: px_val | B6: WACC 權益權重用股價（最近收盤；評價日 2026-09-30 收盤本輪未取得） | C6: US$ | E6: 240.35 | G6: Verified | H6: S15 | I6: 與現價分開：現價變動只影響上檔空間（拆解 (e)），本列變動歸 (f)
A7: sh_out | B7: 流通股數（2026-09-30，資產負債表股本說明） | C7: 十億股 | E7: 10.811 | G7: Interested-party | H7: S13 | I7: 10-Q 封面股數未取得；Supplemental 同值 10,811 百萬股
A8: sh_awd | B8: 未歸屬股份獎勵（2026-09-30） | C8: 十億股 | E8: 0.223 | G8: Interested-party | H8: S13 | I8: 223 百萬股（Supplemental）
A9: sh_val | B9: 分部加總用稀釋股數＝流通股數＋未歸屬獎勵（倍數為 SBC 加回口徑，故計入稀釋） | C9: 十億股 | E9: =sh_out+sh_awd -> 11.034 | G9: Derived | H9: 修正一（F2） | I9: DCF 視 SBC 為現金成本，改用流通股數 sh_out，不另計稀釋
A10: cons_tp | B10: 市場共識目標價（Koyfin 60 位平均，2026-10-30 財報後） | C10: US$ | D10: 230 | E10: 332.41 | F10: 405 | G10: Interested-party | H10: S17；S18 | I10: MarketBeat 60 位 325.12（10-29）；區間為最低／最高目標價；只作對照，不進模型
A11: B. 折現率（CAPM）
A12: rf | B12: 無風險利率（10 年美債，2026-10-28） | C12: % | E12: 0.0499 | G12: Verified | H12: S33 | I12: v0.3 為 5.00%（10-26）
A13: beta_sa | B13: 原始 Beta：StockAnalysis 5 年月資料（Yahoo 同值，推測同源） | C13: x | E13: 1.46 | G13: Verified | H13: 沿用 v0.2.2（事實總帳 val.beta.sa）
A14: beta_gf | B14: 原始 Beta：GuruFocus 3 年 | C14: x | E14: 1.567 | G14: Verified | H14: 沿用 v0.2.2（事實總帳 val.beta.gurufocus） | I14: 不同資料商、不同期間（C13 獨立來源）
A15: beta | B15: Beta（Blume 調整 0.67 × 原始＋0.33，兩個獨立來源的中位數） | C15: x | D15: =MIN(0.67*beta_sa+0.33,0.67*beta_gf+0.33) -> 1.3082 | E15: =MEDIAN(0.67*beta_sa+0.33,0.67*beta_gf+0.33) -> 1.344045 | F15: =MAX(0.67*beta_sa+0.33,0.67*beta_gf+0.33) -> 1.37989 | G15: Derived | H15: 修正一（F4） | I15: 低／高＝單一來源
A16: erp | B16: 股權風險溢酬 | C16: % | D16: 0.04 | E16: 0.05 | F16: 0.06 | G16: Assumed | H16: 沿用 v0.2.2（對照表預設 10）
A17: kd_new | B17: 新增借款利率（2026-07 新發 2066 票據有效利率；只用於利息費用） | C17: % | E17: 0.0633 | G17: Interested-party | H17: S02 | I17: 期後事項：固定票面 4.60%–6.25%、有效 4.67%–6.33%
A18: kd_spr | B18: AA 級公司債約 10 年期利差（相對 10 年美債） | C18: % | D18: 0.005 | E18: 0.0065 | F18: 0.01 | G18: Assumed | H18: 修正一（F4）：kd＝約 10 年期公司債殖利率 | I18: Amazon 各期票據的 10 年期殖利率：未找到
A19: kd | B19: 稅前債務成本（WACC 用）＝rf＋利差 | C19: % | E19: =rf+kd_spr -> 0.0564 | G19: Derived | H19: 修正一（F4）
A20: tax | B20: 稅率（2023–2025 有效稅率平均） | C20: % | D20: 0.135 | E20: =AVERAGE(Q!$C$42,Q!$D$42,Q!$E$42) -> 0.17358453 | F20: 0.23 | G20: Derived | H20: S01 | I20: 18.96%、13.50%、19.61%；9M26 有效稅率 23.0%（含 Anthropic 評價利益的遞延稅）
A21: debt_q3 | B21: 債務面額（2026-09-30，推導：6/30 面額 133.0＋Q3 長期借款收入 48.1 − 償還） | C21: US$bn | E21: 181.09 | G21: Derived | H21: S02；S13 | I21: 10-Q 附註未取得；帳面法（長期債帳面變動）為 177.2，差額主要是 2027 年到期票據轉入流動部分
A22: fl_pv | B22: 融資租賃負債現值（沿用 2026-06-30；10-Q 未取得） | C22: US$bn | E22: 13.451 | G22: Verified | H22: S02 | I22: 附註 4；Q3 新增融資租賃取得 1.47、本金償還 0.43
A23: fin_obl | B23: 融資義務（financing obligations；沿用 2026-06-30） | C23: US$bn | E23: 11.07 | G23: Verified | H23: S02
A24: fin_debt | B24: 類債務（融資租賃＋融資義務；淨負債與 WACC 的 D 皆計入，模型期間持平） | C24: US$bn | E24: =fl_pv+fin_obl -> 24.521 | G24: Derived | H24: 修正一（F6、核對第 4 點）
A25: ke | B25: 股權成本＝rf＋β × ERP | C25: % | E25: =rf+beta*erp -> 0.11710225 | G25: Derived | H25: CAPM
A26: wacc_adj | B26: WACC 調整（Sens 用；基準 0） | C26: pt | D26: -0.01 | E26: 0 | F26: 0.01 | G26: Assumed | H26: Sens
A27: wacc | B27: WACC＝E/(D+E) × ke＋D/(D+E) × kd ×（1 − 稅率）＋調整；E＝評價用股價 × 流通股數；D＝債務面額＋類債務 | C27: % | E27: =px_val*sh_out/(px_val*sh_out+debt_q3+fin_debt)*ke+(debt_q3+fin_debt)/(px_val*sh_out+debt_q3+fin_debt)*kd*(1-tax)+wacc_adj -> 0.11193326 | G27: Derived | H27: 修正一（F4）
A28: tg | B28: 永續成長率 g | C28: % | D28: 0.02 | E28: 0.03 | F28: 0.04 | G28: Assumed | H28: 工作單第 2 節（g 3%）
A29: ronic | B29: 永續期新投資報酬率（RONIC；預設＝WACC：永續成長不創造價值） | C29: % | E29: =wacc -> 0.11193326 | F29: =wacc+0.05 -> 0.16193326 | G29: Assumed | H29: 判斷（v0.3 報告第 5 節；F5） | I29: 高值＝WACC＋5pt（Sens）
A30: w_dcf | B30: 目標價中 DCF 的權重；其餘為分部加總（SOTP） | C30: % | D30: 0.3 | E30: 0.5 | F30: 0.7 | G30: Assumed | H30: 工作單第 2 節（[判斷] 預設 DCF 50%＋分部加總 50%） | I30: Andy 可改；低／高只用於 Sens
A31: w_A | B31: 情境權重 A（樂觀） | C31: % | E31: 0.25 | G31: Assumed | H31: 工作單第 2 節（[判斷] 預設 A 25%／B 50%／C 25%） | I31: 三者合計 100%
A32: w_B | B32: 情境權重 B（基準） | C32: % | E32: 0.5 | G32: Assumed | H32: 工作單第 2 節（[判斷] 預設 A 25%／B 50%／C 25%） | I32: 三者合計 100%
A33: w_C | B33: 情境權重 C（保守） | C33: % | E33: 0.25 | G33: Assumed | H33: 工作單第 2 節（[判斷] 預設 A 25%／B 50%／C 25%） | I33: 三者合計 100%
A34: tp_yf | B34: 目標價時點（2027-10-31，約 12 個月後）距 DCF 基準日（2026-12-31）年數 | C34: 年 | E34: =(DATE(2027,10,31)-DATE(2026,12,31))/365 -> 0.83287671 | G34: Derived | H34: 目標價約 12 個月後 | I34: v0.3 為 2027-10-27；DCF 情境價值以 ke 推到目標價時點
A35: C. 命題模組：AWS AI（對外 AI 在役 MW × 每 MW 年收入）
A36: mw_ye23 | B36: 對外 AI 在役 MW（2023 年底） | C36: MW | E36: 120 | G36: Assumed | H36: 沿用 v0.2.2（defaults.mwYearEnd） | I36: 公司未揭露 AI 在役 MW；只用於歷史分拆與折舊年份
A37: mw_ye24 | B37: 對外 AI 在役 MW（2024 年底） | C37: MW | E37: 360 | G37: Assumed | H37: 沿用 v0.2.2（defaults.mwYearEnd） | I37: 同上
A38: mw_ye25 | B38: 對外 AI 在役 MW（2025 年底） | C38: MW | D38: 1100 | E38: 1440 | F38: 1800 | G38: Assumed | H38: 沿用 v0.2.2（defaults.mwYearEnd） | I38: Trainium2 1.4M 顆 × 0.871 kW ≈ 1,220 MW-IT（事實總帳 chip.trn2.mwFromLanded）
A39: mw_open | B39: 對外 AI 在役 MW（2026-06-30；期初機隊錨點）＝在役 AI 2,600 × 對外 80% | C39: MW | D39: 1400 | E39: 2080 | F39: 2970 | G39: Derived | H39: S24；S25 | I39: Epoch 三站 1,422 MW（Trainium2）＋NVIDIA 推估；第三方估計
A40: pace_A | B40: 情境 A：對外 AI MW 每年新增（公司「2027 年底容量為 2025 年兩倍」，以 MS 6＋8 GW 對照） | C40: MW/年 | E40: 3733 | G40: Derived | H40: 沿用 v0.2.2（scenarios.mwPath.pace.high）；S35 | I40: 每年 +7 GW × AI 占新增 80% ÷ PUE 1.2 × 對外 80%
...

Sheet Q
A1: Q — 實績（US$bn；股數十億股）：FY2023–FY2025、最近 8 季（2024Q4–2026Q3）、9M25、9M26、1H26 與近四季。資料取自 data/amazon_facts_20261008.json（10-K、10-Q、財報新聞稿逐季補充表）與 data/amazon_facts_2026q3.json（2026Q3 新聞稿，兩讀核對；10-Q 未取得），藍字＝事實值、黑字＝加總或換算
A2: 核對列（綠底）：零售營收線合計＝北美＋國際、營收線合計＝合併營收、分部合計＝合併營收、分部營業利益合計＋未分攤＝合併營業利益、9M26＝事實總帳九個月值；實績皆須為 0
A3: 項目 | B3: 單位 | C3: FY2023A | D3: FY2024A | E3: FY2025A | F3: 2024Q4 | G3: 2025Q1 | H3: 2025Q2 | I3: 2025Q3 | J3: 2025Q4 | K3: 2026Q1 | L3: 2026Q2 | M3: 2026Q3 | N3: 9M25 | O3: 9M26 | P3: 1H26 | Q3: 近四季（2025Q4–2026Q3） | R3: 標記 | S3: 來源
A4: 1. 官方報告分部營收（10-K 附註：North America、International、AWS）
A5: North America | B5: US$bn | C5: 352.828 | D5: 387.497 | E5: 426.305 | F5: 115.586 | G5: 92.887 | H5: 100.068 | I5: 106.267 | J5: 127.083 | K5: 104.143 | L5: 116.177 | M5: 112.852 | N5: =G5+H5+I5 -> 299.222 | O5: =K5+L5+M5 -> 333.172 | P5: =K5+L5 -> 220.32 | Q5: =J5+K5+L5+M5 -> 460.255 | R5: Verified／Interested-party | S5: S01（FY）；S13、S04、S08（逐季補充表）
A6: International | B6: US$bn | C6: 131.2 | D6: 142.906 | E6: 161.894 | F6: 43.42 | G6: 33.513 | H6: 36.761 | I6: 40.896 | J6: 50.724 | K6: 39.789 | L6: 42.197 | M6: 43.108 | N6: =G6+H6+I6 -> 111.17 | O6: =K6+L6+M6 -> 125.094 | P6: =K6+L6 -> 81.986 | Q6: =J6+K6+L6+M6 -> 175.818 | R6: Verified／Interested-party | S6: S01（FY）；S13、S04、S08（逐季補充表）
A7: AWS | B7: US$bn | C7: 90.757 | D7: 107.556 | E7: 128.725 | F7: 28.786 | G7: 29.267 | H7: 30.873 | I7: 33.006 | J7: 35.579 | K7: 37.587 | L7: 42.232 | M7: 45.984 | N7: =G7+H7+I7 -> 93.146 | O7: =K7+L7+M7 -> 125.803 | P7: =K7+L7 -> 79.819 | Q7: =J7+K7+L7+M7 -> 161.382 | R7: Verified／Interested-party | S7: S01（FY）；S13、S04、S08（逐季補充表）
A8: 合併營收 | B8: US$bn | C8: 574.785 | D8: 637.959 | E8: 716.924 | F8: 187.792 | G8: 155.667 | H8: 167.702 | I8: 180.169 | J8: 213.386 | K8: 181.519 | L8: 200.606 | M8: 201.944 | N8: =G8+H8+I8 -> 503.538 | O8: =K8+L8+M8 -> 584.069 | P8: =K8+L8 -> 382.125 | Q8: =J8+K8+L8+M8 -> 797.455 | R8: Verified／Interested-party | S8: S01（FY）；S13、S04、S08（逐季補充表）
A9: 2. 營收線（10-K 營收類別；零售各線＝北美＋國際，AWS 線＝AWS 分部）
A10: Online stores | B10: US$bn | C10: 231.872 | D10: 247.029 | E10: 269.287 | F10: 75.556 | G10: 57.407 | H10: 61.485 | I10: 67.407 | J10: 82.988 | K10: 64.254 | L10: 70.432 | M10: 68.47 | N10: =G10+H10+I10 -> 186.299 | O10: =K10+L10+M10 -> 203.156 | P10: =K10+L10 -> 134.686 | Q10: =J10+K10+L10+M10 -> 286.144 | R10: Verified／Interested-party | S10: S01（FY）；S13、S04、S08（逐季補充表）
A11: Physical stores | B11: US$bn | C11: 20.03 | D11: 21.215 | E11: 22.561 | F11: 5.579 | G11: 5.533 | H11: 5.595 | I11: 5.578 | J11: 5.855 | K11: 5.785 | L11: 5.794 | M11: 5.71 | N11: =G11+H11+I11 -> 16.706 | O11: =K11+L11+M11 -> 17.289 | P11: =K11+L11 -> 11.579 | Q11: =J11+K11+L11+M11 -> 23.144 | R11: Verified／Interested-party | S11: S01（FY）；S13、S04、S08（逐季補充表）
A12: Third-party seller services | B12: US$bn | C12: 140.053 | D12: 156.146 | E12: 172.162 | F12: 47.485 | G12: 36.512 | H12: 40.348 | I12: 42.486 | J12: 52.816 | K12: 41.578 | L12: 46.78 | M12: 46.492 | N12: =G12+H12+I12 -> 119.346 | O12: =K12+L12+M12 -> 134.85 | P12: =K12+L12 -> 88.358 | Q12: =J12+K12+L12+M12 -> 187.666 | R12: Verified／Interested-party | S12: S01（FY）；S13、S04、S08（逐季補充表）
A13: Advertising services | B13: US$bn | C13: 46.906 | D13: 56.214 | E13: 68.635 | F13: 17.288 | G13: 13.921 | H13: 15.694 | I13: 17.703 | J13: 21.317 | K13: 17.243 | L13: 19.809 | M13: 19.637 | N13: =G13+H13+I13 -> 47.318 | O13: =K13+L13+M13 -> 56.689 | P13: =K13+L13 -> 37.052 | Q13: =J13+K13+L13+M13 -> 78.006 | R13: Verified／Interested-party | S13: S01（FY）；S13、S04、S08（逐季補充表）
A14: Subscription services | B14: US$bn | C14: 40.209 | D14: 44.374 | E14: 49.619 | F14: 11.508 | G14: 11.715 | H14: 12.208 | I14: 12.574 | J14: 13.122 | K14: 13.427 | L14: 13.73 | M14: 14.006 | N14: =G14+H14+I14 -> 36.497 | O14: =K14+L14+M14 -> 41.163 | P14: =K14+L14 -> 27.157 | Q14: =J14+K14+L14+M14 -> 54.285 | R14: Verified／Interested-party | S14: S01（FY）；S13、S04、S08（逐季補充表）
A15: Other | B15: US$bn | C15: 4.958 | D15: 5.425 | E15: 5.935 | F15: 1.59 | G15: 1.312 | H15: 1.499 | I15: 1.415 | J15: 1.709 | K15: 1.645 | L15: 1.829 | M15: 1.645 | N15: =G15+H15+I15 -> 4.226 | O15: =K15+L15+M15 -> 5.119 | P15: =K15+L15 -> 3.474 | Q15: =J15+K15+L15+M15 -> 6.828 | R15: Verified／Interested-party | S15: S01（FY）；S13、S04、S08（逐季補充表）
A16: 零售營收線合計（不含 AWS） | B16: US$bn | C16: =C10+C11+C12+C13+C14+C15 -> 484.028 | D16: =D10+D11+D12+D13+D14+D15 -> 530.403 | E16: =E10+E11+E12+E13+E14+E15 -> 588.199 | F16: =F10+F11+F12+F13+F14+F15 -> 159.006 | G16: =G10+G11+G12+G13+G14+G15 -> 126.4 | H16: =H10+H11+H12+H13+H14+H15 -> 136.829 | I16: =I10+I11+I12+I13+I14+I15 -> 147.163 | J16: =J10+J11+J12+J13+J14+J15 -> 177.807 | ... Q16: =Q10+Q11+Q12+Q13+Q14+Q15 -> 636.073 | R16: Derived
A17: AWS（營收線） | B17: US$bn | C17: =C7 -> 90.757 | D17: =D7 -> 107.556 | E17: =E7 -> 128.725 | F17: =F7 -> 28.786 | G17: =G7 -> 29.267 | H17: =H7 -> 30.873 | I17: =I7 -> 33.006 | J17: =J7 -> 35.579 | ... Q17: =Q7 -> 161.382 | R17: Derived
A18: 檢查：零售營收線合計 − (North America＋International) | B18: US$bn | C18: =C16-(C5+C6) -> 0 | D18: =D16-(D5+D6) -> 0 | E18: =E16-(E5+E6) -> 0 | F18: =F16-(F5+F6) -> 0 | G18: =G16-(G5+G6) -> 0 | H18: =H16-(H5+H6) -> 0 | I18: =I16-(I5+I6) -> 0 | J18: =J16-(J5+J6) -> 0 | ... Q18: =Q16-(Q5+Q6) -> 0 | R18: Derived
A19: 檢查：營收線合計（含 AWS）− 合併營收 | B19: US$bn | C19: =C16+C17-C8 -> 0 | D19: =D16+D17-D8 -> 0 | E19: =E16+E17-E8 -> 0 | F19: =F16+F17-F8 -> 0 | G19: =G16+G17-G8 -> 0 | H19: =H16+H17-H8 -> 0 | I19: =I16+I17-I8 -> 0 | J19: =J16+J17-J8 -> 0 | ... Q19: =Q16+Q17-Q8 -> 0 | R19: Derived
A20: 檢查：分部合計 − 合併營收 | B20: US$bn | C20: =C5+C6+C7-C8 -> 0 | D20: =D5+D6+D7-D8 -> 0 | E20: =E5+E6+E7-E8 -> 0 | F20: =F5+F6+F7-F8 -> 0 | G20: =G5+G6+G7-G8 -> 0 | H20: =H5+H6+H7-H8 -> 0 | I20: =I5+I6+I7-I8 -> 0 | J20: =J5+J6+J7-J8 -> 0 | ... Q20: =Q5+Q6+Q7-Q8 -> 0 | R20: Derived
A21: 檢查：9M26 合併營收 − 新聞稿九個月值（事實 is.TOT.rev.2026m9） | B21: US$bn | O21: =O8-584.069 -> 0 | R21: Derived
A22: 3. 分部營業利益
A23: North America 營業利益 | B23: US$bn | C23: 14.877 | D23: 24.967 | E23: 29.619 | F23: 9.256 | G23: 5.841 | H23: 7.517 | I23: 4.789 | J23: 11.472 | K23: 8.267 | L23: 9.123 | M23: 8.723 | N23: =G23+H23+I23 -> 18.147 | O23: =K23+L23+M23 -> 26.113 | P23: =K23+L23 -> 17.39 | Q23: =J23+K23+L23+M23 -> 37.585 | R23: Verified／Interested-party | S23: S01（FY）；S13、S04、S08（逐季補充表）
A24: International 營業利益 | B24: US$bn | C24: -2.656 | D24: 3.792 | E24: 4.75 | F24: 1.315 | G24: 1.017 | H24: 1.494 | I24: 1.199 | J24: 1.04 | K24: 1.424 | L24: 1.717 | M24: 1.58 | N24: =G24+H24+I24 -> 3.71 | O24: =K24+L24+M24 -> 4.721 | P24: =K24+L24 -> 3.141 | Q24: =J24+K24+L24+M24 -> 5.761 | R24: Verified／Interested-party | S24: S01（FY）；S13、S04、S08（逐季補充表）
A25: AWS 營業利益 | B25: US$bn | C25: 24.631 | D25: 39.834 | E25: 45.606 | F25: 10.632 | G25: 11.547 | H25: 10.16 | I25: 11.434 | J25: 12.465 | K25: 14.161 | L25: 16.621 | M25: 17.773 | N25: =G25+H25+I25 -> 33.141 | O25: =K25+L25+M25 -> 48.555 | P25: =K25+L25 -> 30.782 | Q25: =J25+K25+L25+M25 -> 61.02 | R25: Verified／Interested-party | S25: S01（FY）；S13、S04、S08（逐季補充表）
A26: 合併營業利益 | B26: US$bn | C26: 36.852 | D26: 68.593 | E26: 79.975 | F26: 21.203 | G26: 18.405 | H26: 19.171 | I26: 17.422 | J26: 24.977 | K26: 23.852 | L26: 27.461 | M26: 28.076 | N26: =G26+H26+I26 -> 54.998 | O26: =K26+L26+M26 -> 79.389 | P26: =K26+L26 -> 51.313 | Q26: =J26+K26+L26+M26 -> 104.366 | R26: Verified／Interested-party | S26: S01（FY）；S13、S04、S08（逐季補充表）
A27: 未分攤（合併 − 分部合計；Amazon 分部已含全部費用） | B27: US$bn | C27: =C26-(C23+C24+C25) -> 0 | D27: =D26-(D23+D24+D25) -> 0 | E27: =E26-(E23+E24+E25) -> 0 | F27: =F26-(F23+F24+F25) -> 0 | G27: =G26-(G23+G24+G25) -> 0 | H27: =H26-(H23+H24+H25) -> 0 | I27: =I26-(I23+I24+I25) -> 0 | J27: =J26-(J23+J24+J25) -> 0 | ... Q27: =Q26-(Q23+Q24+Q25) -> 0 | R27: Derived
A28: 檢查：分部營業利益合計＋未分攤 − 合併營業利益 | B28: US$bn | C28: =C23+C24+C25+C27-C26 -> 0 | D28: =D23+D24+D25+D27-D26 -> 0 | E28: =E23+E24+E25+E27-E26 -> 0 | F28: =F23+F24+F25+F27-F26 -> 0 | G28: =G23+G24+G25+G27-G26 -> 0 | H28: =H23+H24+H25+H27-H26 -> 0 | I28: =I23+I24+I25+I27-I26 -> 0 | J28: =J23+J24+J25+J27-J26 -> 0 | ... Q28: =Q23+Q24+Q25+Q27-Q26 -> 0 | R28: Derived
A29: 檢查：9M26 合併營業利益 − 新聞稿九個月值（事實 is.TOT.oi.2026m9） | B29: US$bn | O29: =O26-79.389 -> 0 | R29: Derived
A30: 4. 分部折舊攤銷（不含影音內容與營業租賃資產攤銷；2024 季度未收；2025Q4＝全年 − 前三季；2026Q3＝2026Q2 × 現金流量表 D&A 季增比〔推導，10-Q 未取得〕）
A31: North America 折舊攤銷 | B31: US$bn | C31: 13.678 | D31: 14.285 | E31: 15.503 | G31: 3.53 | H31: 3.742 | I31: 4.001 | J31: =E31-G31-H31-I31 -> 4.23 | K31: 4.28 | L31: 4.5 | M31: =L31*M49/L49 -> 4.7163548 | N31: =G31+H31+I31 -> 11.273 | O31: =K31+L31+M31 -> 13.496355 | P31: =K31+L31 -> 8.78 | Q31: =J31+K31+L31+M31 -> 17.726355 | R31: Verified／Derived（2026Q3） | S31: S01；S02；S03
A32: International 折舊攤銷 | B32: US$bn | C32: 4.016 | D32: 4.462 | E32: 4.907 | G32: 1.136 | H32: 1.18 | I32: 1.276 | J32: =E32-G32-H32-I32 -> 1.315 | K32: 1.277 | L32: 1.293 | M32: =L32*M49/L49 -> 1.3551659 | N32: =G32+H32+I32 -> 3.592 | O32: =K32+L32+M32 -> 3.9251659 | P32: =K32+L32 -> 2.57 | Q32: =J32+K32+L32+M32 -> 5.2401659 | R32: Verified／Derived（2026Q3） | S32: S01；S02；S03
A33: AWS 折舊攤銷 | B33: US$bn | C33: 12.531 | D33: 13.32 | E33: 21.45 | G33: 4.39 | H33: 4.844 | I33: 5.648 | J33: =E33-G33-H33-I33 -> 6.568 | K33: 7.277 | L33: 8.076 | M33: =L33*M49/L49 -> 8.4642848 | N33: =G33+H33+I33 -> 14.882 | O33: =K33+L33+M33 -> 23.817285 | P33: =K33+L33 -> 15.353 | Q33: =J33+K33+L33+M33 -> 30.385285 | R33: Verified／Derived（2026Q3） | S33: S01；S02；S03
A34: 分部折舊攤銷合計 | B34: US$bn | C34: =IF(COUNT(C31:C33)=3,C31+C32+C33,"") -> 30.225 | D34: =IF(COUNT(D31:D33)=3,D31+D32+D33,"") -> 32.067 | E34: =IF(COUNT(E31:E33)=3,E31+E32+E33,"") -> 41.86 | F34: =IF(COUNT(F31:F33)=3,F31+F32+F33,"") | G34: =IF(COUNT(G31:G33)=3,G31+G32+G33,"") -> 9.056 | H34: =IF(COUNT(H31:H33)=3,H31+H32+H33,"") -> 9.766 | I34: =IF(COUNT(I31:I33)=3,I31+I32+I33,"") -> 10.925 | J34: =IF(COUNT(J31:J33)=3,J31+J32+J33,"") -> 12.113 | ... Q34: =IF(COUNT(Q31:Q33)=3,Q31+Q32+Q33,"") -> 53.351806 | R34: Derived
A35: 5. 損益（業外、稅、淨利）
A36: 利息費用 | B36: US$bn | C36: 3.182 | D36: 2.406 | E36: 2.274 | F36: 0.57 | G36: 0.541 | H36: 0.516 | I36: 0.538 | J36: 0.679 | K36: 0.8 | L36: 1.314 | M36: 1.691 | N36: =G36+H36+I36 -> 1.595 | O36: =K36+L36+M36 -> 3.805 | P36: =K36+L36 -> 2.114 | Q36: =J36+K36+L36+M36 -> 4.484 | R36: Verified／Interested-party | S36: S01；S13
A37: 利息收入 | B37: US$bn | L37: 1.295 | M37: 1.187 | R37: Interested-party | S37: S02；S13
A38: 稅前淨利 | B38: US$bn | C38: 37.557 | D38: 68.614 | E38: 97.311 | F38: 22.349 | G38: 21.679 | H38: 20.857 | I38: 28.17 | J38: 26.605 | K38: 39.834 | L38: 80.857 | M38: 26.869 | N38: =G38+H38+I38 -> 70.706 | O38: =K38+L38+M38 -> 147.56 | P38: =K38+L38 -> 120.691 | Q38: =J38+K38+L38+M38 -> 174.165 | R38: Verified／Interested-party | S38: S01；S13
A39: 所得稅 | B39: US$bn | C39: 7.12 | D39: 9.265 | E39: 19.087 | F39: 2.325 | G39: 4.553 | H39: 2.678 | I39: 6.91 | J39: 4.946 | K39: 9.56 | L39: 18.199 | M39: 6.18 | N39: =G39+H39+I39 -> 14.141 | O39: =K39+L39+M39 -> 33.939 | P39: =K39+L39 -> 27.759 | Q39: =J39+K39+L39+M39 -> 38.885 | R39: Verified／Interested-party | S39: S01；S13
A40: 淨利 | B40: US$bn | C40: 30.425 | D40: 59.248 | E40: 77.67 | F40: 20.004 | G40: 17.127 | H40: 18.164 | I40: 21.187 | J40: 21.192 | K40: 30.255 | L40: 62.647 | M40: 20.685 | N40: =G40+H40+I40 -> 56.478 | O40: =K40+L40+M40 -> 113.587 | P40: =K40+L40 -> 92.902 | Q40: =J40+K40+L40+M40 -> 134.779 | R40: Verified／Interested-party | S40: S01；S13
...

Sheet Thesis
A1: Thesis — 命題模組：AWS AI＝對外 AI 在役 MW × 每 MW 年收入（Tokenomics v21.7 IF_HoldEcon × k；新增 Trainium＝GB300 錨 × IF_NonNV_Hold_Trn 0.61，v0.3.1）。AI 資本支出（含自用）→ IT 6 年／機房 20 年折舊（次年起提列）→ 對外部分進 AWS 營業利益、自用部分進北美／國際營業利益。三情境 A／B／C 依序排列
A2: 情境差異集中在命題驅動（In 頁 J 節）：A＝公司容量目標速度＋新產能 k 價格軸高；B＝資本支出指引隱含速度（C10，下半年視窗）＋基準 k；C＝與 B 同速度（資本支出照指引）＋新產能 k 價格軸低。非 AI 業務三情境相同
A4: Thesis｜情境 A（樂觀）：命題模組 AWS AI＝對外 AI 在役 MW × 每 MW 年收入（Tokenomics 持有成本 × k）；AI 資本支出 → 折舊 → 分部營業利益
A5: 項目 | B5: 單位 | C5: FY2024A | D5: FY2025A | E5: 9M26A | F5: Q4 26E | G5: FY2026E（9M 實績＋Q4 模型） | H5: FY2027E | I5: FY2028E | J5: FY2029E | K5: FY2030E | L5: FY2031E | M5: FY2032E | N5: 9M25A | O5: Q4 25A | P5: 說明 | R5: 2023 | S5: 2024 | T5: 2025 | U5: 2026 | V5: 2027 | W5: 2028 | X5: 2029 | Y5: 2030 | Z5: 2031 | AA5: 2032
A6: 1. 容量（對外 AI 在役 MW-IT；期末）
A7: 對外 AI MW 每年新增（2030–2032 線性收斂到 FY2029 年底 MW × g，F5） | B7: MW/年 | H7: =(pace_A*pace_x) -> 3733 | I7: =(pace_A*pace_x) -> 3733 | J7: =(pace_A*pace_x) -> 3733 | K7: =(pace_A*pace_x)+(Thesis!$J$8*tg-(pace_A*pace_x))*1/3 -> 2640.2614 | L7: =(pace_A*pace_x)+(Thesis!$J$8*tg-(pace_A*pace_x))*2/3 -> 1547.5228 | M7: =(pace_A*pace_x)+(Thesis!$J$8*tg-(pace_A*pace_x))*3/3 -> 454.78425 | P7: 終值不落在建置高峰（共同修正 F5）
A8: 對外 AI 在役 MW（期末） | B8: MW | C8: =mw_ye24 -> 360 | D8: =mw_ye25 -> 1440 | E8: =mw_q3 -> 3027.225 | F8: =Thesis!$E$8+(pace_A*pace_x)*0.25 -> 3960.475 | G8: =Thesis!$F$8 -> 3960.475 | H8: =Thesis!$G$8+Thesis!$H$7 -> 7693.475 | I8: =Thesis!$H$8+Thesis!$I$7 -> 11426.475 | J8: =Thesis!$I$8+Thesis!$J$7 -> 15159.475 | K8: =Thesis!$J$8+Thesis!$K$7 -> 17799.736 | L8: =Thesis!$K$8+Thesis!$L$7 -> 19347.259 | M8: =Thesis!$L$8+Thesis!$M$7 -> 19802.043 | N8: =mw_ye24+(mw_ye25-mw_ye24)*0.75 -> 1170 | O8: =mw_ye25 -> 1440 | P8: 評價日 2026-09-30＝In 頁 mw_q3（6/30 機隊＋C10 速度一季）；之後每年新增＝In 頁 pace（情境）× pace_x；歷史年底值只用於分拆與折舊年份
A9: 對外 AI 平均在役 MW（期間） | B9: MW | C9: =(mw_ye23+mw_ye24)/2 -> 240 | D9: =(Thesis!$C$8+Thesis!$D$8)/2 -> 900 | E9: =(Thesis!$D$8+Thesis!$E$8)/2 -> 2233.6125 | F9: =(Thesis!$E$8+Thesis!$F$8)/2 -> 3493.85 | G9: =Thesis!$E$9*0.75+Thesis!$F$9*0.25 -> 2548.6719 | H9: =(Thesis!$G$8+Thesis!$H$8)/2 -> 5826.975 | I9: =(Thesis!$H$8+Thesis!$I$8)/2 -> 9559.975 | J9: =(Thesis!$I$8+Thesis!$J$8)/2 -> 13292.975 | K9: =(Thesis!$J$8+Thesis!$K$8)/2 -> 16479.606 | L9: =(Thesis!$K$8+Thesis!$L$8)/2 -> 18573.498 | M9: =(Thesis!$L$8+Thesis!$M$8)/2 -> 19574.651 | N9: =(Thesis!$C$8+Thesis!$N$8)/2 -> 765 | O9: =(Thesis!$N$8+Thesis!$O$8)/2 -> 1305
A10: 期間長度 | B10: 年 | C10: 1 | D10: 1 | E10: 0.75 | F10: 0.25 | G10: 1 | H10: 1 | I10: 1 | J10: 1 | K10: 1 | L10: 1 | M10: 1 | N10: 0.75 | O10: 0.25
A11: 新增對外 AI MW | B11: MW | C11: =Thesis!$C$8-mw_ye23 -> 240 | D11: =Thesis!$D$8-Thesis!$C$8 -> 1080 | E11: =Thesis!$E$8-Thesis!$D$8 -> 1587.225 | F11: =Thesis!$F$8-Thesis!$E$8 -> 933.25 | G11: =Thesis!$E$11+Thesis!$F$11 -> 2520.475 | H11: =Thesis!$H$8-Thesis!$G$8 -> 3733 | I11: =Thesis!$I$8-Thesis!$H$8 -> 3733 | J11: =Thesis!$J$8-Thesis!$I$8 -> 3733 | K11: =Thesis!$K$8-Thesis!$J$8 -> 2640.2614 | L11: =Thesis!$L$8-Thesis!$K$8 -> 1547.5228 | M11: =Thesis!$M$8-Thesis!$L$8 -> 454.78425 | N11: =Thesis!$N$8-Thesis!$C$8 -> 810 | O11: =Thesis!$O$8-Thesis!$N$8 -> 270
A12: 新增 AI 總 MW（含自用＝對外 ÷ 對外比例） | B12: MW | C12: =Thesis!$C$11/ext_sh -> 300 | D12: =Thesis!$D$11/ext_sh -> 1350 | E12: =Thesis!$E$11/ext_sh -> 1984.0312 | F12: =Thesis!$F$11/ext_sh -> 1166.5625 | G12: =Thesis!$G$11/ext_sh -> 3150.5938 | H12: =Thesis!$H$11/ext_sh -> 4666.25 | I12: =Thesis!$I$11/ext_sh -> 4666.25 | J12: =Thesis!$J$11/ext_sh -> 4666.25 | K12: =Thesis!$K$11/ext_sh -> 3300.3268 | L12: =Thesis!$L$11/ext_sh -> 1934.4035 | M12: =Thesis!$M$11/ext_sh -> 568.48031 | N12: =Thesis!$N$11/ext_sh -> 1012.5 | O12: =Thesis!$O$11/ext_sh -> 337.5 | P12: R–AA 欄：依年份（折舊與汰換用） | R12: =mw_ye23/ext_sh -> 150 | S12: =Thesis!$C$12 -> 300 | T12: =Thesis!$D$12 -> 1350 | U12: =Thesis!$G$12 -> 3150.5938 | V12: =Thesis!$H$12 -> 4666.25 | W12: =Thesis!$I$12 -> 4666.25 | X12: =Thesis!$J$12 -> 4666.25 | Y12: =Thesis!$K$12 -> 3300.3268 | Z12: =Thesis!$L$12 -> 1934.4035 | AA12: =Thesis!$M$12 -> 568.48031
A13: 2. 新增產能的世代與單位經濟（Tokenomics v21.7 基準成本；自研晶片＝GB300 錨 × IF_NonNV_Hold_Trn，v0.3.1）
A14: NVIDIA 新增中 VR200 比例 | B14: % | F14: =na_vr26 -> 0 | G14: =na_vr26 -> 0 | H14: =na_vr27 -> 0.5 | I14: =na_vr28 -> 1 | J14: =na_vr28 -> 1 | K14: =na_vr28 -> 1 | L14: =na_vr28 -> 1 | M14: =na_vr28 -> 1
A15: 新增 MW 加權 IF_HoldEcon（含自研晶片係數） | B15: US$m/MW-年 | F15: =cust_sh*tk_he_gb300*cf_chip+(1-cust_sh)*((1-Thesis!$F$14)*tk_he_gb300+Thesis!$F$14*tk_he_vr200) -> 8.7635609 | G15: =cust_sh*tk_he_gb300*cf_chip+(1-cust_sh)*((1-Thesis!$G$14)*tk_he_gb300+Thesis!$G$14*tk_he_vr200) -> 8.7635609 | H15: =cust_sh*tk_he_gb300*cf_chip+(1-cust_sh)*((1-Thesis!$H$14)*tk_he_gb300+Thesis!$H$14*tk_he_vr200) -> 9.0983259 | I15: =cust_sh*tk_he_gb300*cf_chip+(1-cust_sh)*((1-Thesis!$I$14)*tk_he_gb300+Thesis!$I$14*tk_he_vr200) -> 9.4330909 | J15: =cust_sh*tk_he_gb300*cf_chip+(1-cust_sh)*((1-Thesis!$J$14)*tk_he_gb300+Thesis!$J$14*tk_he_vr200) -> 9.4330909 | K15: =cust_sh*tk_he_gb300*cf_chip+(1-cust_sh)*((1-Thesis!$K$14)*tk_he_gb300+Thesis!$K$14*tk_he_vr200) -> 9.4330909 | L15: =cust_sh*tk_he_gb300*cf_chip+(1-cust_sh)*((1-Thesis!$L$14)*tk_he_gb300+Thesis!$L$14*tk_he_vr200) -> 9.4330909 | M15: =cust_sh*tk_he_gb300*cf_chip+(1-cust_sh)*((1-Thesis!$M$14)*tk_he_gb300+Thesis!$M$14*tk_he_vr200) -> 9.4330909
A16: 新增 MW 加權營運費用（IF_OpexGW） | B16: US$m/MW-年 | F16: =cust_sh*tk_ox_gb300+(1-cust_sh)*((1-Thesis!$F$14)*tk_ox_gb300+Thesis!$F$14*tk_ox_vr200) -> 1.9826348 | G16: =cust_sh*tk_ox_gb300+(1-cust_sh)*((1-Thesis!$G$14)*tk_ox_gb300+Thesis!$G$14*tk_ox_vr200) -> 1.9826348 | H16: =cust_sh*tk_ox_gb300+(1-cust_sh)*((1-Thesis!$H$14)*tk_ox_gb300+Thesis!$H$14*tk_ox_vr200) -> 2.01035 | I16: =cust_sh*tk_ox_gb300+(1-cust_sh)*((1-Thesis!$I$14)*tk_ox_gb300+Thesis!$I$14*tk_ox_vr200) -> 2.0380652 | J16: =cust_sh*tk_ox_gb300+(1-cust_sh)*((1-Thesis!$J$14)*tk_ox_gb300+Thesis!$J$14*tk_ox_vr200) -> 2.0380652 | K16: =cust_sh*tk_ox_gb300+(1-cust_sh)*((1-Thesis!$K$14)*tk_ox_gb300+Thesis!$K$14*tk_ox_vr200) -> 2.0380652 | L16: =cust_sh*tk_ox_gb300+(1-cust_sh)*((1-Thesis!$L$14)*tk_ox_gb300+Thesis!$L$14*tk_ox_vr200) -> 2.0380652 | M16: =cust_sh*tk_ox_gb300+(1-cust_sh)*((1-Thesis!$M$14)*tk_ox_gb300+Thesis!$M$14*tk_ox_vr200) -> 2.0380652
A17: 新增 MW 加權 IT 資本支出（IF_CapexIT；含自研晶片資本支出係數） | B17: US$m/MW | F17: =cust_sh*tk_cx_gb300*cf_cx+(1-cust_sh)*((1-Thesis!$F$14)*tk_cx_gb300+Thesis!$F$14*tk_cx_vr200) -> 25.950965 | G17: =cust_sh*tk_cx_gb300*cf_cx+(1-cust_sh)*((1-Thesis!$G$14)*tk_cx_gb300+Thesis!$G$14*tk_cx_vr200) -> 25.950965 | H17: =cust_sh*tk_cx_gb300*cf_cx+(1-cust_sh)*((1-Thesis!$H$14)*tk_cx_gb300+Thesis!$H$14*tk_cx_vr200) -> 27.288247 | I17: =cust_sh*tk_cx_gb300*cf_cx+(1-cust_sh)*((1-Thesis!$I$14)*tk_cx_gb300+Thesis!$I$14*tk_cx_vr200) -> 28.625529 | J17: =cust_sh*tk_cx_gb300*cf_cx+(1-cust_sh)*((1-Thesis!$J$14)*tk_cx_gb300+Thesis!$J$14*tk_cx_vr200) -> 28.625529 | K17: =cust_sh*tk_cx_gb300*cf_cx+(1-cust_sh)*((1-Thesis!$K$14)*tk_cx_gb300+Thesis!$K$14*tk_cx_vr200) -> 28.625529 | L17: =cust_sh*tk_cx_gb300*cf_cx+(1-cust_sh)*((1-Thesis!$L$14)*tk_cx_gb300+Thesis!$L$14*tk_cx_vr200) -> 28.625529 | M17: =cust_sh*tk_cx_gb300*cf_cx+(1-cust_sh)*((1-Thesis!$M$14)*tk_cx_gb300+Thesis!$M$14*tk_cx_vr200) -> 28.625529
A18: 期初後新增對外 MW 累計（期末） | B18: MW | E18: =Thesis!$E$8-mw_open -> 947.225 | F18: =Thesis!$F$8-mw_open -> 1880.475 | G18: =Thesis!$F$18 -> 1880.475 | H18: =Thesis!$H$8-mw_open -> 5613.475 | I18: =Thesis!$I$8-mw_open -> 9346.475 | J18: =Thesis!$J$8-mw_open -> 13079.475 | K18: =Thesis!$K$8-mw_open -> 15719.736 | L18: =Thesis!$L$8-mw_open -> 17267.259 | M18: =Thesis!$M$8-mw_open -> 17722.043
A19: Σ 新增 MW × HoldEcon | B19: US$m | E19: =Thesis!$E$18*Thesis!$F$15 -> 8301.0639 | F19: =Thesis!$E$19+Thesis!$F$11*Thesis!$F$15 -> 16479.657 | G19: =Thesis!$F$19 -> 16479.657 | H19: =Thesis!$G$19+Thesis!$H$11*Thesis!$H$15 -> 50443.708 | I19: =Thesis!$H$19+Thesis!$I$11*Thesis!$I$15 -> 85657.436 | J19: =Thesis!$I$19+Thesis!$J$11*Thesis!$J$15 -> 120871.16 | K19: =Thesis!$J$19+Thesis!$K$11*Thesis!$K$15 -> 145776.99 | L19: =Thesis!$K$19+Thesis!$L$11*Thesis!$L$15 -> 160374.91 | M19: =Thesis!$L$19+Thesis!$M$11*Thesis!$M$15 -> 164664.93
A20: Σ 新增 MW × 營運費用 | B20: US$m | E20: =Thesis!$E$18*Thesis!$F$16 -> 1878.0013 | F20: =Thesis!$E$20+Thesis!$F$11*Thesis!$F$16 -> 3728.2952 | G20: =Thesis!$F$20 -> 3728.2952 | H20: =Thesis!$G$20+Thesis!$H$11*Thesis!$H$16 -> 11232.932 | I20: =Thesis!$H$20+Thesis!$I$11*Thesis!$I$16 -> 18841.029 | J20: =Thesis!$I$20+Thesis!$J$11*Thesis!$J$16 -> 26449.126 | K20: =Thesis!$J$20+Thesis!$K$11*Thesis!$K$16 -> 31830.151 | L20: =Thesis!$K$20+Thesis!$L$11*Thesis!$L$16 -> 34984.104 | M20: =Thesis!$L$20+Thesis!$M$11*Thesis!$M$16 -> 35910.984
A21: 新增機隊加權 HoldEcon | B21: US$m/MW-年 | F21: =IF(Thesis!$F$18>0,Thesis!$F$19/Thesis!$F$18,Thesis!$F$15) -> 8.7635609 | G21: =IF(Thesis!$G$18>0,Thesis!$G$19/Thesis!$G$18,Thesis!$G$15) -> 8.7635609 | H21: =IF(Thesis!$H$18>0,Thesis!$H$19/Thesis!$H$18,Thesis!$H$15) -> 8.9861819 | I21: =IF(Thesis!$I$18>0,Thesis!$I$19/Thesis!$I$18,Thesis!$I$15) -> 9.1646782 | J21: =IF(Thesis!$J$18>0,Thesis!$J$19/Thesis!$J$18,Thesis!$J$15) -> 9.2412856 | K21: =IF(Thesis!$K$18>0,Thesis!$K$19/Thesis!$K$18,Thesis!$K$15) -> 9.2735009 | L21: =IF(Thesis!$L$18>0,Thesis!$L$19/Thesis!$L$18,Thesis!$L$15) -> 9.2878036 | M21: =IF(Thesis!$M$18>0,Thesis!$M$19/Thesis!$M$18,Thesis!$M$15) -> 9.291532
A22: 新增機隊加權營運費用 | B22: US$m/MW-年 | F22: =IF(Thesis!$F$18>0,Thesis!$F$20/Thesis!$F$18,Thesis!$F$16) -> 1.9826348 | G22: =IF(Thesis!$G$18>0,Thesis!$G$20/Thesis!$G$18,Thesis!$G$16) -> 1.9826348 | H22: =IF(Thesis!$H$18>0,Thesis!$H$20/Thesis!$H$18,Thesis!$H$16) -> 2.0010656 | I22: =IF(Thesis!$I$18>0,Thesis!$I$20/Thesis!$I$18,Thesis!$I$16) -> 2.0158433 | J22: =IF(Thesis!$J$18>0,Thesis!$J$20/Thesis!$J$18,Thesis!$J$16) -> 2.0221856 | K22: =IF(Thesis!$K$18>0,Thesis!$K$20/Thesis!$K$18,Thesis!$K$16) -> 2.0248527 | L22: =IF(Thesis!$L$18>0,Thesis!$L$20/Thesis!$L$18,Thesis!$L$16) -> 2.0260369 | M22: =IF(Thesis!$M$18>0,Thesis!$M$20/Thesis!$M$18,Thesis!$M$16) -> 2.0263455
A23: 新增產能每 MW 年收入＝新增機隊 HoldEcon × 情境 k | B23: US$m/MW-年 | F23: =Thesis!$F$21*k_A -> 13.306014 | G23: =Thesis!$G$21*k_A -> 13.306014 | H23: =Thesis!$H$21*k_A -> 13.644027 | I23: =Thesis!$I$21*k_A -> 13.915044 | J23: =Thesis!$J$21*k_A -> 14.03136 | K23: =Thesis!$K$21*k_A -> 14.080274 | L23: =Thesis!$L$21*k_A -> 14.10199 | M23: =Thesis!$M$21*k_A -> 14.107651 | P23: 6/30 機隊 2,080 MW 三情境同用 rpm_open（k_B）；情境 k 用於 6/30 之後的新產能（含 Q3 新增）
A24: 新增產能平均在役 MW（期間） | B24: MW | F24: =(Thesis!$E$18+Thesis!$F$18)/2 -> 1413.85 | H24: =(Thesis!$G$18+Thesis!$H$18)/2 -> 3746.975 | I24: =(Thesis!$H$18+Thesis!$I$18)/2 -> 7479.975 | J24: =(Thesis!$I$18+Thesis!$J$18)/2 -> 11212.975 | K24: =(Thesis!$J$18+Thesis!$K$18)/2 -> 14399.606 | L24: =(Thesis!$K$18+Thesis!$L$18)/2 -> 16493.498 | M24: =(Thesis!$L$18+Thesis!$M$18)/2 -> 17494.651
A25: 3. AWS AI 損益（收入端不乘 IF_Util：MW-year 計價）
A26: AWS AI 營收（命題子列） | B26: US$bn | C26: =Thesis!$C$9*rpm_open*Thesis!$C$10/1000 -> 2.3210054 | D26: =Thesis!$D$9*rpm_open*Thesis!$D$10/1000 -> 8.7037701 | E26: =Thesis!$E$9*rpm_open*Thesis!$E$10/1000 -> 16.200708 | F26: =(mw_open*rpm_open+Thesis!$F$24*Thesis!$F$23)*Thesis!$F$10/1000 -> 9.732022 | G26: =Thesis!$E$26+Thesis!$F$26 -> 25.93273 | H26: =(mw_open*rpm_open+Thesis!$H$24*Thesis!$H$23)/1000 -> 71.239209 | I26: =(mw_open*rpm_open+Thesis!$I$24*Thesis!$I$23)/1000 -> 124.19956 | J26: =(mw_open*rpm_open+Thesis!$J$24*Thesis!$J$23)/1000 -> 177.44867 | K26: =(mw_open*rpm_open+Thesis!$K$24*Thesis!$K$23)/1000 -> 222.86577 | L26: =(mw_open*rpm_open+Thesis!$L$24*Thesis!$L$23)/1000 -> 252.70652 | M26: =(mw_open*rpm_open+Thesis!$M$24*Thesis!$M$23)/1000 -> 266.92381 | N26: =Thesis!$N$9*rpm_open*Thesis!$N$10/1000 -> 5.5486534 | O26: =Thesis!$O$9*rpm_open*Thesis!$O$10/1000 -> 3.1551167 | P26: 實績欄為分拆估計（期初 k，Derived），不是公司揭露值
A27: 全機隊每 MW 年收入 | B27: US$m/MW-年 | C27: =Thesis!$C$26*1000/(Thesis!$C$9*Thesis!$C$10) -> 9.6708557 | D27: =Thesis!$D$26*1000/(Thesis!$D$9*Thesis!$D$10) -> 9.6708557 | E27: =Thesis!$E$26*1000/(Thesis!$E$9*Thesis!$E$10) -> 9.6708557 | F27: =Thesis!$F$26*1000/(Thesis!$F$9*Thesis!$F$10) -> 11.141889 | G27: =Thesis!$G$26*1000/(Thesis!$G$9*Thesis!$G$10) -> 10.174998 | H27: =Thesis!$H$26*1000/(Thesis!$H$9*Thesis!$H$10) -> 12.225762 | I27: =Thesis!$I$26*1000/(Thesis!$I$9*Thesis!$I$10) -> 12.99162 | J27: =Thesis!$J$26*1000/(Thesis!$J$9*Thesis!$J$10) -> 13.349056 | K27: =Thesis!$K$26*1000/(Thesis!$K$9*Thesis!$K$10) -> 13.523732 | L27: =Thesis!$L$26*1000/(Thesis!$L$9*Thesis!$L$10) -> 13.605758 | M27: =Thesis!$M$26*1000/(Thesis!$M$9*Thesis!$M$10) -> 13.636198 | N27: =Thesis!$N$26*1000/(Thesis!$N$9*Thesis!$N$10) -> 9.6708557 | O27: =Thesis!$O$26*1000/(Thesis!$O$9*Thesis!$O$10) -> 9.6708557
A28: AI 營運成本（含自用 MW、租用機房租金 C22） | B28: US$bn | C28: =Thesis!$C$9/ext_sh*(ox_open+rent_mw)*Thesis!$C$10/1000 -> 0.64256921 | D28: =Thesis!$D$9/ext_sh*(ox_open+rent_mw)*Thesis!$D$10/1000 -> 2.4096345 | E28: =Thesis!$E$9/ext_sh*(ox_open+rent_mw)*Thesis!$E$10/1000 -> 4.4851582 | F28: =((mw_open*ox_open+Thesis!$F$24*Thesis!$F$22)/ext_sh+Thesis!$F$9/ext_sh*rent_mw)*Thesis!$F$10/1000 -> 2.3801764 | G28: =Thesis!$E$28+Thesis!$F$28 -> 6.8653345 | H28: =((mw_open*ox_open+Thesis!$H$24*Thesis!$H$22)/ext_sh+Thesis!$H$9/ext_sh*rent_mw)*Thesis!$H$10/1000 -> 16.128216 | I28: =((mw_open*ox_open+Thesis!$I$24*Thesis!$I$22)/ext_sh+Thesis!$I$9/ext_sh*rent_mw)*Thesis!$I$10/1000 -> 26.786287 | J28: =((mw_open*ox_open+Thesis!$J$24*Thesis!$J$22)/ext_sh+Thesis!$J$9/ext_sh*rent_mw)*Thesis!$J$10/1000 -> 37.464039 | K28: =((mw_open*ox_open+Thesis!$K$24*Thesis!$K$22)/ext_sh+Thesis!$K$9/ext_sh*rent_mw)*Thesis!$K$10/1000 -> 46.576359 | L28: =((mw_open*ox_open+Thesis!$L$24*Thesis!$L$22)/ext_sh+Thesis!$L$9/ext_sh*rent_mw)*Thesis!$L$10/1000 -> 52.563792 | M28: =((mw_open*ox_open+Thesis!$M$24*Thesis!$M$22)/ext_sh+Thesis!$M$9/ext_sh*rent_mw)*Thesis!$M$10/1000 -> 55.423125 | N28: =Thesis!$N$9/ext_sh*(ox_open+rent_mw)*Thesis!$N$10/1000 -> 1.536142 | O28: =Thesis!$O$9/ext_sh*(ox_open+rent_mw)*Thesis!$O$10/1000 -> 0.87349252
A29: AWS 營收（實績，Q 頁） | B29: US$bn | C29: =Q!$D$7 -> 107.556 | D29: =Q!$E$7 -> 128.725 | E29: =Q!$O$7 -> 125.803 | N29: =Q!$N$7 -> 93.146 | O29: =Q!$J$7 -> 35.579
A30: AWS 其他營收（非 AI 雲端） | B30: US$bn | C30: =Thesis!$C$29-Thesis!$C$26 -> 105.23499 | D30: =Thesis!$D$29-Thesis!$D$26 -> 120.02123 | E30: =Thesis!$E$29-Thesis!$E$26 -> 109.60229 | F30: =Thesis!$O$30*(1+Thesis!$F$31) -> 36.97966 | G30: =Thesis!$E$30+Thesis!$F$30 -> 146.58195 | H30: =Thesis!$G$30*(1+Thesis!$H$31) -> 164.96042 | I30: =Thesis!$H$30*(1+Thesis!$I$31) -> 183.14786 | J30: =Thesis!$I$30*(1+Thesis!$J$31) -> 200.57012 | K30: =Thesis!$J$30*(1+Thesis!$K$31) -> 216.61573 | L30: =Thesis!$K$30*(1+Thesis!$L$31) -> 233.94498 | M30: =Thesis!$L$30*(1+Thesis!$M$31) -> 252.66058 | N30: =Thesis!$N$29-Thesis!$N$26 -> 87.597347 | O30: =Thesis!$O$29-Thesis!$O$26 -> 32.423883 | P30: 實績＝AWS 實績 − AWS AI 分拆估計（殘差，Derived）
A31: AWS 其他年增 | B31: % | D31: =Thesis!$D$30/Thesis!$C$30-1 -> 0.14050683 | E31: =Thesis!$E$30/Thesis!$N$30-1 -> 0.25120562 | F31: =IF(awso_g0=1,Thesis!$E$31,Thesis!$D$31) -> 0.14050683 | G31: =Thesis!$G$30/Thesis!$D$30-1 -> 0.2213002 | H31: =Thesis!$F$31+(g_awso_lt-Thesis!$F$31)*1/4 -> 0.12538012 | I31: =Thesis!$F$31+(g_awso_lt-Thesis!$F$31)*2/4 -> 0.11025341 | J31: =Thesis!$F$31+(g_awso_lt-Thesis!$F$31)*3/4 -> 0.095126707 | K31: =Thesis!$F$31+(g_awso_lt-Thesis!$F$31)*4/4 -> 0.08 | L31: =g_awso_lt -> 0.08 | M31: =g_awso_lt -> 0.08 | P31: 起點＝FY2025 年增（D 欄，Derived；In 頁 awso_g0＝0）；9M26 年增（E 欄）受 AI 分拆低估影響偏高，只列不用（awso_g0＝1 時改用，Sens）；收斂到 g_awso_lt
A32: 4. AI 資本支出（現金）→ 折舊（IT 6 年、機房 20 年；次年起提列）
A33: Q4 26 非 AI 資本支出（零售＋AWS 其他） | B33: US$bn | F33: =cx_rt*Seg!$F$20+cx_awso*Thesis!$F$30 -> 19.116381
A34: AI 資本支出中 IT 比例 | B34: % | C34: =tk_cx_h100/(tk_cx_h100+tk_fac*(1-colo_sh)) -> 0.73075646 | D34: =tk_cx_h100/(tk_cx_h100+tk_fac*(1-colo_sh)) -> 0.73075646 | E34: =Thesis!$F$34 -> 0.71912296 | F34: =Thesis!$F$17/(Thesis!$F$17+tk_fac*(1-colo_sh)) -> 0.71912296 | G34: =Thesis!$G$17/(Thesis!$G$17+tk_fac*(1-colo_sh)) -> 0.71912296 | H34: =Thesis!$H$17/(Thesis!$H$17+tk_fac*(1-colo_sh)) -> 0.72915955 | I34: =Thesis!$I$17/(Thesis!$I$17+tk_fac*(1-colo_sh)) -> 0.73850361 | J34: =Thesis!$J$17/(Thesis!$J$17+tk_fac*(1-colo_sh)) -> 0.73850361 | K34: =Thesis!$K$17/(Thesis!$K$17+tk_fac*(1-colo_sh)) -> 0.73850361 | L34: =Thesis!$L$17/(Thesis!$L$17+tk_fac*(1-colo_sh)) -> 0.73850361 | M34: =Thesis!$M$17/(Thesis!$M$17+tk_fac*(1-colo_sh)) -> 0.73850361
A35: AI 資本支出（現金，含自用） | B35: US$bn | C35: =Q!$D$48-cx_rt*Q!$D$16-cx_awso*Thesis!$C$30 -> 25.278105 | D35: =Q!$E$48-cx_rt*Q!$E$16-cx_awso*Thesis!$D$30 -> 69.568632 | E35: =Q!$O$48-cx_rt*Q!$O$16-cx_awso*Thesis!$E$30 -> 123.19605 | F35: =capex_g26-Q!$O$48-Thesis!$F$33 -> 28.695619 | G35: =Thesis!$E$35+Thesis!$F$35 -> 151.89167 | H35: =Thesis!$H$12*(Thesis!$H$17+tk_fac*(1-colo_sh))/1000+Thesis!$H$39 -> 174.63089 | I35: =Thesis!$I$12*(Thesis!$I$17+tk_fac*(1-colo_sh))/1000+Thesis!$I$39 -> 180.87099 | J35: =Thesis!$J$12*(Thesis!$J$17+tk_fac*(1-colo_sh))/1000+Thesis!$J$39 -> 185.16482 | K35: =Thesis!$K$12*(Thesis!$K$17+tk_fac*(1-colo_sh))/1000+Thesis!$K$39 -> 136.51337 | L35: =Thesis!$L$12*(Thesis!$L$17+tk_fac*(1-colo_sh))/1000+Thesis!$L$39 -> 113.6249 | M35: =Thesis!$M$12*(Thesis!$M$17+tk_fac*(1-colo_sh))/1000+Thesis!$M$39 -> 112.22258 | P35: 實績＝公司資本支出淨額 − 非 AI（零售 cx_rt、AWS 其他 cx_awso）；Q4 26＝指引 220 − 9M 實績 − 非 AI（修正三：FY2026 現金資本支出錨定指引；Q4 新增 MW 部分由已投入的在建資本支出支應）；之後＝新增 MW ×（IT＋自建機房）＋汰換 | R35: =Q!$C$48-cx_rt*Q!$C$16-cx_awso*(Q!$C$7-mw_ye23/2*rpm_open/1000) -> 1.5042998 | S35: =Thesis!$C$35 -> 25.278105 | T35: =Thesis!$D$35 -> 69.568632 | U35: =Thesis!$G$35 -> 151.89167 | V35: =Thesis!$H$35 -> 174.63089 | W35: =Thesis!$I$35 -> 180.87099 | X35: =Thesis!$J$35 -> 185.16482 | Y35: =Thesis!$K$35 -> 136.51337 | Z35: =Thesis!$L$35 -> 113.6249 | AA35: =Thesis!$M$35 -> 112.22258
A36: C10：Q4 26 AI 資本支出公式值＝新增總 MW ×（IT＋自建機房） | B36: US$bn | F36: =Thesis!$F$12*(Thesis!$F$17+tk_fac*(1-colo_sh))/1000 -> 42.0977
A37: C10 對帳（下半年視窗）：（指引 − 上半年實績）÷ 2 −（Q4 公式 AI＋Q4 非 AI） | B37: US$bn | F37: =(capex_g26-Q!$P$48)/2-(Thesis!$F$36+Thesis!$F$33) -> 0.6309188 | P37: 情境 B 以 calib_pace_v031.py 解 pace_B 使本列＝0；A／C 情境速度不同，本列不為 0
A38: 對照：Q4 26 指引補足額＝Q4 錨定值 − Q4 公式值（負值＝Q4 公式高於指引隱含） | B38: US$bn | F38: =Thesis!$F$35-Thesis!$F$36 -> -13.402081
A39: IT 汰換（折舊年限前新增的總 MW × 當年 IT 每 MW） | B39: US$bn | H39: =SUMPRODUCT(--(Thesis!$R$5:$AA$5=2027-tk_life),Thesis!$R$12:$AA$12)*Thesis!$H$17/1000 -> 0 | I39: =SUMPRODUCT(--(Thesis!$R$5:$AA$5=2028-tk_life),Thesis!$R$12:$AA$12)*Thesis!$I$17/1000 -> 0 | J39: =SUMPRODUCT(--(Thesis!$R$5:$AA$5=2029-tk_life),Thesis!$R$12:$AA$12)*Thesis!$J$17/1000 -> 4.2938294 | K39: =SUMPRODUCT(--(Thesis!$R$5:$AA$5=2030-tk_life),Thesis!$R$12:$AA$12)*Thesis!$K$17/1000 -> 8.5876588 | L39: =SUMPRODUCT(--(Thesis!$R$5:$AA$5=2031-tk_life),Thesis!$R$12:$AA$12)*Thesis!$L$17/1000 -> 38.644465 | M39: =SUMPRODUCT(--(Thesis!$R$5:$AA$5=2032-tk_life),Thesis!$R$12:$AA$12)*Thesis!$M$17/1000 -> 90.187414
A40: AI 資本支出：折舊基礎（實績期以新增在役 MW × 每 MW 成本為上限） | B40: US$bn | C40: =MIN(Thesis!$C$35,Thesis!$C$12*(tk_cx_h100+tk_fac*(1-colo_sh))/1000) -> 11.293864 | D40: =MIN(Thesis!$D$35,Thesis!$D$12*(tk_cx_h100+tk_fac*(1-colo_sh))/1000) -> 50.822389 | E40: =MIN(Thesis!$E$35,Thesis!$E$12*(Thesis!$F$17+tk_fac*(1-colo_sh))/1000) -> 71.597667 | F40: =Thesis!$F$35 -> 28.695619 | G40: =Thesis!$E$40+Thesis!$F$40 -> 100.29329 | H40: =Thesis!$H$35 -> 174.63089 | I40: =Thesis!$I$35 -> 180.87099 | J40: =Thesis!$J$35 -> 185.16482 | K40: =Thesis!$K$35 -> 136.51337 | L40: =Thesis!$L$35 -> 113.6249 | M40: =Thesis!$M$35 -> 112.22258 | P40: 實績期以新增在役 MW × 每 MW 成本為上限；超出部分見下列在建（修正三：延後轉入在役後提列折舊） | R40: =MIN(Thesis!$R$35,Thesis!$R$12*(tk_cx_h100+tk_fac*(1-colo_sh))/1000) -> 1.5042998 | S40: =Thesis!$C$40 -> 11.293864 | T40: =Thesis!$D$40 -> 50.822389 | U40: =Thesis!$G$40 -> 100.29329 | V40: =Thesis!$H$40 -> 174.63089 | W40: =Thesis!$I$40 -> 180.87099 | X40: =Thesis!$J$40 -> 185.16482 | Y40: =Thesis!$K$40 -> 136.51337 | Z40: =Thesis!$L$40 -> 113.6249 | AA40: =Thesis!$M$40 -> 112.22258
A41: 在建（CIP）：實績期超出新增在役 MW 成本的 AI 資本支出 | B41: US$bn | C41: =Thesis!$C$35-Thesis!$C$40 -> 13.984241 | D41: =Thesis!$D$35-Thesis!$D$40 -> 18.746243 | E41: =Thesis!$E$35-Thesis!$E$40 -> 51.598382 | F41: =Thesis!$F$35-Thesis!$F$40 -> 0 | G41: =Thesis!$G$35-Thesis!$G$40 -> 51.598382 | H41: =Thesis!$H$35-Thesis!$H$40 -> 0 | I41: =Thesis!$I$35-Thesis!$I$40 -> 0 | J41: =Thesis!$J$35-Thesis!$J$40 -> 0 | K41: =Thesis!$K$35-Thesis!$K$40 -> 0 | L41: =Thesis!$L$35-Thesis!$L$40 -> 0 | M41: =Thesis!$M$35-Thesis!$M$40 -> 0 | P41: 修正三：視為在建，延後 cip_lag 年轉入在役後提列折舊（仍計入 AI 投入資本）；AWS 分部折舊 2024→2025→1H26 年化 13.3→21.5→30.7 支持此處理 | R41: =Thesis!$R$35-Thesis!$R$40 -> 0 | S41: =Thesis!$S$35-Thesis!$S$40 -> 13.984241 | T41: =Thesis!$T$35-Thesis!$T$40 -> 18.746243 | U41: =Thesis!$U$35-Thesis!$U$40 -> 51.598382 | V41: =Thesis!$V$35-Thesis!$V$40 -> 0 | W41: =Thesis!$W$35-Thesis!$W$40 -> 0 | X41: =Thesis!$X$35-Thesis!$X$40 -> 0 | Y41: =Thesis!$Y$35-Thesis!$Y$40 -> 0 | Z41: =Thesis!$Z$35-Thesis!$Z$40 -> 0 | AA41: =Thesis!$AA$35-Thesis!$AA$40 -> 0
...

Sheet Seg
A1: Seg — 營收分部層：官方分部 North America、International、AWS；10-K 營收線 Online stores、Physical stores、Third-party seller services、Advertising services、Subscription services、Other（零售各線合計＝北美＋國際）與 AWS。AWS＝AWS AI（命題子列，Thesis）＋AWS 其他。核對列（綠底）每情境每年度皆須為 0
A4: Seg｜情境 A（樂觀）：營收分部層（官方分部 North America、International、AWS；10-K 營收線）
A5: 項目 | B5: 單位 | C5: FY2024A | D5: FY2025A | E5: 9M26A | F5: Q4 26E | G5: FY2026E（9M 實績＋Q4 模型） | H5: FY2027E | I5: FY2028E | J5: FY2029E | K5: FY2030E | L5: FY2031E | M5: FY2032E | N5: 9M25A | O5: Q4 25A | P5: 說明 | R5: 2023 | S5: 2024 | T5: 2025 | U5: 2026 | V5: 2027 | W5: 2028 | X5: 2029 | Y5: 2030 | Z5: 2031 | AA5: 2032
A6: 1. 零售各營收線（Q4 26＝Q4 25 ×（1＋9M26 年增）× 校準係數；2027–2030 年增由 9M26 年增線性收斂到長期值；2031–2032＝長期值）
A7: Online stores | B7: US$bn | C7: =Q!$D$10 -> 247.029 | D7: =Q!$E$10 -> 269.287 | E7: =Q!$O$10 -> 203.156 | F7: =Seg!$O$7*(1+Seg!$F$8)*Seg!$F$19 -> 90.388464 | G7: =Seg!$E$7+Seg!$F$7 -> 293.54446 | H7: =Seg!$G$7*(1+Seg!$H$8) -> 317.13448 | I7: =Seg!$H$7*(1+Seg!$I$8) -> 339.41058 | J7: =Seg!$I$7*(1+Seg!$J$8) -> 359.81625 | K7: =Seg!$J$7*(1+Seg!$K$8) -> 377.80706 | L7: =Seg!$K$7*(1+Seg!$L$8) -> 396.69741 | M7: =Seg!$L$7*(1+Seg!$M$8) -> 416.53228 | N7: =Q!$N$10 -> 186.299 | O7: =Q!$J$10 -> 82.988 | P7: Q 頁實績；預測＝前期 ×（1＋年增）
A8: Online stores 年增 | B8: % | E8: =Seg!$E$7/Seg!$N$7-1 -> 0.090483577 | F8: =Seg!$E$8 -> 0.090483577 | G8: =Seg!$G$7/Seg!$D$7-1 -> 0.090080337 | H8: =Seg!$F$8+(g_os-Seg!$F$8)*1/4 -> 0.080362683 | I8: =Seg!$F$8+(g_os-Seg!$F$8)*2/4 -> 0.070241789 | J8: =Seg!$F$8+(g_os-Seg!$F$8)*3/4 -> 0.060120894 | K8: =Seg!$F$8+(g_os-Seg!$F$8)*4/4 -> 0.05 | L8: =g_os -> 0.05 | M8: =g_os -> 0.05 | P8: E＝9M26 對 9M25（Prime Day 移入 Q2 的時點影響在九個月內抵銷）；F＝Q4 26 成長基準＝E（Derived）；收斂到 In 頁 g_os
A9: Physical stores | B9: US$bn | C9: =Q!$D$11 -> 21.215 | D9: =Q!$E$11 -> 22.561 | E9: =Q!$O$11 -> 17.289 | F9: =Seg!$O$9*(1+Seg!$F$10)*Seg!$F$19 -> 6.0520551 | G9: =Seg!$E$9+Seg!$F$9 -> 23.341055 | H9: =Seg!$G$9*(1+Seg!$H$10) -> 24.127024 | I9: =Seg!$H$9*(1+Seg!$I$10) -> 24.909917 | J9: =Seg!$I$9*(1+Seg!$J$10) -> 25.687715 | K9: =Seg!$J$9*(1+Seg!$K$10) -> 26.458346 | L9: =Seg!$K$9*(1+Seg!$L$10) -> 27.252097 | M9: =Seg!$L$9*(1+Seg!$M$10) -> 28.06966 | N9: =Q!$N$11 -> 16.706 | O9: =Q!$J$11 -> 5.855 | P9: Q 頁實績；預測＝前期 ×（1＋年增）
A10: Physical stores 年增 | B10: % | E10: =Seg!$E$9/Seg!$N$9-1 -> 0.034897642 | F10: =Seg!$E$10 -> 0.034897642 | G10: =Seg!$G$9/Seg!$D$9-1 -> 0.034575378 | H10: =Seg!$F$10+(g_ps-Seg!$F$10)*1/4 -> 0.033673231 | I10: =Seg!$F$10+(g_ps-Seg!$F$10)*2/4 -> 0.032448821 | J10: =Seg!$F$10+(g_ps-Seg!$F$10)*3/4 -> 0.03122441 | K10: =Seg!$F$10+(g_ps-Seg!$F$10)*4/4 -> 0.03 | L10: =g_ps -> 0.03 | M10: =g_ps -> 0.03 | P10: E＝9M26 對 9M25（Prime Day 移入 Q2 的時點影響在九個月內抵銷）；F＝Q4 26 成長基準＝E（Derived）；收斂到 In 頁 g_ps
A11: Third-party seller services | B11: US$bn | C11: =Q!$D$12 -> 156.146 | D11: =Q!$E$12 -> 172.162 | E11: =Q!$O$12 -> 134.85 | F11: =Seg!$O$11*(1+Seg!$F$12)*Seg!$F$19 -> 59.605614 | G11: =Seg!$E$11+Seg!$F$11 -> 194.45561 | H11: =Seg!$G$11*(1+Seg!$H$12) -> 216.80459 | I11: =Seg!$H$11*(1+Seg!$I$12) -> 238.47508 | J11: =Seg!$I$11*(1+Seg!$J$12) -> 258.73997 | K11: =Seg!$J$11*(1+Seg!$K$12) -> 276.85177 | L11: =Seg!$K$11*(1+Seg!$L$12) -> 296.2314 | M11: =Seg!$L$11*(1+Seg!$M$12) -> 316.9676 | N11: =Q!$N$12 -> 119.346 | O11: =Q!$J$12 -> 52.816 | P11: Q 頁實績；預測＝前期 ×（1＋年增）
A12: Third-party seller services 年增 | B12: % | E12: =Seg!$E$11/Seg!$N$11-1 -> 0.129908 | F12: =Seg!$E$12 -> 0.129908 | G12: =Seg!$G$11/Seg!$D$11-1 -> 0.12949207 | H12: =Seg!$F$12+(g_sp-Seg!$F$12)*1/4 -> 0.114931 | I12: =Seg!$F$12+(g_sp-Seg!$F$12)*2/4 -> 0.099953999 | J12: =Seg!$F$12+(g_sp-Seg!$F$12)*3/4 -> 0.084977 | K12: =Seg!$F$12+(g_sp-Seg!$F$12)*4/4 -> 0.07 | L12: =g_sp -> 0.07 | M12: =g_sp -> 0.07 | P12: E＝9M26 對 9M25（Prime Day 移入 Q2 的時點影響在九個月內抵銷）；F＝Q4 26 成長基準＝E（Derived）；收斂到 In 頁 g_sp
A13: Advertising services | B13: US$bn | C13: =Q!$D$13 -> 56.214 | D13: =Q!$E$13 -> 68.635 | E13: =Q!$O$13 -> 56.689 | F13: =Seg!$O$13*(1+Seg!$F$14)*Seg!$F$19 -> 25.508039 | G13: =Seg!$E$13+Seg!$F$13 -> 82.197039 | H13: =Seg!$G$13*(1+Seg!$H$14) -> 96.460878 | I13: =Seg!$H$13*(1+Seg!$I$14) -> 110.83562 | J13: =Seg!$I$13*(1+Seg!$J$14) -> 124.63585 | K13: =Seg!$J$13*(1+Seg!$K$14) -> 137.09944 | L13: =Seg!$K$13*(1+Seg!$L$14) -> 150.80938 | M13: =Seg!$L$13*(1+Seg!$M$14) -> 165.89032 | N13: =Q!$N$13 -> 47.318 | O13: =Q!$J$13 -> 21.317 | P13: Q 頁實績；預測＝前期 ×（1＋年增）
A14: Advertising services 年增 | B14: % | E14: =Seg!$E$13/Seg!$N$13-1 -> 0.19804303 | F14: =Seg!$E$14 -> 0.19804303 | G14: =Seg!$G$13/Seg!$D$13-1 -> 0.19759655 | H14: =Seg!$F$14+(g_ad-Seg!$F$14)*1/4 -> 0.17353227 | I14: =Seg!$F$14+(g_ad-Seg!$F$14)*2/4 -> 0.14902151 | J14: =Seg!$F$14+(g_ad-Seg!$F$14)*3/4 -> 0.12451076 | K14: =Seg!$F$14+(g_ad-Seg!$F$14)*4/4 -> 0.1 | L14: =g_ad -> 0.1 | M14: =g_ad -> 0.1 | P14: E＝9M26 對 9M25（Prime Day 移入 Q2 的時點影響在九個月內抵銷）；F＝Q4 26 成長基準＝E（Derived）；收斂到 In 頁 g_ad
A15: Subscription services | B15: US$bn | C15: =Q!$D$14 -> 44.374 | D15: =Q!$E$14 -> 49.619 | E15: =Q!$O$14 -> 41.163 | F15: =Seg!$O$15*(1+Seg!$F$16)*Seg!$F$19 -> 14.781839 | G15: =Seg!$E$15+Seg!$F$15 -> 55.944839 | H15: =Seg!$G$15*(1+Seg!$H$16) -> 62.288122 | I15: =Seg!$H$15*(1+Seg!$I$16) -> 68.449853 | J15: =Seg!$I$15*(1+Seg!$J$16) -> 74.231233 | K15: =Seg!$J$15*(1+Seg!$K$16) -> 79.427419 | L15: =Seg!$K$15*(1+Seg!$L$16) -> 84.987338 | M15: =Seg!$L$15*(1+Seg!$M$16) -> 90.936452 | N15: =Q!$N$14 -> 36.497 | O15: =Q!$J$14 -> 13.122 | P15: Q 頁實績；預測＝前期 ×（1＋年增）
A16: Subscription services 年增 | B16: % | E16: =Seg!$E$15/Seg!$N$15-1 -> 0.12784612 | F16: =Seg!$E$16 -> 0.12784612 | G16: =Seg!$G$15/Seg!$D$15-1 -> 0.12748824 | H16: =Seg!$F$16+(g_sub-Seg!$F$16)*1/4 -> 0.11338459 | I16: =Seg!$F$16+(g_sub-Seg!$F$16)*2/4 -> 0.098923062 | J16: =Seg!$F$16+(g_sub-Seg!$F$16)*3/4 -> 0.084461531 | K16: =Seg!$F$16+(g_sub-Seg!$F$16)*4/4 -> 0.07 | L16: =g_sub -> 0.07 | M16: =g_sub -> 0.07 | P16: E＝9M26 對 9M25（Prime Day 移入 Q2 的時點影響在九個月內抵銷）；F＝Q4 26 成長基準＝E（Derived）；收斂到 In 頁 g_sub
A17: Other | B17: US$bn | C17: =Q!$D$15 -> 5.425 | D17: =Q!$E$15 -> 5.935 | E17: =Q!$O$15 -> 5.119 | F17: =Seg!$O$17*(1+Seg!$F$18)*Seg!$F$19 -> 2.0676464 | G17: =Seg!$E$17+Seg!$F$17 -> 7.1866464 | H17: =Seg!$G$17*(1+Seg!$H$18) -> 8.4154422 | I17: =Seg!$H$17*(1+Seg!$I$18) -> 9.5149658 | J17: =Seg!$I$17*(1+Seg!$J$18) -> 10.374431 | K17: =Seg!$J$17*(1+Seg!$K$18) -> 10.893153 | L17: =Seg!$K$17*(1+Seg!$L$18) -> 11.43781 | M17: =Seg!$L$17*(1+Seg!$M$18) -> 12.009701 | N17: =Q!$N$15 -> 4.226 | O17: =Q!$J$15 -> 1.709 | P17: Q 頁實績；預測＝前期 ×（1＋年增）
A18: Other 年增 | B18: % | E18: =Seg!$E$17/Seg!$N$17-1 -> 0.21131093 | F18: =Seg!$E$18 -> 0.21131093 | G18: =Seg!$G$17/Seg!$D$17-1 -> 0.21089241 | H18: =Seg!$F$18+(g_ot-Seg!$F$18)*1/4 -> 0.1709832 | I18: =Seg!$F$18+(g_ot-Seg!$F$18)*2/4 -> 0.13065547 | J18: =Seg!$F$18+(g_ot-Seg!$F$18)*3/4 -> 0.090327733 | K18: =Seg!$F$18+(g_ot-Seg!$F$18)*4/4 -> 0.05 | L18: =g_ot -> 0.05 | M18: =g_ot -> 0.05 | P18: E＝9M26 對 9M25（Prime Day 移入 Q2 的時點影響在九個月內抵銷）；F＝Q4 26 成長基準＝E（Derived）；收斂到 In 頁 g_ot
A19: Q4 26 零售營收校準係數（使情境 B 的 Q4 26 合併營收＝指引中點） | B19: x | F19: =(g26q4_mid-Thesis!$F$92-Thesis!$F$96)/(Seg!$O$7*(1+Seg!$F$8)+Seg!$O$9*(1+Seg!$F$10)+Seg!$O$11*(1+Seg!$F$12)+Seg!$O$13*(1+Seg!$F$14)+Seg!$O$15*(1+Seg!$F$16)+Seg!$O$17*(1+Seg!$F$18)) -> 0.9988001 | P19: Q4 26 合併營收目標＝指引中點 243.5 − 主頁情境 B 的 AWS Q4 26；三情境共用同一係數（修正二），零售不隨 AI 分拆變動
A20: 零售營收線合計（＝North America＋International） | B20: US$bn | C20: =Seg!$C$7+Seg!$C$9+Seg!$C$11+Seg!$C$13+Seg!$C$15+Seg!$C$17 -> 530.403 | D20: =Seg!$D$7+Seg!$D$9+Seg!$D$11+Seg!$D$13+Seg!$D$15+Seg!$D$17 -> 588.199 | E20: =Seg!$E$7+Seg!$E$9+Seg!$E$11+Seg!$E$13+Seg!$E$15+Seg!$E$17 -> 458.266 | F20: =Seg!$F$7+Seg!$F$9+Seg!$F$11+Seg!$F$13+Seg!$F$15+Seg!$F$17 -> 198.40366 | G20: =Seg!$G$7+Seg!$G$9+Seg!$G$11+Seg!$G$13+Seg!$G$15+Seg!$G$17 -> 656.66966 | H20: =Seg!$H$7+Seg!$H$9+Seg!$H$11+Seg!$H$13+Seg!$H$15+Seg!$H$17 -> 725.23054 | I20: =Seg!$I$7+Seg!$I$9+Seg!$I$11+Seg!$I$13+Seg!$I$15+Seg!$I$17 -> 791.59602 | J20: =Seg!$J$7+Seg!$J$9+Seg!$J$11+Seg!$J$13+Seg!$J$15+Seg!$J$17 -> 853.48545 | K20: =Seg!$K$7+Seg!$K$9+Seg!$K$11+Seg!$K$13+Seg!$K$15+Seg!$K$17 -> 908.53719 | L20: =Seg!$L$7+Seg!$L$9+Seg!$L$11+Seg!$L$13+Seg!$L$15+Seg!$L$17 -> 967.41543 | M20: =Seg!$M$7+Seg!$M$9+Seg!$M$11+Seg!$M$13+Seg!$M$15+Seg!$M$17 -> 1030.406 | N20: =Seg!$N$7+Seg!$N$9+Seg!$N$11+Seg!$N$13+Seg!$N$15+Seg!$N$17 -> 410.392 | O20: =Seg!$O$7+Seg!$O$9+Seg!$O$11+Seg!$O$13+Seg!$O$15+Seg!$O$17 -> 177.807
A21: 北美占零售營收比例（地區分攤） | B21: % | C21: =Q!$D$5/(Q!$D$5+Q!$D$6) -> 0.73057091 | D21: =Q!$E$5/(Q!$E$5+Q!$E$6) -> 0.72476322 | E21: =Q!$O$5/(Q!$O$5+Q!$O$6) -> 0.72702753 | F21: =Seg!$O$21 -> 0.71472439 | G21: =Seg!$G$22/Seg!$G$20 -> 0.72331031 | H21: =Seg!$G$21 -> 0.72331031 | I21: =Seg!$G$21 -> 0.72331031 | J21: =Seg!$G$21 -> 0.72331031 | K21: =Seg!$G$21 -> 0.72331031 | L21: =Seg!$G$21 -> 0.72331031 | M21: =Seg!$G$21 -> 0.72331031 | N21: =Q!$N$5/(Q!$N$5+Q!$N$6) -> 0.72911265 | O21: =Q!$J$5/(Q!$J$5+Q!$J$6) -> 0.71472439 | P21: Q4 26＝Q4 25 比例；2027 起固定為 FY2026（Derived）；各營收線不分地區揭露，故以本列分攤
A22: North America | B22: US$bn | C22: =Q!$D$5 -> 387.497 | D22: =Q!$E$5 -> 426.305 | E22: =Q!$O$5 -> 333.172 | F22: =Seg!$F$20*Seg!$F$21 -> 141.80393 | G22: =Seg!$E$22+Seg!$F$22 -> 474.97593 | H22: =Seg!$H$20*Seg!$H$21 -> 524.56673 | I22: =Seg!$I$20*Seg!$I$21 -> 572.56956 | J22: =Seg!$J$20*Seg!$J$21 -> 617.33483 | K22: =Seg!$K$20*Seg!$K$21 -> 657.15431 | L22: =Seg!$L$20*Seg!$L$21 -> 699.74156 | M22: =Seg!$M$20*Seg!$M$21 -> 745.30329 | N22: =Q!$N$5 -> 299.222 | O22: =Q!$J$5 -> 127.083 | P22: 官方分部；預測＝零售營收線合計 × 北美比例
A23: International | B23: US$bn | C23: =Q!$D$6 -> 142.906 | D23: =Q!$E$6 -> 161.894 | E23: =Q!$O$6 -> 125.094 | F23: =Seg!$F$20*(1-Seg!$F$21) -> 56.599724 | G23: =Seg!$E$23+Seg!$F$23 -> 181.69372 | H23: =Seg!$H$20*(1-Seg!$H$21) -> 200.66381 | I23: =Seg!$I$20*(1-Seg!$I$21) -> 219.02646 | J23: =Seg!$J$20*(1-Seg!$J$21) -> 236.15062 | K23: =Seg!$K$20*(1-Seg!$K$21) -> 251.38287 | L23: =Seg!$L$20*(1-Seg!$L$21) -> 267.67388 | M23: =Seg!$M$20*(1-Seg!$M$21) -> 285.10272 | N23: =Q!$N$6 -> 111.17 | O23: =Q!$J$6 -> 50.724 | P23: 官方分部；預測＝零售營收線合計 ×（1 − 北美比例）
A24: 廣告營收歸北美（＝廣告 × 北美比例） | B24: US$bn | C24: =Seg!$C$13*Seg!$C$21 -> 41.068313 | D24: =Seg!$D$13*Seg!$D$21 -> 49.744123 | E24: =Seg!$E$13*Seg!$E$21 -> 41.214464 | F24: =Seg!$F$13*Seg!$F$21 -> 18.231218 | G24: =Seg!$G$13*Seg!$G$21 -> 59.453966 | H24: =Seg!$H$13*Seg!$H$21 -> 69.771148 | I24: =Seg!$I$13*Seg!$I$21 -> 80.16855 | J24: =Seg!$J$13*Seg!$J$21 -> 90.150397 | K24: =Seg!$K$13*Seg!$K$21 -> 99.165436 | L24: =Seg!$L$13*Seg!$L$21 -> 109.08198 | M24: =Seg!$M$13*Seg!$M$21 -> 119.99018 | N24: =Seg!$N$13*Seg!$N$21 -> 34.500153 | O24: =Seg!$O$13*Seg!$O$21 -> 15.23578 | P24: 廣告營收依零售營收的地區比例分攤（Assumed；公司未分地區揭露）
A25: 廣告營收歸國際 | B25: US$bn | C25: =Seg!$C$13-Seg!$C$24 -> 15.145687 | D25: =Seg!$D$13-Seg!$D$24 -> 18.890877 | E25: =Seg!$E$13-Seg!$E$24 -> 15.474536 | F25: =Seg!$F$13-Seg!$F$24 -> 7.2768214 | G25: =Seg!$G$13-Seg!$G$24 -> 22.743073 | H25: =Seg!$H$13-Seg!$H$24 -> 26.689731 | I25: =Seg!$I$13-Seg!$I$24 -> 30.667075 | J25: =Seg!$J$13-Seg!$J$24 -> 34.485455 | K25: =Seg!$K$13-Seg!$K$24 -> 37.934001 | L25: =Seg!$L$13-Seg!$L$24 -> 41.727401 | M25: =Seg!$M$13-Seg!$M$24 -> 45.900141 | N25: =Seg!$N$13-Seg!$N$24 -> 12.817847 | O25: =Seg!$O$13-Seg!$O$24 -> 6.0812201
A26: 2. AWS（命題子列＋AWS 其他）與合併營收
A27: AWS AI（命題子列） | B27: US$bn | C27: =Thesis!$C$26 -> 2.3210054 | D27: =Thesis!$D$26 -> 8.7037701 | E27: =Thesis!$E$26 -> 16.200708 | F27: =Thesis!$F$26 -> 9.732022 | G27: =Thesis!$G$26 -> 25.93273 | H27: =Thesis!$H$26 -> 71.239209 | I27: =Thesis!$I$26 -> 124.19956 | J27: =Thesis!$J$26 -> 177.44867 | K27: =Thesis!$K$26 -> 222.86577 | L27: =Thesis!$L$26 -> 252.70652 | M27: =Thesis!$M$26 -> 266.92381 | N27: =Thesis!$N$26 -> 5.5486534 | O27: =Thesis!$O$26 -> 3.1551167 | P27: Thesis 頁
A28: AWS 其他 | B28: US$bn | C28: =Thesis!$C$30 -> 105.23499 | D28: =Thesis!$D$30 -> 120.02123 | E28: =Thesis!$E$30 -> 109.60229 | F28: =Thesis!$F$30 -> 36.97966 | G28: =Thesis!$G$30 -> 146.58195 | H28: =Thesis!$H$30 -> 164.96042 | I28: =Thesis!$I$30 -> 183.14786 | J28: =Thesis!$J$30 -> 200.57012 | K28: =Thesis!$K$30 -> 216.61573 | L28: =Thesis!$L$30 -> 233.94498 | M28: =Thesis!$M$30 -> 252.66058 | N28: =Thesis!$N$30 -> 87.597347 | O28: =Thesis!$O$30 -> 32.423883 | P28: Thesis 頁
A29: AWS | B29: US$bn | C29: =Q!$D$7 -> 107.556 | D29: =Q!$E$7 -> 128.725 | E29: =Q!$O$7 -> 125.803 | F29: =Seg!$F$27+Seg!$F$28 -> 46.711682 | G29: =Seg!$G$27+Seg!$G$28 -> 172.51468 | H29: =Seg!$H$27+Seg!$H$28 -> 236.19962 | I29: =Seg!$I$27+Seg!$I$28 -> 307.34743 | J29: =Seg!$J$27+Seg!$J$28 -> 378.01879 | K29: =Seg!$K$27+Seg!$K$28 -> 439.4815 | L29: =Seg!$L$27+Seg!$L$28 -> 486.65151 | M29: =Seg!$M$27+Seg!$M$28 -> 519.5844 | N29: =Q!$N$7 -> 93.146 | O29: =Q!$J$7 -> 35.579 | P29: 官方分部＝AWS 營收線
A30: 合併營收（實績＝公司揭露；預測＝營收線加總） | B30: US$bn | C30: =Q!$D$8 -> 637.959 | D30: =Q!$E$8 -> 716.924 | E30: =Q!$O$8 -> 584.069 | F30: =Seg!$F$20+Seg!$F$29 -> 245.11534 | G30: =Seg!$G$20+Seg!$G$29 -> 829.18434 | H30: =Seg!$H$20+Seg!$H$29 -> 961.43017 | I30: =Seg!$I$20+Seg!$I$29 -> 1098.9434 | J30: =Seg!$J$20+Seg!$J$29 -> 1231.5042 | K30: =Seg!$K$20+Seg!$K$29 -> 1348.0187 | L30: =Seg!$L$20+Seg!$L$29 -> 1454.0669 | M30: =Seg!$M$20+Seg!$M$29 -> 1549.9904 | N30: =Q!$N$8 -> 503.538 | O30: =Q!$J$8 -> 213.386
A31: 檢查（情境 A）：零售營收線合計 − (North America＋International) | B31: US$bn | C31: =Seg!$C$20-(Seg!$C$22+Seg!$C$23) -> 0 | D31: =Seg!$D$20-(Seg!$D$22+Seg!$D$23) -> 0 | E31: =Seg!$E$20-(Seg!$E$22+Seg!$E$23) -> 0 | F31: =Seg!$F$20-(Seg!$F$22+Seg!$F$23) -> 0 | G31: =Seg!$G$20-(Seg!$G$22+Seg!$G$23) -> 0 | H31: =Seg!$H$20-(Seg!$H$22+Seg!$H$23) -> 0 | I31: =Seg!$I$20-(Seg!$I$22+Seg!$I$23) -> 0 | J31: =Seg!$J$20-(Seg!$J$22+Seg!$J$23) -> 0 | K31: =Seg!$K$20-(Seg!$K$22+Seg!$K$23) -> 0 | L31: =Seg!$L$20-(Seg!$L$22+Seg!$L$23) -> 0 | M31: =Seg!$M$20-(Seg!$M$22+Seg!$M$23) -> 0 | N31: =Seg!$N$20-(Seg!$N$22+Seg!$N$23) -> 0 | O31: =Seg!$O$20-(Seg!$O$22+Seg!$O$23) -> 0
A32: 檢查（情境 A）：AWS AI＋AWS 其他 − AWS | B32: US$bn | C32: =Seg!$C$27+Seg!$C$28-Seg!$C$29 -> 0 | D32: =Seg!$D$27+Seg!$D$28-Seg!$D$29 -> 0 | E32: =Seg!$E$27+Seg!$E$28-Seg!$E$29 -> 0 | F32: =Seg!$F$27+Seg!$F$28-Seg!$F$29 -> 0 | G32: =Seg!$G$27+Seg!$G$28-Seg!$G$29 -> 0 | H32: =Seg!$H$27+Seg!$H$28-Seg!$H$29 -> 0 | I32: =Seg!$I$27+Seg!$I$28-Seg!$I$29 -> 0 | J32: =Seg!$J$27+Seg!$J$28-Seg!$J$29 -> 0 | K32: =Seg!$K$27+Seg!$K$28-Seg!$K$29 -> 0 | L32: =Seg!$L$27+Seg!$L$28-Seg!$L$29 -> 0 | M32: =Seg!$M$27+Seg!$M$28-Seg!$M$29 -> 0 | N32: =Seg!$N$27+Seg!$N$28-Seg!$N$29 -> 0 | O32: =Seg!$O$27+Seg!$O$28-Seg!$O$29 -> 0
A33: 檢查（情境 A）：分部合計 − 合併營收 | B33: US$bn | C33: =Seg!$C$22+Seg!$C$23+Seg!$C$29-Seg!$C$30 -> 0 | D33: =Seg!$D$22+Seg!$D$23+Seg!$D$29-Seg!$D$30 -> 0 | E33: =Seg!$E$22+Seg!$E$23+Seg!$E$29-Seg!$E$30 -> 0 | F33: =Seg!$F$22+Seg!$F$23+Seg!$F$29-Seg!$F$30 -> 0 | G33: =Seg!$G$22+Seg!$G$23+Seg!$G$29-Seg!$G$30 -> 0 | H33: =Seg!$H$22+Seg!$H$23+Seg!$H$29-Seg!$H$30 -> 0 | I33: =Seg!$I$22+Seg!$I$23+Seg!$I$29-Seg!$I$30 -> 0 | J33: =Seg!$J$22+Seg!$J$23+Seg!$J$29-Seg!$J$30 -> 0 | K33: =Seg!$K$22+Seg!$K$23+Seg!$K$29-Seg!$K$30 -> 0 | L33: =Seg!$L$22+Seg!$L$23+Seg!$L$29-Seg!$L$30 -> 0 | M33: =Seg!$M$22+Seg!$M$23+Seg!$M$29-Seg!$M$30 -> 0 | N33: =Seg!$N$22+Seg!$N$23+Seg!$N$29-Seg!$N$30 -> 0 | O33: =Seg!$O$22+Seg!$O$23+Seg!$O$29-Seg!$O$30 -> 0
A34: 合併營收年增 | B34: % | G34: =Seg!$G$30/Seg!$D$30-1 -> 0.15658611 | H34: =Seg!$H$30/Seg!$G$30-1 -> 0.15948906 | I34: =Seg!$I$30/Seg!$H$30-1 -> 0.14302992 | J34: =Seg!$J$30/Seg!$I$30-1 -> 0.12062567 | K34: =Seg!$K$30/Seg!$J$30-1 -> 0.094611484 | L34: =Seg!$L$30/Seg!$K$30-1 -> 0.078669725 | M34: =Seg!$M$30/Seg!$L$30-1 -> 0.065969085
A35: AWS 占合併營收 | B35: % | C35: =Seg!$C$29/Seg!$C$30 -> 0.16859391 | D35: =Seg!$D$29/Seg!$D$30 -> 0.17955181 | E35: =Seg!$E$29/Seg!$E$30 -> 0.21539065 | F35: =Seg!$F$29/Seg!$F$30 -> 0.19057021 | G35: =Seg!$G$29/Seg!$G$30 -> 0.20805347 | H35: =Seg!$H$29/Seg!$H$30 -> 0.24567528 | I35: =Seg!$I$29/Seg!$I$30 -> 0.27967538 | J35: =Seg!$J$29/Seg!$J$30 -> 0.30695695 | K35: =Seg!$K$29/Seg!$K$30 -> 0.32602033 | L35: =Seg!$L$29/Seg!$L$30 -> 0.33468301 | M35: =Seg!$M$29/Seg!$M$30 -> 0.33521782 | N35: =Seg!$N$29/Seg!$N$30 -> 0.18498306 | O35: =Seg!$O$29/Seg!$O$30 -> 0.1667354
A36: AWS AI 占 AWS | B36: % | C36: =Seg!$C$27/Seg!$C$29 -> 0.021579506 | D36: =Seg!$D$27/Seg!$D$29 -> 0.067615227 | E36: =Seg!$E$27/Seg!$E$29 -> 0.12877839 | F36: =Seg!$F$27/Seg!$F$29 -> 0.20834236 | G36: =Seg!$G$27/Seg!$G$29 -> 0.15032187 | H36: =Seg!$H$27/Seg!$H$29 -> 0.30160594 | I36: =Seg!$I$27/Seg!$I$29 -> 0.40410152 | J36: =Seg!$J$27/Seg!$J$29 -> 0.46941759 | K36: =Seg!$K$27/Seg!$K$29 -> 0.5071107 | L36: =Seg!$L$27/Seg!$L$29 -> 0.51927615 | M36: =Seg!$M$27/Seg!$M$29 -> 0.51372561 | N36: =Seg!$N$27/Seg!$N$29 -> 0.059569423 | O36: =Seg!$O$27/Seg!$O$29 -> 0.088679183
A39: Seg｜情境 B（基準）：營收分部層（官方分部 North America、International、AWS；10-K 營收線）
A40: 項目 | B40: 單位 | C40: FY2024A | D40: FY2025A | E40: 9M26A | F40: Q4 26E | G40: FY2026E（9M 實績＋Q4 模型） | H40: FY2027E | I40: FY2028E | J40: FY2029E | K40: FY2030E | L40: FY2031E | M40: FY2032E | N40: 9M25A | O40: Q4 25A | P40: 說明 | R40: 2023 | S40: 2024 | T40: 2025 | U40: 2026 | V40: 2027 | W40: 2028 | X40: 2029 | Y40: 2030 | Z40: 2031 | AA40: 2032
A41: 1. 零售各營收線（Q4 26＝Q4 25 ×（1＋9M26 年增）× 校準係數；2027–2030 年增由 9M26 年增線性收斂到長期值；2031–2032＝長期值）
A42: Online stores | B42: US$bn | C42: =Q!$D$10 -> 247.029 | D42: =Q!$E$10 -> 269.287 | E42: =Q!$O$10 -> 203.156 | F42: =Seg!$O$42*(1+Seg!$F$43)*Seg!$F$54 -> 90.388464 | G42: =Seg!$E$42+Seg!$F$42 -> 293.54446 | H42: =Seg!$G$42*(1+Seg!$H$43) -> 317.13448 | I42: =Seg!$H$42*(1+Seg!$I$43) -> 339.41058 | J42: =Seg!$I$42*(1+Seg!$J$43) -> 359.81625 | K42: =Seg!$J$42*(1+Seg!$K$43) -> 377.80706 | L42: =Seg!$K$42*(1+Seg!$L$43) -> 396.69741 | M42: =Seg!$L$42*(1+Seg!$M$43) -> 416.53228 | N42: =Q!$N$10 -> 186.299 | O42: =Q!$J$10 -> 82.988 | P42: Q 頁實績；預測＝前期 ×（1＋年增）
