Workbook

Sheet README
A1: Dell Technologies（DELL US）收支與估值模型 v0.1.1（AI 半導體 Project：AI 伺服器品牌，樣板＝wiwynn/） 2026-10-25
A2: 版本：v0.1（初版）。Dell 是企業與 neocloud 的 AI 伺服器品牌（ISG：AI 伺服器、傳統伺服器與網通、儲存）兼 PC 大廠（CSG）。AI 伺服器以加速器顆數 × 每顆系統價值 × Dell 份額推；傳統伺服器、儲存、PC 另列，不隨 AI 情境。
A3: 模型命題：Dell 的 AI 伺服器營收＝商用 GPU 顆數（NVIDIA、AMD；tsmc 成品，同字母情境係數）× 每顆系統價值（橋接表機架價 ÷ 72）× Dell 有效份額（FY2027 以公司 AI 營收指引 740 億美元校準）× 份額相對值；營業利益＝AI 營益率（FY2027 殘差校準）× AI 營收＋非 AI ISG 與 CSG 營益率 × 營收。
A4: 核心問題：FY2027 指引 EPS 25.50 美元已比年初指引高一倍；在手訂單 950 億美元能否在 FY2028 轉成 AI 營收再成長、同時守住約 10% 的 AI 營益率？現價約 16 倍前瞻 P/E，高於 OEM 同業約 11 倍，隱含什麼路徑？
A5: ="重點觀察 1：目標價 US$"&TEXT(Val!$B$39,"0.00")&"（DCF "&TEXT(Val!$B$24,"0.00")&"、Comparable（相對倍數調整後）"&TEXT(tp_comp_adj,"0.00")&"；DCF 權重 "&TEXT(tp_w_dcf,"0%")&"），比現價 "&TEXT(px,"0.00")&"（2026-10-23）"&IF(Val!$B$42>=0,"高 "&TEXT(Val!$B$42,"0.0%"),"低 "&TEXT(-Val!$B$42,"0.0%"))&"，級距 "&Val!$B$48&"、投資建議 "&Val!$B$49&"。相對倍數調整係數 "&TEXT(rm_factor,"0.00")&"（本公司 10 年前瞻倍數中位數 ÷ 同業的中位數，夾在 0.5–2.0；Val 第 0.5 節），調整前加權上檔空間 "&TEXT((tp_w_dcf*Val!$B$24+(1-tp_w_dcf)*Val!$B$35)/px-1,"+0.0%;−0.0%")&"；Comparable 單獨（市場主流同業法、未調整）為 "&TEXT(Val!$B$43,"+0.0%;−0.0%")&"。"&"以下為 2026-10-29 相對倍數調整前撰寫的說明，其中數字為調整前：主因是倍數不是 EPS：本模型 12 個月後前瞻 EPS 28.54 只比共識前瞻 EPS 28.14 高 1.4%，但同業（HPE、Supermicro、Lenovo、HP Inc.、NetApp）前瞻 P/E 中位數 11.3 倍，現價隱含 16.2 倍、共識目標價 593 隱含 21.1 倍（比同業高 87%）；市場給"&" Dell 的 AI 份額溢價，Comparable 未計入。" -> 重點觀察 1：目標價 US$334.49（DCF 424.95、Comparable（相對倍數調整後）244.04；DCF 權重 50%），比現價 456.44（2026-10-23）低 26.7%，級距 −25%～−50%、投資建議 放空。相對倍數調整係數 0.74（本公司 10 年前瞻倍數中位數 ÷ 同業的中位數，夾在 0.5–2.0；Val 第 0.5 節），調整前加權上檔空間 −17.2%；Comparable 單獨（市場主流同業法、未調整）為 −27.4%。以下為 2026-10-29 相對倍數調整前撰寫的說明，其中數字為調整前：主因是倍數不是 EPS：本模型 12 個月後前瞻 EPS 28.54 只比共識前瞻 EPS 28.14 高 1.4%，但同業（HPE、Supermicro、Lenovo、HP Inc.、NetApp）前瞻 P/E 中位數 11.3 倍，現價隱含 16.2 倍、共識目標價 593 隱含 21.1 倍（比同業高 87%）；市場給 Dell 的 AI 份額溢價，Comparable 未計入。
A6: 重點觀察 2：FY2028 EPS 30.20（三情境相同）比共識 29.93 高 0.9%，前提是 AI 伺服器營收由 FY2027 指引 740 億美元升到 1,221 億美元（+65%；份額相對值 0.90 為 Assumed），2Q FY27 在手訂單 950 億美元可支撐約八成。追蹤 3Q FY27 財報（約 2026-11 下旬）的 AI 訂單、在手訂單與出貨。
A7: 重點觀察 3：AI 伺服器營益率是最大的不確定：公司不揭露，本模型以非 AI ISG 營益率 16% 拆分得 FY2027 約 11.1%（FY2026 約 5.4%）；拆分改用 19% 時 FY2028 EPS −11%，AI 營益率 −3pt 時 −10%。3Q FY27 的 ISG 營益率（2Q 為 15.0%）是第一個檢驗點。
A8: 會計年度：FY(t)＝t−1 年 2 月～t 年 1 月底，FY(t) 直接取 CY(t−1)（FY2027≈CY2026、FY2030≈CY2029）。金額：十億美元。口徑：non-GAAP（公司指引、共識、同業倍數一致）；GAAP EPS 只在 Q 頁對照。
A10: 驅動因子 → 推導量（全部唯讀上游，不修改）
A11: AI 伺服器營收：tsmc 成品的 Blackwell＋Hopper（GB300 級；2026 另含 AMD MI355）與 Rubin＋Rubin Ultra（VR200 級；2027 起另含 AMD MI450）顆數（世代分組與 Siliconomics Rack 頁、美超微模型相同，CF10） × 同字母情境係數 × 每顆系統價值（橋接表 Tokenomics v20.1 機架價 ÷ 72：GB300 約 59.7、VR200 約 116.7 千美元）＝商用 GPU 系統市場；× Dell 份額（FY2027 校準）× 份額相對值（Assumed）× 情境份額乘數（FY2029 起）。
A12: 非 AI：傳統伺服器與網通、儲存、CSG 依成長率推（Assumed，不隨 AI 情境）。營業利益：AI 營益率＝FY2027 殘差（ISG 營業利益 − 非 AI 營益率 16% × 非 AI 營收）＋ai_dm（FY2029 起加情境變動）；非 AI ISG、CSG 營益率為 Assumed。淨利＝分部營業利益 × 淨利係數；股數每年 −3%（回購）。
A13: 校準：FY2027 ＝ 公司全年指引（營收、AI 營收、non-GAAP EPS）＋1H FY27 實績＋2H 假設。不用券商數字（只在 Recon 對帳）。
A14: 估值：Val 第 0 節目標價＝0.5 × DCF 目標價（股東現金流＝EPS ×（1 − g／ROE），ROE 用預設 20%，FY2027 只計一個月，r 10%、g 4%，三情境權重 0.3／0.5／0.2）＋0.5 × Comparable 目標價（HPE、Supermicro、Lenovo、HP Inc.、NetApp 前瞻 P/E 中位數 × 12 個月後前瞻 EPS；不含 A 股）；另列 Comparable 單獨目標價、市場共識目標價、差距拆解與上檔空間級距。十年 P/E 規則值 × FY2027 EPS 保留為參考（不是目標價）。本版未做先驗，無 Andy 合理 P/E 對照。
A15: 預估期間：FY2028–FY2030 由驅動因子推導；FY2031 起為收斂法，非驅動因子推導（上游顆數到 CY2029＝FY2030；營收年增由 FY2030 線性收斂到 fade_g、淨利率收斂到 fade_m，FY2032 達到；PL 頁灰底）。
A16: 標記：Verified、Interested-party、Analogy、Assumed、Derived。SemiAnalysis 未使用。
A18: 已知限制：(1) AI 營益率公司不揭露，以非 AI 營益率 16% 拆分（Sens 有 19% 案例）；(2) 份額相對值、情境份額乘數與營益率變動是 Assumed；(3) AMD Helios、Rubin Ultra 每顆系統價值假設同 VR200；(4) 股東權益為負，ROE 用預設 20%；(5) 十年 P/E 只有 2019–2025，且為 GAAP；(6) 共識 FY2029 EPS 未找到；(7) 3Q FY27 財報（約 2026-11 下旬）後更新錨點；R4 產業部署路徑未建。
A19: v0.1.1（2026-10-28）：分部原則重建（數值不變）。Q 頁最後追加核對列「檢查：分部合計 − 合併營收」；官方分部與子列宣告見 segments.json。
A21: 2026-10-29：加權目標價中的 Comparable 改用相對倍數調整後的值（Val 第 0.5 節：同業前瞻倍數中位數 × 本公司 10 年相對同業的倍數比，Bloomberg 前瞻倍數；Andy 2026-10-27「照建議做」、10-29 資料取回）。「Comparable 目標價（市場主流同業法）」維持不調整。重點觀察 1 的第一句已改為公式；重點觀察 2、3 與其他說明中的目標價與上檔空間數字為調整前撰寫，以 Val 頁為準。

Sheet In
A1: In — 輸入（藍字；基準欄 E，低 D、高 F）。金額：十億美元（US$B）；每顆系統價值：千美元／顆；比例：%。口徑：non-GAAP。每個輸入盡量附兩個來源（找不到者寫「未找到」）；公司原文算一個
A2: 標記：Verified／Interested-party／Analogy／Assumed／Derived；Analogy、Assumed 給低／高區間，不當點估計（放情境或 Sens）。SemiAnalysis 未使用。公司原文＝Dell 8-K 財報新聞稿（SEC）；公司指引與展望為 Interested-party；券商與資料商估計皆為 Interested-party。加速器顆數讀 tsmc 成品、每顆系統價值讀橋接表（唯讀）
A3: 鍵 | B3: 項目 | C3: 單位 | D3: 低 | E3: 基準 | F3: 高 | G3: 標記 | H3: 來源1 | I3: 來源2／說明
A4: A. 加速器顆數與每顆系統價值（讀 tsmc、markets/chip_bridge 成品；情境 A 基準，B／C 依同字母顆數係數縮放）
A5: ug_26 | B5: GB300 級商用 GPU 顆數 CY2026（Blackwell＋Hopper＋AMD MI355） | C5: 百萬顆 | E5: 6.65 | G5: Derived | H5: tsmc/dist/20261028_台積電個股模型_v0.4.xlsx｜In!E5:E24 | I5: tsmc 成品 u_bw、u_hp（2026 另含 u_amd）；CY2029＝CY2028 × (1＋各類成長)；世代分組與 Siliconomics Rack 頁、美超微模型相同（CF10）
A6: ug_27 | B6: GB300 級商用 GPU 顆數 CY2027（Blackwell＋Hopper） | C6: 百萬顆 | E6: 2.4 | G6: Derived | H6: 同上 | I6: 同上
A7: ug_28 | B7: GB300 級商用 GPU 顆數 CY2028（Blackwell＋Hopper） | C7: 百萬顆 | E7: 0.5 | G7: Derived | H7: 同上 | I7: 同上
A8: ug_29 | B8: GB300 級商用 GPU 顆數 CY2029（Blackwell＋Hopper） | C8: 百萬顆 | E8: 0.25 | G8: Derived | H8: 同上 | I8: 同上
A9: uv_26 | B9: VR200 級商用 GPU 顆數 CY2026（Rubin＋Rubin Ultra） | C9: 百萬顆 | E9: 1.7 | G9: Derived | H9: tsmc/dist/20261028_台積電個股模型_v0.4.xlsx｜In!E5:E24 | I9: tsmc 成品 u_rb、u_ru、u_amd；Google TPU、Trainium 與其他 ASIC 不含（雲端自建，Dell 不是主要供應商）
A10: uv_27 | B10: VR200 級商用 GPU 顆數 CY2027（Rubin＋Rubin Ultra＋AMD MI450） | C10: 百萬顆 | E10: 8.8 | G10: Derived | H10: 同上 | I10: 同上
A11: uv_28 | B11: VR200 級商用 GPU 顆數 CY2028（Rubin＋Rubin Ultra＋AMD MI450） | C11: 百萬顆 | E11: 11 | G11: Derived | H11: 同上 | I11: 同上
A12: uv_29 | B12: VR200 級商用 GPU 顆數 CY2029（Rubin＋Rubin Ultra＋AMD MI450） | C12: 百萬顆 | E12: 12.65 | G12: Derived | H12: 同上 | I12: 同上
A13: um28_A | B13: 情境 A：CY2028 顆數 ÷ 基準 | C13: x | E13: 1 | G13: Assumed | H13: tsmc/dist/20261028_台積電個股模型_v0.4.xlsx｜In!E37 | I13: A＝順利（基準）；B＝平平；C＝不如預期；與台積電、廣達、緯穎模型同字母
A14: um29_A | B14: 情境 A：CY2029 顆數 ÷ 基準 | C14: x | E14: 1 | G14: Assumed | H14: tsmc/dist/20261028_台積電個股模型_v0.4.xlsx｜In!E38 | I14: 同上
A15: um28_B | B15: 情境 B：CY2028 顆數 ÷ 基準 | C15: x | E15: 0.8 | G15: Assumed | H15: tsmc/dist/20261028_台積電個股模型_v0.4.xlsx｜In!E39 | I15: A＝順利（基準）；B＝平平；C＝不如預期；與台積電、廣達、緯穎模型同字母
A16: um29_B | B16: 情境 B：CY2029 顆數 ÷ 基準 | C16: x | E16: 0.85 | G16: Assumed | H16: tsmc/dist/20261028_台積電個股模型_v0.4.xlsx｜In!E40 | I16: 同上
... A18: um29_C | B18: 情境 C：CY2029 顆數 ÷ 基準 | C18: x | E18: 0.6 | G18: Assumed | H18: tsmc/dist/20261028_台積電個股模型_v0.4.xlsx｜In!E42 | I18: 同上
A19: v_gb | B19: 每顆系統價值（GB300 NVL72 機架價 ÷ 72） | C19: US$K/顆 | D19: 55.555556 | E19: 59.722222 | F19: 69.444444 | G19: Derived | H19: markets/chip_bridge/dist/20261027_晶片內容橋接表_v0.2.2.xlsx｜In!D5:I5（機架單價）÷ In!E14（每架 GPU 數） | I19: Tokenomics v20.1 機架單價（經橋接表；唯讀）；Dell 為 OEM，營收含整櫃（含 GPU）
A20: v_vr | B20: 每顆系統價值（VR200 NVL72 機架價 ÷ 72；AMD Helios 假設相同） | C20: US$K/顆 | D20: 104.16667 | E20: 116.66667 | F20: 126.38889 | G20: Derived | H20: markets/chip_bridge/dist/20261027_晶片內容橋接表_v0.2.2.xlsx｜In!D5:I5（機架單價）÷ In!E14（每架 GPU 數） | I20: 同上；AMD MI450／Rubin Ultra 每顆價值未另訂（Assumed：同 VR200）
A21: mf | B21: AI 部署係數（Sens 用；FY2028 起） | C21: x | D21: 0.8 | E21: 1 | F21: 1.2 | G21: Assumed | H21: 無 | I21: ±20%
A22: B. Dell 份額（FY2027 以公司 AI 伺服器營收指引校準）
A23: rel_28 | B23: Dell 份額相對值 FY2028 ÷ FY2027（全部情境） | C23: x | D23: 0.75 | E23: 0.9 | F23: 1.05 | G23: Assumed | H23: Dell 8-K 2Q FY27（2026-09-01）：2Q FY27 AI 訂單 609 億美元、在手訂單 950 億美元（公司） | I23: Pulse 2.0 2026-09-01：近四季 AI 訂單 1,317 億美元；份額下檔：雲端與 neocloud 直接向 ODM 採購、Supermicro／HPE 競價
A24: rel_29 | B24: Dell 份額相對值 FY2029 ÷ FY2027 | C24: x | D24: 0.65 | E24: 0.85 | F24: 1 | G24: Assumed | H24: 同上；客戶集中於 neocloud 與大型 AI 實驗室（xAI、CoreWeave 等，媒體） | I24: —
A25: rel_30 | B25: Dell 份額相對值 FY2030 ÷ FY2027 | C25: x | D25: 0.55 | E25: 0.8 | F25: 1 | G25: Assumed | H25: 同上 | I25: —
A26: srel_A | B26: 情境 A：FY2029 起份額額外乘數 | C26: x | E26: 1 | G26: Assumed | H26: 公司特有變數依情境調整，方向 A 最有利 | I26: —
A27: srel_B | B27: 情境 B：FY2029 起份額額外乘數 | C27: x | E27: 0.95 | G27: Assumed | H27: AI 資本支出消化時，neocloud 客戶（信用較弱）先縮 | I27: —
A28: srel_C | B28: 情境 C：FY2029 起份額額外乘數 | C28: x | E28: 0.85 | G28: Assumed | H28: 同上，下修更深 | I28: —
A29: C. FY2027 錨點（1H FY27 實績＋公司全年指引＋2H 假設）
A30: g_rev | B30: FY2027 營收指引 | C30: US$B | D30: 190 | E30: 192 | F30: 194 | G30: Interested-party | H30: Dell 8-K 2Q FY27（2026-09-01）：FY27 營收 1,920 億美元（由 1,670 上修） | I30: Zacks 2026-09：±20 億美元
A31: g_ai | B31: FY2027 AI 伺服器營收指引 | C31: US$B | E31: 74 | G31: Interested-party | H31: Dell 8-K 2Q FY27（2026-09-01）：FY27 AI-Optimized Servers 約 740 億美元（由 600 上修） | I31: Pulse 2.0 2026-09-01：同
A32: g_eps | B32: FY2027 non-GAAP EPS 指引 | C32: US$ | D32: 25.25 | E32: 25.5 | F32: 25.75 | G32: Interested-party | H32: Dell 8-K 2Q FY27（2026-09-01）：non-GAAP 稀釋 EPS 25.50（GAAP 24.37） | I32: Zacks 2026-09：±0.25
A33: g_q3rev | B33: 3Q FY27 營收指引（參考） | C33: US$B | D33: 48.5 | E33: 49 | F33: 49.5 | G33: Interested-party | H33: Dell 8-K 2Q FY27（2026-09-01）：3Q FY27 營收 490 億美元、non-GAAP EPS 6.50 | I33: Zacks 2026-09：±5 億美元
A34: st_h2 | B34: 2H FY27 儲存營收 ÷ 1H | C34: x | D34: 1.05 | E34: 1.12 | F34: 1.2 | G34: Assumed | H34: StorageNewsletter 2026-09-03：3Q 儲存年增約 mid-teens、全年約 200 億美元（媒體轉述） | I34: 1H FY27 91.84 億 × 1.12 ＝ 2H 102.9 億（全年 194.7 億）
A35: csg_h2 | B35: 2H FY27 CSG 營收 ÷ 1H − 1 | C35: % | D35: -0.03 | E35: 0.03 | F35: 0.08 | G35: Assumed | H35: CSG 2Q FY27 年增 20%、季增 6%（公司） | I35: 公司未給 CSG 全年指引：未找到
A36: isg_h2m | B36: 2H FY27 ISG 營業利益率 | C36: % | D36: 0.12 | E36: 0.135 | F36: 0.155 | G36: Assumed | H36: Dell 8-K 2Q FY27（2026-09-01）：2Q FY27 ISG 營益率 15.0%、1H 12.9%（公司） | I36: AI 比重上升稀釋 ISG 營益率（Assumed）
A37: csg_h2m | B37: 2H FY27 CSG 營業利益率 | C37: % | D37: 0.065 | E37: 0.075 | F37: 0.08 | G37: Assumed | H37: Dell 8-K 2Q FY27（2026-09-01）：2Q FY27 CSG 營益率 7.6%、1H 7.8%（公司） | I37: FY26 5.6%
A38: h2_sh | B38: 2H FY27 稀釋股數（3Q、4Q 平均） | C38: 十億股 | D38: 0.635 | E38: 0.642 | F38: 0.65 | G38: Assumed | H38: Dell 8-K 2Q FY27（2026-09-01）：2Q 稀釋股數 6.52 億、1H 6.54 億；2Q 買回 950 萬股（均價 401 美元） | I38: stockanalysis.com（統計）：流通股數 6.3581 億股（2026-10-23）
A39: m_nai | B39: 非 AI ISG（傳統伺服器、網通、儲存）營業利益率（拆分 AI 毛利用） | C39: % | D39: 0.14 | E39: 0.16 | F39: 0.19 | G39: Assumed | H39: 公司不揭露 AI 伺服器營益率：未找到 | I39: FY26：ISG 營益率 11.7%；非 AI 取 16% 時 AI 約 5%（Q 頁檢查列）
A40: D. 營業利益率（FY2028 起）
A41: ai_dm | B41: AI 伺服器營業利益率變動（FY2028 起，相對 FY2027 校準值；全部情境） | C41: pt | D41: -0.03 | E41: -0.01 | F41: 0.01 | G41: Assumed | H41: Rubin 機架單價較高、GPU 轉手比重高，營益率（%）下降；規模效益為上檔 | I41: —
...

Sheet Q
A1: Q — 實績與 FY2027 錨點（十億美元；EPS 美元；股數十億股；non-GAAP）。藍字＝輸入；黑字＝公式。實績取自 Dell 8-K 財報新聞稿（SEC）
A2: FY2027 錨點＝公司全年指引（營收 1,920 億、AI 伺服器 740 億、non-GAAP EPS 25.50）＋1H FY27 實績＋2H 假設（儲存、CSG、ISG 與 CSG 營益率、股數）；傳統伺服器與網通為全年營收殘差。分部營業利益合計約等於 non-GAAP 營業利益（FY26 差 0.05、1H FY27 差 0.02）
A3: 項目 | B3: FY2026A | C3: 1H FY27（實績） | D3: 2H FY27（模型） | E3: FY2027 錨點 | G3: 標記 | H3: 來源1（公司） | I3: 來源2／說明
A4: AI 伺服器（AI-Optimized Servers） | B4: 24.683 | C4: 32.533 | D4: =g_ai-C4 -> 41.467 | E4: =g_ai -> 74 | G4: Verified／Interested-party（全年指引） | H4: FY2026：Dell 8-K 4Q FY26（2026-02-26）；1H FY27：Dell 8-K 2Q FY27（2026-09-01） | I4: 1Q FY27 161.32 億、2Q 164.01 億
A5: 傳統伺服器與網通 | B5: 19.512 | C5: 19.074 | D5: =E5-C5 -> 18.52263 | E5: =g_rev-E4-E6-E8-E9 -> 37.59663 | G5: Verified／Derived（全年殘差） | H5: FY2026：Dell 8-K 4Q FY26（2026-02-26）；1H FY27：Dell 8-K 2Q FY27（2026-09-01） | I5: 1Q 85.43 億、2Q 105.31 億
A6: 儲存 | B6: 16.631 | C6: 9.184 | D6: =C6*st_h2 -> 10.28608 | E6: =C6+D6 -> 19.47008 | G6: Verified／Assumed（2H） | H6: FY2026：Dell 8-K 4Q FY26（2026-02-26）；1H FY27：Dell 8-K 2Q FY27（2026-09-01） | I6: 1Q 43.34 億、2Q 48.50 億
A7: ISG 營收 | B7: =B4+B5+B6 -> 60.826 | C7: =C4+C5+C6 -> 60.791 | D7: =D4+D5+D6 -> 70.27571 | E7: =C7+D7 -> 131.06671 | G7: Derived | H7: FY2026：Dell 8-K 4Q FY26（2026-02-26）；1H FY27：Dell 8-K 2Q FY27（2026-09-01） | I7: FY26 608.26、1H FY27 607.91（公司合計）
A8: CSG 營收（商用＋消費） | B8: 50.984 | C8: 29.643 | D8: =C8*(1+csg_h2) -> 30.53229 | E8: =C8+D8 -> 60.17529 | G8: Verified／Assumed（2H） | H8: FY2026：Dell 8-K 4Q FY26（2026-02-26）；1H FY27：Dell 8-K 2Q FY27（2026-09-01） | I8: FY26 商用 440.62、消費 69.22；1H FY27 商用 262.12、消費 34.31
A9: 其他業務（營收 − ISG − CSG） | B9: =B10-B7-B8 -> 1.728 | C9: =C10-C7-C8 -> 0.379 | D9: =C9 -> 0.379 | E9: =C9+D9 -> 0.758 | G9: Derived／Assumed（2H＝1H） | H9: FY2026：Dell 8-K 4Q FY26（2026-02-26）；1H FY27：Dell 8-K 2Q FY27（2026-09-01） | I9: Secureworks 出售後的剩餘業務、VMware 轉售等；營業利益併入淨利係數
A10: 營收 | B10: 113.538 | C10: 90.813 | D10: =E10-C10 -> 101.187 | E10: =g_rev -> 192 | G10: Verified／Interested-party（全年指引） | H10: FY2026：Dell 8-K 4Q FY26（2026-02-26）；1H FY27：Dell 8-K 2Q FY27（2026-09-01） | I10: FY27 錨點＝全年指引 1,920 億
A11: ISG 營業利益 | B11: 7.111 | C11: 7.836 | D11: =D7*isg_h2m -> 9.4872208 | E11: =C11+D11 -> 17.323221 | G11: Verified／Assumed（2H） | H11: FY2026：Dell 8-K 4Q FY26（2026-02-26）；1H FY27：Dell 8-K 2Q FY27（2026-09-01） | I11: 2Q FY27 47.81 億（營益率 15.0%）
A12: CSG 營業利益 | B12: 2.833 | C12: 2.312 | D12: =D8*csg_h2m -> 2.2899217 | E12: =C12+D12 -> 4.6019217 | G12: Verified／Assumed（2H） | H12: FY2026：Dell 8-K 4Q FY26（2026-02-26）；1H FY27：Dell 8-K 2Q FY27（2026-09-01） | I12: 2Q FY27 11.42 億（7.6%）
A13: 分部營業利益合計 | B13: =B11+B12 -> 9.944 | C13: =C11+C12 -> 10.148 | D13: =D11+D12 -> 11.777143 | E13: =C13+D13 -> 21.925143 | G13: Derived | H13: FY2026：Dell 8-K 4Q FY26（2026-02-26）；1H FY27：Dell 8-K 2Q FY27（2026-09-01） | I13: non-GAAP 營業利益：FY26 99.91、1H FY27 101.64（公司）
A14: non-GAAP 營業利益（公司揭露） | B14: 9.991 | C14: 10.164 | G14: Verified | H14: FY2026：Dell 8-K 4Q FY26（2026-02-26）；1H FY27：Dell 8-K 2Q FY27（2026-09-01） | I14: —
A15: non-GAAP 淨利 | B15: 7.046 | C15: 7.781 | D15: =E15-C15 -> 8.743 | E15: =g_eps*E17 -> 16.524 | G15: Verified／Interested-party（全年＝指引 EPS × 股數） | H15: FY2026：Dell 8-K 4Q FY26（2026-02-26）；1H FY27：Dell 8-K 2Q FY27（2026-09-01） | I15: GAAP 淨利 FY26 59.36、1H FY27 75.71
A16: 淨利 ÷ 分部營業利益 | B16: =B15/B13 -> 0.70856798 | C16: =C15/C13 -> 0.76675207 | D16: =D15/D13 -> 0.74237022 | E16: =E15/E13 -> 0.7536553 | G16: Derived | H16: — | I16: FY2028 起 nio_f 的對照
A17: 稀釋股數（十億股） | B17: =7.046/10.3 -> 0.68407767 | C17: 0.654 | D17: =h2_sh -> 0.642 | E17: =(C17+D17)/2 -> 0.648 | G17: Verified／Derived／Assumed | H17: FY2026：Dell 8-K 4Q FY26（2026-02-26）；1H FY27：Dell 8-K 2Q FY27（2026-09-01） | I17: FY26＝non-GAAP 淨利 ÷ non-GAAP EPS；1H FY27 公司揭露 6.54 億
A18: non-GAAP EPS | B18: =B15/B17 -> 10.3 | C18: =C15/C17 -> 11.897554 | D18: =D15/D17 -> 13.61838 | E18: =E15/E17 -> 25.5 | G18: Derived | H18: 淨利 ÷ 股數 | I18: —
A19: 公司揭露 non-GAAP EPS | B19: 10.3 | C19: 11.9 | E19: =g_eps -> 25.5 | G19: Verified／Interested-party（指引） | H19: FY2026：Dell 8-K 4Q FY26（2026-02-26）；1H FY27：Dell 8-K 2Q FY27（2026-09-01） | I19: GAAP EPS：FY26 8.68、1H FY27 11.58、FY27 指引 24.37
A21: 錨點與拆分的檢查（參考；校準未使用券商數字）
A22: FY2027 營收年增 | B22: =E10/B10-1 -> 0.69106378
A23: 2H FY27 傳統伺服器與網通 ÷ 1H − 1 | B23: =D5/C5-1 -> -0.028906889
A24: FY2026 AI 伺服器營業利益率（隱含；非 AI ISG 取 m_nai） | B24: =(B11-m_nai*(B5+B6))/B4 -> 0.053807074
A25: FY2027 AI 伺服器營業利益率（隱含；PL 校準值） | B25: =(E11-m_nai*(E5+E6))/E4 -> 0.1107101
A26: FY2027 EPS ÷ 共識（25.90）− 1 | B26: =E18/c_eps27-1 -> -0.015444015
A27: 1H FY27 EPS 自算 − 公司揭露（應約為 0） | B27: =C18-C19 -> -0.0024464832
A28: 2H FY27 non-GAAP EPS（隱含；3Q 指引 6.50） | B28: =D18 -> 13.61838
A30: 檢查：分部合計 − 合併營收 | B30: =ROUND(B7+B8+B9-B10,3) -> 0 | C30: =ROUND(C7+C8+C9-C10,3) -> 0 | D30: =ROUND(D7+D8+D9-D10,3) -> 0 | E30: =ROUND(E7+E8+E9-E10,3) -> 0
A31: 分部原則第 3 條（2026-10-28 追加）：其他業務為差額；分部宣告見 segments.json

Sheet Units
A1: Units — 商用 GPU 系統市場（tsmc 顆數 × 橋接表每顆系統價值）、Dell 份額與組裝廠份額對照（情境 A）。FY(t)≈CY(t−1)
A3: 項目 | B3: 單位 | C3: CY2026（FY2027） | D3: CY2027（FY2028） | E3: CY2028（FY2029） | F3: CY2029（FY2030） | G3: 說明
A4: GB300 級 GPU 顆數（Blackwell＋Hopper） | B4: 百萬顆 | C4: =PL!D63 -> 6.65 | D4: =PL!E63 -> 2.4 | E4: =PL!F63 -> 0.5 | F4: =PL!G63 -> 0.25 | G4: tsmc 成品
A5: VR200 級 GPU 顆數（Rubin＋Rubin Ultra；2027 起＋AMD） | B5: 百萬顆 | C5: =PL!D64 -> 1.7 | D5: =PL!E64 -> 8.8 | E5: =PL!F64 -> 11 | F5: =PL!G64 -> 12.65 | G5: tsmc 成品
A6: 每顆系統價值 GB300 級 | B6: US$K/顆 | C6: =v_gb -> 59.722222 | D6: =v_gb -> 59.722222 | E6: =v_gb -> 59.722222 | F6: =v_gb -> 59.722222 | G6: 橋接表機架價 ÷ 72
A7: 每顆系統價值 VR200 級 | B7: US$K/顆 | C7: =v_vr -> 116.66667 | D7: =v_vr -> 116.66667 | E7: =v_vr -> 116.66667 | F7: =v_vr -> 116.66667 | G7: 同上
A8: 商用 GPU 系統市場（整櫃售價） | B8: US$B | C8: =PL!D65 -> 595.48611 | D8: =PL!E65 -> 1170 | E8: =PL!F65 -> 1313.1944 | F8: =PL!G65 -> 1490.7639 | G8: OEM／整櫃售價口徑（含 GPU）
A9: Dell 有效份額 | B9: % | C9: =PL!D69 -> 0.12426822 | D9: =PL!E69 -> 0.1118414 | E9: =PL!F69 -> 0.10562799 | F9: =PL!G69 -> 0.099414577 | G9: FY2027 以 AI 營收指引 740 億校準
A10: Dell AI 伺服器營收 | B10: US$B | C10: =PL!D70 -> 74 | D10: =PL!E70 -> 130.85444 | E10: =PL!F70 -> 138.71009 | F10: =PL!G70 -> 148.20366
A11: 隱含 Dell 出貨櫃數（NVL72 等值，按當年組合） | B11: 千櫃 | C11: =PL!D70/PL!D65*(PL!D63+PL!D64)/72*1000 -> 14.411662 | D11: =PL!E70/PL!E65*(PL!E63+PL!E64)/72*1000 -> 17.397551 | E11: =PL!F70/PL!F65*(PL!F63+PL!F64)/72*1000 -> 16.871137 | F11: =PL!G70/PL!G65*(PL!G63+PL!G64)/72*1000 -> 17.811778 | G11: 營收 ÷ 平均每櫃售價
A12: 對照：AI 伺服器組裝市場（ODM 價，廣達模型；含 ASIC） | B12: US$B | C12: 634.61653 | D12: 1139.0807 | E12: 1443.9178 | F12: 1644.8506 | G12: quanta/dist/20261028_廣達個股模型_v0.3.xlsx｜Units!C6:F6
A13: Dell AI 營收 ÷ 組裝市場（ODM 口徑） | B13: % | C13: =C10/C12 -> 0.11660585 | D13: =D10/D12 -> 0.11487723 | E13: =E10/E12 -> 0.096065088 | F13: =F10/F12 -> 0.090101594 | G13: Dell 為 OEM 售價、含加價，同口徑時份額更低
A14: 對照：鴻海＋廣達＋緯創（含緯穎）合計有效份額（緯創模型） | B14: % | C14: 0.43018513 | D14: 0.43018513 | E14: 0.41911484 | F14: 0.39760559 | G14: wistron/dist/20261028_緯創個股模型_v0.2.xlsx｜Units!C11:F11
A15: 合計：ODM 三家＋Dell（未扣重複） | B15: % | C15: =C14+C13 -> 0.54679098 | D15: =D14+D13 -> 0.54506237 | E15: =E14+E13 -> 0.51517993 | F15: =F14+F13 -> 0.48770718 | G15: Dell 的機架多由鴻海、緯創代工，兩者重複計算；未扣重複仍低於 100%
A17: 讀法：Dell 份額的分母是 NVIDIA 與 AMD 商用 GPU 的整櫃售價（不含 Google TPU、Trainium 等 ASIC，Dell 不是其主要供應商）。FY2027 份額約一成，換算到廣達模型的 ODM 組裝市場（含 ASIC）約 12%；鴻海、廣達、緯創（含緯穎）合計約 44%，加上 Dell 仍約 55%，其餘為 Supermicro、HPE、Lenovo、英業達與雲端自建。Dell 的機架多由 ODM 代工，兩者營收有重複，所以實際份額合計更低，不會超過 100%。

Sheet PL
A1: PL — Dell 損益（十億美元；EPS 美元；non-GAAP）。FY2026A 實績、FY2027 錨點（公司指引＋1H 實績＋2H 假設；三情境相同），FY2028 起為模型。FY(t)≈CY(t−1)。三情境各一個完整推導區塊（本頁下方），頂端為摘要。FY2027–FY2028 三情境相同（顆數係數從 CY2028＝FY2029 開始）
A2: 灰底＝FY2031–FY2032 收斂法（上游顆數只到 CY2029＝FY2030）：營收年增線性收斂到 fade_g、淨利率線性收斂到 fade_m（In 頁 I 節），非驅動因子推導
A3: 情境／項目 | B3: 單位 | C3: FY2026A | D3: FY2027（錨點） | E3: FY2028 | F3: FY2029 | G3: FY2030 | H3: FY2031（收斂） | I3: FY2032（收斂） | J3: 說明
A4: 情境 A
A5: 營收 | B5: US$B | C5: =C77 -> 113.538 | D5: =D77 -> 192 | E5: =E77 -> 249.55867 | F5: =F77 -> 260.79803 | G5: =G77 -> 274.14209 | H5: =H77 -> 289.37976 | I5: =I77 -> 306.74255
A6: 營收年增 | B6: % | D6: =D78 -> 0.69106378 | E6: =E78 -> 0.29978473 | F6: =F78 -> 0.045036937 | G6: =G78 -> 0.051166265 | H6: =H78 -> 0.055583133 | I6: =I78 -> 0.06
A7: AI 伺服器營收 | B7: US$B | C7: =C70 -> 24.683 | D7: =D70 -> 74 | E7: =E70 -> 130.85444 | F7: =F70 -> 138.71009 | G7: =G70 -> 148.20366
A8: 傳統伺服器與網通 | B8: US$B | C8: =C72 -> 19.512 | D8: =D72 -> 37.59663 | E8: =E72 -> 35.716799 | F8: =F72 -> 36.431134 | G8: =G72 -> 37.524069
A9: 儲存 | B9: US$B | C9: =C73 -> 16.631 | D9: =D73 -> 19.47008 | E9: =E73 -> 20.248883 | F9: =F73 -> 21.058839 | G9: =G73 -> 21.901192
A10: CSG（PC） | B10: US$B | C10: =C75 -> 50.984 | D10: =D75 -> 60.17529 | E10: =E75 -> 61.980549 | F10: =F75 -> 63.839965 | G10: =G75 -> 65.755164
A11: AI 伺服器營業利益率 | B11: % | C11: =C81 -> 0.053807074 | D11: =D81 -> 0.1107101 | E11: =E81 -> 0.1007101 | F11: =F81 -> 0.1007101 | G11: =G81 -> 0.1007101
A12: 營業利益率 | B12: % | C12: =C87 -> 0.087583012 | D12: =D87 -> 0.11419345 | E12: =E87 -> 0.104952 | F12: =F87 -> 0.10486755 | G12: =G87 -> 0.10483389
A13: non-GAAP 淨利 | B13: US$B | C13: =C89 -> 7.046 | D13: =D89 -> 16.524 | E13: =E89 -> 19.643762 | F13: =F89 -> 20.511937 | G13: =G89 -> 21.554537 | H13: =H89 -> 22.752605 | I13: =I89 -> 24.117762
A14: 淨利率 | B14: % | C14: =C93 -> 0.062058518 | D14: =D93 -> 0.0860625 | E14: =E93 -> 0.078714003 | F14: =F93 -> 0.078650662 | G14: =G93 -> 0.07862542 | H14: =H93 -> 0.07862542 | I14: =I93 -> 0.07862542
A15: non-GAAP EPS | B15: US$ | C15: =C91 -> 10.3 | D15: =D91 -> 25.5 | E15: =E91 -> 31.252007 | F15: =F91 -> 33.642496 | G15: =G91 -> 36.445884 | H15: =H91 -> 39.661505 | I15: =I91 -> 43.341439
A16: EPS 年增 | B16: % | D16: =D92 -> 1.4757282 | E16: =E92 -> 0.22556892 | F16: =F92 -> 0.076490722 | G16: =G92 -> 0.083328764 | H16: =H92 -> 0.088230034 | I16: =I92 -> 0.092783505
A18: 情境 B
A19: 營收 | B19: US$B | C19: =C114 -> 113.538 | D19: =D114 -> 192 | E19: =E114 -> 249.55867 | F19: =F114 -> 227.50761 | G19: =G114 -> 245.61288 | H19: =H114 -> 260.2982 | I19: =I114 -> 270.71012
A20: 營收年增 | B20: % | D20: =D115 -> 0.69106378 | E20: =E115 -> 0.29978473 | F20: =F115 -> -0.088360237 | G20: =G115 -> 0.079580975 | H20: =H115 -> 0.059790488 | I20: =I115 -> 0.04
A21: AI 伺服器營收 | B21: US$B | C21: =C107 -> 24.683 | D21: =D107 -> 74 | E21: =E107 -> 130.85444 | F21: =F107 -> 105.41967 | G21: =G107 -> 119.67446
A22: 傳統伺服器與網通 | B22: US$B | C22: =C109 -> 19.512 | D22: =D109 -> 37.59663 | E22: =E109 -> 35.716799 | F22: =F109 -> 36.431134 | G22: =G109 -> 37.524069
A23: 儲存 | B23: US$B | C23: =C110 -> 16.631 | D23: =D110 -> 19.47008 | E23: =E110 -> 20.248883 | F23: =F110 -> 21.058839 | G23: =G110 -> 21.901192
A24: CSG（PC） | B24: US$B | C24: =C112 -> 50.984 | D24: =D112 -> 60.17529 | E24: =E112 -> 61.980549 | F24: =F112 -> 63.839965 | G24: =G112 -> 65.755164
A25: AI 伺服器營業利益率 | B25: % | C25: =C118 -> 0.053807074 | D25: =D118 -> 0.1107101 | E25: =E118 -> 0.1007101 | F25: =F118 -> 0.090710098 | G25: =G118 -> 0.090710098
A26: 營業利益率 | B26: % | C26: =C124 -> 0.087583012 | D26: =D124 -> 0.11419345 | E26: =E124 -> 0.104952 | F26: =F124 -> 0.10084222 | G26: =G124 -> 0.10044041
A27: non-GAAP 淨利 | B27: US$B | C27: =C126 -> 7.046 | D27: =D126 -> 16.524 | E27: =E126 -> 19.643762 | F27: =F126 -> 17.206779 | G27: =G126 -> 18.502094 | H27: =H126 -> 18.627926 | I27: =I126 -> 18.353409
A28: 淨利率 | B28: % | C28: =C130 -> 0.062058518 | D28: =D130 -> 0.0860625 | E28: =E130 -> 0.078714003 | F28: =F130 -> 0.075631664 | G28: =G130 -> 0.075330308 | H28: =H130 -> 0.071563792 | I28: =I130 -> 0.067797277
A29: non-GAAP EPS | B29: US$ | C29: =C128 -> 10.3 | D29: =D128 -> 25.5 | E29: =E128 -> 31.252007 | F29: =F128 -> 28.221565 | G29: =G128 -> 31.284605 | H29: =H128 -> 32.471516 | I29: =I128 -> 32.982462
A30: EPS 年增 | B30: % | D30: =D129 -> 1.4757282 | E30: =E129 -> 0.22556892 | F30: =F129 -> -0.096967912 | G30: =G129 -> 0.10853542 | H30: =H129 -> 0.037939137 | I30: =I129 -> 0.015735214
A32: 情境 C
A33: 營收 | B33: US$B | C33: =C151 -> 113.538 | D33: =D151 -> 192 | E33: =E151 -> 249.55867 | F33: =F151 -> 192.83008 | G33: =G151 -> 201.52229 | H33: =H151 -> 208.07953 | I33: =I151 -> 212.24112
A34: 營收年增 | B34: % | D34: =D152 -> 0.69106378 | E34: =E152 -> 0.29978473 | F34: =F152 -> -0.22731563 | G34: =G152 -> 0.045077041 | H34: =H152 -> 0.03253852 | I34: =I152 -> 0.02
A35: AI 伺服器營收 | B35: US$B | C35: =C144 -> 24.683 | D35: =D144 -> 74 | E35: =E144 -> 130.85444 | F35: =F144 -> 70.742145 | G35: =G144 -> 75.583868
A36: 傳統伺服器與網通 | B36: US$B | C36: =C146 -> 19.512 | D36: =D146 -> 37.59663 | E36: =E146 -> 35.716799 | F36: =F146 -> 36.431134 | G36: =G146 -> 37.524069
A37: 儲存 | B37: US$B | C37: =C147 -> 16.631 | D37: =D147 -> 19.47008 | E37: =E147 -> 20.248883 | F37: =F147 -> 21.058839 | G37: =G147 -> 21.901192
A38: CSG（PC） | B38: US$B | C38: =C149 -> 50.984 | D38: =D149 -> 60.17529 | E38: =E149 -> 61.980549 | F38: =F149 -> 63.839965 | G38: =G149 -> 65.755164
A39: AI 伺服器營業利益率 | B39: % | C39: =C155 -> 0.053807074 | D39: =D155 -> 0.1107101 | E39: =E155 -> 0.1007101 | F39: =F155 -> 0.075710098 | G39: =G155 -> 0.075710098
A40: 營業利益率 | B40: % | C40: =C161 -> 0.087583012 | D40: =D161 -> 0.11419345 | E40: =E161 -> 0.104952 | F40: =F161 -> 0.097161386 | G40: =G161 -> 0.096943314
A41: non-GAAP 淨利 | B41: US$B | C41: =C163 -> 7.046 | D41: =D163 -> 16.524 | E41: =E163 -> 19.643762 | F41: =F163 -> 14.051729 | G41: =G163 -> 14.652179 | H41: =H163 -> 13.616045 | I41: =I163 -> 12.345215
A42: 淨利率 | B42: % | C42: =C167 -> 0.062058518 | D42: =D167 -> 0.0860625 | E42: =E167 -> 0.078714003 | F42: =F167 -> 0.072871039 | G42: =G167 -> 0.072707486 | H42: =H167 -> 0.065436737 | I42: =I167 -> 0.058165988
...

Sheet Val
A1: Val — P/E 估值（美元；non-GAAP EPS）。目標價＝DCF 與 Comparable 加權（第 0 節）；結論另列「現價 ÷ FY2027、FY2028 EPS（模型）」；十年 P/E 規則值（第 3 節，年底落後 P/E）只作參考
A2: 循環位置：Dell 不是設備股，不套設備市場見頂年；以本模型營收最高的會計年度為見頂年（比照廣達、緯穎）。營收到 FY2030 仍在增加時，見頂年未知，判為中段
A4: 0. 目標價
A5: 0.1 DCF（股東權益現金流，FY2027–FY2032 明確期＋FY2032 後永續）
A6: 項目 | B6: A（順利） | C6: B（平平） | D6: C（不如預期） | E6: 說明 | F6: 折現年數 t | G6: 期內占比（基準日後）
A7: 情境 EPS（FY2027–FY2032） | E7: PL 頁各情境（non-GAAP）；FY2031 起為收斂法；F 欄＝距 2026 年底的年數（會計年度 1 月底結束）
A8: FY2027 | B8: =PL!D15 -> 25.5 | C8: =PL!D29 -> 25.5 | D8: =PL!D43 -> 25.5 | F8: 0.083333 | G8: 0.083333
A9: FY2028 | B9: =PL!E15 -> 31.252007 | C9: =PL!E29 -> 31.252007 | D9: =PL!E43 -> 31.252007 | F9: 1.083333 | G9: 1
A10: FY2029 | B10: =PL!F15 -> 33.642496 | C10: =PL!F29 -> 28.221565 | D10: =PL!F43 -> 23.046834 | F10: 2.083333 | G10: 1
A11: FY2030 | B11: =PL!G15 -> 36.445884 | C11: =PL!G29 -> 31.284605 | D11: =PL!G43 -> 24.774906 | F11: 3.083333 | G11: 1
A12: FY2031 | B12: =PL!H15 -> 39.661505 | C12: =PL!H29 -> 32.471516 | D12: =PL!H43 -> 23.73499 | F12: 4.083333 | G12: 1
A13: FY2032 | B13: =PL!I15 -> 43.341439 | C13: =PL!I29 -> 32.982462 | D13: =PL!I43 -> 22.185283 | F13: 5.083333 | G13: 1
A14: 股東現金流＝EPS ×（1 − tp_g ÷ tp_roe） | E14: 下列六列＝EPS × (1 − 再投資率) × 期內占比（FY2027 只計 2027-01 一個月）
A15: 再投資率（tp_g ÷ tp_roe，上限 0.8） | B15: =MIN(tp_g/tp_roe,0.8) -> 0.2 | E15: tp_roe 用預設 0.20（股東權益為負，ROE 無意義）
A16: FY2027 | B16: =B8*(1-$B$15)*$G$8 -> 1.6999932 | C16: =C8*(1-$B$15)*$G$8 -> 1.6999932 | D16: =D8*(1-$B$15)*$G$8 -> 1.6999932
A17: FY2028 | B17: =B9*(1-$B$15)*$G$9 -> 25.001606 | C17: =C9*(1-$B$15)*$G$9 -> 25.001606 | D17: =D9*(1-$B$15)*$G$9 -> 25.001606
A18: FY2029 | B18: =B10*(1-$B$15)*$G$10 -> 26.913997 | C18: =C10*(1-$B$15)*$G$10 -> 22.577252 | D18: =D10*(1-$B$15)*$G$10 -> 18.437467
A19: FY2030 | B19: =B11*(1-$B$15)*$G$11 -> 29.156707 | C19: =C11*(1-$B$15)*$G$11 -> 25.027684 | D19: =D11*(1-$B$15)*$G$11 -> 19.819925
A20: FY2031 | B20: =B12*(1-$B$15)*$G$12 -> 31.729204 | C20: =C12*(1-$B$15)*$G$12 -> 25.977213 | D20: =D12*(1-$B$15)*$G$12 -> 18.987992
A21: FY2032 | B21: =B13*(1-$B$15)*$G$13 -> 34.673151 | C21: =C13*(1-$B$15)*$G$13 -> 26.38597 | D21: =D13*(1-$B$15)*$G$13 -> 17.748226
A22: DCF 情境每股價值（折現率 tp_r） | B22: =MAX(0,SUMPRODUCT(B16:B21,1/(1+tp_r)^$F$8:$F$13)+B21*(1+tp_g)/(tp_r-tp_g)/(1+tp_r)^$F$13) -> 481.11637 | C22: =MAX(0,SUMPRODUCT(C16:C21,1/(1+tp_r)^$F$8:$F$13)+C21*(1+tp_g)/(tp_r-tp_g)/(1+tp_r)^$F$13) -> 376.99408 | D22: =MAX(0,SUMPRODUCT(D16:D21,1/(1+tp_r)^$F$8:$F$13)+D21*(1+tp_g)/(tp_r-tp_g)/(1+tp_r)^$F$13) -> 267.43178 | E22: Σ 明確期現金流 ÷ (1＋r)^t ＋ 永續價值 ÷ (1＋r)^t；永續價值＝FY2032 現金流 ×(1＋g)÷(r−g)；基準日 2026 年底；小於 0 時取 0
A23: DCF 情境價值推到 12 個月後（×(1＋tp_r)） | B23: =B22*(1+tp_r) -> 529.22801 | C23: =C22*(1+tp_r) -> 414.69349 | D23: =D22*(1+tp_r) -> 294.17496
A24: DCF 目標價（情境加權） | B24: =tp_wA*B23+tp_wB*C23+tp_wC*D23 -> 424.95014 | E24: Σ 權重 × 情境價值 ×(1＋r)；權重見 In 頁
A26: 0.2 Comparable（市場主流同業前瞻 P/E）
A27: 同業與前瞻 P/E | B27: 代號 | C27: 前瞻 12 月 P/E | D27: 日期 | E27: 來源 | F27: 標記
A28: Hewlett Packard Enterprise | B28: HPE | C28: 12.19 | D28: 2026-10-23 | E28: stockanalysis.com forward PE（分析師共識；價格日期如左） | F28: Interested-party
A29: Super Micro Computer（美超微） | B29: SMCI | C29: 7.06 | D29: 2026-10-23 | E29: stockanalysis.com forward PE（分析師共識；價格日期如左） | F29: Interested-party
A30: Lenovo（聯想） | B30: 0992.HK | C30: 9.6 | D30: 2026-10-20 | E30: stockanalysis.com forward PE（分析師共識；價格日期如左） | F30: Interested-party
A31: HP Inc. | B31: HPQ | C31: 11.26 | D31: 2026-10-23 | E31: stockanalysis.com forward PE（分析師共識；價格日期如左） | F31: Interested-party
A32: NetApp | B32: NTAP | C32: 21.69 | D32: 2026-10-23 | E32: stockanalysis.com forward PE（分析師共識；價格日期如左） | F32: Interested-party
A33: 同業前瞻 P/E 中位數 | B33: =MEDIAN(C28:C32) -> 11.26 | E33: 伺服器、儲存與 PC 品牌同業：HPE、Supermicro、Lenovo、HP Inc.、NetApp（不含 A 股）
A34: 12 個月後的前瞻 EPS（情境加權） | B34: =tp_wA*(3/12*B9+9/12*B10)+tp_wB*(3/12*C9+9/12*C10)+tp_wC*(3/12*D9+9/12*D10) -> 29.422676 | E34: 約 2027-10 時的未來 12 月（2027-11～2028-10）EPS ≈ 3／12 × FY2028＋9／12 × FY2029（會計年度 1 月底結束，依月份調整）
A35: Comparable 目標價 | B35: =B33*B34 -> 331.29933 | E35: 同業中位數 × 前瞻 EPS
A37: 0.3 結論
A38: 項目 | B38: 數值 | C38: 對照 | D38: 對照 | E38: 說明
A39: 目標價（DCF 與 Comparable 加權） | B39: =tp_w_dcf*B24+(1-tp_w_dcf)*tp_comp_adj -> 334.49455 | E39: tp_w_dcf × DCF＋（1 − tp_w_dcf）× Comparable；tp_w_dcf 見 In 頁（0.5）
A40: Comparable 目標價（市場主流同業法） | B40: =B35 -> 331.29933
A41: 市場共識目標價 | B41: =cons_tp -> 593 | E41: stockanalysis：29 位分析師平均 593（中位數 600、最高 735、最低 480），2026-10-21；MarketScreener 29 位 593
A42: 上檔空間：加權目標價 | B42: =B39/px-1 -> -0.26716644 | E42: 現價＝In 頁 px（2026-10-23 收盤）
A43: 上檔空間：Comparable 目標價 | B43: =B40/px-1 -> -0.27416675
...

Sheet Recon
A1: Recon — 本模型 vs 公司指引、共識與組裝廠份額。只作事後對照，不為對上數字而調參數
A3: 項目 | B3: 對照值 | C3: 模型 A | D3: 差距 A | E3: 模型 B | F3: 差距 B | G3: 模型 C | H3: 差距 C | I3: 對照來源 | J3: 說明
A4: A. 共識（校準未使用）
A5: FY2027 營收 vs 共識 | B5: =c_rev27 -> 193.4 | C5: =PL!D77 -> 192 | D5: =C5/B5-1 -> -0.0072388831 | E5: =PL!D114 -> 192 | F5: =E5/B5-1 -> -0.0072388831 | G5: =PL!D151 -> 192 | H5: =G5/B5-1 -> -0.0072388831 | I5: stockanalysis（22 位，10-21） | J5: 錨點＝公司指引 1,920 億
A6: FY2027 EPS vs 共識 | B6: =c_eps27 -> 25.9 | C6: =PL!D91 -> 25.5 | D6: =C6/B6-1 -> -0.015444015 | E6: =PL!D128 -> 25.5 | F6: =E6/B6-1 -> -0.015444015 | G6: =PL!D165 -> 25.5 | H6: =G6/B6-1 -> -0.015444015 | I6: stockanalysis（22 位） | J6: 錨點＝公司指引 25.50
A7: FY2028 營收 vs 共識 | B7: =c_rev28 -> 229.12 | C7: =PL!E77 -> 249.55867 | D7: =C7/B7-1 -> 0.089205081 | E7: =PL!E114 -> 249.55867 | F7: =E7/B7-1 -> 0.089205081 | G7: =PL!E151 -> 249.55867 | H7: =G7/B7-1 -> 0.089205081 | I7: stockanalysis（Revenue Next Year）
A8: FY2028 EPS vs 共識 | B8: =c_eps28 -> 29.93 | C8: =PL!E91 -> 31.252007 | D8: =C8/B8-1 -> 0.044169975 | E8: =PL!E128 -> 31.252007 | F8: =E8/B8-1 -> 0.044169975 | G8: =PL!E165 -> 31.252007 | H8: =G8/B8-1 -> 0.044169975 | I8: stockanalysis（EPS Next Year）
A9: FY2029 EPS vs 共識 | C9: =PL!F91 -> 33.642496 | E9: =PL!F128 -> 28.221565 | G9: =PL!F165 -> 23.046834 | I9: 未找到 | J9: 共識 FY2029 EPS：未找到
A10: B. 公司指引與在手訂單
A11: FY2027 AI 伺服器營收 vs 指引 740 億 | B11: =g_ai -> 74 | C11: =PL!D70 -> 74 | D11: =C11/B11-1 -> 0 | E11: =PL!D107 -> 74 | F11: =E11/B11-1 -> 0 | G11: =PL!D144 -> 74 | H11: =G11/B11-1 -> 0 | I11: Dell 8-K 2Q FY27 | J11: 校準點（差距應為 0）
A12: FY2028 AI 伺服器營收 vs FY2027 指引 | B12: =g_ai -> 74 | C12: =PL!E70 -> 130.85444 | D12: =C12/B12-1 -> 0.76830321 | E12: =PL!E107 -> 130.85444 | F12: =E12/B12-1 -> 0.76830321 | G12: =PL!E144 -> 130.85444 | H12: =G12/B12-1 -> 0.76830321 | I12: Dell 8-K 2Q FY27 | J12: 2Q FY27 在手訂單 950 億美元；近四季訂單 1,317 億美元
A13: C. 份額與組裝廠合計（廣達、鴻海、緯創模型；唯讀）
A14: FY2027 Dell AI 營收 ÷ 組裝市場（ODM 口徑） | C14: =Units!C13 -> 0.11660585 | E14: =Units!C13 -> 0.11660585 | G14: =Units!C13 -> 0.11660585 | I14: quanta Units | J14: Dell 為 OEM 售價，同口徑時更低
A15: FY2027 ODM 三家＋Dell 合計份額（未扣重複） | C15: =Units!C15 -> 0.54679098 | E15: =Units!C15 -> 0.54679098 | G15: =Units!C15 -> 0.54679098 | I15: wistron Units | J15: 應遠低於 100%；其餘為 Supermicro、HPE、Lenovo、英業達、自建
A16: FY2028 Dell 有效份額 | C16: =PL!E69 -> 0.1118414 | E16: =PL!E106 -> 0.1118414 | G16: =PL!E143 -> 0.1118414 | I16: — | J16: 份額相對值 0.90（Assumed）
A17: FY2028 Dell AI 營收 ÷ 商用 GPU 顆數（US$K／顆） | C17: =PL!E94 -> 11.683432 | E17: =PL!E131 -> 11.683432 | G17: =PL!E168 -> 11.683432 | I17: —
A18: D. 校準
A19: FY2027 AI 伺服器營業利益率（Derived） | C19: =PL!D81 -> 0.1107101 | E19: =PL!D118 -> 0.1107101 | G19: =PL!D155 -> 0.1107101 | I19: FY2027 錨點 | J19: ISG 營業利益 − 16% × 非 AI 營收
A20: FY2026 AI 伺服器營業利益率（Derived） | C20: =PL!C81 -> 0.053807074 | E20: =PL!C118 -> 0.053807074 | G20: =PL!C155 -> 0.053807074 | I20: FY2026 實績
A21: 2H FY27 non-GAAP EPS（模型） | C21: =Q!D18 -> 13.61838 | E21: =Q!D18 -> 13.61838 | G21: =Q!D18 -> 13.61838 | I21: 3Q FY27 指引 6.50 | J21: 2H＝全年指引 − 1H 實績
A22: E. 預留
A23: R4 產業部署路徑（markets/deploy_path/，尚未建立）：上線後以部署路徑取代 tsmc 顆數 × 每顆系統價值 | J23: 預留列：本版無數值

Sheet Sens
A1: Sens — 一次動一個輸入（情境 A；Dell 份額、AI 營益率在每個案例內依 FY2027 錨點重算，FY2027 恆等於錨點）：對 FY2028、FY2029 營收、營業利益率與 EPS 的影響。每個案例是一個完整推導區塊（本頁下方）
A3: 案例 | B3: 設定 | C3: FY2028 營收 | D3: FY2028 營益率 | E3: FY2028 EPS | F3: FY2028 EPS 相對基準 | G3: FY2029 營收 | H3: FY2029 營益率 | I3: FY2029 EPS | J3: FY2029 EPS 相對基準
A4: 基準（情境 A） | B4: PL 區塊 A | C4: =PL!E77 -> 249.55867 | D4: =PL!E87 -> 0.104952 | E4: =PL!E91 -> 31.252007 | F4: =E4/E$4-1 -> 0 | G4: =PL!F77 -> 260.79803 | H4: =PL!F87 -> 0.10486755 | I4: =PL!F91 -> 33.642496 | J4: =I4/I$4-1 -> 0
A5: AI 部署 ×0.8 | B5: FY2028 起商用 GPU 顆數 ×0.8 | C5: =E59 -> 223.38778 | D5: =E69 -> 0.10544896 | E5: =E73 -> 28.107113 | F5: =E5/E$4-1 -> -0.10063014 | G5: =F59 -> 233.05601 | H5: =F69 -> 0.10536244 | I5: =F73 -> 30.205699 | J5: =I5/I$4-1 -> -0.10215641
A6: AI 部署 ×1.2 | B6: ×1.2 | C6: =E96 -> 275.72956 | D6: =E106 -> 0.10454938 | E6: =E110 -> 34.396901 | F6: =E6/E$4-1 -> 0.10063014 | G6: =F96 -> 288.54004 | H6: =F106 -> 0.10446783 | I6: =F110 -> 37.079293 | J6: =I6/I$4-1 -> 0.10215641
A7: 份額流失（低） | B7: 份額相對值 FY2028 0.75、FY2029 0.65、FY2030 0.55 | C7: =E133 -> 227.7496 | D7: =E143 -> 0.1053582 | E7: =E147 -> 28.631262 | F7: =E7/E$4-1 -> -0.08385845 | G7: =F133 -> 228.16036 | H7: =F143 -> 0.10546226 | I7: =F147 -> 29.599206 | J7: =I7/I$4-1 -> -0.12018402
A8: 份額維持（高） | B8: 份額相對值 1.05／1.0／1.0 | C8: =E170 -> 271.36774 | D8: =E180 -> 0.10461109 | E8: =E184 -> 33.872752 | F8: =E8/E$4-1 -> 0.08385845 | G8: =F170 -> 285.27628 | H8: =F180 -> 0.10451082 | I8: =F184 -> 36.674964 | J8: =I8/I$4-1 -> 0.090138013
A9: 每顆系統價值 低 | B9: GB300／VR200 機架價取橋接表低值 | C9: =E207 -> 246.65747 | D9: =E217 -> 0.1050019 | E9: =E221 -> 30.903377 | F9: =E9/E$4-1 -> -0.011155447 | G9: =F207 -> 257.15909 | H9: =F217 -> 0.10492638 | I9: =F221 -> 33.19169 | J9: =I9/I$4-1 -> -0.0133999
A10: 每顆系統價值 高 | B10: 取高值 | C10: =E244 -> 244.57714 | D10: =E254 -> 0.1050384 | E10: =E258 -> 30.653389 | F10: =E10/E$4-1 -> -0.019154572 | G10: =F244 -> 254.54976 | H10: =F254 -> 0.1049696 | I10: =F258 -> 32.868435 | J10: =I10/I$4-1 -> -0.023008432
A11: AI 營益率 −3pt | B11: FY2028 起 AI 營益率比 FY2027 低 3 個百分點 | C11: =E281 -> 249.55867 | D11: =E291 -> 0.094465136 | E11: =E295 -> 28.129288 | F11: =E11/E$4-1 -> -0.099920605 | G11: =F281 -> 260.79803 | H11: =F291 -> 0.094230192 | I11: =F295 -> 30.229932 | J11: =I11/I$4-1 -> -0.10143612
A12: AI 營益率 +1pt | B12: 高 1 個百分點 | C12: =E318 -> 249.55867 | D12: =E328 -> 0.11543887 | E12: =E332 -> 34.374727 | F12: =E12/E$4-1 -> 0.099920605 | G12: =F318 -> 260.79803 | H12: =F328 -> 0.11550491 | I12: =F332 -> 37.05506 | J12: =I12/I$4-1 -> 0.10143612
A13: 非 AI 營益率拆分 19% | B13: FY2027 拆分用 m_nai 19%（AI 營益率校準值較低） | C13: =E355 -> 249.55867 | D13: =E365 -> 0.09282124 | E13: =E369 -> 27.639778 | F13: =E13/E$4-1 -> -0.11558392 | G13: =F355 -> 260.79803 | H13: =F365 -> 0.092562705 | I13: =F369 -> 29.694986 | J13: =I13/I$4-1 -> -0.117337
A14: 非 AI ISG 營益率 低 | B14: FY2028 起 13.5% | C14: =E392 -> 249.55867 | D14: =E402 -> 0.10046683 | E14: =E406 -> 29.916438 | F14: =E14/E$4-1 -> -0.042735462 | G14: =F392 -> 260.79803 | H14: =F402 -> 0.10045878 | I14: =F406 -> 32.22812 | J14: =I14/I$4-1 -> -0.042041353
A15: 非 AI ISG 營益率 高 | B15: 17.5% | C15: =E429 -> 249.55867 | D15: =E439 -> 0.10943718 | E15: =E443 -> 32.587576 | F15: =E15/E$4-1 -> 0.042735462 | G15: =F429 -> 260.79803 | H15: =F439 -> 0.10927632 | I15: =F443 -> 35.056872 | J15: =I15/I$4-1 -> 0.042041353
A16: CSG 營益率 低 | B16: 6% | C16: =E466 -> 249.55867 | D16: =E476 -> 0.1024684 | E16: =E480 -> 30.512453 | F16: =E16/E$4-1 -> -0.023664211 | G16: =F466 -> 260.79803 | H16: =F476 -> 0.10241968 | I16: =F480 -> 32.857196 | J16: =I16/I$4-1 -> -0.023342492
A17: CSG 營益率 高 | B17: 8% | C17: =E503 -> 249.55867 | D17: =E513 -> 0.10743561 | E17: =E517 -> 31.991561 | F17: =E17/E$4-1 -> 0.023664211 | G17: =F503 -> 260.79803 | H17: =F513 -> 0.10731542 | I17: =F517 -> 34.427796 | J17: =I17/I$4-1 -> 0.023342492
A18: 傳統伺服器 低 | B18: FY2028 −15%、FY2029 −5%、FY2030 −3% | C18: =E540 -> 245.79901 | D18: =E550 -> 0.10418649 | E18: =E554 -> 30.556671 | F18: =E18/E$4-1 -> -0.022249345 | G18: =F540 -> 254.72617 | H18: =F550 -> 0.10367255 | I18: =F554 -> 32.484796 | J18: =I18/I$4-1 -> -0.034411826
A19: 傳統伺服器 高 | B19: +5%／+6%／+6% | C19: =E577 -> 253.31833 | D19: =E587 -> 0.1056948 | E19: =E591 -> 31.947344 | F19: =E19/E$4-1 -> 0.022249345 | G19: =F577 -> 266.21194 | H19: =F587 -> 0.10588709 | I19: =F591 -> 34.674748 | J19: =I19/I$4-1 -> 0.030682991
A20: PC 成長 低 | B20: FY2028 −6%、之後 −4% | C20: =E614 -> 244.14289 | D20: =E624 -> 0.10572734 | E20: =E628 -> 30.799659 | F20: =E20/E$4-1 -> -0.014474226 | G20: =F614 -> 251.26024 | H20: =F624 -> 0.10619111 | I20: =F628 -> 32.821222 | J20: =I20/I$4-1 -> -0.024411815
A21: PC 成長 高 | B21: +8%／+6%／+6% | C21: =E651 -> 252.56743 | D21: =E661 -> 0.10453563 | E21: =E665 -> 31.503312 | F21: =E21/E$4-1 -> 0.0080412366 | G21: =F651 -> 265.84673 | H21: =F661 -> 0.10420538 | I21: =F665 -> 34.077227 | J21: =I21/I$4-1 -> 0.01292209
A22: 淨利 ÷ 營業利益 0.70 | B22: FY2028 起 0.70 | C22: =E688 -> 249.55867 | D22: =E698 -> 0.104952 | E22: =E702 -> 29.16854 | F22: =E22/E$4-1 -> -0.066666667 | G22: =F688 -> 260.79803 | H22: =F698 -> 0.10486755 | I22: =F702 -> 31.399663 | J22: =I22/I$4-1 -> -0.066666667
A23: 回購 少（−1%） | B23: 股數年變動 −1% | C23: =E725 -> 249.55867 | D23: =E735 -> 0.104952 | E23: =E739 -> 30.620654 | F23: =E23/E$4-1 -> -0.02020202 | G23: =F725 -> 260.79803 | H23: =F735 -> 0.10486755 | I23: =F739 -> 32.296933 | J23: =I23/I$4-1 -> -0.039995919
A24: 情境 B | B24: CY2028 顆數 ×0.8、CY2029 ×0.85；份額 ×0.95、AI 營益率 −1pt | C24: =PL!E114 -> 249.55867 | D24: =PL!E124 -> 0.104952 | E24: =PL!E128 -> 31.252007 | F24: =E24/E$4-1 -> 0 | G24: =PL!F114 -> 227.50761 | H24: =PL!F124 -> 0.10084222 | I24: =PL!F128 -> 28.221565 | J24: =I24/I$4-1 -> -0.16113342
A25: 情境 C | B25: CY2028–29 顆數 ×0.6；份額 ×0.85、AI 營益率 −2.5pt | C25: =PL!E151 -> 249.55867 | D25: =PL!E161 -> 0.104952 | E25: =PL!E165 -> 31.252007 | F25: =E25/E$4-1 -> 0 | G25: =PL!F151 -> 192.83008 | H25: =PL!F161 -> 0.097161386 | I25: =PL!F165 -> 23.046834 | J25: =I25/I$4-1 -> -0.31494874
A27: 讀法：情境 B、C 的差異從 FY2029（CY2028）起。FY2028 EPS 主要受 Dell 份額、每顆系統價值與 AI 營益率影響；非 AI（傳統伺服器、儲存、PC）約占營業利益四成，營益率假設影響也大。每顆系統價值的變動大多被 FY2027 份額校準抵銷（只剩世代組合效果）。
A29: 目標價參數（只改 DCF 參數；PL 收斂法的 fade_g 不隨 tp_g 變動）
A30: 案例 | B30: 設定 | C30: DCF 目標價 | D30: Comparable 目標價（相對倍數調整後） | E30: 加權目標價 | F30: 相對基準
A31: 基準 | B31: r 10%、g 4%、DCF 權重 0.5 | C31: =(tp_wA*MAX(0,Val!B8*(1-MIN(tp_g/tp_roe,0.8))*Val!$G$8/(1+tp_r)^Val!$F$8+Val!B9*(1-MIN(tp_g/tp_roe,0.8))*Val!$G$9/(1+tp_r)^Val!$F$9+Val!B10*(1-MIN(tp_g/tp_roe,0.8))*Val!$G$10/(1+tp_r)^Val!$F$10+Val!B11*(1-MIN(tp_g/tp_roe,0.8))*Val!$G$11/(1+tp_r)^Val!$F$11+Val!B12*(1-MIN(tp_g/tp_roe,0.8))*Val!$G$12/(1+tp_r)^Val!$F$12+Val!B13*(1-MIN(tp_g/tp_roe,0.8))*Val!$G$13/(1+tp_r)^Val!$F$13+Val!B13*(1-MIN(tp_g/tp_roe,0.8))*Val!$G$13*(1+tp_g)/(tp_r-tp_g)/(1+tp_r)^Val!$F$13)+tp_wB*MAX(0,Val!C8*(1-MIN(tp_g/tp_roe,0.8))*Val!$G$8/(1+tp_r)^Val!$F$8+Val!C9*(1-MIN(tp_g/tp_roe,0.8))*Val!$G$9/(1+tp_r)^Val!$F$9+Val!C10*(1-MIN(tp_g/tp_roe,0.8))*Val!$G$10/(1+tp_r)^Val!$F$10+Val!C11*(1-MIN(tp_g/tp_roe,0.8))*Val!$G$11/(1+tp_r)^Val!$F$11+Val!C12*(1-MIN(tp_g/tp_roe,0.8))*Val!$G$12/(1+tp_r)^Val!$F$12+Val!C13*(1-MIN(tp_g/tp_roe,0.8))*Val!$G$13/(1+tp_r)^Val!$F$13+Val!C13*(1-MIN(tp_g/tp_roe,0.8))*Val!$G$13*(1+tp_g)/(tp_r-tp_g)/(1+tp_r)^Val!$F$13)+tp_wC*MAX(0,Val!D8*(1-MIN(tp_g/tp_roe,0.8))*Val!$G$8/(1+tp_r)^Val!$F$8+Val!D9*(1-MIN(tp_g/tp_roe,0.8))*Val!$G$9/(1+tp_r)^Val!$F$9+Val!D10*(1-MIN(tp_g/tp_roe,0.8))*Val!$G$10/(1+tp_r)^Val!$F$10+Val!D11*(1-MIN(tp_g/tp_roe,0.8))*Val!$G$11/(1+tp_r)^Val!$F$11+Val!D12*(1-MIN(tp_g/tp_roe,0.8))*Val!$G$12/(1+tp_r)^Val!$F$12+Val!D13*(1-MIN(tp_g/tp_roe,0.8))*Val!$G$13/(1+tp_r)^Val!$F$13+Val!D13*(1-MIN(tp_g/tp_roe,0.8))*Val!$G$13*(1+tp_g)/(tp_r-tp_g)/(1+tp_r)^Val!$F$13))*(1+tp_r) -> 424.95014 | D31: =tp_comp_adj -> 244.03896 | E31: =tp_w_dcf*C31+(1-tp_w_dcf)*D31 -> 334.49455 | F31: =E31/E$31-1 -> 0
A32: 折現率 +1pt | B32: r 11% | C32: =(tp_wA*MAX(0,Val!B8*(1-MIN(tp_g/tp_roe,0.8))*Val!$G$8/(1+(tp_r+0.01))^Val!$F$8+Val!B9*(1-MIN(tp_g/tp_roe,0.8))*Val!$G$9/(1+(tp_r+0.01))^Val!$F$9+Val!B10*(1-MIN(tp_g/tp_roe,0.8))*Val!$G$10/(1+(tp_r+0.01))^Val!$F$10+Val!B11*(1-MIN(tp_g/tp_roe,0.8))*Val!$G$11/(1+(tp_r+0.01))^Val!$F$11+Val!B12*(1-MIN(tp_g/tp_roe,0.8))*Val!$G$12/(1+(tp_r+0.01))^Val!$F$12+Val!B13*(1-MIN(tp_g/tp_roe,0.8))*Val!$G$13/(1+(tp_r+0.01))^Val!$F$13+Val!B13*(1-MIN(tp_g/tp_roe,0.8))*Val!$G$13*(1+tp_g)/((tp_r+0.01)-tp_g)/(1+(tp_r+0.01))^Val!$F$13)+tp_wB*MAX(0,Val!C8*(1-MIN(tp_g/tp_roe,0.8))*Val!$G$8/(1+(tp_r+0.01))^Val!$F$8+Val!C9*(1-MIN(tp_g/tp_roe,0.8))*Val!$G$9/(1+(tp_r+0.01))^Val!$F$9+Val!C10*(1-MIN(tp_g/tp_roe,0.8))*Val!$G$10/(1+(tp_r+0.01))^Val!$F$10+Val!C11*(1-MIN(tp_g/tp_roe,0.8))*Val!$G$11/(1+(tp_r+0.01))^Val!$F$11+Val!C12*(1-MIN(tp_g/tp_roe,0.8))*Val!$G$12/(1+(tp_r+0.01))^Val!$F$12+Val!C13*(1-MIN(tp_g/tp_roe,0.8))*Val!$G$13/(1+(tp_r+0.01))^Val!$F$13+Val!C13*(1-MIN(tp_g/tp_roe,0.8))*Val!$G$13*(1+tp_g)/((tp_r+0.01)-tp_g)/(1+(tp_r+0.01))^Val!$F$13)+tp_wC*MAX(0,Val!D8*(1-MIN(tp_g/tp_roe,0.8))*Val!$G$8/(1+(tp_r+0.01))^Val!$F$8+Val!D9*(1-MIN(tp_g/tp_roe,0.8))*Val!$G$9/(1+(tp_r+0.01))^Val!$F$9+Val!D10*(1-MIN(tp_g/tp_roe,0.8))*Val!$G$10/(1+(tp_r+0.01))^Val!$F$10+Val!D11*(1-MIN(tp_g/tp_roe,0.8))*Val!$G$11/(1+(tp_r+0.01))^Val!$F$11+Val!D12*(1-MIN(tp_g/tp_roe,0.8))*Val!$G$12/(1+(tp_r+0.01))^Val!$F$12+Val!D13*(1-MIN(tp_g/tp_roe,0.8))*Val!$G$13/(1+(tp_r+0.01))^Val!$F$13+Val!D13*(1-MIN(tp_g/tp_roe,0.8))*Val!$G$13*(1+tp_g)/((tp_r+0.01)-tp_g)/(1+(tp_r+0.01))^Val!$F$13))*(1+(tp_r+0.01)) -> 367.69118 | D32: =tp_comp_adj -> 244.03896 | E32: =tp_w_dcf*C32+(1-tp_w_dcf)*D32 -> 305.86507 | F32: =E32/E$31-1 -> -0.085590278
A33: 折現率 −1pt | B33: r 9% | C33: =(tp_wA*MAX(0,Val!B8*(1-MIN(tp_g/tp_roe,0.8))*Val!$G$8/(1+(tp_r-0.01))^Val!$F$8+Val!B9*(1-MIN(tp_g/tp_roe,0.8))*Val!$G$9/(1+(tp_r-0.01))^Val!$F$9+Val!B10*(1-MIN(tp_g/tp_roe,0.8))*Val!$G$10/(1+(tp_r-0.01))^Val!$F$10+Val!B11*(1-MIN(tp_g/tp_roe,0.8))*Val!$G$11/(1+(tp_r-0.01))^Val!$F$11+Val!B12*(1-MIN(tp_g/tp_roe,0.8))*Val!$G$12/(1+(tp_r-0.01))^Val!$F$12+Val!B13*(1-MIN(tp_g/tp_roe,0.8))*Val!$G$13/(1+(tp_r-0.01))^Val!$F$13+Val!B13*(1-MIN(tp_g/tp_roe,0.8))*Val!$G$13*(1+tp_g)/((tp_r-0.01)-tp_g)/(1+(tp_r-0.01))^Val!$F$13)+tp_wB*MAX(0,Val!C8*(1-MIN(tp_g/tp_roe,0.8))*Val!$G$8/(1+(tp_r-0.01))^Val!$F$8+Val!C9*(1-MIN(tp_g/tp_roe,0.8))*Val!$G$9/(1+(tp_r-0.01))^Val!$F$9+Val!C10*(1-MIN(tp_g/tp_roe,0.8))*Val!$G$10/(1+(tp_r-0.01))^Val!$F$10+Val!C11*(1-MIN(tp_g/tp_roe,0.8))*Val!$G$11/(1+(tp_r-0.01))^Val!$F$11+Val!C12*(1-MIN(tp_g/tp_roe,0.8))*Val!$G$12/(1+(tp_r-0.01))^Val!$F$12+Val!C13*(1-MIN(tp_g/tp_roe,0.8))*Val!$G$13/(1+(tp_r-0.01))^Val!$F$13+Val!C13*(1-MIN(tp_g/tp_roe,0.8))*Val!$G$13*(1+tp_g)/((tp_r-0.01)-tp_g)/(1+(tp_r-0.01))^Val!$F$13)+tp_wC*MAX(0,Val!D8*(1-MIN(tp_g/tp_roe,0.8))*Val!$G$8/(1+(tp_r-0.01))^Val!$F$8+Val!D9*(1-MIN(tp_g/tp_roe,0.8))*Val!$G$9/(1+(tp_r-0.01))^Val!$F$9+Val!D10*(1-MIN(tp_g/tp_roe,0.8))*Val!$G$10/(1+(tp_r-0.01))^Val!$F$10+Val!D11*(1-MIN(tp_g/tp_roe,0.8))*Val!$G$11/(1+(tp_r-0.01))^Val!$F$11+Val!D12*(1-MIN(tp_g/tp_roe,0.8))*Val!$G$12/(1+(tp_r-0.01))^Val!$F$12+Val!D13*(1-MIN(tp_g/tp_roe,0.8))*Val!$G$13/(1+(tp_r-0.01))^Val!$F$13+Val!D13*(1-MIN(tp_g/tp_roe,0.8))*Val!$G$13*(1+tp_g)/((tp_r-0.01)-tp_g)/(1+(tp_r-0.01))^Val!$F$13))*(1+(tp_r-0.01)) -> 505.11651 | D33: =tp_comp_adj -> 244.03896 | E33: =tp_w_dcf*C33+(1-tp_w_dcf)*D33 -> 374.57774 | F33: =E33/E$31-1 -> 0.1198321
A34: 長期成長 +1pt | B34: g 5% | C34: =(tp_wA*MAX(0,Val!B8*(1-MIN((tp_g+0.01)/tp_roe,0.8))*Val!$G$8/(1+tp_r)^Val!$F$8+Val!B9*(1-MIN((tp_g+0.01)/tp_roe,0.8))*Val!$G$9/(1+tp_r)^Val!$F$9+Val!B10*(1-MIN((tp_g+0.01)/tp_roe,0.8))*Val!$G$10/(1+tp_r)^Val!$F$10+Val!B11*(1-MIN((tp_g+0.01)/tp_roe,0.8))*Val!$G$11/(1+tp_r)^Val!$F$11+Val!B12*(1-MIN((tp_g+0.01)/tp_roe,0.8))*Val!$G$12/(1+tp_r)^Val!$F$12+Val!B13*(1-MIN((tp_g+0.01)/tp_roe,0.8))*Val!$G$13/(1+tp_r)^Val!$F$13+Val!B13*(1-MIN((tp_g+0.01)/tp_roe,0.8))*Val!$G$13*(1+(tp_g+0.01))/(tp_r-(tp_g+0.01))/(1+tp_r)^Val!$F$13)+tp_wB*MAX(0,Val!C8*(1-MIN((tp_g+0.01)/tp_roe,0.8))*Val!$G$8/(1+tp_r)^Val!$F$8+Val!C9*(1-MIN((tp_g+0.01)/tp_roe,0.8))*Val!$G$9/(1+tp_r)^Val!$F$9+Val!C10*(1-MIN((tp_g+0.01)/tp_roe,0.8))*Val!$G$10/(1+tp_r)^Val!$F$10+Val!C11*(1-MIN((tp_g+0.01)/tp_roe,0.8))*Val!$G$11/(1+tp_r)^Val!$F$11+Val!C12*(1-MIN((tp_g+0.01)/tp_roe,0.8))*Val!$G$12/(1+tp_r)^Val!$F$12+Val!C13*(1-MIN((tp_g+0.01)/tp_roe,0.8))*Val!$G$13/(1+tp_r)^Val!$F$13+Val!C13*(1-MIN((tp_g+0.01)/tp_roe,0.8))*Val!$G$13*(1+(tp_g+0.01))/(tp_r-(tp_g+0.01))/(1+tp_r)^Val!$F$13)+tp_wC*MAX(0,Val!D8*(1-MIN((tp_g+0.01)/tp_roe,0.8))*Val!$G$8/(1+tp_r)^Val!$F$8+Val!D9*(1-MIN((tp_g+0.01)/tp_roe,0.8))*Val!$G$9/(1+tp_r)^Val!$F$9+Val!D10*(1-MIN((tp_g+0.01)/tp_roe,0.8))*Val!$G$10/(1+tp_r)^Val!$F$10+Val!D11*(1-MIN((tp_g+0.01)/tp_roe,0.8))*Val!$G$11/(1+tp_r)^Val!$F$11+Val!D12*(1-MIN((tp_g+0.01)/tp_roe,0.8))*Val!$G$12/(1+tp_r)^Val!$F$12+Val!D13*(1-MIN((tp_g+0.01)/tp_roe,0.8))*Val!$G$13/(1+tp_r)^Val!$F$13+Val!D13*(1-MIN((tp_g+0.01)/tp_roe,0.8))*Val!$G$13*(1+(tp_g+0.01))/(tp_r-(tp_g+0.01))/(1+tp_r)^Val!$F$13))*(1+tp_r) -> 461.6182 | D34: =tp_comp_adj -> 244.03896 | E34: =tp_w_dcf*C34+(1-tp_w_dcf)*D34 -> 352.82858 | F34: =E34/E$31-1 -> 0.054811151
A35: 長期成長 −1pt | B35: g 3% | C35: =(tp_wA*MAX(0,Val!B8*(1-MIN((tp_g-0.01)/tp_roe,0.8))*Val!$G$8/(1+tp_r)^Val!$F$8+Val!B9*(1-MIN((tp_g-0.01)/tp_roe,0.8))*Val!$G$9/(1+tp_r)^Val!$F$9+Val!B10*(1-MIN((tp_g-0.01)/tp_roe,0.8))*Val!$G$10/(1+tp_r)^Val!$F$10+Val!B11*(1-MIN((tp_g-0.01)/tp_roe,0.8))*Val!$G$11/(1+tp_r)^Val!$F$11+Val!B12*(1-MIN((tp_g-0.01)/tp_roe,0.8))*Val!$G$12/(1+tp_r)^Val!$F$12+Val!B13*(1-MIN((tp_g-0.01)/tp_roe,0.8))*Val!$G$13/(1+tp_r)^Val!$F$13+Val!B13*(1-MIN((tp_g-0.01)/tp_roe,0.8))*Val!$G$13*(1+(tp_g-0.01))/(tp_r-(tp_g-0.01))/(1+tp_r)^Val!$F$13)+tp_wB*MAX(0,Val!C8*(1-MIN((tp_g-0.01)/tp_roe,0.8))*Val!$G$8/(1+tp_r)^Val!$F$8+Val!C9*(1-MIN((tp_g-0.01)/tp_roe,0.8))*Val!$G$9/(1+tp_r)^Val!$F$9+Val!C10*(1-MIN((tp_g-0.01)/tp_roe,0.8))*Val!$G$10/(1+tp_r)^Val!$F$10+Val!C11*(1-MIN((tp_g-0.01)/tp_roe,0.8))*Val!$G$11/(1+tp_r)^Val!$F$11+Val!C12*(1-MIN((tp_g-0.01)/tp_roe,0.8))*Val!$G$12/(1+tp_r)^Val!$F$12+Val!C13*(1-MIN((tp_g-0.01)/tp_roe,0.8))*Val!$G$13/(1+tp_r)^Val!$F$13+Val!C13*(1-MIN((tp_g-0.01)/tp_roe,0.8))*Val!$G$13*(1+(tp_g-0.01))/(tp_r-(tp_g-0.01))/(1+tp_r)^Val!$F$13)+tp_wC*MAX(0,Val!D8*(1-MIN((tp_g-0.01)/tp_roe,0.8))*Val!$G$8/(1+tp_r)^Val!$F$8+Val!D9*(1-MIN((tp_g-0.01)/tp_roe,0.8))*Val!$G$9/(1+tp_r)^Val!$F$9+Val!D10*(1-MIN((tp_g-0.01)/tp_roe,0.8))*Val!$G$10/(1+tp_r)^Val!$F$10+Val!D11*(1-MIN((tp_g-0.01)/tp_roe,0.8))*Val!$G$11/(1+tp_r)^Val!$F$11+Val!D12*(1-MIN((tp_g-0.01)/tp_roe,0.8))*Val!$G$12/(1+tp_r)^Val!$F$12+Val!D13*(1-MIN((tp_g-0.01)/tp_roe,0.8))*Val!$G$13/(1+tp_r)^Val!$F$13+Val!D13*(1-MIN((tp_g-0.01)/tp_roe,0.8))*Val!$G$13*(1+(tp_g-0.01))/(tp_r-(tp_g-0.01))/(1+tp_r)^Val!$F$13))*(1+tp_r) -> 400.3254 | D35: =tp_comp_adj -> 244.03896 | E35: =tp_w_dcf*C35+(1-tp_w_dcf)*D35 -> 322.18218 | F35: =E35/E$31-1 -> -0.03680888
A36: DCF 權重 0.3 | C36: =(tp_wA*MAX(0,Val!B8*(1-MIN(tp_g/tp_roe,0.8))*Val!$G$8/(1+tp_r)^Val!$F$8+Val!B9*(1-MIN(tp_g/tp_roe,0.8))*Val!$G$9/(1+tp_r)^Val!$F$9+Val!B10*(1-MIN(tp_g/tp_roe,0.8))*Val!$G$10/(1+tp_r)^Val!$F$10+Val!B11*(1-MIN(tp_g/tp_roe,0.8))*Val!$G$11/(1+tp_r)^Val!$F$11+Val!B12*(1-MIN(tp_g/tp_roe,0.8))*Val!$G$12/(1+tp_r)^Val!$F$12+Val!B13*(1-MIN(tp_g/tp_roe,0.8))*Val!$G$13/(1+tp_r)^Val!$F$13+Val!B13*(1-MIN(tp_g/tp_roe,0.8))*Val!$G$13*(1+tp_g)/(tp_r-tp_g)/(1+tp_r)^Val!$F$13)+tp_wB*MAX(0,Val!C8*(1-MIN(tp_g/tp_roe,0.8))*Val!$G$8/(1+tp_r)^Val!$F$8+Val!C9*(1-MIN(tp_g/tp_roe,0.8))*Val!$G$9/(1+tp_r)^Val!$F$9+Val!C10*(1-MIN(tp_g/tp_roe,0.8))*Val!$G$10/(1+tp_r)^Val!$F$10+Val!C11*(1-MIN(tp_g/tp_roe,0.8))*Val!$G$11/(1+tp_r)^Val!$F$11+Val!C12*(1-MIN(tp_g/tp_roe,0.8))*Val!$G$12/(1+tp_r)^Val!$F$12+Val!C13*(1-MIN(tp_g/tp_roe,0.8))*Val!$G$13/(1+tp_r)^Val!$F$13+Val!C13*(1-MIN(tp_g/tp_roe,0.8))*Val!$G$13*(1+tp_g)/(tp_r-tp_g)/(1+tp_r)^Val!$F$13)+tp_wC*MAX(0,Val!D8*(1-MIN(tp_g/tp_roe,0.8))*Val!$G$8/(1+tp_r)^Val!$F$8+Val!D9*(1-MIN(tp_g/tp_roe,0.8))*Val!$G$9/(1+tp_r)^Val!$F$9+Val!D10*(1-MIN(tp_g/tp_roe,0.8))*Val!$G$10/(1+tp_r)^Val!$F$10+Val!D11*(1-MIN(tp_g/tp_roe,0.8))*Val!$G$11/(1+tp_r)^Val!$F$11+Val!D12*(1-MIN(tp_g/tp_roe,0.8))*Val!$G$12/(1+tp_r)^Val!$F$12+Val!D13*(1-MIN(tp_g/tp_roe,0.8))*Val!$G$13/(1+tp_r)^Val!$F$13+Val!D13*(1-MIN(tp_g/tp_roe,0.8))*Val!$G$13*(1+tp_g)/(tp_r-tp_g)/(1+tp_r)^Val!$F$13))*(1+tp_r) -> 424.95014 | D36: =tp_comp_adj -> 244.03896 | E36: =0.3*C36+(1-0.3)*D36 -> 298.31231 | F36: =E36/E$31-1 -> -0.10816988
A37: DCF 權重 0.7 | C37: =(tp_wA*MAX(0,Val!B8*(1-MIN(tp_g/tp_roe,0.8))*Val!$G$8/(1+tp_r)^Val!$F$8+Val!B9*(1-MIN(tp_g/tp_roe,0.8))*Val!$G$9/(1+tp_r)^Val!$F$9+Val!B10*(1-MIN(tp_g/tp_roe,0.8))*Val!$G$10/(1+tp_r)^Val!$F$10+Val!B11*(1-MIN(tp_g/tp_roe,0.8))*Val!$G$11/(1+tp_r)^Val!$F$11+Val!B12*(1-MIN(tp_g/tp_roe,0.8))*Val!$G$12/(1+tp_r)^Val!$F$12+Val!B13*(1-MIN(tp_g/tp_roe,0.8))*Val!$G$13/(1+tp_r)^Val!$F$13+Val!B13*(1-MIN(tp_g/tp_roe,0.8))*Val!$G$13*(1+tp_g)/(tp_r-tp_g)/(1+tp_r)^Val!$F$13)+tp_wB*MAX(0,Val!C8*(1-MIN(tp_g/tp_roe,0.8))*Val!$G$8/(1+tp_r)^Val!$F$8+Val!C9*(1-MIN(tp_g/tp_roe,0.8))*Val!$G$9/(1+tp_r)^Val!$F$9+Val!C10*(1-MIN(tp_g/tp_roe,0.8))*Val!$G$10/(1+tp_r)^Val!$F$10+Val!C11*(1-MIN(tp_g/tp_roe,0.8))*Val!$G$11/(1+tp_r)^Val!$F$11+Val!C12*(1-MIN(tp_g/tp_roe,0.8))*Val!$G$12/(1+tp_r)^Val!$F$12+Val!C13*(1-MIN(tp_g/tp_roe,0.8))*Val!$G$13/(1+tp_r)^Val!$F$13+Val!C13*(1-MIN(tp_g/tp_roe,0.8))*Val!$G$13*(1+tp_g)/(tp_r-tp_g)/(1+tp_r)^Val!$F$13)+tp_wC*MAX(0,Val!D8*(1-MIN(tp_g/tp_roe,0.8))*Val!$G$8/(1+tp_r)^Val!$F$8+Val!D9*(1-MIN(tp_g/tp_roe,0.8))*Val!$G$9/(1+tp_r)^Val!$F$9+Val!D10*(1-MIN(tp_g/tp_roe,0.8))*Val!$G$10/(1+tp_r)^Val!$F$10+Val!D11*(1-MIN(tp_g/tp_roe,0.8))*Val!$G$11/(1+tp_r)^Val!$F$11+Val!D12*(1-MIN(tp_g/tp_roe,0.8))*Val!$G$12/(1+tp_r)^Val!$F$12+Val!D13*(1-MIN(tp_g/tp_roe,0.8))*Val!$G$13/(1+tp_r)^Val!$F$13+Val!D13*(1-MIN(tp_g/tp_roe,0.8))*Val!$G$13*(1+tp_g)/(tp_r-tp_g)/(1+tp_r)^Val!$F$13))*(1+tp_r) -> 424.95014 | D37: =tp_comp_adj -> 244.03896 | E37: =0.7*C37+(1-0.7)*D37 -> 370.67679 | F37: =E37/E$31-1 -> 0.10816988
A42: 案例區塊：AI 部署 ×0.8（情境 A）
A43: 項目 | B43: 單位 | C43: FY2026A | D43: FY2027（錨點） | E43: FY2028 | F43: FY2029 | G43: FY2030 | H43: FY2031（收斂） | I43: FY2032（收斂） | J43: 說明
A44: A. 商用 GPU 系統市場與 Dell 份額（D 欄＝FY2027 校準年≈CY2026；E–G＝FY2028–FY2030≈CY2027–29）
A45: GB300 級 GPU 顆數 × 情境係數 | B45: 百萬顆 | D45: =ug_26 -> 6.65 | E45: =ug_27*mf_lo -> 1.92 | F45: =ug_28*um28_A*mf_lo -> 0.4 | G45: =ug_29*um29_A*mf_lo -> 0.2
A46: VR200 級 GPU 顆數 × 情境係數 | B46: 百萬顆 | D46: =uv_26 -> 1.7 | E46: =uv_27*mf_lo -> 7.04 | F46: =uv_28*um28_A*mf_lo -> 8.8 | G46: =uv_29*um29_A*mf_lo -> 10.12
A47: 商用 GPU 系統市場（顆數 × 每顆系統價值） | B47: US$B | D47: =D45*v_gb+D46*v_vr -> 595.48611 | E47: =E45*v_gb+E46*v_vr -> 936 | F47: =F45*v_gb+F46*v_vr -> 1050.5556 | G47: =G45*v_gb+G46*v_vr -> 1192.6111 | J47: 百萬顆 × 千美元／顆＝十億美元；ASIC（TPU、Trainium 等）不含
...

Sheet Sources
A1: 來源（公司原文為 SEC 8-K 附件 99.1；指引為 Interested-party；券商與資料商皆為 Interested-party）
A2: 公司：8-K 4Q FY26（FY2026 全年實績、分部、FY27 初始指引；股東權益） | B2: https://www.sec.gov/Archives/edgar/data/1571996/000157199626000003/exhibit991earnings8kq4fy26.htm
A3: 公司：8-K 1Q FY27（1Q 實績、分部、上修指引；股東權益） | B3: https://www.sec.gov/Archives/edgar/data/0001571996/000157199626000021/exhibit991earnings8kq1fy27.htm
A4: 公司：8-K 2Q FY27（2Q、1H 實績、分部、3Q 與全年指引；股東權益） | B4: https://www.sec.gov/Archives/edgar/data/0001571996/000157199626000039/exhibit991earnings8kq2fy27.htm
A5: 媒體：Pulse 2.0 2026-09-01（AI 訂單、在手訂單、近四季訂單、自由現金流） | B5: https://pulse2.com/dell-technologies-q2-revenue-hits-record-47-billion-as-ai-server-backlog-reaches-95-billion-and-fy27-outlook-rises-to-192-billion/
A6: 媒體：StorageNewsletter 2026-09-03（儲存全年約 200 億、3Q 儲存與 ISG 成長） | B6: https://www.storagenewsletter.com/2026/09/03/dell-technologies-fiscal-2q27-financial-results/
A7: 媒體：Zacks 2026-09（non-GAAP 毛利率、指引區間、回購） | B7: https://www.zacks.com/stock/news/2984030/dell-q2-earnings-beat-estimates-strong-ai-demand-aids-revenue-growth
A8: 資料商：stockanalysis 統計（價格、股數、P/E、前瞻 P/E） | B8: https://stockanalysis.com/stocks/dell/statistics/
A9: 資料商：stockanalysis 預估（共識 EPS、營收、目標價） | B9: https://stockanalysis.com/stocks/dell/forecast/
A10: 資料商：MarketScreener（10-23 收盤、目標價 29 位） | B10: https://uk.marketscreener.com/quote/stock/DELL-TECHNOLOGIES-INC-50061235/consensus/
A11: 資料商：Alpha Spread（目標價 599.25） | B11: https://alphaspread.com/security/nyse/dell/analyst-estimates
A12: 資料商：Investing.com（目標價 23 位 502.78） | B12: https://www.investing.com/equities/dell-inc-consensus-estimates
A13: 資料商：companiesmarketcap 年底 P/E | B13: https://companiesmarketcap.com/dell/pe-ratio/
... A18: SemiAnalysis | B18: 未使用
