Workbook

Sheet 導覽
A1: Oracle 收支與評價模型 — Excel 版 v0.2（更新 2026-10-08；與 HTML v0.2 同步；市價截至 2026-10-06 收盤）
A3: 這個活頁簿在回答什麼
A4: 一句話：客戶預付與投資級債能否把 $664B RPO 變成現金、而不需再發股——Oracle 用客戶預付款支應多少擴張資本支出，剩下的缺口要靠多少債務與新股。
A5: 所有分頁用同一組數字，改任何一個輸入，後面全部會跟著動。
A7: 分頁結構（依模組分組，分頁標籤顏色相同者為同一模組）
A8: 摘要 一頁摘要：結論、與市場共識的差異、現價隱含什麼、驗證點（全部活公式）。
A9: 輸入與假設 所有可調參數（A 情境 → B 產能與收入 → C 利潤率 → D 支出 → E 融資 → F 評價 → G 1Q 實際 → H 情境區間運算表 → I 市場共識 → J 季度追蹤輸入）。
A10: 各期收支 類現金流量：來源（含客戶預付）、用途、融資前缺口、期前融資瀑布。
A11: 季度追蹤 焦點季的模型／共識／指引／實際與差距（由年度模型拆分，只用於追蹤；實際數填在輸入與假設 J 區）。
A12: 運營_產能與收入 已連網 MW → 在役 MW → 營收（MW × 每 MW 年收入 × 利用率）；RPO 排程只作對照與產能瓶頸旗標。
A13: 資產負債_既有債務／新債與新股／租賃承諾 類資產負債表：季報債務明細、每期現金與總債務與股數、租賃承諾。
A14: 損益 類損益表（FY27＝1Q 實際＋第 2–4 季模型）。
... A42: DCF 以融資後股數計每股，並加回新股募得現金的現值；EV/EBITDA 用錨定年末淨負債與錨定年末股數。

Sheet 摘要
A1: 一頁摘要 — 結論、與市場的差異、現價隱含什麼、驗證點（全部依輸入連動）
A2: ="模型端＝目前情境：" & CHOOSE(輸入與假設!$C$5,"保守 OpenAI 相關 60%","基準 已簽約站點依 Q1 速度","積極 依公司時程") & "（預設＝基準）；共識＝data/consensus_orcl_20261007.json（2026-10-07）" -> 模型端＝目前情境：基準 已簽約站點依 Q1 速度（預設＝基準）；共識＝data/consensus_orcl_20261007.json（2026-10-07）
A4: 1｜結論
A5: 結論｜評等代碼（1＝買進、0＝中立、−1＝賣出） | C5: =評價_DCF與目標價!C78 -> 0
A6: 結論｜評等 | C6: =CHOOSE(C5+2,"賣出","中立","買進") -> 中立
A7: 結論｜點位（加權目標價） | B7: US$ | C7: =評價_DCF與目標價!C51 -> 133.90498
A8: 結論｜現價 | B8: US$ | C8: =輸入與假設!$C$175 -> 144.77
A9: 結論｜空間 | B9: % | C9: =C7/C8-1 -> -0.075050216
A10: 結論｜情境區間（下緣／上緣） | B10: US$ | C10: =評價_DCF與目標價!C83 -> 73.988812 | D10: =評價_DCF與目標價!D83 -> 226.60959
A11: 結論｜方法區間（下緣／上緣） | B11: US$ | C11: =評價_DCF與目標價!C85 -> 124.83641 | D11: =評價_DCF與目標價!D85 -> 133.90498
A12: 結論｜賣出門檻價 | B12: US$ | C12: =評價_DCF與目標價!$C$79 -> 123.0545
A13: 結論｜點位 − 賣出門檻 | B13: US$ | C13: =C7-C12 -> 10.85048
A14: 結論｜結論句 | C14: =C6&"：點位 $"&TEXT(C7,"0.0")&"，較現價 $"&TEXT(C8,"0.00")&" "&IF(C9>=0,"高","低")&" "&TEXT(ABS(C9)*100,"0")&"%；情境區間 $"&TEXT(C10,"0.0")&"–$"&TEXT(D10,"0.0")&"，方法區間 $"&TEXT(C11,"0.0")&"–$"&TEXT(D11,"0.0")&"；點位"&IF(C13<0,"低於","高於")&"賣出門檻 $"&TEXT(C12,"0.0")&" 達 $"&TEXT(ABS(C13),"0.0")&"。" -> 中立：點位 $133.9，較現價 $144.77 低 8%；情境區間 $74.0–$226.6，方法區間 $124.8–$133.9；點位高於賣出門檻 $123.1 達 $10.9。
A15: 結論｜情境判斷句 | C15: =評價_DCF與目標價!C91 -> 情境區間上緣 $226.6 不低於現價 $144.77：賣出並非在三個擴張情境下都成立。
A16: 結論｜投資級句 | C16: =IF(OR(輸入與假設!$C$146="ebitda",輸入與假設!$C$146="leaseAdj"),"需失去投資級才能融資的金額："&IF(SUM(各期收支!C85:G85)>0.05,"$"&TEXT(SUM(各期收支!C85:G85),"0.0")&"bn（五期高息債溢出）","$0")&"；投資級上限＝"&IF(輸入與假設!$C$146="leaseAdj","(總債務＋租賃負債) ≤ "&IF(輸入與假設!$C$147=INT(輸入與假設!$C$147),TEXT(輸入與假設!$C$147,"0"),TEXT(輸入與假設!$C$147,"0.0"))&"×(EBITDA＋租金)","總債務 ≤ "&IF(輸入與假設!$C$147=INT(輸入與假設!$C$147),TEXT(輸入與假設!$C$147,"0"),TEXT(輸入與假設!$C$147,"0.0"))&"× 當期 EBITDA")&"，股權每年 ≤ 現市值 "&IF(ROUND(ABS(輸入與假設!$C$154)*100,4)=INT(ROUND(ABS(輸入與假設!$C$154)*100,4)),TEXT(ROUND(ABS(輸入與假設!$C$154)*100,4),"0"),TEXT(ROUND(ABS(輸入與假設!$C$154)*100,4),"0.0"))&"%"&"。","") -> 需失去投資級才能融資的金額：$0；投資級上限＝(總債務＋租賃負債) ≤ 4.5×(EBITDA＋租金)，股權每年 ≤ 現市值 5%。
A17: 結論｜調整後槓桿句 | C17: ="調整後槓桿（(債務＋租賃負債) ÷ (EBITDA＋租金)）路徑 "&TEXT(資產負債_新債與新股!C36,"0.0")&"／"&TEXT(資產負債_新債與新股!D36,"0.0")&"／"&TEXT(資產負債_新債與新股!E36,"0.0")&"／"&TEXT(資產負債_新債與新股!F36,"0.0")&"／"&TEXT(資產負債_新債與新股!G36,"0.0")&"×；上限 "&IF(輸入與假設!$C$147=INT(輸入與假設!$C$147),TEXT(輸入與假設!$C$147,"0"),TEXT(輸入與假設!$C$147,"0.0"))&"×，"&IF(MAX(資產負債_新債與新股!$C$36:$G$36)>輸入與假設!$C$147+0.000000001,CHOOSE(MATCH(MAX(資產負債_新債與新股!$C$36:$G$36),資產負債_新債與新股!$C$36:$G$36,0),"FY27","FY28","FY29","FY30","FY31")&" 超過 "&TEXT(MAX(資產負債_新債與新股!$C$36:$G$36)-輸入與假設!$C$147,"0.0")&"×：需股權或失去投資級。","最小空間 "&TEXT(輸入與假設!$C$147-MAX(資產負債_新債與新股!$C$36:$G$36),"0.0")&"×（"&CHOOSE(MATCH(MAX(資產負債_新債與新股!$C$36:$G$36),資產負債_新債與新股!$C$36:$G$36,0),"FY27","FY28","FY29","FY30","FY31")&"）。") -> 調整後槓桿（(債務＋租賃負債) ÷ (EBITDA＋租金)）路徑 3.6／3.5／3.1／2.8／2.7×；上限 4.5×，最小空間 0.9×（FY27）。
A18: 結論｜延誤句 | C18: =IF(運營_產能與收入!$C$50>0,"建設延誤 "&IF(運營_產能與收入!$C$50=INT(運營_產能與收入!$C$50),TEXT(運營_產能與收入!$C$50,"0"),TEXT(運營_產能與收入!$C$50,"0.0"))&" 個月（GPU 資本支出照原時程）：閒置資本（已支出、尚未產生收入）峰值 $"&TEXT(MAX(運營_產能與收入!$C$55:$G$55),"0.0")&"bn（"&CHOOSE(MATCH(MAX(運營_產能與收入!$C$55:$G$55),運營_產能與收入!$C$55:$G$55,0),"FY27","FY28","FY29","FY30","FY31")&" 末）。","建設延誤：本情境 0 個月（無閒置資本）。") -> 建設延誤 3 個月（GPU 資本支出照原時程）：閒置資本（已支出、尚未產生收入）峰值 $25.9bn（FY27 末）。
A20: 2｜與市場的差異（模型：目前情境 vs 共識；FY27–FY29）
A21: 項目 | B21: 單位 | C21: FY27 | D21: FY28 | E21: FY29
A22: 差異｜營收｜模型 | B22: US$bn | C22: =損益!C29 -> 87.49762 | D22: =損益!D29 -> 125.38525 | E22: =損益!E29 -> 168.28174
A23: 差異｜營收｜共識 | B23: US$bn | C23: =輸入與假設!$C$289 -> 90.449 | D23: =輸入與假設!$D$289 -> 131.711 | E23: =輸入與假設!$E$289 -> 183.569
A24: 差異｜營收｜差距 | B24: % | C24: =C22/C23-1 -> -0.032630324 | D24: =D22/D23-1 -> -0.048027522 | E24: =E22/E23-1 -> -0.083278023
A25: 差異｜調整後 EBITDA｜模型 | B25: US$bn | C25: =輸入與假設!$C$260+損益!C22 -> 51.371417 | D25: =損益!D34 -> 73.113611 | E25: =損益!E34 -> 94.158665
A26: 差異｜調整後 EBITDA｜共識 | B26: US$bn | C26: =輸入與假設!$C$290 -> 51.664 | D26: =輸入與假設!$D$290 -> 74.642 | E26: =輸入與假設!$E$290 -> 107.543
A27: 差異｜調整後 EBITDA｜差距 | B27: % | C27: =C25/C26-1 -> -0.0056631825 | D27: =D25/D26-1 -> -0.02047626 | E27: =E25/E26-1 -> -0.12445566 | I27: FY27 模型＝1Q 實際調整後 EBITDA（輸入與假設 G 區，報導轉述 [Verified]）＋2Q–4Q 模型
A28: 差異｜調整後 EBITDA｜差距（金額） | B28: US$bn | C28: =C25-C26 -> -0.29258266 | D28: =D25-D26 -> -1.528389 | E28: =E25-E26 -> -13.384335 | I28: 與 HTML 一頁摘要、市場共識分頁同一呈現；判斷門檻仍用上一列比例
A29: 差異｜EBITDA 率｜模型 | B29: % | C29: =C25/C22 -> 0.58711788 | D29: =D25/D22 -> 0.58311175 | E29: =E25/E22 -> 0.55952991
A30: 差異｜EBITDA 率｜共識 | B30: % | C30: =輸入與假設!$C$291 -> 0.5712 | D30: =輸入與假設!$D$291 -> 0.5667 | E30: =輸入與假設!$E$291 -> 0.5858
A31: 差異｜EBITDA 率｜差距（百分點） | B31: pt | C31: =C29-C30 -> 0.015917883 | D31: =D29-D30 -> 0.016411751 | E31: =E29-E30 -> -0.026270092 | I31: EBITDA 率以百分點列差距，不納入判斷
A32: 差異｜CapEx（毛額）｜模型 | B32: US$bn | C32: =輸入與假設!$C$243+輸入與假設!C$135 -> 106.09585 | D32: =輸入與假設!D$135 -> 86.020956 | E32: =輸入與假設!E$135 -> 31.20158
A33: 差異｜CapEx（毛額）｜共識 | B33: US$bn | C33: =輸入與假設!$C$296 -> 93.961 | D33: =輸入與假設!$D$296 -> 100.962 | E33: =輸入與假設!$E$296 -> 84.848
A34: 差異｜CapEx（毛額）｜差距 | B34: % | C34: =C32/C33-1 -> 0.12914773 | D34: =D32/D33-1 -> -0.14798681 | E34: =E32/E33-1 -> -0.632265 | I34: 共識 CapEx 口徑未揭露；FY27＝1Q 實際毛額＋2Q–4Q 模型毛額
A35: 差異｜淨負債｜模型 | B35: US$bn | C35: =資產負債_新債與新股!C24 -> 124.09865 | D35: =資產負債_新債與新股!D24 -> 144.11829 | E35: =資產負債_新債與新股!E24 -> 106.58015
A36: 差異｜淨負債｜共識 | B36: US$bn | C36: =輸入與假設!$C$298 -> 117.047 | D36: =輸入與假設!$D$298 -> 147.351 | E36: =輸入與假設!$E$298 -> 146.812
A37: 差異｜淨負債｜差距 | B37: % | C37: =C35/C36-1 -> 0.060246322 | D37: =D35/D36-1 -> -0.02193882 | E37: =E35/E36-1 -> -0.27403654 | I37: 共識淨負債不含租賃、口徑未揭露：只列不判斷
A38: 差異｜淨負債｜差距（金額） | B38: US$bn | C38: =C35-C36 -> 7.0516512 | D38: =D35-D36 -> -3.2327071 | E38: =E35-E36 -> -40.231853 | I38: 與 HTML 一頁摘要、市場共識分頁同一呈現；判斷門檻仍用上一列比例
A39: 差異｜分歧項目（超過門檻者） | C39: =MID(IF(ABS(C24)>輸入與假設!$C$333,"、營收 "&IF(C24<0,"−","+")&TEXT(ABS(C24)*100,"0.0")&"%","")&IF(ABS(C27)>輸入與假設!$C$333,"、EBITDA "&IF(C28<0,"−","+")&"$"&TEXT(ABS(C28),"#,##0.00")&"bn"&"／"&IF(C31<0,"−","+")&TEXT(ABS(C31)*100,"0.0")&"pt","")&IF(ABS(C34)>輸入與假設!$C$333,"、CapEx "&IF(C34<0,"−","+")&TEXT(ABS(C34)*100,"0.0")&"%",""),2,999) -> CapEx +12.9% | D39: =MID(IF(ABS(D24)>輸入與假設!$C$333,"、營收 "&IF(D24<0,"−","+")&TEXT(ABS(D24)*100,"0.0")&"%","")&IF(ABS(D27)>輸入與假設!$C$333,"、EBITDA "&IF(D28<0,"−","+")&"$"&TEXT(ABS(D28),"#,##0.00")&"bn"&"／"&IF(D31<0,"−","+")&TEXT(ABS(D31)*100,"0.0")&"pt","")&IF(ABS(D34)>輸入與假設!$C$333,"、CapEx "&IF(D34<0,"−","+")&TEXT(ABS(D34)*100,"0.0")&"%",""),2,999) -> CapEx −14.8% | E39: =MID(IF(ABS(E24)>輸入與假設!$C$333,"、營收 "&IF(E24<0,"−","+")&TEXT(ABS(E24)*100,"0.0")&"%","")&IF(ABS(E27)>輸入與假設!$C$333,"、EBITDA "&IF(E28<0,"−","+")&"$"&TEXT(ABS(E28),"#,##0.00")&"bn"&"／"&IF(E31<0,"−","+")&TEXT(ABS(E31)*100,"0.0")&"pt","")&IF(ABS(E34)>輸入與假設!$C$333,"、CapEx "&IF(E34<0,"−","+")&TEXT(ABS(E34)*100,"0.0")&"%",""),2,999) -> 營收 −8.3%、EBITDA −$13.38bn／−2.6pt、CapEx −63.2% | I39: 營收、EBITDA、CapEx 任一項差距絕對值超過門檻即列出（與 HTML 判斷句同一規則）
A40: 差異｜分歧起始年（1＝FY27…3＝FY29；0＝無） | C40: =IF(C39<>"",1,IF(D39<>"",2,IF(E39<>"",3,0))) -> 1
A41: 差異｜判斷句 | C41: =CHOOSE(C40+1,"FY27–FY29 營收、EBITDA、CapEx 與共識差距皆在 "&IF(ROUND(ABS(輸入與假設!$C$333)*100,4)=INT(ROUND(ABS(輸入與假設!$C$333)*100,4)),TEXT(ROUND(ABS(輸入與假設!$C$333)*100,4),"0"),TEXT(ROUND(ABS(輸入與假設!$C$333)*100,4),"0.0"))&"%"&" 以內。","分歧始於 FY27（"&C39&"）"&"；FY28 "&IF(D39="","回到 "&IF(ROUND(ABS(輸入與假設!$C$333)*100,4)=INT(ROUND(ABS(輸入與假設!$C$333)*100,4)),TEXT(ROUND(ABS(輸入與假設!$C$333)*100,4),"0"),TEXT(ROUND(ABS(輸入與假設!$C$333)*100,4),"0.0"))&"%"&" 以內",D39)&"；FY29 "&IF(E39="","回到 "&IF(ROUND(ABS(輸入與假設!$C$333)*100,4)=INT(ROUND(ABS(輸入與假設!$C$333)*100,4)),TEXT(ROUND(ABS(輸入與假設!$C$333)*100,4),"0"),TEXT(ROUND(ABS(輸入與假設!$C$333)*100,4),"0.0"))&"%"&" 以內",E39)&"。","FY27 營收、EBITDA、CapEx 與共識差距在 "&IF(ROUND(ABS(輸入與假設!$C$333)*100,4)=INT(ROUND(ABS(輸入與假設!$C$333)*100,4)),TEXT(ROUND(ABS(輸入與假設!$C$333)*100,4),"0"),TEXT(ROUND(ABS(輸入與假設!$C$333)*100,4),"0.0"))&"%"&" 以內；分歧始於 FY28（"&D39&"）"&"；FY29 "&IF(E39="","回到 "&IF(ROUND(ABS(輸入與假設!$C$333)*100,4)=INT(ROUND(ABS(輸入與假設!$C$333)*100,4)),TEXT(ROUND(ABS(輸入與假設!$C$333)*100,4),"0"),TEXT(ROUND(ABS(輸入與假設!$C$333)*100,4),"0.0"))&"%"&" 以內",E39)&"。","FY27–FY28 營收、EBITDA、CapEx 與共識差距在 "&IF(ROUND(ABS(輸入與假設!$C$333)*100,4)=INT(ROUND(ABS(輸入與假設!$C$333)*100,4)),TEXT(ROUND(ABS(輸入與假設!$C$333)*100,4),"0"),TEXT(ROUND(ABS(輸入與假設!$C$333)*100,4),"0.0"))&"%"&" 以內；分歧始於 FY29（"&E39&"）。") -> 分歧始於 FY27（CapEx +12.9%）；FY28 CapEx −14.8%；FY29 營收 −8.3%、EBITDA −$13.38bn／−2.6pt、CapEx −63.2%。
A42: 差異原因｜FY27｜營收 | C42: =IF(ABS(C24)>輸入與假設!$C$333,"觀點","") | D42: =IF(ABS(C24)>輸入與假設!$C$333,"營收＝OCI（在役 MW × 每 MW 年收入，Tokenomics 正向推導；年底已連網 "&IF((輸入與假設!C$43)<0,"−","")&TEXT(ABS((輸入與假設!C$43)),"#,##0")&" MW-IT）＋傳統事業四線（近四季年增率收斂）；共識未揭露 MW 假設","") | I42: C＝類型、D＝原因（需附原因時顯示；EBITDA 以利潤率差、其餘以比例門檻判斷）
...

Sheet 輸入與假設
A1: 輸入（依類別排序；點左側 ＋／− 展開或收合。藍字可改；黃底為最關鍵假設）
A2: A 情境 → B 產能與收入 → C 利潤率 → D 支出（CapEx／折舊／租賃／JV）→ E 融資 → F 評價 → G 參考：1Q27 實際 → H 情境區間運算表 → I 市場共識 → J 季度追蹤輸入。灰底『▸』為明細子區，預設收合
A4: A｜情境與規模（管理層擴張力道）
A5: 情境選擇（1＝保守 OpenAI 相關 60%、2＝基準 已簽約站點依 Q1 速度、3＝積極 依公司時程） | C5: 2 | D5: =CHOOSE(C5,"保守 OpenAI 相關 60%","基準 已簽約站點依 Q1 速度","積極 依公司時程") -> 基準 已簽約站點依 Q1 速度 | I5: 三情境改變擴張力道（已連網 MW 路徑）與每 MW 年收入（Tokenomics 正向推導三情境值）；其餘假設相同（對照表 r1 第 4 節第 1 條）
A6: ▸ 情境路徑明細（已連網 MW、在役比例、表外租金基準）
A7: 已連網 MW 路徑 | B7: 單位 | C7: FY27 | D7: FY28 | E7: FY29 | F7: FY30 | G7: FY31 | I7: FY31 新增 MW
A8: 首期期末已連網 MW（三情境共用） | B8: MW | C8: 4668 | I8: 首期期末＝評價日已連網＋首期剩餘季度依最新季交付速度；推導與來源見 company.json → scenarios.mwPath.note [Derived]
A9: 保守 OpenAI 相關 60%｜合約 MW 上限 | B9: MW | C9: 6284 | D9: 6284 | E9: 6284 | F9: 6284 | G9: 6284 | I9: company.json → scenarios.mwPath.contracted
A10: 保守 OpenAI 相關 60%｜併網速度 | B10: MW／年 | C10: 1000 | I10: company.json → scenarios.mwPath.pace
A11: 保守 OpenAI 相關 60% | B11: MW | C11: =MIN(C9,輸入與假設!$C$8) -> 4668 | D11: =MIN(D9,C11+輸入與假設!$C$10*D$41) -> 5668 | E11: =MIN(E9,D11+輸入與假設!$C$10*E$41) -> 6284 | F11: =MIN(F9,E11+輸入與假設!$C$10*F$41) -> 6284 | G11: =MIN(G9,F11+輸入與假設!$C$10*G$41) -> 6284 | I11: 0 | J11: 只交付已交付＋在建站點，OpenAI 相關容量實現 60%（上限 6,284 MW-IT），依 FY26 歷史速度 1,000 MW-IT／年；I 欄＝FY31 新增 MW
A12: 基準 已簽約站點依 Q1 速度｜合約 MW 上限 | B12: MW | C12: 8778 | D12: 8778 | E12: 8778 | F12: 8778 | G12: 8778 | I12: company.json → scenarios.mwPath.contracted
A13: 基準 已簽約站點依 Q1 速度｜併網速度 | B13: MW／年 | C13: 2833 | I13: company.json → scenarios.mwPath.pace
A14: 基準 已簽約站點依 Q1 速度 | B14: MW | C14: =MIN(C12,輸入與假設!$C$8) -> 4668 | D14: =MIN(D12,C14+輸入與假設!$C$13*D$41) -> 7501 | E14: =MIN(E12,D14+輸入與假設!$C$13*E$41) -> 8778 | F14: =MIN(F12,E14+輸入與假設!$C$13*F$41) -> 8778 | G14: =MIN(G12,F14+輸入與假設!$C$13*G$41) -> 8778 | I14: 0 | J14: Oracle 承租的五個 Stargate 站點全數實現（上限 8,778 MW-IT），依 FY27Q1 交付速度 2,833 MW-IT／年；I 欄＝FY31 新增 MW
A15: 積極 依公司時程｜合約 MW 上限 | B15: MW | C15: 8778 | D15: 8778 | E15: 8778 | F15: 8778 | G15: 8778 | I15: company.json → scenarios.mwPath.contracted
A16: 積極 依公司時程｜併網速度 | B16: MW／年 | C16: 3333 | I16: company.json → scenarios.mwPath.pace
A17: 積極 依公司時程 | B17: MW | C17: =MIN(C15,輸入與假設!$C$8) -> 4668 | D17: =MIN(D15,C17+輸入與假設!$C$16*D$41) -> 8001 | E17: =MIN(E15,D17+輸入與假設!$C$16*E$41) -> 8778 | F17: =MIN(F15,E17+輸入與假設!$C$16*F$41) -> 8778 | G17: =MIN(G15,F17+輸入與假設!$C$16*G$41) -> 8778 | I17: 0 | J17: 同基準上限，依公司時程（每季約 1 GW，3,333 MW-IT／年）；I 欄＝FY31 新增 MW
A18: 每 MW 年收入｜保守 OpenAI 相關 60% | B18: US$bn/MW | C18: 0.01162 | D18: 0.01162 | E18: 0.01162 | F18: 0.01162 | G18: 0.01162 | I18: Tokenomics 正向推導三情境（data/permw_tokenomics_20261007.json）；不用公司 ACV [Derived]
A19: 每 MW 年收入｜基準 已簽約站點依 Q1 速度 | B19: US$bn/MW | C19: 0.0174 | D19: 0.0174 | E19: 0.0174 | F19: 0.0174 | G19: 0.0174 | I19: Tokenomics 正向推導三情境（data/permw_tokenomics_20261007.json）；不用公司 ACV [Derived]
A20: 每 MW 年收入｜積極 依公司時程 | B20: US$bn/MW | C20: 0.0242 | D20: 0.0242 | E20: 0.0242 | F20: 0.0242 | G20: 0.0242 | I20: Tokenomics 正向推導三情境（data/permw_tokenomics_20261007.json）；不用公司 ACV [Derived]
A21: 在役 MW 收斂比例（期初校準值 → 已連網） | B21: % | C21: 0.5 | D21: 0.8 | E21: 0.85 | F21: 0.9 | G21: 0.9 | I21: 期初可計費 MW＝Q1 FY27 實際 OCI 營收 7.388 × 4＝29.552 ÷ 各情境每 MW 年收入（保守 2,543／基準 1,698／積極 1,221 MW-IT），是對齊已實現實際數的校準，不是以公司預測反推參數。各期末可計費 MW＝期初校準值＋(已連網 − 期初校準值)× 收斂比例；首期 50% 取能讓基準 FY27 營收落在公司指引 ≥90 的保守值（40% 時基準 FY27 約 89.1，低於指引），之後 80%→90%（新產能自交付到計費約一季）[Derived／Assumed]。
A22: 期初可計費 MW 校準：Q1 2027 實際營收年化 | B22: US$bn | C22: 29.552 | I22: 最新季實際營收 × 4（company.json → scenarios.billableRatio.openAnnualRevenue）[Derived]
A23: 期初可計費 MW｜保守 OpenAI 相關 60% | B23: MW | C23: =ROUND(輸入與假設!$C$22/C18,0) -> 2543 | I23: ＝實際營收年化 ÷ 該情境每 MW 年收入（對齊已實現實際數的校準）
A24: 期初可計費 MW｜基準 已簽約站點依 Q1 速度 | B24: MW | C24: =ROUND(輸入與假設!$C$22/C19,0) -> 1698 | I24: ＝實際營收年化 ÷ 該情境每 MW 年收入（對齊已實現實際數的校準）
A25: 期初可計費 MW｜積極 依公司時程 | B25: MW | C25: =ROUND(輸入與假設!$C$22/C20,0) -> 1221 | I25: ＝實際營收年化 ÷ 該情境每 MW 年收入（對齊已實現實際數的校準）
A26: 未起租租賃總額（未折現） | B26: US$bn | C26: 288 | I26: 季報附註已簽約未起租租賃（company.json → leases.facts.notCommenced）[Interested-party]
A27: 未起租：評價日後第幾季開始起租（0＝首期第一季） | B27: 季 | C27: 0 | I27: company.json → leases.uncommenced.startQ
A28: 未起租：平均分攤起租的季數 | B28: 季 | C28: 11 | I28: 季報：FY27Q2 至 FY2029 起租 → 11 季 [Assumed]
A29: 未起租：每筆租期 | B29: 年 | C29: 17 | I29: 季報 15–19 年取中點；敏感度 15／19 年見報告 [Assumed]
A30: B｜產能與收入（MW、每 MW 年收入、利用率、信用；RPO 只作對照）
A31: 8/31 RPO | B31: US$bn | C31: 664 | I31: 季報 RPO 664.0（只作對照與債務上限的 backlog）[Interested-party]
A32: 評價日後新增承諾 | B32: US$bn | C32: 0 | I32: 評價日後新簽、尚未進 RPO 的承諾；未揭露，取 0 [Assumed]
A33: 五期認列比例（至 2030 末） | B33: % | C33: 0.7975 | I33: 季報 RPO 桶線性分攤後五期合計 79.75% [Derived]
A34: RPO 桶權重合計 | B34: % | C34: 0.7975 | I34: 下方權重列的合計，用於歸一化
A35: 2026-05-31 主動電力 | B35: MW | C35: 1835 | I35: FY26 年底已連網 MW-IT 未揭露：以各情境校準可計費 MW 的最大值（保守 2,543＝Q1 OCI 年化 29.552 ÷ 11.62）減 Q1 交付 708 推得 1,835，使各情境期初可計費不超過已連網 [Derived]
A36: 8/31 Billable MW | B36: MW | C36: =CHOOSE(輸入與假設!$C$5,輸入與假設!$C$23,輸入與假設!$C$24,輸入與假設!$C$25) -> 1698 | I36: ＝依 A 區情境選擇器（以實際營收校準）
A37: 收入用平均在役 MW（1=是） | C37: 1 | I37: 0＝用期末存量全期化；建議 1
A38: 營收驅動（mw＝MW × 每 MW 年收入；rpo＝RPO 排程） | C38: mw | I38: mw：新產能簽約率固定 100%，營收＝容量上限；RPO 只作對照與產能瓶頸旗標（company.json → defaults.revenueDriver）
A39: 每 MW 年收入倍數（整體） | B39: % | C39: 1 | I39: 反向 DCF 與壓力測試用；預設 100%。以『目標搜尋』調整此格即可反解市價隱含單價
A40: 項目 | B40: 單位 | C40: FY27 | D40: FY28 | E40: FY29 | F40: FY30 | G40: FY31 | I40: 來源／標籤
A41: 模型期長度（年） | C41: 0.75 | D41: 1 | E41: 1 | F41: 1 | G41: 1 | I41: 勿改。由 calendar_q.py 推算；只用於容量上限、電力、維護等年率換算 [Derived]
...

Sheet 各期收支
A1: 支出與資金 — 五層支出、四層來源、現金橋
A2: FY27 欄＝1Q 實際（季報現金流量表口徑）＋第 2–4 季模型；FY28 以後為純模型。瀑布以「融資前現金」決定需求並直接由各支出列加總，因此沒有循環參照
A4: 項目 | B4: 單位 | C4: FY27 | D4: FY28 | E4: FY29 | F4: FY30 | G4: FY31 | I4: 公式／來源說明
A5: 支出（五層）
A6: ① 毛 CapEx（認列，備忘） | B6: US$bn | C6: =輸入與假設!$C$243+輸入與假設!C$135 -> 106.09585 | D6: =輸入與假設!D$135 -> 86.020956 | E6: =輸入與假設!E$135 -> 31.20158 | F6: =輸入與假設!F$135 -> 54.99417 | G6: =輸入與假設!G$135 -> 54.99417 | I6: FY27＝1Q 實際認列 28.499＋2Q–4Q 模型；對照公司全年指引 90–95。備忘列：用途合計採現金口徑，不用這一列
A7: 客戶預付率 | B7: % | C7: =輸入與假設!C$116 -> 0.243 | D7: =輸入與假設!D$116 -> 0.243 | E7: =輸入與假設!E$116 -> 0.243 | F7: =輸入與假設!F$116 -> 0.243 | G7: =輸入與假設!G$116 -> 0.243
A8: 客戶預付金額（抵減，2Q–4Q 起） | B8: US$bn | C8: =(輸入與假設!C$128+輸入與假設!C$132)*C7 -> 18.856035 | D8: =(輸入與假設!D$128+輸入與假設!D$132)*D7 -> 20.903092 | E8: =(輸入與假設!E$128+輸入與假設!E$132)*E7 -> 7.5819838 | F8: =(輸入與假設!F$128+輸入與假設!F$132)*F7 -> 13.363583 | G8: =(輸入與假設!G$128+輸入與假設!G$132)*G7 -> 13.363583 | I8: ＝(成長型＋汰換 CapEx)× 預付比率（v0.1c：汰換同樣適用覆蓋比）；1Q 的預付已含在實際 CFO 內，不重複計入
A9: 合約負債期初（客戶預付餘額） | B9: US$bn | C9: =輸入與假設!$C$113 -> 15.955 | D9: =C12 -> 33.730118 | E9: =D12 -> 50.753693 | F9: =E12 -> 51.723798 | G9: =F12 -> 58.531976 | I9: FY27 期初＝8/31 季報遞延營收
A10: 合約負債利息累積（重大財務組成，非現金） | B10: US$bn | C10: =輸入與假設!$C$114*(C9+0.5*C8)*運營_產能與收入!C7 -> 1.543922 | D10: =輸入與假設!$C$114*(D9+0.5*D8)*運營_產能與收入!D7 -> 3.583133 | E10: =輸入與假設!$C$114*(E9+0.5*E8)*運營_產能與收入!E7 -> 4.423574 | F10: =輸入與假設!$C$114*(F9+0.5*F8)*運營_產能與收入!F7 -> 4.7366933 | G10: =輸入與假設!$C$114*(G9+0.5*G8)*運營_產能與收入!G7 -> 5.2888366 | I10: ＝隱含利率 ×(期初合約負債＋本期預付流入 × ½)× 期間長度；進損益利息、不進現金（v0.1b）
A11: 預付認列（非現金營收） | B11: US$bn | C11: =MIN(C9+C10,(C9+C10)/輸入與假設!$C$112*運營_產能與收入!C7) -> 2.6248383 | D11: =MIN(D9+D10,(D9+D10)/輸入與假設!$C$112*運營_產能與收入!D7) -> 7.4626503 | E11: =MIN(E9+E10,(E9+E10)/輸入與假設!$C$112*運營_產能與收入!E7) -> 11.035453 | F11: =MIN(F9+F10,(F9+F10)/輸入與假設!$C$112*運營_產能與收入!F7) -> 11.292098 | G11: =MIN(G9+G10,(G9+G10)/輸入與假設!$C$112*運營_產能與收入!G7) -> 12.764163 | I11: ＝(期初合約負債＋累積利息) ÷ 認列年數 × 期間長度；這部分營收已在預付時收現，自營運來源扣除
A12: 合約負債期末 | B12: US$bn | C12: =C9+C8+C10-C11 -> 33.730118 | D12: =D9+D8+D10-D11 -> 50.753693 | E12: =E9+E8+E10-E11 -> 51.723798 | F12: =F9+F8+F10-F11 -> 58.531976 | G12: =G9+G8+G10-G11 -> 64.420233 | I12: ＝期初＋預付流入＋累積利息−認列
A13: ① CapEx（用途用：1Q 現金／2Q–4Q 毛額） | B13: US$bn | C13: =輸入與假設!$C$242+輸入與假設!C$135 -> 106.09585 | D13: =輸入與假設!D$135 -> 86.020956 | E13: =輸入與假設!E$135 -> 31.20158 | F13: =輸入與假設!F$135 -> 54.99417 | G13: =輸入與假設!G$135 -> 54.99417 | I13: 1Q 採現金流量表的現金購置 28.499；2Q–4Q 起採毛額，客戶預付在來源端抵回（避免重複計入）
A14: ② 在帳現金租金（備忘，1Q 已含在 CFO） | B14: US$bn | C14: =輸入與假設!C$117 -> 3.839 | D14: =輸入與假設!D$117 -> 4.987 | E14: =輸入與假設!E$117 -> 5.02 | F14: =輸入與假設!F$117 -> 5.056 | G14: =輸入與假設!G$117 -> 5.06 | I14: 見『租賃與承諾』頁；2031 後尚有 39.283。FY27 欄僅 2Q–4Q：1Q 租金 1.136 已含在實際 CFO 內
A15: ② 表外現金租金（未起租） | B15: US$bn | C15: =運營_產能與收入!C59 -> 1.7326203 | D15: =運營_產能與收入!D59 -> 7.7005348 | E15: =運營_產能與收入!E59 -> 13.860963 | F15: =運營_產能與收入!F59 -> 16.941176 | G15: =運營_產能與收入!G59 -> 16.941176 | I15: 已簽約未起租租賃 288.0 的現金路徑
A16: 租金合計 | B16: US$bn | C16: =C14+C15 -> 5.5716203 | D16: =D14+D15 -> 12.687535 | E16: =E14+E15 -> 18.880963 | F16: =F14+F15 -> 21.997176 | G16: =G14+G15 -> 22.001176 | I16: 租金已含在 EBITDA 率內（GAAP 營業租賃費用屬營業費用）：營運來源以 EBITDA 率＋租金÷營收計（租前），此列再扣，淨效果中性
A17: ③ 存量債務利息（備忘，1Q 已含在 CFO） | B17: US$bn | C17: =輸入與假設!C$172 -> 4.4795709 | D17: =輸入與假設!D$172 -> 5.6569839 | E17: =輸入與假設!E$172 -> 5.2813593 | F17: =輸入與假設!F$172 -> 4.9752805 | G17: =輸入與假設!G$172 -> 4.5671755 | I17: ="8/31 債務餘額的利息。FY27 全年利息＝1Q 實際 1.428＋2Q–4Q "&TEXT(C17,"0.0")&"＝"&TEXT(1.428+C17,"0.00")&"（見下方備忘）" -> 8/31 債務餘額的利息。FY27 全年利息＝1Q 實際 1.428＋2Q–4Q 4.5＝5.91（見下方備忘）
A18: 期初累積現金 | B18: US$bn | C18: =輸入與假設!$C$240 -> 31.289 | D18: =C52 -> 10 | E18: =D52 -> 10 | F18: =E52 -> 42.038145 | G18: =F52 -> 60.179667 | I18: FY27 自 2026-05-31 起算；之後＝前期期末累積現金
A19: 新債利率 | B19: % | C19: =IF(輸入與假設!$C$165=1,輸入與假設!C$171+MAX(0,輸入與假設!$C$164-450)/100*0.004,輸入與假設!C$171) -> 0.058 | D19: =IF(輸入與假設!$C$165=1,輸入與假設!D$171+MAX(0,輸入與假設!$C$164-450)/100*0.004,輸入與假設!D$171) -> 0.058 | E19: =IF(輸入與假設!$C$165=1,輸入與假設!E$171+MAX(0,輸入與假設!$C$164-450)/100*0.004,輸入與假設!E$171) -> 0.058 | F19: =IF(輸入與假設!$C$165=1,輸入與假設!F$171+MAX(0,輸入與假設!$C$164-450)/100*0.004,輸入與假設!F$171) -> 0.058 | G19: =IF(輸入與假設!$C$165=1,輸入與假設!G$171+MAX(0,輸入與假設!$C$164-450)/100*0.004,輸入與假設!G$171) -> 0.058 | I19: CDS 開關：＋MAX(0,CDS−450)×0.4bp/bp
A20: ③ 新債利息（瀑布） | B20: US$bn | C20: =C86 -> 0.48727183 | D20: =D86 -> 2.399361 | E20: =E86 -> 2.399361 | F20: =F86 -> 2.399361 | G20: =G86 -> 2.399361 | I20: ＝新債利率×期間長度×(期初新債＋本期舉借)；見下方「期前融資瀑布」
A21: 利息合計 | B21: US$bn | C21: =C17+C20 -> 4.9668427 | D21: =D17+D20 -> 8.0563449 | E21: =E17+E20 -> 7.6807203 | F21: =F17+F20 -> 7.3746415 | G21: =G17+G20 -> 6.9665365
A22: ④ JV／策略投資出資 | B22: US$bn | C22: =輸入與假設!$C$244+輸入與假設!C$122 -> 0 | D22: =輸入與假設!D$122 -> 0 | E22: =輸入與假設!E$122 -> 0 | F22: =輸入與假設!F$122 -> 0 | G22: =輸入與假設!G$122 -> 0 | I22: FY27＝1Q 實際 0.0（JV 0.000＋策略投資 0.000）＋2Q–4Q 模型。ORCL 不發股息
A23: ⑧ 股利（普通股＋特別股） | B23: US$bn | C23: =輸入與假設!$C$259+4*輸入與假設!$C$149*運營_產能與收入!C7*(輸入與假設!$C$150+0+SUMPRODUCT(資產負債_既有債務!$D$73:$D$73*資產負債_既有債務!$H$69:$H$69*(資產負債_既有債務!$G$69:$G$69<0)))+輸入與假設!C$169 -> 6.344604 | D23: =4*輸入與假設!$C$149*運營_產能與收入!D7*(輸入與假設!$C$150+C89+SUMPRODUCT(資產負債_既有債務!$D$73:$D$73*資產負債_既有債務!$H$69:$H$69*(資產負債_既有債務!$G$69:$G$69<1)))+輸入與假設!D$169 -> 6.372472 | E23: =4*輸入與假設!$C$149*運營_產能與收入!E7*(輸入與假設!$C$150+D89+SUMPRODUCT(資產負債_既有債務!$D$73:$D$73*資產負債_既有債務!$H$69:$H$69*(資產負債_既有債務!$G$69:$G$69<2)))+輸入與假設!E$169 -> 6.291472 | F23: =4*輸入與假設!$C$149*運營_產能與收入!F7*(輸入與假設!$C$150+E89+SUMPRODUCT(資產負債_既有債務!$D$73:$D$73*資產負債_既有債務!$H$69:$H$69*(資產負債_既有債務!$G$69:$G$69<3)))+輸入與假設!F$169 -> 6.1099486 | G23: =4*輸入與假設!$C$149*運營_產能與收入!G7*(輸入與假設!$C$150+F89+SUMPRODUCT(資產負債_既有債務!$D$73:$D$73*資產負債_既有債務!$H$69:$H$69*(資產負債_既有債務!$G$69:$G$69<4)))+輸入與假設!G$169 -> 6.1099486 | I23: 普通股＝每股每季 × 4 × 期間長度 ×(基礎股數＋前期累計瀑布新股＋已強制轉換特別股)＋特別股股利；FY27＝1Q 實際＋2Q–4Q 模型（v0.1b）
A24: 電力（overlay） | B24: US$bn | C24: =IF(輸入與假設!$C$96=1,運營_產能與收入!C9*8760*輸入與假設!C$98*輸入與假設!C$97/1000000000*運營_產能與收入!C7,0) -> 0 | D24: =IF(輸入與假設!$C$96=1,運營_產能與收入!D9*8760*輸入與假設!D$98*輸入與假設!D$97/1000000000*運營_產能與收入!D7,0) -> 0 | E24: =IF(輸入與假設!$C$96=1,運營_產能與收入!E9*8760*輸入與假設!E$98*輸入與假設!E$97/1000000000*運營_產能與收入!E7,0) -> 0 | F24: =IF(輸入與假設!$C$96=1,運營_產能與收入!F9*8760*輸入與假設!F$98*輸入與假設!F$97/1000000000*運營_產能與收入!F7,0) -> 0 | G24: =IF(輸入與假設!$C$96=1,運營_產能與收入!G9*8760*輸入與假設!G$98*輸入與假設!G$97/1000000000*運營_產能與收入!G7,0) -> 0 | I24: ＝已連網 MW×8760×PUE×電價÷1e9×期間係數。EBITDA 率已含電費，預設關閉
A25: 維護（overlay） | B25: US$bn | C25: =IF(輸入與假設!$C$96=1,運營_產能與收入!C9*輸入與假設!C$99/1000*運營_產能與收入!C7,0) -> 0 | D25: =IF(輸入與假設!$C$96=1,運營_產能與收入!D9*輸入與假設!D$99/1000*運營_產能與收入!D7,0) -> 0 | E25: =IF(輸入與假設!$C$96=1,運營_產能與收入!E9*輸入與假設!E$99/1000*運營_產能與收入!E7,0) -> 0 | F25: =IF(輸入與假設!$C$96=1,運營_產能與收入!F9*輸入與假設!F$99/1000*運營_產能與收入!F7,0) -> 0 | G25: =IF(輸入與假設!$C$96=1,運營_產能與收入!G9*輸入與假設!G$99/1000*運營_產能與收入!G7,0) -> 0
A26: ⑤ 排程還本（季報到期表） | B26: US$bn | C26: =輸入與假設!$C$246+IF(輸入與假設!$C$144=1,輸入與假設!C$170,0)+資產負債_既有債務!C84 -> 7.209 | D26: =IF(輸入與假設!$C$144=1,輸入與假設!D$170,0)+資產負債_既有債務!D84 -> 10.147 | E26: =IF(輸入與假設!$C$144=1,輸入與假設!E$170,0)+資產負債_既有債務!E84 -> 5.5 | F26: =IF(輸入與假設!$C$144=1,輸入與假設!F$170,0)+資產負債_既有債務!F84 -> 7.25 | G26: =IF(輸入與假設!$C$144=1,輸入與假設!G$170,0)+資產負債_既有債務!G84 -> 9.75 | I26: FY27＝1Q 實際還款 4.202＋2Q–4Q 到期表 3.007
A27: ⑥ capped call 支出（1Q 實際） | B27: US$bn | C27: =輸入與假設!$C$247 -> 0 | D27: =0 -> 0 | E27: =0 -> 0 | F27: =0 -> 0 | G27: =0 -> 0 | I27: 可轉債配套 capped call 現金支出（未見揭露，0）
A28: ⑦ 現金稅（2Q–4Q 起） | B28: US$bn | C28: =輸入與假設!$C$163*MAX(0,運營_產能與收入!C38*輸入與假設!C$93+輸入與假設!C$51+輸入與假設!C$83-運營_產能與收入!C62-輸入與假設!C$136-輸入與假設!C$172) -> 3.4555058 | D28: =輸入與假設!$C$163*MAX(0,運營_產能與收入!D38*輸入與假設!D$93+輸入與假設!D$51+輸入與假設!D$83-運營_產能與收入!D62-輸入與假設!D$136-輸入與假設!D$172) -> 5.8406262 | E28: =輸入與假設!$C$163*MAX(0,運營_產能與收入!E38*輸入與假設!E$93+輸入與假設!E$51+輸入與假設!E$83-運營_產能與收入!E62-輸入與假設!E$136-輸入與假設!E$172) -> 7.3727777 | F28: =輸入與假設!$C$163*MAX(0,運營_產能與收入!F38*輸入與假設!F$93+輸入與假設!F$51+輸入與假設!F$83-運營_產能與收入!F62-輸入與假設!F$136-輸入與假設!F$172) -> 7.6994602 | G28: =輸入與假設!$C$163*MAX(0,運營_產能與收入!G38*輸入與假設!G$93+輸入與假設!G$51+輸入與假設!G$83-運營_產能與收入!G62-輸入與假設!G$136-輸入與假設!G$172) -> 7.2870929 | I28: ＝稅率 × MAX(0, 損益 EBITDA − 車隊 D&A − 存量利息)；1Q 的稅已含在 CFO 內（v0.1b）
A29: 用途合計（現金口徑） | B29: US$bn | C29: =C13+C16+C21+C22+C24+C25+C26+C27+C28+C23 -> 133.64342 | D29: =D13+D16+D21+D22+D24+D25+D26+D27+D28+D23 -> 129.12493 | E29: =E13+E16+E21+E22+E24+E25+E26+E27+E28+E23 -> 76.927512 | F29: =F13+F16+F21+F22+F24+F25+F26+F27+F28+F23 -> 105.4254 | G29: =G13+G16+G21+G22+G24+G25+G26+G27+G28+G23 -> 107.10892 | I29: FY27 的 1Q 部分採季報現金流量表口徑（現金購置、還款、JV、capped call）；1Q 的利息與租金已含在 CFO 內，不重複列
A30: 來源（四層）
A31: Ⓐ0 1Q27 實際營運現金流（CFO） | B31: US$bn | C31: =輸入與假設!$C$241 -> 23.103 | D31: =0 -> 0 | E31: =0 -> 0 | F31: =0 -> 0 | G31: =0 -> 0 | I31: 季報實際值，取代模型推算；已含 1Q 的利息、租金與客戶預付
A32: Ⓐ RPO 現金（2Q–4Q 起） | B32: US$bn | C32: =運營_產能與收入!C40 -> 24.124443 | D32: =運營_產能與收入!D40 -> 56.375823 | E32: =運營_產能與收入!E40 -> 82.112849 | F32: =運營_產能與收入!F40 -> 77.813395 | G32: =運營_產能與收入!G40 -> 69.855727
A33: Ⓑ 新簽約現金 | B33: US$bn | C33: =運營_產能與收入!C41 -> 0 | D33: =運營_產能與收入!D41 -> 0 | E33: =運營_產能與收入!E41 -> 0 | F33: =運營_產能與收入!F41 -> 12.278997 | G33: =運營_產能與收入!G41 -> 16.565393
A34: Ⓒ 非算力服務現金 | B34: US$bn | C34: =輸入與假設!C$94 -> 0 | D34: =輸入與假設!D$94 -> 0 | E34: =輸入與假設!E$94 -> 0 | F34: =輸入與假設!F$94 -> 0 | G34: =輸入與假設!G$94 -> 0
A35: Ⓒ2 其他事業 EBITDA（2Q–4Q 起） | B35: US$bn | C35: =輸入與假設!C$51 -> 0 | D35: =輸入與假設!D$51 -> 0 | E35: =輸入與假設!E$51 -> 0 | F35: =輸入與假設!F$51 -> 0 | G35: =輸入與假設!G$51 -> 0 | I35: 非核心事業 EBITDA（負值＝燒錢），視為現金（v0.1b）
A36: Ⓒ3 傳統事業 EBITDA（2Q–4Q 起） | B36: US$bn | C36: =輸入與假設!C$83 -> 21.451132 | D36: =輸入與假設!D$83 -> 29.142027 | E36: =輸入與假設!E$83 -> 30.306278 | F36: =輸入與假設!F$83 -> 31.403042 | G36: =輸入與假設!G$83 -> 32.405417 | I36: SaaS、軟體、硬體、服務四線 EBITDA，視為現金（現金稅另列於用途；v0.1b）
A37: Ⓒ4 減：延誤罰則（營業費用） | B37: US$bn | C37: =-運營_產能與收入!C62 -> 0 | D37: =-運營_產能與收入!D62 -> 0 | E37: =-運營_產能與收入!E62 -> 0 | F37: =-運營_產能與收入!F62 -> 0 | G37: =-運營_產能與收入!G62 -> 0 | I37: 建設延誤期間應計費而未計費營收 × 罰則比例（預設 0；v0.2）
A38: Ⓓ 客戶預付（2Q–4Q 起） | B38: US$bn | C38: =C8 -> 18.856035 | D38: =D8 -> 20.903092 | E38: =E8 -> 7.5819838 | F38: =F8 -> 13.363583 | G38: =G8 -> 13.363583
A39: Ⓓ2 減：預付認列（非現金營收） | B39: US$bn | C39: =-C11 -> -2.6248383 | D39: =-D11 -> -7.4626503 | E39: =-E11 -> -11.035453 | F39: =-F11 -> -11.292098 | G39: =-G11 -> -12.764163 | I39: 營收中由合約負債轉入的部分已在預付時收現，不重複計入服務現金（v0.1b）
A40: 營運來源合計 | B40: US$bn | C40: =C31+C32+C33+C34+C35+C36+C37+C38+C39 -> 84.909772 | D40: =D31+D32+D33+D34+D35+D36+D37+D38+D39 -> 98.958292 | E40: =E31+E32+E33+E34+E35+E36+E37+E38+E39 -> 108.96566 | F40: =F31+F32+F33+F34+F35+F36+F37+F38+F39 -> 123.56692 | G40: =G31+G32+G33+G34+G35+G36+G37+G38+G39 -> 119.42596
A41: Ⓔ 股權／可轉債（融資） | B41: US$bn | C41: =輸入與假設!$C$248+IF(輸入與假設!$C$141=1,輸入與假設!$C$140,0) -> 19.909 | D41: =0 -> 0 | E41: =0 -> 0 | F41: =0 -> 0 | G41: =0 -> 0 | I41: FY27＝1Q ATM 淨收入 19.909（141m 股、均價約 $141.84）＋2Q–4Q 期後股權 0
...

Sheet 季度追蹤
A1: 季度追蹤 — 焦點季的模型／共識／指引／實際與差距（由年度模型拆分；只用於追蹤，不影響年度數字與目標價）
A2: 設定與實際數在『輸入與假設』J 區，共識在 I 區；缺資料顯示「不適用」，實際數空白＝待公布。差距超過門檻的項目附差異原因（拆法＝所屬期間合計差距在門檻內）。第 2 區為 6 季路徑與拆分明細（預設收合）。
A4: 1｜焦點季（『輸入與假設』J 區選擇）：模型／共識／指引／實際與差距
A5: 指標 | B5: 單位 | C5: 模型 | D5: 共識 | E5: 模型 vs 共識 | F5: 指引（低） | G5: 指引（高） | H5: 模型 vs 指引中點 | I5: 實際 | J5: 實際 vs 模型 | K5: 實際 vs 共識 | L5: 實際 vs 指引中點 | M5: 利潤率 pt：模型 vs 共識 | N5: 模型 vs 指引 | O5: 實際 vs 模型 | P5: 實際 vs 共識 | Q5: 實際 vs 指引
A6: 焦點｜營收 | B6: US$bn | C6: =INDEX($C$22:$H$22,輸入與假設!$C$339) -> 21.03127 | D6: =INDEX($C$34:$H$34,輸入與假設!$C$339) -> 21.322 | E6: =INDEX($C$44:$H$44,輸入與假設!$C$339) -> -0.013635214 | F6: =IF(ISNUMBER(INDEX($C$31:$H$31,輸入與假設!$C$339)),INDEX($C$31:$H$31,輸入與假設!$C$339),"不適用") -> 20.875 | G6: =INDEX($C$32:$H$32,輸入與假設!$C$339) -> 21.518 | H6: =INDEX($C$45:$H$45,輸入與假設!$C$339) -> -0.0077951564 | I6: =IF(ISNUMBER(INDEX($C$38:$H$38,輸入與假設!$C$339)),INDEX($C$38:$H$38,輸入與假設!$C$339),"待公布") -> 待公布 | J6: =INDEX($C$46:$H$46,輸入與假設!$C$339) | K6: =INDEX($C$47:$H$47,輸入與假設!$C$339) | L6: =INDEX($C$48:$H$48,輸入與假設!$C$339)
A7: 焦點｜調整後 EBITDA | B7: US$bn | C7: =INDEX($C$28:$H$28,輸入與假設!$C$339) -> 12.397286 | D7: =INDEX($C$35:$H$35,輸入與假設!$C$339) -> 12.359 | E7: =INDEX($C$49:$H$49,輸入與假設!$C$339) -> 0.038286149 | F7: 不適用 | G7: 不適用 | H7: =INDEX($C$50:$H$50,輸入與假設!$C$339) -> 不適用 | I7: =IF(ISNUMBER(INDEX($C$39:$H$39,輸入與假設!$C$339)),INDEX($C$39:$H$39,輸入與假設!$C$339),"待公布") -> 待公布 | J7: =INDEX($C$51:$H$51,輸入與假設!$C$339) | K7: =INDEX($C$52:$H$52,輸入與假設!$C$339) | L7: =INDEX($C$53:$H$53,輸入與假設!$C$339) | M7: =INDEX($C$54:$H$54,輸入與假設!$C$339) -> 0.009833156 | N7: =INDEX($C$55:$H$55,輸入與假設!$C$339) -> 不適用 | O7: =INDEX($C$56:$H$56,輸入與假設!$C$339) | P7: =INDEX($C$57:$H$57,輸入與假設!$C$339) | Q7: =INDEX($C$58:$H$58,輸入與假設!$C$339)
A8: 焦點｜EBITDA 率 | B8: % | C8: =INDEX($C$27:$H$27,輸入與假設!$C$339) -> 0.58946921 | D8: =INDEX($C$36:$H$36,輸入與假設!$C$339) -> 0.57963606 | E8: =INDEX($C$59:$H$59,輸入與假設!$C$339) -> 0.009833156 | F8: 不適用 | G8: 不適用 | H8: =INDEX($C$60:$H$60,輸入與假設!$C$339) -> 不適用 | I8: =IF(ISNUMBER(INDEX($C$40:$H$40,輸入與假設!$C$339)),INDEX($C$40:$H$40,輸入與假設!$C$339),"待公布") -> 待公布 | J8: =INDEX($C$61:$H$61,輸入與假設!$C$339) | K8: =INDEX($C$62:$H$62,輸入與假設!$C$339) | L8: =INDEX($C$63:$H$63,輸入與假設!$C$339)
A9: 焦點｜調整後營業利益 | B9: US$bn | C9: =INDEX($C$30:$H$30,輸入與假設!$C$339) -> 8.8822081 | D9: 不適用 | E9: =INDEX($C$64:$H$64,輸入與假設!$C$339) -> 不適用 | F9: 不適用 | G9: 不適用 | H9: =INDEX($C$65:$H$65,輸入與假設!$C$339) -> 不適用 | I9: =IF(ISNUMBER(INDEX($C$41:$H$41,輸入與假設!$C$339)),INDEX($C$41:$H$41,輸入與假設!$C$339),"待公布") -> 待公布 | J9: =INDEX($C$66:$H$66,輸入與假設!$C$339) | K9: =INDEX($C$67:$H$67,輸入與假設!$C$339) | L9: =INDEX($C$68:$H$68,輸入與假設!$C$339) | M9: =INDEX($C$69:$H$69,輸入與假設!$C$339) -> 不適用 | N9: =INDEX($C$70:$H$70,輸入與假設!$C$339) -> 不適用 | O9: =INDEX($C$71:$H$71,輸入與假設!$C$339) | P9: =INDEX($C$72:$H$72,輸入與假設!$C$339) | Q9: =INDEX($C$73:$H$73,輸入與假設!$C$339)
A10: 焦點｜CapEx（毛額） | B10: US$bn | C10: =INDEX($C$33:$H$33,輸入與假設!$C$339) -> 25.865617 | D10: 不適用 | E10: =INDEX($C$74:$H$74,輸入與假設!$C$339) -> 不適用 | F10: 不適用 | G10: 不適用 | H10: =INDEX($C$75:$H$75,輸入與假設!$C$339) -> 不適用 | I10: =IF(ISNUMBER(INDEX($C$42:$H$42,輸入與假設!$C$339)),INDEX($C$42:$H$42,輸入與假設!$C$339),"待公布") -> 待公布 | J10: =INDEX($C$76:$H$76,輸入與假設!$C$339) | K10: =INDEX($C$77:$H$77,輸入與假設!$C$339) | L10: =INDEX($C$78:$H$78,輸入與假設!$C$339)
A11: 焦點｜季末已連網 MW-IT | B11: MW | C11: =INDEX($C$19:$H$19,輸入與假設!$C$339) -> 3251.3333 | D11: 不適用 | E11: =INDEX($C$79:$H$79,輸入與假設!$C$339) -> 不適用 | F11: 不適用 | G11: 不適用 | H11: =INDEX($C$80:$H$80,輸入與假設!$C$339) -> 不適用 | I11: =IF(ISNUMBER(INDEX($C$43:$H$43,輸入與假設!$C$339)),INDEX($C$43:$H$43,輸入與假設!$C$339),"待公布") -> 待公布 | J11: =INDEX($C$81:$H$81,輸入與假設!$C$339) | K11: =INDEX($C$82:$H$82,輸入與假設!$C$339) | L11: =INDEX($C$83:$H$83,輸入與假設!$C$339)
A12: 焦點｜季度 | C12: =INDEX($C$16:$H$16,輸入與假設!$C$339) -> Q2 FY27
A13: 焦點｜差異原因 | C13: =IF(INDEX($C$123:$H$123,輸入與假設!$C$339)="","無（差距皆在 "&IF(ROUND(ABS(輸入與假設!$C$333)*100,4)=INT(ROUND(ABS(輸入與假設!$C$333)*100,4)),TEXT(ROUND(ABS(輸入與假設!$C$333)*100,4),"0"),TEXT(ROUND(ABS(輸入與假設!$C$333)*100,4),"0.0"))&"%"&" 以內）",INDEX($C$123:$H$123,輸入與假設!$C$339)) -> 無（差距皆在 5% 以內）
A15: 2｜6 季路徑、共識、指引、實際與差距（明細；第 1 區以焦點季引用本區）
A16: 項目 | B16: 單位 | C16: Q2 FY27 | D16: Q3 FY27 | E16: Q4 FY27 | F16: Q1 FY28 | G16: Q2 FY28 | H16: Q3 FY28
A17: 所屬期間 | C17: =輸入與假設!C$338 -> 1 | D17: =輸入與假設!D$338 -> 1 | E17: =輸入與假設!E$338 -> 1 | F17: =輸入與假設!F$338 -> 2 | G17: =輸入與假設!G$338 -> 2 | H17: =輸入與假設!H$338 -> 2 | J17: 1＝2Q–4Q27、2＝FY28
A18: 季序 | C18: 1 | D18: 2 | E18: 3 | F18: 4 | G18: 5 | H18: 6 | J18: EBITDA 率直線的 x 軸
A19: 季末已連網 MW-IT（模型） | B19: MW | C19: =輸入與假設!$C$341+(輸入與假設!C$43-輸入與假設!$C$341)*1/3 -> 3251.3333 | D19: =輸入與假設!$C$341+(輸入與假設!C$43-輸入與假設!$C$341)*2/3 -> 3959.6667 | E19: =輸入與假設!$C$341+(輸入與假設!C$43-輸入與假設!$C$341)*3/3 -> 4668 | F19: =輸入與假設!C$43+(輸入與假設!D$43-輸入與假設!C$43)*1/3 -> 5612.3333 | G19: =輸入與假設!C$43+(輸入與假設!D$43-輸入與假設!C$43)*2/3 -> 6556.6667 | H19: =輸入與假設!C$43+(輸入與假設!D$43-輸入與假設!C$43)*3/3 -> 7501 | J19: 期初與期末 Accepted 之間線性內插；第 1 期起點見 J 區
A20: 平均在役 MW（Billable，拆分依據） | B20: MW | C20: =輸入與假設!$C$36+(運營_產能與收入!C$11-輸入與假設!$C$36)*1/6 -> 1863 | D20: =輸入與假設!$C$36+(運營_產能與收入!C$11-輸入與假設!$C$36)*3/6 -> 2193 | E20: =輸入與假設!$C$36+(運營_產能與收入!C$11-輸入與假設!$C$36)*5/6 -> 2523 | F20: =運營_產能與收入!C$11+(運營_產能與收入!D$11-運營_產能與收入!C$11)*1/6 -> 3165.125 | G20: =運營_產能與收入!C$11+(運營_產能與收入!D$11-運營_產能與收入!C$11)*3/6 -> 4119.375 | H20: =運營_產能與收入!C$11+(運營_產能與收入!D$11-運營_產能與收入!C$11)*5/6 -> 5073.625 | J20: 期初與期末 Billable 之間線性內插的季平均
A21: 季內新增 Accepted MW | B21: MW | C21: =C19-輸入與假設!$C$341 -> 708.33333 | D21: =D19-C19 -> 708.33333 | E21: =E19-D19 -> 708.33333 | F21: =F19-輸入與假設!C$43 -> 944.33333 | G21: =G19-F19 -> 944.33333 | H21: =H19-G19 -> 944.33333 | J21: CapEx 拆分依據
A22: 營收（模型） | B22: US$bn | C22: =輸入與假設!$C$340+1*(損益!C9-3*輸入與假設!$C$340)/6 -> 21.03127 | D22: =輸入與假設!$C$340+2*(損益!C9-3*輸入與假設!$C$340)/6 -> 22.71754 | E22: =輸入與假設!$C$340+3*(損益!C9-3*輸入與假設!$C$340)/6 -> 24.40381 | F22: =損益!D9*F20/(F20+G20+H20) -> 32.113284 | G22: =損益!D9*G20/(F20+G20+H20) -> 41.795082 | H22: =損益!D9*H20/(F20+G20+H20) -> 51.476881 | J22: 拆分方法見『輸入與假設』J 區與 HTML「拆分方法」
A23: EBITDA 率直線｜各期營收合計 S | C23: =C22+D22+E22 -> 68.15262 | D23: =F22+G22+H22 -> 125.38525 | J23: 欄＝期間（2Q–4Q27、FY28）
A24: EBITDA 率直線｜營收 × 季序合計 T | C24: =C22*C18+D22*D18+E22*E18 -> 139.67778 | D24: =F22*F18+G22*G18+H22*H18 -> 646.28983 | J24: 欄＝期間（2Q–4Q27、FY28）
A25: EBITDA 率直線｜年度 EBITDA E | C25: =損益!C22 -> 40.064417 | D25: =損益!D22 -> 73.113611 | J25: 欄＝期間（2Q–4Q27、FY28）
A26: EBITDA 率直線｜截距 a／斜率 b | C26: =(C25*D24-C24*D25)/(C23*D24-C24*D23) -> 0.5909995 | D26: =(C23*D25-D23*C25)/(C23*D24-C24*D23) -> -0.0015302838 | J26: 解兩式：Σ營收×(a＋b×季序)＝各期年度 EBITDA
A27: EBITDA 率（模型） | B27: % | C27: =$C$26+$D$26*C18 -> 0.58946921 | D27: =$C$26+$D$26*D18 -> 0.58793893 | E27: =$C$26+$D$26*E18 -> 0.58640865 | F27: =$C$26+$D$26*F18 -> 0.58487836 | G27: =$C$26+$D$26*G18 -> 0.58334808 | H27: =$C$26+$D$26*H18 -> 0.58181779 | J27: 跨季一條直線，季度 EBITDA 加總＝年度
A28: 調整後 EBITDA（模型） | B28: US$bn | C28: =C22*C27 -> 12.397286 | D28: =D22*D27 -> 13.356526 | E28: =E22*E27 -> 14.310605 | F28: =F22*F27 -> 18.782365 | G28: =G22*G27 -> 24.381081 | H28: =H22*H27 -> 29.950165
A29: 車隊折舊（模型） | B29: US$bn | C29: =(輸入與假設!C$133+運營_產能與收入!C$54*1/6)/輸入與假設!$C$105*輸入與假設!C$41/3 -> 3.515078 | D29: =(輸入與假設!C$133+運營_產能與收入!C$54*3/6)/輸入與假設!$C$105*輸入與假設!C$41/3 -> 4.2335674 | E29: =(輸入與假設!C$133+運營_產能與收入!C$54*5/6)/輸入與假設!$C$105*輸入與假設!C$41/3 -> 4.9520567 | F29: =(輸入與假設!D$133+運營_產能與收入!D$54*1/6)/輸入與假設!$C$105*輸入與假設!D$41/3 -> 7.9185994 | G29: =(輸入與假設!D$133+運營_產能與收入!D$54*3/6)/輸入與假設!$C$105*輸入與假設!D$41/3 -> 9.5923278 | H29: =(輸入與假設!D$133+運營_產能與收入!D$54*5/6)/輸入與假設!$C$105*輸入與假設!D$41/3 -> 11.266056 | J29: 依期內平均 PP&E（與年度車隊折舊公式相同）
A30: 調整後營業利益（模型） | B30: US$bn | C30: =C28-C29 -> 8.8822081 | D30: =D28-D29 -> 9.1229587 | E30: =E28-E29 -> 9.3585484 | F30: =F28-F29 -> 10.863766 | G30: =G28-G29 -> 14.788753 | H30: =H28-H29 -> 18.684109 | J30: ＝調整後 EBITDA − 車隊折舊（未扣 SBC）
A31: 指引｜營收（低） | B31: US$bn | C31: =IF(ISNUMBER(輸入與假設!C$350),輸入與假設!C$350,"不適用") -> 20.875 | D31: =IF(ISNUMBER(輸入與假設!D$350),輸入與假設!D$350,"不適用") -> 不適用 | E31: =IF(ISNUMBER(輸入與假設!E$350),輸入與假設!E$350,"不適用") -> 不適用 | F31: =IF(ISNUMBER(輸入與假設!F$350),輸入與假設!F$350,"不適用") -> 不適用 | G31: =IF(ISNUMBER(輸入與假設!G$350),輸入與假設!G$350,"不適用") -> 不適用 | H31: =IF(ISNUMBER(輸入與假設!H$350),輸入與假設!H$350,"不適用") -> 不適用
A32: 指引｜營收（高） | B32: US$bn | C32: =IF(ISNUMBER(輸入與假設!C$351),輸入與假設!C$351,"不適用") -> 21.518 | D32: =IF(ISNUMBER(輸入與假設!D$351),輸入與假設!D$351,"不適用") -> 不適用 | E32: =IF(ISNUMBER(輸入與假設!E$351),輸入與假設!E$351,"不適用") -> 不適用 | F32: =IF(ISNUMBER(輸入與假設!F$351),輸入與假設!F$351,"不適用") -> 不適用 | G32: =IF(ISNUMBER(輸入與假設!G$351),輸入與假設!G$351,"不適用") -> 不適用 | H32: =IF(ISNUMBER(輸入與假設!H$351),輸入與假設!H$351,"不適用") -> 不適用
A33: CapEx（毛額）（模型） | B33: US$bn | C33: =IF((C21+D21+E21)>0,輸入與假設!C$135*C21/(C21+D21+E21),輸入與假設!C$135/3) -> 25.865617 | D33: =IF((C21+D21+E21)>0,輸入與假設!C$135*D21/(C21+D21+E21),輸入與假設!C$135/3) -> 25.865617 | E33: =IF((C21+D21+E21)>0,輸入與假設!C$135*E21/(C21+D21+E21),輸入與假設!C$135/3) -> 25.865617 | F33: =IF((F21+G21+H21)>0,輸入與假設!D$135*F21/(F21+G21+H21),輸入與假設!D$135/3) -> 28.673652 | G33: =IF((F21+G21+H21)>0,輸入與假設!D$135*G21/(F21+G21+H21),輸入與假設!D$135/3) -> 28.673652 | H33: =IF((F21+G21+H21)>0,輸入與假設!D$135*H21/(F21+G21+H21),輸入與假設!D$135/3) -> 28.673652 | J33: 依季內新增 Accepted MW
A34: 共識｜營收 | B34: US$bn | C34: =IF(ISNUMBER(輸入與假設!$C$305),輸入與假設!$C$305,"不適用") -> 21.322 | D34: =IF(ISNUMBER(輸入與假設!$D$305),輸入與假設!$D$305,"不適用") -> 23.38 | E34: 不適用 | F34: 不適用 | G34: 不適用 | H34: 不適用 | J34: I 區季度共識 [Interested-party]
A35: 共識｜調整後 EBITDA | B35: US$bn | C35: =IF(ISNUMBER(輸入與假設!$C$306),輸入與假設!$C$306,"不適用") -> 12.359 | D35: =IF(ISNUMBER(輸入與假設!$D$306),輸入與假設!$D$306,"不適用") -> 13.515 | E35: 不適用 | F35: 不適用 | G35: 不適用 | H35: 不適用 | J35: I 區季度共識 [Interested-party]
A36: 共識｜EBITDA 率 [Derived] | B36: % | C36: =IF(AND(ISNUMBER(輸入與假設!$C$306),ISNUMBER(輸入與假設!$C$305)),輸入與假設!$C$306/輸入與假設!$C$305,"不適用") -> 0.57963606 | D36: =IF(AND(ISNUMBER(輸入與假設!$D$306),ISNUMBER(輸入與假設!$D$305)),輸入與假設!$D$306/輸入與假設!$D$305,"不適用") -> 0.57805817 | E36: 不適用 | F36: 不適用 | G36: 不適用 | H36: 不適用 | J36: ＝共識 EBITDA ÷ 共識營收
A37: 共識非 GAAP 營業利益（含 SBC 調整，口徑不同） | B37: US$bn | C37: =IF(ISNUMBER(輸入與假設!$C$307),輸入與假設!$C$307,"不適用") -> 8.536 | D37: =IF(ISNUMBER(輸入與假設!$D$307),輸入與假設!$D$307,"不適用") -> 9.23 | E37: 不適用 | F37: 不適用 | G37: 不適用 | H37: 不適用 | J37: 口徑未揭露：只列不比較
A38: 實際｜營收 | B38: US$bn | C38: =IF(ISNUMBER(輸入與假設!C$342),輸入與假設!C$342,"") | D38: =IF(ISNUMBER(輸入與假設!D$342),輸入與假設!D$342,"") | E38: =IF(ISNUMBER(輸入與假設!E$342),輸入與假設!E$342,"") | F38: =IF(ISNUMBER(輸入與假設!F$342),輸入與假設!F$342,"") | G38: =IF(ISNUMBER(輸入與假設!G$342),輸入與假設!G$342,"") | H38: =IF(ISNUMBER(輸入與假設!H$342),輸入與假設!H$342,"")
A39: 實際｜調整後 EBITDA | B39: US$bn | C39: =IF(ISNUMBER(輸入與假設!C$343),輸入與假設!C$343,"") | D39: =IF(ISNUMBER(輸入與假設!D$343),輸入與假設!D$343,"") | E39: =IF(ISNUMBER(輸入與假設!E$343),輸入與假設!E$343,"") | F39: =IF(ISNUMBER(輸入與假設!F$343),輸入與假設!F$343,"") | G39: =IF(ISNUMBER(輸入與假設!G$343),輸入與假設!G$343,"") | H39: =IF(ISNUMBER(輸入與假設!H$343),輸入與假設!H$343,"")
A40: 實際｜EBITDA 率 | B40: % | C40: =IF(AND(ISNUMBER(輸入與假設!C$343),ISNUMBER(輸入與假設!C$342)),輸入與假設!C$343/輸入與假設!C$342,"") | D40: =IF(AND(ISNUMBER(輸入與假設!D$343),ISNUMBER(輸入與假設!D$342)),輸入與假設!D$343/輸入與假設!D$342,"") | E40: =IF(AND(ISNUMBER(輸入與假設!E$343),ISNUMBER(輸入與假設!E$342)),輸入與假設!E$343/輸入與假設!E$342,"") | F40: =IF(AND(ISNUMBER(輸入與假設!F$343),ISNUMBER(輸入與假設!F$342)),輸入與假設!F$343/輸入與假設!F$342,"") | G40: =IF(AND(ISNUMBER(輸入與假設!G$343),ISNUMBER(輸入與假設!G$342)),輸入與假設!G$343/輸入與假設!G$342,"") | H40: =IF(AND(ISNUMBER(輸入與假設!H$343),ISNUMBER(輸入與假設!H$342)),輸入與假設!H$343/輸入與假設!H$342,"") | J40: ＝實際 EBITDA ÷ 實際營收
A41: 實際｜調整後營業利益 | B41: US$bn | C41: =IF(ISNUMBER(輸入與假設!C$344),輸入與假設!C$344,"") | D41: =IF(ISNUMBER(輸入與假設!D$344),輸入與假設!D$344,"") | E41: =IF(ISNUMBER(輸入與假設!E$344),輸入與假設!E$344,"") | F41: =IF(ISNUMBER(輸入與假設!F$344),輸入與假設!F$344,"") | G41: =IF(ISNUMBER(輸入與假設!G$344),輸入與假設!G$344,"") | H41: =IF(ISNUMBER(輸入與假設!H$344),輸入與假設!H$344,"")
A42: 實際｜CapEx（毛額） | B42: US$bn | C42: =IF(ISNUMBER(輸入與假設!C$345),輸入與假設!C$345,"") | D42: =IF(ISNUMBER(輸入與假設!D$345),輸入與假設!D$345,"") | E42: =IF(ISNUMBER(輸入與假設!E$345),輸入與假設!E$345,"") | F42: =IF(ISNUMBER(輸入與假設!F$345),輸入與假設!F$345,"") | G42: =IF(ISNUMBER(輸入與假設!G$345),輸入與假設!G$345,"") | H42: =IF(ISNUMBER(輸入與假設!H$345),輸入與假設!H$345,"")
...

Sheet 運營_產能與收入
A1: 產能與收入 — 合約排程 vs 機房產能
A2: 兩條線獨立產生後相減：排程>容量→瓶頸（收不到）；容量>排程→剩餘產能（要靠新簽約賣掉）
A3: FY27 欄口徑：MW 為年底存量；標示「（模型期）」的收入列只含 2027 第 2–4 季——RPO 桶自 2026-08-31 起算，1Q 收入已實現、不再受產能約束。1Q 實際單列，兩者相加即 FY27 全年（見本頁「FY26 全年」列）。
A5: 項目 | B5: 單位 | C5: FY27 | D5: FY28 | E5: FY29 | F5: FY30 | G5: FY31 | I5: 公式／來源說明
A6: 模型期間 | C6: ="2026-09-01~05-31" -> 2026-09-01~05-31 | D6: ="2028 全年" -> 2028 全年 | E6: ="2029 全年" -> 2029 全年 | F6: ="2030 全年" -> 2030 全年 | G6: ="2031 全年" -> 2031 全年 | I6: FY27 的模型期只有第 2–4 季；1Q 已實現的營收單列於下方
A7: 模型期長度（年） | C7: =輸入與假設!C$41 -> 0.75 | D7: =輸入與假設!D$41 -> 1 | E7: =輸入與假設!E$41 -> 1 | F7: =輸入與假設!F$41 -> 1 | G7: =輸入與假設!G$41 -> 1 | I7: 只用於下方三處：容量上限、電力、維護——把年率換算成該期金額
A8: （A）機房：容量上限
A9: Accepted MW（已驗收，單調不減） | B9: MW | C9: =MAX(0,輸入與假設!C$43) -> 4668 | D9: =MAX(輸入與假設!D$43,C9) -> 7501 | E9: =MAX(輸入與假設!E$43,D9) -> 8778 | F9: =MAX(輸入與假設!F$43,E9) -> 8778 | G9: =MAX(輸入與假設!G$43,F9) -> 8778 | I9: 引擎規則：不得低於前期（產能不會消失）
A10: Billable MW（上限為 Accepted） | B10: MW | C10: =MIN(MAX(0,輸入與假設!C$44),C9) -> 3183 | D10: =MIN(MAX(0,輸入與假設!D$44),D9) -> 6340 | E10: =MIN(MAX(0,輸入與假設!E$44),E9) -> 7716 | F10: =MIN(MAX(0,輸入與假設!F$44),F9) -> 8070 | G10: =MIN(MAX(0,輸入與假設!G$44),G9) -> 8070 | I10: 引擎規則：可計費不得超過已驗收
A11: Billable MW（延誤後，計費用） | B11: MW | C11: =IF($C$50<=0,$C$10,輸入與假設!$C$36+($C$10-輸入與假設!$C$36)*MAX(0,MIN(1,($C$51-$C$50/12-0)/$C$7))+($D$10-$C$10)*MAX(0,MIN(1,($C$51-$C$50/12-$C$51)/$D$7))+($E$10-$D$10)*MAX(0,MIN(1,($C$51-$C$50/12-$D$51)/$E$7))+($F$10-$E$10)*MAX(0,MIN(1,($C$51-$C$50/12-$E$51)/$F$7))+($G$10-$F$10)*MAX(0,MIN(1,($C$51-$C$50/12-$F$51)/$G$7))) -> 2688 | D11: =IF($C$50<=0,$D$10,輸入與假設!$C$36+($C$10-輸入與假設!$C$36)*MAX(0,MIN(1,($D$51-$C$50/12-0)/$C$7))+($D$10-$C$10)*MAX(0,MIN(1,($D$51-$C$50/12-$C$51)/$D$7))+($E$10-$D$10)*MAX(0,MIN(1,($D$51-$C$50/12-$D$51)/$E$7))+($F$10-$E$10)*MAX(0,MIN(1,($D$51-$C$50/12-$E$51)/$F$7))+($G$10-$F$10)*MAX(0,MIN(1,($D$51-$C$50/12-$F$51)/$G$7))) -> 5550.75 | E11: =IF($C$50<=0,$E$10,輸入與假設!$C$36+($C$10-輸入與假設!$C$36)*MAX(0,MIN(1,($E$51-$C$50/12-0)/$C$7))+($D$10-$C$10)*MAX(0,MIN(1,($E$51-$C$50/12-$C$51)/$D$7))+($E$10-$D$10)*MAX(0,MIN(1,($E$51-$C$50/12-$D$51)/$E$7))+($F$10-$E$10)*MAX(0,MIN(1,($E$51-$C$50/12-$E$51)/$F$7))+($G$10-$F$10)*MAX(0,MIN(1,($E$51-$C$50/12-$F$51)/$G$7))) -> 7372 | F11: =IF($C$50<=0,$F$10,輸入與假設!$C$36+($C$10-輸入與假設!$C$36)*MAX(0,MIN(1,($F$51-$C$50/12-0)/$C$7))+($D$10-$C$10)*MAX(0,MIN(1,($F$51-$C$50/12-$C$51)/$D$7))+($E$10-$D$10)*MAX(0,MIN(1,($F$51-$C$50/12-$D$51)/$E$7))+($F$10-$E$10)*MAX(0,MIN(1,($F$51-$C$50/12-$E$51)/$F$7))+($G$10-$F$10)*MAX(0,MIN(1,($F$51-$C$50/12-$F$51)/$G$7))) -> 7981.5 | G11: =IF($C$50<=0,$G$10,輸入與假設!$C$36+($C$10-輸入與假設!$C$36)*MAX(0,MIN(1,($G$51-$C$50/12-0)/$C$7))+($D$10-$C$10)*MAX(0,MIN(1,($G$51-$C$50/12-$C$51)/$D$7))+($E$10-$D$10)*MAX(0,MIN(1,($G$51-$C$50/12-$D$51)/$E$7))+($F$10-$E$10)*MAX(0,MIN(1,($G$51-$C$50/12-$E$51)/$F$7))+($G$10-$F$10)*MAX(0,MIN(1,($G$51-$C$50/12-$F$51)/$G$7))) -> 8070 | I11: ＝上列往後平移建設延誤月數（以期間長度線性內插；評價日之前取期初校準值）；延誤 0 時＝上列；見（E）區（v0.2）
A12: 期初在役 MW | B12: MW | C12: =輸入與假設!$C$36 -> 1698 | D12: =C11 -> 2688 | E12: =D11 -> 5550.75 | F12: =E11 -> 7372 | G12: =F11 -> 7981.5 | I12: 前期期末＝本期期初（延誤後）
A13: 平均在役 MW（FY27 欄為第 2–4 季平均） | B13: MW | C13: =IF(輸入與假設!$C$37=1,(C12+C11)/2,C11) -> 2193 | D13: =IF(輸入與假設!$C$37=1,(D12+D11)/2,D11) -> 4119.375 | E13: =IF(輸入與假設!$C$37=1,(E12+E11)/2,E11) -> 6461.375 | F13: =IF(輸入與假設!$C$37=1,(F12+F11)/2,F11) -> 7676.75 | G13: =IF(輸入與假設!$C$37=1,(G12+G11)/2,G11) -> 8025.75 | I13: 開關在輸入頁：1＝(期初+期末)/2，0＝期末全期化
A14: 利用率 | B14: % | C14: =輸入與假設!C$45 -> 1 | D14: =輸入與假設!D$45 -> 1 | E14: =輸入與假設!E$45 -> 1 | F14: =輸入與假設!F$45 -> 1 | G14: =輸入與假設!G$45 -> 1
A15: 每 MW 年收入 | B15: US$bn/MW | C15: =輸入與假設!C$46 -> 0.0174 | D15: =輸入與假設!D$46 -> 0.0174 | E15: =輸入與假設!E$46 -> 0.0174 | F15: =輸入與假設!F$46 -> 0.0174 | G15: =輸入與假設!G$46 -> 0.0174
A16: 容量上限（模型期最多能交付的收入） | B16: US$bn | C16: =C13*輸入與假設!C$46*輸入與假設!$C$39*輸入與假設!C$45*C7 -> 28.61865 | D16: =D13*輸入與假設!D$46*輸入與假設!$C$39*輸入與假設!D$45*D7 -> 71.677125 | E16: =E13*輸入與假設!E$46*輸入與假設!$C$39*輸入與假設!E$45*E7 -> 112.42793 | F16: =F13*輸入與假設!F$46*輸入與假設!$C$39*輸入與假設!F$45*F7 -> 133.57545 | G16: =G13*輸入與假設!G$46*輸入與假設!$C$39*輸入與假設!G$45*G7 -> 139.64805 | I16: ＝平均在役 MW × 每 MW 年收入 × 利用率 × 期間係數。只看機房，不看合約
A17: （B）合約：排程 RPO
A18: 排程 RPO（模型期，依季報桶分攤） | B18: US$bn | C18: =(輸入與假設!$C$31+輸入與假設!$C$32)*(輸入與假設!C$42/輸入與假設!$C$34)*輸入與假設!$C$33 -> 64.74 | D18: =(輸入與假設!$C$31+輸入與假設!$C$32)*(輸入與假設!D$42/輸入與假設!$C$34)*輸入與假設!$C$33 -> 113.71 | E18: =(輸入與假設!$C$31+輸入與假設!$C$32)*(輸入與假設!E$42/輸入與假設!$C$34)*輸入與假設!$C$33 -> 122.84 | F18: =(輸入與假設!$C$31+輸入與假設!$C$32)*(輸入與假設!F$42/輸入與假設!$C$34)*輸入與假設!$C$33 -> 115.37 | G18: =(輸入與假設!$C$31+輸入與假設!$C$32)*(輸入與假設!G$42/輸入與假設!$C$34)*輸入與假設!$C$33 -> 112.88 | I18: ＝(8/31 RPO＋評價日後新增)×本期權重÷權重合計×五期認列比例。只看合約，不看機房
A19: （C）兩條線相減
A20: 產能瓶頸（模型期：排程 − 容量） | B20: US$bn | C20: =MAX(0,C18-C16) -> 36.12135 | D20: =MAX(0,D18-D16) -> 42.032875 | E20: =MAX(0,E18-E16) -> 10.412075 | F20: =MAX(0,F18-F16) -> 0 | G20: =MAX(0,G18-G16) -> 0 | I20: 合約有、機房沒有 → 本期收不到，且不遞延到下期（保守處理）
A21: 期初 RPO 轉換收入（模型期） | B21: US$bn | C21: =C18-C20 -> 28.61865 | D21: =D18-D20 -> 71.677125 | E21: =E18-E20 -> 112.42793 | F21: =F18-F20 -> 115.37 | G21: =G18-G20 -> 112.88 | I21: ＝排程 − 瓶頸。當瓶頸>0 時，此值恆等於容量上限
A22: 未被期初 RPO 占用的產能 | B22: US$bn | C22: =MAX(0,C16-C18) -> 0 | D22: =MAX(0,D16-D18) -> 0 | E22: =MAX(0,E16-E18) -> 0 | F22: =MAX(0,F16-F18) -> 18.20545 | G22: =MAX(0,G16-G18) -> 26.76805 | I22: 容量 − 排程。機房有、期初合約沒占滿 → 要靠新簽約
A23: 新產能簽約率 | B23: % | C23: =IF(輸入與假設!$C$38="mw",1,輸入與假設!C$47) -> 1 | D23: =IF(輸入與假設!$C$38="mw",1,輸入與假設!D$47) -> 1 | E23: =IF(輸入與假設!$C$38="mw",1,輸入與假設!E$47) -> 1 | F23: =IF(輸入與假設!$C$38="mw",1,輸入與假設!F$47) -> 1 | G23: =IF(輸入與假設!$C$38="mw",1,輸入與假設!G$47) -> 1 | I23: MW 驅動時固定 100%
A24: 新簽約收入 | B24: US$bn | C24: =C22*C23 -> 0 | D24: =D22*D23 -> 0 | E24: =E22*E23 -> 0 | F24: =F22*F23 -> 18.20545 | G24: =G22*G23 -> 26.76805 | I24: 超出期初 RPO 的產能收入（MW 驅動，簽約率 100%）
A25: 未售產能（浪費） | B25: US$bn | C25: =MAX(0,C16-C21-C24) -> 0 | D25: =MAX(0,D16-D21-D24) -> 0 | E25: =MAX(0,E16-E21-E24) -> 0 | F25: =MAX(0,F16-F21-F24) -> 0 | G25: =MAX(0,G16-G21-G24) -> 0 | I25: 蓋好但賣不掉（MW 驅動時為 0）
A26: 損益用算力收入（模型期＝RPO 轉換＋新簽約） | B26: US$bn | C26: =C21+C24 -> 28.61865 | D26: =D21+D24 -> 71.677125 | E26: =E21+E24 -> 112.42793 | F26: =F21+F24 -> 133.57545 | G26: =G21+G24 -> 139.64805 | I26: 損益與評價頁的算力收入由此連結，確保現金與損益同一組數字
A27: 核對：算力收入 − 平均在役 MW × 每 MW × 利用率 × 期間 | B27: US$bn | C27: =C26-C13*輸入與假設!C$46*輸入與假設!$C$39*輸入與假設!C$45*C7 -> 0 | D27: =D26-D13*輸入與假設!D$46*輸入與假設!$C$39*輸入與假設!D$45*D7 -> 0 | E27: =E26-E13*輸入與假設!E$46*輸入與假設!$C$39*輸入與假設!E$45*E7 -> 0 | F27: =F26-F13*輸入與假設!F$46*輸入與假設!$C$39*輸入與假設!F$45*F7 -> 0 | G27: =G26-G13*輸入與假設!G$46*輸入與假設!$C$39*輸入與假設!G$45*G7 -> 0 | I27: MW 驅動時應為 0：營收可追溯為 MW × 每 MW 年收入 × 利用率（v0.1b）
A28: 對照：評價日起 36 個月營收權重 | B28: % | C28: 1 | D28: 1 | E28: 1 | F28: 0.25 | G28: 0 | I28: RPO 36 個月內轉換的對照用（只作對照，不驅動營收）
A29: 對照：評價日起 36 個月 MW 驅動營收 | B29: US$bn | C29: =C26*C28 -> 28.61865 | D29: =D26*D28 -> 71.677125 | E29: =E26*E28 -> 112.42793 | F29: =F26*F28 -> 33.393862 | G29: =G26*G28 -> 0 | I29: 合計對照季報 RPO 664 × 36 個月內 50%（含傳統事業 RPO）；差額不回推每 MW 單價
A30: 1Q27 實際營收（季報，已實現） | B30: US$bn | C30: =輸入與假設!$C$251 -> 19.345 | D30: =0 -> 0 | E30: =0 -> 0 | F30: =0 -> 0 | G30: =0 -> 0 | I30: 2026-06-01 至 08-31 已認列營收。已實現，不受第 2–4 季產能約束，故不進入上方的瓶頸計算
A31: FY27 全年總營收（1Q 實際＋模型期算力＋服務＋傳統事業） | B31: US$bn | C31: =C30+C26+輸入與假設!C$50+輸入與假設!C$81 -> 87.49762 | D31: =D30+D26+輸入與假設!D$50+輸入與假設!D$81 -> 125.38525 | E31: =E30+E26+輸入與假設!E$50+輸入與假設!E$81 -> 168.28174 | F31: =F30+F26+輸入與假設!F$50+輸入與假設!F$81 -> 191.45057 | G31: =G30+G26+輸入與假設!G$50+輸入與假設!G$81 -> 199.37053 | I31: FY27 欄對照公司全年指引 ≥90；FY28 以後即為該年度總營收
A32: （D）收入 → 現金：三道折扣
A33: 客戶違約率 | B33: % | C33: =輸入與假設!C$48 -> 0.005 | D33: =輸入與假設!D$48 -> 0.01 | E33: =輸入與假設!E$48 -> 0.015 | F33: =輸入與假設!F$48 -> 0.02 | G33: =輸入與假設!G$48 -> 0.025
A34: 回收率 | B34: % | C34: =輸入與假設!C$49 -> 0.5 | D34: =輸入與假設!D$49 -> 0.5 | E34: =輸入與假設!E$49 -> 0.5 | F34: =輸入與假設!F$49 -> 0.5 | G34: =輸入與假設!G$49 -> 0.5
A35: 信用損失（期初 RPO 部分） | B35: US$bn | C35: =C21*輸入與假設!C$48*(1-輸入與假設!C$49) -> 0.071546625 | D35: =D21*輸入與假設!D$48*(1-輸入與假設!D$49) -> 0.35838562 | E35: =E21*輸入與假設!E$48*(1-輸入與假設!E$49) -> 0.84320944 | F35: =F21*輸入與假設!F$48*(1-輸入與假設!F$49) -> 1.1537 | G35: =G21*輸入與假設!G$48*(1-輸入與假設!G$49) -> 1.411 | I35: ＝收入 × 違約率 × (1−回收率)
A36: 收現（期初 RPO 部分） | B36: US$bn | C36: =C21-C35 -> 28.547103 | D36: =D21-D35 -> 71.318739 | E36: =E21-E35 -> 111.58472 | F36: =F21-F35 -> 114.2163 | G36: =G21-G35 -> 111.469
A37: EBITDA 率（損益與資金共用） | B37: % | C37: =輸入與假設!C$93 -> 0.65039005 | D37: =輸入與假設!D$93 -> 0.61346746 | E37: =輸入與假設!E$93 -> 0.56794063 | F37: =輸入與假設!F$93 -> 0.51660121 | G37: =輸入與假設!G$93 -> 0.46913568 | I37: 起始→穩態線性爬升
A38: 模型期總營收（算力＋服務） | B38: US$bn | C38: =C26+輸入與假設!C$50 -> 28.61865 | D38: =D26+輸入與假設!D$50 -> 71.677125 | E38: =E26+輸入與假設!E$50 -> 112.42793 | F38: =F26+輸入與假設!F$50 -> 133.57545 | G38: =G26+輸入與假設!G$50 -> 139.64805
A39: EBITDAR 率（EBITDA 率＋租金÷營收） | B39: % | C39: =輸入與假設!C$93+各期收支!C16/MAX(0.01,C38) -> 0.845075 | D39: =輸入與假設!D$93+各期收支!D16/MAX(0.01,D38) -> 0.790477 | E39: =輸入與假設!E$93+各期收支!E16/MAX(0.01,E38) -> 0.735879 | F39: =輸入與假設!F$93+各期收支!F16/MAX(0.01,F38) -> 0.681281 | G39: =輸入與假設!G$93+各期收支!G16/MAX(0.01,G38) -> 0.626683 | I39: 租金前的 EBITDA 率。EBITDA 已扣租金，而資金模型把租金列在支出端，所以要加回，避免重複扣除
A40: RPO 現金（可支應資本用途） | B40: US$bn | C40: =C36*C39 -> 24.124443 | D40: =D36*D39 -> 56.375823 | E40: =E36*E39 -> 82.112849 | F40: =F36*F39 -> 77.813395 | G40: =G36*G39 -> 69.855727 | I40: ×EBITDAR 率。租金與利息在支出頁單獨列示
A41: 新簽約現金 | B41: US$bn | C41: =C24*(1-輸入與假設!C$48*(1-輸入與假設!C$49))*C39 -> 0 | D41: =D24*(1-輸入與假設!D$48*(1-輸入與假設!D$49))*D39 -> 0 | E41: =E24*(1-輸入與假設!E$48*(1-輸入與假設!E$49))*E39 -> 0 | F41: =F24*(1-輸入與假設!F$48*(1-輸入與假設!F$49))*F39 -> 12.278997 | G41: =G24*(1-輸入與假設!G$48*(1-輸入與假設!G$49))*G39 -> 16.565393 | I41: 同樣扣信用損失、乘 EBITDAR 率
...

Sheet 運營_站點
A1: 站點租賃 — 公司揭露 vs 季報總額（檢驗租金路徑用）
A2: 季報不揭露逐站租金；下表為具名站點（company.json → defaults.sites），有租約金額者用來檢驗『每 MW 年租金』與模型租金路徑是否一致
A4: 站點 | B4: 營運方 | C4: 契約 MW | D4: 已驗收 MW | E4: 合約總值 $bn | F4: 年期 | G4: 年租金 $bn | H4: 每 MW 年租金 $m | I4: 時程 | J4: 季報對應 | K4: 說明
A5: Abilene, TX（Stargate 一期） | B5: Crusoe／Blue Owl 開發、Oracle 承租（OpenAI） | C5: 1000 | D5: 515 | E5: 未揭露 | F5: 未揭露 | I5: 2026–2027 | J5: — | K5: 法說：已交付 618 MW＝75%（口徑不明，÷1.2 換 IT 約 515）；Epoch 估設施 1.2 GW [Interested-party／Derived]
A6: Shackelford County, TX（Frontier） | B6: Vantage 開發、Oracle 承租 | C6: 1667 | D6: 0 | E6: 未揭露 | F6: 未揭露 | I6: 2027 起 | J6: — | K6: Epoch 估設施 2.0 GW（÷1.2 約 1,667 MW-IT）；開發商融資 38B（含 Port Washington）[Derived]
A7: Doña Ana County, NM（Project Jupiter） | B7: BorderPlex／STACK 開發、Oracle 承租 | C7: 1833 | D7: 0 | E7: 未揭露 | F7: 未揭露 | I7: 延後 | J7: — | K7: Epoch 估設施 2.2 GW；2026-09-24 Oracle 發不可抗力通知（能源延誤）[Interested-party]
A8: Port Washington, WI | B8: Vantage 開發、Oracle 承租 | C8: 1083 | D8: 0 | E8: 未揭露 | F8: 未揭露 | I8: 2027 起 | J8: — | K8: Epoch 估設施 1.3 GW [Derived]
A9: Saline Township, MI（The Barn） | B9: Related Digital 開發、Oracle 承租 | C9: 1167 | D9: 0 | E9: 未揭露 | F9: 未揭露 | I9: 2027 起 | J9: — | K9: Epoch 估設施 1.4 GW；開發商融資 16B [Derived]
A10: 具名站點合計 | C10: =SUM(C5:C9) -> 6750 | D10: =SUM(D5:D9) -> 515 | E10: =SUM(E5:E9) -> 0 | G10: =SUM(G5:G9) -> 0 | H10: =IF(I10>0,G10/I10*1000,0) -> 0 | I10: =SUMPRODUCT(ISNUMBER(G5:G9)*C5:C9) -> 0 | K10: 加權每 MW 年租金＝具名站點的市場基準（I 欄＝有租約金額站點的契約 MW；沒有時為 0，不適用）
A12: 對帳：具名站點 vs 季報租賃承諾總額
A13: 季報在帳租賃（未折現，已起租） | E13: 63.245 | K13: company.json → leases.facts.onBal
A14: 季報未起租租賃（未折現） | E14: 288 | K14: company.json → leases.facts.notCommenced
A15: 季報單站按造價計租上限 | E15: 0 | K15: company.json → leases.facts.singleCap（無則 0）
A16: 季報已揭露租賃承諾合計 | E16: =SUM(E13:E15) -> 351.245 | K16: 未折現金額
A17: 減：具名站點合約總值 | E17: =-E10 -> 0
A18: ＝ 未具名站點（殘差） | E18: =E16+E17 -> 351.245 | K18: 未具名站點；公司不揭露逐站租金，殘差大是必然
A19: 殘差占季報總額 | E19: =IF(E16<>0,E18/E16,0) -> 1
A21: 檢驗：模型租金路徑 ÷ 在役 MW vs 市場基準
A22: 項目 | B22: 單位 | C22: FY27 | D22: FY28 | E22: FY29 | F22: FY30 | G22: FY31
A23: 模型租金（在帳＋表外） | B23: US$bn | C23: =各期收支!C16 -> 5.5716203 | D23: =各期收支!D16 -> 12.687535 | E23: =各期收支!E16 -> 18.880963 | F23: =各期收支!F16 -> 21.997176 | G23: =各期收支!G16 -> 22.001176
A24: 平均在役 MW（已連網） | B24: MW | C24: =(輸入與假設!C$124+輸入與假設!C$43)/2 -> 3251.5 | D24: =(輸入與假設!D$124+輸入與假設!D$43)/2 -> 6084.5 | E24: =(輸入與假設!E$124+輸入與假設!E$43)/2 -> 8139.5 | F24: =(輸入與假設!F$124+輸入與假設!F$43)/2 -> 8778 | G24: =(輸入與假設!G$124+輸入與假設!G$43)/2 -> 8778
A25: 模型期長度（年） | B25: 年 | C25: =輸入與假設!C$41 -> 0.75 | D25: =輸入與假設!D$41 -> 1 | E25: =輸入與假設!E$41 -> 1 | F25: =輸入與假設!F$41 -> 1 | G25: =輸入與假設!G$41 -> 1
A26: 模型每 MW 年租金 | B26: US$m/MW | C26: =C23/C25/C24*1000 -> 2.2847385 | D26: =D23/D25/D24*1000 -> 2.0852222 | E26: =E23/E25/E24*1000 -> 2.3196711 | F26: =F23/F25/F24*1000 -> 2.505944 | G26: =G23/G25/G24*1000 -> 2.5063997 | K26: FY27 欄只含第 2–4 季租金、MW 取全期平均，略有低估
A27: 第三方租賃占比 | C27: 1 | K27: 其餘為自建，成本走 CapEx（company.json → leases.facts.share）[Assumed]
A28: 基準租金（MW×市場基準×占比） | B28: US$bn | C28: =C24*運營_站點!$H$10/1000*$C$27*C25 -> 0 | D28: =D24*運營_站點!$H$10/1000*$C$27*D25 -> 0 | E28: =E24*運營_站點!$H$10/1000*$C$27*E25 -> 0 | F28: =F24*運營_站點!$H$10/1000*$C$27*F25 -> 0 | G28: =G24*運營_站點!$H$10/1000*$C$27*G25 -> 0 | K28: 具名站點有租約金額時才有意義；否則為 0
A29: 差額（基準 − 模型） | B29: US$bn | C29: =C28-C23 -> -5.5716203 | D29: =D28-D23 -> -12.687535 | E29: =E28-E23 -> -18.880963 | F29: =F28-F23 -> -21.997176 | G29: =G28-G23 -> -22.001176 | K29: 正值＝模型租金可能低估的金額
A30: 五期差額合計 | C30: =SUM(C29:G29) -> -81.138471

Sheet 資產負債_既有債務
A1: 債務明細 — 季報（2026-08-31）逐筆＋存量利息推導
A2: 有效利率為現金票息口徑（可轉債＝票息 ÷ 到期累積倍數，本金以到期累積本金計）。本頁算出的存量利息連回『輸入』頁，再進入支出與資金頁
A4: 工具 | B4: 類別 | C4: 到期 | D4: 有效利率 | E4: 8/31 本金 | F4: 年化利息 | I4: 備註
A5: 2.80% 優先票據 2027-04 | B5: 無擔保 | C5: 2027-04 | D5: 0.028 | E5: 2.25 | F5: =D5*E5 -> 0.063 | I5: 10-K 附註 6（發行 April 2020）[Verified]
A6: 3.25% 優先票據 2027-11 | B6: 無擔保 | C6: 2027-11 | D6: 0.0325 | E6: 2.75 | F6: =D6*E6 -> 0.089375 | I6: 10-K 附註 6（發行 November 2017）[Verified]
A7: 2.30% 優先票據 2028-03 | B7: 無擔保 | C7: 2028-03 | D7: 0.023 | E7: 2 | F7: =D7*E7 -> 0.046 | I7: 10-K 附註 6（發行 March 2021）[Verified]
A8: 4.50% 優先票據 2028-05 | B8: 無擔保 | C8: 2028-05 | D8: 0.045 | E8: 0.75 | F8: =D8*E8 -> 0.03375 | I8: 10-K 附註 6（發行 February 2023）[Verified]
A9: 4.80% 優先票據 2028-08 | B9: 無擔保 | C9: 2028-08 | D9: 0.048 | E9: 1.5 | F9: =D9*E9 -> 0.072 | I9: 10-K 附註 6（發行 February 2025）[Verified]
A10: 4.55% 優先票據 2029-02 | B10: 無擔保 | C10: 2029-02 | D10: 0.0455 | E10: 3 | F10: =D10*E10 -> 0.1365 | I10: 10-K 附註 6（發行 February 2026）[Verified]
A11: 4.20% 優先票據 2029-09 | B11: 無擔保 | C11: 2029-09 | D11: 0.042 | E11: 1.5 | F11: =D11*E11 -> 0.063 | I11: 10-K 附註 6（發行 September 2024）[Verified]
A12: 6.15% 優先票據 2029-11 | B12: 無擔保 | C12: 2029-11 | D12: 0.0615 | E12: 1.25 | F12: =D12*E12 -> 0.076875 | I12: 10-K 附註 6（發行 November 2022）[Verified]
A13: 2.95% 優先票據 2030-04 | B13: 無擔保 | C13: 2030-04 | D13: 0.0295 | E13: 3.25 | F13: =D13*E13 -> 0.095875 | I13: 10-K 附註 6（發行 April 2020）[Verified]
A14: 4.65% 優先票據 2030-05 | B14: 無擔保 | C14: 2030-05 | D14: 0.0465 | E14: 0.75 | F14: =D14*E14 -> 0.034875 | I14: 10-K 附註 6（發行 February 2023）[Verified]
A15: 3.25% 優先票據 2030-05 | B15: 無擔保 | C15: 2030-05 | D15: 0.0325 | E15: 0.5 | F15: =D15*E15 -> 0.01625 | I15: 10-K 附註 6（發行 May 2015）[Verified]
A16: 4.45% 優先票據 2030-09 | B16: 無擔保 | C16: 2030-09 | D16: 0.0445 | E16: 3 | F16: =D16*E16 -> 0.1335 | I16: 10-K 附註 6（發行 September 2025）[Verified]
... A61: 商業本票 | B61: 無擔保 | C61: 2026-11 | D61: 0.0435 | E61: 0.337 | F61: =D61*E61 -> 0.0146595 | I61: 帳面總借款 − 附註 2 不含商本借款推得 [Derived]
A62: 合計（8/31） | E62: =SUM(E5:E61) -> 125.904 | F62: =SUM(F5:F61) -> 6.0449478 | I62: 應等於最新季報本金合計 125.904（company.json → latestQuarter.debtPrincipal）
A63: 加權有效利率 | D63: =F62/E62 -> 0.048012357 | I63: ＝年化利息 ÷ 本金（company.json → debt.instruments 的有效利率）
A65: 評價日後新發可轉債 | D65: 0 | E65: 0 | F65: =D65*E65 -> 0 | I65: company.json → debt.convertible（期後新發；不在五期還本表內，只計利息）
A67: 可轉債逐檔（若轉換法：有效轉換價 < 判斷價 → 視為轉股，不計利息與還本）
A68: 可轉債 | B68: 到期 | C68: 票息 | D68: 原始本金 | E68: 到期累積倍數 | F68: 轉換價 | G68: 到期所屬模型期 | H68: 強制轉換（1＝是） | I68: 備註
A69: 6.50% Series D 強制轉換特別股（2026-02） | B69: 2029-01 | C69: 0.065 | D69: 5 | E69: 1 | F69: 160.06 | G69: 2 | H69: 1 | I69: 清算價 $5B（5,000 萬股 × $100）；2029-01-15 強制轉換為普通股，每股特別股轉 499.8126–624.7657 股（2,499–3,124 萬股）；一律轉股，取稀釋最大 31.238m 股（轉換價下限 $160.06）[Interested-party 8-K 2026-02]；6.50% 股利列於 defaults.dividend.preferred；權益，不列債務本金
I70: 到期所屬模型期：0＝首期 … 4＝末期、5＝模型期後（建置時依期末日推算）
A72: 可轉債（推導） | C72: 到期本金 | D72: 若轉換股數 | E72: 有效轉換價 | F72: 融資分類 | G72: 評價第一輪 | H72: 評價第二輪 | I72: 說明
A73: =A69 -> 6.50% Series D 強制轉換特別股（2026-02） | C73: =D69*E69 -> 5 | D73: =D69/F69 -> 0.031238286 | E73: =F69*E69 -> 160.06 | F73: =IF(OR(H69=1,E73<輸入與假設!$C$152),1,0) -> 1 | G73: =IF(OR(H69=1,E73<輸入與假設!$C$175),1,0) -> 1 | H73: =IF(OR(H69=1,E73<評價_DCF與目標價!$C$66),1,0) -> 1
A74: 合計 | C74: =SUM(C73:C73) -> 5 | D74: =SUM(D73:D73) -> 0.031238286 | I74: 分類 1＝轉股（若轉換法）、0＝債務。強制轉換者一律為 1。融資分類判斷價＝股權發行價；評價第一輪＝現價；第二輪＝MIN(現價, 第一輪加權目標價)
A76: 存量利息推導（本金依季報到期表遞減）
A77: 項目 | B77: 單位 | C77: FY27 | D77: FY28 | E77: FY29 | F77: FY30 | G77: FY31 | I77: 公式／來源說明
A78: 期初本金 | B78: US$bn | C78: =E62 -> 125.904 | D78: =C80 -> 122.897 | E78: =D80 -> 112.75 | F78: =E80 -> 107.25 | G78: =F80 -> 100 | I78: FY27 期初為 8/31 本金（模型期起點）
A79: 排程還本 | B79: US$bn | C79: =輸入與假設!C$170 -> 3.007 | D79: =輸入與假設!D$170 -> 10.147 | E79: =輸入與假設!E$170 -> 5.5 | F79: =輸入與假設!F$170 -> 7.25 | G79: =輸入與假設!G$170 -> 9.75 | I79: 季報到期表
A80: 期末本金 | B80: US$bn | C80: =C78-C79 -> 122.897 | D80: =D78-D79 -> 112.75 | E80: =E78-E79 -> 107.25 | F80: =F78-F79 -> 100 | G80: =G78-G79 -> 90.25
A81: 平均本金 | B81: US$bn | C81: =(C78+C80)/2 -> 124.4005 | D81: =(D78+D80)/2 -> 117.8235 | E81: =(E78+E80)/2 -> 110 | F81: =(F78+F80)/2 -> 103.625 | G81: =(G78+G80)/2 -> 95.125
A82: 存量債務利息 | B82: US$bn | C82: =C81*資產負債_既有債務!$D$63*輸入與假設!C$41 -> 4.4795709 | D82: =D81*資產負債_既有債務!$D$63*輸入與假設!D$41 -> 5.6569839 | E82: =E81*資產負債_既有債務!$D$63*輸入與假設!E$41 -> 5.2813593 | F82: =F81*資產負債_既有債務!$D$63*輸入與假設!F$41 -> 4.9752805 | G82: =G81*資產負債_既有債務!$D$63*輸入與假設!G$41 -> 4.5671755 | I82: ＝平均本金×加權有效利率×期間長度。限制：假設利率組合不變；可轉債折價攤銷（非現金）不計
A83: 期後新發可轉債利息 | B83: US$bn | C83: =資產負債_既有債務!$F$65*輸入與假設!C$41 -> 0 | D83: =資產負債_既有債務!$F$65*輸入與假設!D$41 -> 0 | E83: =資產負債_既有債務!$F$65*輸入與假設!E$41 -> 0 | F83: =資產負債_既有債務!$F$65*輸入與假設!F$41 -> 0 | G83: =資產負債_既有債務!$F$65*輸入與假設!G$41 -> 0
A84: 可轉債到期還本（債務處理） | B84: US$bn | C84: =IF(輸入與假設!$C$144=1,SUMPRODUCT((1-資產負債_既有債務!$F$73:$F$73)*資產負債_既有債務!$C$73:$C$73*(資產負債_既有債務!$G$69:$G$69=0)),0) -> 0 | D84: =IF(輸入與假設!$C$144=1,SUMPRODUCT((1-資產負債_既有債務!$F$73:$F$73)*資產負債_既有債務!$C$73:$C$73*(資產負債_既有債務!$G$69:$G$69=1)),0) -> 0 | E84: =IF(輸入與假設!$C$144=1,SUMPRODUCT((1-資產負債_既有債務!$F$73:$F$73)*資產負債_既有債務!$C$73:$C$73*(資產負債_既有債務!$G$69:$G$69=2)),0) -> 0 | F84: =IF(輸入與假設!$C$144=1,SUMPRODUCT((1-資產負債_既有債務!$F$73:$F$73)*資產負債_既有債務!$C$73:$C$73*(資產負債_既有債務!$G$69:$G$69=3)),0) -> 0 | G84: =IF(輸入與假設!$C$144=1,SUMPRODUCT((1-資產負債_既有債務!$F$73:$F$73)*資產負債_既有債務!$C$73:$C$73*(資產負債_既有債務!$G$69:$G$69=4)),0) -> 0 | I84: 融資分類為債務的可轉債，到期當期以到期累積本金現金還本
A85: 可轉債期末餘額（債務處理） | B85: US$bn | C85: =IF(輸入與假設!$C$144=1,SUMPRODUCT((1-資產負債_既有債務!$F$73:$F$73)*資產負債_既有債務!$C$73:$C$73*(資產負債_既有債務!$G$69:$G$69>0)),SUMPRODUCT((1-資產負債_既有債務!$F$73:$F$73)*資產負債_既有債務!$C$73:$C$73)) -> 0 | D85: =IF(輸入與假設!$C$144=1,SUMPRODUCT((1-資產負債_既有債務!$F$73:$F$73)*資產負債_既有債務!$C$73:$C$73*(資產負債_既有債務!$G$69:$G$69>1)),SUMPRODUCT((1-資產負債_既有債務!$F$73:$F$73)*資產負債_既有債務!$C$73:$C$73)) -> 0 | E85: =IF(輸入與假設!$C$144=1,SUMPRODUCT((1-資產負債_既有債務!$F$73:$F$73)*資產負債_既有債務!$C$73:$C$73*(資產負債_既有債務!$G$69:$G$69>2)),SUMPRODUCT((1-資產負債_既有債務!$F$73:$F$73)*資產負債_既有債務!$C$73:$C$73)) -> 0 | F85: =IF(輸入與假設!$C$144=1,SUMPRODUCT((1-資產負債_既有債務!$F$73:$F$73)*資產負債_既有債務!$C$73:$C$73*(資產負債_既有債務!$G$69:$G$69>3)),SUMPRODUCT((1-資產負債_既有債務!$F$73:$F$73)*資產負債_既有債務!$C$73:$C$73)) -> 0 | G85: =IF(輸入與假設!$C$144=1,SUMPRODUCT((1-資產負債_既有債務!$F$73:$F$73)*資產負債_既有債務!$C$73:$C$73*(資產負債_既有債務!$G$69:$G$69>4)),SUMPRODUCT((1-資產負債_既有債務!$F$73:$F$73)*資產負債_既有債務!$C$73:$C$73)) -> 0 | I85: 到期累積本金；關閉攤還時維持全額
A86: 可轉債票息（債務處理） | B86: US$bn | C86: =IF(輸入與假設!$C$144=1,SUMPRODUCT((1-資產負債_既有債務!$F$73:$F$73)*資產負債_既有債務!$D$69:$D$69*資產負債_既有債務!$C$69:$C$69*((資產負債_既有債務!$G$69:$G$69>0)+0.5*(資產負債_既有債務!$G$69:$G$69=0))),SUMPRODUCT((1-資產負債_既有債務!$F$73:$F$73)*資產負債_既有債務!$D$69:$D$69*資產負債_既有債務!$C$69:$C$69))*輸入與假設!C$41 -> 0 | D86: =IF(輸入與假設!$C$144=1,SUMPRODUCT((1-資產負債_既有債務!$F$73:$F$73)*資產負債_既有債務!$D$69:$D$69*資產負債_既有債務!$C$69:$C$69*((資產負債_既有債務!$G$69:$G$69>1)+0.5*(資產負債_既有債務!$G$69:$G$69=1))),SUMPRODUCT((1-資產負債_既有債務!$F$73:$F$73)*資產負債_既有債務!$D$69:$D$69*資產負債_既有債務!$C$69:$C$69))*輸入與假設!D$41 -> 0 | E86: =IF(輸入與假設!$C$144=1,SUMPRODUCT((1-資產負債_既有債務!$F$73:$F$73)*資產負債_既有債務!$D$69:$D$69*資產負債_既有債務!$C$69:$C$69*((資產負債_既有債務!$G$69:$G$69>2)+0.5*(資產負債_既有債務!$G$69:$G$69=2))),SUMPRODUCT((1-資產負債_既有債務!$F$73:$F$73)*資產負債_既有債務!$D$69:$D$69*資產負債_既有債務!$C$69:$C$69))*輸入與假設!E$41 -> 0 | F86: =IF(輸入與假設!$C$144=1,SUMPRODUCT((1-資產負債_既有債務!$F$73:$F$73)*資產負債_既有債務!$D$69:$D$69*資產負債_既有債務!$C$69:$C$69*((資產負債_既有債務!$G$69:$G$69>3)+0.5*(資產負債_既有債務!$G$69:$G$69=3))),SUMPRODUCT((1-資產負債_既有債務!$F$73:$F$73)*資產負債_既有債務!$D$69:$D$69*資產負債_既有債務!$C$69:$C$69))*輸入與假設!F$41 -> 0 | G86: =IF(輸入與假設!$C$144=1,SUMPRODUCT((1-資產負債_既有債務!$F$73:$F$73)*資產負債_既有債務!$D$69:$D$69*資產負債_既有債務!$C$69:$C$69*((資產負債_既有債務!$G$69:$G$69>4)+0.5*(資產負債_既有債務!$G$69:$G$69=4))),SUMPRODUCT((1-資產負債_既有債務!$F$73:$F$73)*資產負債_既有債務!$D$69:$D$69*資產負債_既有債務!$C$69:$C$69))*輸入與假設!G$41 -> 0 | I86: ＝原始本金 × 票息 × 期間長度；到期當期計半期
A87: FY26 新增借款利息校準 | B87: US$bn | C87: =0 -> 0 | D87: =0 -> 0 | E87: =0 -> 0 | F87: =0 -> 0 | G87: =0 -> 0 | I87: 讓首期模型利息對上公司季度利息指引的校準值（company.json → defaults.intCal）；無指引時為 0
A88: 存量利息合計（連回輸入頁） | B88: US$bn | C88: =C82+C83+C86+C87 -> 4.4795709 | D88: =D82+D83+D86+D87 -> 5.6569839 | E88: =E82+E83+E86+E87 -> 5.2813593 | F88: =F82+F83+F86+F87 -> 4.9752805 | G88: =G82+G83+G86+G87 -> 4.5671755 | I88: ＝存量債務利息＋期後新發可轉債利息＋可轉債票息＋首期校準

Sheet 資產負債_新債與新股
A1: 新債與新股（類資產負債表：現金、債務、股本、槓桿）
A2: 全部為連結公式。FY27 欄的現金自 2026-08-31 起算（模型期），與 HTML『資產與負債 → 新債與新股』同口徑
A4: 項目 | B4: 單位 | C4: FY27 | D4: FY28 | E4: FY29 | F4: FY30 | G4: FY31 | I4: 公式／來源說明
A5: 現金
A6: 期初現金 | B6: US$bn | C6: =輸入與假設!$C$139 -> 36.369 | D6: =各期收支!C52 -> 10 | E6: =各期收支!D52 -> 10 | F6: =各期收支!E52 -> 42.038145 | G6: =各期收支!F52 -> 60.179667 | I6: FY27＝8/31 現金（模型期起點）
A7: 營運收支淨額（含期後股權／可轉債，不含瀑布） | B7: US$bn | C7: =各期收支!C95-輸入與假設!$C$139 -> -37.083379 | D7: =各期收支!D95-各期收支!C95 -> -27.767281 | E7: =各期收支!E95-各期收支!D95 -> 34.437506 | F7: =各期收支!F95-各期收支!E95 -> 20.540883 | G7: =各期收支!G95-各期收支!F95 -> 14.716395 | I7: ＝融資前累積現金的當期變動；負值即當期外部資金需求
A8: ＋ 瀑布：新債（額度＋資產層） | B8: US$bn | C8: =各期收支!C78 -> 11.201651 | D8: =各期收支!D78 -> 30.166642 | E8: =各期收支!E78 -> 0 | F8: =各期收支!F78 -> 0 | G8: =各期收支!G78 -> 0
A9: ＋ 瀑布：可轉債 | B9: US$bn | C9: =各期收支!C81 -> 0 | D9: =各期收支!D81 -> 0 | E9: =各期收支!E81 -> 0 | F9: =各期收支!F81 -> 0 | G9: =各期收支!G81 -> 0
