Workbook

Sheet README
A1: Oracle（ORCL）個股模型 v0.4（命題＋營收分部架構） 2026-10-27
A2: 命題：OCI 已簽約的 backlog（RPO 約 6,640 億美元，約一半來自 OpenAI／Stargate）能否以高於資金成本的報酬轉成營收與現金，同時不把資產負債表撐破。命題模組（已連網 MW × 每 MW 年收入〔Tokenomics 持有成本 × 定價倍數 k〕、延誤、租金、AI 折舊）只驅動 Cloud Infrastructure 營收線的「OCI AI 算力」子列；SaaS、授權、支援、硬體、服務各有自己的成長路徑。
A3: 核心問題：FY2029 的 OCI 營收與營業利益率，相對於資本支出與租約的擴張，以及 Oracle 的資金缺口（自由現金流為負）要如何補。
A4: ="投資建議："&Val!C80&"（加權目標價 US$"&TEXT(Val!C74,"0.0")&"，現價 US$"&TEXT(px,"0.00")&"〔2026-10-26〕，上檔空間 "&TEXT(Val!C77,"+0.0%;-0.0%")&"）" -> 投資建議：放空（加權目標價 US$73.2，現價 US$126.06〔2026-10-26〕，上檔空間 -41.9%）
A5: ="重點觀察 1：情境 B 的 FY2029 OCI 營收 "&TEXT(PL!F50,"0.0")&" 十億美元（其中 AI 算力 "&TEXT(PL!F51,"0.0")&"），只有公司路徑 114 的 "&TEXT(Thesis!D121,"0%")&"；OCI AI 營業利益率 "&TEXT(Thesis!G65,"0.0%")&"，AI 增量 ROIC "&TEXT(Thesis!G72,"0.0%")&"，對照 WACC "&TEXT(wacc,"0.0%")&"。" -> 重點觀察 1：情境 B 的 FY2029 OCI 營收 93.6 十億美元（其中 AI 算力 79.0），只有公司路徑 114 的 82%；OCI AI 營業利益率 6.2%，AI 增量 ROIC 1.7%，對照 WACC 10.5%。
A6: ="重點觀察 2：收支關卡（FY2027–FY2031 自由現金流扣股利合計）情境 A／B／C 為 "&TEXT(CF!C4,"0")&"／"&TEXT(CF!D4,"0")&"／"&TEXT(CF!E4,"0")&" 十億美元；情境 B 需新增投資級債 "&TEXT(CF!D5,"0")&"、新股 "&TEXT(CF!D6,"0")&"、高息債 "&TEXT(CF!D7,"0")&"，調整後槓桿峰值 "&TEXT(CF!D8,"0.00")&" 倍。" -> 重點觀察 2：收支關卡（FY2027–FY2031 自由現金流扣股利合計）情境 A／B／C 為 111／73／8 十億美元；情境 B 需新增投資級債 19、新股 0、高息債 0，調整後槓桿峰值 4.43 倍。
A7: ="重點觀察 3：DCF 情境加權 "&TEXT(Val!C72,"0.0")&"、分部加總 "&TEXT(Val!C73,"0.0")&"（OCI AI 以 AI 模組 DCF 計，只占情境 B 分部企業價值的 "&TEXT(Val!D66,"0%")&"）。若 OCI AI 改用 neocloud 同業倍數，加權目標價為 "&TEXT(Val!C86,"0.0")&"：差額就是 AI 的資本密集度（汰換資本支出幾乎吃掉 EBITDA）；市場共識目標價 "&TEXT(cons_tp,"0")&"，高出本模型 "&TEXT(cons_tp/Val!C74-1,"0%")&"。" -> 重點觀察 3：DCF 情境加權 41.7、分部加總 104.7（OCI AI 以 AI 模組 DCF 計，只占情境 B 分部企業價值的 15%）。若 OCI AI 改用 neocloud 同業倍數，加權目標價為 106.4：差額就是 AI 的資本密集度（汰換資本支出幾乎吃掉 EBITDA）；市場共識目標價 237，高出本模型 224%。
A9: 會計年度：FY(t)＝t−1 年 6 月～t 年 5 月。FY2027＝Q1 實績（2026-06～08）＋Q2–Q4 模型；延伸到 FY2032。金額十億美元，MW 為 IT 口徑。
A10: 營收分部層：官方報告分部（10-K 附註 13）＝Cloud and software（雲端與軟體）、Hardware、Services；其下營收線（新聞稿）＝Cloud Infrastructure（OCI）、Cloud Applications（SaaS）、Software license、Software support（以上屬 Cloud and software）、Hardware、Services。命題子列：OCI＝OCI AI 算力（命題模組）＋OCI 其他（非 AI，成長路徑）；子列合計＝母列（PL 頁核對列）。
A11: 驅動 → 推導對照（每頁輸入、推導量、因果方向）
A12: Thesis：In 頁 MW 速度、上限、延誤、計費比例、世代組合、Tokenomics 每 MW 成本、k → 已連網／計費 MW → OCI AI 營收；營運費用＝在役 MW × IF_OpexGW；租金＝未起租 288B 起租；AI 資本支出（FY27＝指引中點、其後新增 MW × IF_CapexIT、汰換依世代年份）→ AI 折舊 → OCI AI 分部利潤貢獻 → ROIC。
A13: Seg：近四季年增率（Q 頁）→ 線性收斂到長期年增（In 頁 G 節）→ SaaS、授權、支援、硬體、服務；OCI＝Thesis 兩子列 → 三分部 → 合併營收。
A14: PL：分部利潤＝OCI AI 貢獻＋其餘雲端與軟體營收 × m_sw（Q1 FY27 校準，對照 FY2024 64.1%）；硬體、服務 × FY2026 利潤率；− 未分攤費用 → GAAP 營業利益 → 利息（CF 頁）、稅 → 淨利 → EPS。
A15: CF：淨利＋D&A＋SBC＋客戶預付 − 預付認列 → 營運現金；− 資本支出 → 自由現金流；− 股利 → 收支關卡；缺口 → 現金 → 投資級債 → 新股 → 高息債（融資瀑布沿用 v0.3.1）→ 股數、淨借款、槓桿。
A16: Val：DCF（UFCF、WACC、g 3%）50%＋分部加總（OCI AI × neocloud 倍數、其餘 × 軟體倍數，FY2029 EBITDA）50%；情境 25／50／25；五級投資建議。Recon：共識與公司路徑對照；Sens：一次動一個輸入的完整重算。
A18: 與 v0.3.1 的差異：v0.3.1 是 CRWV 樣板（OCI MW × 每 MW 收入＋傳統事業四線壓成成長率），本版改為官方分部與六條營收線；AI 營運費用由 Tokenomics 正向推導（取代 EBITDAR 率校準）、AI 折舊與租金進分部利潤與 EPS；評價改為 DCF 50%＋分部加總 50%。舊引擎保留在 oracle/legacy_v0.3/。
A19: 標記：Verified、Interested-party、Analogy、Assumed、Derived；SemiAnalysis 未使用。SEC 網站在建置環境被擋，SEC 數字取自 v0.1a 事實總帳。
A20: 已知限制：(1) OCI 的 AI／非 AI 拆分不存在公開資料，Q1 非 AI 為殘差；(2) 季度分部利潤只有 Q1 FY27 與 FY26Q1；(3) OCI 同業倍數只有兩家；(4) 預付與營運資金外的營運資金變動不建模；(5) 在帳租賃負債持平、到期借款以原利率展延；(6) 續約價格衰退不建模（公司稱續約 +20%）。

Sheet In
A1: In — 輸入（藍字＝輸入；黑字＝公式；基準欄 E 進主模型；D／F＝敏感度低／高，只用於 Sens 頁、不進目標價；情境 A／B／C 的驅動見本頁最後一節「情境驅動對照」〔v0.4.2〕）。金額：十億美元（US$B）；MW＝IT 口徑（MW-IT）；每 MW 金額：百萬美元／MW·年（＝US$B／GW·年）
A2: 標記：Verified／Interested-party／Analogy／Assumed／Derived；Analogy、Assumed 給低／高區間。SemiAnalysis 未使用。「沿用 v0.3.1」＝沿用 oracle/legacy_v0.3 舊引擎 company.json 已核准的參數（原出處見來源欄）
A3: 鍵 | B3: 項目 | C3: 單位 | D3: 敏感度低 | E3: 基準 | F3: 敏感度高 | G3: 標記 | H3: 來源1 | I3: 來源2／說明
A4: A. 股價、股數
A5: px | B5: 現價（2026-10-26 收盤） | C5: US$ | E5: 126.06 | G5: Verified | H5: stockanalysis.com 歷史股價頁（https://stockanalysis.com/stocks/orcl/history/，2026-10-27 擷取）：2026-10-26 收盤 126.06 | I5: markets/invest_map/data/prices.csv：2026-10-23 收盤 126.16（stockanalysis；stockscan 兩來源），與同頁 10-23 值相同；v0.3.1 為 10-21 收盤 129.13
A6: sh_out | B6: 普通股流通在外（2026-09-07） | C6: 十億股 | E6: 3.023736 | G6: Interested-party | H6: Oracle FY27 Q1 10-Q（2026-09-11） 封面（oracle/data/oracle_facts_20261007.json sh.out.20260907） | I6: Q1 FY27 已含 ATM 發行 1.41 億股
A7: opt_dil | B7: 稀釋股數加項（選擇權等） | C7: 十億股 | E7: 0.034 | G7: Derived | H7: Q1 FY27 稀釋加權 3.000 − 基本加權 2.966（oracle/data/oracle_facts_20261007.json sh.dilW／sh.basicW.fy27q1） | I7: 各年沿用
A8: mcps_sh | B8: 強制轉換特別股轉換股數（2029-01-15，FY2029 計入） | C8: 十億股 | E8: 0.031238 | G8: Derived | H8: Series D 50,000 股 × 轉換比率上限 624.7657（oracle/data/oracle_facts_20261007.json mcps.convShares） | I8: 沿用 v0.3.1：一律轉股、取稀釋最大
A9: B. 命題：已連網 MW 路徑與延誤（沿用 v0.3.1 scenarios.mwPath／delayMonths）
A10: mw_fy26 | B10: 已連網 AI MW-IT（FY2026 年底） | C10: MW | E10: 1835 | G10: Derived | H10: FY26 交付 1.2 GW ÷ PUE 1.2 等（oracle/legacy_v0.3/company.json defaults.mwYearEnd） | I10: Oracle 未揭露累計在役 MW（不存在）；口徑不明者 ÷1.2
A11: mw_q1 | B11: 已連網 AI MW-IT（FY27Q1 末，2026-08-31） | C11: MW | E11: 2543 | G11: Derived | H11: 1,835 ＋ Q1 交付 850 MW ÷ 1.2＝708（oracle/legacy_v0.3/company.json fleet.openMw） | I11: Q1 交付 850 MW：Q1 FY27 法說（二手逐字稿，Interested-party）
A12: pace_A | B12: 情境 A：併網速度 | C12: MW-IT／年 | E12: 3333 | G12: Interested-party／Derived | H12: 公司 Q1 預告每季約 1 GW × 4 ÷ 1.2 | I12: 沿用 v0.3.1（oracle/legacy_v0.3/company.json scenarios.mwPath.pace）
A13: cap_A | B13: 情境 A：合約容量上限（已簽站點） | C13: MW-IT | E13: 8778 | G13: Derived | H13: 2,543 ＋ Oracle 承租五個 Stargate 站點 8.1 GW（Epoch 估計，設施）÷1.2 − 已交付 Abilene 515 | I13: 沿用 v0.3.1（oracle/legacy_v0.3/company.json scenarios.mwPath.contracted）；上限以後不假設新簽站點
A14: delay_A | B14: 情境 A：建設延誤（計費路徑後移月數） | C14: 月 | E14: 0 | G14: Assumed | H14: 沿用 v0.3.1（oracle/legacy_v0.3/company.json scenarios.delayMonths）：保守 6（Jupiter 天然氣管線延後近 6 個月）、基準 3、積極 0 | I14: 敏感度 0／3／6／12 月
A15: pace_B | B15: 情境 B：併網速度 | C15: MW-IT／年 | E15: 2833 | G15: Interested-party／Derived | H15: FY27Q1 實際 850 MW × 4 ÷ 1.2 | I15: 沿用 v0.3.1（oracle/legacy_v0.3/company.json scenarios.mwPath.pace）
A16: cap_B | B16: 情境 B：合約容量上限（已簽站點） | C16: MW-IT | E16: 8778 | G16: Derived | H16: 2,543 ＋ Oracle 承租五個 Stargate 站點 8.1 GW（Epoch 估計，設施）÷1.2 − 已交付 Abilene 515 | I16: 沿用 v0.3.1（oracle/legacy_v0.3/company.json scenarios.mwPath.contracted）；上限以後不假設新簽站點
A17: delay_B | B17: 情境 B：建設延誤（計費路徑後移月數） | C17: 月 | E17: 3 | G17: Assumed | H17: 沿用 v0.3.1（oracle/legacy_v0.3/company.json scenarios.delayMonths）：保守 6（Jupiter 天然氣管線延後近 6 個月）、基準 3、積極 0 | I17: 敏感度 0／3／6／12 月
A18: pace_C | B18: 情境 C：併網速度 | C18: MW-IT／年 | E18: 1000 | G18: Derived | H18: FY26 歷史 1.2 GW ÷ 1.2 | I18: 沿用 v0.3.1（oracle/legacy_v0.3/company.json scenarios.mwPath.pace）
A19: cap_C | B19: 情境 C：合約容量上限（已簽站點） | C19: MW-IT | E19: 6284 | G19: Derived／Assumed | H19: 2,543 ＋ Oracle 承租五個 Stargate 站點 8.1 GW（Epoch 估計，設施）÷1.2 − 已交付 Abilene 515；× OpenAI 相關實現 60%（Project Jupiter 不可抗力，2026-09-24；區間 50–70%） | I19: 沿用 v0.3.1（oracle/legacy_v0.3/company.json scenarios.mwPath.contracted）；上限以後不假設新簽站點
A20: delay_C | B20: 情境 C：建設延誤（計費路徑後移月數） | C20: 月 | E20: 6 | G20: Assumed | H20: 沿用 v0.3.1（oracle/legacy_v0.3/company.json scenarios.delayMonths）：保守 6（Jupiter 天然氣管線延後近 6 個月）、基準 3、積極 0 | I20: 敏感度 0／3／6／12 月
A21: u_bill | B21: 計費比例（計費 MW ÷ 延誤後在役 MW） | C21: x | D21: 0.9 | E21: 0.95 | F21: 1 | G21: Assumed | H21: 公司稱 AI 基礎設施利用率 97.9%（Q1 FY27 法說，Interested-party）；新交付產能約一季後才全額計費 | I21: v0.3.1 以收斂比例 80–90% 處理（不同口徑）
A22: C. 命題：世代組合（沿用 v0.3.1 fleet；Assumed）
A23: om_h100 | B23: Q1 末在役世代占比：Hopper H100 | C23: % | D23: 0.1 | E23: 0.2 | F23: 0.3 | G23: Assumed | H23: Oracle 未揭露機隊世代組合（找不到）；Abilene（已連網約 20%）為 GB200（二手） | I23: 沿用 v0.3.1（oracle/legacy_v0.3/company.json fleet.openMix）
A24: om_gb200 | B24: Q1 末在役世代占比：GB200 NVL72 | C24: % | D24: 0.45 | E24: 0.55 | F24: 0.7 | G24: Assumed | H24: Oracle 未揭露機隊世代組合（找不到）；Abilene（已連網約 20%）為 GB200（二手） | I24: 沿用 v0.3.1（oracle/legacy_v0.3/company.json fleet.openMix）
A25: om_gb300 | B25: Q1 末在役世代占比：GB300 NVL72 | C25: % | D25: 0.1 | E25: 0.25 | F25: 0.35 | G25: Assumed | H25: Oracle 未揭露機隊世代組合（找不到）；Abilene（已連網約 20%）為 GB200（二手） | I25: 沿用 v0.3.1（oracle/legacy_v0.3/company.json fleet.openMix）
A26: nm27_gb300 | B26: FY2027 新增產能中 GB300 占比（其餘 VR200） | C26: % | E26: 1 | G26: Assumed | H26: 沿用 v0.3.1 fleet.newMix：FY27 GB300 100% | I26: VR200 2027 下半年起交付
A27: nm28_gb300 | B27: FY2028 新增產能中 GB300 占比（其餘 VR200） | C27: % | D27: 0 | E27: 0.5 | F27: 1 | G27: Assumed | H27: 沿用 v0.3.1 fleet.newMix：FY28 GB300 50%／VR200 50% | I27: 區間：VR200 提前或延後一年
A28: nm29_gb300 | B28: FY2029 起新增產能中 GB300 占比（其餘 VR200） | C28: % | D28: 0 | E28: 0 | F28: 0.5 | G28: Assumed | H28: 沿用 v0.3.1 fleet.newMix：FY29–FY31 VR200 100% | I28: —
A29: rf_h100_30 | B29: FY2030 汰換：H100 在役量的比例（換成 VR200） | C29: % | E29: 0.5 | G29: Assumed | H29: GPU 經濟壽命 6 年（Tokenomics IF_DeprLifeIT；Oracle 伺服器耐用年限 6 年，10-K）：H100 約 FY24–FY25 上線 | I29: v0.3.1 為觸頂後穩態汰換；本版改依世代年份（判斷，見報告第 5 節）
A30: rf_h100_31 | B30: FY2031 汰換：H100 在役量的比例 | C30: % | E30: 0.5 | G30: Assumed | H30: 同上 | I30: —
A31: rf_gb200_32 | B31: FY2032 汰換：GB200 在役量的比例 | C31: % | E31: 1 | G31: Assumed | H31: GB200 約 FY26 上線 | I31: GB300 以後的汰換落在 FY2033 以後（模型期外；永續價值改用穩態汰換）
A32: D. 命題：每 MW 經濟性（Tokenomics v21.4 快照，基準成本情境；修正一自 v19.0 升級，與 MAG 相同）
A33: he_h100 | B33: 每 MW 年持有成本（經濟口徑）IF_HoldEcon｜Hopper H100 | C33: US$M／MW·年 | D33: 6.7911 | E33: 9.7031 | F33: 16.6638 | G33: Derived | H33: oracle/data/tokenomics_snapshot_v21.4.json（Tokenomics v21.4，3ac70ac；複製自 microsoft/data）Interface!13 列 | I33: 低／高＝Tokenomics 低成本／高成本情境（只作敏感度）
A34: he_gb200 | B34: 每 MW 年持有成本（經濟口徑）IF_HoldEcon｜GB200 NVL72 | C34: US$M／MW·年 | D34: 6.6118 | E34: 8.8282 | F34: 14.3186 | G34: Derived | H34: oracle/data/tokenomics_snapshot_v21.4.json（Tokenomics v21.4，3ac70ac；複製自 microsoft/data）Interface!13 列 | I34: 低／高＝Tokenomics 低成本／高成本情境（只作敏感度）
A35: he_gb300 | B35: 每 MW 年持有成本（經濟口徑）IF_HoldEcon｜GB300 NVL72 | C35: US$M／MW·年 | D35: 8.4289 | E35: 10.8864 | F35: 18.5346 | G35: Derived | H35: oracle/data/tokenomics_snapshot_v21.4.json（Tokenomics v21.4，3ac70ac；複製自 microsoft/data）Interface!13 列 | I35: 低／高＝Tokenomics 低成本／高成本情境（只作敏感度）
A36: he_vr200 | B36: 每 MW 年持有成本（經濟口徑）IF_HoldEcon｜VR200 NVL72 | C36: US$M／MW·年 | D36: 9.2191 | E36: 12.2255 | F36: 19.7506 | G36: Derived | H36: oracle/data/tokenomics_snapshot_v21.4.json（Tokenomics v21.4，3ac70ac；複製自 microsoft/data）Interface!13 列 | I36: 低／高＝Tokenomics 低成本／高成本情境（只作敏感度）
A37: cx_h100 | B37: 每 MW IT 資本支出 IF_CapexIT｜Hopper H100 | C37: US$M／MW | E37: 27.5102 | G37: Derived | H37: 同上 Interface!9 列（只含 IT；機房以租賃取得） | I37: 沿用 v0.3.1 methodology.perMw.capexName
A38: cx_gb200 | B38: 每 MW IT 資本支出 IF_CapexIT｜GB200 NVL72 | C38: US$M／MW | E38: 24.0152 | G38: Derived | H38: 同上 Interface!9 列（只含 IT；機房以租賃取得） | I38: 沿用 v0.3.1 methodology.perMw.capexName
A39: cx_gb300 | B39: 每 MW IT 資本支出 IF_CapexIT｜GB300 NVL72 | C39: US$M／MW | E39: 32.2372 | G39: Derived | H39: 同上 Interface!9 列（只含 IT；機房以租賃取得） | I39: 沿用 v0.3.1 methodology.perMw.capexName
A40: cx_vr200 | B40: 每 MW IT 資本支出 IF_CapexIT｜VR200 NVL72 | C40: US$M／MW | E40: 37.5864 | G40: Derived | H40: 同上 Interface!9 列（只含 IT；機房以租賃取得） | I40: 沿用 v0.3.1 methodology.perMw.capexName
...

Sheet Q
A1: Q — 實績（十億美元）。會計年度 FY(t)＝t−1 年 6 月～t 年 5 月。藍字＝輸入；黑字＝公式。季度＝公司新聞稿「Supplemental analysis of GAAP revenues」；年度＝10-K（經查核）
A2: 資料取自 oracle/data/oracle_facts_20261007.json（v0.1a 起 SEC 一手資料：10-K [Verified]、10-Q 與新聞稿 [Interested-party]）。官方報告分部（10-K 附註 13）：雲端與軟體（Cloud and software）、硬體、服務；營收線（新聞稿）：Cloud Infrastructure、Cloud Applications、Software license、Software support、Hardware、Services
A3: 項目 | B3: FY25 Q2（2024-09～11） | C3: FY25 Q3（～2025-02） | D3: FY25 Q4（～05） | E3: FY26 Q1（～08） | F3: FY26 Q2（～11） | G3: FY26 Q3（～2026-02） | H3: FY26 Q4（～05） | I3: FY27 Q1（2026-06～08） | J3: FY2024 | K3: FY2025 | L3: FY2026 | M3: 標記 | N3: 來源 | O3: 說明
A4: Cloud Infrastructure（OCI） | B4: 2.434 | C4: 2.652 | D4: 2.995 | E4: 3.347 | F4: 4.079 | G4: 4.888 | H4: 5.787 | I4: 7.388 | J4: 6.84 | K4: 10.234 | L4: 18.101 | M4: Verified（年度）／Interested-party（季度） | N4: 公司財報新聞稿（8-K 附件 99.1，各季）；FY2024–FY2026＝10-K
A5: Cloud Applications（SaaS） | B5: 3.503 | C5: 3.558 | D5: 3.742 | E5: 3.839 | F5: 3.898 | G5: 4.026 | H5: 4.126 | I5: 4.219 | J5: 12.934 | K5: 14.272 | L5: 15.888 | M5: Verified（年度）／Interested-party（季度） | N5: 公司財報新聞稿（8-K 附件 99.1，各季）；FY2024–FY2026＝10-K
A6: Software license | B6: 1.195 | C6: 1.129 | D6: 2.007 | E6: 0.766 | F6: 0.939 | G6: 1.15 | H6: 1.881 | I6: 0.655 | J6: 5.081 | K6: 5.201 | L6: 4.737 | M6: Verified（年度）／Interested-party（季度） | N6: 公司財報新聞稿（8-K 附件 99.1，各季）；FY2024–FY2026＝10-K
A7: Software support | B7: 4.869 | C7: 4.797 | D7: 4.961 | E7: 4.955 | F7: 4.938 | G7: 4.969 | H7: 4.943 | I7: 4.895 | J7: 19.609 | K7: 19.523 | L7: 19.804 | M7: Verified（年度）／Interested-party（季度） | N7: 公司財報新聞稿（8-K 附件 99.1，各季）；FY2024–FY2026＝10-K
A8: Hardware | B8: 0.728 | C8: 0.703 | D8: 0.85 | E8: 0.67 | F8: 0.776 | G8: 0.714 | H8: 0.924 | I8: 0.774 | J8: 3.066 | K8: 2.936 | L8: 3.084 | M8: Verified（年度）／Interested-party（季度） | N8: 公司財報新聞稿（8-K 附件 99.1，各季）；FY2024–FY2026＝10-K
A9: Services | B9: 1.33 | C9: 1.291 | D9: 1.348 | E9: 1.349 | F9: 1.428 | G9: 1.443 | H9: 1.523 | I9: 1.414 | J9: 5.431 | K9: 5.233 | L9: 5.743 | M9: Verified（年度）／Interested-party（季度） | N9: 公司財報新聞稿（8-K 附件 99.1，各季）；FY2024–FY2026＝10-K
A10: 合併營收（公司揭露） | B10: 14.059 | C10: 14.13 | D10: 15.903 | E10: 14.926 | F10: 16.058 | G10: 17.19 | H10: 19.184 | I10: 19.345 | J10: 52.961 | K10: 57.399 | L10: 67.357 | M10: Verified（年度）／Interested-party（季度） | N10: 公司財報新聞稿（8-K 附件 99.1，各季）；FY2024–FY2026＝10-K
A11: 分部：Cloud and software（＝OCI＋SaaS＋授權＋支援） | B11: =SUM(B4:B7) -> 12.001 | C11: =SUM(C4:C7) -> 12.136 | D11: =SUM(D4:D7) -> 13.705 | E11: =SUM(E4:E7) -> 12.907 | F11: =SUM(F4:F7) -> 13.854 | G11: =SUM(G4:G7) -> 15.033 | H11: =SUM(H4:H7) -> 16.737 | I11: =SUM(I4:I7) -> 17.157 | ... L11: =SUM(L4:L7) -> 58.53 | M11: Derived | N11: Oracle FY2026 10-K（2026-06-22；附註 13 分部）：雲端與軟體分部營收＝雲端（IaaS＋SaaS）＋軟體（授權＋支援） | O11: FY2026 58.530、Q1 FY27 17.157（10-K／10-Q 分部表）
A12: 分部：Hardware | B12: =B8 -> 0.728 | C12: =C8 -> 0.703 | D12: =D8 -> 0.85 | E12: =E8 -> 0.67 | F12: =F8 -> 0.776 | G12: =G8 -> 0.714 | H12: =H8 -> 0.924 | I12: =I8 -> 0.774 | ... L12: =L8 -> 3.084 | M12: Derived | N12: Oracle FY2026 10-K（2026-06-22；附註 13 分部）
A13: 分部：Services | B13: =B9 -> 1.33 | C13: =C9 -> 1.291 | D13: =D9 -> 1.348 | E13: =E9 -> 1.349 | F13: =F9 -> 1.428 | G13: =G9 -> 1.443 | H13: =H9 -> 1.523 | I13: =I9 -> 1.414 | ... L13: =L9 -> 5.743 | M13: Derived | N13: Oracle FY2026 10-K（2026-06-22；附註 13 分部）
A14: 檢查：營收線合計 − 合併營收（應為 0） | B14: =SUM(B4:B9)-B10 -> 0 | C14: =SUM(C4:C9)-C10 -> 0 | D14: =SUM(D4:D9)-D10 -> 0 | E14: =SUM(E4:E9)-E10 -> 0 | F14: =SUM(F4:F9)-F10 -> 0 | G14: =SUM(G4:G9)-G10 -> 0 | H14: =SUM(H4:H9)-H10 -> 0 | I14: =SUM(I4:I9)-I10 -> 0 | ... L14: =SUM(L4:L9)-L10 -> 0 | M14: — | N14: —
A15: 檢查：分部合計 − 合併營收（應為 0） | B15: =SUM(B11:B13)-B10 -> 0 | C15: =SUM(C11:C13)-C10 -> 0 | D15: =SUM(D11:D13)-D10 -> 0 | E15: =SUM(E11:E13)-E10 -> 0 | F15: =SUM(F11:F13)-F10 -> 0 | G15: =SUM(G11:G13)-G10 -> 0 | H15: =SUM(H11:H13)-H10 -> 0 | I15: =SUM(I11:I13)-I10 -> 0 | ... L15: =SUM(L11:L13)-L10 -> 0 | M15: — | N15: —
A16: 分部利潤：Cloud and software | E16: 7.691 | I16: 9.358 | J16: 28.514 | K16: 30.93 | L16: 34.468 | M16: Verified（年度）／Interested-party（季度） | N16: 10-K 附註 13（年度）；10-Q 附註 9（Q1 FY27 與去年同季） | O16: 分部利潤只含直接成本，不含研發、管理、無形資產攤銷、重組、SBC、利息。FY25 Q2–Q4、FY26 Q2–Q4 季度分部利潤：未找到（10-Q 在本環境無法開啟）
A17: 分部利潤：Hardware | I17: 0.452 | J17: 1.915 | K17: 1.918 | L17: 2.017 | M17: Verified（年度）／Interested-party（季度） | N17: 10-K 附註 13（年度）；10-Q 附註 9（Q1 FY27 與去年同季） | O17: 季度（除 Q1 FY27）：未找到
A18: 分部利潤：Services | I18: 0.445 | J18: 0.916 | K18: 0.993 | L18: 1.533 | M18: Verified（年度）／Interested-party（季度） | N18: 10-K 附註 13（年度）；10-Q 附註 9（Q1 FY27 與去年同季） | O18: 季度（除 Q1 FY27）：未找到
A19: 分部利潤合計 | I19: =SUM(I16:I18) -> 10.255 | J19: =SUM(J16:J18) -> 31.345 | K19: =SUM(K16:K18) -> 33.841 | L19: =SUM(L16:L18) -> 38.018 | M19: Derived | N19: —
A20: 未分攤費用（＝分部利潤合計 − 營業利益） | I20: =I19-I21 -> 3.527 | J20: =J19-J21 -> 15.992 | K20: =K19-K21 -> 16.163 | L20: =L19-L21 -> 17.412 | M20: Derived | N20: — | O20: 研發、管理、無形資產攤銷、重組、SBC、收購相關等
A21: 營業利益（GAAP） | B21: 4.22 | C21: 4.358 | D21: 5.109 | E21: 4.277 | F21: 4.731 | G21: 5.464 | H21: 6.133 | I21: 6.728 | J21: 15.353 | K21: 17.678 | L21: 20.606 | M21: Verified（年度）／Interested-party（季度） | N21: 公司財報新聞稿（8-K 附件 99.1，各季）；FY2024–FY2026＝10-K
A22: 檢查：分部利潤三項合計 − 公司揭露分部利潤合計（FY2026 38.018，應為 0） | L22: =L19-L51 -> 0 | M22: — | N22: Oracle FY2026 10-K（2026-06-22；附註 13 分部）
A23: 營業利益（非 GAAP） | B23: 6.096 | C23: 6.195 | D23: 7.035 | E23: 6.236 | F23: 6.721 | G23: 7.378 | H23: 8.59 | I23: 8.151 | K23: 25.033 | L23: 28.926 | M23: Interested-party | N23: 公司財報新聞稿（8-K 附件 99.1，各季）；FY2024–FY2026＝10-K
A24: 折舊與攤銷（D&A） | B24: 1.499 | C24: 1.551 | D24: 1.696 | E24: 1.771 | F24: 2.11 | G24: 2.566 | H24: 2.847 | I24: 3.358 | J24: 6.139 | K24: 6.174 | L24: 9.294 | M24: Verified（年度）／Interested-party（季度） | N24: 公司財報新聞稿（8-K 附件 99.1，各季）；FY2024–FY2026＝10-K
A25: 股份基礎給付（SBC） | B25: 1.17 | C25: 1.198 | D25: 1.3 | E25: 1.124 | F25: 1.156 | G25: 1.328 | H25: 1.203 | I25: 1.127 | J25: 3.974 | K25: 4.674 | L25: 4.811 | M25: Verified（年度）／Interested-party（季度） | N25: 公司財報新聞稿（8-K 附件 99.1，各季）；FY2024–FY2026＝10-K
A26: 利息費用 | B26: 0.866 | C26: 0.892 | D26: 0.978 | E26: 0.923 | F26: 1.057 | G26: 1.18 | H26: 1.438 | I26: 1.428 | J26: 3.514 | K26: 3.578 | L26: 4.599 | M26: Verified（年度）／Interested-party（季度） | N26: 公司財報新聞稿（8-K 附件 99.1，各季）；FY2024–FY2026＝10-K
A27: 淨利（GAAP） | B27: 3.151 | C27: 2.936 | D27: 3.427 | E27: 2.927 | F27: 6.135 | G27: 3.721 | H27: 4.304 | I27: 4.76 | J27: 10.467 | K27: 12.443 | L27: 17.087 | M27: Verified（年度）／Interested-party（季度） | N27: 公司財報新聞稿（8-K 附件 99.1，各季）；FY2024–FY2026＝10-K
A28: 營運現金流 | B28: 1.304 | C28: 5.933 | D28: 6.157 | E28: 8.14 | F28: 2.066 | G28: 7.151 | H28: 14.62 | I28: 23.103 | J28: 18.673 | K28: 20.821 | L28: 31.977 | M28: Verified（年度）／Interested-party（季度） | N28: 公司財報新聞稿（8-K 附件 99.1，各季）；FY2024–FY2026＝10-K
A29: 資本支出（現金） | B29: 3.97 | C29: 5.862 | D29: 9.08 | E29: 8.502 | F29: 12.033 | G29: 18.635 | H29: 16.493 | I29: 28.499 | J29: 6.866 | K29: 21.215 | L29: 55.663 | M29: Verified（年度）／Interested-party（季度） | N29: 公司財報新聞稿（8-K 附件 99.1，各季）；FY2024–FY2026＝10-K
A30: 自由現金流（營運現金流 − 資本支出） | B30: =B28-B29 -> -2.666 | C30: =C28-C29 -> 0.071 | D30: =D28-D29 -> -2.923 | E30: =E28-E29 -> -0.362 | F30: =F28-F29 -> -9.967 | G30: =G28-G29 -> -11.484 | H30: =H28-H29 -> -1.873 | I30: =I28-I29 -> -5.396 | ... L30: =L28-L29 -> -23.686 | M30: Derived | N30: —
A31: 股利支付（普通股＋特別股） | I31: 1.565 | J31: 4.391 | K31: 4.743 | L31: 5.787 | M31: Verified（年度）／Interested-party（季度） | N31: 公司財報新聞稿（8-K 附件 99.1，各季）；FY2024–FY2026＝10-K | O31: 季度（除 Q1 FY27）：未找到（只取得年度與 Q1）
A32: 買回普通股 | I32: 0 | J32: 1.202 | K32: 0.6 | L32: 0.095 | M32: Verified（年度）／Interested-party（季度） | N32: 公司財報新聞稿（8-K 附件 99.1，各季）；FY2024–FY2026＝10-K | O32: 季度（除 Q1 FY27）：未找到
A33: 檢查：自由現金流 − 公司揭露值（應為 0） | B33: =B30--2.666 -> 0 | C33: =C30-0.071 -> -2.6367797e-16 | D33: =D30--2.923 -> 0 | E33: =E30--0.362 -> 0 | F33: =F30--9.967 -> 0 | G33: =G30--11.484 -> 0 | H33: =H30--1.873 -> 0 | I33: =I30--5.396 -> 0 | J33: =J30-11.807 -> 0 | K33: =K30--0.394 -> 1.6653345e-15 | L33: =L30--23.686 -> 0 | M33: — | N33: —
A35: 近四季年增率（FY26Q2–FY27Q1 合計 ÷ FY25Q2–FY26Q1 合計 − 1；Seg 頁 FY2027 起點；沿用 v0.3.1 g0 方法）
A36: Cloud Infrastructure（OCI）：近四季年增 | B36: =SUM(F4:I4)/SUM(B4:E4)-1 -> 0.93752188 | M36: Derived
A37: Cloud Applications（SaaS）：近四季年增 | B37: =SUM(F5:I5)/SUM(B5:E5)-1 -> 0.1111187 | M37: Derived
A38: Software license：近四季年增 | B38: =SUM(F6:I6)/SUM(B6:E6)-1 -> -0.092603492 | M38: Derived
A39: Software support：近四季年增 | B39: =SUM(F7:I7)/SUM(B7:E7)-1 -> 0.008323971 | M39: Derived
A40: Hardware：近四季年增 | B40: =SUM(F8:I8)/SUM(B8:E8)-1 -> 0.080311759 | M40: Derived
A41: Services：近四季年增 | B41: =SUM(F9:I9)/SUM(B9:E9)-1 -> 0.092139902 | M41: Derived
...

Sheet Thesis
A1: Thesis — 命題模組：OCI 的已簽約 backlog（RPO 664B，OpenAI／Stargate 集中）能否以高於資金成本的報酬轉成營收與現金。只驅動 Cloud Infrastructure 營收線的「OCI AI 算力」子列；AI 資本支出接到 AI 折舊與分部利潤
A2: 已連網 MW（期末）＝MIN(合約上限, 前期＋併網速度 × 期間)；計費 MW＝（平均在役 − 延誤月數 ÷ 12 × 期間新增速度）× 計費比例；每 MW 年收入＝在役世代加權 IF_HoldEcon × k；營運費用＝在役 MW × IF_OpexGW；租金＝未起租 288B 依 11 季起租、17 年直線；折舊＝Q1 在役基數＋在建工程＋新資本支出 ÷ 6 年（當年半年）
A3: 項目 | B3: 單位 | C3: FY27 Q1（估計） | D3: FY27 Q2–Q4（模型） | E3: FY2027 | F3: FY2028 | G3: FY2029 | H3: FY2030 | I3: FY2031 | J3: FY2032 | K3: 說明
A4: 情境 A（樂觀：依公司時程交付、不延誤）
A5: 期間長度 | B5: 年 | C5: 0.25 | D5: 0.75 | E5: 1 | F5: 1 | G5: 1 | H5: 1 | I5: 1 | J5: 1
A6: 已連網 AI MW-IT（期末） | B6: MW | C6: =mw_q1 -> 2543 | D6: =MIN(cap_A,mw_q1+pace_A*D5) -> 5042.75 | E6: =D6 -> 5042.75 | F6: =MIN(cap_A,E6+pace_A*F5) -> 8375.75 | G6: =MIN(cap_A,F6+pace_A*G5) -> 8778 | H6: =G6+MAX(0,MIN(cap_A,G6+pace_A)-G6)+(tp_g*G6-MAX(0,MIN(cap_A,G6+pace_A)-G6))*1/3 -> 8865.78 | I6: =H6+MAX(0,MIN(cap_A,H6+pace_A)-H6)+(tp_g*H6-MAX(0,MIN(cap_A,H6+pace_A)-H6))*2/3 -> 9043.0956 | J6: =I6+MAX(0,MIN(cap_A,I6+pace_A)-I6)+(tp_g*I6-MAX(0,MIN(cap_A,I6+pace_A)-I6))*3/3 -> 9314.3885 | K6: FY2028–29：MIN(上限 cap_A, 前期＋速度)；FY2030–32：新增量線性收斂到「前期 × 永續成長 g」（修正一 F5；超過已簽上限的部分視為新簽約）
A7: 期間新增已連網 MW | B7: MW | C7: =C6-mw_fy26 -> 708 | D7: =D6-C6 -> 2499.75 | E7: =E6-mw_fy26 -> 3207.75 | F7: =F6-E6 -> 3333 | G7: =G6-F6 -> 402.25 | H7: =H6-G6 -> 87.78 | I7: =I6-H6 -> 177.3156 | J7: =J6-I6 -> 271.29287
A8: 平均已連網 MW | B8: MW | C8: =(mw_fy26+C6)/2 -> 2189 | D8: =(C6+D6)/2 -> 3792.875 | E8: =(C8*C5+D8*D5)/E5 -> 3391.9062 | F8: =(E6+F6)/2 -> 6709.25 | G8: =(F6+G6)/2 -> 8576.875 | H8: =(G6+H6)/2 -> 8821.89 | I8: =(H6+I6)/2 -> 8954.4378 | J8: =(I6+J6)/2 -> 9178.742
A9: 延誤後平均在役 MW（Q1 為實績期，不延誤） | B9: MW | C9: =C8 -> 2189 | D9: =MAX(0,D8-delay_A/12*D7/D5) -> 3792.875 | E9: =(C9*C5+D9*D5)/E5 -> 3391.9062 | F9: =MAX(0,F8-delay_A/12*F7/F5) -> 6709.25 | G9: =MAX(0,G8-delay_A/12*G7/G5) -> 8576.875 | H9: =MAX(0,H8-delay_A/12*H7/H5) -> 8821.89 | I9: =MAX(0,I8-delay_A/12*I7/I5) -> 8954.4378 | J9: =MAX(0,J8-delay_A/12*J7/J5) -> 9178.742 | K9: 延誤月數：In 頁 delay_A
A10: 計費 MW（× 計費比例） | B10: MW | C10: =C9*u_bill -> 2079.55 | D10: =D9*u_bill -> 3603.2312 | E10: =E9*u_bill -> 3222.3109 | F10: =F9*u_bill -> 6373.7875 | G10: =G9*u_bill -> 8148.0312 | H10: =H9*u_bill -> 8380.7955 | I10: =I9*u_bill -> 8506.7159 | J10: =J9*u_bill -> 8719.8049
A11: 世代存量（期末，MW）：Q1 末依 In 頁占比；新增依 In 頁新增組合；汰換換成 VR200
A12: Hopper H100 | B12: MW | C12: =C6*om_h100 -> 508.6 | D12: =C12 -> 508.6 | E12: =D12 -> 508.6 | F12: =E12 -> 508.6 | G12: =F12 -> 508.6 | H12: =G12-C12*rf_h100_30 -> 254.3 | I12: =H12-C12*rf_h100_31 -> 0 | J12: =I12 -> 0
A13: GB200 NVL72 | B13: MW | C13: =C6*om_gb200 -> 1398.65 | D13: =C13 -> 1398.65 | E13: =D13 -> 1398.65 | F13: =E13 -> 1398.65 | G13: =F13 -> 1398.65 | H13: =G13 -> 1398.65 | I13: =H13 -> 1398.65 | J13: =I13-C13*rf_gb200_32 -> 0
A14: GB300 NVL72 | B14: MW | C14: =C6*om_gb300 -> 635.75 | D14: =C14+D7*nm27_gb300 -> 3135.5 | E14: =D14 -> 3135.5 | F14: =E14+F7*nm28_gb300 -> 4802 | G14: =F14+G7*nm29_gb300 -> 4802 | H14: =G14+H7*nm29_gb300 -> 4802 | I14: =H14+I7*nm29_gb300 -> 4802 | J14: =I14+J7*nm29_gb300 -> 4802
A15: VR200 NVL72 | B15: MW | C15: =0 -> 0 | D15: =C15+D7*(1-nm27_gb300) -> 0 | E15: =D15 -> 0 | F15: =E15+F7*(1-nm28_gb300) -> 1666.5 | G15: =F15+G7*(1-nm29_gb300) -> 2068.75 | H15: =G15+H7*(1-nm29_gb300)+C12*rf_h100_30 -> 2410.83 | I15: =H15+I7*(1-nm29_gb300)+C12*rf_h100_31 -> 2842.4456 | J15: =I15+J7*(1-nm29_gb300)+C13*rf_gb200_32 -> 4512.3885
A16: 檢查：世代存量合計 − 已連網 MW（應為 0） | B16: MW | C16: =SUM(C12:C15)-C6 -> 0 | D16: =SUM(D12:D15)-D6 -> 0 | E16: =SUM(E12:E15)-E6 -> 0 | F16: =SUM(F12:F15)-F6 -> 0 | G16: =SUM(G12:G15)-G6 -> 0 | H16: =SUM(H12:H15)-H6 -> 0 | I16: =SUM(I12:I15)-I6 -> 0 | J16: =SUM(J12:J15)-J6 -> 0
A17: 每 MW 錨：在役世代加權 IF_HoldEcon | B17: US$M／MW·年 | C17: =om_h100*he_h100+om_gb200*he_gb200+om_gb300*he_gb300 -> 9.51773 | D17: =((C12+D12)*he_h100+(C13+D13)*he_gb200+(C14+D14)*he_gb300+(C15+D15)*he_vr200)/(C6+D6) -> 9.968751 | E17: =(C17*C10*C5+D17*D10*D5)/(C10*C5+D10*D5) -> 9.8959833 | F17: =((E12+F12)*he_h100+(E13+F13)*he_gb200+(E14+F14)*he_gb300+(E15+F15)*he_vr200)/(E6+F6) -> 10.533943 | G17: =((F12+G12)*he_h100+(F13+G13)*he_gb200+(F14+G14)*he_gb300+(F15+G15)*he_vr200)/(F6+G6) -> 10.772187 | H17: =((G12+H12)*he_h100+(G13+H13)*he_gb200+(G14+H14)*he_gb300+(G15+H15)*he_vr200)/(G6+H6) -> 10.848906 | I17: =((H12+I12)*he_h100+(H13+I13)*he_gb200+(H14+I14)*he_gb300+(H15+I15)*he_vr200)/(H6+I6) -> 10.940917 | J17: =((I12+J12)*he_h100+(I13+J13)*he_gb200+(I14+J14)*he_gb300+(I15+J15)*he_vr200)/(I6+J6) -> 11.26609 | K17: 期初＋期末存量平均加權（Tokenomics v21.4 基準成本）
A18: 每 MW 年收入（錨 × k × k 調整） | B18: US$M／MW·年 | C18: =C17*k_mix*k_adj -> 9.3723584 | D18: =D17*k_mix*k_adj -> 9.8164907 | E18: =E17*k_mix*k_adj -> 9.7448344 | F18: =F17*k_mix*k_adj -> 10.37305 | G18: =G17*k_mix*k_adj -> 10.607655 | H18: =H17*k_mix*k_adj -> 10.683202 | I18: =I17*k_mix*k_adj -> 10.773808 | J18: =J17*k_mix*k_adj -> 11.094015 | K18: k：In 頁 k_mix
A19: OCI AI 算力營收（命題子列） | B19: US$B | C19: =C10*C18*C5/1000 -> 4.872572 | D19: =D10*D18*D5/1000 -> 26.528314 | E19: =C19+D19 -> 31.400886 | F19: =F10*F18*F5/1000 -> 66.115616 | G19: =G10*G18*G5/1000 -> 86.431505 | H19: =H10*H18*H5/1000 -> 89.533734 | I19: =I10*I18*I5/1000 -> 91.649727 | J19: =J10*J18*J5/1000 -> 96.737643 | K19: Q1 為估計（Q1 實際 OCI 7.388 的 AI 部分；其餘為非 AI 殘差）
A20: 每 MW 年營運費用：在役世代加權 IF_OpexGW | B20: US$M／MW·年 | C20: =om_h100*ox_h100+om_gb200*ox_gb200+om_gb300*ox_gb300 -> 1.8693 | D20: =((C12+D12)*ox_h100+(C13+D13)*ox_gb200+(C14+D14)*ox_gb300+(C15+D15)*ox_vr200)/(C6+D6) -> 1.906636 | E20: =(C20*C9*C5+D20*D9*D5)/(C9*C5+D9*D5) -> 1.9006122 | F20: =((E12+F12)*ox_h100+(E13+F13)*ox_gb200+(E14+F14)*ox_gb300+(E15+F15)*ox_vr200)/(E6+F6) -> 1.9534292 | G20: =((F12+G12)*ox_h100+(F13+G13)*ox_gb200+(F14+G14)*ox_gb300+(F15+G15)*ox_vr200)/(F6+G6) -> 1.9731557 | H20: =((G12+H12)*ox_h100+(G13+H13)*ox_gb200+(G14+H14)*ox_gb300+(G15+H15)*ox_vr200)/(G6+H6) -> 1.9795076 | I20: =((H12+I12)*ox_h100+(H13+I13)*ox_gb200+(H14+I14)*ox_gb300+(H15+I15)*ox_vr200)/(H6+I6) -> 1.9871247 | J20: =((I12+J12)*ox_h100+(I13+J13)*ox_gb200+(I14+J14)*ox_gb300+(I15+J15)*ox_vr200)/(I6+J6) -> 2.0140488
A21: AI 營運費用（電費、維護、人員、稅與保險；不含折舊、租金） | B21: US$B | C21: =C9*C20*C5/1000 -> 1.0229744 | D21: =D9*D20*D5/1000 -> 5.4237241 | E21: =C21+D21 -> 6.4466985 | F21: =F9*F20*F5/1000 -> 13.106045 | G21: =G9*G20*G5/1000 -> 16.92351 | H21: =H9*H20*H5/1000 -> 17.462998 | I21: =I9*I20*I5/1000 -> 17.793585 | J21: =J9*J20*J5/1000 -> 18.486435 | K21: 延誤後在役 MW × 每 MW 營運費用
A22: AI 機房租金（未起租 288B 依序起租＋超過已簽範圍的新租約） | B22: US$B | C22: =0 -> 0 | D22: =lease_unc/lease_term*IF(lease_q0<=lease_q,(lease_q0)*((lease_q0)+1)/2,lease_q*(lease_q+1)/2+((lease_q0)-lease_q)*lease_q)/(lease_q*4) -> 2.3101604 | E22: =D22 -> 2.3101604 | F22: =lease_unc/lease_term*(IF(lease_q0+4*1<=lease_q,(lease_q0+4*1)*((lease_q0+4*1)+1)/2,lease_q*(lease_q+1)/2+((lease_q0+4*1)-lease_q)*lease_q)-IF(lease_q0+4*0<=lease_q,(lease_q0+4*0)*((lease_q0+4*0)+1)/2,lease_q*(lease_q+1)/2+((lease_q0+4*0)-lease_q)*lease_q))/(lease_q*4)+MAX(0,F8-cap_B)*lease_unc/lease_term/(cap_B-mw_q1) -> 8.4705882 | G22: =lease_unc/lease_term*(IF(lease_q0+4*2<=lease_q,(lease_q0+4*2)*((lease_q0+4*2)+1)/2,lease_q*(lease_q+1)/2+((lease_q0+4*2)-lease_q)*lease_q)-IF(lease_q0+4*1<=lease_q,(lease_q0+4*1)*((lease_q0+4*1)+1)/2,lease_q*(lease_q+1)/2+((lease_q0+4*1)-lease_q)*lease_q))/(lease_q*4)+MAX(0,G8-cap_B)*lease_unc/lease_term/(cap_B-mw_q1) -> 14.631016 | H22: =lease_unc/lease_term*(IF(lease_q0+4*3<=lease_q,(lease_q0+4*3)*((lease_q0+4*3)+1)/2,lease_q*(lease_q+1)/2+((lease_q0+4*3)-lease_q)*lease_q)-IF(lease_q0+4*2<=lease_q,(lease_q0+4*2)*((lease_q0+4*2)+1)/2,lease_q*(lease_q+1)/2+((lease_q0+4*2)-lease_q)*lease_q))/(lease_q*4)+MAX(0,H8-cap_B)*lease_unc/lease_term/(cap_B-mw_q1) -> 17.06043 | I22: =lease_unc/lease_term*(IF(lease_q0+4*4<=lease_q,(lease_q0+4*4)*((lease_q0+4*4)+1)/2,lease_q*(lease_q+1)/2+((lease_q0+4*4)-lease_q)*lease_q)-IF(lease_q0+4*3<=lease_q,(lease_q0+4*3)*((lease_q0+4*3)+1)/2,lease_q*(lease_q+1)/2+((lease_q0+4*3)-lease_q)*lease_q))/(lease_q*4)+MAX(0,I8-cap_B)*lease_unc/lease_term/(cap_B-mw_q1) -> 17.420577 | J22: =lease_unc/lease_term*(IF(lease_q0+4*5<=lease_q,(lease_q0+4*5)*((lease_q0+4*5)+1)/2,lease_q*(lease_q+1)/2+((lease_q0+4*5)-lease_q)*lease_q)-IF(lease_q0+4*4<=lease_q,(lease_q0+4*4)*((lease_q0+4*4)+1)/2,lease_q*(lease_q+1)/2+((lease_q0+4*4)-lease_q)*lease_q))/(lease_q*4)+MAX(0,J8-cap_B)*lease_unc/lease_term/(cap_B-mw_q1) -> 18.030036 | K22: lease_q 季平均起租（第 j 季已起租 MIN(j, lease_q)／lease_q）、lease_term 年直線；平均在役超過 cap_B 的部分以同一每 MW 租金加計（修正一）
A23: AI 成長型資本支出（FY27＝指引中點 − 非 AI；其後＝新增 MW × IF_CapexIT，λ 提前付款） | B23: US$B | C23: =capex_q1-nonai_cx*(q1_rev-C19) -> 27.341206 | D23: =E23-C23 -> 60.18958 | E23: =capex_g27-nonai_cx*(Seg!D28-E19) -> 87.530786 | F23: =(F7*(1-lam)*(nm28_gb300*cx_gb300+(1-nm28_gb300)*cx_vr200)+G7*lam*(nm29_gb300*cx_gb300+(1-nm29_gb300)*cx_vr200))/1000 -> 80.926364 | G23: =(G7*(1-lam)*(nm29_gb300*cx_gb300+(1-nm29_gb300)*cx_vr200)+H7*lam*(nm29_gb300*cx_gb300+(1-nm29_gb300)*cx_vr200))/1000 -> 10.982201 | H23: =(H7*(1-lam)*(nm29_gb300*cx_gb300+(1-nm29_gb300)*cx_vr200)+I7*lam*(nm29_gb300*cx_gb300+(1-nm29_gb300)*cx_vr200))/1000 -> 4.4771965 | I23: =(I7*(1-lam)*(nm29_gb300*cx_gb300+(1-nm29_gb300)*cx_vr200)+J7*lam*(nm29_gb300*cx_gb300+(1-nm29_gb300)*cx_vr200))/1000 -> 7.9009486 | J23: =(J7*(1-lam)*(nm29_gb300*cx_gb300+(1-nm29_gb300)*cx_vr200)+J7*(1+tp_g)*lam*(nm29_gb300*cx_gb300+(1-nm29_gb300)*cx_vr200))/1000 -> 10.30399 | K23: FY2027：In 頁 capex_g27（三情境相同）
A24: AI 汰換資本支出（依世代年份，換成 VR200） | B24: US$B | C24: =0 -> 0 | D24: =0 -> 0 | E24: =0 -> 0 | F24: =0 -> 0 | G24: =0 -> 0 | H24: =C12*rf_h100_30*cx_vr200/1000 -> 9.5582215 | I24: =C12*rf_h100_31*cx_vr200/1000 -> 9.5582215 | J24: =C13*rf_gb200_32*cx_vr200/1000 -> 52.570218
A25: AI 資本支出合計 | B25: US$B | C25: =C23+C24 -> 27.341206 | D25: =D23+D24 -> 60.18958 | E25: =E23+E24 -> 87.530786 | F25: =F23+F24 -> 80.926364 | G25: =G23+G24 -> 10.982201 | H25: =H23+H24 -> 14.035418 | I25: =I23+I24 -> 17.45917 | J25: =J23+J24 -> 62.874208
A26: Q1 在役 AI 設備折舊（年率；扣汰換世代） | B26: US$B／年 | C26: =(dep_q1-nonai_dep_q)*4 -> 9.671 | D26: =(dep_q1-nonai_dep_q)*4 -> 9.671 | E26: =(dep_q1-nonai_dep_q)*4 -> 9.671 | F26: =(dep_q1-nonai_dep_q)*4 -> 9.671 | G26: =(dep_q1-nonai_dep_q)*4 -> 9.671 | H26: =MAX(0,(dep_q1-nonai_dep_q)*4-rf_h100_30*C12*cx_h100/life_ai/1000) -> 8.505026 | I26: =MAX(0,(dep_q1-nonai_dep_q)*4-(rf_h100_30+rf_h100_31)*C12*cx_h100/life_ai/1000) -> 7.339052 | J26: =MAX(0,(dep_q1-nonai_dep_q)*4-(rf_h100_30+rf_h100_31)*C12*cx_h100/life_ai/1000-rf_gb200_32*C13*cx_gb200/life_ai/1000) -> 1.7409088 | K26: Q1 折舊 3.2 − 非 AI 折舊（FY2024 水準）；汰換世代的舊折舊扣除
A27: AI 折舊（進分部利潤與營業利益） | B27: US$B | C27: =C26*C5 -> 2.41775 | D27: =D26*D5+(cip_q1+D25)/life_ai*D5/2 -> 14.049224 | E27: =C27+D27 -> 16.466974 | F27: =F26+(cip_q1+D25)/life_ai+F25/life_ai/2 -> 34.53746 | G27: =G26+(cip_q1+D25+F25)/life_ai+G25/life_ai/2 -> 42.196508 | H27: =H26+(cip_q1+D25+F25+G25)/life_ai+H25/life_ai/2 -> 43.115335 | I27: =I26+(cip_q1+D25+F25+G25+H25)/life_ai+I25/life_ai/2 -> 44.57391 | J27: =J26+(cip_q1+D25+F25+G25+H25+I25)/life_ai+J25/life_ai/2 -> 45.670215 | K27: 在建工程 48.5 與 FY27 Q2–Q4 起的資本支出 ÷ 6 年，當年半年
A28: OCI AI EBITDA（租金後） | B28: US$B | C28: =C19-C21-C22 -> 3.8495976 | D28: =D19-D21-D22 -> 18.79443 | E28: =E19-E21-E22 -> 22.644028 | F28: =F19-F21-F22 -> 44.538983 | G28: =G19-G21-G22 -> 54.876979 | H28: =H19-H21-H22 -> 55.010306 | I28: =I19-I21-I22 -> 56.435565 | J28: =J19-J21-J22 -> 60.221172
A29: OCI AI 分部利潤貢獻（營業利益口徑） | B29: US$B | C29: =C28-C27 -> 1.4318476 | D29: =D28-D27 -> 4.7452062 | E29: =E28-E27 -> 6.1770538 | F29: =F28-F27 -> 10.001523 | G29: =G28-G27 -> 12.680471 | H29: =H28-H27 -> 11.89497 | I29: =I28-I27 -> 11.861655 | J29: =J28-J27 -> 14.550957 | K29: 進 PL 頁 Cloud and software 分部利潤
A30: OCI AI 營業利益率 | B30: % | C30: =IF(C19=0,0,C29/C19) -> 0.29385868 | D30: =IF(D19=0,0,D29/D19) -> 0.17887326 | E30: =IF(E19=0,0,E29/E19) -> 0.1967159 | F30: =IF(F19=0,0,F29/F19) -> 0.15127323 | G30: =IF(G19=0,0,G29/G19) -> 0.14671122 | H30: =IF(H19=0,0,H29/H19) -> 0.13285462 | I30: =IF(I19=0,0,I29/I19) -> 0.12942379 | J30: =IF(J19=0,0,J29/J19) -> 0.1504167
A31: OCI 其他（非 AI）營收（子列） | B31: US$B | C31: =q1_oci-C19 -> 2.515428 | D31: =C31*((1+gna0)^0.25+(1+gna0)^0.5+(1+gna0)^0.75) -> 8.2722657 | E31: =C31+D31 -> 10.787694 | F31: =E31*(1+F32) -> 12.686328 | G31: =F31*(1+G32) -> 14.61465 | H31: =G31*(1+H32) -> 16.485325 | I31: =H31*(1+I32) -> 18.199799 | J31: =I31*(1+J32) -> 19.655782 | K31: Q1＝實際 OCI − 命題 AI 估計（殘差）；之後依成長路徑
A32: OCI 其他年增 | B32: % | F32: =gna0+(gnaLT-gna0)*1/5 -> 0.176 | G32: =gna0+(gnaLT-gna0)*2/5 -> 0.152 | H32: =gna0+(gnaLT-gna0)*3/5 -> 0.128 | I32: =gna0+(gnaLT-gna0)*4/5 -> 0.104 | J32: =gna0+(gnaLT-gna0)*5/5 -> 0.08
A33: Cloud Infrastructure（OCI）營收 | B33: US$B | C33: =C19+C31 -> 7.388 | D33: =D19+D31 -> 34.80058 | E33: =E19+E31 -> 42.18858 | F33: =F19+F31 -> 78.801944 | G33: =G19+G31 -> 101.04615 | H33: =H19+H31 -> 106.01906 | I33: =I19+I31 -> 109.84953 | J33: =J19+J31 -> 116.39343
A34: OCI（含非 AI）營業利益率（非 AI 以 m_sw 計） | B34: % | C34: =(C29+(m_sw+m_adj)*C31)/C33 -> 0.41348819 | D34: =(D29+(m_sw+m_adj)*D31)/D33 -> 0.28972601 | E34: =(E29+(m_sw+m_adj)*E31)/E33 -> 0.31139906 | F34: =(F29+(m_sw+m_adj)*F31)/F33 -> 0.23079366 | G34: =(G29+(m_sw+m_adj)*G31)/G33 -> 0.21881217 | H34: =(H29+(m_sw+m_adj)*H31)/H33 -> 0.21252427 | I34: =(I29+(m_sw+m_adj)*I31)/I33 -> 0.21488049 | J34: =(J29+(m_sw+m_adj)*J31)/J33 -> 0.23397585
A35: OCI AI 稅後營業利益 | B35: US$B | C35: =C29*(1-etr) -> 1.2156386 | D35: =D29*(1-etr) -> 4.0286801 | E35: =E29*(1-etr) -> 5.2443187 | F35: =F29*(1-etr) -> 8.4912929 | G35: =G29*(1-etr) -> 10.76572 | H35: =H29*(1-etr) -> 10.09883 | I35: =I29*(1-etr) -> 10.070545 | J35: =J29*(1-etr) -> 12.353763
A36: AI 累計投入資本（毛額，期末） | B36: US$B | C36: =(dep_q1-nonai_dep_q)*4*life_ai -> 58.026 | D36: =C36+cip_q1 -> 106.572 | E36: =D36+D25 -> 166.76158 | F36: =E36+F25 -> 247.68794 | G36: =F36+G25 -> 258.67015 | H36: =G36+H25 -> 272.70556 | I36: =H36+I25 -> 290.16473 | J36: =I36+J25 -> 353.03894 | K36: Q1 在役基數（年折舊 × 6）＋在建工程＋其後資本支出；機房以租賃取得不計
A37: AI 增量 ROIC（稅後營業利益 ÷ 期初投入資本毛額） | B37: % | F37: =F35/E36 -> 0.05091876 | G37: =G35/F36 -> 0.043464854 | H37: =H35/G36 -> 0.039041343 | I37: =I35/H36 -> 0.036928272 | J37: =J35/I36 -> 0.042574997 | K37: 對照 Val 頁 WACC
A39: 情境 B（基準：依 FY27Q1 交付速度、延誤 3 個月）
A40: 期間長度 | B40: 年 | C40: 0.25 | D40: 0.75 | E40: 1 | F40: 1 | G40: 1 | H40: 1 | I40: 1 | J40: 1
A41: 已連網 AI MW-IT（期末） | B41: MW | C41: =mw_q1 -> 2543 | D41: =MIN(cap_B,mw_q1+pace_B*D40) -> 4667.75 | E41: =D41 -> 4667.75 | F41: =MIN(cap_B,E41+pace_B*F40) -> 7500.75 | G41: =MIN(cap_B,F41+pace_B*G40) -> 8778 | H41: =G41+MAX(0,MIN(cap_B,G41+pace_B)-G41)+(tp_g*G41-MAX(0,MIN(cap_B,G41+pace_B)-G41))*1/3 -> 8865.78 | I41: =H41+MAX(0,MIN(cap_B,H41+pace_B)-H41)+(tp_g*H41-MAX(0,MIN(cap_B,H41+pace_B)-H41))*2/3 -> 9043.0956 | J41: =I41+MAX(0,MIN(cap_B,I41+pace_B)-I41)+(tp_g*I41-MAX(0,MIN(cap_B,I41+pace_B)-I41))*3/3 -> 9314.3885 | K41: FY2028–29：MIN(上限 cap_B, 前期＋速度)；FY2030–32：新增量線性收斂到「前期 × 永續成長 g」（修正一 F5；超過已簽上限的部分視為新簽約）
...

Sheet Seg
A1: Seg — 營收分部層：營收線（公司新聞稿）→ 官方報告分部（10-K 附註 13：Cloud and software、Hardware、Services）→ 合併營收。FY2026 為實績（Q 頁）；FY2027＝Q1 實績＋Q2–Q4 模型；延伸到 FY2032
A2: 驅動：OCI AI 算力＝Thesis 頁命題模組；OCI 其他＝成長路徑；SaaS、授權、支援、硬體、服務＝FY2027 為 Q1 實績＋去年 Q2–Q4 ×（1＋近四季年增率），其後線性收斂到 In 頁長期年增（三情境相同）。核對列：子列合計＝母列、分部合計＝合併營收
A3: 項目 | B3: 單位 | C3: FY2026A | D3: FY2027 | E3: FY2028 | F3: FY2029 | G3: FY2030 | H3: FY2031 | I3: FY2032 | J3: 說明
A4: 共同（三情境相同）：OCI 以外的營收線
A5: Cloud Applications（SaaS） | B5: US$B | C5: =a26_saas -> 15.888 | D5: =q1_saas+(a26_saas-q0_saas)*(1+g0_saas) -> 17.606869 | E5: =D5*(1+E6) -> 19.453741 | F5: =E5*(1+F6) -> 21.373265 | G5: =F5*(1+G6) -> 23.34917 | H5: =G5*(1+H6) -> 25.362423 | I5: =H5*(1+I6) -> 27.391417 | J5: FY2027＝Q1 實績＋（FY2026 − FY26Q1）×（1＋近四季年增率 Q 頁）；FY2028 起年增率線性收斂到 In 頁 gLT_saas
A6: Cloud Applications（SaaS） 年增 | B6: % | D6: =D5/C5-1 -> 0.10818663 | E6: =g0_saas+(gLT_saas-g0_saas)*1/5 -> 0.10489496 | F6: =g0_saas+(gLT_saas-g0_saas)*2/5 -> 0.09867122 | G6: =g0_saas+(gLT_saas-g0_saas)*3/5 -> 0.09244748 | H6: =g0_saas+(gLT_saas-g0_saas)*4/5 -> 0.08622374 | I6: =g0_saas+(gLT_saas-g0_saas)*5/5 -> 0.08
A7: Software license | B7: US$B | C7: =a26_lic -> 4.737 | D7: =q1_lic+(a26_lic-q0_lic)*(1+g0_lic) -> 4.2582715 | E7: =D7*(1+E8) -> 3.9257738 | F7: =E7*(1+F8) -> 3.6762434 | G7: =F7*(1+G8) -> 3.4959553 | H7: =G7*(1+H8) -> 3.3752725 | I7: =H7*(1+I8) -> 3.307767 | J7: FY2027＝Q1 實績＋（FY2026 − FY26Q1）×（1＋近四季年增率 Q 頁）；FY2028 起年增率線性收斂到 In 頁 gLT_lic
A8: Software license 年增 | B8: % | D8: =D7/C7-1 -> -0.10106153 | E8: =g0_lic+(gLT_lic-g0_lic)*1/5 -> -0.078082794 | F8: =g0_lic+(gLT_lic-g0_lic)*2/5 -> -0.063562095 | G8: =g0_lic+(gLT_lic-g0_lic)*3/5 -> -0.049041397 | H8: =g0_lic+(gLT_lic-g0_lic)*4/5 -> -0.034520698 | I8: =g0_lic+(gLT_lic-g0_lic)*5/5 -> -0.02
A9: Software support | B9: US$B | C9: =a26_sup -> 19.804 | D9: =q1_sup+(a26_sup-q0_sup)*(1+g0_sup) -> 19.867603 | E9: =D9*(1+E10) -> 19.960169 | F9: =E9*(1+F10) -> 19.980017 | G9: =F9*(1+G10) -> 19.926662 | H9: =G9*(1+H10) -> 19.800423 | I9: =H9*(1+I10) -> 19.602419 | J9: FY2027＝Q1 實績＋（FY2026 − FY26Q1）×（1＋近四季年增率 Q 頁）；FY2028 起年增率線性收斂到 In 頁 gLT_sup
A10: Software support 年增 | B10: % | D10: =D9/C9-1 -> 0.003211606 | E10: =g0_sup+(gLT_sup-g0_sup)*1/5 -> 0.0046591768 | F10: =g0_sup+(gLT_sup-g0_sup)*2/5 -> 0.0009943826 | G10: =g0_sup+(gLT_sup-g0_sup)*3/5 -> -0.0026704116 | H10: =g0_sup+(gLT_sup-g0_sup)*4/5 -> -0.0063352058 | I10: =g0_sup+(gLT_sup-g0_sup)*5/5 -> -0.01
A11: Hardware | B11: US$B | C11: =a26_hw -> 3.084 | D11: =q1_hw+(a26_hw-q0_hw)*(1+g0_hw) -> 3.3818726 | E11: =D11*(1+E12) -> 3.5991559 | F11: =E11*(1+F12) -> 3.7725886 | G11: =F11*(1+G12) -> 3.8937819 | H11: =G11*(1+H12) -> 3.9563252 | I11: =H11*(1+I12) -> 3.9563252 | J11: FY2027＝Q1 實績＋（FY2026 − FY26Q1）×（1＋近四季年增率 Q 頁）；FY2028 起年增率線性收斂到 In 頁 gLT_hw
A12: Hardware 年增 | B12: % | D12: =D11/C11-1 -> 0.096586441 | E12: =g0_hw+(gLT_hw-g0_hw)*1/5 -> 0.064249407 | F12: =g0_hw+(gLT_hw-g0_hw)*2/5 -> 0.048187055 | G12: =g0_hw+(gLT_hw-g0_hw)*3/5 -> 0.032124703 | H12: =g0_hw+(gLT_hw-g0_hw)*4/5 -> 0.016062352 | I12: =g0_hw+(gLT_hw-g0_hw)*5/5 -> 0
A13: Services | B13: US$B | C13: =a26_svc -> 5.743 | D13: =q1_svc+(a26_svc-q0_svc)*(1+g0_svc) -> 6.2128627 | E13: =D13*(1+E14) -> 6.708102 | F13: =E13*(1+F14) -> 7.1594495 | G13: =F13*(1+G14) -> 7.552188 | H13: =G13*(1+H14) -> 7.8726121 | I13: =H13*(1+I14) -> 8.1087904 | J13: FY2027＝Q1 實績＋（FY2026 − FY26Q1）×（1＋近四季年增率 Q 頁）；FY2028 起年增率線性收斂到 In 頁 gLT_svc
A14: Services 年增 | B14: % | D14: =D13/C13-1 -> 0.081814858 | E14: =g0_svc+(gLT_svc-g0_svc)*1/5 -> 0.079711922 | F14: =g0_svc+(gLT_svc-g0_svc)*2/5 -> 0.067283941 | G14: =g0_svc+(gLT_svc-g0_svc)*3/5 -> 0.054855961 | H14: =g0_svc+(gLT_svc-g0_svc)*4/5 -> 0.04242798 | I14: =g0_svc+(gLT_svc-g0_svc)*5/5 -> 0.03
A16: 情境 A（樂觀：依公司時程交付、不延誤）
A17: Cloud Infrastructure（OCI） | B17: US$B | C17: =a26_oci -> 18.101 | D17: =D18+D19 -> 42.18858 | E17: =E18+E19 -> 78.801944 | F17: =F18+F19 -> 101.04615 | G17: =G18+G19 -> 106.01906 | H17: =H18+H19 -> 109.84953 | I17: =I18+I19 -> 116.39343 | J17: FY2026 實績（不拆 AI／非 AI：公司未揭露）
A18: OCI AI 算力（命題子列） | B18: US$B | D18: =Thesis!E19 -> 31.400886 | E18: =Thesis!F19 -> 66.115616 | F18: =Thesis!G19 -> 86.431505 | G18: =Thesis!H19 -> 89.533734 | H18: =Thesis!I19 -> 91.649727 | I18: =Thesis!J19 -> 96.737643 | J18: Thesis 頁命題模組
A19: OCI 其他（非 AI）（子列） | B19: US$B | D19: =Thesis!E31 -> 10.787694 | E19: =Thesis!F31 -> 12.686328 | F19: =Thesis!G31 -> 14.61465 | G19: =Thesis!H31 -> 16.485325 | H19: =Thesis!I31 -> 18.199799 | I19: =Thesis!J31 -> 19.655782
A20: Cloud Applications（SaaS） | B20: US$B | C20: =C5 -> 15.888 | D20: =D5 -> 17.606869 | E20: =E5 -> 19.453741 | F20: =F5 -> 21.373265 | G20: =G5 -> 23.34917 | H20: =H5 -> 25.362423 | I20: =I5 -> 27.391417
A21: Software license | B21: US$B | C21: =C7 -> 4.737 | D21: =D7 -> 4.2582715 | E21: =E7 -> 3.9257738 | F21: =F7 -> 3.6762434 | G21: =G7 -> 3.4959553 | H21: =H7 -> 3.3752725 | I21: =I7 -> 3.307767
A22: Software support | B22: US$B | C22: =C9 -> 19.804 | D22: =D9 -> 19.867603 | E22: =E9 -> 19.960169 | F22: =F9 -> 19.980017 | G22: =G9 -> 19.926662 | H22: =H9 -> 19.800423 | I22: =I9 -> 19.602419
A23: Hardware | B23: US$B | C23: =C11 -> 3.084 | D23: =D11 -> 3.3818726 | E23: =E11 -> 3.5991559 | F23: =F11 -> 3.7725886 | G23: =G11 -> 3.8937819 | H23: =H11 -> 3.9563252 | I23: =I11 -> 3.9563252
A24: Services | B24: US$B | C24: =C13 -> 5.743 | D24: =D13 -> 6.2128627 | E24: =E13 -> 6.708102 | F24: =F13 -> 7.1594495 | G24: =G13 -> 7.552188 | H24: =H13 -> 7.8726121 | I24: =I13 -> 8.1087904
A25: 分部：Cloud and software | B25: US$B | C25: =C17+C20+C21+C22 -> 58.53 | D25: =D17+D20+D21+D22 -> 83.921324 | E25: =E17+E20+E21+E22 -> 122.14163 | F25: =F17+F20+F21+F22 -> 146.07568 | G25: =G17+G20+G21+G22 -> 152.79085 | H25: =H17+H20+H21+H22 -> 158.38764 | I25: =I17+I20+I21+I22 -> 166.69503 | J25: 10-K 官方分部（雲端與軟體）
A26: 分部：Hardware | B26: US$B | C26: =C23 -> 3.084 | D26: =D23 -> 3.3818726 | E26: =E23 -> 3.5991559 | F26: =F23 -> 3.7725886 | G26: =G23 -> 3.8937819 | H26: =H23 -> 3.9563252 | I26: =I23 -> 3.9563252
A27: 分部：Services | B27: US$B | C27: =C24 -> 5.743 | D27: =D24 -> 6.2128627 | E27: =E24 -> 6.708102 | F27: =F24 -> 7.1594495 | G27: =G24 -> 7.552188 | H27: =H24 -> 7.8726121 | I27: =I24 -> 8.1087904
A28: 合併營收 | B28: US$B | C28: =C25+C26+C27 -> 67.357 | D28: =D25+D26+D27 -> 93.516059 | E28: =E25+E26+E27 -> 132.44889 | F28: =F25+F26+F27 -> 157.00772 | G28: =G25+G26+G27 -> 164.23682 | H28: =H25+H26+H27 -> 170.21658 | I28: =I25+I26+I27 -> 178.76014
A29: 合併營收年增 | B29: % | D29: =D28/C28-1 -> 0.38836437 | E29: =E28/D28-1 -> 0.41632237 | F29: =F28/E28-1 -> 0.18542121 | G29: =G28/F28-1 -> 0.046042941 | H29: =H28/G28-1 -> 0.036409407 | I29: =I28/H28-1 -> 0.050192303
A30: 檢查：OCI 子列合計 − OCI（應為 0） | B30: US$B | D30: =D18+D19-D17 -> 0 | E30: =E18+E19-E17 -> 0 | F30: =F18+F19-F17 -> 0 | G30: =G18+G19-G17 -> 0 | H30: =H18+H19-H17 -> 0 | I30: =I18+I19-I17 -> 0
A31: 檢查：營收線合計 − 合併營收（應為 0） | B31: US$B | C31: =C17+C20+C21+C22+C23+C24-C28 -> 0 | D31: =D17+D20+D21+D22+D23+D24-D28 -> 0 | E31: =E17+E20+E21+E22+E23+E24-E28 -> 0 | F31: =F17+F20+F21+F22+F23+F24-F28 -> 0 | G31: =G17+G20+G21+G22+G23+G24-G28 -> 0 | H31: =H17+H20+H21+H22+H23+H24-H28 -> 0 | I31: =I17+I20+I21+I22+I23+I24-I28 -> 0
A32: 檢查：FY2026 合併營收 − 公司揭露（應為 0） | B32: US$B | C32: =C28-a26_rev -> 0
A34: 情境 B（基準：依 FY27Q1 交付速度、延誤 3 個月）
A35: Cloud Infrastructure（OCI） | B35: US$B | C35: =a26_oci -> 18.101 | D35: =D36+D37 -> 35.826476 | E35: =E36+E37 -> 65.343121 | F35: =F36+F37 -> 93.600308 | G35: =G36+G37 -> 106.57734 | H35: =H36+H37 -> 110.17489 | I35: =I36+I37 -> 116.45578 | J35: FY2026 實績（不拆 AI／非 AI：公司未揭露）
A36: OCI AI 算力（命題子列） | B36: US$B | D36: =Thesis!E54 -> 25.038782 | E36: =Thesis!F54 -> 52.656793 | F36: =Thesis!G54 -> 78.985658 | G36: =Thesis!H54 -> 90.092012 | H36: =Thesis!I54 -> 91.975086 | I36: =Thesis!J54 -> 96.799994 | J36: Thesis 頁命題模組
A37: OCI 其他（非 AI）（子列） | B37: US$B | D37: =Thesis!E66 -> 10.787694 | E37: =Thesis!F66 -> 12.686328 | F37: =Thesis!G66 -> 14.61465 | G37: =Thesis!H66 -> 16.485325 | H37: =Thesis!I66 -> 18.199799 | I37: =Thesis!J66 -> 19.655782
A38: Cloud Applications（SaaS） | B38: US$B | C38: =C5 -> 15.888 | D38: =D5 -> 17.606869 | E38: =E5 -> 19.453741 | F38: =F5 -> 21.373265 | G38: =G5 -> 23.34917 | H38: =H5 -> 25.362423 | I38: =I5 -> 27.391417
A39: Software license | B39: US$B | C39: =C7 -> 4.737 | D39: =D7 -> 4.2582715 | E39: =E7 -> 3.9257738 | F39: =F7 -> 3.6762434 | G39: =G7 -> 3.4959553 | H39: =H7 -> 3.3752725 | I39: =I7 -> 3.307767
A40: Software support | B40: US$B | C40: =C9 -> 19.804 | D40: =D9 -> 19.867603 | E40: =E9 -> 19.960169 | F40: =F9 -> 19.980017 | G40: =G9 -> 19.926662 | H40: =H9 -> 19.800423 | I40: =I9 -> 19.602419
A41: Hardware | B41: US$B | C41: =C11 -> 3.084 | D41: =D11 -> 3.3818726 | E41: =E11 -> 3.5991559 | F41: =F11 -> 3.7725886 | G41: =G11 -> 3.8937819 | H41: =H11 -> 3.9563252 | I41: =I11 -> 3.9563252
A42: Services | B42: US$B | C42: =C13 -> 5.743 | D42: =D13 -> 6.2128627 | E42: =E13 -> 6.708102 | F42: =F13 -> 7.1594495 | G42: =G13 -> 7.552188 | H42: =H13 -> 7.8726121 | I42: =I13 -> 8.1087904
...

Sheet PL
A1: PL — 三情境損益（十億美元；EPS 美元）。分部營收（Seg 頁）→ 分部利潤（Cloud and software＝OCI AI 貢獻〔Thesis 頁，含 AI 折舊與租金〕＋其餘營收 × m_sw；硬體、服務＝營收 × FY2026 利潤率）→ 減未分攤費用＝GAAP 營業利益 → 利息、稅 → 淨利 → EPS（GAAP）
A2: FY2026 為實績；FY2027＝Q1 實績＋Q2–Q4 模型。持股評價損益：預測期設 0。EPS 為 GAAP 稀釋口徑（共識 GAAP EPS 對照見 Recon）
A3: 項目 | B3: 單位 | C3: FY2026A | D3: FY2027 | E3: FY2028 | F3: FY2029 | G3: FY2030 | H3: FY2031 | I3: FY2032 | J3: 說明
A4: 分部核對（三情境合計絕對差；每年度應為 0）
A5: 檢查：分部合計 − 合併營收 | C5: =ABS(C18+C19+C20-C21)+ABS(C58+C59+C60-C61)+ABS(C98+C99+C100-C101) -> 0 | D5: =ABS(D18+D19+D20-D21)+ABS(D58+D59+D60-D61)+ABS(D98+D99+D100-D101) -> 0 | E5: =ABS(E18+E19+E20-E21)+ABS(E58+E59+E60-E61)+ABS(E98+E99+E100-E101) -> 0 | F5: =ABS(F18+F19+F20-F21)+ABS(F58+F59+F60-F61)+ABS(F98+F99+F100-F101) -> 0 | G5: =ABS(G18+G19+G20-G21)+ABS(G58+G59+G60-G61)+ABS(G98+G99+G100-G101) -> 0 | H5: =ABS(H18+H19+H20-H21)+ABS(H58+H59+H60-H61)+ABS(H98+H99+H100-H101) -> 0 | I5: =ABS(I18+I19+I20-I21)+ABS(I58+I59+I60-I61)+ABS(I98+I99+I100-I101) -> 0
A6: 檢查：子列合計 − 母列（OCI 兩子列；Cloud and software 四營收線） | C6: =ABS(C10+C13+C14+C15-C18)+ABS(C50+C53+C54+C55-C58)+ABS(C90+C93+C94+C95-C98) -> 0 | D6: =ABS(D10+D13+D14+D15-D18)+ABS(D50+D53+D54+D55-D58)+ABS(D90+D93+D94+D95-D98)+ABS(D11+D12-D10)+ABS(D51+D52-D50)+ABS(D91+D92-D90) -> 0 | E6: =ABS(E10+E13+E14+E15-E18)+ABS(E50+E53+E54+E55-E58)+ABS(E90+E93+E94+E95-E98)+ABS(E11+E12-E10)+ABS(E51+E52-E50)+ABS(E91+E92-E90) -> 0 | F6: =ABS(F10+F13+F14+F15-F18)+ABS(F50+F53+F54+F55-F58)+ABS(F90+F93+F94+F95-F98)+ABS(F11+F12-F10)+ABS(F51+F52-F50)+ABS(F91+F92-F90) -> 0 | G6: =ABS(G10+G13+G14+G15-G18)+ABS(G50+G53+G54+G55-G58)+ABS(G90+G93+G94+G95-G98)+ABS(G11+G12-G10)+ABS(G51+G52-G50)+ABS(G91+G92-G90) -> 0 | H6: =ABS(H10+H13+H14+H15-H18)+ABS(H50+H53+H54+H55-H58)+ABS(H90+H93+H94+H95-H98)+ABS(H11+H12-H10)+ABS(H51+H52-H50)+ABS(H91+H92-H90) -> 0 | I6: =ABS(I10+I13+I14+I15-I18)+ABS(I50+I53+I54+I55-I58)+ABS(I90+I93+I94+I95-I98)+ABS(I11+I12-I10)+ABS(I51+I52-I50)+ABS(I91+I92-I90) -> 0
A7: 檢查：營收線合計 − 合併營收 | C7: =ABS(C10+C13+C14+C15+C16+C17-C21)+ABS(C50+C53+C54+C55+C56+C57-C61)+ABS(C90+C93+C94+C95+C96+C97-C101) -> 0 | D7: =ABS(D10+D13+D14+D15+D16+D17-D21)+ABS(D50+D53+D54+D55+D56+D57-D61)+ABS(D90+D93+D94+D95+D96+D97-D101) -> 0 | E7: =ABS(E10+E13+E14+E15+E16+E17-E21)+ABS(E50+E53+E54+E55+E56+E57-E61)+ABS(E90+E93+E94+E95+E96+E97-E101) -> 0 | F7: =ABS(F10+F13+F14+F15+F16+F17-F21)+ABS(F50+F53+F54+F55+F56+F57-F61)+ABS(F90+F93+F94+F95+F96+F97-F101) -> 0 | G7: =ABS(G10+G13+G14+G15+G16+G17-G21)+ABS(G50+G53+G54+G55+G56+G57-G61)+ABS(G90+G93+G94+G95+G96+G97-G101) -> 0 | H7: =ABS(H10+H13+H14+H15+H16+H17-H21)+ABS(H50+H53+H54+H55+H56+H57-H61)+ABS(H90+H93+H94+H95+H96+H97-H101) -> 0 | I7: =ABS(I10+I13+I14+I15+I16+I17-I21)+ABS(I50+I53+I54+I55+I56+I57-I61)+ABS(I90+I93+I94+I95+I96+I97-I101) -> 0
A9: 情境 A（樂觀：依公司時程交付、不延誤）
A10: Cloud Infrastructure（OCI） | B10: US$B | C10: =Seg!C17 -> 18.101 | D10: =Seg!D17 -> 42.18858 | E10: =Seg!E17 -> 78.801944 | F10: =Seg!F17 -> 101.04615 | G10: =Seg!G17 -> 106.01906 | H10: =Seg!H17 -> 109.84953 | I10: =Seg!I17 -> 116.39343
A11: OCI AI 算力（命題子列） | B11: US$B | D11: =Seg!D18 -> 31.400886 | E11: =Seg!E18 -> 66.115616 | F11: =Seg!F18 -> 86.431505 | G11: =Seg!G18 -> 89.533734 | H11: =Seg!H18 -> 91.649727 | I11: =Seg!I18 -> 96.737643
A12: OCI 其他（非 AI）（子列） | B12: US$B | D12: =Seg!D19 -> 10.787694 | E12: =Seg!E19 -> 12.686328 | F12: =Seg!F19 -> 14.61465 | G12: =Seg!G19 -> 16.485325 | H12: =Seg!H19 -> 18.199799 | I12: =Seg!I19 -> 19.655782
A13: Cloud Applications（SaaS） | B13: US$B | C13: =Seg!C20 -> 15.888 | D13: =Seg!D20 -> 17.606869 | E13: =Seg!E20 -> 19.453741 | F13: =Seg!F20 -> 21.373265 | G13: =Seg!G20 -> 23.34917 | H13: =Seg!H20 -> 25.362423 | I13: =Seg!I20 -> 27.391417
A14: Software license | B14: US$B | C14: =Seg!C21 -> 4.737 | D14: =Seg!D21 -> 4.2582715 | E14: =Seg!E21 -> 3.9257738 | F14: =Seg!F21 -> 3.6762434 | G14: =Seg!G21 -> 3.4959553 | H14: =Seg!H21 -> 3.3752725 | I14: =Seg!I21 -> 3.307767
A15: Software support | B15: US$B | C15: =Seg!C22 -> 19.804 | D15: =Seg!D22 -> 19.867603 | E15: =Seg!E22 -> 19.960169 | F15: =Seg!F22 -> 19.980017 | G15: =Seg!G22 -> 19.926662 | H15: =Seg!H22 -> 19.800423 | I15: =Seg!I22 -> 19.602419
A16: Hardware | B16: US$B | C16: =Seg!C23 -> 3.084 | D16: =Seg!D23 -> 3.3818726 | E16: =Seg!E23 -> 3.5991559 | F16: =Seg!F23 -> 3.7725886 | G16: =Seg!G23 -> 3.8937819 | H16: =Seg!H23 -> 3.9563252 | I16: =Seg!I23 -> 3.9563252
A17: Services | B17: US$B | C17: =Seg!C24 -> 5.743 | D17: =Seg!D24 -> 6.2128627 | E17: =Seg!E24 -> 6.708102 | F17: =Seg!F24 -> 7.1594495 | G17: =Seg!G24 -> 7.552188 | H17: =Seg!H24 -> 7.8726121 | I17: =Seg!I24 -> 8.1087904
A18: 分部：Cloud and software | B18: US$B | C18: =C10+C13+C14+C15 -> 58.53 | D18: =D10+D13+D14+D15 -> 83.921324 | E18: =E10+E13+E14+E15 -> 122.14163 | F18: =F10+F13+F14+F15 -> 146.07568 | G18: =G10+G13+G14+G15 -> 152.79085 | H18: =H10+H13+H14+H15 -> 158.38764 | I18: =I10+I13+I14+I15 -> 166.69503
A19: 分部：Hardware | B19: US$B | C19: =C16 -> 3.084 | D19: =D16 -> 3.3818726 | E19: =E16 -> 3.5991559 | F19: =F16 -> 3.7725886 | G19: =G16 -> 3.8937819 | H19: =H16 -> 3.9563252 | I19: =I16 -> 3.9563252
A20: 分部：Services | B20: US$B | C20: =C17 -> 5.743 | D20: =D17 -> 6.2128627 | E20: =E17 -> 6.708102 | F20: =F17 -> 7.1594495 | G20: =G17 -> 7.552188 | H20: =H17 -> 7.8726121 | I20: =I17 -> 8.1087904
A21: 合併營收 | B21: US$B | C21: =Seg!C28 -> 67.357 | D21: =Seg!D28 -> 93.516059 | E21: =Seg!E28 -> 132.44889 | F21: =Seg!F28 -> 157.00772 | G21: =Seg!G28 -> 164.23682 | H21: =Seg!H28 -> 170.21658 | I21: =Seg!I28 -> 178.76014
A22: 合併營收年增 | B22: % | D22: =D21/C21-1 -> 0.38836437 | E22: =E21/D21-1 -> 0.41632237 | F22: =F21/E21-1 -> 0.18542121 | G22: =G21/F21-1 -> 0.046042941 | H22: =H21/G21-1 -> 0.036409407 | I22: =I21/H21-1 -> 0.050192303
A23: 分部利潤：Cloud and software | B23: US$B | C23: =Q!L16 -> 34.468 | D23: =Q!I16+Thesis!D29+(m_sw+m_adj)*((D18-Q!I11)-Thesis!D19) -> 40.064264 | E23: =Thesis!F29+(m_sw+m_adj)*(E18-Thesis!F19) -> 46.150598 | F23: =Thesis!G29+(m_sw+m_adj)*(F18-Thesis!G19) -> 51.164056 | G23: =Thesis!H29+(m_sw+m_adj)*(G18-Thesis!H19) -> 52.709693 | H23: =Thesis!I29+(m_sw+m_adj)*(H18-Thesis!I19) -> 54.92226 | I23: =Thesis!J29+(m_sw+m_adj)*(I18-Thesis!J19) -> 59.688826 | J23: OCI AI 貢獻（Thesis，含 AI 折舊與租金）＋（分部營收 − OCI AI 營收）× m_sw
A24: 其中：OCI AI 貢獻（命題） | B24: US$B | D24: =Thesis!E29 -> 6.1770538 | E24: =Thesis!F29 -> 10.001523 | F24: =Thesis!G29 -> 12.680471 | G24: =Thesis!H29 -> 11.89497 | H24: =Thesis!I29 -> 11.861655 | I24: =Thesis!J29 -> 14.550957
A25: 分部利潤：Hardware | B25: US$B | C25: =Q!L17 -> 2.017 | D25: =Q!I17+m_hw*(D19-Q!I12) -> 2.1576028 | E25: =m_hw*E19 -> 2.3539226 | F25: =m_hw*F19 -> 2.4673512 | G25: =m_hw*G19 -> 2.5466142 | H25: =m_hw*H19 -> 2.5875188 | I25: =m_hw*I19 -> 2.5875188
A26: 分部利潤：Services | B26: US$B | C26: =Q!L18 -> 1.533 | D26: =Q!I18+m_svc*(D20-Q!I13) -> 1.725978 | E26: =m_svc*E20 -> 1.7906182 | F26: =m_svc*F20 -> 1.911098 | G26: =m_svc*G20 -> 2.0159332 | H26: =m_svc*H20 -> 2.1014651 | I26: =m_svc*I20 -> 2.1645091
A27: 分部利潤合計 | B27: US$B | C27: =C23+C25+C26 -> 38.018 | D27: =D23+D25+D26 -> 43.947844 | E27: =E23+E25+E26 -> 50.295139 | F27: =F23+F25+F26 -> 55.542506 | G27: =G23+G25+G26 -> 57.27224 | H27: =H23+H25+H26 -> 59.611244 | I27: =I23+I25+I26 -> 64.440853
A28: Cloud and software 分部利潤率 | B28: % | C28: =C23/C18 -> 0.58889458 | D28: =D23/D18 -> 0.47740267 | E28: =E23/E18 -> 0.37784496 | F28: =F23/F18 -> 0.35025718 | G28: =G23/G18 -> 0.34497939 | H28: =H23/H18 -> 0.34675849 | I28: =I23/I18 -> 0.35807202
A29: 未分攤費用（研發、管理、攤銷、SBC 等） | B29: US$B | C29: =Q!L20 -> 17.412 | D29: =Q!I20*(1+3*un_rr) -> 16.586 | E29: =D29*(1+un_g) -> 17.24944 | F29: =E29*(1+un_g) -> 17.939418 | G29: =F29*(1+un_g) -> 18.656994 | H29: =G29*(1+un_g) -> 19.403274 | I29: =H29*(1+un_g) -> 20.179405 | J29: FY2027＝Q1 實績 ×（1＋3 × un_rr）；其後年增 un_g
A30: 營業利益（GAAP） | B30: US$B | C30: =C27-C29 -> 20.606 | D30: =D27-D29 -> 27.361844 | E30: =E27-E29 -> 33.045699 | F30: =F27-F29 -> 37.603088 | G30: =G27-G29 -> 38.615246 | H30: =H27-H29 -> 40.20797 | I30: =I27-I29 -> 44.261448
A31: 營業利益率 | B31: % | C31: =C30/C21 -> 0.30592218 | D31: =D30/D21 -> 0.29258979 | E31: =E30/E21 -> 0.24949775 | F31: =F30/F21 -> 0.23949834 | G31: =G30/G21 -> 0.2351193 | H31: =H30/H21 -> 0.23621653 | I31: =I30/I21 -> 0.24760244
A32: OCI AI 營業利益率（命題） | B32: % | D32: =Thesis!E30 -> 0.1967159 | E32: =Thesis!F30 -> 0.15127323 | F32: =Thesis!G30 -> 0.14671122 | G32: =Thesis!H30 -> 0.13285462 | H32: =Thesis!I30 -> 0.12942379 | I32: =Thesis!J30 -> 0.1504167
A33: 利息費用 | B33: US$B | C33: =Q!L26 -> 4.599 | D33: =CF!D46 -> 5.712 | E33: =CF!E46 -> 5.712 | F33: =CF!F46 -> 5.9945969 | G33: =CF!G46 -> 5.9945969 | H33: =CF!H46 -> 5.9945969 | I33: =CF!I46 -> 5.9945969 | J33: CF 頁：既有借款 × r_old＋期初新債 × r_new＋高息債 × 12%
A34: 利息收入 | B34: US$B | D34: =CF!D47 -> 1.2418708 | E34: =CF!E47 -> 0.54679545 | F34: =CF!F47 -> 0.33655036 | G34: =CF!G47 -> 1.9922606 | H34: =CF!H47 -> 3.6695961 | I34: =CF!I47 -> 5.3839236 | J34: FY2026 含在其他收益（未拆）
A35: 稅前利益 | B35: US$B | D35: =D30-D33+D34 -> 22.891715 | E35: =E30-E33+E34 -> 27.880494 | F35: =F30-F33+F34 -> 31.945042 | G35: =G30-G33+G34 -> 34.612909 | H35: =H30-H33+H34 -> 37.882969 | I35: =I30-I33+I34 -> 43.650775 | J35: 其他收益與持股評價損益：預測期設 0
A36: 所得稅 | B36: US$B | D36: =D35*etr -> 3.456649 | E36: =E35*etr -> 4.2099546 | F36: =F35*etr -> 4.8237013 | G36: =G35*etr -> 5.2265493 | H36: =H35*etr -> 5.7203284 | I36: =I35*etr -> 6.591267
A37: 淨利 | B37: US$B | C37: =Q!L27 -> 17.087 | D37: =D35-D36 -> 19.435066 | E37: =E35-E36 -> 23.67054 | F37: =F35-F36 -> 27.12134 | G37: =G35-G36 -> 29.38636 | H37: =H35-H36 -> 32.162641 | I37: =I35-I36 -> 37.059508
A38: 特別股股利 | B38: US$B | C38: =Q!L48 -> 0.103 | D38: =pref_q1+pref27 -> 0.325 | E38: =pref28 -> 0.325 | F38: =pref29 -> 0.244 | G38: =0 -> 0 | H38: =0 -> 0 | I38: =0 -> 0 | J38: FY27 Q1 實績 0.081＋Q2–Q4；2029-01-15 強制轉換
A39: 歸屬普通股淨利 | B39: US$B | C39: =C37-C38 -> 16.984 | D39: =D37-D38 -> 19.110066 | E39: =E37-E38 -> 23.34554 | F39: =F37-F38 -> 26.87734 | G39: =G37-G38 -> 29.38636 | H39: =H37-H38 -> 32.162641 | I39: =I37-I38 -> 37.059508
A40: 稀釋股數 | B40: 十億股 | C40: =Q!L49 -> 2.914 | D40: =CF!D45 -> 3.043302 | E40: =CF!E45 -> 3.057736 | F40: =CF!F45 -> 3.073355 | G40: =CF!G45 -> 3.088974 | H40: =CF!H45 -> 3.088974 | I40: =CF!I45 -> 3.088974
A41: EPS（GAAP 稀釋） | B41: US$ | C41: =Q!L50 -> 5.83 | D41: =D39/D40 -> 6.2793854 | E41: =E39/E40 -> 7.6349102 | F41: =F39/F40 -> 8.7452768 | G41: =G39/G40 -> 9.5133077 | H41: =H39/H40 -> 10.412079 | I41: =I39/I40 -> 11.997352
...

Sheet CF
A1: CF — 現金流與融資瀑布（收支模組）。營運現金＝淨利＋D&A＋SBC＋客戶預付流入 − 預付認列（非現金營收）；資本支出＝AI（Thesis）＋非 AI；自由現金流扣股利後的缺口依序由現金（保留最低 10）→ 投資級債（租賃調整後槓桿 ≤ 4.5×）→ 新股（每年 ≤ 市值 5%）→ 高息債 補足
A2: FY2027＝Q1 實績＋Q2–Q4 模型（瀑布只計 Q2–Q4，起點為 Q1 末現金）。利息以期初餘額計（不循環）。租賃負債＝在帳 43.8＋已起租的未起租租約現值（17 年、5.7%）
A3: 項目 | B3: 單位 | C3: 情境 A | D3: 情境 B | E3: 情境 C | F3: 說明
A4: 收支關卡：自由現金流扣股利（五年合計） | B4: US$B | C4: =SUM(D26:H26) -> 111.06343 | D4: =SUM(D61:H61) -> 72.763561 | E4: =SUM(D96:H96) -> 8.3534777 | F4: FY2027–FY2031 自由現金流 − 普通股與特別股股利 的合計（負值＝需外部融資；地圖收支關卡讀這一列）
A5: 融資需求（五年合計）：新增投資級債 | B5: US$B | C5: =SUM(D34:H34) -> 4.8723598 | D5: =SUM(D69:H69) -> 18.615845 | E5: =SUM(D104:H104) -> 0
A6: 融資需求（五年合計）：新股 | B6: US$B | C6: =SUM(D35:H35) -> 0 | D6: =SUM(D70:H70) -> 0 | E6: =SUM(D105:H105) -> 2.4135042
A7: 融資需求（五年合計）：高息債 | B7: US$B | C7: =SUM(D36:H36) -> 0 | D7: =SUM(D71:H71) -> 0 | E7: =SUM(D106:H106) -> 0
A8: 調整後槓桿峰值（FY2027–FY2031） | B8: x | C8: =MAX(D41:H41) -> 4.0195256 | D8: =MAX(D76:H76) -> 4.4336828 | E8: =MAX(D111:H111) -> 5.1998972
A9: 是否需要發新股或高息債（五年） | B9: — | C9: =IF(C6+C7>eq_tol,"需要","不需要") -> 不需要 | D9: =IF(D6+D7>eq_tol,"需要","不需要") -> 不需要 | E9: =IF(E6+E7>eq_tol,"需要","不需要") -> 需要
A10: 累計自由現金流（五年合計） | B10: US$B | C10: =SUM(D24:H24) -> 142.29187 | D10: =SUM(D59:H59) -> 103.99201 | E10: =SUM(D94:H94) -> 39.720298
A11: 檢查：收支關卡＝首年起五年自由現金流扣股利（逐欄加總，應為 0） | B11: US$B | C11: =C4-(D26+E26+F26+G26+H26) -> 0 | D11: =D4-(D61+E61+F61+G61+H61) -> 0 | E11: =E4-(D96+E96+F96+G96+H96) -> 0
A13: 項目 | B13: 單位 | C13: FY2026A | D13: FY2027 | E13: FY2028 | F13: FY2029 | G13: FY2030 | H13: FY2031 | I13: FY2032 | J13: 說明
A14: 情境 A（樂觀：依公司時程交付、不延誤）
A15: 淨利 | B15: US$B | C15: =PL!C37 -> 17.087 | D15: =PL!D37 -> 19.435066 | E15: =PL!E37 -> 23.67054 | F15: =PL!F37 -> 27.12134 | G15: =PL!G37 -> 29.38636 | H15: =PL!H37 -> 32.162641 | I15: =PL!I37 -> 37.059508
A16: 折舊與攤銷 | B16: US$B | C16: =PL!C43 -> 9.294 | D16: =PL!D43 -> 20.227974 | E16: =PL!E43 -> 38.754844 | F16: =PL!F43 -> 46.643226 | G16: =PL!G43 -> 47.785116 | H16: =PL!H43 -> 49.452532 | I16: =PL!I43 -> 50.735618
A17: SBC（非現金） | B17: US$B | C17: =PL!C44 -> 4.811 | D17: =PL!D44 -> 5.2998078 | E17: =PL!E44 -> 5.5118001 | F17: =PL!F44 -> 5.7322721 | G17: =PL!G44 -> 5.961563 | H17: =PL!H44 -> 6.2000255 | I17: =PL!I44 -> 6.4480265
A18: 客戶預付流入（AI 資本支出 × 覆蓋比） | B18: US$B | D18: =prepay_cov*Thesis!D25 -> 14.626068 | E18: =prepay_cov*Thesis!F25 -> 19.665107 | F18: =prepay_cov*Thesis!G25 -> 2.6686749 | G18: =prepay_cov*Thesis!H25 -> 3.4106066 | H18: =prepay_cov*Thesis!I25 -> 4.2425783 | I18: =prepay_cov*Thesis!J25 -> 15.278433 | J18: FY2027 只計 Q2–Q4（Q1 實績 11.363 已在營運現金流）
A19: 預付認列（非現金營收，自營運現金扣除） | B19: US$B | D19: =prepay_open/prepay_yrs*MAX(0,MIN(D27,prepay_yrs)-MIN(0,prepay_yrs)) -> 2.39325 | E19: =prepay_open/prepay_yrs*MAX(0,MIN(D27+E27,prepay_yrs)-MIN(D27,prepay_yrs))+D18/prepay_yrs*MAX(0,MIN(1,prepay_yrs)-MIN(0,prepay_yrs)) -> 6.1162136 | F19: =prepay_open/prepay_yrs*MAX(0,MIN(D27+E27+F27,prepay_yrs)-MIN(D27+E27,prepay_yrs))+D18/prepay_yrs*MAX(0,MIN(2,prepay_yrs)-MIN(1,prepay_yrs))+E18/prepay_yrs*MAX(0,MIN(1,prepay_yrs)-MIN(0,prepay_yrs)) -> 10.049235 | G19: =prepay_open/prepay_yrs*MAX(0,MIN(D27+E27+F27+G27,prepay_yrs)-MIN(D27+E27+F27,prepay_yrs))+D18/prepay_yrs*MAX(0,MIN(3,prepay_yrs)-MIN(2,prepay_yrs))+E18/prepay_yrs*MAX(0,MIN(2,prepay_yrs)-MIN(1,prepay_yrs))+F18/prepay_yrs*MAX(0,MIN(1,prepay_yrs)-MIN(0,prepay_yrs)) -> 10.58297 | H19: =prepay_open/prepay_yrs*MAX(0,MIN(D27+E27+F27+G27+H27,prepay_yrs)-MIN(D27+E27+F27+G27,prepay_yrs))+D18/prepay_yrs*MAX(0,MIN(4,prepay_yrs)-MIN(3,prepay_yrs))+E18/prepay_yrs*MAX(0,MIN(3,prepay_yrs)-MIN(2,prepay_yrs))+F18/prepay_yrs*MAX(0,MIN(2,prepay_yrs)-MIN(1,prepay_yrs))+G18/prepay_yrs*MAX(0,MIN(1,prepay_yrs)-MIN(0,prepay_yrs)) -> 11.265091 | I19: =prepay_open/prepay_yrs*MAX(0,MIN(D27+E27+F27+G27+H27+I27,prepay_yrs)-MIN(D27+E27+F27+G27+H27,prepay_yrs))+D18/prepay_yrs*MAX(0,MIN(5,prepay_yrs)-MIN(4,prepay_yrs))+E18/prepay_yrs*MAX(0,MIN(4,prepay_yrs)-MIN(3,prepay_yrs))+F18/prepay_yrs*MAX(0,MIN(3,prepay_yrs)-MIN(2,prepay_yrs))+G18/prepay_yrs*MAX(0,MIN(2,prepay_yrs)-MIN(1,prepay_yrs))+H18/prepay_yrs*MAX(0,MIN(1,prepay_yrs)-MIN(0,prepay_yrs)) -> 9.7203569 | J19: 期初餘額自 FY27Q2 起、各年新流入自次年起，皆依 prepay_yrs 年直線（一般化）
A20: 營運現金流 | B20: US$B | C20: =Q!L28 -> 31.977 | D20: =cfo_q1+(D15-Q!I27)+(D16-Q!I24)+(D17-sbc_q1)+D18-D19 -> 71.053666 | E20: =E15+E16+E17+E18-E19 -> 81.486076 | F20: =F15+F16+F17+F18-F19 -> 72.116279 | G20: =G15+G16+G17+G18-G19 -> 75.960675 | H20: =H15+H16+H17+H18-H19 -> 80.792685 | I20: =I15+I16+I17+I18-I19 -> 99.801228 | J20: FY2027＝Q1 實績 23.103＋Q2–Q4；營運資金變動除預付外不建模
A21: 資本支出：AI（Thesis） | B21: US$B | D21: =Thesis!E25 -> 87.530786 | E21: =Thesis!F25 -> 80.926364 | F21: =Thesis!G25 -> 10.982201 | G21: =Thesis!H25 -> 14.035418 | H21: =Thesis!I25 -> 17.45917 | I21: =Thesis!J25 -> 62.874208
A22: 資本支出：非 AI | B22: US$B | D22: =capex_g27-D21 -> 4.9692138 | E22: =nonai_cx*(PL!E21-Thesis!F19) -> 5.3066616 | F22: =nonai_cx*(PL!F21-Thesis!G19) -> 5.6460971 | G22: =nonai_cx*(PL!G21-Thesis!H19) -> 5.9762466 | H22: =nonai_cx*(PL!H21-Thesis!I19) -> 6.2853483 | I22: =nonai_cx*(PL!I21-Thesis!J19) -> 6.5618
A23: 資本支出合計 | B23: US$B | C23: =Q!L29 -> 55.663 | D23: =D21+D22 -> 92.5 | E23: =E21+E22 -> 86.233026 | F23: =F21+F22 -> 16.628298 | G23: =G21+G22 -> 20.011665 | H23: =H21+H22 -> 23.744518 | I23: =I21+I22 -> 69.436008 | J23: FY2027＝公司指引中點 92.5（含 Q1 實績 28.499）
A24: 自由現金流 | B24: US$B | C24: =C20-C23 -> -23.686 | D24: =D20-D23 -> -21.446334 | E24: =E20-E23 -> -4.7469497 | F24: =F20-F23 -> 55.487981 | G24: =G20-G23 -> 55.949011 | H24: =H20-H23 -> 57.048167 | I24: =I20-I23 -> 30.36522
