Workbook

Sheet README
A1: 雙鴻（3324）收支與估值模型 v0.1.2（AI 半導體 Project：電源與散熱次產業；樣板＝奇鋐） 2026-10-25
A2: 版本：v0.1.1（2026-10-25：補上檔空間級距、投資建議、重點觀察；上游奇鋐 v0.2.1 液冷滲透率改依情境字母（奇鋐），雙鴻本已依情境字母讀奇鋐 In 頁同一組數值，數值不變）。v0.1（初版）。液冷市場口徑（每架機架內液冷取自橋接表、分歧管、內容調整、滲透率）與奇鋐模型相同（唯讀奇鋐模型 In 頁）；雙鴻份額以 FY2026 液冷占比校準，份額相對值區間與奇鋐相同。目標價＝DCF 與 Comparable 加權；三情境延伸到 FY2032（FY2030 起為收斂法）。
A3: 模型命題：雙鴻的液冷營收＝部署 GW（AI IT 資本支出 ÷ 每 GW IT 資本支出）× 液冷滲透率 × 每 GW 液冷內容 × 雙鴻有效份額；非 AI（伺服器氣冷、筆電與桌機、電競顯卡與其他）另以成長率推估。液冷已占 2026 年營收約六成，EPS 幾乎由液冷市場成長與份額決定。
A4: 核心問題：液冷市場隨部署 GW 與 Rubin 全液冷擴大時，雙鴻能不能守住相對奇鋐的份額（三個 ASIC 液冷專案、Vera Rubin 分歧管），讓 FY2027–28 EPS 達到券商預期的高成長；現價隱含的倍數合不合理。
A6: 會計年度＝日曆年，FY(t)＝CY(t)，不平移。預測期 FY2027–FY2029 為驅動因子推導，FY2030–FY2032 為收斂法，非驅動因子推導。金額：十億新台幣；市場以美元計、以匯率換算。口徑：歸屬母公司淨利。
A8: 驅動因子 → 推導量（全部唯讀上游，不修改）
A9: 液冷營收：markets/network 的 AI IT 資本支出 × 同字母顆數係數（tsmc；＝markets/memory SCEN_UNITS）÷ 每 GW IT 資本支出（Tokenomics，經橋接表）＝部署 GW；× 液冷滲透率 × 每 GW 液冷內容（橋接表每架機架內液冷＋分歧管 × 每 GW 機架數 × 內容調整；皆讀奇鋐模型）× 匯率 × 雙鴻有效份額（FY2026 以凱基液冷占比校準）× 份額相對值。
A10: 非 AI：伺服器氣冷（含 AI 氣冷）、筆電與桌機、電競筆電顯卡主機板與其他，FY2026 以產品比重拆分 × 成長率（Assumed）。毛利率：液冷比其他營收高 d_lc（Assumed），其他毛利率為 FY2026 殘差（Derived）。營業費用：彈性 phi（Derived）。
A11: 情境：A＝順利（顆數係數 A、FY2027 起液冷滲透率高值、份額相對值高值）；B＝平平（顆數係數 B、基準）；C＝不如預期（顆數係數 C、低值）。液冷滲透率屬行業情境（技術替代），份額屬公司特有變數；方向一致：A 最有利、C 最不利。
A12: 校準：FY2026 ＝ 1H26 實績＋3Q26 營收實績（月營收）＋假設（4Q 季增、毛利率、營業費用率）。不用共識或券商數字校準（只在 Recon 對帳）。
A13: 估值：Val 第 0 節目標價＝0.5 × DCF 目標價（股東現金流＝EPS ×（1 − tp_g ÷ tp_roe），FY2027–FY2032 明確期＋永續，r 10%、g 4%，三情境權重 0.3／0.5／0.2，推到 12 個月後；負值取 0）＋0.5 × Comparable 目標價（奇鋐、健策、Vertiv、台達電前瞻 P/E 中位數 × 12 個月後前瞻 EPS）；另列 Comparable 單獨目標價、市場共識目標價與差距拆解、DCF 價格帶、十年 P/E 分位檢查。第 3、6 節十年 P/E 規則值保留給 AI 投資地圖，不是目標價。本版未做先驗，無 Andy 合理 P/E 對照。
A14: 標記：Verified、Interested-party、Analogy、Assumed、Derived。SemiAnalysis 未使用。公司原文經媒體與資料商轉載；券商多經媒體轉述。
A16: 已知限制：(1) 液冷占比只有凱基說法（2025 年 34%、1H26 55%、2026F 60%），公司只給液冷營收年增；(2) 液冷滲透率、每架內容調整、份額相對值為 Assumed（與奇鋐模型同值），是 FY2028 EPS 最敏感的輸入；(3) 本模型的液冷市場只含機架內液冷與分歧管，雙鴻的 CDU 營收計入有效份額的分子，份額偏高估；(4) 十年 P/E 只有 9 年（2016 年未找到），2017–2022 年為 AI 前的倍數；(5) 未建資本支出與折舊；(6) 3Q26 財報（預計 11 月中）後更新錨點；R4 產業部署路徑未建。
A17: ="投資建議："&Val!B130&"（依上檔空間固定規則）" -> 投資建議：強力買進（依上檔空間固定規則）
A18: ="重點觀察 1：目標價 NT$"&TEXT(Val!$B$39,"#,##0")&"（DCF "&TEXT(Val!$B$24,"#,##0")&"、Comparable（相對倍數調整後）"&TEXT(tp_comp_adj,"#,##0")&"；DCF 權重 "&TEXT(tp_w_dcf,"0%")&"），比現價 "&TEXT(px,"#,##0")&"（2026-10-22）"&IF(Val!$B$42>=0,"高 "&TEXT(Val!$B$42,"0.0%"),"低 "&TEXT(-Val!$B$42,"0.0%"))&"，級距 "&Val!$B$129&"、投資建議 "&Val!$B$130&"。相對倍數調整係數 "&TEXT(rm_factor,"0.00")&"（本公司 10 年前瞻倍數中位數 ÷ 同業的中位數，夾在 0.5–2.0；Val 第 0.5 節），調整前加權上檔空間 "&TEXT((tp_w_dcf*Val!$B$24+(1-tp_w_dcf)*Val!$B$35)/px-1,"+0.0%;−0.0%")&"；Comparable 單獨（市場主流同業法、未調整）為 "&TEXT(Val!$B$43,"+0.0%;−0.0%")&"。"&"以下為 2026-10-29 相對倍數調整前撰寫的說明，其中數字為調整前：主因是 EPS 與倍數兩者：本模型 12 個月後前瞻 EPS 123.7 比共識前瞻 EPS 74.3 高 66.4%（兩者期間差約一年；FY2027 B 101.6 比共識 77.97 高 30.4%），同業（奇鋐、健策、Vertiv、台達電）前瞻 P/E 中位數 28.8 倍也高於現價隱含 18.3 倍與共識目標價 1,"&"523 隱含的 20.5 倍；Comparable 未扣雙鴻相對奇鋐的份額折價（雙鴻自身前瞻 P/E 17.3 倍）。" -> 重點觀察 1：目標價 NT$2,290（DCF 1,979、Comparable（相對倍數調整後）2,602；DCF 權重 50%），比現價 1,360（2026-10-22）高 68.4%，級距 大於 50%、投資建議 強力買進。相對倍數調整係數 0.73（本公司 10 年前瞻倍數中位數 ÷ 同業的中位數，夾在 0.5–2.0；Val 第 0.5 節），調整前加權上檔空間 +103.6%；Comparable 單獨（市場主流同業法、未調整）為 +161.7%。以下為 2026-10-29 相對倍數調整前撰寫的說明，其中數字為調整前：主因是 EPS 與倍數兩者：本模型 12 個月後前瞻 EPS 123.7 比共識前瞻 EPS 74.3 高 66.4%（兩者期間差約一年；FY2027 B 101.6 比共識 77.97 高 30.4%），同業（奇鋐、健策、Vertiv、台達電）前瞻 P/E 中位數 28.8 倍也高於現價隱含 18.3 倍與共識目標價 1,523 隱含的 20.5 倍；Comparable 未扣雙鴻相對奇鋐的份額折價（雙鴻自身前瞻 P/E 17.3 倍）。
A19: 重點觀察 2：每架液冷內容調整是最敏感的變數：調整 1.0 時 FY2027 EPS −20.9%，2027 1.6 時 +20.9%；營業費用率 +2pt 時 −10.0%。液冷滲透率與內容調整讀奇鋐模型 In 頁同一組數值（奇鋐 v0.2.1 改依情境字母後，本模型數值不變）。
A20: 重點觀察 3：情境分歧大：FY2028 EPS A／B／C＝188.5／117.8／61.3（A 約為 C 的三倍），DCF 情境價值 3,223／1,744／700；美系券商 FY2028 EPS 110 接近情境 B。10 月營收（約 11-10）與 3Q26 財報與法說（預計 11 月中）可檢驗 2026 年液冷占比約六成（凱基）。
A21: v0.1.2（2026-10-28）：分部原則重建（數值不變）。Q 頁最後追加核對列「檢查：分部合計 − 合併營收」；官方分部與子列宣告見 segments.json。
A23: 2026-10-29：加權目標價中的 Comparable 改用相對倍數調整後的值（Val 第 0.5 節：同業前瞻倍數中位數 × 本公司 10 年相對同業的倍數比，Bloomberg 前瞻倍數；Andy 2026-10-27「照建議做」、10-29 資料取回）。「Comparable 目標價（市場主流同業法）」維持不調整。重點觀察 1 的第一句已改為公式；重點觀察 2、3 與其他說明中的目標價與上檔空間數字為調整前撰寫，以 Val 頁為準。
A25: v0.1.3（2026-10-30）：依個股模型原則第 8 節調整 In 頁呈現（數值不變）。In 頁 D／F 欄名改「敏感度低」「敏感度高」（只用於 Sens 頁、不進目標價）；In 頁最後新增「情境驅動對照」一節，把上方各情境專屬輸入三情境並排（只引用上方各列，純展示）；HTML 驅動因子一節分「情境驅動」與「單一參數」兩張表。

Sheet In
A1: In — 輸入（藍字；基準欄 E，低 D、高 F）。金額：十億新台幣（NT$B），市場與每架內容為美元；比例：%。每個輸入盡量附兩個來源（找不到者寫「未找到」）；公司原文算一個。【v0.1.3】基準欄 E 進主模型；D／F＝敏感度低／高，只用於 Sens 頁（一次動一個參數）、不進目標價；情境 A／B／C 的驅動見本頁最後一節「情境驅動對照」。
A2: 標記：Verified／Interested-party／Analogy／Assumed／Derived；Analogy、Assumed 給低／高區間。SemiAnalysis 未使用。公司原文＝雙鴻財報與月營收（經 HiStock、玩股網、時報轉載）；公司的產品比重說法為 Interested-party；券商估計皆為 Interested-party
A3: 鍵 | B3: 項目 | C3: 單位 | D3: 敏感度低 | E3: 基準 | F3: 敏感度高 | G3: 標記 | H3: 來源1 | I3: 來源2／說明
A4: A. AI 部署規模（讀 markets/network、markets/chip_bridge、tsmc 成品；情境 A 基準，B／C 依同字母顆數係數縮放；與奇鋐模型相同上游）
A5: itc_26 | B5: AI IT 資本支出 2026 | C5: US$B | E5: 781.87292 | G5: Derived | H5: markets/network/dist/20261026_AI網通市場模型_v0.2.3.xlsx｜Mkt!C27:F27 | I5: 加速器顆數 × 每顆 IT capex（含 ASIC）；本模型以此除以每 GW IT 資本支出得到部署 GW
A6: itc_27 | B6: AI IT 資本支出 2027 | C6: US$B | E6: 1565.35 | G6: Derived | H6: markets/network/dist/20261026_AI網通市場模型_v0.2.3.xlsx｜Mkt!C27:F27 | I6: 同上
A7: itc_28 | B7: AI IT 資本支出 2028 | C7: US$B | E7: 1984.2639 | G7: Derived | H7: markets/network/dist/20261026_AI網通市場模型_v0.2.3.xlsx｜Mkt!C27:F27 | I7: 同上
A8: itc_29 | B8: AI IT 資本支出 2029 | C8: US$B | E8: 2260.3903 | G8: Derived | H8: markets/network/dist/20261026_AI網通市場模型_v0.2.3.xlsx｜Mkt!C27:F27 | I8: 同上
A9: itpg_gb | B9: 每 GW IT 資本支出（GB300） | C9: US$B | E9: 32.237224 | G9: Derived | H9: markets/chip_bridge/dist/20261027_晶片內容橋接表_v0.2.2.xlsx｜In!E10（GB300）、H10（VR200） | I9: Tokenomics v20.1 IF_CapexIT（經橋接表；唯讀）
A10: itpg_vr | B10: 每 GW IT 資本支出（VR200；2027 起） | C10: US$B | E10: 37.586352 | G10: Derived | H10: markets/chip_bridge/dist/20261027_晶片內容橋接表_v0.2.2.xlsx｜In!E10（GB300）、H10（VR200） | I10: 同上；Rubin Ultra 與 ASIC 機架未另訂（Assumed：同 VR200）
A11: vr26 | B11: 2026 年部署中 Rubin 世代占比（混合每 GW 數值用） | C11: % | D11: 0.15 | E11: 0.22 | F11: 0.3 | G11: Interested-party | H11: avc/dist/20261030_奇鋐個股模型_v0.2.3.xlsx｜In!D11:F11 | I11: TrendForce 2026 組合 Rubin 22%（經 markets/memory；與奇鋐、台達電模型相同）
A12: racks_gb | B12: 每 GW 機架數（GB300） | C12: 架 | E12: 6764 | G12: Derived | H12: markets/chip_bridge/dist/20261027_晶片內容橋接表_v0.2.2.xlsx｜In!E6（GB300）、H6（VR200） | I12: Tokenomics（經橋接表）
A13: racks_vr | B13: 每 GW 機架數（VR200） | C13: 架 | E13: 4052 | G13: Derived | H13: markets/chip_bridge/dist/20261027_晶片內容橋接表_v0.2.2.xlsx｜In!E6（GB300）、H6（VR200） | I13: 同上
A14: cool_gb | B14: GB300 每架機架內液冷（運算匣＋交換匣，橋接表） | C14: US$K | E14: 50 | G14: Interested-party | H14: markets/chip_bridge/dist/20261027_晶片內容橋接表_v0.2.2.xlsx｜In!E33（GB300）、H33（VR200） | I14: Morgan Stanley（經 Tom's Hardware 2025-11-05）：GB300 NVL72 冷卻 BOM；不含 CDU、分歧管
A15: cool_vr | B15: VR200 每架機架內液冷（橋接表） | C15: US$K | E15: 56 | G15: Interested-party | H15: markets/chip_bridge/dist/20261027_晶片內容橋接表_v0.2.2.xlsx｜In!E33（GB300）、H33（VR200） | I15: 同上：VR NVL144
A16: um28_A | B16: 情境 A：2028 顆數 ÷ 基準 | C16: x | E16: 1 | G16: Assumed | H16: tsmc/dist/20261030_台積電個股模型_v0.4.1.xlsx｜In!E37 | I16: A＝順利（基準）；B＝平平；C＝不如預期；與台積電、奇鋐模型相同（＝markets/memory SCEN_UNITS，建置時核對）
A17: um29_A | B17: 情境 A：2029 顆數 ÷ 基準 | C17: x | E17: 1 | G17: Assumed | H17: tsmc/dist/20261030_台積電個股模型_v0.4.1.xlsx｜In!E38 | I17: 同上
A18: um28_B | B18: 情境 B：2028 顆數 ÷ 基準 | C18: x | E18: 0.8 | G18: Assumed | H18: tsmc/dist/20261030_台積電個股模型_v0.4.1.xlsx｜In!E39 | I18: A＝順利（基準）；B＝平平；C＝不如預期；與台積電、奇鋐模型相同（＝markets/memory SCEN_UNITS，建置時核對）
A19: um29_B | B19: 情境 B：2029 顆數 ÷ 基準 | C19: x | E19: 0.85 | G19: Assumed | H19: tsmc/dist/20261030_台積電個股模型_v0.4.1.xlsx｜In!E40 | I19: 同上
A20: um28_C | B20: 情境 C：2028 顆數 ÷ 基準 | C20: x | E20: 0.6 | G20: Assumed | H20: tsmc/dist/20261030_台積電個股模型_v0.4.1.xlsx｜In!E41 | I20: A＝順利（基準）；B＝平平；C＝不如預期；與台積電、奇鋐模型相同（＝markets/memory SCEN_UNITS，建置時核對）
A21: um29_C | B21: 情境 C：2029 顆數 ÷ 基準 | C21: x | E21: 0.6 | G21: Assumed | H21: tsmc/dist/20261030_台積電個股模型_v0.4.1.xlsx｜In!E42 | I21: 同上
A22: fx | B22: 匯率（新台幣 ÷ 美元） | C22: NT$/US$ | D22: 30.5 | E22: 32 | F22: 33 | G22: Derived | H22: avc/dist/20261030_奇鋐個股模型_v0.2.3.xlsx｜In!D22:F22 | I22: 與奇鋐、台達電模型相同
A23: B. 液冷內容、滲透率（讀奇鋐模型 In 頁：兩家用同一液冷市場口徑）與雙鴻份額相對值
A24: mani | B24: 每架分歧管與快接頭（橋接表未含） | C24: US$K | D24: 3 | E24: 6 | F24: 10 | G24: Assumed | H24: siliconomics｜SIF_lc_mani | I24: Siliconomics M19（與奇鋐模型同一值）；雙鴻另做機架分歧管（Vera Rubin inner／rack manifold，經濟日報 2026-09-18）
A25: lcadj_27 | B25: 每架液冷內容 ÷ 橋接表 2027（Rubin 全液冷、ASIC 液冷；2026＝1） | C25: x | D25: 1 | E25: 1.3 | F25: 1.6 | G25: Assumed | H25: siliconomics｜SIF_lc_adj_27 | I25: Siliconomics M19（與奇鋐模型同一值）：TrendForce 稱 Vera Rubin 全液冷提高單架散熱價值（Interested-party）；本模型三情境用基準值，區間只在 Sens
A26: lcadj_28 | B26: 每架液冷內容 ÷ 橋接表 2028（Rubin 全液冷、ASIC 液冷；2026＝1） | C26: x | D26: 1 | E26: 1.4 | F26: 1.8 | G26: Assumed | H26: siliconomics｜SIF_lc_adj_28 | I26: 同上
A27: lcadj_29 | B27: 每架液冷內容 ÷ 橋接表 2029（Rubin 全液冷、ASIC 液冷；2026＝1） | C27: x | D27: 1 | E27: 1.4 | F27: 1.8 | G27: Assumed | H27: siliconomics｜SIF_lc_adj_29 | I27: 同上
A28: lpen_26 | B28: 液冷滲透率 2026（部署 GW 中液冷占比） | C28: % | D28: 0.45 | E28: 0.55 | F28: 0.65 | G28: Assumed | H28: siliconomics｜SIF_lc_pen_26 | I28: Siliconomics M19（與奇鋐模型同一值；TrendForce 以顆數計 2026 53%、2027 近 60%）。技術替代屬行業情境：FY2027 起 A 取高值、B 基準、C 低值；FY2026 三情境皆基準
A29: lpen_27 | B29: 液冷滲透率 2027（部署 GW 中液冷占比） | C29: % | D29: 0.6 | E29: 0.75 | F29: 0.85 | G29: Assumed | H29: siliconomics｜SIF_lc_pen_27 | I29: 同上
A30: lpen_28 | B30: 液冷滲透率 2028（部署 GW 中液冷占比） | C30: % | D30: 0.7 | E30: 0.85 | F30: 0.95 | G30: Assumed | H30: siliconomics｜SIF_lc_pen_28 | I30: 同上
A31: lpen_29 | B31: 液冷滲透率 2029（部署 GW 中液冷占比） | C31: % | D31: 0.75 | E31: 0.9 | F31: 0.95 | G31: Assumed | H31: siliconomics｜SIF_lc_pen_29 | I31: 同上
A32: rel_27 | B32: 雙鴻液冷份額 2027 ÷ 2026（相對值） | C32: x | D32: 0.85 | E32: 0.95 | F32: 1.05 | G32: Assumed | H32: siliconomics｜SIF_lc_avrel_27（區間與奇鋐相同） | I32: 公司特有：A 取高值（三個 ASIC 液冷專案 3Q／4Q26 量產、Vera Rubin 分歧管）、B 基準（與奇鋐相同的份額流失斜率：酷碼、台達電、富世達等追趕）、C 低值；凱基 2026-08-07：雙鴻為台灣前三大散熱廠（未給份額，Interested-party）；份額數字：未找到
A33: rel_28 | B33: 雙鴻液冷份額 2028 ÷ 2026（相對值） | C33: x | D33: 0.75 | E33: 0.9 | F33: 1.05 | G33: Assumed | H33: siliconomics｜SIF_lc_avrel_28（區間與奇鋐相同） | I33: 同上
A34: rel_29 | B34: 雙鴻液冷份額 2029 ÷ 2026（相對值） | C34: x | D34: 0.7 | E34: 0.85 | F34: 1.05 | G34: Assumed | H34: siliconomics｜SIF_lc_avrel_29（區間與奇鋐相同） | I34: 同上
A35: C. 營收結構錨點（公司揭露比例 × 營收）
A36: srv_25 | B36: 2025 年伺服器 ÷ 營收 | C36: % | E36: 0.57 | G36: Interested-party | H36: https://wantrich.chinatimes.com/news/20260521900232-420101：2025 年伺服器 57%、PC 27%、VGA 14%、其他 2%（公司，股東會） | I36: https://www.kgi.com.hk/zh-cn/-/media/files/kgishk/research-reports/tw-reports/auras-technology-3324-tt20260807en.pdf：2025 年伺服器 57%、筆電與桌機 27%、電競筆電顯卡主機板 14%、其他 2%
A37: nb_25 | B37: 2025 年筆電與桌機 ÷ 營收 | C37: % | E37: 0.27 | G37: Interested-party | H37: 同上（公司 PC 27%） | I37: 同上（凱基 27%）
A38: lc_25 | B38: 2025 年液冷 ÷ 營收 | C38: % | D38: 0.3 | E38: 0.34 | F38: 0.38 | G38: Interested-party | H38: 凱基 2026-08-07（網址見 Sources）：2025 年液冷占營收 34% | I38: 第二來源：未找到
A39: srv_26 | B39: 2026 年伺服器 ÷ 營收 | C39: % | D39: 0.72 | E39: 0.74 | F39: 0.76 | G39: Interested-party | H39: https://www.kgi.com.hk/zh-cn/-/media/files/kgishk/research-reports/tw-reports/auras-technology-3324-tt20260807en.pdf：2026F 伺服器 74%（2Q26 78%） | I39: 公司：2026 年伺服器營收年增 110–120%（凱基轉述）→ 2025 年 57% × 2.15 ÷ 營收年增約 64% ≈ 75%（Derived）
A40: nb_26 | B40: 2026 年筆電與桌機 ÷ 營收 | C40: % | D40: 0.13 | E40: 0.15 | F40: 0.17 | G40: Interested-party | H40: 凱基 2026-08-07（網址見 Sources）：2026F 筆電與桌機 15%（2Q26 17%） | I40: 第二來源：未找到
...

Sheet Q
A1: Q — 實績與 FY2026 錨點（十億新台幣；EPS 為新台幣；股數為十億股）。藍字＝輸入；黑字＝公式。實績取自雙鴻財報（經玩股網、時報、HiStock 轉載）與月營收
A2: FY2026 錨點＝1H26 實績＋3Q26 營收實績（月營收）＋3Q、4Q 假設（毛利率、營業費用率、業外、淨利 ÷ 稅前；4Q 營收＝3Q × (1＋季增)）。3Q26 財報與法說（2025 年為 11 月中）尚未公布。各季毛利、營業利益、稅前取自玩股網各季損益（合併）；歸屬母公司淨利與 EPS 取自公司公告（經時報、凱基、HiStock）
A3: 項目 | B3: FY2025A | C3: 1H26（實績） | D3: 3Q26（營收實績） | E3: 4Q26（模型） | F3: FY2026 錨點 | G3: 標記 | H3: 來源1（公司） | I3: 來源2／說明
A4: 營收 | B4: 23.276 | C4: =8.551657+8.700121 -> 17.251778 | D4: =q3_rev -> 9.790776 | E4: =D4*(1+q4g) -> 11.161485 | F4: =SUM(C4:E4) -> 38.204039 | G4: Verified／Interested-party（4Q 季增） | H4: FY2025：https://wantrich.chinatimes.com/news/20260304900286-420101；各季：https://www.wantgoo.com/stock/3324/financial-statements/income-statement | I4: FY2025 232.76 億元（時報 2026-03-04）；1Q26 85.52、2Q26 87.00 億元（玩股網；凱基 2Q 87.00）
A5: 毛利 | B5: 6.372 | C5: =2.536523+2.472471 -> 5.008994 | D5: =D4*q_gm -> 2.839325 | E5: =E4*q_gm -> 3.2368305 | F5: =SUM(C5:E5) -> 11.08515 | G5: Verified／Interested-party（3Q、4Q） | H5: FY2025：https://wantrich.chinatimes.com/news/20260304900286-420101；各季：https://www.wantgoo.com/stock/3324/financial-statements/income-statement | I5: FY2025 毛利率 27.38%（時報）；2Q26 28.4%（凱基）
A6: 毛利率 | B6: =B5/B4 -> 0.27375838 | C6: =C5/C4 -> 0.29034654 | D6: =D5/D4 -> 0.29 | E6: =E5/E4 -> 0.29 | F6: =F5/F4 -> 0.29015649 | G6: Derived | H6: — | I6: FY2025 27.4%；1H26 29.0%
A7: 營業費用 | B7: =B5-B8 -> 3.113 | C7: =C5-C8 -> 2.099071 | D7: =D4*q_opx -> 1.0769854 | E7: =E4*q_opx -> 1.2277633 | F7: =SUM(C7:E7) -> 4.4038197 | G7: Derived（毛利 − 營業利益）／Interested-party | H7: FY2025：https://wantrich.chinatimes.com/news/20260304900286-420101；各季：https://www.wantgoo.com/stock/3324/financial-statements/income-statement | I7: 凱基 2026-08-07（https://www.kgi.com.hk/zh-cn/-/media/files/kgishk/research-reports/tw-reports/auras-technology-3324-tt20260807en.pdf）
A8: 營業利益 | B8: 3.259 | C8: =1.519644+1.390279 -> 2.909923 | D8: =D5-D7 -> 1.7623397 | E8: =E5-E7 -> 2.0090672 | F8: =SUM(C8:E8) -> 6.6813299 | G8: Verified／Derived | H8: FY2025：https://wantrich.chinatimes.com/news/20260304900286-420101；各季：https://www.wantgoo.com/stock/3324/financial-statements/income-statement | I8: FY2025 營益率 14.0%（時報）；2Q26 13.90 億元、營益率 16.0%（凱基）
A9: 營業利益率 | B9: =B8/B4 -> 0.14001547 | C9: =C8/C4 -> 0.1686738 | D9: =D8/D4 -> 0.18 | E9: =E8/E4 -> 0.18 | F9: =F8/F4 -> 0.17488543 | G9: Derived | H9: — | I9: —
A10: 業外收益 | B10: =B11-B8 -> 0.018436 | C10: =C11-C8 -> -0.022684 | D10: =q_nop -> 0 | E10: =q_nop -> 0 | F10: =SUM(C10:E10) -> -0.022684 | G10: Derived | H10: FY2025：https://wantrich.chinatimes.com/news/20260304900286-420101；各季：https://www.wantgoo.com/stock/3324/financial-statements/income-statement | I10: 凱基 2026-08-07（https://www.kgi.com.hk/zh-cn/-/media/files/kgishk/research-reports/tw-reports/auras-technology-3324-tt20260807en.pdf）
A11: 稅前利益 | B11: 3.277436 | C11: =1.570048+1.317191 -> 2.887239 | D11: =D8+D10 -> 1.7623397 | E11: =E8+E10 -> 2.0090672 | F11: =SUM(C11:E11) -> 6.6586459 | G11: Verified（資料商轉載）／Derived | H11: https://www.wantgoo.com/stock/3324/financial-statements/income-statement | I11: FY2025 為四季加總
A12: 歸屬母公司淨利 | B12: 2.572 | C12: =1.164+0.969 -> 2.133 | D12: =D11*q_nir -> 1.3041314 | E12: =E11*q_nir -> 1.4867098 | F12: =SUM(C12:E12) -> 4.9238411 | G12: Verified／Derived（3Q、4Q） | H12: FY2025：https://wantrich.chinatimes.com/news/20260304900286-420101；各季：https://www.wantgoo.com/stock/3324/financial-statements/income-statement | I12: FY2025 25.72 億（時報 2026-03-04）；1Q26 11.64 億（時報 2026-05-21）；2Q26 9.69 億（凱基）；合併淨利 FY2025 26.98、1Q26 12.65、2Q26 10.39（玩股網）
A13: 淨利 ÷ 稅前（含稅與非控制權益） | B13: =B12/B11 -> 0.78475979 | C13: =C12/C11 -> 0.73876808 | D13: =D12/D11 -> 0.74 | E13: =E12/E11 -> 0.74 | F13: =F12/F11 -> 0.73946583 | G13: Derived | H13: — | I13: —
A14: 股數（十億股） | B14: =2.572/28.26 -> 0.091012031 | C14: =2.133/23.02 -> 0.092658558 | D14: =q_sh -> 0.093076837 | E14: =q_sh -> 0.093076837 | F14: =q_sh -> 0.093076837 | G14: Derived／Verified | H14: FY2025：https://wantrich.chinatimes.com/news/20260304900286-420101；各季：https://www.wantgoo.com/stock/3324/financial-statements/income-statement | I14: FY2025、1H26＝淨利 ÷ EPS（加權）；3Q 起＝已發行股數
A15: EPS | B15: =B12/B14 -> 28.26 | C15: =C12/C14 -> 23.02 | D15: =D12/D14 -> 14.011342 | E15: =E12/E14 -> 15.972929 | F15: =F12/F14 -> 52.900821 | G15: Derived | H15: 淨利 ÷ 股數 | I15: FY2026 錨點以已發行股數換算（1H26 加權股數較少，差約 0.4%）
A16: 公司揭露 EPS | B16: 28.26 | C16: 23.02 | G16: Verified | H16: https://histock.tw/stock/3324/每股盈餘 | I16: 1Q26 12.61、2Q26 10.41；3Q25 10.66、4Q25 10.19（https://winvest.tw/News/Detail/95436）
A17: 液冷營收（＝營收 × 液冷占比） | B17: =B4*lc_25 -> 7.91384 | F17: =F4*lc_26 -> 22.922423 | G17: Derived／Interested-party | H17: 公司與凱基產品比重（In 頁 C 節） | I17: 液冷、伺服器氣冷的季度金額未揭露：未找到
A18: 伺服器氣冷（＝營收 ×（伺服器 − 液冷）） | B18: =B4*(srv_25-lc_25) -> 5.35348 | F18: =F4*(srv_26-lc_26) -> 5.3485654 | G18: Derived／Interested-party | H18: 公司與凱基產品比重（In 頁 C 節） | I18: —
A19: 筆電與桌機（＝營收 × 筆電與桌機占比） | B19: =B4*nb_25 -> 6.28452 | F19: =F4*nb_26 -> 5.7306058 | G19: Derived／Interested-party | H19: 公司與凱基產品比重（In 頁 C 節） | I19: —
A20: 電競筆電、顯卡、主機板與其他（＝營收 ×（1 − 伺服器 − 筆電與桌機）） | B20: =B4*(1-srv_25-nb_25) -> 3.72416 | F20: =F4*(1-srv_26-nb_26) -> 4.2024443 | G20: Derived／Interested-party | H20: 公司與凱基產品比重（In 頁 C 節） | I20: —
A21: 液冷（Sens：2026 液冷占比 低） | F21: =F4*lc_26_lo -> 21.012221 | G21: Derived | H21: Sens 用 | I21: —
A22: 伺服器氣冷（Sens：液冷占比 低） | F22: =F4*(srv_26-lc_26_lo) -> 7.2587673 | G22: Derived | H22: Sens 用 | I22: —
A23: 液冷（Sens：2026 液冷占比 高） | F23: =F4*lc_26_hi -> 24.068544 | G23: Derived | H23: Sens 用 | I23: —
A24: 伺服器氣冷（Sens：液冷占比 高） | F24: =F4*(srv_26-lc_26_hi) -> 4.2024443 | G24: Derived | H24: Sens 用 | I24: —
A26: 營業費用彈性（FY2026 營業費用年增 ÷ 營收年增；In 頁 phi 的依據） | B26: =(F7/B7-1)/(F4/B4-1) -> 0.64653502
A28: FY2026 錨點的檢查（參考；校準未使用券商數字）
A29: FY2026 營收年增 | B29: =F4/B4-1 -> 0.64134897
A30: FY2026 液冷營收年增（公司：+190–200%） | B30: =F17/B17-1 -> 1.8964982
A31: FY2026 伺服器營收年增（公司：+110–120%） | B31: =(F17+F18)/(B17+B18)-1 -> 1.1308741
A32: FY2026 營收 ÷ 共識（stockanalysis）− 1 | B32: =F4/c_rev26-1 -> -0.012815539
A33: FY2026 EPS ÷ 共識（stockanalysis）− 1 | B33: =F15/c_eps26-1 -> -0.058369148
A35: 檢查：分部合計 − 合併營收 | B35: =ROUND(B17+B18+B19+B20-B4,6) -> 0
A36: 分部原則第 3 條（2026-10-28 追加）；分部宣告見 segments.json

Sheet Units
A1: Units — AI 液冷市場（機架內液冷＋分歧管，與奇鋐模型同口徑）、雙鴻份額與每 GW 營收（情境 B）。部署 GW＝AI IT 資本支出（markets/network）÷ 每 GW IT 資本支出（Tokenomics，經橋接表）；每架液冷取自橋接表
A3: 項目 | B3: 單位 | C3: CY2026 | D3: CY2027 | E3: CY2028 | F3: CY2029 | G3: 說明
A4: 部署 GW（情境 B） | B4: GW | C4: =PL!D103 -> 23.399538 | D4: =PL!E103 -> 41.646766 | E4: =PL!F103 -> 42.233711 | F4: =PL!G103 -> 51.117803 | G4: AI IT 資本支出 × 顆數係數 B ÷ 每 GW IT 資本支出
A5: 液冷滲透率（部署 GW） | B5: % | C5: =PL!D104 -> 0.55 | D5: =PL!E104 -> 0.75 | E5: =PL!F104 -> 0.85 | F5: =PL!G104 -> 0.9 | G5: 奇鋐模型的假設（In 頁 B 節）
A6: 每 GW 液冷內容 | B6: US$M/GW | C6: =PL!D105 -> 350.7208 | D6: =PL!E105 -> 326.5912 | E6: =PL!F105 -> 351.7136 | F6: =PL!G105 -> 351.7136 | G6: 橋接表機架內液冷＋分歧管 × 每 GW 機架數 × 內容調整
A7: AI 液冷市場（機架內液冷＋分歧管） | B7: US$B | C7: =PL!D106 -> 4.5136876 | D7: =PL!E106 -> 10.2011 | E7: =PL!F106 -> 12.626045 | F7: =PL!G106 -> 16.180944 | G7: 不含機架外 CDU、液對氣
A8: 雙鴻有效份額 | B8: % | C8: =PL!D110 -> 0.15870078 | D8: =PL!E110 -> 0.15076574 | E8: =PL!F110 -> 0.1428307 | F8: =PL!G110 -> 0.13489566 | G8: FY2026 以凱基液冷占比校準
A9: 奇鋐有效份額（奇鋐模型） | B9: % | C9: =avsh_26 -> 0.49892764 | D9: =avsh_27 -> 0.47398126 | E9: =avsh_28 -> 0.44903488 | F9: =avsh_29 -> 0.42408849 | G9: 奇鋐模型 Units（唯讀）；奇鋐三情境份額相同
A10: 兩家有效份額合計（奇鋐＋雙鴻） | B10: % | C10: =C8+C9 -> 0.65762842 | D10: =D8+D9 -> 0.624747 | E10: =E8+E9 -> 0.59186558 | F10: =F8+F9 -> 0.55898415 | G10: 兩家分子都含 CDU 與機架外產品，合計偏高估實際冷板份額
A11: 其他廠商（酷碼、台達電、富世達、Boyd、CoolIT 等）＝ 1 − 兩家合計 | B11: % | C11: =1-C10 -> 0.34237158 | D11: =1-D10 -> 0.375253 | E11: =1-E10 -> 0.40813442 | F11: =1-F10 -> 0.44101585
A12: 雙鴻液冷營收 | B12: US$B | C12: =PL!D111/fx -> 0.71632572 | D12: =PL!E111/fx -> 1.5379764 | E12: =PL!F111/fx -> 1.8033868 | F12: =PL!G111/fx -> 2.1827391
A13: 每 GW 雙鴻液冷營收 | B13: US$M/GW | C13: =PL!D119 -> 30.612815 | D13: =PL!E119 -> 36.929072 | E13: =PL!F119 -> 42.700174 | F13: =PL!G119 -> 42.700174
A15: 讀法：液冷市場口徑、滲透率、每架內容調整與奇鋐模型相同；雙鴻份額以 FY2026 液冷占比（凱基）校準。兩家有效份額合計約六成，其餘為酷碼、台達電、富世達、Boyd、CoolIT 等；合計若超過八成即不合理，應回頭檢查份額相對值或市場口徑。

Sheet PL
A1: PL — 雙鴻損益（十億新台幣；EPS 新台幣；歸屬母公司）。FY2025A 實績、FY2026 錨點（1H26 實績＋3Q26 營收實績＋假設），FY2027–FY2029 為驅動因子推導，FY2030–FY2032 為收斂法（本頁延伸表，灰底）。FY(t)＝CY(t)。三情境各一個完整推導區塊（本頁下方），頂端為摘要
A3: 情境／項目 | B3: 單位 | C3: FY2025A | D3: FY2026（錨點） | E3: FY2027 | F3: FY2028 | G3: FY2029 | H3: 說明
A4: 情境 A
A5: 營收 | B5: NT$B | C5: =C78 -> 23.276 | D5: =D78 -> 38.204039 | E5: =E78 -> 76.49084 | F5: =F78 -> 108.64721 | G5: =G78 -> 121.49493
A6: 營收年增 | B6: % | D6: =D79 -> 0.64134897 | E6: =E79 -> 1.0021663 | F6: =F79 -> 0.42039505 | G6: =G79 -> 0.1182517
A7: 液冷營收 | B7: NT$B | C7: =C73 -> 7.91384 | D7: =D73 -> 22.922423 | E7: =E73 -> 61.648571 | F7: =F73 -> 94.058998 | G7: =G73 -> 107.14807
A8: 伺服器氣冷營收 | B8: NT$B | C8: =C75 -> 5.35348 | D8: =D75 -> 5.3485654 | E8: =E75 -> 5.0811371 | F8: =F75 -> 4.8270803 | G8: =G75 -> 4.5857263
A9: 筆電與桌機營收 | B9: NT$B | C9: =C76 -> 6.28452 | D9: =D76 -> 5.7306058 | E9: =E76 -> 5.5586876 | F9: =F76 -> 5.5586876 | G9: =G76 -> 5.5586876
A10: 電競、顯卡與其他營收 | B10: NT$B | C10: =C77 -> 3.72416 | D10: =D77 -> 4.2024443 | E10: =E77 -> 4.2024443 | F10: =F77 -> 4.2024443 | G10: =G77 -> 4.2024443
A11: 液冷 ÷ 營收 | B11: % | C11: =C80 -> 0.34 | D11: =D80 -> 0.6 | E11: =E80 -> 0.80596018 | F11: =F80 -> 0.86572861 | G11: =G80 -> 0.88191393
A12: 毛利率 | B12: % | C12: =C85 -> 0.27375838 | D12: =D85 -> 0.29015649 | E12: =E85 -> 0.30045449 | F12: =F85 -> 0.30344292 | G12: =G85 -> 0.30425218
A13: 營業利益率 | B13: % | C13: =C89 -> 0.14001547 | D13: =D89 -> 0.17488543 | E13: =E89 -> 0.2053777 | F13: =F89 -> 0.2182151 | G13: =G89 -> 0.22217877
A14: 歸屬母公司淨利 | B14: NT$B | C14: =C92 -> 2.572 | D14: =D92 -> 4.9238411 | E14: =E92 -> 11.62504 | F14: =F92 -> 17.544262 | G14: =G92 -> 19.975259
A15: EPS | B15: NT$ | C15: =C94 -> 28.26 | D15: =D94 -> 52.900821 | E15: =E94 -> 124.89724 | F15: =F94 -> 188.49224 | G15: =G94 -> 214.61042
A16: EPS 年增 | B16: % | D16: =D95 -> 0.87193281 | E16: =E95 -> 1.3609697 | F16: =F95 -> 0.50917865 | G16: =G95 -> 0.13856368
A18: 情境 B
A19: 營收 | B19: NT$B | C19: =C116 -> 23.276 | D19: =D116 -> 38.204039 | E19: =E116 -> 64.057515 | F19: =F116 -> 72.29659 | G19: =G116 -> 84.194509
A20: 營收年增 | B20: % | D20: =D117 -> 0.64134897 | E20: =E117 -> 0.67672102 | F20: =F117 -> 0.12861996 | G20: =G117 -> 0.16457096
A21: 液冷營收 | B21: NT$B | C21: =C111 -> 7.91384 | D21: =D111 -> 22.922423 | E21: =E111 -> 49.215246 | F21: =F111 -> 57.708378 | G21: =G111 -> 69.847651
A22: 伺服器氣冷營收 | B22: NT$B | C22: =C113 -> 5.35348 | D22: =D113 -> 5.3485654 | E22: =E113 -> 5.0811371 | F22: =F113 -> 4.8270803 | G22: =G113 -> 4.5857263
A23: 筆電與桌機營收 | B23: NT$B | C23: =C114 -> 6.28452 | D23: =D114 -> 5.7306058 | E23: =E114 -> 5.5586876 | F23: =F114 -> 5.5586876 | G23: =G114 -> 5.5586876
A24: 電競、顯卡與其他營收 | B24: NT$B | C24: =C115 -> 3.72416 | D24: =D115 -> 4.2024443 | E24: =E115 -> 4.2024443 | F24: =F115 -> 4.2024443 | G24: =G115 -> 4.2024443
A25: 液冷 ÷ 營收 | B25: % | C25: =C118 -> 0.34 | D25: =D118 -> 0.6 | E25: =E118 -> 0.76829777 | F25: =F118 -> 0.79821715 | G25: =G118 -> 0.82959865
A26: 毛利率 | B26: % | C26: =C123 -> 0.27375838 | D26: =D123 -> 0.29015649 | E26: =E123 -> 0.29857137 | F26: =F123 -> 0.30006734 | G26: =G123 -> 0.30163642
A27: 營業利益率 | B27: % | C27: =C127 -> 0.14001547 | D27: =D127 -> 0.17488543 | E27: =E127 -> 0.19958343 | F27: =F127 -> 0.2050277 | G27: =G127 -> 0.21129745
A28: 歸屬母公司淨利 | B28: NT$B | C28: =C130 -> 2.572 | D28: =D130 -> 4.9238411 | E28: =E130 -> 9.4607655 | F28: =F130 -> 10.968875 | G28: =G130 -> 13.164663
A29: EPS | B29: NT$ | C29: =C132 -> 28.26 | D29: =D132 -> 52.900821 | E29: =E132 -> 101.64468 | F29: =F132 -> 117.84752 | G29: =G132 -> 141.43866
A30: EPS 年增 | B30: % | D30: =D133 -> 0.87193281 | E30: =E133 -> 0.92141974 | F30: =F133 -> 0.15940669 | G30: =G133 -> 0.20018355
A32: 情境 C
A33: 營收 | B33: NT$B | C33: =C154 -> 23.276 | D33: =D154 -> 38.204039 | E33: =E154 -> 50.070024 | F33: =F154 -> 44.291054 | G33: =G154 -> 48.183091
A34: 營收年增 | B34: % | D34: =D155 -> 0.64134897 | E34: =E155 -> 0.31059505 | F34: =F155 -> -0.11541776 | G34: =G155 -> 0.08787411
A35: 液冷營收 | B35: NT$B | C35: =C149 -> 7.91384 | D35: =D149 -> 22.922423 | E35: =E149 -> 35.227755 | F35: =F149 -> 29.702841 | G35: =G149 -> 33.836232
A36: 伺服器氣冷營收 | B36: NT$B | C36: =C151 -> 5.35348 | D36: =D151 -> 5.3485654 | E36: =E151 -> 5.0811371 | F36: =F151 -> 4.8270803 | G36: =G151 -> 4.5857263
A37: 筆電與桌機營收 | B37: NT$B | C37: =C152 -> 6.28452 | D37: =D152 -> 5.7306058 | E37: =E152 -> 5.5586876 | F37: =F152 -> 5.5586876 | G37: =G152 -> 5.5586876
A38: 電競、顯卡與其他營收 | B38: NT$B | C38: =C153 -> 3.72416 | D38: =D153 -> 4.2024443 | E38: =E153 -> 4.2024443 | F38: =F153 -> 4.2024443 | G38: =G153 -> 4.2024443
A39: 液冷 ÷ 營收 | B39: % | C39: =C156 -> 0.34 | D39: =D156 -> 0.6 | E39: =E156 -> 0.70356976 | F39: =F156 -> 0.67062847 | G39: =G156 -> 0.70224288
A40: 毛利率 | B40: % | C40: =C161 -> 0.27375838 | D40: =D161 -> 0.29015649 | E40: =E161 -> 0.29533497 | F40: =F161 -> 0.29368791 | G40: =G161 -> 0.29526863
A41: 營業利益率 | B41: % | C41: =C165 -> 0.14001547 | D41: =D165 -> 0.17488543 | E41: =E165 -> 0.18962516 | F41: =F165 -> 0.17418539 | G41: =G165 -> 0.17914463
A42: 歸屬母公司淨利 | B42: NT$B | C42: =C168 -> 2.572 | D42: =D168 -> 4.9238411 | E42: =E168 -> 7.025957 | F42: =F168 -> 5.7089922 | G42: =G168 -> 6.3874892
A43: EPS | B43: NT$ | C43: =C170 -> 28.26 | D43: =D170 -> 52.900821 | E43: =E170 -> 75.485559 | F43: =F170 -> 61.336336 | G43: =G170 -> 68.62598
...

Sheet Val
A1: Val — P/E 估值（新台幣）。目標價＝DCF 與 Comparable 加權（第 0 節）；另列「現價 ÷ FY2027、FY2028 EPS（模型）」與十年 P/E 規則值（年底落後 P/E，基準為 FY2027 EPS；參考，不是目標價）
A2: 循環位置：雙鴻不是設備股，不套設備市場見頂年；以本模型營收最高的會計年度為見頂年（比照奇鋐、台達電；FY(t)＝CY(t)）。營收到 FY2029 仍在增加時，見頂年未知，判為中段
A3: 目標價：見第 0 節（本頁第 4 列起）。第 3 節與第 6 節「規則值」保留給 AI 投資地圖抽數，不是目標價
A4: 0. 目標價
A5: 0.1 DCF（股東權益現金流，FY2027–FY2032 明確期＋FY2032 後永續）
A6: 項目 | B6: A（順利） | C6: B（平平） | D6: C（不如預期） | E6: 說明
A7: 情境 EPS（FY2027–FY2032） | E7: PL 頁延伸表；FY2030 起為收斂法
A8: FY2027 | B8: =PL!E182 -> 124.89724 | C8: =PL!E194 -> 101.64468 | D8: =PL!E206 -> 75.485559
A9: FY2028 | B9: =PL!F182 -> 188.49224 | C9: =PL!F194 -> 117.84752 | D9: =PL!F206 -> 61.336336
A10: FY2029 | B10: =PL!G182 -> 214.61042 | C10: =PL!G194 -> 141.43866 | D10: =PL!G206 -> 68.62598
A11: FY2030 | B11: =PL!H182 -> 235.82133 | C11: =PL!H194 -> 146.83164 | D11: =PL!H206 -> 64.437819
A12: FY2031 | B12: =PL!I182 -> 254.5496 | C12: =PL!I194 -> 145.81206 | D12: =PL!I206 -> 58.149113
A13: FY2032 | B13: =PL!J182 -> 269.82258 | C13: =PL!J194 -> 138.13513 | D13: =PL!J206 -> 50.096039
A14: 股東現金流＝EPS ×（1 − tp_g ÷ tp_roe）
A15: 再投資率（tp_g ÷ tp_roe，上限 0.8） | B15: =MIN(tp_g/tp_roe,0.8) -> 0.17286085 | E15: ROE 為近三年平均（In 頁 tp_roe）；本模型未建資本支出與折舊，用 g／ROE
A16: FY2027 | B16: =B8*(1-$B$15) -> 103.30739 | C16: =C8*(1-$B$15) -> 84.074296 | D16: =D8*(1-$B$15) -> 62.437061
A17: FY2028 | B17: =B9*(1-$B$15) -> 155.90931 | C17: =C9*(1-$B$15) -> 97.476301 | D17: =D9*(1-$B$15) -> 50.733685
A18: FY2029 | B18: =B10*(1-$B$15) -> 177.51268 | C18: =C10*(1-$B$15) -> 116.98945 | D18: =D10*(1-$B$15) -> 56.763235
A19: FY2030 | B19: =B11*(1-$B$15) -> 195.05705 | C19: =C11*(1-$B$15) -> 121.4502 | D19: =D11*(1-$B$15) -> 53.299043
A20: FY2031 | B20: =B12*(1-$B$15) -> 210.54794 | C20: =C12*(1-$B$15) -> 120.60687 | D20: =D12*(1-$B$15) -> 48.097408
A21: FY2032 | B21: =B13*(1-$B$15) -> 223.18082 | C21: =C13*(1-$B$15) -> 114.25697 | D21: =D13*(1-$B$15) -> 41.436395
A22: DCF 情境每股價值（折現率 tp_r） | B22: =MAX(0,SUMPRODUCT(B16:B21,1/(1+tp_r)^{1;2;3;4;5;6})+B21*(1+tp_g)/(tp_r-tp_g)/(1+tp_r)^6) -> 2929.7235 | C22: =MAX(0,SUMPRODUCT(C16:C21,1/(1+tp_r)^{1;2;3;4;5;6})+C21*(1+tp_g)/(tp_r-tp_g)/(1+tp_r)^6) -> 1585.1354 | D22: =MAX(0,SUMPRODUCT(D16:D21,1/(1+tp_r)^{1;2;3;4;5;6})+D21*(1+tp_g)/(tp_r-tp_g)/(1+tp_r)^6) -> 636.41771 | E22: Σ 明確期現金流 ÷ (1＋r)^t ＋ 永續價值 ÷ (1＋r)^6；永續價值＝FY2032 現金流 ×(1＋g)÷(r−g)；基準日 2026 年底；負值取 0（Andy 12:22）
A23: DCF 情境價值推到 12 個月後（×(1＋tp_r)） | B23: =B22*(1+tp_r) -> 3222.6959 | C23: =C22*(1+tp_r) -> 1743.6489 | D23: =D22*(1+tp_r) -> 700.05948
A24: DCF 目標價（情境加權） | B24: =tp_wA*B23+tp_wB*C23+tp_wC*D23 -> 1978.6451 | E24: Σ 權重 × 情境價值 ×(1＋r)；權重見 In 頁
A26: 0.2 Comparable（市場主流同業前瞻 P/E；非 A 股公司，同業不放 A 股）
A27: 同業與前瞻 P/E | B27: 代號 | C27: 前瞻 12 月 P/E | D27: 日期 | E27: 來源 | F27: 標記
A28: 奇鋐（AVC） | B28: 3017.TW | C28: 27.04 | D28: 2026-10-05 | E28: stockanalysis.com 個股頁 Forward PE（分析師共識；價格日期如左，臺股頁面為快取日期） | F28: Interested-party（賣方共識）
A29: 健策（Jentech） | B29: 3653.TW | C29: 59.27 | D29: 2026-08-27 | E29: stockanalysis.com 個股頁 Forward PE（分析師共識；價格日期如左，臺股頁面為快取日期） | F29: Interested-party（賣方共識）
A30: Vertiv | B30: VRT | C30: 24.53 | D30: 2026-10-23 | E30: stockanalysis.com 個股頁 Forward PE（分析師共識；價格日期如左，臺股頁面為快取日期） | F30: Interested-party（賣方共識）
A31: 台達電（Delta） | B31: 2308.TW | C31: 30.51 | D31: 2026-10-22 | E31: stockanalysis.com 個股頁 Forward PE（分析師共識；價格日期如左，臺股頁面為快取日期） | F31: Interested-party（賣方共識）
A32: 並列參考（不進目標價）：無。英維克（002837.SZ）為 A 股，依規則不列；酷碼（Cooler Master）、Boyd、CoolIT 未上市
A33: 同業前瞻 P/E 中位數 | B33: =MEDIAN(C28:C31) -> 28.775 | E33: 散熱與液冷同業：奇鋐、健策、Vertiv、台達電（與奇鋐模型同一比較組，雙鴻換成奇鋐）；非 A 股公司的同業名單不放中國 A 股（Andy 2026-10-25 11:53）
A34: 12 個月後的前瞻 EPS（情境加權） | B34: =tp_wA*(2/12*B8+10/12*B9)+tp_wB*(2/12*C8+10/12*C9)+tp_wC*(2/12*D8+10/12*D9) -> 123.68036 | E34: 約 2027-10 時的未來 12 月 EPS ≈ 2／12 × FY2027＋10／12 × FY2028（會計年度＝日曆年）
A35: Comparable 目標價 | B35: =B33*B34 -> 3558.9022 | E35: 同業中位數 × 上列 EPS
A37: 0.3 結論
A38: 項目 | B38: 數值 | E38: 說明
A39: 目標價（DCF 與 Comparable 加權） | B39: =tp_w_dcf*B24+(1-tp_w_dcf)*tp_comp_adj -> 2290.2186 | E39: tp_w_dcf × DCF＋（1 − tp_w_dcf）× Comparable；tp_w_dcf 見 In 頁
A40: Comparable 目標價（市場主流同業法） | B40: =B35 -> 3558.9022 | E40: 引用 0.2
A41: 市場共識目標價 | B41: =cons_tp -> 1523 | E41: stockanalysis（S&P Global）：17 位分析師平均 1,523、中位數 1,550（頁面時間 2026-10-19）
A42: 上檔空間：加權目標價 | B42: =B39/px-1 -> 0.68398427 | E42: 現價＝In 頁 px（2026-10-22 收盤 1,360）
...

Sheet Recon
A1: Recon — 本模型 vs 共識、券商估計與奇鋐模型的份額（兩家份額合計檢查）。只作事後對照，不為對上數字而調參數。共識取自 stockanalysis（S&P Global）；券商多經媒體轉述
A3: 項目 | B3: 對照值 | C3: 模型 A | D3: 差距 A | E3: 模型 B | F3: 差距 B | G3: 模型 C | H3: 差距 C | I3: 對照來源 | J3: 說明
A4: A. 共識與券商估計（校準未使用）
A5: FY2026 營收 vs 共識（stockanalysis） | B5: =c_rev26 -> 38.7 | C5: =PL!D78 -> 38.204039 | D5: =C5/B5-1 -> -0.012815539 | E5: =PL!D116 -> 38.204039 | F5: =E5/B5-1 -> -0.012815539 | G5: =PL!D154 -> 38.204039 | H5: =G5/B5-1 -> -0.012815539 | I5: stockanalysis（2026-10-19） | J5: 區間 375–399 億
A6: FY2026 營收 vs 凱基（08-07，3Q 前） | B6: =b_rev26 -> 39.016 | C6: =PL!D78 -> 38.204039 | D6: =C6/B6-1 -> -0.020810984 | E6: =PL!D116 -> 38.204039 | F6: =E6/B6-1 -> -0.020810984 | G6: =PL!D154 -> 38.204039 | H6: =G6/B6-1 -> -0.020810984 | I6: 凱基 2026-08-07 | J6: 凱基 3Q 估 102.7 億，實際 97.9 億
A7: FY2026 EPS vs 共識（stockanalysis） | B7: =c_eps26 -> 56.18 | C7: =PL!D94 -> 52.900821 | D7: =C7/B7-1 -> -0.058369148 | E7: =PL!D132 -> 52.900821 | F7: =E7/B7-1 -> -0.058369148 | G7: =PL!D170 -> 52.900821 | H7: =G7/B7-1 -> -0.058369148 | I7: stockanalysis（2026-10-19） | J7: 3Q26 財報前
A8: FY2026 EPS vs 凱基（08-07） | B8: =b_eps26 -> 55.69 | C8: =PL!D94 -> 52.900821 | D8: =C8/B8-1 -> -0.050084014 | E8: =PL!D132 -> 52.900821 | F8: =E8/B8-1 -> -0.050084014 | G8: =PL!D170 -> 52.900821 | H8: =G8/B8-1 -> -0.050084014 | I8: 凱基 2026-08-07
A9: FY2026 EPS vs 美系券商（09-18） | B9: =u_eps26 -> 58.8 | C9: =PL!D94 -> 52.900821 | D9: =C9/B9-1 -> -0.10032617 | E9: =PL!D132 -> 52.900821 | F9: =E9/B9-1 -> -0.10032617 | G9: =PL!D170 -> 52.900821 | H9: =G9/B9-1 -> -0.10032617 | I9: 經濟日報 2026-09-18
A10: FY2027 營收 vs 共識（stockanalysis） | B10: =c_rev27 -> 49.1 | C10: =PL!E78 -> 76.49084 | D10: =C10/B10-1 -> 0.55785825 | E10: =PL!E116 -> 64.057515 | F10: =E10/B10-1 -> 0.3046337 | G10: =PL!E154 -> 50.070024 | H10: =G10/B10-1 -> 0.019756087 | I10: stockanalysis（2026-10-19）
A11: FY2027 營收 vs 凱基（08-07） | B11: =b_rev27 -> 50.486 | C11: =PL!E78 -> 76.49084 | D11: =C11/B11-1 -> 0.51509012 | E11: =PL!E116 -> 64.057515 | F11: =E11/B11-1 -> 0.26881739 | G11: =PL!E154 -> 50.070024 | H11: =G11/B11-1 -> -0.0082394355 | I11: 凱基 2026-08-07
A12: FY2027 EPS vs 共識（stockanalysis） | B12: =c_eps27 -> 77.97 | C12: =PL!E94 -> 124.89724 | D12: =C12/B12-1 -> 0.60186272 | E12: =PL!E132 -> 101.64468 | F12: =E12/B12-1 -> 0.30363835 | G12: =PL!E170 -> 75.485559 | H12: =G12/B12-1 -> -0.031864068 | I12: stockanalysis（2026-10-19）
A13: FY2027 EPS vs 凱基（08-07） | B13: =b_eps27 -> 81.55 | C13: =PL!E94 -> 124.89724 | D13: =C13/B13-1 -> 0.53154183 | E13: =PL!E132 -> 101.64468 | F13: =E13/B13-1 -> 0.24640934 | G13: =PL!E170 -> 75.485559 | H13: =G13/B13-1 -> -0.074364701 | I13: 凱基 2026-08-07
A14: FY2027 EPS vs 美系券商（09-18） | B14: =u_eps27 -> 89 | C14: =PL!E94 -> 124.89724 | D14: =C14/B14-1 -> 0.40333973 | E14: =PL!E132 -> 101.64468 | F14: =E14/B14-1 -> 0.14207508 | G14: =PL!E170 -> 75.485559 | H14: =G14/B14-1 -> -0.15184766 | I14: 經濟日報 2026-09-18
A15: FY2028 EPS vs 美系券商（09-18） | B15: =u_eps28 -> 110 | C15: =PL!F94 -> 188.49224 | D15: =C15/B15-1 -> 0.71356584 | E15: =PL!F132 -> 117.84752 | F15: =E15/B15-1 -> 0.071341126 | G15: =PL!F170 -> 61.336336 | H15: =G15/B15-1 -> -0.44239694 | I15: 經濟日報 2026-09-18 | J15: FY2028 共識：未找到
A16: B. 液冷結構與兩家份額合計（機制檢查）
A17: FY2027 液冷 ÷ 營收 vs 凱基（72%） | B17: =b_lc27 -> 0.72 | C17: =PL!E80 -> 0.80596018 | D17: =C17-B17 -> 0.085960178 | E17: =PL!E118 -> 0.76829777 | F17: =E17-B17 -> 0.04829777 | G17: =PL!E156 -> 0.70356976 | H17: =G17-B17 -> -0.016430236 | I17: 凱基 2026-08-07
A18: FY2026 雙鴻有效份額（本模型市場口徑） | C18: =PL!D70 -> 0.15870078 | E18: =PL!D108 -> 0.15870078 | G18: =PL!D146 -> 0.15870078 | I18: — | J18: 份額第二來源：未找到
A19: CY2026 兩家有效份額合計（奇鋐＋雙鴻） | C19: =avsh_26+PL!D72 -> 0.65762842 | E19: =avsh_26+PL!D110 -> 0.65762842 | G19: =avsh_26+PL!D148 -> 0.65762842 | I19: 奇鋐模型 Units（唯讀）＋本模型 | J19: 奇鋐三情境份額相同（只讀其值）；兩家分子都含 CDU 等機架外產品，合計偏高估冷板份額。超過八成應視為不合理
A20: CY2027 兩家有效份額合計（奇鋐＋雙鴻） | C20: =avsh_27+PL!E72 -> 0.64061707 | E20: =avsh_27+PL!E110 -> 0.624747 | G20: =avsh_27+PL!E148 -> 0.60887692 | I20: 奇鋐模型 Units（唯讀）＋本模型 | J20: —
A21: CY2028 兩家有效份額合計（奇鋐＋雙鴻） | C21: =avsh_28+PL!F72 -> 0.61567069 | E21: =avsh_28+PL!F110 -> 0.59186558 | G21: =avsh_28+PL!F148 -> 0.56806046 | I21: 奇鋐模型 Units（唯讀）＋本模型 | J21: —
A22: CY2029 兩家有效份額合計（奇鋐＋雙鴻） | C22: =avsh_29+PL!G72 -> 0.59072431 | E22: =avsh_29+PL!G110 -> 0.55898415 | G22: =avsh_29+PL!G148 -> 0.53517904 | I22: 奇鋐模型 Units（唯讀）＋本模型 | J22: —
A23: FY2027 每 GW 雙鴻液冷營收（US$M） | C23: =PL!E81 -> 46.258522 | E23: =PL!E119 -> 36.929072 | G23: =PL!E157 -> 26.433441 | I23: —
A24: C. 校準
A25: 其他營收毛利率（Derived） | C25: =PL!D83 -> 0.26015649 | E25: =PL!D121 -> 0.26015649 | G25: =PL!D159 -> 0.26015649 | I25: FY2026 錨點 | J25: 液冷毛利率＝此值＋d_lc
A26: FY2027 毛利率 vs FY2026（百分點） | B26: =a26_gp/a26_rev -> 0.29015649 | C26: =PL!E85 -> 0.30045449 | D26: =C26-B26 -> 0.010298009 | E26: =PL!E123 -> 0.29857137 | F26: =E26-B26 -> 0.0084148885 | G26: =PL!E161 -> 0.29533497 | H26: =G26-B26 -> 0.0051784882 | I26: 錨點 | J26: 液冷占比上升使毛利率上升
A27: 4Q26 EPS（模型） | C27: =Q!E15 -> 15.972929 | E27: =Q!E15 -> 15.972929 | G27: =Q!E15 -> 15.972929 | I27: — | J27: 凱基 08-07 估 17.83（以 4Q 營收 115.0 億為基礎）
A28: D. 目標價對帳（模型欄為情境加權值，非情境 A）
A29: 12 個月後的前瞻 EPS（情境加權）vs 共識前瞻 EPS | B29: =cons_feps -> 74.338333 | C29: =Val!B34 -> 123.68036 | D29: =C29/B29-1 -> 0.66374937 | I29: stockanalysis 共識（期間不同） | J29: 共識只作對帳，不作校準
A30: 目標價（DCF 與 Comparable 加權）vs 市場共識目標價 | B30: =cons_tp -> 1523 | C30: =Val!B39 -> 2290.2186 | D30: =C30/B30-1 -> 0.50375483 | I30: stockanalysis（2026-10-19） | J30: 共識只作對帳，不作校準
A31: Comparable 目標價 vs 市場共識目標價 | B31: =cons_tp -> 1523 | C31: =Val!B35 -> 3558.9022 | D31: =C31/B31-1 -> 1.336771 | I31: 同上 | J31: 共識只作對帳，不作校準
A32: E. 預留
A33: R4 產業部署路徑（markets/deploy_path/，尚未建立）：上線後以部署路徑取代「AI IT 資本支出 ÷ 每 GW IT 資本支出」 | J33: 預留列：本版無數值

Sheet Sens
A1: Sens — 一次動一個輸入（情境 B＝基準輸入；有效份額、其他營收毛利率在每個案例內依 FY2026 錨點重算，FY2026 恆等於錨點）：對 FY2027、FY2028 的營收、液冷營收、毛利率與 EPS 的影響。每個案例是一個完整推導區塊（本頁下方）
A3: 案例 | B3: 設定 | C3: FY2027 營收 | D3: FY2027 液冷營收 | E3: FY2027 毛利率 | F3: FY2027 EPS | G3: FY2027 EPS 相對基準 | H3: FY2028 營收 | I3: FY2028 液冷營收 | J3: FY2028 毛利率 | K3: FY2028 EPS | L3: FY2028 EPS 相對基準
A4: 基準（情境 B） | B4: PL 區塊 B | C4: =PL!E116 -> 64.057515 | D4: =PL!E111 -> 49.215246 | E4: =PL!E123 -> 0.29857137 | F4: =PL!E132 -> 101.64468 | G4: =F4/F$4-1 -> 0 | H4: =PL!F116 -> 72.29659 | I4: =PL!F111 -> 57.708378 | J4: =PL!F123 -> 0.30006734 | K4: =PL!F132 -> 117.84752 | L4: =K4/K$4-1 -> 0
A5: 份額流失（低） | B5: 份額相對值 2027 0.85、2028 0.75、2029 0.70（＝情境 C 的份額） | C5: =E68 -> 58.876963 | D5: =E63 -> 44.034694 | E5: =E75 -> 0.29755201 | F5: =E84 -> 91.956118 | G5: =F5/F$4-1 -> -0.095317965 | H5: =F68 -> 62.678527 | I5: =F63 -> 48.090315 | J5: =F75 -> 0.29851916 | K5: =F84 -> 99.445018 | L5: =K5/K$4-1 -> -0.15615522
A6: 份額上升（高） | B6: 份額相對值 1.05（＝情境 A 的份額） | C6: =E106 -> 69.238067 | D6: =E101 -> 54.395798 | E6: =E113 -> 0.2994382 | F6: =E122 -> 111.33325 | G6: =F6/F$4-1 -> 0.095317965 | H6: =F106 -> 81.914653 | I6: =F101 -> 67.326441 | J6: =F113 -> 0.30125197 | K6: =F122 -> 136.32638 | L6: =K6/K$4-1 -> 0.15680307
A7: 每架液冷內容 低 | B7: 內容調整 1.0（只有橋接表的機架內液冷） | C7: =E144 -> 52.70015 | D7: =E139 -> 37.857881 | E7: =E151 -> 0.29607468 | F7: =E160 -> 80.404368 | G7: =F7/F$4-1 -> -0.20896631 | H7: =F144 -> 55.808482 | I7: =F139 -> 41.22027 | J7: =F151 -> 0.2970866 | K7: =F160 -> 86.496762 | L7: =K7/K$4-1 -> -0.26602817
A8: 每架液冷內容 高 | B8: 內容調整 2027 1.6、2028–29 1.8 | C8: =E182 -> 75.414879 | D8: =E177 -> 60.57261 | E8: =E189 -> 0.30031607 | F8: =E198 -> 122.885 | G8: =F8/F$4-1 -> 0.20896631 | H8: =F182 -> 88.784698 | I8: =F177 -> 74.196486 | J8: =F189 -> 0.30194099 | K8: =F198 -> 149.36536 | L8: =K8/K$4-1 -> 0.26744586
A9: 液冷滲透率 低 | B9: 2026 45%、2027 60%、2028 70%、2029 75%（FY2026 份額反向調整） | C9: =E220 -> 62.963843 | D9: =E215 -> 48.121574 | E9: =E227 -> 0.29837014 | F9: =E236 -> 99.599318 | G9: =F9/F$4-1 -> -0.020122681 | H9: =F220 -> 72.673769 | I9: =F215 -> 58.085557 | J9: =F227 -> 0.30011971 | K9: =F236 -> 118.65571 | L9: =K9/K$4-1 -> 0.0068579173
A10: 液冷滲透率 高 | B10: 2026 65%、2027 85%、2028–29 95% | C10: =E258 -> 62.038428 | D10: =E253 -> 47.196159 | E10: =E265 -> 0.29819433 | F10: =E274 -> 97.868626 | G10: =F10/F$4-1 -> -0.037149566 | H10: =F258 -> 69.163103 | I10: =F253 -> 54.574891 | J10: =F265 -> 0.29961025 | K10: =F274 -> 111.86473 | L10: =K10/K$4-1 -> -0.050767212
A11: AI 部署 ×0.8 | B11: FY2027 起 AI IT 資本支出 ×0.8 | C11: =E296 -> 54.214466 | D11: =E291 -> 39.372197 | E11: =E303 -> 0.29646801 | F11: =E312 -> 83.23641 | G11: =F11/F$4-1 -> -0.18110413 | H11: =F296 -> 60.754914 | I11: =F291 -> 46.166702 | J11: =F303 -> 0.2981507 | K11: =F312 -> 95.971923 | L11: =K11/K$4-1 -> -0.18562631
A12: AI 部署 ×1.2 | B12: ×1.2 | C12: =E334 -> 73.900564 | D12: =E329 -> 59.058295 | E12: =E341 -> 0.30011443 | F12: =E350 -> 120.05295 | G12: =F12/F$4-1 -> 0.18110413 | H12: =F334 -> 83.838265 | I12: =F329 -> 69.250053 | J12: =F341 -> 0.30145627 | K12: =F350 -> 139.74006 | L12: =K12/K$4-1 -> 0.18576998
A13: 伺服器氣冷 低 | B13: 2027–29 每年 −20% | C13: =E372 -> 63.25523 | D13: =E367 -> 49.215246 | E13: =E379 -> 0.2990586 | F13: =E388 -> 100.46319 | G13: =F13/F$4-1 -> -0.011623744 | H13: =F372 -> 70.892591 | I13: =F367 -> 57.708378 | J13: =F379 -> 0.30085776 | K13: =F388 -> 115.71724 | L13: =K13/K$4-1 -> -0.018076648
A14: 伺服器氣冷 高 | B14: 2027–29 每年 +5% | C14: =E410 -> 64.592371 | D14: =E405 -> 49.215246 | E14: =E417 -> 0.29825328 | F14: =E426 -> 102.43234 | G14: =F14/F$4-1 -> 0.0077491629 | H14: =F410 -> 73.366303 | I14: =F405 -> 57.708378 | J14: =F417 -> 0.29948542 | K14: =F426 -> 119.47689 | L14: =K14/K$4-1 -> 0.013826028
A15: 筆電與其他 低 | B15: 筆電與桌機 −10／−8／−8%、電競顯卡與其他 −15／−10／−10% | C15: =E448 -> 63.026006 | D15: =E443 -> 49.215246 | E15: =E455 -> 0.29920009 | F15: =E464 -> 100.12562 | G15: =F15/F$4-1 -> -0.014944814 | H15: =F448 -> 70.495269 | I15: =F443 -> 57.708378 | J15: =F455 -> 0.30108716 | K15: =F464 -> 115.11482 | L15: =K15/K$4-1 -> -0.023188511
A16: 筆電與其他 高 | B16: 筆電與桌機 +5%、電競顯卡與其他 +8% | C16: =E486 -> 64.852159 | D16: =E481 -> 49.215246 | E16: =E493 -> 0.29810067 | F16: =E502 -> 102.81492 | G16: =F16/F$4-1 -> 0.011513042 | H16: =F486 -> 73.755182 | I16: =F481 -> 57.708378 | J16: =F493 -> 0.29927806 | K16: =F502 -> 120.06497 | L16: =K16/K$4-1 -> 0.018816201
A17: 液冷毛利率差距 2pt | B17: 液冷毛利率只高 2 個百分點 | C17: =E524 -> 64.057515 | D17: =E519 -> 49.215246 | E17: =E531 -> 0.29352244 | F17: =E540 -> 99.07334 | G17: =F17/F$4-1 -> -0.025297357 | H17: =F524 -> 72.29659 | I17: =F519 -> 57.708378 | J17: =F531 -> 0.29412083 | K17: =F540 -> 114.42954 | L17: =K17/K$4-1 -> -0.029003468
A18: 液冷毛利率差距 8pt | B18: 高 8 個百分點 | C18: =E562 -> 64.057515 | D18: =E557 -> 49.215246 | E18: =E569 -> 0.30362031 | F18: =E578 -> 104.21602 | G18: =F18/F$4-1 -> 0.025297357 | H18: =F562 -> 72.29659 | I18: =F557 -> 57.708378 | J18: =F569 -> 0.30601386 | K18: =F578 -> 121.26551 | L18: =K18/K$4-1 -> 0.029003468
A19: 營業費用率 +2pt | B19: 營業費用額外 +2% × 營收 | C19: =E600 -> 64.057515 | D19: =E595 -> 49.215246 | E19: =E607 -> 0.29857137 | F19: =E616 -> 91.458998 | G19: =F19/F$4-1 -> -0.10020872 | H19: =F600 -> 72.29659 | I19: =F595 -> 57.708378 | J19: =F607 -> 0.30006734 | K19: =F616 -> 106.35176 | L19: =K19/K$4-1 -> -0.097547793
A20: 淨利 ÷ 稅前 0.72 | B20: 基準 0.74 | C20: =E638 -> 64.057515 | D20: =E633 -> 49.215246 | E20: =E645 -> 0.29857137 | F20: =E654 -> 98.897528 | G20: =F20/F$4-1 -> -0.027027027 | H20: =F638 -> 72.29659 | I20: =F633 -> 57.708378 | J20: =F645 -> 0.30006734 | K20: =F654 -> 114.66246 | L20: =K20/K$4-1 -> -0.027027027
A21: 淨利 ÷ 稅前 0.78 | C21: =E676 -> 64.057515 | D21: =E671 -> 49.215246 | E21: =E683 -> 0.29857137 | F21: =E692 -> 107.13899 | G21: =F21/F$4-1 -> 0.054054054 | H21: =F676 -> 72.29659 | I21: =F671 -> 57.708378 | J21: =F683 -> 0.30006734 | K21: =F692 -> 124.21766 | L21: =K21/K$4-1 -> 0.054054054
A22: 2026 液冷占比 55%（讀法） | B22: FY2026 液冷＝營收 × 55%（1H26 實績比例）；份額分子變小、氣冷變大 | C22: =E714 -> 61.770936 | D22: =E709 -> 45.113975 | E22: =E721 -> 0.29917364 | F22: =E730 -> 97.874753 | G22: =F22/F$4-1 -> -0.03708929 | H22: =F714 -> 69.211516 | I22: =F709 -> 52.899346 | J22: =F721 -> 0.3008722 | K22: =F730 -> 112.66678 | L22: =K22/K$4-1 -> -0.04396139
A23: 2026 液冷占比 63%（讀法） | B23: FY2026 液冷＝營收 × 63% | C23: =E752 -> 65.429462 | D23: =E747 -> 51.676008 | E23: =E759 -> 0.29814635 | F23: =E768 -> 103.86301 | G23: =F23/F$4-1 -> 0.021824332 | H23: =F752 -> 74.147634 | I23: =F747 -> 60.593797 | J23: =F759 -> 0.29951672 | K23: =F768 -> 120.89928 | L23: =K23/K$4-1 -> 0.025895837
A24: 情境 A（全部） | B24: 顆數係數 A＋液冷滲透率、份額相對值高值 | C24: =PL!E78 -> 76.49084 | D24: =PL!E73 -> 61.648571 | E24: =PL!E85 -> 0.30045449 | F24: =PL!E94 -> 124.89724 | G24: =F24/F$4-1 -> 0.22876312 | H24: =PL!F78 -> 108.64721 | I24: =PL!F73 -> 94.058998 | J24: =PL!F85 -> 0.30344292 | K24: =PL!F94 -> 188.49224 | L24: =K24/K$4-1 -> 0.59945866
A25: 情境 C（全部） | B25: 顆數係數 C＋液冷滲透率、份額相對值低值 | C25: =PL!E154 -> 50.070024 | D25: =PL!E149 -> 35.227755 | E25: =PL!E161 -> 0.29533497 | F25: =PL!E170 -> 75.485559 | G25: =F25/F$4-1 -> -0.25735851 | H25: =PL!F154 -> 44.291054 | I25: =PL!F149 -> 29.702841 | J25: =PL!F161 -> 0.29368791 | K25: =PL!F170 -> 61.336336 | L25: =K25/K$4-1 -> -0.479528
A27: 讀法：基準為情境 B。每個案例的 FY2026 有效份額與其他營收毛利率依該案例重算，所以 FY2026 恆等於錨點。「液冷滲透率」案例的 FY2026 份額會反向調整（滲透率低 → 份額高），只影響 FY2027 起的成長路徑；情境 A／C 的滲透率只在 FY2027 起取高／低值，所以影響較大。
A29: 目標價參數（只改 DCF 參數；PL 收斂法的 fade_g 不隨 tp_g 變動）
A30: 案例 | B30: 設定 | C30: DCF 目標價 | D30: Comparable 目標價（相對倍數調整後） | E30: 加權目標價 | F30: 相對基準
A31: 基準 | B31: r 10%、g 4%、DCF 權重 0.5 | C31: =(tp_wA*MAX(0,Val!B8*(1-MIN(tp_g/tp_roe,0.8))/(1+tp_r)^1+Val!B9*(1-MIN(tp_g/tp_roe,0.8))/(1+tp_r)^2+Val!B10*(1-MIN(tp_g/tp_roe,0.8))/(1+tp_r)^3+Val!B11*(1-MIN(tp_g/tp_roe,0.8))/(1+tp_r)^4+Val!B12*(1-MIN(tp_g/tp_roe,0.8))/(1+tp_r)^5+Val!B13*(1-MIN(tp_g/tp_roe,0.8))/(1+tp_r)^6+Val!B13*(1-MIN(tp_g/tp_roe,0.8))*(1+tp_g)/(tp_r-tp_g)/(1+tp_r)^6)+tp_wB*MAX(0,Val!C8*(1-MIN(tp_g/tp_roe,0.8))/(1+tp_r)^1+Val!C9*(1-MIN(tp_g/tp_roe,0.8))/(1+tp_r)^2+Val!C10*(1-MIN(tp_g/tp_roe,0.8))/(1+tp_r)^3+Val!C11*(1-MIN(tp_g/tp_roe,0.8))/(1+tp_r)^4+Val!C12*(1-MIN(tp_g/tp_roe,0.8))/(1+tp_r)^5+Val!C13*(1-MIN(tp_g/tp_roe,0.8))/(1+tp_r)^6+Val!C13*(1-MIN(tp_g/tp_roe,0.8))*(1+tp_g)/(tp_r-tp_g)/(1+tp_r)^6)+tp_wC*MAX(0,Val!D8*(1-MIN(tp_g/tp_roe,0.8))/(1+tp_r)^1+Val!D9*(1-MIN(tp_g/tp_roe,0.8))/(1+tp_r)^2+Val!D10*(1-MIN(tp_g/tp_roe,0.8))/(1+tp_r)^3+Val!D11*(1-MIN(tp_g/tp_roe,0.8))/(1+tp_r)^4+Val!D12*(1-MIN(tp_g/tp_roe,0.8))/(1+tp_r)^5+Val!D13*(1-MIN(tp_g/tp_roe,0.8))/(1+tp_r)^6+Val!D13*(1-MIN(tp_g/tp_roe,0.8))*(1+tp_g)/(tp_r-tp_g)/(1+tp_r)^6))*(1+tp_r) -> 1978.6451 | D31: =tp_comp_adj -> 2601.7921 | E31: =tp_w_dcf*C31+(1-tp_w_dcf)*D31 -> 2290.2186 | F31: =E31/E$31-1 -> 0
A32: 折現率 +1pt | B32: r 11% | C32: =(tp_wA*MAX(0,Val!B8*(1-MIN(tp_g/tp_roe,0.8))/(1+(tp_r+0.01))^1+Val!B9*(1-MIN(tp_g/tp_roe,0.8))/(1+(tp_r+0.01))^2+Val!B10*(1-MIN(tp_g/tp_roe,0.8))/(1+(tp_r+0.01))^3+Val!B11*(1-MIN(tp_g/tp_roe,0.8))/(1+(tp_r+0.01))^4+Val!B12*(1-MIN(tp_g/tp_roe,0.8))/(1+(tp_r+0.01))^5+Val!B13*(1-MIN(tp_g/tp_roe,0.8))/(1+(tp_r+0.01))^6+Val!B13*(1-MIN(tp_g/tp_roe,0.8))*(1+tp_g)/((tp_r+0.01)-tp_g)/(1+(tp_r+0.01))^6)+tp_wB*MAX(0,Val!C8*(1-MIN(tp_g/tp_roe,0.8))/(1+(tp_r+0.01))^1+Val!C9*(1-MIN(tp_g/tp_roe,0.8))/(1+(tp_r+0.01))^2+Val!C10*(1-MIN(tp_g/tp_roe,0.8))/(1+(tp_r+0.01))^3+Val!C11*(1-MIN(tp_g/tp_roe,0.8))/(1+(tp_r+0.01))^4+Val!C12*(1-MIN(tp_g/tp_roe,0.8))/(1+(tp_r+0.01))^5+Val!C13*(1-MIN(tp_g/tp_roe,0.8))/(1+(tp_r+0.01))^6+Val!C13*(1-MIN(tp_g/tp_roe,0.8))*(1+tp_g)/((tp_r+0.01)-tp_g)/(1+(tp_r+0.01))^6)+tp_wC*MAX(0,Val!D8*(1-MIN(tp_g/tp_roe,0.8))/(1+(tp_r+0.01))^1+Val!D9*(1-MIN(tp_g/tp_roe,0.8))/(1+(tp_r+0.01))^2+Val!D10*(1-MIN(tp_g/tp_roe,0.8))/(1+(tp_r+0.01))^3+Val!D11*(1-MIN(tp_g/tp_roe,0.8))/(1+(tp_r+0.01))^4+Val!D12*(1-MIN(tp_g/tp_roe,0.8))/(1+(tp_r+0.01))^5+Val!D13*(1-MIN(tp_g/tp_roe,0.8))/(1+(tp_r+0.01))^6+Val!D13*(1-MIN(tp_g/tp_roe,0.8))*(1+tp_g)/((tp_r+0.01)-tp_g)/(1+(tp_r+0.01))^6))*(1+(tp_r+0.01)) -> 1708.9279 | D32: =tp_comp_adj -> 2601.7921 | E32: =tp_w_dcf*C32+(1-tp_w_dcf)*D32 -> 2155.36 | F32: =E32/E$31-1 -> -0.058884598
A33: 折現率 −1pt | B33: r 9% | C33: =(tp_wA*MAX(0,Val!B8*(1-MIN(tp_g/tp_roe,0.8))/(1+(tp_r-0.01))^1+Val!B9*(1-MIN(tp_g/tp_roe,0.8))/(1+(tp_r-0.01))^2+Val!B10*(1-MIN(tp_g/tp_roe,0.8))/(1+(tp_r-0.01))^3+Val!B11*(1-MIN(tp_g/tp_roe,0.8))/(1+(tp_r-0.01))^4+Val!B12*(1-MIN(tp_g/tp_roe,0.8))/(1+(tp_r-0.01))^5+Val!B13*(1-MIN(tp_g/tp_roe,0.8))/(1+(tp_r-0.01))^6+Val!B13*(1-MIN(tp_g/tp_roe,0.8))*(1+tp_g)/((tp_r-0.01)-tp_g)/(1+(tp_r-0.01))^6)+tp_wB*MAX(0,Val!C8*(1-MIN(tp_g/tp_roe,0.8))/(1+(tp_r-0.01))^1+Val!C9*(1-MIN(tp_g/tp_roe,0.8))/(1+(tp_r-0.01))^2+Val!C10*(1-MIN(tp_g/tp_roe,0.8))/(1+(tp_r-0.01))^3+Val!C11*(1-MIN(tp_g/tp_roe,0.8))/(1+(tp_r-0.01))^4+Val!C12*(1-MIN(tp_g/tp_roe,0.8))/(1+(tp_r-0.01))^5+Val!C13*(1-MIN(tp_g/tp_roe,0.8))/(1+(tp_r-0.01))^6+Val!C13*(1-MIN(tp_g/tp_roe,0.8))*(1+tp_g)/((tp_r-0.01)-tp_g)/(1+(tp_r-0.01))^6)+tp_wC*MAX(0,Val!D8*(1-MIN(tp_g/tp_roe,0.8))/(1+(tp_r-0.01))^1+Val!D9*(1-MIN(tp_g/tp_roe,0.8))/(1+(tp_r-0.01))^2+Val!D10*(1-MIN(tp_g/tp_roe,0.8))/(1+(tp_r-0.01))^3+Val!D11*(1-MIN(tp_g/tp_roe,0.8))/(1+(tp_r-0.01))^4+Val!D12*(1-MIN(tp_g/tp_roe,0.8))/(1+(tp_r-0.01))^5+Val!D13*(1-MIN(tp_g/tp_roe,0.8))/(1+(tp_r-0.01))^6+Val!D13*(1-MIN(tp_g/tp_roe,0.8))*(1+tp_g)/((tp_r-0.01)-tp_g)/(1+(tp_r-0.01))^6))*(1+(tp_r-0.01)) -> 2356.1379 | D33: =tp_comp_adj -> 2601.7921 | E33: =tp_w_dcf*C33+(1-tp_w_dcf)*D33 -> 2478.965 | F33: =E33/E$31-1 -> 0.082414139
A34: 長期成長 +1pt | B34: g 5% | C34: =(tp_wA*MAX(0,Val!B8*(1-MIN((tp_g+0.01)/tp_roe,0.8))/(1+tp_r)^1+Val!B9*(1-MIN((tp_g+0.01)/tp_roe,0.8))/(1+tp_r)^2+Val!B10*(1-MIN((tp_g+0.01)/tp_roe,0.8))/(1+tp_r)^3+Val!B11*(1-MIN((tp_g+0.01)/tp_roe,0.8))/(1+tp_r)^4+Val!B12*(1-MIN((tp_g+0.01)/tp_roe,0.8))/(1+tp_r)^5+Val!B13*(1-MIN((tp_g+0.01)/tp_roe,0.8))/(1+tp_r)^6+Val!B13*(1-MIN((tp_g+0.01)/tp_roe,0.8))*(1+(tp_g+0.01))/(tp_r-(tp_g+0.01))/(1+tp_r)^6)+tp_wB*MAX(0,Val!C8*(1-MIN((tp_g+0.01)/tp_roe,0.8))/(1+tp_r)^1+Val!C9*(1-MIN((tp_g+0.01)/tp_roe,0.8))/(1+tp_r)^2+Val!C10*(1-MIN((tp_g+0.01)/tp_roe,0.8))/(1+tp_r)^3+Val!C11*(1-MIN((tp_g+0.01)/tp_roe,0.8))/(1+tp_r)^4+Val!C12*(1-MIN((tp_g+0.01)/tp_roe,0.8))/(1+tp_r)^5+Val!C13*(1-MIN((tp_g+0.01)/tp_roe,0.8))/(1+tp_r)^6+Val!C13*(1-MIN((tp_g+0.01)/tp_roe,0.8))*(1+(tp_g+0.01))/(tp_r-(tp_g+0.01))/(1+tp_r)^6)+tp_wC*MAX(0,Val!D8*(1-MIN((tp_g+0.01)/tp_roe,0.8))/(1+tp_r)^1+Val!D9*(1-MIN((tp_g+0.01)/tp_roe,0.8))/(1+tp_r)^2+Val!D10*(1-MIN((tp_g+0.01)/tp_roe,0.8))/(1+tp_r)^3+Val!D11*(1-MIN((tp_g+0.01)/tp_roe,0.8))/(1+tp_r)^4+Val!D12*(1-MIN((tp_g+0.01)/tp_roe,0.8))/(1+tp_r)^5+Val!D13*(1-MIN((tp_g+0.01)/tp_roe,0.8))/(1+tp_r)^6+Val!D13*(1-MIN((tp_g+0.01)/tp_roe,0.8))*(1+(tp_g+0.01))/(tp_r-(tp_g+0.01))/(1+tp_r)^6))*(1+tp_r) -> 2160.8905 | D34: =tp_comp_adj -> 2601.7921 | E34: =tp_w_dcf*C34+(1-tp_w_dcf)*D34 -> 2381.3413 | F34: =E34/E$31-1 -> 0.039787768
A35: 長期成長 −1pt | B35: g 3% | C35: =(tp_wA*MAX(0,Val!B8*(1-MIN((tp_g-0.01)/tp_roe,0.8))/(1+tp_r)^1+Val!B9*(1-MIN((tp_g-0.01)/tp_roe,0.8))/(1+tp_r)^2+Val!B10*(1-MIN((tp_g-0.01)/tp_roe,0.8))/(1+tp_r)^3+Val!B11*(1-MIN((tp_g-0.01)/tp_roe,0.8))/(1+tp_r)^4+Val!B12*(1-MIN((tp_g-0.01)/tp_roe,0.8))/(1+tp_r)^5+Val!B13*(1-MIN((tp_g-0.01)/tp_roe,0.8))/(1+tp_r)^6+Val!B13*(1-MIN((tp_g-0.01)/tp_roe,0.8))*(1+(tp_g-0.01))/(tp_r-(tp_g-0.01))/(1+tp_r)^6)+tp_wB*MAX(0,Val!C8*(1-MIN((tp_g-0.01)/tp_roe,0.8))/(1+tp_r)^1+Val!C9*(1-MIN((tp_g-0.01)/tp_roe,0.8))/(1+tp_r)^2+Val!C10*(1-MIN((tp_g-0.01)/tp_roe,0.8))/(1+tp_r)^3+Val!C11*(1-MIN((tp_g-0.01)/tp_roe,0.8))/(1+tp_r)^4+Val!C12*(1-MIN((tp_g-0.01)/tp_roe,0.8))/(1+tp_r)^5+Val!C13*(1-MIN((tp_g-0.01)/tp_roe,0.8))/(1+tp_r)^6+Val!C13*(1-MIN((tp_g-0.01)/tp_roe,0.8))*(1+(tp_g-0.01))/(tp_r-(tp_g-0.01))/(1+tp_r)^6)+tp_wC*MAX(0,Val!D8*(1-MIN((tp_g-0.01)/tp_roe,0.8))/(1+tp_r)^1+Val!D9*(1-MIN((tp_g-0.01)/tp_roe,0.8))/(1+tp_r)^2+Val!D10*(1-MIN((tp_g-0.01)/tp_roe,0.8))/(1+tp_r)^3+Val!D11*(1-MIN((tp_g-0.01)/tp_roe,0.8))/(1+tp_r)^4+Val!D12*(1-MIN((tp_g-0.01)/tp_roe,0.8))/(1+tp_r)^5+Val!D13*(1-MIN((tp_g-0.01)/tp_roe,0.8))/(1+tp_r)^6+Val!D13*(1-MIN((tp_g-0.01)/tp_roe,0.8))*(1+(tp_g-0.01))/(tp_r-(tp_g-0.01))/(1+tp_r)^6))*(1+tp_r) -> 1855.5127 | D35: =tp_comp_adj -> 2601.7921 | E35: =tp_w_dcf*C35+(1-tp_w_dcf)*D35 -> 2228.6524 | F35: =E35/E$31-1 -> -0.026882231
A36: DCF 權重 0.3 | C36: =(tp_wA*MAX(0,Val!B8*(1-MIN(tp_g/tp_roe,0.8))/(1+tp_r)^1+Val!B9*(1-MIN(tp_g/tp_roe,0.8))/(1+tp_r)^2+Val!B10*(1-MIN(tp_g/tp_roe,0.8))/(1+tp_r)^3+Val!B11*(1-MIN(tp_g/tp_roe,0.8))/(1+tp_r)^4+Val!B12*(1-MIN(tp_g/tp_roe,0.8))/(1+tp_r)^5+Val!B13*(1-MIN(tp_g/tp_roe,0.8))/(1+tp_r)^6+Val!B13*(1-MIN(tp_g/tp_roe,0.8))*(1+tp_g)/(tp_r-tp_g)/(1+tp_r)^6)+tp_wB*MAX(0,Val!C8*(1-MIN(tp_g/tp_roe,0.8))/(1+tp_r)^1+Val!C9*(1-MIN(tp_g/tp_roe,0.8))/(1+tp_r)^2+Val!C10*(1-MIN(tp_g/tp_roe,0.8))/(1+tp_r)^3+Val!C11*(1-MIN(tp_g/tp_roe,0.8))/(1+tp_r)^4+Val!C12*(1-MIN(tp_g/tp_roe,0.8))/(1+tp_r)^5+Val!C13*(1-MIN(tp_g/tp_roe,0.8))/(1+tp_r)^6+Val!C13*(1-MIN(tp_g/tp_roe,0.8))*(1+tp_g)/(tp_r-tp_g)/(1+tp_r)^6)+tp_wC*MAX(0,Val!D8*(1-MIN(tp_g/tp_roe,0.8))/(1+tp_r)^1+Val!D9*(1-MIN(tp_g/tp_roe,0.8))/(1+tp_r)^2+Val!D10*(1-MIN(tp_g/tp_roe,0.8))/(1+tp_r)^3+Val!D11*(1-MIN(tp_g/tp_roe,0.8))/(1+tp_r)^4+Val!D12*(1-MIN(tp_g/tp_roe,0.8))/(1+tp_r)^5+Val!D13*(1-MIN(tp_g/tp_roe,0.8))/(1+tp_r)^6+Val!D13*(1-MIN(tp_g/tp_roe,0.8))*(1+tp_g)/(tp_r-tp_g)/(1+tp_r)^6))*(1+tp_r) -> 1978.6451 | D36: =tp_comp_adj -> 2601.7921 | E36: =0.3*C36+(1-0.3)*D36 -> 2414.848 | F36: =E36/E$31-1 -> 0.054418122
A37: DCF 權重 0.7 | C37: =(tp_wA*MAX(0,Val!B8*(1-MIN(tp_g/tp_roe,0.8))/(1+tp_r)^1+Val!B9*(1-MIN(tp_g/tp_roe,0.8))/(1+tp_r)^2+Val!B10*(1-MIN(tp_g/tp_roe,0.8))/(1+tp_r)^3+Val!B11*(1-MIN(tp_g/tp_roe,0.8))/(1+tp_r)^4+Val!B12*(1-MIN(tp_g/tp_roe,0.8))/(1+tp_r)^5+Val!B13*(1-MIN(tp_g/tp_roe,0.8))/(1+tp_r)^6+Val!B13*(1-MIN(tp_g/tp_roe,0.8))*(1+tp_g)/(tp_r-tp_g)/(1+tp_r)^6)+tp_wB*MAX(0,Val!C8*(1-MIN(tp_g/tp_roe,0.8))/(1+tp_r)^1+Val!C9*(1-MIN(tp_g/tp_roe,0.8))/(1+tp_r)^2+Val!C10*(1-MIN(tp_g/tp_roe,0.8))/(1+tp_r)^3+Val!C11*(1-MIN(tp_g/tp_roe,0.8))/(1+tp_r)^4+Val!C12*(1-MIN(tp_g/tp_roe,0.8))/(1+tp_r)^5+Val!C13*(1-MIN(tp_g/tp_roe,0.8))/(1+tp_r)^6+Val!C13*(1-MIN(tp_g/tp_roe,0.8))*(1+tp_g)/(tp_r-tp_g)/(1+tp_r)^6)+tp_wC*MAX(0,Val!D8*(1-MIN(tp_g/tp_roe,0.8))/(1+tp_r)^1+Val!D9*(1-MIN(tp_g/tp_roe,0.8))/(1+tp_r)^2+Val!D10*(1-MIN(tp_g/tp_roe,0.8))/(1+tp_r)^3+Val!D11*(1-MIN(tp_g/tp_roe,0.8))/(1+tp_r)^4+Val!D12*(1-MIN(tp_g/tp_roe,0.8))/(1+tp_r)^5+Val!D13*(1-MIN(tp_g/tp_roe,0.8))/(1+tp_r)^6+Val!D13*(1-MIN(tp_g/tp_roe,0.8))*(1+tp_g)/(tp_r-tp_g)/(1+tp_r)^6))*(1+tp_r) -> 1978.6451 | D37: =tp_comp_adj -> 2601.7921 | E37: =0.7*C37+(1-0.7)*D37 -> 2165.5892 | F37: =E37/E$31-1 -> -0.054418122
A50: 案例區塊：份額流失（低）（情境 B）
A51: 項目 | B51: 單位 | C51: FY2025A | D51: FY2026（錨點） | E51: FY2027 | F51: FY2028 | G51: FY2029 | H51: 說明
A52: A. AI 部署與液冷市場（D 欄＝FY2026 校準年；E–G＝FY2027–FY2029）
A53: AI IT 資本支出 × 情境顆數係數 | B53: US$B | D53: =itc_26*1 -> 781.87292 | E53: =itc_27*1*1 -> 1565.35 | F53: =itc_28*um28_B*1 -> 1587.4111 | G53: =itc_29*um29_B*1 -> 1921.3317
A54: 每 GW IT 資本支出 | B54: US$B | D54: =itpg_gb*(1-vr26)+itpg_vr*vr26 -> 33.414032 | E54: =itpg_vr -> 37.586352 | F54: =itpg_vr -> 37.586352 | G54: =itpg_vr -> 37.586352
A55: 部署 GW（IT 電力） | B55: GW | D55: =D53/D54 -> 23.399538 | E55: =E53/E54 -> 41.646766 | F55: =F53/F54 -> 42.233711 | G55: =G53/G54 -> 51.117803
...

Sheet Sources
A1: 來源（公司原文經媒體與資料商轉載：法說簡報原檔未逐份抓取；券商與研調皆為 Interested-party）
A2: 公司（經時報）：FY2025 財報 2026-03-04（營收、毛利率、營業利益、淨利、EPS） | B2: https://wantrich.chinatimes.com/news/20260304900286-420101
A3: 公司（經時報）：股東會 2026-05-21（1Q26 淨利、EPS；2025 產品比重） | B3: https://wantrich.chinatimes.com/news/20260521900232-420101
A4: 資料商：玩股網各季損益（1Q25–2Q26 營收、毛利、營業利益、稅前、合併淨利） | B4: https://www.wantgoo.com/stock/3324/financial-statements/income-statement
A5: 資料商：HiStock 月營收（2025-01–2026-09）、各季 EPS、已發行股數、股價 | B5: https://histock.tw/stock/financial.aspx?no=3324
A6: 公司（經 TechNews）：9 月營收與前 9 月累計 2026-10-08 | B6: https://finance.technews.tw/2026/10/08/auras-3324-202609-financial-report/
A7: 公司（經 Win 投資）：2Q26 EPS、1H26 累計 EPS 2026-10-08 | B7: https://winvest.tw/News/Detail/95436
A8: 券商：凱基 2026-08-07（2Q26 實績、產品比重、液冷占比、3Q／4Q 與 2026–27 估計、目標價） | B8: https://www.kgi.com.hk/zh-cn/-/media/files/kgishk/research-reports/tw-reports/auras-technology-3324-tt20260807en.pdf
A9: 券商：美系券商（經濟日報 2026-09-18；EPS 2026–28） | B9: https://money.udn.com/money/story/5607/9762508
A10: 券商：花旗（經濟日報 2026-09-19；目標價 1,800、3Q／4Q 季增） | B10: https://money.udn.com/money/story/5607/9764013
A11: 資料商：stockanalysis forecast 頁（共識目標價、2026–27 營收與 EPS，2026-10-19） | B11: https://stockanalysis.com/quote/tpex/3324/forecast/
A12: 資料商：stockanalysis 個股頁（股數、Forward PE）與比率頁（年底 P/E、ROE） | B12: https://stockanalysis.com/quote/tpex/3324/financials/ratios/
A13: 資料商：Goodinfo 歷年年底收盤、EPS、淨利率、ROE（2017–2025；2016 年未取得） | B13: https://goodinfo.tw/tw/StockBzPerformance.asp?STOCK_ID=3324
... A15: 同業前瞻 P/E：stockanalysis 個股頁（3017、3653、VRT、2308） | B15: https://stockanalysis.com/quote/tpe/3017/
A16: 市場層：markets/network、markets/chip_bridge、tsmc 成品；奇鋐模型 In 頁（液冷內容、滲透率、份額相對值）與 Units 頁（份額）（本 repo，唯讀）
A17: 待補（人工）：3Q26 財報與法說（預計 11 月中）；法說簡報原檔；液冷、CDU、分歧管的金額拆分；雙鴻液冷份額；2016 年 EPS 與年底股價；前瞻 P/E 十年歷史（Bloomberg）；FY2028 共識（付費） | B17: 未找到
A18: SemiAnalysis | B18: 未使用
