Workbook

Sheet README
A1: 新易盛（300502.SZ）收支與估值模型 v0.2.3（AI 半導體 Project：網通次產業內複製——光模組） 2026-10-26
A2: 版本：v0.2.1（2026-10-25：補上檔空間級距、投資建議、重點觀察，數值不變）；v0.2（2026-10-25：三情境延伸到 FY2032、目標價＝DCF 與 Comparable 加權；v0.1 初版）。新易盛在 AI 光模組的份額在本模型 Units 頁建立，為本專案權威資料（規則第 13 條）；中際旭創份額讀 innolight 成品，兩家合計在 Units 頁檢查。
A3: 模型命題：新易盛的 AI 營收＝AI 可插拔光模組市場（本專案網通模型）× 新易盛份額 × 單價係數＋CPO 光學 × 新易盛 CPO 份額；其他營收另依成長率推。股價 261 元（10-23）自 9 月底下跌約三成、只約 10 倍模型 FY2027 EPS：市場定價像是 2027 年就是獲利高點，或份額與美國限制風險遠大於模型。
A4: 核心問題：以 15 倍看 FY2028，現價隱含的 EPS 約等於模型情境 C、比情境 A 低四成——要成立，份額（主要客戶轉單、1.6T 落後）、美國限制、單價三條路徑各要不利到什麼程度？
A6: 會計年度＝日曆年，FY(t)＝CY(t)，不平移。預測期 FY2027–FY2029 由驅動因子推導；FY2030–FY2032 為收斂法。口徑：中國會計準則；淨利＝歸母淨利；股數與 EPS 全部以 10 轉 4 後表示（FY2025 EPS 9.61 ÷ 1.4 重述）。
A8: 驅動因子 → 推導量（全部唯讀上游，不修改）
A9: AI 營收：markets/network 的 AI 可插拔光模組市場 × 情境顆數係數 × 新易盛有效份額（FY2026 以 1H26 實績＋2H26 假設校準）× 份額相對值（Assumed）× 單價係數（基準 1）＋ CPO 光學市場 × CPO 份額（Assumed）；乘匯率換成人民幣。
A10: 其他營收：FY2026 營收 × 5%（Assumed）× 成長率。毛利率：FY2027 起為輸入路徑（Assumed）。營業費用、減值與其他：彈性 phi 0.6（Analogy：中際旭創）。稅率 12%（Assumed）、歸母比例 0.998（Derived）。
A11: 校準：FY2026 ＝ 1H26 實績（營收 20.91、綜合毛利率 48.44%、歸母淨利 7.53）＋ 2H26（季增 20%、毛利率 48%、營業費用率 5%，Assumed）。公司不給指引；不用共識（只在 Recon 對帳）。3Q26 季報預計 10-30 公布，本版未納入。
A12: 估值：目標價（Val 第 0 節）＝0.5 × DCF（股東現金流＝EPS ×（1 − g／ROE），FY2027–32 明確期＋永續，r 10%、g 4%，情境權重 0.3／0.5／0.2）＋0.5 × Comparable（A 股光通訊同業前瞻 P/E 中位數 × 12 個月後前瞻 EPS）。舊法規則值情境加權保留參考；現價 ÷ FY2027、FY2028 EPS；市場隱含 FY2028 EPS（Val 第 4 節）；十年 P/E 規則值（2016–2025，兩個資料商）× FY2027 EPS；循環位置以本模型營收最高年判定。本版未做先驗，無 Andy 合理 P/E 對照。
A13: 標記：Verified、Interested-party、Analogy、Assumed、Derived。SemiAnalysis 未使用。公司原文經財經媒體轉載；客戶名稱、客戶集中度與 800G／1.6T 份額未找到第一手來源。
A15: 已知限制：(1) 份額相對值、CPO 份額、毛利率路徑皆為 Assumed，是 FY2028 EPS 最敏感的輸入（Sens）；(2) FY2026 錨點的 2H26 為假設，3Q26 季報 10-30 公布；(3) 網通模型 2027 年可插拔光模組 +84%，未設雷射、DSP 供給上限（Sens 用市場 ×0.8）；(4) 十年 P/E 兩個來源差距大，且含低基期與高成長期溢價，規則值偏高；(5) 稅率與泰國子公司獲利占比未找到；(6) 主要客戶與美國限制風險只有次級來源；(7) R4 產業部署路徑未建（Recon 預留列）。
... A17: v0.2.1（2026-10-25）：補上檔空間級距、投資建議、重點觀察（Val 頁 0.3 結論加「上檔空間級距」「投資建議」兩列、README 頁加重點觀察三點；數值不變，既有儲存格位置不變）。
A18: ="投資建議："&Val!B50&"（依上檔空間固定規則）" -> 投資建議：強力買進（依上檔空間固定規則）
A19: ="重點觀察 1：目標價 ¥"&TEXT(Val!$B$39,"#,##0.00")&"（DCF "&TEXT(Val!$B$24,"#,##0.00")&"、Comparable（相對倍數調整後）"&TEXT(tp_comp_adj,"#,##0.00")&"；DCF 權重 "&TEXT(tp_w_dcf,"0%")&"），比現價 "&TEXT(px,"#,##0.00")&"（2026-10-23）"&IF(Val!$B$42>=0,"高 "&TEXT(Val!$B$42,"0.0%"),"低 "&TEXT(-Val!$B$42,"0.0%"))&"，級距 "&Val!$B$49&"、投資建議 "&Val!$B$50&"。相對倍數調整係數 "&TEXT(rm_factor,"0.00")&"（本公司 10 年前瞻倍數中位數 ÷ 同業的中位數，夾在 0.5–2.0；Val 第 0.5 節），調整前加權上檔空間 "&TEXT((tp_w_dcf*Val!$B$24+(1-tp_w_dcf)*Val!$B$35)/px-1,"+0.0%;−0.0%")&"；Comparable 單獨（市場主流同業法、未調整）為 "&TEXT(Val!$B$43,"+0.0%;−0.0%")&"。"&"以下為 2026-10-29 相對倍數調整前撰寫的說明，其中數字為調整前：主因是倍數不是 EPS：本模型 12 個月後前瞻 EPS 23.74 比共識前瞻 EPS 37.82 低 37.2%，但 A 股光通訊同業前瞻 P/E 中位數 45.1 倍，現價只隱含 10.3 倍（共識未來 12 月 EPS）、共識目標價 460.89 隱含 12.2 倍；Comparable 未扣同業溢價與客戶集中、美國"&"限制風險。DCF 單獨也有 +96.4%（ROE 42.3%，現價只有 FY2027 EPS 的 10.0–10.2 倍）。" -> 重點觀察 1：目標價 ¥705.63（DCF 510.23、Comparable（相對倍數調整後）901.04；DCF 權重 50%），比現價 261.00（2026-10-23）高 170.4%，級距 大於 50%、投資建議 強力買進。相對倍數調整係數 0.84（本公司 10 年前瞻倍數中位數 ÷ 同業的中位數，夾在 0.5–2.0；Val 第 0.5 節），調整前加權上檔空間 +202.5%；Comparable 單獨（市場主流同業法、未調整）為 +309.6%。以下為 2026-10-29 相對倍數調整前撰寫的說明，其中數字為調整前：主因是倍數不是 EPS：本模型 12 個月後前瞻 EPS 23.74 比共識前瞻 EPS 37.82 低 37.2%，但 A 股光通訊同業前瞻 P/E 中位數 45.1 倍，現價只隱含 10.3 倍（共識未來 12 月 EPS）、共識目標價 460.89 隱含 12.2 倍；Comparable 未扣同業溢價與客戶集中、美國限制風險。DCF 單獨也有 +96.4%（ROE 42.3%，現價只有 FY2027 EPS 的 10.0–10.2 倍）。
A20: 重點觀察 2：最敏感的是美國限制與份額：美國限制案例 FY2028 EPS −45.0%、份額流失 −33.9%、降價快於模型 −19.2%；情境 C FY2028 EPS 16.93，比情境 A 的 28.11 低 39.8%。股價自 52 週高點下跌 68.1%、自 9 月底下跌 32.9%，現價 ÷ 情境 C 的 FY2028 EPS 為 15.4 倍，市場定價接近情境 C。
A21: 重點觀察 3：追蹤 3Q26 季報（2026-10-30）：本版 2H26 季增 20%、毛利率 48% 為假設；客戶名稱與集中度未找到第一手來源。網通 CPO 已改三情境（v0.2.2；A＝替代快、C＝慢）：CPO 快對新易盛是減分，情境 A FY2028 EPS 由 28.99 降到 28.11（−3.0%）、C 由 16.72 升到 16.93（+1.3%）、B 不變；CPO 份額 0 時 FY2028 EPS −4.4%。
A22: v0.2.3（2026-10-28）：分部原則重建（數值不變）。Q 頁第 30 列起追加 FY2025 年報產品別：光互聯產品（約 99.7%）、其他（差額）與核對列「分部合計 − 合併營收」；AI 營收屬光互聯產品，推估年仍以 AI／其他拆分。
A23: v0.2.2（2026-10-26）：網通模型 v0.2.3 的 CPO 滲透改三情境（A＝替代快、B＝平平、C＝慢），本模型 A／B／C 改讀同字母的可插拔與 CPO 市場（In 頁末新增 B、C 兩組；情境 A 沿用 A 節 mpl_／mcp_，數值改為網通情境 A）；FY2027 起三情境不再相同。其他輸入不變。
A25: 2026-10-29：加權目標價中的 Comparable 改用相對倍數調整後的值（Val 第 0.5 節：同業前瞻倍數中位數 × 本公司 10 年相對同業的倍數比，Bloomberg 前瞻倍數；Andy 2026-10-27「照建議做」、10-29 資料取回）。「Comparable 目標價（市場主流同業法）」維持不調整。重點觀察 1 的第一句已改為公式；重點觀察 2、3 與其他說明中的目標價與上檔空間數字為調整前撰寫，以 Val 頁為準。

Sheet In
A1: In — 輸入（藍字；基準欄 E，低 D、高 F）。公司金額：十億人民幣（RMB B）；市場：十億美元（US$B）；比例：%。每個輸入附兩個來源（找不到者寫「未找到」）；公司原文算一個
A2: 標記：Verified／Interested-party／Analogy／Assumed／Derived；Analogy、Assumed 給低／高區間。SemiAnalysis 未使用。公司原文＝深交所定期報告與公告（經財經媒體轉載）；公司不給營收指引；客戶名稱、客戶集中度、800G／1.6T 份額：未找到第一手來源
A3: 鍵 | B3: 項目 | C3: 單位 | D3: 低 | E3: 基準 | F3: 高 | G3: 標記 | H3: 來源1 | I3: 來源2／說明
A4: A. AI 光模組市場（讀 markets/network 成品；情境 A 基準，B／C 依顆數係數縮放）與中際旭創份額（讀 innolight 成品）
A5: mpl_26 | B5: AI 可插拔光模組市場 2026 | C5: US$B | E5: 29.753262 | G5: Derived | H5: markets/network/dist/20261026_AI網通市場模型_v0.2.3.xlsx｜Mkt!C45:F45 | I5: 加速器顆數 × 每顆光學內容（scale-out 為主；2029 含 scale-up 光學）− CPO
A6: mpl_27 | B6: AI 可插拔光模組市場 2027 | C6: US$B | E6: 53.560715 | G6: Derived | H6: markets/network/dist/20261026_AI網通市場模型_v0.2.3.xlsx｜Mkt!C45:F45 | I6: 同上
A7: mpl_28 | B7: AI 可插拔光模組市場 2028 | C7: US$B | E7: 57.9915 | G7: Derived | H7: markets/network/dist/20261026_AI網通市場模型_v0.2.3.xlsx｜Mkt!C45:F45 | I7: 同上
A8: mpl_29 | B8: AI 可插拔光模組市場 2029 | C8: US$B | E8: 72.9348 | G8: Derived | H8: markets/network/dist/20261026_AI網通市場模型_v0.2.3.xlsx｜Mkt!C45:F45 | I8: 同上
A9: mcp_26 | B9: AI CPO 光學市場 2026 | C9: US$B | E9: 0.300538 | G9: Derived | H9: markets/network/dist/20261026_AI網通市場模型_v0.2.3.xlsx｜Mkt!C44:F44 | I9: 共同封裝光學；網通模型的 CPO 滲透路徑
A10: mcp_27 | B10: AI CPO 光學市場 2027 | C10: US$B | E10: 2.818985 | G10: Derived | H10: markets/network/dist/20261026_AI網通市場模型_v0.2.3.xlsx｜Mkt!C44:F44 | I10: 同上
A11: mcp_28 | B11: AI CPO 光學市場 2028 | C11: US$B | E11: 6.4435 | G11: Derived | H11: markets/network/dist/20261026_AI網通市場模型_v0.2.3.xlsx｜Mkt!C44:F44 | I11: 同上
A12: mcp_29 | B12: AI CPO 光學市場 2029 | C12: US$B | E12: 11.74736 | G12: Derived | H12: markets/network/dist/20261026_AI網通市場模型_v0.2.3.xlsx｜Mkt!C44:F44 | I12: 同上
A13: itc_26 | B13: AI IT 資本支出 2026 | C13: US$B | E13: 781.87292 | G13: Derived | H13: markets/network/dist/20261026_AI網通市場模型_v0.2.3.xlsx｜Mkt!C27:F27 | I13: Recon 用：新易盛 AI 營收 ÷ AI IT 資本支出
A14: itc_27 | B14: AI IT 資本支出 2027 | C14: US$B | E14: 1565.35 | G14: Derived | H14: markets/network/dist/20261026_AI網通市場模型_v0.2.3.xlsx｜Mkt!C27:F27 | I14: 同上
A15: itc_28 | B15: AI IT 資本支出 2028 | C15: US$B | E15: 1984.2639 | G15: Derived | H15: markets/network/dist/20261026_AI網通市場模型_v0.2.3.xlsx｜Mkt!C27:F27 | I15: 同上
A16: itc_29 | B16: AI IT 資本支出 2029 | C16: US$B | E16: 2260.3903 | G16: Derived | H16: markets/network/dist/20261026_AI網通市場模型_v0.2.3.xlsx｜Mkt!C27:F27 | I16: 同上
... A27: um29_C | B27: 情境 C：2029 顆數 ÷ 基準 | C27: x | E27: 0.6 | G27: Assumed | H27: tsmc/dist/20261028_台積電個股模型_v0.4.xlsx｜In!E42 | I27: 同上
A28: B. 新易盛份額與單價（本專案為權威：新易盛在 AI 光模組的份額，規則第 13 條）
A29: rel_27 | B29: 可插拔份額 2027 ÷ 2026（相對值） | C29: x | D29: 0.8 | E29: 1 | F29: 1.15 | G29: Assumed | H29: https://lightcounting.com/newsletter/en/may-2026-optical-vendor-landscape-376：LightCounting 2025 排名新易盛第二（US$3.5B，+189%，首次超過 Coherent）（Interested-party） | I29: 中際旭創模型同年相對值 0.95（讓出份額給新易盛、Coherent）；新易盛持平時兩家合計仍在 65% 左右（Units 頁）
A30: rel_28 | B30: 可插拔份額 2028 ÷ 2026 | C30: x | D30: 0.65 | E30: 1 | F30: 1.2 | G30: Assumed | H30: 同上；1.6T 份額仍在爬坡（西南證券 9-15，Interested-party） | I30: 主要客戶轉單或 1.6T 落後為低值；美國限制另列
A31: rel_29 | B31: 可插拔份額 2029 ÷ 2026 | C31: x | D31: 0.55 | E31: 0.95 | F31: 1.2 | G31: Assumed | H31: 同上；2029 起 scale-up 光學與 CPO 比重上升 | I31: —
A32: us_27 | B32: 美國限制情境：份額相對值 2027（Sens 用） | C32: x | E32: 0.9 | G32: Assumed | H32: https://hao.cnyes.com/post/262773：花旗認為短期嚴格執行機率低；中國廠供美國大型雲端高速光模組約 60–70%（Interested-party） | I32: 新易盛境外營收占 97.92%（1H26，西南證券轉引公司）；泰國產能不必然豁免（美國價值含量門檻）
A33: us_28 | B33: 美國限制情境：份額相對值 2028（Sens 用） | C33: x | E33: 0.55 | G33: Assumed | H33: 同上；與中際旭創模型相同 | I33: —
A34: us_29 | B34: 美國限制情境：份額相對值 2029（Sens 用） | C34: x | E34: 0.5 | G34: Assumed | H34: 同上 | I34: —
A35: cpo_27 | B35: 新易盛占 CPO 光學金額 2027 | C35: % | D35: 0 | E35: 0.05 | F35: 0.2 | G35: Assumed | H35: https://stock.10jqka.com.cn/20260928/c680329640.shtml：NPO 預計 2027 年批量交付、2028 年規模化供應（公司說法經媒體轉載，Interested-party） | I35: 中際旭創模型 2027–29 為 10%／15%／20%；兩家合計 15–35%
A36: cpo_28 | B36: 新易盛占 CPO 光學金額 2028 | C36: % | D36: 0 | E36: 0.1 | F36: 0.25 | G36: Assumed | H36: 同上 | I36: —
A37: cpo_29 | B37: 新易盛占 CPO 光學金額 2029 | C37: % | D37: 0 | E37: 0.15 | F37: 0.3 | G37: Assumed | H37: 同上 | I37: —
A38: pxr_27 | B38: 單價係數 2027（相對網通模型每顆內容；基準 1） | C38: x | D38: 0.9 | E38: 1 | F38: 1.05 | G38: Assumed | H38: 網通模型每顆光學內容已含世代單價；本係數只在 Sens 動（降價快於模型） | I38: 與中際旭創模型相同
A39: pxr_28 | B39: 單價係數 2028 | C39: x | D39: 0.8 | E39: 1 | F39: 1.05 | G39: Assumed | H39: 同上 | I39: —
A40: pxr_29 | B40: 單價係數 2029 | C40: x | D40: 0.72 | E40: 1 | F40: 1.05 | G40: Assumed | H40: 同上 | I40: —
A41: fx | B41: 人民幣兌美元（RMB／USD） | C41: RMB | D41: 6.5 | E41: 6.72 | F41: 7 | G41: Verified | H41: Siliconomics SIF_fx_rmb（中國經濟網 2026-10-16 中間價 6.7220；v0.8.2 前 7.1） | I41: 1Q26 財務費用 5.22 億元，主因匯兌損失（每日經濟新聞轉載公司一季報）
A42: C. 其他營收（國內、電信、非 AI 數通；網通模型未涵蓋）
A43: oth_s | B43: 其他營收 ÷ 總營收（FY2025、FY2026） | C43: % | D43: 0.03 | E43: 0.05 | F43: 0.1 | G43: Assumed | H43: 西南證券 9-15（網址見 Sources）：境外收入占比約 97.92%（1H26） | I43: 光互聯產品占營收 99.9%（1H26 208.83 ÷ 209.10）；非 AI 部分比重：未找到
A44: g_oth | B44: 其他營收年增（FY2027 起） | C44: % | D44: 0 | E44: 0.1 | F44: 0.2 | G44: Assumed | H44: 與中際旭創模型相同 | I44: —
A45: D. 毛利率
A46: gm_h2 | B46: 2H26 毛利率 | C46: % | D46: 0.45 | E46: 0.48 | F46: 0.5 | G46: Assumed | H46: https://m.gelonghui.com/news/5306856：2Q26 綜合毛利率 47.96%（季減 1.20pt）→ 1Q26 49.16%（推導） | I46: https://stock.10jqka.com.cn/20260915/c679905127.shtml：1H26 綜合毛利率 48.44%
A47: gm_27 | B47: 毛利率 2027 | C47: % | D47: 0.43 | E47: 0.47 | F47: 0.49 | G47: Assumed | H47: 1.6T 占比上升（上推）vs 降價（下壓）；FY2024 光互聯 44.85%、FY2025 47.81%（公司） | I47: 開源證券 2026E–2028E 47.0%（Interested-party）
A48: gm_28 | B48: 毛利率 2028 | C48: % | D48: 0.4 | E48: 0.46 | F48: 0.48 | G48: Assumed | H48: 同上；與中際旭創模型路徑相同 | I48: —
A49: gm_29 | B49: 毛利率 2029 | C49: % | D49: 0.36 | E49: 0.45 | F49: 0.47 | G49: Assumed | H49: 同上 | I49: —
A50: E. FY2026 錨點（1H26 實績＋2H26 假設）
...

Sheet Q
A1: Q — 實績與 FY2026 錨點（十億人民幣；EPS 為人民幣；股數為十億股，轉增後）。藍字＝輸入；黑字＝公式。口徑：歸母淨利；FY2025 毛利率以光互聯產品（占營收 99.7%）代用
A2: FY2026 錨點＝1H26 實績＋2H26（3Q、4Q 營收依季增假設；毛利率 gm_h2；營業費用率 opx_h2）。營業費用、減值與其他為殘差：毛利 − 歸母淨利 ÷［（1 − 稅率）× 歸母比例］。3Q26 季報預計 2026-10-30 公布（截至 10-25 尚未公布），公布後以實績取代 3Q
A3: 項目 | B3: FY2025A | C3: 1H26（實績） | D3: 3Q26（假設） | E3: 4Q26（假設） | F3: 2H26 合計 | G3: FY2026 錨點 | H3: 標記 | I3: 說明
A4: 營收 | B4: =a25_rev_in -> 24.842 | C4: =h1_rev -> 20.91 | D4: =(h1_rev-q1_rev)*(1+q_g) -> 15.0864 | E4: =D4*(1+q_g) -> 18.10368 | F4: =D4+E4 -> 33.19008 | G4: =C4+F4 -> 54.10008 | H4: Verified／Assumed（3Q、4Q） | I4: 2Q26＝1H26 − 1Q26（125.72）；3Q＝2Q ×（1＋季增）
A5: 毛利 | B5: =B4*a25_gm_in -> 11.87696 | C5: =C4*h1_gm -> 10.128804 | D5: =D4*gm_h2 -> 7.241472 | E5: =E4*gm_h2 -> 8.6897664 | F5: =D5+E5 -> 15.931238 | G5: =C5+F5 -> 26.060042 | H5: Derived
A6: 毛利率 | B6: =B5/B4 -> 0.4781 | C6: =C5/C4 -> 0.4844 | D6: =D5/D4 -> 0.48 | E6: =E5/E4 -> 0.48 | F6: =F5/F4 -> 0.48 | G6: =G5/G4 -> 0.48170063 | H6: Derived
A7: 稅後歸母係數 ＝（1 − 稅率）× 歸母比例 | B7: =(1-tx)*attr -> 0.87806553 | C7: =(1-tx)*attr -> 0.87806553 | D7: =(1-tx)*attr -> 0.87806553 | E7: =(1-tx)*attr -> 0.87806553 | H7: Assumed／Derived
A8: 營業費用、減值與其他（淨） | B8: =B5-B10/B7 -> 1.0212784 | C8: =C5-C10/C7 -> 1.5542731 | D8: =D4*opx_h2 -> 0.75432 | E8: =E4*opx_h2 -> 0.905184 | F8: =D8+E8 -> 1.659504 | G8: =C8+F8 -> 3.2137771 | H8: Derived（殘差）／Assumed（2H） | I8: 1H26 殘差含 1Q26 匯兌損失（財務費用 5.22 億元）
A9: 營業費用率 | B9: =B8/B4 -> 0.041110957 | C9: =C8/C4 -> 0.074331569 | D9: =D8/D4 -> 0.05 | E9: =E8/E4 -> 0.05 | F9: =F8/F4 -> 0.05 | G9: =G8/G4 -> 0.059404295 | H9: Derived
A10: 歸母淨利 | B10: =a25_ni_in -> 9.532 | C10: =h1_ni -> 7.529 | D10: =(D5-D8)*D7 -> 5.6961446 | E10: =(E5-E8)*E7 -> 6.8353735 | F10: =D10+E10 -> 12.531518 | G10: =C10+F10 -> 20.060518 | H10: Verified／Derived（3Q、4Q）
A11: 淨利率 | B11: =B10/B4 -> 0.38370502 | C11: =C10/C4 -> 0.36006695 | D11: =D10/D4 -> 0.37756818 | E11: =E10/E4 -> 0.37756818 | F11: =F10/F4 -> 0.37756818 | G11: =G10/G4 -> 0.37080385 | H11: Derived
A12: 股數（十億股，轉增後） | B12: =a25_sh_in -> 1.3886368 | C12: =q_sh_h1 -> 1.3916821 | D12: =sh_post -> 1.394 | E12: =sh_post -> 1.394 | G12: =(C12*2+D12+E12)/4 -> 1.392841 | H12: Derived | I12: FY2026＝1H 加權 × ½ ＋ 期末股數 × ½（近似）
A13: EPS | B13: =B10/B12 -> 6.8642857 | C13: =C10/C12 -> 5.41 | D13: =D10/D12 -> 4.0861869 | E13: =E10/E12 -> 4.9034243 | G13: =G10/G12 -> 14.40259 | H13: Derived | I13: FY2025 轉增後重述 ＝ 9.61 ÷ 1.4；1H26 公司揭露 5.41
A14: 其他營收（國內、電信等；＝營收 × oth_s） | B14: =B4*oth_s -> 1.2421 | G14: =G4*oth_s -> 2.705004 | H14: Assumed
A15: AI 營收（＝營收 − 其他） | B15: =B4-B14 -> 23.5999 | G15: =G4-G14 -> 51.395076 | H15: Derived
A16: AI 營收（US$B ＝ ÷ fx） | B16: =B15/fx -> 3.5118899 | G16: =G15/fx -> 7.6480768 | H16: Derived
A18: 季度拆分（推導）
A19: 2Q26 營業費用、減值與其他 ÷ 營收（殘差；2Q26 毛利率 47.96%、歸母淨利 47.49 億元） | B19: =(12.572*0.4796-4.749/((1-tx)*attr))/12.572 -> 0.049399541
A20: 1Q26 營業費用、減值與其他 ÷ 營收（殘差；1Q26 毛利率 49.16%、歸母淨利 27.80 億元） | B20: =(q1_rev*0.4916-(h1_ni-4.749)/((1-tx)*attr))/q1_rev -> 0.11188655
A21: FY2026 錨點與共識的距離（參考；校準未使用共識）
A22: FY2026 營收 ÷ 共識 − 1 | B22: =G4/cons_rev26-1 -> -0.019730743
A23: FY2026 歸母淨利 ÷ 共識 − 1 | B23: =G10/cons_ni26-1 -> -0.00369913
A24: FY2026 營收年增 | B24: =G4/B4-1 -> 1.1777667
A25: FY2026 營業費用年增 | B25: =G8/B8-1 -> 2.1468179
A26: 營業費用彈性（營業費用年增 ÷ 營收年增；受 1Q26 匯兌損失影響，In 頁 phi 不採用） | B26: =B25/B24 -> 1.8227871
A27: 1H26 EPS（模型）vs 公司揭露 5.41 | B27: =C13/h1_eps-1 -> 0
A28: FY2026 營收 vs 股權激勵第一期考核 500 億元（÷ 50 − 1） | B28: =G4/50-1 -> 0.0820016
A30: 官方報告產品別（FY2025 年報；分部原則第 3 條）
A31: 光互聯產品營收（含 AI 與國內、電信） | B31: =B4*0.997 -> 24.767474 | H31: Verified | I31: 每日經濟新聞轉載公司 FY2025 年報：光互聯產品占營收 99.7%（金額為推得）
A32: 其他產品營收（差額） | B32: =B4-B31 -> 0.074526 | H32: Derived | I32: 合併營收 − 光互聯產品
A33: 檢查：分部合計 − 合併營收 | B33: =ROUND(B31+B32-B4,6) -> 0 | H33: Derived | I33: 應為 0；PL 的 AI 營收屬光互聯產品，推估年以 AI／其他拆分

Sheet Units
A1: Units — 新易盛在 AI 光模組的份額（本專案權威，規則第 13 條）。市場取自 markets/network（加速器顆數 × 每顆光學內容；美元）；中際旭創份額取自 innolight 成品（唯讀）
A3: 項目 | B3: 單位 | C3: CY2026 | D3: CY2027 | E3: CY2028 | F3: CY2029 | G3: 說明
A4: AI 可插拔光模組市場（情境 A） | B4: US$B | C4: =PL!D63 -> 29.753262 | D4: =PL!E63 -> 53.560715 | E4: =PL!F63 -> 57.9915 | F4: =PL!G63 -> 72.9348 | G4: markets/network Mkt 頁
A5: AI CPO 光學市場（情境 A） | B5: US$B | C5: =PL!D64 -> 0.300538 | D5: =PL!E64 -> 2.818985 | E5: =PL!F64 -> 6.4435 | F5: =PL!G64 -> 11.74736 | G5: 同上
A6: 新易盛可插拔有效份額 | B6: % | C6: =PL!D68 -> 0.25705003 | D6: =PL!E68 -> 0.25705003 | E6: =PL!F68 -> 0.25705003 | F6: =PL!G68 -> 0.24419753 | G6: FY2026 以 1H26 實績＋2H26 假設校準
A7: 中際旭創可插拔有效份額（innolight 成品，情境 A） | B7: % | C7: =inl_26 -> 0.44568706 | D7: =inl_27 -> 0.42340271 | E7: =inl_28 -> 0.40111835 | F7: =inl_29 -> 0.378834 | G7: 唯讀；中際旭創份額的權威在 innolight/
A8: 兩家合計可插拔份額 | B8: % | C8: =C6+C7 -> 0.70273709 | D8: =D6+D7 -> 0.68045273 | E8: =E6+E7 -> 0.65816838 | F8: =F6+F7 -> 0.62303153 | G8: 其餘為 Coherent、光迅、Lumentum、華工等
A9: 新易盛 AI 營收（情境 A；美元） | B9: US$B | C9: =PL!D71 -> 7.6480768 | D9: =PL!E71 -> 13.908732 | E9: =PL!F71 -> 15.551067 | F9: =PL!G71 -> 19.572602
A10: 其他廠商（Coherent 等）＝ 可插拔 ×（1 − 兩家合計份額） | B10: US$B | C10: =C4*(1-C8) -> 8.8445414 | D10: =D4*(1-D8) -> 17.11518 | E10: =E4*(1-E8) -> 19.823328 | F10: =F4*(1-F8) -> 27.49412 | G10: 不含 CPO
A11: 新易盛 AI 營收 ÷ AI IT 資本支出 | B11: % | C11: =PL!D71/itc_26 -> 0.009781739 | D11: =PL!E71/itc_27 -> 0.0088853818 | E11: =PL!F71/itc_28 -> 0.0078371968 | F11: =PL!G71/itc_29 -> 0.0086589479 | G11: markets/network 的 AI IT 資本支出（加速器 × 每顆 IT capex）
A13: 讀法：FY2026 有效份額由 1H26 實績＋2H26 假設校準；與中際旭創合計約三分之二，其餘由 Coherent 等分食。份額相對值與 CPO 份額是 Assumed，是最需要每季檢查的輸入。

Sheet PL
A1: PL — 新易盛損益（RMB B）。FY2025A 實績、FY2026 錨點（1H26 實績＋2H26 假設），FY2027 起為模型。FY(t)＝CY(t)。三情境各一個完整推導區塊（本頁下方），頂端為摘要。FY2026 三情境相同；FY2027 起三情境讀不同的網通 CPO 情境（A 替代快、C 慢），顆數係數從 CY2028 開始
A2: 灰底＝FY2030–FY2032 收斂法，非驅動因子推導（上游市場層只到 2029）：營收年增由 FY2029 線性收斂到 fade_g（A＝tp_g＋2pt、B＝tp_g、C＝tp_g−2pt），淨利率由 FY2029 線性收斂到 fade_m（In 頁 K 節），FY2032 達到；股數依 sh_g
A3: 情境／項目 | B3: 單位 | C3: FY2025A | D3: FY2026（錨點） | E3: FY2027 | F3: FY2028 | G3: FY2029 | H3: FY2030（收斂） | I3: FY2031（收斂） | J3: FY2032（收斂） | K3: 說明
A4: 情境 A
A5: 營收 | B5: RMB B | C5: =C75 -> 24.842 | D5: =D75 -> 54.10008 | E5: =E75 -> 96.442187 | F5: =F75 -> 107.77622 | G5: =G75 -> 135.12824 | H5: =H75 -> 160.69318 | I5: =I75 -> 180.71477 | J5: =J75 -> 191.55765
A6: 營收年增 | B6: % | D6: =D76 -> 1.1777667 | E6: =E76 -> 0.78266255 | F6: =F76 -> 0.11752156 | G6: =G76 -> 0.2537853 | H6: =H76 -> 0.1891902 | I6: =I76 -> 0.1245951 | J6: =J76 -> 0.06
A7: AI 營收 | B7: RMB B | C7: =C72 -> 23.5999 | D7: =D72 -> 51.395076 | E7: =E72 -> 93.466682 | F7: =F72 -> 104.50317 | G7: =G72 -> 131.52788
A8: 其他營收 | B8: RMB B | C8: =C74 -> 1.2421 | D8: =D74 -> 2.705004 | E8: =E74 -> 2.9755044 | F8: =F74 -> 3.2730548 | G8: =G74 -> 3.6003603
A9: AI ÷ 營收 | B9: % | C9: =C77 -> 0.95 | D9: =D77 -> 0.95 | E9: =E77 -> 0.96914727 | F9: =F77 -> 0.96963101 | G9: =G77 -> 0.97335597
A10: 毛利率 | B10: % | C10: =C79 -> 0.4781 | D10: =D79 -> 0.48170063 | E10: =E79 -> 0.47 | F10: =F79 -> 0.46 | G10: =G79 -> 0.45
A11: 淨利率 | B11: % | C11: =C86 -> 0.38370502 | D11: =D86 -> 0.37080385 | E11: =E86 -> 0.36969025 | F11: =F86 -> 0.36271841 | G11: =G86 -> 0.35727289 | H11: =H86 -> 0.35727289 | I11: =I86 -> 0.35727289 | J11: =J86 -> 0.35727289
A12: 歸母淨利 | B12: RMB B | C12: =C85 -> 9.532 | D12: =D85 -> 20.060518 | E12: =E85 -> 35.653736 | F12: =F85 -> 39.09242 | G12: =G85 -> 48.277658 | H12: =H85 -> 57.411318 | I12: =I85 -> 64.564487 | J12: =J85 -> 68.438356
A13: EPS | B13: RMB | C13: =C88 -> 6.8642857 | D13: =D88 -> 14.40259 | E13: =E88 -> 25.576568 | F13: =F88 -> 28.043343 | G13: =G88 -> 34.632466 | H13: =H88 -> 41.18459 | I13: =I88 -> 46.315988 | J13: =J88 -> 49.094947
A14: EPS 年增 | B14: % | D14: =D89 -> 1.0981921 | E14: =E89 -> 0.77583117 | F14: =F89 -> 0.096446685 | G14: =G89 -> 0.23496212 | H14: =H89 -> 0.1891902 | I14: =I89 -> 0.1245951 | J14: =J89 -> 0.06
A16: 情境 B
A17: 營收 | B17: RMB B | C17: =C107 -> 24.842 | D17: =D107 -> 54.10008 | E17: =E107 -> 98.011094 | F17: =F107 -> 89.595716 | G17: =G107 -> 118.55943 | H17: =H107 -> 145.69146 | I17: =I107 -> 165.27585 | J17: =J107 -> 171.88688
A18: 營收年增 | B18: % | D18: =D108 -> 1.1777667 | E18: =E108 -> 0.81166264 | F18: =F108 -> -0.085861489 | G18: =G108 -> 0.32327121 | H18: =H108 -> 0.22884748 | I18: =I108 -> 0.13442374 | J18: =J108 -> 0.04
A19: AI 營收 | B19: RMB B | C19: =C104 -> 23.5999 | D19: =D104 -> 51.395076 | E19: =E104 -> 95.03559 | F19: =F104 -> 86.322661 | G19: =G104 -> 114.95907
A20: 其他營收 | B20: RMB B | C20: =C106 -> 1.2421 | D20: =D106 -> 2.705004 | E20: =E106 -> 2.9755044 | F20: =F106 -> 3.2730548 | G20: =G106 -> 3.6003603
A21: AI ÷ 營收 | B21: % | C21: =C109 -> 0.95 | D21: =D109 -> 0.95 | E21: =E109 -> 0.96964115 | F21: =F109 -> 0.96346862 | G21: =G109 -> 0.96963244
A22: 毛利率 | B22: % | C22: =C111 -> 0.4781 | D22: =D111 -> 0.48170063 | E22: =E111 -> 0.47 | F22: =F111 -> 0.46 | G22: =G111 -> 0.45
A23: 淨利率 | B23: % | C23: =C118 -> 0.38370502 | D23: =D118 -> 0.37080385 | E23: =E118 -> 0.3698776 | F23: =F118 -> 0.35707566 | G23: =G118 -> 0.35287162 | H23: =H118 -> 0.34110923 | I23: =I118 -> 0.32934684 | J23: =J118 -> 0.31758446
A24: 歸母淨利 | B24: RMB B | C24: =C117 -> 9.532 | D24: =D117 -> 20.060518 | E24: =E117 -> 36.252108 | F24: =F117 -> 31.99245 | G24: =G117 -> 41.836258 | H24: =H117 -> 49.696701 | I24: =I117 -> 54.433079 | J24: =J117 -> 54.588602
A25: EPS | B25: RMB | C25: =C120 -> 6.8642857 | D25: =D120 -> 14.40259 | E25: =E120 -> 26.005816 | F25: =F120 -> 22.950107 | G25: =G120 -> 30.011663 | H25: =H120 -> 35.650431 | I25: =I120 -> 39.04812 | J25: =J120 -> 39.159686
A26: EPS 年增 | B26: % | D26: =D121 -> 1.0981921 | E26: =E121 -> 0.80563473 | F26: =F121 -> -0.11750098 | G26: =G121 -> 0.30769162 | H26: =H121 -> 0.18788589 | I26: =I121 -> 0.095305678 | J26: =J121 -> 0.0028571429
A28: 情境 C
A29: 營收 | B29: RMB B | C29: =C139 -> 24.842 | D29: =D139 -> 54.10008 | E29: =E139 -> 98.795548 | F29: =F139 -> 68.831088 | G29: =G139 -> 85.584508 | H29: =H139 -> 100.04253 | I29: =I139 -> 109.49318 | J29: =J139 -> 111.68305
A30: 營收年增 | B30: % | D30: =D140 -> 1.1777667 | E30: =E140 -> 0.82616269 | F30: =F140 -> -0.30329767 | G30: =G140 -> 0.24339903 | H30: =H140 -> 0.16893269 | I30: =I140 -> 0.094466343 | J30: =J140 -> 0.02
A31: AI 營收 | B31: RMB B | C31: =C136 -> 23.5999 | D31: =D136 -> 51.395076 | E31: =E136 -> 95.820043 | F31: =F136 -> 65.558033 | G31: =G136 -> 81.984148
A32: 其他營收 | B32: RMB B | C32: =C138 -> 1.2421 | D32: =D138 -> 2.705004 | E32: =E138 -> 2.9755044 | F32: =F138 -> 3.2730548 | G32: =G138 -> 3.6003603
A33: AI ÷ 營收 | B33: % | C33: =C141 -> 0.95 | D33: =D141 -> 0.95 | E33: =E141 -> 0.9698822 | F33: =F141 -> 0.95244802 | G33: =G141 -> 0.9579321
A34: 毛利率 | B34: % | C34: =C143 -> 0.4781 | D34: =D143 -> 0.48170063 | E34: =E143 -> 0.47 | F34: =F143 -> 0.46 | G34: =G143 -> 0.45
A35: 淨利率 | B35: % | C35: =C150 -> 0.38370502 | D35: =D150 -> 0.37080385 | E35: =E150 -> 0.36996904 | F35: =F150 -> 0.34259019 | G35: =G150 -> 0.33861096 | H35: =H150 -> 0.31603689 | I35: =I150 -> 0.29346283 | J35: =J150 -> 0.27088876
A36: 歸母淨利 | B36: RMB B | C36: =C149 -> 9.532 | D36: =D149 -> 20.060518 | E36: =E149 -> 36.551294 | F36: =F149 -> 23.580855 | G36: =G149 -> 28.979852 | H36: =H149 -> 31.61713 | I36: =I149 -> 32.132179 | J36: =J149 -> 30.253682
A37: EPS | B37: RMB | C37: =C152 -> 6.8642857 | D37: =D152 -> 14.40259 | E37: =E152 -> 26.220441 | F37: =F152 -> 16.915965 | G37: =G152 -> 20.78899 | H37: =H152 -> 22.680868 | I37: =I152 -> 23.050343 | J37: =J152 -> 21.702785
A38: EPS 年增 | B38: % | D38: =D153 -> 1.0981921 | E38: =E153 -> 0.82053651 | F38: =F153 -> -0.3548558 | G38: =G153 -> 0.22895679 | H38: =H153 -> 0.091003841 | I38: =I153 -> 0.016290176 | J38: =J153 -> -0.058461538
A40: 核對（應為 0）：FY2026 模型營收、AI 營收、歸母淨利 − 錨點（校準恆等式）
A41: 情境 A：營收差（RMB B） | D41: =D75-a26_rev -> 0
A42: 情境 A：AI 營收差（RMB B） | D42: =D72-a26_ai -> 0
A43: 情境 A：稅前利益 ×（1 − 稅率）× 歸母比例 − 歸母淨利錨點 | D43: =D83*(1-tx)*attr-a26_ni -> 0
...

Sheet Val
A1: Val — P/E 估值（人民幣；A 股）。目標價＝DCF 與 Comparable 加權（第 0 節）；舊法規則值情境加權保留參考；另列「現價 ÷ FY2027、FY2028 EPS（模型）」、市場隱含 EPS。十年 P/E 用 2016–2025（兩個資料商來源）
A2: 循環位置：新易盛不是設備股，不套設備市場見頂年；以本模型營收最高的會計年度為見頂年（比照中際旭創、Arista；FY(t)＝CY(t)，不平移）。營收到 FY2029 仍在增加時，見頂年未知，判為中段
A4: 0. 目標價
A5: 0.1 DCF（股東權益現金流，FY2027–FY2032 明確期＋FY2032 後永續）
A6: 項目 | B6: A（順利） | C6: B（平平） | D6: C（不如預期） | E6: 說明
A7: 情境 EPS（FY2027–FY2032） | E7: PL 頁各情境；FY2030 起為收斂法（PL 頁灰底）
A8: FY2027 | B8: =PL!E13 -> 25.576568 | C8: =PL!E25 -> 26.005816 | D8: =PL!E37 -> 26.220441
A9: FY2028 | B9: =PL!F13 -> 28.043343 | C9: =PL!F25 -> 22.950107 | D9: =PL!F37 -> 16.915965
A10: FY2029 | B10: =PL!G13 -> 34.632466 | C10: =PL!G25 -> 30.011663 | D10: =PL!G37 -> 20.78899
A11: FY2030 | B11: =PL!H13 -> 41.18459 | C11: =PL!H25 -> 35.650431 | D11: =PL!H37 -> 22.680868
A12: FY2031 | B12: =PL!I13 -> 46.315988 | C12: =PL!I25 -> 39.04812 | D12: =PL!I37 -> 23.050343
A13: FY2032 | B13: =PL!J13 -> 49.094947 | C13: =PL!J25 -> 39.159686 | D13: =PL!J37 -> 21.702785
A14: 股東現金流＝EPS ×（1 − tp_g ÷ tp_roe）
A15: 再投資率（tp_g ÷ tp_roe，上限 0.8） | B15: =IF(tp_roe<=tp_g,0.8,MIN(tp_g/tp_roe,0.8)) -> 0.094562648 | E15: ROE＝In 頁 tp_roe；tp_roe ≤ tp_g 時取上限 0.8
A16: FY2027 | B16: =B8*(1-$B$15) -> 23.15798 | C16: =C8*(1-$B$15) -> 23.546637 | D16: =D8*(1-$B$15) -> 23.740966
A17: FY2028 | B17: =B9*(1-$B$15) -> 25.39149 | C17: =C9*(1-$B$15) -> 20.779884 | D17: =D9*(1-$B$15) -> 15.316347
A18: FY2029 | B18: =B10*(1-$B$15) -> 31.357529 | C18: =C10*(1-$B$15) -> 27.173681 | D18: =D10*(1-$B$15) -> 18.823128
A19: FY2030 | B19: =B11*(1-$B$15) -> 37.290066 | C19: =C11*(1-$B$15) -> 32.279232 | D19: =D11*(1-$B$15) -> 20.536105
A20: FY2031 | B20: =B12*(1-$B$15) -> 41.936225 | C20: =C12*(1-$B$15) -> 35.355626 | D20: =D12*(1-$B$15) -> 20.870642
A21: FY2032 | B21: =B13*(1-$B$15) -> 44.452399 | C21: =C13*(1-$B$15) -> 35.456642 | D21: =D13*(1-$B$15) -> 19.650512
A22: DCF 情境每股價值（折現率 tp_r） | B22: =SUMPRODUCT(B16:B21,1/(1+tp_r)^{1;2;3;4;5;6})+B21*(1+tp_g)/(tp_r-tp_g)/(1+tp_r)^6 -> 577.12954 | C22: =SUMPRODUCT(C16:C21,1/(1+tp_r)^{1;2;3;4;5;6})+C21*(1+tp_g)/(tp_r-tp_g)/(1+tp_r)^6 -> 469.92545 | D22: =SUMPRODUCT(D16:D21,1/(1+tp_r)^{1;2;3;4;5;6})+D21*(1+tp_g)/(tp_r-tp_g)/(1+tp_r)^6 -> 278.72542 | E22: Σ 明確期現金流 ÷ (1＋r)^t ＋ 永續價值 ÷ (1＋r)^6；永續價值＝FY2032 現金流 ×(1＋g)÷(r−g)；基準日 2026 年底，t＝1 對 FY2027
A23: DCF 情境價值推到 12 個月後（×(1＋tp_r)） | B23: =B22*(1+tp_r) -> 634.84249 | C23: =C22*(1+tp_r) -> 516.91799 | D23: =D22*(1+tp_r) -> 306.59797
A24: DCF 目標價（情境加權） | B24: =tp_wA*B23+tp_wB*C23+tp_wC*D23 -> 510.23134 | E24: Σ 權重 × 情境價值 ×(1＋r)；權重見 In 頁
A26: 0.2 Comparable（市場主流同業前瞻 P/E）
A27: 同業與前瞻 P/E | B27: 代號 | C27: 前瞻 12 月 P/E | D27: 日期 | E27: 來源 | F27: 標記
A28: 中際旭創（Innolight） | B28: 300308.SZ | C28: 14.11 | D28: 2026-10-12 | E28: stockanalysis forward PE（S&P Global 共識；價格日期如左） | F28: Interested-party
A29: 天孚通信（TFC） | B29: 300394.SZ | C29: 46.53 | D29: 2026-09-30 | E29: 同上（頁面價格日期較舊） | F29: Interested-party
A30: 光迅科技（Accelink） | B30: 002281.SZ | C30: 77.09 | D30: 2026-08-18 | E30: 同上（頁面價格日期較舊） | F30: Interested-party
A31: 華工科技（HGTECH） | B31: 000988.SZ | C31: 45.08 | D31: 2026-08-07 | E31: 同上（頁面價格日期較舊） | F31: Interested-party
A32: 劍橋科技（CIG） | B32: 603083.SS | C32: 31.74 | D32: 2026-10-23 | E32: 同上 | F32: Interested-party
A33: 同業前瞻 P/E 中位數 | B33: =MEDIAN(C28:C32) -> 45.08 | E33: A 股光通訊同業（新易盛是 A 股公司，同業只用 A 股；工作單 Andy 11:53）
A34: 12 個月後的前瞻 EPS（情境加權） | B34: =tp_wA*(2/12*B8+10/12*B9)+tp_wB*(2/12*C8+10/12*C9)+tp_wC*(2/12*D8+10/12*D9) -> 23.712702 | E34: 約 2027-10 時的未來 12 月 EPS ≈ 2／12 × FY2027＋10／12 × FY2028（會計年度＝日曆年）
A35: Comparable 目標價 | B35: =B33*B34 -> 1068.9686 | E35: 同業中位數 × 前瞻 EPS
A37: 0.3 結論
A38: 項目 | B38: 數值 | E38: 說明
A39: 目標價（DCF 與 Comparable 加權） | B39: =tp_w_dcf*B24+(1-tp_w_dcf)*tp_comp_adj -> 705.6347 | E39: tp_w_dcf × DCF＋（1 − tp_w_dcf）× Comparable；tp_w_dcf 見 In 頁
A40: Comparable 目標價（市場主流同業法） | B40: =B35 -> 1068.9686
A41: 市場共識目標價 | B41: =cons_tp -> 460.89 | E41: 同花順 90 天機構目標均價 460.89（15 家；In 頁 tp_avg90）；多數訂於 9 月前股價較高時
A42: 上檔空間：加權目標價 | B42: =B39/px-1 -> 1.7035812 | E42: 現價＝In 頁 px
A43: 上檔空間：Comparable 目標價 | B43: =B40/px-1 -> 3.0956652
...

Sheet Recon
A1: Recon — 本模型 vs 共識、券商、研調。只作事後對照，不為對上數字而調參數。共識（同花順 19 家，明細只列 10 家）區間很寬（FY2027 EPS 16.29–54.49），均值明顯高於高盛（FY2027 歸母淨利 +21%）：天風、國金兩家特別高
A3: 項目 | B3: 對照值 | C3: 模型 A | D3: 差距 A | E3: 模型 B | F3: 差距 B | G3: 模型 C | H3: 差距 C | I3: 對照來源 | J3: 說明
A4: A. 共識與券商（校準未使用）
A5: FY2026 營收 vs 共識 | B5: =cons_rev26 -> 55.189 | C5: =PL!D75 -> 54.10008 | D5: =C5/B5-1 -> -0.019730743 | E5: =PL!D107 -> 54.10008 | F5: =E5/B5-1 -> -0.019730743 | G5: =PL!D139 -> 54.10008 | H5: =G5/B5-1 -> -0.019730743 | I5: 同花順（19 家；440.5–684.8） | J5: 錨點＝1H26 實績＋2H26 季增假設
A6: FY2026 歸母淨利 vs 共識 | B6: =cons_ni26 -> 20.135 | C6: =PL!D85 -> 20.060518 | D6: =C6/B6-1 -> -0.00369913 | E6: =PL!D117 -> 20.060518 | F6: =E6/B6-1 -> -0.00369913 | G6: =PL!D149 -> 20.060518 | H6: =G6/B6-1 -> -0.00369913 | I6: 同花順（19 家；126.9–272.9）
A7: FY2026 歸母淨利 vs 高盛 | B7: =gs_ni26 -> 20.683 | C7: =PL!D85 -> 20.060518 | D7: =C7/B7-1 -> -0.03009631 | E7: =PL!D117 -> 20.060518 | F7: =E7/B7-1 -> -0.03009631 | G7: =PL!D149 -> 20.060518 | H7: =G7/B7-1 -> -0.03009631 | I7: 華爾街見聞轉引高盛（2026-07）
A8: FY2027 營收 vs 共識 | B8: =cons_rev27 -> 99.385 | C8: =PL!E75 -> 96.442187 | D8: =C8/B8-1 -> -0.029610238 | E8: =PL!E107 -> 98.011094 | F8: =E8/B8-1 -> -0.013824078 | G8: =PL!E139 -> 98.795548 | H8: =G8/B8-1 -> -0.0059309989 | I8: 同花順（570.5–1,566.6）
A9: FY2027 歸母淨利 vs 共識 | B9: =cons_ni27 -> 36.358 | C9: =PL!E85 -> 35.653736 | D9: =C9/B9-1 -> -0.019370274 | E9: =PL!E117 -> 36.252108 | F9: =E9/B9-1 -> -0.0029124842 | G9: =PL!E149 -> 36.551294 | H9: =G9/B9-1 -> 0.0053164106 | I9: 同花順（227.1–541.6）
A10: FY2027 歸母淨利 vs 高盛 | B10: =gs_ni27 -> 30.08 | C10: =PL!E85 -> 35.653736 | D10: =C10/B10-1 -> 0.18529706 | E10: =PL!E117 -> 36.252108 | F10: =E10/B10-1 -> 0.20518976 | G10: =PL!E149 -> 36.551294 | H10: =G10/B10-1 -> 0.21513611 | I10: 華爾街見聞轉引高盛（2026-07） | J10: 高盛低於共識均值約兩成
A11: FY2027 EPS vs 共識 | B11: =cons_eps27 -> 27.29 | C11: =PL!E88 -> 25.576568 | D11: =C11/B11-1 -> -0.062786081 | E11: =PL!E120 -> 26.005816 | F11: =E11/B11-1 -> -0.047056934 | G11: =PL!E152 -> 26.220441 | H11: =G11/B11-1 -> -0.03919236 | I11: 同花順（16.29–54.49）
A12: FY2028 營收 vs 共識 | B12: =cons_rev28 -> 143.815 | C12: =PL!F75 -> 107.77622 | D12: =C12/B12-1 -> -0.25059123 | E12: =PL!F107 -> 89.595716 | F12: =E12/B12-1 -> -0.37700716 | G12: =PL!F139 -> 68.831088 | H12: =G12/B12-1 -> -0.52139145 | I12: 同花順（711.4–2,371.1）
A13: FY2028 歸母淨利 vs 高盛 | B13: =gs_ni28 -> 34.576 | C13: =PL!F85 -> 39.09242 | D13: =C13/B13-1 -> 0.13062298 | E13: =PL!F117 -> 31.99245 | F13: =E13/B13-1 -> -0.074720918 | G13: =PL!F149 -> 23.580855 | H13: =G13/B13-1 -> -0.31799933 | I13: 華爾街見聞轉引高盛（2026-07）
A14: FY2028 EPS vs 共識 | B14: =cons_eps28 -> 39.93 | C14: =PL!F88 -> 28.043343 | D14: =C14/B14-1 -> -0.29768738 | E14: =PL!F120 -> 22.950107 | F14: =E14/B14-1 -> -0.42524149 | G14: =PL!F152 -> 16.915965 | H14: =G14/B14-1 -> -0.5763595 | I14: 同花順（21.94–65.32）
A15: 3Q26 營收（模型假設）vs 共識 | B15: =q3_cons_rev -> 17.76 | C15: =Q!D4 -> 15.0864 | D15: =C15/B15-1 -> -0.15054054 | E15: =Q!D4 -> 15.0864 | F15: =E15/B15-1 -> -0.15054054 | G15: =Q!D4 -> 15.0864 | H15: =G15/B15-1 -> -0.15054054 | I15: investing.com | J15: 季報 2026-10-30 公布後取代
A16: B. 份額與市場（機制檢查）
A17: FY2025 AI 營收（美元）vs LightCounting 2025 新易盛光模組營收 | B17: =lc_eo25 -> 3.5 | C17: =a25_aiu -> 3.5118899 | D17: =C17/B17-1 -> 0.0033971088 | E17: =a25_aiu -> 3.5118899 | F17: =E17/B17-1 -> 0.0033971088 | G17: =a25_aiu -> 3.5118899 | H17: =G17/B17-1 -> 0.0033971088 | I17: LightCounting | J17: 口徑不同：LightCounting 含全部光模組
A18: FY2026 可插拔有效份額＋中際旭創份額（兩家合計） | C18: =PL!D66+inl_26 -> 0.70273709 | E18: =PL!D98+inl_26 -> 0.70273709 | G18: =PL!D130+inl_26 -> 0.70273709 | I18: innolight 成品 | J18: 合計應明顯低於 100%（另有 Coherent 等）
A19: FY2028 兩家合計可插拔份額 | C19: =PL!F68+inl_28 -> 0.65816838 | E19: =PL!F100+inl_28 -> 0.65816838 | G19: =PL!F132+inl_28 -> 0.65816838 | I19: innolight 成品（情境 A）
A20: FY2026 新易盛 AI 營收 ÷ 中際旭創 AI 營收（美元） | C20: =PL!D71/inl_aiu26 -> 0.57675003 | E20: =PL!D103/inl_aiu26 -> 0.57675003 | G20: =PL!D135/inl_aiu26 -> 0.57675003 | I20: innolight 成品 Units 頁 | J20: 西南證券：1H26 營收約為中際旭創的 50.1%
A21: FY2027 新易盛 AI 營收 ÷ AI IT 資本支出 | C21: =PL!E71/itc_27 -> 0.0088853818 | E21: =PL!E103/itc_27 -> 0.0090345295 | G21: =PL!E135/itc_27 -> 0.0091091034 | I21: markets/network | J21: 每 1 美元 AI IT 資本支出分到的光模組營收
A22: C. 校準與價格
A23: 1H26 EPS（模型）vs 公司揭露 5.41 | B23: =h1_eps -> 5.41 | C23: =Q!C13 -> 5.41 | D23: =C23/B23-1 -> 0 | E23: =Q!C13 -> 5.41 | F23: =E23/B23-1 -> 0 | G23: =Q!C13 -> 5.41 | H23: =G23/B23-1 -> 0 | I23: 公司 | J23: 股數以淨利 ÷ EPS 推導，恆等
A24: FY2026 營業費用率（Derived） | C24: =Q!G9 -> 0.059404295 | E24: =Q!G9 -> 0.059404295 | G24: =Q!G9 -> 0.059404295 | I24: Q 頁殘差
A25: 規則值情境加權價（舊法，參考）vs 高盛目標價 | B25: =gs_tp -> 633 | C25: =Val!B53 -> 1145.9457 | D25: =C25/B25-1 -> 0.81034076 | E25: =Val!B53 -> 1145.9457 | F25: =E25/B25-1 -> 0.81034076 | G25: =Val!B53 -> 1145.9457 | H25: =G25/B25-1 -> 0.81034076 | I25: 高盛（2026-07） | J25: 本模型用十年落後 P/E，高盛用前瞻 29.3x
A26: 規則值情境加權價（舊法，參考）vs 同花順 90 天機構目標均價 | B26: =tp_avg90 -> 460.89 | C26: =Val!B53 -> 1145.9457 | D26: =C26/B26-1 -> 1.4863757 | E26: =Val!B53 -> 1145.9457 | F26: =E26/B26-1 -> 1.4863757 | G26: =Val!B53 -> 1145.9457 | H26: =G26/B26-1 -> 1.4863757 | I26: 同花順（15 家）
A27: D. 預留
A28: R4 產業部署路徑（markets/deploy_path/，尚未建立）：上線後以新易盛 AI 營收 ÷ 部署 GW 計算每 GW 營收 | J28: 預留列：本版無數值
A29: 3Q26 季報（預計 2026-10-30）：公布後以實績取代 Q 頁 3Q 假設 | J29: 預留列：本版無數值

Sheet Sens
A1: Sens — 一次動一個輸入（情境 A；有效份額在每個案例內依 FY2026 錨點重算，FY2026 恆等於錨點）：對 FY2027、FY2028 的營收、AI 營收、毛利率與 EPS 的影響。每個案例是一個完整推導區塊（本頁下方）
A3: 案例 | B3: 設定 | C3: FY2027 營收 | D3: FY2027 AI 營收 | E3: FY2027 毛利率 | F3: FY2027 EPS | G3: FY2027 EPS 相對基準 | H3: FY2028 營收 | I3: FY2028 AI 營收 | J3: FY2028 毛利率 | K3: FY2028 EPS | L3: FY2028 EPS 相對基準
A4: 基準（情境 A） | B4: PL 區塊 A | C4: =PL!E75 -> 96.442187 | D4: =PL!E72 -> 93.466682 | E4: =PL!E79 -> 0.47 | F4: =PL!E88 -> 25.576568 | G4: =F4/F$4-1 -> 0 | H4: =PL!F75 -> 107.77622 | I4: =PL!F72 -> 104.50317 | J4: =PL!F79 -> 0.46 | K4: =PL!F88 -> 28.043343 | L4: =K4/K$4-1 -> 0
A5: 份額流失（低） | B5: 份額相對值 2027 0.80、2028 0.65、2029 0.55（主要客戶轉單、1.6T 落後） | C5: =E55 -> 77.938286 | D5: =E52 -> 74.962781 | E5: =E59 -> 0.47 | F5: =E68 -> 20.513955 | G5: =F5/F$4-1 -> -0.19793948 | H5: =F55 -> 72.715625 | I5: =F52 -> 69.44257 | J5: =F59 -> 0.46 | K5: =F68 -> 18.50977 | L5: =K5/K$4-1 -> -0.33995852
A6: 份額上升（高） | B6: 份額相對值 2027 1.15、2028–29 1.20（搶中際旭創、Coherent 份額） | C6: =E87 -> 110.32011 | D6: =E84 -> 107.34461 | E6: =E91 -> 0.47 | F6: =E100 -> 29.373527 | G6: =F6/F$4-1 -> 0.14845461 | H6: =F87 -> 127.81085 | I6: =F84 -> 124.53779 | J6: =F91 -> 0.46 | K6: =F100 -> 33.43392 | L6: =K6/K$4-1 -> 0.19222306
A7: 美國限制 | B7: 份額相對值 2027 0.90、2028 0.55、2029 0.50（Covered List 擴及光模組） | C7: =E119 -> 87.190236 | D7: =E116 -> 84.214732 | E7: =E123 -> 0.47 | F7: =E132 -> 23.045262 | G7: =F7/F$4-1 -> -0.09896974 | H7: =F119 -> 62.698311 | I7: =F116 -> 59.425257 | J7: =F123 -> 0.46 | K7: =F132 -> 15.399548 | L7: =K7/K$4-1 -> -0.45086617
A8: 降價快於模型 | B8: 單價係數 2027 0.90、2028 0.80、2029 0.72 | C8: =E151 -> 87.190236 | D8: =E148 -> 84.214732 | E8: =E155 -> 0.47 | F8: =E164 -> 23.045262 | G8: =F8/F$4-1 -> -0.09896974 | H8: =F151 -> 87.741595 | I8: =F148 -> 84.468541 | J8: =F155 -> 0.46 | K8: =F164 -> 22.645316 | L8: =K8/K$4-1 -> -0.19248871
A9: 毛利率 低（價格戰） | B9: 毛利率 2027 43%、2028 40%、2029 36% | C9: =E183 -> 96.442187 | D9: =E180 -> 93.466682 | E9: =E187 -> 0.43 | F9: =E196 -> 23.146652 | G9: =F9/F$4-1 -> -0.095005539 | H9: =F183 -> 107.77622 | I9: =F180 -> 104.50317 | J9: =F187 -> 0.4 | K9: =F196 -> 23.970118 | L9: =K9/K$4-1 -> -0.14524747
A10: 毛利率 高 | B10: 毛利率 2027 49%、2028 48%、2029 47% | C10: =E215 -> 96.442187 | D10: =E212 -> 93.466682 | E10: =E219 -> 0.49 | F10: =E228 -> 26.791526 | G10: =F10/F$4-1 -> 0.04750277 | H10: =F215 -> 107.77622 | I10: =F212 -> 104.50317 | J10: =F219 -> 0.48 | K10: =F228 -> 29.401085 | L10: =K10/K$4-1 -> 0.048415824
A11: CPO 份額 0 | B11: 新易盛不參與 CPO 光學 | C11: =E247 -> 95.495008 | D11: =E244 -> 92.519503 | E11: =E251 -> 0.47 | F11: =E260 -> 25.317422 | G11: =F11/F$4-1 -> -0.01013214 | H11: =F247 -> 103.44619 | I11: =F244 -> 100.17314 | J11: =F251 -> 0.46 | K11: =F260 -> 26.872198 | L11: =K11/K$4-1 -> -0.041761946
A12: CPO 份額 高 | B12: 2027 20%、2028 25%、2029 30% | C12: =E279 -> 99.283723 | D12: =E276 -> 96.308219 | E12: =E283 -> 0.47 | F12: =E292 -> 26.354004 | G12: =F12/F$4-1 -> 0.03039642 | H12: =F279 -> 114.27127 | I12: =F276 -> 110.99822 | J12: =F283 -> 0.46 | K12: =F292 -> 29.796023 | L12: =K12/K$4-1 -> 0.062498971
A13: AI 市場 ×0.8 | B13: FY2027 起可插拔光模組市場 ×0.8 | C13: =E311 -> 77.938286 | D13: =E308 -> 74.962781 | E13: =E315 -> 0.47 | F13: =E324 -> 20.513955 | G13: =F13/F$4-1 -> -0.19793948 | H13: =F311 -> 87.741595 | I13: =F308 -> 84.468541 | J13: =F315 -> 0.46 | K13: =F324 -> 22.670364 | L13: =K13/K$4-1 -> -0.19159552
A14: AI 市場 ×1.2 | B14: ×1.2 | C14: =E343 -> 114.94609 | D14: =E340 -> 111.97058 | E14: =E347 -> 0.47 | F14: =E356 -> 30.63918 | G14: =F14/F$4-1 -> 0.19793948 | H14: =F343 -> 127.81085 | I14: =F340 -> 124.53779 | J14: =F347 -> 0.46 | K14: =F356 -> 33.41503 | L14: =K14/K$4-1 -> 0.19154944
A15: 人民幣升值（6.9） | B15: FY2027 起 RMB／USD 6.9 | C15: =E375 -> 93.382265 | D15: =E372 -> 90.406761 | E15: =E379 -> 0.47 | F15: =E388 -> 24.739382 | G15: =F15/F$4-1 -> -0.032732515 | H15: =F375 -> 104.35499 | I15: =F372 -> 101.08193 | J15: =F379 -> 0.46 | K15: =F388 -> 27.125617 | L15: =K15/K$4-1 -> -0.032725255
A16: 人民幣貶值（7.3） | B16: FY2027 起 7.3 | C16: =E407 -> 100.33663 | D16: =E404 -> 97.361127 | E16: =E411 -> 0.47 | F16: =E420 -> 26.642077 | G16: =F16/F$4-1 -> 0.041659564 | H16: =F407 -> 112.13052 | I16: =F404 -> 108.85747 | J16: =F411 -> 0.46 | K16: =F420 -> 29.211358 | L16: =K16/K$4-1 -> 0.041650352
A17: 營業費用率 +2pt | B17: 營業費用額外 +2% × 營收 | C17: =E439 -> 96.442187 | D17: =E436 -> 93.466682 | E17: =E443 -> 0.47 | F17: =E452 -> 24.36161 | G17: =F17/F$4-1 -> -0.04750277 | H17: =F439 -> 107.77622 | I17: =F436 -> 104.50317 | J17: =F443 -> 0.46 | K17: =F452 -> 26.685601 | L17: =K17/K$4-1 -> -0.048415824
A18: 營業費用彈性 1.0 | B18: phi＝1.0（費用與營收同步成長） | C18: =E471 -> 96.442187 | D18: =E468 -> 93.466682 | E18: =E475 -> 0.47 | F18: =E484 -> 24.942823 | G18: =F18/F$4-1 -> -0.024778339 | H18: =F471 -> 107.77622 | I18: =F468 -> 104.50317 | J18: =F475 -> 0.46 | K18: =F484 -> 27.195272 | L18: =K18/K$4-1 -> -0.030241452
A19: 顆數情境 B | B19: CY2028 ×0.8、CY2029 ×0.85；CPO 情境 B | C19: =PL!E107 -> 98.011094 | D19: =PL!E104 -> 95.03559 | E19: =PL!E111 -> 0.47 | F19: =PL!E120 -> 26.005816 | G19: =F19/F$4-1 -> 0.016782879 | H19: =PL!F107 -> 89.595716 | I19: =PL!F104 -> 86.322661 | J19: =PL!F111 -> 0.46 | K19: =PL!F120 -> 22.950107 | L19: =K19/K$4-1 -> -0.18162013
A20: 顆數情境 C | B20: CY2028–29 ×0.6；CPO 情境 C | C20: =PL!E139 -> 98.795548 | D20: =PL!E136 -> 95.820043 | E20: =PL!E143 -> 0.47 | F20: =PL!E152 -> 26.220441 | G20: =F20/F$4-1 -> 0.025174318 | H20: =PL!F139 -> 68.831088 | I20: =PL!F136 -> 65.558033 | J20: =PL!F143 -> 0.46 | K20: =PL!F152 -> 16.915965 | L20: =K20/K$4-1 -> -0.39679213
A22: 讀法：FY2027 三情境只差在網通 CPO 情境（A 替代快、C 慢）；顆數差異從 FY2028 起。「美國限制」「份額流失」「降價」「毛利率」四案例對應市場隱含衰退的路徑；新易盛境外營收占九成七以上，美國限制與主要客戶轉單是最大的單一風險。
A24: 目標價參數（只改 DCF 參數與權重；PL 收斂法的 fade_g 不隨 tp_g 變動）
A25: 案例 | B25: 設定 | C25: DCF 目標價 | D25: Comparable 目標價（相對倍數調整後） | E25: 加權目標價 | F25: 相對基準
A26: 基準 | B26: r 10%、g 4%、DCF 權重 0.5 | C26: =(tp_wA*(Val!B8*(1-IF(tp_roe<=tp_g,0.8,MIN(tp_g/tp_roe,0.8)))/(1+tp_r)^1+Val!B9*(1-IF(tp_roe<=tp_g,0.8,MIN(tp_g/tp_roe,0.8)))/(1+tp_r)^2+Val!B10*(1-IF(tp_roe<=tp_g,0.8,MIN(tp_g/tp_roe,0.8)))/(1+tp_r)^3+Val!B11*(1-IF(tp_roe<=tp_g,0.8,MIN(tp_g/tp_roe,0.8)))/(1+tp_r)^4+Val!B12*(1-IF(tp_roe<=tp_g,0.8,MIN(tp_g/tp_roe,0.8)))/(1+tp_r)^5+Val!B13*(1-IF(tp_roe<=tp_g,0.8,MIN(tp_g/tp_roe,0.8)))/(1+tp_r)^6+Val!B13*(1-IF(tp_roe<=tp_g,0.8,MIN(tp_g/tp_roe,0.8)))*(1+tp_g)/(tp_r-tp_g)/(1+tp_r)^6)+tp_wB*(Val!C8*(1-IF(tp_roe<=tp_g,0.8,MIN(tp_g/tp_roe,0.8)))/(1+tp_r)^1+Val!C9*(1-IF(tp_roe<=tp_g,0.8,MIN(tp_g/tp_roe,0.8)))/(1+tp_r)^2+Val!C10*(1-IF(tp_roe<=tp_g,0.8,MIN(tp_g/tp_roe,0.8)))/(1+tp_r)^3+Val!C11*(1-IF(tp_roe<=tp_g,0.8,MIN(tp_g/tp_roe,0.8)))/(1+tp_r)^4+Val!C12*(1-IF(tp_roe<=tp_g,0.8,MIN(tp_g/tp_roe,0.8)))/(1+tp_r)^5+Val!C13*(1-IF(tp_roe<=tp_g,0.8,MIN(tp_g/tp_roe,0.8)))/(1+tp_r)^6+Val!C13*(1-IF(tp_roe<=tp_g,0.8,MIN(tp_g/tp_roe,0.8)))*(1+tp_g)/(tp_r-tp_g)/(1+tp_r)^6)+tp_wC*(Val!D8*(1-IF(tp_roe<=tp_g,0.8,MIN(tp_g/tp_roe,0.8)))/(1+tp_r)^1+Val!D9*(1-IF(tp_roe<=tp_g,0.8,MIN(tp_g/tp_roe,0.8)))/(1+tp_r)^2+Val!D10*(1-IF(tp_roe<=tp_g,0.8,MIN(tp_g/tp_roe,0.8)))/(1+tp_r)^3+Val!D11*(1-IF(tp_roe<=tp_g,0.8,MIN(tp_g/tp_roe,0.8)))/(1+tp_r)^4+Val!D12*(1-IF(tp_roe<=tp_g,0.8,MIN(tp_g/tp_roe,0.8)))/(1+tp_r)^5+Val!D13*(1-IF(tp_roe<=tp_g,0.8,MIN(tp_g/tp_roe,0.8)))/(1+tp_r)^6+Val!D13*(1-IF(tp_roe<=tp_g,0.8,MIN(tp_g/tp_roe,0.8)))*(1+tp_g)/(tp_r-tp_g)/(1+tp_r)^6))*(1+tp_r) -> 510.23134 | D26: =tp_comp_adj -> 901.03807 | E26: =tp_w_dcf*C26+(1-tp_w_dcf)*D26 -> 705.6347 | F26: =E26/E$26-1 -> 0
A27: 折現率 +1pt | B27: r 11% | C27: =(tp_wA*(Val!B8*(1-IF(tp_roe<=tp_g,0.8,MIN(tp_g/tp_roe,0.8)))/(1+(tp_r+0.01))^1+Val!B9*(1-IF(tp_roe<=tp_g,0.8,MIN(tp_g/tp_roe,0.8)))/(1+(tp_r+0.01))^2+Val!B10*(1-IF(tp_roe<=tp_g,0.8,MIN(tp_g/tp_roe,0.8)))/(1+(tp_r+0.01))^3+Val!B11*(1-IF(tp_roe<=tp_g,0.8,MIN(tp_g/tp_roe,0.8)))/(1+(tp_r+0.01))^4+Val!B12*(1-IF(tp_roe<=tp_g,0.8,MIN(tp_g/tp_roe,0.8)))/(1+(tp_r+0.01))^5+Val!B13*(1-IF(tp_roe<=tp_g,0.8,MIN(tp_g/tp_roe,0.8)))/(1+(tp_r+0.01))^6+Val!B13*(1-IF(tp_roe<=tp_g,0.8,MIN(tp_g/tp_roe,0.8)))*(1+tp_g)/((tp_r+0.01)-tp_g)/(1+(tp_r+0.01))^6)+tp_wB*(Val!C8*(1-IF(tp_roe<=tp_g,0.8,MIN(tp_g/tp_roe,0.8)))/(1+(tp_r+0.01))^1+Val!C9*(1-IF(tp_roe<=tp_g,0.8,MIN(tp_g/tp_roe,0.8)))/(1+(tp_r+0.01))^2+Val!C10*(1-IF(tp_roe<=tp_g,0.8,MIN(tp_g/tp_roe,0.8)))/(1+(tp_r+0.01))^3+Val!C11*(1-IF(tp_roe<=tp_g,0.8,MIN(tp_g/tp_roe,0.8)))/(1+(tp_r+0.01))^4+Val!C12*(1-IF(tp_roe<=tp_g,0.8,MIN(tp_g/tp_roe,0.8)))/(1+(tp_r+0.01))^5+Val!C13*(1-IF(tp_roe<=tp_g,0.8,MIN(tp_g/tp_roe,0.8)))/(1+(tp_r+0.01))^6+Val!C13*(1-IF(tp_roe<=tp_g,0.8,MIN(tp_g/tp_roe,0.8)))*(1+tp_g)/((tp_r+0.01)-tp_g)/(1+(tp_r+0.01))^6)+tp_wC*(Val!D8*(1-IF(tp_roe<=tp_g,0.8,MIN(tp_g/tp_roe,0.8)))/(1+(tp_r+0.01))^1+Val!D9*(1-IF(tp_roe<=tp_g,0.8,MIN(tp_g/tp_roe,0.8)))/(1+(tp_r+0.01))^2+Val!D10*(1-IF(tp_roe<=tp_g,0.8,MIN(tp_g/tp_roe,0.8)))/(1+(tp_r+0.01))^3+Val!D11*(1-IF(tp_roe<=tp_g,0.8,MIN(tp_g/tp_roe,0.8)))/(1+(tp_r+0.01))^4+Val!D12*(1-IF(tp_roe<=tp_g,0.8,MIN(tp_g/tp_roe,0.8)))/(1+(tp_r+0.01))^5+Val!D13*(1-IF(tp_roe<=tp_g,0.8,MIN(tp_g/tp_roe,0.8)))/(1+(tp_r+0.01))^6+Val!D13*(1-IF(tp_roe<=tp_g,0.8,MIN(tp_g/tp_roe,0.8)))*(1+tp_g)/((tp_r+0.01)-tp_g)/(1+(tp_r+0.01))^6))*(1+(tp_r+0.01)) -> 439.14596 | D27: =tp_comp_adj -> 901.03807 | E27: =tp_w_dcf*C27+(1-tp_w_dcf)*D27 -> 670.09201 | F27: =E27/E$26-1 -> -0.050369815
A28: 折現率 −1pt | B28: r 9% | C28: =(tp_wA*(Val!B8*(1-IF(tp_roe<=tp_g,0.8,MIN(tp_g/tp_roe,0.8)))/(1+(tp_r-0.01))^1+Val!B9*(1-IF(tp_roe<=tp_g,0.8,MIN(tp_g/tp_roe,0.8)))/(1+(tp_r-0.01))^2+Val!B10*(1-IF(tp_roe<=tp_g,0.8,MIN(tp_g/tp_roe,0.8)))/(1+(tp_r-0.01))^3+Val!B11*(1-IF(tp_roe<=tp_g,0.8,MIN(tp_g/tp_roe,0.8)))/(1+(tp_r-0.01))^4+Val!B12*(1-IF(tp_roe<=tp_g,0.8,MIN(tp_g/tp_roe,0.8)))/(1+(tp_r-0.01))^5+Val!B13*(1-IF(tp_roe<=tp_g,0.8,MIN(tp_g/tp_roe,0.8)))/(1+(tp_r-0.01))^6+Val!B13*(1-IF(tp_roe<=tp_g,0.8,MIN(tp_g/tp_roe,0.8)))*(1+tp_g)/((tp_r-0.01)-tp_g)/(1+(tp_r-0.01))^6)+tp_wB*(Val!C8*(1-IF(tp_roe<=tp_g,0.8,MIN(tp_g/tp_roe,0.8)))/(1+(tp_r-0.01))^1+Val!C9*(1-IF(tp_roe<=tp_g,0.8,MIN(tp_g/tp_roe,0.8)))/(1+(tp_r-0.01))^2+Val!C10*(1-IF(tp_roe<=tp_g,0.8,MIN(tp_g/tp_roe,0.8)))/(1+(tp_r-0.01))^3+Val!C11*(1-IF(tp_roe<=tp_g,0.8,MIN(tp_g/tp_roe,0.8)))/(1+(tp_r-0.01))^4+Val!C12*(1-IF(tp_roe<=tp_g,0.8,MIN(tp_g/tp_roe,0.8)))/(1+(tp_r-0.01))^5+Val!C13*(1-IF(tp_roe<=tp_g,0.8,MIN(tp_g/tp_roe,0.8)))/(1+(tp_r-0.01))^6+Val!C13*(1-IF(tp_roe<=tp_g,0.8,MIN(tp_g/tp_roe,0.8)))*(1+tp_g)/((tp_r-0.01)-tp_g)/(1+(tp_r-0.01))^6)+tp_wC*(Val!D8*(1-IF(tp_roe<=tp_g,0.8,MIN(tp_g/tp_roe,0.8)))/(1+(tp_r-0.01))^1+Val!D9*(1-IF(tp_roe<=tp_g,0.8,MIN(tp_g/tp_roe,0.8)))/(1+(tp_r-0.01))^2+Val!D10*(1-IF(tp_roe<=tp_g,0.8,MIN(tp_g/tp_roe,0.8)))/(1+(tp_r-0.01))^3+Val!D11*(1-IF(tp_roe<=tp_g,0.8,MIN(tp_g/tp_roe,0.8)))/(1+(tp_r-0.01))^4+Val!D12*(1-IF(tp_roe<=tp_g,0.8,MIN(tp_g/tp_roe,0.8)))/(1+(tp_r-0.01))^5+Val!D13*(1-IF(tp_roe<=tp_g,0.8,MIN(tp_g/tp_roe,0.8)))/(1+(tp_r-0.01))^6+Val!D13*(1-IF(tp_roe<=tp_g,0.8,MIN(tp_g/tp_roe,0.8)))*(1+tp_g)/((tp_r-0.01)-tp_g)/(1+(tp_r-0.01))^6))*(1+(tp_r-0.01)) -> 609.80251 | D28: =tp_comp_adj -> 901.03807 | E28: =tp_w_dcf*C28+(1-tp_w_dcf)*D28 -> 755.42029 | F28: =E28/E$26-1 -> 0.070554333
A29: 長期成長 +1pt | B29: g 5% | C29: =(tp_wA*(Val!B8*(1-IF(tp_roe<=(tp_g+0.01),0.8,MIN((tp_g+0.01)/tp_roe,0.8)))/(1+tp_r)^1+Val!B9*(1-IF(tp_roe<=(tp_g+0.01),0.8,MIN((tp_g+0.01)/tp_roe,0.8)))/(1+tp_r)^2+Val!B10*(1-IF(tp_roe<=(tp_g+0.01),0.8,MIN((tp_g+0.01)/tp_roe,0.8)))/(1+tp_r)^3+Val!B11*(1-IF(tp_roe<=(tp_g+0.01),0.8,MIN((tp_g+0.01)/tp_roe,0.8)))/(1+tp_r)^4+Val!B12*(1-IF(tp_roe<=(tp_g+0.01),0.8,MIN((tp_g+0.01)/tp_roe,0.8)))/(1+tp_r)^5+Val!B13*(1-IF(tp_roe<=(tp_g+0.01),0.8,MIN((tp_g+0.01)/tp_roe,0.8)))/(1+tp_r)^6+Val!B13*(1-IF(tp_roe<=(tp_g+0.01),0.8,MIN((tp_g+0.01)/tp_roe,0.8)))*(1+(tp_g+0.01))/(tp_r-(tp_g+0.01))/(1+tp_r)^6)+tp_wB*(Val!C8*(1-IF(tp_roe<=(tp_g+0.01),0.8,MIN((tp_g+0.01)/tp_roe,0.8)))/(1+tp_r)^1+Val!C9*(1-IF(tp_roe<=(tp_g+0.01),0.8,MIN((tp_g+0.01)/tp_roe,0.8)))/(1+tp_r)^2+Val!C10*(1-IF(tp_roe<=(tp_g+0.01),0.8,MIN((tp_g+0.01)/tp_roe,0.8)))/(1+tp_r)^3+Val!C11*(1-IF(tp_roe<=(tp_g+0.01),0.8,MIN((tp_g+0.01)/tp_roe,0.8)))/(1+tp_r)^4+Val!C12*(1-IF(tp_roe<=(tp_g+0.01),0.8,MIN((tp_g+0.01)/tp_roe,0.8)))/(1+tp_r)^5+Val!C13*(1-IF(tp_roe<=(tp_g+0.01),0.8,MIN((tp_g+0.01)/tp_roe,0.8)))/(1+tp_r)^6+Val!C13*(1-IF(tp_roe<=(tp_g+0.01),0.8,MIN((tp_g+0.01)/tp_roe,0.8)))*(1+(tp_g+0.01))/(tp_r-(tp_g+0.01))/(1+tp_r)^6)+tp_wC*(Val!D8*(1-IF(tp_roe<=(tp_g+0.01),0.8,MIN((tp_g+0.01)/tp_roe,0.8)))/(1+tp_r)^1+Val!D9*(1-IF(tp_roe<=(tp_g+0.01),0.8,MIN((tp_g+0.01)/tp_roe,0.8)))/(1+tp_r)^2+Val!D10*(1-IF(tp_roe<=(tp_g+0.01),0.8,MIN((tp_g+0.01)/tp_roe,0.8)))/(1+tp_r)^3+Val!D11*(1-IF(tp_roe<=(tp_g+0.01),0.8,MIN((tp_g+0.01)/tp_roe,0.8)))/(1+tp_r)^4+Val!D12*(1-IF(tp_roe<=(tp_g+0.01),0.8,MIN((tp_g+0.01)/tp_roe,0.8)))/(1+tp_r)^5+Val!D13*(1-IF(tp_roe<=(tp_g+0.01),0.8,MIN((tp_g+0.01)/tp_roe,0.8)))/(1+tp_r)^6+Val!D13*(1-IF(tp_roe<=(tp_g+0.01),0.8,MIN((tp_g+0.01)/tp_roe,0.8)))*(1+(tp_g+0.01))/(tp_r-(tp_g+0.01))/(1+tp_r)^6))*(1+tp_r) -> 574.50074 | D29: =tp_comp_adj -> 901.03807 | E29: =tp_w_dcf*C29+(1-tp_w_dcf)*D29 -> 737.76941 | F29: =E29/E$26-1 -> 0.045540138
A30: 長期成長 −1pt | B30: g 3% | C30: =(tp_wA*(Val!B8*(1-IF(tp_roe<=(tp_g-0.01),0.8,MIN((tp_g-0.01)/tp_roe,0.8)))/(1+tp_r)^1+Val!B9*(1-IF(tp_roe<=(tp_g-0.01),0.8,MIN((tp_g-0.01)/tp_roe,0.8)))/(1+tp_r)^2+Val!B10*(1-IF(tp_roe<=(tp_g-0.01),0.8,MIN((tp_g-0.01)/tp_roe,0.8)))/(1+tp_r)^3+Val!B11*(1-IF(tp_roe<=(tp_g-0.01),0.8,MIN((tp_g-0.01)/tp_roe,0.8)))/(1+tp_r)^4+Val!B12*(1-IF(tp_roe<=(tp_g-0.01),0.8,MIN((tp_g-0.01)/tp_roe,0.8)))/(1+tp_r)^5+Val!B13*(1-IF(tp_roe<=(tp_g-0.01),0.8,MIN((tp_g-0.01)/tp_roe,0.8)))/(1+tp_r)^6+Val!B13*(1-IF(tp_roe<=(tp_g-0.01),0.8,MIN((tp_g-0.01)/tp_roe,0.8)))*(1+(tp_g-0.01))/(tp_r-(tp_g-0.01))/(1+tp_r)^6)+tp_wB*(Val!C8*(1-IF(tp_roe<=(tp_g-0.01),0.8,MIN((tp_g-0.01)/tp_roe,0.8)))/(1+tp_r)^1+Val!C9*(1-IF(tp_roe<=(tp_g-0.01),0.8,MIN((tp_g-0.01)/tp_roe,0.8)))/(1+tp_r)^2+Val!C10*(1-IF(tp_roe<=(tp_g-0.01),0.8,MIN((tp_g-0.01)/tp_roe,0.8)))/(1+tp_r)^3+Val!C11*(1-IF(tp_roe<=(tp_g-0.01),0.8,MIN((tp_g-0.01)/tp_roe,0.8)))/(1+tp_r)^4+Val!C12*(1-IF(tp_roe<=(tp_g-0.01),0.8,MIN((tp_g-0.01)/tp_roe,0.8)))/(1+tp_r)^5+Val!C13*(1-IF(tp_roe<=(tp_g-0.01),0.8,MIN((tp_g-0.01)/tp_roe,0.8)))/(1+tp_r)^6+Val!C13*(1-IF(tp_roe<=(tp_g-0.01),0.8,MIN((tp_g-0.01)/tp_roe,0.8)))*(1+(tp_g-0.01))/(tp_r-(tp_g-0.01))/(1+tp_r)^6)+tp_wC*(Val!D8*(1-IF(tp_roe<=(tp_g-0.01),0.8,MIN((tp_g-0.01)/tp_roe,0.8)))/(1+tp_r)^1+Val!D9*(1-IF(tp_roe<=(tp_g-0.01),0.8,MIN((tp_g-0.01)/tp_roe,0.8)))/(1+tp_r)^2+Val!D10*(1-IF(tp_roe<=(tp_g-0.01),0.8,MIN((tp_g-0.01)/tp_roe,0.8)))/(1+tp_r)^3+Val!D11*(1-IF(tp_roe<=(tp_g-0.01),0.8,MIN((tp_g-0.01)/tp_roe,0.8)))/(1+tp_r)^4+Val!D12*(1-IF(tp_roe<=(tp_g-0.01),0.8,MIN((tp_g-0.01)/tp_roe,0.8)))/(1+tp_r)^5+Val!D13*(1-IF(tp_roe<=(tp_g-0.01),0.8,MIN((tp_g-0.01)/tp_roe,0.8)))/(1+tp_r)^6+Val!D13*(1-IF(tp_roe<=(tp_g-0.01),0.8,MIN((tp_g-0.01)/tp_roe,0.8)))*(1+(tp_g-0.01))/(tp_r-(tp_g-0.01))/(1+tp_r)^6))*(1+tp_r) -> 465.15918 | D30: =tp_comp_adj -> 901.03807 | E30: =tp_w_dcf*C30+(1-tp_w_dcf)*D30 -> 683.09863 | F30: =E30/E$26-1 -> -0.031937312
A31: DCF 權重 0.3 | B31: Comparable 0.7 | C31: =(tp_wA*(Val!B8*(1-IF(tp_roe<=tp_g,0.8,MIN(tp_g/tp_roe,0.8)))/(1+tp_r)^1+Val!B9*(1-IF(tp_roe<=tp_g,0.8,MIN(tp_g/tp_roe,0.8)))/(1+tp_r)^2+Val!B10*(1-IF(tp_roe<=tp_g,0.8,MIN(tp_g/tp_roe,0.8)))/(1+tp_r)^3+Val!B11*(1-IF(tp_roe<=tp_g,0.8,MIN(tp_g/tp_roe,0.8)))/(1+tp_r)^4+Val!B12*(1-IF(tp_roe<=tp_g,0.8,MIN(tp_g/tp_roe,0.8)))/(1+tp_r)^5+Val!B13*(1-IF(tp_roe<=tp_g,0.8,MIN(tp_g/tp_roe,0.8)))/(1+tp_r)^6+Val!B13*(1-IF(tp_roe<=tp_g,0.8,MIN(tp_g/tp_roe,0.8)))*(1+tp_g)/(tp_r-tp_g)/(1+tp_r)^6)+tp_wB*(Val!C8*(1-IF(tp_roe<=tp_g,0.8,MIN(tp_g/tp_roe,0.8)))/(1+tp_r)^1+Val!C9*(1-IF(tp_roe<=tp_g,0.8,MIN(tp_g/tp_roe,0.8)))/(1+tp_r)^2+Val!C10*(1-IF(tp_roe<=tp_g,0.8,MIN(tp_g/tp_roe,0.8)))/(1+tp_r)^3+Val!C11*(1-IF(tp_roe<=tp_g,0.8,MIN(tp_g/tp_roe,0.8)))/(1+tp_r)^4+Val!C12*(1-IF(tp_roe<=tp_g,0.8,MIN(tp_g/tp_roe,0.8)))/(1+tp_r)^5+Val!C13*(1-IF(tp_roe<=tp_g,0.8,MIN(tp_g/tp_roe,0.8)))/(1+tp_r)^6+Val!C13*(1-IF(tp_roe<=tp_g,0.8,MIN(tp_g/tp_roe,0.8)))*(1+tp_g)/(tp_r-tp_g)/(1+tp_r)^6)+tp_wC*(Val!D8*(1-IF(tp_roe<=tp_g,0.8,MIN(tp_g/tp_roe,0.8)))/(1+tp_r)^1+Val!D9*(1-IF(tp_roe<=tp_g,0.8,MIN(tp_g/tp_roe,0.8)))/(1+tp_r)^2+Val!D10*(1-IF(tp_roe<=tp_g,0.8,MIN(tp_g/tp_roe,0.8)))/(1+tp_r)^3+Val!D11*(1-IF(tp_roe<=tp_g,0.8,MIN(tp_g/tp_roe,0.8)))/(1+tp_r)^4+Val!D12*(1-IF(tp_roe<=tp_g,0.8,MIN(tp_g/tp_roe,0.8)))/(1+tp_r)^5+Val!D13*(1-IF(tp_roe<=tp_g,0.8,MIN(tp_g/tp_roe,0.8)))/(1+tp_r)^6+Val!D13*(1-IF(tp_roe<=tp_g,0.8,MIN(tp_g/tp_roe,0.8)))*(1+tp_g)/(tp_r-tp_g)/(1+tp_r)^6))*(1+tp_r) -> 510.23134 | D31: =tp_comp_adj -> 901.03807 | E31: =0.3*C31+(1-0.3)*D31 -> 783.79605 | F31: =E31/E$26-1 -> 0.11076744
A32: DCF 權重 0.7 | B32: Comparable 0.3 | C32: =(tp_wA*(Val!B8*(1-IF(tp_roe<=tp_g,0.8,MIN(tp_g/tp_roe,0.8)))/(1+tp_r)^1+Val!B9*(1-IF(tp_roe<=tp_g,0.8,MIN(tp_g/tp_roe,0.8)))/(1+tp_r)^2+Val!B10*(1-IF(tp_roe<=tp_g,0.8,MIN(tp_g/tp_roe,0.8)))/(1+tp_r)^3+Val!B11*(1-IF(tp_roe<=tp_g,0.8,MIN(tp_g/tp_roe,0.8)))/(1+tp_r)^4+Val!B12*(1-IF(tp_roe<=tp_g,0.8,MIN(tp_g/tp_roe,0.8)))/(1+tp_r)^5+Val!B13*(1-IF(tp_roe<=tp_g,0.8,MIN(tp_g/tp_roe,0.8)))/(1+tp_r)^6+Val!B13*(1-IF(tp_roe<=tp_g,0.8,MIN(tp_g/tp_roe,0.8)))*(1+tp_g)/(tp_r-tp_g)/(1+tp_r)^6)+tp_wB*(Val!C8*(1-IF(tp_roe<=tp_g,0.8,MIN(tp_g/tp_roe,0.8)))/(1+tp_r)^1+Val!C9*(1-IF(tp_roe<=tp_g,0.8,MIN(tp_g/tp_roe,0.8)))/(1+tp_r)^2+Val!C10*(1-IF(tp_roe<=tp_g,0.8,MIN(tp_g/tp_roe,0.8)))/(1+tp_r)^3+Val!C11*(1-IF(tp_roe<=tp_g,0.8,MIN(tp_g/tp_roe,0.8)))/(1+tp_r)^4+Val!C12*(1-IF(tp_roe<=tp_g,0.8,MIN(tp_g/tp_roe,0.8)))/(1+tp_r)^5+Val!C13*(1-IF(tp_roe<=tp_g,0.8,MIN(tp_g/tp_roe,0.8)))/(1+tp_r)^6+Val!C13*(1-IF(tp_roe<=tp_g,0.8,MIN(tp_g/tp_roe,0.8)))*(1+tp_g)/(tp_r-tp_g)/(1+tp_r)^6)+tp_wC*(Val!D8*(1-IF(tp_roe<=tp_g,0.8,MIN(tp_g/tp_roe,0.8)))/(1+tp_r)^1+Val!D9*(1-IF(tp_roe<=tp_g,0.8,MIN(tp_g/tp_roe,0.8)))/(1+tp_r)^2+Val!D10*(1-IF(tp_roe<=tp_g,0.8,MIN(tp_g/tp_roe,0.8)))/(1+tp_r)^3+Val!D11*(1-IF(tp_roe<=tp_g,0.8,MIN(tp_g/tp_roe,0.8)))/(1+tp_r)^4+Val!D12*(1-IF(tp_roe<=tp_g,0.8,MIN(tp_g/tp_roe,0.8)))/(1+tp_r)^5+Val!D13*(1-IF(tp_roe<=tp_g,0.8,MIN(tp_g/tp_roe,0.8)))/(1+tp_r)^6+Val!D13*(1-IF(tp_roe<=tp_g,0.8,MIN(tp_g/tp_roe,0.8)))*(1+tp_g)/(tp_r-tp_g)/(1+tp_r)^6))*(1+tp_r) -> 510.23134 | D32: =tp_comp_adj -> 901.03807 | E32: =0.7*C32+(1-0.7)*D32 -> 627.47336 | F32: =E32/E$26-1 -> -0.11076744
A40: 案例區塊：份額流失（低）（情境 A）
A41: 項目 | B41: 單位 | C41: FY2025A | D41: FY2026（錨點） | E41: FY2027 | F41: FY2028 | G41: FY2029 | H41: 說明
A42: A. AI 營收（D 欄＝FY2026 校準年；E–G＝FY2027–FY2029）
A43: AI 可插拔光模組市場 × 情境顆數係數 | B43: US$B | D43: =mpl_26*1 -> 29.753262 | E43: =mpl_27*1*1 -> 53.560715 | F43: =mpl_28*um28_A*1 -> 57.9915 | G43: =mpl_29*um29_A*1 -> 72.9348
A44: AI CPO 光學市場 × 情境顆數係數 | B44: US$B | D44: =mcp_26*1 -> 0.300538 | E44: =mcp_27*1 -> 2.818985 | F44: =mcp_28*um28_A -> 6.4435 | G44: =mcp_29*um29_A -> 11.74736
A45: 人民幣兌美元 | B45: RMB | D45: =fx -> 6.72 | E45: =fx -> 6.72 | F45: =fx -> 6.72 | G45: =fx -> 6.72 | H45: FY2026 校準用基準匯率；Sens 只動 FY2027 起
A46: 新易盛可插拔有效份額（FY2026 校準）＝ AI 營收（美元）÷ 可插拔市場 | B46: % | D46: =a26_aiu/D43 -> 0.25705003 | H46: Derived：FY2026 CPO 營收視為 0；FY2027 起乘相對值
A47: 份額相對值（÷ FY2026） | B47: x | D47: =1 -> 1 | E47: =RLO_27 -> 0.8 | F47: =RLO_28 -> 0.65 | G47: =RLO_29 -> 0.55
A48: 可插拔有效份額 | B48: % | D48: =$D$46*D47 -> 0.25705003 | E48: =$D$46*E47 -> 0.20564002 | F48: =$D$46*F47 -> 0.16708252 | G48: =$D$46*G47 -> 0.14137751
A49: 單價係數（相對網通模型） | B49: x | D49: =1 -> 1 | E49: =pxr_27 -> 1 | F49: =pxr_28 -> 1 | G49: =pxr_29 -> 1
A50: 新易盛占 CPO 光學金額 | B50: % | D50: =0 -> 0 | E50: =cpo_27 -> 0.05 | F50: =cpo_28 -> 0.1 | G50: =cpo_29 -> 0.15
...

Sheet Sources
A1: 來源（公司原文＝深交所定期報告與公告，經財經媒體轉載；原文 PDF 待人工複核）
A2: 公司（轉載）：FY2025 營收、歸母淨利、EPS、10 轉 4 派 10（東方財富／中證網） | B2: https://finance.eastmoney.com/a/202604243717729349.html
A3: 公司（轉載）：FY2025 光互聯毛利率、4Q25、1Q26 實績與匯兌損失（每日經濟新聞） | B3: https://www.nbd.com.cn/articles/2026-04-24/4356482.html
A4: 公司（轉載）：FY2025 存貨、減值、1Q26 季減（虎嗅） | B4: https://www.huxiu.com/article/4853326.html
A5: 公司（轉載）：1H26 實績、光互聯毛利率 48.46%、境外收入、研發（C114） | B5: https://m.c114.com.cn/w123-1316262.html
A6: 公司（轉載）：1H26 基本 EPS 5.41（東方財富） | B6: https://finance.eastmoney.com/a/202608243851382445.html
A7: 券商：西南證券 9-15（1H26 綜合毛利率 48.44%、境外 97.92%、與中際旭創比較） | B7: https://stock.10jqka.com.cn/20260915/c679905127.shtml
A8: 券商：長江證券（2Q26 毛利率 47.96%、淨利率 37.77%） | B8: https://m.gelonghui.com/news/5306856
A9: 券商：開源證券 8-25（總股本 13.94 億、少數股東損益、費用率） | B9: https://pdf.dfcfw.com/pdf/H3_AP202608251828397684_1.pdf
A10: 券商：天風證券 10-10（2Q26、產能、盈利預測） | B10: https://stock.10jqka.com.cn/20261010/c680549851.shtml
A11: 公司（轉載）：2026 年限制性股票激勵（同花順） | B11: https://stock.10jqka.com.cn/20260820/c679144690.shtml
A12: 公司說法（轉載）：NPO 2027 批量、1.6T 下半年放量（同花順 9-28） | B12: https://stock.10jqka.com.cn/20260928/c680329640.shtml
A13: 共識：同花順 F10 盈利預測（2026-10-23） | B13: https://basic.10jqka.com.cn/300502/worth.html
... A21: 資料商：stockanalysis 會計年底 P/E | B21: https://stockanalysis.com/quote/she/300502/financials/ratios/
A22: 市場層：markets/network、tsmc、innolight 成品（本 repo，唯讀）
A23: 待補（人工）：3Q26 季報（10-30）；全公司 FY2025 毛利率；客戶名稱與集中度；800G／1.6T 份額第一手來源；泰國子公司稅率；52 週高點（資料商不一致）；近一個月跌幅原因；前瞻 P/E 歷史（Bloomberg） | B23: 未找到
A24: SemiAnalysis | B24: 未使用
