Workbook

Sheet README
A1: 奇鋐（3017）收支與估值模型 v0.2（AI 半導體 Project：電源與散熱次產業；樣板＝台達電） 2026-10-25
A2: 版本：v0.2（2026-10-25：目標價改為 DCF 與 Comparable 加權、三情境延伸到 FY2032；FY2025–FY2029 數值不變）。前版：v0.1.1（2026-10-25：Val 新增第 0 節「目標價與上檔空間」、In 新增情境權重 tp_wA／tp_wB／tp_wC；其餘數值與 v0.1 相同）。v0.1（初版）：每架液冷內容取自橋接表（Morgan Stanley BOM）；液冷滲透率、每架內容調整、奇鋐份額為本模型 Assumed，在 Units 頁建立。台達電液冷線只在 Recon 對帳。
A3: 模型命題：奇鋐的 AI 營收＝部署 GW（AI IT 資本支出 ÷ 每 GW IT 資本支出）×（液冷滲透率 × 每 GW 液冷內容 × 奇鋐份額＋每 GW AI 氣冷與機構）。VR200 每 GW 機架數較少，橋接表的每 GW 液冷內容下降；成長要靠液冷滲透率、Rubin 全液冷與 ASIC 液冷提高每架內容，同時守住冷板份額。
A4: 核心問題：液冷滲透率與每架液冷內容的上升，能不能抵銷 VR200 每 GW 機架數下降與份額流失，讓 FY2027–28 EPS 維持券商預期的高成長；現價約 20 倍 FY2027 EPS 隱含的路徑合不合理。
A6: 會計年度＝日曆年，FY(t)＝CY(t)，不平移。預測期 FY2027–FY2029（三年）。金額：十億新台幣；市場以美元計、以匯率換算。口徑：歸屬母公司淨利。
A8: 驅動因子 → 推導量（全部唯讀上游，不修改）
A9: 液冷營收：markets/network 的 AI IT 資本支出 × 情境顆數係數 ÷ 每 GW IT 資本支出（Tokenomics，經橋接表）＝部署 GW；× 液冷滲透率（Assumed）× 每 GW 液冷內容（橋接表每架機架內液冷＋分歧管 × 每 GW 機架數 × 內容調整）× 匯率 × 奇鋐有效份額（FY2026 以券商液冷占比校準）× 份額相對值（Assumed）。
A10: AI 氣冷與機構：FY2026 以伺服器與網通比重（公司）× AI 比例（Assumed）校準每 GW 營收 × 相對值（氣冷轉液冷，Assumed）。一般伺服器與網通、非伺服器（3C、系統、富世達）：FY2026 拆分 × 成長率（Assumed）。毛利率：液冷比其他營收高 d_lc（Assumed），其他毛利率為 FY2026 殘差（Derived）。營業費用：彈性 phi（Derived）。
A11: 校準：FY2026 ＝ 1H26 實績＋3Q26 營收實績（月營收）＋假設（4Q 季增、毛利率、營業費用率）。不用券商數字（只在 Recon 對帳）。
A12: 估值：Val 第 0 節目標價＝0.5 × DCF 目標價（股東現金流＝EPS ×（1 − tp_g ÷ tp_roe），FY2027–FY2032 明確期＋永續，r 10%、g 4%，三情境權重 0.3／0.5／0.2，推到 12 個月後）＋0.5 × Comparable 目標價（雙鴻、健策、Vertiv、台達電 前瞻 P/E 中位數 × 12 個月後前瞻 EPS）；另列 Comparable 單獨目標價、市場共識目標價與差距拆解（EPS 因素、倍數因素）、DCF 價格帶、十年 P/E 分位檢查（只作檢查）。（v0.1.1 原估值說明，保留作參考：現價 ÷ FY2027、FY2028 EPS；十年 P/E 規則值（Goodinfo 年底收盤 ÷ EPS；stockanalysis 核對）× FY2027 EPS；循環位置以本模型營收最高年判定（奇鋐不套設備股見頂年）。本版未做先驗，無 Andy 合理 P/E 對照。）
A13: 標記：Verified、Interested-party、Analogy、Assumed、Derived。SemiAnalysis 未使用。公司原文經媒體轉述；券商多經媒體轉述。
A15: 已知限制：(1) 2026 液冷占比只有券商說法（30–35%），公司未揭露；(2) 液冷滲透率、每架內容調整、份額相對值為 Assumed，是 FY2028 EPS 最敏感的輸入；(3) 部署 GW 以 VR200 每 GW IT 資本支出換算，ASIC 機架的每 GW 資本支出較低，GW 可能低估；(4) 十年 P/E 的 2016–2022 年為 AI 前的低倍數（約 10–15x），規則值可能低估 AI 期的合理倍數；(5) 稅前利益與 FY2025 各季營收為推導；(6) 3Q26 財報（預計 11 月中）後更新錨點；R4 產業部署路徑未建。
... A18: 先驗：本版未做先驗，無 Andy 合理 P/E 對照。

Sheet In
A1: In — 輸入（藍字；基準欄 E，低 D、高 F）。金額：十億新台幣（NT$B），市場與每架內容為美元；比例：%。每個輸入盡量附兩個來源（找不到者寫「未找到」）；公司原文算一個
A2: 標記：Verified／Interested-party／Analogy／Assumed／Derived；Analogy、Assumed 給低／高區間。SemiAnalysis 未使用。公司原文＝奇鋐法說（經鉅亨、優分析、時報轉述）與月營收公告；公司的產品比重說法為 Interested-party；券商估計皆為 Interested-party
A3: 鍵 | B3: 項目 | C3: 單位 | D3: 低 | E3: 基準 | F3: 高 | G3: 標記 | H3: 來源1 | I3: 來源2／說明
A4: A. AI 部署規模（讀 markets/network、markets/chip_bridge、tsmc 成品；情境 A 基準，B／C 依顆數係數縮放）
A5: itc_26 | B5: AI IT 資本支出 2026 | C5: US$B | E5: 781.87292 | G5: Derived | H5: markets/network/dist/20261023_AI網通市場模型_v0.2.2.xlsx｜Mkt!C27:F27 | I5: 加速器顆數 × 每顆 IT capex（含 ASIC）；本模型以此除以每 GW IT 資本支出得到部署 GW
A6: itc_27 | B6: AI IT 資本支出 2027 | C6: US$B | E6: 1565.35 | G6: Derived | H6: markets/network/dist/20261023_AI網通市場模型_v0.2.2.xlsx｜Mkt!C27:F27 | I6: 同上
A7: itc_28 | B7: AI IT 資本支出 2028 | C7: US$B | E7: 1984.2639 | G7: Derived | H7: markets/network/dist/20261023_AI網通市場模型_v0.2.2.xlsx｜Mkt!C27:F27 | I7: 同上
A8: itc_29 | B8: AI IT 資本支出 2029 | C8: US$B | E8: 2260.3903 | G8: Derived | H8: markets/network/dist/20261023_AI網通市場模型_v0.2.2.xlsx｜Mkt!C27:F27 | I8: 同上
A9: itpg_gb | B9: 每 GW IT 資本支出（GB300） | C9: US$B | E9: 32.237224 | G9: Derived | H9: markets/chip_bridge/dist/20261023_晶片內容橋接表_v0.2.1.xlsx｜In!E10（GB300）、H10（VR200） | I9: Tokenomics v20.1 IF_CapexIT（經橋接表；唯讀）
A10: itpg_vr | B10: 每 GW IT 資本支出（VR200；2027 起） | C10: US$B | E10: 37.586352 | G10: Derived | H10: markets/chip_bridge/dist/20261023_晶片內容橋接表_v0.2.1.xlsx｜In!E10（GB300）、H10（VR200） | I10: 同上；Rubin Ultra 與 ASIC 機架未另訂（Assumed：同 VR200）
A11: vr26 | B11: 2026 年部署中 Rubin 世代占比（混合每 GW 數值用） | C11: % | D11: 0.15 | E11: 0.22 | F11: 0.3 | G11: Interested-party | H11: TrendForce 2026 組合 Rubin 22%（經 markets/memory；與 delta 模型相同） | I11: 公司 2Q26 法說：GPU 量在 3Q 末放大，Vera Rubin 下半年推出（時報 2026-06-02 股東會）
A12: racks_gb | B12: 每 GW 機架數（GB300） | C12: 架 | E12: 6764 | G12: Derived | H12: markets/chip_bridge/dist/20261023_晶片內容橋接表_v0.2.1.xlsx｜In!E6（GB300）、H6（VR200） | I12: Tokenomics（經橋接表）
A13: racks_vr | B13: 每 GW 機架數（VR200） | C13: 架 | E13: 4052 | G13: Derived | H13: markets/chip_bridge/dist/20261023_晶片內容橋接表_v0.2.1.xlsx｜In!E6（GB300）、H6（VR200） | I13: 同上
A14: cool_gb | B14: GB300 每架機架內液冷（運算匣＋交換匣，橋接表） | C14: US$K | E14: 50 | G14: Interested-party | H14: markets/chip_bridge/dist/20261023_晶片內容橋接表_v0.2.1.xlsx｜In!E33（GB300）、H33（VR200） | I14: Morgan Stanley（經 Tom's Hardware 2025-11-05）：GB300 NVL72 冷卻 BOM US$49.9K；不含 CDU、分歧管
A15: cool_vr | B15: VR200 每架機架內液冷（橋接表） | C15: US$K | E15: 56 | G15: Interested-party | H15: markets/chip_bridge/dist/20261023_晶片內容橋接表_v0.2.1.xlsx｜In!E33（GB300）、H33（VR200） | I15: 同上：VR NVL144 US$55.7K（運算匣每匣 2,660、交換匣每匣 870）
A16: um28_A | B16: 情境 A：2028 顆數 ÷ 基準 | C16: x | E16: 1 | G16: Assumed | H16: tsmc/dist/20261025_台積電模型_v0.2.2.xlsx｜In!E37 | I16: A＝基準；B＝AI 資本支出消化；C＝明顯下修（與台積電、NVIDIA、台達電模型相同）
A17: um29_A | B17: 情境 A：2029 顆數 ÷ 基準 | C17: x | E17: 1 | G17: Assumed | H17: tsmc/dist/20261025_台積電模型_v0.2.2.xlsx｜In!E38 | I17: 同上
A18: um28_B | B18: 情境 B：2028 顆數 ÷ 基準 | C18: x | E18: 0.8 | G18: Assumed | H18: tsmc/dist/20261025_台積電模型_v0.2.2.xlsx｜In!E39 | I18: A＝基準；B＝AI 資本支出消化；C＝明顯下修（與台積電、NVIDIA、台達電模型相同）
A19: um29_B | B19: 情境 B：2029 顆數 ÷ 基準 | C19: x | E19: 0.85 | G19: Assumed | H19: tsmc/dist/20261025_台積電模型_v0.2.2.xlsx｜In!E40 | I19: 同上
A20: um28_C | B20: 情境 C：2028 顆數 ÷ 基準 | C20: x | E20: 0.6 | G20: Assumed | H20: tsmc/dist/20261025_台積電模型_v0.2.2.xlsx｜In!E41 | I20: A＝基準；B＝AI 資本支出消化；C＝明顯下修（與台積電、NVIDIA、台達電模型相同）
A21: um29_C | B21: 情境 C：2029 顆數 ÷ 基準 | C21: x | E21: 0.6 | G21: Assumed | H21: tsmc/dist/20261025_台積電模型_v0.2.2.xlsx｜In!E42 | I21: 同上
A22: fx | B22: 匯率（新台幣 ÷ 美元） | C22: NT$/US$ | D22: 30.5 | E22: 32 | F22: 33 | G22: Derived | H22: 與 delta 模型相同（公司 2Q26 法說換算隱含約 32.7） | I22: 凱基 2026-08-12：市值 NT$1,148bn ≈ US$33.6bn（隱含約 34.2，口徑待查）
A23: dlc_26 | B23: 台達電液冷營收 2026（台達電模型，情境 A；Recon 用） | C23: US$B | E23: 2.9547809 | G23: Derived | H23: delta/dist/20261025_台達電模型_v0.2.xlsx｜Units!C10:F10 | I23: 只作對帳（台達電液冷多在機架外：CDU、Liquid-to-Air），不進本模型計算
A24: dlc_27 | B24: 台達電液冷營收 2027（台達電模型，情境 A；Recon 用） | C24: US$B | E24: 5.7848481 | G24: Derived | H24: delta/dist/20261025_台達電模型_v0.2.xlsx｜Units!C10:F10 | I24: 同上
A25: dlc_28 | B25: 台達電液冷營收 2028（台達電模型，情境 A；Recon 用） | C25: US$B | E25: 7.6662872 | G25: Derived | H25: delta/dist/20261025_台達電模型_v0.2.xlsx｜Units!C10:F10 | I25: 同上
A26: dlc_29 | B26: 台達電液冷營收 2029（台達電模型，情境 A；Recon 用） | C26: US$B | E26: 9.1128137 | G26: Derived | H26: delta/dist/20261025_台達電模型_v0.2.xlsx｜Units!C10:F10 | I26: 同上
A27: B. 液冷內容、滲透率與奇鋐份額（每架液冷內容取自橋接表；分歧管、內容調整、滲透率、份額為本模型 Assumed）
A28: mani | B28: 每架分歧管與快接頭（橋接表未含） | C28: US$K | D28: 3 | E28: 6 | F28: 10 | G28: Assumed | H28: 公司：分歧管月產能 7,000 支，約供 3,000–4,000 架（優分析 2026-08-12）→ 每架約 2 支 | I28: 分歧管單價：未找到
A29: lcadj_27 | B29: 每架液冷內容 ÷ 橋接表 2027（Rubin 全液冷、ASIC 液冷；2026＝1） | C29: x | D29: 1 | E29: 1.3 | F29: 1.6 | G29: Assumed | H29: https://finance.ettoday.net/news/3220835：Vera Rubin 無風扇全液冷，液冷延伸到網卡、電源板、光模組，單架散熱價值提升（TrendForce，Interested-party） | I29: Morgan Stanley BOM 只計運算匣與交換匣；大和：2027 ASIC 營收超過 GPU（時報 2026-08-13）
A30: lcadj_28 | B30: 每架液冷內容 ÷ 橋接表 2028（Rubin 全液冷、ASIC 液冷；2026＝1） | C30: x | D30: 1 | E30: 1.4 | F30: 1.8 | G30: Assumed | H30: 同上 | I30: —
A31: lcadj_29 | B31: 每架液冷內容 ÷ 橋接表 2029（Rubin 全液冷、ASIC 液冷；2026＝1） | C31: x | D31: 1 | E31: 1.4 | F31: 1.8 | G31: Assumed | H31: 同上 | I31: —
A32: lpen_26 | B32: 液冷滲透率 2026（部署 GW 中液冷占比） | C32: % | D32: 0.45 | E32: 0.55 | F32: 0.65 | G32: Assumed | H32: https://finance.ettoday.net/news/3220835：TrendForce AI 晶片液冷滲透率 2025 約 33%、2026 53%、2027 近 60%（以顆數計，Interested-party） | I32: 以 GW 計高於顆數計（液冷晶片功耗較高）；Trainium 3 先氣冷後液冷（TechNews 2026-04-29）
A33: lpen_27 | B33: 液冷滲透率 2027（部署 GW 中液冷占比） | C33: % | D33: 0.6 | E33: 0.75 | F33: 0.85 | G33: Assumed | H33: 同上 | I33: —
A34: lpen_28 | B34: 液冷滲透率 2028（部署 GW 中液冷占比） | C34: % | D34: 0.7 | E34: 0.85 | F34: 0.95 | G34: Assumed | H34: 同上 | I34: —
A35: lpen_29 | B35: 液冷滲透率 2029（部署 GW 中液冷占比） | C35: % | D35: 0.75 | E35: 0.9 | F35: 0.95 | G35: Assumed | H35: 同上 | I35: —
A36: rel_27 | B36: 奇鋐液冷份額 2027 ÷ 2026（相對值） | C36: x | D36: 0.85 | E36: 0.95 | F36: 1.05 | G36: Assumed | H36: 凱基 2026-08-05（網址見 Sources）：奇鋐為 CSP 與企業 GPU／ASIC 伺服器氣冷與液冷領導廠（未給份額，Interested-party） | I36: 對手：雙鴻、酷碼、台達電、Boyd、CoolIT；公司 2027 液冷產能再擴約 50%（優分析 2026-08-12）；份額數字：未找到
A37: rel_28 | B37: 奇鋐液冷份額 2028 ÷ 2026（相對值） | C37: x | D37: 0.75 | E37: 0.9 | F37: 1.05 | G37: Assumed | H37: 同上 | I37: —
A38: rel_29 | B38: 奇鋐液冷份額 2029 ÷ 2026（相對值） | C38: x | D38: 0.7 | E38: 0.85 | F38: 1.05 | G38: Assumed | H38: 同上 | I38: —
A39: acr_27 | B39: AI 氣冷每 GW 營收 2027 ÷ 2026（相對值） | C39: x | D39: 0.6 | E39: 0.75 | F39: 0.9 | G39: Assumed | H39: 氣冷轉液冷：液冷滲透率上升，每 GW 氣冷金額下降（本模型推論） | I39: Trainium 3、T3 機櫃 2H26 以氣冷為主，T3 液冷 2027 起（凱基 2026-08-05）
... A41: acr_29 | B41: AI 氣冷每 GW 營收 2029 ÷ 2026（相對值） | C41: x | D41: 0.4 | E41: 0.6 | F41: 0.8 | G41: Assumed | H41: 同上 | I41: —
...

Sheet Q
A1: Q — 實績與 FY2026 錨點（十億新台幣；EPS 為新台幣；股數為十億股）。藍字＝輸入；黑字＝公式。實績取自奇鋐法說（經媒體轉述）、凱基報告與月營收
A2: FY2026 錨點＝1H26 實績＋3Q26 營收實績（月營收）＋3Q、4Q 假設（毛利率、營業費用率、業外、淨利 ÷ 稅前；4Q 營收＝3Q × (1＋季增)）。3Q26 財報（預計 11 月中）尚未公布。稅前利益以 HiStock 各季稅前淨利率 × 營收推導（公司稅前金額原文：未找到）；FY2025 各季營收以年增率回推
A3: 項目 | B3: FY2025A | C3: 1H26（實績） | D3: 3Q26（營收實績） | E3: 4Q26（模型） | F3: FY2026 錨點 | G3: 標記 | H3: 來源1（公司） | I3: 來源2／說明
A4: 營收 | B4: 139.639 | C4: 98.159 | D4: =q3_rev -> 59.089 | E4: =D4*(1+q4g) -> 67.95235 | F4: =SUM(C4:E4) -> 225.20035 | G4: Verified／Interested-party（4Q 季增） | H4: FY2025：https://uanalyze.com.tw/articles/1131748834；1H26：https://uanalyze.com.tw/articles/5815653290 | I4: 凱基 2026-08-12（https://www.kgi.com.hk/zh-cn/-/media/files/kgishk/research-reports/tw-reports/asia-vital-components-3017-tt20260812en.pdf）
A5: 毛利 | B5: 36.034 | C5: =14.597+49.121*0.3257 -> 30.59571 | D5: =D4*q_gm -> 19.49937 | E5: =E4*q_gm -> 22.424276 | F5: =SUM(C5:E5) -> 72.519355 | G5: Verified／Derived（2Q26＝營收 × 毛利率） | H5: FY2025：https://uanalyze.com.tw/articles/1131748834；1H26：https://uanalyze.com.tw/articles/5815653290 | I5: FY2025 毛利率 25.81%（公司）；1Q26 毛利 145.97 億（時報 2026-05-14）
A6: 毛利率 | B6: =B5/B4 -> 0.25805112 | C6: =C5/C4 -> 0.31169541 | D6: =D5/D4 -> 0.33 | E6: =E5/E4 -> 0.33 | F6: =F5/F4 -> 0.3220215 | G6: Derived | H6: — | I6: FY2025 25.8%；1H26 31.17%（公司）
A7: 營業費用 | B7: =B5-B8 -> 8.4832253 | C7: =C5-C8 -> 5.0987097 | D7: =D4*q_opx -> 3.072628 | E7: =E4*q_opx -> 3.5335222 | F7: =SUM(C7:E7) -> 11.70486 | G7: Derived（毛利 − 營業利益）／Assumed | H7: FY2025：https://uanalyze.com.tw/articles/1131748834；1H26：https://uanalyze.com.tw/articles/5815653290 | I7: 凱基 2026-08-12（https://www.kgi.com.hk/zh-cn/-/media/files/kgishk/research-reports/tw-reports/asia-vital-components-3017-tt20260812en.pdf）
A8: 營業利益 | B8: =139.639*0.1973 -> 27.550775 | C8: =12.019+13.478 -> 25.497 | D8: =D5-D7 -> 16.426742 | E8: =E5-E7 -> 18.890753 | F8: =SUM(C8:E8) -> 60.814495 | G8: Derived（FY2025 營益率 19.73%）／Verified | H8: FY2025：https://uanalyze.com.tw/articles/1131748834；1H26：https://uanalyze.com.tw/articles/5815653290 | I8: 1Q26 120.19 億（時報）；2Q26 134.78 億（凱基）
A9: 營業利益率 | B9: =B8/B4 -> 0.1973 | C9: =C8/C4 -> 0.25975203 | D9: =D8/D4 -> 0.278 | E9: =E8/E4 -> 0.278 | F9: =F8/F4 -> 0.27004618 | G9: Derived | H9: — | I9: FY2025 19.7%；1H26 25.97%（公司）
A10: 業外收益 | B10: =B11-B8 -> 1.2317944 | C10: =C11-C8 -> 0.4186111 | D10: =q_nop -> 0.2 | E10: =q_nop -> 0.2 | F10: =SUM(C10:E10) -> 0.8186111 | G10: Derived | H10: FY2025：https://uanalyze.com.tw/articles/1131748834；1H26：https://uanalyze.com.tw/articles/5815653290 | I10: 凱基 2026-08-12（https://www.kgi.com.hk/zh-cn/-/media/files/kgishk/research-reports/tw-reports/asia-vital-components-3017-tt20260812en.pdf）
A11: 稅前利益 | B11: =(49.038/2.1017)*0.198+(98.159/1.8546-49.038/2.1017)*0.1992+(47.775/1.227)*0.211+47.775*0.2104 -> 28.782569 | C11: =49.038*0.2443+49.121*0.2837 -> 25.915611 | D11: =D8+D10 -> 16.626742 | E11: =E8+E10 -> 19.090753 | F11: =SUM(C11:E11) -> 61.633106 | G11: Derived（稅前淨利率 × 營收） | H11: https://histock.tw/stock/3017/%E5%88%A9%E6%BD%A4%E6%AF%94%E7%8E%87 | I11: 各季稅前淨利率：1Q25 19.80%、2Q25 19.92%、3Q25 21.10%、4Q25 21.04%、1Q26 24.43%、2Q26 28.37%
A12: 歸屬母公司淨利 | B12: 19.186 | C12: 17.483 | D12: =D11*q_nir -> 11.223051 | E12: =E11*q_nir -> 12.886258 | F12: =SUM(C12:E12) -> 41.592309 | G12: Verified／Derived（3Q、4Q） | H12: FY2025：https://uanalyze.com.tw/articles/1131748834；1H26：https://uanalyze.com.tw/articles/5815653290 | I12: 凱基 2026-08-12（https://www.kgi.com.hk/zh-cn/-/media/files/kgishk/research-reports/tw-reports/asia-vital-components-3017-tt20260812en.pdf）
A13: 淨利 ÷ 稅前（含稅與非控制權益） | B13: =B12/B11 -> 0.666584 | C13: =C12/C11 -> 0.67461269 | D13: =D12/D11 -> 0.675 | E13: =E12/E11 -> 0.675 | F13: =F12/F11 -> 0.67483714 | G13: Derived | H13: — | I13: —
A14: 股數（十億股） | B14: =19.186/49.17 -> 0.39019727 | C14: =q_sh -> 0.39252357 | D14: =q_sh -> 0.39252357 | E14: =q_sh -> 0.39252357 | F14: =q_sh -> 0.39252357 | G14: Derived | H14: FY2025：https://uanalyze.com.tw/articles/1131748834；1H26：https://uanalyze.com.tw/articles/5815653290 | I14: 淨利 ÷ EPS
A15: EPS | B15: =B12/B14 -> 49.17 | C15: =C12/C14 -> 44.54 | D15: =D12/D14 -> 28.592043 | E15: =E12/E14 -> 32.82926 | F15: =F12/F14 -> 105.9613 | G15: Derived | H15: 淨利 ÷ 股數 | I15: —
A16: 公司揭露 EPS | B16: 49.17 | C16: 44.54 | G16: Verified | H16: FY2025：https://uanalyze.com.tw/articles/1131748834；1H26：https://uanalyze.com.tw/articles/5815653290 | I16: 1Q26 20.17、2Q26 24.37；4Q25 16.92
A17: 液冷營收（＝營收 × 液冷占比） | B17: =B4*lc_25 -> 20.94585 | F17: =F4*lc_26 -> 72.064112 | G17: Derived／Interested-party | H17: 公司產品比重（In 頁 C 節） | I17: 液冷、AI 與一般伺服器的季度金額未揭露：未找到
A18: AI 氣冷與機構（＝營收 ×（伺服器與網通 − 液冷）× AI 比例） | B18: =B4*(srv_25-lc_25)*aiair -> 30.999858 | F18: =F4*(srv_26-lc_26)*aiair -> 47.292074 | G18: Derived／Interested-party | H18: 公司產品比重（In 頁 C 節） | I18: —
A19: 一般伺服器與網通（＝營收 ×（伺服器與網通 − 液冷）×（1 − AI 比例）） | B19: =B4*(srv_25-lc_25)*(1-aiair) -> 20.666572 | F19: =F4*(srv_26-lc_26)*(1-aiair) -> 31.528049 | G19: Derived／Interested-party | H19: 公司產品比重（In 頁 C 節） | I19: —
A20: 非伺服器（＝營收 ×（1 − 伺服器與網通）；3C、系統、富世達） | B20: =B4*(1-srv_25) -> 67.02672 | F20: =F4*(1-srv_26) -> 74.316115 | G20: Derived／Interested-party | H20: 公司產品比重（In 頁 C 節） | I20: —
A21: AI 氣冷（Sens：AI 比例 低） | F21: =F4*(srv_26-lc_26)*aiair_lo -> 31.528049 | G21: Derived | H21: Sens 用 | I21: —
A22: 一般伺服器（Sens：AI 比例 低） | F22: =F4*(srv_26-lc_26)*(1-aiair_lo) -> 47.292074 | G22: Derived | H22: Sens 用 | I22: —
A23: AI 氣冷（Sens：AI 比例 高） | F23: =F4*(srv_26-lc_26)*aiair_hi -> 63.056098 | G23: Derived | H23: Sens 用 | I23: —
A24: 一般伺服器（Sens：AI 比例 高） | F24: =F4*(srv_26-lc_26)*(1-aiair_hi) -> 15.764024 | G24: Derived | H24: Sens 用 | I24: —
A25: 液冷（Sens：2026 液冷占比 低） | F25: =F4*lc_26_lo -> 63.056098 | G25: Derived | H25: Sens 用 | I25: —
A26: AI 氣冷（Sens：液冷占比 低） | F26: =F4*(srv_26-lc_26_lo)*aiair -> 52.696882 | G26: Derived | H26: Sens 用 | I26: —
A27: 一般伺服器（Sens：液冷占比 低） | F27: =F4*(srv_26-lc_26_lo)*(1-aiair) -> 35.131255 | G27: Derived | H27: Sens 用 | I27: —
A28: 液冷（Sens：2026 液冷占比 高） | F28: =F4*lc_26_hi -> 78.820122 | G28: Derived | H28: Sens 用 | I28: —
A29: AI 氣冷（Sens：液冷占比 高） | F29: =F4*(srv_26-lc_26_hi)*aiair -> 43.238467 | G29: Derived | H29: Sens 用 | I29: —
A30: 一般伺服器（Sens：液冷占比 高） | F30: =F4*(srv_26-lc_26_hi)*(1-aiair) -> 28.825645 | G30: Derived | H30: Sens 用 | I30: —
A32: FY2026 錨點的檢查（參考；校準未使用券商數字）
A33: FY2026 營收年增 | B33: =F4/B4-1 -> 0.61273247
A34: FY2026 營業費用年增 | B34: =F7/B7-1 -> 0.3797653
A35: 營業費用彈性（營業費用年增 ÷ 營收年增；In 頁 phi 的依據） | B35: =B34/B33 -> 0.61978974
A36: FY2026 營收 ÷ 凱基（08-12，3Q 前）− 1 | B36: =F4/b_rev26-1 -> 0.053278159
A37: FY2026 EPS ÷ 高盛（10-19）− 1 | B37: =F15/b_eps26gs-1 -> 0.04849894
A38: 非伺服器營收 FY2026 年增 | B38: =F20/B20-1 -> 0.10875358

Sheet Units
A1: Units — AI 液冷市場（奇鋐可做部分：冷板、分歧管、快接頭）、奇鋐份額與每 GW 營收。部署 GW＝AI IT 資本支出（markets/network）÷ 每 GW IT 資本支出（Tokenomics，經橋接表）；每架液冷取自橋接表
A3: 項目 | B3: 單位 | C3: CY2026 | D3: CY2027 | E3: CY2028 | F3: CY2029 | G3: 說明
A4: 部署 GW（情境 A） | B4: GW | C4: =PL!D65 -> 23.399538 | D4: =PL!E65 -> 41.646766 | E4: =PL!F65 -> 52.792138 | F4: =PL!G65 -> 60.138592 | G4: AI IT 資本支出 ÷ 每 GW IT 資本支出
A5: 液冷滲透率（部署 GW） | B5: % | C5: =PL!D66 -> 0.55 | D5: =PL!E66 -> 0.75 | E5: =PL!F66 -> 0.85 | F5: =PL!G66 -> 0.9 | G5: In 頁 B 節（Assumed）
A6: 每 GW 液冷內容 | B6: US$M/GW | C6: =PL!D67 -> 350.7208 | D6: =PL!E67 -> 326.5912 | E6: =PL!F67 -> 351.7136 | F6: =PL!G67 -> 351.7136 | G6: 橋接表機架內液冷＋分歧管 × 每 GW 機架數 × 內容調整
A7: 每架液冷內容（以 VR200 每 GW 架數換算） | B7: US$K/架 | C7: =PL!D67*1000/racks_vr -> 86.554985 | D7: =PL!E67*1000/racks_vr -> 80.6 | E7: =PL!F67*1000/racks_vr -> 86.8 | F7: =PL!G67*1000/racks_vr -> 86.8 | G7: 對照：橋接表 VR200 機架內液冷 US$56K＋分歧管
A8: AI 液冷市場（奇鋐可做部分） | B8: US$B | C8: =PL!D68 -> 4.5136876 | D8: =PL!E68 -> 10.2011 | E8: =PL!F68 -> 15.782556 | F8: =PL!G68 -> 19.036405 | G8: 不含 CDU、機架外冷卻與液對氣
A9: 奇鋐有效份額 | B9: % | C9: =PL!D72 -> 0.49892764 | D9: =PL!E72 -> 0.47398126 | E9: =PL!F72 -> 0.44903488 | F9: =PL!G72 -> 0.42408849 | G9: FY2026 以券商液冷占比校準
A10: 奇鋐液冷營收 | B10: US$B | C10: =PL!D73/fx -> 2.2520035 | D10: =PL!E73/fx -> 4.8351304 | E10: =PL!F73/fx -> 7.0869181 | F10: =PL!G73/fx -> 8.0731202
A11: 奇鋐 AI 氣冷與機構營收 | B11: US$B | C11: =PL!D77/fx -> 1.4778773 | D11: =PL!E77/fx -> 1.9727572 | E11: =PL!F77/fx -> 2.1672734 | F11: =PL!G77/fx -> 2.2789542 | G11: FY2026 以伺服器比重與 AI 比例校準
A12: 每 GW 奇鋐 AI 營收（液冷＋氣冷與機構） | B12: US$M/GW | C12: =PL!D84 -> 159.39976 | D12: =PL!E84 -> 163.46738 | E12: =PL!F84 -> 175.29488 | F12: =PL!G84 -> 172.13696
A13: 其他廠商液冷（雙鴻、酷碼、台達電、Boyd、CoolIT 等）＝ 市場 − 奇鋐 | B13: US$B | C13: =PL!D68-PL!D73/fx -> 2.2616841 | D13: =PL!E68-PL!E73/fx -> 5.36597 | E13: =PL!F68-PL!F73/fx -> 8.6956379 | F13: =PL!G68-PL!G73/fx -> 10.963284
A15: 讀法：VR200 每 GW 機架數較少（6,764 → 4,052 架），橋接表的每 GW 液冷內容下降；FY2027 起的成長來自液冷滲透率與每架內容調整（Rubin 全液冷、ASIC 液冷），兩者與份額相對值都是 Assumed，是最需要每季檢查的輸入。

Sheet PL
A1: PL — 奇鋐損益（十億新台幣；EPS 新台幣；歸屬母公司）。FY2025A 實績、FY2026 錨點（1H26 實績＋3Q26 營收實績＋假設），FY2027 起為模型。FY(t)＝CY(t)。三情境各一個完整推導區塊（本頁下方），頂端為摘要。FY2026–FY2027 三情境相同（顆數係數從 CY2028 開始）
A3: 情境／項目 | B3: 單位 | C3: FY2025A | D3: FY2026（錨點） | E3: FY2027 | F3: FY2028 | G3: FY2029 | H3: 說明
A4: 情境 A
A5: 營收 | B5: NT$B | C5: =C80 -> 139.639 | D5: =D80 -> 225.20035 | E5: =E80 -> 330.67778 | F5: =F80 -> 414.94128 | G5: =G80 -> 455.18675
A6: 營收年增 | B6: % | D6: =D81 -> 0.61273247 | E6: =E81 -> 0.46837152 | F6: =F81 -> 0.25482056 | G6: =G81 -> 0.09699076
A7: 液冷營收 | B7: NT$B | C7: =C73 -> 20.94585 | D7: =D73 -> 72.064112 | E7: =E73 -> 154.72417 | F7: =F73 -> 226.78138 | G7: =G73 -> 258.33984
A8: AI 氣冷與機構營收 | B8: NT$B | C8: =C77 -> 30.999858 | D8: =D77 -> 47.292074 | E8: =E77 -> 63.128231 | F8: =F77 -> 69.352749 | G8: =G77 -> 72.926535
A9: 一般伺服器與網通營收 | B9: NT$B | C9: =C78 -> 20.666572 | D9: =D78 -> 31.528049 | E9: =E78 -> 34.050293 | F9: =F78 -> 36.09331 | G9: =G78 -> 37.897976
A10: 非伺服器營收 | B10: NT$B | C10: =C79 -> 67.02672 | D10: =D79 -> 74.316115 | E10: =E79 -> 78.775082 | F10: =F79 -> 82.713837 | G10: =G79 -> 86.02239
A11: 液冷 ÷ 營收 | B11: % | C11: =C82 -> 0.15 | D11: =D82 -> 0.32 | E11: =E82 -> 0.46790012 | F11: =F82 -> 0.54653849 | G11: =G82 -> 0.56754694
A12: 毛利率 | B12: % | C12: =C88 -> 0.25805112 | D12: =D88 -> 0.3220215 | E12: =E88 -> 0.33089551 | F12: =F88 -> 0.33561381 | G12: =G88 -> 0.33687432
A13: 營業利益率 | B13: % | C13: =C92 -> 0.1973 | D13: =D92 -> 0.27004618 | E13: =E92 -> 0.28389382 | F13: =F92 -> 0.29147555 | G13: =G92 -> 0.29390681
A14: 歸屬母公司淨利 | B14: NT$B | C14: =C95 -> 19.186 | D14: =D95 -> 41.592309 | E14: =E95 -> 64.042229 | F14: =F95 -> 82.313036 | G14: =G95 -> 90.978177
A15: EPS | B15: NT$ | C15: =C97 -> 49.17 | D15: =D97 -> 105.9613 | E15: =E97 -> 163.15512 | F15: =F97 -> 209.70215 | G15: =G97 -> 231.77761
A16: EPS 年增 | B16: % | D16: =D98 -> 1.154999 | E16: =E98 -> 0.53976132 | F16: =F98 -> 0.28529311 | G16: =G98 -> 0.10527058
A18: 情境 B
A19: 營收 | B19: NT$B | C19: =C121 -> 139.639 | D19: =D121 -> 225.20035 | E19: =E121 -> 330.67778 | F19: =F121 -> 355.71445 | G19: =G121 -> 405.49679
A20: 營收年增 | B20: % | D20: =D122 -> 0.61273247 | E20: =E122 -> 0.46837152 | F20: =F122 -> 0.075713193 | G20: =G122 -> 0.13995029
A21: 液冷營收 | B21: NT$B | C21: =C114 -> 20.94585 | D21: =D114 -> 72.064112 | E21: =E114 -> 154.72417 | F21: =F114 -> 181.4251 | G21: =G114 -> 219.58887
A22: AI 氣冷與機構營收 | B22: NT$B | C22: =C118 -> 30.999858 | D22: =D118 -> 47.292074 | E22: =E118 -> 63.128231 | F22: =F118 -> 55.482199 | G22: =G118 -> 61.987554
A23: 一般伺服器與網通營收 | B23: NT$B | C23: =C119 -> 20.666572 | D23: =D119 -> 31.528049 | E23: =E119 -> 34.050293 | F23: =F119 -> 36.09331 | G23: =G119 -> 37.897976
A24: 非伺服器營收 | B24: NT$B | C24: =C120 -> 67.02672 | D24: =D120 -> 74.316115 | E24: =E120 -> 78.775082 | F24: =F120 -> 82.713837 | G24: =G120 -> 86.02239
A25: 液冷 ÷ 營收 | B25: % | C25: =C123 -> 0.15 | D25: =D123 -> 0.32 | E25: =E123 -> 0.46790012 | F25: =F123 -> 0.51003018 | G25: =G123 -> 0.54153047
A26: 毛利率 | B26: % | C26: =C129 -> 0.25805112 | D26: =D129 -> 0.3220215 | E26: =E129 -> 0.33089551 | F26: =F129 -> 0.33342331 | G26: =G129 -> 0.33531333
A27: 營業利益率 | B27: % | C27: =C133 -> 0.1973 | D27: =D133 -> 0.27004618 | E27: =E133 -> 0.28389382 | F27: =F133 -> 0.28741407 | G27: =G133 -> 0.29099864
A28: 歸屬母公司淨利 | B28: NT$B | C28: =C136 -> 19.186 | D28: =D136 -> 41.592309 | E28: =E136 -> 64.042229 | F28: =F136 -> 69.685203 | G28: =G136 -> 80.324334
A29: EPS | B29: NT$ | C29: =C138 -> 49.17 | D29: =D138 -> 105.9613 | E29: =E138 -> 163.15512 | F29: =F138 -> 177.53126 | G29: =G138 -> 204.63569
A30: EPS 年增 | B30: % | D30: =D139 -> 1.154999 | E30: =E139 -> 0.53976132 | F30: =F139 -> 0.088113332 | G30: =G139 -> 0.15267417
A32: 情境 C
A33: 營收 | B33: NT$B | C33: =C162 -> 139.639 | D33: =D162 -> 225.20035 | E33: =E162 -> 330.67778 | F33: =F162 -> 296.48762 | G33: =G162 -> 322.68019
A34: 營收年增 | B34: % | D34: =D163 -> 0.61273247 | E34: =E163 -> 0.46837152 | F34: =F163 -> -0.10339417 | G34: =G163 -> 0.088342876
A35: 液冷營收 | B35: NT$B | C35: =C155 -> 20.94585 | D35: =D155 -> 72.064112 | E35: =E155 -> 154.72417 | F35: =F155 -> 136.06883 | G35: =G155 -> 155.00391
A36: AI 氣冷與機構營收 | B36: NT$B | C36: =C159 -> 30.999858 | D36: =D159 -> 47.292074 | E36: =E159 -> 63.128231 | F36: =F159 -> 41.611649 | G36: =G159 -> 43.755921
A37: 一般伺服器與網通營收 | B37: NT$B | C37: =C160 -> 20.666572 | D37: =D160 -> 31.528049 | E37: =E160 -> 34.050293 | F37: =F160 -> 36.09331 | G37: =G160 -> 37.897976
A38: 非伺服器營收 | B38: NT$B | C38: =C161 -> 67.02672 | D38: =D161 -> 74.316115 | E38: =E161 -> 78.775082 | F38: =F161 -> 82.713837 | G38: =G161 -> 86.02239
A39: 液冷 ÷ 營收 | B39: % | C39: =C164 -> 0.15 | D39: =D164 -> 0.32 | E39: =E164 -> 0.46790012 | F39: =F164 -> 0.45893594 | G39: =G164 -> 0.48036387
A40: 毛利率 | B40: % | C40: =C170 -> 0.25805112 | D40: =D170 -> 0.3220215 | E40: =E170 -> 0.33089551 | F40: =F170 -> 0.33035766 | G40: =G170 -> 0.33164334
A41: 營業利益率 | B41: % | C41: =C174 -> 0.1973 | D41: =D174 -> 0.27004618 | E41: =E174 -> 0.28389382 | F41: =F174 -> 0.27793586 | G41: =G174 -> 0.28049809
A42: 歸屬母公司淨利 | B42: NT$B | C42: =C177 -> 19.186 | D42: =D177 -> 41.592309 | E42: =E177 -> 64.042229 | F42: =F177 -> 56.298066 | G42: =G177 -> 61.770044
A43: EPS | B43: NT$ | C43: =C179 -> 49.17 | D43: =D179 -> 105.9613 | E43: =E179 -> 163.15512 | F43: =F179 -> 143.42595 | G43: =G179 -> 157.36646
...

Sheet Val
A1: Val — P/E 估值（新台幣）。結論用「現價 ÷ FY2027、FY2028 EPS（模型）」與十年 P/E 規則值（年底落後 P/E，基準為 FY2027 EPS）
A2: 循環位置：奇鋐不是設備股，不套設備市場見頂年；以本模型營收最高的會計年度為見頂年（比照台達電、NVIDIA、Arista；FY(t)＝CY(t)）。營收到 FY2029 仍在增加時，見頂年未知，判為中段
A3: 目標價：見第 0 節（本頁第 85 列；v0.2 新增，DCF 與 Comparable 加權）。第 74 列「舊法：規則值情境加權（參考）」不再是目標價，只作參考
A4: 1. 價格與市場隱含倍數
A5: 項目 | B5: A | C5: B | D5: C | E5: 說明
A6: 現價（2026-10-22 收盤） | B6: =px -> 3145
A7: 現價 ÷ FY2026 EPS（錨點） | B7: =px/PL!D15 -> 29.680647 | C7: =px/PL!D29 -> 29.680647 | D7: =px/PL!D43 -> 29.680647
A8: 現價 ÷ FY2027 EPS（模型） | B8: =px/PL!E15 -> 19.276135 | C8: =px/PL!E29 -> 19.276135 | D8: =px/PL!E43 -> 19.276135 | E8: FY2027 三情境相同（顆數係數從 CY2028 開始）
A9: 現價 ÷ FY2028 EPS（模型） | B9: =px/PL!F15 -> 14.997462 | C9: =px/PL!F29 -> 17.71519 | D9: =px/PL!F43 -> 21.927692
A10: 現價 ÷ FY2029 EPS（模型） | B10: =px/PL!G15 -> 13.569041 | C10: =px/PL!G29 -> 15.368775 | D10: =px/PL!G43 -> 19.985199
A11: 未來 12 月 EPS（模型 A）≈ ¼ FY2026＋¾ FY2027 | B11: =0.25*PL!D15+0.75*PL!E15 -> 148.85666
A12: 現價 ÷ 未來 12 月 EPS（模型 A） | B12: =px/B11 -> 21.127707
A13: 近 12 月 P/E（HiStock，10-22） | B13: =pe_ttm -> 41.92
A15: 2. 循環位置（本模型營收最高年；FY(t)＝CY(t)）
A16: 情境 | B16: 營收最高年（FY2026–FY2029） | C16: FY2027 判定 | D16: 規則倍數（P/E） | E16: 見頂年是否未知 | F16: 說明
A17: A | B17: =INDEX({2026,2027,2028,2029},MATCH(MAX(PL!D80:G80),PL!D80:G80,0)) -> 2029 | C17: =IF(B17=2029,"中段",IF(2027<B17,"中段",IF(2027=B17,"見頂","谷底"))) -> 中段 | D17: =IF(C17="見頂",pe_peak,IF(C17="谷底",pe_trough,pe_mid)) -> 12.74 | E17: =IF(B17=2029,"是：營收到觀測期末仍在增加","否") -> 是：營收到觀測期末仍在增加 | F17: tools/cycle_position.py excel_rule；營收最高年取代設備市場見頂年
A18: B | B18: =INDEX({2026,2027,2028,2029},MATCH(MAX(PL!D121:G121),PL!D121:G121,0)) -> 2029 | C18: =IF(B18=2029,"中段",IF(2027<B18,"中段",IF(2027=B18,"見頂","谷底"))) -> 中段 | D18: =IF(C18="見頂",pe_peak,IF(C18="谷底",pe_trough,pe_mid)) -> 12.74 | E18: =IF(B18=2029,"是：營收到觀測期末仍在增加","否") -> 是：營收到觀測期末仍在增加 | F18: 同上
A19: C | B19: =INDEX({2026,2027,2028,2029},MATCH(MAX(PL!D162:G162),PL!D162:G162,0)) -> 2027 | C19: =IF(B19=2029,"中段",IF(2027<B19,"中段",IF(2027=B19,"見頂","谷底"))) -> 見頂 | D19: =IF(C19="見頂",pe_peak,IF(C19="谷底",pe_trough,pe_mid)) -> 11.11 | E19: =IF(B19=2029,"是：營收到觀測期末仍在增加","否") -> 否 | F19: 同上
A21: 3. 規則值隱含股價（新台幣；約 FY2027 年底，未折現）＝ FY2027 EPS × 規則倍數
A22: 情境 | B22: FY2027 EPS | C22: （同左） | D22: 規則倍數 | E22: 隱含股價 | F22: 相對現價 | G22: 現價 ÷ FY2027 EPS
A23: A | B23: =PL!E15 -> 163.15512 | C23: =B23 -> 163.15512 | D23: =D17 -> 12.74 | E23: =C23*D23 -> 2078.5962 | F23: =E23/px-1 -> -0.33907912 | G23: =px/C23 -> 19.276135
A24: B | B24: =PL!E29 -> 163.15512 | C24: =B24 -> 163.15512 | D24: =D18 -> 12.74 | E24: =C24*D24 -> 2078.5962 | F24: =E24/px-1 -> -0.33907912 | G24: =px/C24 -> 19.276135
A25: C | B25: =PL!E43 -> 163.15512 | C25: =B25 -> 163.15512 | D25: =D19 -> 11.11 | E25: =C25*D25 -> 1812.6533 | F25: =E25/px-1 -> -0.42363964 | G25: =px/C25 -> 19.276135
A26: 4. What must be true：FY2027 年底價 ＝ 現價 ×（1＋報酬）所需的倍數（FY2028 EPS；約 2027 年底的價格看下一年 EPS）
A27: FY2027 年底價 ÷ 現價 | B27: 所需倍數（÷ FY2028 EPS，A） | C27: 所需倍數（÷ FY2028 EPS，C） | D27: 對照：十年中位數 | E27: 對照：十年 75 分位
A28: 1 | B28: =px*A28/PL!F15 -> 14.997462 | C28: =px*A28/PL!F43 -> 21.927692 | D28: =pe_mid -> 12.74 | E28: =pe_trough -> 21.73
A29: 1.1 | B29: =px*A29/PL!F15 -> 16.497208 | C29: =px*A29/PL!F43 -> 24.120461 | D29: =pe_mid -> 12.74 | E29: =pe_trough -> 21.73
A30: 1.21 | B30: =px*A30/PL!F15 -> 18.146929 | C30: =px*A30/PL!F43 -> 26.532507 | D30: =pe_mid -> 12.74 | E30: =pe_trough -> 21.73
A31: 1.5 | B31: =px*A31/PL!F15 -> 22.496193 | C31: =px*A31/PL!F43 -> 32.891538 | D31: =pe_mid -> 12.74 | E31: =pe_trough -> 21.73
A32: 2 | B32: =px*A32/PL!F15 -> 29.994924 | C32: =px*A32/PL!F43 -> 43.855384 | D32: =pe_mid -> 12.74 | E32: =pe_trough -> 21.73
A33: 讀法：1.00＝價格不變、1.21＝一年約 21%。所需倍數低於歷史中位數時，現價相對便宜；倍數是否合理，另看前瞻 P/E 歷史（Bloomberg）。本版未做先驗，無 Andy 合理 P/E 對照。
A40: 6. 十年倍數與規則值（2016–2025 年底；見頂年 25 分位、中段中位數、谷底 75 分位）
A41: 規則（Andy 2026-10-13）：合理倍數＝2016–2025 年底 P/E 依循環位置取分位。採用 Goodinfo 年底收盤 ÷ 當年 EPS（10 年）；stockanalysis 只有 2021–2025 且全為 AI 前後高倍數期，只作核對。2016–2022 年奇鋐為筆電、伺服器氣冷散熱廠（約 10–15x），AI 前後的倍數口徑不同，規則值可能低估 AI 期的合理倍數。
A43: P/E：十年歷史倍數
A44: 年底 | B44: Goodinfo（年底收盤 ÷ 當年 EPS） | C44: stockanalysis（年底 P/E） | D44: 標記／說明
A45: 2016 | B45: =25.1/2.43 -> 10.329218 | D45: Goodinfo（年底收盤 ÷ 當年 EPS）：Derived（資料商年底收盤與 EPS；2016–2025 共 10 年）；stockanalysis（年底 P/E）：Interested-party（資料商；只有 2021–2025，只作核對、不採用）
A46: 2017 | B46: =32.4/2.51 -> 12.908367 | D46: stockanalysis 2021–2025 與 Goodinfo 推導差距在 0.5x 內；2016–2020 年：未找到第二來源
A47: 2018 | B47: =25.25/2.01 -> 12.562189
A48: 2019 | B48: =41.65/2.71 -> 15.369004
A49: 2020 | B49: =66.1/5.42 -> 12.195572
...

Sheet Recon
A1: Recon — 本模型 vs 券商估計、研調滲透率與台達電液冷。只作事後對照，不為對上數字而調參數。券商數字多經媒體轉述；付費共識未找到
A3: 項目 | B3: 對照值 | C3: 模型 A | D3: 差距 A | E3: 模型 B | F3: 差距 B | G3: 模型 C | H3: 差距 C | I3: 對照來源 | J3: 說明
A4: A. 券商估計（校準未使用）
A5: FY2026 營收 vs 凱基（08-12，3Q 前） | B5: =b_rev26 -> 213.809 | C5: =PL!D80 -> 225.20035 | D5: =C5/B5-1 -> 0.053278159 | E5: =PL!D121 -> 225.20035 | F5: =E5/B5-1 -> 0.053278159 | G5: =PL!D162 -> 225.20035 | H5: =G5/B5-1 -> 0.053278159 | I5: 凱基 2026-08-12 | J5: 凱基 3Q 估 530.5 億，實際 590.9 億
A6: 4Q26 營收 vs 高盛（10-19） | B6: =b_q4 -> 68.057 | C6: =Q!E4 -> 67.95235 | D6: =C6/B6-1 -> -0.0015376816 | E6: =Q!E4 -> 67.95235 | F6: =E6/B6-1 -> -0.0015376816 | G6: =Q!E4 -> 67.95235 | H6: =G6/B6-1 -> -0.0015376816 | I6: 高盛（TechNews 2026-10-19）
A7: FY2026 EPS vs 高盛（10-19） | B7: =b_eps26gs -> 101.06 | C7: =PL!D97 -> 105.9613 | D7: =C7/B7-1 -> 0.04849894 | E7: =PL!D138 -> 105.9613 | F7: =E7/B7-1 -> 0.04849894 | G7: =PL!D179 -> 105.9613 | H7: =G7/B7-1 -> 0.04849894 | I7: 高盛（TechNews 2026-10-19）
A8: FY2026 EPS vs 凱基（08-12） | B8: =b_eps26kgi -> 103.17 | C8: =PL!D97 -> 105.9613 | D8: =C8/B8-1 -> 0.027055373 | E8: =PL!D138 -> 105.9613 | F8: =E8/B8-1 -> 0.027055373 | G8: =PL!D179 -> 105.9613 | H8: =G8/B8-1 -> 0.027055373 | I8: 凱基 2026-08-12 | J8: 美銀、大和、花旗 102.7–105.0
A9: FY2027 營收 vs 凱基（08-12） | B9: =b_rev27 -> 311.893 | C9: =PL!E80 -> 330.67778 | D9: =C9/B9-1 -> 0.060228281 | E9: =PL!E121 -> 330.67778 | F9: =E9/B9-1 -> 0.060228281 | G9: =PL!E162 -> 330.67778 | H9: =G9/B9-1 -> 0.060228281 | I9: 凱基 2026-08-12
A10: FY2027 EPS vs 高盛（10-19） | B10: =b_eps27gs -> 154.78 | C10: =PL!E97 -> 163.15512 | D10: =C10/B10-1 -> 0.054109806 | E10: =PL!E138 -> 163.15512 | F10: =E10/B10-1 -> 0.054109806 | G10: =PL!E179 -> 163.15512 | H10: =G10/B10-1 -> 0.054109806 | I10: 高盛（TechNews 2026-10-19）
A11: FY2027 EPS vs 凱基（08-12） | B11: =b_eps27kgi -> 160.03 | C11: =PL!E97 -> 163.15512 | D11: =C11/B11-1 -> 0.019528312 | E11: =PL!E138 -> 163.15512 | F11: =E11/B11-1 -> 0.019528312 | G11: =PL!E179 -> 163.15512 | H11: =G11/B11-1 -> 0.019528312 | I11: 凱基 2026-08-12
A12: FY2027 EPS vs 美銀 | B12: =b_eps27bofa -> 143.99 | C12: =PL!E97 -> 163.15512 | D12: =C12/B12-1 -> 0.13310032 | E12: =PL!E138 -> 163.15512 | F12: =E12/B12-1 -> 0.13310032 | G12: =PL!E179 -> 163.15512 | H12: =G12/B12-1 -> 0.13310032 | I12: 時報 2026-08-13
A13: FY2027 EPS vs 大和 | B13: =b_eps27dw -> 139.53 | C13: =PL!E97 -> 163.15512 | D13: =C13/B13-1 -> 0.16931926 | E13: =PL!E138 -> 163.15512 | F13: =E13/B13-1 -> 0.16931926 | G13: =PL!E179 -> 163.15512 | H13: =G13/B13-1 -> 0.16931926 | I13: 時報 2026-08-13
A14: FY2027 EPS vs 花旗（08 月） | B14: =b_eps27citi -> 153.21 | C14: =PL!E97 -> 163.15512 | D14: =C14/B14-1 -> 0.064911662 | E14: =PL!E138 -> 163.15512 | F14: =E14/B14-1 -> 0.064911662 | G14: =PL!E179 -> 163.15512 | H14: =G14/B14-1 -> 0.064911662 | I14: 時報 2026-08-13 | J14: 花旗 09-19 再上修 13%（絕對值未找到）
A15: FY2028 EPS vs 高盛（10-19） | B15: =b_eps28gs -> 195.18 | C15: =PL!F97 -> 209.70215 | D15: =C15/B15-1 -> 0.074403865 | E15: =PL!F138 -> 177.53126 | F15: =E15/B15-1 -> -0.090422908 | G15: =PL!F179 -> 143.42595 | H15: =G15/B15-1 -> -0.26516063 | I15: 高盛（TechNews 2026-10-19） | J15: 美銀 178.74、大和 183.06、花旗 185.53（08 月）
A16: FY2027 毛利率 vs 花旗（百分點） | B16: =b_gm27 -> 0.349 | C16: =PL!E88 -> 0.33089551 | D16: =C16-B16 -> -0.01810449 | E16: =PL!E129 -> 0.33089551 | F16: =E16-B16 -> -0.01810449 | G16: =PL!E170 -> 0.33089551 | H16: =G16-B16 -> -0.01810449 | I16: 經濟日報 2026-09-19 | J16: 高盛 33.4%、凱基 33.8%
A17: B. 液冷結構（機制檢查）
A18: FY2027 液冷 ÷ 營收 vs 凱基（超過 50%） | B18: =b_lc27 -> 0.5 | C18: =PL!E82 -> 0.46790012 | D18: =C18-B18 -> -0.032099878 | E18: =PL!E123 -> 0.46790012 | F18: =E18-B18 -> -0.032099878 | G18: =PL!E164 -> 0.46790012 | H18: =G18-B18 -> -0.032099878 | I18: 凱基 2026-08-12
A19: CY2026 液冷滲透率（GW）vs TrendForce（顆數） | B19: =tf_pen26 -> 0.53 | C19: =PL!D66 -> 0.55 | D19: =C19-B19 -> 0.02 | E19: =PL!D107 -> 0.55 | F19: =E19-B19 -> 0.02 | G19: =PL!D148 -> 0.55 | H19: =G19-B19 -> 0.02 | I19: TrendForce（ETtoday 2026-08-17） | J19: 口徑不同：GW 計高於顆數計
A20: CY2027 液冷滲透率（GW）vs TrendForce（顆數） | B20: =tf_pen27 -> 0.6 | C20: =PL!E66 -> 0.75 | D20: =C20-B20 -> 0.15 | E20: =PL!E107 -> 0.75 | F20: =E20-B20 -> 0.15 | G20: =PL!E148 -> 0.75 | H20: =G20-B20 -> 0.15 | I20: 同上
A21: FY2026 奇鋐有效份額（本模型市場口徑） | C21: =PL!D70 -> 0.49892764 | E21: =PL!D111 -> 0.49892764 | G21: =PL!D152 -> 0.49892764 | I21: — | J21: 份額第二來源：未找到
A22: CY2027（台達電液冷＋奇鋐液冷）÷ 本模型液冷市場 | C22: =(dlc_27+PL!E73/fx)/PL!E68 -> 1.0410621 | E22: =(dlc_27+PL!E114/fx)/PL!E109 -> 1.0410621 | G22: =(dlc_27+PL!E155/fx)/PL!E150 -> 1.0410621 | I22: 台達電模型 Units（唯讀） | J22: 超過 100%：台達電液冷多在機架外（CDU、液對氣），不在本市場口徑內；但也提示本模型的液冷市場口徑可能偏窄、奇鋐份額可能偏高
A23: CY2026（台達電液冷＋奇鋐液冷）÷ 本模型液冷市場 | C23: =(dlc_26+PL!D73/fx)/PL!D68 -> 1.1535544 | E23: =(dlc_26+PL!D114/fx)/PL!D109 -> 1.1535544 | G23: =(dlc_26+PL!D155/fx)/PL!D150 -> 1.1535544 | I23: 同上
A24: FY2027 每 GW 奇鋐 AI 營收（US$M） | C24: =PL!E84 -> 163.46738 | E24: =PL!E125 -> 163.46738 | G24: =PL!E166 -> 163.46738 | I24: —
A25: FY2027 AI ÷ 營收 | C25: =PL!E83 -> 0.65880569 | E25: =PL!E124 -> 0.65880569 | G25: =PL!E165 -> 0.65880569 | I25: —
A26: C. 校準
A27: 其他營收毛利率（Derived） | C27: =PL!D86 -> 0.3028215 | E27: =PL!D127 -> 0.3028215 | G27: =PL!D168 -> 0.3028215 | I27: FY2026 錨點 | J27: 液冷毛利率＝此值＋d_lc
A28: FY2027 毛利率 vs FY2026（百分點） | B28: =a26_gp/a26_rev -> 0.3220215 | C28: =PL!E88 -> 0.33089551 | D28: =C28-B28 -> 0.0088740073 | E28: =PL!E129 -> 0.33089551 | F28: =E28-B28 -> 0.0088740073 | G28: =PL!E170 -> 0.33089551 | H28: =G28-B28 -> 0.0088740073 | I28: 錨點 | J28: 液冷占比上升使毛利率上升
A29: 4Q26 EPS（模型） | C29: =Q!E15 -> 32.82926 | E29: =Q!E15 -> 32.82926 | G29: =Q!E15 -> 32.82926 | I29: — | J29: 凱基 08-05 估 32.82（以 4Q 營收 626 億為基礎）
A30: D. 預留
A31: R4 產業部署路徑（markets/deploy_path/，尚未建立）：上線後以部署路徑取代「AI IT 資本支出 ÷ 每 GW IT 資本支出」 | J31: 預留列：本版無數值
A33: E. 目標價對帳（v0.2；模型欄為情境加權值，非情境 A）
A34: 12 個月後的前瞻 EPS（情境加權）vs 共識前瞻 EPS | B34: =cons_feps -> 132.58136 | C34: =Val!B114 -> 177.49374 | D34: =C34/B34-1 -> 0.33875332 | I34: stockanalysis 個股頁 2026-10-05：價格 3,585 ÷ Forward PE 27.04 | J34: 共識只作對帳，不作校準
A35: 目標價（DCF 與 Comparable 加權）vs 市場共識目標價 | B35: =cons_tp -> 4130 | C35: =Val!B119 -> 3955.894 | D35: =C35/B35-1 -> -0.042156421 | I35: stockanalysis forecast 頁（S&P Global）17 位分析師平均 4,130（中位數 4,250），頁面時間 2026-10-01 | J35: 共識只作對帳，不作校準
A36: Comparable 目標價 vs 市場共識目標價 | B36: =cons_tp -> 4130 | C36: =Val!B115 -> 4884.6277 | D36: =C36/B36-1 -> 0.18271856 | I36: 同上 | J36: 共識只作對帳，不作校準

Sheet Sens
A1: Sens — 一次動一個輸入（情境 A；有效份額、AI 氣冷每 GW、其他營收毛利率在每個案例內依 FY2026 錨點重算，FY2026 恆等於錨點）：對 FY2027、FY2028 的營收、液冷營收、毛利率與 EPS 的影響。每個案例是一個完整推導區塊（本頁下方）
A3: 案例 | B3: 設定 | C3: FY2027 營收 | D3: FY2027 液冷營收 | E3: FY2027 毛利率 | F3: FY2027 EPS | G3: FY2027 EPS 相對基準 | H3: FY2028 營收 | I3: FY2028 液冷營收 | J3: FY2028 毛利率 | K3: FY2028 EPS | L3: FY2028 EPS 相對基準
A4: 基準（情境 A） | B4: PL 區塊 A | C4: =PL!E80 -> 330.67778 | D4: =PL!E73 -> 154.72417 | E4: =PL!E88 -> 0.33089551 | F4: =PL!E97 -> 163.15512 | G4: =F4/F$4-1 -> 0 | H4: =PL!F80 -> 414.94128 | I4: =PL!F73 -> 226.78138 | J4: =PL!F88 -> 0.33561381 | K4: =PL!F97 -> 209.70215 | L4: =K4/K$4-1 -> 0
A5: 份額流失（低） | B5: 份額相對值 2027 0.85、2028 0.75、2029 0.70（雙鴻、酷碼、台達電追趕） | C5: =E60 -> 314.39102 | D5: =E53 -> 138.43742 | E5: =E68 -> 0.32924161 | F5: =E77 -> 154.01242 | G5: =F5/F$4-1 -> -0.056036841 | H5: =F60 -> 377.14438 | I5: =F53 -> 188.98448 | J5: =F68 -> 0.33288709 | K5: =F77 -> 188.31423 | L5: =K5/K$4-1 -> -0.10199189
A6: 份額上升（高） | B6: 份額相對值 1.05 | C6: =E101 -> 346.96453 | D6: =E94 -> 171.01093 | E6: =E109 -> 0.33239414 | F6: =E118 -> 172.29781 | G6: =F6/F$4-1 -> 0.056036841 | H6: =F101 -> 452.73817 | I6: =F94 -> 264.57828 | J6: =F109 -> 0.33788525 | K6: =F118 -> 231.11198 | L6: =K6/K$4-1 -> 0.10209639
A7: 每架液冷內容 低 | B7: 內容調整 1.0（只有橋接表的機架內液冷） | C7: =E142 -> 294.9722 | D7: =E135 -> 119.01859 | E7: =E150 -> 0.32703096 | F7: =E159 -> 143.11151 | G7: =F7/F$4-1 -> -0.12285 | H7: =F142 -> 350.1466 | I7: =F135 -> 161.9867 | J7: =F150 -> 0.33057903 | K7: =F159 -> 173.06962 | L7: =K7/K$4-1 -> -0.17468838
A8: 每架液冷內容 高 | B8: 內容調整 2027 1.6、2028–29 1.8 | C8: =E183 -> 366.38336 | D8: =E176 -> 190.42975 | E8: =E191 -> 0.33400683 | F8: =E200 -> 183.19872 | G8: =F8/F$4-1 -> 0.12285 | H8: =F183 -> 479.73596 | I8: =F176 -> 291.57606 | J8: =F191 -> 0.33928857 | K8: =F200 -> 246.39051 | L8: =K8/K$4-1 -> 0.17495463
A9: 液冷滲透率 低 | B9: 2026 45%、2027 60%、2028 70%、2029 75% | C9: =E224 -> 327.23946 | D9: =E217 -> 151.28586 | E9: =E232 -> 0.33056006 | F9: =E241 -> 161.22499 | G9: =F9/F$4-1 -> -0.01183 | H9: =F224 -> 416.42351 | I9: =F217 -> 228.26361 | J9: =F232 -> 0.33571066 | K9: =F241 -> 210.55169 | L9: =K9/K$4-1 -> 0.0040511905
A10: 液冷滲透率 高 | B10: 2026 65%、2027 85%、2028–29 95% | C10: =E265 -> 324.33012 | D10: =E258 -> 148.37652 | E10: =E273 -> 0.33027067 | F10: =E282 -> 159.59181 | G10: =F10/F$4-1 -> -0.02184 | H10: =F265 -> 402.62735 | I10: =F258 -> 214.46746 | J10: =F273 -> 0.33478169 | K10: =F282 -> 202.73432 | L10: =K10/K$4-1 -> -0.033227242
A11: AI 氣冷每 GW 低 | B11: 相對值 0.60／0.45／0.40 | C11: =E306 -> 318.05213 | D11: =E299 -> 154.72417 | E11: =E314 -> 0.33200996 | F11: =E323 -> 157.37031 | G11: =F11/F$4-1 -> -0.035455889 | H11: =F306 -> 393.60197 | I11: =F299 -> 226.78138 | J11: =F314 -> 0.33739166 | K11: =F323 -> 199.83441 | L11: =K11/K$4-1 -> -0.04705595
A12: AI 氣冷每 GW 高 | B12: 相對值 0.90／0.85／0.80 | C12: =E347 -> 343.30343 | D12: =E340 -> 154.72417 | E12: =E355 -> 0.32986303 | F12: =E364 -> 168.93993 | G12: =F12/F$4-1 -> 0.035455889 | H12: =F347 -> 436.28058 | I12: =F340 -> 226.78138 | J12: =F355 -> 0.33400988 | K12: =F364 -> 219.57525 | L12: =K12/K$4-1 -> 0.047081571
A13: AI 部署 ×0.8 | B13: FY2027 起 AI IT 資本支出 ×0.8 | C13: =E388 -> 287.1073 | D13: =E381 -> 123.77934 | E13: =E396 -> 0.32868905 | F13: =E405 -> 139.99918 | G13: =F13/F$4-1 -> -0.14192589 | H13: =F388 -> 355.71445 | I13: =F381 -> 181.4251 | J13: =F396 -> 0.33342331 | K13: =F405 -> 177.65903 | L13: =K13/K$4-1 -> -0.15280302
A14: AI 部署 ×1.2 | B14: ×1.2 | C14: =E429 -> 374.24826 | D14: =E422 -> 185.66901 | E14: =E437 -> 0.33258822 | F14: =E446 -> 186.31105 | G14: =F14/F$4-1 -> 0.14192589 | H14: =F429 -> 474.1681 | I14: =F422 -> 272.13766 | J14: =F437 -> 0.3372571 | K14: =F446 -> 241.76088 | L14: =K14/K$4-1 -> 0.15287746
A15: 非 AI 成長 低 | B15: 一般伺服器與非伺服器 2027–29 0% | C15: =E470 -> 323.69657 | D15: =E463 -> 154.72417 | E15: =E478 -> 0.33150099 | F15: =E487 -> 159.95647 | G15: =F15/F$4-1 -> -0.01960494 | H15: =F470 -> 401.97829 | I15: =F463 -> 226.78138 | J15: =F478 -> 0.3366713 | K15: =F487 -> 203.70538 | L15: =K15/K$4-1 -> -0.02859658
A16: 非 AI 成長 高 | B16: 一般伺服器 +15／12／10%、非伺服器 +12／10／8% | C16: =E511 -> 337.34371 | D16: =E504 -> 154.72417 | E16: =E519 -> 0.33034077 | F16: =E528 -> 166.20931 | G16: =F16/F$4-1 -> 0.018719556 | H16: =F511 -> 428.29971 | I16: =F504 -> 226.78138 | J16: =F519 -> 0.33459104 | K16: =F528 -> 215.88575 | L16: =K16/K$4-1 -> 0.029487539
A17: 液冷毛利率差距 2pt | B17: 液冷毛利率只高 2 個百分點 | C17: =E552 -> 330.67778 | D17: =E545 -> 154.72417 | E17: =E560 -> 0.32497951 | F17: =E569 -> 159.791 | G17: =F17/F$4-1 -> -0.020619155 | H17: =F552 -> 414.94128 | I17: =F545 -> 226.78138 | J17: =F560 -> 0.32655227 | K17: =F569 -> 203.23628 | L17: =K17/K$4-1 -> -0.030833568
A18: 液冷毛利率差距 10pt | B18: 高 10 個百分點 | C18: =E593 -> 330.67778 | D18: =E586 -> 154.72417 | E18: =E601 -> 0.33681152 | F18: =E610 -> 166.51924 | G18: =F18/F$4-1 -> 0.020619155 | H18: =F593 -> 414.94128 | I18: =F586 -> 226.78138 | J18: =F601 -> 0.34467535 | K18: =F610 -> 216.16801 | L18: =K18/K$4-1 -> 0.030833568
A19: 營業費用率 +2pt | B19: 營業費用額外 +2% × 營收 | C19: =E634 -> 330.67778 | D19: =E627 -> 154.72417 | E19: =E642 -> 0.33089551 | F19: =E651 -> 151.78217 | G19: =F19/F$4-1 -> -0.06970635 | H19: =F634 -> 414.94128 | I19: =F627 -> 226.78138 | J19: =F642 -> 0.33561381 | K19: =F651 -> 195.43114 | L19: =K19/K$4-1 -> -0.068053707
A20: 2026 液冷占比 28%（讀法） | B20: FY2026 液冷＝營收 × 28%；份額分子變小、氣冷變大 | C20: =E675 -> 322.44337 | D20: =E668 -> 135.38365 | E20: =E683 -> 0.33041358 | F20: =E692 -> 158.71752 | G20: =F20/F$4-1 -> -0.027198601 | H20: =F675 -> 398.64458 | I20: =F668 -> 198.43371 | J20: =F683 -> 0.33508776 | K20: =F692 -> 200.88259 | L20: =K20/K$4-1 -> -0.042057558
A21: 2026 液冷占比 35%（讀法） | B21: FY2026 液冷＝營收 × 35% | C21: =E716 -> 336.85358 | D21: =E709 -> 169.22956 | E21: =E724 -> 0.33116449 | F21: =E733 -> 166.4387 | G21: =F21/F$4-1 -> 0.020125563 | H21: =F716 -> 427.1638 | I21: =F709 -> 248.04213 | J21: =F724 -> 0.33586183 | K21: =F733 -> 216.23105 | L21: =K21/K$4-1 -> 0.031134166
A22: AI 比例 40%（讀法） | B22: 伺服器非液冷中屬 AI 的比例 40% | C22: =E757 -> 326.66018 | D22: =E750 -> 154.72417 | E22: =E765 -> 0.33124079 | F22: =E774 -> 161.31434 | G22: =F22/F$4-1 -> -0.011282391 | H22: =F757 -> 409.87035 | I22: =F750 -> 226.78138 | J22: =F765 -> 0.33601952 | K22: =F774 -> 207.35936 | L22: =K22/K$4-1 -> -0.011171951
A23: AI 比例 80%（讀法） | B23: 80% | C23: =E798 -> 334.69538 | D23: =E791 -> 154.72417 | E23: =E806 -> 0.33055852 | F23: =E815 -> 164.9959 | G23: =F23/F$4-1 -> 0.011282391 | H23: =F798 -> 420.0122 | I23: =F791 -> 226.78138 | J23: =F806 -> 0.3352179 | K23: =F815 -> 212.04494 | L23: =K23/K$4-1 -> 0.011171995
A24: 顆數情境 B | B24: CY2028 ×0.8、CY2029 ×0.85 | C24: =PL!E121 -> 330.67778 | D24: =PL!E114 -> 154.72417 | E24: =PL!E129 -> 0.33089551 | F24: =PL!E138 -> 163.15512 | G24: =F24/F$4-1 -> 0 | H24: =PL!F121 -> 355.71445 | I24: =PL!F114 -> 181.4251 | J24: =PL!F129 -> 0.33342331 | K24: =PL!F138 -> 177.53126 | L24: =K24/K$4-1 -> -0.1534123
A25: 顆數情境 C | B25: CY2028–29 ×0.6 | C25: =PL!E162 -> 330.67778 | D25: =PL!E155 -> 154.72417 | E25: =PL!E170 -> 0.33089551 | F25: =PL!E179 -> 163.15512 | G25: =F25/F$4-1 -> 0 | H25: =PL!F162 -> 296.48762 | I25: =PL!F155 -> 136.06883 | J25: =PL!F170 -> 0.33035766 | K25: =PL!F179 -> 143.42595 | L25: =K25/K$4-1 -> -0.31604921
A27: 讀法：FY2027 三情境相同；顆數情境 B、C 的差異從 FY2028 起。每個案例的 FY2026 有效份額與 AI 氣冷每 GW 依該案例重算，所以 FY2026 恆等於錨點。「液冷滲透率」案例的 FY2026 份額會反向調整（滲透率低 → 份額高），所以只影響 FY2027 起的成長路徑。
A40: 案例區塊：份額流失（低）（情境 A）
A41: 項目 | B41: 單位 | C41: FY2025A | D41: FY2026（錨點） | E41: FY2027 | F41: FY2028 | G41: FY2029 | H41: 說明
A42: A. AI 部署與液冷市場（D 欄＝FY2026 校準年；E–G＝FY2027–FY2029）
A43: AI IT 資本支出 × 情境顆數係數 | B43: US$B | D43: =itc_26*1 -> 781.87292 | E43: =itc_27*1*1 -> 1565.35 | F43: =itc_28*um28_A*1 -> 1984.2639 | G43: =itc_29*um29_A*1 -> 2260.3903
A44: 每 GW IT 資本支出 | B44: US$B | D44: =itpg_gb*(1-vr26)+itpg_vr*vr26 -> 33.414032 | E44: =itpg_vr -> 37.586352 | F44: =itpg_vr -> 37.586352 | G44: =itpg_vr -> 37.586352
A45: 部署 GW（IT 電力） | B45: GW | D45: =D43/D44 -> 23.399538 | E45: =E43/E44 -> 41.646766 | F45: =F43/F44 -> 52.792138 | G45: =G43/G44 -> 60.138592
A46: 液冷滲透率（部署 GW 中液冷占比） | B46: % | D46: =lpen_26 -> 0.55 | E46: =lpen_27 -> 0.75 | F46: =lpen_28 -> 0.85 | G46: =lpen_29 -> 0.9
A47: 每 GW 液冷內容（機架內液冷＋分歧管） | B47: US$M/GW | D47: =((1-vr26)*racks_gb*(cool_gb+mani)+vr26*racks_vr*(cool_vr+mani))/1000 -> 350.7208 | E47: =racks_vr*(cool_vr+mani)*lcadj_27/1000 -> 326.5912 | F47: =racks_vr*(cool_vr+mani)*lcadj_28/1000 -> 351.7136 | G47: =racks_vr*(cool_vr+mani)*lcadj_29/1000 -> 351.7136 | H47: 橋接表每架機架內液冷 × 每 GW 機架數；FY2027 起 × 內容調整（Rubin 全液冷、ASIC 液冷）
A48: AI 液冷市場（奇鋐可做部分；美元） | B48: US$B | D48: =D45*D46*D47/1000 -> 4.5136876 | E48: =E45*E46*E47/1000 -> 10.2011 | F48: =F45*F46*F47/1000 -> 15.782556 | G48: =G45*G46*G47/1000 -> 19.036405
A49: AI 液冷市場（新台幣） | B49: NT$B | D49: =D48*fx -> 144.438 | E49: =E48*fx -> 326.43521 | F49: =F48*fx -> 505.04179 | G49: =G48*fx -> 609.16495
A50: 奇鋐有效份額（FY2026 校準）＝ 液冷營收 ÷ 市場 | B50: % | D50: =a26_lc/D49 -> 0.49892764 | H50: Derived：分子為公司液冷占比（券商說法）× 營收；分母為本模型的液冷市場（不含 CDU、機架外冷卻）
A51: 份額相對值（÷ FY2026） | B51: x | D51: =1 -> 1 | E51: =RLO_27 -> 0.85 | F51: =RLO_28 -> 0.75 | G51: =RLO_29 -> 0.7
A52: 奇鋐有效份額 | B52: % | D52: =$D$50*D51 -> 0.49892764 | E52: =$D$50*E51 -> 0.42408849 | F52: =$D$50*F51 -> 0.37419573 | G52: =$D$50*G51 -> 0.34924935
A53: 液冷營收 | B53: NT$B | C53: =a25_lc -> 20.94585 | D53: =D49*D52 -> 72.064112 | E53: =E49*E52 -> 138.43742 | F53: =F49*F52 -> 188.98448 | G53: =G49*G52 -> 212.75046
A54: B. AI 氣冷、一般伺服器、非伺服器與合計
...

Sheet Sources
A1: 來源（公司原文經媒體轉述：法說簡報原檔未逐份抓取；券商與研調皆為 Interested-party）
A2: 公司（經優分析）：4Q25 法說 2026-03-11（FY2025 損益、資本支出、產能、GPU／ASIC 組合） | B2: https://uanalyze.com.tw/articles/1131748834
A3: 公司（經時報）：1Q26 法說 2026-05-14（1Q26 損益、產品與應用比重） | B3: https://wantrich.chinatimes.com/news/20260514900569-420101
A4: 公司（經優分析）：2Q26 法說 2026-08-12（1H26 損益、伺服器應用比重、3Q／4Q 展望、液冷產能） | B4: https://uanalyze.com.tw/articles/5815653290
A5: 公司（經時報）：2Q26 法說與外資 EPS 2026-08-13（7 月營收、美銀、大和、花旗、中信、群益） | B5: https://wantrich.chinatimes.com/news/20260813900226-420101
A6: 公司（經 TechNews）：9 月營收 2026-10-07 | B6: https://finance.technews.tw/2026/10/07/avc-3017-202609-financial-report/
A7: 資料商：HiStock 各季利潤比率（稅前淨利率）、股價、股數 | B7: https://histock.tw/stock/3017/%E5%88%A9%E6%BD%A4%E6%AF%94%E7%8E%87
A8: 券商：凱基 2026-08-12（2Q26 實績、估計、產品比重） | B8: https://www.kgi.com.hk/zh-cn/-/media/files/kgishk/research-reports/tw-reports/asia-vital-components-3017-tt20260812en.pdf
A9: 券商：凱基 2026-08-05（2025 產品比重、伺服器比重展望） | B9: https://www.kgi.com.hk/zh-cn/-/media/files/kgishk/research-reports/tw-reports/asia-vital-components_20260805_en.pdf
A10: 券商：高盛（經 TechNews 2026-10-19；EPS 2026–28、4Q26 月營收） | B10: https://finance.technews.tw/2026/10/19/avc-target-price/
A11: 券商：澳系（經 TechNews 2026-04-29；液冷占 2026 營收 30–35%） | B11: https://finance.technews.tw/2026/04/29/avc-ai-server/
A12: 券商：花旗（經濟日報 2026-09-19；2027 毛利率 34.9%） | B12: https://money.udn.com/money/amp/story/5607/9764013
A13: 研調：TrendForce AI 晶片液冷滲透率（經 ETtoday 2026-08-17） | B13: https://finance.ettoday.net/news/3220835
... A17: 資料商：鉅亨（10-22 收盤）、財報狗（近 12 月 P/E） | B17: https://www.cnyes.com/twstock/3017
A18: 市場層：markets/network、markets/chip_bridge、tsmc 成品；台達電模型 Units（Recon 用）（本 repo，唯讀）
A19: 待補（人工）：3Q26 財報與法說（預計 11 月中）；法說簡報原檔；液冷與 AI 的季度金額；奇鋐液冷份額；分歧管單價；2016–2020 年 P/E 第二來源；前瞻 P/E 十年歷史（Bloomberg）；券商共識（付費） | B19: 未找到
A20: SemiAnalysis | B20: 未使用
